Workbook
Name asefadf: #REF!
Name bn: '[1]Code List'!#REF!
Name Slicer_1_FR___1_MIS: #N/A
Name Slicer_1_FR___N_MIS: #N/A
Name Slicer_Column1: #N/A
Name Slicer_N_FR___N_MIS: #N/A
Name Slicer_Owner: #N/A
Name Slicer_Resumo_Origem: #N/A
Name Slicer_Status_Universo: #N/A

Sheet Indicadores
A2: Base da lt002_instrument
G3: All Cruza | H3: 2017197 | N3: 1 business Area
A4: All | B4: 2020862
G5: 1 MIS para 1 FR | H5: 1226331 | I5: =H5/$H$3 -> 0.60793814
A6: Tradutor FR + MIS | G6: N MIS para 1 FR | H6: 668181 | I6: =H6/$H$3 -> 0.33124231 | N6: N MIS para 1 FR | O6: 632383
G7: 1 MIS para N FR | H7: 0 | I7: =H7/$H$3 -> 0
A8: All | B8: 7480477 | G8: N MIS para N FR | H8: 122685 | I8: =H8/$H$3 -> 0.060819543
A11: Distinct FR | B11: 5835277
A12: Distinct MIS | B12: 7172852 | G12: All N Cruza | H12: 3665

Sheet Sheet2
D2: 45313 | E2: 45314 | F2: 45315 | G2: 45316 | H2: 45317 | I2: 45318 | J2: 45319 | K2: 45320 | L2: 45321 | M2: 45322 | N2: 45323 | O2: 45324 | P2: 45325 | Q2: 45326
A3: Satélite | B3: Data
A4: Satélite 79 | B4: 45317 | F4: x | H4: X | K4: Q
A5: Satélite 80 | B5: 45315 | F5: x | H5: Q
A6: Satélite 83 | B6: 45320 | E6: x | G6: X | H6: Q | K6: X
A7: Satélite 84 | B7: 45315 | E7: x | F7: X | G7: Q
A8: Satélite 93 | B8: 45320 | E8: x | K8: X | L8: Q
A9: Satélite 109 | B9: 45316 | G9: X | H9: x | K9: X | N9: Q
B15: conta | C15: ESG
A16: 84 | B16: A | C16: x
B17: B | C17: y
A20: 83 | B20: A | C20: XXX
B25: Alerta: Saldo negativo de 1000 € no satelite 84
C27: Ajuste -1000 no id_comb xx no 84
C28: Ajuste -1000 no id_comb xx no 83

Sheet N Cruza
A1: instrmnt_id | B1: chave_fr | C1: tipo
A2: SNCN00000811 | B2: NULL | C2: SNCN
A3: SNCN00000132 | B3: NULL | C3: SNCN | I3: Row Labels | J3: Count of instrmnt_id
A4: SNCN00000449 | B4: NULL | C4: SNCN | I4: C pelo meio | J4: 6
A5: 80CMAH000000WP455000000000086388 | B5: NULL | C5: CMAH | I5: CMAH | J5: 2844
A6: 31000310419104090069674560100000 | B6: NULL | I6: Emp 82 | J6: 331
A7: 31000310171753091069673570100000 | B7: NULL | I7: SNCN | J7: 417
A8: 31000310172199091069674210100000 | B8: NULL | I8: SUPRIMENTOSPTTA | J8: 1
A9: 31CMAH0000000000R262304820019730 | B9: NULL | C9: CMAH | I9: (blank) | J9: 66
A10: 31CMAH0000000000R362304820963130 | B10: NULL | C10: CMAH | I10: Grand Total | J10: 3665
A11: 31CMAH0000000000RAPL384459860000 | B11: NULL | C11: CMAH
A12: 82000000000021154000450000404079 | B12: NULL | C12: Emp 82
A13: 82000000007002745000200000645171 | B13: NULL | C13: Emp 82
A14: 82000000007007660000200000654205 | B14: NULL | C14: Emp 82
A15: 82000000007008136000200000656216 | B15: NULL | C15: Emp 82
A16: 82000000007009031000200000661116 | B16: NULL | C16: Emp 82
A17: 82000000007011204000200000681045 | B17: NULL | C17: Emp 82
A18: 82000000007013337000200000690590 | B18: NULL | C18: Emp 82
A19: 82000000007017412000200000680116 | B19: NULL | C19: Emp 82
A20: 82000000007017955000200000753985 | B20: NULL | C20: Emp 82
A21: 89CMAH2022000041R001520220603343 | B21: NULL | C21: CMAH
A22: 89CMAH2022000041R001520230085361 | B22: NULL | C22: CMAH
... A419: SNCN00000520 | B419: NULL | C419: SNCN
A420: 31000010884341149000000000000000 | B420: NULL
A421: 31000310568959090069674420100000 | B421: NULL
A422: 31000310473499090069673790100000 | B422: NULL
A423: 31000310454895090069674350100000 | B423: NULL
A424: 31CMAH0000000000R262304820011790 | B424: NULL | C424: CMAH
A425: 31CMAH0000000000R262304880020300 | B425: NULL | C425: CMAH
A426: 31CMAH0000000000R962304820211210 | B426: NULL | C426: CMAH
A427: 31CMAH0000000000R962304820311040 | B427: NULL | C427: CMAH
A428: 31CMAH0000000000R962304830389610 | B428: NULL | C428: CMAH
A429: 31CMAH0000000000R962304880395500 | B429: NULL | C429: CMAH
A430: 31CMAHenergyS1xS2OVER2ENFGDRST0A | B430: NULL | C430: CMAH
A431: 82000000000121090000450000416648 | B431: NULL | C431: Emp 82
A432: 82000000000121529000420000424412 | B432: NULL | C432: Emp 82
A433: 82000000000136141000450000506204 | B433: NULL | C433: Emp 82
A434: 31CMAH0000000000R362304820801370 | B434: NULL | C434: CMAH
A435: 31CMAH0000000000R362304820812140 | B435: NULL | C435: CMAH
... A635: SNCN00000398 | B635: NULL | C635: SNCN
...

Sheet Sheet7
A1: GRSS_FEE_CMMSSN_INCM | E1: GRSS_FEE_CMMSSN_INCM_OFF_BLNC
A3: EQUAL | E3: EQUAL
A4: w/o null | B4: 395234 | C4: 801323 | E4: w/o null | F4: 13991 | G4: 1175876
A5: only mant null | B5: 11579 | E5: both null | F5: 1161885
A6: only mat null | B6: 1046
A7: both null | B7: 393464
A9: DIFFERENT | E9: DIFFERENT
A10: w/o null | B10: 365304 | C10: 383485 | E10: w/o null | F10: 3137 | G10: 8932
A11: only mant null | B11: 2116 | E11: both null | F11: 5795
A12: both null | B12: 16065

Sheet Por campo
H11: =23280+47624 -> 70904
C18: Status dos testes
C19: OK | E19: OK (MISS/ NA) | G19: NOK | I19: WIP | K19: Not Started | M19: NA | T19: Testes Universos
B20: Campo | C20: # Instrumentos | D20: % | E20: # Instrumentos | F20: % | G20: # Instrumentos | H20: % | I20: # Instrumentos | J20: % | K20: # Instrumentos 2 | L20: % 3 | M20: # Instrumentos | N20: % | O20: Status do campo | P20: Data Status | Q20: Origem | R20: Resumo Origem | S20: Alterações Corp | T20: 1 FR - 1 MIS | U20: 1 FR - N MIS | V20: Status Universo | W20: N FR - N MIS | X20: Owner | Y20: Notas | Z20: OK | AA20: OK (MISS/ NA) | AB20: NOK | AC20: NOK (MISS/ NA) | AD20: WIP Erro | AE20: WIP (MISS/ NA) | AF20: WIP N/N | AG20: NA | AH20: all | AI20: controlo | AJ20: controlo_2 | AK20: Status (Atualizado) | AL20: Column1
B21: AVRG_BLNC | C21: =1225899+668159+105919 -> 1999977 | D21: =C21/$AH21 -> 0.9896653 | F21: =E21/$AH21 -> 0 | H21: =G21/$AH21 -> 0 | I21: =432+22+16766 -> 17220 | J21: =I21/$AH21 -> 0.0085211162 | K21: 0 | L21: =K21/$AH21 -> 0 | M21: 3665 | N21: =M21/$AH21 -> 0.0018135825 | O21: Em Correção | P21: 45369 | Q21: CT209 | R21: =IF(OR(Q21="CT207",Q21="CT209",Q21="CT211"),"Rentabilidade",IF(Q21="Corporativo","Corporativo",IF(Q21="Calculado","Calculado",IF(Q21="LT ESTR","LT ESTR", IF(Q21="Modelo Verde","Modelo Verde",NA))))) -> Rentabilidade | S21: Sem alterações | T21: OK | U21: OK | V21: =IF(AND(T21="OK",U21="OK"),"OK",IF(AND(T21="Not Started",U21="Not Started"),"Not Started",IF(AND(T21="NOK",U21="NOK"),"NOK",IF(AND(T21="WIP",U21="WIP"),"WIP",IF(AND(OR(T21="OK",U21="OK"))*(OR(T21="NOK",U21="NOK")),"NOK","NA"))))) -> OK | W21: WIP | X21: =IF(OR(O21="Em teste",O21="Em análise de requisitos"),"Test Team",IF(OR(O21="Em Correção",O21="Em Implementação"),"IT Team",IF(O21="Concluído","Fechado","NA"))) -> IT Team | Z21: 1225899 | AE21: 432 | AF21: 790866 | AG21: 3665 | AH21: 2020862 | AI21: =AH21-M21-K21-G21-E21-C21-I21 -> 0 | AJ21: =AH21-SUM(Z21:AG21) -> 0 | AK21: OK | AL21: Alterações Corporação
B22: AVRG_BLNC_OFF_BLNC | C22: =1225899+668159+122462+220+3 -> 2016743 | D22: =C22/$AH22 -> 0.99796176 | F22: =E22/$AH22 -> 0 | H22: =G22/$AH22 -> 0 | I22: =432+22 -> 454 | J22: =I22/$AH22 -> 0.00022465661 | K22: =AH22-C22-I22-M22 -> 0 | L22: =K22/$AH22 -> 0 | M22: 3665 | N22: =M22/$AH22 -> 0.0018135825 | O22: Em Implementação | P22: 45369 | Q22: CT209 | R22: =IF(OR(Q22="CT207",Q22="CT209",Q22="CT211"),"Rentabilidade",IF(Q22="Corporativo","Corporativo",IF(Q22="Calculado","Calculado",IF(Q22="LT ESTR","LT ESTR", IF(Q22="Modelo Verde","Modelo Verde",NA))))) -> Rentabilidade | S22: Sem alterações | T22: OK | U22: OK | V22: =IF(AND(T22="OK",U22="OK"),"OK",IF(AND(T22="Not Started",U22="Not Started"),"Not Started",IF(AND(T22="NOK",U22="NOK"),"NOK",IF(AND(T22="WIP",U22="WIP"),"WIP",IF(AND(OR(T22="OK",U22="OK"))*(OR(T22="NOK",U22="NOK")),"NOK","NA"))))) -> OK | W22: OK | X22: =IF(OR(O22="Em teste",O22="Em análise de requisitos"),"Test Team",IF(OR(O22="Em Correção",O22="Em Implementação"),"IT Team",IF(O22="Concluído","Fechado","NA"))) -> IT Team | AE22: 432 | AH22: 2020862 | AI22: =AH22-M22-K22-G22-E22-C22-I22 -> 0 | AJ22: =AH22-SUM(Z22:AG22) -> 2020430 | AK22: OK | AL22: =IF(S21 <> "Removido 22/12/2023", "A Considerar", "Removido") -> A Considerar
B23: DFLT_STTS_INSTRMNT | C23: 2020862 | D23: =C23/$AH23 -> 1 | F23: =E23/$AH23 -> 0 | H23: =G23/$AH23 -> 0 | J23: =I23/$AH23 -> 0 | L23: =K23/$AH23 -> 0 | N23: =M23/$AH23 -> 0 | O23: Concluído | P23: 45324 | Q23: LT ESTR | R23: =IF(OR(Q23="CT207",Q23="CT209",Q23="CT211"),"Rentabilidade",IF(Q23="Corporativo","Corporativo",IF(Q23="Calculado","Calculado",IF(Q23="LT ESTR","LT ESTR", IF(Q23="Modelo Verde","Modelo Verde",NA))))) -> LT ESTR | S23: Sem alterações | T23: OK | U23: OK | V23: =IF(AND(T23="OK",U23="OK"),"OK",IF(AND(T23="Not Started",U23="Not Started"),"Not Started",IF(AND(T23="NOK",U23="NOK"),"NOK",IF(AND(T23="WIP",U23="WIP"),"WIP",IF(AND(OR(T23="OK",U23="OK"))*(OR(T23="NOK",U23="NOK")),"NOK","NA"))))) -> OK | W23: OK | X23: =IF(OR(O23="Em teste",O23="Em análise de requisitos"),"Test Team",IF(OR(O23="Em Correção",O23="Em Implementação"),"IT Team",IF(O23="Concluído","Fechado","NA"))) -> Fechado | Y23: Tudo a 11111111111 | AH23: 2020862 | AI23: =AH23-M23-K23-G23-E23-C23-I23 -> 0 | AJ23: =AH23-SUM(Z23:AG23) -> 2020862 | AK23: OK | AL23: =IF(S22 <> "Removido 22/12/2023", "A Considerar", "Removido") -> A Considerar
B24: INTRNL_TRNSFR_RT | C24: =1184384+666817+23280+47624 -> 1922105 | D24: =C24/$AH24 -> 0.95113125 | F24: =E24/$AH24 -> 0 | G24: 1 | H24: =G24/$AH24 -> 4.9483834e-07 | I24: =432+22+51780 -> 52234 | J24: =I24/$AH24 -> 0.025847386 | K24: =AH24-C24-Table13[[#This Row],['# Instrumentos ]]-I24-M24 -> 42857 | L24: =K24/$AH24 -> 0.021207287 | M24: 3665 | N24: =M24/$AH24 -> 0.0018135825 | O24: Em Correção | P24: 45369 | Q24: CT209 | R24: =IF(OR(Q24="CT207",Q24="CT209",Q24="CT211"),"Rentabilidade",IF(Q24="Corporativo","Corporativo",IF(Q24="Calculado","Calculado",IF(Q24="LT ESTR","LT ESTR", IF(Q24="Modelo Verde","Modelo Verde",NA))))) -> Rentabilidade | S24: Sem alterações | T24: OK | U24: OK | V24: =IF(AND(T24="OK",U24="OK"),"OK",IF(AND(T24="Not Started",U24="Not Started"),"Not Started",IF(AND(T24="NOK",U24="NOK"),"NOK",IF(AND(T24="WIP",U24="WIP"),"WIP",IF(AND(OR(T24="OK",U24="OK"))*(OR(T24="NOK",U24="NOK")),"NOK","NA"))))) -> OK | W24: WIP | X24: =IF(OR(O24="Em teste",O24="Em análise de requisitos"),"Test Team",IF(OR(O24="Em Correção",O24="Em Implementação"),"IT Team",IF(O24="Concluído","Fechado","NA"))) -> IT Team | Z24: 1184384 | AE24: 424 | AF24: =AH24-AG24-AE24-Z24 -> 832389 | AG24: 3665 | AH24: 2020862 | AI24: =AH24-M24-K24-G24-E24-C24-I24 -> 0 | AJ24: =AH24-SUM(Z24:AG24) -> 0 | AK24: OK | AL24: =IF(S23 <> "Removido 22/12/2023", "A Considerar", "Removido") -> A Considerar
B25: MNGMNT_PRDCT | C25: =1223988+668180 -> 1892168 | D25: =C25/$AH25 -> 0.93631727 | F25: =E25/$AH25 -> 0 | H25: =G25/$AH25 -> 0 | I25: =36+2307+1 -> 2344 | J25: =I25/$AH25 -> 0.0011599011 | K25: =AH25-C25-G25-I25-M25 -> 122685 | L25: =K25/$AH25 -> 0.060709242 | M25: 3665 | N25: =M25/$AH25 -> 0.0018135825 | O25: Em teste | P25: 45338 | Q25: CT207 | R25: =IF(OR(Q25="CT207",Q25="CT209",Q25="CT211"),"Rentabilidade",IF(Q25="Corporativo","Corporativo",IF(Q25="Calculado","Calculado",IF(Q25="LT ESTR","LT ESTR", IF(Q25="Modelo Verde","Modelo Verde",NA))))) -> Rentabilidade | S25: Sem alterações | T25: WIP | U25: WIP | V25: =IF(AND(T25="OK",U25="OK"),"OK",IF(AND(T25="Not Started",U25="Not Started"),"Not Started",IF(AND(T25="NOK",U25="NOK"),"NOK",IF(AND(T25="WIP",U25="WIP"),"WIP",IF(AND(OR(T25="OK",U25="OK"))*(OR(T25="NOK",U25="NOK")),"NOK","NA"))))) -> WIP | W25: Not Started | X25: =IF(OR(O25="Em teste",O25="Em análise de requisitos"),"Test Team",IF(OR(O25="Em Correção",O25="Em Implementação"),"IT Team",IF(O25="Concluído","Fechado","NA"))) -> Test Team | AH25: 2020862 | AI25: =AH25-M25-K25-G25-E25-C25-I25 -> 0 | AJ25: =AH25-SUM(Z25:AG25) -> 2020862 | AK25: Pending quando os 30 casos estiverem ok | AL25: =IF(S24 <> "Removido 22/12/2023", "A Considerar", "Removido") -> A Considerar
B26: NT_LN_LSS_PRVSN | C26: =1225899+668159+122631+46 -> 2016735 | D26: =C26/$AH26 -> 0.9979578 | F26: =E26/$AH26 -> 0 | G26: 8 | H26: =G26/$AH26 -> 3.9587067e-06 | I26: =432+22 -> 454 | J26: =I26/$AH26 -> 0.00022465661 | K26: =AH26-C26-G26-I26-M26 -> 0 | L26: =K26/$AH26 -> 0 | M26: 3665 | N26: =M26/$AH26 -> 0.0018135825 | O26: Em Correção | P26: 45369 | Q26: CT209 | R26: =IF(OR(Q26="CT207",Q26="CT209",Q26="CT211"),"Rentabilidade",IF(Q26="Corporativo","Corporativo",IF(Q26="Calculado","Calculado",IF(Q26="LT ESTR","LT ESTR", IF(Q26="Modelo Verde","Modelo Verde",NA))))) -> Rentabilidade | S26: Sem alterações | T26: OK | U26: OK | V26: =IF(AND(T26="OK",U26="OK"),"OK",IF(AND(T26="Not Started",U26="Not Started"),"Not Started",IF(AND(T26="NOK",U26="NOK"),"NOK",IF(AND(T26="WIP",U26="WIP"),"WIP",IF(AND(OR(T26="OK",U26="OK"))*(OR(T26="NOK",U26="NOK")),"NOK","NA"))))) -> OK | W26: NOK | X26: =IF(OR(O26="Em teste",O26="Em análise de requisitos"),"Test Team",IF(OR(O26="Em Correção",O26="Em Implementação"),"IT Team",IF(O26="Concluído","Fechado","NA"))) -> IT Team | Z26: 1225899 | AD26: 790866 | AE26: 432 | AG26: 3665 | AH26: 2020862 | AI26: =AH26-M26-K26-G26-E26-C26-I26 -> 0 | AJ26: =AH26-SUM(Z26:AG26) -> 0 | AK26: Validar | AL26: =IF(S25 <> "Removido 22/12/2023", "A Considerar", "Removido") -> A Considerar
B27: NT_LN_LSS_PRVSN_OFF_BLNC | C27: =1225899+668159+122682+3 -> 2016743 | D27: =C27/$AH27 -> 0.99796176 | F27: =E27/$AH27 -> 0 | H27: =G27/$AH27 -> 0 | I27: =432+22 -> 454 | J27: =I27/$AH27 -> 0.00022465661 | K27: =AH27-C27-G27-I27-M27 -> 0 | L27: =K27/$AH27 -> 0 | M27: 3665 | N27: =M27/$AH27 -> 0.0018135825 | O27: Em Implementação | P27: 45369 | Q27: CT209 | R27: =IF(OR(Q27="CT207",Q27="CT209",Q27="CT211"),"Rentabilidade",IF(Q27="Corporativo","Corporativo",IF(Q27="Calculado","Calculado",IF(Q27="LT ESTR","LT ESTR", IF(Q27="Modelo Verde","Modelo Verde",NA))))) -> Rentabilidade | S27: Sem alterações | T27: OK | U27: OK | V27: =IF(AND(T27="OK",U27="OK"),"OK",IF(AND(T27="Not Started",U27="Not Started"),"Not Started",IF(AND(T27="NOK",U27="NOK"),"NOK",IF(AND(T27="WIP",U27="WIP"),"WIP",IF(AND(OR(T27="OK",U27="OK"))*(OR(T27="NOK",U27="NOK")),"NOK","NA"))))) -> OK | W27: Not Started | X27: =IF(OR(O27="Em teste",O27="Em análise de requisitos"),"Test Team",IF(OR(O27="Em Correção",O27="Em Implementação"),"IT Team",IF(O27="Concluído","Fechado","NA"))) -> IT Team | Y27: Valores apurados são diferentes | Z27: 1225309 | AB27: 590 | AE27: 432 | AF27: 790866 | AG27: 3665 | AH27: 2020862 | AI27: =AH27-M27-K27-G27-E27-C27-I27 -> 0 | AJ27: =AH27-SUM(Z27:AG27) -> 0 | AK27: Validar | AL27: =IF(S26 <> "Removido 22/12/2023", "A Considerar", "Removido") -> A Considerar
B28: ACCMLTD_CHNGS_FV_CR_INSTRMNT | C28: 2020862 | D28: =C28/$AH28 -> 1 | F28: =E28/$AH28 -> 0 | H28: =G28/$AH28 -> 0 | J28: =I28/$AH28 -> 0 | L28: =K28/$AH28 -> 0 | N28: =M28/$AH28 -> 0 | O28: Concluído | P28: 45317 | Q28: LT ESTR | R28: =IF(OR(Q28="CT207",Q28="CT209",Q28="CT211"),"Rentabilidade",IF(Q28="Corporativo","Corporativo",IF(Q28="Calculado","Calculado",IF(Q28="LT ESTR","LT ESTR", IF(Q28="Modelo Verde","Modelo Verde",NA))))) -> LT ESTR | S28: Sem alterações | T28: OK | U28: OK | V28: =IF(AND(T28="OK",U28="OK"),"OK",IF(AND(T28="Not Started",U28="Not Started"),"Not Started",IF(AND(T28="NOK",U28="NOK"),"NOK",IF(AND(T28="WIP",U28="WIP"),"WIP",IF(AND(OR(T28="OK",U28="OK"))*(OR(T28="NOK",U28="NOK")),"NOK","NA"))))) -> OK | W28: OK | X28: =IF(OR(O28="Em teste",O28="Em análise de requisitos"),"Test Team",IF(OR(O28="Em Correção",O28="Em Implementação"),"IT Team",IF(O28="Concluído","Fechado","NA"))) -> Fechado | Y28: Tudo a 11111111111.00 | AH28: 2020862 | AI28: =AH28-M28-K28-G28-E28-C28-I28 -> 0 | AJ28: =AH28-SUM(Z28:AG28) -> 2020862 | AK28: OK | AL28: =IF(S27 <> "Removido 22/12/2023", "A Considerar", "Removido") -> A Considerar
B29: ACCMLTD_IMPRMNT_INSTRMNT | C29: 2020862 | D29: =C29/$AH29 -> 1 | F29: =E29/$AH29 -> 0 | H29: =G29/$AH29 -> 0 | J29: =I29/$AH29 -> 0 | L29: =K29/$AH29 -> 0 | N29: =M29/$AH29 -> 0 | O29: Concluído | P29: 45321 | Q29: LT ESTR | R29: =IF(OR(Q29="CT207",Q29="CT209",Q29="CT211"),"Rentabilidade",IF(Q29="Corporativo","Corporativo",IF(Q29="Calculado","Calculado",IF(Q29="LT ESTR","LT ESTR", IF(Q29="Modelo Verde","Modelo Verde",NA))))) -> LT ESTR | S29: Sem alterações | T29: OK | U29: OK | V29: =IF(AND(T29="OK",U29="OK"),"OK",IF(AND(T29="Not Started",U29="Not Started"),"Not Started",IF(AND(T29="NOK",U29="NOK"),"NOK",IF(AND(T29="WIP",U29="WIP"),"WIP",IF(AND(OR(T29="OK",U29="OK"))*(OR(T29="NOK",U29="NOK")),"NOK","NA"))))) -> OK | W29: OK | X29: =IF(OR(O29="Em teste",O29="Em análise de requisitos"),"Test Team",IF(OR(O29="Em Correção",O29="Em Implementação"),"IT Team",IF(O29="Concluído","Fechado","NA"))) -> Fechado | AH29: 2020862 | AI29: =AH29-M29-K29-G29-E29-C29-I29 -> 0 | AJ29: =AH29-SUM(Z29:AG29) -> 2020862 | AK29: OK | AL29: =IF(S28 <> "Removido 22/12/2023", "A Considerar", "Removido") -> A Considerar
B30: ACCNTNG_CLSSFCTN | C30: 2020862 | D30: =C30/$AH30 -> 1 | F30: =E30/$AH30 -> 0 | H30: =G30/$AH30 -> 0 | J30: =I30/$AH30 -> 0 | L30: =K30/$AH30 -> 0 | N30: =M30/$AH30 -> 0 | O30: Concluído | P30: 45321 | Q30: LT ESTR | R30: =IF(OR(Q30="CT207",Q30="CT209",Q30="CT211"),"Rentabilidade",IF(Q30="Corporativo","Corporativo",IF(Q30="Calculado","Calculado",IF(Q30="LT ESTR","LT ESTR", IF(Q30="Modelo Verde","Modelo Verde",NA))))) -> LT ESTR | S30: Sem alterações | T30: OK | U30: OK | V30: =IF(AND(T30="OK",U30="OK"),"OK",IF(AND(T30="Not Started",U30="Not Started"),"Not Started",IF(AND(T30="NOK",U30="NOK"),"NOK",IF(AND(T30="WIP",U30="WIP"),"WIP",IF(AND(OR(T30="OK",U30="OK"))*(OR(T30="NOK",U30="NOK")),"NOK","NA"))))) -> OK | W30: OK | X30: =IF(OR(O30="Em teste",O30="Em análise de requisitos"),"Test Team",IF(OR(O30="Em Correção",O30="Em Implementação"),"IT Team",IF(O30="Concluído","Fechado","NA"))) -> Fechado | AH30: 2020862 | AI30: =AH30-M30-K30-G30-E30-C30-I30 -> 0 | AJ30: =AH30-SUM(Z30:AG30) -> 2020862 | AK30: OK | AL30: =IF(S29 <> "Removido 22/12/2023", "A Considerar", "Removido") -> A Considerar
B31: BSNSS_AREA | C31: =1110197+588278 -> 1698475 | D31: =C31/$AH31 -> 0.84047055 | F31: =E31/$AH31 -> 0 | H31: =G31/$AH31 -> 0 | I31: =12+116122+44105 -> 160239 | J31: =I31/$AH31 -> 0.079292401 | K31: =AH31-C31-G31-I31-M31 -> 158483 | L31: =K31/$AH31 -> 0.078423465 | M31: 3665 | N31: =M31/$AH31 -> 0.0018135825 | O31: Em Correção | P31: 45352 | Q31: CT207 | R31: =IF(OR(Q31="CT207",Q31="CT209",Q31="CT211"),"Rentabilidade",IF(Q31="Corporativo","Corporativo",IF(Q31="Calculado","Calculado",IF(Q31="LT ESTR","LT ESTR", IF(Q31="Modelo Verde","Modelo Verde",NA))))) -> Rentabilidade | S31: Sem alterações | T31: WIP | U31: WIP | V31: =IF(AND(T31="OK",U31="OK"),"OK",IF(AND(T31="Not Started",U31="Not Started"),"Not Started",IF(AND(T31="NOK",U31="NOK"),"NOK",IF(AND(T31="WIP",U31="WIP"),"WIP",IF(AND(OR(T31="OK",U31="OK"))*(OR(T31="NOK",U31="NOK")),"NOK","NA"))))) -> WIP | W31: Not Started | X31: =IF(OR(O31="Em teste",O31="Em análise de requisitos"),"Test Team",IF(OR(O31="Em Correção",O31="Em Implementação"),"IT Team",IF(O31="Concluído","Fechado","NA"))) -> IT Team | AH31: 2020862 | AI31: =AH31-M31-K31-G31-E31-C31-I31 -> 0 | AJ31: =AH31-SUM(Z31:AG31) -> 2020862 | AK31: OK | AL31: =IF(S30 <> "Removido 22/12/2023", "A Considerar", "Removido") -> A Considerar
B32: BSNSS_AREA_CCRR | C32: 1952146 | D32: =C32/$AH32 -> 0.96599669 | F32: =E32/$AH32 -> 0 | H32: =G32/$AH32 -> 0 | I32: =AH32-Table13[[#This Row],['# Instrumentos]]-Table13[[#This Row],['# Instrumentos ]] -> 65051 | J32: =I32/$AH32 -> 0.032189729 | L32: =K32/$AH32 -> 0 | M32: 3665 | N32: =M32/$AH32 -> 0.0018135825 | O32: Em teste | P32: 45320 | Q32: CT207 | R32: =IF(OR(Q32="CT207",Q32="CT209",Q32="CT211"),"Rentabilidade",IF(Q32="Corporativo","Corporativo",IF(Q32="Calculado","Calculado",IF(Q32="LT ESTR","LT ESTR", IF(Q32="Modelo Verde","Modelo Verde",NA))))) -> Rentabilidade | S32: Sem alterações | T32: WIP | U32: WIP | V32: =IF(AND(T32="OK",U32="OK"),"OK",IF(AND(T32="Not Started",U32="Not Started"),"Not Started",IF(AND(T32="NOK",U32="NOK"),"NOK",IF(AND(T32="WIP",U32="WIP"),"WIP",IF(AND(OR(T32="OK",U32="OK"))*(OR(T32="NOK",U32="NOK")),"NOK","NA"))))) -> WIP | W32: WIP | X32: =IF(OR(O32="Em teste",O32="Em análise de requisitos"),"Test Team",IF(OR(O32="Em Correção",O32="Em Implementação"),"IT Team",IF(O32="Concluído","Fechado","NA"))) -> Test Team | AH32: 2020862 | AI32: =AH32-M32-K32-G32-E32-C32-I32 -> 0 | AJ32: =AH32-SUM(Z32:AG32) -> 2020862 | AK32: OK | AL32: =IF(S31 <> "Removido 22/12/2023", "A Considerar", "Removido") -> A Considerar
B33: BSNSS_AREA_DSTNTN | C33: 2020862 | D33: =C33/$AH33 -> 1 | F33: =E33/$AH33 -> 0 | H33: =G33/$AH33 -> 0 | J33: =I33/$AH33 -> 0 | L33: =K33/$AH33 -> 0 | N33: =M33/$AH33 -> 0 | O33: Concluído | P33: 45317 | Q33: Corporativo | R33: =IF(OR(Q33="CT207",Q33="CT209",Q33="CT211"),"Rentabilidade",IF(Q33="Corporativo","Corporativo",IF(Q33="Calculado","Calculado",IF(Q33="LT ESTR","LT ESTR", IF(Q33="Modelo Verde","Modelo Verde",NA))))) -> Corporativo | S33: Sem alterações | T33: OK | U33: OK | V33: =IF(AND(T33="OK",U33="OK"),"OK",IF(AND(T33="Not Started",U33="Not Started"),"Not Started",IF(AND(T33="NOK",U33="NOK"),"NOK",IF(AND(T33="WIP",U33="WIP"),"WIP",IF(AND(OR(T33="OK",U33="OK"))*(OR(T33="NOK",U33="NOK")),"NOK","NA"))))) -> OK | W33: OK | X33: =IF(OR(O33="Em teste",O33="Em análise de requisitos"),"Test Team",IF(OR(O33="Em Correção",O33="Em Implementação"),"IT Team",IF(O33="Concluído","Fechado","NA"))) -> Fechado | AH33: 2020862 | AI33: =AH33-M33-K33-G33-E33-C33-I33 -> 0 | AJ33: =AH33-SUM(Z33:AG33) -> 2020862 | AK33: OK | AL33: =IF(S32 <> "Removido 22/12/2023", "A Considerar", "Removido") -> A Considerar
B34: CNCLLD_INSTRMNT_STTS | D34: =C34/$AH34 -> 0 | F34: =E34/$AH34 -> 0 | H34: =G34/$AH34 -> 0 | J34: =I34/$AH34 -> 0 | K34: 2020862 | L34: =K34/$AH34 -> 1 | N34: =M34/$AH34 -> 0 | O34: Em Implementação | P34: 45321 | Q34: Calculado | R34: =IF(OR(Q34="CT207",Q34="CT209",Q34="CT211"),"Rentabilidade",IF(Q34="Corporativo","Corporativo",IF(Q34="Calculado","Calculado",IF(Q34="LT ESTR","LT ESTR", IF(Q34="Modelo Verde","Modelo Verde",NA))))) -> Calculado | S34: Adicionado 22/12/2023 | T34: Not Started | U34: Not Started | V34: =IF(AND(T34="OK",U34="OK"),"OK",IF(AND(T34="Not Started",U34="Not Started"),"Not Started",IF(AND(T34="NOK",U34="NOK"),"NOK",IF(AND(T34="WIP",U34="WIP"),"WIP",IF(AND(OR(T34="OK",U34="OK"))*(OR(T34="NOK",U34="NOK")),"NOK","NA"))))) -> Not Started | W34: Not Started | X34: =IF(OR(O34="Em teste",O34="Em análise de requisitos"),"Test Team",IF(OR(O34="Em Correção",O34="Em Implementação"),"IT Team",IF(O34="Concluído","Fechado","NA"))) -> IT Team | AH34: 2020862 | AI34: =AH34-M34-K34-G34-E34-C34-I34 -> 0 | AJ34: =AH34-SUM(Z34:AG34) -> 2020862 | AK34: OK | AL34: =IF(S33 <> "Removido 22/12/2023", "A Considerar", "Removido") -> A Considerar
B35: COD_SOC | C35: 2020862 | D35: =C38/$AH35 -> 1 | F35: =E35/$AH35 -> 0 | H35: =G35/$AH35 -> 0 | J35: =I35/$AH35 -> 0 | L35: =K35/$AH35 -> 0 | N35: =M35/$AH35 -> 0 | O35: Concluído | P35: 45321 | Q35: LT ESTR | R35: =IF(OR(Q35="CT207",Q35="CT209",Q35="CT211"),"Rentabilidade",IF(Q35="Corporativo","Corporativo",IF(Q35="Calculado","Calculado",IF(Q35="LT ESTR","LT ESTR", IF(Q35="Modelo Verde","Modelo Verde",NA))))) -> LT ESTR | S35: Sem alterações | T35: OK | U35: OK | V35: =IF(AND(T35="OK",U35="OK"),"OK",IF(AND(T35="Not Started",U35="Not Started"),"Not Started",IF(AND(T35="NOK",U35="NOK"),"NOK",IF(AND(T35="WIP",U35="WIP"),"WIP",IF(AND(OR(T35="OK",U35="OK"))*(OR(T35="NOK",U35="NOK")),"NOK","NA"))))) -> OK | W35: OK | X35: =IF(OR(O35="Em teste",O35="Em análise de requisitos"),"Test Team",IF(OR(O35="Em Correção",O35="Em Implementação"),"IT Team",IF(O35="Concluído","Fechado","NA"))) -> Fechado | AH35: 2020862 | AI35: =AH35-M35-K35-G35-E35-C35-I35 -> 0 | AJ35: =AH35-SUM(Z35:AG35) -> 2020862 | AK35: OK | AL35: =IF(S34 <> "Removido 22/12/2023", "A Considerar", "Removido") -> A Considerar
B36: COD_SOC_DSTNTN | C36: 2020862 | D36: =C36/$AH36 -> 1 | F36: =E36/$AH36 -> 0 | H36: =G36/$AH36 -> 0 | J36: =I36/$AH36 -> 0 | L36: =K36/$AH36 -> 0 | N36: =M36/$AH36 -> 0 | O36: Concluído | P36: 45317 | Q36: Corporativo | R36: =IF(OR(Q36="CT207",Q36="CT209",Q36="CT211"),"Rentabilidade",IF(Q36="Corporativo","Corporativo",IF(Q36="Calculado","Calculado",IF(Q36="LT ESTR","LT ESTR", IF(Q36="Modelo Verde","Modelo Verde",NA))))) -> Corporativo | S36: Sem alterações | T36: OK | U36: OK | V36: =IF(AND(T36="OK",U36="OK"),"OK",IF(AND(T36="Not Started",U36="Not Started"),"Not Started",IF(AND(T36="NOK",U36="NOK"),"NOK",IF(AND(T36="WIP",U36="WIP"),"WIP",IF(AND(OR(T36="OK",U36="OK"))*(OR(T36="NOK",U36="NOK")),"NOK","NA"))))) -> OK | W36: OK | X36: =IF(OR(O36="Em teste",O36="Em análise de requisitos"),"Test Team",IF(OR(O36="Em Correção",O36="Em Implementação"),"IT Team",IF(O36="Concluído","Fechado","NA"))) -> Fechado | AH36: 2020862 | AI36: =AH36-M36-K36-G36-E36-C36-I36 -> 0 | AJ36: =AH36-SUM(Z36:AG36) -> 2020862 | AK36: OK | AL36: =IF(S35 <> "Removido 22/12/2023", "A Considerar", "Removido") -> A Considerar
B37: COD_SOC_INTRGRP | D37: =C37/$AH37 -> 0 | F37: =E37/$AH37 -> 0 | H37: =G37/$AH37 -> 0 | J37: =I37/$AH37 -> 0 | K37: 2020862 | L37: =K37/$AH37 -> 1 | N37: =M37/$AH37 -> 0 | O37: Em Implementação | P37: 45322 | Q37: LT ESTR | R37: =IF(OR(Q37="CT207",Q37="CT209",Q37="CT211"),"Rentabilidade",IF(Q37="Corporativo","Corporativo",IF(Q37="Calculado","Calculado",IF(Q37="LT ESTR","LT ESTR", IF(Q37="Modelo Verde","Modelo Verde",NA))))) -> LT ESTR | S37: Adicionado 22/12/2023 | T37: Not Started | U37: Not Started | V37: =IF(AND(T37="OK",U37="OK"),"OK",IF(AND(T37="Not Started",U37="Not Started"),"Not Started",IF(AND(T37="NOK",U37="NOK"),"NOK",IF(AND(T37="WIP",U37="WIP"),"WIP",IF(AND(OR(T37="OK",U37="OK"))*(OR(T37="NOK",U37="NOK")),"NOK","NA"))))) -> Not Started | W37: Not Started | X37: =IF(OR(O37="Em teste",O37="Em análise de requisitos"),"Test Team",IF(OR(O37="Em Correção",O37="Em Implementação"),"IT Team",IF(O37="Concluído","Fechado","NA"))) -> IT Team | Y37: Quem está owner deste campo ? | AH37: 2020862 | AI37: =AH37-M37-K37-G37-E37-C37-I37 -> 0 | AJ37: =AH37-SUM(Z37:AG37) -> 2020862 | AK37: OK | AL37: =IF(S36 <> "Removido 22/12/2023", "A Considerar", "Removido") -> A Considerar
B38: DT_RFRNC | C38: 2020862 | D38: =C38/$AH38 -> 1 | F38: =E38/$AH38 -> 0 | H38: =G38/$AH38 -> 0 | J38: =I38/$AH38 -> 0 | L38: =K38/$AH38 -> 0 | N38: =M38/$AH38 -> 0 | O38: Concluído | P38: 45317 | Q38: LT ESTR | R38: =IF(OR(Q38="CT207",Q38="CT209",Q38="CT211"),"Rentabilidade",IF(Q38="Corporativo","Corporativo",IF(Q38="Calculado","Calculado",IF(Q38="LT ESTR","LT ESTR", IF(Q38="Modelo Verde","Modelo Verde",NA))))) -> LT ESTR | S38: Sem alterações | T38: OK | U38: OK | V38: =IF(AND(T38="OK",U38="OK"),"OK",IF(AND(T38="Not Started",U38="Not Started"),"Not Started",IF(AND(T38="NOK",U38="NOK"),"NOK",IF(AND(T38="WIP",U38="WIP"),"WIP",IF(AND(OR(T38="OK",U38="OK"))*(OR(T38="NOK",U38="NOK")),"NOK","NA"))))) -> OK | W38: OK | X38: =IF(OR(O38="Em teste",O38="Em análise de requisitos"),"Test Team",IF(OR(O38="Em Correção",O38="Em Implementação"),"IT Team",IF(O38="Concluído","Fechado","NA"))) -> Fechado | Z38: 2020862 | AH38: 2020862 | AI38: =AH38-M38-K38-G38-E38-C38-I38 -> 0 | AJ38: =AH38-SUM(Z38:AG38) -> 0 | AK38: OK | AL38: =IF(S37 <> "Removido 22/12/2023", "A Considerar", "Removido") -> A Considerar
B39: FLG_INSTRMNT_CNCLLD | D39: =C39/$AH39 -> 0 | F39: =E39/$AH39 -> 0 | G39: 2020862 | H39: =G39/$AH39 -> 1 | J39: =I39/$AH39 -> 0 | L39: =K39/$AH39 -> 0 | N39: =M39/$AH39 -> 0 | O39: NA | P39: NA | Q39: Calculado | R39: =IF(OR(Q39="CT207",Q39="CT209",Q39="CT211"),"Rentabilidade",IF(Q39="Corporativo","Corporativo",IF(Q39="Calculado","Calculado",IF(Q39="LT ESTR","LT ESTR", IF(Q39="Modelo Verde","Modelo Verde",NA))))) -> Calculado | S39: Removido 22/12/2023 | T39: NA | U39: NA | V39: =IF(AND(T39="OK",U39="OK"),"OK",IF(AND(T39="Not Started",U39="Not Started"),"Not Started",IF(AND(T39="NOK",U39="NOK"),"NOK",IF(AND(T39="WIP",U39="WIP"),"WIP",IF(AND(OR(T39="OK",U39="OK"))*(OR(T39="NOK",U39="NOK")),"NOK","NA"))))) -> NA | W39: NA | X39: =IF(OR(O39="Em teste",O39="Em análise de requisitos"),"Test Team",IF(OR(O39="Em Correção",O39="Em Implementação"),"IT Team",IF(O39="Concluído","Fechado","NA"))) -> NA | AB39: 2020862 | AH39: 2020862 | AI39: =AH39-M39-K39-G39-E39-C39 -> 0 | AJ39: =AH39-SUM(Z39:AG39) -> 0 | AK39: OK | AL39: =IF(S38 <> "Removido 22/12/2023", "A Considerar", "Removido") -> A Considerar
B40: FLG_INTRBSNSS | C40: 2020862 | D40: =C40/$AH40 -> 1 | F40: =E40/$AH40 -> 0 | H40: =G40/$AH40 -> 0 | J40: =I40/$AH40 -> 0 | L40: =K40/$AH40 -> 0 | N40: =M40/$AH40 -> 0 | O40: Concluído | P40: 45317 | Q40: Corporativo | R40: =IF(OR(Q40="CT207",Q40="CT209",Q40="CT211"),"Rentabilidade",IF(Q40="Corporativo","Corporativo",IF(Q40="Calculado","Calculado",IF(Q40="LT ESTR","LT ESTR", IF(Q40="Modelo Verde","Modelo Verde",NA))))) -> Corporativo | S40: Sem alterações | T40: OK | U40: OK | V40: =IF(AND(T40="OK",U40="OK"),"OK",IF(AND(T40="Not Started",U40="Not Started"),"Not Started",IF(AND(T40="NOK",U40="NOK"),"NOK",IF(AND(T40="WIP",U40="WIP"),"WIP",IF(AND(OR(T40="OK",U40="OK"))*(OR(T40="NOK",U40="NOK")),"NOK","NA"))))) -> OK | W40: OK | X40: =IF(OR(O40="Em teste",O40="Em análise de requisitos"),"Test Team",IF(OR(O40="Em Correção",O40="Em Implementação"),"IT Team",IF(O40="Concluído","Fechado","NA"))) -> Fechado | Z40: 2020862 | AH40: 2020862 | AI40: =AH40-M40-K40-G40-E40-C40-I40 -> 0 | AJ40: =AH40-SUM(Z40:AG40) -> 0 | AK40: OK | AL40: =IF(S39 <> "Removido 22/12/2023", "A Considerar", "Removido") -> Removido
B41: GNS_FNNCL_TRNSCTN_EXCHNG_CCRR | D41: =C41/$AH41 -> 0 | F41: =E41/$AH41 -> 0 | H41: =G41/$AH41 -> 0 | J41: =I41/$AH41 -> 0 | K41: =2020862-3665 -> 2017197 | L41: =K41/$AH41 -> 0.99818642 | M41: 3665 | N41: =M41/$AH41 -> 0.0018135825 | O41: Em teste | P41: 45320 | Q41: CT209 | R41: =IF(OR(Q41="CT207",Q41="CT209",Q41="CT211"),"Rentabilidade",IF(Q41="Corporativo","Corporativo",IF(Q41="Calculado","Calculado",IF(Q41="LT ESTR","LT ESTR", IF(Q41="Modelo Verde","Modelo Verde",NA))))) -> Rentabilidade | S41: Sem alterações | T41: Not Started | U41: Not Started | V41: =IF(AND(T41="OK",U41="OK"),"OK",IF(AND(T41="Not Started",U41="Not Started"),"Not Started",IF(AND(T41="NOK",U41="NOK"),"NOK",IF(AND(T41="WIP",U41="WIP"),"WIP",IF(AND(OR(T41="OK",U41="OK"))*(OR(T41="NOK",U41="NOK")),"NOK","NA"))))) -> Not Started | W41: Not Started | X41: =IF(OR(O41="Em teste",O41="Em análise de requisitos"),"Test Team",IF(OR(O41="Em Correção",O41="Em Implementação"),"IT Team",IF(O41="Concluído","Fechado","NA"))) -> Test Team | AE41: 424 | AH41: 2020862 | AI41: =AH41-M41-#REF!-K41-E41-C41-I41 -> #REF! | AJ41: =AH41-SUM(Z41:AG41) -> 2020438 | AK41: OK | AL41: =IF(S40 <> "Removido 22/12/2023", "A Considerar", "Removido") -> A Considerar
B42: GNS_FNNCL_TRNSCTN_EXCHNG_DFFRNCS | C42: =1184384+632361 -> 1816745 | D42: =C42/$AH42 -> 0.89899508 | F42: =E42/$AH42 -> 0 | H42: =G42/$AH42 -> 0 | I42: =424+22 -> 446 | J42: =I42/$AH42 -> 0.0002206979 | K42: =AH42-C42-I42-M42 -> 200006 | L42: =K42/$AH42 -> 0.098970637 | M42: 3665 | N42: =M42/$AH42 -> 0.0018135825 | O42: Em teste | P42: 45338 | Q42: CT209 | R42: =IF(OR(Q42="CT207",Q42="CT209",Q42="CT211"),"Rentabilidade",IF(Q42="Corporativo","Corporativo",IF(Q42="Calculado","Calculado",IF(Q42="LT ESTR","LT ESTR", IF(Q42="Modelo Verde","Modelo Verde",NA))))) -> Rentabilidade | S42: Sem alterações | T42: OK | U42: OK | V42: =IF(AND(T42="OK",U42="OK"),"OK",IF(AND(T42="Not Started",U42="Not Started"),"Not Started",IF(AND(T42="NOK",U42="NOK"),"NOK",IF(AND(T42="WIP",U42="WIP"),"WIP",IF(AND(OR(T42="OK",U42="OK"))*(OR(T42="NOK",U42="NOK")),"NOK","NA"))))) -> OK | W42: Not Started | X42: =IF(OR(O42="Em teste",O42="Em análise de requisitos"),"Test Team",IF(OR(O42="Em Correção",O42="Em Implementação"),"IT Team",IF(O42="Concluído","Fechado","NA"))) -> Test Team | AE42: 424 | AH42: 2020862 | AI42: =AH42-M42-K42-G42-E42-C42-I42 -> 0 | AJ42: =AH42-SUM(Z42:AG42) -> 2020438 | AK42: NOK (CCRR - Alterar para Em correção quando enviado email a especificar como devem ser aprovisionados este tipos de campos ?) | AL42: =IF(S41 <> "Removido 22/12/2023", "A Considerar", "Removido") -> A Considerar
B43: GRSS_CMMSSN_EXPNS | C43: =1223921+632357 -> 1856278 | D43: =C43/$AH43 -> 0.91855753 | F43: =E43/$AH43 -> 0 | H43: =G43/$AH43 -> 0 | I43: =1978+432+4+22 -> 2436 | J43: =I43/$AH43 -> 0.0012054262 | K43: =AH43-C43-I43-M43-G43 -> 158483 | L43: =K43/$AH43 -> 0.078423465 | M43: 3665 | N43: =M43/$AH43 -> 0.0018135825 | O43: Em teste | P43: 45345 | Q43: CT211 | R43: =IF(OR(Q43="CT207",Q43="CT209",Q43="CT211"),"Rentabilidade",IF(Q43="Corporativo","Corporativo",IF(Q43="Calculado","Calculado",IF(Q43="LT ESTR","LT ESTR", IF(Q43="Modelo Verde","Modelo Verde",NA))))) -> Rentabilidade | S43: Alterado 22/12/2023 | T43: WIP | U43: WIP | V43: =IF(AND(T43="OK",U43="OK"),"OK",IF(AND(T43="Not Started",U43="Not Started"),"Not Started",IF(AND(T43="NOK",U43="NOK"),"NOK",IF(AND(T43="WIP",U43="WIP"),"WIP",IF(AND(OR(T43="OK",U43="OK"))*(OR(T43="NOK",U43="NOK")),"NOK","NA"))))) -> WIP | W43: Not Started | X43: =IF(OR(O43="Em teste",O43="Em análise de requisitos"),"Test Team",IF(OR(O43="Em Correção",O43="Em Implementação"),"IT Team",IF(O43="Concluído","Fechado","NA"))) -> Test Team | AH43: 2020862 | AI43: =AH43-M43-K43-G43-E43-C43-I43 -> 0 | AJ43: =AH43-SUM(Z43:AG43) -> 2020862 | AK43: OK | AL43: =IF(S42 <> "Removido 22/12/2023", "A Considerar", "Removido") -> A Considerar
B44: GRSS_CMMSSN_EXPNS_CCRR | D44: =C44/$AH44 -> 0 | F44: =E44/$AH44 -> 0 | H44: =G44/$AH44 -> 0 | J44: =I44/$AH44 -> 0 | K44: =2020862-3665 -> 2017197 | L44: =K44/$AH44 -> 0.99818642 | M44: 3665 | N44: =M44/$AH44 -> 0.0018135825 | O44: Em teste | P44: 45321 | Q44: CT211 | R44: =IF(OR(Q44="CT207",Q44="CT209",Q44="CT211"),"Rentabilidade",IF(Q44="Corporativo","Corporativo",IF(Q44="Calculado","Calculado",IF(Q44="LT ESTR","LT ESTR", IF(Q44="Modelo Verde","Modelo Verde",NA))))) -> Rentabilidade | S44: Alterado 22/12/2023 | T44: Not Started | U44: Not Started | V44: =IF(AND(T44="OK",U44="OK"),"OK",IF(AND(T44="Not Started",U44="Not Started"),"Not Started",IF(AND(T44="NOK",U44="NOK"),"NOK",IF(AND(T44="WIP",U44="WIP"),"WIP",IF(AND(OR(T44="OK",U44="OK"))*(OR(T44="NOK",U44="NOK")),"NOK","NA"))))) -> Not Started | W44: Not Started | X44: =IF(OR(O44="Em teste",O44="Em análise de requisitos"),"Test Team",IF(OR(O44="Em Correção",O44="Em Implementação"),"IT Team",IF(O44="Concluído","Fechado","NA"))) -> Test Team | AH44: 2020862 | AI44: =AH44-M44-#REF!-K44-E44-C44-I44 -> #REF! | AJ44: =AH44-SUM(Z44:AG44) -> 2020862 | AK44: OK | AL44: =IF(S43 <> "Removido 22/12/2023", "A Considerar", "Removido") -> A Considerar
B45: GRSS_CMMSSN_EXPNS_OFF_BLNC | C45: =1223823+632381 -> 1856204 | D45: =C45/$AH45 -> 0.91852091 | F45: =E45/$AH45 -> 0 | H45: =G45/$AH45 -> 0 | I45: =2076+432+1+22 -> 2531 | J45: =I45/$AH45 -> 0.0012524358 | K45: =AH45-C45-I45-M45-G45 -> 158462 | L45: =K45/$AH45 -> 0.078413073 | M45: 3665 | N45: =M45/$AH45 -> 0.0018135825 | O45: Em teste | P45: 45338 | Q45: CT211 | R45: =IF(OR(Q45="CT207",Q45="CT209",Q45="CT211"),"Rentabilidade",IF(Q45="Corporativo","Corporativo",IF(Q45="Calculado","Calculado",IF(Q45="LT ESTR","LT ESTR", IF(Q45="Modelo Verde","Modelo Verde",NA))))) -> Rentabilidade | S45: Alterado 22/12/2023 | T45: WIP | U45: WIP | V45: =IF(AND(T45="OK",U45="OK"),"OK",IF(AND(T45="Not Started",U45="Not Started"),"Not Started",IF(AND(T45="NOK",U45="NOK"),"NOK",IF(AND(T45="WIP",U45="WIP"),"WIP",IF(AND(OR(T45="OK",U45="OK"))*(OR(T45="NOK",U45="NOK")),"NOK","NA"))))) -> WIP | W45: Not Started | X45: =IF(OR(O45="Em teste",O45="Em análise de requisitos"),"Test Team",IF(OR(O45="Em Correção",O45="Em Implementação"),"IT Team",IF(O45="Concluído","Fechado","NA"))) -> Test Team | AH45: 2020862 | AI45: =AH45-M45-K45-G45-E45-C45-I45 -> 0 | AJ45: =AH45-SUM(Z45:AG45) -> 2020862 | AK45: OK | AL45: =IF(S44 <> "Removido 22/12/2023", "A Considerar", "Removido") -> A Considerar
B46: GRSS_CMMSSN_EXPNS_OFF_BLNC_CCRR | D46: =C46/$AH46 -> 0 | F46: =E46/$AH46 -> 0 | H46: =G46/$AH46 -> 0 | J46: =I46/$AH46 -> 0 | K46: =2020862-3665 -> 2017197 | L46: =K46/$AH46 -> 0.99818642 | M46: 3665 | N46: =M46/$AH46 -> 0.0018135825 | O46: Em teste | P46: 45321 | Q46: CT211 | R46: =IF(OR(Q46="CT207",Q46="CT209",Q46="CT211"),"Rentabilidade",IF(Q46="Corporativo","Corporativo",IF(Q46="Calculado","Calculado",IF(Q46="LT ESTR","LT ESTR", IF(Q46="Modelo Verde","Modelo Verde",NA))))) -> Rentabilidade | S46: Alterado 22/12/2023 | T46: Not Started | U46: Not Started | V46: =IF(AND(T46="OK",U46="OK"),"OK",IF(AND(T46="Not Started",U46="Not Started"),"Not Started",IF(AND(T46="NOK",U46="NOK"),"NOK",IF(AND(T46="WIP",U46="WIP"),"WIP",IF(AND(OR(T46="OK",U46="OK"))*(OR(T46="NOK",U46="NOK")),"NOK","NA"))))) -> Not Started | W46: Not Started | X46: =IF(OR(O46="Em teste",O46="Em análise de requisitos"),"Test Team",IF(OR(O46="Em Correção",O46="Em Implementação"),"IT Team",IF(O46="Concluído","Fechado","NA"))) -> Test Team | AH46: 2020862 | AI46: =AH46-M46-#REF!-K46-E46-C46-I46 -> #REF! | AJ46: =AH46-SUM(Z46:AG46) -> 2020862 | AK46: OK | AL46: =IF(S45 <> "Removido 22/12/2023", "A Considerar", "Removido") -> A Considerar
B47: GRSS_CMMSSN_INCM | C47: =1216748+632330 -> 1849078 | D47: =C47/$AH47 -> 0.91499469 | F47: =E47/$AH47 -> 0 | H47: =G47/$AH47 -> 0 | I47: =9151+432+31+22 -> 9636 | J47: =I47/$AH47 -> 0.0047682623 | K47: =AH47-C47-I47-M47-G47 -> 158483 | L47: =K47/$AH47 -> 0.078423465 | M47: 3665 | N47: =M47/$AH47 -> 0.0018135825 | O47: Em teste | P47: 45345 | Q47: CT211 | R47: =IF(OR(Q47="CT207",Q47="CT209",Q47="CT211"),"Rentabilidade",IF(Q47="Corporativo","Corporativo",IF(Q47="Calculado","Calculado",IF(Q47="LT ESTR","LT ESTR", IF(Q47="Modelo Verde","Modelo Verde",NA))))) -> Rentabilidade | S47: Alterado 22/12/2023 | T47: WIP | U47: WIP | V47: =IF(AND(T47="OK",U47="OK"),"OK",IF(AND(T47="Not Started",U47="Not Started"),"Not Started",IF(AND(T47="NOK",U47="NOK"),"NOK",IF(AND(T47="WIP",U47="WIP"),"WIP",IF(AND(OR(T47="OK",U47="OK"))*(OR(T47="NOK",U47="NOK")),"NOK","NA"))))) -> WIP | W47: Not Started | X47: =IF(OR(O47="Em teste",O47="Em análise de requisitos"),"Test Team",IF(OR(O47="Em Correção",O47="Em Implementação"),"IT Team",IF(O47="Concluído","Fechado","NA"))) -> Test Team | Y47: Falta correr um teste - Processo de GD não terminado | AH47: 2020862 | AI47: =AH47-M47-K47-G47-E47-C47-I47 -> 0 | AJ47: =AH47-SUM(Z47:AG47) -> 2020862 | AK47: OK | AL47: =IF(S46 <> "Removido 22/12/2023", "A Considerar", "Removido") -> A Considerar
B48: GRSS_CMMSSN_INCM_CCRR | D48: =C48/$AH48 -> 0 | F48: =E48/$AH48 -> 0 | H48: =G48/$AH48 -> 0 | J48: =I48/$AH48 -> 0 | K48: =2020862-3665 -> 2017197 | L48: =K48/$AH48 -> 0.99818642 | M48: 3665 | N48: =M48/$AH48 -> 0.0018135825 | O48: Em teste | P48: 45321 | Q48: CT211 | R48: =IF(OR(Q48="CT207",Q48="CT209",Q48="CT211"),"Rentabilidade",IF(Q48="Corporativo","Corporativo",IF(Q48="Calculado","Calculado",IF(Q48="LT ESTR","LT ESTR", IF(Q48="Modelo Verde","Modelo Verde",NA))))) -> Rentabilidade | S48: Alterado 22/12/2023 | T48: Not Started | U48: Not Started | V48: =IF(AND(T48="OK",U48="OK"),"OK",IF(AND(T48="Not Started",U48="Not Started"),"Not Started",IF(AND(T48="NOK",U48="NOK"),"NOK",IF(AND(T48="WIP",U48="WIP"),"WIP",IF(AND(OR(T48="OK",U48="OK"))*(OR(T48="NOK",U48="NOK")),"NOK","NA"))))) -> Not Started | W48: Not Started | X48: =IF(OR(O48="Em teste",O48="Em análise de requisitos"),"Test Team",IF(OR(O48="Em Correção",O48="Em Implementação"),"IT Team",IF(O48="Concluído","Fechado","NA"))) -> Test Team | AH48: 2020862 | AI48: =AH48-M48-#REF!-K48-E48-C48-I48 -> #REF! | AJ48: =AH48-SUM(Z48:AG48) -> 2020862 | AK48: OK | AL48: =IF(S47 <> "Removido 22/12/2023", "A Considerar", "Removido") -> A Considerar
B49: GRSS_CMMSSN_INCM_OFF_BLNC | C49: =1217133+632325 -> 1849458 | D49: =C49/$AH49 -> 0.91518273 | F49: =E49/$AH49 -> 0 | H49: =G49/$AH49 -> 0 | I49: =8766+432+36+22 -> 9256 | J49: =I49/$AH49 -> 0.0045802237 | K49: =AH49-C49-I49-M49-G49 -> 158483 | L49: =K49/$AH49 -> 0.078423465 | M49: 3665 | N49: =M49/$AH49 -> 0.0018135825 | O49: Em teste | P49: 45338 | Q49: CT211 | R49: =IF(OR(Q49="CT207",Q49="CT209",Q49="CT211"),"Rentabilidade",IF(Q49="Corporativo","Corporativo",IF(Q49="Calculado","Calculado",IF(Q49="LT ESTR","LT ESTR", IF(Q49="Modelo Verde","Modelo Verde",NA))))) -> Rentabilidade | S49: Alterado 22/12/2023 | T49: WIP | U49: WIP | V49: =IF(AND(T49="OK",U49="OK"),"OK",IF(AND(T49="Not Started",U49="Not Started"),"Not Started",IF(AND(T49="NOK",U49="NOK"),"NOK",IF(AND(T49="WIP",U49="WIP"),"WIP",IF(AND(OR(T49="OK",U49="OK"))*(OR(T49="NOK",U49="NOK")),"NOK","NA"))))) -> WIP | W49: Not Started | X49: =IF(OR(O49="Em teste",O49="Em análise de requisitos"),"Test Team",IF(OR(O49="Em Correção",O49="Em Implementação"),"IT Team",IF(O49="Concluído","Fechado","NA"))) -> Test Team | Y49: Falta correr um teste - Processo de GD não terminado | AH49: 2020862 | AI49: =AH49-M49-K49-G49-E49-C49-I49 -> 0 | AJ49: =AH49-SUM(Z49:AG49) -> 2020862 | AK49: OK | AL49: =IF(S48 <> "Removido 22/12/2023", "A Considerar", "Removido") -> A Considerar
B50: GRSS_CMMSSN_INCM_OFF_BLNC_CCRR | D50: =C50/$AH50 -> 0 | F50: =E50/$AH50 -> 0 | H50: =G50/$AH50 -> 0 | J50: =I50/$AH50 -> 0 | K50: =2020862-3665 -> 2017197 | L50: =K50/$AH50 -> 0.99818642 | M50: 3665 | N50: =M50/$AH50 -> 0.0018135825 | O50: Em teste | P50: 45321 | Q50: CT211 | R50: =IF(OR(Q50="CT207",Q50="CT209",Q50="CT211"),"Rentabilidade",IF(Q50="Corporativo","Corporativo",IF(Q50="Calculado","Calculado",IF(Q50="LT ESTR","LT ESTR", IF(Q50="Modelo Verde","Modelo Verde",NA))))) -> Rentabilidade | S50: Alterado 22/12/2023 | T50: Not Started | U50: Not Started | V50: =IF(AND(T50="OK",U50="OK"),"OK",IF(AND(T50="Not Started",U50="Not Started"),"Not Started",IF(AND(T50="NOK",U50="NOK"),"NOK",IF(AND(T50="WIP",U50="WIP"),"WIP",IF(AND(OR(T50="OK",U50="OK"))*(OR(T50="NOK",U50="NOK")),"NOK","NA"))))) -> Not Started | W50: Not Started | X50: =IF(OR(O50="Em teste",O50="Em análise de requisitos"),"Test Team",IF(OR(O50="Em Correção",O50="Em Implementação"),"IT Team",IF(O50="Concluído","Fechado","NA"))) -> Test Team | AH50: 2020862 | AI50: =AH50-M50-#REF!-K50-E50-C50-I50 -> #REF! | AJ50: =AH50-SUM(Z50:AG50) -> 2020862 | AK50: OK | AL50: =IF(S49 <> "Removido 22/12/2023", "A Considerar", "Removido") -> A Considerar
B51: GRSS_CRRYNG_AMNT_INSTRMNT | C51: 2020862 | D51: =C51/$AH51 -> 1 | F51: =E51/$AH51 -> 0 | H51: =G51/$AH51 -> 0 | J51: =I51/$AH51 -> 0 | L51: =K51/$AH51 -> 0 | N51: =M51/$AH51 -> 0 | O51: Concluído | P51: 45321 | Q51: LT ESTR | R51: =IF(OR(Q51="CT207",Q51="CT209",Q51="CT211"),"Rentabilidade",IF(Q51="Corporativo","Corporativo",IF(Q51="Calculado","Calculado",IF(Q51="LT ESTR","LT ESTR", IF(Q51="Modelo Verde","Modelo Verde",NA))))) -> LT ESTR | S51: Sem alterações | T51: OK | U51: OK | V51: =IF(AND(T51="OK",U51="OK"),"OK",IF(AND(T51="Not Started",U51="Not Started"),"Not Started",IF(AND(T51="NOK",U51="NOK"),"NOK",IF(AND(T51="WIP",U51="WIP"),"WIP",IF(AND(OR(T51="OK",U51="OK"))*(OR(T51="NOK",U51="NOK")),"NOK","NA"))))) -> OK | W51: OK | X51: =IF(OR(O51="Em teste",O51="Em análise de requisitos"),"Test Team",IF(OR(O51="Em Correção",O51="Em Implementação"),"IT Team",IF(O51="Concluído","Fechado","NA"))) -> Fechado | Y51: Tudo a 11111111111.00 | AB51: 2020862 | AH51: 2020862 | AI51: =AH51-M51-K51-G51-E51-C51-I51 -> 0 | AJ51: =AH51-SUM(Z51:AG51) -> 0 | AK51: OK | AL51: =IF(S50 <> "Removido 22/12/2023", "A Considerar", "Removido") -> A Considerar
B52: GRSS_INTRST_EXPNS | C52: =1184384+632361 -> 1816745 | D52: =C52/$AH52 -> 0.89899508 | F52: =E52/$AH52 -> 0 | H52: =G52/$AH52 -> 0 | I52: =424+22 -> 446 | J52: =I52/$AH52 -> 0.0002206979 | K52: =AH52-C52-I52-M52 -> 200006 | L52: =K52/$AH52 -> 0.098970637 | M52: 3665 | N52: =M52/$AH52 -> 0.0018135825 | O52: Em teste | P52: 45338 | Q52: CT209 | R52: =IF(OR(Q52="CT207",Q52="CT209",Q52="CT211"),"Rentabilidade",IF(Q52="Corporativo","Corporativo",IF(Q52="Calculado","Calculado",IF(Q52="LT ESTR","LT ESTR", IF(Q52="Modelo Verde","Modelo Verde",NA))))) -> Rentabilidade | S52: Sem alterações | T52: OK | U52: OK | V52: =IF(AND(T52="OK",U52="OK"),"OK",IF(AND(T52="Not Started",U52="Not Started"),"Not Started",IF(AND(T52="NOK",U52="NOK"),"NOK",IF(AND(T52="WIP",U52="WIP"),"WIP",IF(AND(OR(T52="OK",U52="OK"))*(OR(T52="NOK",U52="NOK")),"NOK","NA"))))) -> OK | W52: Not Started | X52: =IF(OR(O52="Em teste",O52="Em análise de requisitos"),"Test Team",IF(OR(O52="Em Correção",O52="Em Implementação"),"IT Team",IF(O52="Concluído","Fechado","NA"))) -> Test Team | Z52: 1184384 | AE52: 424 | AF52: =AH52-AG52-AE52-Z52 -> 832389 | AG52: 3665 | AH52: 2020862 | AI52: =AH52-M52-K52-G52-E52-C52-I52 -> 0 | AJ52: =AH52-SUM(Z52:AG52) -> 0 | AK52: NOK (CCRR - Alterar para Em correção quando enviado email a especificar como devem ser aprovisionados este tipos de campos ?) | AL52: =IF(S51 <> "Removido 22/12/2023", "A Considerar", "Removido") -> A Considerar
B53: GRSS_INTRST_EXPNS_CCRR | D53: =C53/$AH53 -> 0 | F53: =E53/$AH53 -> 0 | H53: =G53/$AH53 -> 0 | J53: =I53/$AH53 -> 0 | K53: =2020862-3665 -> 2017197 | L53: =K53/$AH53 -> 0.99818642 | M53: 3665 | N53: =M53/$AH53 -> 0.0018135825 | O53: Em teste | P53: 45320 | Q53: CT209 | R53: =IF(OR(Q53="CT207",Q53="CT209",Q53="CT211"),"Rentabilidade",IF(Q53="Corporativo","Corporativo",IF(Q53="Calculado","Calculado",IF(Q53="LT ESTR","LT ESTR", IF(Q53="Modelo Verde","Modelo Verde",NA))))) -> Rentabilidade | S53: Sem alterações | T53: Not Started | U53: Not Started | V53: =IF(AND(T53="OK",U53="OK"),"OK",IF(AND(T53="Not Started",U53="Not Started"),"Not Started",IF(AND(T53="NOK",U53="NOK"),"NOK",IF(AND(T53="WIP",U53="WIP"),"WIP",IF(AND(OR(T53="OK",U53="OK"))*(OR(T53="NOK",U53="NOK")),"NOK","NA"))))) -> Not Started | W53: Not Started | X53: =IF(OR(O53="Em teste",O53="Em análise de requisitos"),"Test Team",IF(OR(O53="Em Correção",O53="Em Implementação"),"IT Team",IF(O53="Concluído","Fechado","NA"))) -> Test Team | AH53: 2020862 | AI53: =AH53-M53-#REF!-K53-E53-C53-I53 -> #REF! | AJ53: =AH53-SUM(Z53:AG53) -> 2020862 | AK53: OK | AL53: =IF(S52 <> "Removido 22/12/2023", "A Considerar", "Removido") -> A Considerar
B54: GRSS_INTRST_INCM | C54: =1184384+631570 -> 1815954 | D54: =C54/$AH54 -> 0.89860367 | F54: =E54/$AH54 -> 0 | H54: =G54/$AH54 -> 0 | I54: =424+22 -> 446 | J54: =I54/$AH54 -> 0.0002206979 | K54: =AH54-C54-I54-M54-G54+791 -> 201588 | L54: =K54/$AH54 -> 0.099753472 | M54: 3665 | N54: =M54/$AH54 -> 0.0018135825 | O54: Em teste | P54: 45345 | Q54: CT209 | R54: =IF(OR(Q54="CT207",Q54="CT209",Q54="CT211"),"Rentabilidade",IF(Q54="Corporativo","Corporativo",IF(Q54="Calculado","Calculado",IF(Q54="LT ESTR","LT ESTR", IF(Q54="Modelo Verde","Modelo Verde",NA))))) -> Rentabilidade | S54: Sem alterações | T54: OK | U54: OK | V54: =IF(AND(T54="OK",U54="OK"),"OK",IF(AND(T54="Not Started",U54="Not Started"),"Not Started",IF(AND(T54="NOK",U54="NOK"),"NOK",IF(AND(T54="WIP",U54="WIP"),"WIP",IF(AND(OR(T54="OK",U54="OK"))*(OR(T54="NOK",U54="NOK")),"NOK","NA"))))) -> OK | W54: Not Started | X54: =IF(OR(O54="Em teste",O54="Em análise de requisitos"),"Test Team",IF(OR(O54="Em Correção",O54="Em Implementação"),"IT Team",IF(O54="Concluído","Fechado","NA"))) -> Test Team | Z54: 1184384 | AB54: 0 | AE54: 424 | AF54: =AH54-AG54-AE54-Z54 -> 832389 | AG54: 3665 | AH54: 2020862 | AI54: =AH54-M54-K54-G54-E54-C54-I54 -> -791 | AJ54: =AH54-SUM(Z54:AG54) -> 0 | AK54: NOK (CCRR - Alterar para Em correção quando enviado email a especificar como devem ser aprovisionados este tipos de campos ?) | AL54: =IF(S53 <> "Removido 22/12/2023", "A Considerar", "Removido") -> A Considerar
B55: GRSS_INTRST_INCM_CCRR | D55: =C55/$AH55 -> 0 | F55: =E55/$AH55 -> 0 | H55: =G55/$AH55 -> 0 | J55: =I55/$AH55 -> 0 | K55: =2020862-3665 -> 2017197 | L55: =K55/$AH55 -> 0.99818642 | M55: 3665 | N55: =M55/$AH55 -> 0.0018135825 | O55: Em teste | P55: 45320 | Q55: CT209 | R55: =IF(OR(Q55="CT207",Q55="CT209",Q55="CT211"),"Rentabilidade",IF(Q55="Corporativo","Corporativo",IF(Q55="Calculado","Calculado",IF(Q55="LT ESTR","LT ESTR", IF(Q55="Modelo Verde","Modelo Verde",NA))))) -> Rentabilidade | S55: Sem alterações | T55: Not Started | U55: Not Started | V55: =IF(AND(T55="OK",U55="OK"),"OK",IF(AND(T55="Not Started",U55="Not Started"),"Not Started",IF(AND(T55="NOK",U55="NOK"),"NOK",IF(AND(T55="WIP",U55="WIP"),"WIP",IF(AND(OR(T55="OK",U55="OK"))*(OR(T55="NOK",U55="NOK")),"NOK","NA"))))) -> Not Started | W55: Not Started | X55: =IF(OR(O55="Em teste",O55="Em análise de requisitos"),"Test Team",IF(OR(O55="Em Correção",O55="Em Implementação"),"IT Team",IF(O55="Concluído","Fechado","NA"))) -> Test Team | Y55: Todos os valores estão iguais ao GRSS_INTRST_INCM | Z55: 0 | AH55: 2020862 | AI55: =AH55-M55-#REF!-K55-E55-C55-I55 -> #REF! | AJ55: =AH55-SUM(Z55:AG55) -> 2020862 | AK55: OK | AL55: =IF(S54 <> "Removido 22/12/2023", "A Considerar", "Removido") -> A Considerar
B56: IDCMB | C56: 2020862 | D56: =C56/$AH56 -> 1 | F56: =E56/$AH56 -> 0 | H56: =G56/$AH56 -> 0 | J56: =I56/$AH56 -> 0 | L56: =K56/$AH56 -> 0 | N56: =M56/$AH56 -> 0 | O56: Concluído | P56: 45338 | Q56: LT ESTR | R56: =IF(OR(Q56="CT207",Q56="CT209",Q56="CT211"),"Rentabilidade",IF(Q56="Corporativo","Corporativo",IF(Q56="Calculado","Calculado",IF(Q56="LT ESTR","LT ESTR", IF(Q56="Modelo Verde","Modelo Verde",NA))))) -> LT ESTR | S56: Adicionado 22/12/2023 | T56: NOK | U56: NOK | V56: =IF(AND(T56="OK",U56="OK"),"OK",IF(AND(T56="Not Started",U56="Not Started"),"Not Started",IF(AND(T56="NOK",U56="NOK"),"NOK",IF(AND(T56="WIP",U56="WIP"),"WIP",IF(AND(OR(T56="OK",U56="OK"))*(OR(T56="NOK",U56="NOK")),"NOK","NA"))))) -> NOK | W56: NOK | X56: =IF(OR(O56="Em teste",O56="Em análise de requisitos"),"Test Team",IF(OR(O56="Em Correção",O56="Em Implementação"),"IT Team",IF(O56="Concluído","Fechado","NA"))) -> Fechado | AH56: 2020862 | AI56: =AH56-M56-K56-G56-E56-C56-I56 -> 0 | AJ56: =AH56-SUM(Z56:AG56) -> 2020862 | AK56: OK | AL56: =IF(S55 <> "Removido 22/12/2023", "A Considerar", "Removido") -> A Considerar
...

Sheet Dashboard
B5: 1. Campos a testar | L5: 2. # Campos por Status | V5: 3. # Status dos testes por campo
W7: WIP | X7: NA
W9: =SUMIF(#REF!,"<>Removido 22/12/2023",#REF!)/50 -> #REF! | X9: =SUMIF(#REF!,"<>Removido 22/12/2023",#REF!)/50 -> #REF!
B22: Atualmente a corporação prevê que o GD reporte 50 campos
B25: 3. Status dos testes por universo LT002
C27: OK | D27: NOK | E27: WIP | F27: NS | G27: NA
C28: =SUMIF('Por campo'!S21:S71,"<>Removido 22/12/2023",'Por campo'!D21:D71)/50 -> 0.700826 | D28: =SUMIF('Por campo'!S21:S71,"<>Removido 22/12/2023",'Por campo'!H21:H71)/50 -> 3.2659331e-07 | E28: =SUMIF('Por campo'!S21:S71,"<>Removido 22/12/2023",'Por campo'!J21:J71)/50 -> 0.0032030589 | F28: =SUMIF('Por campo'!S21:S71,"<>Removido 22/12/2023",'Por campo'!L21:L71)/50 -> 0.29514419 | G28: =SUMIF('Por campo'!S21:S71,"<>Removido 22/12/2023",'Por campo'!N21:N71)/50 -> 0.00083424796
C29: =C28-C30 -> 0.050826004 | D29: =D28-D30 -> -0.18499967 | E29: =E28-E30 -> -0.0077969411 | F29: =F28-F30 -> 0.12714419 | G29: =G28-G30 -> -0.00016575204 | H29: Δ último PdS
C30: 0.65 | D30: 0.185 | E30: 0.011 | F30: 0.168 | G30: 0.001
C31: *NS - Not Started inclui campos "Em implementação" e "Em análise de requisitos"

Sheet Resumo
B3: 21 Campos Concluídos | F3: 13 Campos Pendentes
F4: 7 Campos Em Implementação
B5: Origem | C5: Campo | D5: Status Campo | F5: Origem | G5: Campo | H5: Status Campo | I5: Owner | J5: Data Entrega | K5: Observação
B6: LT ESTR | C6: DFLT_STTS_INSTRMNT | D6: Concluído | F6: Rentabilidade | G6: AVRG_BLNC_OFF_BLNC | H6: Em Implementação | I6: IT | J6: A definir IT | K6: Miss vs 0
B7: LT ESTR | C7: ACCMLTD_CHNGS_FV_CR_INSTRMNT | D7: Concluído | F7: Rentabilidade | G7: NT_LN_LSS_PRVSN_OFF_BLNC | H7: Em Implementação | I7: IT | J7: A definir IT | K7: Miss vs 0
B8: LT ESTR | C8: ACCMLTD_IMPRMNT_INSTRMNT | D8: Concluído | F8: Rentabilidade | G8: NW_BSNSS | H8: Em Implementação | I8: IT | J8: 45379 | K8: Já foi clarificada a EF (foi enviado email pelo Jacinto e Luís Silva a clarificar)
B9: LT ESTR | C9: ACCNTNG_CLSSFCTN | D9: Concluído | F9: LT ESTR | G9: COD_SOC_INTRGRP | H9: Em Implementação | I9: IT | J9: 45379 | K9: Not Started IT
B10: LT ESTR | C10: COD_SOC | D10: Concluído | F10: Modelo Verde | G10: SSTNBL_CTGRY | H10: Em Implementação | I10: IT | J10: 45372 | K10: Pendente do Modelo Verde
B11: LT ESTR | C11: DT_RFRNC | D11: Concluído | F11: Modelo Verde | G11: SSTNBL_INDCTR | H11: Em Implementação | I11: IT | J11: 45372 | K11: Pendente do Modelo Verde
B12: LT ESTR | C12: GRSS_CRRYNG_AMNT_INSTRMNT | D12: Concluído | F12: Calculado | G12: CNCLLD_INSTRMNT_STTS | H12: Em implementação | I12: IT | J12: A definir IT / LCM | K12: Falta o novo universo | L12: concluido para teste
B13: LT ESTR | C13: IDCMB | D13: Concluído
B14: LT ESTR | C14: IMPRMNT_STTS | D14: Concluído
B15: LT ESTR | C15: INSTRMNT_ID | D15: Concluído | F15: 2 Campos em Análise de Requisitos
B16: LT ESTR | C16: LCL_INSTMRNT_ID | D16: Concluído | F16: Origem | G16: Campo | H16: Status Campo | I16: Owner | J16: Data Entrega | K16: Observação
B17: LT ESTR | C17: OFF_BLNC_SHT_AMNT_INSTRMNT | D17: Concluído | F17: Rentabilidade | G17: INTRNL_TRNSFR_RT_OFF_BLNC | H17: Em Análise de Requisitos | I17: IT | J17: 45379 | K17: Pendente de receber a especificação funcional da Corporação
B18: LT ESTR | C18: PRFRMNG_STTS | D18: Concluído | F18: Corporativo | G18: RWA_OFF_BLNC | H18: Em Análise de Requisitos | I18: IT | J18: 45379 | K18: Pendente de receber a especificação funcional da Corporação
B19: LT ESTR | C19: PRVSNS_OFF_BLNC_SHT | D19: Concluído
B20: LT ESTR | C20: SUBPORTFOLIO_ID | D20: Concluído
B21: LT ESTR | C21: TYP_INSTRMNT | D21: Concluído | F21: 4 Campos em Correção
B22: Corporativo | C22: BSNSS_AREA_DSTNTN | D22: Concluído | F22: Origem | G22: Campo | H22: Status Campo | I22: Owner | J22: Data Entrega | K22: Observação
B23: Corporativo | C23: FLG_INTRBSNSS | D23: Concluído | F23: Rentabilidade | G23: AVRG_BLNC | H23: Em Correção | I23: IT | J23: A definir IT | K23: Ponderação
B24: Corporativo | C24: INTRBSNSS_ADJ_COD | D24: Concluído | F24: Rentabilidade | G24: NT_LN_LSS_PRVSN | H24: Em Correção | I24: IT | J24: A definir IT | K24: Ponderação
B25: Corporativo | C25: COD_SOC_DSTNTN | D25: Concluído | F25: Rentabilidade | G25: INTRNL_TRNSFR_RT | H25: Em Correção | I25: IT | J25: A definir IT | K25: Ponderação
B26: LT ESTR | C26: RWA | D26: Concluído | F26: Rentabilidade | G26: BSNSS_AREA | H26: Em Correção | I26: IT / LCM | J26: 28/mar / Velez | K26: IT: 2 BSNSS Areas com a mesma prioridade; (Fica a faltar abrir change request dos cartões) Velez : Pymes ; Factoring
B29: 16 Campos em Teste
B30: Origem | C30: Campo | D30: Status Campo
B31: Rentabilidade | C31: MNGMNT_PRDCT | D31: Em teste
B32: Rentabilidade | C32: BSNSS_AREA_CCRR | D32: Em teste
B33: Rentabilidade | C33: GNS_FNNCL_TRNSCTN_EXCHNG_CCRR | D33: Em teste
B34: Rentabilidade | C34: GNS_FNNCL_TRNSCTN_EXCHNG_DFFRNCS | D34: Em teste
B35: Rentabilidade | C35: GRSS_CMMSSN_EXPNS | D35: Em teste
B36: Rentabilidade | C36: GRSS_CMMSSN_EXPNS_CCRR | D36: Em teste
B37: Rentabilidade | C37: GRSS_CMMSSN_EXPNS_OFF_BLNC | D37: Em teste
B38: Rentabilidade | C38: GRSS_CMMSSN_EXPNS_OFF_BLNC_CCRR | D38: Em teste
B39: Rentabilidade | C39: GRSS_CMMSSN_INCM | D39: Em teste
B40: Rentabilidade | C40: GRSS_CMMSSN_INCM_CCRR | D40: Em teste
B41: Rentabilidade | C41: GRSS_CMMSSN_INCM_OFF_BLNC | D41: Em teste
... B46: Rentabilidade | C46: GRSS_INTRST_INCM_CCRR | D46: Em teste

Sheet Status Relações
B3: 8 Campos OK 1:1 & 1:N | H3: 14 Campos Not-Started
B4: Origem | C4: Campo | D4: Status Campo | E4: Status 1-1 / 1-N | F4: Status N-N | H4: Origem | I4: Campo | J4: Status Campo | K4: Status 1-1 / 1-N | L4: Status N-N
B5: Rentabilidade | C5: AVRG_BLNC | D5: Em Correção | E5: OK | F5: Em Correção | H5: Calculado | I5: CNCLLD_INSTRMNT_STTS | J5: Em Implementação | K5: Not Started | L5: Not Started
B6: Rentabilidade | C6: AVRG_BLNC_OFF_BLNC | D6: Em Implementação | E6: OK | F6: OK | H6: LT ESTR | I6: COD_SOC_INTRGRP | J6: Em Implementação | K6: Not Started | L6: Not Started
B7: Rentabilidade | C7: INTRNL_TRNSFR_RT | D7: Em Correção | E7: OK | F7: Em Correção | H7: Rentabilidade | I7: GNS_FNNCL_TRNSCTN_EXCHNG_CCRR | J7: Em teste | K7: Not Started | L7: Not Started
B8: Rentabilidade | C8: NT_LN_LSS_PRVSN | D8: Em Correção | E8: OK | F8: Em Correção | H8: Rentabilidade | I8: GRSS_CMMSSN_EXPNS_CCRR | J8: Em teste | K8: Not Started | L8: Not Started
B9: Rentabilidade | C9: NT_LN_LSS_PRVSN_OFF_BLNC | D9: Em Implementação | E9: OK | F9: OK | H9: Rentabilidade | I9: GRSS_CMMSSN_EXPNS_OFF_BLNC_CCRR | J9: Em teste | K9: Not Started | L9: Not Started
B10: Rentabilidade | C10: GNS_FNNCL_TRNSCTN_EXCHNG_DFFRNCS | D10: Em teste | E10: OK | F10: Not Started | H10: Rentabilidade | I10: GRSS_CMMSSN_INCM_CCRR | J10: Em teste | K10: Not Started | L10: Not Started
B11: Rentabilidade | C11: GRSS_INTRST_EXPNS | D11: Em teste | E11: OK | F11: Not Started | H11: Rentabilidade | I11: GRSS_CMMSSN_INCM_OFF_BLNC_CCRR | J11: Em teste | K11: Not Started | L11: Not Started
B12: Rentabilidade | C12: GRSS_INTRST_INCM | D12: Em teste | E12: OK | F12: Not Started | H12: Rentabilidade | I12: GRSS_INTRST_EXPNS_CCRR | J12: Em teste | K12: Not Started | L12: Not Started
B13: countif | H13: Rentabilidade | I13: GRSS_INTRST_INCM_CCRR | J13: Em teste | K13: Not Started | L13: Not Started
H14: Rentabilidade | I14: INTRNL_TRNSFR_RT_OFF_BLNC | J14: Em análise de requisitos | K14: Not Started | L14: Not Started
B15: 7 Campos WIP 1:1 & 1:N | H15: Rentabilidade | I15: NW_BSNSS | J15: Em Implementação | K15: Not Started | L15: Not Started
B16: Origem | C16: Campo | D16: Status Campo | E16: Status 1-1 / 1-N | F16: Status N-N | H16: Corporativo | I16: RWA_OFF_BLNC | J16: Em análise de requisitos | K16: Not Started | L16: Not Started
B17: Rentabilidade | C17: MNGMNT_PRDCT | D17: Em teste | E17: WIP | F17: Not Started | H17: Modelo Verde | I17: SSTNBL_CTGRY | J17: Em implementação | K17: Not Started | L17: Not Started
B18: Rentabilidade | C18: BSNSS_AREA | D18: Em Correção | E18: WIP | F18: Not Started | H18: Modelo Verde | I18: SSTNBL_INDCTR | J18: Em implementação | K18: Not Started | L18: Not Started
B19: Rentabilidade | C19: BSNSS_AREA_CCRR | D19: Em teste | E19: WIP | F19: WIP
B20: Rentabilidade | C20: GRSS_CMMSSN_EXPNS | D20: Em teste | E20: WIP | F20: Not Started
B21: Rentabilidade | C21: GRSS_CMMSSN_EXPNS_OFF_BLNC | D21: Em teste | E21: WIP | F21: Not Started
B22: Rentabilidade | C22: GRSS_CMMSSN_INCM | D22: Em teste | E22: WIP | F22: Not Started
B23: Rentabilidade | C23: GRSS_CMMSSN_INCM_OFF_BLNC | D23: Em teste | E23: WIP | F23: Not Started

Sheet Plano
N3: =SUM(N7:N54) -> 0 | O3: =SUM(O7:O54) -> 0 | P3: =SUM(P7:P54) -> 0 | Q3: =SUM(Q7:Q54) -> 0 | R3: =SUM(R7:R54) -> 0 | S3: =SUM(S7:S54) -> 0 | T3: =SUM(T7:T54) -> 0 | U3: =SUM(U7:U54) -> 0 | ... X3: =SUM(X7:X54) -> 0 | Y3: =SUM(Y7:Y70) -> 2 | Z3: =SUM(Z7:Z70) -> 2 | AA3: =SUM(AA7:AA70) -> 0 | AB3: =SUM(AB7:AB70) -> 0 | AC3: =SUM(AC7:AC70) -> 2 | AD3: =SUM(AD7:AD70) -> 2 | AE3: =SUM(AE7:AE70) -> 2 | AF3: =SUM(AF7:AF70) -> 2 | ... GL3: =SUM(GL7:GL70) -> 0
N4: 45354 | O4: =N4+1 -> 45355 | P4: =O4+1 -> 45356 | Q4: =P4+1 -> 45357 | R4: =Q4+1 -> 45358 | S4: =R4+1 -> 45359 | T4: =S4+1 -> 45360 | U4: =T4+1 -> 45361 | V4: =U4+1 -> 45362 | ... LH4: =LG4+1 -> 45660
L5: =SUM(L7:L57,) -> 157 | M5: =SUM(M7:M57,) -> 157 | N5: Março | AQ5: Abril | BU5: Maio | DB5: Junho | ED5: Julho | FI5: Agosto
B6: LT ESTR | C6: Campo | D6: Report | E6: Tabela | F6: Status Campo | G6: Incidência | H6: Implementação/Análise de Requisitos/ Alteração Especificação | I6: Data Entrega | J6: Data conclusão do teste | K6: Tema | L6: Estimativa | M6: Plano | N6: =DAY(N4) -> 3 | O6: =DAY(O4) -> 4 | P6: =DAY(P4) -> 5 | Q6: =DAY(Q4) -> 6 | R6: =DAY(R4) -> 7 | S6: =DAY(S4) -> 8 | T6: =DAY(T4) -> 9 | U6: =DAY(U4) -> 10 | ... HQ6: =DAY(HQ4) -> 30
B7: Rentabilidade | C7: AVRG_BLNC | D7: GD | E7: INSTRUMENT | F7: Em Correção | G7: Sim | H7: - | I7: 45372 | K7: Ponderação | L7: 2 | M7: =SUM(N7:EA7) -> 2 | AF7: IT | AG7: 1 | AJ7: 1
B8: Rentabilidade | C8: AVRG_BLNC_OFF_BLNC | D8: GD | E8: INSTRUMENT | F8: Em Implementação | G8: - | H8: Sim | I8: A definir dia 14/03 | K8: NA vs MISS | L8: 2 | M8: =SUM(N8:EA8) -> 2 | AS8: IT | AT8: 1 | AU8: 1
