Workbook

Sheet Indicadores
A2: Base da lt002_instrument
G3: All Cruza | H3: 2017197
A4: All | B4: 2020862
G5: 1 MIS para 1 FR | H5: 1226331 | I5: =H5/$H$3 -> 0.60793814
A6: Tradutor FR + MIS | G6: N MIS para 1 FR | H6: 668181 | I6: =H6/$H$3 -> 0.33124231
G7: 1 MIS para N FR | H7: 0 | I7: =H7/$H$3 -> 0
A8: All | B8: 7480477 | G8: N MIS para N FR | H8: 122685 | I8: =H8/$H$3 -> 0.060819543
A11: Distinct FR | B11: 5835277
A12: Distinct MIS | B12: 7172852 | G12: All N Cruza | H12: 3665

Sheet Sheet2
D2: 45313 | E2: 45314 | F2: 45315 | G2: 45316 | H2: 45317 | I2: 45318 | J2: 45319 | K2: 45320 | L2: 45321 | M2: 45322 | N2: 45323 | O2: 45324 | P2: 45325 | Q2: 45326
A3: Satélite | B3: Data
A4: Satélite 79 | B4: 45317 | F4: x | H4: X | K4: Q
A5: Satélite 80 | B5: 45315 | F5: x | H5: Q
A6: Satélite 83 | B6: 45320 | E6: x | G6: X | H6: Q | K6: X
A7: Satélite 84 | B7: 45315 | E7: x | F7: X | G7: Q
A8: Satélite 93 | B8: 45320 | E8: x | K8: X | L8: Q
A9: Satélite 109 | B9: 45316 | G9: X | H9: x | K9: X | N9: Q
B15: conta | C15: ESG
A16: 84 | B16: A | C16: x
B17: B | C17: y
A20: 83 | B20: A | C20: XXX
B25: Alerta: Saldo negativo de 1000 € no satelite 84
C27: Ajuste -1000 no id_comb xx no 84
C28: Ajuste -1000 no id_comb xx no 83

Sheet N Cruza
A1: instrmnt_id | B1: chave_fr | C1: tipo
A2: SNCN00000811 | B2: NULL | C2: SNCN
A3: SNCN00000132 | B3: NULL | C3: SNCN | I3: Row Labels | J3: Count of instrmnt_id
A4: SNCN00000449 | B4: NULL | C4: SNCN | I4: C pelo meio | J4: 6
A5: 80CMAH000000WP455000000000086388 | B5: NULL | C5: CMAH | I5: CMAH | J5: 2844
A6: 31000310419104090069674560100000 | B6: NULL | I6: Emp 82 | J6: 331
A7: 31000310171753091069673570100000 | B7: NULL | I7: SNCN | J7: 417
A8: 31000310172199091069674210100000 | B8: NULL | I8: SUPRIMENTOSPTTA | J8: 1
A9: 31CMAH0000000000R262304820019730 | B9: NULL | C9: CMAH | I9: (blank) | J9: 66
A10: 31CMAH0000000000R362304820963130 | B10: NULL | C10: CMAH | I10: Grand Total | J10: 3665
A11: 31CMAH0000000000RAPL384459860000 | B11: NULL | C11: CMAH
A12: 82000000000021154000450000404079 | B12: NULL | C12: Emp 82
A13: 82000000007002745000200000645171 | B13: NULL | C13: Emp 82
A14: 82000000007007660000200000654205 | B14: NULL | C14: Emp 82
A15: 82000000007008136000200000656216 | B15: NULL | C15: Emp 82
A16: 82000000007009031000200000661116 | B16: NULL | C16: Emp 82
A17: 82000000007011204000200000681045 | B17: NULL | C17: Emp 82
A18: 82000000007013337000200000690590 | B18: NULL | C18: Emp 82
A19: 82000000007017412000200000680116 | B19: NULL | C19: Emp 82
A20: 82000000007017955000200000753985 | B20: NULL | C20: Emp 82
A21: 89CMAH2022000041R001520220603343 | B21: NULL | C21: CMAH
A22: 89CMAH2022000041R001520230085361 | B22: NULL | C22: CMAH
... A419: SNCN00000520 | B419: NULL | C419: SNCN
A420: 31000010884341149000000000000000 | B420: NULL
A421: 31000310568959090069674420100000 | B421: NULL
A422: 31000310473499090069673790100000 | B422: NULL
A423: 31000310454895090069674350100000 | B423: NULL
A424: 31CMAH0000000000R262304820011790 | B424: NULL | C424: CMAH
A425: 31CMAH0000000000R262304880020300 | B425: NULL | C425: CMAH
A426: 31CMAH0000000000R962304820211210 | B426: NULL | C426: CMAH
A427: 31CMAH0000000000R962304820311040 | B427: NULL | C427: CMAH
A428: 31CMAH0000000000R962304830389610 | B428: NULL | C428: CMAH
A429: 31CMAH0000000000R962304880395500 | B429: NULL | C429: CMAH
A430: 31CMAHenergyS1xS2OVER2ENFGDRST0A | B430: NULL | C430: CMAH
A431: 82000000000121090000450000416648 | B431: NULL | C431: Emp 82
A432: 82000000000121529000420000424412 | B432: NULL | C432: Emp 82
A433: 82000000000136141000450000506204 | B433: NULL | C433: Emp 82
A434: 31CMAH0000000000R362304820801370 | B434: NULL | C434: CMAH
A435: 31CMAH0000000000R362304820812140 | B435: NULL | C435: CMAH
... A635: SNCN00000398 | B635: NULL | C635: SNCN
...

Sheet Por campo
C1: Status dos testes
C2: OK | E2: OK (MISS/ NA) | G2: NOK | I2: WIP | K2: Not Started | M2: NA | S2: Testes Universos
B3: Campo | C3: # Instrumentos | D3: % | E3: # Instrumentos | F3: % | G3: # Instrumentos | H3: % | I3: # Instrumentos | J3: % | K3: # Instrumentos | L3: % | M3: # Instrumentos | N3: % | O3: Status do campo | P3: Data Status | Q3: Origem | R3: Alterações Corp | S3: 1 FR - 1 MIS | T3: 1 FR - N MIS | U3: N FR - N MIS | V3: Notas | W3: OK | X3: OK (MISS/ NA) | Y3: NOK | Z3: NOK (MISS/ NA) | AA3: WIP Erro | AB3: WIP (MISS/ NA) | AC3: WIP N/N | AD3: NA | AE3: all | AF3: controlo | AG3: controlo_2 | AH3: Status (Atualizado)
B4: AVRG_BLNC | C4: =1225899+668159 -> 1894058 | D4: =C4/$AE4 -> 0.93725252 | F4: =E4/$AE4 -> 0 | H4: =G4/$AE4 -> 0 | I4: =432+22+122685 -> 123139 | J4: =I4/$AE4 -> 0.060933899 | K4: 0 | L4: =K4/$AE4 -> 0 | M4: 3665 | N4: =M4/$AE4 -> 0.0018135825 | O4: Em teste | P4: 45344 | Q4: CT209 | R4: Sem alterações | S4: OK | T4: OK | U4: WIP | W4: 1225899 | AB4: 432 | AC4: 790866 | AD4: 3665 | AE4: 2020862 | AF4: =AE4-M4-K4-G4-E4-C4-I4 -> 0 | AG4: =AE4-SUM(W4:AD4) -> 0 | AH4: OK
A5: HC - Amostragem 1-1 ? | B5: AVRG_BLNC_OFF_BLNC | C5: =1225899+668159 -> 1894058 | D5: =C5/$AE5 -> 0.93725252 | F5: =E5/$AE5 -> 0 | H5: =G5/$AE5 -> 0 | I5: =432+22 -> 454 | J5: =I5/$AE5 -> 0.00022465661 | K5: =AE5-C5-I5-M5 -> 122685 | L5: =K5/$AE5 -> 0.060709242 | M5: 3665 | N5: =M5/$AE5 -> 0.0018135825 | O5: Em teste | P5: 45344 | Q5: CT209 | R5: Sem alterações | S5: OK | T5: OK | U5: Not Started | AB5: 432 | AE5: 2020862 | AF5: =AE5-M5-K5-G5-E5-C5-I5 -> 0 | AG5: =AE5-SUM(W5:AD5) -> 2020430 | AH5: OK
B6: DFLT_STTS_INSTRMNT | C6: 2020862 | D6: =C6/$AE6 -> 1 | F6: =E6/$AE6 -> 0 | H6: =G6/$AE6 -> 0 | J6: =I6/$AE6 -> 0 | L6: =K6/$AE6 -> 0 | N6: =M6/$AE6 -> 0 | O6: Concluído | P6: 45324 | Q6: LT ESTR | R6: Sem alterações | S6: OK | T6: OK | U6: OK | V6: Tudo a 11111111111 | AE6: 2020862 | AF6: =AE6-M6-K6-G6-E6-C6-I6 -> 0 | AG6: =AE6-SUM(W6:AD6) -> 2020862 | AH6: OK
A7: HC- Amostragem ? | B7: INTRNL_TRNSFR_RT | C7: =1184384+666817 -> 1851201 | D7: =C7/$AE7 -> 0.91604523 | F7: =E7/$AE7 -> 0 | H7: =G7/$AE7 -> 0 | I7: =432+22 -> 454 | J7: =I7/$AE7 -> 0.00022465661 | K7: =AE7-C7-I7-M7+1342 -> 166884 | L7: =K7/$AE7 -> 0.082580602 | M7: 3665 | N7: =M7/$AE7 -> 0.0018135825 | O7: Em teste | P7: 45344 | Q7: CT209 | R7: Sem alterações | S7: OK | T7: OK | U7: Not Started | W7: 1184384 | AB7: 424 | AC7: =AE7-AD7-AB7-W7 -> 832389 | AD7: 3665 | AE7: 2020862 | AF7: =AE7-M7-K7-G7-E7-C7-I7 -> -1342 | AG7: =AE7-SUM(W7:AD7) -> 0 | AH7: OK
B8: MNGMNT_PRDCT | C8: =1225899+668158 -> 1894057 | D8: =C8/$AE8 -> 0.93725202 | F8: =E8/$AE8 -> 0 | G8: 1 | H8: =G8/$AE8 -> 4.9483834e-07 | I8: =432+22 -> 454 | J8: =I8/$AE8 -> 0.00022465661 | K8: =AE8-C8-G8-I8-M8 -> 122685 | L8: =K8/$AE8 -> 0.060709242 | M8: 3665 | N8: =M8/$AE8 -> 0.0018135825 | O8: Em Correção | P8: 45338 | Q8: CT207 | R8: Sem alterações | S8: OK | T8: NOK | U8: Not Started | AE8: 2020862 | AF8: =AE8-M8-K8-G8-E8-C8-I8 -> 0 | AG8: =AE8-SUM(W8:AD8) -> 2020862 | AH8: Pending quando os 30 casos estiverem ok
B9: NT_LN_LSS_PRVSN | C9: =1225899+668159 -> 1894058 | D9: =C9/$AE9 -> 0.93725252 | F9: =E9/$AE9 -> 0 | H9: =G9/$AE9 -> 0 | I9: =432+22 -> 454 | J9: =I9/$AE9 -> 0.00022465661 | K9: =AE9-C9-G9-I9-M9 -> 122685 | L9: =K9/$AE9 -> 0.060709242 | M9: 3665 | N9: =M9/$AE9 -> 0.0018135825 | O9: Em teste | P9: 45338 | Q9: CT209 | R9: Sem alterações | S9: OK | T9: OK | U9: Not Started | W9: 1225899 | AA9: 790866 | AB9: 432 | AD9: 3665 | AE9: 2020862 | AF9: =AE9-M9-K9-G9-E9-C9-I9 -> 0 | AG9: =AE9-SUM(W9:AD9) -> 0 | AH9: Validar
B10: NT_LN_LSS_PRVSN_OFF_BLNC | C10: =1225899+668159 -> 1894058 | D10: =C10/$AE10 -> 0.93725252 | F10: =E10/$AE10 -> 0 | H10: =G10/$AE10 -> 0 | I10: =432+22 -> 454 | J10: =I10/$AE10 -> 0.00022465661 | K10: =AE10-C10-G10-I10-M10 -> 122685 | L10: =K10/$AE10 -> 0.060709242 | M10: 3665 | N10: =M10/$AE10 -> 0.0018135825 | O10: Em teste | P10: 45317 | Q10: CT209 | R10: Sem alterações | S10: OK | T10: OK | U10: Not Started | V10: Valores apurados são diferentes | W10: 1225309 | Y10: 590 | AB10: 432 | AC10: 790866 | AD10: 3665 | AE10: 2020862 | AF10: =AE10-M10-K10-G10-E10-C10-I10 -> 0 | AG10: =AE10-SUM(W10:AD10) -> 0 | AH10: Validar
B11: ACCMLTD_CHNGS_FV_CR_INSTRMNT | C11: 2020862 | D11: =C11/$AE11 -> 1 | F11: =E11/$AE11 -> 0 | H11: =G11/$AE11 -> 0 | J11: =I11/$AE11 -> 0 | L11: =K11/$AE11 -> 0 | N11: =M11/$AE11 -> 0 | O11: Concluído | P11: 45317 | Q11: LT ESTR | R11: Sem alterações | S11: OK | T11: OK | U11: OK | V11: Tudo a 11111111111.00 | AE11: 2020862 | AF11: =AE11-M11-K11-G11-E11-C11-I11 -> 0 | AG11: =AE11-SUM(W11:AD11) -> 2020862 | AH11: OK
B12: ACCMLTD_IMPRMNT_INSTRMNT | C12: 2020862 | D12: =C12/$AE12 -> 1 | F12: =E12/$AE12 -> 0 | H12: =G12/$AE12 -> 0 | J12: =I12/$AE12 -> 0 | L12: =K12/$AE12 -> 0 | N12: =M12/$AE12 -> 0 | O12: Concluído | P12: 45321 | Q12: LT ESTR | R12: Sem alterações | S12: OK | T12: OK | U12: OK | AE12: 2020862 | AF12: =AE12-M12-K12-G12-E12-C12-I12 -> 0 | AG12: =AE12-SUM(W12:AD12) -> 2020862 | AH12: OK
B13: ACCNTNG_CLSSFCTN | C13: 2020862 | D13: =C13/$AE13 -> 1 | F13: =E13/$AE13 -> 0 | H13: =G13/$AE13 -> 0 | J13: =I13/$AE13 -> 0 | L13: =K13/$AE13 -> 0 | N13: =M13/$AE13 -> 0 | O13: Concluído | P13: 45321 | Q13: LT ESTR | R13: Sem alterações | S13: OK | T13: OK | U13: OK | AE13: 2020862 | AF13: =AE13-M13-K13-G13-E13-C13-I13 -> 0 | AG13: =AE13-SUM(W13:AD13) -> 2020862 | AH13: OK
A14: HR | B14: BSNSS_AREA | C14: 16935 | D14: =C14/$AE14 -> 0.0083800873 | F14: =E14/$AE14 -> 0 | G14: =AE14-C14-K14-M14 -> 1209396 | H14: =G14/$AE14 -> 0.59845551 | J14: =I14/$AE14 -> 0 | K14: 790866 | L14: =K14/$AE14 -> 0.39135082 | M14: 3665 | N14: =M14/$AE14 -> 0.0018135825 | O14: Em Correção | P14: 45321 | Q14: CT207 | R14: Sem alterações | S14: NOK | T14: Not Started | U14: Not Started | AE14: 2020862 | AF14: =AE14-M14-K14-G14-E14-C14-I14 -> 0 | AG14: =AE14-SUM(W14:AD14) -> 2020862 | AH14: OK
B15: BSNSS_AREA_CCRR | D15: =C15/$AE15 -> 0 | F15: =E15/$AE15 -> 0 | G15: =2020862-3665 -> 2017197 | H15: =G15/$AE15 -> 0.99818642 | J15: =I15/$AE15 -> 0 | L15: =K15/$AE15 -> 0 | M15: 3665 | N15: =M15/$AE15 -> 0.0018135825 | O15: Em Implementação | P15: 45320 | Q15: CT207 | R15: Sem alterações | S15: NOK | T15: NOK | U15: NOK | AE15: 2020862 | AF15: =AE15-M15-K15-G15-E15-C15-I15 -> 0 | AG15: =AE15-SUM(W15:AD15) -> 2020862 | AH15: OK
B16: BSNSS_AREA_DSTNTN | C16: 2020862 | D16: =C16/$AE16 -> 1 | F16: =E16/$AE16 -> 0 | H16: =G16/$AE16 -> 0 | J16: =I16/$AE16 -> 0 | L16: =K16/$AE16 -> 0 | N16: =M16/$AE16 -> 0 | O16: Concluído | P16: 45317 | Q16: Corporativo | R16: Sem alterações | S16: OK | T16: OK | U16: OK | AE16: 2020862 | AF16: =AE16-M16-K16-G16-E16-C16-I16 -> 0 | AG16: =AE16-SUM(W16:AD16) -> 2020862 | AH16: OK
B17: CNCLLD_INSTRMNT_STTS | D17: =C17/$AE17 -> 0 | F17: =E17/$AE17 -> 0 | H17: =G17/$AE17 -> 0 | J17: =I17/$AE17 -> 0 | K17: 2020862 | L17: =K17/$AE17 -> 1 | N17: =M17/$AE17 -> 0 | O17: Em Implementação | P17: 45321 | Q17: Calculado | R17: Adicionado 22/12/2023 | S17: Not Started | T17: Not Started | U17: Not Started | AE17: 2020862 | AF17: =AE17-M17-K17-G17-E17-C17-I17 -> 0 | AG17: =AE17-SUM(W17:AD17) -> 2020862 | AH17: OK
B18: COD_SOC | C18: 2020862 | D18: =C21/$AE18 -> 1 | F18: =E18/$AE18 -> 0 | H18: =G18/$AE18 -> 0 | J18: =I18/$AE18 -> 0 | L18: =K18/$AE18 -> 0 | N18: =M18/$AE18 -> 0 | O18: Concluído | P18: 45321 | Q18: LT ESTR | R18: Sem alterações | S18: OK | T18: OK | U18: OK | AE18: 2020862 | AF18: =AE18-M18-K18-G18-E18-C18-I18 -> 0 | AG18: =AE18-SUM(W18:AD18) -> 2020862 | AH18: OK
B19: COD_SOC_DSTNTN | C19: 2020862 | D19: =C19/$AE19 -> 1 | F19: =E19/$AE19 -> 0 | H19: =G19/$AE19 -> 0 | J19: =I19/$AE19 -> 0 | L19: =K19/$AE19 -> 0 | N19: =M19/$AE19 -> 0 | O19: Concluído | P19: 45317 | Q19: Corporativo | R19: Sem alterações | S19: OK | T19: OK | U19: OK | AE19: 2020862 | AF19: =AE19-M19-K19-G19-E19-C19-I19 -> 0 | AG19: =AE19-SUM(W19:AD19) -> 2020862 | AH19: OK
B20: COD_SOC_INTRGRP | D20: =C20/$AE20 -> 0 | F20: =E20/$AE20 -> 0 | H20: =G20/$AE20 -> 0 | J20: =I20/$AE20 -> 0 | K20: 2020862 | L20: =K20/$AE20 -> 1 | N20: =M20/$AE20 -> 0 | O20: Em Implementação | P20: 45322 | Q20: LT ESTR | R20: Adicionado 22/12/2023 | S20: Not Started | T20: Not Started | U20: Not Started | AE20: 2020862 | AF20: =AE20-M20-K20-G20-E20-C20-I20 -> 0 | AG20: =AE20-SUM(W20:AD20) -> 2020862 | AH20: OK
B21: DT_RFRNC | C21: 2020862 | D21: =C21/$AE21 -> 1 | F21: =E21/$AE21 -> 0 | H21: =G21/$AE21 -> 0 | J21: =I21/$AE21 -> 0 | L21: =K21/$AE21 -> 0 | N21: =M21/$AE21 -> 0 | O21: Concluído | P21: 45317 | Q21: LT ESTR | R21: Sem alterações | S21: OK | T21: OK | U21: OK | W21: 2020862 | AE21: 2020862 | AF21: =AE21-M21-K21-G21-E21-C21-I21 -> 0 | AG21: =AE21-SUM(W21:AD21) -> 0 | AH21: OK
B22: FLG_INSTRMNT_CNCLLD | D22: =C22/$AE22 -> 0 | F22: =E22/$AE22 -> 0 | G22: 2020862 | H22: =G22/$AE22 -> 1 | J22: =I22/$AE22 -> 0 | L22: =K22/$AE22 -> 0 | N22: =M22/$AE22 -> 0 | O22: NA | P22: NA | Q22: Calculado | R22: Removido 22/12/2023 | S22: NA | T22: NA | U22: NA | Y22: 2020862 | AE22: 2020862 | AF22: =AE22-M22-K22-G22-E22-C22 -> 0 | AG22: =AE22-SUM(W22:AD22) -> 0 | AH22: OK
B23: FLG_INTRBSNSS | C23: 2020862 | D23: =C23/$AE23 -> 1 | F23: =E23/$AE23 -> 0 | H23: =G23/$AE23 -> 0 | J23: =I23/$AE23 -> 0 | L23: =K23/$AE23 -> 0 | N23: =M23/$AE23 -> 0 | O23: Concluído | P23: 45317 | Q23: Corporativo | R23: Sem alterações | S23: OK | T23: OK | U23: OK | W23: 2020862 | AE23: 2020862 | AF23: =AE23-M23-K23-G23-E23-C23-I23 -> 0 | AG23: =AE23-SUM(W23:AD23) -> 0 | AH23: OK
B24: GNS_FNNCL_TRNSCTN_EXCHNG_CCRR | D24: =C24/$AE24 -> 0 | F24: =E24/$AE24 -> 0 | G24: =2020862-3665 -> 2017197 | H24: =G24/$AE24 -> 0.99818642 | J24: =I24/$AE24 -> 0 | L24: =K24/$AE24 -> 0 | M24: 3665 | N24: =M24/$AE24 -> 0.0018135825 | O24: Em Implementação | P24: 45320 | Q24: CT209 | R24: Sem alterações | S24: NOK | T24: NOK | U24: NOK | AB24: 424 | AE24: 2020862 | AF24: =AE24-M24-K24-G24-E24-C24-I24 -> 0 | AG24: =AE24-SUM(W24:AD24) -> 2020438 | AH24: OK
B25: GNS_FNNCL_TRNSCTN_EXCHNG_DFFRNCS | C25: =1184384+632361 -> 1816745 | D25: =C25/$AE25 -> 0.89899508 | F25: =E25/$AE25 -> 0 | H25: =G25/$AE25 -> 0 | I25: =424+22 -> 446 | J25: =I25/$AE25 -> 0.0002206979 | K25: =AE25-C25-I25-M25 -> 200006 | L25: =K25/$AE25 -> 0.098970637 | M25: 3665 | N25: =M25/$AE25 -> 0.0018135825 | O25: Em teste | P25: 45338 | Q25: CT209 | R25: Sem alterações | S25: OK | T25: OK | U25: Not Started | AB25: 424 | AE25: 2020862 | AF25: =AE25-M25-K25-G25-E25-C25-I25 -> 0 | AG25: =AE25-SUM(W25:AD25) -> 2020438 | AH25: NOK (CCRR - Alterar para Em correção quando enviado email a especificar como devem ser aprovisionados este tipos de campos ?)
A26: JB - Msg Mariana | B26: GRSS_CMMSSN_EXPNS | C26: =1222920+330327 -> 1553247 | D26: =C26/$AE26 -> 0.76860617 | F26: =E26/$AE26 -> 0 | G26: =2979+302034 -> 305013 | H26: =G26/$AE26 -> 0.15093213 | I26: =432+22 -> 454 | J26: =I26/$AE26 -> 0.00022465661 | K26: =AE26-C26-I26-M26-G26 -> 158483 | L26: =K26/$AE26 -> 0.078423465 | M26: 3665 | N26: =M26/$AE26 -> 0.0018135825 | O26: Em Correção | P26: 45345 | Q26: CT211 | R26: Alterado 22/12/2023 | S26: WIP | T26: WIP | U26: Not Started | AE26: 2020862 | AF26: =AE26-M26-K26-G26-E26-C26-I26 -> 0 | AG26: =AE26-SUM(W26:AD26) -> 2020862 | AH26: OK
B27: GRSS_CMMSSN_EXPNS_CCRR | D27: =C27/$AE27 -> 0 | F27: =E27/$AE27 -> 0 | G27: =2020862-3665 -> 2017197 | H27: =G27/$AE27 -> 0.99818642 | J27: =I27/$AE27 -> 0 | L27: =K27/$AE27 -> 0 | M27: 3665 | N27: =M27/$AE27 -> 0.0018135825 | O27: Em Implementação | P27: 45321 | Q27: CT211 | R27: Alterado 22/12/2023 | S27: NOK | T27: NOK | U27: NOK | AE27: 2020862 | AF27: =AE27-M27-K27-G27-E27-C27-I27 -> 0 | AG27: =AE27-SUM(W27:AD27) -> 2020862 | AH27: OK
B28: GRSS_CMMSSN_EXPNS_OFF_BLNC | C28: =1225898+632361 -> 1858259 | D28: =C28/$AE28 -> 0.9195378 | F28: =E28/$AE28 -> 0 | G28: 1 | H28: =G28/$AE28 -> 4.9483834e-07 | I28: =432+22 -> 454 | J28: =I28/$AE28 -> 0.00022465661 | K28: =AE28-C28-I28-M28-G28 -> 158483 | L28: =K28/$AE28 -> 0.078423465 | M28: 3665 | N28: =M28/$AE28 -> 0.0018135825 | O28: Em Correção | P28: 45338 | Q28: CT211 | R28: Alterado 22/12/2023 | S28: NOK | T28: NOK | U28: Not Started | AE28: 2020862 | AF28: =AE28-M28-K28-G28-E28-C28-I28 -> 0 | AG28: =AE28-SUM(W28:AD28) -> 2020862 | AH28: OK
B29: GRSS_CMMSSN_EXPNS_OFF_BLNC_CCRR | D29: =C29/$AE29 -> 0 | F29: =E29/$AE29 -> 0 | G29: =2020862-3665 -> 2017197 | H29: =G29/$AE29 -> 0.99818642 | J29: =I29/$AE29 -> 0 | L29: =K29/$AE29 -> 0 | M29: 3665 | N29: =M29/$AE29 -> 0.0018135825 | O29: Em Implementação | P29: 45321 | Q29: CT211 | R29: Alterado 22/12/2023 | S29: NOK | T29: NOK | U29: NOK | AE29: 2020862 | AF29: =AE29-M29-K29-G29-E29-C29-I29 -> 0 | AG29: =AE29-SUM(W29:AD29) -> 2020862 | AH29: OK
A30: JB | B30: GRSS_CMMSSN_INCM | C30: =1001533+96013 -> 1097546 | D30: =C30/$AE30 -> 0.54310784 | F30: =E30/$AE30 -> 0 | G30: =224366+536348 -> 760714 | H30: =G30/$AE30 -> 0.37643045 | I30: =432+22 -> 454 | J30: =I30/$AE30 -> 0.00022465661 | K30: =AE30-C30-I30-M30-G30 -> 158483 | L30: =K30/$AE30 -> 0.078423465 | M30: 3665 | N30: =M30/$AE30 -> 0.0018135825 | O30: Em Correção | P30: 45345 | Q30: CT211 | R30: Alterado 22/12/2023 | S30: WIP | T30: WIP | U30: Not Started | V30: Falta correr um teste - Processo de GD não terminado | AE30: 2020862 | AF30: =AE30-M30-K30-G30-E30-C30-I30 -> 0 | AG30: =AE30-SUM(W30:AD30) -> 2020862 | AH30: OK
B31: GRSS_CMMSSN_INCM_CCRR | D31: =C31/$AE31 -> 0 | F31: =E31/$AE31 -> 0 | G31: =2020862-3665 -> 2017197 | H31: =G31/$AE31 -> 0.99818642 | J31: =I31/$AE31 -> 0 | L31: =K31/$AE31 -> 0 | M31: 3665 | N31: =M31/$AE31 -> 0.0018135825 | O31: Em Implementação | P31: 45321 | Q31: CT211 | R31: Alterado 22/12/2023 | S31: NOK | T31: NOK | U31: NOK | AE31: 2020862 | AF31: =AE31-M31-K31-G31-E31-C31-I31 -> 0 | AG31: =AE31-SUM(W31:AD31) -> 2020862 | AH31: OK
B32: GRSS_CMMSSN_INCM_OFF_BLNC | C32: =1225897+632361 -> 1858258 | D32: =C32/$AE32 -> 0.91953731 | F32: =E32/$AE32 -> 0 | G32: 2 | H32: =G32/$AE32 -> 9.8967668e-07 | I32: =432+22 -> 454 | J32: =I32/$AE32 -> 0.00022465661 | K32: =AE32-C32-I32-M32-G32 -> 158483 | L32: =K32/$AE32 -> 0.078423465 | M32: 3665 | N32: =M32/$AE32 -> 0.0018135825 | O32: Em Correção | P32: 45338 | Q32: CT211 | R32: Alterado 22/12/2023 | S32: NOK | T32: NOK | U32: Not Started | V32: Falta correr um teste - Processo de GD não terminado | AE32: 2020862 | AF32: =AE32-M32-K32-G32-E32-C32-I32 -> 0 | AG32: =AE32-SUM(W32:AD32) -> 2020862 | AH32: OK
B33: GRSS_CMMSSN_INCM_OFF_BLNC_CCRR | D33: =C33/$AE33 -> 0 | F33: =E33/$AE33 -> 0 | G33: =2020862-3665 -> 2017197 | H33: =G33/$AE33 -> 0.99818642 | J33: =I33/$AE33 -> 0 | L33: =K33/$AE33 -> 0 | M33: 3665 | N33: =M33/$AE33 -> 0.0018135825 | O33: Em Implementação | P33: 45321 | Q33: CT211 | R33: Alterado 22/12/2023 | S33: NOK | T33: NOK | U33: NOK | AE33: 2020862 | AF33: =AE33-M33-K33-G33-E33-C33-I33 -> 0 | AG33: =AE33-SUM(W33:AD33) -> 2020862 | AH33: OK
B34: GRSS_CRRYNG_AMNT_INSTRMNT | C34: 2020862 | D34: =C34/$AE34 -> 1 | F34: =E34/$AE34 -> 0 | H34: =G34/$AE34 -> 0 | J34: =I34/$AE34 -> 0 | L34: =K34/$AE34 -> 0 | N34: =M34/$AE34 -> 0 | O34: Concluído | P34: 45321 | Q34: LT ESTR | R34: Sem alterações | S34: OK | T34: OK | U34: OK | V34: Tudo a 11111111111.00 | Y34: 2020862 | AE34: 2020862 | AF34: =AE34-M34-K34-G34-E34-C34-I34 -> 0 | AG34: =AE34-SUM(W34:AD34) -> 0 | AH34: OK
B35: GRSS_INTRST_EXPNS | C35: =1184384+632361 -> 1816745 | D35: =C35/$AE35 -> 0.89899508 | F35: =E35/$AE35 -> 0 | H35: =G35/$AE35 -> 0 | I35: =424+22 -> 446 | J35: =I35/$AE35 -> 0.0002206979 | K35: =AE35-C35-I35-M35 -> 200006 | L35: =K35/$AE35 -> 0.098970637 | M35: 3665 | N35: =M35/$AE35 -> 0.0018135825 | O35: Em teste | P35: 45338 | Q35: CT209 | R35: Sem alterações | S35: OK | T35: OK | U35: Not Started | W35: 1184384 | AB35: 424 | AC35: =AE35-AD35-AB35-W35 -> 832389 | AD35: 3665 | AE35: 2020862 | AF35: =AE35-M35-K35-G35-E35-C35-I35 -> 0 | AG35: =AE35-SUM(W35:AD35) -> 0 | AH35: NOK (CCRR - Alterar para Em correção quando enviado email a especificar como devem ser aprovisionados este tipos de campos ?)
B36: GRSS_INTRST_EXPNS_CCRR | D36: =C36/$AE36 -> 0 | F36: =E36/$AE36 -> 0 | G36: =2020862-3665 -> 2017197 | H36: =G36/$AE36 -> 0.99818642 | J36: =I36/$AE36 -> 0 | L36: =K36/$AE36 -> 0 | M36: 3665 | N36: =M36/$AE36 -> 0.0018135825 | O36: Em Implementação | P36: 45320 | Q36: CT209 | R36: Sem alterações | S36: NOK | T36: NOK | U36: NOK | AE36: 2020862 | AF36: =AE36-M36-K36-G36-E36-C36-I36 -> 0 | AG36: =AE36-SUM(W36:AD36) -> 2020862 | AH36: OK
A37: HC - Finalizar Amostragem ? | B37: GRSS_INTRST_INCM | C37: =1184384+631570 -> 1815954 | D37: =C37/$AE37 -> 0.89860367 | F37: =E37/$AE37 -> 0 | H37: =G37/$AE37 -> 0 | I37: =424+22 -> 446 | J37: =I37/$AE37 -> 0.0002206979 | K37: =AE37-C37-I37-M37-G37+791 -> 201588 | L37: =K37/$AE37 -> 0.099753472 | M37: 3665 | N37: =M37/$AE37 -> 0.0018135825 | O37: Em teste | P37: 45345 | Q37: CT209 | R37: Sem alterações | S37: OK | T37: OK | U37: Not Started | W37: 1184384 | Y37: 0 | AB37: 424 | AC37: =AE37-AD37-AB37-W37 -> 832389 | AD37: 3665 | AE37: 2020862 | AF37: =AE37-M37-K37-G37-E37-C37-I37 -> -791 | AG37: =AE37-SUM(W37:AD37) -> 0 | AH37: NOK (CCRR - Alterar para Em correção quando enviado email a especificar como devem ser aprovisionados este tipos de campos ?)
B38: GRSS_INTRST_INCM_CCRR | D38: =C38/$AE38 -> 0 | F38: =E38/$AE38 -> 0 | G38: =2020862-3665 -> 2017197 | H38: =G38/$AE38 -> 0.99818642 | J38: =I38/$AE38 -> 0 | L38: =K38/$AE38 -> 0 | M38: 3665 | N38: =M38/$AE38 -> 0.0018135825 | O38: Em Implementação | P38: 45320 | Q38: CT209 | R38: Sem alterações | S38: NOK | T38: NOK | U38: NOK | V38: Todos os valores estão iguais ao GRSS_INTRST_INCM | W38: 0 | AE38: 2020862 | AF38: =AE38-M38-K38-G38-E38-C38-I38 -> 0 | AG38: =AE38-SUM(W38:AD38) -> 2020862 | AH38: OK
B39: IDCMB | C39: 2020821 | D39: =C39/$AE39 -> 0.99997971 | F39: =E39/$AE39 -> 0 | G39: 41 | H39: =G39/$AE39 -> 2.0288372e-05 | J39: =I39/$AE39 -> 0 | L39: =K39/$AE39 -> 0 | N39: =M39/$AE39 -> 0 | O39: Em Correção | P39: 45338 | Q39: LT ESTR | R39: Adicionado 22/12/2023 | S39: NOK | T39: NOK | U39: NOK | AE39: 2020862 | AF39: =AE39-M39-K39-G39-E39-C39-I39 -> 0 | AG39: =AE39-SUM(W39:AD39) -> 2020862 | AH39: OK
B40: IMPRMNT_STTS | C40: 2020862 | D40: =C40/$AE40 -> 1 | F40: =E40/$AE40 -> 0 | H40: =G40/$AE40 -> 0 | J40: =I40/$AE40 -> 0 | L40: =K40/$AE40 -> 0 | N40: =M40/$AE40 -> 0 | O40: Concluído | P40: 45321 | Q40: LT ESTR | R40: Sem alterações | S40: OK | T40: OK | U40: OK | AE40: 2020862 | AF40: =AE40-M40-K40-G40-E40-C40-I40 -> 0 | AG40: =AE40-SUM(W40:AD40) -> 2020862 | AH40: OK
...

Sheet Sheet7
A1: GRSS_FEE_CMMSSN_INCM | E1: GRSS_FEE_CMMSSN_INCM_OFF_BLNC
A3: EQUAL | E3: EQUAL
A4: w/o null | B4: 395234 | C4: 801323 | E4: w/o null | F4: 13991 | G4: 1175876
A5: only mant null | B5: 11579 | E5: both null | F5: 1161885
A6: only mat null | B6: 1046
A7: both null | B7: 393464
A9: DIFFERENT | E9: DIFFERENT
A10: w/o null | B10: 365304 | C10: 383485 | E10: w/o null | F10: 3137 | G10: 8932
A11: only mant null | B11: 2116 | E11: both null | F11: 5795
A12: both null | B12: 16065

Sheet Dashboard
B5: 1. Campos a testar | L5: 2. # Campos por Status | V5: 3. # Status dos testes por campo
W7: WIP | X7: NA
W9: =SUMIF('Por campo'!R4:R54,"<>Removido 22/12/2023",'Por campo'!L4:L54)/50 -> 0.16652687 | X9: =SUMIF('Por campo'!R4:R54,"<>Removido 22/12/2023",'Por campo'!N4:N54)/50 -> 0.00083424796
B22: Atualmente a corporação prevê que o GD reporte 50 campos
B25: 3. Status dos testes por universo LT002
C27: OK | D27: NOK | E27: WIP | F27: NS | G27: NA
C28: =SUMIF('Por campo'!R4:R54,"<>Removido 22/12/2023",'Por campo'!D4:D54)/50 -> 0.64916076 | D28: =SUMIF('Por campo'!R4:R54,"<>Removido 22/12/2023",'Por campo'!H4:H54)/50 -> 0.18222687 | E28: =SUMIF('Por campo'!R4:R54,"<>Removido 22/12/2023",'Por campo'!J4:J54)/50 -> 0.001272358 | F28: =SUMIF('Por campo'!R4:R54,"<>Removido 22/12/2023",'Por campo'!L4:L54)/50 -> 0.16652687 | G28: =SUMIF('Por campo'!V4:V54,"<>Removido 22/12/2023",'Por campo'!N4:N54)/50 -> 0.00083424796
C29: =C28-C30 -> 0.013160764 | D29: =D28-D30 -> -0.0027731285 | E29: =E28-E30 -> -0.009727642 | F29: =F28-F30 -> -0.0014731318 | G29: =G28-G30 -> -0.00016575204 | H29: Δ último PdS
C30: 0.636 | D30: 0.185 | E30: 0.011 | F30: 0.168 | G30: 0.001
C31: *NS - Not Started inclui campos "Em implementação" e "Em análise de requisitos"

Sheet aux
A1: Campo | B1: OK | C1: NOK | D1: WIP | E1: Not Started | F1: NA | G1: Status | H1: Alterações Corp | I1: Status base | J1: Status teste | O1: Row Labels | P1: Count of Alterações Corp
A2: ACCMLTD_IMPRMNT_INSTRMNT | B2: =VLOOKUP(A2,'Por campo'!B:U,2,FALSE) -> 2020862 | C2: =VLOOKUP(A2,'Por campo'!B:U,6,FALSE) -> 0 | D2: =VLOOKUP(A2,'Por campo'!B:U,8,FALSE) -> 0 | E2: =VLOOKUP(A2,'Por campo'!B:U,10,FALSE) -> 0 | F2: =VLOOKUP($A2,'Por campo'!B:U,12,FALSE) -> 0 | G2: =VLOOKUP($A2,'Por campo'!B:U,14,FALSE) -> Concluído | H2: =VLOOKUP($A2,'Por campo'!B:U,17,FALSE) -> Sem alterações | I2: =IF(OR(G2="Concluído",G2="Em teste"),"Disponibilizado para teste",IF(G2="Em correção","Disponibilizado para teste",IF(G2="Em especificação","Em especificação",IF(G2="Em implementação","Em implementação",IF(G2="Em análise de requisitos","Em análise de requisitos","NA"))))) -> Disponibilizado para teste | J2: =IF(G2="Concluído","OK",IF(G2="Em correção","NOK",G2)) -> OK | O2: Adicionado 22/12/2023 | P2: 4
A3: ACCNTNG_CLSSFCTN | B3: =VLOOKUP(A3,'Por campo'!B:U,2,FALSE) -> 2020862 | C3: =VLOOKUP(A3,'Por campo'!B:U,6,FALSE) -> 0 | D3: =VLOOKUP(A3,'Por campo'!B:U,8,FALSE) -> 0 | E3: =VLOOKUP(A3,'Por campo'!B:U,10,FALSE) -> 0 | F3: =VLOOKUP($A3,'Por campo'!B:U,12,FALSE) -> 0 | G3: =VLOOKUP($A3,'Por campo'!B:U,14,FALSE) -> Concluído | H3: =VLOOKUP($A3,'Por campo'!B:U,17,FALSE) -> Sem alterações | I3: =IF(OR(G3="Concluído",G3="Em teste"),"Disponibilizado para teste",IF(G3="Em correção","Disponibilizado para teste",IF(G3="Em especificação","Em especificação",IF(G3="Em implementação","Em implementação",IF(G3="Em análise de requisitos","Em análise de requisitos","NA"))))) -> Disponibilizado para teste | J3: =IF(G3="Concluído","OK",IF(G3="Em correção","NOK",G3)) -> OK | O3: Alterado 22/12/2023 | P3: 8
A4: COD_SOC | B4: =VLOOKUP(A4,'Por campo'!B:U,2,FALSE) -> 2020862 | C4: =VLOOKUP(A4,'Por campo'!B:U,6,FALSE) -> 0 | D4: =VLOOKUP(A4,'Por campo'!B:U,8,FALSE) -> 0 | E4: =VLOOKUP(A4,'Por campo'!B:U,10,FALSE) -> 0 | F4: =VLOOKUP($A4,'Por campo'!B:U,12,FALSE) -> 0 | G4: =VLOOKUP($A4,'Por campo'!B:U,14,FALSE) -> Concluído | H4: =VLOOKUP($A4,'Por campo'!B:U,17,FALSE) -> Sem alterações | I4: =IF(OR(G4="Concluído",G4="Em teste"),"Disponibilizado para teste",IF(G4="Em correção","Disponibilizado para teste",IF(G4="Em especificação","Em especificação",IF(G4="Em implementação","Em implementação",IF(G4="Em análise de requisitos","Em análise de requisitos","NA"))))) -> Disponibilizado para teste | J4: =IF(G4="Concluído","OK",IF(G4="Em correção","NOK",G4)) -> OK | O4: Removido 22/12/2023 | P4: 1
A5: DFLT_STTS_INSTRMNT | B5: =VLOOKUP(A5,'Por campo'!B:U,2,FALSE) -> 2020862 | C5: =VLOOKUP(A5,'Por campo'!B:U,6,FALSE) -> 0 | D5: =VLOOKUP(A5,'Por campo'!B:U,8,FALSE) -> 0 | E5: =VLOOKUP(A5,'Por campo'!B:U,10,FALSE) -> 0 | F5: =VLOOKUP($A5,'Por campo'!B:U,12,FALSE) -> 0 | G5: =VLOOKUP($A5,'Por campo'!B:U,14,FALSE) -> Concluído | H5: =VLOOKUP($A5,'Por campo'!B:U,17,FALSE) -> Sem alterações | I5: =IF(OR(G5="Concluído",G5="Em teste"),"Disponibilizado para teste",IF(G5="Em correção","Disponibilizado para teste",IF(G5="Em especificação","Em especificação",IF(G5="Em implementação","Em implementação",IF(G5="Em análise de requisitos","Em análise de requisitos","NA"))))) -> Disponibilizado para teste | J5: =IF(G5="Concluído","OK",IF(G5="Em correção","NOK",G5)) -> OK | O5: Sem alterações | P5: 38
A6: FLG_INSTRMNT_CNCLLD | B6: =VLOOKUP(A6,'Por campo'!B:U,2,FALSE) -> 0 | C6: =VLOOKUP(A6,'Por campo'!B:U,6,FALSE) -> 2020862 | D6: =VLOOKUP(A6,'Por campo'!B:U,8,FALSE) -> 0 | E6: =VLOOKUP(A6,'Por campo'!B:U,10,FALSE) -> 0 | F6: =VLOOKUP($A6,'Por campo'!B:U,12,FALSE) -> 0 | G6: =VLOOKUP($A6,'Por campo'!B:U,14,FALSE) -> NA | H6: =VLOOKUP($A6,'Por campo'!B:U,17,FALSE) -> Removido 22/12/2023 | I6: =IF(OR(G6="Concluído",G6="Em teste"),"Disponibilizado para teste",IF(G6="Em correção","Disponibilizado para teste",IF(G6="Em especificação","Em especificação",IF(G6="Em implementação","Em implementação",IF(G6="Em análise de requisitos","Em análise de requisitos","NA"))))) -> NA | J6: =IF(G6="Concluído","OK",IF(G6="Em correção","NOK",G6)) -> NA | O6: Grand Total | P6: 51
A7: GRSS_CRRYNG_AMNT_INSTRMNT | B7: =VLOOKUP(A7,'Por campo'!B:U,2,FALSE) -> 2020862 | C7: =VLOOKUP(A7,'Por campo'!B:U,6,FALSE) -> 0 | D7: =VLOOKUP(A7,'Por campo'!B:U,8,FALSE) -> 0 | E7: =VLOOKUP(A7,'Por campo'!B:U,10,FALSE) -> 0 | F7: =VLOOKUP($A7,'Por campo'!B:U,12,FALSE) -> 0 | G7: =VLOOKUP($A7,'Por campo'!B:U,14,FALSE) -> Concluído | H7: =VLOOKUP($A7,'Por campo'!B:U,17,FALSE) -> Sem alterações | I7: =IF(OR(G7="Concluído",G7="Em teste"),"Disponibilizado para teste",IF(G7="Em correção","Disponibilizado para teste",IF(G7="Em especificação","Em especificação",IF(G7="Em implementação","Em implementação",IF(G7="Em análise de requisitos","Em análise de requisitos","NA"))))) -> Disponibilizado para teste | J7: =IF(G7="Concluído","OK",IF(G7="Em correção","NOK",G7)) -> OK
A8: IMPRMNT_STTS | B8: =VLOOKUP(A8,'Por campo'!B:U,2,FALSE) -> 2020862 | C8: =VLOOKUP(A8,'Por campo'!B:U,6,FALSE) -> 0 | D8: =VLOOKUP(A8,'Por campo'!B:U,8,FALSE) -> 0 | E8: =VLOOKUP(A8,'Por campo'!B:U,10,FALSE) -> 0 | F8: =VLOOKUP($A8,'Por campo'!B:U,12,FALSE) -> 0 | G8: =VLOOKUP($A8,'Por campo'!B:U,14,FALSE) -> Concluído | H8: =VLOOKUP($A8,'Por campo'!B:U,17,FALSE) -> Sem alterações | I8: =IF(OR(G8="Concluído",G8="Em teste"),"Disponibilizado para teste",IF(G8="Em correção","Disponibilizado para teste",IF(G8="Em especificação","Em especificação",IF(G8="Em implementação","Em implementação",IF(G8="Em análise de requisitos","Em análise de requisitos","NA"))))) -> Disponibilizado para teste | J8: =IF(G8="Concluído","OK",IF(G8="Em correção","NOK",G8)) -> OK
A9: OFF_BLNC_SHT_AMNT_INSTRMNT | B9: =VLOOKUP(A9,'Por campo'!B:U,2,FALSE) -> 2020862 | C9: =VLOOKUP(A9,'Por campo'!B:U,6,FALSE) -> 0 | D9: =VLOOKUP(A9,'Por campo'!B:U,8,FALSE) -> 0 | E9: =VLOOKUP(A9,'Por campo'!B:U,10,FALSE) -> 0 | F9: =VLOOKUP($A9,'Por campo'!B:U,12,FALSE) -> 0 | G9: =VLOOKUP($A9,'Por campo'!B:U,14,FALSE) -> Concluído | H9: =VLOOKUP($A9,'Por campo'!B:U,17,FALSE) -> Sem alterações | I9: =IF(OR(G9="Concluído",G9="Em teste"),"Disponibilizado para teste",IF(G9="Em correção","Disponibilizado para teste",IF(G9="Em especificação","Em especificação",IF(G9="Em implementação","Em implementação",IF(G9="Em análise de requisitos","Em análise de requisitos","NA"))))) -> Disponibilizado para teste | J9: =IF(G9="Concluído","OK",IF(G9="Em correção","NOK",G9)) -> OK | O9: Alterações Corp | P9: (Multiple Items)
A10: PRFRMNG_STTS | B10: =VLOOKUP(A10,'Por campo'!B:U,2,FALSE) -> 2020862 | C10: =VLOOKUP(A10,'Por campo'!B:U,6,FALSE) -> 0 | D10: =VLOOKUP(A10,'Por campo'!B:U,8,FALSE) -> 0 | E10: =VLOOKUP(A10,'Por campo'!B:U,10,FALSE) -> 0 | F10: =VLOOKUP($A10,'Por campo'!B:U,12,FALSE) -> 0 | G10: =VLOOKUP($A10,'Por campo'!B:U,14,FALSE) -> Concluído | H10: =VLOOKUP($A10,'Por campo'!B:U,17,FALSE) -> Sem alterações | I10: =IF(OR(G10="Concluído",G10="Em teste"),"Disponibilizado para teste",IF(G10="Em correção","Disponibilizado para teste",IF(G10="Em especificação","Em especificação",IF(G10="Em implementação","Em implementação",IF(G10="Em análise de requisitos","Em análise de requisitos","NA"))))) -> Disponibilizado para teste | J10: =IF(G10="Concluído","OK",IF(G10="Em correção","NOK",G10)) -> OK
A11: PRVSNS_OFF_BLNC_SHT | B11: =VLOOKUP(A11,'Por campo'!B:U,2,FALSE) -> 2020862 | C11: =VLOOKUP(A11,'Por campo'!B:U,6,FALSE) -> 0 | D11: =VLOOKUP(A11,'Por campo'!B:U,8,FALSE) -> 0 | E11: =VLOOKUP(A11,'Por campo'!B:U,10,FALSE) -> 0 | F11: =VLOOKUP($A11,'Por campo'!B:U,12,FALSE) -> 0 | G11: =VLOOKUP($A11,'Por campo'!B:U,14,FALSE) -> Concluído | H11: =VLOOKUP($A11,'Por campo'!B:U,17,FALSE) -> Sem alterações | I11: =IF(OR(G11="Concluído",G11="Em teste"),"Disponibilizado para teste",IF(G11="Em correção","Disponibilizado para teste",IF(G11="Em especificação","Em especificação",IF(G11="Em implementação","Em implementação",IF(G11="Em análise de requisitos","Em análise de requisitos","NA"))))) -> Disponibilizado para teste | J11: =IF(G11="Concluído","OK",IF(G11="Em correção","NOK",G11)) -> OK | O11: Row Labels | P11: Count of Alterações Corp
A12: RWA | B12: =VLOOKUP(A12,'Por campo'!B:U,2,FALSE) -> 2020838 | C12: =VLOOKUP(A12,'Por campo'!B:U,6,FALSE) -> 24 | D12: =VLOOKUP(A12,'Por campo'!B:U,8,FALSE) -> 0 | E12: =VLOOKUP(A12,'Por campo'!B:U,10,FALSE) -> 0 | F12: =VLOOKUP($A12,'Por campo'!B:U,12,FALSE) -> 0 | G12: =VLOOKUP($A12,'Por campo'!B:U,14,FALSE) -> Em Correção | H12: =VLOOKUP($A12,'Por campo'!B:U,17,FALSE) -> Sem alterações | I12: =IF(OR(G12="Concluído",G12="Em teste"),"Disponibilizado para teste",IF(G12="Em correção","Disponibilizado para teste",IF(G12="Em especificação","Em especificação",IF(G12="Em implementação","Em implementação",IF(G12="Em análise de requisitos","Em análise de requisitos","NA"))))) -> Disponibilizado para teste | J12: =IF(G12="Concluído","OK",IF(G12="Em correção","NOK",G12)) -> NOK | O12: Concluído | P12: 19
A13: TYP_INSTRMNT | B13: =VLOOKUP(A13,'Por campo'!B:U,2,FALSE) -> 2020862 | C13: =VLOOKUP(A13,'Por campo'!B:U,6,FALSE) -> 0 | D13: =VLOOKUP(A13,'Por campo'!B:U,8,FALSE) -> 0 | E13: =VLOOKUP(A13,'Por campo'!B:U,10,FALSE) -> 0 | F13: =VLOOKUP($A13,'Por campo'!B:U,12,FALSE) -> 0 | G13: =VLOOKUP($A13,'Por campo'!B:U,14,FALSE) -> Concluído | H13: =VLOOKUP($A13,'Por campo'!B:U,17,FALSE) -> Sem alterações | I13: =IF(OR(G13="Concluído",G13="Em teste"),"Disponibilizado para teste",IF(G13="Em correção","Disponibilizado para teste",IF(G13="Em especificação","Em especificação",IF(G13="Em implementação","Em implementação",IF(G13="Em análise de requisitos","Em análise de requisitos","NA"))))) -> Disponibilizado para teste | J13: =IF(G13="Concluído","OK",IF(G13="Em correção","NOK",G13)) -> OK | O13: Em correção | P13: 6
A14: NT_LN_LSS_PRVSN_OFF_BLNC | B14: =VLOOKUP(A14,'Por campo'!B:U,2,FALSE) -> 1894058 | C14: =VLOOKUP(A14,'Por campo'!B:U,6,FALSE) -> 0 | D14: =VLOOKUP(A14,'Por campo'!B:U,8,FALSE) -> 454 | E14: =VLOOKUP(A14,'Por campo'!B:U,10,FALSE) -> 122685 | F14: =VLOOKUP($A14,'Por campo'!B:U,12,FALSE) -> 3665 | G14: =VLOOKUP($A14,'Por campo'!B:U,14,FALSE) -> Em teste | H14: =VLOOKUP($A14,'Por campo'!B:U,17,FALSE) -> Sem alterações | I14: =IF(OR(G14="Concluído",G14="Em teste"),"Disponibilizado para teste",IF(G14="Em correção","Disponibilizado para teste",IF(G14="Em especificação","Em especificação",IF(G14="Em implementação","Em implementação",IF(G14="Em análise de requisitos","Em análise de requisitos","NA"))))) -> Disponibilizado para teste | J14: =IF(G14="Concluído","OK",IF(G14="Em correção","NOK",G14)) -> Em teste | O14: Em Implementação | P14: 13
A15: AVRG_BLNC | B15: =VLOOKUP(A15,'Por campo'!B:U,2,FALSE) -> 1894058 | C15: =VLOOKUP(A15,'Por campo'!B:U,6,FALSE) -> 0 | D15: =VLOOKUP(A15,'Por campo'!B:U,8,FALSE) -> 123139 | E15: =VLOOKUP(A15,'Por campo'!B:U,10,FALSE) -> 0 | F15: =VLOOKUP($A15,'Por campo'!B:U,12,FALSE) -> 3665 | G15: =VLOOKUP($A15,'Por campo'!B:U,14,FALSE) -> Em teste | H15: =VLOOKUP($A15,'Por campo'!B:U,17,FALSE) -> Sem alterações | I15: =IF(OR(G15="Concluído",G15="Em teste"),"Disponibilizado para teste",IF(G15="Em correção","Disponibilizado para teste",IF(G15="Em especificação","Em especificação",IF(G15="Em implementação","Em implementação",IF(G15="Em análise de requisitos","Em análise de requisitos","NA"))))) -> Disponibilizado para teste | J15: =IF(G15="Concluído","OK",IF(G15="Em correção","NOK",G15)) -> Em teste | O15: Em teste | P15: 10
A16: INTRNL_TRNSFR_RT | B16: =VLOOKUP(A16,'Por campo'!B:U,2,FALSE) -> 1851201 | C16: =VLOOKUP(A16,'Por campo'!B:U,6,FALSE) -> 0 | D16: =VLOOKUP(A16,'Por campo'!B:U,8,FALSE) -> 454 | E16: =VLOOKUP(A16,'Por campo'!B:U,10,FALSE) -> 166884 | F16: =VLOOKUP($A16,'Por campo'!B:U,12,FALSE) -> 3665 | G16: =VLOOKUP($A16,'Por campo'!B:U,14,FALSE) -> Em teste | H16: =VLOOKUP($A16,'Por campo'!B:U,17,FALSE) -> Sem alterações | I16: =IF(OR(G16="Concluído",G16="Em teste"),"Disponibilizado para teste",IF(G16="Em correção","Disponibilizado para teste",IF(G16="Em especificação","Em especificação",IF(G16="Em implementação","Em implementação",IF(G16="Em análise de requisitos","Em análise de requisitos","NA"))))) -> Disponibilizado para teste | J16: =IF(G16="Concluído","OK",IF(G16="Em correção","NOK",G16)) -> Em teste | O16: Em análise de requisitos | P16: 2
A17: NT_LN_LSS_PRVSN | B17: =VLOOKUP(A17,'Por campo'!B:U,2,FALSE) -> 1894058 | C17: =VLOOKUP(A17,'Por campo'!B:U,6,FALSE) -> 0 | D17: =VLOOKUP(A17,'Por campo'!B:U,8,FALSE) -> 454 | E17: =VLOOKUP(A17,'Por campo'!B:U,10,FALSE) -> 122685 | F17: =VLOOKUP($A17,'Por campo'!B:U,12,FALSE) -> 3665 | G17: =VLOOKUP($A17,'Por campo'!B:U,14,FALSE) -> Em teste | H17: =VLOOKUP($A17,'Por campo'!B:U,17,FALSE) -> Sem alterações | I17: =IF(OR(G17="Concluído",G17="Em teste"),"Disponibilizado para teste",IF(G17="Em correção","Disponibilizado para teste",IF(G17="Em especificação","Em especificação",IF(G17="Em implementação","Em implementação",IF(G17="Em análise de requisitos","Em análise de requisitos","NA"))))) -> Disponibilizado para teste | J17: =IF(G17="Concluído","OK",IF(G17="Em correção","NOK",G17)) -> Em teste | O17: Grand Total | P17: 50
A18: ACCMLTD_CHNGS_FV_CR_INSTRMNT | B18: =VLOOKUP(A18,'Por campo'!B:U,2,FALSE) -> 2020862 | C18: =VLOOKUP(A18,'Por campo'!B:U,6,FALSE) -> 0 | D18: =VLOOKUP(A18,'Por campo'!B:U,8,FALSE) -> 0 | E18: =VLOOKUP(A18,'Por campo'!B:U,10,FALSE) -> 0 | F18: =VLOOKUP($A18,'Por campo'!B:U,12,FALSE) -> 0 | G18: =VLOOKUP($A18,'Por campo'!B:U,14,FALSE) -> Concluído | H18: =VLOOKUP($A18,'Por campo'!B:U,17,FALSE) -> Sem alterações | I18: =IF(OR(G18="Concluído",G18="Em teste"),"Disponibilizado para teste",IF(G18="Em correção","Disponibilizado para teste",IF(G18="Em especificação","Em especificação",IF(G18="Em implementação","Em implementação",IF(G18="Em análise de requisitos","Em análise de requisitos","NA"))))) -> Disponibilizado para teste | J18: =IF(G18="Concluído","OK",IF(G18="Em correção","NOK",G18)) -> OK
A19: AVRG_BLNC_OFF_BLNC | B19: =VLOOKUP(A19,'Por campo'!B:U,2,FALSE) -> 1894058 | C19: =VLOOKUP(A19,'Por campo'!B:U,6,FALSE) -> 0 | D19: =VLOOKUP(A19,'Por campo'!B:U,8,FALSE) -> 454 | E19: =VLOOKUP(A19,'Por campo'!B:U,10,FALSE) -> 122685 | F19: =VLOOKUP($A19,'Por campo'!B:U,12,FALSE) -> 3665 | G19: =VLOOKUP($A19,'Por campo'!B:U,14,FALSE) -> Em teste | H19: =VLOOKUP($A19,'Por campo'!B:U,17,FALSE) -> Sem alterações | I19: =IF(OR(G19="Concluído",G19="Em teste"),"Disponibilizado para teste",IF(G19="Em correção","Disponibilizado para teste",IF(G19="Em especificação","Em especificação",IF(G19="Em implementação","Em implementação",IF(G19="Em análise de requisitos","Em análise de requisitos","NA"))))) -> Disponibilizado para teste | J19: =IF(G19="Concluído","OK",IF(G19="Em correção","NOK",G19)) -> Em teste
A20: BSNSS_AREA | B20: =VLOOKUP(A20,'Por campo'!B:U,2,FALSE) -> 16935 | C20: =VLOOKUP(A20,'Por campo'!B:U,6,FALSE) -> 1209396 | D20: =VLOOKUP(A20,'Por campo'!B:U,8,FALSE) -> 0 | E20: =VLOOKUP(A20,'Por campo'!B:U,10,FALSE) -> 790866 | F20: =VLOOKUP($A20,'Por campo'!B:U,12,FALSE) -> 3665 | G20: =VLOOKUP($A20,'Por campo'!B:U,14,FALSE) -> Em Correção | H20: =VLOOKUP($A20,'Por campo'!B:U,17,FALSE) -> Sem alterações | I20: =IF(OR(G20="Concluído",G20="Em teste"),"Disponibilizado para teste",IF(G20="Em correção","Disponibilizado para teste",IF(G20="Em especificação","Em especificação",IF(G20="Em implementação","Em implementação",IF(G20="Em análise de requisitos","Em análise de requisitos","NA"))))) -> Disponibilizado para teste | J20: =IF(G20="Concluído","OK",IF(G20="Em correção","NOK",G20)) -> NOK
A21: BSNSS_AREA_CCRR | B21: =VLOOKUP(A21,'Por campo'!B:U,2,FALSE) -> 0 | C21: =VLOOKUP(A21,'Por campo'!B:U,6,FALSE) -> 2017197 | D21: =VLOOKUP(A21,'Por campo'!B:U,8,FALSE) -> 0 | E21: =VLOOKUP(A21,'Por campo'!B:U,10,FALSE) -> 0 | F21: =VLOOKUP($A21,'Por campo'!B:U,12,FALSE) -> 3665 | G21: =VLOOKUP($A21,'Por campo'!B:U,14,FALSE) -> Em Implementação | H21: =VLOOKUP($A21,'Por campo'!B:U,17,FALSE) -> Sem alterações | I21: =IF(OR(G21="Concluído",G21="Em teste"),"Disponibilizado para teste",IF(G21="Em correção","Disponibilizado para teste",IF(G21="Em especificação","Em especificação",IF(G21="Em implementação","Em implementação",IF(G21="Em análise de requisitos","Em análise de requisitos","NA"))))) -> Em implementação | J21: =IF(G21="Concluído","OK",IF(G21="Em correção","NOK",G21)) -> Em Implementação
A22: BSNSS_AREA_DSTNTN | B22: =VLOOKUP(A22,'Por campo'!B:U,2,FALSE) -> 2020862 | C22: =VLOOKUP(A22,'Por campo'!B:U,6,FALSE) -> 0 | D22: =VLOOKUP(A22,'Por campo'!B:U,8,FALSE) -> 0 | E22: =VLOOKUP(A22,'Por campo'!B:U,10,FALSE) -> 0 | F22: =VLOOKUP($A22,'Por campo'!B:U,12,FALSE) -> 0 | G22: =VLOOKUP($A22,'Por campo'!B:U,14,FALSE) -> Concluído | H22: =VLOOKUP($A22,'Por campo'!B:U,17,FALSE) -> Sem alterações | I22: =IF(OR(G22="Concluído",G22="Em teste"),"Disponibilizado para teste",IF(G22="Em correção","Disponibilizado para teste",IF(G22="Em especificação","Em especificação",IF(G22="Em implementação","Em implementação",IF(G22="Em análise de requisitos","Em análise de requisitos","NA"))))) -> Disponibilizado para teste | J22: =IF(G22="Concluído","OK",IF(G22="Em correção","NOK",G22)) -> OK | O22: Alterações Corp | P22: (Multiple Items)
A23: CNCLLD_INSTRMNT_STTS | B23: =VLOOKUP(A23,'Por campo'!B:U,2,FALSE) -> 0 | C23: =VLOOKUP(A23,'Por campo'!B:U,6,FALSE) -> 0 | D23: =VLOOKUP(A23,'Por campo'!B:U,8,FALSE) -> 0 | E23: =VLOOKUP(A23,'Por campo'!B:U,10,FALSE) -> 2020862 | F23: =VLOOKUP($A23,'Por campo'!B:U,12,FALSE) -> 0 | G23: =VLOOKUP($A23,'Por campo'!B:U,14,FALSE) -> Em Implementação | H23: =VLOOKUP($A23,'Por campo'!B:U,17,FALSE) -> Adicionado 22/12/2023 | I23: =IF(OR(G23="Concluído",G23="Em teste"),"Disponibilizado para teste",IF(G23="Em correção","Disponibilizado para teste",IF(G23="Em especificação","Em especificação",IF(G23="Em implementação","Em implementação",IF(G23="Em análise de requisitos","Em análise de requisitos","NA"))))) -> Em implementação | J23: =IF(G23="Concluído","OK",IF(G23="Em correção","NOK",G23)) -> Em Implementação
A24: COD_SOC_DSTNTN | B24: =VLOOKUP(A24,'Por campo'!B:U,2,FALSE) -> 2020862 | C24: =VLOOKUP(A24,'Por campo'!B:U,6,FALSE) -> 0 | D24: =VLOOKUP(A24,'Por campo'!B:U,8,FALSE) -> 0 | E24: =VLOOKUP(A24,'Por campo'!B:U,10,FALSE) -> 0 | F24: =VLOOKUP($A24,'Por campo'!B:U,12,FALSE) -> 0 | G24: =VLOOKUP($A24,'Por campo'!B:U,14,FALSE) -> Concluído | H24: =VLOOKUP($A24,'Por campo'!B:U,17,FALSE) -> Sem alterações | I24: =IF(OR(G24="Concluído",G24="Em teste"),"Disponibilizado para teste",IF(G24="Em correção","Disponibilizado para teste",IF(G24="Em especificação","Em especificação",IF(G24="Em implementação","Em implementação",IF(G24="Em análise de requisitos","Em análise de requisitos","NA"))))) -> Disponibilizado para teste | J24: =IF(G24="Concluído","OK",IF(G24="Em correção","NOK",G24)) -> OK | O24: Row Labels | P24: Count of Status base
A25: COD_SOC_INTRGRP | B25: =VLOOKUP(A25,'Por campo'!B:U,2,FALSE) -> 0 | C25: =VLOOKUP(A25,'Por campo'!B:U,6,FALSE) -> 0 | D25: =VLOOKUP(A25,'Por campo'!B:U,8,FALSE) -> 0 | E25: =VLOOKUP(A25,'Por campo'!B:U,10,FALSE) -> 2020862 | F25: =VLOOKUP($A25,'Por campo'!B:U,12,FALSE) -> 0 | G25: =VLOOKUP($A25,'Por campo'!B:U,14,FALSE) -> Em Implementação | H25: =VLOOKUP($A25,'Por campo'!B:U,17,FALSE) -> Adicionado 22/12/2023 | I25: =IF(OR(G25="Concluído",G25="Em teste"),"Disponibilizado para teste",IF(G25="Em correção","Disponibilizado para teste",IF(G25="Em especificação","Em especificação",IF(G25="Em implementação","Em implementação",IF(G25="Em análise de requisitos","Em análise de requisitos","NA"))))) -> Em implementação | J25: =IF(G25="Concluído","OK",IF(G25="Em correção","NOK",G25)) -> Em Implementação | O25: Disponibilizado para teste | P25: 35
A26: DT_RFRNC | B26: =VLOOKUP(A26,'Por campo'!B:U,2,FALSE) -> 2020862 | C26: =VLOOKUP(A26,'Por campo'!B:U,6,FALSE) -> 0 | D26: =VLOOKUP(A26,'Por campo'!B:U,8,FALSE) -> 0 | E26: =VLOOKUP(A26,'Por campo'!B:U,10,FALSE) -> 0 | F26: =VLOOKUP($A26,'Por campo'!B:U,12,FALSE) -> 0 | G26: =VLOOKUP($A26,'Por campo'!B:U,14,FALSE) -> Concluído | H26: =VLOOKUP($A26,'Por campo'!B:U,17,FALSE) -> Sem alterações | I26: =IF(OR(G26="Concluído",G26="Em teste"),"Disponibilizado para teste",IF(G26="Em correção","Disponibilizado para teste",IF(G26="Em especificação","Em especificação",IF(G26="Em implementação","Em implementação",IF(G26="Em análise de requisitos","Em análise de requisitos","NA"))))) -> Disponibilizado para teste | J26: =IF(G26="Concluído","OK",IF(G26="Em correção","NOK",G26)) -> OK | O26: Em implementação | P26: 13
A27: FLG_INTRBSNSS | B27: =VLOOKUP(A27,'Por campo'!B:U,2,FALSE) -> 2020862 | C27: =VLOOKUP(A27,'Por campo'!B:U,6,FALSE) -> 0 | D27: =VLOOKUP(A27,'Por campo'!B:U,8,FALSE) -> 0 | E27: =VLOOKUP(A27,'Por campo'!B:U,10,FALSE) -> 0 | F27: =VLOOKUP($A27,'Por campo'!B:U,12,FALSE) -> 0 | G27: =VLOOKUP($A27,'Por campo'!B:U,14,FALSE) -> Concluído | H27: =VLOOKUP($A27,'Por campo'!B:U,17,FALSE) -> Sem alterações | I27: =IF(OR(G27="Concluído",G27="Em teste"),"Disponibilizado para teste",IF(G27="Em correção","Disponibilizado para teste",IF(G27="Em especificação","Em especificação",IF(G27="Em implementação","Em implementação",IF(G27="Em análise de requisitos","Em análise de requisitos","NA"))))) -> Disponibilizado para teste | J27: =IF(G27="Concluído","OK",IF(G27="Em correção","NOK",G27)) -> OK | O27: Em análise de requisitos | P27: 2
A28: GNS_FNNCL_TRNSCTN_EXCHNG_CCRR | B28: =VLOOKUP(A28,'Por campo'!B:U,2,FALSE) -> 0 | C28: =VLOOKUP(A28,'Por campo'!B:U,6,FALSE) -> 2017197 | D28: =VLOOKUP(A28,'Por campo'!B:U,8,FALSE) -> 0 | E28: =VLOOKUP(A28,'Por campo'!B:U,10,FALSE) -> 0 | F28: =VLOOKUP($A28,'Por campo'!B:U,12,FALSE) -> 3665 | G28: =VLOOKUP($A28,'Por campo'!B:U,14,FALSE) -> Em Implementação | H28: =VLOOKUP($A28,'Por campo'!B:U,17,FALSE) -> Sem alterações | I28: =IF(OR(G28="Concluído",G28="Em teste"),"Disponibilizado para teste",IF(G28="Em correção","Disponibilizado para teste",IF(G28="Em especificação","Em especificação",IF(G28="Em implementação","Em implementação",IF(G28="Em análise de requisitos","Em análise de requisitos","NA"))))) -> Em implementação | J28: =IF(G28="Concluído","OK",IF(G28="Em correção","NOK",G28)) -> Em Implementação | O28: Grand Total | P28: 50
A29: GNS_FNNCL_TRNSCTN_EXCHNG_DFFRNCS | B29: =VLOOKUP(A29,'Por campo'!B:U,2,FALSE) -> 1816745 | C29: =VLOOKUP(A29,'Por campo'!B:U,6,FALSE) -> 0 | D29: =VLOOKUP(A29,'Por campo'!B:U,8,FALSE) -> 446 | E29: =VLOOKUP(A29,'Por campo'!B:U,10,FALSE) -> 200006 | F29: =VLOOKUP($A29,'Por campo'!B:U,12,FALSE) -> 3665 | G29: =VLOOKUP($A29,'Por campo'!B:U,14,FALSE) -> Em teste | H29: =VLOOKUP($A29,'Por campo'!B:U,17,FALSE) -> Sem alterações | I29: =IF(OR(G29="Concluído",G29="Em teste"),"Disponibilizado para teste",IF(G29="Em correção","Disponibilizado para teste",IF(G29="Em especificação","Em especificação",IF(G29="Em implementação","Em implementação",IF(G29="Em análise de requisitos","Em análise de requisitos","NA"))))) -> Disponibilizado para teste | J29: =IF(G29="Concluído","OK",IF(G29="Em correção","NOK",G29)) -> Em teste
A30: GRSS_CMMSSN_EXPNS | B30: =VLOOKUP(A30,'Por campo'!B:U,2,FALSE) -> 1553247 | C30: =VLOOKUP(A30,'Por campo'!B:U,6,FALSE) -> 305013 | D30: =VLOOKUP(A30,'Por campo'!B:U,8,FALSE) -> 454 | E30: =VLOOKUP(A30,'Por campo'!B:U,10,FALSE) -> 158483 | F30: =VLOOKUP($A30,'Por campo'!B:U,12,FALSE) -> 3665 | G30: =VLOOKUP($A30,'Por campo'!B:U,14,FALSE) -> Em Correção | H30: =VLOOKUP($A30,'Por campo'!B:U,17,FALSE) -> Alterado 22/12/2023 | I30: =IF(OR(G30="Concluído",G30="Em teste"),"Disponibilizado para teste",IF(G30="Em correção","Disponibilizado para teste",IF(G30="Em especificação","Em especificação",IF(G30="Em implementação","Em implementação",IF(G30="Em análise de requisitos","Em análise de requisitos","NA"))))) -> Disponibilizado para teste | J30: =IF(G30="Concluído","OK",IF(G30="Em correção","NOK",G30)) -> NOK
A31: GRSS_CMMSSN_EXPNS_CCRR | B31: =VLOOKUP(A31,'Por campo'!B:U,2,FALSE) -> 0 | C31: =VLOOKUP(A31,'Por campo'!B:U,6,FALSE) -> 2017197 | D31: =VLOOKUP(A31,'Por campo'!B:U,8,FALSE) -> 0 | E31: =VLOOKUP(A31,'Por campo'!B:U,10,FALSE) -> 0 | F31: =VLOOKUP($A31,'Por campo'!B:U,12,FALSE) -> 3665 | G31: =VLOOKUP($A31,'Por campo'!B:U,14,FALSE) -> Em Implementação | H31: =VLOOKUP($A31,'Por campo'!B:U,17,FALSE) -> Alterado 22/12/2023 | I31: =IF(OR(G31="Concluído",G31="Em teste"),"Disponibilizado para teste",IF(G31="Em correção","Disponibilizado para teste",IF(G31="Em especificação","Em especificação",IF(G31="Em implementação","Em implementação",IF(G31="Em análise de requisitos","Em análise de requisitos","NA"))))) -> Em implementação | J31: =IF(G31="Concluído","OK",IF(G31="Em correção","NOK",G31)) -> Em Implementação | O31: Alterações Corp | P31: (Multiple Items)
A32: GRSS_CMMSSN_EXPNS_OFF_BLNC | B32: =VLOOKUP(A32,'Por campo'!B:U,2,FALSE) -> 1858259 | C32: =VLOOKUP(A32,'Por campo'!B:U,6,FALSE) -> 1 | D32: =VLOOKUP(A32,'Por campo'!B:U,8,FALSE) -> 454 | E32: =VLOOKUP(A32,'Por campo'!B:U,10,FALSE) -> 158483 | F32: =VLOOKUP($A32,'Por campo'!B:U,12,FALSE) -> 3665 | G32: =VLOOKUP($A32,'Por campo'!B:U,14,FALSE) -> Em Correção | H32: =VLOOKUP($A32,'Por campo'!B:U,17,FALSE) -> Alterado 22/12/2023 | I32: =IF(OR(G32="Concluído",G32="Em teste"),"Disponibilizado para teste",IF(G32="Em correção","Disponibilizado para teste",IF(G32="Em especificação","Em especificação",IF(G32="Em implementação","Em implementação",IF(G32="Em análise de requisitos","Em análise de requisitos","NA"))))) -> Disponibilizado para teste | J32: =IF(G32="Concluído","OK",IF(G32="Em correção","NOK",G32)) -> NOK
A33: GRSS_CMMSSN_EXPNS_OFF_BLNC_CCRR | B33: =VLOOKUP(A33,'Por campo'!B:U,2,FALSE) -> 0 | C33: =VLOOKUP(A33,'Por campo'!B:U,6,FALSE) -> 2017197 | D33: =VLOOKUP(A33,'Por campo'!B:U,8,FALSE) -> 0 | E33: =VLOOKUP(A33,'Por campo'!B:U,10,FALSE) -> 0 | F33: =VLOOKUP($A33,'Por campo'!B:U,12,FALSE) -> 3665 | G33: =VLOOKUP($A33,'Por campo'!B:U,14,FALSE) -> Em Implementação | H33: =VLOOKUP($A33,'Por campo'!B:U,17,FALSE) -> Alterado 22/12/2023 | I33: =IF(OR(G33="Concluído",G33="Em teste"),"Disponibilizado para teste",IF(G33="Em correção","Disponibilizado para teste",IF(G33="Em especificação","Em especificação",IF(G33="Em implementação","Em implementação",IF(G33="Em análise de requisitos","Em análise de requisitos","NA"))))) -> Em implementação | J33: =IF(G33="Concluído","OK",IF(G33="Em correção","NOK",G33)) -> Em Implementação | O33: Row Labels | P33: Count of Status teste
A34: GRSS_CMMSSN_INCM | B34: =VLOOKUP(A34,'Por campo'!B:U,2,FALSE) -> 1097546 | C34: =VLOOKUP(A34,'Por campo'!B:U,6,FALSE) -> 760714 | D34: =VLOOKUP(A34,'Por campo'!B:U,8,FALSE) -> 454 | E34: =VLOOKUP(A34,'Por campo'!B:U,10,FALSE) -> 158483 | F34: =VLOOKUP($A34,'Por campo'!B:U,12,FALSE) -> 3665 | G34: =VLOOKUP($A34,'Por campo'!B:U,14,FALSE) -> Em Correção | H34: =VLOOKUP($A34,'Por campo'!B:U,17,FALSE) -> Alterado 22/12/2023 | I34: =IF(OR(G34="Concluído",G34="Em teste"),"Disponibilizado para teste",IF(G34="Em correção","Disponibilizado para teste",IF(G34="Em especificação","Em especificação",IF(G34="Em implementação","Em implementação",IF(G34="Em análise de requisitos","Em análise de requisitos","NA"))))) -> Disponibilizado para teste | J34: =IF(G34="Concluído","OK",IF(G34="Em correção","NOK",G34)) -> NOK | O34: Em teste | P34: 10
A35: GRSS_CMMSSN_INCM_CCRR | B35: =VLOOKUP(A35,'Por campo'!B:U,2,FALSE) -> 0 | C35: =VLOOKUP(A35,'Por campo'!B:U,6,FALSE) -> 2017197 | D35: =VLOOKUP(A35,'Por campo'!B:U,8,FALSE) -> 0 | E35: =VLOOKUP(A35,'Por campo'!B:U,10,FALSE) -> 0 | F35: =VLOOKUP($A35,'Por campo'!B:U,12,FALSE) -> 3665 | G35: =VLOOKUP($A35,'Por campo'!B:U,14,FALSE) -> Em Implementação | H35: =VLOOKUP($A35,'Por campo'!B:U,17,FALSE) -> Alterado 22/12/2023 | I35: =IF(OR(G35="Concluído",G35="Em teste"),"Disponibilizado para teste",IF(G35="Em correção","Disponibilizado para teste",IF(G35="Em especificação","Em especificação",IF(G35="Em implementação","Em implementação",IF(G35="Em análise de requisitos","Em análise de requisitos","NA"))))) -> Em implementação | J35: =IF(G35="Concluído","OK",IF(G35="Em correção","NOK",G35)) -> Em Implementação | O35: NOK | P35: 6
A36: GRSS_CMMSSN_INCM_OFF_BLNC | B36: =VLOOKUP(A36,'Por campo'!B:U,2,FALSE) -> 1858258 | C36: =VLOOKUP(A36,'Por campo'!B:U,6,FALSE) -> 2 | D36: =VLOOKUP(A36,'Por campo'!B:U,8,FALSE) -> 454 | E36: =VLOOKUP(A36,'Por campo'!B:U,10,FALSE) -> 158483 | F36: =VLOOKUP($A36,'Por campo'!B:U,12,FALSE) -> 3665 | G36: =VLOOKUP($A36,'Por campo'!B:U,14,FALSE) -> Em Correção | H36: =VLOOKUP($A36,'Por campo'!B:U,17,FALSE) -> Alterado 22/12/2023 | I36: =IF(OR(G36="Concluído",G36="Em teste"),"Disponibilizado para teste",IF(G36="Em correção","Disponibilizado para teste",IF(G36="Em especificação","Em especificação",IF(G36="Em implementação","Em implementação",IF(G36="Em análise de requisitos","Em análise de requisitos","NA"))))) -> Disponibilizado para teste | J36: =IF(G36="Concluído","OK",IF(G36="Em correção","NOK",G36)) -> NOK | O36: OK | P36: 19
A37: GRSS_CMMSSN_INCM_OFF_BLNC_CCRR | B37: =VLOOKUP(A37,'Por campo'!B:U,2,FALSE) -> 0 | C37: =VLOOKUP(A37,'Por campo'!B:U,6,FALSE) -> 2017197 | D37: =VLOOKUP(A37,'Por campo'!B:U,8,FALSE) -> 0 | E37: =VLOOKUP(A37,'Por campo'!B:U,10,FALSE) -> 0 | F37: =VLOOKUP($A37,'Por campo'!B:U,12,FALSE) -> 3665 | G37: =VLOOKUP($A37,'Por campo'!B:U,14,FALSE) -> Em Implementação | H37: =VLOOKUP($A37,'Por campo'!B:U,17,FALSE) -> Alterado 22/12/2023 | I37: =IF(OR(G37="Concluído",G37="Em teste"),"Disponibilizado para teste",IF(G37="Em correção","Disponibilizado para teste",IF(G37="Em especificação","Em especificação",IF(G37="Em implementação","Em implementação",IF(G37="Em análise de requisitos","Em análise de requisitos","NA"))))) -> Em implementação | J37: =IF(G37="Concluído","OK",IF(G37="Em correção","NOK",G37)) -> Em Implementação | O37: Grand Total | P37: 35
A38: GRSS_INTRST_EXPNS | B38: =VLOOKUP(A38,'Por campo'!B:U,2,FALSE) -> 1816745 | C38: =VLOOKUP(A38,'Por campo'!B:U,6,FALSE) -> 0 | D38: =VLOOKUP(A38,'Por campo'!B:U,8,FALSE) -> 446 | E38: =VLOOKUP(A38,'Por campo'!B:U,10,FALSE) -> 200006 | F38: =VLOOKUP($A38,'Por campo'!B:U,12,FALSE) -> 3665 | G38: =VLOOKUP($A38,'Por campo'!B:U,14,FALSE) -> Em teste | H38: =VLOOKUP($A38,'Por campo'!B:U,17,FALSE) -> Sem alterações | I38: =IF(OR(G38="Concluído",G38="Em teste"),"Disponibilizado para teste",IF(G38="Em correção","Disponibilizado para teste",IF(G38="Em especificação","Em especificação",IF(G38="Em implementação","Em implementação",IF(G38="Em análise de requisitos","Em análise de requisitos","NA"))))) -> Disponibilizado para teste | J38: =IF(G38="Concluído","OK",IF(G38="Em correção","NOK",G38)) -> Em teste
A39: GRSS_INTRST_EXPNS_CCRR | B39: =VLOOKUP(A39,'Por campo'!B:U,2,FALSE) -> 0 | C39: =VLOOKUP(A39,'Por campo'!B:U,6,FALSE) -> 2017197 | D39: =VLOOKUP(A39,'Por campo'!B:U,8,FALSE) -> 0 | E39: =VLOOKUP(A39,'Por campo'!B:U,10,FALSE) -> 0 | F39: =VLOOKUP($A39,'Por campo'!B:U,12,FALSE) -> 3665 | G39: =VLOOKUP($A39,'Por campo'!B:U,14,FALSE) -> Em Implementação | H39: =VLOOKUP($A39,'Por campo'!B:U,17,FALSE) -> Sem alterações | I39: =IF(OR(G39="Concluído",G39="Em teste"),"Disponibilizado para teste",IF(G39="Em correção","Disponibilizado para teste",IF(G39="Em especificação","Em especificação",IF(G39="Em implementação","Em implementação",IF(G39="Em análise de requisitos","Em análise de requisitos","NA"))))) -> Em implementação | J39: =IF(G39="Concluído","OK",IF(G39="Em correção","NOK",G39)) -> Em Implementação | O39: Alterações Corp | P39: (Multiple Items)
A40: GRSS_INTRST_INCM | B40: =VLOOKUP(A40,'Por campo'!B:U,2,FALSE) -> 1815954 | C40: =VLOOKUP(A40,'Por campo'!B:U,6,FALSE) -> 0 | D40: =VLOOKUP(A40,'Por campo'!B:U,8,FALSE) -> 446 | E40: =VLOOKUP(A40,'Por campo'!B:U,10,FALSE) -> 201588 | F40: =VLOOKUP($A40,'Por campo'!B:U,12,FALSE) -> 3665 | G40: =VLOOKUP($A40,'Por campo'!B:U,14,FALSE) -> Em teste | H40: =VLOOKUP($A40,'Por campo'!B:U,17,FALSE) -> Sem alterações | I40: =IF(OR(G40="Concluído",G40="Em teste"),"Disponibilizado para teste",IF(G40="Em correção","Disponibilizado para teste",IF(G40="Em especificação","Em especificação",IF(G40="Em implementação","Em implementação",IF(G40="Em análise de requisitos","Em análise de requisitos","NA"))))) -> Disponibilizado para teste | J40: =IF(G40="Concluído","OK",IF(G40="Em correção","NOK",G40)) -> Em teste
...
