Workbook

Sheet Instruções
C3: =TODAY() -> 45954
B7: 1. Instruções
B9: 1. Alterar apenas o que está assinalado a amarelo.
B10: Nota: No campo ref_date, colocar plica no início da data, de modo a manter o formato texto.
C12: Info | F12: Table_name | G12: Table as-is | H12: Table to-be | I12: Chave1 | J12: Chave2
C13: schema as-is (prod.) | D13: cd_loan_tapes_bce | F13: ENTTY | G13: lt003_entity | H13: lt003_entity | I13: entty_id
C14: schema to-be (testes) | D14: bu_loantape_work | F14: INSTR_ENTTY | G14: lt005_instr_ent | H14: lt005_instr_ent | I14: instrmnt_id | J14: entty_id
C15: ref_date | D15: 2024-09-30 | F15: INSTR_PRTCTN | G15: lt006_instr_prot | H15: lt006_instr_prot | I15: instrmnt_id | J15: prtctn_id
C16: nome_perimetro | D16: Individual Corporativo | F16: INSTRMNT | G16: lt002_instrument | H16: lt002_instrument | I16: instrmnt_id
C17: segmento | D17: ESTR | F17: PRTCTN | G17: lt004_protection | H17: lt004_protection | I17: prtctn_id
C18: ambito_1 | D18: PM
C19: ambito_2 | D19: PM | F19: Tipologia testes
C20: filtro_f_1 | D20: ="ref_date='"&$D$15&"' AND nome_perimetro='"&$D$16&"' AND segmento='"&$D$17&"' AND ambito='"&$D$18&"' AND entidade='00100' " -> ref_date='2024-09-30' AND nome_perimetro='Individual Corporativo' AND segmento='ESTR' AND ambito='PM' AND entidade='00100' | F20: Validação campos
C21: filtro_f_2 | D21: ="ref_date='"&$D$15&"' AND nome_perimetro='"&$D$16&"' AND segmento='"&$D$17&"' AND ambito='"&$D$18&"' AND entidade='00100' " -> ref_date='2024-09-30' AND nome_perimetro='Individual Corporativo' AND segmento='ESTR' AND ambito='PM' AND entidade='00100' | F21: Validação universo
B23: 2. Executar, no HUE, as linhas da coluna Union all por blocos > correr cada bloco de 30 em 30.

Sheet Testes regressivos
C3: =TODAY() -> 45954
F7: as_is | G7: to_be
B8: Table_name | C8: Table as-is | D8: Table to-be | E8: Column_name | F8: Column_name_1 | G8: Column_name_2 | H8: Universo_1 | I8: Universo_2 | J8: Metodologia de cruzamento | K8: Condição | L8: Query 1 | M8: Tipologia testes | N8: Query 2 | O8: Union all | P8: Contagem
B9: ENTTY | C9: =_xlfn.CONCAT(Instruções!$D$13,".",VLOOKUP(B9,Instruções!$F$12:$H$17,2,0)) -> cd_loan_tapes_bce.lt003_entity | D9: =_xlfn.CONCAT(Instruções!$D$14,".",VLOOKUP(B9,Instruções!$F$12:$H$17,3,0)) -> bu_loantape_work.lt003_entity | E9: accntng_frmwrk_sl | F9: =E9&"_"&$F$7 -> accntng_frmwrk_sl_as_is | G9: =E9&"_"&$G$7 -> accntng_frmwrk_sl_to_be | H9: =IF(VLOOKUP(B9,Instruções!$F$13:$J$17,5,0)="", "(SELECT "&VLOOKUP(B9,Instruções!$F$13:$J$17,4,0)&" as "&VLOOKUP(B9,Instruções!$F$13:$J$17,4,0)&"_"&$F$2&", "&E9&" as "&F9&" FROM "&C9&" WHERE "&Instruções!$D$20&") A ", "(SELECT "&VLOOKUP(B9,Instruções!$F$13:$J$17,4,0)&" as "&VLOOKUP(B9,Instruções!$F$13:$J$17,4,0)&"_"&$F$2&", "&VLOOKUP(B9,Instruções!$F$13:$J$17,5,0)&" as "&VLOOKUP(B9,Instruções!$F$13:$J$17,5,0)&"_"&$F$2&","&E9&" as "&F9&" FROM "&C9&" WHERE "&Instruções!$D$20&") A ") -> (SELECT entty_id as entty_id_, accntng_frmwrk_sl as accntng_frmwrk_sl_as_is FROM cd_loan_tapes_bce.lt003_entity WHERE ref_date='2024-09-30' AND nome_perimetro='Individual Corporativo' AND segmento='ESTR' AND ambito='PM' AND entidade='00100' ) A | I9: =IF(VLOOKUP(B9,Instruções!$F$13:$J$17,5,0)="", "(SELECT "&VLOOKUP(B9,Instruções!$F$13:$J$17,4,0)&" as "&VLOOKUP(B9,Instruções!$F$13:$J$17,4,0)&"_"&$G$2&", "&E9&" as "&G9&" FROM "&D9&" WHERE "&Instruções!$D$21&") B ", "(SELECT "&VLOOKUP(B9,Instruções!$F$13:$J$17,4,0)&" as "&VLOOKUP(B9,Instruções!$F$13:$J$17,4,0)&"_"&$G$2&", "&VLOOKUP(B9,Instruções!$F$13:$J$17,5,0)&" as "&VLOOKUP(B9,Instruções!$F$13:$J$17,5,0)&"_"&$G$2&","&E9&" as "&G9&" FROM "&D9&" WHERE "&Instruções!$D$21&") B ") -> (SELECT entty_id as entty_id_, accntng_frmwrk_sl as accntng_frmwrk_sl_to_be FROM bu_loantape_work.lt003_entity WHERE ref_date='2024-09-30' AND nome_perimetro='Individual Corporativo' AND segmento='ESTR' AND ambito='PM' AND entidade='00100' ) B | J9: =+IF(VLOOKUP(B9,Instruções!$F$13:$J$17,5,0)="", "ON "&VLOOKUP(B9,Instruções!$F$13:$J$17,4,0)&"_"&$F$7&"="&VLOOKUP(B9,Instruções!$F$13:$J$17,4,0)&"_"&$G$7&" ", "ON "&VLOOKUP(B9,Instruções!$F$13:$J$17,4,0)&"_"&$F$7&"="&VLOOKUP(B9,Instruções!$F$13:$J$17,4,0)&"_"&$G$7&" AND "&VLOOKUP(B9,Instruções!$F$13:$J$17,5,0)&"_"&$F$7&"="&VLOOKUP(B9,Instruções!$F$13:$J$17,5,0)&"_"&$G$7&" ") -> ON entty_id_as_is=entty_id_to_be | K9: ="WHERE coalesce(cast("&F9&" AS string),'')<>coalesce(cast("&G9&" AS string),'') " -> WHERE coalesce(cast(accntng_frmwrk_sl_as_is AS string),'')<>coalesce(cast(accntng_frmwrk_sl_to_be AS string),'') | L9: ="SELECT count(*) AS NUM_REG_DIF FROM "&H9&" Inner join "&I9&J9&K9 -> SELECT count(*) AS NUM_REG_DIF FROM (SELECT entty_id as entty_id_, accntng_frmwrk_sl as accntng_frmwrk_sl_as_is FROM cd_loan_tapes_bce.lt003_entity WHERE ref_date='2024-09-30' AND nome_perimetro='Individual Corporativo' AND segmento='ESTR' AND ambito='PM' AND entidade='00100' ) A Inner join (SELECT entty_id as entty_id_, accntng_frmwrk_sl as accntng_frmwrk_sl_to_be FROM bu_loantape_work.lt003_entity WHERE ref_date='2024-09-30' AND nome_perimetro='Individual Corporativo' AND segmento='ESTR' AND ambito='PM' AND entidade='00100' ) B ON entty_id_as_is=entty_id_to_be WHERE coalesce(cast(accntng_frmwrk_sl_as_is AS string),'')<>coalesce(cast(accntng_frmwrk_sl_to_be AS string),'') | M9: Validação de campos | N9: ="SELECT 'Validação de campos' as tipologia_teste, '"&VLOOKUP(B9,Instruções!$F$13:$J$17,3,0)&"' AS TABELA, '"&E9&"' AS CAMPO, '"&Instruções!$D$15&"' as ref_date, coalesce(NUM_REG_DIF, 0) AS NUM_REG_DIF FROM ("&L9&") A " -> SELECT 'Validação de campos' as tipologia_teste, 'lt003_entity' AS TABELA, 'accntng_frmwrk_sl' AS CAMPO, '2024-09-30' as ref_date, coalesce(NUM_REG_DIF, 0) AS NUM_REG_DIF FROM (SELECT count(*) AS NUM_REG_DIF FROM (SELECT entty_id as entty_id_, accntng_frmwrk_sl as accntng_frmwrk_sl_as_is FROM cd_loan_tapes_bce.lt003_entity WHERE ref_date='2024-09-30' AND nome_perimetro='Individual Corporativo' AND segmento='ESTR' AND ambito='PM' AND entidade='00100' ) A Inner join (SELECT entty_id as entty_id_, accntng_frmwrk_sl as accntng_frmwrk_sl_to_be FROM bu_loantape_work.lt003_entity WHERE ref_date='2024-09-30' AND nome_perimetro='Individual Corporativo' AND segmento='ESTR' AND ambito='PM' AND entidade='00100' ) B ON entty_id_as_is=entty_id_to_be WHERE coalesce(cast(accntng_frmwrk_sl_as_is AS string),'')<>coalesce(cast(accntng_frmwrk_sl_to_be AS string),'') ) A | O9: =IF(O10="",N9,N9&$O$8) -> SELECT 'Validação de campos' as tipologia_teste, 'lt003_entity' AS TABELA, 'accntng_frmwrk_sl' AS CAMPO, '2024-09-30' as ref_date, coalesce(NUM_REG_DIF, 0) AS NUM_REG_DIF FROM (SELECT count(*) AS NUM_REG_DIF FROM (SELECT entty_id as entty_id_, accntng_frmwrk_sl as accntng_frmwrk_sl_as_is FROM cd_loan_tapes_bce.lt003_entity WHERE ref_date='2024-09-30' AND nome_perimetro='Individual Corporativo' AND segmento='ESTR' AND ambito='PM' AND entidade='00100' ) A Inner join (SELECT entty_id as entty_id_, accntng_frmwrk_sl as accntng_frmwrk_sl_to_be FROM bu_loantape_work.lt003_entity WHERE ref_date='2024-09-30' AND nome_perimetro='Individual Corporativo' AND segmento='ESTR' AND ambito='PM' AND entidade='00100' ) B ON entty_id_as_is=entty_id_to_be WHERE coalesce(cast(accntng_frmwrk_sl_as_is AS string),'')<>coalesce(cast(accntng_frmwrk_sl_to_be AS string),'') ) A Union all | P9: 1
B10: ENTTY | C10: =_xlfn.CONCAT(Instruções!$D$13,".",VLOOKUP(B10,Instruções!$F$12:$H$17,2,0)) -> cd_loan_tapes_bce.lt003_entity | D10: =_xlfn.CONCAT(Instruções!$D$14,".",VLOOKUP(B10,Instruções!$F$12:$H$17,3,0)) -> bu_loantape_work.lt003_entity | E10: annl_trnvr_le | F10: =E10&"_"&$F$7 -> annl_trnvr_le_as_is | G10: =E10&"_"&$G$7 -> annl_trnvr_le_to_be | H10: =IF(VLOOKUP(B10,Instruções!$F$13:$J$17,5,0)="", "(SELECT "&VLOOKUP(B10,Instruções!$F$13:$J$17,4,0)&" as "&VLOOKUP(B10,Instruções!$F$13:$J$17,4,0)&"_"&$F$2&", "&E10&" as "&F10&" FROM "&C10&" WHERE "&Instruções!$D$20&") A ", "(SELECT "&VLOOKUP(B10,Instruções!$F$13:$J$17,4,0)&" as "&VLOOKUP(B10,Instruções!$F$13:$J$17,4,0)&"_"&$F$2&", "&VLOOKUP(B10,Instruções!$F$13:$J$17,5,0)&" as "&VLOOKUP(B10,Instruções!$F$13:$J$17,5,0)&"_"&$F$2&","&E10&" as "&F10&" FROM "&C10&" WHERE "&Instruções!$D$20&") A ") -> (SELECT entty_id as entty_id_, annl_trnvr_le as annl_trnvr_le_as_is FROM cd_loan_tapes_bce.lt003_entity WHERE ref_date='2024-09-30' AND nome_perimetro='Individual Corporativo' AND segmento='ESTR' AND ambito='PM' AND entidade='00100' ) A | I10: =IF(VLOOKUP(B10,Instruções!$F$13:$J$17,5,0)="", "(SELECT "&VLOOKUP(B10,Instruções!$F$13:$J$17,4,0)&" as "&VLOOKUP(B10,Instruções!$F$13:$J$17,4,0)&"_"&$G$2&", "&E10&" as "&G10&" FROM "&D10&" WHERE "&Instruções!$D$21&") B ", "(SELECT "&VLOOKUP(B10,Instruções!$F$13:$J$17,4,0)&" as "&VLOOKUP(B10,Instruções!$F$13:$J$17,4,0)&"_"&$G$2&", "&VLOOKUP(B10,Instruções!$F$13:$J$17,5,0)&" as "&VLOOKUP(B10,Instruções!$F$13:$J$17,5,0)&"_"&$G$2&","&E10&" as "&G10&" FROM "&D10&" WHERE "&Instruções!$D$21&") B ") -> (SELECT entty_id as entty_id_, annl_trnvr_le as annl_trnvr_le_to_be FROM bu_loantape_work.lt003_entity WHERE ref_date='2024-09-30' AND nome_perimetro='Individual Corporativo' AND segmento='ESTR' AND ambito='PM' AND entidade='00100' ) B | J10: =+IF(VLOOKUP(B10,Instruções!$F$13:$J$17,5,0)="", "ON "&VLOOKUP(B10,Instruções!$F$13:$J$17,4,0)&"_"&$F$7&"="&VLOOKUP(B10,Instruções!$F$13:$J$17,4,0)&"_"&$G$7&" ", "ON "&VLOOKUP(B10,Instruções!$F$13:$J$17,4,0)&"_"&$F$7&"="&VLOOKUP(B10,Instruções!$F$13:$J$17,4,0)&"_"&$G$7&" AND "&VLOOKUP(B10,Instruções!$F$13:$J$17,5,0)&"_"&$F$7&"="&VLOOKUP(B10,Instruções!$F$13:$J$17,5,0)&"_"&$G$7&" ") -> ON entty_id_as_is=entty_id_to_be | K10: ="WHERE coalesce(cast("&F10&" AS string),'')<>coalesce(cast("&G10&" AS string),'') " -> WHERE coalesce(cast(annl_trnvr_le_as_is AS string),'')<>coalesce(cast(annl_trnvr_le_to_be AS string),'') | L10: ="SELECT count(*) AS NUM_REG_DIF FROM "&H10&" Inner join "&I10&J10&K10 -> SELECT count(*) AS NUM_REG_DIF FROM (SELECT entty_id as entty_id_, annl_trnvr_le as annl_trnvr_le_as_is FROM cd_loan_tapes_bce.lt003_entity WHERE ref_date='2024-09-30' AND nome_perimetro='Individual Corporativo' AND segmento='ESTR' AND ambito='PM' AND entidade='00100' ) A Inner join (SELECT entty_id as entty_id_, annl_trnvr_le as annl_trnvr_le_to_be FROM bu_loantape_work.lt003_entity WHERE ref_date='2024-09-30' AND nome_perimetro='Individual Corporativo' AND segmento='ESTR' AND ambito='PM' AND entidade='00100' ) B ON entty_id_as_is=entty_id_to_be WHERE coalesce(cast(annl_trnvr_le_as_is AS string),'')<>coalesce(cast(annl_trnvr_le_to_be AS string),'') | M10: Validação de campos | N10: ="SELECT 'Validação de campos' as tipologia_teste, '"&VLOOKUP(B10,Instruções!$F$13:$J$17,3,0)&"' AS TABELA, '"&E10&"' AS CAMPO, '"&Instruções!$D$15&"' as ref_date, coalesce(NUM_REG_DIF, 0) AS NUM_REG_DIF FROM ("&L10&") A " -> SELECT 'Validação de campos' as tipologia_teste, 'lt003_entity' AS TABELA, 'annl_trnvr_le' AS CAMPO, '2024-09-30' as ref_date, coalesce(NUM_REG_DIF, 0) AS NUM_REG_DIF FROM (SELECT count(*) AS NUM_REG_DIF FROM (SELECT entty_id as entty_id_, annl_trnvr_le as annl_trnvr_le_as_is FROM cd_loan_tapes_bce.lt003_entity WHERE ref_date='2024-09-30' AND nome_perimetro='Individual Corporativo' AND segmento='ESTR' AND ambito='PM' AND entidade='00100' ) A Inner join (SELECT entty_id as entty_id_, annl_trnvr_le as annl_trnvr_le_to_be FROM bu_loantape_work.lt003_entity WHERE ref_date='2024-09-30' AND nome_perimetro='Individual Corporativo' AND segmento='ESTR' AND ambito='PM' AND entidade='00100' ) B ON entty_id_as_is=entty_id_to_be WHERE coalesce(cast(annl_trnvr_le_as_is AS string),'')<>coalesce(cast(annl_trnvr_le_to_be AS string),'') ) A | O10: =IF(O11="",N10,N10&$O$8) -> SELECT 'Validação de campos' as tipologia_teste, 'lt003_entity' AS TABELA, 'annl_trnvr_le' AS CAMPO, '2024-09-30' as ref_date, coalesce(NUM_REG_DIF, 0) AS NUM_REG_DIF FROM (SELECT count(*) AS NUM_REG_DIF FROM (SELECT entty_id as entty_id_, annl_trnvr_le as annl_trnvr_le_as_is FROM cd_loan_tapes_bce.lt003_entity WHERE ref_date='2024-09-30' AND nome_perimetro='Individual Corporativo' AND segmento='ESTR' AND ambito='PM' AND entidade='00100' ) A Inner join (SELECT entty_id as entty_id_, annl_trnvr_le as annl_trnvr_le_to_be FROM bu_loantape_work.lt003_entity WHERE ref_date='2024-09-30' AND nome_perimetro='Individual Corporativo' AND segmento='ESTR' AND ambito='PM' AND entidade='00100' ) B ON entty_id_as_is=entty_id_to_be WHERE coalesce(cast(annl_trnvr_le_as_is AS string),'')<>coalesce(cast(annl_trnvr_le_to_be AS string),'') ) A Union all | P10: =+P9+1 -> 2
B11: ENTTY | C11: =_xlfn.CONCAT(Instruções!$D$13,".",VLOOKUP(B11,Instruções!$F$12:$H$17,2,0)) -> cd_loan_tapes_bce.lt003_entity | D11: =_xlfn.CONCAT(Instruções!$D$14,".",VLOOKUP(B11,Instruções!$F$12:$H$17,3,0)) -> bu_loantape_work.lt003_entity | E11: annl_trnvr_le_bdr | F11: =E11&"_"&$F$7 -> annl_trnvr_le_bdr_as_is | G11: =E11&"_"&$G$7 -> annl_trnvr_le_bdr_to_be | H11: =IF(VLOOKUP(B11,Instruções!$F$13:$J$17,5,0)="", "(SELECT "&VLOOKUP(B11,Instruções!$F$13:$J$17,4,0)&" as "&VLOOKUP(B11,Instruções!$F$13:$J$17,4,0)&"_"&$F$2&", "&E11&" as "&F11&" FROM "&C11&" WHERE "&Instruções!$D$20&") A ", "(SELECT "&VLOOKUP(B11,Instruções!$F$13:$J$17,4,0)&" as "&VLOOKUP(B11,Instruções!$F$13:$J$17,4,0)&"_"&$F$2&", "&VLOOKUP(B11,Instruções!$F$13:$J$17,5,0)&" as "&VLOOKUP(B11,Instruções!$F$13:$J$17,5,0)&"_"&$F$2&","&E11&" as "&F11&" FROM "&C11&" WHERE "&Instruções!$D$20&") A ") -> (SELECT entty_id as entty_id_, annl_trnvr_le_bdr as annl_trnvr_le_bdr_as_is FROM cd_loan_tapes_bce.lt003_entity WHERE ref_date='2024-09-30' AND nome_perimetro='Individual Corporativo' AND segmento='ESTR' AND ambito='PM' AND entidade='00100' ) A | I11: =IF(VLOOKUP(B11,Instruções!$F$13:$J$17,5,0)="", "(SELECT "&VLOOKUP(B11,Instruções!$F$13:$J$17,4,0)&" as "&VLOOKUP(B11,Instruções!$F$13:$J$17,4,0)&"_"&$G$2&", "&E11&" as "&G11&" FROM "&D11&" WHERE "&Instruções!$D$21&") B ", "(SELECT "&VLOOKUP(B11,Instruções!$F$13:$J$17,4,0)&" as "&VLOOKUP(B11,Instruções!$F$13:$J$17,4,0)&"_"&$G$2&", "&VLOOKUP(B11,Instruções!$F$13:$J$17,5,0)&" as "&VLOOKUP(B11,Instruções!$F$13:$J$17,5,0)&"_"&$G$2&","&E11&" as "&G11&" FROM "&D11&" WHERE "&Instruções!$D$21&") B ") -> (SELECT entty_id as entty_id_, annl_trnvr_le_bdr as annl_trnvr_le_bdr_to_be FROM bu_loantape_work.lt003_entity WHERE ref_date='2024-09-30' AND nome_perimetro='Individual Corporativo' AND segmento='ESTR' AND ambito='PM' AND entidade='00100' ) B | J11: =+IF(VLOOKUP(B11,Instruções!$F$13:$J$17,5,0)="", "ON "&VLOOKUP(B11,Instruções!$F$13:$J$17,4,0)&"_"&$F$7&"="&VLOOKUP(B11,Instruções!$F$13:$J$17,4,0)&"_"&$G$7&" ", "ON "&VLOOKUP(B11,Instruções!$F$13:$J$17,4,0)&"_"&$F$7&"="&VLOOKUP(B11,Instruções!$F$13:$J$17,4,0)&"_"&$G$7&" AND "&VLOOKUP(B11,Instruções!$F$13:$J$17,5,0)&"_"&$F$7&"="&VLOOKUP(B11,Instruções!$F$13:$J$17,5,0)&"_"&$G$7&" ") -> ON entty_id_as_is=entty_id_to_be | K11: ="WHERE coalesce(cast("&F11&" AS string),'')<>coalesce(cast("&G11&" AS string),'') " -> WHERE coalesce(cast(annl_trnvr_le_bdr_as_is AS string),'')<>coalesce(cast(annl_trnvr_le_bdr_to_be AS string),'') | L11: ="SELECT count(*) AS NUM_REG_DIF FROM "&H11&" Inner join "&I11&J11&K11 -> SELECT count(*) AS NUM_REG_DIF FROM (SELECT entty_id as entty_id_, annl_trnvr_le_bdr as annl_trnvr_le_bdr_as_is FROM cd_loan_tapes_bce.lt003_entity WHERE ref_date='2024-09-30' AND nome_perimetro='Individual Corporativo' AND segmento='ESTR' AND ambito='PM' AND entidade='00100' ) A Inner join (SELECT entty_id as entty_id_, annl_trnvr_le_bdr as annl_trnvr_le_bdr_to_be FROM bu_loantape_work.lt003_entity WHERE ref_date='2024-09-30' AND nome_perimetro='Individual Corporativo' AND segmento='ESTR' AND ambito='PM' AND entidade='00100' ) B ON entty_id_as_is=entty_id_to_be WHERE coalesce(cast(annl_trnvr_le_bdr_as_is AS string),'')<>coalesce(cast(annl_trnvr_le_bdr_to_be AS string),'') | M11: Validação de campos | N11: ="SELECT 'Validação de campos' as tipologia_teste, '"&VLOOKUP(B11,Instruções!$F$13:$J$17,3,0)&"' AS TABELA, '"&E11&"' AS CAMPO, '"&Instruções!$D$15&"' as ref_date, coalesce(NUM_REG_DIF, 0) AS NUM_REG_DIF FROM ("&L11&") A " -> SELECT 'Validação de campos' as tipologia_teste, 'lt003_entity' AS TABELA, 'annl_trnvr_le_bdr' AS CAMPO, '2024-09-30' as ref_date, coalesce(NUM_REG_DIF, 0) AS NUM_REG_DIF FROM (SELECT count(*) AS NUM_REG_DIF FROM (SELECT entty_id as entty_id_, annl_trnvr_le_bdr as annl_trnvr_le_bdr_as_is FROM cd_loan_tapes_bce.lt003_entity WHERE ref_date='2024-09-30' AND nome_perimetro='Individual Corporativo' AND segmento='ESTR' AND ambito='PM' AND entidade='00100' ) A Inner join (SELECT entty_id as entty_id_, annl_trnvr_le_bdr as annl_trnvr_le_bdr_to_be FROM bu_loantape_work.lt003_entity WHERE ref_date='2024-09-30' AND nome_perimetro='Individual Corporativo' AND segmento='ESTR' AND ambito='PM' AND entidade='00100' ) B ON entty_id_as_is=entty_id_to_be WHERE coalesce(cast(annl_trnvr_le_bdr_as_is AS string),'')<>coalesce(cast(annl_trnvr_le_bdr_to_be AS string),'') ) A | O11: =IF(O12="",N11,N11&$O$8) -> SELECT 'Validação de campos' as tipologia_teste, 'lt003_entity' AS TABELA, 'annl_trnvr_le_bdr' AS CAMPO, '2024-09-30' as ref_date, coalesce(NUM_REG_DIF, 0) AS NUM_REG_DIF FROM (SELECT count(*) AS NUM_REG_DIF FROM (SELECT entty_id as entty_id_, annl_trnvr_le_bdr as annl_trnvr_le_bdr_as_is FROM cd_loan_tapes_bce.lt003_entity WHERE ref_date='2024-09-30' AND nome_perimetro='Individual Corporativo' AND segmento='ESTR' AND ambito='PM' AND entidade='00100' ) A Inner join (SELECT entty_id as entty_id_, annl_trnvr_le_bdr as annl_trnvr_le_bdr_to_be FROM bu_loantape_work.lt003_entity WHERE ref_date='2024-09-30' AND nome_perimetro='Individual Corporativo' AND segmento='ESTR' AND ambito='PM' AND entidade='00100' ) B ON entty_id_as_is=entty_id_to_be WHERE coalesce(cast(annl_trnvr_le_bdr_as_is AS string),'')<>coalesce(cast(annl_trnvr_le_bdr_to_be AS string),'') ) A Union all | P11: =+P10+1 -> 3
B12: ENTTY | C12: =_xlfn.CONCAT(Instruções!$D$13,".",VLOOKUP(B12,Instruções!$F$12:$H$17,2,0)) -> cd_loan_tapes_bce.lt003_entity | D12: =_xlfn.CONCAT(Instruções!$D$14,".",VLOOKUP(B12,Instruções!$F$12:$H$17,3,0)) -> bu_loantape_work.lt003_entity | E12: annl_trnvr_prvs | F12: =E12&"_"&$F$7 -> annl_trnvr_prvs_as_is | G12: =E12&"_"&$G$7 -> annl_trnvr_prvs_to_be | H12: =IF(VLOOKUP(B12,Instruções!$F$13:$J$17,5,0)="", "(SELECT "&VLOOKUP(B12,Instruções!$F$13:$J$17,4,0)&" as "&VLOOKUP(B12,Instruções!$F$13:$J$17,4,0)&"_"&$F$2&", "&E12&" as "&F12&" FROM "&C12&" WHERE "&Instruções!$D$20&") A ", "(SELECT "&VLOOKUP(B12,Instruções!$F$13:$J$17,4,0)&" as "&VLOOKUP(B12,Instruções!$F$13:$J$17,4,0)&"_"&$F$2&", "&VLOOKUP(B12,Instruções!$F$13:$J$17,5,0)&" as "&VLOOKUP(B12,Instruções!$F$13:$J$17,5,0)&"_"&$F$2&","&E12&" as "&F12&" FROM "&C12&" WHERE "&Instruções!$D$20&") A ") -> (SELECT entty_id as entty_id_, annl_trnvr_prvs as annl_trnvr_prvs_as_is FROM cd_loan_tapes_bce.lt003_entity WHERE ref_date='2024-09-30' AND nome_perimetro='Individual Corporativo' AND segmento='ESTR' AND ambito='PM' AND entidade='00100' ) A | I12: =IF(VLOOKUP(B12,Instruções!$F$13:$J$17,5,0)="", "(SELECT "&VLOOKUP(B12,Instruções!$F$13:$J$17,4,0)&" as "&VLOOKUP(B12,Instruções!$F$13:$J$17,4,0)&"_"&$G$2&", "&E12&" as "&G12&" FROM "&D12&" WHERE "&Instruções!$D$21&") B ", "(SELECT "&VLOOKUP(B12,Instruções!$F$13:$J$17,4,0)&" as "&VLOOKUP(B12,Instruções!$F$13:$J$17,4,0)&"_"&$G$2&", "&VLOOKUP(B12,Instruções!$F$13:$J$17,5,0)&" as "&VLOOKUP(B12,Instruções!$F$13:$J$17,5,0)&"_"&$G$2&","&E12&" as "&G12&" FROM "&D12&" WHERE "&Instruções!$D$21&") B ") -> (SELECT entty_id as entty_id_, annl_trnvr_prvs as annl_trnvr_prvs_to_be FROM bu_loantape_work.lt003_entity WHERE ref_date='2024-09-30' AND nome_perimetro='Individual Corporativo' AND segmento='ESTR' AND ambito='PM' AND entidade='00100' ) B | J12: =+IF(VLOOKUP(B12,Instruções!$F$13:$J$17,5,0)="", "ON "&VLOOKUP(B12,Instruções!$F$13:$J$17,4,0)&"_"&$F$7&"="&VLOOKUP(B12,Instruções!$F$13:$J$17,4,0)&"_"&$G$7&" ", "ON "&VLOOKUP(B12,Instruções!$F$13:$J$17,4,0)&"_"&$F$7&"="&VLOOKUP(B12,Instruções!$F$13:$J$17,4,0)&"_"&$G$7&" AND "&VLOOKUP(B12,Instruções!$F$13:$J$17,5,0)&"_"&$F$7&"="&VLOOKUP(B12,Instruções!$F$13:$J$17,5,0)&"_"&$G$7&" ") -> ON entty_id_as_is=entty_id_to_be | K12: ="WHERE coalesce(cast("&F12&" AS string),'')<>coalesce(cast("&G12&" AS string),'') " -> WHERE coalesce(cast(annl_trnvr_prvs_as_is AS string),'')<>coalesce(cast(annl_trnvr_prvs_to_be AS string),'') | L12: ="SELECT count(*) AS NUM_REG_DIF FROM "&H12&" Inner join "&I12&J12&K12 -> SELECT count(*) AS NUM_REG_DIF FROM (SELECT entty_id as entty_id_, annl_trnvr_prvs as annl_trnvr_prvs_as_is FROM cd_loan_tapes_bce.lt003_entity WHERE ref_date='2024-09-30' AND nome_perimetro='Individual Corporativo' AND segmento='ESTR' AND ambito='PM' AND entidade='00100' ) A Inner join (SELECT entty_id as entty_id_, annl_trnvr_prvs as annl_trnvr_prvs_to_be FROM bu_loantape_work.lt003_entity WHERE ref_date='2024-09-30' AND nome_perimetro='Individual Corporativo' AND segmento='ESTR' AND ambito='PM' AND entidade='00100' ) B ON entty_id_as_is=entty_id_to_be WHERE coalesce(cast(annl_trnvr_prvs_as_is AS string),'')<>coalesce(cast(annl_trnvr_prvs_to_be AS string),'') | M12: Validação de campos | N12: ="SELECT 'Validação de campos' as tipologia_teste, '"&VLOOKUP(B12,Instruções!$F$13:$J$17,3,0)&"' AS TABELA, '"&E12&"' AS CAMPO, '"&Instruções!$D$15&"' as ref_date, coalesce(NUM_REG_DIF, 0) AS NUM_REG_DIF FROM ("&L12&") A " -> SELECT 'Validação de campos' as tipologia_teste, 'lt003_entity' AS TABELA, 'annl_trnvr_prvs' AS CAMPO, '2024-09-30' as ref_date, coalesce(NUM_REG_DIF, 0) AS NUM_REG_DIF FROM (SELECT count(*) AS NUM_REG_DIF FROM (SELECT entty_id as entty_id_, annl_trnvr_prvs as annl_trnvr_prvs_as_is FROM cd_loan_tapes_bce.lt003_entity WHERE ref_date='2024-09-30' AND nome_perimetro='Individual Corporativo' AND segmento='ESTR' AND ambito='PM' AND entidade='00100' ) A Inner join (SELECT entty_id as entty_id_, annl_trnvr_prvs as annl_trnvr_prvs_to_be FROM bu_loantape_work.lt003_entity WHERE ref_date='2024-09-30' AND nome_perimetro='Individual Corporativo' AND segmento='ESTR' AND ambito='PM' AND entidade='00100' ) B ON entty_id_as_is=entty_id_to_be WHERE coalesce(cast(annl_trnvr_prvs_as_is AS string),'')<>coalesce(cast(annl_trnvr_prvs_to_be AS string),'') ) A | O12: =IF(O13="",N12,N12&$O$8) -> SELECT 'Validação de campos' as tipologia_teste, 'lt003_entity' AS TABELA, 'annl_trnvr_prvs' AS CAMPO, '2024-09-30' as ref_date, coalesce(NUM_REG_DIF, 0) AS NUM_REG_DIF FROM (SELECT count(*) AS NUM_REG_DIF FROM (SELECT entty_id as entty_id_, annl_trnvr_prvs as annl_trnvr_prvs_as_is FROM cd_loan_tapes_bce.lt003_entity WHERE ref_date='2024-09-30' AND nome_perimetro='Individual Corporativo' AND segmento='ESTR' AND ambito='PM' AND entidade='00100' ) A Inner join (SELECT entty_id as entty_id_, annl_trnvr_prvs as annl_trnvr_prvs_to_be FROM bu_loantape_work.lt003_entity WHERE ref_date='2024-09-30' AND nome_perimetro='Individual Corporativo' AND segmento='ESTR' AND ambito='PM' AND entidade='00100' ) B ON entty_id_as_is=entty_id_to_be WHERE coalesce(cast(annl_trnvr_prvs_as_is AS string),'')<>coalesce(cast(annl_trnvr_prvs_to_be AS string),'') ) A Union all | P12: =+P11+1 -> 4
B13: ENTTY | C13: =_xlfn.CONCAT(Instruções!$D$13,".",VLOOKUP(B13,Instruções!$F$12:$H$17,2,0)) -> cd_loan_tapes_bce.lt003_entity | D13: =_xlfn.CONCAT(Instruções!$D$14,".",VLOOKUP(B13,Instruções!$F$12:$H$17,3,0)) -> bu_loantape_work.lt003_entity | E13: annl_trnvr_prvs_bdr | F13: =E13&"_"&$F$7 -> annl_trnvr_prvs_bdr_as_is | G13: =E13&"_"&$G$7 -> annl_trnvr_prvs_bdr_to_be | H13: =IF(VLOOKUP(B13,Instruções!$F$13:$J$17,5,0)="", "(SELECT "&VLOOKUP(B13,Instruções!$F$13:$J$17,4,0)&" as "&VLOOKUP(B13,Instruções!$F$13:$J$17,4,0)&"_"&$F$2&", "&E13&" as "&F13&" FROM "&C13&" WHERE "&Instruções!$D$20&") A ", "(SELECT "&VLOOKUP(B13,Instruções!$F$13:$J$17,4,0)&" as "&VLOOKUP(B13,Instruções!$F$13:$J$17,4,0)&"_"&$F$2&", "&VLOOKUP(B13,Instruções!$F$13:$J$17,5,0)&" as "&VLOOKUP(B13,Instruções!$F$13:$J$17,5,0)&"_"&$F$2&","&E13&" as "&F13&" FROM "&C13&" WHERE "&Instruções!$D$20&") A ") -> (SELECT entty_id as entty_id_, annl_trnvr_prvs_bdr as annl_trnvr_prvs_bdr_as_is FROM cd_loan_tapes_bce.lt003_entity WHERE ref_date='2024-09-30' AND nome_perimetro='Individual Corporativo' AND segmento='ESTR' AND ambito='PM' AND entidade='00100' ) A | I13: =IF(VLOOKUP(B13,Instruções!$F$13:$J$17,5,0)="", "(SELECT "&VLOOKUP(B13,Instruções!$F$13:$J$17,4,0)&" as "&VLOOKUP(B13,Instruções!$F$13:$J$17,4,0)&"_"&$G$2&", "&E13&" as "&G13&" FROM "&D13&" WHERE "&Instruções!$D$21&") B ", "(SELECT "&VLOOKUP(B13,Instruções!$F$13:$J$17,4,0)&" as "&VLOOKUP(B13,Instruções!$F$13:$J$17,4,0)&"_"&$G$2&", "&VLOOKUP(B13,Instruções!$F$13:$J$17,5,0)&" as "&VLOOKUP(B13,Instruções!$F$13:$J$17,5,0)&"_"&$G$2&","&E13&" as "&G13&" FROM "&D13&" WHERE "&Instruções!$D$21&") B ") -> (SELECT entty_id as entty_id_, annl_trnvr_prvs_bdr as annl_trnvr_prvs_bdr_to_be FROM bu_loantape_work.lt003_entity WHERE ref_date='2024-09-30' AND nome_perimetro='Individual Corporativo' AND segmento='ESTR' AND ambito='PM' AND entidade='00100' ) B | J13: =+IF(VLOOKUP(B13,Instruções!$F$13:$J$17,5,0)="", "ON "&VLOOKUP(B13,Instruções!$F$13:$J$17,4,0)&"_"&$F$7&"="&VLOOKUP(B13,Instruções!$F$13:$J$17,4,0)&"_"&$G$7&" ", "ON "&VLOOKUP(B13,Instruções!$F$13:$J$17,4,0)&"_"&$F$7&"="&VLOOKUP(B13,Instruções!$F$13:$J$17,4,0)&"_"&$G$7&" AND "&VLOOKUP(B13,Instruções!$F$13:$J$17,5,0)&"_"&$F$7&"="&VLOOKUP(B13,Instruções!$F$13:$J$17,5,0)&"_"&$G$7&" ") -> ON entty_id_as_is=entty_id_to_be | K13: ="WHERE coalesce(cast("&F13&" AS string),'')<>coalesce(cast("&G13&" AS string),'') " -> WHERE coalesce(cast(annl_trnvr_prvs_bdr_as_is AS string),'')<>coalesce(cast(annl_trnvr_prvs_bdr_to_be AS string),'') | L13: ="SELECT count(*) AS NUM_REG_DIF FROM "&H13&" Inner join "&I13&J13&K13 -> SELECT count(*) AS NUM_REG_DIF FROM (SELECT entty_id as entty_id_, annl_trnvr_prvs_bdr as annl_trnvr_prvs_bdr_as_is FROM cd_loan_tapes_bce.lt003_entity WHERE ref_date='2024-09-30' AND nome_perimetro='Individual Corporativo' AND segmento='ESTR' AND ambito='PM' AND entidade='00100' ) A Inner join (SELECT entty_id as entty_id_, annl_trnvr_prvs_bdr as annl_trnvr_prvs_bdr_to_be FROM bu_loantape_work.lt003_entity WHERE ref_date='2024-09-30' AND nome_perimetro='Individual Corporativo' AND segmento='ESTR' AND ambito='PM' AND entidade='00100' ) B ON entty_id_as_is=entty_id_to_be WHERE coalesce(cast(annl_trnvr_prvs_bdr_as_is AS string),'')<>coalesce(cast(annl_trnvr_prvs_bdr_to_be AS string),'') | M13: Validação de campos | N13: ="SELECT 'Validação de campos' as tipologia_teste, '"&VLOOKUP(B13,Instruções!$F$13:$J$17,3,0)&"' AS TABELA, '"&E13&"' AS CAMPO, '"&Instruções!$D$15&"' as ref_date, coalesce(NUM_REG_DIF, 0) AS NUM_REG_DIF FROM ("&L13&") A " -> SELECT 'Validação de campos' as tipologia_teste, 'lt003_entity' AS TABELA, 'annl_trnvr_prvs_bdr' AS CAMPO, '2024-09-30' as ref_date, coalesce(NUM_REG_DIF, 0) AS NUM_REG_DIF FROM (SELECT count(*) AS NUM_REG_DIF FROM (SELECT entty_id as entty_id_, annl_trnvr_prvs_bdr as annl_trnvr_prvs_bdr_as_is FROM cd_loan_tapes_bce.lt003_entity WHERE ref_date='2024-09-30' AND nome_perimetro='Individual Corporativo' AND segmento='ESTR' AND ambito='PM' AND entidade='00100' ) A Inner join (SELECT entty_id as entty_id_, annl_trnvr_prvs_bdr as annl_trnvr_prvs_bdr_to_be FROM bu_loantape_work.lt003_entity WHERE ref_date='2024-09-30' AND nome_perimetro='Individual Corporativo' AND segmento='ESTR' AND ambito='PM' AND entidade='00100' ) B ON entty_id_as_is=entty_id_to_be WHERE coalesce(cast(annl_trnvr_prvs_bdr_as_is AS string),'')<>coalesce(cast(annl_trnvr_prvs_bdr_to_be AS string),'') ) A | O13: =IF(O14="",N13,N13&$O$8) -> SELECT 'Validação de campos' as tipologia_teste, 'lt003_entity' AS TABELA, 'annl_trnvr_prvs_bdr' AS CAMPO, '2024-09-30' as ref_date, coalesce(NUM_REG_DIF, 0) AS NUM_REG_DIF FROM (SELECT count(*) AS NUM_REG_DIF FROM (SELECT entty_id as entty_id_, annl_trnvr_prvs_bdr as annl_trnvr_prvs_bdr_as_is FROM cd_loan_tapes_bce.lt003_entity WHERE ref_date='2024-09-30' AND nome_perimetro='Individual Corporativo' AND segmento='ESTR' AND ambito='PM' AND entidade='00100' ) A Inner join (SELECT entty_id as entty_id_, annl_trnvr_prvs_bdr as annl_trnvr_prvs_bdr_to_be FROM bu_loantape_work.lt003_entity WHERE ref_date='2024-09-30' AND nome_perimetro='Individual Corporativo' AND segmento='ESTR' AND ambito='PM' AND entidade='00100' ) B ON entty_id_as_is=entty_id_to_be WHERE coalesce(cast(annl_trnvr_prvs_bdr_as_is AS string),'')<>coalesce(cast(annl_trnvr_prvs_bdr_to_be AS string),'') ) A Union all | P13: =+P12+1 -> 5
B14: ENTTY | C14: =_xlfn.CONCAT(Instruções!$D$13,".",VLOOKUP(B14,Instruções!$F$12:$H$17,2,0)) -> cd_loan_tapes_bce.lt003_entity | D14: =_xlfn.CONCAT(Instruções!$D$14,".",VLOOKUP(B14,Instruções!$F$12:$H$17,3,0)) -> bu_loantape_work.lt003_entity | E14: capex | F14: =E14&"_"&$F$7 -> capex_as_is | G14: =E14&"_"&$G$7 -> capex_to_be | H14: =IF(VLOOKUP(B14,Instruções!$F$13:$J$17,5,0)="", "(SELECT "&VLOOKUP(B14,Instruções!$F$13:$J$17,4,0)&" as "&VLOOKUP(B14,Instruções!$F$13:$J$17,4,0)&"_"&$F$2&", "&E14&" as "&F14&" FROM "&C14&" WHERE "&Instruções!$D$20&") A ", "(SELECT "&VLOOKUP(B14,Instruções!$F$13:$J$17,4,0)&" as "&VLOOKUP(B14,Instruções!$F$13:$J$17,4,0)&"_"&$F$2&", "&VLOOKUP(B14,Instruções!$F$13:$J$17,5,0)&" as "&VLOOKUP(B14,Instruções!$F$13:$J$17,5,0)&"_"&$F$2&","&E14&" as "&F14&" FROM "&C14&" WHERE "&Instruções!$D$20&") A ") -> (SELECT entty_id as entty_id_, capex as capex_as_is FROM cd_loan_tapes_bce.lt003_entity WHERE ref_date='2024-09-30' AND nome_perimetro='Individual Corporativo' AND segmento='ESTR' AND ambito='PM' AND entidade='00100' ) A | I14: =IF(VLOOKUP(B14,Instruções!$F$13:$J$17,5,0)="", "(SELECT "&VLOOKUP(B14,Instruções!$F$13:$J$17,4,0)&" as "&VLOOKUP(B14,Instruções!$F$13:$J$17,4,0)&"_"&$G$2&", "&E14&" as "&G14&" FROM "&D14&" WHERE "&Instruções!$D$21&") B ", "(SELECT "&VLOOKUP(B14,Instruções!$F$13:$J$17,4,0)&" as "&VLOOKUP(B14,Instruções!$F$13:$J$17,4,0)&"_"&$G$2&", "&VLOOKUP(B14,Instruções!$F$13:$J$17,5,0)&" as "&VLOOKUP(B14,Instruções!$F$13:$J$17,5,0)&"_"&$G$2&","&E14&" as "&G14&" FROM "&D14&" WHERE "&Instruções!$D$21&") B ") -> (SELECT entty_id as entty_id_, capex as capex_to_be FROM bu_loantape_work.lt003_entity WHERE ref_date='2024-09-30' AND nome_perimetro='Individual Corporativo' AND segmento='ESTR' AND ambito='PM' AND entidade='00100' ) B | J14: =+IF(VLOOKUP(B14,Instruções!$F$13:$J$17,5,0)="", "ON "&VLOOKUP(B14,Instruções!$F$13:$J$17,4,0)&"_"&$F$7&"="&VLOOKUP(B14,Instruções!$F$13:$J$17,4,0)&"_"&$G$7&" ", "ON "&VLOOKUP(B14,Instruções!$F$13:$J$17,4,0)&"_"&$F$7&"="&VLOOKUP(B14,Instruções!$F$13:$J$17,4,0)&"_"&$G$7&" AND "&VLOOKUP(B14,Instruções!$F$13:$J$17,5,0)&"_"&$F$7&"="&VLOOKUP(B14,Instruções!$F$13:$J$17,5,0)&"_"&$G$7&" ") -> ON entty_id_as_is=entty_id_to_be | K14: ="WHERE coalesce(cast("&F14&" AS string),'')<>coalesce(cast("&G14&" AS string),'') " -> WHERE coalesce(cast(capex_as_is AS string),'')<>coalesce(cast(capex_to_be AS string),'') | L14: ="SELECT count(*) AS NUM_REG_DIF FROM "&H14&" Inner join "&I14&J14&K14 -> SELECT count(*) AS NUM_REG_DIF FROM (SELECT entty_id as entty_id_, capex as capex_as_is FROM cd_loan_tapes_bce.lt003_entity WHERE ref_date='2024-09-30' AND nome_perimetro='Individual Corporativo' AND segmento='ESTR' AND ambito='PM' AND entidade='00100' ) A Inner join (SELECT entty_id as entty_id_, capex as capex_to_be FROM bu_loantape_work.lt003_entity WHERE ref_date='2024-09-30' AND nome_perimetro='Individual Corporativo' AND segmento='ESTR' AND ambito='PM' AND entidade='00100' ) B ON entty_id_as_is=entty_id_to_be WHERE coalesce(cast(capex_as_is AS string),'')<>coalesce(cast(capex_to_be AS string),'') | M14: Validação de campos | N14: ="SELECT 'Validação de campos' as tipologia_teste, '"&VLOOKUP(B14,Instruções!$F$13:$J$17,3,0)&"' AS TABELA, '"&E14&"' AS CAMPO, '"&Instruções!$D$15&"' as ref_date, coalesce(NUM_REG_DIF, 0) AS NUM_REG_DIF FROM ("&L14&") A " -> SELECT 'Validação de campos' as tipologia_teste, 'lt003_entity' AS TABELA, 'capex' AS CAMPO, '2024-09-30' as ref_date, coalesce(NUM_REG_DIF, 0) AS NUM_REG_DIF FROM (SELECT count(*) AS NUM_REG_DIF FROM (SELECT entty_id as entty_id_, capex as capex_as_is FROM cd_loan_tapes_bce.lt003_entity WHERE ref_date='2024-09-30' AND nome_perimetro='Individual Corporativo' AND segmento='ESTR' AND ambito='PM' AND entidade='00100' ) A Inner join (SELECT entty_id as entty_id_, capex as capex_to_be FROM bu_loantape_work.lt003_entity WHERE ref_date='2024-09-30' AND nome_perimetro='Individual Corporativo' AND segmento='ESTR' AND ambito='PM' AND entidade='00100' ) B ON entty_id_as_is=entty_id_to_be WHERE coalesce(cast(capex_as_is AS string),'')<>coalesce(cast(capex_to_be AS string),'') ) A | O14: =IF(O15="",N14,N14&$O$8) -> SELECT 'Validação de campos' as tipologia_teste, 'lt003_entity' AS TABELA, 'capex' AS CAMPO, '2024-09-30' as ref_date, coalesce(NUM_REG_DIF, 0) AS NUM_REG_DIF FROM (SELECT count(*) AS NUM_REG_DIF FROM (SELECT entty_id as entty_id_, capex as capex_as_is FROM cd_loan_tapes_bce.lt003_entity WHERE ref_date='2024-09-30' AND nome_perimetro='Individual Corporativo' AND segmento='ESTR' AND ambito='PM' AND entidade='00100' ) A Inner join (SELECT entty_id as entty_id_, capex as capex_to_be FROM bu_loantape_work.lt003_entity WHERE ref_date='2024-09-30' AND nome_perimetro='Individual Corporativo' AND segmento='ESTR' AND ambito='PM' AND entidade='00100' ) B ON entty_id_as_is=entty_id_to_be WHERE coalesce(cast(capex_as_is AS string),'')<>coalesce(cast(capex_to_be AS string),'') ) A Union all | P14: =+P13+1 -> 6
B15: ENTTY | C15: =_xlfn.CONCAT(Instruções!$D$13,".",VLOOKUP(B15,Instruções!$F$12:$H$17,2,0)) -> cd_loan_tapes_bce.lt003_entity | D15: =_xlfn.CONCAT(Instruções!$D$14,".",VLOOKUP(B15,Instruções!$F$12:$H$17,3,0)) -> bu_loantape_work.lt003_entity | E15: capex_prvs | F15: =E15&"_"&$F$7 -> capex_prvs_as_is | G15: =E15&"_"&$G$7 -> capex_prvs_to_be | H15: =IF(VLOOKUP(B15,Instruções!$F$13:$J$17,5,0)="", "(SELECT "&VLOOKUP(B15,Instruções!$F$13:$J$17,4,0)&" as "&VLOOKUP(B15,Instruções!$F$13:$J$17,4,0)&"_"&$F$2&", "&E15&" as "&F15&" FROM "&C15&" WHERE "&Instruções!$D$20&") A ", "(SELECT "&VLOOKUP(B15,Instruções!$F$13:$J$17,4,0)&" as "&VLOOKUP(B15,Instruções!$F$13:$J$17,4,0)&"_"&$F$2&", "&VLOOKUP(B15,Instruções!$F$13:$J$17,5,0)&" as "&VLOOKUP(B15,Instruções!$F$13:$J$17,5,0)&"_"&$F$2&","&E15&" as "&F15&" FROM "&C15&" WHERE "&Instruções!$D$20&") A ") -> (SELECT entty_id as entty_id_, capex_prvs as capex_prvs_as_is FROM cd_loan_tapes_bce.lt003_entity WHERE ref_date='2024-09-30' AND nome_perimetro='Individual Corporativo' AND segmento='ESTR' AND ambito='PM' AND entidade='00100' ) A | I15: =IF(VLOOKUP(B15,Instruções!$F$13:$J$17,5,0)="", "(SELECT "&VLOOKUP(B15,Instruções!$F$13:$J$17,4,0)&" as "&VLOOKUP(B15,Instruções!$F$13:$J$17,4,0)&"_"&$G$2&", "&E15&" as "&G15&" FROM "&D15&" WHERE "&Instruções!$D$21&") B ", "(SELECT "&VLOOKUP(B15,Instruções!$F$13:$J$17,4,0)&" as "&VLOOKUP(B15,Instruções!$F$13:$J$17,4,0)&"_"&$G$2&", "&VLOOKUP(B15,Instruções!$F$13:$J$17,5,0)&" as "&VLOOKUP(B15,Instruções!$F$13:$J$17,5,0)&"_"&$G$2&","&E15&" as "&G15&" FROM "&D15&" WHERE "&Instruções!$D$21&") B ") -> (SELECT entty_id as entty_id_, capex_prvs as capex_prvs_to_be FROM bu_loantape_work.lt003_entity WHERE ref_date='2024-09-30' AND nome_perimetro='Individual Corporativo' AND segmento='ESTR' AND ambito='PM' AND entidade='00100' ) B | J15: =+IF(VLOOKUP(B15,Instruções!$F$13:$J$17,5,0)="", "ON "&VLOOKUP(B15,Instruções!$F$13:$J$17,4,0)&"_"&$F$7&"="&VLOOKUP(B15,Instruções!$F$13:$J$17,4,0)&"_"&$G$7&" ", "ON "&VLOOKUP(B15,Instruções!$F$13:$J$17,4,0)&"_"&$F$7&"="&VLOOKUP(B15,Instruções!$F$13:$J$17,4,0)&"_"&$G$7&" AND "&VLOOKUP(B15,Instruções!$F$13:$J$17,5,0)&"_"&$F$7&"="&VLOOKUP(B15,Instruções!$F$13:$J$17,5,0)&"_"&$G$7&" ") -> ON entty_id_as_is=entty_id_to_be | K15: ="WHERE coalesce(cast("&F15&" AS string),'')<>coalesce(cast("&G15&" AS string),'') " -> WHERE coalesce(cast(capex_prvs_as_is AS string),'')<>coalesce(cast(capex_prvs_to_be AS string),'') | L15: ="SELECT count(*) AS NUM_REG_DIF FROM "&H15&" Inner join "&I15&J15&K15 -> SELECT count(*) AS NUM_REG_DIF FROM (SELECT entty_id as entty_id_, capex_prvs as capex_prvs_as_is FROM cd_loan_tapes_bce.lt003_entity WHERE ref_date='2024-09-30' AND nome_perimetro='Individual Corporativo' AND segmento='ESTR' AND ambito='PM' AND entidade='00100' ) A Inner join (SELECT entty_id as entty_id_, capex_prvs as capex_prvs_to_be FROM bu_loantape_work.lt003_entity WHERE ref_date='2024-09-30' AND nome_perimetro='Individual Corporativo' AND segmento='ESTR' AND ambito='PM' AND entidade='00100' ) B ON entty_id_as_is=entty_id_to_be WHERE coalesce(cast(capex_prvs_as_is AS string),'')<>coalesce(cast(capex_prvs_to_be AS string),'') | M15: Validação de campos | N15: ="SELECT 'Validação de campos' as tipologia_teste, '"&VLOOKUP(B15,Instruções!$F$13:$J$17,3,0)&"' AS TABELA, '"&E15&"' AS CAMPO, '"&Instruções!$D$15&"' as ref_date, coalesce(NUM_REG_DIF, 0) AS NUM_REG_DIF FROM ("&L15&") A " -> SELECT 'Validação de campos' as tipologia_teste, 'lt003_entity' AS TABELA, 'capex_prvs' AS CAMPO, '2024-09-30' as ref_date, coalesce(NUM_REG_DIF, 0) AS NUM_REG_DIF FROM (SELECT count(*) AS NUM_REG_DIF FROM (SELECT entty_id as entty_id_, capex_prvs as capex_prvs_as_is FROM cd_loan_tapes_bce.lt003_entity WHERE ref_date='2024-09-30' AND nome_perimetro='Individual Corporativo' AND segmento='ESTR' AND ambito='PM' AND entidade='00100' ) A Inner join (SELECT entty_id as entty_id_, capex_prvs as capex_prvs_to_be FROM bu_loantape_work.lt003_entity WHERE ref_date='2024-09-30' AND nome_perimetro='Individual Corporativo' AND segmento='ESTR' AND ambito='PM' AND entidade='00100' ) B ON entty_id_as_is=entty_id_to_be WHERE coalesce(cast(capex_prvs_as_is AS string),'')<>coalesce(cast(capex_prvs_to_be AS string),'') ) A | O15: =IF(O16="",N15,N15&$O$8) -> SELECT 'Validação de campos' as tipologia_teste, 'lt003_entity' AS TABELA, 'capex_prvs' AS CAMPO, '2024-09-30' as ref_date, coalesce(NUM_REG_DIF, 0) AS NUM_REG_DIF FROM (SELECT count(*) AS NUM_REG_DIF FROM (SELECT entty_id as entty_id_, capex_prvs as capex_prvs_as_is FROM cd_loan_tapes_bce.lt003_entity WHERE ref_date='2024-09-30' AND nome_perimetro='Individual Corporativo' AND segmento='ESTR' AND ambito='PM' AND entidade='00100' ) A Inner join (SELECT entty_id as entty_id_, capex_prvs as capex_prvs_to_be FROM bu_loantape_work.lt003_entity WHERE ref_date='2024-09-30' AND nome_perimetro='Individual Corporativo' AND segmento='ESTR' AND ambito='PM' AND entidade='00100' ) B ON entty_id_as_is=entty_id_to_be WHERE coalesce(cast(capex_prvs_as_is AS string),'')<>coalesce(cast(capex_prvs_to_be AS string),'') ) A Union all | P15: =+P14+1 -> 7
B16: ENTTY | C16: =_xlfn.CONCAT(Instruções!$D$13,".",VLOOKUP(B16,Instruções!$F$12:$H$17,2,0)) -> cd_loan_tapes_bce.lt003_entity | D16: =_xlfn.CONCAT(Instruções!$D$14,".",VLOOKUP(B16,Instruções!$F$12:$H$17,3,0)) -> bu_loantape_work.lt003_entity | E16: cllctn_md | F16: =E16&"_"&$F$7 -> cllctn_md_as_is | G16: =E16&"_"&$G$7 -> cllctn_md_to_be | H16: =IF(VLOOKUP(B16,Instruções!$F$13:$J$17,5,0)="", "(SELECT "&VLOOKUP(B16,Instruções!$F$13:$J$17,4,0)&" as "&VLOOKUP(B16,Instruções!$F$13:$J$17,4,0)&"_"&$F$2&", "&E16&" as "&F16&" FROM "&C16&" WHERE "&Instruções!$D$20&") A ", "(SELECT "&VLOOKUP(B16,Instruções!$F$13:$J$17,4,0)&" as "&VLOOKUP(B16,Instruções!$F$13:$J$17,4,0)&"_"&$F$2&", "&VLOOKUP(B16,Instruções!$F$13:$J$17,5,0)&" as "&VLOOKUP(B16,Instruções!$F$13:$J$17,5,0)&"_"&$F$2&","&E16&" as "&F16&" FROM "&C16&" WHERE "&Instruções!$D$20&") A ") -> (SELECT entty_id as entty_id_, cllctn_md as cllctn_md_as_is FROM cd_loan_tapes_bce.lt003_entity WHERE ref_date='2024-09-30' AND nome_perimetro='Individual Corporativo' AND segmento='ESTR' AND ambito='PM' AND entidade='00100' ) A | I16: =IF(VLOOKUP(B16,Instruções!$F$13:$J$17,5,0)="", "(SELECT "&VLOOKUP(B16,Instruções!$F$13:$J$17,4,0)&" as "&VLOOKUP(B16,Instruções!$F$13:$J$17,4,0)&"_"&$G$2&", "&E16&" as "&G16&" FROM "&D16&" WHERE "&Instruções!$D$21&") B ", "(SELECT "&VLOOKUP(B16,Instruções!$F$13:$J$17,4,0)&" as "&VLOOKUP(B16,Instruções!$F$13:$J$17,4,0)&"_"&$G$2&", "&VLOOKUP(B16,Instruções!$F$13:$J$17,5,0)&" as "&VLOOKUP(B16,Instruções!$F$13:$J$17,5,0)&"_"&$G$2&","&E16&" as "&G16&" FROM "&D16&" WHERE "&Instruções!$D$21&") B ") -> (SELECT entty_id as entty_id_, cllctn_md as cllctn_md_to_be FROM bu_loantape_work.lt003_entity WHERE ref_date='2024-09-30' AND nome_perimetro='Individual Corporativo' AND segmento='ESTR' AND ambito='PM' AND entidade='00100' ) B | J16: =+IF(VLOOKUP(B16,Instruções!$F$13:$J$17,5,0)="", "ON "&VLOOKUP(B16,Instruções!$F$13:$J$17,4,0)&"_"&$F$7&"="&VLOOKUP(B16,Instruções!$F$13:$J$17,4,0)&"_"&$G$7&" ", "ON "&VLOOKUP(B16,Instruções!$F$13:$J$17,4,0)&"_"&$F$7&"="&VLOOKUP(B16,Instruções!$F$13:$J$17,4,0)&"_"&$G$7&" AND "&VLOOKUP(B16,Instruções!$F$13:$J$17,5,0)&"_"&$F$7&"="&VLOOKUP(B16,Instruções!$F$13:$J$17,5,0)&"_"&$G$7&" ") -> ON entty_id_as_is=entty_id_to_be | K16: ="WHERE coalesce(cast("&F16&" AS string),'')<>coalesce(cast("&G16&" AS string),'') " -> WHERE coalesce(cast(cllctn_md_as_is AS string),'')<>coalesce(cast(cllctn_md_to_be AS string),'') | L16: ="SELECT count(*) AS NUM_REG_DIF FROM "&H16&" Inner join "&I16&J16&K16 -> SELECT count(*) AS NUM_REG_DIF FROM (SELECT entty_id as entty_id_, cllctn_md as cllctn_md_as_is FROM cd_loan_tapes_bce.lt003_entity WHERE ref_date='2024-09-30' AND nome_perimetro='Individual Corporativo' AND segmento='ESTR' AND ambito='PM' AND entidade='00100' ) A Inner join (SELECT entty_id as entty_id_, cllctn_md as cllctn_md_to_be FROM bu_loantape_work.lt003_entity WHERE ref_date='2024-09-30' AND nome_perimetro='Individual Corporativo' AND segmento='ESTR' AND ambito='PM' AND entidade='00100' ) B ON entty_id_as_is=entty_id_to_be WHERE coalesce(cast(cllctn_md_as_is AS string),'')<>coalesce(cast(cllctn_md_to_be AS string),'') | M16: Validação de campos | N16: ="SELECT 'Validação de campos' as tipologia_teste, '"&VLOOKUP(B16,Instruções!$F$13:$J$17,3,0)&"' AS TABELA, '"&E16&"' AS CAMPO, '"&Instruções!$D$15&"' as ref_date, coalesce(NUM_REG_DIF, 0) AS NUM_REG_DIF FROM ("&L16&") A " -> SELECT 'Validação de campos' as tipologia_teste, 'lt003_entity' AS TABELA, 'cllctn_md' AS CAMPO, '2024-09-30' as ref_date, coalesce(NUM_REG_DIF, 0) AS NUM_REG_DIF FROM (SELECT count(*) AS NUM_REG_DIF FROM (SELECT entty_id as entty_id_, cllctn_md as cllctn_md_as_is FROM cd_loan_tapes_bce.lt003_entity WHERE ref_date='2024-09-30' AND nome_perimetro='Individual Corporativo' AND segmento='ESTR' AND ambito='PM' AND entidade='00100' ) A Inner join (SELECT entty_id as entty_id_, cllctn_md as cllctn_md_to_be FROM bu_loantape_work.lt003_entity WHERE ref_date='2024-09-30' AND nome_perimetro='Individual Corporativo' AND segmento='ESTR' AND ambito='PM' AND entidade='00100' ) B ON entty_id_as_is=entty_id_to_be WHERE coalesce(cast(cllctn_md_as_is AS string),'')<>coalesce(cast(cllctn_md_to_be AS string),'') ) A | O16: =IF(O17="",N16,N16&$O$8) -> SELECT 'Validação de campos' as tipologia_teste, 'lt003_entity' AS TABELA, 'cllctn_md' AS CAMPO, '2024-09-30' as ref_date, coalesce(NUM_REG_DIF, 0) AS NUM_REG_DIF FROM (SELECT count(*) AS NUM_REG_DIF FROM (SELECT entty_id as entty_id_, cllctn_md as cllctn_md_as_is FROM cd_loan_tapes_bce.lt003_entity WHERE ref_date='2024-09-30' AND nome_perimetro='Individual Corporativo' AND segmento='ESTR' AND ambito='PM' AND entidade='00100' ) A Inner join (SELECT entty_id as entty_id_, cllctn_md as cllctn_md_to_be FROM bu_loantape_work.lt003_entity WHERE ref_date='2024-09-30' AND nome_perimetro='Individual Corporativo' AND segmento='ESTR' AND ambito='PM' AND entidade='00100' ) B ON entty_id_as_is=entty_id_to_be WHERE coalesce(cast(cllctn_md_as_is AS string),'')<>coalesce(cast(cllctn_md_to_be AS string),'') ) A Union all | P16: =+P15+1 -> 8
B17: ENTTY | C17: =_xlfn.CONCAT(Instruções!$D$13,".",VLOOKUP(B17,Instruções!$F$12:$H$17,2,0)) -> cd_loan_tapes_bce.lt003_entity | D17: =_xlfn.CONCAT(Instruções!$D$14,".",VLOOKUP(B17,Instruções!$F$12:$H$17,3,0)) -> bu_loantape_work.lt003_entity | E17: cntry | F17: =E17&"_"&$F$7 -> cntry_as_is | G17: =E17&"_"&$G$7 -> cntry_to_be | H17: =IF(VLOOKUP(B17,Instruções!$F$13:$J$17,5,0)="", "(SELECT "&VLOOKUP(B17,Instruções!$F$13:$J$17,4,0)&" as "&VLOOKUP(B17,Instruções!$F$13:$J$17,4,0)&"_"&$F$2&", "&E17&" as "&F17&" FROM "&C17&" WHERE "&Instruções!$D$20&") A ", "(SELECT "&VLOOKUP(B17,Instruções!$F$13:$J$17,4,0)&" as "&VLOOKUP(B17,Instruções!$F$13:$J$17,4,0)&"_"&$F$2&", "&VLOOKUP(B17,Instruções!$F$13:$J$17,5,0)&" as "&VLOOKUP(B17,Instruções!$F$13:$J$17,5,0)&"_"&$F$2&","&E17&" as "&F17&" FROM "&C17&" WHERE "&Instruções!$D$20&") A ") -> (SELECT entty_id as entty_id_, cntry as cntry_as_is FROM cd_loan_tapes_bce.lt003_entity WHERE ref_date='2024-09-30' AND nome_perimetro='Individual Corporativo' AND segmento='ESTR' AND ambito='PM' AND entidade='00100' ) A | I17: =IF(VLOOKUP(B17,Instruções!$F$13:$J$17,5,0)="", "(SELECT "&VLOOKUP(B17,Instruções!$F$13:$J$17,4,0)&" as "&VLOOKUP(B17,Instruções!$F$13:$J$17,4,0)&"_"&$G$2&", "&E17&" as "&G17&" FROM "&D17&" WHERE "&Instruções!$D$21&") B ", "(SELECT "&VLOOKUP(B17,Instruções!$F$13:$J$17,4,0)&" as "&VLOOKUP(B17,Instruções!$F$13:$J$17,4,0)&"_"&$G$2&", "&VLOOKUP(B17,Instruções!$F$13:$J$17,5,0)&" as "&VLOOKUP(B17,Instruções!$F$13:$J$17,5,0)&"_"&$G$2&","&E17&" as "&G17&" FROM "&D17&" WHERE "&Instruções!$D$21&") B ") -> (SELECT entty_id as entty_id_, cntry as cntry_to_be FROM bu_loantape_work.lt003_entity WHERE ref_date='2024-09-30' AND nome_perimetro='Individual Corporativo' AND segmento='ESTR' AND ambito='PM' AND entidade='00100' ) B | J17: =+IF(VLOOKUP(B17,Instruções!$F$13:$J$17,5,0)="", "ON "&VLOOKUP(B17,Instruções!$F$13:$J$17,4,0)&"_"&$F$7&"="&VLOOKUP(B17,Instruções!$F$13:$J$17,4,0)&"_"&$G$7&" ", "ON "&VLOOKUP(B17,Instruções!$F$13:$J$17,4,0)&"_"&$F$7&"="&VLOOKUP(B17,Instruções!$F$13:$J$17,4,0)&"_"&$G$7&" AND "&VLOOKUP(B17,Instruções!$F$13:$J$17,5,0)&"_"&$F$7&"="&VLOOKUP(B17,Instruções!$F$13:$J$17,5,0)&"_"&$G$7&" ") -> ON entty_id_as_is=entty_id_to_be | K17: ="WHERE coalesce(cast("&F17&" AS string),'')<>coalesce(cast("&G17&" AS string),'') " -> WHERE coalesce(cast(cntry_as_is AS string),'')<>coalesce(cast(cntry_to_be AS string),'') | L17: ="SELECT count(*) AS NUM_REG_DIF FROM "&H17&" Inner join "&I17&J17&K17 -> SELECT count(*) AS NUM_REG_DIF FROM (SELECT entty_id as entty_id_, cntry as cntry_as_is FROM cd_loan_tapes_bce.lt003_entity WHERE ref_date='2024-09-30' AND nome_perimetro='Individual Corporativo' AND segmento='ESTR' AND ambito='PM' AND entidade='00100' ) A Inner join (SELECT entty_id as entty_id_, cntry as cntry_to_be FROM bu_loantape_work.lt003_entity WHERE ref_date='2024-09-30' AND nome_perimetro='Individual Corporativo' AND segmento='ESTR' AND ambito='PM' AND entidade='00100' ) B ON entty_id_as_is=entty_id_to_be WHERE coalesce(cast(cntry_as_is AS string),'')<>coalesce(cast(cntry_to_be AS string),'') | M17: Validação de campos | N17: ="SELECT 'Validação de campos' as tipologia_teste, '"&VLOOKUP(B17,Instruções!$F$13:$J$17,3,0)&"' AS TABELA, '"&E17&"' AS CAMPO, '"&Instruções!$D$15&"' as ref_date, coalesce(NUM_REG_DIF, 0) AS NUM_REG_DIF FROM ("&L17&") A " -> SELECT 'Validação de campos' as tipologia_teste, 'lt003_entity' AS TABELA, 'cntry' AS CAMPO, '2024-09-30' as ref_date, coalesce(NUM_REG_DIF, 0) AS NUM_REG_DIF FROM (SELECT count(*) AS NUM_REG_DIF FROM (SELECT entty_id as entty_id_, cntry as cntry_as_is FROM cd_loan_tapes_bce.lt003_entity WHERE ref_date='2024-09-30' AND nome_perimetro='Individual Corporativo' AND segmento='ESTR' AND ambito='PM' AND entidade='00100' ) A Inner join (SELECT entty_id as entty_id_, cntry as cntry_to_be FROM bu_loantape_work.lt003_entity WHERE ref_date='2024-09-30' AND nome_perimetro='Individual Corporativo' AND segmento='ESTR' AND ambito='PM' AND entidade='00100' ) B ON entty_id_as_is=entty_id_to_be WHERE coalesce(cast(cntry_as_is AS string),'')<>coalesce(cast(cntry_to_be AS string),'') ) A | O17: =IF(O18="",N17,N17&$O$8) -> SELECT 'Validação de campos' as tipologia_teste, 'lt003_entity' AS TABELA, 'cntry' AS CAMPO, '2024-09-30' as ref_date, coalesce(NUM_REG_DIF, 0) AS NUM_REG_DIF FROM (SELECT count(*) AS NUM_REG_DIF FROM (SELECT entty_id as entty_id_, cntry as cntry_as_is FROM cd_loan_tapes_bce.lt003_entity WHERE ref_date='2024-09-30' AND nome_perimetro='Individual Corporativo' AND segmento='ESTR' AND ambito='PM' AND entidade='00100' ) A Inner join (SELECT entty_id as entty_id_, cntry as cntry_to_be FROM bu_loantape_work.lt003_entity WHERE ref_date='2024-09-30' AND nome_perimetro='Individual Corporativo' AND segmento='ESTR' AND ambito='PM' AND entidade='00100' ) B ON entty_id_as_is=entty_id_to_be WHERE coalesce(cast(cntry_as_is AS string),'')<>coalesce(cast(cntry_to_be AS string),'') ) A Union all | P17: =+P16+1 -> 9
B18: ENTTY | C18: =_xlfn.CONCAT(Instruções!$D$13,".",VLOOKUP(B18,Instruções!$F$12:$H$17,2,0)) -> cd_loan_tapes_bce.lt003_entity | D18: =_xlfn.CONCAT(Instruções!$D$14,".",VLOOKUP(B18,Instruções!$F$12:$H$17,3,0)) -> bu_loantape_work.lt003_entity | E18: cod_soc | F18: =E18&"_"&$F$7 -> cod_soc_as_is | G18: =E18&"_"&$G$7 -> cod_soc_to_be | H18: =IF(VLOOKUP(B18,Instruções!$F$13:$J$17,5,0)="", "(SELECT "&VLOOKUP(B18,Instruções!$F$13:$J$17,4,0)&" as "&VLOOKUP(B18,Instruções!$F$13:$J$17,4,0)&"_"&$F$2&", "&E18&" as "&F18&" FROM "&C18&" WHERE "&Instruções!$D$20&") A ", "(SELECT "&VLOOKUP(B18,Instruções!$F$13:$J$17,4,0)&" as "&VLOOKUP(B18,Instruções!$F$13:$J$17,4,0)&"_"&$F$2&", "&VLOOKUP(B18,Instruções!$F$13:$J$17,5,0)&" as "&VLOOKUP(B18,Instruções!$F$13:$J$17,5,0)&"_"&$F$2&","&E18&" as "&F18&" FROM "&C18&" WHERE "&Instruções!$D$20&") A ") -> (SELECT entty_id as entty_id_, cod_soc as cod_soc_as_is FROM cd_loan_tapes_bce.lt003_entity WHERE ref_date='2024-09-30' AND nome_perimetro='Individual Corporativo' AND segmento='ESTR' AND ambito='PM' AND entidade='00100' ) A | I18: =IF(VLOOKUP(B18,Instruções!$F$13:$J$17,5,0)="", "(SELECT "&VLOOKUP(B18,Instruções!$F$13:$J$17,4,0)&" as "&VLOOKUP(B18,Instruções!$F$13:$J$17,4,0)&"_"&$G$2&", "&E18&" as "&G18&" FROM "&D18&" WHERE "&Instruções!$D$21&") B ", "(SELECT "&VLOOKUP(B18,Instruções!$F$13:$J$17,4,0)&" as "&VLOOKUP(B18,Instruções!$F$13:$J$17,4,0)&"_"&$G$2&", "&VLOOKUP(B18,Instruções!$F$13:$J$17,5,0)&" as "&VLOOKUP(B18,Instruções!$F$13:$J$17,5,0)&"_"&$G$2&","&E18&" as "&G18&" FROM "&D18&" WHERE "&Instruções!$D$21&") B ") -> (SELECT entty_id as entty_id_, cod_soc as cod_soc_to_be FROM bu_loantape_work.lt003_entity WHERE ref_date='2024-09-30' AND nome_perimetro='Individual Corporativo' AND segmento='ESTR' AND ambito='PM' AND entidade='00100' ) B | J18: =+IF(VLOOKUP(B18,Instruções!$F$13:$J$17,5,0)="", "ON "&VLOOKUP(B18,Instruções!$F$13:$J$17,4,0)&"_"&$F$7&"="&VLOOKUP(B18,Instruções!$F$13:$J$17,4,0)&"_"&$G$7&" ", "ON "&VLOOKUP(B18,Instruções!$F$13:$J$17,4,0)&"_"&$F$7&"="&VLOOKUP(B18,Instruções!$F$13:$J$17,4,0)&"_"&$G$7&" AND "&VLOOKUP(B18,Instruções!$F$13:$J$17,5,0)&"_"&$F$7&"="&VLOOKUP(B18,Instruções!$F$13:$J$17,5,0)&"_"&$G$7&" ") -> ON entty_id_as_is=entty_id_to_be | K18: ="WHERE coalesce(cast("&F18&" AS string),'')<>coalesce(cast("&G18&" AS string),'') " -> WHERE coalesce(cast(cod_soc_as_is AS string),'')<>coalesce(cast(cod_soc_to_be AS string),'') | L18: ="SELECT count(*) AS NUM_REG_DIF FROM "&H18&" Inner join "&I18&J18&K18 -> SELECT count(*) AS NUM_REG_DIF FROM (SELECT entty_id as entty_id_, cod_soc as cod_soc_as_is FROM cd_loan_tapes_bce.lt003_entity WHERE ref_date='2024-09-30' AND nome_perimetro='Individual Corporativo' AND segmento='ESTR' AND ambito='PM' AND entidade='00100' ) A Inner join (SELECT entty_id as entty_id_, cod_soc as cod_soc_to_be FROM bu_loantape_work.lt003_entity WHERE ref_date='2024-09-30' AND nome_perimetro='Individual Corporativo' AND segmento='ESTR' AND ambito='PM' AND entidade='00100' ) B ON entty_id_as_is=entty_id_to_be WHERE coalesce(cast(cod_soc_as_is AS string),'')<>coalesce(cast(cod_soc_to_be AS string),'') | M18: Validação de campos | N18: ="SELECT 'Validação de campos' as tipologia_teste, '"&VLOOKUP(B18,Instruções!$F$13:$J$17,3,0)&"' AS TABELA, '"&E18&"' AS CAMPO, '"&Instruções!$D$15&"' as ref_date, coalesce(NUM_REG_DIF, 0) AS NUM_REG_DIF FROM ("&L18&") A " -> SELECT 'Validação de campos' as tipologia_teste, 'lt003_entity' AS TABELA, 'cod_soc' AS CAMPO, '2024-09-30' as ref_date, coalesce(NUM_REG_DIF, 0) AS NUM_REG_DIF FROM (SELECT count(*) AS NUM_REG_DIF FROM (SELECT entty_id as entty_id_, cod_soc as cod_soc_as_is FROM cd_loan_tapes_bce.lt003_entity WHERE ref_date='2024-09-30' AND nome_perimetro='Individual Corporativo' AND segmento='ESTR' AND ambito='PM' AND entidade='00100' ) A Inner join (SELECT entty_id as entty_id_, cod_soc as cod_soc_to_be FROM bu_loantape_work.lt003_entity WHERE ref_date='2024-09-30' AND nome_perimetro='Individual Corporativo' AND segmento='ESTR' AND ambito='PM' AND entidade='00100' ) B ON entty_id_as_is=entty_id_to_be WHERE coalesce(cast(cod_soc_as_is AS string),'')<>coalesce(cast(cod_soc_to_be AS string),'') ) A | O18: =IF(O19="",N18,N18&$O$8) -> SELECT 'Validação de campos' as tipologia_teste, 'lt003_entity' AS TABELA, 'cod_soc' AS CAMPO, '2024-09-30' as ref_date, coalesce(NUM_REG_DIF, 0) AS NUM_REG_DIF FROM (SELECT count(*) AS NUM_REG_DIF FROM (SELECT entty_id as entty_id_, cod_soc as cod_soc_as_is FROM cd_loan_tapes_bce.lt003_entity WHERE ref_date='2024-09-30' AND nome_perimetro='Individual Corporativo' AND segmento='ESTR' AND ambito='PM' AND entidade='00100' ) A Inner join (SELECT entty_id as entty_id_, cod_soc as cod_soc_to_be FROM bu_loantape_work.lt003_entity WHERE ref_date='2024-09-30' AND nome_perimetro='Individual Corporativo' AND segmento='ESTR' AND ambito='PM' AND entidade='00100' ) B ON entty_id_as_is=entty_id_to_be WHERE coalesce(cast(cod_soc_as_is AS string),'')<>coalesce(cast(cod_soc_to_be AS string),'') ) A Union all | P18: =+P17+1 -> 10
B19: ENTTY | C19: =_xlfn.CONCAT(Instruções!$D$13,".",VLOOKUP(B19,Instruções!$F$12:$H$17,2,0)) -> cd_loan_tapes_bce.lt003_entity | D19: =_xlfn.CONCAT(Instruções!$D$14,".",VLOOKUP(B19,Instruções!$F$12:$H$17,3,0)) -> bu_loantape_work.lt003_entity | E19: cr_flg | F19: =E19&"_"&$F$7 -> cr_flg_as_is | G19: =E19&"_"&$G$7 -> cr_flg_to_be | H19: =IF(VLOOKUP(B19,Instruções!$F$13:$J$17,5,0)="", "(SELECT "&VLOOKUP(B19,Instruções!$F$13:$J$17,4,0)&" as "&VLOOKUP(B19,Instruções!$F$13:$J$17,4,0)&"_"&$F$2&", "&E19&" as "&F19&" FROM "&C19&" WHERE "&Instruções!$D$20&") A ", "(SELECT "&VLOOKUP(B19,Instruções!$F$13:$J$17,4,0)&" as "&VLOOKUP(B19,Instruções!$F$13:$J$17,4,0)&"_"&$F$2&", "&VLOOKUP(B19,Instruções!$F$13:$J$17,5,0)&" as "&VLOOKUP(B19,Instruções!$F$13:$J$17,5,0)&"_"&$F$2&","&E19&" as "&F19&" FROM "&C19&" WHERE "&Instruções!$D$20&") A ") -> (SELECT entty_id as entty_id_, cr_flg as cr_flg_as_is FROM cd_loan_tapes_bce.lt003_entity WHERE ref_date='2024-09-30' AND nome_perimetro='Individual Corporativo' AND segmento='ESTR' AND ambito='PM' AND entidade='00100' ) A | I19: =IF(VLOOKUP(B19,Instruções!$F$13:$J$17,5,0)="", "(SELECT "&VLOOKUP(B19,Instruções!$F$13:$J$17,4,0)&" as "&VLOOKUP(B19,Instruções!$F$13:$J$17,4,0)&"_"&$G$2&", "&E19&" as "&G19&" FROM "&D19&" WHERE "&Instruções!$D$21&") B ", "(SELECT "&VLOOKUP(B19,Instruções!$F$13:$J$17,4,0)&" as "&VLOOKUP(B19,Instruções!$F$13:$J$17,4,0)&"_"&$G$2&", "&VLOOKUP(B19,Instruções!$F$13:$J$17,5,0)&" as "&VLOOKUP(B19,Instruções!$F$13:$J$17,5,0)&"_"&$G$2&","&E19&" as "&G19&" FROM "&D19&" WHERE "&Instruções!$D$21&") B ") -> (SELECT entty_id as entty_id_, cr_flg as cr_flg_to_be FROM bu_loantape_work.lt003_entity WHERE ref_date='2024-09-30' AND nome_perimetro='Individual Corporativo' AND segmento='ESTR' AND ambito='PM' AND entidade='00100' ) B | J19: =+IF(VLOOKUP(B19,Instruções!$F$13:$J$17,5,0)="", "ON "&VLOOKUP(B19,Instruções!$F$13:$J$17,4,0)&"_"&$F$7&"="&VLOOKUP(B19,Instruções!$F$13:$J$17,4,0)&"_"&$G$7&" ", "ON "&VLOOKUP(B19,Instruções!$F$13:$J$17,4,0)&"_"&$F$7&"="&VLOOKUP(B19,Instruções!$F$13:$J$17,4,0)&"_"&$G$7&" AND "&VLOOKUP(B19,Instruções!$F$13:$J$17,5,0)&"_"&$F$7&"="&VLOOKUP(B19,Instruções!$F$13:$J$17,5,0)&"_"&$G$7&" ") -> ON entty_id_as_is=entty_id_to_be | K19: ="WHERE coalesce(cast("&F19&" AS string),'')<>coalesce(cast("&G19&" AS string),'') " -> WHERE coalesce(cast(cr_flg_as_is AS string),'')<>coalesce(cast(cr_flg_to_be AS string),'') | L19: ="SELECT count(*) AS NUM_REG_DIF FROM "&H19&" Inner join "&I19&J19&K19 -> SELECT count(*) AS NUM_REG_DIF FROM (SELECT entty_id as entty_id_, cr_flg as cr_flg_as_is FROM cd_loan_tapes_bce.lt003_entity WHERE ref_date='2024-09-30' AND nome_perimetro='Individual Corporativo' AND segmento='ESTR' AND ambito='PM' AND entidade='00100' ) A Inner join (SELECT entty_id as entty_id_, cr_flg as cr_flg_to_be FROM bu_loantape_work.lt003_entity WHERE ref_date='2024-09-30' AND nome_perimetro='Individual Corporativo' AND segmento='ESTR' AND ambito='PM' AND entidade='00100' ) B ON entty_id_as_is=entty_id_to_be WHERE coalesce(cast(cr_flg_as_is AS string),'')<>coalesce(cast(cr_flg_to_be AS string),'') | M19: Validação de campos | N19: ="SELECT 'Validação de campos' as tipologia_teste, '"&VLOOKUP(B19,Instruções!$F$13:$J$17,3,0)&"' AS TABELA, '"&E19&"' AS CAMPO, '"&Instruções!$D$15&"' as ref_date, coalesce(NUM_REG_DIF, 0) AS NUM_REG_DIF FROM ("&L19&") A " -> SELECT 'Validação de campos' as tipologia_teste, 'lt003_entity' AS TABELA, 'cr_flg' AS CAMPO, '2024-09-30' as ref_date, coalesce(NUM_REG_DIF, 0) AS NUM_REG_DIF FROM (SELECT count(*) AS NUM_REG_DIF FROM (SELECT entty_id as entty_id_, cr_flg as cr_flg_as_is FROM cd_loan_tapes_bce.lt003_entity WHERE ref_date='2024-09-30' AND nome_perimetro='Individual Corporativo' AND segmento='ESTR' AND ambito='PM' AND entidade='00100' ) A Inner join (SELECT entty_id as entty_id_, cr_flg as cr_flg_to_be FROM bu_loantape_work.lt003_entity WHERE ref_date='2024-09-30' AND nome_perimetro='Individual Corporativo' AND segmento='ESTR' AND ambito='PM' AND entidade='00100' ) B ON entty_id_as_is=entty_id_to_be WHERE coalesce(cast(cr_flg_as_is AS string),'')<>coalesce(cast(cr_flg_to_be AS string),'') ) A | O19: =IF(O20="",N19,N19&$O$8) -> SELECT 'Validação de campos' as tipologia_teste, 'lt003_entity' AS TABELA, 'cr_flg' AS CAMPO, '2024-09-30' as ref_date, coalesce(NUM_REG_DIF, 0) AS NUM_REG_DIF FROM (SELECT count(*) AS NUM_REG_DIF FROM (SELECT entty_id as entty_id_, cr_flg as cr_flg_as_is FROM cd_loan_tapes_bce.lt003_entity WHERE ref_date='2024-09-30' AND nome_perimetro='Individual Corporativo' AND segmento='ESTR' AND ambito='PM' AND entidade='00100' ) A Inner join (SELECT entty_id as entty_id_, cr_flg as cr_flg_to_be FROM bu_loantape_work.lt003_entity WHERE ref_date='2024-09-30' AND nome_perimetro='Individual Corporativo' AND segmento='ESTR' AND ambito='PM' AND entidade='00100' ) B ON entty_id_as_is=entty_id_to_be WHERE coalesce(cast(cr_flg_as_is AS string),'')<>coalesce(cast(cr_flg_to_be AS string),'') ) A Union all | P19: =+P18+1 -> 11
