Workbook
Name asefadf: #REF!
Name bn: '[1]Code List'!#REF!

Sheet Sheet1
A1: LOANS Efectivo y otros depósitos a la vista / Cash balances and other deposits | B1: (All)
A2: LOANS Administraciones públicas / General governments | B2: (All)
A3: LOANS Entidades de crédito / Credit institutions | B3: (All)
A4: LOANS Otras sociedades financieras / Other financial corporations | B4: (All)
A5: LOANS Sociedad no financieras / Non financial corporations | B5: (All)
A6: LOANS Hogares / Households | B6: (All)
A7: DEBT SECURITIES | B7: (All)
A9: Row Labels | B9: Count of Data field
A10: ENTITY | B10: 85
A11: INSTR_ENTITY | B11: 5
A12: INSTR_PROTECTION | B12: 6
A13: INSTRUMENT | B13: 184
A14: PROTECTION | B14: 39
A15: Grand Total | B15: 319

Sheet READ ME - APPLICABILITY
B5: GUIDANCE ON THE APPLICABILITY OF LOAN TAPE' DATA FIELDS
B7: Corporation has performed an assessment of the applicability of data fields considering two axis:
B8: - counterparty sector (central banks, general governments, credit institutions, other financial corporations, non-financial corporations and households) and
B9: - type of product (cash and other demand deposits, debt securities and loans)
B11: As a consequence, within 'Overview' tab, columns F to M (highlighted in red) determine the applicability of data fields, considering the following rules:
B13: Possible values:
B14: - If remarked as 'Y' = Yes, it does apply, those fields might be applicable, depending on the characteristics of each instrument,entity or protection.
B16: - If remarked as 'N' = No, not applicable, it means that given the counterparty sector or the type of product we conclude that this field is not applicable and therefore,
B17: Unit shall informe these fields as 'Not applicable', with the proper format set up for each field (Date: 1111-11-11 ; Text: N/A ; Numeric: 11111111111).
B19: - If remarked as 'Corporation' = Field to be populated by Corporation, it means that the Unit will inform this field as not applicable, with the proper format
B20: set up for each field (Date: 1111-11-11 ; Text: N/A ; Numeric: 11111111111).
B22: Special case for debt securities:
... B24: given that 'Entity' table might be populated with loan information (in almost all cases, we estimate that the issuer of debt securities acquired will have direct exposures - loans as well).

Sheet Overview
B1: ID Data field / Field order | C1: Table | D1: Category | E1: Anacredit | F1: Data field | G1: Efectivo y otros depósitos a la vista / Cash balances and other deposits | H1: Bancos Centrales / Central Banks | I1: Administraciones públicas / General governments | J1: Entidades de crédito / Credit institutions | K1: Otras sociedades financieras / Other financial corporations | L1: Sociedades no financieras / Non financial corporations | M1: Hogares / Households | N1: DEBT SECURITIES (this column only applies to report the instrument table) | O1: Non-contractual balances and Accounting adjustments (this column only applies to report the instrument table) | P1: Instrument cancelled (this column only applies to report the instrument table) | Q1: Data Types | R1: Guidance on data types | S1: Default value for missing data | T1: Default value for not applicable fields to be used WHEN the field is applicable for the corresponding segment (F to L columns ) | U1: Default value for not applicable fields to be used WHEN: (1) Non-contractual balances and accounting adjustments (2) If the field is not applicable for the corresponding segment (F to L columns) | V1: Field name | W1: Field Definition / Additional Guidance | X1: BDR Status (*) Not applicable = not identified as available in BDR | Y1: BDR Definition | Z1: BDR Comments | AA1: Structural ECB Loan Tape | AB1: Green Dashboard | AC1: Pillar III ESG | AD1: Green Finance | AE1: ESG Risks | AF1: Leveraged Finance | AG1: D + 15 [Green Dashboard] | AH1: D + 18 [+ Pillar III ESG] | AI1: > D + 18 [+ ECB Loan Tape]
A2: 0 | B2: IN.061 | C2: INSTRUMENT | D2: Financial Information | E2: Y | F2: ACCMLTD_CHNGS_FV_CR_INSTRMNT | G2: N | H2: Y | I2: Y | J2: Y | K2: Y | L2: Y | M2: Y | N2: Y | O2: Y | P2: Y | Q2: FLOAT 2 decimal places | R2: Use decimal point, no thousands seperator | S2: 99999999999 | T2: 11111111111 | U2: 11111111111 | V2: Accumulated changes in fair value due to credit risk | W2: Accumulated changes in fair value due to credit risk in accordance with Part 2.46 of Annex V to Implementing Regulation (EU) No 680/2014. | X2: Not applicable | Y2: N/A | Z2: - | AA2: Y | AB2: Y | AC2: Y | AD2: N | AE2: N | AF2: N | AG2: Y | AH2: Y | AI2: Y | AJ2: N | AK2: 0
A3: 6.1. Fora âmbito | Campos concluídos - Sem necessidade de espec. | B3: IN.088 | C3: INSTRUMENT | D3: Impairment | E3: Y | F3: ACCMLTD_IMPRMNT_INSTRMNT | G3: Y | H3: Y | I3: Y | J3: Y | K3: Y | L3: Y | M3: Y | N3: Y | O3: Y | P3: Y | Q3: FLOAT 2 decimal places | R3: Use decimal point, no thousands seperator | S3: 99999999999 | T3: 11111111111 | U3: 11111111111 | V3: Sum of LLPs and other allowances | W3: The amount of loss allowances that are held against or are allocated to the instrument on the reporting reference date. This data attribute applies to instruments subject to impairment under the applied accounting standard. Under IFRS, the accumulated impairment relates to the following amounts: (i) loss allowance at an amount equal to 12-month expected credit losses; (ii) loss allowance at an amount equal to lifetime expected credit losses. Under nGAAP, the accumulated impairment relates to the following amounts: (i) loss allowance at an amount equal to specific allowances; (ii) loss allowance at an amount equal to general allowances. | X3: Not applicable | Y3: N/A | Z3: - | AA3: Y | AB3: Y | AC3: Y | AD3: N | AE3: N | AF3: Y | AG3: Y | AH3: Y | AI3: Y | AJ3: Y | AK3: 0
A4: 3. Campos em testes ou c/ incidências | B4: IN.089 | C4: INSTRUMENT | D4: Impairment | E4: N | F4: ACCMLTD_IMPRMNT_INSTRMNT_PRVS | G4: Y | H4: Y | I4: Y | J4: Y | K4: Y | L4: Y | M4: Y | N4: Y | O4: N | P4: N | Q4: FLOAT 2 decimal places | R4: Use decimal point, no thousands seperator | S4: 99999999999 | T4: 11111111111 | U4: 11111111111 | V4: Previous sum of LLPs and other allowances | W4: The amount of loss allowances that are held against or are allocated to the instrument one year before the reference date, i.e. T-1. This data attribute applies to instruments subject to impairment under the applied accounting standard. Under IFRS, the accumulated impairment relates to the following amounts: (i) loss allowance at an amount equal to 12-month expected credit losses; (ii) loss allowance at an amount equal to lifetime expected credit losses. Under nGAAP, the accumulated impairment relates to the following amounts: (i) loss allowance at an amount equal to specific allowances; (ii) loss allowance at an amount equal to general allowances. | X4: Not applicable | Y4: N/A | Z4: - | AA4: Y | AB4: N | AC4: N | AD4: N | AE4: N | AF4: Y | AG4: N | AH4: N | AI4: Y | AJ4: Y | AK4: 0
A5: 6.1. Fora âmbito | Campos concluídos - Sem necessidade de espec. | B5: IN.090 | C5: INSTRUMENT | D5: Impairment | E5: Y | F5: ACCMLTD_WRTFFS_INSTRMNT | G5: N | H5: Y | I5: Y | J5: Y | K5: Y | L5: Y | M5: Y | N5: Y | O5: N | P5: N | Q5: FLOAT 2 decimal places | R5: Use decimal point, no thousands seperator | S5: 99999999999 | T5: 11111111111 | U5: 11111111111 | V5: Accumulated write-offs | W5: Cumulative amount of principal and past due interest of any debt instrument that the institution is no longer recognising because they are considered uncollectible, independently of the portfolio in which they were included. Write-offs could be caused both by reductions in the carrying amount of financial assets recognised directly in profit or loss and by reductions in the amounts of the allowance accounts for credit losses set off against the carrying amount of financial assets. | X5: Not applicable | Y5: N/A | Z5: - | AA5: Y | AB5: N | AC5: N | AD5: N | AE5: N | AF5: Y | AG5: N | AH5: N | AI5: Y | AJ5: Y | AK5: 0
A6: 6.1. Fora âmbito | Campos concluídos - Sem necessidade de espec. | B6: IN.062 | C6: INSTRUMENT | D6: Financial Information | E6: Y | F6: ACCNTNG_CLSSFCTN | G6: Y | H6: Y | I6: Y | J6: Y | K6: Y | L6: Y | M6: Y | N6: Y | O6: Y | P6: Y | Q6: =HYPERLINK("#"&"CodeList!"&ADDRESS(2,MATCH($F6,CodeList!$2:$2,0)+1,),"Code List") -> Code List | R6: Use codes from the code list sheet | S6: 99999999999 | T6: 11111111111 | U6: 11111111111 | V6: Accounting portfolio | W6: Accounting portfolio where the instrument is recorded in accordance with the accounting standard – IFRS or national GAAP – under Regulation (EU) 2015/534 (ECB/2015/13) applied by the observed agent’s legal entity. | X6: Not applicable | Y6: N/A | Z6: - | AA6: Y | AB6: Y | AC6: Y | AD6: N | AE6: N | AF6: Y | AG6: Y | AH6: Y | AI6: Y | AJ6: Y | AK6: 0
A7: 6.4. Fora âmbito | Re-especificação de campos complexos - Dem. Fin. CIB | B7: EN.018 | C7: ENTITY | D7: Classification | E7: Y | F7: ACCNTNG_FRMWRK_SL | G7: Y | H7: Y | I7: Y | J7: Y | K7: Y | L7: Y | M7: N | Q7: =HYPERLINK("#"&"CodeList!"&ADDRESS(2,MATCH($F7,CodeList!$2:$2,0)+1,),"Code List") -> Code List | R7: Use codes from the code list sheet | S7: 99999999999 | T7: 11111111111 | U7: 11111111111 | V7: Accounting standard counterparty | W7: Accounting standard counterparty. | X7: Not applicable | Y7: N/A | Z7: - | AA7: Y | AB7: N | AC7: N | AD7: N | AE7: N | AF7: Y | AG7: N | AH7: N | AI7: Y | AJ7: Y | AK7: 0
A8: 2.2 Re-especificação de campos complexos - Resto | B8: IN.063 | C8: INSTRUMENT | D8: Financial Information | E8: Y | F8: ACCRD_INTRST_INSTRMNT | G8: N | H8: Y | I8: Y | J8: Y | K8: Y | L8: Y | M8: Y | N8: Y | O8: N | P8: N | Q8: FLOAT 2 decimal places | R8: Use decimal point, no thousands seperator | S8: 99999999999 | T8: 11111111111 | U8: 11111111111 | V8: Accrued interest balance as recognised on the balance sheet | W8: The amount of accrued interest on loans at the reporting reference date as defined in Regulation (EU) No 1071/2013 (ECB/2013/33). In accordance with the general principle of accruals accounting, interest receivable on instruments should be subject to on-balance sheet recording as it accrues (i.e. on an accruals basis) rather than when it is actually received (i.e. on a cash basis). | X8: Yes - Equivalent | Y8: JM_CAMB_SIT_BDI - E0688_INTEDEV | Z8: - | AA8: Y | AB8: N | AC8: N | AD8: N | AE8: N | AF8: Y | AG8: N | AH8: N | AI8: Y | AJ8: Y | AK8: 0
A9: 0 | B9: EN.130 | C9: ENTITY | D9: General | E9: Y | F9: ADDRSS_CTY | G9: Y | H9: Y | I9: Y | J9: Y | K9: Y | L9: Y | M9: Y | Q9: VARCHAR2(255) | R9: Free (latin) text without special characters (semicolon, quotes, …) | S9: MISS | T9: N/A | U9: N/A | V9: Address: city/town/village | W9: Unit should report in this field the city, town or village of residence of the counterparty. | X9: Not applicable | Y9: N/A | AA9: Y | AB9: N | AC9: N | AD9: N | AE9: N | AF9: N | AG9: N | AH9: N | AI9: Y | AJ9: #N/A | AK9: 0
A10: 0 | B10: EN.131 | C10: ENTITY | D10: General | E10: Y | F10: ADDRSS_STRT | G10: Y | H10: Y | I10: Y | J10: Y | K10: Y | L10: Y | M10: Y | Q10: VARCHAR2(255) | R10: Free (latin) text without special characters (semicolon, quotes, …) | S10: MISS | T10: N/A | U10: N/A | V10: Address: street | W10: Unit should report in this field the street address of residence of the counterparty, including the street number. | X10: Not applicable | Y10: N/A | AA10: Y | AB10: N | AC10: N | AD10: N | AE10: N | AF10: N | AG10: N | AH10: N | AI10: Y | AJ10: #N/A | AK10: 0
A11: #N/A | B11: PR.060 | C11: PROTECTION | D11: Collateral Insurance | E11: N | F11: AMNT_CVRD_INSRNC | G11: N | H11: Y | I11: Y | J11: Y | K11: Y | L11: Y | M11: Y | Q11: FLOAT 2 decimal places | R11: Use decimal point, no thousands seperator | S11: 99999999999 | T11: 11111111111 | U11: 11111111111 | V11: Total amount covered by the insurance | W11: Total amount covered by the insurance. If the insurance covers more than one hazard, please report the sum up of all the amounts covered by the insurance | X11: Not applicable | Y11: N/A | Z11: - | AA11: N | AB11: N | AC11: N | AD11: N | AE11: Y | AF11: N | AG11: N | AH11: N | AI11: Y | AJ11: #N/A | AK11: 0
A12: 2.2 Re-especificação de campos complexos - Resto | B12: IN.064 | C12: INSTRUMENT | D12: Financial Information | E12: N | F12: AMNT_D_AT_MTRTY | G12: N | H12: Y | I12: Y | J12: Y | K12: Y | L12: Y | M12: Y | N12: N | O12: N | P12: N | Q12: FLOAT 2 decimal places | R12: Use decimal point, no thousands seperator | S12: 99999999999 | T12: 11111111111 | U12: 11111111111 | V12: Amount due at the legal final maturity date | W12: Total amount of principal repayment to be paid at the final legal maturity date (i.e. DT_LGL_FNL_MTRTY), i.e. amount of last instalment at maturity date. | X12: Not applicable | Y12: N/A | Z12: - | AA12: Y | AB12: N | AC12: N | AD12: N | AE12: N | AF12: Y | AG12: N | AH12: N | AI12: Y | AJ12: Y | AK12: 0
A13: 6.4. Fora âmbito | Re-especificação de campos complexos - Dem. Fin. CIB | B13: EN.051 | C13: ENTITY | D13: Financial Information | E13: Y | F13: ANNL_TRNVR_LE | G13: Y | H13: Y | I13: Y | J13: Y | K13: Y | L13: Y | M13: N | Q13: FLOAT 2 decimal places | R13: Use decimal point, no thousands seperator | S13: 99999999999 | T13: 11111111111 | U13: 11111111111 | V13: Annual turnover counterparty (LE) | W13: Annual sales volume net of all discounts and sales taxes in accordance with Recommendation 2003/361/EC. Equivalent to the concept of 'total annual sales' in Article 153(4) of Regulation (EU) No 575/2013. Please report on solo entity level unless advised otherwise. | X13: Not applicable | Y13: N/A | Z13: - | AA13: Y | AB13: N | AC13: Y | AD13: N | AE13: N | AF13: Y | AG13: N | AH13: Y | AI13: Y | AJ13: Y | AK13: 0
A14: 0 | B14: EN.086 | C14: ENTITY | D14: Financial Information | E14: N | F14: ANNL_TRNVR_LE_BDR | G14: Y | H14: Y | I14: Y | J14: Y | K14: Y | L14: Y | M14: N | Q14: FLOAT 2 decimal places | R14: Use decimal point, no thousands seperator | S14: 99999999999 | T14: 11111111111 | U14: 11111111111 | V14: BDR Annual turnover counterparty (LE) | W14: BDR Annual sales volume net of all discounts and sales taxes in accordance with Recommendation 2003/361/EC. Equivalent to the concept of 'total annual sales' in Article 153(4) of Regulation (EU) No 575/2013. Please report on solo entity level unless advised otherwise. | X14: Yes - Equivalent | Y14: JM_CLIEN_JURI - G5508_IMPFACTM | Z14: - | AA14: Y | AB14: N | AC14: N | AD14: N | AE14: N | AF14: N | AG14: N | AH14: N | AI14: Y | AJ14: #N/A | AK14: 0
A15: 6.4. Fora âmbito | Re-especificação de campos complexos - Dem. Fin. CIB | B15: EN.052 | C15: ENTITY | D15: Financial Information | E15: N | F15: ANNL_TRNVR_PRVS | G15: Y | H15: Y | I15: Y | J15: Y | K15: Y | L15: Y | M15: N | Q15: FLOAT 2 decimal places | R15: Use decimal point, no thousands seperator | S15: 99999999999 | T15: 11111111111 | U15: 11111111111 | V15: Annual turnover counterparty (LE) at previous reporting | W15: Annual sales volume net of all discounts and sales taxes in accordance with Recommendation 2003/361/EC. Equivalent to the concept of 'total annual sales' in Article 153(4) of Regulation (EU) No 575/2013. Please report on solo entity level unless advised otherwise. | X15: Not applicable | Y15: N/A | Z15: - | AA15: Y | AB15: N | AC15: N | AD15: N | AE15: N | AF15: Y | AG15: N | AH15: N | AI15: Y | AJ15: Y | AK15: 0
A16: 0 | B16: EN.087 | C16: ENTITY | D16: Financial Information | E16: N | F16: ANNL_TRNVR_PRVS_BDR | G16: Y | H16: Y | I16: Y | J16: Y | K16: Y | L16: Y | M16: N | Q16: FLOAT 2 decimal places | R16: Use decimal point, no thousands seperator | S16: 99999999999 | T16: 11111111111 | U16: 11111111111 | V16: BDR Annual turnover counterparty (LE) at previous reporting | W16: BDR Annual sales volume net of all discounts and sales taxes in accordance with Recommendation 2003/361/EC. Equivalent to the concept of 'total annual sales' in Article 153(4) of Regulation (EU) No 575/2013. Please report on solo entity level unless advised otherwise. | X16: Yes - Equivalent | Y16: JM_CLIEN_JURI - G5508_IMPFACTM | Z16: To be computed using the one at previous reporting | AA16: Y | AB16: N | AC16: N | AD16: N | AE16: N | AF16: N | AG16: N | AH16: N | AI16: Y | AJ16: #N/A | AK16: 0
A17: 0 | B17: IN.125 | C17: INSTRUMENT | D17: Interest Rates | E17: Y | F17: ANNLSD_AGRD_RT | G17: Y | H17: Y | I17: Y | J17: Y | K17: Y | L17: Y | M17: Y | N17: Y | O17: N | P17: N | Q17: FLOAT 6 decimal places | R17: Use decimal point, no thousands seperator | S17: 99999999999 | T17: 11111111111 | U17: 11111111111 | V17: Interest rate at the reference date | W17: Annualised agreed rate or narrowly defined interest rate in accordance with Regulation (EU) No 1072/2013 of the European Central Bank (ECB/2013/34). | X17: Yes - Equivalent | Y17: JM_CONTR_OTROS - E0623_TIP_INT | Z17: - | AA17: Y | AB17: N | AC17: Y | AD17: N | AE17: N | AF17: N | AG17: N | AH17: Y | AI17: Y | AJ17: N | AK17: 0
A18: #N/A | B18: PR.017 | C18: PROTECTION | D18: Appraisal | E18: N | F18: APPRSL_CRRNCY | G18: N | H18: Y | I18: Y | J18: Y | K18: Y | L18: Y | M18: Y | Q18: =HYPERLINK("#"&"CodeList!"&ADDRESS(2,MATCH($F18,CodeList!$2:$2,0)+1,),"Code List") -> Code List | R18: Use codes from the code list sheet | S18: MISS | T18: N/A | U18: N/A | V18: Appraisal currency | W18: Appraisal currency. | X18: Yes - Equivalent | Y18: JM_VAL_GARA - G4134_CODDIV | Z18: - | AA18: Y | AB18: N | AC18: N | AD18: N | AE18: N | AF18: N | AG18: N | AH18: N | AI18: Y | AJ18: N | AK18: 0
A19: #N/A | B19: PR.018 | C19: PROTECTION | D19: Appraisal | E19: N | F19: APPRSR | G19: N | H19: Y | I19: Y | J19: Y | K19: Y | L19: Y | M19: Y | Q19: VARCHAR2(255) | R19: Free (latin) text without special characters (semicolon, quotes, …) | S19: MISS | T19: N/A | U19: N/A | V19: Provider of latest valuation (appraiser) | W19: Name of the appraising company. If the bank carries out the appraisal itself report "Internal". | X19: Yes - Equivalent | Y19: JM_VAL_GARA - G4134_NOMENTI | Z19: - | AA19: Y | AB19: N | AC19: N | AD19: N | AE19: N | AF19: N | AG19: N | AH19: N | AI19: Y | AJ19: N | AK19: 0
A20: 4. Campos com NOK controlos Corporativos | B20: IN.091 | C20: INSTRUMENT | D20: Impairment | E20: Y | F20: ARRRS_INSTRMNT | G20: N | H20: Y | I20: Y | J20: Y | K20: Y | L20: Y | M20: Y | N20: Y | O20: N | P20: N | Q20: FLOAT 2 decimal places | R20: Use decimal point, no thousands seperator | S20: 99999999999 | T20: 11111111111 | U20: 11111111111 | V20: Total exposure in arrears | W20: Aggregated amount of the principal, interest and any fee payment outstanding at the reporting date, which is contractually due and has not been paid (past due). | X20: Not applicable | Y20: N/A | Z20: - | AA20: Y | AB20: N | AC20: N | AD20: N | AE20: N | AF20: Y | AG20: N | AH20: N | AI20: Y | AJ20: Y | AK20: 0
A21: 0 | B21: IN.092 | C21: INSTRUMENT | D21: Impairment | E21: N | F21: ARRRS_INSTRMNT_12M | G21: N | H21: Y | I21: Y | J21: Y | K21: Y | L21: Y | M21: Y | N21: Y | O21: N | P21: N | Q21: FLOAT 2 decimal places | R21: Use decimal point, no thousands seperator | S21: 99999999999 | T21: 11111111111 | U21: 11111111111 | V21: Highest total exposure in arrears in the last 12 months before the reference date | W21: Highest aggregated amount of the principal, interest and any fee payment outstanding at a period of 12 months before the reference date, which is contractually due and has not been paid (past due). | X21: Not applicable | Y21: N/A | Z21: - | AA21: Y | AB21: N | AC21: N | AD21: N | AE21: N | AF21: N | AG21: N | AH21: N | AI21: Y | AJ21: N | AK21: 0
A22: 0 | B22: IN.155 | C22: INSTRUMENT | D22: Security characteristics | E22: Y | F22: ASST_SCRT_CLSS | G22: N | H22: N | I22: N | J22: N | K22: N | L22: N | M22: N | N22: Y | O22: N | P22: N | Q22: =HYPERLINK("#"&"CodeList!"&ADDRESS(2,MATCH($F22,CodeList!$2:$2,0)+1,),"Code List") -> Code List | R22: Use codes from the code list sheet | S22: 99999999999 | T22: 11111111111 | U22: 11111111111 | V22: Asset securitisation class | W22: To be reported if the instrument is a securitisation or covered bond. | X22: Not applicable | Y22: N/A | Z22: - | AA22: Y | AB22: N | AC22: N | AD22: N | AE22: N | AF22: N | AG22: N | AH22: N | AI22: Y | AJ22: #N/A | AK22: 0
A23: 0 | B23: IN.196 | C23: INSTRUMENT | D23: Financial Information | E23: N | F23: AVRG_BLNC | G23: Y | H23: Y | I23: Y | J23: Y | K23: Y | L23: Y | M23: Y | N23: Y | O23: N | P23: Y | Q23: FLOAT 2 decimal places | R23: Use decimal point, no thousands seperator | S23: 99999999999 | T23: 11111111111 | U23: 11111111111 | V23: Average balance | W23: The average balance is a monthly data, which is calculated at instrument level as the average of daily balances of the instrument. | X23: Not applicable | Y23: N/A | Z23: - | AA23: N | AB23: Y | AC23: N | AD23: N | AE23: N | AF23: N | AG23: Y | AH23: Y | AI23: Y | AJ23: #N/A | AK23: 0
A24: 0 | B24: IN.210 | C24: INSTRUMENT | D24: Financial Information | E24: N | F24: AVRG_BLNC_OFF_BLNC | G24: Y | H24: Y | I24: Y | J24: Y | K24: Y | L24: Y | M24: Y | N24: N | O24: N | P24: Y | Q24: FLOAT 2 decimal places | R24: Use decimal point, no thousands seperator | S24: 99999999999 | T24: 11111111111 | U24: 11111111111 | V24: Average off balance | W24: The average off balance amount is a monthly data, which is calculated at instrument level as the average of daily off balances of the instrument. | X24: Not applicable | Y24: N/A | Z24: - | AA24: N | AB24: Y | AC24: N | AD24: N | AE24: N | AF24: N | AG24: Y | AH24: Y | AI24: Y | AJ24: #N/A | AK24: 0
A25: #N/A | B25: PR.064 | C25: PROTECTION | D25: Collateral Features | E25: N | F25: BLDNG_AR | G25: N | H25: Y | I25: Y | J25: Y | K25: Y | L25: Y | M25: Y | Q25: FLOAT 6 decimal places | R25: Use decimal point, no thousands seperator | S25: 99999999999 | T25: 11111111111 | U25: 11111111111 | V25: Building Area (M2) | W25: The area of the building in square metres. | X25: Not applicable | Y25: N/A | Z25: - | AA25: N | AB25: N | AC25: Y | AD25: N | AE25: Y | AF25: N | AG25: N | AH25: Y | AI25: Y | AJ25: #N/A | AK25: 0
A26: 0 | B26: IN.248 | C26: INSTRUMENT | D26: Accounting information | E26: Y | F26: BLNC_SHT_RCGNTN | G26: Y | H26: Y | I26: Y | J26: Y | K26: Y | L26: Y | M26: Y | N26: Y | O26: N | P26: N | Q26: =HYPERLINK("#"&"CodeList!"&ADDRESS(2,MATCH($F26,CodeList!$2:$2,0)+1,),"Code List") -> Code List | R26: Use codes from the code list sheet | S26: MISS | T26: N/A | U26: N/A | V26: Balance sheet recognition | W26: Balance sheet recognition of the financial asset. This data attribute classifies the reported instruments pursuant to their balance sheet recognition in accordance with Annex III and Template 15 in Annex IV to the ITS. | X26: Not applicable | Y26: N/A | Z26: - | AA26: Y | AB26: N | AC26: N | AD26: N | AE26: N | AF26: N | AG26: N | AH26: N | AI26: Y | AJ26: #N/A | AK26: 0
A27: 6.1. Fora âmbito | Campos concluídos - Sem necessidade de espec. | B27: IN.015 | C27: INSTRUMENT | D27: Classification | E27: N | F27: BRCHD_CVNNTS | G27: N | H27: N | I27: N | J27: N | K27: Y | L27: Y | M27: N | N27: N | O27: N | P27: N | Q27: VARCHAR2(255) | R27: Free (latin) text without special characters (semicolon, quotes, …) | S27: MISS | T27: N/A | U27: N/A | V27: Breached covenants | W27: Breached covenants separated by comma (,). | X27: Not applicable | Y27: N/A | Z27: - | AA27: Y | AB27: N | AC27: N | AD27: N | AE27: N | AF27: Y | AG27: N | AH27: N | AI27: Y | AJ27: Y | AK27: 0
A28: 0 | B28: IN.202 | C28: INSTRUMENT | D28: Classification | E28: N | F28: BSNSS_AREA | G28: Y | H28: Y | I28: Y | J28: Y | K28: Y | L28: Y | M28: Y | N28: Y | O28: N | P28: Y | Q28: Code List | R28: Use codes from the code list sheet | S28: MISS | T28: Default value not allowed | U28: N/A | V28: Business Area | W28: Business areas where the instrument falls according to Management Control segmentation | X28: Not applicable | Y28: N/A | Z28: - | AA28: N | AB28: Y | AC28: N | AD28: N | AE28: N | AF28: N | AG28: Y | AH28: Y | AI28: Y | AJ28: #N/A | AK28: 0
A29: 0 | B29: IN.222 | C29: INSTRUMENT | D29: Classification | E29: N | F29: BSNSS_AREA_CCRR | G29: Y | H29: Y | I29: Y | J29: Y | K29: Y | L29: Y | M29: Y | N29: Y | O29: N | P29: Y | Q29: Code List | R29: Use codes from the code list sheet | S29: MISS | T29: Default value not allowed | U29: N/A | V29: Business Area related to CIB | W29: Business areas where the instrument falls according to Management Control segmentation | X29: Not applicable | Y29: N/A | Z29: - | AA29: N | AB29: Y | AC29: N | AD29: N | AE29: N | AF29: N | AG29: Y | AH29: Y | AI29: Y | AJ29: #N/A | AK29: 0
A30: 0 | B30: IN.209 | C30: INSTRUMENT | D30: Classification | E30: N | F30: BSNSS_AREA_DSTNTN | G30: Y | H30: Y | I30: Y | J30: Y | K30: Y | L30: Y | M30: Y | N30: Y | O30: N | P30: Y | Q30: Code List | R30: Use codes from the code list sheet | S30: MISS | T30: N/A | U30: N/A | V30: Destination Business area | W30: Entity code of the business area to which interbusiness applies (business area destination) | X30: Not applicable | Y30: N/A | Z30: - | AA30: N | AB30: Y | AC30: N | AD30: N | AE30: N | AF30: N | AG30: Y | AH30: Y | AI30: Y | AJ30: #N/A | AK30: 0
A31: 0 | B31: EN.053 | C31: ENTITY | D31: Financial Information | E31: N | F31: CAPEX | G31: Y | H31: Y | I31: Y | J31: Y | K31: Y | L31: Y | M31: N | Q31: FLOAT 2 decimal places | R31: Use decimal point, no thousands seperator | S31: 99999999999 | T31: 11111111111 | U31: 11111111111 | V31: Capital expenditures at most recent reported figures | W31: Capital expenditures at most recent reported figures. Please report on solo entity level unless advised otherwise. | X31: Not applicable | Y31: N/A | Z31: - | AA31: Y | AB31: N | AC31: N | AD31: N | AE31: N | AF31: N | AG31: N | AH31: N | AI31: Y | AJ31: N | AK31: 0
A32: 0 | B32: EN.054 | C32: ENTITY | D32: Financial Information | E32: N | F32: CAPEX_PRVS | G32: Y | H32: Y | I32: Y | J32: Y | K32: Y | L32: Y | M32: N | Q32: FLOAT 2 decimal places | R32: Use decimal point, no thousands seperator | S32: 99999999999 | T32: 11111111111 | U32: 11111111111 | V32: Capital expenditures at previous reported figures | W32: Capital expenditures at previous reported figures. Please report on solo entity level unless advised otherwise. | X32: Not applicable | Y32: N/A | Z32: - | AA32: Y | AB32: N | AC32: N | AD32: N | AE32: N | AF32: N | AG32: N | AH32: N | AI32: Y | AJ32: N | AK32: 0
A33: 6.1. Fora âmbito | Campos concluídos - Sem necessidade de espec. | B33: IN.065 | C33: INSTRUMENT | D33: Financial Information | E33: N | F33: CCF | G33: Y | H33: Y | I33: Y | J33: Y | K33: Y | L33: Y | M33: Y | N33: N | O33: N | P33: N | Q33: FLOAT 6 decimal places | R33: Use decimal point, no thousands seperator | S33: 99999999999 | T33: 11111111111 | U33: 11111111111 | V33: Credit conversion factor (CCF) according to CRR | W33: Credit conversion factor according to regulation (EU) No 575/2013. | X33: Yes - Computed | Y33: IF Contract in JM_CTO_AJ_REG THEN O9209_K2; ELSE IF Contract in JM_AMP_AJ_STD THEN T0254_CCF_SFB; ELSE IF Contract in JM_SIM_AJ_STD THEN T0256_CCF_SFB | Z33: - | AA33: Y | AB33: Y | AC33: N | AD33: N | AE33: N | AF33: Y | AG33: Y | AH33: Y | AI33: Y | AJ33: Y | AK33: 0
A34: 0 | B34: IN.016 | C34: INSTRUMENT | D34: Classification | E34: N | F34: CHNNL_ORGNTN | G34: N | H34: Y | I34: Y | J34: Y | K34: Y | L34: Y | M34: Y | N34: N | O34: N | P34: N | Q34: =HYPERLINK("#"&"CodeList!"&ADDRESS(2,MATCH($F34,CodeList!$2:$2,0)+1,),"Code List") -> Code List | R34: Use codes from the code list sheet | S34: 99999999999 | T34: 11111111111 | U34: 11111111111 | V34: Channel of origination | W34: Description of the loan origination channel. | X34: Yes - Mapping | Y34: BDR - Code List | Z34: - | AA34: Y | AB34: N | AC34: N | AD34: N | AE34: N | AF34: N | AG34: N | AH34: N | AI34: Y | AJ34: N | AK34: 0
A35: 0 | B35: EN.055 | C35: ENTITY | D35: Financial Information | E35: N | F35: CLLCTN_MD | G35: N | H35: Y | I35: Y | J35: Y | K35: Y | L35: Y | M35: Y | Q35: =HYPERLINK("#"&"CodeList!"&ADDRESS(2,MATCH($F35,CodeList!$2:$2,0)+1,),"Code List") -> Code List | R35: Use codes from the code list sheet | S35: 99999999999 | T35: 11111111111 | U35: 11111111111 | V35: Collection mode | W35: Collection mode. Hard collection would be similar to foreclosure proceedings while soft collection means to call the collateral without any legal proceedings. | X35: Not applicable | Y35: N/A | Z35: - | AA35: Y | AB35: N | AC35: N | AD35: N | AE35: N | AF35: N | AG35: N | AH35: N | AI35: Y | AJ35: N | AK35: 0
A36: 0 | B36: IN.093 | C36: INSTRUMENT | D36: Impairment | E36: Y | F36: CMLTV_RCVRS_SNC_DFLT_INSTRMNT | G36: N | H36: Y | I36: Y | J36: Y | K36: Y | L36: Y | M36: Y | N36: Y | O36: N | P36: N | Q36: FLOAT 2 decimal places | R36: Use decimal point, no thousands seperator | S36: 99999999999 | T36: 11111111111 | U36: 11111111111 | V36: Cumulative recoveries since default | W36: The total amount recovered since the date of default. | X36: Not applicable | Y36: N/A | Z36: - | AA36: Y | AB36: N | AC36: N | AD36: N | AE36: N | AF36: N | AG36: N | AH36: N | AI36: Y | AJ36: N | AK36: 0
A37: 0 | B37: IN.066 | C37: INSTRUMENT | D37: Financial Information | E37: Y | F37: CMMTMNT_INCPTN_INSTRMNT | G37: N | H37: Y | I37: Y | J37: Y | K37: Y | L37: Y | M37: Y | N37: N | O37: N | P37: N | Q37: FLOAT 2 decimal places | R37: Use decimal point, no thousands seperator | S37: 99999999999 | T37: 11111111111 | U37: 11111111111 | V37: Commitment amount at inception | W37: Observed agent’s maximum exposure to credit risk on the inception date of the instrument, without taking into account any protection held or other credit enhancements. Total commitment amount on the inception date is established during the approval process and is intended to restrict an observed agent’s amount of credit risk to a given counterparty for the relevant instrument. | X37: Yes - Computed | Y37: E0623_IMP1LIMI at inception date (G4095_FECHAPER) | Z37: - | AA37: Y | AB37: N | AC37: N | AD37: N | AE37: N | AF37: N | AG37: N | AH37: N | AI37: Y | AJ37: N | AK37: 0
A38: 0 | B38: IN.067 | C38: INSTRUMENT | D38: Financial Information | E38: N | F38: CMMTMNT_INSTRMNT | G38: N | H38: Y | I38: Y | J38: Y | K38: Y | L38: Y | M38: Y | N38: N | O38: N | P38: N | Q38: FLOAT 2 decimal places | R38: Use decimal point, no thousands seperator | S38: 99999999999 | T38: 11111111111 | U38: 11111111111 | V38: Commitment amount at reference date | W38: Observed agent’s maximum exposure to credit risk on the reference date of the instrument, without taking into account any protection held or other credit enhancements. Total commitment amount on the reference date is established during the life cycle of the loan and is intended to restrict an observed agent’s amount of credit risk to a given counterparty for the relevant instrument. | X38: Not applicable | Y38: N/A | Z38: - | AA38: Y | AB38: N | AC38: N | AD38: N | AE38: N | AF38: N | AG38: N | AH38: N | AI38: Y | AJ38: N | AK38: 0
A39: 0 | B39: IN.145 | C39: INSTRUMENT | D39: COVID19 | E39: N | F39: CMPLNT_MRTR_C19_NM | G39: N | H39: N | I39: N | J39: N | K39: N | L39: Y | M39: Y | N39: N | O39: N | P39: N | Q39: VARCHAR2(255) | R39: Free (latin) text without special characters (semicolon, quotes, …) | S39: MISS | T39: N/A | U39: N/A | V39: Internal name of EBA compliant moratoria as registered by the bank. Please report all COVID-related measures until 31 December 2022. Afterwards, please report Not Applicable default value | W39: The name of the EBA compliant moratoria. EBA/GL/2020/07 Guidelines on reporting and disclosure of exposures subject to measures applied in response to the COVID-19 crisis. Data attribute shall be reported if not waived by the competent authority according to points (a), (c), (d) or (e) of Article 19 of EBA/GL/2020/07 Guidelines on reporting and disclosure of exposures subject to measures applied in response to the COVID-19 crisis. | X39: Yes - Computed | Y39: IF G7025_MOTRENUG in (26;27;28;29) THEN R8180_DESCBARL | Z39: It is necessary to identify the link between the global encoder and the local one | AA39: Y | AB39: N | AC39: N | AD39: N | AE39: N | AF39: N | AG39: N | AH39: N | AI39: Y | AJ39: Y | AK39: 0
A40: 0 | B40: IN.233 | C40: INSTRUMENT | D40: General | E40: N | F40: CNCLLD_INSTRMNT_STTS | G40: Y | H40: Y | I40: Y | J40: Y | K40: Y | L40: Y | M40: Y | N40: Y | O40: Y | P40: Y | Q40: =HYPERLINK("#"&"CodeList!"&ADDRESS(2,MATCH($F40,CodeList!$2:$2,0)+1,),"Code List") -> Code List | R40: Use codes from the code list sheet | S40: MISS | T40: Default value not allowed | U40: Default value not allowed | V40: Cancelled instrument status | W40: This field indicates if the instrument has been cancelled or not during the month of the reference date | X40: Not applicable | Y40: N/A | Z40: - | AA40: N | AB40: Y | AC40: N | AD40: N | AE40: N | AF40: N | AG40: Y | AH40: Y | AI40: Y | AJ40: #N/A | AK40: 0
...

Sheet Overview (2)
E1: Table | F1: Data field | G1: Efectivo y otros depósitos a la vista / Cash balances and other deposits | H1: Bancos Centrales / Central Banks | I1: Administraciones públicas / General governments | J1: Entidades de crédito / Credit institutions | K1: Otras sociedades financieras / Other financial corporations | L1: Sociedades no financieras / Non financial corporations | M1: Hogares / Households | N1: Data Types | O1: Field name | P1: Field Definition / Additional Guidance | R1: Default value for missing data | S1: Default value for not applicable fields to be used WHEN: (1) Non-contractual balances and accounting adjustments (2) If the field is not applicable for the corresponding segment (F to L columns)
C2: 6.1. Fora âmbito | Campos concluídos - Sem necessidade de espec. | E2: ENTITY | F2: COD_SOC | G2: Y | H2: Y | I2: Y | J2: Y | K2: Y | L2: Y | M2: Y | N2: VARCHAR2(5) | O2: Entity code of the informing society. | P2: Cargabal code or internal identifier of the informing society. | R2: Default value not allowed | S2: Default value not allowed | T2: #N/A | U2: 0
C3: 6.1. Fora âmbito | Campos concluídos - Sem necessidade de espec. | E3: ENTITY | F3: CNTRY | G3: Y | H3: Y | I3: Y | J3: Y | K3: Y | L3: Y | M3: Y | N3: =HYPERLINK("#"&"CodeList!"&ADDRESS(2,MATCH($F3,CodeList!$2:$2,0)+1,),"Code List") -> Code List | O3: Country of counterparty residence | P3: Country of counterparty residence. | R3: MISS | S3: N/A | T3: Y | U3: 0
C4: 5. Campos com outras possíveis alterações - Dependente de decisões OSI | E4: ENTITY | F4: DT_DFLT_STTS | G4: Y | H4: Y | I4: Y | J4: Y | K4: Y | L4: Y | M4: Y | N4: DATE | O4: Date of default status | P4: The date on which the default status, as reported in the data attribute “Default status”, is considered to have arisen. If "Not in default" since inception then this attribute is to be reported equally to the inception date. If default classification performed on instrument level then Entity is classified as defaulted when at least one instrument is classified as defaulted. If more than one Instrument is classified as defaulted then the earliest date has to be provided. The definition of default is aligned with Art 178 of Regulation (EU) No 575/2013. | R4: 0000-00-00 | S4: 1111-11-11 | T4: Y | U4: 0
C5: 6.4. Fora âmbito | Re-especificação de campos complexos - Dem. Fin. CIB | E5: ENTITY | F5: DT_FNNCL_STTMTS | G5: Y | H5: Y | I5: Y | J5: Y | K5: Y | L5: Y | M5: N | N5: DATE | O5: Date of financial statements | P5: Date of financial statements. Please report on solo entity level unless advised otherwise. | R5: 0000-00-00 | S5: 1111-11-11 | T5: Y | U5: 0
C6: 6.4. Fora âmbito | Re-especificação de campos complexos - Dem. Fin. CIB | E6: ENTITY | F6: DT_FNNCL_STTMTS_PRVS | G6: Y | H6: Y | I6: Y | J6: Y | K6: Y | L6: Y | M6: N | N6: DATE | O6: Date of previous fiscal year financial statements | P6: Date of previous fiscal year financial statements. Please report on solo entity level unless advised otherwise. | R6: 0000-00-00 | S6: 1111-11-11 | T6: Y | U6: 0
C7: 6.1. Fora âmbito | Campos concluídos - Sem necessidade de espec. | E7: ENTITY | F7: DT_INTTN_LGL_PRCDNGS_LE | G7: Y | H7: Y | I7: Y | J7: Y | K7: Y | L7: Y | M7: Y | N7: DATE | O7: Date of initiation of legal proceedings counterparty (LE) | P7: Date of initiation of legal proceedings counterparty (LE). Only for Retail portfolios: The date when the hard collection process was initiated for given entity. If the hard collection process is defined on the level of instrument or protection and more instruments or protections with status "Other legal measures" are linked to the same entity the oldest date is reported. | R7: 0000-00-00 | S7: 1111-11-11 | T7: Y | U7: 0
C8: 5. Campos com outras possíveis alterações - Dependente de decisões OSI | E8: ENTITY | F8: DT_PRFRMNG_STTS_LE | G8: Y | H8: Y | I8: Y | J8: Y | K8: Y | L8: Y | M8: Y | N8: DATE | O8: Date of performing status | P8: The date at which the latest change of the performing status according to Part 17 of Annex V to Implementing Regulation (EU) No 680/2014 occurred. For entities performing from inception this date should be equal to inception date. | R8: 0000-00-00 | S8: 1111-11-11 | T8: Y | U8: 0
C9: 6.1. Fora âmbito | Campos concluídos - Sem necessidade de espec. | E9: ENTITY | F9: DT_RFRNC | G9: Y | H9: Y | I9: Y | J9: Y | K9: Y | L9: Y | M9: Y | N9: DATE | O9: Reference date. | P9: Reference date. The reference date can refer to end-of-month, end-of-quarter or end-of-year. The value is fixed for the entire loan tape and will be defined and communicated by the Head of Mission. | R9: Default value not allowed | S9: Default value not allowed | T9: Y | U9: 0
C10: 4. Campos com NOK controlos Corporativos | E10: ENTITY | F10: ENTTY_ID | G10: Y | H10: Y | I10: Y | J10: Y | K10: Y | L10: Y | M10: Y | N10: VARCHAR2(255) | O10: Entity ID | P10: An identifier applied by the reporting agent to uniquely identify each counterparty. Each counterparty has a unique and exclusive counterparty identifier. This means that this value will not change over time and can never be used as the counterparty identifier for any other counterparty. | R10: Default value not allowed | S10: Default value not allowed | T10: Y | U10: 0
C11: 6.1. Fora âmbito | Campos concluídos - Sem necessidade de espec. | E11: ENTITY | F11: GCC_PRNT_ID | G11: Y | H11: Y | I11: Y | J11: Y | K11: Y | L11: Y | M11: N | N11: VARCHAR2(255) | O11: Identifier for the parent entity of a group of connected clients | P11: The unique identifier of the group of connected clients according to Art 4 para. 39 of Regulation (EU) No 575/2013. If an entity is part of more than one group of connected clients please report the identifier for the most relevant. | R11: MISS | S11: N/A | T11: Y | U11: 0
C12: 6.1. Fora âmbito | Campos concluídos - Sem necessidade de espec. | E12: ENTITY | F12: GCC_PRNT_NM | G12: Y | H12: Y | I12: Y | J12: Y | K12: Y | L12: Y | M12: N | N12: VARCHAR2(255) | O12: Name of the parent entity of a group of connected clients | P12: The name of the group of connected clients according to Art 4 para. 39 of Regulation (EU) No 575/2013. If an entity is part of more than one group of connected clients please report the name for the most relevant. | R12: MISS | S12: N/A | T12: Y | U12: 0
C13: 6.1. Fora âmbito | Campos concluídos - Sem necessidade de espec. | E13: ENTITY | F13: INTRNL_SGMNT | G13: Y | H13: Y | I13: Y | J13: Y | K13: Y | L13: Y | M13: Y | N13: VARCHAR2(255) | O13: Internal code for segment/portfolio | P13: Internal classification of the bank. Segmentation of the counterpart according to bank-internal definition / nomenclature, e.g. corporate, sme, leverage finance exposure, commercial real estate spv etc.. | R13: MISS | S13: N/A | T13: Y | U13: 0
C14: 6.1. Fora âmbito | Campos concluídos - Sem necessidade de espec. | E14: ENTITY | F14: INTRNL_UNT | G14: Y | H14: Y | I14: Y | J14: Y | K14: Y | L14: Y | M14: Y | N14: VARCHAR2(255) | O14: Internal code for business line/unit | P14: Internal classification of the bank of the obligor administrating business unit, e.g. if the obligor has been transferred to the intensified loan management department it should be flagged as such. | R14: MISS | S14: N/A | T14: Y | U14: 0
C15: 6.1. Fora âmbito | Campos concluídos - Sem necessidade de espec. | E15: ENTITY | F15: LEI | G15: Y | H15: Y | I15: Y | J15: Y | K15: Y | L15: Y | M15: N | N15: VARCHAR2(20) | O15: Legal entity identifier Counterparty | P15: Legal entity identifier counterparty. | R15: MISS | S15: N/A | T15: Y | U15: 0
... C17: 2.2 Re-especificação de campos complexos - Resto | E17: ENTITY | F17: EXTRNL_RTNG_NM | G17: Y | H17: Y | I17: Y | J17: Y | K17: Y | L17: Y | M17: N | N17: VARCHAR2(255) | O17: Name of external rating agency | P17: Name of external rating agency for the external rating at the reference date. | R17: MISS | S17: N/A | T17: Y | U17: 0
C18: 6.4. Fora âmbito | Re-especificação de campos complexos - Dem. Fin. CIB | E18: ENTITY | F18: ACCNTNG_FRMWRK_SL | G18: Y | H18: Y | I18: Y | J18: Y | K18: Y | L18: Y | M18: N | N18: =HYPERLINK("#"&"CodeList!"&ADDRESS(2,MATCH($F18,CodeList!$2:$2,0)+1,),"Code List") -> Code List | O18: Accounting standard counterparty | P18: Accounting standard counterparty. | R18: 99999999999 | S18: 11111111111 | T18: Y | U18: 0
C19: 5. Campos com outras possíveis alterações - Dependente de decisões OSI | E19: ENTITY | F19: DFLT_STTS | G19: Y | H19: Y | I19: Y | J19: Y | K19: Y | L19: Y | M19: Y | N19: =HYPERLINK("#"&"CodeList!"&ADDRESS(2,MATCH($F19,CodeList!$2:$2,0)+1,),"Code List") -> Code List | O19: Default status of the entity | P19: Identification of the default status of the counterparty. Categories describing the motives for which the counterparty can be in default in accordance with Article 178 of Regulation (EU) No 575/2013. For retail only: If default classification performed on instrument level then Entity is classified as defaulted when at least one instrument is classified as defaulted. For corporate, SME, CRE and LF: if default classification performed on instrument level then entity level is "not applicable". | R19: 99999999999 | S19: 11111111111 | T19: Y | U19: 0
C20: 2.2 Re-especificação de campos complexos - Resto | E20: ENTITY | F20: DT_EXTRNL_RTNG | G20: Y | H20: Y | I20: Y | J20: Y | K20: Y | L20: Y | M20: N | N20: DATE | O20: Date of external rating | P20: Date of the most recent external rating, i.e. applicable at the reference date. | R20: 0000-00-00 | S20: 1111-11-11 | T20: Y | U20: 0
C21: 3. Campos em testes ou c/ incidências | E21: ENTITY | F21: DT_INTRNL_RTNG | G21: Y | H21: Y | I21: Y | J21: Y | K21: Y | L21: Y | M21: Y | N21: DATE | O21: Date of internal rating | P21: Date of the most recent internal rating according to Regulation (EU) No 575/2013, i.e. applicable rating as at the reference date. If the rating is assigned on instrument level then provide the rating for the instrument with the highest EAD. | R21: 0000-00-00 | S21: 1111-11-11 | T21: Y | U21: 0
C22: 6.1. Fora âmbito | Campos concluídos - Sem necessidade de espec. | E22: ENTITY | F22: ECNMC_ACTVTY | G22: N | H22: N | I22: N | J22: N | K22: Y | L22: Y | M22: N | N22: Code List | O22: Economic activity counterparty | P22: The level four NACE code in accordance with Regulation (EC) No 1893/2006 is generally reported. If the level four NACE code is not available it may be allowed to report a level three or level two NACE code. | R22: MISS | S22: N/A | T22: Y | U22: 0
C23: 2.2 Re-especificação de campos complexos - Resto | E23: ENTITY | F23: EXTRNL_RTNG | G23: Y | H23: Y | I23: Y | J23: Y | K23: Y | L23: Y | M23: N | N23: Code List | O23: External rating | P23: External rating at the reference date. | R23: 99999999999 | S23: 11111111111 | T23: Y | U23: 0
C24: 2.2 Re-especificação de campos complexos - Resto | E24: ENTITY | F24: EXTRNL_RTNG_PRVS | G24: Y | H24: Y | I24: Y | J24: Y | K24: Y | L24: Y | M24: N | N24: Code List | O24: External rating T-1 | P24: External rating one year prior to the reference date. | R24: 99999999999 | S24: 11111111111 | T24: Y | U24: 0
C25: 6.1. Fora âmbito | Campos concluídos - Sem necessidade de espec. | E25: ENTITY | F25: FLG_RQST_EMRGNCY_FNDNG | G25: N | H25: N | I25: N | J25: N | K25: Y | L25: Corporation | M25: Corporation | N25: Y, N | O25: Request by the debtor for emergency funding from the bank | P25: Report "Y" if there is a request by the debtor for emergency funding from the bank. | R25: MISS | S25: N/A | T25: Y | U25: 0
C26: 3. Campos em testes ou c/ incidências | E26: ENTITY | F26: INTRNL_RTNG | G26: Y | H26: Y | I26: Y | J26: Y | K26: Y | L26: Y | M26: Y | N26: =HYPERLINK("#"&"CodeList!"&ADDRESS(2,MATCH($F26,CodeList!$2:$2,0)+1,),"Code List") -> Code List | O26: Internal rating at reference date | P26: Internal rating at the reference date according to Regulation (EU) No 575/2013. Please also add in sheet "Code List" the list of values used, i.e. bank-internal masterscale. | R26: MISS | S26: N/A | T26: Y | U26: 0
C27: 3. Campos em testes ou c/ incidências | E27: ENTITY | F27: INTRNL_RTNG_PRVS | G27: Y | H27: Y | I27: Y | J27: Y | K27: Y | L27: Y | M27: Y | N27: =HYPERLINK("#"&"CodeList!"&ADDRESS(2,MATCH($F27,CodeList!$2:$2,0)+1,),"Code List") -> Code List | O27: Previous internal rating | P27: Internal rating according to Regulation (EU) No 575/2013 one year prior to the reference date. | R27: MISS | S27: N/A | T27: Y | U27: 0
C28: 4. Campos com NOK controlos Corporativos | E28: ENTITY | F28: LGL_PRCDNG_STTS_LE | G28: Y | H28: Y | I28: Y | J28: Y | K28: Y | L28: Y | M28: Y | N28: =HYPERLINK("#"&"CodeList!"&ADDRESS(2,MATCH($F28,CodeList!$2:$2,0)+1,),"Code List") -> Code List | O28: Legal proceedings status Counterparty (LE) | P28: Legal proceedings status Counterparty (LE). Only for Retail portfolios: Status "No legal action taken" or "Other legal measures" are possible. Status "Other legal measures" is reported when the hard collection process was initiated at the level of a given entity or at the level of any associated instrument or protection of this entity. | R28: 99999999999 | S28: Default value not allowed | T28: Y | U28: 0
C29: 6.3. Fora âmbito | Fonte Manual LF | E29: ENTITY | F29: OWND_BY_SPNSR | G29: N | H29: N | I29: N | J29: N | K29: Y | L29: Y | M29: N | N29: Y, N | O29: >50% owned by a sponsor as per ECB Guidance on leveraged transactions | P29: In accordance the ECB Guidance on Leveraged Transactions. As per point (37) of Article 4(1) of Regulation (EU) No 575/2013, a financial sponsor is deemed to be the owner if it controls or owns more than 50% of the borrower’s equity. The term “financial sponsor” refers to an investment firm that undertakes private equity investments in and/or leveraged buyouts of companies with the intention of exiting those investments on a mediumterm basis | R29: MISS | S29: N/A | T29: Y | U29: 0
C30: 6.1. Fora âmbito | Campos concluídos - Sem necessidade de espec. | E30: ENTITY | F30: PRFRMNG_STTS_LE | G30: Y | H30: Y | I30: Y | J30: Y | K30: Y | L30: Y | M30: Y | N30: =HYPERLINK("#"&"CodeList!"&ADDRESS(2,MATCH($F30,CodeList!$2:$2,0)+1,),"Code List") -> Code List | O30: Performing status | P30: Performing status. Identification of the performing status of the counterparty. Categories describing the motives for which the counterparty can be non-performing in accordance with Implementing Technical Standard (ITS) on Supervisory Reporting (Forbearance and non-performing exposures). For retail only: If performing classification performed on instrument level then Entity is classified as non-performing when at least one instrument is classified as non-performing For corporate, SME, CRE and LF: if default classification performed on instrument level then entity level is "not applicable". | R30: 99999999999 | S30: 11111111111 | T30: Y | U30: 0
C31: 3. Campos em testes ou c/ incidências | E31: ENTITY | F31: RTNG_MTHD | G31: Y | H31: Y | I31: Y | J31: Y | K31: Y | L31: Y | M31: Y | N31: =HYPERLINK("#"&"CodeList!"&ADDRESS(2,MATCH($F31,CodeList!$2:$2,0)+1,),"Code List") -> Code List | O31: Rating method | P31: Internal definition and name of the rating/scoring model. | R31: 99999999999 | S31: 11111111111 | T31: Y | U31: 0
C32: 6.1. Fora âmbito | Campos concluídos - Sem necessidade de espec. | E32: ENTITY | F32: RTNG_SCL | G32: Corporation | H32: Corporation | I32: Corporation | J32: Corporation | K32: Corporation | L32: Corporation | M32: Corporation | N32: =HYPERLINK("#"&"CodeList!"&ADDRESS(2,MATCH($F32,CodeList!$2:$2,0)+1,),"Code List") -> Code List | O32: Rating scale | P32: Internal name and definition of the rating master scale. It should be mapped to the assigned rating, i.e. INTRNL_RTNG. | R32: 99999999999 | S32: 11111111111 | T32: Y | U32: 0
C33: 6.1. Fora âmbito | Campos concluídos - Sem necessidade de espec. | E33: ENTITY | F33: WTCH_LST | G33: N | H33: Y | I33: Y | J33: Y | K33: Y | L33: Y | M33: Y | N33: Y, N | O33: Debtor on watch-list (Y/N) | P33: Report "Y" when the debtor has been added to an internal watch list. | R33: MISS | S33: N/A | T33: Y | U33: 0
C34: 6.1. Fora âmbito | Campos concluídos - Sem necessidade de espec. | E34: ENTITY | F34: GRP_EBITDA | G34: Y | H34: Y | I34: Y | J34: Y | K34: Y | L34: Y | M34: N | N34: FLOAT 2 decimal places | O34: Group's EBITDA at most recent reported figures | P34: EBITDA at latest reported figures. Please report level of the consolidated financial statement of the group accoding to the applicable accounting standard. | R34: 99999999999 | S34: 11111111111 | T34: Y | U34: 0
C35: 6.1. Fora âmbito | Campos concluídos - Sem necessidade de espec. | E35: ENTITY | F35: GRP_EQTY | G35: Y | H35: Y | I35: Y | J35: Y | K35: Y | L35: Y | M35: N | N35: FLOAT 2 decimal places | O35: Group's equity at most recent reported figures | P35: Equity at most recent reported figures. Please report level of the consolidated financial statement of the group accoding to the applicable accounting standard. | R35: 99999999999 | S35: 11111111111 | T35: Y | U35: 0
C36: 6.1. Fora âmbito | Campos concluídos - Sem necessidade de espec. | E36: ENTITY | F36: GRP_NT_DBT | G36: Y | H36: Y | I36: Y | J36: Y | K36: Y | L36: Y | M36: N | N36: FLOAT 2 decimal places | O36: Total net debt at most recent reported figures | P36: Total net debt at most recent reported figures. Please report level of the consolidated financial statement of the group accoding to the applicable accounting standard. | R36: 99999999999 | S36: 11111111111 | T36: Y | U36: 0
C37: 6.4. Fora âmbito | Re-especificação de campos complexos - Dem. Fin. CIB | E37: ENTITY | F37: ANNL_TRNVR_LE | G37: Y | H37: Y | I37: Y | J37: Y | K37: Y | L37: Y | M37: N | N37: FLOAT 2 decimal places | O37: Annual turnover counterparty (LE) | P37: Annual sales volume net of all discounts and sales taxes in accordance with Recommendation 2003/361/EC. Equivalent to the concept of 'total annual sales' in Article 153(4) of Regulation (EU) No 575/2013. Please report on solo entity level unless advised otherwise. | R37: 99999999999 | S37: 11111111111 | T37: Y | U37: 0
C38: 6.4. Fora âmbito | Re-especificação de campos complexos - Dem. Fin. CIB | E38: ENTITY | F38: ANNL_TRNVR_PRVS | G38: Y | H38: Y | I38: Y | J38: Y | K38: Y | L38: Y | M38: N | N38: FLOAT 2 decimal places | O38: Annual turnover counterparty (LE) at previous reporting | P38: Annual sales volume net of all discounts and sales taxes in accordance with Recommendation 2003/361/EC. Equivalent to the concept of 'total annual sales' in Article 153(4) of Regulation (EU) No 575/2013. Please report on solo entity level unless advised otherwise. | R38: 99999999999 | S38: 11111111111 | T38: Y | U38: 0
C39: 6.4. Fora âmbito | Re-especificação de campos complexos - Dem. Fin. CIB | E39: ENTITY | F39: EBITDA | G39: Y | H39: Y | I39: Y | J39: Y | K39: Y | L39: Y | M39: N | N39: FLOAT 2 decimal places | O39: EBITDA at latest reported figures | P39: EBITDA at latest reported figures. Please report on solo entity level unless advised otherwise. | R39: 99999999999 | S39: 11111111111 | T39: Y | U39: 0
C40: 6.4. Fora âmbito | Re-especificação de campos complexos - Dem. Fin. CIB | E40: ENTITY | F40: EBITDA_PRVS | G40: Y | H40: Y | I40: Y | J40: Y | K40: Y | L40: Y | M40: N | N40: FLOAT 2 decimal places | O40: EBITDA at previous reported figures | P40: EBITDA at previous reported figures. Please report on solo entity level unless advised otherwise. | R40: 99999999999 | S40: 11111111111 | T40: Y | U40: 0
C41: 6.4. Fora âmbito | Re-especificação de campos complexos - Dem. Fin. CIB | E41: ENTITY | F41: EQTY | G41: Y | H41: Y | I41: Y | J41: Y | K41: Y | L41: Y | M41: N | N41: FLOAT 2 decimal places | O41: Equity at most recent reported figures | P41: Equity at most recent reported figures. Please report on solo entity level unless advised otherwise. | R41: 99999999999 | S41: 11111111111 | T41: Y | U41: 0
...

Sheet CodeList
A1: Table | B1: INSTRUMENT | D1: INSTRUMENT / ENTITY | F1: INSTRUMENT / PROTECTION | H1: INSTRUMENT | J1: INSTRUMENT | L1: PROTECTION | N1: PROTECTION | P1: INSTRUMENT | R1: INSTRUMENT | T1: INSTRUMENT | V1: INSTRUMENT | X1: INSTRUMENT | Z1: INSTRUMENT | AB1: INSTRUMENT | AD1: INSTRUMENT | AF1: INSTRUMENT | AH1: INSTRUMENT | AJ1: INSTRUMENT | AL1: INSTRUMENT / ENTITY | AN1: INSTRUMENT / ENTITY | AP1: INSTRUMENT | AR1: INSTRUMENT | AT1: INSTRUMENT | AV1: INSTRUMENT | AX1: INSTRUMENT | AZ1: INSTRUMENT | BB1: INSTRUMENT | BD1: INSTRUMENT | BF1: INSTRUMENT | BH1: INSTRUMENT | BJ1: INSTRUMENT | BL1: INSTRUMENT | BN1: INSTRUMENT | BP1: INSTRUMENT | BR1: INSTRUMENT | BT1: ENTITY | BV1: PROTECTION | BX1: PROTECTION | BZ1: PROTECTION | CB1: PROTECTION | CD1: PROTECTION | CF1: PROTECTION | CH1: ENTITY | CJ1: ENTITY | CL1: ENTITY | CN1: ENTITY | CP1: ENTITY | CR1: ENTITY | CT1: ENTITY | CV1: ENTITY | CX1: ENTITY | CZ1: ENTITY | DB1: ENTITY | DD1: INSTRUMENT / ENTITY | DF1: INSTRUMENT | DH1: ENTITY | DJ1: INSTRUMENT / ENTITY | DL1: ENTITY | DN1: INSTRUMENT_C19 | DP1: INSTRUMENT_C19 | DR1: INSTRUMENT_C19 | DT1: INSTRUMENT_C19 | DV1: INSTRUMENT | DX1: INSTRUMENT | DZ1: INSTRUMENT | EB1: INSTRUMENT | ED1: INSTRUMENT | EF1: INSTRUMENT | EH1: INSTRUMENT | EJ1: INSTRUMENT | EL1: INSTRUMENT | EN1: INSTRUMENT | EP1: INSTRUMENT | ER1: INSTRUMENT | ET1: INSTRUMENT | EV1: INSTRUMENT | EX1: INSTRUMENT | EZ1: INSTRUMENT | FB1: INSTRUMENT | FD1: INSTRUMENT | FF1: INSTRUMENT | FH1: PROTECTION | FJ1: PROTECTION | FL1: PROTECTION | FN1: PROTECTION | FP1: ENTITY | FR1: INSTRUMENT | FT1: INSTRUMENT | FV1: INSTRUMENT | GC1: INSTRUMENT | GE1: INSTRUMENT | GG1: INSTRUMENT | GI1: INSTRUMENT | GK1: INSTRUMENT | GQ1: INSTRUMENT | GS1: PROTECTION | HA1: PROTECTION | HC1: PROTECTION | HE1: INSTRUMENT | HG1: ENTITY | HI1: INSTRUMENT | HK1: INSTRUMENT | HM1: INSTRUMENT | HO1: INSTRUMENT | HQ1: INSTRUMENT | HS1: INSTRUMENT | HU1: INSTRUMENT | HW1: INSTRUMENT | HY1: INSTRUMENT - PROTECTION
A2: Data field | B2: ACCNTNG_CLSSFCTN | D2: CHNNL_ORGNTN | F2: CRRNCY_DNMNTN | H2: CPN_CRRNCY | J2: VLTN_CRRNCY | L2: APPRSL_CRRNCY | N2: CRE_INCM_CRRNCY | P2: CVNNT_STTS | R2: CVNNT_TYP | T2: DFLT_STTS_INSTRMNT | V2: PRFRMNG_STTS | X2: PRFRMNG_STTS_PRVS | Z2: FRBRNC_STTS_INSTRMNT | AB2: IMPRMNT_STTS | AD2: IMPRMNT_STTS_PRVS | AF2: IMPRMNT_ASSSSMNT_MTHD | AH2: IMPRMNT_CLCLTN_MTHD | AJ2: INTRST_RT_RST_FRQNCY | AL2: LGL_PRCDNG_STTS | AN2: LGL_PRCDNG_STTS_LE | AP2: PRJCT_FNNC_LN | AR2: PRPS | AT2: PYMNT_FRQNCY | AV2: RCRS | AX2: RWA_MTHD | AZ2: SICR_ASSSSMNT_MTHD | BB2: STTS_UNDRWRTTN_TRNSCTN | BD2: SYNDCT_RL | BF2: SYNDCTN_TYP | BH2: TRNCH | BJ2: TYP_AMRTSTN | BL2: TYP_CRE_OPRTN | BN2: TYP_INSTRMNT | BP2: TYP_INTRST_RT | BR2: TYP_MRTGG | BT2: EXTRNL_RTNG / EXTRNL_RTNG_PRVS / ISSR_RTNG | BV2: CNSTRCTN_STTS | BX2: DVLPMNT_STTS | BZ2: MN_PRPS | CB2: PRTCTN_VLTN_APPRCH | CD2: TYP_PRTCTN | CF2: TYP_PRTCTN_VL | CH2: ACCNTNG_FRMWRK_SL | CJ2: CLLCTN_MD | CL2: CNTRY | CN2: RL_ESTT_CLLTRL_LCTN | CP2: CNTRY/RL_ESTT_CLLTRL_LCTN | CR2: DFLT_STTS | CT2: ECNMC_ACTVTY/GRP_ECNMC_ACTVTY/ISSR_NACE_SCTR/NACE_ESG | CV2: EMPLYMNT_STTS | CX2: ENTRPRS_SZ_LE | CZ2: PRFRMNG_STTS_LE | DB2: RTNG_MTHD | DD2: INTRNL_RTNG | DF2: INTRNL_RTNG_INCPTN | DH2: INTRNL_RTNG_PRVS | DJ2: RTNG_SCL | DL2: SNGL_PRPS_VHCL | DN2: EBA_CMPLNT_MRTR_ST_C19 | DP2: TYP_CMPLNT_MRTR_C19 | DR2: FRBRNC_STTS_C19 | DT2: SBJCT_PBLC_GRNT_SCHM_C19 | DV2: ISSR_ID_TYP | DX2: GRNTR_ID_TYP | DZ2: ISSR_CNTRY | EB2: ISSR_ESA_2010 | ED2: ISSR_RTNG | EF2: ISSR_TYP | EH2: VLTN_TYP | EJ2: INSTRMNT_CLSS | EL2: PRMRY_ASST_CLSSF | EN2: ASST_SCRT_CLSS | EP2: TYPE_OF_PLCMNT | ER2: INSTR_SNRTY_CLSS | ET2: SRCS_ENCMBRNC | EV2: LCR_BFFR_CTGRY | EX2: PRDNTL_PRTFL | EZ2: INTRNL_SGMNT_CAT_MSTA | FB2: INTRNL_SGMNT_CATGSUB | FD2: RSK_MTGTD_CCT | FF2: RSK_MTGTD_CCP | FH2: TYP_EP_SCR/TYP_EMSSNS_SCR | FJ2: EP_SCR | FL2: TYP_LBL/TYP_EMSSNS_LBL/TYP_EPC_LBL | FN2: EPC_LBL/EPC_EMSSNS_LBL | FP2: ESG_SBSCTR | FR2: BSNSS_AREA/BSNSS_AREA_DSTNTN/BSNN_AREA_CIB/BSNSS_AREA_CCRR | FT2: SSTNBL_CTGRY_TXNMY | FV2: SSTNBL_CTGRY | GC2: MNGMNT_PRDCT | GE2: ENVRNMNTL_OBJCTV | GG2: TYP_ACTVTY | GK2: LNS_CLLTRLZD_CLSSFCTN | GM2: INTRBSNSS_ADJ_COD | GO2: TYP_VHCL | GQ2: MTHD_USD_INSTRMNT_SCP_1 / MTHD_USD_INSTRMNT_SCP_2 / MTHD_USD_INSTRMNT_SCP_3 | GS2: MTHD_USD_PRTCTN_SCP_1 / MTHD_USD_PRTCTN_SCP_2 / MTHD_USD_PRTCTN_SCP_3 | GU2: RL_ESTT_CRTFCTN | GW2: DNSH_DTL | GY2: SSTNBL_INDCTR | HA2: TYP_HZRDS_INSRD | HC2: VHCL_EMSSNS_LBL | HE2: CNCLLD_INSTRMNT_STTS | HG2: PRSN_TYP | HI2: RFRNC_RT | HK2: TYP_SCRTZTN | HM2: TYP_OFF_BLNC_PRDCT | HO2: BLNC_SHT_RCGNTN | HQ2: EXCLDD_LF | HS2: US_PRCDS | HU2: TYP_FCLTY | HW2: TYP_CL | HY2: TYP_RLTN | IA2: RL_ESTT_CLMT_ZN | IC2: s | IE2: TYP_DL | IG2: DSTNTN_FNDS
DD3: The rating collected in local databases should be reported. | DF3: The rating collected in local databases should be reported. | DH3: The rating collected in local databases should be reported. | DJ3: to be populated by Corporation
