Workbook
Name asefadf: #REF!
Name asefadf: #REF!
Name asefadf: #REF!
Name asefadf: #REF!
Name asefadf: #REF!
Name bn: #REF!
Name bn: #REF!

Sheet PlanoV1.0
H1: =I1/8/5 -> 68.2 | I1: =SUM(J1:AF1) -> 2728 | K1: =K4*8*5 -> 124 | L1: =L4*8*5 -> 124 | M1: =M4*8*5 -> 124 | N1: =N4*8*5 -> 124 | O1: =O4*8*5 -> 124 | P1: =P4*8*5 -> 124 | Q1: =Q4*8*5 -> 124 | R1: =R4*8*5 -> 124 | ... BU1: =BU4*8*5 -> 84
I2: VAL | K2: =K3-K4 -> 0 | L2: =L3-L4 -> 0 | M2: =M3-M4 -> 0 | N2: =N3-N4 -> 0 | O2: =O3-O4 -> 0 | P2: =P3-P4 -> 0 | Q2: =Q3-Q4 -> 0 | R2: =R3-R4 -> 0 | ... BA2: =BA3-BA4 -> 0 | BC2: =BC3-BC4 -> 0 | BD2: =BD3-BD4 -> 0 | BE2: =BE3-BE4 -> 0 | BF2: =BF3-BF4 -> 0 | BG2: =BG3-BG4 -> 0 | BH2: =BH3-BH4 -> 0 | BI2: =BI3-BI4 -> 0 | BJ2: =BJ3-BJ4 -> 0 | ... BU2: =BU3-BU4 -> 0
I3: FTE REAIS | K3: =SUM(K9:K226) -> 3.1 | L3: =SUM(L9:L226) -> 3.1 | M3: =SUM(M9:M226) -> 3.1 | N3: =SUM(N9:N226) -> 3.1 | O3: =SUM(O9:O226) -> 3.1 | P3: =SUM(P9:P226) -> 3.1 | Q3: =SUM(Q9:Q226) -> 3.1 | R3: =SUM(R9:R226) -> 3.1 | ... BA3: =SUM(BA9:BA226) -> 2.1 | BC3: =SUM(BC9:BC226) -> 2.1 | BD3: =SUM(BD9:BD226) -> 2.1 | BE3: =SUM(BE9:BE226) -> 2.1 | BF3: =SUM(BF9:BF226) -> 2.1 | BG3: =SUM(BG9:BG226) -> 2.1 | BH3: =SUM(BH9:BH226) -> 2.1 | BI3: =SUM(BI9:BI226) -> 2.1 | BJ3: =SUM(BJ9:BJ226) -> 2.1 | ... BU3: =SUM(BU9:BU226) -> 2.1
I4: FTE ESP. | K4: 3.1 | L4: 3.1 | M4: 3.1 | N4: 3.1 | O4: 3.1 | P4: 3.1 | Q4: 3.1 | R4: 3.1 | S4: 3.1 | T4: 3.1 | U4: 3.1 | V4: 3.1 | W4: 3.1 | X4: 3.1 | Y4: 3.1 | Z4: 3.1 | AA4: 3.1 | AB4: 3.1 | AC4: 3.1 | AD4: 3.1 | AE4: 3.1 | AF4: 3.1 | AG4: 2.1 | AH4: 2.1 | AI4: 2.1 | AJ4: 2.1 | AK4: 2.1 | AL4: 2.1 | AM4: 2.1 | AN4: 2.1 | AO4: 2.1 | AP4: 2.1 | AQ4: 2.1 | AR4: 2.1 | AS4: 2.1 | AT4: 2.1 | AU4: 2.1 | AV4: 2.1 | AW4: 2.1 | AX4: 2.1 | AY4: 2.1 | AZ4: 2.1 | BA4: 2.1 | BC4: 2.1 | BD4: 2.1 | BE4: 2.1 | BF4: 2.1 | BG4: 2.1 | BH4: 2.1 | BI4: 2.1 | BJ4: 2.1 | BK4: 2.1 | BL4: 2.1 | BM4: 2.1 | BN4: 2.1 | BO4: 2.1 | BP4: 2.1 | BQ4: 2.1 | BR4: 2.1 | BS4: 2.1 | BT4: 2.1 | BU4: 2.1
J5: Janeiro | AG5: Fevereiro | BA5: Março | BV5: Abril
J6: 45649 | K6: 45650 | L6: 45651 | M6: 45652 | N6: 45653 | O6: 45649 | P6: 45650 | Q6: 45651 | R6: 45652 | S6: 45653 | T6: 45649 | U6: 45650 | V6: 45651 | W6: 45652 | X6: 45653 | Y6: 45649 | Z6: 45650 | AA6: 45651 | AB6: 45652 | AC6: 45653 | AD6: 45649 | AE6: 45650 | AF6: 45651 | AG6: 45652 | AH6: 45653 | AI6: 45649 | AJ6: 45650 | AK6: 45651 | AL6: 45652 | AM6: 45653 | AN6: 45649 | AO6: 45650 | AP6: 45651 | AQ6: 45652 | AR6: 45653 | AS6: 45649 | AT6: 45650 | AU6: 45651 | AV6: 45652 | AW6: 45653 | AX6: 45649 | AY6: 45650 | AZ6: 45651 | BA6: 45652 | BB6: 45653 | BC6: 45649 | BD6: 45650 | BE6: 45651 | BF6: 45652 | BG6: 45653 | BH6: 45649 | BI6: 45650 | BJ6: 45651 | BK6: 45652 | BL6: 45653 | BM6: 45649 | BN6: 45650 | BO6: 45651 | BP6: 45652 | BQ6: 45653 | BR6: 45649 | BS6: 45650 | BT6: 45651 | BU6: 45652 | BV6: 45653 | BW6: 45649 | BX6: 45650 | BY6: 45651 | BZ6: 45652 | CA6: 45653 | CB6: 45649 | CC6: 45650 | CD6: 45651 | CE6: 45652 | CF6: 45653 | CG6: 45649 | CH6: 45650 | CI6: 45651 | CJ6: 45652 | CK6: 45653 | CL6: 45649 | CM6: 45650 | CN6: 45651 | CO6: 45652 | CP6: 45653 | CQ6: 45649
I7: 45657 | J7: =WORKDAY(I7,1) -> 45658 | K7: =WORKDAY(J7,1) -> 45659 | L7: =WORKDAY(K7,1) -> 45660 | M7: =WORKDAY(L7,1) -> 45663 | N7: =WORKDAY(M7,1) -> 45664 | O7: =WORKDAY(N7,1) -> 45665 | P7: =WORKDAY(O7,1) -> 45666 | Q7: =WORKDAY(P7,1) -> 45667 | ... X7: =WORKDAY(W7,1) -> 45678
F8: # Campos | G8: Duração (horas) | H8: Duração (Dias) | I8: VAL | J8: =WORKDAY(I7,1) -> 45658 | K8: =WORKDAY(J8,1) -> 45659 | L8: =WORKDAY(K8,1) -> 45660 | M8: =WORKDAY(L8,1) -> 45663 | N8: =WORKDAY(M8,1) -> 45664 | O8: =WORKDAY(N8,1) -> 45665 | P8: =WORKDAY(O8,1) -> 45666 | Q8: =WORKDAY(P8,1) -> 45667 | R8: =WORKDAY(Q8,1) -> 45670 | ... CQ8: =WORKDAY(CP8,1) -> 45777
C10: Gestão Projeto | F10: n.a. | G10: =H10*8*5 -> 0 | H10: =SUM(J10:M10) -> 0
C11: Gestão Projeto | F11: n.a. | G11: =H11*8*5 -> 12 | H11: =SUM(J11:M11) -> 0.3 | I11: =SUM(J11:M11)-H11 -> 0 | K11: 0.1 | L11: 0.1 | M11: 0.1 | N11: 0.1 | O11: 0.1 | P11: 0.1 | Q11: 0.1 | R11: 0.1 | S11: 0.1 | T11: 0.1 | U11: 0.1 | V11: 0.1 | W11: 0.1 | X11: 0.1 | Y11: 0.1 | Z11: 0.1 | AA11: 0.1 | AB11: 0.1 | AC11: 0.1 | AD11: 0.1 | AE11: 0.1 | AF11: 0.1 | AG11: 0.1 | AH11: 0.1 | AI11: 0.1 | AJ11: 0.1 | AK11: 0.1 | AL11: 0.1 | AM11: 0.1 | AN11: 0.1 | AO11: 0.1 | AP11: 0.1 | AQ11: 0.1 | AR11: 0.1 | AS11: 0.1 | AT11: 0.1 | AU11: 0.1 | AV11: 0.1 | AW11: 0.1 | AX11: 0.1 | AY11: 0.1 | AZ11: 0.1 | BA11: 0.1 | BC11: 0.1 | BD11: 0.1 | BE11: 0.1 | BF11: 0.1 | BG11: 0.1 | BH11: 0.1 | BI11: 0.1 | BJ11: 0.1 | BK11: 0.1 | BL11: 0.1 | BM11: 0.1 | BN11: 0.1 | BO11: 0.1 | BP11: 0.1 | BQ11: 0.1 | BR11: 0.1 | BS11: 0.1 | BT11: 0.1 | BU11: 0.1 | BV11: 0.1 | BW11: 0.1 | BX11: 0.1 | BY11: 0.1 | BZ11: 0.1 | CA11: 0.1 | CB11: 0.1 | CC11: 0.1 | CD11: 0.1 | CE11: 0.1 | CF11: 0.1 | CG11: 0.1 | CH11: 0.1 | CJ11: 0.1 | CK11: 0.1 | CL11: 0.1 | CM11: 0.1 | CO11: 0.1 | CP11: 0.1 | CQ11: 0.1
C12: 1. Re-especificações + Simulação + Testes + Re-testes requisitos atuais) | G12: =SUM(G13:G15) -> 128 | H12: =ROUND(SUM(H13:H15),0) -> 16
C13: MunichRe | G13: 16 | H13: =ROUNDUP(G13/8,1) -> 2 | I13: 0 | K13: 3
C14: Gloval - Tabela intermédia | G14: 16 | H14: =ROUNDUP(G14/8,1) -> 2 | I14: 0 | L14: 3
C15: Re-testes | G15: =12*8 -> 96 | H15: =ROUNDUP(G15/8,1) -> 12 | I15: 0 | M15: 3 | N15: 3 | O15: 3 | P15: 3 | Q15: 3 | R15: 3 | S15: 3 | T15: 3 | U15: 3 | V15: 3 | W15: 3 | X15: 3
C16: 2. Novos Campos (Especificação + Simulação + Testes+ Re-testes) | F16: =F17+F66 -> 68 | G16: =G17+G66+G87+G156+G225 -> #N/A | H16: =H17+H66+H87+H156+H225 -> #N/A
C17: Especificação de Requisitos - P3 | F17: =COUNTA(E18:E65) -> 48 | G17: =SUM(G18:G55) -> #N/A | H17: =ROUND(SUM(H18:H55),0) -> #N/A
B18: =Table1[[#Headers],[Especificação]] -> Especificação | C18: =D18&"_"&E18 -> ENTITY_TXNMY_ELGBL_CAPEX_W | D18: ENTITY | E18: TXNMY_ELGBL_CAPEX_W | G18: =INDEX(Table1[[Especificação]:[Total Testes]],MATCH(PlanoV1.0!C18,Table1[CONCAT],0),MATCH(PlanoV1.0!B18,Table1[[#Headers],[Especificação]:[Total Testes]],0)) -> #N/A | H18: =ROUNDUP(G18/8,1) -> #N/A | I18: =SUM(J18:CQ18)-H18 -> #N/A | Y18: 1
B19: =Table1[[#Headers],[Especificação]] -> Especificação | C19: =D19&"_"&E19 -> ENTITY_TXNMY_ELGBL_TRNVR_W | D19: ENTITY | E19: TXNMY_ELGBL_TRNVR_W | G19: =INDEX(Table1[[Especificação]:[Total Testes]],MATCH(PlanoV1.0!C19,Table1[CONCAT],0),MATCH(PlanoV1.0!B19,Table1[[#Headers],[Especificação]:[Total Testes]],0)) -> #N/A | H19: =ROUNDUP(G19/8,1) -> #N/A | I19: =SUM(J19:CQ19)-H19 -> #N/A | Z19: 0.5
B20: =Table1[[#Headers],[Especificação]] -> Especificação | C20: =D20&"_"&E20 -> ENTITY_TXNMY_ELGBL_CAPEX_P | D20: ENTITY | E20: TXNMY_ELGBL_CAPEX_P | G20: =INDEX(Table1[[Especificação]:[Total Testes]],MATCH(PlanoV1.0!C20,Table1[CONCAT],0),MATCH(PlanoV1.0!B20,Table1[[#Headers],[Especificação]:[Total Testes]],0)) -> #N/A | H20: =ROUNDUP(G20/8,1) -> #N/A | I20: =SUM(J20:CQ20)-H20 -> #N/A | Z20: 0.3
B21: =Table1[[#Headers],[Especificação]] -> Especificação | C21: =D21&"_"&E21 -> ENTITY_TXNMY_ELGBL_TRNVR_P | D21: ENTITY | E21: TXNMY_ELGBL_TRNVR_P | G21: =INDEX(Table1[[Especificação]:[Total Testes]],MATCH(PlanoV1.0!C21,Table1[CONCAT],0),MATCH(PlanoV1.0!B21,Table1[[#Headers],[Especificação]:[Total Testes]],0)) -> #N/A | H21: =ROUNDUP(G21/8,1) -> #N/A | I21: =SUM(J21:CQ21)-H21 -> #N/A | Z21: 0.2 | AA21: 0.1
B22: =Table1[[#Headers],[Especificação]] -> Especificação | C22: =D22&"_"&E22 -> ENTITY_TXNMY_ELGBL_CAPEX_B | D22: ENTITY | E22: TXNMY_ELGBL_CAPEX_B | G22: =INDEX(Table1[[Especificação]:[Total Testes]],MATCH(PlanoV1.0!C22,Table1[CONCAT],0),MATCH(PlanoV1.0!B22,Table1[[#Headers],[Especificação]:[Total Testes]],0)) -> #N/A | H22: =ROUNDUP(G22/8,1) -> #N/A | I22: =SUM(J22:CQ22)-H22 -> #N/A | AA22: 0.3
B23: =Table1[[#Headers],[Especificação]] -> Especificação | C23: =D23&"_"&E23 -> ENTITY_TXNMY_ELGBL_TRNVR_B | D23: ENTITY | E23: TXNMY_ELGBL_TRNVR_B | G23: =INDEX(Table1[[Especificação]:[Total Testes]],MATCH(PlanoV1.0!C23,Table1[CONCAT],0),MATCH(PlanoV1.0!B23,Table1[[#Headers],[Especificação]:[Total Testes]],0)) -> #N/A | H23: =ROUNDUP(G23/8,1) -> #N/A | I23: =SUM(J23:CQ23)-H23 -> #N/A | AA23: 0.3
B24: =Table1[[#Headers],[Especificação]] -> Especificação | C24: =D24&"_"&E24 -> ENTITY_TXNMY_ELGBL_CAPEX_CE | D24: ENTITY | E24: TXNMY_ELGBL_CAPEX_CE | G24: =INDEX(Table1[[Especificação]:[Total Testes]],MATCH(PlanoV1.0!C24,Table1[CONCAT],0),MATCH(PlanoV1.0!B24,Table1[[#Headers],[Especificação]:[Total Testes]],0)) -> #N/A | H24: =ROUNDUP(G24/8,1) -> #N/A | I24: =SUM(J24:CQ24)-H24 -> #N/A | AA24: 0.2
B25: =Table1[[#Headers],[Especificação]] -> Especificação | C25: =D25&"_"&E25 -> ENTITY_TXNMY_ELGBL_TRNVR_CE | D25: ENTITY | E25: TXNMY_ELGBL_TRNVR_CE | G25: =INDEX(Table1[[Especificação]:[Total Testes]],MATCH(PlanoV1.0!C25,Table1[CONCAT],0),MATCH(PlanoV1.0!B25,Table1[[#Headers],[Especificação]:[Total Testes]],0)) -> #N/A | H25: =ROUNDUP(G25/8,1) -> #N/A | I25: =SUM(J25:CQ25)-H25 -> #N/A | AA25: 0.1 | AB25: 0.1
B26: =Table1[[#Headers],[Especificação]] -> Especificação | C26: =D26&"_"&E26 -> ENTITY_PURE_CAPEX_P | D26: ENTITY | E26: PURE_CAPEX_P | G26: =INDEX(Table1[[Especificação]:[Total Testes]],MATCH(PlanoV1.0!C26,Table1[CONCAT],0),MATCH(PlanoV1.0!B26,Table1[[#Headers],[Especificação]:[Total Testes]],0)) -> #N/A | H26: =ROUNDUP(G26/8,1) -> #N/A | I26: =SUM(J26:CQ26)-H26 -> #N/A | AB26: 0.2
B27: =Table1[[#Headers],[Especificação]] -> Especificação | C27: =D27&"_"&E27 -> ENTITY_PURE_TRNVR_P | D27: ENTITY | E27: PURE_TRNVR_P | G27: =INDEX(Table1[[Especificação]:[Total Testes]],MATCH(PlanoV1.0!C27,Table1[CONCAT],0),MATCH(PlanoV1.0!B27,Table1[[#Headers],[Especificação]:[Total Testes]],0)) -> #N/A | H27: =ROUNDUP(G27/8,1) -> #N/A | I27: =SUM(J27:CQ27)-H27 -> #N/A | AB27: 0.2
B28: =Table1[[#Headers],[Especificação]] -> Especificação | C28: =D28&"_"&E28 -> ENTITY_PURE_CAPEX_B | D28: ENTITY | E28: PURE_CAPEX_B | G28: =INDEX(Table1[[Especificação]:[Total Testes]],MATCH(PlanoV1.0!C28,Table1[CONCAT],0),MATCH(PlanoV1.0!B28,Table1[[#Headers],[Especificação]:[Total Testes]],0)) -> #N/A | H28: =ROUNDUP(G28/8,1) -> #N/A | I28: =SUM(J28:CQ28)-H28 -> #N/A | AB28: 0.2
B29: =Table1[[#Headers],[Especificação]] -> Especificação | C29: =D29&"_"&E29 -> ENTITY_PURE_TRNVR_B | D29: ENTITY | E29: PURE_TRNVR_B | G29: =INDEX(Table1[[Especificação]:[Total Testes]],MATCH(PlanoV1.0!C29,Table1[CONCAT],0),MATCH(PlanoV1.0!B29,Table1[[#Headers],[Especificação]:[Total Testes]],0)) -> #N/A | H29: =ROUNDUP(G29/8,1) -> #N/A | I29: =SUM(J29:CQ29)-H29 -> #N/A | AB29: 0.2
B30: =Table1[[#Headers],[Especificação]] -> Especificação | C30: =D30&"_"&E30 -> ENTITY_PURE_CAPEX_W | D30: ENTITY | E30: PURE_CAPEX_W | G30: =INDEX(Table1[[Especificação]:[Total Testes]],MATCH(PlanoV1.0!C30,Table1[CONCAT],0),MATCH(PlanoV1.0!B30,Table1[[#Headers],[Especificação]:[Total Testes]],0)) -> #N/A | H30: =ROUNDUP(G30/8,1) -> #N/A | I30: =SUM(J30:CQ30)-H30 -> #N/A | AB30: 0.1 | AC30: 0.1
B31: =Table1[[#Headers],[Especificação]] -> Especificação | C31: =D31&"_"&E31 -> ENTITY_PURE_TRNVR_W | D31: ENTITY | E31: PURE_TRNVR_W | G31: =INDEX(Table1[[Especificação]:[Total Testes]],MATCH(PlanoV1.0!C31,Table1[CONCAT],0),MATCH(PlanoV1.0!B31,Table1[[#Headers],[Especificação]:[Total Testes]],0)) -> #N/A | H31: =ROUNDUP(G31/8,1) -> #N/A | I31: =SUM(J31:CQ31)-H31 -> #N/A | AC31: 0.2
B32: =Table1[[#Headers],[Especificação]] -> Especificação | C32: =D32&"_"&E32 -> ENTITY_PURE_CAPEX_CE | D32: ENTITY | E32: PURE_CAPEX_CE | G32: =INDEX(Table1[[Especificação]:[Total Testes]],MATCH(PlanoV1.0!C32,Table1[CONCAT],0),MATCH(PlanoV1.0!B32,Table1[[#Headers],[Especificação]:[Total Testes]],0)) -> #N/A | H32: =ROUNDUP(G32/8,1) -> #N/A | I32: =SUM(J32:CQ32)-H32 -> #N/A | AC32: 0.2
B33: =Table1[[#Headers],[Especificação]] -> Especificação | C33: =D33&"_"&E33 -> ENTITY_PURE_TRNVR_CE | D33: ENTITY | E33: PURE_TRNVR_CE | G33: =INDEX(Table1[[Especificação]:[Total Testes]],MATCH(PlanoV1.0!C33,Table1[CONCAT],0),MATCH(PlanoV1.0!B33,Table1[[#Headers],[Especificação]:[Total Testes]],0)) -> #N/A | H33: =ROUNDUP(G33/8,1) -> #N/A | I33: =SUM(J33:CQ33)-H33 -> #N/A | AC33: 0.2
B34: =Table1[[#Headers],[Especificação]] -> Especificação | C34: =D34&"_"&E34 -> ENTITY_ENBLNG_CAPEX_W | D34: ENTITY | E34: ENBLNG_CAPEX_W | G34: =INDEX(Table1[[Especificação]:[Total Testes]],MATCH(PlanoV1.0!C34,Table1[CONCAT],0),MATCH(PlanoV1.0!B34,Table1[[#Headers],[Especificação]:[Total Testes]],0)) -> #N/A | H34: =ROUNDUP(G34/8,1) -> #N/A | I34: =SUM(J34:CQ34)-H34 -> #N/A | AC34: 0.2
B35: =Table1[[#Headers],[Especificação]] -> Especificação | C35: =D35&"_"&E35 -> ENTITY_ENBLNG_TRNVR_W | D35: ENTITY | E35: ENBLNG_TRNVR_W | G35: =INDEX(Table1[[Especificação]:[Total Testes]],MATCH(PlanoV1.0!C35,Table1[CONCAT],0),MATCH(PlanoV1.0!B35,Table1[[#Headers],[Especificação]:[Total Testes]],0)) -> #N/A | H35: =ROUNDUP(G35/8,1) -> #N/A | I35: =SUM(J35:CQ35)-H35 -> #N/A | AC35: 0.1 | AD35: 0.1
B36: =Table1[[#Headers],[Especificação]] -> Especificação | C36: =D36&"_"&E36 -> ENTITY_ENBLNG_CAPEX_CE | D36: ENTITY | E36: ENBLNG_CAPEX_CE | G36: =INDEX(Table1[[Especificação]:[Total Testes]],MATCH(PlanoV1.0!C36,Table1[CONCAT],0),MATCH(PlanoV1.0!B36,Table1[[#Headers],[Especificação]:[Total Testes]],0)) -> #N/A | H36: =ROUNDUP(G36/8,1) -> #N/A | I36: =SUM(J36:CQ36)-H36 -> #N/A | AD36: 0.2
B37: =Table1[[#Headers],[Especificação]] -> Especificação | C37: =D37&"_"&E37 -> ENTITY_ENBLNG_TRNVR_CE | D37: ENTITY | E37: ENBLNG_TRNVR_CE | G37: =INDEX(Table1[[Especificação]:[Total Testes]],MATCH(PlanoV1.0!C37,Table1[CONCAT],0),MATCH(PlanoV1.0!B37,Table1[[#Headers],[Especificação]:[Total Testes]],0)) -> #N/A | H37: =ROUNDUP(G37/8,1) -> #N/A | I37: =SUM(J37:CQ37)-H37 -> #N/A | AD37: 0.2
B38: =Table1[[#Headers],[Especificação]] -> Especificação | C38: =D38&"_"&E38 -> INSTRUMENT_TYP_OFF_BLNC_PRDCT | D38: INSTRUMENT | E38: TYP_OFF_BLNC_PRDCT | G38: =INDEX(Table1[[Especificação]:[Total Testes]],MATCH(PlanoV1.0!C38,Table1[CONCAT],0),MATCH(PlanoV1.0!B38,Table1[[#Headers],[Especificação]:[Total Testes]],0)) -> 1 | H38: =ROUNDUP(G38/8,1) -> 0.2 | I38: =SUM(J38:CQ38)-H38 -> 0 | AD38: 0.2
B39: =Table1[[#Headers],[Especificação]] -> Especificação | C39: =D39&"_"&E39 -> INSTRUMENT_FLG_MNMM_SFGRDS | D39: INSTRUMENT | E39: FLG_MNMM_SFGRDS | G39: =INDEX(Table1[[Especificação]:[Total Testes]],MATCH(PlanoV1.0!C39,Table1[CONCAT],0),MATCH(PlanoV1.0!B39,Table1[[#Headers],[Especificação]:[Total Testes]],0)) -> #N/A | H39: =ROUNDUP(G39/8,1) -> #N/A | I39: =SUM(J39:CQ39)-H39 -> #N/A | Y39: 1.3
B40: =Table1[[#Headers],[Especificação]] -> Especificação | C40: =D40&"_"&E40 -> INSTR_PROTECTION_TYP_RLTN | D40: INSTR_PROTECTION | E40: TYP_RLTN | G40: =INDEX(Table1[[Especificação]:[Total Testes]],MATCH(PlanoV1.0!C40,Table1[CONCAT],0),MATCH(PlanoV1.0!B40,Table1[[#Headers],[Especificação]:[Total Testes]],0)) -> 0 | H40: =ROUNDUP(G40/8,1) -> 0 | I40: =SUM(J40:CQ40)-H40 -> 0.5 | Y40: 0.5
B41: =Table1[[#Headers],[Especificação]] -> Especificação | C41: =D41&"_"&E41 -> PROTECTION_BLDNG_AR | D41: PROTECTION | E41: BLDNG_AR | G41: =INDEX(Table1[[Especificação]:[Total Testes]],MATCH(PlanoV1.0!C41,Table1[CONCAT],0),MATCH(PlanoV1.0!B41,Table1[[#Headers],[Especificação]:[Total Testes]],0)) -> #N/A | H41: =ROUNDUP(G41/8,1) -> #N/A | I41: =SUM(J41:CQ41)-H41 -> #N/A | AD41: 0.3
...

Sheet Sheet1
H1: =I1/8 -> 150.3 | I1: =SUM(J1:BU1) -> 1202.4 | K1: =K4*8 -> 24.8 | L1: =L4*8 -> 24.8 | M1: =M4*8 -> 24.8 | N1: =N4*8 -> 24.8 | O1: =O4*8 -> 24.8 | P1: =P4*8 -> 24.8 | Q1: =Q4*8 -> 24.8 | R1: =R4*8 -> 24.8 | ... BU1: =BU4*8 -> 1.6
I2: VAL | K2: =K3-K4 -> 0 | L2: =L3-L4 -> 0 | M2: =M3-M4 -> 0 | N2: =N3-N4 -> 0 | O2: =O3-O4 -> 0 | P2: =P3-P4 -> 0 | Q2: =Q3-Q4 -> 0 | R2: =R3-R4 -> 0 | ... BA2: =BA3-BA4 -> 0 | BC2: =BC3-BC4 -> 0 | BD2: =BD3-BD4 -> 0 | BE2: =BE3-BE4 -> 0 | BF2: =BF3-BF4 -> 0 | BG2: =BG3-BG4 -> 0 | BH2: =BH3-BH4 -> 0 | BI2: =BI3-BI4 -> 0 | BJ2: =BJ3-BJ4 -> 0 | ... BU2: =BU3-BU4 -> 0
I3: FTE REAIS | K3: =SUM(K9:K226) -> 3.1 | L3: =SUM(L9:L226) -> 3.1 | M3: =SUM(M9:M226) -> 3.1 | N3: =SUM(N9:N226) -> 3.1 | O3: =SUM(O9:O226) -> 3.1 | P3: =SUM(P9:P226) -> 3.1 | Q3: =SUM(Q9:Q226) -> 3.1 | R3: =SUM(R9:R226) -> 3.1 | ... BA3: =SUM(BA9:BA226) -> 2.1 | BC3: =SUM(BC9:BC226) -> 2.1 | BD3: =SUM(BD9:BD226) -> 2.1 | BE3: =SUM(BE9:BE226) -> 2.1 | BF3: =SUM(BF9:BF226) -> 2.1 | BG3: =SUM(BG9:BG226) -> 2.1 | BH3: =SUM(BH9:BH226) -> 2.1 | BI3: =SUM(BI9:BI226) -> 2.1 | BJ3: =SUM(BJ9:BJ226) -> 2.1 | ... BU3: =SUM(BU9:BU226) -> 0.2
I4: FTE ESP. | K4: 3.1 | L4: 3.1 | M4: 3.1 | N4: 3.1 | O4: 3.1 | P4: 3.1 | Q4: 3.1 | R4: 3.1 | S4: 3.1 | T4: 3.1 | U4: 3.1 | V4: 3.1 | W4: 3.1 | X4: 3.1 | Y4: 3.1 | Z4: 3.1 | AA4: 3.1 | AB4: 3.1 | AC4: 3.1 | AD4: 3.1 | AE4: 3.1 | AF4: 3.1 | AG4: 2.1 | AH4: 2.1 | AI4: 2.1 | AJ4: 2.1 | AK4: 2.1 | AL4: 2.1 | AM4: 2.1 | AN4: 2.1 | AO4: 2.1 | AP4: 2.1 | AQ4: 2.1 | AR4: 2.1 | AS4: 2.1 | AT4: 2.1 | AU4: 2.1 | AV4: 2.1 | AW4: 2.1 | AX4: 2.1 | AY4: 2.1 | AZ4: 2.1 | BA4: 2.1 | BC4: 2.1 | BD4: 2.1 | BE4: 2.1 | BF4: 2.1 | BG4: 2.1 | BH4: 2.1 | BI4: 2.1 | BJ4: 2.1 | BK4: 2.1 | BL4: 2.1 | BM4: 2.1 | BN4: 2.1 | BO4: 2.1 | BP4: 2.1 | BQ4: 2.1 | BR4: 2.1 | BS4: 2.1 | BT4: 2.1 | BU4: 0.2
G5: =G11+G12+G16 -> #N/A | H5: =H11+H12+H16 -> #N/A | J5: Janeiro | AG5: Fevereiro | BA5: Março | BV5: Abril
G6: =G5/8 -> #N/A | H6: =H5-G6 -> #N/A | J6: 45649 | K6: 45650 | L6: 45651 | M6: 45652 | N6: 45653 | O6: 45649 | P6: 45650 | Q6: 45651 | R6: 45652 | S6: 45653 | T6: 45649 | U6: 45650 | V6: 45651 | W6: 45652 | X6: 45653 | Y6: 45649 | Z6: 45650 | AA6: 45651 | AB6: 45652 | AC6: 45653 | AD6: 45649 | AE6: 45650 | AF6: 45651 | AG6: 45652 | AH6: 45653 | AI6: 45649 | AJ6: 45650 | AK6: 45651 | AL6: 45652 | AM6: 45653 | AN6: 45649 | AO6: 45650 | AP6: 45651 | AQ6: 45652 | AR6: 45653 | AS6: 45649 | AT6: 45650 | AU6: 45651 | AV6: 45652 | AW6: 45653 | AX6: 45649 | AY6: 45650 | AZ6: 45651 | BA6: 45652 | BB6: 45653 | BC6: 45649 | BD6: 45650 | BE6: 45651 | BF6: 45652 | BG6: 45653 | BH6: 45649 | BI6: 45650 | BJ6: 45651 | BK6: 45652 | BL6: 45653 | BM6: 45649 | BN6: 45650 | BO6: 45651 | BP6: 45652 | BQ6: 45653 | BR6: 45649 | BS6: 45650 | BT6: 45651 | BU6: 45652 | BV6: 45653 | BW6: 45649 | BX6: 45650 | BY6: 45651 | BZ6: 45652 | CA6: 45653 | CB6: 45649 | CC6: 45650 | CD6: 45651 | CE6: 45652 | CF6: 45653 | CG6: 45649 | CH6: 45650 | CI6: 45651 | CJ6: 45652 | CK6: 45653 | CL6: 45649 | CM6: 45650 | CN6: 45651 | CO6: 45652 | CP6: 45653 | CQ6: 45649
I7: 45657 | J7: =WORKDAY(I7,1) -> 45658 | K7: =WORKDAY(J7,1) -> 45659 | L7: =WORKDAY(K7,1) -> 45660 | M7: =WORKDAY(L7,1) -> 45663 | N7: =WORKDAY(M7,1) -> 45664 | O7: =WORKDAY(N7,1) -> 45665 | P7: =WORKDAY(O7,1) -> 45666 | Q7: =WORKDAY(P7,1) -> 45667 | ... X7: =WORKDAY(W7,1) -> 45678
F8: # Campos | G8: Duração (horas) | H8: Duração (Dias) | I8: VAL | J8: =WORKDAY(I7,1) -> 45658 | K8: =WORKDAY(J8,1) -> 45659 | L8: =WORKDAY(K8,1) -> 45660 | M8: =WORKDAY(L8,1) -> 45663 | N8: =WORKDAY(M8,1) -> 45664 | O8: =WORKDAY(N8,1) -> 45665 | P8: =WORKDAY(O8,1) -> 45666 | Q8: =WORKDAY(P8,1) -> 45667 | R8: =WORKDAY(Q8,1) -> 45670 | ... CQ8: =WORKDAY(CP8,1) -> 45777
C10: Gestão Projeto | F10: n.a. | G10: =H10*8*5 -> 0 | H10: =SUM(J10:M10) -> 0
C11: Gestão Projeto | F11: n.a. | G11: =H11*8 -> 49.6 | H11: =SUM(J11:BU11) -> 6.2 | I11: =SUM(J11:BU11)-H11 -> 0 | K11: 0.1 | L11: 0.1 | M11: 0.1 | N11: 0.1 | O11: 0.1 | P11: 0.1 | Q11: 0.1 | R11: 0.1 | S11: 0.1 | T11: 0.1 | U11: 0.1 | V11: 0.1 | W11: 0.1 | X11: 0.1 | Y11: 0.1 | Z11: 0.1 | AA11: 0.1 | AB11: 0.1 | AC11: 0.1 | AD11: 0.1 | AE11: 0.1 | AF11: 0.1 | AG11: 0.1 | AH11: 0.1 | AI11: 0.1 | AJ11: 0.1 | AK11: 0.1 | AL11: 0.1 | AM11: 0.1 | AN11: 0.1 | AO11: 0.1 | AP11: 0.1 | AQ11: 0.1 | AR11: 0.1 | AS11: 0.1 | AT11: 0.1 | AU11: 0.1 | AV11: 0.1 | AW11: 0.1 | AX11: 0.1 | AY11: 0.1 | AZ11: 0.1 | BA11: 0.1 | BC11: 0.1 | BD11: 0.1 | BE11: 0.1 | BF11: 0.1 | BG11: 0.1 | BH11: 0.1 | BI11: 0.1 | BJ11: 0.1 | BK11: 0.1 | BL11: 0.1 | BM11: 0.1 | BN11: 0.1 | BO11: 0.1 | BP11: 0.1 | BQ11: 0.1 | BR11: 0.1 | BS11: 0.1 | BT11: 0.1 | BU11: 0.1
C12: 1. Re-especificações + Simulação + Testes + Re-testes requisitos atuais) | G12: =SUM(G13:G15) -> 128 | H12: =ROUND(SUM(H13:H15),1) -> 16
C13: MunichRe | G13: 16 | H13: =ROUNDUP(G13/8,1) -> 2 | I13: 0 | K13: 3
C14: Gloval - Tabela intermédia | G14: 16 | H14: =ROUNDUP(G14/8,1) -> 2 | I14: 0 | L14: 3
C15: Re-testes | G15: =12*8 -> 96 | H15: =ROUNDUP(G15/8,1) -> 12 | I15: 0 | M15: 3 | N15: 3 | O15: 3 | P15: 3 | Q15: 3 | R15: 3 | S15: 3 | T15: 3 | U15: 3 | V15: 3 | W15: 3 | X15: 3
C16: 2. Novos Campos (Especificação + Simulação + Testes+ Re-testes) | F16: =F17+F66 -> 68 | G16: =G17+G66+G87+G156+G225 -> #N/A | H16: =H17+H66+H87+H156+H225 -> #N/A
C17: Especificação de Requisitos - P3 | F17: =COUNTA(E18:E65) -> 48 | G17: =SUM(G18:G65) -> #N/A | H17: =ROUND(SUM(H18:H65),1) -> #N/A | I17: =SUM(J17:CQ17)-H17 -> #N/A | Y17: 3 | Z17: 3 | AA17: 3 | AB17: 3 | AC17: 3 | AD17: 3 | AE17: 3 | AF17: 0.1
B18: =Table1[[#Headers],[Especificação]] -> Especificação | C18: =D18&"_"&E18 -> ENTITY_TXNMY_ELGBL_CAPEX_W | D18: ENTITY | E18: TXNMY_ELGBL_CAPEX_W | G18: =INDEX(Table1[[Especificação]:[Total Testes]],MATCH(Sheet1!C18,Table1[CONCAT],0),MATCH(Sheet1!B18,Table1[[#Headers],[Especificação]:[Total Testes]],0)) -> #N/A | H18: =ROUND(G18/8,2) -> #N/A
B19: =Table1[[#Headers],[Especificação]] -> Especificação | C19: =D19&"_"&E19 -> ENTITY_TXNMY_ELGBL_TRNVR_W | D19: ENTITY | E19: TXNMY_ELGBL_TRNVR_W | G19: =INDEX(Table1[[Especificação]:[Total Testes]],MATCH(Sheet1!C19,Table1[CONCAT],0),MATCH(Sheet1!B19,Table1[[#Headers],[Especificação]:[Total Testes]],0)) -> #N/A | H19: =ROUND(G19/8,2) -> #N/A
B20: =Table1[[#Headers],[Especificação]] -> Especificação | C20: =D20&"_"&E20 -> ENTITY_TXNMY_ELGBL_CAPEX_P | D20: ENTITY | E20: TXNMY_ELGBL_CAPEX_P | G20: =INDEX(Table1[[Especificação]:[Total Testes]],MATCH(Sheet1!C20,Table1[CONCAT],0),MATCH(Sheet1!B20,Table1[[#Headers],[Especificação]:[Total Testes]],0)) -> #N/A | H20: =ROUND(G20/8,2) -> #N/A
B21: =Table1[[#Headers],[Especificação]] -> Especificação | C21: =D21&"_"&E21 -> ENTITY_TXNMY_ELGBL_TRNVR_P | D21: ENTITY | E21: TXNMY_ELGBL_TRNVR_P | G21: =INDEX(Table1[[Especificação]:[Total Testes]],MATCH(Sheet1!C21,Table1[CONCAT],0),MATCH(Sheet1!B21,Table1[[#Headers],[Especificação]:[Total Testes]],0)) -> #N/A | H21: =ROUND(G21/8,2) -> #N/A
B22: =Table1[[#Headers],[Especificação]] -> Especificação | C22: =D22&"_"&E22 -> ENTITY_TXNMY_ELGBL_CAPEX_B | D22: ENTITY | E22: TXNMY_ELGBL_CAPEX_B | G22: =INDEX(Table1[[Especificação]:[Total Testes]],MATCH(Sheet1!C22,Table1[CONCAT],0),MATCH(Sheet1!B22,Table1[[#Headers],[Especificação]:[Total Testes]],0)) -> #N/A | H22: =ROUND(G22/8,2) -> #N/A
B23: =Table1[[#Headers],[Especificação]] -> Especificação | C23: =D23&"_"&E23 -> ENTITY_TXNMY_ELGBL_TRNVR_B | D23: ENTITY | E23: TXNMY_ELGBL_TRNVR_B | G23: =INDEX(Table1[[Especificação]:[Total Testes]],MATCH(Sheet1!C23,Table1[CONCAT],0),MATCH(Sheet1!B23,Table1[[#Headers],[Especificação]:[Total Testes]],0)) -> #N/A | H23: =ROUND(G23/8,2) -> #N/A
B24: =Table1[[#Headers],[Especificação]] -> Especificação | C24: =D24&"_"&E24 -> ENTITY_TXNMY_ELGBL_CAPEX_CE | D24: ENTITY | E24: TXNMY_ELGBL_CAPEX_CE | G24: =INDEX(Table1[[Especificação]:[Total Testes]],MATCH(Sheet1!C24,Table1[CONCAT],0),MATCH(Sheet1!B24,Table1[[#Headers],[Especificação]:[Total Testes]],0)) -> #N/A | H24: =ROUND(G24/8,2) -> #N/A
B25: =Table1[[#Headers],[Especificação]] -> Especificação | C25: =D25&"_"&E25 -> ENTITY_TXNMY_ELGBL_TRNVR_CE | D25: ENTITY | E25: TXNMY_ELGBL_TRNVR_CE | G25: =INDEX(Table1[[Especificação]:[Total Testes]],MATCH(Sheet1!C25,Table1[CONCAT],0),MATCH(Sheet1!B25,Table1[[#Headers],[Especificação]:[Total Testes]],0)) -> #N/A | H25: =ROUND(G25/8,2) -> #N/A
B26: =Table1[[#Headers],[Especificação]] -> Especificação | C26: =D26&"_"&E26 -> ENTITY_PURE_CAPEX_P | D26: ENTITY | E26: PURE_CAPEX_P | G26: =INDEX(Table1[[Especificação]:[Total Testes]],MATCH(Sheet1!C26,Table1[CONCAT],0),MATCH(Sheet1!B26,Table1[[#Headers],[Especificação]:[Total Testes]],0)) -> #N/A | H26: =ROUND(G26/8,2) -> #N/A
B27: =Table1[[#Headers],[Especificação]] -> Especificação | C27: =D27&"_"&E27 -> ENTITY_PURE_TRNVR_P | D27: ENTITY | E27: PURE_TRNVR_P | G27: =INDEX(Table1[[Especificação]:[Total Testes]],MATCH(Sheet1!C27,Table1[CONCAT],0),MATCH(Sheet1!B27,Table1[[#Headers],[Especificação]:[Total Testes]],0)) -> #N/A | H27: =ROUND(G27/8,2) -> #N/A
B28: =Table1[[#Headers],[Especificação]] -> Especificação | C28: =D28&"_"&E28 -> ENTITY_PURE_CAPEX_B | D28: ENTITY | E28: PURE_CAPEX_B | G28: =INDEX(Table1[[Especificação]:[Total Testes]],MATCH(Sheet1!C28,Table1[CONCAT],0),MATCH(Sheet1!B28,Table1[[#Headers],[Especificação]:[Total Testes]],0)) -> #N/A | H28: =ROUND(G28/8,2) -> #N/A
B29: =Table1[[#Headers],[Especificação]] -> Especificação | C29: =D29&"_"&E29 -> ENTITY_PURE_TRNVR_B | D29: ENTITY | E29: PURE_TRNVR_B | G29: =INDEX(Table1[[Especificação]:[Total Testes]],MATCH(Sheet1!C29,Table1[CONCAT],0),MATCH(Sheet1!B29,Table1[[#Headers],[Especificação]:[Total Testes]],0)) -> #N/A | H29: =ROUND(G29/8,2) -> #N/A
... B65: =Table1[[#Headers],[Especificação]] -> Especificação | C65: =D65&"_"&E65 -> PROTECTION_YR_CNSTRCTN | D65: PROTECTION | E65: YR_CNSTRCTN | G65: =INDEX(Table1[[Especificação]:[Total Testes]],MATCH(Sheet1!C65,Table1[CONCAT],0),MATCH(Sheet1!B65,Table1[[#Headers],[Especificação]:[Total Testes]],0)) -> #N/A | H65: =ROUND(G65/8,2) -> #N/A
C66: Especificação de Requisitos - ESG Risks | F66: =+COUNTA(E67:E86) -> 20 | G66: =SUM(G67:G86) -> #N/A | H66: =ROUND(SUM(H67:H86),1) -> #N/A | I66: =SUM(J66:CQ66)-H66 -> #N/A | AF66: 2.9 | AG66: 2 | AH66: 2 | AI66: 2 | AJ66: 2 | AK66: 0.5
B67: =Table1[[#Headers],[Especificação]] -> Especificação | C67: =D67&"_"&E67 -> ENTITY_GRP_ECNMC_ACTVTY | D67: ENTITY | E67: GRP_ECNMC_ACTVTY | G67: =INDEX(Table1[[Especificação]:[Total Testes]],MATCH(Sheet1!C67,Table1[CONCAT],0),MATCH(Sheet1!B67,Table1[[#Headers],[Especificação]:[Total Testes]],0)) -> #N/A | H67: =ROUND(G67/8,2) -> #N/A
B68: =Table1[[#Headers],[Especificação]] -> Especificação | C68: =D68&"_"&E68 -> PROTECTION_TYP_EMSSNS_LBL | D68: PROTECTION | E68: TYP_EMSSNS_LBL | G68: =INDEX(Table1[[Especificação]:[Total Testes]],MATCH(Sheet1!C68,Table1[CONCAT],0),MATCH(Sheet1!B68,Table1[[#Headers],[Especificação]:[Total Testes]],0)) -> #N/A | H68: =ROUND(G68/8,2) -> #N/A
B69: =Table1[[#Headers],[Especificação]] -> Especificação | C69: =D69&"_"&E69 -> PROTECTION_EPC_EMSSNS_LBL | D69: PROTECTION | E69: EPC_EMSSNS_LBL | G69: =INDEX(Table1[[Especificação]:[Total Testes]],MATCH(Sheet1!C69,Table1[CONCAT],0),MATCH(Sheet1!B69,Table1[[#Headers],[Especificação]:[Total Testes]],0)) -> #N/A | H69: =ROUND(G69/8,2) -> #N/A
B70: =Table1[[#Headers],[Especificação]] -> Especificação | C70: =D70&"_"&E70 -> PROTECTION_VHCL_EMSSNS_LBL | D70: PROTECTION | E70: VHCL_EMSSNS_LBL | G70: =INDEX(Table1[[Especificação]:[Total Testes]],MATCH(Sheet1!C70,Table1[CONCAT],0),MATCH(Sheet1!B70,Table1[[#Headers],[Especificação]:[Total Testes]],0)) -> #N/A | H70: =ROUND(G70/8,2) -> #N/A
B71: =Table1[[#Headers],[Especificação]] -> Especificação | C71: =D71&"_"&E71 -> PROTECTION_TYP_EMSSNS_SCR | D71: PROTECTION | E71: TYP_EMSSNS_SCR | G71: =INDEX(Table1[[Especificação]:[Total Testes]],MATCH(Sheet1!C71,Table1[CONCAT],0),MATCH(Sheet1!B71,Table1[[#Headers],[Especificação]:[Total Testes]],0)) -> #N/A | H71: =ROUND(G71/8,2) -> #N/A
B72: =Table1[[#Headers],[Especificação]] -> Especificação | C72: =D72&"_"&E72 -> PROTECTION_EPC_EMSSNS_SCR | D72: PROTECTION | E72: EPC_EMSSNS_SCR | G72: =INDEX(Table1[[Especificação]:[Total Testes]],MATCH(Sheet1!C72,Table1[CONCAT],0),MATCH(Sheet1!B72,Table1[[#Headers],[Especificação]:[Total Testes]],0)) -> #N/A | H72: =ROUND(G72/8,2) -> #N/A
B73: =Table1[[#Headers],[Especificação]] -> Especificação | C73: =D73&"_"&E73 -> PROTECTION_VHCL_EMSSNS_SCR | D73: PROTECTION | E73: VHCL_EMSSNS_SCR | G73: =INDEX(Table1[[Especificação]:[Total Testes]],MATCH(Sheet1!C73,Table1[CONCAT],0),MATCH(Sheet1!B73,Table1[[#Headers],[Especificação]:[Total Testes]],0)) -> #N/A | H73: =ROUND(G73/8,2) -> #N/A
B74: =Table1[[#Headers],[Especificação]] -> Especificação | C74: =D74&"_"&E74 -> PROTECTION_INSRNC_ID | D74: PROTECTION | E74: INSRNC_ID | G74: =INDEX(Table1[[Especificação]:[Total Testes]],MATCH(Sheet1!C74,Table1[CONCAT],0),MATCH(Sheet1!B74,Table1[[#Headers],[Especificação]:[Total Testes]],0)) -> #N/A | H74: =ROUND(G74/8,2) -> #N/A
B75: =Table1[[#Headers],[Especificação]] -> Especificação | C75: =D75&"_"&E75 -> PROTECTION_TYP_HZRDS_INSRD | D75: PROTECTION | E75: TYP_HZRDS_INSRD | G75: =INDEX(Table1[[Especificação]:[Total Testes]],MATCH(Sheet1!C75,Table1[CONCAT],0),MATCH(Sheet1!B75,Table1[[#Headers],[Especificação]:[Total Testes]],0)) -> #N/A | H75: =ROUND(G75/8,2) -> #N/A
B76: =Table1[[#Headers],[Especificação]] -> Especificação | C76: =D76&"_"&E76 -> PROTECTION_AMNT_CVRD_INSRNC | D76: PROTECTION | E76: AMNT_CVRD_INSRNC | G76: =INDEX(Table1[[Especificação]:[Total Testes]],MATCH(Sheet1!C76,Table1[CONCAT],0),MATCH(Sheet1!B76,Table1[[#Headers],[Especificação]:[Total Testes]],0)) -> #N/A | H76: =ROUND(G76/8,2) -> #N/A
...

Sheet RESUMO
B2: Leverage Finance = "Y" | C2: =COUNTIFS('Lista - Âmbito Projeto GD'!$K$3:$K$71,"Y") -> 17
B4: Alteração | C4: Âmbito | D4: # Campos | E4: Observações | H4: Leveraged Finance | I4: STATUS | J4: AMBITO | K4: Status Data Lake | L4: # Campos
B5: Novo Campo | C5: ESTR (& outros) | D5: =GETPIVOTDATA("[Measures].[Count of ID Data field / Field order]",$H$4,"[Range].[STATUS]","[Range].[STATUS].&[Novo Campo]","[Range].[AMBITO]","[Range].[AMBITO].&[ESTR & GD & PILAR3]","[Range].[Status Data Lake]","[Range].[Status Data Lake].&[n/a]","[Range].[Leveraged Finance]","[Range].[Leveraged Finance].&[Y]") -> 1 | E5: n.a. | H5: N | I5: Campo eliminado | J5: PILAR3 | K5: n/a | L5: 1
C6: LF | D6: =GETPIVOTDATA("[Measures].[Count of ID Data field / Field order]",$H$4,"[Range].[STATUS]","[Range].[STATUS].&[Novo Campo]","[Range].[AMBITO]","[Range].[AMBITO].&[LF]","[Range].[Status Data Lake]","[Range].[Status Data Lake].&[n/a]","[Range].[Leveraged Finance]","[Range].[Leveraged Finance].&[Y]") -> 19 | E6: n.a. | I6: Campo eliminado - troca tabela | J6: GD & PILAR3 | K6: n/a | L6: 2
B7: Sem alterações | C7: ESTR (& outros) | D7: =SUM(L50:L72) -> 154 | E7: De notar que destes campos: - 9 provém da fonte manual de LF (lt601_lev_fin) - 39 estão sem dados/pouca qualidade com necessidades de (re)-especificações (Sindicados, Demonstrações Financeiras CIB, Re-estruturados) - 24 em testes/implementação - 15 com incidências nos controlos corporativos | J7: PILAR3 | K7: n/a | L7: 2
C8: Total | D8: =SUM(D5:D7) -> 174 | I8: Nome campo alterado | J8: PILAR3 | K8: n/a | L8: 2
I9: Nova Tabela | J9: ESTR & GD & PILAR3 | K9: n/a | L9: 1
J10: GD & PILAR3 | K10: n/a | L10: 3
B11: Leverage Finance = "N" | C11: =COUNTIFS('Lista - Âmbito Projeto GD'!$K$3:$K$71,"N") -> 51 | J11: PILAR3 | K11: n/a | L11: 3
I12: Nova Tabela - Campo existente | J12: GD & PILAR3 | K12: n/a | L12: 2
J13: PILAR3 | K13: n/a | L13: 2
B14: Alteração | C14: Âmbito | D14: # Campos | E14: Observações | I14: Novo Campo | J14: ESG_RISKS | K14: n/a | L14: 12
B15: Nova tabela | C15: ESTR (& outros) | D15: =GETPIVOTDATA("[Measures].[Count of ID Data field / Field order]",$H$4,"[Range].[STATUS]","[Range].[STATUS].&[Nova Tabela]","[Range].[AMBITO]","[Range].[AMBITO].&[ESTR & GD & PILAR3]","[Range].[Status Data Lake]","[Range].[Status Data Lake].&[n/a]","[Range].[Leveraged Finance]","[Range].[Leveraged Finance].&[N]") -> 1 | E15: Apenas 1 campo reportado na LT estrutural (questionar corporação) >>> é para ESG | J15: ESTR | K15: n/a | L15: 25
C16: GD & PILAR3 | D16: =GETPIVOTDATA("[Measures].[Count of ID Data field / Field order]",$H$4,"[Range].[STATUS]","[Range].[STATUS].&[Nova Tabela]","[Range].[AMBITO]","[Range].[AMBITO].&[GD & PILAR3]","[Range].[Status Data Lake]","[Range].[Status Data Lake].&[n/a]","[Range].[Leveraged Finance]","[Range].[Leveraged Finance].&[N]")+GETPIVOTDATA("[Measures].[Count of ID Data field / Field order]",$H$4,"[Range].[STATUS]","[Range].[STATUS].&[Nova Tabela - Campo existente]","[Range].[AMBITO]","[Range].[AMBITO].&[GD & PILAR3]","[Range].[Status Data Lake]","[Range].[Status Data Lake].&[n/a]","[Range].[Leveraged Finance]","[Range].[Leveraged Finance].&[N]") -> 5 | E16: De notar que 2 campos trocaram de tabela | J16: ESTR & GFINANCE | K16: n/a | L16: 7
C17: PILAR3 | D17: =GETPIVOTDATA("[Measures].[Count of ID Data field / Field order]",$H$4,"[Range].[STATUS]","[Range].[STATUS].&[Nova Tabela]","[Range].[AMBITO]","[Range].[AMBITO].&[PILAR3]","[Range].[Status Data Lake]","[Range].[Status Data Lake].&[n/a]","[Range].[Leveraged Finance]","[Range].[Leveraged Finance].&[N]")+GETPIVOTDATA("[Measures].[Count of ID Data field / Field order]",$H$4,"[Range].[STATUS]","[Range].[STATUS].&[Nova Tabela - Campo existente]","[Range].[AMBITO]","[Range].[AMBITO].&[PILAR3]","[Range].[Status Data Lake]","[Range].[Status Data Lake].&[n/a]","[Range].[Leveraged Finance]","[Range].[Leveraged Finance].&[N]") -> 5 | E17: De notar que 2 campos trocaram de tabela | J17: GD | K17: n/a | L17: 1
B18: Novo Campo | C18: ESTR | D18: =GETPIVOTDATA("[Measures].[Count of ID Data field / Field order]",$H$4,"[Range].[STATUS]","[Range].[STATUS].&[Novo Campo]","[Range].[AMBITO]","[Range].[AMBITO].&[ESTR]","[Range].[Status Data Lake]","[Range].[Status Data Lake].&[n/a]","[Range].[Leveraged Finance]","[Range].[Leveraged Finance].&[N]") -> 25 | E18: n.a. | J18: GD & PILAR3 | K18: n/a | L18: 1
C19: ESTR (& Green Finance) | D19: =GETPIVOTDATA("[Measures].[Count of ID Data field / Field order]",$H$4,"[Range].[STATUS]","[Range].[STATUS].&[Novo Campo]","[Range].[AMBITO]","[Range].[AMBITO].&[ESTR & GFINANCE]","[Range].[Status Data Lake]","[Range].[Status Data Lake].&[n/a]","[Range].[Leveraged Finance]","[Range].[Leveraged Finance].&[N]") -> 7 | E19: n.a. | J19: PILAR3 | K19: n/a | L19: 29
C20: GD & PILAR3 | D20: =GETPIVOTDATA("[Measures].[Count of ID Data field / Field order]",$H$4,"[Range].[STATUS]","[Range].[STATUS].&[Novo Campo]","[Range].[AMBITO]","[Range].[AMBITO].&[GD & PILAR3]","[Range].[Status Data Lake]","[Range].[Status Data Lake].&[n/a]","[Range].[Leveraged Finance]","[Range].[Leveraged Finance].&[N]") -> 1 | E20: n.a. | I20: Sem alteração | J20: ESTR | K20: 1. Especificar | L20: 9
C21: PILAR3 | D21: =GETPIVOTDATA("[Measures].[Count of ID Data field / Field order]",$H$4,"[Range].[STATUS]","[Range].[STATUS].&[Novo Campo]","[Range].[AMBITO]","[Range].[AMBITO].&[PILAR3]","[Range].[Status Data Lake]","[Range].[Status Data Lake].&[n/a]","[Range].[Leveraged Finance]","[Range].[Leveraged Finance].&[N]") -> 29 | E21: n.a. | K21: 2. Alterar especificação | L21: 15
C22: GD | D22: =GETPIVOTDATA("[Measures].[Count of ID Data field / Field order]",$H$4,"[Range].[STATUS]","[Range].[STATUS].&[Novo Campo]","[Range].[AMBITO]","[Range].[AMBITO].&[GD]","[Range].[Status Data Lake]","[Range].[Status Data Lake].&[n/a]","[Range].[Leveraged Finance]","[Range].[Leveraged Finance].&[N]") -> 1 | E22: n.a. | K22: 3. Pendente de decisão | L22: 1
C23: ESG Risks | D23: =GETPIVOTDATA("[Measures].[Count of ID Data field / Field order]",$H$4,"[Range].[STATUS]","[Range].[STATUS].&[Novo Campo]","[Range].[AMBITO]","[Range].[AMBITO].&[ESG_RISKS]","[Range].[Status Data Lake]","[Range].[Status Data Lake].&[n/a]","[Range].[Leveraged Finance]","[Range].[Leveraged Finance].&[N]") -> 12 | E23: Campos adicionados pela Corporação antes de abril e não contemplados no Data Lake. | K23: 4.1 Em implementação - Re-especificação | L23: 13
B24: Nome de campo alterado | C24: PILAR3 | D24: =GETPIVOTDATA("[Measures].[Count of ID Data field / Field order]",$H$4,"[Range].[STATUS]","[Range].[STATUS].&[Nome campo alterado]","[Range].[AMBITO]","[Range].[AMBITO].&[PILAR3]","[Range].[Status Data Lake]","[Range].[Status Data Lake].&[n/a]","[Range].[Leveraged Finance]","[Range].[Leveraged Finance].&[N]") -> 2 | E24: Sem impacto previsto a nível de re-especificação. | K24: 4.2 Em implementação - Incidência | L24: 1
B25: Sem alterações | C25: - | D25: =SUM(L20:L47) -> 269 | E25: De notar que destes campos (âmbito ESTR): - 29 estão sem dados/pouca qualidade com necessidades de (re)-especificações (Salários, Demonstrações Financeiras CIB) - 27 em testes/implementação - 42 com incidências nos controlos corporativos | K25: 5.1 Em testes - Re-especificação | L25: 7
C26: Total (excl. campos elim.) | D26: =SUM(D15:D25) -> 357 | K26: 5.2 Em testes - Incidência | L26: 2
B27: Campo eliminado | C27: GD & PILAR3 | D27: =GETPIVOTDATA("[Measures].[Count of ID Data field / Field order]",$H$4,"[Range].[STATUS]","[Range].[STATUS].&[Campo eliminado - troca tabela]","[Range].[AMBITO]","[Range].[AMBITO].&[GD & PILAR3]","[Range].[Status Data Lake]","[Range].[Status Data Lake].&[n/a]","[Range].[Leveraged Finance]","[Range].[Leveraged Finance].&[N]") -> 2 | E27: De notar que 2 campos trocaram de tabela | K27: 7. Analisar controlos e completude | L27: 36
C28: PILAR3 | D28: =GETPIVOTDATA("[Measures].[Count of ID Data field / Field order]",$H$4,"[Range].[STATUS]","[Range].[STATUS].&[Campo eliminado]","[Range].[AMBITO]","[Range].[AMBITO].&[PILAR3]","[Range].[Status Data Lake]","[Range].[Status Data Lake].&[n/a]","[Range].[Leveraged Finance]","[Range].[Leveraged Finance].&[N]")+GETPIVOTDATA("[Measures].[Count of ID Data field / Field order]",$H$4,"[Range].[STATUS]","[Range].[STATUS].&[Campo eliminado - troca tabela]","[Range].[AMBITO]","[Range].[AMBITO].&[PILAR3]","[Range].[Status Data Lake]","[Range].[Status Data Lake].&[n/a]","[Range].[Leveraged Finance]","[Range].[Leveraged Finance].&[N]") -> 3 | E28: De notar que 2 campos trocaram de tabela | K28: 8. Concluído - sem dados | L28: 6
D29: =D26+SUM(D27:D28) -> 362 | K29: 9. Concluído | L29: 73
J30: ESTR & GD | K30: 5.1 Em testes - Re-especificação | L30: 1
K31: 9. Concluído | L31: 1
J32: ESTR & GD & PILAR3 | K32: 4.1 Em implementação - Re-especificação | L32: 1
K33: 5.2 Em testes - Incidência | L33: 1
K34: 7. Analisar controlos e completude | L34: 3
K35: 9. Concluído | L35: 6
J36: ESTR & GFINANCE | K36: 9. Concluído | L36: 1
J37: ESTR & PILAR3 | K37: 1. Especificar | L37: 1
K38: 2. Alterar especificação | L38: 2
C39: Green finance + ESG Risks o que são e para que são utilizados >> 7+12 | K39: 3. Pendente de decisão | L39: 1
C40: Quem está a solicitar esta informação? >> 25 campos ESTR >> custo à unidade | K40: 4.1 Em implementação - Re-especificação | L40: 1
K41: 7. Analisar controlos e completude | L41: 3
B42: Confirmar com ficheiro enviado pela Raquel > LF | K42: 9. Concluído | L42: 6
...

Sheet Plano SCA
I1: =SUM(J1:BF1) -> 823.2 | J1: =J4*8 -> 16.8 | K1: =K4*8 -> 16.8 | L1: =L4*8 -> 16.8 | M1: =M4*8 -> 16.8 | N1: =N4*8 -> 16.8 | O1: =O4*8 -> 16.8 | P1: =P4*8 -> 16.8 | Q1: =Q4*8 -> 16.8 | ... BF1: =BF4*8 -> 16.8
I2: VAL | J2: =J3-J4 -> 0 | K2: =K3-K4 -> 0 | L2: =L3-L4 -> 0 | M2: =M3-M4 -> 0 | N2: =N3-N4 -> 0 | O2: =O3-O4 -> 0 | P2: =P3-P4 -> 0 | Q2: =Q3-Q4 -> 0 | ... BF2: =BF3-BF4 -> -1.575
I3: FTE REAIS | J3: =SUM(J8:J102) -> 2.1 | K3: =SUM(K8:K102) -> 2.1 | L3: =SUM(L8:L102) -> 2.1 | M3: =SUM(M8:M102) -> 2.1 | N3: =SUM(N8:N102) -> 2.1 | O3: =SUM(O8:O102) -> 2.1 | P3: =SUM(P8:P102) -> 2.1 | Q3: =SUM(Q8:Q102) -> 2.1 | ... BF3: =SUM(BF8:BF102) -> 0.525
I4: FTE ESP. | J4: 2.1 | K4: 2.1 | L4: 2.1 | M4: 2.1 | N4: 2.1 | O4: 2.1 | P4: 2.1 | Q4: 2.1 | R4: 2.1 | S4: 2.1 | T4: 2.1 | U4: 2.1 | V4: 2.1 | W4: 2.1 | X4: 2.1 | Y4: 2.1 | Z4: 2.1 | AA4: 2.1 | AB4: 2.1 | AC4: 2.1 | AD4: 2.1 | AE4: 2.1 | AF4: 2.1 | AG4: 2.1 | AH4: 2.1 | AI4: 2.1 | AJ4: 2.1 | AK4: 2.1 | AL4: 2.1 | AM4: 2.1 | AN4: 2.1 | AO4: 2.1 | AP4: 2.1 | AQ4: 2.1 | AR4: 2.1 | AS4: 2.1 | AT4: 2.1 | AU4: 2.1 | AV4: 2.1 | AW4: 2.1 | AX4: 2.1 | AY4: 2.1 | AZ4: 2.1 | BA4: 2.1 | BB4: 2.1 | BC4: 2.1 | BD4: 2.1 | BE4: 2.1 | BF4: 2.1
J5: Mês 1 | AG5: Mês 2 | BD5: Mês 3
I6: 45657 | J6: =WORKDAY(I6,1) -> 45658 | K6: =WORKDAY(J6,1) -> 45659 | L6: =WORKDAY(K6,1) -> 45660 | M6: 4 | N6: =WORKDAY(M6,1) -> 5 | O6: =WORKDAY(N6,1) -> 6 | P6: =WORKDAY(O6,1) -> 9 | Q6: =WORKDAY(P6,1) -> 10 | R6: =WORKDAY(Q6,1) -> 11 | S6: =WORKDAY(R6,1) -> 12 | T6: =WORKDAY(S6,1) -> 13 | U6: =WORKDAY(T6,1) -> 16 | ... X6: =WORKDAY(W6,1) -> 19
F7: # Campos | G7: Duração (horas) | H7: Duração (Dias) | I7: VAL | J7: 1 | K7: =J7+1 -> 2 | L7: =K7+1 -> 3 | M7: =L7+1 -> 4 | N7: =M7+1 -> 5 | O7: =N7+1 -> 6 | P7: =O7+1 -> 7 | Q7: =P7+1 -> 8 | R7: =Q7+1 -> 9 | ... BZ7: =BY7+1 -> 69
C9: Gestão Projeto | F9: n.a. | G9: =H9*8*5 -> 0 | H9: =SUM(J9:M9) -> 0
C10: 0. Gestão Projeto | F10: n.a. | G10: =H10*8 -> 51.2 | H10: =SUM(J10:BU10) -> 6.4 | I10: =SUM(J10:BU10)-H10 -> 0 | J10: 0.1 | K10: 0.1 | L10: 0.1 | M10: 0.1 | N10: 0.1 | O10: 0.1 | P10: 0.1 | Q10: 0.1 | R10: 0.1 | S10: 0.1 | T10: 0.1 | U10: 0.1 | V10: 0.1 | W10: 0.1 | X10: 0.1 | Y10: 0.1 | Z10: 0.1 | AA10: 0.1 | AB10: 0.1 | AC10: 0.1 | AD10: 0.1 | AE10: 0.1 | AF10: 0.1 | AG10: 0.1 | AH10: 0.1 | AI10: 0.1 | AJ10: 0.1 | AK10: 0.1 | AL10: 0.1 | AM10: 0.1 | AN10: 0.1 | AO10: 0.1 | AP10: 0.1 | AQ10: 0.1 | AR10: 0.1 | AS10: 0.1 | AT10: 0.1 | AU10: 0.1 | AV10: 0.1 | AW10: 0.1 | AX10: 0.1 | AY10: 0.1 | AZ10: 0.1 | BA10: 0.1 | BB10: 0.1 | BC10: 0.1 | BD10: 0.1 | BE10: 0.1 | BF10: 0.1 | BG10: 0.1 | BH10: 0.1 | BI10: 0.1 | BJ10: 0.1 | BK10: 0.1 | BL10: 0.1 | BM10: 0.1 | BN10: 0.1 | BO10: 0.1 | BP10: 0.1 | BQ10: 0.1 | BR10: 0.1 | BS10: 0.1 | BT10: 0.1 | BU10: 0.1 | BV10: 0.1 | BW10: 0.1 | BX10: 0.1 | BY10: 0.1 | BZ10: 0.1
C11: 1. Set-Up | F11: n.a. | G11: =8*4 -> 32 | H11: =G11/8 -> 4 | I11: =SUM(J11:CQ11)-H11 -> 0 | J11: 2 | K11: 2
C12: 2. Assessment ao Green Dashboard (Esp. Atual) | F12: n.a. | G12: =8*8 -> 64 | H12: =G12/8 -> 8 | I12: =SUM(J12:CQ12)-H12 -> 0 | L12: 2 | M12: 2 | N12: 2 | O12: 2
C13: 3. Re-testes aos campos concluídos do GD âmbito projeto anterior | F13: =COUNTA(D14:D36) -> 23 | G13: =SUM(G14:G36) -> 82 | H13: =G13/8 -> 10.25 | I13: =SUM(J13:CQ13)-H13 -> 0 | P13: 2 | Q13: 2 | R13: 2 | S13: 2 | T13: 2 | U13: 0.25
B14: =C14&"_"&D14 -> INSTRUMENT_COD_SOC | C14: INSTRUMENT | D14: COD_SOC | F14: =VLOOKUP(B14,'Aux DE'!B:P,15,0) -> SCA SCB1 | G14: =SUMIF('Aux DE'!B:B,'Plano SCA'!B14,'Aux DE'!I:I)+SUMIF('Aux DE'!B:B,'Plano SCA'!B14,'Aux DE'!O:O) -> 3.5 | I14: =SUM(J14:CQ14)-H14 -> 0
B15: =C15&"_"&D15 -> INSTRUMENT_SUBPORTFOLIO_ID | C15: INSTRUMENT | D15: SUBPORTFOLIO_ID | F15: =VLOOKUP(B15,'Aux DE'!B:P,15,0) -> SCA SCB1 | G15: =SUMIF('Aux DE'!B:B,'Plano SCA'!B15,'Aux DE'!I:I)+SUMIF('Aux DE'!B:B,'Plano SCA'!B15,'Aux DE'!O:O) -> 3.5 | I15: =SUM(J15:CQ15)-H15 -> 0
B16: =C16&"_"&D16 -> INSTRUMENT_DT_RFRNC | C16: INSTRUMENT | D16: DT_RFRNC | F16: =VLOOKUP(B16,'Aux DE'!B:P,15,0) -> SCA SCB1 | G16: =SUMIF('Aux DE'!B:B,'Plano SCA'!B16,'Aux DE'!I:I)+SUMIF('Aux DE'!B:B,'Plano SCA'!B16,'Aux DE'!O:O) -> 3.5 | I16: =SUM(J16:CQ16)-H16 -> 0
B17: =C17&"_"&D17 -> INSTRUMENT_DFLT_STTS_INSTRMNT | C17: INSTRUMENT | D17: DFLT_STTS_INSTRMNT | F17: =VLOOKUP(B17,'Aux DE'!B:P,15,0) -> SCA SCB1 | G17: =SUMIF('Aux DE'!B:B,'Plano SCA'!B17,'Aux DE'!I:I)+SUMIF('Aux DE'!B:B,'Plano SCA'!B17,'Aux DE'!O:O) -> 3.5 | I17: =SUM(J17:CQ17)-H17 -> 0
B18: =C18&"_"&D18 -> INSTRUMENT_IMPRMNT_STTS | C18: INSTRUMENT | D18: IMPRMNT_STTS | F18: =VLOOKUP(B18,'Aux DE'!B:P,15,0) -> SCA SCB1 | G18: =SUMIF('Aux DE'!B:B,'Plano SCA'!B18,'Aux DE'!I:I)+SUMIF('Aux DE'!B:B,'Plano SCA'!B18,'Aux DE'!O:O) -> 3.5 | I18: =SUM(J18:CQ18)-H18 -> 0
B19: =C19&"_"&D19 -> INSTRUMENT_PRFRMNG_STTS | C19: INSTRUMENT | D19: PRFRMNG_STTS | F19: =VLOOKUP(B19,'Aux DE'!B:P,15,0) -> SCA SCB1 | G19: =SUMIF('Aux DE'!B:B,'Plano SCA'!B19,'Aux DE'!I:I)+SUMIF('Aux DE'!B:B,'Plano SCA'!B19,'Aux DE'!O:O) -> 3.5 | I19: =SUM(J19:CQ19)-H19 -> 0
B20: =C20&"_"&D20 -> INSTRUMENT_TYP_INSTRMNT | C20: INSTRUMENT | D20: TYP_INSTRMNT | F20: =VLOOKUP(B20,'Aux DE'!B:P,15,0) -> SCA SCB1 | G20: =SUMIF('Aux DE'!B:B,'Plano SCA'!B20,'Aux DE'!I:I)+SUMIF('Aux DE'!B:B,'Plano SCA'!B20,'Aux DE'!O:O) -> 3.5 | I20: =SUM(J20:CQ20)-H20 -> 0
B21: =C21&"_"&D21 -> INSTRUMENT_GRSS_CRRYNG_AMNT_INSTRMNT | C21: INSTRUMENT | D21: GRSS_CRRYNG_AMNT_INSTRMNT | F21: =VLOOKUP(B21,'Aux DE'!B:P,15,0) -> SCA SCB1 | G21: =SUMIF('Aux DE'!B:B,'Plano SCA'!B21,'Aux DE'!I:I)+SUMIF('Aux DE'!B:B,'Plano SCA'!B21,'Aux DE'!O:O) -> 3.5 | I21: =SUM(J21:CQ21)-H21 -> 0
B22: =C22&"_"&D22 -> INSTRUMENT_ACCMLTD_CHNGS_FV_CR_INSTRMNT | C22: INSTRUMENT | D22: ACCMLTD_CHNGS_FV_CR_INSTRMNT | F22: =VLOOKUP(B22,'Aux DE'!B:P,15,0) -> SCA SCB1 | G22: =SUMIF('Aux DE'!B:B,'Plano SCA'!B22,'Aux DE'!I:I)+SUMIF('Aux DE'!B:B,'Plano SCA'!B22,'Aux DE'!O:O) -> 3.5 | I22: =SUM(J22:CQ22)-H22 -> 0
B23: =C23&"_"&D23 -> INSTRUMENT_ACCNTNG_CLSSFCTN | C23: INSTRUMENT | D23: ACCNTNG_CLSSFCTN | F23: =VLOOKUP(B23,'Aux DE'!B:P,15,0) -> SCA SCB1 | G23: =SUMIF('Aux DE'!B:B,'Plano SCA'!B23,'Aux DE'!I:I)+SUMIF('Aux DE'!B:B,'Plano SCA'!B23,'Aux DE'!O:O) -> 3.5 | I23: =SUM(J23:CQ23)-H23 -> 0
B24: =C24&"_"&D24 -> INSTRUMENT_OFF_BLNC_SHT_AMNT_INSTRMNT | C24: INSTRUMENT | D24: OFF_BLNC_SHT_AMNT_INSTRMNT | F24: =VLOOKUP(B24,'Aux DE'!B:P,15,0) -> SCA SCB1 | G24: =SUMIF('Aux DE'!B:B,'Plano SCA'!B24,'Aux DE'!I:I)+SUMIF('Aux DE'!B:B,'Plano SCA'!B24,'Aux DE'!O:O) -> 3.5 | I24: =SUM(J24:CQ24)-H24 -> 0
B25: =C25&"_"&D25 -> INSTRUMENT_PRVSNS_OFF_BLNC_SHT | C25: INSTRUMENT | D25: PRVSNS_OFF_BLNC_SHT | F25: =VLOOKUP(B25,'Aux DE'!B:P,15,0) -> SCA SCB1 | G25: =SUMIF('Aux DE'!B:B,'Plano SCA'!B25,'Aux DE'!I:I)+SUMIF('Aux DE'!B:B,'Plano SCA'!B25,'Aux DE'!O:O) -> 3.5 | I25: =SUM(J25:CQ25)-H25 -> 0
... B36: =C36&"_"&D36 -> INSTRUMENT_RWA_OFF_BLNC | C36: INSTRUMENT | D36: RWA_OFF_BLNC | F36: =VLOOKUP(B36,'Aux DE'!B:P,15,0) -> SCA SCB1 | G36: =SUMIF('Aux DE'!B:B,'Plano SCA'!B36,'Aux DE'!I:I)+SUMIF('Aux DE'!B:B,'Plano SCA'!B36,'Aux DE'!O:O) -> 3.5 | I36: =SUM(J36:CQ36)-H36 -> 0
C37: 4. Especificação de novos requisitos | F37: =COUNTA(D38:D51) -> 14 | G37: =SUM(G38:G51) -> 15 | H37: =G37/8 -> 1.875 | I37: =SUM(J37:CQ37)-H37 -> 0 | U37: 1.75 | V37: 0.125
B38: =C38&"_"&D38 -> INSTRUMENT_CCF | C38: INSTRUMENT | D38: CCF | F38: =VLOOKUP(B38,'Aux DE'!B:P,15,0) -> SCA SCB1 | G38: =SUMIF('Aux DE'!B:B,'Plano SCA'!B38,'Aux DE'!H:H) -> 1 | I38: =SUM(J38:CQ38)-H38 -> 0
B39: =C39&"_"&D39 -> INSTRUMENT_EAD | C39: INSTRUMENT | D39: EAD | F39: =VLOOKUP(B39,'Aux DE'!B:P,15,0) -> SCA SCB1 | G39: =SUMIF('Aux DE'!B:B,'Plano SCA'!B39,'Aux DE'!H:H) -> 1 | I39: =SUM(J39:CQ39)-H39 -> 0
B40: =C40&"_"&D40 -> INSTRUMENT_TYP_OFF_BLNC_PRDCT | C40: INSTRUMENT | D40: TYP_OFF_BLNC_PRDCT | F40: =VLOOKUP(B40,'Aux DE'!B:P,15,0) -> SCA SCB1 | G40: =SUMIF('Aux DE'!B:B,'Plano SCA'!B40,'Aux DE'!H:H) -> 1 | I40: =SUM(J40:CQ40)-H40 -> 0
B41: =C41&"_"&D41 -> INSTR_PROTECTION_COD_SOC | C41: INSTR_PROTECTION | D41: COD_SOC | F41: =VLOOKUP(B41,'Aux DE'!B:P,15,0) -> SCA SCB1 | G41: =SUMIF('Aux DE'!B:B,'Plano SCA'!B41,'Aux DE'!H:H) -> 1 | I41: =SUM(J41:CQ41)-H41 -> 0
B42: =C42&"_"&D42 -> INSTR_PROTECTION_DT_RFRNC | C42: INSTR_PROTECTION | D42: DT_RFRNC | F42: =VLOOKUP(B42,'Aux DE'!B:P,15,0) -> SCA SCB1 | G42: =SUMIF('Aux DE'!B:B,'Plano SCA'!B42,'Aux DE'!H:H) -> 1 | I42: =SUM(J42:CQ42)-H42 -> 0
B43: =C43&"_"&D43 -> INSTR_PROTECTION_INSTRMNT_ID | C43: INSTR_PROTECTION | D43: INSTRMNT_ID | F43: =VLOOKUP(B43,'Aux DE'!B:P,15,0) -> SCA SCB1 | G43: =SUMIF('Aux DE'!B:B,'Plano SCA'!B43,'Aux DE'!H:H) -> 1 | I43: =SUM(J43:CQ43)-H43 -> 0
B44: =C44&"_"&D44 -> INSTR_PROTECTION_PRTCTN_ID | C44: INSTR_PROTECTION | D44: PRTCTN_ID | F44: =VLOOKUP(B44,'Aux DE'!B:P,15,0) -> SCA SCB1 | G44: =SUMIF('Aux DE'!B:B,'Plano SCA'!B44,'Aux DE'!H:H) -> 1 | I44: =SUM(J44:CQ44)-H44 -> 0
B45: =C45&"_"&D45 -> PROTECTION_COD_SOC | C45: PROTECTION | D45: COD_SOC | F45: =VLOOKUP(B45,'Aux DE'!B:P,15,0) -> SCA SCB1 | G45: =SUMIF('Aux DE'!B:B,'Plano SCA'!B45,'Aux DE'!H:H) -> 1 | I45: =SUM(J45:CQ45)-H45 -> 0
B46: =C46&"_"&D46 -> PROTECTION_DT_RFRNC | C46: PROTECTION | D46: DT_RFRNC | F46: =VLOOKUP(B46,'Aux DE'!B:P,15,0) -> SCA SCB1 | G46: =SUMIF('Aux DE'!B:B,'Plano SCA'!B46,'Aux DE'!H:H) -> 1 | I46: =SUM(J46:CQ46)-H46 -> 0
B47: =C47&"_"&D47 -> PROTECTION_PRTCTN_ID | C47: PROTECTION | D47: PRTCTN_ID | F47: =VLOOKUP(B47,'Aux DE'!B:P,15,0) -> SCA SCB1 | G47: =SUMIF('Aux DE'!B:B,'Plano SCA'!B47,'Aux DE'!H:H) -> 1 | I47: =SUM(J47:CQ47)-H47 -> 0
B48: =C48&"_"&D48 -> PROTECTION_TYP_PRTCTN | C48: PROTECTION | D48: TYP_PRTCTN | F48: =VLOOKUP(B48,'Aux DE'!B:P,15,0) -> SCA SCB1 | G48: =SUMIF('Aux DE'!B:B,'Plano SCA'!B48,'Aux DE'!H:H) -> 1 | I48: =SUM(J48:CQ48)-H48 -> 0
B49: =C49&"_"&D49 -> PROTECTION_PRTCTN_VL | C49: PROTECTION | D49: PRTCTN_VL | F49: =VLOOKUP(B49,'Aux DE'!B:P,15,0) -> SCA SCB1 | G49: =SUMIF('Aux DE'!B:B,'Plano SCA'!B49,'Aux DE'!H:H) -> 1 | I49: =SUM(J49:CQ49)-H49 -> 0
... B51: =C51&"_"&D51 -> INSTR_ACTIVITY_PRCNTG_ACTVTY | C51: INSTR_ACTIVITY | D51: PRCNTG_ACTVTY | F51: =VLOOKUP(B51,'Aux DE'!B:P,15,0) -> SCA SCB1 | G51: =SUMIF('Aux DE'!B:B,'Plano SCA'!B51,'Aux DE'!H:H) -> 1 | I51: =SUM(J51:CQ51)-H51 -> 0
C52: 5. Testes/Re-testes | G52: =G53+G54+G100 -> 498.4 | I52: =SUM(J52:CQ52)-H52 -> 0
...

Sheet LISTA - Abril2024
A1: ID Data field / Field order | C1: Table | D1: Data field | E1: Field name | F1: Structural ECB Loan Tape | G1: Green Dashboard | H1: Pillar III ESG | I1: ESG Risks
A2: EN.001 | B2: =C2&"_"&D2 -> ENTITY_COD_SOC | C2: ENTITY | D2: COD_SOC | E2: Entity code of the informing society. | F2: Y | G2: N | H2: Y | I2: Y
A3: EN.002 | B3: =C3&"_"&D3 -> ENTITY_CNTRY | C3: ENTITY | D3: CNTRY | E3: Country of counterparty residence | F3: Y | G3: N | H3: Y | I3: Y
A4: EN.003 | B4: =C4&"_"&D4 -> ENTITY_DT_BRTH | C4: ENTITY | D4: DT_BRTH | E4: Birth date counterparty | F4: Y | G4: N | H4: N | I4: N
A5: EN.004 | B5: =C5&"_"&D5 -> ENTITY_DT_DFLT_STTS | C5: ENTITY | D5: DT_DFLT_STTS | E5: Date of default status | F5: Y | G5: N | H5: N | I5: N
A6: EN.005 | B6: =C6&"_"&D6 -> ENTITY_DT_FNNCL_STTMTS | C6: ENTITY | D6: DT_FNNCL_STTMTS | E6: Date of financial statements | F6: Y | G6: N | H6: N | I6: N
A7: EN.006 | B7: =C7&"_"&D7 -> ENTITY_DT_FNNCL_STTMTS_PRVS | C7: ENTITY | D7: DT_FNNCL_STTMTS_PRVS | E7: Date of previous fiscal year financial statements | F7: Y | G7: N | H7: N | I7: N
A8: EN.007 | B8: =C8&"_"&D8 -> ENTITY_DT_INTTN_LGL_PRCDNGS_LE | C8: ENTITY | D8: DT_INTTN_LGL_PRCDNGS_LE | E8: Date of initiation of legal proceedings counterparty (LE) | F8: Y | G8: N | H8: N | I8: N
A9: EN.008 | B9: =C9&"_"&D9 -> ENTITY_DT_PRFRMNG_STTS_LE | C9: ENTITY | D9: DT_PRFRMNG_STTS_LE | E9: Date of performing status | F9: Y | G9: N | H9: N | I9: N
A10: EN.009 | B10: =C10&"_"&D10 -> ENTITY_DT_RFRNC | C10: ENTITY | D10: DT_RFRNC | E10: Reference date. | F10: Y | G10: N | H10: Y | I10: N
A11: EN.010 | B11: =C11&"_"&D11 -> ENTITY_ENTTY_ID | C11: ENTITY | D11: ENTTY_ID | E11: Entity ID | F11: Y | G11: N | H11: Y | I11: Y
A12: EN.011 | B12: =C12&"_"&D12 -> ENTITY_GCC_PRNT_ID | C12: ENTITY | D12: GCC_PRNT_ID | E12: Identifier for the parent entity of a group of connected clients | F12: Y | G12: N | H12: N | I12: N
A13: EN.012 | B13: =C13&"_"&D13 -> ENTITY_GCC_PRNT_NM | C13: ENTITY | D13: GCC_PRNT_NM | E13: Name of the parent entity of a group of connected clients | F13: Y | G13: N | H13: N | I13: N
... A478: PR.066 | B478: =C478&"_"&D478 -> PROTECTION_LN_PSTN | C478: PROTECTION | D478: LN_PSTN | E478: Lien position | F478: Y | G478: N | H478: N | I478: N

Sheet LISTA - Atual
A1: ID Data field / Field order | C1: Table | D1: Data field | E1: Field name | F1: Structural ECB Loan Tape | G1: Green Dashboard | H1: Pillar III ESG | I1: ESG Risks | J1: SCIB GLOBAL FIELD | L1: Structural ECB Loan Tape | M1: val | N1: Green Dashboard | O1: val | P1: Pillar III ESG | Q1: val | R1: ESG Risks | S1: val | U1: xx
A2: EN.001 | B2: =C2&"_"&D2 -> ENTITY_COD_SOC | C2: ENTITY | D2: COD_SOC | E2: Entity code of the informing society. | F2: Y | G2: N | H2: Y | I2: Y | J2: N | L2: =IFERROR(VLOOKUP($B2,'Lista - Âmbito Projeto GD'!$B$3:$F$71,5,0),"Campo eliminado") -> Campo eliminado | M2: =IF(L2="Campo eliminado","Campo eliminado",IF(L2=F2,"Igual","Diferente")) -> Campo eliminado | N2: =IFERROR(VLOOKUP($B2,'Lista - Âmbito Projeto GD'!$B$3:$K$71,6,0),"Campo eliminado") -> Campo eliminado | O2: =IF(N2="Campo eliminado","Campo eliminado",IF(N2=G2,"Igual","Diferente")) -> Campo eliminado | P2: =IFERROR(VLOOKUP($B2,'Lista - Âmbito Projeto GD'!$B$3:$K$71,7,0),"Campo eliminado") -> Campo eliminado | Q2: =IF(P2="Campo eliminado","Campo eliminado",IF(P2=H2,"Igual","Diferente")) -> Campo eliminado | R2: =IFERROR(VLOOKUP($B2,'Lista - Âmbito Projeto GD'!$B$3:$K$71,9,0),"Campo eliminado") -> Campo eliminado | S2: =IF(R2="Campo eliminado","Campo eliminado",IF(R2=I2,"Igual","Diferente")) -> Campo eliminado | U2: =VLOOKUP(B2,DataLake!$A$4:$A$429,1,0) -> ENTITY_COD_SOC
A3: EN.002 | B3: =C3&"_"&D3 -> ENTITY_CNTRY | C3: ENTITY | D3: CNTRY | E3: Country of counterparty residence | F3: Y | G3: N | H3: Y | I3: Y | J3: N | L3: =IFERROR(VLOOKUP($B3,'Lista - Âmbito Projeto GD'!$B$3:$F$71,5,0),"Campo eliminado") -> Campo eliminado | M3: =IF(L3="Campo eliminado","Campo eliminado",IF(L3=F3,"Igual","Diferente")) -> Campo eliminado | N3: =IFERROR(VLOOKUP($B3,'Lista - Âmbito Projeto GD'!$B$3:$K$71,6,0),"Campo eliminado") -> Campo eliminado | O3: =IF(N3="Campo eliminado","Campo eliminado",IF(N3=G3,"Igual","Diferente")) -> Campo eliminado | P3: =IFERROR(VLOOKUP($B3,'Lista - Âmbito Projeto GD'!$B$3:$K$71,7,0),"Campo eliminado") -> Campo eliminado | Q3: =IF(P3="Campo eliminado","Campo eliminado",IF(P3=H3,"Igual","Diferente")) -> Campo eliminado | R3: =IFERROR(VLOOKUP($B3,'Lista - Âmbito Projeto GD'!$B$3:$K$71,9,0),"Campo eliminado") -> Campo eliminado | S3: =IF(R3="Campo eliminado","Campo eliminado",IF(R3=I3,"Igual","Diferente")) -> Campo eliminado | U3: =VLOOKUP(B3,DataLake!$A$4:$A$429,1,0) -> ENTITY_CNTRY
A4: EN.003 | B4: =C4&"_"&D4 -> ENTITY_DT_BRTH | C4: ENTITY | D4: DT_BRTH | E4: Birth date counterparty | F4: Y | G4: N | H4: N | I4: N | J4: N | L4: =IFERROR(VLOOKUP($B4,'Lista - Âmbito Projeto GD'!$B$3:$F$71,5,0),"Campo eliminado") -> Campo eliminado | M4: =IF(L4="Campo eliminado","Campo eliminado",IF(L4=F4,"Igual","Diferente")) -> Campo eliminado | N4: =IFERROR(VLOOKUP($B4,'Lista - Âmbito Projeto GD'!$B$3:$K$71,6,0),"Campo eliminado") -> Campo eliminado | O4: =IF(N4="Campo eliminado","Campo eliminado",IF(N4=G4,"Igual","Diferente")) -> Campo eliminado | P4: =IFERROR(VLOOKUP($B4,'Lista - Âmbito Projeto GD'!$B$3:$K$71,7,0),"Campo eliminado") -> Campo eliminado | Q4: =IF(P4="Campo eliminado","Campo eliminado",IF(P4=H4,"Igual","Diferente")) -> Campo eliminado | R4: =IFERROR(VLOOKUP($B4,'Lista - Âmbito Projeto GD'!$B$3:$K$71,9,0),"Campo eliminado") -> Campo eliminado | S4: =IF(R4="Campo eliminado","Campo eliminado",IF(R4=I4,"Igual","Diferente")) -> Campo eliminado | U4: =VLOOKUP(B4,DataLake!$A$4:$A$429,1,0) -> ENTITY_DT_BRTH
A5: EN.004 | B5: =C5&"_"&D5 -> ENTITY_DT_DFLT_STTS | C5: ENTITY | D5: DT_DFLT_STTS | E5: Date of default status | F5: Y | G5: N | H5: N | I5: N | J5: DT_DFLT_STTS | L5: =IFERROR(VLOOKUP($B5,'Lista - Âmbito Projeto GD'!$B$3:$F$71,5,0),"Campo eliminado") -> Campo eliminado | M5: =IF(L5="Campo eliminado","Campo eliminado",IF(L5=F5,"Igual","Diferente")) -> Campo eliminado | N5: =IFERROR(VLOOKUP($B5,'Lista - Âmbito Projeto GD'!$B$3:$K$71,6,0),"Campo eliminado") -> Campo eliminado | O5: =IF(N5="Campo eliminado","Campo eliminado",IF(N5=G5,"Igual","Diferente")) -> Campo eliminado | P5: =IFERROR(VLOOKUP($B5,'Lista - Âmbito Projeto GD'!$B$3:$K$71,7,0),"Campo eliminado") -> Campo eliminado | Q5: =IF(P5="Campo eliminado","Campo eliminado",IF(P5=H5,"Igual","Diferente")) -> Campo eliminado | R5: =IFERROR(VLOOKUP($B5,'Lista - Âmbito Projeto GD'!$B$3:$K$71,9,0),"Campo eliminado") -> Campo eliminado | S5: =IF(R5="Campo eliminado","Campo eliminado",IF(R5=I5,"Igual","Diferente")) -> Campo eliminado | U5: =VLOOKUP(B5,DataLake!$A$4:$A$429,1,0) -> ENTITY_DT_DFLT_STTS
A6: EN.005 | B6: =C6&"_"&D6 -> ENTITY_DT_FNNCL_STTMTS | C6: ENTITY | D6: DT_FNNCL_STTMTS | E6: Date of financial statements | F6: Y | G6: N | H6: N | I6: N | J6: DT_FNNCL_STTMTS | L6: =IFERROR(VLOOKUP($B6,'Lista - Âmbito Projeto GD'!$B$3:$F$71,5,0),"Campo eliminado") -> Campo eliminado | M6: =IF(L6="Campo eliminado","Campo eliminado",IF(L6=F6,"Igual","Diferente")) -> Campo eliminado | N6: =IFERROR(VLOOKUP($B6,'Lista - Âmbito Projeto GD'!$B$3:$K$71,6,0),"Campo eliminado") -> Campo eliminado | O6: =IF(N6="Campo eliminado","Campo eliminado",IF(N6=G6,"Igual","Diferente")) -> Campo eliminado | P6: =IFERROR(VLOOKUP($B6,'Lista - Âmbito Projeto GD'!$B$3:$K$71,7,0),"Campo eliminado") -> Campo eliminado | Q6: =IF(P6="Campo eliminado","Campo eliminado",IF(P6=H6,"Igual","Diferente")) -> Campo eliminado | R6: =IFERROR(VLOOKUP($B6,'Lista - Âmbito Projeto GD'!$B$3:$K$71,9,0),"Campo eliminado") -> Campo eliminado | S6: =IF(R6="Campo eliminado","Campo eliminado",IF(R6=I6,"Igual","Diferente")) -> Campo eliminado | U6: =VLOOKUP(B6,DataLake!$A$4:$A$429,1,0) -> ENTITY_DT_FNNCL_STTMTS
A7: EN.006 | B7: =C7&"_"&D7 -> ENTITY_DT_FNNCL_STTMTS_PRVS | C7: ENTITY | D7: DT_FNNCL_STTMTS_PRVS | E7: Date of previous fiscal year financial statements | F7: Y | G7: N | H7: N | I7: N | J7: DT_FNNCL_STTMTS_PRVS | L7: =IFERROR(VLOOKUP($B7,'Lista - Âmbito Projeto GD'!$B$3:$F$71,5,0),"Campo eliminado") -> Campo eliminado | M7: =IF(L7="Campo eliminado","Campo eliminado",IF(L7=F7,"Igual","Diferente")) -> Campo eliminado | N7: =IFERROR(VLOOKUP($B7,'Lista - Âmbito Projeto GD'!$B$3:$K$71,6,0),"Campo eliminado") -> Campo eliminado | O7: =IF(N7="Campo eliminado","Campo eliminado",IF(N7=G7,"Igual","Diferente")) -> Campo eliminado | P7: =IFERROR(VLOOKUP($B7,'Lista - Âmbito Projeto GD'!$B$3:$K$71,7,0),"Campo eliminado") -> Campo eliminado | Q7: =IF(P7="Campo eliminado","Campo eliminado",IF(P7=H7,"Igual","Diferente")) -> Campo eliminado | R7: =IFERROR(VLOOKUP($B7,'Lista - Âmbito Projeto GD'!$B$3:$K$71,9,0),"Campo eliminado") -> Campo eliminado | S7: =IF(R7="Campo eliminado","Campo eliminado",IF(R7=I7,"Igual","Diferente")) -> Campo eliminado | U7: =VLOOKUP(B7,DataLake!$A$4:$A$429,1,0) -> ENTITY_DT_FNNCL_STTMTS_PRVS
A8: EN.007 | B8: =C8&"_"&D8 -> ENTITY_DT_INTTN_LGL_PRCDNGS_LE | C8: ENTITY | D8: DT_INTTN_LGL_PRCDNGS_LE | E8: Date of initiation of legal proceedings counterparty (LE) | F8: Y | G8: N | H8: N | I8: N | J8: N | L8: =IFERROR(VLOOKUP($B8,'Lista - Âmbito Projeto GD'!$B$3:$F$71,5,0),"Campo eliminado") -> Campo eliminado | M8: =IF(L8="Campo eliminado","Campo eliminado",IF(L8=F8,"Igual","Diferente")) -> Campo eliminado | N8: =IFERROR(VLOOKUP($B8,'Lista - Âmbito Projeto GD'!$B$3:$K$71,6,0),"Campo eliminado") -> Campo eliminado | O8: =IF(N8="Campo eliminado","Campo eliminado",IF(N8=G8,"Igual","Diferente")) -> Campo eliminado | P8: =IFERROR(VLOOKUP($B8,'Lista - Âmbito Projeto GD'!$B$3:$K$71,7,0),"Campo eliminado") -> Campo eliminado | Q8: =IF(P8="Campo eliminado","Campo eliminado",IF(P8=H8,"Igual","Diferente")) -> Campo eliminado | R8: =IFERROR(VLOOKUP($B8,'Lista - Âmbito Projeto GD'!$B$3:$K$71,9,0),"Campo eliminado") -> Campo eliminado | S8: =IF(R8="Campo eliminado","Campo eliminado",IF(R8=I8,"Igual","Diferente")) -> Campo eliminado | U8: =VLOOKUP(B8,DataLake!$A$4:$A$429,1,0) -> ENTITY_DT_INTTN_LGL_PRCDNGS_LE
A9: EN.008 | B9: =C9&"_"&D9 -> ENTITY_DT_PRFRMNG_STTS_LE | C9: ENTITY | D9: DT_PRFRMNG_STTS_LE | E9: Date of performing status | F9: Y | G9: N | H9: N | I9: N | J9: N | L9: =IFERROR(VLOOKUP($B9,'Lista - Âmbito Projeto GD'!$B$3:$F$71,5,0),"Campo eliminado") -> Campo eliminado | M9: =IF(L9="Campo eliminado","Campo eliminado",IF(L9=F9,"Igual","Diferente")) -> Campo eliminado | N9: =IFERROR(VLOOKUP($B9,'Lista - Âmbito Projeto GD'!$B$3:$K$71,6,0),"Campo eliminado") -> Campo eliminado | O9: =IF(N9="Campo eliminado","Campo eliminado",IF(N9=G9,"Igual","Diferente")) -> Campo eliminado | P9: =IFERROR(VLOOKUP($B9,'Lista - Âmbito Projeto GD'!$B$3:$K$71,7,0),"Campo eliminado") -> Campo eliminado | Q9: =IF(P9="Campo eliminado","Campo eliminado",IF(P9=H9,"Igual","Diferente")) -> Campo eliminado | R9: =IFERROR(VLOOKUP($B9,'Lista - Âmbito Projeto GD'!$B$3:$K$71,9,0),"Campo eliminado") -> Campo eliminado | S9: =IF(R9="Campo eliminado","Campo eliminado",IF(R9=I9,"Igual","Diferente")) -> Campo eliminado | U9: =VLOOKUP(B9,DataLake!$A$4:$A$429,1,0) -> ENTITY_DT_PRFRMNG_STTS_LE
