Workbook

Sheet Sheet
B2: 1. Contratos do universo PM com chave MIS associada. No entanto o produto associado a essa chave MIS não é de ativo para âmbito GD.
B4: univ | C4: ref_date | D4: ambito | E4: segmento | F4: instrmnt_id | G4: cempcta | H4: ckbalcao | I4: cknumcta | J4: zdeposit_mis | K4: ckarea | L4: bsnss_area | M4: ckmetamis | O4: ckmetamis CT207 | P4: Notas
B5: COMUM PM | C5: 2025-01-31 | D5: GD | E5: ESTR | F5: 82000020210000346001520250013427 | G5: 31 | H5: 0000 | I5: 20210000346 | J5: V00500C68695I31 | K5: NULL | L5: ANALISE | M5: NULL | O5: {=INDEX(Sheet2!$A$1:$E$21,MATCH(1,(Sheet2!$B$1:$B$21=Sheet!H5)*(Sheet!I5=Sheet2!$C$1:$C$21)*(Sheet2!$D$1:$D$21=Sheet!J5),0),5)} -> SO0711 | P5: Apesar de ser produto de ativo, não o é para âmbito GD.
B6: COMUM PM | C6: 2025-01-31 | D6: GD | E6: ESTR | F6: 82000020210000171001520240616328 | G6: 31 | H6: 0000 | I6: 20210000171 | J6: V00500C16548I51 | K6: NULL | L6: ANALISE | M6: NULL | O6: {=INDEX(Sheet2!$A$1:$E$21,MATCH(1,(Sheet2!$B$1:$B$21=Sheet!H6)*(Sheet!I6=Sheet2!$C$1:$C$21)*(Sheet2!$D$1:$D$21=Sheet!J6),0),5)} -> SO0711 | P6: Apesar de ser produto de ativo, não o é para âmbito GD.
B7: COMUM PM | C7: 2025-01-31 | D7: GD | E7: ESTR | F7: 82000020210000346001520240581088 | G7: 31 | H7: 0000 | I7: 20210000346 | J7: V00500C19900I74 | K7: NULL | L7: ANALISE | M7: NULL | O7: {=INDEX(Sheet2!$A$1:$E$21,MATCH(1,(Sheet2!$B$1:$B$21=Sheet!H7)*(Sheet!I7=Sheet2!$C$1:$C$21)*(Sheet2!$D$1:$D$21=Sheet!J7),0),5)} -> SO0711 | P7: Apesar de ser produto de ativo, não o é para âmbito GD.
B8: COMUM PM | C8: 2025-01-31 | D8: GD | E8: ESTR | F8: 82000020220000261001520250017911 | G8: 31 | H8: 0000 | I8: 20220000261 | J8: V00500000C456I2 | K8: NULL | L8: ANALISE | M8: NULL | O8: {=INDEX(Sheet2!$A$1:$E$21,MATCH(1,(Sheet2!$B$1:$B$21=Sheet!H8)*(Sheet!I8=Sheet2!$C$1:$C$21)*(Sheet2!$D$1:$D$21=Sheet!J8),0),5)} -> SO0711 | P8: Apesar de ser produto de ativo, não o é para âmbito GD.
B9: COMUM PM | C9: 2025-01-31 | D9: GD | E9: ESTR | F9: 82000020240000766001520240655214 | G9: 31 | H9: 0000 | I9: 20240000766 | J9: V0050000C1250I2 | K9: NULL | L9: ANALISE | M9: NULL | O9: {=INDEX(Sheet2!$A$1:$E$21,MATCH(1,(Sheet2!$B$1:$B$21=Sheet!H9)*(Sheet!I9=Sheet2!$C$1:$C$21)*(Sheet2!$D$1:$D$21=Sheet!J9),0),5)} -> SO0711 | P9: Apesar de ser produto de ativo, não o é para âmbito GD.
B10: COMUM PM | C10: 2025-01-31 | D10: GD | E10: ESTR | F10: 82000020210000346001520250033068 | G10: 31 | H10: 0000 | I10: 20210000346 | J10: V0050C19903I387 | K10: NULL | L10: ANALISE | M10: NULL | O10: {=INDEX(Sheet2!$A$1:$E$21,MATCH(1,(Sheet2!$B$1:$B$21=Sheet!H10)*(Sheet!I10=Sheet2!$C$1:$C$21)*(Sheet2!$D$1:$D$21=Sheet!J10),0),5)} -> SO0711 | P10: Apesar de ser produto de ativo, não o é para âmbito GD.
B11: COMUM PM | C11: 2025-01-31 | D11: GD | E11: ESTR | F11: 31641600005800001PTOTEMOE0035000 | G11: 31 | H11: 6416 | I11: 00005800001 | J11: PTOTEMOE0035000 | K11: NULL | L11: ANALISE | M11: NULL | O11: {=INDEX(Sheet2!$A$1:$E$21,MATCH(1,(Sheet2!$B$1:$B$21=Sheet!H11)*(Sheet!I11=Sheet2!$C$1:$C$21)*(Sheet2!$D$1:$D$21=Sheet!J11),0),5)} -> SO20T1 | P11: Apesar de ser produto de ativo, não o é para âmbito GD.
B12: COMUM PM | C12: 2025-01-31 | D12: GD | E12: ESTR | F12: 82000020180003566000009000641544 | G12: 31 | H12: 0000 | I12: 20180003566 | J12: V005000C15754I5 | K12: NULL | L12: ANALISE | M12: NULL | O12: {=INDEX(Sheet2!$A$1:$E$21,MATCH(1,(Sheet2!$B$1:$B$21=Sheet!H12)*(Sheet!I12=Sheet2!$C$1:$C$21)*(Sheet2!$D$1:$D$21=Sheet!J12),0),5)} -> SO0711 | P12: Apesar de ser produto de ativo, não o é para âmbito GD.
B13: COMUM PM | C13: 2025-01-31 | D13: GD | E13: ESTR | F13: 31000311607554029116075540290000 | G13: 31 | H13: 0003 | I13: 11607554029 | J13: 116075540290000 | K13: NULL | L13: ANALISE | M13: NULL | O13: {=INDEX(Sheet2!$A$1:$E$21,MATCH(1,(Sheet2!$B$1:$B$21=Sheet!H13)*(Sheet!I13=Sheet2!$C$1:$C$21)*(Sheet2!$D$1:$D$21=Sheet!J13),0),5)} -> AAAAAA | P13: Apesar de ser produto de ativo, não o é para âmbito GD.
B14: COMUM PM | C14: 2025-01-31 | D14: GD | E14: ESTR | F14: 82000020240000772001520240676048 | G14: 31 | H14: 0000 | I14: 20240000772 | J14: 001520240676048 | K14: NULL | L14: ANALISE | M14: NULL | O14: {=INDEX(Sheet2!$A$1:$E$21,MATCH(1,(Sheet2!$B$1:$B$21=Sheet!H14)*(Sheet!I14=Sheet2!$C$1:$C$21)*(Sheet2!$D$1:$D$21=Sheet!J14),0),5)} -> SO0721 | P14: Apesar de ser produto de ativo, não o é para âmbito GD.
B15: COMUM PM | C15: 2025-01-31 | D15: GD | E15: ESTR | F15: 82000020220000128001520240514314 | G15: 31 | H15: 0000 | I15: 20220000128 | J15: 001520240514314 | K15: NULL | L15: ANALISE | M15: NULL | O15: {=INDEX(Sheet2!$A$1:$E$21,MATCH(1,(Sheet2!$B$1:$B$21=Sheet!H15)*(Sheet!I15=Sheet2!$C$1:$C$21)*(Sheet2!$D$1:$D$21=Sheet!J15),0),5)} -> SO0721 | P15: Apesar de ser produto de ativo, não o é para âmbito GD.
B16: COMUM PM | C16: 2025-01-31 | D16: GD | E16: ESTR | F16: 82000020210000346001520250003226 | G16: 31 | H16: 0000 | I16: 20210000346 | J16: V0050119990I406 | K16: NULL | L16: ANALISE | M16: NULL | O16: {=INDEX(Sheet2!$A$1:$E$21,MATCH(1,(Sheet2!$B$1:$B$21=Sheet!H16)*(Sheet!I16=Sheet2!$C$1:$C$21)*(Sheet2!$D$1:$D$21=Sheet!J16),0),5)} -> SO0711 | P16: Apesar de ser produto de ativo, não o é para âmbito GD.
... B24: COMUM PM | C24: 2025-01-31 | D24: GD | E24: ESTR | F24: 82000020210000070001520240617504 | G24: 31 | H24: 0000 | I24: 20210000070 | J24: V00500C53795I34 | K24: NULL | L24: ANALISE | M24: NULL | O24: {=INDEX(Sheet2!$A$1:$E$21,MATCH(1,(Sheet2!$B$1:$B$21=Sheet!H24)*(Sheet!I24=Sheet2!$C$1:$C$21)*(Sheet2!$D$1:$D$21=Sheet!J24),0),5)} -> SO0711 | P24: Apesar de ser produto de ativo, não o é para âmbito GD.

Sheet Sheet2
A1: cempcta | B1: ckbalcao | C1: cknumcta | D1: zdeposit | E1: ckmetamis
A2: 31 | B2: 0000 | C2: 20220000261 | D2: V00500000C456I2 | E2: SO0711
A3: 31 | B3: 0000 | C3: 20210000346 | D3: V0050119990I406 | E3: SO0711
A4: 31 | B4: 0000 | C4: 20240000766 | D4: V0050000C1250I2 | E4: SO0711
A5: 31 | B5: 0000 | C5: 20220000128 | D5: 001520240514314 | E5: SO0721
A6: 31 | B6: 0000 | C6: 20240000764 | D6: V0050C121362I11 | E6: SO0711
A7: 31 | B7: 0000 | C7: 20180003566 | D7: V005000C15754I5 | E7: SO0711
A8: 31 | B8: 0000 | C8: 20210000346 | D8: V00500C68695I31 | E8: SO0711
A9: 31 | B9: 6636 | C9: 00350249966 | D9: 036360350249966 | E9: SO0503
A10: 31 | B10: 0000 | C10: 20230000339 | D10: V0051C117043I10 | E10: SO0721
A11: 31 | B11: 0000 | C11: 20090004009 | D11: V00510C64286I19 | E11: SO0721
A12: 31 | B12: 0000 | C12: 20210000346 | D12: V0050C19903I387 | E12: SO0711
... A21: 31 | B21: 0000 | C21: 20210000346 | D21: V0050117622I295 | E21: SO0711

Sheet Sheet3
A1: metaproduto | B1: tipo_conta_local | C1: ambito
A2: AAAAAA | B2: Ativo | C2: ALM | G2: AAAAAA
A3: AAAAAA | B3: Ativo | C3: BDR | G3: SO0303
A4: SO0303 | B4: Ativo | C4: ALM | G4: SO0503
A5: SO0303 | B5: Ativo | C5: RORAC | G5: SO0702
A6: SO0303 | B6: Ativo | C6: BDR | G6: SO0711
A7: SO0303 | B7: Ativo | C7: SMES | G7: SO0721
A8: SO0503 | B8: Ativo | C8: RORAC | G8: SO0722
A9: SO0503 | B9: Ativo | C9: SMES | G9: SO201A
A10: SO0503 | B10: Ativo | C10: BDR | G10: SO202A
A11: SO0503 | B11: Ativo | C11: ALM | G11: SO20T1
A12: SO0702 | B12: Ativo | C12: ALM
A13: SO0702 | B13: Ativo | C13: SMES
A14: SO0702 | B14: Ativo | C14: RORAC
A15: SO0702 | B15: Ativo | C15: BDR
A16: SO0711 | B16: Ativo | C16: ALM
A17: SO0711 | B17: Ativo | C17: RORAC
A18: SO0711 | B18: Ativo | C18: BDR
A19: SO0711 | B19: Ativo | C19: SMES
A20: SO0721 | B20: Ativo | C20: BDR
A21: SO0721 | B21: Ativo | C21: RORAC
A22: SO0721 | B22: Ativo | C22: SMES
A23: SO0721 | B23: Ativo | C23: ALM
... A39: SO20T1 | B39: Ativo | C39: RORAC

Sheet Detalhe ckmetamis
B6: 1) ckmetamis dos contratos que apresentam chave MIS mas que não conseguimos cruzar com o universo de rentabilidade filtrado por produto de ativo
B8: ckmetamis | C8: tipo_conta_local | D8: Âmbito | E8: # Registos | F8: Observações
B9: AAAAAA | C9: Ativo | D9: ALM | E9: 1226 | F9: Incluir na tabela de parametrização ct831
B10: AAAAAA | C10: Ativo | D10: BDR | E10: 1226 | F10: Incluir na tabela de parametrização ct831
B11: GGGGGG | C11: Passivo | D11: BDR | E11: 2
B12: GGGGGG | C12: Passivo | D12: SMES | E12: 2
B13: GGGGGG | C13: Passivo | D13: RORAC | E13: 2
B14: GGGGGG | C14: Passivo | D14: ALM | E14: 2
B15: INFORM | C15: Passivo | D15: ALM | E15: 90
B16: INFORM | C16: Passivo | D16: RORAC | E16: 90
B17: INFORM | C17: Passivo | D17: BDR | E17: 90
B18: INFORM | C18: Passivo | D18: SMES | E18: 90
B19: NULL | C19: NULL | D19: NULL | E19: 12
B20: PI0101 | C20: Passivo | D20: SMES | E20: 2
B21: PI0101 | C21: Passivo | D21: ALM | E21: 2
B22: PI0101 | C22: Passivo | D22: RORAC | E22: 2
... B55: PI0275 | C55: Passivo | D55: RORAC | E55: 12
B56: SO0303 | C56: Ativo | D56: ALM | E56: 2 | F56: Incluir na tabela de parametrização ct831
B57: SO0303 | C57: Ativo | D57: SMES | E57: 2 | F57: Incluir na tabela de parametrização ct831
B58: SO0303 | C58: Ativo | D58: BDR | E58: 2 | F58: Incluir na tabela de parametrização ct831
B59: SO0303 | C59: Ativo | D59: RORAC | E59: 2 | F59: Incluir na tabela de parametrização ct831
B60: SO0501 | C60: Passivo | D60: ALM | E60: 1
B61: SO0501 | C61: Passivo | D61: RORAC | E61: 1
B62: SO0501 | C62: Passivo | D62: SMES | E62: 1
B63: SO0501 | C63: Passivo | D63: BDR | E63: 1
B64: SO0503 | C64: Ativo | D64: RORAC | E64: 1723 | F64: Incluir na tabela de parametrização ct831
B65: SO0503 | C65: Ativo | D65: BDR | E65: 1723 | F65: Incluir na tabela de parametrização ct831
B66: SO0503 | C66: Ativo | D66: ALM | E66: 1723 | F66: Incluir na tabela de parametrização ct831
B67: SO0503 | C67: Ativo | D67: SMES | E67: 1723 | F67: Incluir na tabela de parametrização ct831
B68: SO0505 | C68: Passivo | D68: BDR | E68: 1
B69: SO0505 | C69: Passivo | D69: ALM | E69: 1
B70: SO0505 | C70: Passivo | D70: RORAC | E70: 1
B71: SO0505 | C71: Passivo | D71: SMES | E71: 1
B72: SO0702 | C72: Ativo | D72: SMES | E72: 1 | F72: Incluir na tabela de parametrização ct831
B73: SO0702 | C73: Ativo | D73: ALM | E73: 1 | F73: Incluir na tabela de parametrização ct831
B74: SO0702 | C74: Ativo | D74: RORAC | E74: 1 | F74: Incluir na tabela de parametrização ct831
B75: SO0702 | C75: Ativo | D75: BDR | E75: 1 | F75: Incluir na tabela de parametrização ct831
B76: SO0711 | C76: Ativo | D76: RORAC | E76: 107399 | F76: Incluir na tabela de parametrização ct831
B77: SO0711 | C77: Ativo | D77: ALM | E77: 107399 | F77: Incluir na tabela de parametrização ct831
B78: SO0711 | C78: Ativo | D78: BDR | E78: 107399 | F78: Incluir na tabela de parametrização ct831
...

Sheet ckmetamis em falta
B6: ckmetamis em falta
B7: AAAAAA | C7: generico de ativo | D7: vai entrar como ativo patrimonial | H7: SO0702 | I7: =+VLOOKUP(H7,$B$7:$B$13,1,TRUE) -> SO0702 | J7: =+VLOOKUP(B7,$H$7:$H$16,1,TRUE) -> #N/A
B8: SO0303 | C8: emprestimos moratoria | D8: Serviços | H8: SO20T1 | I8: =+VLOOKUP(H8,$B$7:$B$13,1,TRUE) -> SO0722 | J8: =+VLOOKUP(B8,$H$7:$H$16,1,TRUE) -> #N/A
B9: SO0503 | C9: remessas doc. De exportacao | D9: Serviços | H9: SO0503 | I9: =+VLOOKUP(H9,$B$7:$B$13,1,TRUE) -> SO0503 | J9: =+VLOOKUP(B9,$H$7:$H$16,1,TRUE) -> #N/A
B10: SO0702 | C10: Serviços | D10: outros servios renting | E10: intermediario de negócio. Não pertence balanço | H10: SO0721 | I10: =+VLOOKUP(H10,$B$7:$B$13,1,TRUE) -> SO0721 | J10: =+VLOOKUP(B10,$H$7:$H$16,1,TRUE) -> SO0702
B11: SO0711 | C11: Serviços | D11: outros serviços factoring nacional | H11: SO0711 | I11: =+VLOOKUP(H11,$B$7:$B$13,1,TRUE) -> SO0711 | J11: =+VLOOKUP(B11,$H$7:$H$16,1,TRUE) -> SO0711
B12: SO0721 | C12: Serviços | D12: outr serv. Factoring exportacao | H12: SO201A | I12: =+VLOOKUP(H12,$B$7:$B$13,1,TRUE) -> SO0722 | J12: =+VLOOKUP(B12,$H$7:$H$16,1,TRUE) -> AAAAAA
B13: SO0722 | C13: Serviços | D13: importacao | H13: SO202A | I13: =+VLOOKUP(H13,$B$7:$B$13,1,TRUE) -> SO0722 | J13: =+VLOOKUP(B13,$H$7:$H$16,1,TRUE) -> SO0722
H14: AAAAAA | I14: =+VLOOKUP(H14,$B$7:$B$13,1,TRUE) -> AAAAAA
H15: SO0722 | I15: =+VLOOKUP(H15,$B$7:$B$13,1,TRUE) -> SO0722
H16: SO0303 | I16: =+VLOOKUP(H16,$B$7:$B$13,1,TRUE) -> SO0303

Sheet Sheet1
A1: GGGGGG
A2: INFORM | D2: INSTRMNT_ID | E2: CHAVE_MIS
A3: PI0101 | D3: 31000311591402029000000000000000 | E3: 31000311591402029000000000000000 | F3: tem um saldo devedor na contabilidade
A4: PI0102 | D4: 31000040144033650000000000000000 | E4: 31000040144033650000000000000000
A5: PI0103
A6: PI0104
A7: PI0108
A8: PI0113
A9: PI0207
A10: PI0262
A11: PI0275
A12: SO0501
A13: SO0505
A14: SO201P
A15: SO202P
A16: UP0000
