Workbook

Sheet Exemplos Validação
A1: univ | B1: ref_date | C1: ambito | D1: segmento | E1: instrmnt_id_aux | F1: instrmnt_id | G1: lcl_instrmnt_id | H1: cempcta | I1: ckbalcao | J1: cknumcta | K1: zdeposit_mis | L1: ckarea | M1: bsnss_area | N1: cnclld_instrmnt_stts | O1: nw_bsnss | P1: mngmnt_prdct | Q1: flg_intrbsnss | R1: intrbsnss_adj_cod | S1: cod_soc_dstntn | T1: bsnss_area_dstntn | U1: intrnl_trnsfr_rt_off_blnc | V1: rwa_off_blnc | W1: grss_intrst_incm_ccrr | X1: grss_intrst_expns_ccrr | Y1: grss_cmmssn_incm_ccrr | Z1: grss_cmmssn_expns_ccrr | AA1: gns_fnncl_trnsctn_exchng_ccrr | AB1: bsnss_area_ccrr | AC1: grss_cmmssn_incm_off_blnc_ccrr | AD1: grss_cmmssn_expns_off_blnc_ccrr | AE1: ccf | AF1: ead | AG1: imprmnt_stts | AH1: prfrmng_stts | AI1: grss_crryng_amnt_instrmnt | AJ1: accmltd_chngs_fv_cr_instrmnt | AK1: off_blnc_sht_amnt_instrmnt | AL1: prvsns_off_blnc_sht | AM1: rwa | AN1: accmltd_imprmnt_instrmnt | AO1: last_ref_date | AP1: typ_off_blnc_prdct | AQ1: subportfolio_id | AR1: dflt_stts_instrmnt | AS1: typ_instrmnt | AT1: accntng_clssfctn | AU1: cod_soc_intrgrp | AV1: msaldo_final | AW1: msaldo_mis | AX1: count_chave | AY1: ponderador | AZ1: grss_cmmssn_incm | BA1: EXCEL_grss_cmmssn_incm | BB1: VALIDAÇÃO | BC1: grss_cmmssn_incm_off_blnc | BD1: =_xlfn.CONCAT("EXCEL_",BC1) -> EXCEL_grss_cmmssn_incm_off_blnc | BE1: VALIDAÇÃO | BF1: grss_cmmssn_expns | BG1: =_xlfn.CONCAT("EXCEL_",BF1) -> EXCEL_grss_cmmssn_expns | BH1: VALIDAÇÃO | BI1: grss_cmmssn_expns_off_blnc | BJ1: =_xlfn.CONCAT("EXCEL_",BI1) -> EXCEL_grss_cmmssn_expns_off_blnc | BK1: VALIDAÇÃO | BL1: nt_ln_lss_prvsn | BM1: =_xlfn.CONCAT("EXCEL_",BL1) -> EXCEL_nt_ln_lss_prvsn | BN1: VALIDAÇÃO | BO1: nt_ln_lss_prvsn_off_blnc | BP1: =_xlfn.CONCAT("EXCEL_",BO1) -> EXCEL_nt_ln_lss_prvsn_off_blnc | BQ1: VALIDAÇÃO | BR1: grss_intrst_incm | BS1: =_xlfn.CONCAT("EXCEL_",BR1) -> EXCEL_grss_intrst_incm | BT1: VALIDAÇÃO | BU1: grss_intrst_expns | BV1: =_xlfn.CONCAT("EXCEL_",BU1) -> EXCEL_grss_intrst_expns | BW1: VALIDAÇÃO | BX1: gns_fnncl_trnsctn_exchng_dffrncs | BY1: =_xlfn.CONCAT("EXCEL_",BX1) -> EXCEL_gns_fnncl_trnsctn_exchng_dffrncs | BZ1: VALIDAÇÃO | CA1: intrnl_trnsfr_rt | CB1: =_xlfn.CONCAT("EXCEL_",CA1) -> EXCEL_intrnl_trnsfr_rt | CC1: VALIDAÇÃO | CD1: avrg_blnc | CE1: =_xlfn.CONCAT("EXCEL_",CD1) -> EXCEL_avrg_blnc | CF1: VALIDAÇÃO | CG1: avrg_blnc_off_blnc | CH1: =_xlfn.CONCAT("EXCEL_",CG1) -> EXCEL_avrg_blnc_off_blnc | CI1: VALIDAÇÃO
A2: COMUM PM | B2: 2025-03-31 | C2: GD | D2: ESTR | E2: 82000020100005442001520240283046 | F2: 82000020100005442001520240283046 | G2: 82000020100005442001520240283046 | H2: 31 | I2: 0000 | J2: 20100005442 | K2: V0050C33343I125 | L2: AN01040220 | M2: BA5 | N2: N | O2: Y | P2: PRDCT010103 | Q2: N | R2: N/A | S2: 00000 | T2: N/A | U2: 11111111111 | V2: 11111111111 | W2: 11111111111 | X2: 11111111111 | Y2: 11111111111 | Z2: 11111111111 | AA2: 11111111111 | AB2: N/A | AC2: 11111111111 | AD2: 11111111111 | AE2: 0.000000 | AF2: 23319.29 | AG2: 23 | AH2: 11 | AI2: 75291.08 | AJ2: 11111111111.00 | AK2: 0.00 | AL2: 0.00 | AM2: 0.00 | AN2: 0.00 | AO2: 2025-03-31 | AP2: N/A | AQ2: APCAPRES1P | AR2: 14 | AS2: 71 | AT2: 6 | AU2: 00000 | AV2: 75291.08 | AW2: 929165.44 | AX2: 21 | AY2: 0.08103 | AZ2: 0 | BA2: {=INDEX('Cálculo excel'!$B$2:$X$36,MATCH(1,('Exemplos Validação'!$F2='Cálculo excel'!$B$2:$B$36)*('Cálculo excel'!$C$2:$C$36='Exemplos Validação'!$H2)*('Exemplos Validação'!$I2='Cálculo excel'!$D$2:$D$36)*('Cálculo excel'!$E$2:$E$36='Exemplos Validação'!$J2)*('Exemplos Validação'!$K2='Cálculo excel'!$F$2:$F$36),0),11)} -> 0 | BB2: =BA2-AZ2 -> 0 | BC2: 0 | BD2: {=INDEX('Cálculo excel'!$B$2:$X$36,MATCH(1,('Exemplos Validação'!$F2='Cálculo excel'!$B$2:$B$36)*('Cálculo excel'!$C$2:$C$36='Exemplos Validação'!$H2)*('Exemplos Validação'!$I2='Cálculo excel'!$D$2:$D$36)*('Cálculo excel'!$E$2:$E$36='Exemplos Validação'!$J2)*('Exemplos Validação'!$K2='Cálculo excel'!$F$2:$F$36),0),12)} -> 0 | BE2: =BD2-BC2 -> 0 | BF2: 0 | BG2: {=INDEX('Cálculo excel'!$B$2:$X$36,MATCH(1,('Exemplos Validação'!$F2='Cálculo excel'!$B$2:$B$36)*('Cálculo excel'!$C$2:$C$36='Exemplos Validação'!$H2)*('Exemplos Validação'!$I2='Cálculo excel'!$D$2:$D$36)*('Cálculo excel'!$E$2:$E$36='Exemplos Validação'!$J2)*('Exemplos Validação'!$K2='Cálculo excel'!$F$2:$F$36),0),13)} -> 0 | BH2: =BG2-BF2 -> 0 | BI2: 0 | BJ2: {=INDEX('Cálculo excel'!$B$2:$X$36,MATCH(1,('Exemplos Validação'!$F2='Cálculo excel'!$B$2:$B$36)*('Cálculo excel'!$C$2:$C$36='Exemplos Validação'!$H2)*('Exemplos Validação'!$I2='Cálculo excel'!$D$2:$D$36)*('Cálculo excel'!$E$2:$E$36='Exemplos Validação'!$J2)*('Exemplos Validação'!$K2='Cálculo excel'!$F$2:$F$36),0),14)} -> 0 | BK2: =BJ2-BI2 -> 0 | BL2: 0 | BM2: {=INDEX('Cálculo excel'!$B$2:$X$36,MATCH(1,('Exemplos Validação'!$F2='Cálculo excel'!$B$2:$B$36)*('Cálculo excel'!$C$2:$C$36='Exemplos Validação'!$H2)*('Exemplos Validação'!$I2='Cálculo excel'!$D$2:$D$36)*('Cálculo excel'!$E$2:$E$36='Exemplos Validação'!$J2)*('Exemplos Validação'!$K2='Cálculo excel'!$F$2:$F$36),0),15)} -> 0 | BN2: =BM2-BL2 -> 0 | BO2: 0 | BP2: {=INDEX('Cálculo excel'!$B$2:$X$36,MATCH(1,('Exemplos Validação'!$F2='Cálculo excel'!$B$2:$B$36)*('Cálculo excel'!$C$2:$C$36='Exemplos Validação'!$H2)*('Exemplos Validação'!$I2='Cálculo excel'!$D$2:$D$36)*('Cálculo excel'!$E$2:$E$36='Exemplos Validação'!$J2)*('Exemplos Validação'!$K2='Cálculo excel'!$F$2:$F$36),0),16)} -> 0 | BQ2: =BP2-BO2 -> 0 | BR2: 0 | BS2: {=INDEX('Cálculo excel'!$B$2:$X$36,MATCH(1,('Exemplos Validação'!$F2='Cálculo excel'!$B$2:$B$36)*('Cálculo excel'!$C$2:$C$36='Exemplos Validação'!$H2)*('Exemplos Validação'!$I2='Cálculo excel'!$D$2:$D$36)*('Cálculo excel'!$E$2:$E$36='Exemplos Validação'!$J2)*('Exemplos Validação'!$K2='Cálculo excel'!$F$2:$F$36),0),17)} -> 0 | BT2: =BS2-BR2 -> 0 | BU2: 0 | BV2: {=INDEX('Cálculo excel'!$B$2:$X$36,MATCH(1,('Exemplos Validação'!$F2='Cálculo excel'!$B$2:$B$36)*('Cálculo excel'!$C$2:$C$36='Exemplos Validação'!$H2)*('Exemplos Validação'!$I2='Cálculo excel'!$D$2:$D$36)*('Cálculo excel'!$E$2:$E$36='Exemplos Validação'!$J2)*('Exemplos Validação'!$K2='Cálculo excel'!$F$2:$F$36),0),18)} -> 0 | BW2: =BV2-BU2 -> 0 | BX2: 0 | BY2: {=INDEX('Cálculo excel'!$B$2:$X$36,MATCH(1,('Exemplos Validação'!$F2='Cálculo excel'!$B$2:$B$36)*('Cálculo excel'!$C$2:$C$36='Exemplos Validação'!$H2)*('Exemplos Validação'!$I2='Cálculo excel'!$D$2:$D$36)*('Cálculo excel'!$E$2:$E$36='Exemplos Validação'!$J2)*('Exemplos Validação'!$K2='Cálculo excel'!$F$2:$F$36),0),19)} -> 0 | BZ2: =BY2-BX2 -> 0 | CA2: 0 | CB2: {=INDEX('Cálculo excel'!$B$2:$X$36,MATCH(1,('Exemplos Validação'!$F2='Cálculo excel'!$B$2:$B$36)*('Cálculo excel'!$C$2:$C$36='Exemplos Validação'!$H2)*('Exemplos Validação'!$I2='Cálculo excel'!$D$2:$D$36)*('Cálculo excel'!$E$2:$E$36='Exemplos Validação'!$J2)*('Exemplos Validação'!$K2='Cálculo excel'!$F$2:$F$36),0),20)} -> 0 | CC2: =CB2-CA2 -> 0 | CD2: 0 | CE2: {=INDEX('Cálculo excel'!$B$2:$X$36,MATCH(1,('Exemplos Validação'!$F2='Cálculo excel'!$B$2:$B$36)*('Cálculo excel'!$C$2:$C$36='Exemplos Validação'!$H2)*('Exemplos Validação'!$I2='Cálculo excel'!$D$2:$D$36)*('Cálculo excel'!$E$2:$E$36='Exemplos Validação'!$J2)*('Exemplos Validação'!$K2='Cálculo excel'!$F$2:$F$36),0),21)} -> 0 | CF2: =CE2-CD2 -> 0 | CG2: 0 | CH2: {=INDEX('Cálculo excel'!$B$2:$X$36,MATCH(1,('Exemplos Validação'!$F2='Cálculo excel'!$B$2:$B$36)*('Cálculo excel'!$C$2:$C$36='Exemplos Validação'!$H2)*('Exemplos Validação'!$I2='Cálculo excel'!$D$2:$D$36)*('Cálculo excel'!$E$2:$E$36='Exemplos Validação'!$J2)*('Exemplos Validação'!$K2='Cálculo excel'!$F$2:$F$36),0),22)+INDEX('Cálculo excel'!$B$2:$X$36,MATCH(1,('Exemplos Validação'!$F2='Cálculo excel'!$B$2:$B$36)*('Cálculo excel'!$C$2:$C$36='Exemplos Validação'!$H2)*('Exemplos Validação'!$I2='Cálculo excel'!$D$2:$D$36)*('Cálculo excel'!$E$2:$E$36='Exemplos Validação'!$J2)*('Exemplos Validação'!$K2='Cálculo excel'!$F$2:$F$36),0),23)} -> 0 | CI2: =CH2-CG2 -> 0
A3: COMUM PM | B3: 2025-03-31 | C3: GD | D3: ESTR | E3: 82000020100005442001520250102622 | F3: 82000020100005442001520250102622 | G3: 82000020100005442001520250102622 | H3: 31 | I3: 0000 | J3: 20100005442 | K3: V0050C33343I125 | L3: AN01040220 | M3: BA5 | N3: N | O3: Y | P3: PRDCT010103 | Q3: N | R3: N/A | S3: 00000 | T3: N/A | U3: 11111111111 | V3: 11111111111 | W3: 11111111111 | X3: 11111111111 | Y3: 11111111111 | Z3: 11111111111 | AA3: 11111111111 | AB3: N/A | AC3: 11111111111 | AD3: 11111111111 | AE3: 0.000000 | AF3: 684.80 | AG3: 23 | AH3: 11 | AI3: 2211.01 | AJ3: 11111111111.00 | AK3: 0.00 | AL3: 0.00 | AM3: 0.00 | AN3: 0.00 | AO3: 2025-03-31 | AP3: N/A | AQ3: APCAPRES1P | AR3: 14 | AS3: 71 | AT3: 6 | AU3: 00000 | AV3: 2211.01 | AW3: 929165.44 | AX3: 21 | AY3: 0.002379 | AZ3: 0 | BA3: {=INDEX('Cálculo excel'!$B$2:$X$36,MATCH(1,('Exemplos Validação'!$F3='Cálculo excel'!$B$2:$B$36)*('Cálculo excel'!$C$2:$C$36='Exemplos Validação'!$H3)*('Exemplos Validação'!$I3='Cálculo excel'!$D$2:$D$36)*('Cálculo excel'!$E$2:$E$36='Exemplos Validação'!$J3)*('Exemplos Validação'!$K3='Cálculo excel'!$F$2:$F$36),0),11)} -> 0 | BB3: =BA3-AZ3 -> 0 | BC3: 0 | BD3: {=INDEX('Cálculo excel'!$B$2:$X$36,MATCH(1,('Exemplos Validação'!$F3='Cálculo excel'!$B$2:$B$36)*('Cálculo excel'!$C$2:$C$36='Exemplos Validação'!$H3)*('Exemplos Validação'!$I3='Cálculo excel'!$D$2:$D$36)*('Cálculo excel'!$E$2:$E$36='Exemplos Validação'!$J3)*('Exemplos Validação'!$K3='Cálculo excel'!$F$2:$F$36),0),12)} -> 0 | BE3: =BD3-BC3 -> 0 | BF3: 0 | BG3: {=INDEX('Cálculo excel'!$B$2:$X$36,MATCH(1,('Exemplos Validação'!$F3='Cálculo excel'!$B$2:$B$36)*('Cálculo excel'!$C$2:$C$36='Exemplos Validação'!$H3)*('Exemplos Validação'!$I3='Cálculo excel'!$D$2:$D$36)*('Cálculo excel'!$E$2:$E$36='Exemplos Validação'!$J3)*('Exemplos Validação'!$K3='Cálculo excel'!$F$2:$F$36),0),13)} -> 0 | BH3: =BG3-BF3 -> 0 | BI3: 0 | BJ3: {=INDEX('Cálculo excel'!$B$2:$X$36,MATCH(1,('Exemplos Validação'!$F3='Cálculo excel'!$B$2:$B$36)*('Cálculo excel'!$C$2:$C$36='Exemplos Validação'!$H3)*('Exemplos Validação'!$I3='Cálculo excel'!$D$2:$D$36)*('Cálculo excel'!$E$2:$E$36='Exemplos Validação'!$J3)*('Exemplos Validação'!$K3='Cálculo excel'!$F$2:$F$36),0),14)} -> 0 | BK3: =BJ3-BI3 -> 0 | BL3: 0 | BM3: {=INDEX('Cálculo excel'!$B$2:$X$36,MATCH(1,('Exemplos Validação'!$F3='Cálculo excel'!$B$2:$B$36)*('Cálculo excel'!$C$2:$C$36='Exemplos Validação'!$H3)*('Exemplos Validação'!$I3='Cálculo excel'!$D$2:$D$36)*('Cálculo excel'!$E$2:$E$36='Exemplos Validação'!$J3)*('Exemplos Validação'!$K3='Cálculo excel'!$F$2:$F$36),0),15)} -> 0 | BN3: =BM3-BL3 -> 0 | BO3: 0 | BP3: {=INDEX('Cálculo excel'!$B$2:$X$36,MATCH(1,('Exemplos Validação'!$F3='Cálculo excel'!$B$2:$B$36)*('Cálculo excel'!$C$2:$C$36='Exemplos Validação'!$H3)*('Exemplos Validação'!$I3='Cálculo excel'!$D$2:$D$36)*('Cálculo excel'!$E$2:$E$36='Exemplos Validação'!$J3)*('Exemplos Validação'!$K3='Cálculo excel'!$F$2:$F$36),0),16)} -> 0 | BQ3: =BP3-BO3 -> 0 | BR3: 0 | BS3: {=INDEX('Cálculo excel'!$B$2:$X$36,MATCH(1,('Exemplos Validação'!$F3='Cálculo excel'!$B$2:$B$36)*('Cálculo excel'!$C$2:$C$36='Exemplos Validação'!$H3)*('Exemplos Validação'!$I3='Cálculo excel'!$D$2:$D$36)*('Cálculo excel'!$E$2:$E$36='Exemplos Validação'!$J3)*('Exemplos Validação'!$K3='Cálculo excel'!$F$2:$F$36),0),17)} -> 0 | BT3: =BS3-BR3 -> 0 | BU3: 0 | BV3: {=INDEX('Cálculo excel'!$B$2:$X$36,MATCH(1,('Exemplos Validação'!$F3='Cálculo excel'!$B$2:$B$36)*('Cálculo excel'!$C$2:$C$36='Exemplos Validação'!$H3)*('Exemplos Validação'!$I3='Cálculo excel'!$D$2:$D$36)*('Cálculo excel'!$E$2:$E$36='Exemplos Validação'!$J3)*('Exemplos Validação'!$K3='Cálculo excel'!$F$2:$F$36),0),18)} -> 0 | BW3: =BV3-BU3 -> 0 | BX3: 0 | BY3: {=INDEX('Cálculo excel'!$B$2:$X$36,MATCH(1,('Exemplos Validação'!$F3='Cálculo excel'!$B$2:$B$36)*('Cálculo excel'!$C$2:$C$36='Exemplos Validação'!$H3)*('Exemplos Validação'!$I3='Cálculo excel'!$D$2:$D$36)*('Cálculo excel'!$E$2:$E$36='Exemplos Validação'!$J3)*('Exemplos Validação'!$K3='Cálculo excel'!$F$2:$F$36),0),19)} -> 0 | BZ3: =BY3-BX3 -> 0 | CA3: 0 | CB3: {=INDEX('Cálculo excel'!$B$2:$X$36,MATCH(1,('Exemplos Validação'!$F3='Cálculo excel'!$B$2:$B$36)*('Cálculo excel'!$C$2:$C$36='Exemplos Validação'!$H3)*('Exemplos Validação'!$I3='Cálculo excel'!$D$2:$D$36)*('Cálculo excel'!$E$2:$E$36='Exemplos Validação'!$J3)*('Exemplos Validação'!$K3='Cálculo excel'!$F$2:$F$36),0),20)} -> 0 | CC3: =CB3-CA3 -> 0 | CD3: 0 | CE3: {=INDEX('Cálculo excel'!$B$2:$X$36,MATCH(1,('Exemplos Validação'!$F3='Cálculo excel'!$B$2:$B$36)*('Cálculo excel'!$C$2:$C$36='Exemplos Validação'!$H3)*('Exemplos Validação'!$I3='Cálculo excel'!$D$2:$D$36)*('Cálculo excel'!$E$2:$E$36='Exemplos Validação'!$J3)*('Exemplos Validação'!$K3='Cálculo excel'!$F$2:$F$36),0),21)} -> 0 | CF3: =CE3-CD3 -> 0 | CG3: 0 | CH3: {=INDEX('Cálculo excel'!$B$2:$X$36,MATCH(1,('Exemplos Validação'!$F3='Cálculo excel'!$B$2:$B$36)*('Cálculo excel'!$C$2:$C$36='Exemplos Validação'!$H3)*('Exemplos Validação'!$I3='Cálculo excel'!$D$2:$D$36)*('Cálculo excel'!$E$2:$E$36='Exemplos Validação'!$J3)*('Exemplos Validação'!$K3='Cálculo excel'!$F$2:$F$36),0),22)+INDEX('Cálculo excel'!$B$2:$X$36,MATCH(1,('Exemplos Validação'!$F3='Cálculo excel'!$B$2:$B$36)*('Cálculo excel'!$C$2:$C$36='Exemplos Validação'!$H3)*('Exemplos Validação'!$I3='Cálculo excel'!$D$2:$D$36)*('Cálculo excel'!$E$2:$E$36='Exemplos Validação'!$J3)*('Exemplos Validação'!$K3='Cálculo excel'!$F$2:$F$36),0),23)} -> 0 | CI3: =CH3-CG3 -> 0
A4: CANCELADOS | B4: 2025-03-31 | C4: GD | D4: ESTR | E4: 31000314940851096000000000000000 | F4: 31000314940851096000000000000000 | G4: 31000314940851096000000000000000 | H4: 31 | I4: 0003 | J4: 14940851096 | K4: 000000000000000 | L4: AN01010201 | M4: BA2 | N4: C | O4: Y | P4: PRDCT010101 | Q4: N | R4: N/A | S4: 00000 | T4: N/A | U4: 11111111111 | V4: 11111111111 | W4: 11111111111 | X4: 11111111111 | Y4: 11111111111 | Z4: 11111111111 | AA4: 11111111111 | AB4: N/A | AC4: 11111111111 | AD4: 11111111111 | AE4: 11111111111.000000 | AF4: 11111111111.00 | AG4: 11111111111 | AH4: 11111111111 | AI4: 0.00 | AJ4: 0.00 | AK4: 0.00 | AL4: 0.00 | AM4: 0.00 | AN4: 0.00 | AO4: 2025-02-28 | AP4: N/A | AQ4: HOGCAPRES1P | AR4: 14 | AS4: 1004 | AT4: 6 | AU4: 00000 | AV4: 29706.82 | AW4: 29706.82 | AX4: 1 | AY4: 1 | AZ4: 947.63 | BA4: {=INDEX('Cálculo excel'!$B$2:$X$36,MATCH(1,('Exemplos Validação'!$F4='Cálculo excel'!$B$2:$B$36)*('Cálculo excel'!$C$2:$C$36='Exemplos Validação'!$H4)*('Exemplos Validação'!$I4='Cálculo excel'!$D$2:$D$36)*('Cálculo excel'!$E$2:$E$36='Exemplos Validação'!$J4)*('Exemplos Validação'!$K4='Cálculo excel'!$F$2:$F$36),0),11)} -> 947.63 | BB4: =BA4-AZ4 -> 0 | BC4: 0 | BD4: {=INDEX('Cálculo excel'!$B$2:$X$36,MATCH(1,('Exemplos Validação'!$F4='Cálculo excel'!$B$2:$B$36)*('Cálculo excel'!$C$2:$C$36='Exemplos Validação'!$H4)*('Exemplos Validação'!$I4='Cálculo excel'!$D$2:$D$36)*('Cálculo excel'!$E$2:$E$36='Exemplos Validação'!$J4)*('Exemplos Validação'!$K4='Cálculo excel'!$F$2:$F$36),0),12)} -> 0 | BE4: =BD4-BC4 -> 0 | BF4: 285.38 | BG4: {=INDEX('Cálculo excel'!$B$2:$X$36,MATCH(1,('Exemplos Validação'!$F4='Cálculo excel'!$B$2:$B$36)*('Cálculo excel'!$C$2:$C$36='Exemplos Validação'!$H4)*('Exemplos Validação'!$I4='Cálculo excel'!$D$2:$D$36)*('Cálculo excel'!$E$2:$E$36='Exemplos Validação'!$J4)*('Exemplos Validação'!$K4='Cálculo excel'!$F$2:$F$36),0),13)} -> 285.38 | BH4: =BG4-BF4 -> 0 | BI4: 0 | BJ4: {=INDEX('Cálculo excel'!$B$2:$X$36,MATCH(1,('Exemplos Validação'!$F4='Cálculo excel'!$B$2:$B$36)*('Cálculo excel'!$C$2:$C$36='Exemplos Validação'!$H4)*('Exemplos Validação'!$I4='Cálculo excel'!$D$2:$D$36)*('Cálculo excel'!$E$2:$E$36='Exemplos Validação'!$J4)*('Exemplos Validação'!$K4='Cálculo excel'!$F$2:$F$36),0),14)} -> 0 | BK4: =BJ4-BI4 -> 0 | BL4: -3.07 | BM4: {=INDEX('Cálculo excel'!$B$2:$X$36,MATCH(1,('Exemplos Validação'!$F4='Cálculo excel'!$B$2:$B$36)*('Cálculo excel'!$C$2:$C$36='Exemplos Validação'!$H4)*('Exemplos Validação'!$I4='Cálculo excel'!$D$2:$D$36)*('Cálculo excel'!$E$2:$E$36='Exemplos Validação'!$J4)*('Exemplos Validação'!$K4='Cálculo excel'!$F$2:$F$36),0),15)} -> -3.07 | BN4: =BM4-BL4 -> 0 | BO4: 0 | BP4: {=INDEX('Cálculo excel'!$B$2:$X$36,MATCH(1,('Exemplos Validação'!$F4='Cálculo excel'!$B$2:$B$36)*('Cálculo excel'!$C$2:$C$36='Exemplos Validação'!$H4)*('Exemplos Validação'!$I4='Cálculo excel'!$D$2:$D$36)*('Cálculo excel'!$E$2:$E$36='Exemplos Validação'!$J4)*('Exemplos Validação'!$K4='Cálculo excel'!$F$2:$F$36),0),16)} -> 0 | BQ4: =BP4-BO4 -> 0 | BR4: 134.29 | BS4: {=INDEX('Cálculo excel'!$B$2:$X$36,MATCH(1,('Exemplos Validação'!$F4='Cálculo excel'!$B$2:$B$36)*('Cálculo excel'!$C$2:$C$36='Exemplos Validação'!$H4)*('Exemplos Validação'!$I4='Cálculo excel'!$D$2:$D$36)*('Cálculo excel'!$E$2:$E$36='Exemplos Validação'!$J4)*('Exemplos Validação'!$K4='Cálculo excel'!$F$2:$F$36),0),17)} -> 134.29 | BT4: =BS4-BR4 -> 0 | BU4: 0 | BV4: {=INDEX('Cálculo excel'!$B$2:$X$36,MATCH(1,('Exemplos Validação'!$F4='Cálculo excel'!$B$2:$B$36)*('Cálculo excel'!$C$2:$C$36='Exemplos Validação'!$H4)*('Exemplos Validação'!$I4='Cálculo excel'!$D$2:$D$36)*('Cálculo excel'!$E$2:$E$36='Exemplos Validação'!$J4)*('Exemplos Validação'!$K4='Cálculo excel'!$F$2:$F$36),0),18)} -> 0 | BW4: =BV4-BU4 -> 0 | BX4: 0 | BY4: {=INDEX('Cálculo excel'!$B$2:$X$36,MATCH(1,('Exemplos Validação'!$F4='Cálculo excel'!$B$2:$B$36)*('Cálculo excel'!$C$2:$C$36='Exemplos Validação'!$H4)*('Exemplos Validação'!$I4='Cálculo excel'!$D$2:$D$36)*('Cálculo excel'!$E$2:$E$36='Exemplos Validação'!$J4)*('Exemplos Validação'!$K4='Cálculo excel'!$F$2:$F$36),0),19)} -> 0 | BZ4: =BY4-BX4 -> 0 | CA4: 36.97 | CB4: {=INDEX('Cálculo excel'!$B$2:$X$36,MATCH(1,('Exemplos Validação'!$F4='Cálculo excel'!$B$2:$B$36)*('Cálculo excel'!$C$2:$C$36='Exemplos Validação'!$H4)*('Exemplos Validação'!$I4='Cálculo excel'!$D$2:$D$36)*('Cálculo excel'!$E$2:$E$36='Exemplos Validação'!$J4)*('Exemplos Validação'!$K4='Cálculo excel'!$F$2:$F$36),0),20)} -> 36.97 | CC4: =CB4-CA4 -> 0 | CD4: 14152.03 | CE4: {=INDEX('Cálculo excel'!$B$2:$X$36,MATCH(1,('Exemplos Validação'!$F4='Cálculo excel'!$B$2:$B$36)*('Cálculo excel'!$C$2:$C$36='Exemplos Validação'!$H4)*('Exemplos Validação'!$I4='Cálculo excel'!$D$2:$D$36)*('Cálculo excel'!$E$2:$E$36='Exemplos Validação'!$J4)*('Exemplos Validação'!$K4='Cálculo excel'!$F$2:$F$36),0),21)} -> 14152.03 | CF4: =CE4-CD4 -> 0 | CG4: 0 | CH4: {=INDEX('Cálculo excel'!$B$2:$X$36,MATCH(1,('Exemplos Validação'!$F4='Cálculo excel'!$B$2:$B$36)*('Cálculo excel'!$C$2:$C$36='Exemplos Validação'!$H4)*('Exemplos Validação'!$I4='Cálculo excel'!$D$2:$D$36)*('Cálculo excel'!$E$2:$E$36='Exemplos Validação'!$J4)*('Exemplos Validação'!$K4='Cálculo excel'!$F$2:$F$36),0),22)+INDEX('Cálculo excel'!$B$2:$X$36,MATCH(1,('Exemplos Validação'!$F4='Cálculo excel'!$B$2:$B$36)*('Cálculo excel'!$C$2:$C$36='Exemplos Validação'!$H4)*('Exemplos Validação'!$I4='Cálculo excel'!$D$2:$D$36)*('Cálculo excel'!$E$2:$E$36='Exemplos Validação'!$J4)*('Exemplos Validação'!$K4='Cálculo excel'!$F$2:$F$36),0),23)} -> 0 | CI4: =CH4-CG4 -> 0
A5: COMUM PM | B5: 2025-03-31 | C5: GD | D5: ESTR | E5: 82000020100005442000007400570696 | F5: 82000020100005442000007400570696 | G5: 82000020100005442000007400570696 | H5: 31 | I5: 0000 | J5: 20100005442 | K5: V0050C33343I125 | L5: AN01040220 | M5: BA5 | N5: N | O5: N | P5: PRDCT010103 | Q5: N | R5: N/A | S5: 00000 | T5: N/A | U5: 11111111111 | V5: 11111111111 | W5: 11111111111 | X5: 11111111111 | Y5: 11111111111 | Z5: 11111111111 | AA5: 11111111111 | AB5: N/A | AC5: 11111111111 | AD5: 11111111111 | AE5: 0.000000 | AF5: 641382.64 | AG5: 23 | AH5: 11 | AI5: 0.00 | AJ5: 11111111111.00 | AK5: 2070834.56 | AL5: 0.00 | AM5: 0.00 | AN5: 0.00 | AO5: 2025-03-31 | AP5: MC42 | AQ5: APGUARS1P | AR5: 14 | AS5: 71 | AT5: 11111111111 | AU5: 00000 | AV5: 0 | AW5: 929165.44 | AX5: 21 | AY5: 0 | AZ5: 0 | BA5: {=INDEX('Cálculo excel'!$B$2:$X$36,MATCH(1,('Exemplos Validação'!$F5='Cálculo excel'!$B$2:$B$36)*('Cálculo excel'!$C$2:$C$36='Exemplos Validação'!$H5)*('Exemplos Validação'!$I5='Cálculo excel'!$D$2:$D$36)*('Cálculo excel'!$E$2:$E$36='Exemplos Validação'!$J5)*('Exemplos Validação'!$K5='Cálculo excel'!$F$2:$F$36),0),11)} -> 0 | BB5: =BA5-AZ5 -> 0 | BC5: 0 | BD5: {=INDEX('Cálculo excel'!$B$2:$X$36,MATCH(1,('Exemplos Validação'!$F5='Cálculo excel'!$B$2:$B$36)*('Cálculo excel'!$C$2:$C$36='Exemplos Validação'!$H5)*('Exemplos Validação'!$I5='Cálculo excel'!$D$2:$D$36)*('Cálculo excel'!$E$2:$E$36='Exemplos Validação'!$J5)*('Exemplos Validação'!$K5='Cálculo excel'!$F$2:$F$36),0),12)} -> 0 | BE5: =BD5-BC5 -> 0 | BF5: 0 | BG5: {=INDEX('Cálculo excel'!$B$2:$X$36,MATCH(1,('Exemplos Validação'!$F5='Cálculo excel'!$B$2:$B$36)*('Cálculo excel'!$C$2:$C$36='Exemplos Validação'!$H5)*('Exemplos Validação'!$I5='Cálculo excel'!$D$2:$D$36)*('Cálculo excel'!$E$2:$E$36='Exemplos Validação'!$J5)*('Exemplos Validação'!$K5='Cálculo excel'!$F$2:$F$36),0),13)} -> 0 | BH5: =BG5-BF5 -> 0 | BI5: 0 | BJ5: {=INDEX('Cálculo excel'!$B$2:$X$36,MATCH(1,('Exemplos Validação'!$F5='Cálculo excel'!$B$2:$B$36)*('Cálculo excel'!$C$2:$C$36='Exemplos Validação'!$H5)*('Exemplos Validação'!$I5='Cálculo excel'!$D$2:$D$36)*('Cálculo excel'!$E$2:$E$36='Exemplos Validação'!$J5)*('Exemplos Validação'!$K5='Cálculo excel'!$F$2:$F$36),0),14)} -> 0 | BK5: =BJ5-BI5 -> 0 | BL5: 0 | BM5: {=INDEX('Cálculo excel'!$B$2:$X$36,MATCH(1,('Exemplos Validação'!$F5='Cálculo excel'!$B$2:$B$36)*('Cálculo excel'!$C$2:$C$36='Exemplos Validação'!$H5)*('Exemplos Validação'!$I5='Cálculo excel'!$D$2:$D$36)*('Cálculo excel'!$E$2:$E$36='Exemplos Validação'!$J5)*('Exemplos Validação'!$K5='Cálculo excel'!$F$2:$F$36),0),15)} -> 0 | BN5: =BM5-BL5 -> 0 | BO5: 0 | BP5: {=INDEX('Cálculo excel'!$B$2:$X$36,MATCH(1,('Exemplos Validação'!$F5='Cálculo excel'!$B$2:$B$36)*('Cálculo excel'!$C$2:$C$36='Exemplos Validação'!$H5)*('Exemplos Validação'!$I5='Cálculo excel'!$D$2:$D$36)*('Cálculo excel'!$E$2:$E$36='Exemplos Validação'!$J5)*('Exemplos Validação'!$K5='Cálculo excel'!$F$2:$F$36),0),16)} -> 0 | BQ5: =BP5-BO5 -> 0 | BR5: 0 | BS5: {=INDEX('Cálculo excel'!$B$2:$X$36,MATCH(1,('Exemplos Validação'!$F5='Cálculo excel'!$B$2:$B$36)*('Cálculo excel'!$C$2:$C$36='Exemplos Validação'!$H5)*('Exemplos Validação'!$I5='Cálculo excel'!$D$2:$D$36)*('Cálculo excel'!$E$2:$E$36='Exemplos Validação'!$J5)*('Exemplos Validação'!$K5='Cálculo excel'!$F$2:$F$36),0),17)} -> 0 | BT5: =BS5-BR5 -> 0 | BU5: 0 | BV5: {=INDEX('Cálculo excel'!$B$2:$X$36,MATCH(1,('Exemplos Validação'!$F5='Cálculo excel'!$B$2:$B$36)*('Cálculo excel'!$C$2:$C$36='Exemplos Validação'!$H5)*('Exemplos Validação'!$I5='Cálculo excel'!$D$2:$D$36)*('Cálculo excel'!$E$2:$E$36='Exemplos Validação'!$J5)*('Exemplos Validação'!$K5='Cálculo excel'!$F$2:$F$36),0),18)} -> 0 | BW5: =BV5-BU5 -> 0 | BX5: 0 | BY5: {=INDEX('Cálculo excel'!$B$2:$X$36,MATCH(1,('Exemplos Validação'!$F5='Cálculo excel'!$B$2:$B$36)*('Cálculo excel'!$C$2:$C$36='Exemplos Validação'!$H5)*('Exemplos Validação'!$I5='Cálculo excel'!$D$2:$D$36)*('Cálculo excel'!$E$2:$E$36='Exemplos Validação'!$J5)*('Exemplos Validação'!$K5='Cálculo excel'!$F$2:$F$36),0),19)} -> 0 | BZ5: =BY5-BX5 -> 0 | CA5: 0 | CB5: {=INDEX('Cálculo excel'!$B$2:$X$36,MATCH(1,('Exemplos Validação'!$F5='Cálculo excel'!$B$2:$B$36)*('Cálculo excel'!$C$2:$C$36='Exemplos Validação'!$H5)*('Exemplos Validação'!$I5='Cálculo excel'!$D$2:$D$36)*('Cálculo excel'!$E$2:$E$36='Exemplos Validação'!$J5)*('Exemplos Validação'!$K5='Cálculo excel'!$F$2:$F$36),0),20)} -> 0 | CC5: =CB5-CA5 -> 0 | CD5: 0 | CE5: {=INDEX('Cálculo excel'!$B$2:$X$36,MATCH(1,('Exemplos Validação'!$F5='Cálculo excel'!$B$2:$B$36)*('Cálculo excel'!$C$2:$C$36='Exemplos Validação'!$H5)*('Exemplos Validação'!$I5='Cálculo excel'!$D$2:$D$36)*('Cálculo excel'!$E$2:$E$36='Exemplos Validação'!$J5)*('Exemplos Validação'!$K5='Cálculo excel'!$F$2:$F$36),0),21)} -> 0 | CF5: =CE5-CD5 -> 0 | CG5: 0 | CH5: {=INDEX('Cálculo excel'!$B$2:$X$36,MATCH(1,('Exemplos Validação'!$F5='Cálculo excel'!$B$2:$B$36)*('Cálculo excel'!$C$2:$C$36='Exemplos Validação'!$H5)*('Exemplos Validação'!$I5='Cálculo excel'!$D$2:$D$36)*('Cálculo excel'!$E$2:$E$36='Exemplos Validação'!$J5)*('Exemplos Validação'!$K5='Cálculo excel'!$F$2:$F$36),0),22)+INDEX('Cálculo excel'!$B$2:$X$36,MATCH(1,('Exemplos Validação'!$F5='Cálculo excel'!$B$2:$B$36)*('Cálculo excel'!$C$2:$C$36='Exemplos Validação'!$H5)*('Exemplos Validação'!$I5='Cálculo excel'!$D$2:$D$36)*('Cálculo excel'!$E$2:$E$36='Exemplos Validação'!$J5)*('Exemplos Validação'!$K5='Cálculo excel'!$F$2:$F$36),0),23)} -> 0 | CI5: =CH5-CG5 -> 0
A6: COMUM PM | B6: 2025-03-31 | C6: GD | D6: ESTR | E6: 82000020100005442001520250102730 | F6: 82000020100005442001520250102730 | G6: 82000020100005442001520250102730 | H6: 31 | I6: 0000 | J6: 20100005442 | K6: V0050C33343I125 | L6: AN01040220 | M6: BA5 | N6: N | O6: Y | P6: PRDCT010103 | Q6: N | R6: N/A | S6: 00000 | T6: N/A | U6: 11111111111 | V6: 11111111111 | W6: 11111111111 | X6: 11111111111 | Y6: 11111111111 | Z6: 11111111111 | AA6: 11111111111 | AB6: N/A | AC6: 11111111111 | AD6: 11111111111 | AE6: 0.000000 | AF6: 569.49 | AG6: 23 | AH6: 11 | AI6: 1838.72 | AJ6: 11111111111.00 | AK6: 0.00 | AL6: 0.00 | AM6: 0.00 | AN6: 0.00 | AO6: 2025-03-31 | AP6: N/A | AQ6: APCAPRES1P | AR6: 14 | AS6: 71 | AT6: 6 | AU6: 00000 | AV6: 1838.72 | AW6: 929165.44 | AX6: 21 | AY6: 0.001978 | AZ6: 0 | BA6: {=INDEX('Cálculo excel'!$B$2:$X$36,MATCH(1,('Exemplos Validação'!$F6='Cálculo excel'!$B$2:$B$36)*('Cálculo excel'!$C$2:$C$36='Exemplos Validação'!$H6)*('Exemplos Validação'!$I6='Cálculo excel'!$D$2:$D$36)*('Cálculo excel'!$E$2:$E$36='Exemplos Validação'!$J6)*('Exemplos Validação'!$K6='Cálculo excel'!$F$2:$F$36),0),11)} -> 0 | BB6: =BA6-AZ6 -> 0 | BC6: 0 | BD6: {=INDEX('Cálculo excel'!$B$2:$X$36,MATCH(1,('Exemplos Validação'!$F6='Cálculo excel'!$B$2:$B$36)*('Cálculo excel'!$C$2:$C$36='Exemplos Validação'!$H6)*('Exemplos Validação'!$I6='Cálculo excel'!$D$2:$D$36)*('Cálculo excel'!$E$2:$E$36='Exemplos Validação'!$J6)*('Exemplos Validação'!$K6='Cálculo excel'!$F$2:$F$36),0),12)} -> 0 | BE6: =BD6-BC6 -> 0 | BF6: 0 | BG6: {=INDEX('Cálculo excel'!$B$2:$X$36,MATCH(1,('Exemplos Validação'!$F6='Cálculo excel'!$B$2:$B$36)*('Cálculo excel'!$C$2:$C$36='Exemplos Validação'!$H6)*('Exemplos Validação'!$I6='Cálculo excel'!$D$2:$D$36)*('Cálculo excel'!$E$2:$E$36='Exemplos Validação'!$J6)*('Exemplos Validação'!$K6='Cálculo excel'!$F$2:$F$36),0),13)} -> 0 | BH6: =BG6-BF6 -> 0 | BI6: 0 | BJ6: {=INDEX('Cálculo excel'!$B$2:$X$36,MATCH(1,('Exemplos Validação'!$F6='Cálculo excel'!$B$2:$B$36)*('Cálculo excel'!$C$2:$C$36='Exemplos Validação'!$H6)*('Exemplos Validação'!$I6='Cálculo excel'!$D$2:$D$36)*('Cálculo excel'!$E$2:$E$36='Exemplos Validação'!$J6)*('Exemplos Validação'!$K6='Cálculo excel'!$F$2:$F$36),0),14)} -> 0 | BK6: =BJ6-BI6 -> 0 | BL6: 0 | BM6: {=INDEX('Cálculo excel'!$B$2:$X$36,MATCH(1,('Exemplos Validação'!$F6='Cálculo excel'!$B$2:$B$36)*('Cálculo excel'!$C$2:$C$36='Exemplos Validação'!$H6)*('Exemplos Validação'!$I6='Cálculo excel'!$D$2:$D$36)*('Cálculo excel'!$E$2:$E$36='Exemplos Validação'!$J6)*('Exemplos Validação'!$K6='Cálculo excel'!$F$2:$F$36),0),15)} -> 0 | BN6: =BM6-BL6 -> 0 | BO6: 0 | BP6: {=INDEX('Cálculo excel'!$B$2:$X$36,MATCH(1,('Exemplos Validação'!$F6='Cálculo excel'!$B$2:$B$36)*('Cálculo excel'!$C$2:$C$36='Exemplos Validação'!$H6)*('Exemplos Validação'!$I6='Cálculo excel'!$D$2:$D$36)*('Cálculo excel'!$E$2:$E$36='Exemplos Validação'!$J6)*('Exemplos Validação'!$K6='Cálculo excel'!$F$2:$F$36),0),16)} -> 0 | BQ6: =BP6-BO6 -> 0 | BR6: 0 | BS6: {=INDEX('Cálculo excel'!$B$2:$X$36,MATCH(1,('Exemplos Validação'!$F6='Cálculo excel'!$B$2:$B$36)*('Cálculo excel'!$C$2:$C$36='Exemplos Validação'!$H6)*('Exemplos Validação'!$I6='Cálculo excel'!$D$2:$D$36)*('Cálculo excel'!$E$2:$E$36='Exemplos Validação'!$J6)*('Exemplos Validação'!$K6='Cálculo excel'!$F$2:$F$36),0),17)} -> 0 | BT6: =BS6-BR6 -> 0 | BU6: 0 | BV6: {=INDEX('Cálculo excel'!$B$2:$X$36,MATCH(1,('Exemplos Validação'!$F6='Cálculo excel'!$B$2:$B$36)*('Cálculo excel'!$C$2:$C$36='Exemplos Validação'!$H6)*('Exemplos Validação'!$I6='Cálculo excel'!$D$2:$D$36)*('Cálculo excel'!$E$2:$E$36='Exemplos Validação'!$J6)*('Exemplos Validação'!$K6='Cálculo excel'!$F$2:$F$36),0),18)} -> 0 | BW6: =BV6-BU6 -> 0 | BX6: 0 | BY6: {=INDEX('Cálculo excel'!$B$2:$X$36,MATCH(1,('Exemplos Validação'!$F6='Cálculo excel'!$B$2:$B$36)*('Cálculo excel'!$C$2:$C$36='Exemplos Validação'!$H6)*('Exemplos Validação'!$I6='Cálculo excel'!$D$2:$D$36)*('Cálculo excel'!$E$2:$E$36='Exemplos Validação'!$J6)*('Exemplos Validação'!$K6='Cálculo excel'!$F$2:$F$36),0),19)} -> 0 | BZ6: =BY6-BX6 -> 0 | CA6: 0 | CB6: {=INDEX('Cálculo excel'!$B$2:$X$36,MATCH(1,('Exemplos Validação'!$F6='Cálculo excel'!$B$2:$B$36)*('Cálculo excel'!$C$2:$C$36='Exemplos Validação'!$H6)*('Exemplos Validação'!$I6='Cálculo excel'!$D$2:$D$36)*('Cálculo excel'!$E$2:$E$36='Exemplos Validação'!$J6)*('Exemplos Validação'!$K6='Cálculo excel'!$F$2:$F$36),0),20)} -> 0 | CC6: =CB6-CA6 -> 0 | CD6: 0 | CE6: {=INDEX('Cálculo excel'!$B$2:$X$36,MATCH(1,('Exemplos Validação'!$F6='Cálculo excel'!$B$2:$B$36)*('Cálculo excel'!$C$2:$C$36='Exemplos Validação'!$H6)*('Exemplos Validação'!$I6='Cálculo excel'!$D$2:$D$36)*('Cálculo excel'!$E$2:$E$36='Exemplos Validação'!$J6)*('Exemplos Validação'!$K6='Cálculo excel'!$F$2:$F$36),0),21)} -> 0 | CF6: =CE6-CD6 -> 0 | CG6: 0 | CH6: {=INDEX('Cálculo excel'!$B$2:$X$36,MATCH(1,('Exemplos Validação'!$F6='Cálculo excel'!$B$2:$B$36)*('Cálculo excel'!$C$2:$C$36='Exemplos Validação'!$H6)*('Exemplos Validação'!$I6='Cálculo excel'!$D$2:$D$36)*('Cálculo excel'!$E$2:$E$36='Exemplos Validação'!$J6)*('Exemplos Validação'!$K6='Cálculo excel'!$F$2:$F$36),0),22)+INDEX('Cálculo excel'!$B$2:$X$36,MATCH(1,('Exemplos Validação'!$F6='Cálculo excel'!$B$2:$B$36)*('Cálculo excel'!$C$2:$C$36='Exemplos Validação'!$H6)*('Exemplos Validação'!$I6='Cálculo excel'!$D$2:$D$36)*('Cálculo excel'!$E$2:$E$36='Exemplos Validação'!$J6)*('Exemplos Validação'!$K6='Cálculo excel'!$F$2:$F$36),0),23)} -> 0 | CI6: =CH6-CG6 -> 0
A7: COMUM PM | B7: 2025-03-31 | C7: GD | D7: ESTR | E7: 82000020100005442001520250106448 | F7: 82000020100005442001520250106448 | G7: 82000020100005442001520250106448 | H7: 31 | I7: 0000 | J7: 20100005442 | K7: V0050C33343I125 | L7: AN01040220 | M7: BA5 | N7: N | O7: Y | P7: PRDCT010103 | Q7: N | R7: N/A | S7: 00000 | T7: N/A | U7: 11111111111 | V7: 11111111111 | W7: 11111111111 | X7: 11111111111 | Y7: 11111111111 | Z7: 11111111111 | AA7: 11111111111 | AB7: N/A | AC7: 11111111111 | AD7: 11111111111 | AE7: 0.000000 | AF7: 13482.49 | AG7: 23 | AH7: 11 | AI7: 43530.97 | AJ7: 11111111111.00 | AK7: 0.00 | AL7: 0.00 | AM7: 0.00 | AN7: 0.00 | AO7: 2025-03-31 | AP7: N/A | AQ7: APCAPRES1P | AR7: 14 | AS7: 71 | AT7: 6 | AU7: 00000 | AV7: 43530.97 | AW7: 929165.44 | AX7: 21 | AY7: 0.046849 | AZ7: 0 | BA7: {=INDEX('Cálculo excel'!$B$2:$X$36,MATCH(1,('Exemplos Validação'!$F7='Cálculo excel'!$B$2:$B$36)*('Cálculo excel'!$C$2:$C$36='Exemplos Validação'!$H7)*('Exemplos Validação'!$I7='Cálculo excel'!$D$2:$D$36)*('Cálculo excel'!$E$2:$E$36='Exemplos Validação'!$J7)*('Exemplos Validação'!$K7='Cálculo excel'!$F$2:$F$36),0),11)} -> 0 | BB7: =BA7-AZ7 -> 0 | BC7: 0 | BD7: {=INDEX('Cálculo excel'!$B$2:$X$36,MATCH(1,('Exemplos Validação'!$F7='Cálculo excel'!$B$2:$B$36)*('Cálculo excel'!$C$2:$C$36='Exemplos Validação'!$H7)*('Exemplos Validação'!$I7='Cálculo excel'!$D$2:$D$36)*('Cálculo excel'!$E$2:$E$36='Exemplos Validação'!$J7)*('Exemplos Validação'!$K7='Cálculo excel'!$F$2:$F$36),0),12)} -> 0 | BE7: =BD7-BC7 -> 0 | BF7: 0 | BG7: {=INDEX('Cálculo excel'!$B$2:$X$36,MATCH(1,('Exemplos Validação'!$F7='Cálculo excel'!$B$2:$B$36)*('Cálculo excel'!$C$2:$C$36='Exemplos Validação'!$H7)*('Exemplos Validação'!$I7='Cálculo excel'!$D$2:$D$36)*('Cálculo excel'!$E$2:$E$36='Exemplos Validação'!$J7)*('Exemplos Validação'!$K7='Cálculo excel'!$F$2:$F$36),0),13)} -> 0 | BH7: =BG7-BF7 -> 0 | BI7: 0 | BJ7: {=INDEX('Cálculo excel'!$B$2:$X$36,MATCH(1,('Exemplos Validação'!$F7='Cálculo excel'!$B$2:$B$36)*('Cálculo excel'!$C$2:$C$36='Exemplos Validação'!$H7)*('Exemplos Validação'!$I7='Cálculo excel'!$D$2:$D$36)*('Cálculo excel'!$E$2:$E$36='Exemplos Validação'!$J7)*('Exemplos Validação'!$K7='Cálculo excel'!$F$2:$F$36),0),14)} -> 0 | BK7: =BJ7-BI7 -> 0 | BL7: 0 | BM7: {=INDEX('Cálculo excel'!$B$2:$X$36,MATCH(1,('Exemplos Validação'!$F7='Cálculo excel'!$B$2:$B$36)*('Cálculo excel'!$C$2:$C$36='Exemplos Validação'!$H7)*('Exemplos Validação'!$I7='Cálculo excel'!$D$2:$D$36)*('Cálculo excel'!$E$2:$E$36='Exemplos Validação'!$J7)*('Exemplos Validação'!$K7='Cálculo excel'!$F$2:$F$36),0),15)} -> 0 | BN7: =BM7-BL7 -> 0 | BO7: 0 | BP7: {=INDEX('Cálculo excel'!$B$2:$X$36,MATCH(1,('Exemplos Validação'!$F7='Cálculo excel'!$B$2:$B$36)*('Cálculo excel'!$C$2:$C$36='Exemplos Validação'!$H7)*('Exemplos Validação'!$I7='Cálculo excel'!$D$2:$D$36)*('Cálculo excel'!$E$2:$E$36='Exemplos Validação'!$J7)*('Exemplos Validação'!$K7='Cálculo excel'!$F$2:$F$36),0),16)} -> 0 | BQ7: =BP7-BO7 -> 0 | BR7: 0 | BS7: {=INDEX('Cálculo excel'!$B$2:$X$36,MATCH(1,('Exemplos Validação'!$F7='Cálculo excel'!$B$2:$B$36)*('Cálculo excel'!$C$2:$C$36='Exemplos Validação'!$H7)*('Exemplos Validação'!$I7='Cálculo excel'!$D$2:$D$36)*('Cálculo excel'!$E$2:$E$36='Exemplos Validação'!$J7)*('Exemplos Validação'!$K7='Cálculo excel'!$F$2:$F$36),0),17)} -> 0 | BT7: =BS7-BR7 -> 0 | BU7: 0 | BV7: {=INDEX('Cálculo excel'!$B$2:$X$36,MATCH(1,('Exemplos Validação'!$F7='Cálculo excel'!$B$2:$B$36)*('Cálculo excel'!$C$2:$C$36='Exemplos Validação'!$H7)*('Exemplos Validação'!$I7='Cálculo excel'!$D$2:$D$36)*('Cálculo excel'!$E$2:$E$36='Exemplos Validação'!$J7)*('Exemplos Validação'!$K7='Cálculo excel'!$F$2:$F$36),0),18)} -> 0 | BW7: =BV7-BU7 -> 0 | BX7: 0 | BY7: {=INDEX('Cálculo excel'!$B$2:$X$36,MATCH(1,('Exemplos Validação'!$F7='Cálculo excel'!$B$2:$B$36)*('Cálculo excel'!$C$2:$C$36='Exemplos Validação'!$H7)*('Exemplos Validação'!$I7='Cálculo excel'!$D$2:$D$36)*('Cálculo excel'!$E$2:$E$36='Exemplos Validação'!$J7)*('Exemplos Validação'!$K7='Cálculo excel'!$F$2:$F$36),0),19)} -> 0 | BZ7: =BY7-BX7 -> 0 | CA7: 0 | CB7: {=INDEX('Cálculo excel'!$B$2:$X$36,MATCH(1,('Exemplos Validação'!$F7='Cálculo excel'!$B$2:$B$36)*('Cálculo excel'!$C$2:$C$36='Exemplos Validação'!$H7)*('Exemplos Validação'!$I7='Cálculo excel'!$D$2:$D$36)*('Cálculo excel'!$E$2:$E$36='Exemplos Validação'!$J7)*('Exemplos Validação'!$K7='Cálculo excel'!$F$2:$F$36),0),20)} -> 0 | CC7: =CB7-CA7 -> 0 | CD7: 0 | CE7: {=INDEX('Cálculo excel'!$B$2:$X$36,MATCH(1,('Exemplos Validação'!$F7='Cálculo excel'!$B$2:$B$36)*('Cálculo excel'!$C$2:$C$36='Exemplos Validação'!$H7)*('Exemplos Validação'!$I7='Cálculo excel'!$D$2:$D$36)*('Cálculo excel'!$E$2:$E$36='Exemplos Validação'!$J7)*('Exemplos Validação'!$K7='Cálculo excel'!$F$2:$F$36),0),21)} -> 0 | CF7: =CE7-CD7 -> 0 | CG7: 0 | CH7: {=INDEX('Cálculo excel'!$B$2:$X$36,MATCH(1,('Exemplos Validação'!$F7='Cálculo excel'!$B$2:$B$36)*('Cálculo excel'!$C$2:$C$36='Exemplos Validação'!$H7)*('Exemplos Validação'!$I7='Cálculo excel'!$D$2:$D$36)*('Cálculo excel'!$E$2:$E$36='Exemplos Validação'!$J7)*('Exemplos Validação'!$K7='Cálculo excel'!$F$2:$F$36),0),22)+INDEX('Cálculo excel'!$B$2:$X$36,MATCH(1,('Exemplos Validação'!$F7='Cálculo excel'!$B$2:$B$36)*('Cálculo excel'!$C$2:$C$36='Exemplos Validação'!$H7)*('Exemplos Validação'!$I7='Cálculo excel'!$D$2:$D$36)*('Cálculo excel'!$E$2:$E$36='Exemplos Validação'!$J7)*('Exemplos Validação'!$K7='Cálculo excel'!$F$2:$F$36),0),23)} -> 0 | CI7: =CH7-CG7 -> 0
A8: COMUM PM | B8: 2025-03-31 | C8: GD | D8: ESTR | E8: 82000020100005442001520250102766 | F8: 82000020100005442001520250102766 | G8: 82000020100005442001520250102766 | H8: 31 | I8: 0000 | J8: 20100005442 | K8: V0050C33343I125 | L8: AN01040220 | M8: BA5 | N8: N | O8: Y | P8: PRDCT010103 | Q8: N | R8: N/A | S8: 00000 | T8: N/A | U8: 11111111111 | V8: 11111111111 | W8: 11111111111 | X8: 11111111111 | Y8: 11111111111 | Z8: 11111111111 | AA8: 11111111111 | AB8: N/A | AC8: 11111111111 | AD8: 11111111111 | AE8: 0.000000 | AF8: 0.16 | AG8: 23 | AH8: 11 | AI8: 0.51 | AJ8: 11111111111.00 | AK8: 0.00 | AL8: 0.00 | AM8: 0.00 | AN8: 0.00 | AO8: 2025-03-31 | AP8: N/A | AQ8: APCAPRES1P | AR8: 14 | AS8: 71 | AT8: 6 | AU8: 00000 | AV8: 0.51 | AW8: 929165.44 | AX8: 21 | AY8: 0 | AZ8: 0 | BA8: {=INDEX('Cálculo excel'!$B$2:$X$36,MATCH(1,('Exemplos Validação'!$F8='Cálculo excel'!$B$2:$B$36)*('Cálculo excel'!$C$2:$C$36='Exemplos Validação'!$H8)*('Exemplos Validação'!$I8='Cálculo excel'!$D$2:$D$36)*('Cálculo excel'!$E$2:$E$36='Exemplos Validação'!$J8)*('Exemplos Validação'!$K8='Cálculo excel'!$F$2:$F$36),0),11)} -> 0 | BB8: =BA8-AZ8 -> 0 | BC8: 0 | BD8: {=INDEX('Cálculo excel'!$B$2:$X$36,MATCH(1,('Exemplos Validação'!$F8='Cálculo excel'!$B$2:$B$36)*('Cálculo excel'!$C$2:$C$36='Exemplos Validação'!$H8)*('Exemplos Validação'!$I8='Cálculo excel'!$D$2:$D$36)*('Cálculo excel'!$E$2:$E$36='Exemplos Validação'!$J8)*('Exemplos Validação'!$K8='Cálculo excel'!$F$2:$F$36),0),12)} -> 0 | BE8: =BD8-BC8 -> 0 | BF8: 0 | BG8: {=INDEX('Cálculo excel'!$B$2:$X$36,MATCH(1,('Exemplos Validação'!$F8='Cálculo excel'!$B$2:$B$36)*('Cálculo excel'!$C$2:$C$36='Exemplos Validação'!$H8)*('Exemplos Validação'!$I8='Cálculo excel'!$D$2:$D$36)*('Cálculo excel'!$E$2:$E$36='Exemplos Validação'!$J8)*('Exemplos Validação'!$K8='Cálculo excel'!$F$2:$F$36),0),13)} -> 0 | BH8: =BG8-BF8 -> 0 | BI8: 0 | BJ8: {=INDEX('Cálculo excel'!$B$2:$X$36,MATCH(1,('Exemplos Validação'!$F8='Cálculo excel'!$B$2:$B$36)*('Cálculo excel'!$C$2:$C$36='Exemplos Validação'!$H8)*('Exemplos Validação'!$I8='Cálculo excel'!$D$2:$D$36)*('Cálculo excel'!$E$2:$E$36='Exemplos Validação'!$J8)*('Exemplos Validação'!$K8='Cálculo excel'!$F$2:$F$36),0),14)} -> 0 | BK8: =BJ8-BI8 -> 0 | BL8: 0 | BM8: {=INDEX('Cálculo excel'!$B$2:$X$36,MATCH(1,('Exemplos Validação'!$F8='Cálculo excel'!$B$2:$B$36)*('Cálculo excel'!$C$2:$C$36='Exemplos Validação'!$H8)*('Exemplos Validação'!$I8='Cálculo excel'!$D$2:$D$36)*('Cálculo excel'!$E$2:$E$36='Exemplos Validação'!$J8)*('Exemplos Validação'!$K8='Cálculo excel'!$F$2:$F$36),0),15)} -> 0 | BN8: =BM8-BL8 -> 0 | BO8: 0 | BP8: {=INDEX('Cálculo excel'!$B$2:$X$36,MATCH(1,('Exemplos Validação'!$F8='Cálculo excel'!$B$2:$B$36)*('Cálculo excel'!$C$2:$C$36='Exemplos Validação'!$H8)*('Exemplos Validação'!$I8='Cálculo excel'!$D$2:$D$36)*('Cálculo excel'!$E$2:$E$36='Exemplos Validação'!$J8)*('Exemplos Validação'!$K8='Cálculo excel'!$F$2:$F$36),0),16)} -> 0 | BQ8: =BP8-BO8 -> 0 | BR8: 0 | BS8: {=INDEX('Cálculo excel'!$B$2:$X$36,MATCH(1,('Exemplos Validação'!$F8='Cálculo excel'!$B$2:$B$36)*('Cálculo excel'!$C$2:$C$36='Exemplos Validação'!$H8)*('Exemplos Validação'!$I8='Cálculo excel'!$D$2:$D$36)*('Cálculo excel'!$E$2:$E$36='Exemplos Validação'!$J8)*('Exemplos Validação'!$K8='Cálculo excel'!$F$2:$F$36),0),17)} -> 0 | BT8: =BS8-BR8 -> 0 | BU8: 0 | BV8: {=INDEX('Cálculo excel'!$B$2:$X$36,MATCH(1,('Exemplos Validação'!$F8='Cálculo excel'!$B$2:$B$36)*('Cálculo excel'!$C$2:$C$36='Exemplos Validação'!$H8)*('Exemplos Validação'!$I8='Cálculo excel'!$D$2:$D$36)*('Cálculo excel'!$E$2:$E$36='Exemplos Validação'!$J8)*('Exemplos Validação'!$K8='Cálculo excel'!$F$2:$F$36),0),18)} -> 0 | BW8: =BV8-BU8 -> 0 | BX8: 0 | BY8: {=INDEX('Cálculo excel'!$B$2:$X$36,MATCH(1,('Exemplos Validação'!$F8='Cálculo excel'!$B$2:$B$36)*('Cálculo excel'!$C$2:$C$36='Exemplos Validação'!$H8)*('Exemplos Validação'!$I8='Cálculo excel'!$D$2:$D$36)*('Cálculo excel'!$E$2:$E$36='Exemplos Validação'!$J8)*('Exemplos Validação'!$K8='Cálculo excel'!$F$2:$F$36),0),19)} -> 0 | BZ8: =BY8-BX8 -> 0 | CA8: 0 | CB8: {=INDEX('Cálculo excel'!$B$2:$X$36,MATCH(1,('Exemplos Validação'!$F8='Cálculo excel'!$B$2:$B$36)*('Cálculo excel'!$C$2:$C$36='Exemplos Validação'!$H8)*('Exemplos Validação'!$I8='Cálculo excel'!$D$2:$D$36)*('Cálculo excel'!$E$2:$E$36='Exemplos Validação'!$J8)*('Exemplos Validação'!$K8='Cálculo excel'!$F$2:$F$36),0),20)} -> 0 | CC8: =CB8-CA8 -> 0 | CD8: 0 | CE8: {=INDEX('Cálculo excel'!$B$2:$X$36,MATCH(1,('Exemplos Validação'!$F8='Cálculo excel'!$B$2:$B$36)*('Cálculo excel'!$C$2:$C$36='Exemplos Validação'!$H8)*('Exemplos Validação'!$I8='Cálculo excel'!$D$2:$D$36)*('Cálculo excel'!$E$2:$E$36='Exemplos Validação'!$J8)*('Exemplos Validação'!$K8='Cálculo excel'!$F$2:$F$36),0),21)} -> 0 | CF8: =CE8-CD8 -> 0 | CG8: 0 | CH8: {=INDEX('Cálculo excel'!$B$2:$X$36,MATCH(1,('Exemplos Validação'!$F8='Cálculo excel'!$B$2:$B$36)*('Cálculo excel'!$C$2:$C$36='Exemplos Validação'!$H8)*('Exemplos Validação'!$I8='Cálculo excel'!$D$2:$D$36)*('Cálculo excel'!$E$2:$E$36='Exemplos Validação'!$J8)*('Exemplos Validação'!$K8='Cálculo excel'!$F$2:$F$36),0),22)+INDEX('Cálculo excel'!$B$2:$X$36,MATCH(1,('Exemplos Validação'!$F8='Cálculo excel'!$B$2:$B$36)*('Cálculo excel'!$C$2:$C$36='Exemplos Validação'!$H8)*('Exemplos Validação'!$I8='Cálculo excel'!$D$2:$D$36)*('Cálculo excel'!$E$2:$E$36='Exemplos Validação'!$J8)*('Exemplos Validação'!$K8='Cálculo excel'!$F$2:$F$36),0),23)} -> 0 | CI8: =CH8-CG8 -> 0
A9: COMUM PM | B9: 2025-03-31 | C9: GD | D9: ESTR | E9: 82000000000247479000450000764712 | F9: 82000000000247479000450000764712 | G9: 82000000000247479000450000764712 | H9: 31 | I9: 0000 | J9: 00000247479 | K9: 000450000764712 | L9: AN01020410 | M9: BA4 | N9: N | O9: N | P9: PRDCT010103 | Q9: N | R9: N/A | S9: 00000 | T9: N/A | U9: 11111111111 | V9: 11111111111 | W9: 11111111111 | X9: 11111111111 | Y9: 11111111111 | Z9: 11111111111 | AA9: 11111111111 | AB9: N/A | AC9: 11111111111 | AD9: 11111111111 | AE9: 0.400000 | AF9: 16970.40 | AG9: 24 | AH9: 11 | AI9: 17067.51 | AJ9: 11111111111.00 | AK9: 0.00 | AL9: 0.00 | AM9: 9153.75 | AN9: 951.24 | AO9: 2025-03-31 | AP9: N/A | AQ9: SNFCAPRES2P | AR9: 14 | AS9: 80 | AT9: 6 | AU9: 00000 | AV9: 17067.51 | AW9: 17067.51 | AX9: 1 | AY9: 1 | AZ9: 16.5 | BA9: {=INDEX('Cálculo excel'!$B$2:$X$36,MATCH(1,('Exemplos Validação'!$F9='Cálculo excel'!$B$2:$B$36)*('Cálculo excel'!$C$2:$C$36='Exemplos Validação'!$H9)*('Exemplos Validação'!$I9='Cálculo excel'!$D$2:$D$36)*('Cálculo excel'!$E$2:$E$36='Exemplos Validação'!$J9)*('Exemplos Validação'!$K9='Cálculo excel'!$F$2:$F$36),0),11)} -> 16.5 | BB9: =BA9-AZ9 -> 0 | BC9: 0 | BD9: {=INDEX('Cálculo excel'!$B$2:$X$36,MATCH(1,('Exemplos Validação'!$F9='Cálculo excel'!$B$2:$B$36)*('Cálculo excel'!$C$2:$C$36='Exemplos Validação'!$H9)*('Exemplos Validação'!$I9='Cálculo excel'!$D$2:$D$36)*('Cálculo excel'!$E$2:$E$36='Exemplos Validação'!$J9)*('Exemplos Validação'!$K9='Cálculo excel'!$F$2:$F$36),0),12)} -> 0 | BE9: =BD9-BC9 -> 0 | BF9: 0 | BG9: {=INDEX('Cálculo excel'!$B$2:$X$36,MATCH(1,('Exemplos Validação'!$F9='Cálculo excel'!$B$2:$B$36)*('Cálculo excel'!$C$2:$C$36='Exemplos Validação'!$H9)*('Exemplos Validação'!$I9='Cálculo excel'!$D$2:$D$36)*('Cálculo excel'!$E$2:$E$36='Exemplos Validação'!$J9)*('Exemplos Validação'!$K9='Cálculo excel'!$F$2:$F$36),0),13)} -> 0 | BH9: =BG9-BF9 -> 0 | BI9: 0 | BJ9: {=INDEX('Cálculo excel'!$B$2:$X$36,MATCH(1,('Exemplos Validação'!$F9='Cálculo excel'!$B$2:$B$36)*('Cálculo excel'!$C$2:$C$36='Exemplos Validação'!$H9)*('Exemplos Validação'!$I9='Cálculo excel'!$D$2:$D$36)*('Cálculo excel'!$E$2:$E$36='Exemplos Validação'!$J9)*('Exemplos Validação'!$K9='Cálculo excel'!$F$2:$F$36),0),14)} -> 0 | BK9: =BJ9-BI9 -> 0 | BL9: -69.4 | BM9: {=INDEX('Cálculo excel'!$B$2:$X$36,MATCH(1,('Exemplos Validação'!$F9='Cálculo excel'!$B$2:$B$36)*('Cálculo excel'!$C$2:$C$36='Exemplos Validação'!$H9)*('Exemplos Validação'!$I9='Cálculo excel'!$D$2:$D$36)*('Cálculo excel'!$E$2:$E$36='Exemplos Validação'!$J9)*('Exemplos Validação'!$K9='Cálculo excel'!$F$2:$F$36),0),15)} -> -69.4 | BN9: =BM9-BL9 -> 0 | BO9: 0 | BP9: {=INDEX('Cálculo excel'!$B$2:$X$36,MATCH(1,('Exemplos Validação'!$F9='Cálculo excel'!$B$2:$B$36)*('Cálculo excel'!$C$2:$C$36='Exemplos Validação'!$H9)*('Exemplos Validação'!$I9='Cálculo excel'!$D$2:$D$36)*('Cálculo excel'!$E$2:$E$36='Exemplos Validação'!$J9)*('Exemplos Validação'!$K9='Cálculo excel'!$F$2:$F$36),0),16)} -> 0 | BQ9: =BP9-BO9 -> 0 | BR9: 215.11 | BS9: {=INDEX('Cálculo excel'!$B$2:$X$36,MATCH(1,('Exemplos Validação'!$F9='Cálculo excel'!$B$2:$B$36)*('Cálculo excel'!$C$2:$C$36='Exemplos Validação'!$H9)*('Exemplos Validação'!$I9='Cálculo excel'!$D$2:$D$36)*('Cálculo excel'!$E$2:$E$36='Exemplos Validação'!$J9)*('Exemplos Validação'!$K9='Cálculo excel'!$F$2:$F$36),0),17)} -> 215.11 | BT9: =BS9-BR9 -> 0 | BU9: 0 | BV9: {=INDEX('Cálculo excel'!$B$2:$X$36,MATCH(1,('Exemplos Validação'!$F9='Cálculo excel'!$B$2:$B$36)*('Cálculo excel'!$C$2:$C$36='Exemplos Validação'!$H9)*('Exemplos Validação'!$I9='Cálculo excel'!$D$2:$D$36)*('Cálculo excel'!$E$2:$E$36='Exemplos Validação'!$J9)*('Exemplos Validação'!$K9='Cálculo excel'!$F$2:$F$36),0),18)} -> 0 | BW9: =BV9-BU9 -> 0 | BX9: 0 | BY9: {=INDEX('Cálculo excel'!$B$2:$X$36,MATCH(1,('Exemplos Validação'!$F9='Cálculo excel'!$B$2:$B$36)*('Cálculo excel'!$C$2:$C$36='Exemplos Validação'!$H9)*('Exemplos Validação'!$I9='Cálculo excel'!$D$2:$D$36)*('Cálculo excel'!$E$2:$E$36='Exemplos Validação'!$J9)*('Exemplos Validação'!$K9='Cálculo excel'!$F$2:$F$36),0),19)} -> 0 | BZ9: =BY9-BX9 -> 0 | CA9: 37.7 | CB9: {=INDEX('Cálculo excel'!$B$2:$X$36,MATCH(1,('Exemplos Validação'!$F9='Cálculo excel'!$B$2:$B$36)*('Cálculo excel'!$C$2:$C$36='Exemplos Validação'!$H9)*('Exemplos Validação'!$I9='Cálculo excel'!$D$2:$D$36)*('Cálculo excel'!$E$2:$E$36='Exemplos Validação'!$J9)*('Exemplos Validação'!$K9='Cálculo excel'!$F$2:$F$36),0),20)} -> 37.7 | CC9: =CB9-CA9 -> 0 | CD9: 17381.96 | CE9: {=INDEX('Cálculo excel'!$B$2:$X$36,MATCH(1,('Exemplos Validação'!$F9='Cálculo excel'!$B$2:$B$36)*('Cálculo excel'!$C$2:$C$36='Exemplos Validação'!$H9)*('Exemplos Validação'!$I9='Cálculo excel'!$D$2:$D$36)*('Cálculo excel'!$E$2:$E$36='Exemplos Validação'!$J9)*('Exemplos Validação'!$K9='Cálculo excel'!$F$2:$F$36),0),21)} -> 17381.96 | CF9: =CE9-CD9 -> 0 | CG9: 0 | CH9: {=INDEX('Cálculo excel'!$B$2:$X$36,MATCH(1,('Exemplos Validação'!$F9='Cálculo excel'!$B$2:$B$36)*('Cálculo excel'!$C$2:$C$36='Exemplos Validação'!$H9)*('Exemplos Validação'!$I9='Cálculo excel'!$D$2:$D$36)*('Cálculo excel'!$E$2:$E$36='Exemplos Validação'!$J9)*('Exemplos Validação'!$K9='Cálculo excel'!$F$2:$F$36),0),22)+INDEX('Cálculo excel'!$B$2:$X$36,MATCH(1,('Exemplos Validação'!$F9='Cálculo excel'!$B$2:$B$36)*('Cálculo excel'!$C$2:$C$36='Exemplos Validação'!$H9)*('Exemplos Validação'!$I9='Cálculo excel'!$D$2:$D$36)*('Cálculo excel'!$E$2:$E$36='Exemplos Validação'!$J9)*('Exemplos Validação'!$K9='Cálculo excel'!$F$2:$F$36),0),23)} -> 0 | CI9: =CH9-CG9 -> 0
A10: COMUM PM | B10: 2025-03-31 | C10: GD | D10: ESTR | E10: 82000000000247494000420000767284 | F10: 82000000000247494000420000767284 | G10: 82000000000247494000420000767284 | H10: 31 | I10: 0000 | J10: 00000247494 | K10: 000420000767284 | L10: AN01020410 | M10: BA4 | N10: N | O10: N | P10: PRDCT010103 | Q10: N | R10: N/A | S10: 00000 | T10: N/A | U10: 11111111111 | V10: 11111111111 | W10: 11111111111 | X10: 11111111111 | Y10: 11111111111 | Z10: 11111111111 | AA10: 11111111111 | AB10: N/A | AC10: 11111111111 | AD10: 11111111111 | AE10: 0.400000 | AF10: 4650.25 | AG10: 25 | AH10: 1 | AI10: 4650.25 | AJ10: 11111111111.00 | AK10: 0.00 | AL10: 0.00 | AM10: 1654.23 | AN10: 2996.02 | AO10: 2025-03-31 | AP10: N/A | AQ10: SNFCAPRES3NP | AR10: 18 | AS10: 80 | AT10: 6 | AU10: 00000 | AV10: 4650.25 | AW10: 4650.25 | AX10: 1 | AY10: 1 | AZ10: 0 | BA10: {=INDEX('Cálculo excel'!$B$2:$X$36,MATCH(1,('Exemplos Validação'!$F10='Cálculo excel'!$B$2:$B$36)*('Cálculo excel'!$C$2:$C$36='Exemplos Validação'!$H10)*('Exemplos Validação'!$I10='Cálculo excel'!$D$2:$D$36)*('Cálculo excel'!$E$2:$E$36='Exemplos Validação'!$J10)*('Exemplos Validação'!$K10='Cálculo excel'!$F$2:$F$36),0),11)} -> 0 | BB10: =BA10-AZ10 -> 0 | BC10: 0 | BD10: {=INDEX('Cálculo excel'!$B$2:$X$36,MATCH(1,('Exemplos Validação'!$F10='Cálculo excel'!$B$2:$B$36)*('Cálculo excel'!$C$2:$C$36='Exemplos Validação'!$H10)*('Exemplos Validação'!$I10='Cálculo excel'!$D$2:$D$36)*('Cálculo excel'!$E$2:$E$36='Exemplos Validação'!$J10)*('Exemplos Validação'!$K10='Cálculo excel'!$F$2:$F$36),0),12)} -> 0 | BE10: =BD10-BC10 -> 0 | BF10: 0 | BG10: {=INDEX('Cálculo excel'!$B$2:$X$36,MATCH(1,('Exemplos Validação'!$F10='Cálculo excel'!$B$2:$B$36)*('Cálculo excel'!$C$2:$C$36='Exemplos Validação'!$H10)*('Exemplos Validação'!$I10='Cálculo excel'!$D$2:$D$36)*('Cálculo excel'!$E$2:$E$36='Exemplos Validação'!$J10)*('Exemplos Validação'!$K10='Cálculo excel'!$F$2:$F$36),0),13)} -> 0 | BH10: =BG10-BF10 -> 0 | BI10: 0 | BJ10: {=INDEX('Cálculo excel'!$B$2:$X$36,MATCH(1,('Exemplos Validação'!$F10='Cálculo excel'!$B$2:$B$36)*('Cálculo excel'!$C$2:$C$36='Exemplos Validação'!$H10)*('Exemplos Validação'!$I10='Cálculo excel'!$D$2:$D$36)*('Cálculo excel'!$E$2:$E$36='Exemplos Validação'!$J10)*('Exemplos Validação'!$K10='Cálculo excel'!$F$2:$F$36),0),14)} -> 0 | BK10: =BJ10-BI10 -> 0 | BL10: 227.07 | BM10: {=INDEX('Cálculo excel'!$B$2:$X$36,MATCH(1,('Exemplos Validação'!$F10='Cálculo excel'!$B$2:$B$36)*('Cálculo excel'!$C$2:$C$36='Exemplos Validação'!$H10)*('Exemplos Validação'!$I10='Cálculo excel'!$D$2:$D$36)*('Cálculo excel'!$E$2:$E$36='Exemplos Validação'!$J10)*('Exemplos Validação'!$K10='Cálculo excel'!$F$2:$F$36),0),15)} -> 227.07 | BN10: =BM10-BL10 -> 0 | BO10: 0 | BP10: {=INDEX('Cálculo excel'!$B$2:$X$36,MATCH(1,('Exemplos Validação'!$F10='Cálculo excel'!$B$2:$B$36)*('Cálculo excel'!$C$2:$C$36='Exemplos Validação'!$H10)*('Exemplos Validação'!$I10='Cálculo excel'!$D$2:$D$36)*('Cálculo excel'!$E$2:$E$36='Exemplos Validação'!$J10)*('Exemplos Validação'!$K10='Cálculo excel'!$F$2:$F$36),0),16)} -> 0 | BQ10: =BP10-BO10 -> 0 | BR10: 0 | BS10: {=INDEX('Cálculo excel'!$B$2:$X$36,MATCH(1,('Exemplos Validação'!$F10='Cálculo excel'!$B$2:$B$36)*('Cálculo excel'!$C$2:$C$36='Exemplos Validação'!$H10)*('Exemplos Validação'!$I10='Cálculo excel'!$D$2:$D$36)*('Cálculo excel'!$E$2:$E$36='Exemplos Validação'!$J10)*('Exemplos Validação'!$K10='Cálculo excel'!$F$2:$F$36),0),17)} -> 0 | BT10: =BS10-BR10 -> 0 | BU10: 0 | BV10: {=INDEX('Cálculo excel'!$B$2:$X$36,MATCH(1,('Exemplos Validação'!$F10='Cálculo excel'!$B$2:$B$36)*('Cálculo excel'!$C$2:$C$36='Exemplos Validação'!$H10)*('Exemplos Validação'!$I10='Cálculo excel'!$D$2:$D$36)*('Cálculo excel'!$E$2:$E$36='Exemplos Validação'!$J10)*('Exemplos Validação'!$K10='Cálculo excel'!$F$2:$F$36),0),18)} -> 0 | BW10: =BV10-BU10 -> 0 | BX10: 0 | BY10: {=INDEX('Cálculo excel'!$B$2:$X$36,MATCH(1,('Exemplos Validação'!$F10='Cálculo excel'!$B$2:$B$36)*('Cálculo excel'!$C$2:$C$36='Exemplos Validação'!$H10)*('Exemplos Validação'!$I10='Cálculo excel'!$D$2:$D$36)*('Cálculo excel'!$E$2:$E$36='Exemplos Validação'!$J10)*('Exemplos Validação'!$K10='Cálculo excel'!$F$2:$F$36),0),19)} -> 0 | BZ10: =BY10-BX10 -> 0 | CA10: 0 | CB10: {=INDEX('Cálculo excel'!$B$2:$X$36,MATCH(1,('Exemplos Validação'!$F10='Cálculo excel'!$B$2:$B$36)*('Cálculo excel'!$C$2:$C$36='Exemplos Validação'!$H10)*('Exemplos Validação'!$I10='Cálculo excel'!$D$2:$D$36)*('Cálculo excel'!$E$2:$E$36='Exemplos Validação'!$J10)*('Exemplos Validação'!$K10='Cálculo excel'!$F$2:$F$36),0),20)} -> 0 | CC10: =CB10-CA10 -> 0 | CD10: 4650.25 | CE10: {=INDEX('Cálculo excel'!$B$2:$X$36,MATCH(1,('Exemplos Validação'!$F10='Cálculo excel'!$B$2:$B$36)*('Cálculo excel'!$C$2:$C$36='Exemplos Validação'!$H10)*('Exemplos Validação'!$I10='Cálculo excel'!$D$2:$D$36)*('Cálculo excel'!$E$2:$E$36='Exemplos Validação'!$J10)*('Exemplos Validação'!$K10='Cálculo excel'!$F$2:$F$36),0),21)} -> 4650.25 | CF10: =CE10-CD10 -> 0 | CG10: 0 | CH10: {=INDEX('Cálculo excel'!$B$2:$X$36,MATCH(1,('Exemplos Validação'!$F10='Cálculo excel'!$B$2:$B$36)*('Cálculo excel'!$C$2:$C$36='Exemplos Validação'!$H10)*('Exemplos Validação'!$I10='Cálculo excel'!$D$2:$D$36)*('Cálculo excel'!$E$2:$E$36='Exemplos Validação'!$J10)*('Exemplos Validação'!$K10='Cálculo excel'!$F$2:$F$36),0),22)+INDEX('Cálculo excel'!$B$2:$X$36,MATCH(1,('Exemplos Validação'!$F10='Cálculo excel'!$B$2:$B$36)*('Cálculo excel'!$C$2:$C$36='Exemplos Validação'!$H10)*('Exemplos Validação'!$I10='Cálculo excel'!$D$2:$D$36)*('Cálculo excel'!$E$2:$E$36='Exemplos Validação'!$J10)*('Exemplos Validação'!$K10='Cálculo excel'!$F$2:$F$36),0),23)} -> 0 | CI10: =CH10-CG10 -> 0
A11: COMUM PM | B11: 2025-03-31 | C11: GD | D11: ESTR | E11: 82000000000247524000450000763856 | F11: 82000000000247524000450000763856 | G11: 82000000000247524000450000763856 | H11: 31 | I11: 0000 | J11: 00000247524 | K11: 000450000763856 | L11: AN01020410 | M11: BA4 | N11: N | O11: N | P11: PRDCT010103 | Q11: N | R11: N/A | S11: 00000 | T11: N/A | U11: 11111111111 | V11: 11111111111 | W11: 11111111111 | X11: 11111111111 | Y11: 11111111111 | Z11: 11111111111 | AA11: 11111111111 | AB11: N/A | AC11: 11111111111 | AD11: 11111111111 | AE11: 0.400000 | AF11: 23136.50 | AG11: 24 | AH11: 11 | AI11: 23223.74 | AJ11: 11111111111.00 | AK11: 0.00 | AL11: 0.00 | AM11: 12706.29 | AN11: 6459.39 | AO11: 2025-03-31 | AP11: N/A | AQ11: SNFCAPRES2P | AR11: 14 | AS11: 80 | AT11: 6 | AU11: 00000 | AV11: 23223.74 | AW11: 23223.74 | AX11: 1 | AY11: 1 | AZ11: 87.45 | BA11: {=INDEX('Cálculo excel'!$B$2:$X$36,MATCH(1,('Exemplos Validação'!$F11='Cálculo excel'!$B$2:$B$36)*('Cálculo excel'!$C$2:$C$36='Exemplos Validação'!$H11)*('Exemplos Validação'!$I11='Cálculo excel'!$D$2:$D$36)*('Cálculo excel'!$E$2:$E$36='Exemplos Validação'!$J11)*('Exemplos Validação'!$K11='Cálculo excel'!$F$2:$F$36),0),11)} -> 87.45 | BB11: =BA11-AZ11 -> 0 | BC11: 0 | BD11: {=INDEX('Cálculo excel'!$B$2:$X$36,MATCH(1,('Exemplos Validação'!$F11='Cálculo excel'!$B$2:$B$36)*('Cálculo excel'!$C$2:$C$36='Exemplos Validação'!$H11)*('Exemplos Validação'!$I11='Cálculo excel'!$D$2:$D$36)*('Cálculo excel'!$E$2:$E$36='Exemplos Validação'!$J11)*('Exemplos Validação'!$K11='Cálculo excel'!$F$2:$F$36),0),12)} -> 0 | BE11: =BD11-BC11 -> 0 | BF11: 0 | BG11: {=INDEX('Cálculo excel'!$B$2:$X$36,MATCH(1,('Exemplos Validação'!$F11='Cálculo excel'!$B$2:$B$36)*('Cálculo excel'!$C$2:$C$36='Exemplos Validação'!$H11)*('Exemplos Validação'!$I11='Cálculo excel'!$D$2:$D$36)*('Cálculo excel'!$E$2:$E$36='Exemplos Validação'!$J11)*('Exemplos Validação'!$K11='Cálculo excel'!$F$2:$F$36),0),13)} -> 0 | BH11: =BG11-BF11 -> 0 | BI11: 0 | BJ11: {=INDEX('Cálculo excel'!$B$2:$X$36,MATCH(1,('Exemplos Validação'!$F11='Cálculo excel'!$B$2:$B$36)*('Cálculo excel'!$C$2:$C$36='Exemplos Validação'!$H11)*('Exemplos Validação'!$I11='Cálculo excel'!$D$2:$D$36)*('Cálculo excel'!$E$2:$E$36='Exemplos Validação'!$J11)*('Exemplos Validação'!$K11='Cálculo excel'!$F$2:$F$36),0),14)} -> 0 | BK11: =BJ11-BI11 -> 0 | BL11: 5263.09 | BM11: {=INDEX('Cálculo excel'!$B$2:$X$36,MATCH(1,('Exemplos Validação'!$F11='Cálculo excel'!$B$2:$B$36)*('Cálculo excel'!$C$2:$C$36='Exemplos Validação'!$H11)*('Exemplos Validação'!$I11='Cálculo excel'!$D$2:$D$36)*('Cálculo excel'!$E$2:$E$36='Exemplos Validação'!$J11)*('Exemplos Validação'!$K11='Cálculo excel'!$F$2:$F$36),0),15)} -> 5263.09 | BN11: =BM11-BL11 -> 0 | BO11: 0 | BP11: {=INDEX('Cálculo excel'!$B$2:$X$36,MATCH(1,('Exemplos Validação'!$F11='Cálculo excel'!$B$2:$B$36)*('Cálculo excel'!$C$2:$C$36='Exemplos Validação'!$H11)*('Exemplos Validação'!$I11='Cálculo excel'!$D$2:$D$36)*('Cálculo excel'!$E$2:$E$36='Exemplos Validação'!$J11)*('Exemplos Validação'!$K11='Cálculo excel'!$F$2:$F$36),0),16)} -> 0 | BQ11: =BP11-BO11 -> 0 | BR11: 190.22 | BS11: {=INDEX('Cálculo excel'!$B$2:$X$36,MATCH(1,('Exemplos Validação'!$F11='Cálculo excel'!$B$2:$B$36)*('Cálculo excel'!$C$2:$C$36='Exemplos Validação'!$H11)*('Exemplos Validação'!$I11='Cálculo excel'!$D$2:$D$36)*('Cálculo excel'!$E$2:$E$36='Exemplos Validação'!$J11)*('Exemplos Validação'!$K11='Cálculo excel'!$F$2:$F$36),0),17)} -> 190.22 | BT11: =BS11-BR11 -> 0 | BU11: 0 | BV11: {=INDEX('Cálculo excel'!$B$2:$X$36,MATCH(1,('Exemplos Validação'!$F11='Cálculo excel'!$B$2:$B$36)*('Cálculo excel'!$C$2:$C$36='Exemplos Validação'!$H11)*('Exemplos Validação'!$I11='Cálculo excel'!$D$2:$D$36)*('Cálculo excel'!$E$2:$E$36='Exemplos Validação'!$J11)*('Exemplos Validação'!$K11='Cálculo excel'!$F$2:$F$36),0),18)} -> 0 | BW11: =BV11-BU11 -> 0 | BX11: 0 | BY11: {=INDEX('Cálculo excel'!$B$2:$X$36,MATCH(1,('Exemplos Validação'!$F11='Cálculo excel'!$B$2:$B$36)*('Cálculo excel'!$C$2:$C$36='Exemplos Validação'!$H11)*('Exemplos Validação'!$I11='Cálculo excel'!$D$2:$D$36)*('Cálculo excel'!$E$2:$E$36='Exemplos Validação'!$J11)*('Exemplos Validação'!$K11='Cálculo excel'!$F$2:$F$36),0),19)} -> 0 | BZ11: =BY11-BX11 -> 0 | CA11: 41.98 | CB11: {=INDEX('Cálculo excel'!$B$2:$X$36,MATCH(1,('Exemplos Validação'!$F11='Cálculo excel'!$B$2:$B$36)*('Cálculo excel'!$C$2:$C$36='Exemplos Validação'!$H11)*('Exemplos Validação'!$I11='Cálculo excel'!$D$2:$D$36)*('Cálculo excel'!$E$2:$E$36='Exemplos Validação'!$J11)*('Exemplos Validação'!$K11='Cálculo excel'!$F$2:$F$36),0),20)} -> 41.98 | CC11: =CB11-CA11 -> 0 | CD11: 23910.355 | CE11: {=INDEX('Cálculo excel'!$B$2:$X$36,MATCH(1,('Exemplos Validação'!$F11='Cálculo excel'!$B$2:$B$36)*('Cálculo excel'!$C$2:$C$36='Exemplos Validação'!$H11)*('Exemplos Validação'!$I11='Cálculo excel'!$D$2:$D$36)*('Cálculo excel'!$E$2:$E$36='Exemplos Validação'!$J11)*('Exemplos Validação'!$K11='Cálculo excel'!$F$2:$F$36),0),21)} -> 23910.355 | CF11: =CE11-CD11 -> 0 | CG11: 0 | CH11: {=INDEX('Cálculo excel'!$B$2:$X$36,MATCH(1,('Exemplos Validação'!$F11='Cálculo excel'!$B$2:$B$36)*('Cálculo excel'!$C$2:$C$36='Exemplos Validação'!$H11)*('Exemplos Validação'!$I11='Cálculo excel'!$D$2:$D$36)*('Cálculo excel'!$E$2:$E$36='Exemplos Validação'!$J11)*('Exemplos Validação'!$K11='Cálculo excel'!$F$2:$F$36),0),22)+INDEX('Cálculo excel'!$B$2:$X$36,MATCH(1,('Exemplos Validação'!$F11='Cálculo excel'!$B$2:$B$36)*('Cálculo excel'!$C$2:$C$36='Exemplos Validação'!$H11)*('Exemplos Validação'!$I11='Cálculo excel'!$D$2:$D$36)*('Cálculo excel'!$E$2:$E$36='Exemplos Validação'!$J11)*('Exemplos Validação'!$K11='Cálculo excel'!$F$2:$F$36),0),23)} -> 0 | CI11: =CH11-CG11 -> 0
