Workbook
Name asefadf: #REF!
Name bn: #REF!

Sheet Status Resumo
B7: Sumário Executivo | 11/jul a 17/jul
C15: 1 Inclui os campos classificados com o status "1. Concluído" e "4. Em Correção".
C16: 2 Inclui os campos classificados com o status "1. Concluído".
C18: Resumo das entregas da equipa de IT | I18: Highlights
D20: Entregas IT | G20: Campos em correção | I20: 1. Encontram-se 3 campos em correção do lado da equipa de IT assim como o universo da tabela lt002_instrument. 2. O foco da equipa de testes durante a última semana foi: • Ajustar a simulação para a data de referência de junho/2025. • Validação das correções efetuadas pela equipa de IT referentes às entregas dos dias 11 e 16 de julho.
C21: Tabela | D21: Planeado | E21: Real | F21: ∆
C22: lt002_instrument | D22: =43+8 -> 51 | E22: =43+8 -> 51 | F22: =E22-D22 -> 0 | G22: =COUNTIFS('Aux Gráficos'!$D$3:$D$75,"4. Em Correção",'Aux Gráficos'!$B$3:$B$75,'Status Resumo'!C22,'Aux Gráficos'!$C$3:$C$75,"<>"&"UNIVERSO") -> 3
C23: lt004_protection | D23: 7 | E23: 7 | F23: =E23-D23 -> 0 | G23: =COUNTIFS('Aux Gráficos'!$D$3:$D$75,"4. Em Correção",'Aux Gráficos'!$B$3:$B$75,'Status Resumo'!C23,'Aux Gráficos'!$C$3:$C$75,"<>"&"UNIVERSO") -> 0
C24: lt006_instr_protection | D24: 5 | E24: 5 | F24: =E24-D24 -> 0 | G24: =COUNTIFS('Aux Gráficos'!$D$3:$D$75,"4. Em Correção",'Aux Gráficos'!$B$3:$B$75,'Status Resumo'!C24,'Aux Gráficos'!$C$3:$C$75,"<>"&"UNIVERSO") -> 0
C25: lt007_instr_activity | D25: 6 | E25: 6 | F25: =E25-D25 -> 0 | G25: =COUNTIFS('Aux Gráficos'!$D$3:$D$75,"4. Em Correção",'Aux Gráficos'!$B$3:$B$75,'Status Resumo'!C25,'Aux Gráficos'!$C$3:$C$75,"<>"&"UNIVERSO") -> 0
C26: Total | D26: =SUM(D22:D25) -> 69 | E26: =SUM(E22:E25) -> 69 | F26: =SUM(F22:F25) -> 0 | G26: =SUM(G22:G25) -> 3
C28: Tracking das incidências detetadas e correções efetuadas pela equipa de IT
C30: Tabela | D30: Tema | G30: Descritivo | Q30: Status Neyond | R30: Status IT
C31: lt002_instrument | D31: Universo | G31: Identificação de contratos exclusivos entre a simulação da equipa de testes e a execução de IT | Q31: Comunicado | R31: Done
C32: lt002_instrument | D32: Campos provenientes de rentabilidade | G32: Erro na forma como estava a ser aplicada a ponderação aos kpm para obtenção do valor em termos de chave FinRep (13 campos afetados) | Q32: Re-especificado | R32: Done
C33: lt002_instrument | D33: Campos "_CCRR" | G33: Preenchimento com os valores default para os campos com o sufixo '_CCRR' | Q33: Done | R33: Done
C34: lt002_instrument | D34: Flg_intrbsnss | G34: Preenchimento incorreto do campo. Encontra-se preenchido com 'N' e 'Miss'. Apenas o 'N' era admissível | Q34: Comunicado | R34: Done
C35: lt002_instrument | D35: Duplicação de linhas na tabela | G35: Preenchimento duplicado de grande parte do universo da tabela - Afeta 12 campos | Q35: Comunicado | R35: Em correção
C36: lt002_instrument | D36: Incorreta aplicação de defaults | G36: Preenchimento incorreto para as linhas onde se aplica o 'Default Value' e o 'Non Applicable Value' - Afeta 12 campos | Q36: Comunicado | R36: Em correção
C37: lt004_protection | D37: Flg_elctrc_vhcl | G37: O campo não foi entregue na data prevista | Q37: Comunicado | R37: Done
C38: lt004_protection | D38: Preenchimento de campos | G38: Preenchimento incorreto dos campos prtctn_vl e flg_elctrcl_vhcl. | Q38: Comunicado | R38: Done
C39: lt006_instr_protection | D39: Preenchimento de campos | G39: Preenchimento incorreto do campo typ_rltn. | Q39: Comunicado | R39: Done
C40: lt007_instr_activity | D40: Universo | G40: Diferenças detetadas entre o universo GD e o universo Pilar3. | Q40: Comunicado | R40: Em correção
C41: lt007_instr_activity | D41: Preenchimento de campos | G41: Diferenças detetadas entre o preenchimento dos campos para o âmbito GD e Pilar3. | Q41: Comunicado | R41: Em correção
C42: lt002_instrument | D42: Preenchimento de campos | G42: Diferenças detetadas entre a simulação da equipa de testes e a execução de IT para os campos typ_off_blnc_prdct, subportfolio_id, dflt_stts_instrmnt, typ_instrmnt, accntng_clssfctn, nw_bsnss, grss_intrst_incm, intrnl_trnsfr_rt. | Q42: Comunicado | R42: Done
B45: 1. LT002_INSTRUMENT
C48: Resumo | G48: Status (Campos) | I48: 45855 | J48: 45848 | K48: ∆ | M48: Highlights
G49: 1. Concluído | I49: =COUNTIFS('Detalhe Entregas e Status'!$V:$V,'Status Resumo'!G49,'Detalhe Entregas e Status'!$B:$B,"lt002_instrument",'Detalhe Entregas e Status'!$C:$C,"<>"&"UNIVERSO") -> 31 | J49: =COUNTIFS('Detalhe Entregas e Status'!$W:$W,'Status Resumo'!G49,'Detalhe Entregas e Status'!$B:$B,"lt002_instrument",'Detalhe Entregas e Status'!$C:$C,"<>"&"UNIVERSO") -> 31 | K49: =IF(I49-J49=0,"-",IF(I49-J49>0,_xlfn.CONCAT("+ ",I49-J49),_xlfn.CONCAT("- ",J49-I49))) -> - | M49: Dos 51 campos entregues por IT, encontram-se 3 em correção e 17 para re-teste.
G50: 2. Em Teste | I50: =COUNTIFS('Detalhe Entregas e Status'!$V:$V,'Status Resumo'!G50,'Detalhe Entregas e Status'!$B:$B,"lt002_instrument",'Detalhe Entregas e Status'!$C:$C,"<>"&"UNIVERSO") -> 0 | J50: =COUNTIFS('Detalhe Entregas e Status'!$W:$W,'Status Resumo'!G50,'Detalhe Entregas e Status'!$B:$B,"lt002_instrument",'Detalhe Entregas e Status'!$C:$C,"<>"&"UNIVERSO") -> 0 | K50: =IF(I50-J50=0,"-",IF(I50-J50>0,_xlfn.CONCAT("+ ",I50-J50),_xlfn.CONCAT("- ",J50-I50))) -> -
G51: 3. Em Re-especificação | I51: =COUNTIFS('Detalhe Entregas e Status'!$V:$V,'Status Resumo'!G51,'Detalhe Entregas e Status'!$B:$B,"lt002_instrument",'Detalhe Entregas e Status'!$C:$C,"<>"&"UNIVERSO") -> 0 | J51: =COUNTIFS('Detalhe Entregas e Status'!$W:$W,'Status Resumo'!G51,'Detalhe Entregas e Status'!$B:$B,"lt002_instrument",'Detalhe Entregas e Status'!$C:$C,"<>"&"UNIVERSO") -> 0 | K51: =IF(I51-J51=0,"-",IF(I51-J51>0,_xlfn.CONCAT("+ ",I51-J51),_xlfn.CONCAT("- ",J51-I51))) -> -
G52: 4. Em Correção | I52: =COUNTIFS('Detalhe Entregas e Status'!$V:$V,'Status Resumo'!G52,'Detalhe Entregas e Status'!$B:$B,"lt002_instrument",'Detalhe Entregas e Status'!$C:$C,"<>"&"UNIVERSO") -> 3 | J52: =COUNTIFS('Detalhe Entregas e Status'!$W:$W,'Status Resumo'!G52,'Detalhe Entregas e Status'!$B:$B,"lt002_instrument",'Detalhe Entregas e Status'!$C:$C,"<>"&"UNIVERSO") -> 3 | K52: =IF(I52-J52=0,"-",IF(I52-J52>0,_xlfn.CONCAT("+ ",I52-J52),_xlfn.CONCAT("- ",J52-I52))) -> -
G53: 5. Em Re-teste | I53: =COUNTIFS('Detalhe Entregas e Status'!$V:$V,'Status Resumo'!G53,'Detalhe Entregas e Status'!$B:$B,"lt002_instrument",'Detalhe Entregas e Status'!$C:$C,"<>"&"UNIVERSO") -> 17 | J53: =COUNTIFS('Detalhe Entregas e Status'!$W:$W,'Status Resumo'!G53,'Detalhe Entregas e Status'!$B:$B,"lt002_instrument",'Detalhe Entregas e Status'!$C:$C,"<>"&"UNIVERSO") -> 17 | K53: =IF(I53-J53=0,"-",IF(I53-J53>0,_xlfn.CONCAT("+ ",I53-J53),_xlfn.CONCAT("- ",J53-I53))) -> -
G54: 6. Por Iniciar | I54: =COUNTIFS('Detalhe Entregas e Status'!$V:$V,'Status Resumo'!G54,'Detalhe Entregas e Status'!$B:$B,"lt002_instrument",'Detalhe Entregas e Status'!$C:$C,"<>"&"UNIVERSO") -> 0 | J54: =COUNTIFS('Detalhe Entregas e Status'!$W:$W,'Status Resumo'!G54,'Detalhe Entregas e Status'!$B:$B,"lt002_instrument",'Detalhe Entregas e Status'!$C:$C,"<>"&"UNIVERSO") -> 0 | K54: =IF(I54-J54=0,"-",IF(I54-J54>0,_xlfn.CONCAT("+ ",I54-J54),_xlfn.CONCAT("- ",J54-I54))) -> -
G55: 7. Por Entregar | I55: =COUNTIFS('Detalhe Entregas e Status'!$V:$V,'Status Resumo'!G55,'Detalhe Entregas e Status'!$B:$B,"lt002_instrument",'Detalhe Entregas e Status'!$C:$C,"<>"&"UNIVERSO") -> 0 | J55: =COUNTIFS('Detalhe Entregas e Status'!$W:$W,'Status Resumo'!G55,'Detalhe Entregas e Status'!$B:$B,"lt002_instrument",'Detalhe Entregas e Status'!$C:$C,"<>"&"UNIVERSO") -> 0 | K55: =IF(I55-J55=0,"-",IF(I55-J55>0,_xlfn.CONCAT("+ ",I55-J55),_xlfn.CONCAT("- ",J55-I55))) -> -
G56: 8. Pendente | I56: =COUNTIFS('Detalhe Entregas e Status'!$V:$V,'Status Resumo'!G56,'Detalhe Entregas e Status'!$B:$B,"lt002_instrument",'Detalhe Entregas e Status'!$C:$C,"<>"&"UNIVERSO") -> 0 | J56: =COUNTIFS('Detalhe Entregas e Status'!$W:$W,'Status Resumo'!G56,'Detalhe Entregas e Status'!$B:$B,"lt002_instrument",'Detalhe Entregas e Status'!$C:$C,"<>"&"UNIVERSO") -> 0 | K56: =IF(I56-J56=0,"-",IF(I56-J56>0,_xlfn.CONCAT("+ ",I56-J56),_xlfn.CONCAT("- ",J56-I56))) -> -
G57: Total | I57: =SUM(I49:I56) -> 51 | J57: =SUM(J49:J56) -> 51
G59: Status (Universo) | I59: =I48 -> 45855
G60: lt002_instrument | I60: em análise
B63: 2. LT004_PROTECTION
C66: Resumo | G66: Status (Campos) | I66: =I48 -> 45855 | J66: =J48 -> 45848 | K66: ∆ | M66: Highlights
...

Sheet Aux Gráficos
B2: Tabela | C2: Campo | D2: Status Atual | F2: Tabela | G2: lt002_instrument
B3: lt002_instrument | C3: UNIVERSO | D3: 4. Em Correção | F3: Campo | G3: (Multiple Items) | N3: Total campos | O3: 69 | P3: =P4+P7+P8 -> 0.65217391
B4: lt002_instrument | C4: AVRG_BLNC | D4: 5. Em Re-teste | N4: Testados | O4: =COUNTIFS($D$3:$D$75,"<>"&"6. Por Iniciar",$D$3:$D$75,"<>"&"2. Em Teste",$C$3:$C$75,"<>"&"UNIVERSO",$D$3:$D$75,"<>"&"5. Em Re-teste",$D$3:$D$75,"<>"&"8. Pendente ") -> 45 | P4: =O4/$O$3 -> 0.65217391
B5: lt002_instrument | C5: NW_BSNSS | D5: 5. Em Re-teste | F5: Row Labels | G5: Count of Status Atual | N5: Concluidos | O5: =COUNTIFS($D$3:$D$75,"1. Concluído",$C$3:$C$75,"<>"&"UNIVERSO") -> 42 | P5: =O5/$O$3 -> 0.60869565
B6: lt002_instrument | C6: GRSS_INTRST_INCM | D6: 5. Em Re-teste | F6: 1. Concluído | G6: 31 | N6: Em correção | O6: =COUNTIFS($D$3:$D$75,"4. Em Correção",$C$3:$C$75,"<>"&"UNIVERSO") -> 3 | P6: =O6/$O$3 -> 0.043478261
B7: lt002_instrument | C7: GRSS_CMMSSN_INCM | D7: 5. Em Re-teste | F7: 4. Em Correção | G7: 3 | N7: Em teste | O7: =COUNTIFS($D$3:$D$75,"2. Em Teste",$C$3:$C$75,"<>"&"UNIVERSO") -> 0 | P7: =O7/$O$3 -> 0
B8: lt002_instrument | C8: INTRNL_TRNSFR_RT | D8: 5. Em Re-teste | F8: 5. Em Re-teste | G8: 17 | N8: Por iniciar | O8: =COUNTIFS($D$3:$D$75,"6. Por Iniciar",$C$3:$C$75,"<>"&"UNIVERSO") -> 0 | P8: =O8/$O$3 -> 0
B9: lt002_instrument | C9: NT_LN_LSS_PRVSN | D9: 5. Em Re-teste | N9: Em Re-teste | O9: =COUNTIFS($D$3:$D$75,"5. Em Re-teste",$C$3:$C$75,"<>"&"UNIVERSO") -> 22 | P9: =O9/$O$3 -> 0.31884058
B10: lt002_instrument | C10: BSNSS_AREA | D10: 4. Em Correção | N10: Pendente | O10: =COUNTIFS($D$3:$D$75,"8. Pendente ",$C$3:$C$75,"<>"&"UNIVERSO") -> 2 | P10: =O10/$O$3 -> 0.028985507
B11: lt002_instrument | C11: MNGMNT_PRDCT | D11: 1. Concluído
B12: lt002_instrument | C12: GRSS_CMMSSN_EXPNS | D12: 5. Em Re-teste
B13: lt002_instrument | C13: GNS_FNNCL_TRNSCTN_EXCHNG_DFFRNCS | D13: 1. Concluído
B14: lt002_instrument | C14: FLG_INTRBSNSS | D14: 5. Em Re-teste
B15: lt002_instrument | C15: INTRBSNSS_ADJ_COD | D15: 1. Concluído
B16: lt002_instrument | C16: COD_SOC_DSTNTN | D16: 1. Concluído | F16: Tabela | G16: lt004_protection
B17: lt002_instrument | C17: BSNSS_AREA_DSTNTN | D17: 1. Concluído | F17: Campo | G17: (Multiple Items)
B18: lt002_instrument | C18: AVRG_BLNC_OFF_BLNC | D18: 5. Em Re-teste
B19: lt002_instrument | C19: INTRNL_TRNSFR_RT_OFF_BLNC | D19: 1. Concluído | F19: Row Labels | G19: Count of Status Atual
B20: lt002_instrument | C20: GRSS_CMMSSN_INCM_OFF_BLNC | D20: 5. Em Re-teste | F20: 1. Concluído | G20: 5
B21: lt002_instrument | C21: GRSS_CMMSSN_EXPNS_OFF_BLNC | D21: 1. Concluído | F21: 5. Em Re-teste | G21: 2
B22: lt002_instrument | C22: RWA_OFF_BLNC | D22: 1. Concluído
B23: lt002_instrument | C23: GRSS_INTRST_EXPNS | D23: 1. Concluído
B24: lt002_instrument | C24: NT_LN_LSS_PRVSN_OFF_BLNC | D24: 5. Em Re-teste | F24: Tabela | G24: lt007_instr_activity | J24: Tabela | K24: lt006_instr_protection
B25: lt002_instrument | C25: GRSS_INTRST_INCM_CCRR | D25: 1. Concluído | F25: Campo | G25: (Multiple Items) | J25: Campo | K25: (Multiple Items)
B26: lt002_instrument | C26: GRSS_INTRST_EXPNS_CCRR | D26: 1. Concluído
B27: lt002_instrument | C27: GRSS_CMMSSN_INCM_CCRR | D27: 1. Concluído | F27: Row Labels | G27: Count of Status Atual | J27: Row Labels | K27: Count of Status Atual
B28: lt002_instrument | C28: GRSS_CMMSSN_EXPNS_CCRR | D28: 1. Concluído | F28: 1. Concluído | G28: 2 | J28: 1. Concluído | K28: 4
B29: lt002_instrument | C29: GNS_FNNCL_TRNSCTN_EXCHNG_CCRR | D29: 1. Concluído | F29: 5. Em Re-teste | G29: 2 | J29: 5. Em Re-teste | K29: 1
B30: lt002_instrument | C30: BSNSS_AREA_CCRR | D30: 1. Concluído | F30: 8. Pendente | G30: 2
B31: lt002_instrument | C31: GRSS_CMMSSN_INCM_OFF_BLNC_CCRR | D31: 1. Concluído
B32: lt002_instrument | C32: GRSS_CMMSSN_EXPNS_OFF_BLNC_CCRR | D32: 1. Concluído
B33: lt002_instrument | C33: CCF | D33: 1. Concluído
B34: lt002_instrument | C34: EAD | D34: 1. Concluído
B35: lt002_instrument | C35: TYP_OFF_BLNC_PRDCT | D35: 5. Em Re-teste
B36: lt002_instrument | C36: COD_SOC | D36: 1. Concluído
B37: lt002_instrument | C37: SUBPORTFOLIO_ID | D37: 5. Em Re-teste
B38: lt002_instrument | C38: DT_RFRNC | D38: 1. Concluído
B39: lt002_instrument | C39: DFLT_STTS_INSTRMNT | D39: 5. Em Re-teste
B40: lt002_instrument | C40: IMPRMNT_STTS | D40: 1. Concluído
B41: lt002_instrument | C41: PRFRMNG_STTS | D41: 1. Concluído
...

Sheet MacroPlano
B7: Legenda:
B9: « | C9: Entregas da equipa de IT
B10: ♦ | C10: Reuniões de PdS com cliente
B11: 3 | C11: Tempo estimado para a realização da atividade
C12: Feriados
G14: Semana 1 | K14: Semana 2 | P14: Semana 3 | U14: Semana 4 | Z14: Semana 5 | AF14: Semana 6 | AK14: Semana 7 | AO14: Semana 8 | AT14: Semana 9
B15: ID | C15: Atividade | E15: Owner | G15: 12/mai a 15/mai | K15: 16/mai a 22/mai | P15: 23/mai a 29/mai | U15: 30/mai a 05/jun | Z15: 06/jun a 13/jun | AF15: 16/jun a 20/jun | AK15: 23/jun a 26/jun | AO15: 27/jun a 03/jul | AT15: 04/jul a 11/jul
B16: 0. | C16: Gestão
B17: 0.1 | C17: SetUp | E17: Neyond
B18: 0.2 | C18: Reuniões de PdS | E18: Neyond/CdG/IT | J18: ♦ | O18: ♦ | T18: ♦ | Y18: ♦ | AD18: ♦ | AJ18: ♦ | AN18: ♦ | AS18: ♦ | AX18: ♦
B19: 1. | C19: Testes - Entrega 1 | G19: «
B20: 1.1 | C20: lt002_instrument | D20: UNIVERSO | E20: Neyond
B21: 1.2 | C21: lt002_instrument | D21: NW_BSNSS | E21: Neyond
B22: 1.3 | C22: lt002_instrument | D22: GRSS_INTRST_INCM_CCRR | E22: Neyond
B23: =_xlfn.CONCAT(B19,RIGHT(B22,1)+1) -> 1.4 | C23: lt002_instrument | D23: GRSS_INTRST_EXPNS_CCRR | E23: Neyond
B24: 1.5 | C24: lt002_instrument | D24: GRSS_CMMSSN_INCM_CCRR | E24: Neyond
B25: 1.6 | C25: lt002_instrument | D25: GRSS_CMMSSN_EXPNS_CCRR | E25: Neyond
B26: 1.7 | C26: lt002_instrument | D26: GNS_FNNCL_TRNSCTN_EXCHNG_CCRR | E26: Neyond
B27: 1.8 | C27: lt002_instrument | D27: BSNSS_AREA_CCRR | E27: Neyond
B28: 1.9 | C28: lt002_instrument | D28: GRSS_CMMSSN_INCM_OFF_BLNC_CCRR | E28: Neyond
B29: 1.10 | C29: lt002_instrument | D29: GRSS_CMMSSN_EXPNS_OFF_BLNC_CCRR | E29: Neyond
B30: 1.11 | C30: lt002_instrument | D30: DT_RFRNC | E30: Neyond
B31: 1.12 | C31: lt002_instrument | D31: CNCLLD_INSTRMNT_STTS | E31: Neyond
B32: 1.13 | C32: lt002_instrument | D32: INSTRMNT_ID | E32: Neyond
B33: 2. | C33: Testes - Entrega 2 | G33: «
B34: 2.1 | C34: lt002_instrument | D34: GRSS_INTRST_INCM | E34: Neyond
B35: 2.2 | C35: lt002_instrument | D35: GRSS_CMMSSN_INCM | E35: Neyond
B36: 2.3 | C36: lt002_instrument | D36: GRSS_CMMSSN_EXPNS | E36: Neyond
B37: 2.4 | C37: lt002_instrument | D37: AVRG_BLNC_OFF_BLNC | E37: Neyond
B38: 2.5 | C38: lt002_instrument | D38: GRSS_CMMSSN_INCM_OFF_BLNC | E38: Neyond
B39: 2.6 | C39: lt002_instrument | D39: GRSS_CMMSSN_EXPNS_OFF_BLNC | E39: Neyond
B40: 2.7 | C40: lt004_protection | D40: UNIVERSO | E40: Neyond
B41: 2.8 | C41: lt004_protection | D41: TYP_VHCL | E41: Neyond
B42: 2.9 | C42: lt007_instr_activity | D42: UNIVERSO | E42: Neyond
B43: 2.10 | C43: lt007_instr_activity | D43: PRCNTG_ACTVTY | E43: Neyond
B44: 2.11 | C44: lt007_instr_activity | D44: SSTNBL_CTGRY | E44: Neyond
B45: 2.12 | C45: lt007_instr_activity | D45: COD_SOC | E45: Neyond
... B47: 2.14 | C47: lt007_instr_activity | D47: INSTRMNT_ID | E47: Neyond
B48: 3. | C48: Testes - Entrega 3 | L48: «
B49: 3.1 | C49: lt002_instrument | D49: AVRG_BLNC | E49: Neyond
...

Sheet MacroPlano Equipa
B7: Legenda:
B9: « | C9: Entregas da equipa de IT
B10: ♦ | C10: Reuniões de PdS com cliente
B11: 3 | C11: Tempo estimado para a realização da atividade | L11: FTE's | O11: 2 | P11: 2 | Q11: 2 | R11: 2 | S11: 2 | T11: 0 | U11: 0 | V11: 2 | W11: 2 | X11: 2 | Y11: 2 | Z11: 2 | AA11: 0 | AB11: 0 | AC11: 2 | AD11: 2 | AE11: 2 | AF11: 2 | AG11: 2 | AH11: 0 | AI11: 0 | AJ11: 1 | AK11: 1 | AL11: 1 | AM11: 1 | AN11: 1 | AO11: 0 | AP11: 0 | AQ11: 1 | AR11: 0 | AS11: 1 | AT11: 1 | AU11: 0 | AV11: 0 | AW11: 0 | AX11: 2 | AY11: 2 | AZ11: 1 | BA11: 0 | BB11: 1 | BC11: 0 | BD11: 0 | BE11: 1 | BF11: 1 | BG11: 1 | BH11: 1 | BI11: 1 | BJ11: 0 | BK11: 0 | BL11: 2 | BM11: 2 | BN11: 2 | BO11: 2 | BP11: 2 | BQ11: 0 | BR11: 0 | BS11: 2 | BT11: 2 | BU11: 2 | BV11: 2 | BW11: 2 | BX11: 0 | BY11: 0
C12: Feriados | L12: SUM(FTE's) | O12: =SUM(O17:O101)/8 -> 2 | P12: =SUM(P17:P101)/8 -> 2 | Q12: =SUM(Q17:Q101)/8 -> 2.1875 | R12: =SUM(R17:R101)/8 -> 2 | S12: =SUM(S17:S101)/8 -> 2 | T12: =SUM(T17:T101)/8 -> 0 | U12: =SUM(U17:U101)/8 -> 0 | V12: =SUM(V17:V101)/8 -> 2 | ... BY12: =SUM(BY17:BY101)/8 -> 0
B13: 0 | C13: Fins-de-semana | L13: VAL | O13: =O11-O12 -> 0 | P13: =P11-P12 -> 0 | Q13: =Q11-Q12 -> -0.1875 | R13: =R11-R12 -> 0 | S13: =S11-S12 -> 0 | T13: =T11-T12 -> 0 | U13: =U11-U12 -> 0 | V13: =V11-V12 -> 0 | ... BY13: =BY11-BY12 -> 0
L14: sai
F15: Tempo Previsto | H15: Tempo Real | J15: Status | O15: Semana 1 | V15: Semana 2 | AC15: Semana 3 | AJ15: Semana 4 | AQ15: Semana 5 | AX15: Semana 6 | BE15: Semana 7 | BL15: Semana 8 | BS15: Semana 9
B16: ID | C16: Atividade | E16: Owner | F16: Horas | G16: Dias | H16: Horas | I16: Dias | J16: Previsto | K16: Real | L16: Desvio (%) | M16: Val | O16: 45789 | P16: =O16+1 -> 45790 | Q16: =P16+1 -> 45791 | R16: =Q16+1 -> 45792 | S16: =R16+1 -> 45793 | T16: =S16+1 -> 45794 | U16: =T16+1 -> 45795 | V16: =U16+1 -> 45796 | W16: =V16+1 -> 45797 | ... AH16: =AG16+1 -> 45808 | AI16: 45809 | AJ16: =AI16+1 -> 45810 | AK16: =AJ16+1 -> 45811 | AL16: 45812 | AM16: =AL16+1 -> 45813 | AN16: =AM16+1 -> 45814 | AO16: =AN16+1 -> 45815 | AP16: =AO16+1 -> 45816 | AQ16: =AP16+1 -> 45817 | AR16: =AQ16+1 -> 45818 | AS16: =AR16+1 -> 45819 | AT16: =AS16+1 -> 45820 | ... BY16: =BX16+1 -> 45851
B17: 0. | C17: Gestão | T17: 0 | U17: 0 | AA17: 0 | AB17: 0 | AH17: 0 | AI17: 0 | AO17: 0 | AP17: 0 | AV17: 0 | AW17: 0 | BC17: 0 | BD17: 0 | BJ17: 0 | BK17: 0 | BQ17: 0 | BR17: 0 | BX17: 0 | BY17: 0
B18: 0.1 | C18: SetUp | E18: Neyond | F18: 48 | G18: =F18/8/2 -> 3 | H18: {=SUMPRODUCT((COLUMN(O18:BY18)>=MIN(IF(O18:BY18<>"",COLUMN(O18:BY18))))*($O$16:$BY$16<=TODAY())*(O18:BY18))} -> 48 | I18: =H18/8/2 -> 3 | J18: {=SUMPRODUCT(($O$16:$Q$16<=TODAY())*(O18:Q18))/F18} -> 1 | K18: {=IFERROR(SUMPRODUCT(($O$16:$BY$16<=TODAY())*(O18:BY18))/H18,"")} -> 1 | L18: =IFERROR(K18-J18,"") -> 0 | M18: =SUM(O18:BY18)-F18 -> 0 | O18: 16 | P18: 16 | Q18: 16 | T18: 0 | U18: 0 | AA18: 0 | AB18: 0 | AH18: 0 | AI18: 0 | AO18: 0 | AP18: 0 | AV18: 0 | AW18: 0 | BC18: 0 | BD18: 0 | BJ18: 0 | BK18: 0 | BQ18: 0 | BR18: 0 | BX18: 0 | BY18: 0
B19: 0.2 | C19: Reuniões de PdS | E19: Neyond/CdG/IT | F19: 9 | G19: =F19/8 -> 1.125 | R19: ♦ | T19: 0 | U19: 0 | Y19: ♦ | AA19: 0 | AB19: 0 | AF19: ♦ | AH19: 0 | AI19: 0 | AM19: ♦ | AO19: 0 | AP19: 0 | AT19: ♦ | AV19: 0 | AW19: 0 | AZ19: ♦ | BC19: 0 | BD19: 0 | BH19: ♦ | BJ19: 0 | BK19: 0 | BO19: ♦ | BQ19: 0 | BR19: 0 | BV19: ♦ | BX19: 0 | BY19: 0
B20: 1. | C20: Testes - Entrega 1 | O20: « | T20: 0 | U20: 0 | AA20: 0 | AB20: 0 | AH20: 0 | AI20: 0 | AO20: 0 | AP20: 0 | AV20: 0 | AW20: 0 | BC20: 0 | BD20: 0 | BJ20: 0 | BK20: 0 | BQ20: 0 | BR20: 0 | BX20: 0 | BY20: 0
B21: 1.1 | C21: lt002_instrument | D21: UNIVERSO | E21: Neyond | F21: =SUMIFS('Detalhe Testes'!$F:$F,'Detalhe Testes'!$B:$B,'MacroPlano Equipa'!C21,'Detalhe Testes'!$C:$C,'MacroPlano Equipa'!D21) -> 16 | G21: =F21/8 -> 2 | H21: {=SUMPRODUCT((COLUMN(O21:BY21)>=MIN(IF(O21:BY21<>"",COLUMN(O21:BY21))))*($O$16:$BY$16<=TODAY())*(O21:BY21))} -> 16 | I21: =H21/8 -> 2 | M21: =SUM(O21:BY21)-F21 -> 0 | T21: 0 | U21: 0 | V21: 8 | W21: 8 | AA21: 0 | AB21: 0 | AH21: 0 | AI21: 0 | AO21: 0 | AP21: 0 | AV21: 0 | AW21: 0 | BC21: 0 | BD21: 0 | BJ21: 0 | BK21: 0 | BQ21: 0 | BR21: 0 | BX21: 0 | BY21: 0
B22: 1.2 | C22: lt002_instrument | D22: NW_BSNSS | E22: Neyond | F22: =SUMIFS('Detalhe Testes'!$F:$F,'Detalhe Testes'!$B:$B,'MacroPlano Equipa'!C22,'Detalhe Testes'!$C:$C,'MacroPlano Equipa'!D22) -> 5 | G22: =F22/8 -> 0.625 | H22: {=SUMPRODUCT((COLUMN(O22:BY22)>=MIN(IF(O22:BY22<>"",COLUMN(O22:BY22))))*($O$16:$BY$16<=TODAY())*(O22:BY22))} -> 5 | I22: =H22/8 -> 0.625 | M22: =SUM(O22:BY22)-F22 -> 0 | T22: 0 | U22: 0 | W22: 3 | X22: 2 | AA22: 0 | AB22: 0 | AH22: 0 | AI22: 0 | AO22: 0 | AP22: 0 | AV22: 0 | AW22: 0 | BC22: 0 | BD22: 0 | BJ22: 0 | BK22: 0 | BQ22: 0 | BR22: 0 | BX22: 0 | BY22: 0
B23: 1.3 | C23: lt002_instrument | D23: GRSS_INTRST_INCM_CCRR | E23: Neyond | F23: =SUMIFS('Detalhe Testes'!$F:$F,'Detalhe Testes'!$B:$B,'MacroPlano Equipa'!C23,'Detalhe Testes'!$C:$C,'MacroPlano Equipa'!D23) -> 3 | G23: =F23/8 -> 0.375 | H23: {=SUMPRODUCT((COLUMN(O23:BY23)>=MIN(IF(O23:BY23<>"",COLUMN(O23:BY23))))*($O$16:$BY$16<=TODAY())*(O23:BY23))} -> 3 | I23: =H23/8 -> 0.375 | M23: =SUM(O23:BY23)-F23 -> 0 | R23: 3 | T23: 0 | U23: 0 | AA23: 0 | AB23: 0 | AH23: 0 | AI23: 0 | AO23: 0 | AP23: 0 | AV23: 0 | AW23: 0 | BC23: 0 | BD23: 0 | BJ23: 0 | BK23: 0 | BQ23: 0 | BR23: 0 | BX23: 0 | BY23: 0
B24: =_xlfn.CONCAT(B20,RIGHT(B23,1)+1) -> 1.4 | C24: lt002_instrument | D24: GRSS_INTRST_EXPNS_CCRR | E24: Neyond | F24: =SUMIFS('Detalhe Testes'!$F:$F,'Detalhe Testes'!$B:$B,'MacroPlano Equipa'!C24,'Detalhe Testes'!$C:$C,'MacroPlano Equipa'!D24) -> 3 | G24: =F24/8 -> 0.375 | H24: {=SUMPRODUCT((COLUMN(O24:BY24)>=MIN(IF(O24:BY24<>"",COLUMN(O24:BY24))))*($O$16:$BY$16<=TODAY())*(O24:BY24))} -> 3 | I24: =H24/8 -> 0.375 | M24: =SUM(O24:BY24)-F24 -> 0 | R24: 3 | T24: 0 | U24: 0 | AA24: 0 | AB24: 0 | AH24: 0 | AI24: 0 | AO24: 0 | AP24: 0 | AV24: 0 | AW24: 0 | BC24: 0 | BD24: 0 | BJ24: 0 | BK24: 0 | BQ24: 0 | BR24: 0 | BX24: 0 | BY24: 0
B25: 1.5 | C25: lt002_instrument | D25: GRSS_CMMSSN_INCM_CCRR | E25: Neyond | F25: =SUMIFS('Detalhe Testes'!$F:$F,'Detalhe Testes'!$B:$B,'MacroPlano Equipa'!C25,'Detalhe Testes'!$C:$C,'MacroPlano Equipa'!D25) -> 3 | G25: =F25/8 -> 0.375 | H25: {=SUMPRODUCT((COLUMN(O25:BY25)>=MIN(IF(O25:BY25<>"",COLUMN(O25:BY25))))*($O$16:$BY$16<=TODAY())*(O25:BY25))} -> 3 | I25: =H25/8 -> 0.375 | M25: =SUM(O25:BY25)-F25 -> 0 | R25: 3 | T25: 0 | U25: 0 | AA25: 0 | AB25: 0 | AH25: 0 | AI25: 0 | AO25: 0 | AP25: 0 | AV25: 0 | AW25: 0 | BC25: 0 | BD25: 0 | BJ25: 0 | BK25: 0 | BQ25: 0 | BR25: 0 | BX25: 0 | BY25: 0
B26: 1.6 | C26: lt002_instrument | D26: GRSS_CMMSSN_EXPNS_CCRR | E26: Neyond | F26: =SUMIFS('Detalhe Testes'!$F:$F,'Detalhe Testes'!$B:$B,'MacroPlano Equipa'!C26,'Detalhe Testes'!$C:$C,'MacroPlano Equipa'!D26) -> 3 | G26: =F26/8 -> 0.375 | H26: {=SUMPRODUCT((COLUMN(O26:BY26)>=MIN(IF(O26:BY26<>"",COLUMN(O26:BY26))))*($O$16:$BY$16<=TODAY())*(O26:BY26))} -> 3 | I26: =H26/8 -> 0.375 | M26: =SUM(O26:BY26)-F26 -> 0 | R26: 3 | T26: 0 | U26: 0 | AA26: 0 | AB26: 0 | AH26: 0 | AI26: 0 | AO26: 0 | AP26: 0 | AV26: 0 | AW26: 0 | BC26: 0 | BD26: 0 | BJ26: 0 | BK26: 0 | BQ26: 0 | BR26: 0 | BX26: 0 | BY26: 0
B27: 1.7 | C27: lt002_instrument | D27: GNS_FNNCL_TRNSCTN_EXCHNG_CCRR | E27: Neyond | F27: =SUMIFS('Detalhe Testes'!$F:$F,'Detalhe Testes'!$B:$B,'MacroPlano Equipa'!C27,'Detalhe Testes'!$C:$C,'MacroPlano Equipa'!D27) -> 3 | G27: =F27/8 -> 0.375 | H27: {=SUMPRODUCT((COLUMN(O27:BY27)>=MIN(IF(O27:BY27<>"",COLUMN(O27:BY27))))*($O$16:$BY$16<=TODAY())*(O27:BY27))} -> 3 | I27: =H27/8 -> 0.375 | M27: =SUM(O27:BY27)-F27 -> 0 | R27: 3 | T27: 0 | U27: 0 | AA27: 0 | AB27: 0 | AH27: 0 | AI27: 0 | AO27: 0 | AP27: 0 | AV27: 0 | AW27: 0 | BC27: 0 | BD27: 0 | BJ27: 0 | BK27: 0 | BQ27: 0 | BR27: 0 | BX27: 0 | BY27: 0
B28: 1.8 | C28: lt002_instrument | D28: BSNSS_AREA_CCRR | E28: Neyond | F28: =SUMIFS('Detalhe Testes'!$F:$F,'Detalhe Testes'!$B:$B,'MacroPlano Equipa'!C28,'Detalhe Testes'!$C:$C,'MacroPlano Equipa'!D28) -> 3 | G28: =F28/8 -> 0.375 | H28: {=SUMPRODUCT((COLUMN(O28:BY28)>=MIN(IF(O28:BY28<>"",COLUMN(O28:BY28))))*($O$16:$BY$16<=TODAY())*(O28:BY28))} -> 3 | I28: =H28/8 -> 0.375 | M28: =SUM(O28:BY28)-F28 -> 0 | R28: 1 | S28: 2 | T28: 0 | U28: 0 | AA28: 0 | AB28: 0 | AH28: 0 | AI28: 0 | AO28: 0 | AP28: 0 | AV28: 0 | AW28: 0 | BC28: 0 | BD28: 0 | BJ28: 0 | BK28: 0 | BQ28: 0 | BR28: 0 | BX28: 0 | BY28: 0
B29: 1.9 | C29: lt002_instrument | D29: GRSS_CMMSSN_INCM_OFF_BLNC_CCRR | E29: Neyond | F29: =SUMIFS('Detalhe Testes'!$F:$F,'Detalhe Testes'!$B:$B,'MacroPlano Equipa'!C29,'Detalhe Testes'!$C:$C,'MacroPlano Equipa'!D29) -> 3 | G29: =F29/8 -> 0.375 | H29: {=SUMPRODUCT((COLUMN(O29:BY29)>=MIN(IF(O29:BY29<>"",COLUMN(O29:BY29))))*($O$16:$BY$16<=TODAY())*(O29:BY29))} -> 3 | I29: =H29/8 -> 0.375 | M29: =SUM(O29:BY29)-F29 -> 0 | S29: 3 | T29: 0 | U29: 0 | AA29: 0 | AB29: 0 | AH29: 0 | AI29: 0 | AO29: 0 | AP29: 0 | AV29: 0 | AW29: 0 | BC29: 0 | BD29: 0 | BJ29: 0 | BK29: 0 | BQ29: 0 | BR29: 0 | BX29: 0 | BY29: 0
B30: 1.10 | C30: lt002_instrument | D30: GRSS_CMMSSN_EXPNS_OFF_BLNC_CCRR | E30: Neyond | F30: =SUMIFS('Detalhe Testes'!$F:$F,'Detalhe Testes'!$B:$B,'MacroPlano Equipa'!C30,'Detalhe Testes'!$C:$C,'MacroPlano Equipa'!D30) -> 3 | G30: =F30/8 -> 0.375 | H30: {=SUMPRODUCT((COLUMN(O30:BY30)>=MIN(IF(O30:BY30<>"",COLUMN(O30:BY30))))*($O$16:$BY$16<=TODAY())*(O30:BY30))} -> 3 | I30: =H30/8 -> 0.375 | M30: =SUM(O30:BY30)-F30 -> 0 | S30: 3 | T30: 0 | U30: 0 | AA30: 0 | AB30: 0 | AH30: 0 | AI30: 0 | AO30: 0 | AP30: 0 | AV30: 0 | AW30: 0 | BC30: 0 | BD30: 0 | BJ30: 0 | BK30: 0 | BQ30: 0 | BR30: 0 | BX30: 0 | BY30: 0
B31: 1.11 | C31: lt002_instrument | D31: DT_RFRNC | E31: Neyond | F31: =SUMIFS('Detalhe Testes'!$F:$F,'Detalhe Testes'!$B:$B,'MacroPlano Equipa'!C31,'Detalhe Testes'!$C:$C,'MacroPlano Equipa'!D31) -> 3 | G31: =F31/8 -> 0.375 | H31: {=SUMPRODUCT((COLUMN(O31:BY31)>=MIN(IF(O31:BY31<>"",COLUMN(O31:BY31))))*($O$16:$BY$16<=TODAY())*(O31:BY31))} -> 3 | I31: =H31/8 -> 0.375 | M31: =SUM(O31:BY31)-F31 -> 0 | S31: 3 | T31: 0 | U31: 0 | AA31: 0 | AB31: 0 | AH31: 0 | AI31: 0 | AO31: 0 | AP31: 0 | AV31: 0 | AW31: 0 | BC31: 0 | BD31: 0 | BJ31: 0 | BK31: 0 | BQ31: 0 | BR31: 0 | BX31: 0 | BY31: 0
B32: 1.12 | C32: lt002_instrument | D32: CNCLLD_INSTRMNT_STTS | E32: Neyond | F32: =SUMIFS('Detalhe Testes'!$F:$F,'Detalhe Testes'!$B:$B,'MacroPlano Equipa'!C32,'Detalhe Testes'!$C:$C,'MacroPlano Equipa'!D32) -> 11 | G32: =F32/8 -> 1.375 | H32: {=SUMPRODUCT((COLUMN(O32:BY32)>=MIN(IF(O32:BY32<>"",COLUMN(O32:BY32))))*($O$16:$BY$16<=TODAY())*(O32:BY32))} -> 11 | I32: =H32/8 -> 1.375 | M32: =SUM(O32:BY32)-F32 -> 0 | T32: 0 | U32: 0 | V32: 6 | W32: 5 | AA32: 0 | AB32: 0 | AH32: 0 | AI32: 0 | AO32: 0 | AP32: 0 | AV32: 0 | AW32: 0 | BC32: 0 | BD32: 0 | BJ32: 0 | BK32: 0 | BQ32: 0 | BR32: 0 | BX32: 0 | BY32: 0
B33: 1.13 | C33: lt002_instrument | D33: INSTRMNT_ID | E33: Neyond | F33: =SUMIFS('Detalhe Testes'!$F:$F,'Detalhe Testes'!$B:$B,'MacroPlano Equipa'!C33,'Detalhe Testes'!$C:$C,'MacroPlano Equipa'!D33) -> 7 | G33: =F33/8 -> 0.875 | H33: {=SUMPRODUCT((COLUMN(O33:BY33)>=MIN(IF(O33:BY33<>"",COLUMN(O33:BY33))))*($O$16:$BY$16<=TODAY())*(O33:BY33))} -> 7 | I33: =H33/8 -> 0.875 | M33: =SUM(O33:BY33)-F33 -> 0 | S33: 5 | T33: 0 | U33: 0 | V33: 2 | AA33: 0 | AB33: 0 | AH33: 0 | AI33: 0 | AO33: 0 | AP33: 0 | AV33: 0 | AW33: 0 | BC33: 0 | BD33: 0 | BJ33: 0 | BK33: 0 | BQ33: 0 | BR33: 0 | BX33: 0 | BY33: 0
B34: 2. | C34: Testes - Entrega 2 | M34: =SUM(O34:BY34)-F34 -> 0 | O34: « | T34: 0 | U34: 0 | AA34: 0 | AB34: 0 | AH34: 0 | AI34: 0 | AO34: 0 | AP34: 0 | AV34: 0 | AW34: 0 | BC34: 0 | BD34: 0 | BJ34: 0 | BK34: 0 | BQ34: 0 | BR34: 0 | BX34: 0 | BY34: 0
B35: 2.1 | C35: lt002_instrument | D35: GRSS_INTRST_INCM | E35: Neyond | F35: =SUMIFS('Detalhe Testes'!$F:$F,'Detalhe Testes'!$B:$B,'MacroPlano Equipa'!C35,'Detalhe Testes'!$C:$C,'MacroPlano Equipa'!D35) -> 5 | G35: =F35/8 -> 0.625 | H35: {=SUMPRODUCT((COLUMN(O35:BY35)>=MIN(IF(O35:BY35<>"",COLUMN(O35:BY35))))*($O$16:$BY$16<=TODAY())*(O35:BY35))} -> 5 | I35: =H35/8 -> 0.625 | M35: =SUM(O35:BY35)-F35 -> 0 | T35: 0 | U35: 0 | X35: 5 | AA35: 0 | AB35: 0 | AH35: 0 | AI35: 0 | AO35: 0 | AP35: 0 | AV35: 0 | AW35: 0 | BC35: 0 | BD35: 0 | BJ35: 0 | BK35: 0 | BQ35: 0 | BR35: 0 | BX35: 0 | BY35: 0
B36: 2.2 | C36: lt002_instrument | D36: GRSS_CMMSSN_INCM | E36: Neyond | F36: =SUMIFS('Detalhe Testes'!$F:$F,'Detalhe Testes'!$B:$B,'MacroPlano Equipa'!C36,'Detalhe Testes'!$C:$C,'MacroPlano Equipa'!D36) -> 5 | G36: =F36/8 -> 0.625 | H36: {=SUMPRODUCT((COLUMN(O36:BY36)>=MIN(IF(O36:BY36<>"",COLUMN(O36:BY36))))*($O$16:$BY$16<=TODAY())*(O36:BY36))} -> 5 | I36: =H36/8 -> 0.625 | M36: =SUM(O36:BY36)-F36 -> 0 | T36: 0 | U36: 0 | X36: 1 | Y36: 4 | AA36: 0 | AB36: 0 | AH36: 0 | AI36: 0 | AO36: 0 | AP36: 0 | AV36: 0 | AW36: 0 | BC36: 0 | BD36: 0 | BJ36: 0 | BK36: 0 | BQ36: 0 | BR36: 0 | BX36: 0 | BY36: 0
B37: 2.3 | C37: lt002_instrument | D37: GRSS_CMMSSN_EXPNS | E37: Neyond | F37: =SUMIFS('Detalhe Testes'!$F:$F,'Detalhe Testes'!$B:$B,'MacroPlano Equipa'!C37,'Detalhe Testes'!$C:$C,'MacroPlano Equipa'!D37) -> 5 | G37: =F37/8 -> 0.625 | H37: {=SUMPRODUCT((COLUMN(O37:BY37)>=MIN(IF(O37:BY37<>"",COLUMN(O37:BY37))))*($O$16:$BY$16<=TODAY())*(O37:BY37))} -> 5 | I37: =H37/8 -> 0.625 | M37: =SUM(O37:BY37)-F37 -> 0 | T37: 0 | U37: 0 | Y37: 4 | Z37: 1 | AA37: 0 | AB37: 0 | AH37: 0 | AI37: 0 | AO37: 0 | AP37: 0 | AV37: 0 | AW37: 0 | BC37: 0 | BD37: 0 | BJ37: 0 | BK37: 0 | BQ37: 0 | BR37: 0 | BX37: 0 | BY37: 0
B38: 2.4 | C38: lt002_instrument | D38: AVRG_BLNC_OFF_BLNC | E38: Neyond | F38: =SUMIFS('Detalhe Testes'!$F:$F,'Detalhe Testes'!$B:$B,'MacroPlano Equipa'!C38,'Detalhe Testes'!$C:$C,'MacroPlano Equipa'!D38) -> 5 | G38: =F38/8 -> 0.625 | H38: {=SUMPRODUCT((COLUMN(O38:BY38)>=MIN(IF(O38:BY38<>"",COLUMN(O38:BY38))))*($O$16:$BY$16<=TODAY())*(O38:BY38))} -> 5 | I38: =H38/8 -> 0.625 | M38: =SUM(O38:BY38)-F38 -> 0 | T38: 0 | U38: 0 | Z38: 5 | AA38: 0 | AB38: 0 | AH38: 0 | AI38: 0 | AO38: 0 | AP38: 0 | AV38: 0 | AW38: 0 | BC38: 0 | BD38: 0 | BJ38: 0 | BK38: 0 | BQ38: 0 | BR38: 0 | BX38: 0 | BY38: 0
B39: 2.5 | C39: lt002_instrument | D39: GRSS_CMMSSN_INCM_OFF_BLNC | E39: Neyond | F39: =SUMIFS('Detalhe Testes'!$F:$F,'Detalhe Testes'!$B:$B,'MacroPlano Equipa'!C39,'Detalhe Testes'!$C:$C,'MacroPlano Equipa'!D39) -> 5 | G39: =F39/8 -> 0.625 | H39: {=SUMPRODUCT((COLUMN(O39:BY39)>=MIN(IF(O39:BY39<>"",COLUMN(O39:BY39))))*($O$16:$BY$16<=TODAY())*(O39:BY39))} -> 5 | I39: =H39/8 -> 0.625 | M39: =SUM(O39:BY39)-F39 -> 0 | T39: 0 | U39: 0 | Z39: 2 | AA39: 0 | AB39: 0 | AC39: 3 | AH39: 0 | AI39: 0 | AO39: 0 | AP39: 0 | AV39: 0 | AW39: 0 | BC39: 0 | BD39: 0 | BJ39: 0 | BK39: 0 | BQ39: 0 | BR39: 0 | BX39: 0 | BY39: 0
B40: 2.6 | C40: lt002_instrument | D40: GRSS_CMMSSN_EXPNS_OFF_BLNC | E40: Neyond | F40: =SUMIFS('Detalhe Testes'!$F:$F,'Detalhe Testes'!$B:$B,'MacroPlano Equipa'!C40,'Detalhe Testes'!$C:$C,'MacroPlano Equipa'!D40) -> 5 | G40: =F40/8 -> 0.625 | H40: {=SUMPRODUCT((COLUMN(O40:BY40)>=MIN(IF(O40:BY40<>"",COLUMN(O40:BY40))))*($O$16:$BY$16<=TODAY())*(O40:BY40))} -> 5 | I40: =H40/8 -> 0.625 | M40: =SUM(O40:BY40)-F40 -> 0 | T40: 0 | U40: 0 | AA40: 0 | AB40: 0 | AC40: 5 | AH40: 0 | AI40: 0 | AO40: 0 | AP40: 0 | AV40: 0 | AW40: 0 | BC40: 0 | BD40: 0 | BJ40: 0 | BK40: 0 | BQ40: 0 | BR40: 0 | BX40: 0 | BY40: 0
B41: 2.7 | C41: lt004_protection | D41: UNIVERSO | E41: Neyond | F41: =SUMIFS('Detalhe Testes'!$F:$F,'Detalhe Testes'!$B:$B,'MacroPlano Equipa'!C41,'Detalhe Testes'!$C:$C,'MacroPlano Equipa'!D41) -> 6 | G41: =F41/8 -> 0.75 | H41: {=SUMPRODUCT((COLUMN(O41:BY41)>=MIN(IF(O41:BY41<>"",COLUMN(O41:BY41))))*($O$16:$BY$16<=TODAY())*(O41:BY41))} -> 6.5 | I41: =H41/8 -> 0.8125 | M41: =SUM(O41:BY41)-F41 -> 0.5 | Q41: 0.5 | T41: 0 | U41: 0 | X41: 6 | AA41: 0 | AB41: 0 | AH41: 0 | AI41: 0 | AO41: 0 | AP41: 0 | AV41: 0 | AW41: 0 | BC41: 0 | BD41: 0 | BJ41: 0 | BK41: 0 | BQ41: 0 | BR41: 0 | BX41: 0 | BY41: 0
B42: 2.8 | C42: lt004_protection | D42: TYP_VHCL | E42: Neyond | F42: =SUMIFS('Detalhe Testes'!$F:$F,'Detalhe Testes'!$B:$B,'MacroPlano Equipa'!C42,'Detalhe Testes'!$C:$C,'MacroPlano Equipa'!D42) -> 9 | G42: =F42/8 -> 1.125 | H42: {=SUMPRODUCT((COLUMN(O42:BY42)>=MIN(IF(O42:BY42<>"",COLUMN(O42:BY42))))*($O$16:$BY$16<=TODAY())*(O42:BY42))} -> 10 | I42: =H42/8 -> 1.25 | M42: =SUM(O42:BY42)-F42 -> 1 | Q42: 1 | T42: 0 | U42: 0 | X42: 2 | Y42: 7 | AA42: 0 | AB42: 0 | AH42: 0 | AI42: 0 | AO42: 0 | AP42: 0 | AV42: 0 | AW42: 0 | BC42: 0 | BD42: 0 | BJ42: 0 | BK42: 0 | BQ42: 0 | BR42: 0 | BX42: 0 | BY42: 0
B43: 2.9 | C43: lt007_instr_activity | D43: UNIVERSO | E43: Neyond | F43: =SUMIFS('Detalhe Testes'!$F:$F,'Detalhe Testes'!$B:$B,'MacroPlano Equipa'!C43,'Detalhe Testes'!$C:$C,'MacroPlano Equipa'!D43) -> 16 | G43: =F43/8 -> 2 | H43: {=SUMPRODUCT((COLUMN(O43:BY43)>=MIN(IF(O43:BY43<>"",COLUMN(O43:BY43))))*($O$16:$BY$16<=TODAY())*(O43:BY43))} -> 16 | I43: =H43/8 -> 2 | M43: =SUM(O43:BY43)-F43 -> 0 | T43: 0 | U43: 0 | AH43: 0 | AI43: 0 | AO43: 0 | AP43: 0 | AV43: 0 | AW43: 0 | AZ43: 3 | BB43: 8 | BC43: 0 | BD43: 0 | BE43: 5 | BJ43: 0 | BK43: 0 | BQ43: 0 | BR43: 0 | BX43: 0 | BY43: 0
B44: 2.10 | C44: lt007_instr_activity | D44: PRCNTG_ACTVTY | E44: Neyond | F44: =SUMIFS('Detalhe Testes'!$F:$F,'Detalhe Testes'!$B:$B,'MacroPlano Equipa'!C44,'Detalhe Testes'!$C:$C,'MacroPlano Equipa'!D44) -> 11 | G44: =F44/8 -> 1.375 | H44: {=SUMPRODUCT((COLUMN(O44:BY44)>=MIN(IF(O44:BY44<>"",COLUMN(O44:BY44))))*($O$16:$BY$16<=TODAY())*(O44:BY44))} -> 11 | I44: =H44/8 -> 1.375 | M44: =SUM(O44:BY44)-F44 -> 0 | T44: 0 | U44: 0 | AH44: 0 | AI44: 0 | AO44: 0 | AP44: 0 | AV44: 0 | AW44: 0 | BC44: 0 | BD44: 0 | BF44: 2 | BG44: 8 | BH44: 1 | BJ44: 0 | BK44: 0 | BQ44: 0 | BR44: 0 | BX44: 0 | BY44: 0
B45: 2.11 | C45: lt007_instr_activity | D45: SSTNBL_CTGRY | E45: Neyond | F45: =SUMIFS('Detalhe Testes'!$F:$F,'Detalhe Testes'!$B:$B,'MacroPlano Equipa'!C45,'Detalhe Testes'!$C:$C,'MacroPlano Equipa'!D45) -> 9 | G45: =F45/8 -> 1.125 | H45: {=SUMPRODUCT((COLUMN(O45:BY45)>=MIN(IF(O45:BY45<>"",COLUMN(O45:BY45))))*($O$16:$BY$16<=TODAY())*(O45:BY45))} -> 9 | I45: =H45/8 -> 1.125 | M45: =SUM(O45:BY45)-F45 -> 0 | T45: 0 | U45: 0 | AH45: 0 | AI45: 0 | AO45: 0 | AP45: 0 | AV45: 0 | AW45: 0 | BC45: 0 | BD45: 0 | BH45: 7 | BI45: 2 | BJ45: 0 | BK45: 0 | BQ45: 0 | BR45: 0 | BX45: 0 | BY45: 0
B46: 2.12 | C46: lt007_instr_activity | D46: COD_SOC | E46: Neyond | F46: =SUMIFS('Detalhe Testes'!$F:$F,'Detalhe Testes'!$B:$B,'MacroPlano Equipa'!C46,'Detalhe Testes'!$C:$C,'MacroPlano Equipa'!D46) -> 3 | G46: =F46/8 -> 0.375 | H46: {=SUMPRODUCT((COLUMN(O46:BY46)>=MIN(IF(O46:BY46<>"",COLUMN(O46:BY46))))*($O$16:$BY$16<=TODAY())*(O46:BY46))} -> 3 | I46: =H46/8 -> 0.375 | M46: =SUM(O46:BY46)-F46 -> 0 | T46: 0 | U46: 0 | AH46: 0 | AI46: 0 | AO46: 0 | AP46: 0 | AV46: 0 | AW46: 0 | BC46: 0 | BD46: 0 | BF46: 3 | BJ46: 0 | BK46: 0 | BQ46: 0 | BR46: 0 | BX46: 0 | BY46: 0
B47: 2.13 | C47: lt007_instr_activity | D47: DT_RFRNC | E47: Neyond | F47: =SUMIFS('Detalhe Testes'!$F:$F,'Detalhe Testes'!$B:$B,'MacroPlano Equipa'!C47,'Detalhe Testes'!$C:$C,'MacroPlano Equipa'!D47) -> 3 | G47: =F47/8 -> 0.375 | H47: {=SUMPRODUCT((COLUMN(O47:BY47)>=MIN(IF(O47:BY47<>"",COLUMN(O47:BY47))))*($O$16:$BY$16<=TODAY())*(O47:BY47))} -> 3 | I47: =H47/8 -> 0.375 | M47: =SUM(O47:BY47)-F47 -> 0 | T47: 0 | U47: 0 | AH47: 0 | AI47: 0 | AO47: 0 | AP47: 0 | AV47: 0 | AW47: 0 | BC47: 0 | BD47: 0 | BF47: 3 | BJ47: 0 | BK47: 0 | BQ47: 0 | BR47: 0 | BX47: 0 | BY47: 0
...

Sheet Detalhe Entregas e Status
I7: Entrega IT | Q7: Re-testes
B8: Tabela | C8: Campo | D8: Concat | E8: Structural | F8: Green Dashboard | G8: Pillar III ESG | H8: Entrega Neyond | I8: Data Prevista | J8: Data Real | K8: Atraso (em dias) | M8: # Incidências | N8: Re-especificação Neyond | O8: Correção IT | Q8: Dt c/ Pedido Correção | R8: Dt Prevista Correção | S8: Dt c/ Novo Pedido Correção | T8: Comentários | V8: Status Atual | W8: Status Anterior
B9: lt002_instrument | C9: UNIVERSO | D9: =_xlfn.CONCAT(B9,C9) -> lt002_instrumentUNIVERSO | E9: - | F9: - | G9: - | H9: Package 1 | I9: 45782 | J9: 45782 | K9: =+IF(J9="","N/A",J9-I9) -> 0 | M9: =SUMIFS('Detalhe Testes'!$H:$H,'Detalhe Testes'!$B:$B,'Detalhe Entregas e Status'!B9,'Detalhe Testes'!$C:$C,'Detalhe Entregas e Status'!C9) -> #N/A | N9: Não | O9: Sim | Q9: 45814 | R9: 45849 | T9: Enviadas incidências no dia 15/jul | V9: 4. Em Correção | W9: 4. Em Correção
B10: lt002_instrument | C10: AVRG_BLNC | D10: =_xlfn.CONCAT(B10,C10) -> lt002_instrumentAVRG_BLNC | E10: N | F10: Y | G10: N | H10: Package 4 | I10: 45796 | J10: 45796 | K10: =+IF(J10="","N/A",J10-I10) -> 0 | M10: =SUMIFS('Detalhe Testes'!$H:$H,'Detalhe Testes'!$B:$B,'Detalhe Entregas e Status'!B10,'Detalhe Testes'!$C:$C,'Detalhe Entregas e Status'!C10) -> #N/A | N10: Sim | O10: Sim | Q10: 45803 | R10: 45846 | V10: 5. Em Re-teste | W10: 5. Em Re-teste
A11: x | B11: lt002_instrument | C11: NW_BSNSS | D11: =_xlfn.CONCAT(B11,C11) -> lt002_instrumentNW_BSNSS | E11: N | F11: Y | G11: Y | H11: Package 5 | I11: 45782 | J11: 45782 | K11: =+IF(J11="","N/A",J11-I11) -> 0 | M11: =SUMIFS('Detalhe Testes'!$H:$H,'Detalhe Testes'!$B:$B,'Detalhe Entregas e Status'!B11,'Detalhe Testes'!$C:$C,'Detalhe Entregas e Status'!C11) -> #N/A | R11: 45849 | T11: nok | V11: 5. Em Re-teste | W11: 5. Em Re-teste
A12: x | B12: lt002_instrument | C12: GRSS_INTRST_INCM | D12: =_xlfn.CONCAT(B12,C12) -> lt002_instrumentGRSS_INTRST_INCM | E12: N | F12: Y | G12: Y | H12: Package 4 | I12: 45789 | J12: 45789 | K12: =+IF(J12="","N/A",J12-I12) -> 0 | M12: =SUMIFS('Detalhe Testes'!$H:$H,'Detalhe Testes'!$B:$B,'Detalhe Entregas e Status'!B12,'Detalhe Testes'!$C:$C,'Detalhe Entregas e Status'!C12) -> #N/A | N12: Sim | O12: Sim | Q12: 45803 | R12: 45849 | T12: nok | V12: 5. Em Re-teste | W12: 5. Em Re-teste
A13: x | B13: lt002_instrument | C13: GRSS_CMMSSN_INCM | D13: =_xlfn.CONCAT(B13,C13) -> lt002_instrumentGRSS_CMMSSN_INCM | E13: N | F13: Y | G13: Y | H13: Package 4 | I13: 45789 | J13: 45789 | K13: =+IF(J13="","N/A",J13-I13) -> 0 | M13: =SUMIFS('Detalhe Testes'!$H:$H,'Detalhe Testes'!$B:$B,'Detalhe Entregas e Status'!B13,'Detalhe Testes'!$C:$C,'Detalhe Entregas e Status'!C13) -> #N/A | N13: Sim | O13: Sim | Q13: 45803 | R13: 45849 | T13: nok | V13: 5. Em Re-teste | W13: 5. Em Re-teste
B14: lt002_instrument | C14: INTRNL_TRNSFR_RT | D14: =_xlfn.CONCAT(B14,C14) -> lt002_instrumentINTRNL_TRNSFR_RT | E14: N | F14: Y | G14: N | H14: Package 1 | I14: 45796 | J14: 45796 | K14: =+IF(J14="","N/A",J14-I14) -> 0 | M14: =SUMIFS('Detalhe Testes'!$H:$H,'Detalhe Testes'!$B:$B,'Detalhe Entregas e Status'!B14,'Detalhe Testes'!$C:$C,'Detalhe Entregas e Status'!C14) -> #N/A | N14: Sim | O14: Sim | Q14: 45803 | R14: 45849 | T14: nok | V14: 5. Em Re-teste | W14: 5. Em Re-teste
B15: lt002_instrument | C15: NT_LN_LSS_PRVSN | D15: =_xlfn.CONCAT(B15,C15) -> lt002_instrumentNT_LN_LSS_PRVSN | E15: N | F15: Y | G15: N | H15: Package 4 | I15: 45796 | J15: 45796 | K15: =+IF(J15="","N/A",J15-I15) -> 0 | M15: =SUMIFS('Detalhe Testes'!$H:$H,'Detalhe Testes'!$B:$B,'Detalhe Entregas e Status'!B15,'Detalhe Testes'!$C:$C,'Detalhe Entregas e Status'!C15) -> #N/A | N15: Sim | O15: Sim | Q15: 45803 | R15: 45854 | V15: 5. Em Re-teste | W15: 5. Em Re-teste
B16: lt002_instrument | C16: BSNSS_AREA | D16: =_xlfn.CONCAT(B16,C16) -> lt002_instrumentBSNSS_AREA | E16: N | F16: Y | G16: N | H16: Package 5 | I16: 45803 | J16: 45803 | K16: =+IF(J16="","N/A",J16-I16) -> 0 | M16: =SUMIFS('Detalhe Testes'!$H:$H,'Detalhe Testes'!$B:$B,'Detalhe Entregas e Status'!B16,'Detalhe Testes'!$C:$C,'Detalhe Entregas e Status'!C16) -> #N/A | Q16: 45833 | R16: 45849 | T16: nok | V16: 4. Em Correção | W16: 4. Em Correção
B17: lt002_instrument | C17: MNGMNT_PRDCT | D17: =_xlfn.CONCAT(B17,C17) -> lt002_instrumentMNGMNT_PRDCT | E17: N | F17: Y | G17: N | H17: Package 1 | I17: 45796 | J17: 45796 | K17: =+IF(J17="","N/A",J17-I17) -> 0 | M17: =SUMIFS('Detalhe Testes'!$H:$H,'Detalhe Testes'!$B:$B,'Detalhe Entregas e Status'!B17,'Detalhe Testes'!$C:$C,'Detalhe Entregas e Status'!C17) -> #N/A | Q17: 45833 | R17: 45849 | T17: 60 NOK devido a diferenças na BA | V17: 1. Concluído | W17: 1. Concluído
B18: lt002_instrument | C18: GRSS_CMMSSN_EXPNS | D18: =_xlfn.CONCAT(B18,C18) -> lt002_instrumentGRSS_CMMSSN_EXPNS | E18: N | F18: Y | G18: N | H18: Package 4 | I18: 45789 | J18: 45789 | K18: =+IF(J18="","N/A",J18-I18) -> 0 | M18: =SUMIFS('Detalhe Testes'!$H:$H,'Detalhe Testes'!$B:$B,'Detalhe Entregas e Status'!B18,'Detalhe Testes'!$C:$C,'Detalhe Entregas e Status'!C18) -> #N/A | N18: Sim | O18: Sim | Q18: 45803 | R18: 45849 | T18: nok | V18: 5. Em Re-teste | W18: 5. Em Re-teste
B19: lt002_instrument | C19: GNS_FNNCL_TRNSCTN_EXCHNG_DFFRNCS | D19: =_xlfn.CONCAT(B19,C19) -> lt002_instrumentGNS_FNNCL_TRNSCTN_EXCHNG_DFFRNCS | E19: N | F19: Y | G19: N | H19: Package 4 | I19: 45796 | J19: 45796 | K19: =+IF(J19="","N/A",J19-I19) -> 0 | M19: =SUMIFS('Detalhe Testes'!$H:$H,'Detalhe Testes'!$B:$B,'Detalhe Entregas e Status'!B19,'Detalhe Testes'!$C:$C,'Detalhe Entregas e Status'!C19) -> #N/A | N19: Sim | O19: Sim | Q19: 45803 | R19: 18/jun e 26/jun | V19: 1. Concluído | W19: 1. Concluído
B20: lt002_instrument | C20: FLG_INTRBSNSS | D20: =_xlfn.CONCAT(B20,C20) -> lt002_instrumentFLG_INTRBSNSS | E20: N | F20: Y | G20: N | H20: Package 1 | I20: 45796 | J20: 45796 | K20: =+IF(J20="","N/A",J20-I20) -> 0 | M20: =SUMIFS('Detalhe Testes'!$H:$H,'Detalhe Testes'!$B:$B,'Detalhe Entregas e Status'!B20,'Detalhe Testes'!$C:$C,'Detalhe Entregas e Status'!C20) -> #N/A | N20: Não | O20: Sim | Q20: 45804 | R20: 45854 | V20: 5. Em Re-teste | W20: 5. Em Re-teste
B21: lt002_instrument | C21: INTRBSNSS_ADJ_COD | D21: =_xlfn.CONCAT(B21,C21) -> lt002_instrumentINTRBSNSS_ADJ_COD | E21: N | F21: Y | G21: N | H21: Package 1 | I21: 45796 | J21: 45796 | K21: =+IF(J21="","N/A",J21-I21) -> 0 | M21: =SUMIFS('Detalhe Testes'!$H:$H,'Detalhe Testes'!$B:$B,'Detalhe Entregas e Status'!B21,'Detalhe Testes'!$C:$C,'Detalhe Entregas e Status'!C21) -> #N/A | V21: 1. Concluído | W21: 1. Concluído
B22: lt002_instrument | C22: COD_SOC_DSTNTN | D22: =_xlfn.CONCAT(B22,C22) -> lt002_instrumentCOD_SOC_DSTNTN | E22: N | F22: Y | G22: N | H22: Package 1 | I22: 45796 | J22: 45796 | K22: =+IF(J22="","N/A",J22-I22) -> 0 | M22: =SUMIFS('Detalhe Testes'!$H:$H,'Detalhe Testes'!$B:$B,'Detalhe Entregas e Status'!B22,'Detalhe Testes'!$C:$C,'Detalhe Entregas e Status'!C22) -> #N/A | V22: 1. Concluído | W22: 1. Concluído
B23: lt002_instrument | C23: BSNSS_AREA_DSTNTN | D23: =_xlfn.CONCAT(B23,C23) -> lt002_instrumentBSNSS_AREA_DSTNTN | E23: N | F23: Y | G23: N | H23: Package 1 | I23: 45796 | J23: 45796 | K23: =+IF(J23="","N/A",J23-I23) -> 0 | M23: =SUMIFS('Detalhe Testes'!$H:$H,'Detalhe Testes'!$B:$B,'Detalhe Entregas e Status'!B23,'Detalhe Testes'!$C:$C,'Detalhe Entregas e Status'!C23) -> #N/A | V23: 1. Concluído | W23: 1. Concluído
B24: lt002_instrument | C24: AVRG_BLNC_OFF_BLNC | D24: =_xlfn.CONCAT(B24,C24) -> lt002_instrumentAVRG_BLNC_OFF_BLNC | E24: N | F24: Y | G24: N | H24: Package 4 | I24: 45789 | J24: 45789 | K24: =+IF(J24="","N/A",J24-I24) -> 0 | M24: =SUMIFS('Detalhe Testes'!$H:$H,'Detalhe Testes'!$B:$B,'Detalhe Entregas e Status'!B24,'Detalhe Testes'!$C:$C,'Detalhe Entregas e Status'!C24) -> #N/A | N24: Sim | O24: Sim | Q24: 45803 | R24: 45846 | V24: 5. Em Re-teste | W24: 5. Em Re-teste
B25: lt002_instrument | C25: INTRNL_TRNSFR_RT_OFF_BLNC | D25: =_xlfn.CONCAT(B25,C25) -> lt002_instrumentINTRNL_TRNSFR_RT_OFF_BLNC | E25: N | F25: Y | G25: N | H25: Package 1 | I25: 45796 | J25: 45796 | K25: =+IF(J25="","N/A",J25-I25) -> 0 | M25: =SUMIFS('Detalhe Testes'!$H:$H,'Detalhe Testes'!$B:$B,'Detalhe Entregas e Status'!B25,'Detalhe Testes'!$C:$C,'Detalhe Entregas e Status'!C25) -> #N/A | V25: 1. Concluído | W25: 1. Concluído
A26: x | B26: lt002_instrument | C26: GRSS_CMMSSN_INCM_OFF_BLNC | D26: =_xlfn.CONCAT(B26,C26) -> lt002_instrumentGRSS_CMMSSN_INCM_OFF_BLNC | E26: N | F26: Y | G26: Y | H26: Package 4 | I26: 45789 | J26: 45789 | K26: =+IF(J26="","N/A",J26-I26) -> 0 | M26: =SUMIFS('Detalhe Testes'!$H:$H,'Detalhe Testes'!$B:$B,'Detalhe Entregas e Status'!B26,'Detalhe Testes'!$C:$C,'Detalhe Entregas e Status'!C26) -> #N/A | N26: Sim | O26: Sim | Q26: 45803 | R26: 45849 | T26: nok | V26: 5. Em Re-teste | W26: 5. Em Re-teste
B27: lt002_instrument | C27: GRSS_CMMSSN_EXPNS_OFF_BLNC | D27: =_xlfn.CONCAT(B27,C27) -> lt002_instrumentGRSS_CMMSSN_EXPNS_OFF_BLNC | E27: N | F27: Y | G27: N | H27: Package 4 | I27: 45789 | J27: 45789 | K27: =+IF(J27="","N/A",J27-I27) -> 0 | M27: =SUMIFS('Detalhe Testes'!$H:$H,'Detalhe Testes'!$B:$B,'Detalhe Entregas e Status'!B27,'Detalhe Testes'!$C:$C,'Detalhe Entregas e Status'!C27) -> #N/A | N27: Sim | O27: Sim | Q27: 45803 | R27: 45849 | T27: ok para univ comum | V27: 1. Concluído | W27: 1. Concluído
B28: lt002_instrument | C28: RWA_OFF_BLNC | D28: =_xlfn.CONCAT(B28,C28) -> lt002_instrumentRWA_OFF_BLNC | E28: N | F28: Y | G28: N | H28: Package 1 | I28: 45803 | J28: 45803 | K28: =+IF(J28="","N/A",J28-I28) -> 0 | M28: =SUMIFS('Detalhe Testes'!$H:$H,'Detalhe Testes'!$B:$B,'Detalhe Entregas e Status'!B28,'Detalhe Testes'!$C:$C,'Detalhe Entregas e Status'!C28) -> #N/A | Q28: 45833 | R28: 45849 | T28: ok para univ comum | V28: 1. Concluído | W28: 1. Concluído
B29: lt002_instrument | C29: GRSS_INTRST_EXPNS | D29: =_xlfn.CONCAT(B29,C29) -> lt002_instrumentGRSS_INTRST_EXPNS | E29: N | F29: Y | G29: N | H29: Package 4 | I29: 45796 | J29: 45796 | K29: =+IF(J29="","N/A",J29-I29) -> 0 | M29: =SUMIFS('Detalhe Testes'!$H:$H,'Detalhe Testes'!$B:$B,'Detalhe Entregas e Status'!B29,'Detalhe Testes'!$C:$C,'Detalhe Entregas e Status'!C29) -> #N/A | N29: Sim | O29: Sim | Q29: 45803 | R29: 18/jun e 26/jun | V29: 1. Concluído | W29: 1. Concluído
B30: lt002_instrument | C30: NT_LN_LSS_PRVSN_OFF_BLNC | D30: =_xlfn.CONCAT(B30,C30) -> lt002_instrumentNT_LN_LSS_PRVSN_OFF_BLNC | E30: N | F30: Y | G30: N | H30: Package 4 | I30: 45803 | J30: 45803 | K30: =+IF(J30="","N/A",J30-I30) -> 0 | M30: =SUMIFS('Detalhe Testes'!$H:$H,'Detalhe Testes'!$B:$B,'Detalhe Entregas e Status'!B30,'Detalhe Testes'!$C:$C,'Detalhe Entregas e Status'!C30) -> #N/A | N30: Sim | O30: Sim | Q30: 45803 | R30: 45854 | V30: 5. Em Re-teste | W30: 5. Em Re-teste
B31: lt002_instrument | C31: GRSS_INTRST_INCM_CCRR | D31: =_xlfn.CONCAT(B31,C31) -> lt002_instrumentGRSS_INTRST_INCM_CCRR | E31: N | F31: Y | G31: N | H31: Package 4 | I31: 45782 | J31: 45782 | K31: =+IF(J31="","N/A",J31-I31) -> 0 | M31: =SUMIFS('Detalhe Testes'!$H:$H,'Detalhe Testes'!$B:$B,'Detalhe Entregas e Status'!B31,'Detalhe Testes'!$C:$C,'Detalhe Entregas e Status'!C31) -> #N/A | V31: 1. Concluído | W31: 1. Concluído
B32: lt002_instrument | C32: GRSS_INTRST_EXPNS_CCRR | D32: =_xlfn.CONCAT(B32,C32) -> lt002_instrumentGRSS_INTRST_EXPNS_CCRR | E32: N | F32: Y | G32: N | H32: Package 4 | I32: 45782 | J32: 45782 | K32: =+IF(J32="","N/A",J32-I32) -> 0 | M32: =SUMIFS('Detalhe Testes'!$H:$H,'Detalhe Testes'!$B:$B,'Detalhe Entregas e Status'!B32,'Detalhe Testes'!$C:$C,'Detalhe Entregas e Status'!C32) -> #N/A | V32: 1. Concluído | W32: 1. Concluído
B33: lt002_instrument | C33: GRSS_CMMSSN_INCM_CCRR | D33: =_xlfn.CONCAT(B33,C33) -> lt002_instrumentGRSS_CMMSSN_INCM_CCRR | E33: N | F33: Y | G33: N | H33: Package 4 | I33: 45782 | J33: 45782 | K33: =+IF(J33="","N/A",J33-I33) -> 0 | M33: =SUMIFS('Detalhe Testes'!$H:$H,'Detalhe Testes'!$B:$B,'Detalhe Entregas e Status'!B33,'Detalhe Testes'!$C:$C,'Detalhe Entregas e Status'!C33) -> #N/A | V33: 1. Concluído | W33: 1. Concluído
B34: lt002_instrument | C34: GRSS_CMMSSN_EXPNS_CCRR | D34: =_xlfn.CONCAT(B34,C34) -> lt002_instrumentGRSS_CMMSSN_EXPNS_CCRR | E34: N | F34: Y | G34: N | H34: Package 4 | I34: 45782 | J34: 45782 | K34: =+IF(J34="","N/A",J34-I34) -> 0 | M34: =SUMIFS('Detalhe Testes'!$H:$H,'Detalhe Testes'!$B:$B,'Detalhe Entregas e Status'!B34,'Detalhe Testes'!$C:$C,'Detalhe Entregas e Status'!C34) -> #N/A | V34: 1. Concluído | W34: 1. Concluído
B35: lt002_instrument | C35: GNS_FNNCL_TRNSCTN_EXCHNG_CCRR | D35: =_xlfn.CONCAT(B35,C35) -> lt002_instrumentGNS_FNNCL_TRNSCTN_EXCHNG_CCRR | E35: N | F35: Y | G35: N | H35: Package 4 | I35: 45782 | J35: 45782 | K35: =+IF(J35="","N/A",J35-I35) -> 0 | M35: =SUMIFS('Detalhe Testes'!$H:$H,'Detalhe Testes'!$B:$B,'Detalhe Entregas e Status'!B35,'Detalhe Testes'!$C:$C,'Detalhe Entregas e Status'!C35) -> #N/A | V35: 1. Concluído | W35: 1. Concluído
B36: lt002_instrument | C36: BSNSS_AREA_CCRR | D36: =_xlfn.CONCAT(B36,C36) -> lt002_instrumentBSNSS_AREA_CCRR | E36: N | F36: Y | G36: N | H36: Package 4 | I36: 45782 | J36: 45782 | K36: =+IF(J36="","N/A",J36-I36) -> 0 | M36: =SUMIFS('Detalhe Testes'!$H:$H,'Detalhe Testes'!$B:$B,'Detalhe Entregas e Status'!B36,'Detalhe Testes'!$C:$C,'Detalhe Entregas e Status'!C36) -> #N/A | N36: Não | O36: Sim | Q36: 45825 | V36: 1. Concluído | W36: 1. Concluído
B37: lt002_instrument | C37: GRSS_CMMSSN_INCM_OFF_BLNC_CCRR | D37: =_xlfn.CONCAT(B37,C37) -> lt002_instrumentGRSS_CMMSSN_INCM_OFF_BLNC_CCRR | E37: N | F37: Y | G37: N | H37: Package 4 | I37: 45782 | J37: 45782 | K37: =+IF(J37="","N/A",J37-I37) -> 0 | M37: =SUMIFS('Detalhe Testes'!$H:$H,'Detalhe Testes'!$B:$B,'Detalhe Entregas e Status'!B37,'Detalhe Testes'!$C:$C,'Detalhe Entregas e Status'!C37) -> #N/A | V37: 1. Concluído | W37: 1. Concluído
B38: lt002_instrument | C38: GRSS_CMMSSN_EXPNS_OFF_BLNC_CCRR | D38: =_xlfn.CONCAT(B38,C38) -> lt002_instrumentGRSS_CMMSSN_EXPNS_OFF_BLNC_CCRR | E38: N | F38: Y | G38: N | H38: Package 4 | I38: 45782 | J38: 45782 | K38: =+IF(J38="","N/A",J38-I38) -> 0 | M38: =SUMIFS('Detalhe Testes'!$H:$H,'Detalhe Testes'!$B:$B,'Detalhe Entregas e Status'!B38,'Detalhe Testes'!$C:$C,'Detalhe Entregas e Status'!C38) -> #N/A | V38: 1. Concluído | W38: 1. Concluído
B39: lt002_instrument | C39: CCF | D39: =_xlfn.CONCAT(B39,C39) -> lt002_instrumentCCF | E39: Y | F39: Y | G39: N | H39: Package 2 | I39: 45803 | J39: 45803 | K39: =+IF(J39="","N/A",J39-I39) -> 0 | M39: =SUMIFS('Detalhe Testes'!$H:$H,'Detalhe Testes'!$B:$B,'Detalhe Entregas e Status'!B39,'Detalhe Testes'!$C:$C,'Detalhe Entregas e Status'!C39) -> #N/A | N39: Não | O39: Sim | Q39: 45814 | R39: 45846 | V39: 1. Concluído | W39: 1. Concluído
B40: lt002_instrument | C40: EAD | D40: =_xlfn.CONCAT(B40,C40) -> lt002_instrumentEAD | E40: Y | F40: Y | G40: N | H40: Package 2 | I40: 45810 | J40: 45810 | K40: =+IF(J40="","N/A",J40-I40) -> 0 | M40: =SUMIFS('Detalhe Testes'!$H:$H,'Detalhe Testes'!$B:$B,'Detalhe Entregas e Status'!B40,'Detalhe Testes'!$C:$C,'Detalhe Entregas e Status'!C40) -> #N/A | N40: Não | O40: Sim | Q40: 45814 | R40: 45846 | V40: 1. Concluído | W40: 1. Concluído
B41: lt002_instrument | C41: TYP_OFF_BLNC_PRDCT | D41: =_xlfn.CONCAT(B41,C41) -> lt002_instrumentTYP_OFF_BLNC_PRDCT | E41: Y | F41: Y | G41: Y | H41: Package 2 | I41: 45810 | J41: 45810 | K41: =+IF(J41="","N/A",J41-I41) -> 0 | M41: =SUMIFS('Detalhe Testes'!$H:$H,'Detalhe Testes'!$B:$B,'Detalhe Entregas e Status'!B41,'Detalhe Testes'!$C:$C,'Detalhe Entregas e Status'!C41) -> #N/A | Q41: 45841 | R41: 45854 | V41: 5. Em Re-teste | W41: 5. Em Re-teste
B42: lt002_instrument | C42: COD_SOC | D42: =_xlfn.CONCAT(B42,C42) -> lt002_instrumentCOD_SOC | E42: Y | F42: Y | G42: Y | H42: Package 2 | I42: 45803 | J42: 45803 | K42: =+IF(J42="","N/A",J42-I42) -> 0 | M42: =SUMIFS('Detalhe Testes'!$H:$H,'Detalhe Testes'!$B:$B,'Detalhe Entregas e Status'!B42,'Detalhe Testes'!$C:$C,'Detalhe Entregas e Status'!C42) -> #N/A | V42: 1. Concluído | W42: 1. Concluído
B43: lt002_instrument | C43: SUBPORTFOLIO_ID | D43: =_xlfn.CONCAT(B43,C43) -> lt002_instrumentSUBPORTFOLIO_ID | E43: Y | F43: Y | G43: Y | H43: Package 2 | I43: 45803 | J43: 45803 | K43: =+IF(J43="","N/A",J43-I43) -> 0 | M43: =SUMIFS('Detalhe Testes'!$H:$H,'Detalhe Testes'!$B:$B,'Detalhe Entregas e Status'!B43,'Detalhe Testes'!$C:$C,'Detalhe Entregas e Status'!C43) -> #N/A | Q43: 45841 | R43: 45854 | V43: 5. Em Re-teste | W43: 5. Em Re-teste
B44: lt002_instrument | C44: DT_RFRNC | D44: =_xlfn.CONCAT(B44,C44) -> lt002_instrumentDT_RFRNC | E44: Y | F44: Y | G44: Y | H44: Package 2 | I44: 45782 | J44: 45782 | K44: =+IF(J44="","N/A",J44-I44) -> 0 | M44: =SUMIFS('Detalhe Testes'!$H:$H,'Detalhe Testes'!$B:$B,'Detalhe Entregas e Status'!B44,'Detalhe Testes'!$C:$C,'Detalhe Entregas e Status'!C44) -> #N/A | V44: 1. Concluído | W44: 1. Concluído
B45: lt002_instrument | C45: DFLT_STTS_INSTRMNT | D45: =_xlfn.CONCAT(B45,C45) -> lt002_instrumentDFLT_STTS_INSTRMNT | E45: Y | F45: Y | G45: Y | H45: Package 2 | I45: 45803 | J45: 45803 | K45: =+IF(J45="","N/A",J45-I45) -> 0 | M45: =SUMIFS('Detalhe Testes'!$H:$H,'Detalhe Testes'!$B:$B,'Detalhe Entregas e Status'!B45,'Detalhe Testes'!$C:$C,'Detalhe Entregas e Status'!C45) -> #N/A | Q45: 45841 | R45: 45849 | V45: 5. Em Re-teste | W45: 5. Em Re-teste
B46: lt002_instrument | C46: IMPRMNT_STTS | D46: =_xlfn.CONCAT(B46,C46) -> lt002_instrumentIMPRMNT_STTS | E46: Y | F46: Y | G46: Y | H46: Package 2 | I46: 45803 | J46: 45803 | K46: =+IF(J46="","N/A",J46-I46) -> 0 | M46: =SUMIFS('Detalhe Testes'!$H:$H,'Detalhe Testes'!$B:$B,'Detalhe Entregas e Status'!B46,'Detalhe Testes'!$C:$C,'Detalhe Entregas e Status'!C46) -> #N/A | N46: Não | O46: Sim | Q46: 45814 | R46: 45846 | V46: 1. Concluído | W46: 1. Concluído
...

Sheet Detalhe Testes
H7: REVER FORMULA | K7: Tracking da evolução do # incidências (Data das entregas de IT)
B8: Tabela | C8: Campo | D8: Tipologia de Teste | E8: Complexidade | F8: Horas Estimadas | H8: # Incidências | I8: Notas | K8: Dts Anteriores | L8: 45846 | M8: 45849 | N8: 45854
B9: lt002_instrument | C9: UNIVERSO | D9: 1. Teste de universo | E9: Alta | F9: 16 | H9: {=IF(INDEX($K:$Z,ROW(C9),MATCH(IF(VLOOKUP(_xlfn.CONCAT(B9,C9),'Detalhe Entregas e Status'!$D$9:$J$81,7,0)=DATE(2025,5,5),DATE(2025,5,12),VLOOKUP(_xlfn.CONCAT(B9,C9),'Detalhe Entregas e Status'!$D$9:$J$81,7,0)),$L$8:$Z$8,0))="","",INDEX($K:$Z,ROW(C9),MATCH(IF(VLOOKUP(_xlfn.CONCAT(B9,C9),'Detalhe Entregas e Status'!$D$9:$J$81,7,0)=DATE(2025,5,5),DATE(2025,5,12),VLOOKUP(_xlfn.CONCAT(B9,C9),'Detalhe Entregas e Status'!$D$9:$J$81,7,0)),$L$8:$Z$8,0)))} -> #N/A | K9: NOK
B10: lt002_instrument | C10: AVRG_BLNC | D10: 3. Testes comparativos (Espec. VS Impl.) | E10: Média | F10: 4 | H10: {=IF(INDEX($K:$Z,ROW(C10),MATCH(IF(VLOOKUP(_xlfn.CONCAT(B10,C10),'Detalhe Entregas e Status'!$D$9:$J$81,7,0)=DATE(2025,5,5),DATE(2025,5,12),VLOOKUP(_xlfn.CONCAT(B10,C10),'Detalhe Entregas e Status'!$D$9:$J$81,7,0)),$L$8:$Z$8,0))="","",INDEX($K:$Z,ROW(C10),MATCH(IF(VLOOKUP(_xlfn.CONCAT(B10,C10),'Detalhe Entregas e Status'!$D$9:$J$81,7,0)=DATE(2025,5,5),DATE(2025,5,12),VLOOKUP(_xlfn.CONCAT(B10,C10),'Detalhe Entregas e Status'!$D$9:$J$81,7,0)),$L$8:$Z$8,0)))} -> #N/A | I10: Foi enviada uma nova especificação | K10: NOK | L10: NOK
B11: lt002_instrument | C11: AVRG_BLNC | D11: 6. Validação de formatos | E11: Baixa | F11: 1 | H11: {=IF(INDEX($K:$Z,ROW(C11),MATCH(IF(VLOOKUP(_xlfn.CONCAT(B11,C11),'Detalhe Entregas e Status'!$D$9:$J$81,7,0)=DATE(2025,5,5),DATE(2025,5,12),VLOOKUP(_xlfn.CONCAT(B11,C11),'Detalhe Entregas e Status'!$D$9:$J$81,7,0)),$L$8:$Z$8,0))="","",INDEX($K:$Z,ROW(C11),MATCH(IF(VLOOKUP(_xlfn.CONCAT(B11,C11),'Detalhe Entregas e Status'!$D$9:$J$81,7,0)=DATE(2025,5,5),DATE(2025,5,12),VLOOKUP(_xlfn.CONCAT(B11,C11),'Detalhe Entregas e Status'!$D$9:$J$81,7,0)),$L$8:$Z$8,0)))} -> #N/A | K11: NOK | L11: NOK
B12: lt002_instrument | C12: NW_BSNSS | D12: 3. Testes comparativos (Espec. VS Impl.) | E12: Média | F12: 4 | H12: {=IF(INDEX($K:$Z,ROW(C12),MATCH(IF(VLOOKUP(_xlfn.CONCAT(B12,C12),'Detalhe Entregas e Status'!$D$9:$J$81,7,0)=DATE(2025,5,5),DATE(2025,5,12),VLOOKUP(_xlfn.CONCAT(B12,C12),'Detalhe Entregas e Status'!$D$9:$J$81,7,0)),$L$8:$Z$8,0))="","",INDEX($K:$Z,ROW(C12),MATCH(IF(VLOOKUP(_xlfn.CONCAT(B12,C12),'Detalhe Entregas e Status'!$D$9:$J$81,7,0)=DATE(2025,5,5),DATE(2025,5,12),VLOOKUP(_xlfn.CONCAT(B12,C12),'Detalhe Entregas e Status'!$D$9:$J$81,7,0)),$L$8:$Z$8,0)))} -> #N/A | I12: Em teste | K12: NOK
B13: lt002_instrument | C13: NW_BSNSS | D13: 6. Validação de formatos | E13: Baixa | F13: 1 | H13: {=IF(INDEX($K:$Z,ROW(C13),MATCH(IF(VLOOKUP(_xlfn.CONCAT(B13,C13),'Detalhe Entregas e Status'!$D$9:$J$81,7,0)=DATE(2025,5,5),DATE(2025,5,12),VLOOKUP(_xlfn.CONCAT(B13,C13),'Detalhe Entregas e Status'!$D$9:$J$81,7,0)),$L$8:$Z$8,0))="","",INDEX($K:$Z,ROW(C13),MATCH(IF(VLOOKUP(_xlfn.CONCAT(B13,C13),'Detalhe Entregas e Status'!$D$9:$J$81,7,0)=DATE(2025,5,5),DATE(2025,5,12),VLOOKUP(_xlfn.CONCAT(B13,C13),'Detalhe Entregas e Status'!$D$9:$J$81,7,0)),$L$8:$Z$8,0)))} -> #N/A | K13: NOK
B14: lt002_instrument | C14: GRSS_INTRST_INCM | D14: 3. Testes comparativos (Espec. VS Impl.) | E14: Média | F14: 4 | H14: {=IF(INDEX($K:$Z,ROW(C14),MATCH(IF(VLOOKUP(_xlfn.CONCAT(B14,C14),'Detalhe Entregas e Status'!$D$9:$J$81,7,0)=DATE(2025,5,5),DATE(2025,5,12),VLOOKUP(_xlfn.CONCAT(B14,C14),'Detalhe Entregas e Status'!$D$9:$J$81,7,0)),$L$8:$Z$8,0))="","",INDEX($K:$Z,ROW(C14),MATCH(IF(VLOOKUP(_xlfn.CONCAT(B14,C14),'Detalhe Entregas e Status'!$D$9:$J$81,7,0)=DATE(2025,5,5),DATE(2025,5,12),VLOOKUP(_xlfn.CONCAT(B14,C14),'Detalhe Entregas e Status'!$D$9:$J$81,7,0)),$L$8:$Z$8,0)))} -> #N/A | I14: IT estava calcular mal a ponderação quando o msaldo_final é zero (20/mai: "Já estivemos a validar e parece-nos um erro na forma como tínhamos interpretado a especificação das ponderações, quando o saldo final das chaves FR é zero estávamos a dividir sempre 1 pelo número de chaves, em vez do kpm em si, vamos corrigir") | K14: NOK
B15: lt002_instrument | C15: GRSS_INTRST_INCM | D15: 6. Validação de formatos | E15: Baixa | F15: 1 | H15: {=IF(INDEX($K:$Z,ROW(C15),MATCH(IF(VLOOKUP(_xlfn.CONCAT(B15,C15),'Detalhe Entregas e Status'!$D$9:$J$81,7,0)=DATE(2025,5,5),DATE(2025,5,12),VLOOKUP(_xlfn.CONCAT(B15,C15),'Detalhe Entregas e Status'!$D$9:$J$81,7,0)),$L$8:$Z$8,0))="","",INDEX($K:$Z,ROW(C15),MATCH(IF(VLOOKUP(_xlfn.CONCAT(B15,C15),'Detalhe Entregas e Status'!$D$9:$J$81,7,0)=DATE(2025,5,5),DATE(2025,5,12),VLOOKUP(_xlfn.CONCAT(B15,C15),'Detalhe Entregas e Status'!$D$9:$J$81,7,0)),$L$8:$Z$8,0)))} -> #N/A | K15: NOK
B16: lt002_instrument | C16: GRSS_CMMSSN_INCM | D16: 3. Testes comparativos (Espec. VS Impl.) | E16: Média | F16: 4 | H16: {=IF(INDEX($K:$Z,ROW(C16),MATCH(IF(VLOOKUP(_xlfn.CONCAT(B16,C16),'Detalhe Entregas e Status'!$D$9:$J$81,7,0)=DATE(2025,5,5),DATE(2025,5,12),VLOOKUP(_xlfn.CONCAT(B16,C16),'Detalhe Entregas e Status'!$D$9:$J$81,7,0)),$L$8:$Z$8,0))="","",INDEX($K:$Z,ROW(C16),MATCH(IF(VLOOKUP(_xlfn.CONCAT(B16,C16),'Detalhe Entregas e Status'!$D$9:$J$81,7,0)=DATE(2025,5,5),DATE(2025,5,12),VLOOKUP(_xlfn.CONCAT(B16,C16),'Detalhe Entregas e Status'!$D$9:$J$81,7,0)),$L$8:$Z$8,0)))} -> #N/A | I16: IT estava calcular mal a ponderação quando o msaldo_final é zero (20/mai: "Já estivemos a validar e parece-nos um erro na forma como tínhamos interpretado a especificação das ponderações, quando o saldo final das chaves FR é zero estávamos a dividir sempre 1 pelo número de chaves, em vez do kpm em si, vamos corrigir") | K16: NOK
B17: lt002_instrument | C17: GRSS_CMMSSN_INCM | D17: 6. Validação de formatos | E17: Baixa | F17: 1 | H17: {=IF(INDEX($K:$Z,ROW(C17),MATCH(IF(VLOOKUP(_xlfn.CONCAT(B17,C17),'Detalhe Entregas e Status'!$D$9:$J$81,7,0)=DATE(2025,5,5),DATE(2025,5,12),VLOOKUP(_xlfn.CONCAT(B17,C17),'Detalhe Entregas e Status'!$D$9:$J$81,7,0)),$L$8:$Z$8,0))="","",INDEX($K:$Z,ROW(C17),MATCH(IF(VLOOKUP(_xlfn.CONCAT(B17,C17),'Detalhe Entregas e Status'!$D$9:$J$81,7,0)=DATE(2025,5,5),DATE(2025,5,12),VLOOKUP(_xlfn.CONCAT(B17,C17),'Detalhe Entregas e Status'!$D$9:$J$81,7,0)),$L$8:$Z$8,0)))} -> #N/A | K17: NOK
