Workbook
Name asefadf: #REF!
Name bn: #REF!

Sheet 1. Status Resumo old
B7: Sumário Executivo | 12/mai a 15/mai
B9: - Setup do projeto; - Inicio dos testes aos campos entregues no dia 12/mai, referentes às tabelas lt002_instrument e lt004_protection. - Os testes são realizados para a data de referência de 28-02-2025.
B15: 1. LT002_INSTRUMENT
C18: Resumo | H18: Status (campos) | J18: 45792 | L18: Highlights
H19: 1. Concluído | J19: =COUNTIFS('Detalhe Entregas e Status'!$T:$T,'1. Status Resumo old'!H19,'Detalhe Entregas e Status'!$B:$B,"lt002_instrument") -> 0 | L19: Relativamente à tabela lt002_instrument foram entregues para testes, à data de 12/mai, um total de 18 campos assim como o universo da tabela. Desta amostra encontra-se em análise por parte da equipa de testes: • Universo (inclui contratos de 'PM' assim como cancelados) • Campo: INSTRMNT_ID
H20: 2. Em Teste | J20: =COUNTIFS('Detalhe Entregas e Status'!$T:$T,'1. Status Resumo old'!H20,'Detalhe Entregas e Status'!$B:$B,"lt002_instrument") -> 2
H21: 3. Em Re-especificação | J21: =COUNTIFS('Detalhe Entregas e Status'!$T:$T,'1. Status Resumo old'!H21,'Detalhe Entregas e Status'!$B:$B,"lt002_instrument") -> 0
H22: 4. Em Correção | J22: =COUNTIFS('Detalhe Entregas e Status'!$T:$T,'1. Status Resumo old'!H22,'Detalhe Entregas e Status'!$B:$B,"lt002_instrument") -> 0
H23: 5. Em Re-teste | J23: =COUNTIFS('Detalhe Entregas e Status'!$T:$T,'1. Status Resumo old'!H23,'Detalhe Entregas e Status'!$B:$B,"lt002_instrument") -> 0
H24: 6. Por Iniciar | J24: =COUNTIFS('Detalhe Entregas e Status'!$T:$T,'1. Status Resumo old'!H24,'Detalhe Entregas e Status'!$B:$B,"lt002_instrument") -> 17
H25: Total | J25: =SUM(J19:J24) -> 19
H26: Nota: O total = 52 inclui os 51 campos âmbito 'GD' assim como o universo da tabela.
B30: 2. LT004_PROTECTION
C33: Resumo | H33: Status (campos) | J33: 45792 | L33: Highlights
H34: 1. Concluído | J34: =COUNTIFS('Detalhe Entregas e Status'!$T:$T,'1. Status Resumo old'!H34,'Detalhe Entregas e Status'!$B:$B,"lt004_protection") -> 1 | L34: Relativamente à tabela lt004_protection foi entregue para testes, à data de 12/mai, o universo da tabela assim como o campo typ_vhcl. Foi concluida a análise de ambos e verificou-se o seguinte: • Universo: universo comum entre a simulação da equipa de testes e a execução efetuada pela equipa de IT. • TYP_VHCL: todas as proteções apresentam o mesmo valor entre a simulação da equipa de testes e a execução da equipa de IT.
H35: 2. Em Teste | J35: =COUNTIFS('Detalhe Entregas e Status'!$T:$T,'1. Status Resumo old'!H35,'Detalhe Entregas e Status'!$B:$B,"lt004_protection") -> 1
H36: 3. Em Re-especificação | J36: =COUNTIFS('Detalhe Entregas e Status'!$T:$T,'1. Status Resumo old'!H36,'Detalhe Entregas e Status'!$B:$B,"lt004_protection") -> 0
H37: 4. Em Correção | J37: =COUNTIFS('Detalhe Entregas e Status'!$T:$T,'1. Status Resumo old'!H37,'Detalhe Entregas e Status'!$B:$B,"lt004_protection") -> 0
H38: 5. Em Re-teste | J38: =COUNTIFS('Detalhe Entregas e Status'!$T:$T,'1. Status Resumo old'!H38,'Detalhe Entregas e Status'!$B:$B,"lt004_protection") -> 0
H39: 6. Por Iniciar | J39: =COUNTIFS('Detalhe Entregas e Status'!$T:$T,'1. Status Resumo old'!H39,'Detalhe Entregas e Status'!$B:$B,"lt004_protection") -> 0
H40: Total | J40: =SUM(J34:J39) -> 2
H41: Nota: O total = 8 inclui os 7 campos âmbito 'GD' assim como o universo da tabela.
C42: Validação Campos
H44: Validação Universo
H46: Comum | I46: 469321
H47: Exclusivo Simulação | I47: 0
H48: Exclusivo IT | I48: 0

Sheet Status Resumo
B7: Sumário Executivo | 12/mai a 15/mai
B9: - Setup do projeto; - Inicio dos testes aos campos entregues no dia 12/mai, referentes às tabelas lt002_instrument e lt004_protection. - Os testes são realizados para a data de referência de 28-02-2025.
B15: 1. LT002_INSTRUMENT
C18: Resumo | G18: Status (Campos) | H18: 45792 | J18: Highlights
G19: 1. Concluído | H19: =COUNTIFS('Detalhe Entregas e Status'!$T:$T,'Status Resumo'!G19,'Detalhe Entregas e Status'!$B:$B,"lt002_instrument",'Detalhe Entregas e Status'!$C:$C,"<>"&"UNIVERSO") -> 0 | J19: Relativamente à tabela lt002_instrument foram entregues para testes, à data de 12/mai, um total de 18 campos assim como o universo da tabela. Desta amostra encontra-se em análise por parte da equipa de testes: • Universo (inclui contratos de 'PM' assim como cancelados) • Campo: INSTRMNT_ID
G20: 2. Em Teste | H20: =COUNTIFS('Detalhe Entregas e Status'!$T:$T,'Status Resumo'!G20,'Detalhe Entregas e Status'!$B:$B,"lt002_instrument",'Detalhe Entregas e Status'!$C:$C,"<>"&"UNIVERSO") -> 1
G21: 3. Em Re-especificação | H21: =COUNTIFS('Detalhe Entregas e Status'!$T:$T,'Status Resumo'!G21,'Detalhe Entregas e Status'!$B:$B,"lt002_instrument",'Detalhe Entregas e Status'!$C:$C,"<>"&"UNIVERSO") -> 0
G22: 4. Em Correção | H22: =COUNTIFS('Detalhe Entregas e Status'!$T:$T,'Status Resumo'!G22,'Detalhe Entregas e Status'!$B:$B,"lt002_instrument",'Detalhe Entregas e Status'!$C:$C,"<>"&"UNIVERSO") -> 0
G23: 5. Em Re-teste | H23: =COUNTIFS('Detalhe Entregas e Status'!$T:$T,'Status Resumo'!G23,'Detalhe Entregas e Status'!$B:$B,"lt002_instrument",'Detalhe Entregas e Status'!$C:$C,"<>"&"UNIVERSO") -> 0
G24: 6. Por Iniciar | H24: =COUNTIFS('Detalhe Entregas e Status'!$T:$T,'Status Resumo'!G24,'Detalhe Entregas e Status'!$B:$B,"lt002_instrument",'Detalhe Entregas e Status'!$C:$C,"<>"&"UNIVERSO") -> 17
G25: 7. Por Entregar | H25: =COUNTIFS('Detalhe Entregas e Status'!$T:$T,'Status Resumo'!G25,'Detalhe Entregas e Status'!$B:$B,"lt002_instrument",'Detalhe Entregas e Status'!$C:$C,"<>"&"UNIVERSO") -> 33
G26: Total | H26: =SUM(H19:H25) -> 51
G28: Status (Universo) | H28: 45792
G29: lt002_instrument | H29: wip
B32: 2. LT004_PROTECTION
C35: Resumo | G35: Status (Campos) | H35: 45792 | J35: Highlights
G36: 1. Concluído | H36: =COUNTIFS('Detalhe Entregas e Status'!$T:$T,'Status Resumo'!G36,'Detalhe Entregas e Status'!$B:$B,"lt004_protection",'Detalhe Entregas e Status'!$C:$C,"<>"&"UNIVERSO") -> 0 | J36: Relativamente à tabela lt004_protection foi entregue para testes, à data de 12/mai, o universo da tabela assim como o campo typ_vhcl. Foi concluida a análise de ambos e verificou-se o seguinte: • Universo: universo comum entre a simulação da equipa de testes e a execução efetuada pela equipa de IT. • TYP_VHCL: todas as proteções apresentam o mesmo valor entre a simulação da equipa de testes e a execução da equipa de IT.
G37: 2. Em Teste | H37: =COUNTIFS('Detalhe Entregas e Status'!$T:$T,'Status Resumo'!G37,'Detalhe Entregas e Status'!$B:$B,"lt004_protection",'Detalhe Entregas e Status'!$C:$C,"<>"&"UNIVERSO") -> 1
G38: 3. Em Re-especificação | H38: =COUNTIFS('Detalhe Entregas e Status'!$T:$T,'Status Resumo'!G38,'Detalhe Entregas e Status'!$B:$B,"lt004_protection",'Detalhe Entregas e Status'!$C:$C,"<>"&"UNIVERSO") -> 0
G39: 4. Em Correção | H39: =COUNTIFS('Detalhe Entregas e Status'!$T:$T,'Status Resumo'!G39,'Detalhe Entregas e Status'!$B:$B,"lt004_protection",'Detalhe Entregas e Status'!$C:$C,"<>"&"UNIVERSO") -> 0
G40: 5. Em Re-teste | H40: =COUNTIFS('Detalhe Entregas e Status'!$T:$T,'Status Resumo'!G40,'Detalhe Entregas e Status'!$B:$B,"lt004_protection",'Detalhe Entregas e Status'!$C:$C,"<>"&"UNIVERSO") -> 0
G41: 6. Por Iniciar | H41: =COUNTIFS('Detalhe Entregas e Status'!$T:$T,'Status Resumo'!G41,'Detalhe Entregas e Status'!$B:$B,"lt004_protection",'Detalhe Entregas e Status'!$C:$C,"<>"&"UNIVERSO") -> 0
G42: 7. Por Entregar | H42: =COUNTIFS('Detalhe Entregas e Status'!$T:$T,'Status Resumo'!G42,'Detalhe Entregas e Status'!$B:$B,"lt004_protection",'Detalhe Entregas e Status'!$C:$C,"<>"&"UNIVERSO") -> 6
G43: Total | H43: =SUM(H36:H42) -> 7
G45: Status (Universo) | H45: 45792
G46: lt004_protection | H46: ok

Sheet Aux Gráficos
F1: Tabela | G1: lt002_instrument
B2: Tabela | C2: Campo | D2: Status Atual | F2: Campo | G2: (Multiple Items)
B3: lt002_instrument | C3: UNIVERSO | D3: 2. Em Teste
B4: lt002_instrument | C4: AVRG_BLNC | D4: 7. Por Entregar | F4: Row Labels | G4: Count of Status Atual
B5: lt002_instrument | C5: NW_BSNSS | D5: 6. Por Iniciar | F5: 2. Em Teste | G5: 1
B6: lt002_instrument | C6: GRSS_INTRST_INCM | D6: 6. Por Iniciar | F6: 6. Por Iniciar | G6: 17
B7: lt002_instrument | C7: GRSS_CMMSSN_INCM | D7: 6. Por Iniciar | F7: 7. Por Entregar | G7: 33
B8: lt002_instrument | C8: INTRNL_TRNSFR_RT | D8: 7. Por Entregar
B9: lt002_instrument | C9: NT_LN_LSS_PRVSN | D9: 7. Por Entregar | F9: Tabela | G9: lt004_protection
B10: lt002_instrument | C10: BSNSS_AREA | D10: 7. Por Entregar | F10: Campo | G10: (Multiple Items)
B11: lt002_instrument | C11: MNGMNT_PRDCT | D11: 7. Por Entregar
B12: lt002_instrument | C12: GRSS_CMMSSN_EXPNS | D12: 6. Por Iniciar | F12: Row Labels | G12: Count of Status Atual
B13: lt002_instrument | C13: GNS_FNNCL_TRNSCTN_EXCHNG_DFFRNCS | D13: 7. Por Entregar | F13: 2. Em Teste | G13: 1
B14: lt002_instrument | C14: FLG_INTRBSNSS | D14: 7. Por Entregar | F14: 7. Por Entregar | G14: 6
B15: lt002_instrument | C15: INTRBSNSS_ADJ_COD | D15: 7. Por Entregar
B16: lt002_instrument | C16: COD_SOC_DSTNTN | D16: 7. Por Entregar
B17: lt002_instrument | C17: BSNSS_AREA_DSTNTN | D17: 7. Por Entregar
B18: lt002_instrument | C18: AVRG_BLNC_OFF_BLNC | D18: 6. Por Iniciar
B19: lt002_instrument | C19: INTRNL_TRNSFR_RT_OFF_BLNC | D19: 7. Por Entregar
B20: lt002_instrument | C20: GRSS_CMMSSN_INCM_OFF_BLNC | D20: 6. Por Iniciar
B21: lt002_instrument | C21: GRSS_CMMSSN_EXPNS_OFF_BLNC | D21: 6. Por Iniciar
B22: lt002_instrument | C22: RWA_OFF_BLNC | D22: 7. Por Entregar
B23: lt002_instrument | C23: GRSS_INTRST_EXPNS | D23: 7. Por Entregar
B24: lt002_instrument | C24: NT_LN_LSS_PRVSN_OFF_BLNC | D24: 7. Por Entregar
B25: lt002_instrument | C25: GRSS_INTRST_INCM_CCRR | D25: 6. Por Iniciar
B26: lt002_instrument | C26: GRSS_INTRST_EXPNS_CCRR | D26: 6. Por Iniciar
... B75: lt007_instr_activity | C75: INSTRMNT_ID | D75: 6. Por Iniciar

Sheet MacroPlano
B7: Legenda:
B9: « | C9: Entregas da equipa de IT
B10: ♦ | C10: Reuniões de PdS com cliente
B11: 3 | C11: Tempo estimado para a realização da atividade
C12: Feriados
G14: Semana 1 | K14: Semana 2 | P14: Semana 3 | U14: Semana 4 | Z14: Semana 5 | AF14: Semana 6 | AK14: Semana 7 | AO14: Semana 8 | AT14: Semana 9
B15: ID | C15: Atividade | E15: Owner | G15: 12/mai a 15/mai | K15: 16/mai a 22/mai | P15: 23/mai a 29/mai | U15: 30/mai a 05/jun | Z15: 06/jun a 13/jun | AF15: 16/jun a 20/jun | AK15: 23/jun a 26/jun | AO15: 27/jun a 03/jul | AT15: 04/jul a 11/jul
B16: 0. | C16: Gestão
B17: 0.1 | C17: SetUp | E17: Neyond
B18: 0.2 | C18: Reuniões de PdS | E18: Neyond/CdG/IT | J18: ♦ | O18: ♦ | T18: ♦ | Y18: ♦ | AD18: ♦ | AJ18: ♦ | AN18: ♦ | AS18: ♦ | AX18: ♦
B19: 1. | C19: Testes - Entrega 1 | G19: 
B20: 1.1 | C20: lt002_instrument | D20: UNIVERSO | E20: Neyond
B21: 1.2 | C21: lt002_instrument | D21: NW_BSNSS | E21: Neyond
B22: 1.3 | C22: lt002_instrument | D22: GRSS_INTRST_INCM_CCRR | E22: Neyond
B23: =_xlfn.CONCAT(B19,RIGHT(B22,1)+1) -> 1.4 | C23: lt002_instrument | D23: GRSS_INTRST_EXPNS_CCRR | E23: Neyond
B24: 1.5 | C24: lt002_instrument | D24: GRSS_CMMSSN_INCM_CCRR | E24: Neyond
B25: 1.6 | C25: lt002_instrument | D25: GRSS_CMMSSN_EXPNS_CCRR | E25: Neyond
B26: 1.7 | C26: lt002_instrument | D26: GNS_FNNCL_TRNSCTN_EXCHNG_CCRR | E26: Neyond
B27: 1.8 | C27: lt002_instrument | D27: BSNSS_AREA_CCRR | E27: Neyond
B28: 1.9 | C28: lt002_instrument | D28: GRSS_CMMSSN_INCM_OFF_BLNC_CCRR | E28: Neyond
B29: 1.10 | C29: lt002_instrument | D29: GRSS_CMMSSN_EXPNS_OFF_BLNC_CCRR | E29: Neyond
B30: 1.11 | C30: lt002_instrument | D30: DT_RFRNC | E30: Neyond
B31: 1.12 | C31: lt002_instrument | D31: CNCLLD_INSTRMNT_STTS | E31: Neyond
B32: 1.13 | C32: lt002_instrument | D32: INSTRMNT_ID | E32: Neyond
B33: 2. | C33: Testes - Entrega 2 | G33: «
B34: 2.1 | C34: lt002_instrument | D34: GRSS_INTRST_INCM | E34: Neyond
B35: 2.2 | C35: lt002_instrument | D35: GRSS_CMMSSN_INCM | E35: Neyond
B36: 2.3 | C36: lt002_instrument | D36: GRSS_CMMSSN_EXPNS | E36: Neyond
B37: 2.4 | C37: lt002_instrument | D37: AVRG_BLNC_OFF_BLNC | E37: Neyond
B38: 2.5 | C38: lt002_instrument | D38: GRSS_CMMSSN_INCM_OFF_BLNC | E38: Neyond
B39: 2.6 | C39: lt002_instrument | D39: GRSS_CMMSSN_EXPNS_OFF_BLNC | E39: Neyond
B40: 2.7 | C40: lt004_protection | D40: UNIVERSO | E40: Neyond
B41: 2.8 | C41: lt004_protection | D41: TYP_VHCL | E41: Neyond
B42: 2.9 | C42: lt007_instr_activity | D42: UNIVERSO | E42: Neyond
B43: 2.10 | C43: lt007_instr_activity | D43: PRCNTG_ACTVTY | E43: Neyond
B44: 2.11 | C44: lt007_instr_activity | D44: SSTNBL_CTGRY | E44: Neyond
B45: 2.12 | C45: lt007_instr_activity | D45: COD_SOC | E45: Neyond
... B47: 2.14 | C47: lt007_instr_activity | D47: INSTRMNT_ID | E47: Neyond
B48: 3. | C48: Testes - Entrega 3 | L48: «
B49: 3.1 | C49: lt002_instrument | D49: AVRG_BLNC | E49: Neyond
...

Sheet MacroPlano Equipa
B7: Legenda:
B9:  | C9: Entregas da equipa de IT
B10: ♦ | C10: Reuniões de PdS com cliente
B11: 3 | C11: Tempo estimado para a realização da atividade | L11: FTE's | O11: 2 | P11: 2 | Q11: 2 | R11: 2 | S11: 2 | T11: 0 | U11: 0 | V11: 2 | W11: 2 | X11: 2 | Y11: 2 | Z11: 2 | AA11: 0 | AB11: 0 | AC11: 2 | AD11: 2 | AE11: 2 | AF11: 2 | AG11: 2 | AH11: 0 | AI11: 0 | AJ11: 1 | AK11: 1 | AL11: 1 | AM11: 1 | AN11: 1 | AO11: 0 | AP11: 0 | AQ11: 1 | AR11: 0 | AS11: 1 | AT11: 1 | AU11: 0 | AV11: 0 | AW11: 0 | AX11: 2 | AY11: 2 | AZ11: 1 | BA11: 0 | BB11: 1 | BC11: 0 | BD11: 0 | BE11: 1 | BF11: 1 | BG11: 1 | BH11: 1 | BI11: 1 | BJ11: 0 | BK11: 0 | BL11: 2 | BM11: 2 | BN11: 2 | BO11: 2 | BP11: 2 | BQ11: 0 | BR11: 0 | BS11: 2 | BT11: 2 | BU11: 2 | BV11: 2 | BW11: 2 | BX11: 0 | BY11: 0
C12: Feriados | L12: SUM(FTE's) | O12: =SUM(O17:O101)/8 -> 2 | P12: =SUM(P17:P101)/8 -> 2 | Q12: =SUM(Q17:Q101)/8 -> 2.1875 | R12: =SUM(R17:R101)/8 -> 2 | S12: =SUM(S17:S101)/8 -> 2 | T12: =SUM(T17:T101)/8 -> 0 | U12: =SUM(U17:U101)/8 -> 0 | V12: =SUM(V17:V101)/8 -> 2 | ... BY12: =SUM(BY17:BY101)/8 -> 0
B13: 0 | C13: Fins-de-semana | L13: VAL | O13: =O11-O12 -> 0 | P13: =P11-P12 -> 0 | Q13: =Q11-Q12 -> -0.1875 | R13: =R11-R12 -> 0 | S13: =S11-S12 -> 0 | T13: =T11-T12 -> 0 | U13: =U11-U12 -> 0 | V13: =V11-V12 -> 0 | ... BY13: =BY11-BY12 -> 0
L14: sai
F15: Tempo Previsto | H15: Tempo Real | J15: Status | O15: Semana 1 | V15: Semana 2 | AC15: Semana 3 | AJ15: Semana 4 | AQ15: Semana 5 | AX15: Semana 6 | BE15: Semana 7 | BL15: Semana 8 | BS15: Semana 9
B16: ID | C16: Atividade | E16: Owner | F16: Horas | G16: Dias | H16: Horas | I16: Dias | J16: Previsto | K16: Real | L16: Desvio (%) | M16: Val | O16: 45789 | P16: =O16+1 -> 45790 | Q16: =P16+1 -> 45791 | R16: =Q16+1 -> 45792 | S16: =R16+1 -> 45793 | T16: =S16+1 -> 45794 | U16: =T16+1 -> 45795 | V16: =U16+1 -> 45796 | W16: =V16+1 -> 45797 | ... AH16: =AG16+1 -> 45808 | AI16: 45809 | AJ16: =AI16+1 -> 45810 | AK16: =AJ16+1 -> 45811 | AL16: 45812 | AM16: =AL16+1 -> 45813 | AN16: =AM16+1 -> 45814 | AO16: =AN16+1 -> 45815 | AP16: =AO16+1 -> 45816 | AQ16: =AP16+1 -> 45817 | AR16: =AQ16+1 -> 45818 | AS16: =AR16+1 -> 45819 | AT16: =AS16+1 -> 45820 | ... BY16: =BX16+1 -> 45851
B17: 0. | C17: Gestão | T17: 0 | U17: 0 | AA17: 0 | AB17: 0 | AH17: 0 | AI17: 0 | AO17: 0 | AP17: 0 | AV17: 0 | AW17: 0 | BC17: 0 | BD17: 0 | BJ17: 0 | BK17: 0 | BQ17: 0 | BR17: 0 | BX17: 0 | BY17: 0
B18: 0.1 | C18: SetUp | E18: Neyond | F18: 48 | G18: =F18/8/2 -> 3 | H18: {=SUMPRODUCT((COLUMN(O18:BY18)>=MIN(IF(O18:BY18<>"",COLUMN(O18:BY18))))*($O$16:$BY$16<=TODAY())*(O18:BY18))} -> 48 | I18: =H18/8/2 -> 3 | J18: {=SUMPRODUCT(($O$16:$Q$16<=TODAY())*(O18:Q18))/F18} -> 1 | K18: {=IFERROR(SUMPRODUCT(($O$16:$BY$16<=TODAY())*(O18:BY18))/H18,"")} -> 1 | L18: =IFERROR(K18-J18,"") -> 0 | M18: =SUM(O18:BY18)-F18 -> 0 | O18: 16 | P18: 16 | Q18: 16 | T18: 0 | U18: 0 | AA18: 0 | AB18: 0 | AH18: 0 | AI18: 0 | AO18: 0 | AP18: 0 | AV18: 0 | AW18: 0 | BC18: 0 | BD18: 0 | BJ18: 0 | BK18: 0 | BQ18: 0 | BR18: 0 | BX18: 0 | BY18: 0
B19: 0.2 | C19: Reuniões de PdS | E19: Neyond/CdG/IT | F19: 9 | G19: =F19/8 -> 1.125 | R19: ♦ | T19: 0 | U19: 0 | Y19: ♦ | AA19: 0 | AB19: 0 | AF19: ♦ | AH19: 0 | AI19: 0 | AM19: ♦ | AO19: 0 | AP19: 0 | AT19: ♦ | AV19: 0 | AW19: 0 | AZ19: ♦ | BC19: 0 | BD19: 0 | BH19: ♦ | BJ19: 0 | BK19: 0 | BO19: ♦ | BQ19: 0 | BR19: 0 | BV19: ♦ | BX19: 0 | BY19: 0
B20: 1. | C20: Testes - Entrega 1 | O20:  | T20: 0 | U20: 0 | AA20: 0 | AB20: 0 | AH20: 0 | AI20: 0 | AO20: 0 | AP20: 0 | AV20: 0 | AW20: 0 | BC20: 0 | BD20: 0 | BJ20: 0 | BK20: 0 | BQ20: 0 | BR20: 0 | BX20: 0 | BY20: 0
B21: 1.1 | C21: lt002_instrument | D21: UNIVERSO | E21: Neyond | F21: =SUMIFS('Detalhe Testes'!$F:$F,'Detalhe Testes'!$B:$B,'MacroPlano Equipa'!C21,'Detalhe Testes'!$C:$C,'MacroPlano Equipa'!D21) -> 16 | G21: =F21/8 -> 2 | H21: {=SUMPRODUCT((COLUMN(O21:BY21)>=MIN(IF(O21:BY21<>"",COLUMN(O21:BY21))))*($O$16:$BY$16<=TODAY())*(O21:BY21))} -> 8 | I21: =H21/8 -> 1 | M21: =SUM(O21:BY21)-F21 -> 0 | T21: 0 | U21: 0 | V21: 8 | W21: 8 | AA21: 0 | AB21: 0 | AH21: 0 | AI21: 0 | AO21: 0 | AP21: 0 | AV21: 0 | AW21: 0 | BC21: 0 | BD21: 0 | BJ21: 0 | BK21: 0 | BQ21: 0 | BR21: 0 | BX21: 0 | BY21: 0
B22: 1.2 | C22: lt002_instrument | D22: NW_BSNSS | E22: Neyond | F22: =SUMIFS('Detalhe Testes'!$F:$F,'Detalhe Testes'!$B:$B,'MacroPlano Equipa'!C22,'Detalhe Testes'!$C:$C,'MacroPlano Equipa'!D22) -> 5 | G22: =F22/8 -> 0.625 | H22: {=SUMPRODUCT((COLUMN(O22:BY22)>=MIN(IF(O22:BY22<>"",COLUMN(O22:BY22))))*($O$16:$BY$16<=TODAY())*(O22:BY22))} -> 0 | I22: =H22/8 -> 0 | M22: =SUM(O22:BY22)-F22 -> 0 | T22: 0 | U22: 0 | W22: 3 | X22: 2 | AA22: 0 | AB22: 0 | AH22: 0 | AI22: 0 | AO22: 0 | AP22: 0 | AV22: 0 | AW22: 0 | BC22: 0 | BD22: 0 | BJ22: 0 | BK22: 0 | BQ22: 0 | BR22: 0 | BX22: 0 | BY22: 0
B23: 1.3 | C23: lt002_instrument | D23: GRSS_INTRST_INCM_CCRR | E23: Neyond | F23: =SUMIFS('Detalhe Testes'!$F:$F,'Detalhe Testes'!$B:$B,'MacroPlano Equipa'!C23,'Detalhe Testes'!$C:$C,'MacroPlano Equipa'!D23) -> 3 | G23: =F23/8 -> 0.375 | H23: {=SUMPRODUCT((COLUMN(O23:BY23)>=MIN(IF(O23:BY23<>"",COLUMN(O23:BY23))))*($O$16:$BY$16<=TODAY())*(O23:BY23))} -> 3 | I23: =H23/8 -> 0.375 | M23: =SUM(O23:BY23)-F23 -> 0 | R23: 3 | T23: 0 | U23: 0 | AA23: 0 | AB23: 0 | AH23: 0 | AI23: 0 | AO23: 0 | AP23: 0 | AV23: 0 | AW23: 0 | BC23: 0 | BD23: 0 | BJ23: 0 | BK23: 0 | BQ23: 0 | BR23: 0 | BX23: 0 | BY23: 0
B24: =_xlfn.CONCAT(B20,RIGHT(B23,1)+1) -> 1.4 | C24: lt002_instrument | D24: GRSS_INTRST_EXPNS_CCRR | E24: Neyond | F24: =SUMIFS('Detalhe Testes'!$F:$F,'Detalhe Testes'!$B:$B,'MacroPlano Equipa'!C24,'Detalhe Testes'!$C:$C,'MacroPlano Equipa'!D24) -> 3 | G24: =F24/8 -> 0.375 | H24: {=SUMPRODUCT((COLUMN(O24:BY24)>=MIN(IF(O24:BY24<>"",COLUMN(O24:BY24))))*($O$16:$BY$16<=TODAY())*(O24:BY24))} -> 3 | I24: =H24/8 -> 0.375 | M24: =SUM(O24:BY24)-F24 -> 0 | R24: 3 | T24: 0 | U24: 0 | AA24: 0 | AB24: 0 | AH24: 0 | AI24: 0 | AO24: 0 | AP24: 0 | AV24: 0 | AW24: 0 | BC24: 0 | BD24: 0 | BJ24: 0 | BK24: 0 | BQ24: 0 | BR24: 0 | BX24: 0 | BY24: 0
B25: 1.5 | C25: lt002_instrument | D25: GRSS_CMMSSN_INCM_CCRR | E25: Neyond | F25: =SUMIFS('Detalhe Testes'!$F:$F,'Detalhe Testes'!$B:$B,'MacroPlano Equipa'!C25,'Detalhe Testes'!$C:$C,'MacroPlano Equipa'!D25) -> 3 | G25: =F25/8 -> 0.375 | H25: {=SUMPRODUCT((COLUMN(O25:BY25)>=MIN(IF(O25:BY25<>"",COLUMN(O25:BY25))))*($O$16:$BY$16<=TODAY())*(O25:BY25))} -> 3 | I25: =H25/8 -> 0.375 | M25: =SUM(O25:BY25)-F25 -> 0 | R25: 3 | T25: 0 | U25: 0 | AA25: 0 | AB25: 0 | AH25: 0 | AI25: 0 | AO25: 0 | AP25: 0 | AV25: 0 | AW25: 0 | BC25: 0 | BD25: 0 | BJ25: 0 | BK25: 0 | BQ25: 0 | BR25: 0 | BX25: 0 | BY25: 0
B26: 1.6 | C26: lt002_instrument | D26: GRSS_CMMSSN_EXPNS_CCRR | E26: Neyond | F26: =SUMIFS('Detalhe Testes'!$F:$F,'Detalhe Testes'!$B:$B,'MacroPlano Equipa'!C26,'Detalhe Testes'!$C:$C,'MacroPlano Equipa'!D26) -> 3 | G26: =F26/8 -> 0.375 | H26: {=SUMPRODUCT((COLUMN(O26:BY26)>=MIN(IF(O26:BY26<>"",COLUMN(O26:BY26))))*($O$16:$BY$16<=TODAY())*(O26:BY26))} -> 3 | I26: =H26/8 -> 0.375 | M26: =SUM(O26:BY26)-F26 -> 0 | R26: 3 | T26: 0 | U26: 0 | AA26: 0 | AB26: 0 | AH26: 0 | AI26: 0 | AO26: 0 | AP26: 0 | AV26: 0 | AW26: 0 | BC26: 0 | BD26: 0 | BJ26: 0 | BK26: 0 | BQ26: 0 | BR26: 0 | BX26: 0 | BY26: 0
B27: 1.7 | C27: lt002_instrument | D27: GNS_FNNCL_TRNSCTN_EXCHNG_CCRR | E27: Neyond | F27: =SUMIFS('Detalhe Testes'!$F:$F,'Detalhe Testes'!$B:$B,'MacroPlano Equipa'!C27,'Detalhe Testes'!$C:$C,'MacroPlano Equipa'!D27) -> 3 | G27: =F27/8 -> 0.375 | H27: {=SUMPRODUCT((COLUMN(O27:BY27)>=MIN(IF(O27:BY27<>"",COLUMN(O27:BY27))))*($O$16:$BY$16<=TODAY())*(O27:BY27))} -> 3 | I27: =H27/8 -> 0.375 | M27: =SUM(O27:BY27)-F27 -> 0 | R27: 3 | T27: 0 | U27: 0 | AA27: 0 | AB27: 0 | AH27: 0 | AI27: 0 | AO27: 0 | AP27: 0 | AV27: 0 | AW27: 0 | BC27: 0 | BD27: 0 | BJ27: 0 | BK27: 0 | BQ27: 0 | BR27: 0 | BX27: 0 | BY27: 0
B28: 1.8 | C28: lt002_instrument | D28: BSNSS_AREA_CCRR | E28: Neyond | F28: =SUMIFS('Detalhe Testes'!$F:$F,'Detalhe Testes'!$B:$B,'MacroPlano Equipa'!C28,'Detalhe Testes'!$C:$C,'MacroPlano Equipa'!D28) -> 3 | G28: =F28/8 -> 0.375 | H28: {=SUMPRODUCT((COLUMN(O28:BY28)>=MIN(IF(O28:BY28<>"",COLUMN(O28:BY28))))*($O$16:$BY$16<=TODAY())*(O28:BY28))} -> 3 | I28: =H28/8 -> 0.375 | M28: =SUM(O28:BY28)-F28 -> 0 | R28: 1 | S28: 2 | T28: 0 | U28: 0 | AA28: 0 | AB28: 0 | AH28: 0 | AI28: 0 | AO28: 0 | AP28: 0 | AV28: 0 | AW28: 0 | BC28: 0 | BD28: 0 | BJ28: 0 | BK28: 0 | BQ28: 0 | BR28: 0 | BX28: 0 | BY28: 0
B29: 1.9 | C29: lt002_instrument | D29: GRSS_CMMSSN_INCM_OFF_BLNC_CCRR | E29: Neyond | F29: =SUMIFS('Detalhe Testes'!$F:$F,'Detalhe Testes'!$B:$B,'MacroPlano Equipa'!C29,'Detalhe Testes'!$C:$C,'MacroPlano Equipa'!D29) -> 3 | G29: =F29/8 -> 0.375 | H29: {=SUMPRODUCT((COLUMN(O29:BY29)>=MIN(IF(O29:BY29<>"",COLUMN(O29:BY29))))*($O$16:$BY$16<=TODAY())*(O29:BY29))} -> 3 | I29: =H29/8 -> 0.375 | M29: =SUM(O29:BY29)-F29 -> 0 | S29: 3 | T29: 0 | U29: 0 | AA29: 0 | AB29: 0 | AH29: 0 | AI29: 0 | AO29: 0 | AP29: 0 | AV29: 0 | AW29: 0 | BC29: 0 | BD29: 0 | BJ29: 0 | BK29: 0 | BQ29: 0 | BR29: 0 | BX29: 0 | BY29: 0
B30: 1.10 | C30: lt002_instrument | D30: GRSS_CMMSSN_EXPNS_OFF_BLNC_CCRR | E30: Neyond | F30: =SUMIFS('Detalhe Testes'!$F:$F,'Detalhe Testes'!$B:$B,'MacroPlano Equipa'!C30,'Detalhe Testes'!$C:$C,'MacroPlano Equipa'!D30) -> 3 | G30: =F30/8 -> 0.375 | H30: {=SUMPRODUCT((COLUMN(O30:BY30)>=MIN(IF(O30:BY30<>"",COLUMN(O30:BY30))))*($O$16:$BY$16<=TODAY())*(O30:BY30))} -> 3 | I30: =H30/8 -> 0.375 | M30: =SUM(O30:BY30)-F30 -> 0 | S30: 3 | T30: 0 | U30: 0 | AA30: 0 | AB30: 0 | AH30: 0 | AI30: 0 | AO30: 0 | AP30: 0 | AV30: 0 | AW30: 0 | BC30: 0 | BD30: 0 | BJ30: 0 | BK30: 0 | BQ30: 0 | BR30: 0 | BX30: 0 | BY30: 0
B31: 1.11 | C31: lt002_instrument | D31: DT_RFRNC | E31: Neyond | F31: =SUMIFS('Detalhe Testes'!$F:$F,'Detalhe Testes'!$B:$B,'MacroPlano Equipa'!C31,'Detalhe Testes'!$C:$C,'MacroPlano Equipa'!D31) -> 3 | G31: =F31/8 -> 0.375 | H31: {=SUMPRODUCT((COLUMN(O31:BY31)>=MIN(IF(O31:BY31<>"",COLUMN(O31:BY31))))*($O$16:$BY$16<=TODAY())*(O31:BY31))} -> 3 | I31: =H31/8 -> 0.375 | M31: =SUM(O31:BY31)-F31 -> 0 | S31: 3 | T31: 0 | U31: 0 | AA31: 0 | AB31: 0 | AH31: 0 | AI31: 0 | AO31: 0 | AP31: 0 | AV31: 0 | AW31: 0 | BC31: 0 | BD31: 0 | BJ31: 0 | BK31: 0 | BQ31: 0 | BR31: 0 | BX31: 0 | BY31: 0
B32: 1.12 | C32: lt002_instrument | D32: CNCLLD_INSTRMNT_STTS | E32: Neyond | F32: =SUMIFS('Detalhe Testes'!$F:$F,'Detalhe Testes'!$B:$B,'MacroPlano Equipa'!C32,'Detalhe Testes'!$C:$C,'MacroPlano Equipa'!D32) -> 11 | G32: =F32/8 -> 1.375 | H32: {=SUMPRODUCT((COLUMN(O32:BY32)>=MIN(IF(O32:BY32<>"",COLUMN(O32:BY32))))*($O$16:$BY$16<=TODAY())*(O32:BY32))} -> 6 | I32: =H32/8 -> 0.75 | M32: =SUM(O32:BY32)-F32 -> 0 | T32: 0 | U32: 0 | V32: 6 | W32: 5 | AA32: 0 | AB32: 0 | AH32: 0 | AI32: 0 | AO32: 0 | AP32: 0 | AV32: 0 | AW32: 0 | BC32: 0 | BD32: 0 | BJ32: 0 | BK32: 0 | BQ32: 0 | BR32: 0 | BX32: 0 | BY32: 0
B33: 1.13 | C33: lt002_instrument | D33: INSTRMNT_ID | E33: Neyond | F33: =SUMIFS('Detalhe Testes'!$F:$F,'Detalhe Testes'!$B:$B,'MacroPlano Equipa'!C33,'Detalhe Testes'!$C:$C,'MacroPlano Equipa'!D33) -> 7 | G33: =F33/8 -> 0.875 | H33: {=SUMPRODUCT((COLUMN(O33:BY33)>=MIN(IF(O33:BY33<>"",COLUMN(O33:BY33))))*($O$16:$BY$16<=TODAY())*(O33:BY33))} -> 7 | I33: =H33/8 -> 0.875 | M33: =SUM(O33:BY33)-F33 -> 0 | S33: 5 | T33: 0 | U33: 0 | V33: 2 | AA33: 0 | AB33: 0 | AH33: 0 | AI33: 0 | AO33: 0 | AP33: 0 | AV33: 0 | AW33: 0 | BC33: 0 | BD33: 0 | BJ33: 0 | BK33: 0 | BQ33: 0 | BR33: 0 | BX33: 0 | BY33: 0
B34: 2. | C34: Testes - Entrega 2 | M34: =SUM(O34:BY34)-F34 -> 0 | O34:  | T34: 0 | U34: 0 | AA34: 0 | AB34: 0 | AH34: 0 | AI34: 0 | AO34: 0 | AP34: 0 | AV34: 0 | AW34: 0 | BC34: 0 | BD34: 0 | BJ34: 0 | BK34: 0 | BQ34: 0 | BR34: 0 | BX34: 0 | BY34: 0
B35: 2.1 | C35: lt002_instrument | D35: GRSS_INTRST_INCM | E35: Neyond | F35: =SUMIFS('Detalhe Testes'!$F:$F,'Detalhe Testes'!$B:$B,'MacroPlano Equipa'!C35,'Detalhe Testes'!$C:$C,'MacroPlano Equipa'!D35) -> 5 | G35: =F35/8 -> 0.625 | H35: {=SUMPRODUCT((COLUMN(O35:BY35)>=MIN(IF(O35:BY35<>"",COLUMN(O35:BY35))))*($O$16:$BY$16<=TODAY())*(O35:BY35))} -> 0 | I35: =H35/8 -> 0 | M35: =SUM(O35:BY35)-F35 -> 0 | T35: 0 | U35: 0 | X35: 5 | AA35: 0 | AB35: 0 | AH35: 0 | AI35: 0 | AO35: 0 | AP35: 0 | AV35: 0 | AW35: 0 | BC35: 0 | BD35: 0 | BJ35: 0 | BK35: 0 | BQ35: 0 | BR35: 0 | BX35: 0 | BY35: 0
B36: 2.2 | C36: lt002_instrument | D36: GRSS_CMMSSN_INCM | E36: Neyond | F36: =SUMIFS('Detalhe Testes'!$F:$F,'Detalhe Testes'!$B:$B,'MacroPlano Equipa'!C36,'Detalhe Testes'!$C:$C,'MacroPlano Equipa'!D36) -> 5 | G36: =F36/8 -> 0.625 | H36: {=SUMPRODUCT((COLUMN(O36:BY36)>=MIN(IF(O36:BY36<>"",COLUMN(O36:BY36))))*($O$16:$BY$16<=TODAY())*(O36:BY36))} -> 0 | I36: =H36/8 -> 0 | M36: =SUM(O36:BY36)-F36 -> 0 | T36: 0 | U36: 0 | X36: 1 | Y36: 4 | AA36: 0 | AB36: 0 | AH36: 0 | AI36: 0 | AO36: 0 | AP36: 0 | AV36: 0 | AW36: 0 | BC36: 0 | BD36: 0 | BJ36: 0 | BK36: 0 | BQ36: 0 | BR36: 0 | BX36: 0 | BY36: 0
B37: 2.3 | C37: lt002_instrument | D37: GRSS_CMMSSN_EXPNS | E37: Neyond | F37: =SUMIFS('Detalhe Testes'!$F:$F,'Detalhe Testes'!$B:$B,'MacroPlano Equipa'!C37,'Detalhe Testes'!$C:$C,'MacroPlano Equipa'!D37) -> 5 | G37: =F37/8 -> 0.625 | H37: {=SUMPRODUCT((COLUMN(O37:BY37)>=MIN(IF(O37:BY37<>"",COLUMN(O37:BY37))))*($O$16:$BY$16<=TODAY())*(O37:BY37))} -> 0 | I37: =H37/8 -> 0 | M37: =SUM(O37:BY37)-F37 -> 0 | T37: 0 | U37: 0 | Y37: 4 | Z37: 1 | AA37: 0 | AB37: 0 | AH37: 0 | AI37: 0 | AO37: 0 | AP37: 0 | AV37: 0 | AW37: 0 | BC37: 0 | BD37: 0 | BJ37: 0 | BK37: 0 | BQ37: 0 | BR37: 0 | BX37: 0 | BY37: 0
B38: 2.4 | C38: lt002_instrument | D38: AVRG_BLNC_OFF_BLNC | E38: Neyond | F38: =SUMIFS('Detalhe Testes'!$F:$F,'Detalhe Testes'!$B:$B,'MacroPlano Equipa'!C38,'Detalhe Testes'!$C:$C,'MacroPlano Equipa'!D38) -> 5 | G38: =F38/8 -> 0.625 | H38: {=SUMPRODUCT((COLUMN(O38:BY38)>=MIN(IF(O38:BY38<>"",COLUMN(O38:BY38))))*($O$16:$BY$16<=TODAY())*(O38:BY38))} -> 0 | I38: =H38/8 -> 0 | M38: =SUM(O38:BY38)-F38 -> 0 | T38: 0 | U38: 0 | Z38: 5 | AA38: 0 | AB38: 0 | AH38: 0 | AI38: 0 | AO38: 0 | AP38: 0 | AV38: 0 | AW38: 0 | BC38: 0 | BD38: 0 | BJ38: 0 | BK38: 0 | BQ38: 0 | BR38: 0 | BX38: 0 | BY38: 0
B39: 2.5 | C39: lt002_instrument | D39: GRSS_CMMSSN_INCM_OFF_BLNC | E39: Neyond | F39: =SUMIFS('Detalhe Testes'!$F:$F,'Detalhe Testes'!$B:$B,'MacroPlano Equipa'!C39,'Detalhe Testes'!$C:$C,'MacroPlano Equipa'!D39) -> 5 | G39: =F39/8 -> 0.625 | H39: {=SUMPRODUCT((COLUMN(O39:BY39)>=MIN(IF(O39:BY39<>"",COLUMN(O39:BY39))))*($O$16:$BY$16<=TODAY())*(O39:BY39))} -> 0 | I39: =H39/8 -> 0 | M39: =SUM(O39:BY39)-F39 -> 0 | T39: 0 | U39: 0 | Z39: 2 | AA39: 0 | AB39: 0 | AC39: 3 | AH39: 0 | AI39: 0 | AO39: 0 | AP39: 0 | AV39: 0 | AW39: 0 | BC39: 0 | BD39: 0 | BJ39: 0 | BK39: 0 | BQ39: 0 | BR39: 0 | BX39: 0 | BY39: 0
B40: 2.6 | C40: lt002_instrument | D40: GRSS_CMMSSN_EXPNS_OFF_BLNC | E40: Neyond | F40: =SUMIFS('Detalhe Testes'!$F:$F,'Detalhe Testes'!$B:$B,'MacroPlano Equipa'!C40,'Detalhe Testes'!$C:$C,'MacroPlano Equipa'!D40) -> 5 | G40: =F40/8 -> 0.625 | H40: {=SUMPRODUCT((COLUMN(O40:BY40)>=MIN(IF(O40:BY40<>"",COLUMN(O40:BY40))))*($O$16:$BY$16<=TODAY())*(O40:BY40))} -> 0 | I40: =H40/8 -> 0 | M40: =SUM(O40:BY40)-F40 -> 0 | T40: 0 | U40: 0 | AA40: 0 | AB40: 0 | AC40: 5 | AH40: 0 | AI40: 0 | AO40: 0 | AP40: 0 | AV40: 0 | AW40: 0 | BC40: 0 | BD40: 0 | BJ40: 0 | BK40: 0 | BQ40: 0 | BR40: 0 | BX40: 0 | BY40: 0
B41: 2.7 | C41: lt004_protection | D41: UNIVERSO | E41: Neyond | F41: =SUMIFS('Detalhe Testes'!$F:$F,'Detalhe Testes'!$B:$B,'MacroPlano Equipa'!C41,'Detalhe Testes'!$C:$C,'MacroPlano Equipa'!D41) -> 6 | G41: =F41/8 -> 0.75 | H41: {=SUMPRODUCT((COLUMN(O41:BY41)>=MIN(IF(O41:BY41<>"",COLUMN(O41:BY41))))*($O$16:$BY$16<=TODAY())*(O41:BY41))} -> 0.5 | I41: =H41/8 -> 0.0625 | M41: =SUM(O41:BY41)-F41 -> 0.5 | Q41: 0.5 | T41: 0 | U41: 0 | X41: 6 | AA41: 0 | AB41: 0 | AH41: 0 | AI41: 0 | AO41: 0 | AP41: 0 | AV41: 0 | AW41: 0 | BC41: 0 | BD41: 0 | BJ41: 0 | BK41: 0 | BQ41: 0 | BR41: 0 | BX41: 0 | BY41: 0
B42: 2.8 | C42: lt004_protection | D42: TYP_VHCL | E42: Neyond | F42: =SUMIFS('Detalhe Testes'!$F:$F,'Detalhe Testes'!$B:$B,'MacroPlano Equipa'!C42,'Detalhe Testes'!$C:$C,'MacroPlano Equipa'!D42) -> 9 | G42: =F42/8 -> 1.125 | H42: {=SUMPRODUCT((COLUMN(O42:BY42)>=MIN(IF(O42:BY42<>"",COLUMN(O42:BY42))))*($O$16:$BY$16<=TODAY())*(O42:BY42))} -> 1 | I42: =H42/8 -> 0.125 | M42: =SUM(O42:BY42)-F42 -> 1 | Q42: 1 | T42: 0 | U42: 0 | X42: 2 | Y42: 7 | AA42: 0 | AB42: 0 | AH42: 0 | AI42: 0 | AO42: 0 | AP42: 0 | AV42: 0 | AW42: 0 | BC42: 0 | BD42: 0 | BJ42: 0 | BK42: 0 | BQ42: 0 | BR42: 0 | BX42: 0 | BY42: 0
B43: 2.9 | C43: lt007_instr_activity | D43: UNIVERSO | E43: Neyond | F43: =SUMIFS('Detalhe Testes'!$F:$F,'Detalhe Testes'!$B:$B,'MacroPlano Equipa'!C43,'Detalhe Testes'!$C:$C,'MacroPlano Equipa'!D43) -> 16 | G43: =F43/8 -> 2 | H43: {=SUMPRODUCT((COLUMN(O43:BY43)>=MIN(IF(O43:BY43<>"",COLUMN(O43:BY43))))*($O$16:$BY$16<=TODAY())*(O43:BY43))} -> 0 | I43: =H43/8 -> 0 | M43: =SUM(O43:BY43)-F43 -> 0 | T43: 0 | U43: 0 | Y43: 1 | Z43: 8 | AA43: 0 | AB43: 0 | AC43: 7 | AH43: 0 | AI43: 0 | AO43: 0 | AP43: 0 | AV43: 0 | AW43: 0 | BC43: 0 | BD43: 0 | BJ43: 0 | BK43: 0 | BQ43: 0 | BR43: 0 | BX43: 0 | BY43: 0
B44: 2.10 | C44: lt007_instr_activity | D44: PRCNTG_ACTVTY | E44: Neyond | F44: =SUMIFS('Detalhe Testes'!$F:$F,'Detalhe Testes'!$B:$B,'MacroPlano Equipa'!C44,'Detalhe Testes'!$C:$C,'MacroPlano Equipa'!D44) -> 11 | G44: =F44/8 -> 1.375 | H44: {=SUMPRODUCT((COLUMN(O44:BY44)>=MIN(IF(O44:BY44<>"",COLUMN(O44:BY44))))*($O$16:$BY$16<=TODAY())*(O44:BY44))} -> 0 | I44: =H44/8 -> 0 | M44: =SUM(O44:BY44)-F44 -> 0 | T44: 0 | U44: 0 | AA44: 0 | AB44: 0 | AD44: 8 | AE44: 3 | AH44: 0 | AI44: 0 | AO44: 0 | AP44: 0 | AV44: 0 | AW44: 0 | BC44: 0 | BD44: 0 | BJ44: 0 | BK44: 0 | BQ44: 0 | BR44: 0 | BX44: 0 | BY44: 0
B45: 2.11 | C45: lt007_instr_activity | D45: SSTNBL_CTGRY | E45: Neyond | F45: =SUMIFS('Detalhe Testes'!$F:$F,'Detalhe Testes'!$B:$B,'MacroPlano Equipa'!C45,'Detalhe Testes'!$C:$C,'MacroPlano Equipa'!D45) -> 9 | G45: =F45/8 -> 1.125 | H45: {=SUMPRODUCT((COLUMN(O45:BY45)>=MIN(IF(O45:BY45<>"",COLUMN(O45:BY45))))*($O$16:$BY$16<=TODAY())*(O45:BY45))} -> 0 | I45: =H45/8 -> 0 | M45: =SUM(O45:BY45)-F45 -> 0 | T45: 0 | U45: 0 | AA45: 0 | AB45: 0 | AE45: 5 | AF45: 4 | AH45: 0 | AI45: 0 | AO45: 0 | AP45: 0 | AV45: 0 | AW45: 0 | BC45: 0 | BD45: 0 | BJ45: 0 | BK45: 0 | BQ45: 0 | BR45: 0 | BX45: 0 | BY45: 0
B46: 2.12 | C46: lt007_instr_activity | D46: COD_SOC | E46: Neyond | F46: =SUMIFS('Detalhe Testes'!$F:$F,'Detalhe Testes'!$B:$B,'MacroPlano Equipa'!C46,'Detalhe Testes'!$C:$C,'MacroPlano Equipa'!D46) -> 3 | G46: =F46/8 -> 0.375 | H46: {=SUMPRODUCT((COLUMN(O46:BY46)>=MIN(IF(O46:BY46<>"",COLUMN(O46:BY46))))*($O$16:$BY$16<=TODAY())*(O46:BY46))} -> 0 | I46: =H46/8 -> 0 | M46: =SUM(O46:BY46)-F46 -> 0 | T46: 0 | U46: 0 | AA46: 0 | AB46: 0 | AD46: 3 | AH46: 0 | AI46: 0 | AO46: 0 | AP46: 0 | AV46: 0 | AW46: 0 | BC46: 0 | BD46: 0 | BJ46: 0 | BK46: 0 | BQ46: 0 | BR46: 0 | BX46: 0 | BY46: 0
B47: 2.13 | C47: lt007_instr_activity | D47: DT_RFRNC | E47: Neyond | F47: =SUMIFS('Detalhe Testes'!$F:$F,'Detalhe Testes'!$B:$B,'MacroPlano Equipa'!C47,'Detalhe Testes'!$C:$C,'MacroPlano Equipa'!D47) -> 3 | G47: =F47/8 -> 0.375 | H47: {=SUMPRODUCT((COLUMN(O47:BY47)>=MIN(IF(O47:BY47<>"",COLUMN(O47:BY47))))*($O$16:$BY$16<=TODAY())*(O47:BY47))} -> 0 | I47: =H47/8 -> 0 | M47: =SUM(O47:BY47)-F47 -> 0 | T47: 0 | U47: 0 | AA47: 0 | AB47: 0 | AD47: 3 | AH47: 0 | AI47: 0 | AO47: 0 | AP47: 0 | AV47: 0 | AW47: 0 | BC47: 0 | BD47: 0 | BJ47: 0 | BK47: 0 | BQ47: 0 | BR47: 0 | BX47: 0 | BY47: 0
...

Sheet Detalhe Entregas e Status
H7: Entrega IT | P7: Re-testes
B8: Tabela | C8: Campo | D8: Structural | E8: Green Dashboard | F8: Pillar III ESG | G8: Entrega Neyond | H8: Data Prevista | I8: Data Real | J8: Atraso (em dias) | L8: # Incidências | M8: Re-especificação Neyond | N8: Correção IT | P8: Dt c/ Pedido Correção | Q8: Dt Prevista Correção | R8: Dt Efetiva Correção | T8: Status Atual | U8: Status Anterior
B9: lt002_instrument | C9: UNIVERSO | D9: - | E9: - | F9: - | G9: Package 1 | H9: 45782 | I9: 45782 | J9: =+IF(I9="","N/A",I9-H9) -> 0 | L9: =SUMIFS('Detalhe Testes'!$H:$H,'Detalhe Testes'!$B:$B,'Detalhe Entregas e Status'!B9,'Detalhe Testes'!$C:$C,'Detalhe Entregas e Status'!C9) -> 0 | T9: 2. Em Teste
B10: lt002_instrument | C10: AVRG_BLNC | D10: N | E10: Y | F10: N | G10: Package 4 | H10: 45796 | J10: =+IF(I10="","N/A",I10-H10) -> N/A | L10: =SUMIFS('Detalhe Testes'!$H:$H,'Detalhe Testes'!$B:$B,'Detalhe Entregas e Status'!B10,'Detalhe Testes'!$C:$C,'Detalhe Entregas e Status'!C10) -> 0 | T10: 7. Por Entregar
B11: lt002_instrument | C11: NW_BSNSS | D11: N | E11: Y | F11: Y | G11: Package 5 | H11: 45782 | I11: 45782 | J11: =+IF(I11="","N/A",I11-H11) -> 0 | L11: =SUMIFS('Detalhe Testes'!$H:$H,'Detalhe Testes'!$B:$B,'Detalhe Entregas e Status'!B11,'Detalhe Testes'!$C:$C,'Detalhe Entregas e Status'!C11) -> 0 | T11: 6. Por Iniciar
B12: lt002_instrument | C12: GRSS_INTRST_INCM | D12: N | E12: Y | F12: Y | G12: Package 4 | H12: 45789 | I12: 45789 | J12: =+IF(I12="","N/A",I12-H12) -> 0 | L12: =SUMIFS('Detalhe Testes'!$H:$H,'Detalhe Testes'!$B:$B,'Detalhe Entregas e Status'!B12,'Detalhe Testes'!$C:$C,'Detalhe Entregas e Status'!C12) -> 0 | T12: 6. Por Iniciar
B13: lt002_instrument | C13: GRSS_CMMSSN_INCM | D13: N | E13: Y | F13: Y | G13: Package 4 | H13: 45789 | I13: 45789 | J13: =+IF(I13="","N/A",I13-H13) -> 0 | L13: =SUMIFS('Detalhe Testes'!$H:$H,'Detalhe Testes'!$B:$B,'Detalhe Entregas e Status'!B13,'Detalhe Testes'!$C:$C,'Detalhe Entregas e Status'!C13) -> 0 | T13: 6. Por Iniciar
B14: lt002_instrument | C14: INTRNL_TRNSFR_RT | D14: N | E14: Y | F14: N | G14: Package 1 | H14: 45796 | J14: =+IF(I14="","N/A",I14-H14) -> N/A | L14: =SUMIFS('Detalhe Testes'!$H:$H,'Detalhe Testes'!$B:$B,'Detalhe Entregas e Status'!B14,'Detalhe Testes'!$C:$C,'Detalhe Entregas e Status'!C14) -> 0 | T14: 7. Por Entregar
B15: lt002_instrument | C15: NT_LN_LSS_PRVSN | D15: N | E15: Y | F15: N | G15: Package 4 | H15: 45796 | J15: =+IF(I15="","N/A",I15-H15) -> N/A | L15: =SUMIFS('Detalhe Testes'!$H:$H,'Detalhe Testes'!$B:$B,'Detalhe Entregas e Status'!B15,'Detalhe Testes'!$C:$C,'Detalhe Entregas e Status'!C15) -> 0 | T15: 7. Por Entregar
B16: lt002_instrument | C16: BSNSS_AREA | D16: N | E16: Y | F16: N | G16: Package 5 | H16: 45803 | J16: =+IF(I16="","N/A",I16-H16) -> N/A | L16: =SUMIFS('Detalhe Testes'!$H:$H,'Detalhe Testes'!$B:$B,'Detalhe Entregas e Status'!B16,'Detalhe Testes'!$C:$C,'Detalhe Entregas e Status'!C16) -> 0 | T16: 7. Por Entregar
B17: lt002_instrument | C17: MNGMNT_PRDCT | D17: N | E17: Y | F17: N | G17: Package 1 | H17: 45796 | J17: =+IF(I17="","N/A",I17-H17) -> N/A | L17: =SUMIFS('Detalhe Testes'!$H:$H,'Detalhe Testes'!$B:$B,'Detalhe Entregas e Status'!B17,'Detalhe Testes'!$C:$C,'Detalhe Entregas e Status'!C17) -> 0 | T17: 7. Por Entregar
B18: lt002_instrument | C18: GRSS_CMMSSN_EXPNS | D18: N | E18: Y | F18: N | G18: Package 4 | H18: 45789 | I18: 45789 | J18: =+IF(I18="","N/A",I18-H18) -> 0 | L18: =SUMIFS('Detalhe Testes'!$H:$H,'Detalhe Testes'!$B:$B,'Detalhe Entregas e Status'!B18,'Detalhe Testes'!$C:$C,'Detalhe Entregas e Status'!C18) -> 0 | T18: 6. Por Iniciar
B19: lt002_instrument | C19: GNS_FNNCL_TRNSCTN_EXCHNG_DFFRNCS | D19: N | E19: Y | F19: N | G19: Package 4 | H19: 45796 | J19: =+IF(I19="","N/A",I19-H19) -> N/A | L19: =SUMIFS('Detalhe Testes'!$H:$H,'Detalhe Testes'!$B:$B,'Detalhe Entregas e Status'!B19,'Detalhe Testes'!$C:$C,'Detalhe Entregas e Status'!C19) -> 0 | T19: 7. Por Entregar
B20: lt002_instrument | C20: FLG_INTRBSNSS | D20: N | E20: Y | F20: N | G20: Package 1 | H20: 45796 | J20: =+IF(I20="","N/A",I20-H20) -> N/A | L20: =SUMIFS('Detalhe Testes'!$H:$H,'Detalhe Testes'!$B:$B,'Detalhe Entregas e Status'!B20,'Detalhe Testes'!$C:$C,'Detalhe Entregas e Status'!C20) -> 0 | T20: 7. Por Entregar
B21: lt002_instrument | C21: INTRBSNSS_ADJ_COD | D21: N | E21: Y | F21: N | G21: Package 1 | H21: 45796 | J21: =+IF(I21="","N/A",I21-H21) -> N/A | L21: =SUMIFS('Detalhe Testes'!$H:$H,'Detalhe Testes'!$B:$B,'Detalhe Entregas e Status'!B21,'Detalhe Testes'!$C:$C,'Detalhe Entregas e Status'!C21) -> 0 | T21: 7. Por Entregar
B22: lt002_instrument | C22: COD_SOC_DSTNTN | D22: N | E22: Y | F22: N | G22: Package 1 | H22: 45796 | J22: =+IF(I22="","N/A",I22-H22) -> N/A | L22: =SUMIFS('Detalhe Testes'!$H:$H,'Detalhe Testes'!$B:$B,'Detalhe Entregas e Status'!B22,'Detalhe Testes'!$C:$C,'Detalhe Entregas e Status'!C22) -> 0 | T22: 7. Por Entregar
B23: lt002_instrument | C23: BSNSS_AREA_DSTNTN | D23: N | E23: Y | F23: N | G23: Package 1 | H23: 45796 | J23: =+IF(I23="","N/A",I23-H23) -> N/A | L23: =SUMIFS('Detalhe Testes'!$H:$H,'Detalhe Testes'!$B:$B,'Detalhe Entregas e Status'!B23,'Detalhe Testes'!$C:$C,'Detalhe Entregas e Status'!C23) -> 0 | T23: 7. Por Entregar
B24: lt002_instrument | C24: AVRG_BLNC_OFF_BLNC | D24: N | E24: Y | F24: N | G24: Package 4 | H24: 45789 | I24: 45789 | J24: =+IF(I24="","N/A",I24-H24) -> 0 | L24: =SUMIFS('Detalhe Testes'!$H:$H,'Detalhe Testes'!$B:$B,'Detalhe Entregas e Status'!B24,'Detalhe Testes'!$C:$C,'Detalhe Entregas e Status'!C24) -> 0 | T24: 6. Por Iniciar
B25: lt002_instrument | C25: INTRNL_TRNSFR_RT_OFF_BLNC | D25: N | E25: Y | F25: N | G25: Package 1 | H25: 45796 | J25: =+IF(I25="","N/A",I25-H25) -> N/A | L25: =SUMIFS('Detalhe Testes'!$H:$H,'Detalhe Testes'!$B:$B,'Detalhe Entregas e Status'!B25,'Detalhe Testes'!$C:$C,'Detalhe Entregas e Status'!C25) -> 0 | T25: 7. Por Entregar
B26: lt002_instrument | C26: GRSS_CMMSSN_INCM_OFF_BLNC | D26: N | E26: Y | F26: Y | G26: Package 4 | H26: 45789 | I26: 45789 | J26: =+IF(I26="","N/A",I26-H26) -> 0 | L26: =SUMIFS('Detalhe Testes'!$H:$H,'Detalhe Testes'!$B:$B,'Detalhe Entregas e Status'!B26,'Detalhe Testes'!$C:$C,'Detalhe Entregas e Status'!C26) -> 0 | T26: 6. Por Iniciar
B27: lt002_instrument | C27: GRSS_CMMSSN_EXPNS_OFF_BLNC | D27: N | E27: Y | F27: N | G27: Package 4 | H27: 45789 | I27: 45789 | J27: =+IF(I27="","N/A",I27-H27) -> 0 | L27: =SUMIFS('Detalhe Testes'!$H:$H,'Detalhe Testes'!$B:$B,'Detalhe Entregas e Status'!B27,'Detalhe Testes'!$C:$C,'Detalhe Entregas e Status'!C27) -> 0 | T27: 6. Por Iniciar
B28: lt002_instrument | C28: RWA_OFF_BLNC | D28: N | E28: Y | F28: N | G28: Package 1 | H28: 45803 | J28: =+IF(I28="","N/A",I28-H28) -> N/A | L28: =SUMIFS('Detalhe Testes'!$H:$H,'Detalhe Testes'!$B:$B,'Detalhe Entregas e Status'!B28,'Detalhe Testes'!$C:$C,'Detalhe Entregas e Status'!C28) -> 0 | T28: 7. Por Entregar
B29: lt002_instrument | C29: GRSS_INTRST_EXPNS | D29: N | E29: Y | F29: N | G29: Package 4 | H29: 45796 | J29: =+IF(I29="","N/A",I29-H29) -> N/A | L29: =SUMIFS('Detalhe Testes'!$H:$H,'Detalhe Testes'!$B:$B,'Detalhe Entregas e Status'!B29,'Detalhe Testes'!$C:$C,'Detalhe Entregas e Status'!C29) -> 0 | T29: 7. Por Entregar
B30: lt002_instrument | C30: NT_LN_LSS_PRVSN_OFF_BLNC | D30: N | E30: Y | F30: N | G30: Package 4 | H30: 45803 | J30: =+IF(I30="","N/A",I30-H30) -> N/A | L30: =SUMIFS('Detalhe Testes'!$H:$H,'Detalhe Testes'!$B:$B,'Detalhe Entregas e Status'!B30,'Detalhe Testes'!$C:$C,'Detalhe Entregas e Status'!C30) -> 0 | T30: 7. Por Entregar
B31: lt002_instrument | C31: GRSS_INTRST_INCM_CCRR | D31: N | E31: Y | F31: N | G31: Package 4 | H31: 45782 | I31: 45782 | J31: =+IF(I31="","N/A",I31-H31) -> 0 | L31: =SUMIFS('Detalhe Testes'!$H:$H,'Detalhe Testes'!$B:$B,'Detalhe Entregas e Status'!B31,'Detalhe Testes'!$C:$C,'Detalhe Entregas e Status'!C31) -> 0 | T31: 6. Por Iniciar
B32: lt002_instrument | C32: GRSS_INTRST_EXPNS_CCRR | D32: N | E32: Y | F32: N | G32: Package 4 | H32: 45782 | I32: 45782 | J32: =+IF(I32="","N/A",I32-H32) -> 0 | L32: =SUMIFS('Detalhe Testes'!$H:$H,'Detalhe Testes'!$B:$B,'Detalhe Entregas e Status'!B32,'Detalhe Testes'!$C:$C,'Detalhe Entregas e Status'!C32) -> 0 | T32: 6. Por Iniciar
B33: lt002_instrument | C33: GRSS_CMMSSN_INCM_CCRR | D33: N | E33: Y | F33: N | G33: Package 4 | H33: 45782 | I33: 45782 | J33: =+IF(I33="","N/A",I33-H33) -> 0 | L33: =SUMIFS('Detalhe Testes'!$H:$H,'Detalhe Testes'!$B:$B,'Detalhe Entregas e Status'!B33,'Detalhe Testes'!$C:$C,'Detalhe Entregas e Status'!C33) -> 0 | T33: 6. Por Iniciar
B34: lt002_instrument | C34: GRSS_CMMSSN_EXPNS_CCRR | D34: N | E34: Y | F34: N | G34: Package 4 | H34: 45782 | I34: 45782 | J34: =+IF(I34="","N/A",I34-H34) -> 0 | L34: =SUMIFS('Detalhe Testes'!$H:$H,'Detalhe Testes'!$B:$B,'Detalhe Entregas e Status'!B34,'Detalhe Testes'!$C:$C,'Detalhe Entregas e Status'!C34) -> 0 | T34: 6. Por Iniciar
B35: lt002_instrument | C35: GNS_FNNCL_TRNSCTN_EXCHNG_CCRR | D35: N | E35: Y | F35: N | G35: Package 4 | H35: 45782 | I35: 45782 | J35: =+IF(I35="","N/A",I35-H35) -> 0 | L35: =SUMIFS('Detalhe Testes'!$H:$H,'Detalhe Testes'!$B:$B,'Detalhe Entregas e Status'!B35,'Detalhe Testes'!$C:$C,'Detalhe Entregas e Status'!C35) -> 0 | T35: 6. Por Iniciar
B36: lt002_instrument | C36: BSNSS_AREA_CCRR | D36: N | E36: Y | F36: N | G36: Package 4 | H36: 45782 | I36: 45782 | J36: =+IF(I36="","N/A",I36-H36) -> 0 | L36: =SUMIFS('Detalhe Testes'!$H:$H,'Detalhe Testes'!$B:$B,'Detalhe Entregas e Status'!B36,'Detalhe Testes'!$C:$C,'Detalhe Entregas e Status'!C36) -> 0 | T36: 6. Por Iniciar
B37: lt002_instrument | C37: GRSS_CMMSSN_INCM_OFF_BLNC_CCRR | D37: N | E37: Y | F37: N | G37: Package 4 | H37: 45782 | I37: 45782 | J37: =+IF(I37="","N/A",I37-H37) -> 0 | L37: =SUMIFS('Detalhe Testes'!$H:$H,'Detalhe Testes'!$B:$B,'Detalhe Entregas e Status'!B37,'Detalhe Testes'!$C:$C,'Detalhe Entregas e Status'!C37) -> 0 | T37: 6. Por Iniciar
B38: lt002_instrument | C38: GRSS_CMMSSN_EXPNS_OFF_BLNC_CCRR | D38: N | E38: Y | F38: N | G38: Package 4 | H38: 45782 | I38: 45782 | J38: =+IF(I38="","N/A",I38-H38) -> 0 | L38: =SUMIFS('Detalhe Testes'!$H:$H,'Detalhe Testes'!$B:$B,'Detalhe Entregas e Status'!B38,'Detalhe Testes'!$C:$C,'Detalhe Entregas e Status'!C38) -> 0 | T38: 6. Por Iniciar
B39: lt002_instrument | C39: CCF | D39: Y | E39: Y | F39: N | G39: Package 2 | H39: 45803 | J39: =+IF(I39="","N/A",I39-H39) -> N/A | L39: =SUMIFS('Detalhe Testes'!$H:$H,'Detalhe Testes'!$B:$B,'Detalhe Entregas e Status'!B39,'Detalhe Testes'!$C:$C,'Detalhe Entregas e Status'!C39) -> 0 | T39: 7. Por Entregar
B40: lt002_instrument | C40: EAD | D40: Y | E40: Y | F40: N | G40: Package 2 | H40: 45810 | I40: 45810 | J40: =+IF(I40="","N/A",I40-H40) -> 0 | L40: =SUMIFS('Detalhe Testes'!$H:$H,'Detalhe Testes'!$B:$B,'Detalhe Entregas e Status'!B40,'Detalhe Testes'!$C:$C,'Detalhe Entregas e Status'!C40) -> 0 | T40: 7. Por Entregar
B41: lt002_instrument | C41: TYP_OFF_BLNC_PRDCT | D41: Y | E41: Y | F41: Y | G41: Package 2 | H41: 45810 | I41: 45810 | J41: =+IF(I41="","N/A",I41-H41) -> 0 | L41: =SUMIFS('Detalhe Testes'!$H:$H,'Detalhe Testes'!$B:$B,'Detalhe Entregas e Status'!B41,'Detalhe Testes'!$C:$C,'Detalhe Entregas e Status'!C41) -> 0 | T41: 7. Por Entregar
B42: lt002_instrument | C42: COD_SOC | D42: Y | E42: Y | F42: Y | G42: Package 2 | H42: 45803 | J42: =+IF(I42="","N/A",I42-H42) -> N/A | L42: =SUMIFS('Detalhe Testes'!$H:$H,'Detalhe Testes'!$B:$B,'Detalhe Entregas e Status'!B42,'Detalhe Testes'!$C:$C,'Detalhe Entregas e Status'!C42) -> 0 | T42: 7. Por Entregar
B43: lt002_instrument | C43: SUBPORTFOLIO_ID | D43: Y | E43: Y | F43: Y | G43: Package 2 | H43: 45803 | J43: =+IF(I43="","N/A",I43-H43) -> N/A | L43: =SUMIFS('Detalhe Testes'!$H:$H,'Detalhe Testes'!$B:$B,'Detalhe Entregas e Status'!B43,'Detalhe Testes'!$C:$C,'Detalhe Entregas e Status'!C43) -> 0 | T43: 7. Por Entregar
B44: lt002_instrument | C44: DT_RFRNC | D44: Y | E44: Y | F44: Y | G44: Package 2 | H44: 45782 | I44: 45782 | J44: =+IF(I44="","N/A",I44-H44) -> 0 | L44: =SUMIFS('Detalhe Testes'!$H:$H,'Detalhe Testes'!$B:$B,'Detalhe Entregas e Status'!B44,'Detalhe Testes'!$C:$C,'Detalhe Entregas e Status'!C44) -> 0 | T44: 6. Por Iniciar
B45: lt002_instrument | C45: DFLT_STTS_INSTRMNT | D45: Y | E45: Y | F45: Y | G45: Package 2 | H45: 45803 | J45: =+IF(I45="","N/A",I45-H45) -> N/A | L45: =SUMIFS('Detalhe Testes'!$H:$H,'Detalhe Testes'!$B:$B,'Detalhe Entregas e Status'!B45,'Detalhe Testes'!$C:$C,'Detalhe Entregas e Status'!C45) -> 0 | T45: 7. Por Entregar
B46: lt002_instrument | C46: IMPRMNT_STTS | D46: Y | E46: Y | F46: Y | G46: Package 2 | H46: 45803 | J46: =+IF(I46="","N/A",I46-H46) -> N/A | L46: =SUMIFS('Detalhe Testes'!$H:$H,'Detalhe Testes'!$B:$B,'Detalhe Entregas e Status'!B46,'Detalhe Testes'!$C:$C,'Detalhe Entregas e Status'!C46) -> 0 | T46: 7. Por Entregar
...

Sheet Detalhe Testes
H7: =MAX(K8:V8) -> 45789 | K7: Tracking da evolução do # incidências (Data das entregas de IT)
B8: Tabela | C8: Campo | D8: Tipologia de Teste | E8: Complexidade | F8: Horas Estimadas | H8: # Incidências | I8: Notas | K8: 45789
B9: lt002_instrument | C9: UNIVERSO | D9: 1. Teste de universo | E9: Alta | F9: 16 | H9: {=IF(INDEX($K:$AA,ROW(C9),MATCH($H$7,$K$8:$AA$8,0))="","",INDEX($K:$AA,ROW(C9),MATCH($H$7,$K$8:$AA$8,0)))}
B10: lt002_instrument | C10: AVRG_BLNC | D10: 3. Testes comparativos (Espec. VS Impl.) | E10: Média | F10: 4 | H10: {=IF(INDEX($K:$AA,ROW(C10),MATCH($H$7,$K$8:$AA$8,0))="","",INDEX($K:$AA,ROW(C10),MATCH($H$7,$K$8:$AA$8,0)))}
B11: lt002_instrument | C11: AVRG_BLNC | D11: 6. Validação de formatos | E11: Baixa | F11: 1 | H11: {=IF(INDEX($K:$AA,ROW(C11),MATCH($H$7,$K$8:$AA$8,0))="","",INDEX($K:$AA,ROW(C11),MATCH($H$7,$K$8:$AA$8,0)))}
B12: lt002_instrument | C12: NW_BSNSS | D12: 3. Testes comparativos (Espec. VS Impl.) | E12: Média | F12: 4 | H12: {=IF(INDEX($K:$AA,ROW(C12),MATCH($H$7,$K$8:$AA$8,0))="","",INDEX($K:$AA,ROW(C12),MATCH($H$7,$K$8:$AA$8,0)))}
B13: lt002_instrument | C13: NW_BSNSS | D13: 6. Validação de formatos | E13: Baixa | F13: 1 | H13: {=IF(INDEX($K:$AA,ROW(C13),MATCH($H$7,$K$8:$AA$8,0))="","",INDEX($K:$AA,ROW(C13),MATCH($H$7,$K$8:$AA$8,0)))}
B14: lt002_instrument | C14: GRSS_INTRST_INCM | D14: 3. Testes comparativos (Espec. VS Impl.) | E14: Média | F14: 4 | H14: {=IF(INDEX($K:$AA,ROW(C14),MATCH($H$7,$K$8:$AA$8,0))="","",INDEX($K:$AA,ROW(C14),MATCH($H$7,$K$8:$AA$8,0)))}
B15: lt002_instrument | C15: GRSS_INTRST_INCM | D15: 6. Validação de formatos | E15: Baixa | F15: 1 | H15: {=IF(INDEX($K:$AA,ROW(C15),MATCH($H$7,$K$8:$AA$8,0))="","",INDEX($K:$AA,ROW(C15),MATCH($H$7,$K$8:$AA$8,0)))}
B16: lt002_instrument | C16: GRSS_CMMSSN_INCM | D16: 3. Testes comparativos (Espec. VS Impl.) | E16: Média | F16: 4 | H16: {=IF(INDEX($K:$AA,ROW(C16),MATCH($H$7,$K$8:$AA$8,0))="","",INDEX($K:$AA,ROW(C16),MATCH($H$7,$K$8:$AA$8,0)))}
B17: lt002_instrument | C17: GRSS_CMMSSN_INCM | D17: 6. Validação de formatos | E17: Baixa | F17: 1 | H17: {=IF(INDEX($K:$AA,ROW(C17),MATCH($H$7,$K$8:$AA$8,0))="","",INDEX($K:$AA,ROW(C17),MATCH($H$7,$K$8:$AA$8,0)))}
B18: lt002_instrument | C18: INTRNL_TRNSFR_RT | D18: 3. Testes comparativos (Espec. VS Impl.) | E18: Média | F18: 4 | H18: {=IF(INDEX($K:$AA,ROW(C18),MATCH($H$7,$K$8:$AA$8,0))="","",INDEX($K:$AA,ROW(C18),MATCH($H$7,$K$8:$AA$8,0)))}
B19: lt002_instrument | C19: INTRNL_TRNSFR_RT | D19: 6. Validação de formatos | E19: Baixa | F19: 1 | H19: {=IF(INDEX($K:$AA,ROW(C19),MATCH($H$7,$K$8:$AA$8,0))="","",INDEX($K:$AA,ROW(C19),MATCH($H$7,$K$8:$AA$8,0)))}
B20: lt002_instrument | C20: NT_LN_LSS_PRVSN | D20: 6. Validação de formatos | E20: Baixa | F20: 1 | H20: {=IF(INDEX($K:$AA,ROW(C20),MATCH($H$7,$K$8:$AA$8,0))="","",INDEX($K:$AA,ROW(C20),MATCH($H$7,$K$8:$AA$8,0)))}
... B121: lt002_instrument | C121: INSTRMNT_ID | D121: 3. Testes comparativos (Espec. VS Impl.) | E121: Média | F121: 4 | H121: {=IF(INDEX($K:$AA,ROW(C121),MATCH($H$7,$K$8:$AA$8,0))="","",INDEX($K:$AA,ROW(C121),MATCH($H$7,$K$8:$AA$8,0)))}
B122: lt004_protection | C122: UNIVERSO | D122: 1. Teste de universo | E122: Média | F122: 6 | H122: {=IF(INDEX($K:$AA,ROW(C122),MATCH($H$7,$K$8:$AA$8,0))="","",INDEX($K:$AA,ROW(C122),MATCH($H$7,$K$8:$AA$8,0)))} -> 0 | K122: 0
B123: lt004_protection | C123: COD_SOC | D123: 5. Teste comparativos com LT | E123: Baixa | F123: 2 | H123: {=IF(INDEX($K:$AA,ROW(C123),MATCH($H$7,$K$8:$AA$8,0))="","",INDEX($K:$AA,ROW(C123),MATCH($H$7,$K$8:$AA$8,0)))}
B124: lt004_protection | C124: COD_SOC | D124: 6. Validação de formatos | E124: Baixa | F124: 1 | H124: {=IF(INDEX($K:$AA,ROW(C124),MATCH($H$7,$K$8:$AA$8,0))="","",INDEX($K:$AA,ROW(C124),MATCH($H$7,$K$8:$AA$8,0)))}
B125: lt004_protection | C125: DT_RFRNC | D125: 5. Teste comparativos com LT | E125: Baixa | F125: 2 | H125: {=IF(INDEX($K:$AA,ROW(C125),MATCH($H$7,$K$8:$AA$8,0))="","",INDEX($K:$AA,ROW(C125),MATCH($H$7,$K$8:$AA$8,0)))}
B126: lt004_protection | C126: DT_RFRNC | D126: 6. Validação de formatos | E126: Baixa | F126: 1 | H126: {=IF(INDEX($K:$AA,ROW(C126),MATCH($H$7,$K$8:$AA$8,0))="","",INDEX($K:$AA,ROW(C126),MATCH($H$7,$K$8:$AA$8,0)))}
B127: lt004_protection | C127: PRTCTN_ID | D127: 5. Teste comparativos com LT | E127: Baixa | F127: 2 | H127: {=IF(INDEX($K:$AA,ROW(C127),MATCH($H$7,$K$8:$AA$8,0))="","",INDEX($K:$AA,ROW(C127),MATCH($H$7,$K$8:$AA$8,0)))}
B128: lt004_protection | C128: PRTCTN_ID | D128: 6. Validação de formatos | E128: Baixa | F128: 1 | H128: {=IF(INDEX($K:$AA,ROW(C128),MATCH($H$7,$K$8:$AA$8,0))="","",INDEX($K:$AA,ROW(C128),MATCH($H$7,$K$8:$AA$8,0)))}
B129: lt004_protection | C129: TYP_PRTCTN | D129: 5. Teste comparativos com LT | E129: Baixa | F129: 2 | H129: {=IF(INDEX($K:$AA,ROW(C129),MATCH($H$7,$K$8:$AA$8,0))="","",INDEX($K:$AA,ROW(C129),MATCH($H$7,$K$8:$AA$8,0)))}
B130: lt004_protection | C130: TYP_PRTCTN | D130: 6. Validação de formatos | E130: Baixa | F130: 1 | H130: {=IF(INDEX($K:$AA,ROW(C130),MATCH($H$7,$K$8:$AA$8,0))="","",INDEX($K:$AA,ROW(C130),MATCH($H$7,$K$8:$AA$8,0)))}
B131: lt004_protection | C131: TYP_PRTCTN | D131: 4. Validação de parametrizações | E131: Baixa | F131: 2 | H131: {=IF(INDEX($K:$AA,ROW(C131),MATCH($H$7,$K$8:$AA$8,0))="","",INDEX($K:$AA,ROW(C131),MATCH($H$7,$K$8:$AA$8,0)))}
B132: lt004_protection | C132: PRTCTN_VL | D132: 5. Teste comparativos com LT | E132: Baixa | F132: 2 | H132: {=IF(INDEX($K:$AA,ROW(C132),MATCH($H$7,$K$8:$AA$8,0))="","",INDEX($K:$AA,ROW(C132),MATCH($H$7,$K$8:$AA$8,0)))}
B133: lt004_protection | C133: PRTCTN_VL | D133: 6. Validação de formatos | E133: Baixa | F133: 1 | H133: {=IF(INDEX($K:$AA,ROW(C133),MATCH($H$7,$K$8:$AA$8,0))="","",INDEX($K:$AA,ROW(C133),MATCH($H$7,$K$8:$AA$8,0)))}
B134: lt004_protection | C134: TYP_VHCL | D134: 5. Teste comparativos com LT | E134: Média | F134: 2 | H134: {=IF(INDEX($K:$AA,ROW(C134),MATCH($H$7,$K$8:$AA$8,0))="","",INDEX($K:$AA,ROW(C134),MATCH($H$7,$K$8:$AA$8,0)))}
B135: lt004_protection | C135: TYP_VHCL | D135: 6. Validação de formatos | E135: Baixa | F135: 1 | H135: {=IF(INDEX($K:$AA,ROW(C135),MATCH($H$7,$K$8:$AA$8,0))="","",INDEX($K:$AA,ROW(C135),MATCH($H$7,$K$8:$AA$8,0)))} -> 0 | K135: 0
B136: lt004_protection | C136: TYP_VHCL | D136: 4. Validação de parametrizações | E136: Baixa | F136: 2 | H136: {=IF(INDEX($K:$AA,ROW(C136),MATCH($H$7,$K$8:$AA$8,0))="","",INDEX($K:$AA,ROW(C136),MATCH($H$7,$K$8:$AA$8,0)))} -> 0 | K136: 0
B137: lt004_protection | C137: TYP_VHCL | D137: 3. Testes comparativos (Espec. VS Impl.) | E137: Média | F137: 4 | H137: {=IF(INDEX($K:$AA,ROW(C137),MATCH($H$7,$K$8:$AA$8,0))="","",INDEX($K:$AA,ROW(C137),MATCH($H$7,$K$8:$AA$8,0)))} -> 0 | K137: 0
B138: lt004_protection | C138: FLG_ELCTRC_VHCL | D138: 6. Validação de formatos | E138: Baixa | F138: 1 | H138: {=IF(INDEX($K:$AA,ROW(C138),MATCH($H$7,$K$8:$AA$8,0))="","",INDEX($K:$AA,ROW(C138),MATCH($H$7,$K$8:$AA$8,0)))}
B139: lt004_protection | C139: FLG_ELCTRC_VHCL | D139: 4. Validação de parametrizações | E139: Baixa | F139: 2 | H139: {=IF(INDEX($K:$AA,ROW(C139),MATCH($H$7,$K$8:$AA$8,0))="","",INDEX($K:$AA,ROW(C139),MATCH($H$7,$K$8:$AA$8,0)))}
B140: lt004_protection | C140: FLG_ELCTRC_VHCL | D140: 3. Testes comparativos (Espec. VS Impl.) | E140: Média | F140: 4 | H140: {=IF(INDEX($K:$AA,ROW(C140),MATCH($H$7,$K$8:$AA$8,0))="","",INDEX($K:$AA,ROW(C140),MATCH($H$7,$K$8:$AA$8,0)))}
B141: lt006_instr_protection | C141: UNIVERSO | D141: 1. Teste de universo | E141: Média | F141: 6 | H141: {=IF(INDEX($K:$AA,ROW(C141),MATCH($H$7,$K$8:$AA$8,0))="","",INDEX($K:$AA,ROW(C141),MATCH($H$7,$K$8:$AA$8,0)))}
B142: lt006_instr_protection | C142: COD_SOC | D142: 3. Testes comparativos (Espec. VS Impl.) | E142: Baixa | F142: 2 | H142: {=IF(INDEX($K:$AA,ROW(C142),MATCH($H$7,$K$8:$AA$8,0))="","",INDEX($K:$AA,ROW(C142),MATCH($H$7,$K$8:$AA$8,0)))}
B143: lt006_instr_protection | C143: COD_SOC | D143: 6. Validação de formatos | E143: Baixa | F143: 1 | H143: {=IF(INDEX($K:$AA,ROW(C143),MATCH($H$7,$K$8:$AA$8,0))="","",INDEX($K:$AA,ROW(C143),MATCH($H$7,$K$8:$AA$8,0)))}
B144: lt006_instr_protection | C144: DT_RFRNC | D144: 3. Testes comparativos (Espec. VS Impl.) | E144: Baixa | F144: 2 | H144: {=IF(INDEX($K:$AA,ROW(C144),MATCH($H$7,$K$8:$AA$8,0))="","",INDEX($K:$AA,ROW(C144),MATCH($H$7,$K$8:$AA$8,0)))}
B145: lt006_instr_protection | C145: DT_RFRNC | D145: 6. Validação de formatos | E145: Baixa | F145: 1 | H145: {=IF(INDEX($K:$AA,ROW(C145),MATCH($H$7,$K$8:$AA$8,0))="","",INDEX($K:$AA,ROW(C145),MATCH($H$7,$K$8:$AA$8,0)))}
B146: lt006_instr_protection | C146: INSTRMNT_ID | D146: 3. Testes comparativos (Espec. VS Impl.) | E146: Baixa | F146: 2 | H146: {=IF(INDEX($K:$AA,ROW(C146),MATCH($H$7,$K$8:$AA$8,0))="","",INDEX($K:$AA,ROW(C146),MATCH($H$7,$K$8:$AA$8,0)))}
...

Sheet Aux Testes_Status
B7: Descrição das tipologias de testes aplicadas:
B9: Categoria do Teste | C9: Descrição
B10: 1. Teste de universo | C10: 1. Validação de universo de contratos (quando comparado âmbito "CDG" e "PM", e numero de registos) 2. Controlos sobre o desdobramento de chaves nas relações FR-MIS
B11: 3. Testes comparativos (Espec. VS Impl.) | C11: A partir da simulação realizada, comparar resultados com a implementação de IT.
B12: 4. Validação de parametrizações | C12: A partir da simulação realizada, comparar com as parametrizações implementadas por IT.
B13: 5. Teste comparativos com LT | C13: Garantir que a informação do campo da LT-ESTR âmbito 'PM' está espelhado no âmbito 'CDG'.
B14: 6. Validação de formatos | C14: Validação de formato de acordo com o que é esperado pela Corporação (incluindo validação de codelists, missing e default values) Validar especificação e controlos da especificação vs o que está implementado
B17: Status para Testes/Re-Testes
B19: Status | C19: Descrição
B20: 1. Concluído | C20: Campo concluído com sucesso.
B21: 2. Em Teste | C21: Campo em teste pela equipa Neyond.
B22: 3. Em Re-especificação | C22: Campo em re-especificação pela equipa Neyond.
B23: 4. Em Correção | C23: Campo em correção pela equipa IT.
B24: 5. Em Re-teste | C24: Campo em re-teste pela equipa Neyond.
B25: 6. Por Iniciar | C25: Campo não iniciado pela equipa Neyond.
B26: 7. Por Entregar | C26: Campo ainda não entregue para testes por parte da equipa de IT.
