Workbook
Name asefadf: #REF!
Name bn: #REF!

Sheet 1. Status Resumo
B6: Sumário Executivo | 02/jan a 09/jan
B8: - Inicio do assessment aos campos previamente definidos pela Deloitte. - Início da atualização da documentação (word e excel) com a proposta de especificação to-be.
B13: 1. Assesment | G13: Bens Imóveis - Input | H13: Bens Imóveis - Output | I13: Modelo Verde - Input | J13: Modelo Verde - Output | K13: Pilar III
C16: Resumo | H16: Status (campos) | K16: 45665 | L16: % | N16: Highlights
H17: 0. Cancelado | K17: 3 | L17: =K17/$K$23 -> 0.078947368 | N17: Dos 38 campos em âmbito do Assessment inicial, temos: • 3 campos cancelados: - LG_INSTRMNT_CNCLLD: passou a chamar-se CNCLLD_INSTRMNT_STTS e deixou de ser um campo de sim/não e passou a ser uma code list; - SSTNBL_INDCTR: campo continua a existir mas mudou de tabela (passou da lt002_instrument para a lt007_instr_activity); - SSTNBL_CTGRY: campo continua a existir mas mudou de tabela (passou da lt002_instrument para a lt007_instr_activity) • 10 campos concluídos: especificação validada com CdG. • 6 campos em análise. • 5 campos para validação da especificação com CdG. • 14 campos por iniciar.
H18: 1. Fora de âmbito | K18: 0 | L18: =K18/$K$23 -> 0
H19: 2. Concluído | K19: 10 | L19: =K19/$K$23 -> 0.26315789
H20: 3. Em Análise | K20: 6 | L20: =K20/$K$23 -> 0.15789474
H21: 4. Validação da especificação | K21: 5 | L21: =K21/$K$23 -> 0.13157895
H22: 5. Por Iniciar | K22: 14 | L22: =K22/$K$23 -> 0.36842105
H23: Total | K23: =SUM(K17:K22) -> 38 | L23: =K23/$K$23 -> 1
C28: Detalhe por Tabela

Sheet FC
B6: MacroPlano | Testes GD
F8: Datas Estimadas | J8: Semana 1 | O8: Semana 2 | T8: Semana 3 | Y8: Semana 4 | AD8: Semana 5 | AI8: Semana 6 | AN8: Semana 7 | AS8: Semana 8 | AX8: Semana 9 | BC8: Semana 10 | BH8: Semana 11 | BM8: Semana 12 | BR8: Semana 13
B9: ID | C9: Atividades | D9: Owner | E9: Status | F9: Data Inicio | G9: Data Fim | H9: Data Fim Real | J9: 02/jan-03/jan | O9: 06/jan-10/jan | T9: 13/jan-17/jan | Y9: 20/jan-24/jan | AD9: 27/jan-31/jan | AI9: 03/fev-07/fev | AN9: 10/fev-14/fev | AS9: 17/fev-21/fev | AX9: 24/fev-28/fev | BC9: 03/mar-07/mar | BH9: 10/mar-14/mar | BM9: 17/mar-21/mar
B11: 1. | C11: Assessment Especificação Deloitte
B12: 1.1 | C12: Validação da especificação dos campos (total = 35) | E12: =
B13: 1.2 | C13: Atualização da documentação (word + excel) com a especificação to-be | E13: =
B14: 1.3 | E14: =
B15: 1.4 | E15: =
B16: 1.5 | E16: N/A
B17: 1.6 | E17: =
B18: 1.7 | E18: =
B19: 1.8 | E19: =
B21: 2.
B22: 2.1 | E22: =
B23: 2.2 | E23: =
B24: 2.3 | E24: =
B25: 2.4 | E25: =
B26: 2.5 | E26: =
B27: 2.6 | E27: =
B29: 3.
B30: 3.1 | E30: =
B31: 3.2 | E31: =
B32: 3.3 | E32: =
B33: 3.4 | E33: =
B35: 4.
B36: 4.1 | E36: = | Z36: «
B37: 4.2 | E37: = | AG37: «
B38: 4.3 | E38: = | AW38: «
B39: 4.4 | E39: = | BR39: «
B41: 5. | C41: Outros Temas
B42: 5.1 | C42: Desagregação por Business Area | E42: =
B43: 5.2 | C43: Contratos intra-mês: validação do universo
B46: Legenda:
C48: Feriados
B50: = | C50: Concluído
B51: = | C51: Em progresso
B52: = | C52: Por iniciar
B53: « | C53: Entregas

Sheet Sheet2
B3: 02/jan | C3: 03/jan | D3: 02/jan-03/jan | E3: Semana 1
B4: 06/jan | C4: 10/jan | D4: 06/jan-10/jan | E4: Semana 2
B5: =C4+3 -> 45670 | C5: =B5+4 -> 45674 | D5: 13/jan-17/jan | E5: Semana 3
B6: =C5+3 -> 45677 | C6: =B6+4 -> 45681 | D6: 20/jan-24/jan | E6: Semana 4
B7: =C6+3 -> 45684 | C7: =B7+4 -> 45688 | D7: 27/jan-31/jan | E7: Semana 5
B8: =C7+3 -> 45691 | C8: =B8+4 -> 45695 | D8: 03/fev-07/fev | E8: Semana 6
B9: =C8+3 -> 45698 | C9: =B9+4 -> 45702 | D9: 10/fev-14/fev | E9: Semana 7
B10: =C9+3 -> 45705 | C10: =B10+4 -> 45709 | D10: 17/fev-21/fev | E10: Semana 8
B11: =C10+3 -> 45712 | C11: =B11+4 -> 45716 | D11: 24/fev-28/fev | E11: Semana 9
B12: =C11+3 -> 45719 | C12: =B12+4 -> 45723 | D12: 03/mar-07/mar | E12: Semana 10
B13: =C12+3 -> 45726 | C13: =B13+4 -> 45730 | D13: 10/mar-14/mar | E13: Semana 11
B14: =C13+3 -> 45733 | C14: =B14+4 -> 45737 | D14: 17/mar-21/mar | E14: Semana 12

Sheet 2. Status Detalhe Campos
B6: Âmbito | C6: Categoria | D6: Tipo de teste | E6: Tabela | F6: Campo | G6: Status Atual | H6: Status Anterior | I6: Observações | J6: Data de Pedido correção/esclarecimento | K6: Data de correção prevista | L6: Data de correção efetiva | M6: Data Prevista de Re-especificação | N6: Data Prevista de Teste
A7: =E7&F7 -> lt002_instrumentAVRG_BLNC | B7: Green Dashboard | C7: Assessment | D7: {=INDEX(Plano_Detalhado!$B$10:$H$47,MATCH(1,(Plano_Detalhado!$E$10:$E$47=$E7)*($F7=Plano_Detalhado!$F$10:$F$47),0),3)} -> 2. Campo | E7: lt002_instrument | F7: AVRG_BLNC | G7: {=INDEX(Plano_Detalhado!$B$10:$H$47,MATCH(1,(Plano_Detalhado!$E$10:$E$47=$E7)*($F7=Plano_Detalhado!$F$10:$F$47),0),6)} -> 2. Concluído | H7: {=INDEX(Plano_Detalhado!$B$10:$H$47,MATCH(1,(Plano_Detalhado!$E$10:$E$47=$E7)*($F7=Plano_Detalhado!$F$10:$F$47),0),7)} -> 2. Concluído
A8: =E8&F8 -> lt002_instrumentNW_BSNSS | B8: Green Dashboard | C8: Assessment | D8: {=INDEX(Plano_Detalhado!$B$10:$H$47,MATCH(1,(Plano_Detalhado!$E$10:$E$47=$E8)*($F8=Plano_Detalhado!$F$10:$F$47),0),3)} -> 2. Campo | E8: lt002_instrument | F8: NW_BSNSS | G8: {=INDEX(Plano_Detalhado!$B$10:$H$47,MATCH(1,(Plano_Detalhado!$E$10:$E$47=$E8)*($F8=Plano_Detalhado!$F$10:$F$47),0),6)} -> 4. Validação da especificação | H8: {=INDEX(Plano_Detalhado!$B$10:$H$47,MATCH(1,(Plano_Detalhado!$E$10:$E$47=$E8)*($F8=Plano_Detalhado!$F$10:$F$47),0),7)} -> 8. Por Iniciar
A9: =E9&F9 -> lt002_instrumentGRSS_INTRST_INCM | B9: Green Dashboard | C9: Assessment | D9: {=INDEX(Plano_Detalhado!$B$10:$H$47,MATCH(1,(Plano_Detalhado!$E$10:$E$47=$E9)*($F9=Plano_Detalhado!$F$10:$F$47),0),3)} -> 2. Campo | E9: lt002_instrument | F9: GRSS_INTRST_INCM | G9: {=INDEX(Plano_Detalhado!$B$10:$H$47,MATCH(1,(Plano_Detalhado!$E$10:$E$47=$E9)*($F9=Plano_Detalhado!$F$10:$F$47),0),6)} -> 2. Concluído | H9: {=INDEX(Plano_Detalhado!$B$10:$H$47,MATCH(1,(Plano_Detalhado!$E$10:$E$47=$E9)*($F9=Plano_Detalhado!$F$10:$F$47),0),7)} -> 4. Validação da especificação
A10: =E10&F10 -> lt002_instrumentGRSS_CMMSSN_INCM | B10: Green Dashboard | C10: Assessment | D10: {=INDEX(Plano_Detalhado!$B$10:$H$47,MATCH(1,(Plano_Detalhado!$E$10:$E$47=$E10)*($F10=Plano_Detalhado!$F$10:$F$47),0),3)} -> 2. Campo | E10: lt002_instrument | F10: GRSS_CMMSSN_INCM | G10: {=INDEX(Plano_Detalhado!$B$10:$H$47,MATCH(1,(Plano_Detalhado!$E$10:$E$47=$E10)*($F10=Plano_Detalhado!$F$10:$F$47),0),6)} -> 2. Concluído | H10: {=INDEX(Plano_Detalhado!$B$10:$H$47,MATCH(1,(Plano_Detalhado!$E$10:$E$47=$E10)*($F10=Plano_Detalhado!$F$10:$F$47),0),7)} -> 4. Validação da especificação
A11: =E11&F11 -> lt002_instrumentINTRNL_TRNSFR_RT | B11: Green Dashboard | C11: Assessment | D11: {=INDEX(Plano_Detalhado!$B$10:$H$47,MATCH(1,(Plano_Detalhado!$E$10:$E$47=$E11)*($F11=Plano_Detalhado!$F$10:$F$47),0),3)} -> 2. Campo | E11: lt002_instrument | F11: INTRNL_TRNSFR_RT | G11: {=INDEX(Plano_Detalhado!$B$10:$H$47,MATCH(1,(Plano_Detalhado!$E$10:$E$47=$E11)*($F11=Plano_Detalhado!$F$10:$F$47),0),6)} -> 2. Concluído | H11: {=INDEX(Plano_Detalhado!$B$10:$H$47,MATCH(1,(Plano_Detalhado!$E$10:$E$47=$E11)*($F11=Plano_Detalhado!$F$10:$F$47),0),7)} -> 2. Concluído
A12: =E12&F12 -> lt002_instrumentNT_LN_LSS_PRVSN | B12: Green Dashboard | C12: Assessment | D12: {=INDEX(Plano_Detalhado!$B$10:$H$47,MATCH(1,(Plano_Detalhado!$E$10:$E$47=$E12)*($F12=Plano_Detalhado!$F$10:$F$47),0),3)} -> 2. Campo | E12: lt002_instrument | F12: NT_LN_LSS_PRVSN | G12: {=INDEX(Plano_Detalhado!$B$10:$H$47,MATCH(1,(Plano_Detalhado!$E$10:$E$47=$E12)*($F12=Plano_Detalhado!$F$10:$F$47),0),6)} -> 2. Concluído | H12: {=INDEX(Plano_Detalhado!$B$10:$H$47,MATCH(1,(Plano_Detalhado!$E$10:$E$47=$E12)*($F12=Plano_Detalhado!$F$10:$F$47),0),7)} -> 2. Concluído
A13: =E13&F13 -> lt002_instrumentBSNSS_AREA | B13: Green Dashboard | C13: Assessment | D13: {=INDEX(Plano_Detalhado!$B$10:$H$47,MATCH(1,(Plano_Detalhado!$E$10:$E$47=$E13)*($F13=Plano_Detalhado!$F$10:$F$47),0),3)} -> 2. Campo | E13: lt002_instrument | F13: BSNSS_AREA | G13: {=INDEX(Plano_Detalhado!$B$10:$H$47,MATCH(1,(Plano_Detalhado!$E$10:$E$47=$E13)*($F13=Plano_Detalhado!$F$10:$F$47),0),6)} -> 2. Concluído | H13: {=INDEX(Plano_Detalhado!$B$10:$H$47,MATCH(1,(Plano_Detalhado!$E$10:$E$47=$E13)*($F13=Plano_Detalhado!$F$10:$F$47),0),7)} -> 8. Por Iniciar
A14: =E14&F14 -> lt002_instrumentMNGMNT_PRDCT | B14: Green Dashboard | C14: Assessment | D14: {=INDEX(Plano_Detalhado!$B$10:$H$47,MATCH(1,(Plano_Detalhado!$E$10:$E$47=$E14)*($F14=Plano_Detalhado!$F$10:$F$47),0),3)} -> 2. Campo | E14: lt002_instrument | F14: MNGMNT_PRDCT | G14: {=INDEX(Plano_Detalhado!$B$10:$H$47,MATCH(1,(Plano_Detalhado!$E$10:$E$47=$E14)*($F14=Plano_Detalhado!$F$10:$F$47),0),6)} -> 2. Concluído | H14: {=INDEX(Plano_Detalhado!$B$10:$H$47,MATCH(1,(Plano_Detalhado!$E$10:$E$47=$E14)*($F14=Plano_Detalhado!$F$10:$F$47),0),7)} -> 2. Concluído
A15: =E15&F15 -> lt002_instrumentGRSS_CMMSSN_EXPNS | B15: Green Dashboard | C15: Assessment | D15: {=INDEX(Plano_Detalhado!$B$10:$H$47,MATCH(1,(Plano_Detalhado!$E$10:$E$47=$E15)*($F15=Plano_Detalhado!$F$10:$F$47),0),3)} -> 2. Campo | E15: lt002_instrument | F15: GRSS_CMMSSN_EXPNS | G15: {=INDEX(Plano_Detalhado!$B$10:$H$47,MATCH(1,(Plano_Detalhado!$E$10:$E$47=$E15)*($F15=Plano_Detalhado!$F$10:$F$47),0),6)} -> 2. Concluído | H15: {=INDEX(Plano_Detalhado!$B$10:$H$47,MATCH(1,(Plano_Detalhado!$E$10:$E$47=$E15)*($F15=Plano_Detalhado!$F$10:$F$47),0),7)} -> 2. Concluído
A16: =E16&F16 -> lt002_instrumentGNS_FNNCL_TRNSCTN_EXCHNG_DFFRNCS | B16: Green Dashboard | C16: Assessment | D16: {=INDEX(Plano_Detalhado!$B$10:$H$47,MATCH(1,(Plano_Detalhado!$E$10:$E$47=$E16)*($F16=Plano_Detalhado!$F$10:$F$47),0),3)} -> 2. Campo | E16: lt002_instrument | F16: GNS_FNNCL_TRNSCTN_EXCHNG_DFFRNCS | G16: {=INDEX(Plano_Detalhado!$B$10:$H$47,MATCH(1,(Plano_Detalhado!$E$10:$E$47=$E16)*($F16=Plano_Detalhado!$F$10:$F$47),0),6)} -> 2. Concluído | H16: {=INDEX(Plano_Detalhado!$B$10:$H$47,MATCH(1,(Plano_Detalhado!$E$10:$E$47=$E16)*($F16=Plano_Detalhado!$F$10:$F$47),0),7)} -> 2. Concluído
A17: =E17&F17 -> lt002_instrumentFLG_INTRBSNSS | B17: Green Dashboard | C17: Assessment | D17: {=INDEX(Plano_Detalhado!$B$10:$H$47,MATCH(1,(Plano_Detalhado!$E$10:$E$47=$E17)*($F17=Plano_Detalhado!$F$10:$F$47),0),3)} -> 2. Campo | E17: lt002_instrument | F17: FLG_INTRBSNSS | G17: {=INDEX(Plano_Detalhado!$B$10:$H$47,MATCH(1,(Plano_Detalhado!$E$10:$E$47=$E17)*($F17=Plano_Detalhado!$F$10:$F$47),0),6)} -> 3. Em Análise | H17: {=INDEX(Plano_Detalhado!$B$10:$H$47,MATCH(1,(Plano_Detalhado!$E$10:$E$47=$E17)*($F17=Plano_Detalhado!$F$10:$F$47),0),7)} -> 8. Por Iniciar
A18: =E18&F18 -> lt002_instrumentINTRBSNSS_ADJ_COD | B18: Green Dashboard | C18: Assessment | D18: {=INDEX(Plano_Detalhado!$B$10:$H$47,MATCH(1,(Plano_Detalhado!$E$10:$E$47=$E18)*($F18=Plano_Detalhado!$F$10:$F$47),0),3)} -> 2. Campo | E18: lt002_instrument | F18: INTRBSNSS_ADJ_COD | G18: {=INDEX(Plano_Detalhado!$B$10:$H$47,MATCH(1,(Plano_Detalhado!$E$10:$E$47=$E18)*($F18=Plano_Detalhado!$F$10:$F$47),0),6)} -> 3. Em Análise | H18: {=INDEX(Plano_Detalhado!$B$10:$H$47,MATCH(1,(Plano_Detalhado!$E$10:$E$47=$E18)*($F18=Plano_Detalhado!$F$10:$F$47),0),7)} -> 8. Por Iniciar
... A31: =E31&F31 -> lt002_instrumentGRSS_CMMSSN_EXPNS_CCRR | B31: Green Dashboard | C31: Assessment | D31: {=INDEX(Plano_Detalhado!$B$10:$H$47,MATCH(1,(Plano_Detalhado!$E$10:$E$47=$E31)*($F31=Plano_Detalhado!$F$10:$F$47),0),3)} -> 2. Campo | E31: lt002_instrument | F31: GRSS_CMMSSN_EXPNS_CCRR | G31: {=INDEX(Plano_Detalhado!$B$10:$H$47,MATCH(1,(Plano_Detalhado!$E$10:$E$47=$E31)*($F31=Plano_Detalhado!$F$10:$F$47),0),6)} -> 2. Concluído | H31: {=INDEX(Plano_Detalhado!$B$10:$H$47,MATCH(1,(Plano_Detalhado!$E$10:$E$47=$E31)*($F31=Plano_Detalhado!$F$10:$F$47),0),7)} -> 8. Por Iniciar
B32: Green Dashboard | C32: Assessment | D32: {=INDEX(Plano_Detalhado!$B$10:$H$47,MATCH(1,(Plano_Detalhado!$E$10:$E$47=$E32)*($F32=Plano_Detalhado!$F$10:$F$47),0),3)} -> 2. Campo | E32: lt002_instrument | F32: GNS_FNNCL_TRNSCTN_EXCHNG_CCRR | G32: {=INDEX(Plano_Detalhado!$B$10:$H$47,MATCH(1,(Plano_Detalhado!$E$10:$E$47=$E32)*($F32=Plano_Detalhado!$F$10:$F$47),0),6)} -> 2. Concluído | H32: {=INDEX(Plano_Detalhado!$B$10:$H$47,MATCH(1,(Plano_Detalhado!$E$10:$E$47=$E32)*($F32=Plano_Detalhado!$F$10:$F$47),0),7)} -> 8. Por Iniciar
B33: Green Dashboard | C33: Assessment | D33: {=INDEX(Plano_Detalhado!$B$10:$H$47,MATCH(1,(Plano_Detalhado!$E$10:$E$47=$E33)*($F33=Plano_Detalhado!$F$10:$F$47),0),3)} -> 2. Campo | E33: lt002_instrument | F33: BSNSS_AREA_CCRR | G33: {=INDEX(Plano_Detalhado!$B$10:$H$47,MATCH(1,(Plano_Detalhado!$E$10:$E$47=$E33)*($F33=Plano_Detalhado!$F$10:$F$47),0),6)} -> 2. Concluído | H33: {=INDEX(Plano_Detalhado!$B$10:$H$47,MATCH(1,(Plano_Detalhado!$E$10:$E$47=$E33)*($F33=Plano_Detalhado!$F$10:$F$47),0),7)} -> 8. Por Iniciar
B34: Green Dashboard | C34: Assessment | D34: {=INDEX(Plano_Detalhado!$B$10:$H$47,MATCH(1,(Plano_Detalhado!$E$10:$E$47=$E34)*($F34=Plano_Detalhado!$F$10:$F$47),0),3)} -> 2. Campo | E34: lt002_instrument | F34: GRSS_CMMSSN_INCM_OFF_BLNC_CCRR | G34: {=INDEX(Plano_Detalhado!$B$10:$H$47,MATCH(1,(Plano_Detalhado!$E$10:$E$47=$E34)*($F34=Plano_Detalhado!$F$10:$F$47),0),6)} -> 2. Concluído | H34: {=INDEX(Plano_Detalhado!$B$10:$H$47,MATCH(1,(Plano_Detalhado!$E$10:$E$47=$E34)*($F34=Plano_Detalhado!$F$10:$F$47),0),7)} -> 8. Por Iniciar
B35: Green Dashboard | C35: Assessment | D35: {=INDEX(Plano_Detalhado!$B$10:$H$47,MATCH(1,(Plano_Detalhado!$E$10:$E$47=$E35)*($F35=Plano_Detalhado!$F$10:$F$47),0),3)} -> 2. Campo | E35: lt002_instrument | F35: GRSS_CMMSSN_EXPNS_OFF_BLNC_CCRR | G35: {=INDEX(Plano_Detalhado!$B$10:$H$47,MATCH(1,(Plano_Detalhado!$E$10:$E$47=$E35)*($F35=Plano_Detalhado!$F$10:$F$47),0),6)} -> 2. Concluído | H35: {=INDEX(Plano_Detalhado!$B$10:$H$47,MATCH(1,(Plano_Detalhado!$E$10:$E$47=$E35)*($F35=Plano_Detalhado!$F$10:$F$47),0),7)} -> 8. Por Iniciar
B36: Green Dashboard | C36: Assessment | D36: {=INDEX(Plano_Detalhado!$B$10:$H$47,MATCH(1,(Plano_Detalhado!$E$10:$E$47=$E36)*($F36=Plano_Detalhado!$F$10:$F$47),0),3)} -> 2. Campo | E36: lt002_instrument | F36: FLG_INSTRMNT_CNCLLD | G36: {=INDEX(Plano_Detalhado!$B$10:$H$47,MATCH(1,(Plano_Detalhado!$E$10:$E$47=$E36)*($F36=Plano_Detalhado!$F$10:$F$47),0),6)} -> 0. Cancelado | H36: {=INDEX(Plano_Detalhado!$B$10:$H$47,MATCH(1,(Plano_Detalhado!$E$10:$E$47=$E36)*($F36=Plano_Detalhado!$F$10:$F$47),0),7)} -> 0. Cancelado
B37: Green Dashboard | C37: Assessment | D37: {=INDEX(Plano_Detalhado!$B$10:$H$47,MATCH(1,(Plano_Detalhado!$E$10:$E$47=$E37)*($F37=Plano_Detalhado!$F$10:$F$47),0),3)} -> 2. Campo | E37: lt824_assoc_kpi_gd | F37: ambito | G37: {=INDEX(Plano_Detalhado!$B$10:$H$47,MATCH(1,(Plano_Detalhado!$E$10:$E$47=$E37)*($F37=Plano_Detalhado!$F$10:$F$47),0),6)} -> 2. Concluído | H37: {=INDEX(Plano_Detalhado!$B$10:$H$47,MATCH(1,(Plano_Detalhado!$E$10:$E$47=$E37)*($F37=Plano_Detalhado!$F$10:$F$47),0),7)} -> 3. Em Análise
B38: Green Dashboard | C38: Assessment | D38: {=INDEX(Plano_Detalhado!$B$10:$H$47,MATCH(1,(Plano_Detalhado!$E$10:$E$47=$E38)*($F38=Plano_Detalhado!$F$10:$F$47),0),3)} -> 2. Campo | E38: lt824_assoc_kpi_gd | F38: tipo_conta_local | G38: {=INDEX(Plano_Detalhado!$B$10:$H$47,MATCH(1,(Plano_Detalhado!$E$10:$E$47=$E38)*($F38=Plano_Detalhado!$F$10:$F$47),0),6)} -> 2. Concluído | H38: {=INDEX(Plano_Detalhado!$B$10:$H$47,MATCH(1,(Plano_Detalhado!$E$10:$E$47=$E38)*($F38=Plano_Detalhado!$F$10:$F$47),0),7)} -> 3. Em Análise
B39: Green Dashboard | C39: Assessment | D39: {=INDEX(Plano_Detalhado!$B$10:$H$47,MATCH(1,(Plano_Detalhado!$E$10:$E$47=$E39)*($F39=Plano_Detalhado!$F$10:$F$47),0),3)} -> 2. Campo | E39: lt824_assoc_kpi_gd | F39: valor_gd | G39: {=INDEX(Plano_Detalhado!$B$10:$H$47,MATCH(1,(Plano_Detalhado!$E$10:$E$47=$E39)*($F39=Plano_Detalhado!$F$10:$F$47),0),6)} -> 2. Concluído | H39: {=INDEX(Plano_Detalhado!$B$10:$H$47,MATCH(1,(Plano_Detalhado!$E$10:$E$47=$E39)*($F39=Plano_Detalhado!$F$10:$F$47),0),7)} -> 3. Em Análise
B40: Green Dashboard | C40: Assessment | D40: {=INDEX(Plano_Detalhado!$B$10:$H$47,MATCH(1,(Plano_Detalhado!$E$10:$E$47=$E40)*($F40=Plano_Detalhado!$F$10:$F$47),0),3)} -> 2. Campo | E40: lt824_assoc_kpi_gd | F40: kpi | G40: {=INDEX(Plano_Detalhado!$B$10:$H$47,MATCH(1,(Plano_Detalhado!$E$10:$E$47=$E40)*($F40=Plano_Detalhado!$F$10:$F$47),0),6)} -> 2. Concluído | H40: {=INDEX(Plano_Detalhado!$B$10:$H$47,MATCH(1,(Plano_Detalhado!$E$10:$E$47=$E40)*($F40=Plano_Detalhado!$F$10:$F$47),0),7)} -> 3. Em Análise
B41: Green Dashboard | C41: Assessment | D41: {=INDEX(Plano_Detalhado!$B$10:$H$47,MATCH(1,(Plano_Detalhado!$E$10:$E$47=$E41)*($F41=Plano_Detalhado!$F$10:$F$47),0),3)} -> 2. Campo | E41: lt824_assoc_kpi_gd | F41: ordem | G41: {=INDEX(Plano_Detalhado!$B$10:$H$47,MATCH(1,(Plano_Detalhado!$E$10:$E$47=$E41)*($F41=Plano_Detalhado!$F$10:$F$47),0),6)} -> 2. Concluído | H41: {=INDEX(Plano_Detalhado!$B$10:$H$47,MATCH(1,(Plano_Detalhado!$E$10:$E$47=$E41)*($F41=Plano_Detalhado!$F$10:$F$47),0),7)} -> 3. Em Análise
B42: Green Dashboard | C42: Assessment | D42: {=INDEX(Plano_Detalhado!$B$10:$H$47,MATCH(1,(Plano_Detalhado!$E$10:$E$47=$E42)*($F42=Plano_Detalhado!$F$10:$F$47),0),3)} -> 2. Campo | E42: lt824_assoc_kpi_gd | F42: ref_date | G42: {=INDEX(Plano_Detalhado!$B$10:$H$47,MATCH(1,(Plano_Detalhado!$E$10:$E$47=$E42)*($F42=Plano_Detalhado!$F$10:$F$47),0),6)} -> 2. Concluído | H42: {=INDEX(Plano_Detalhado!$B$10:$H$47,MATCH(1,(Plano_Detalhado!$E$10:$E$47=$E42)*($F42=Plano_Detalhado!$F$10:$F$47),0),7)} -> 3. Em Análise
B43: Green Dashboard | C43: Assessment | D43: {=INDEX(Plano_Detalhado!$B$10:$H$47,MATCH(1,(Plano_Detalhado!$E$10:$E$47=$E43)*($F43=Plano_Detalhado!$F$10:$F$47),0),3)} -> 2. Campo | E43: lt002_instrument | F43: SSTNBL_INDCTR | G43: {=INDEX(Plano_Detalhado!$B$10:$H$47,MATCH(1,(Plano_Detalhado!$E$10:$E$47=$E43)*($F43=Plano_Detalhado!$F$10:$F$47),0),6)} -> 0. Cancelado | H43: {=INDEX(Plano_Detalhado!$B$10:$H$47,MATCH(1,(Plano_Detalhado!$E$10:$E$47=$E43)*($F43=Plano_Detalhado!$F$10:$F$47),0),7)} -> 0. Cancelado
B44: Green Dashboard | C44: Assessment | D44: {=INDEX(Plano_Detalhado!$B$10:$H$47,MATCH(1,(Plano_Detalhado!$E$10:$E$47=$E44)*($F44=Plano_Detalhado!$F$10:$F$47),0),3)} -> 2. Campo | E44: lt002_instrument | F44: SSTNBL_CTGRY | G44: {=INDEX(Plano_Detalhado!$B$10:$H$47,MATCH(1,(Plano_Detalhado!$E$10:$E$47=$E44)*($F44=Plano_Detalhado!$F$10:$F$47),0),6)} -> 0. Cancelado | H44: {=INDEX(Plano_Detalhado!$B$10:$H$47,MATCH(1,(Plano_Detalhado!$E$10:$E$47=$E44)*($F44=Plano_Detalhado!$F$10:$F$47),0),7)} -> 0. Cancelado

Sheet Plano_Detalhado
Q6: Janeiro | AM6: Fevereiro | BG6: Março
Q7: =Q8 -> 45659 | R7: =R8 -> 45660 | S7: =S8 -> 45663 | T7: =T8 -> 45664 | U7: =U8 -> 45665 | V7: =V8 -> 45666 | W7: =W8 -> 45667 | X7: =X8 -> 45670 | ... CA7: =CA8 -> 45747
B8: Âmbito | C8: Sub-âmbito | D8: Tipo de teste | E8: Tabela | F8: Campo | G8: Status Atual | H8: Status Anterior | I8: Horas previstas | J8: Dias | K8: Horas efetivas | L8: Dias efetivos | M8: Status Estimado | N8: Status Real | O8: Desvios | P8: Observações | Q8: 45659 | R8: =WORKDAY(Q8,1) -> 45660 | S8: =WORKDAY(R8,1) -> 45663 | T8: =WORKDAY(S8,1) -> 45664 | U8: =WORKDAY(T8,1) -> 45665 | V8: =WORKDAY(U8,1) -> 45666 | W8: =WORKDAY(V8,1) -> 45667 | X8: =WORKDAY(W8,1) -> 45670 | Y8: =WORKDAY(X8,1) -> 45671 | ... CA8: =WORKDAY(BZ8,1) -> 45747
B9: 1. Assessment | I9: =+Macro_Plano_2025_v1!J15 -> 64 | J9: =I9/8 -> 8 | K9: =SUM(K10:K34) -> 6.5 | L9: =SUM(L10:L34) -> 1.5625 | M9: =SUMPRODUCT(M10:M34,I10:I34)/I9 -> 0.04 | N9: =SUMPRODUCT(N10:N34,J10:J34)/J9 -> 0.04 | O9: =N9-M9 -> 0 | P9: N/A
B10: GD | C10: Exclusivo GD - Campos Deloitte | D10: 2. Campo | E10: lt002_instrument | F10: AVRG_BLNC | G10: 2. Concluído | H10: 2. Concluído | I10: =+$I$9/25 -> 2.56 | J10: =+$J$9/25 -> 0.32 | K10: =SUM(Q10:CA10) -> 0.5 | L10: =K10/8 -> 0.0625 | M10: =100% -> 1 | N10: =100% -> 1 | O10: =N10-M10 -> 0 | P10: N/A | Q10: 0.5
B11: GD | C11: Exclusivo GD - Campos Deloitte | D11: 2. Campo | E11: lt002_instrument | F11: NW_BSNSS | G11: 4. Validação da especificação | H11: 8. Por Iniciar | I11: =+$I$9/25 -> 2.56 | J11: =+$J$9/25 -> 0.32 | K11: =SUM(Q11:CA11) -> 0.5 | L11: 0.0625 | R11: 0.5
B12: GD | C12: Exclusivo GD - Campos Deloitte | D12: 2. Campo | E12: lt002_instrument | F12: GRSS_INTRST_INCM | G12: 2. Concluído | H12: 4. Validação da especificação | I12: =+$I$9/25 -> 2.56 | J12: =+$J$9/25 -> 0.32 | K12: =SUM(Q12:CA12) -> 0.5 | L12: 0.0625 | S12: 0.5
B13: GD | C13: Exclusivo GD - Campos Deloitte | D13: 2. Campo | E13: lt002_instrument | F13: GRSS_CMMSSN_INCM | G13: 2. Concluído | H13: 4. Validação da especificação | I13: =+$I$9/25 -> 2.56 | J13: =+$J$9/25 -> 0.32 | K13: =SUM(Q13:CA13) -> 0 | L13: 0.0625
B14: GD | C14: Exclusivo GD - Campos Deloitte | D14: 2. Campo | E14: lt002_instrument | F14: INTRNL_TRNSFR_RT | G14: 2. Concluído | H14: 2. Concluído | I14: =+$I$9/25 -> 2.56 | J14: =+$J$9/25 -> 0.32 | K14: =SUM(Q14:CA14) -> 1.5 | L14: 0.0625 | R14: 1.5
B15: GD | C15: Exclusivo GD - Campos Deloitte | D15: 2. Campo | E15: lt002_instrument | F15: NT_LN_LSS_PRVSN | G15: 2. Concluído | H15: 2. Concluído | I15: =+$I$9/25 -> 2.56 | J15: =+$J$9/25 -> 0.32 | K15: =SUM(Q15:CA15) -> 0.5 | L15: 0.0625 | R15: 0.5
B16: GD | C16: Exclusivo GD - Campos Deloitte | D16: 2. Campo | E16: lt002_instrument | F16: BSNSS_AREA | G16: 2. Concluído | H16: 8. Por Iniciar | I16: =+$I$9/25 -> 2.56 | J16: =+$J$9/25 -> 0.32 | K16: =SUM(Q16:CA16) -> 0 | L16: 0.0625
B17: GD | C17: Exclusivo GD - Campos Deloitte | D17: 2. Campo | E17: lt002_instrument | F17: MNGMNT_PRDCT | G17: 2. Concluído | H17: 2. Concluído | I17: =+$I$9/25 -> 2.56 | J17: =+$J$9/25 -> 0.32 | K17: =SUM(Q17:CA17) -> 0 | L17: 0.0625
B18: GD | C18: Exclusivo GD - Campos Deloitte | D18: 2. Campo | E18: lt002_instrument | F18: GRSS_CMMSSN_EXPNS | G18: 2. Concluído | H18: 2. Concluído | I18: =+$I$9/25 -> 2.56 | J18: =+$J$9/25 -> 0.32 | K18: =SUM(Q18:CA18) -> 0 | L18: 0.0625
B19: GD | C19: Exclusivo GD - Campos Deloitte | D19: 2. Campo | E19: lt002_instrument | F19: GNS_FNNCL_TRNSCTN_EXCHNG_DFFRNCS | G19: 2. Concluído | H19: 2. Concluído | I19: =+$I$9/25 -> 2.56 | J19: =+$J$9/25 -> 0.32 | K19: =SUM(Q19:CA19) -> 0 | L19: 0.0625
B20: GD | C20: Exclusivo GD - Campos Deloitte | D20: 2. Campo | E20: lt002_instrument | F20: FLG_INTRBSNSS | G20: 3. Em Análise | H20: 8. Por Iniciar | I20: =+$I$9/25 -> 2.56 | J20: =+$J$9/25 -> 0.32 | K20: =SUM(Q20:CA20) -> 0 | L20: 0.0625
B21: GD | C21: Exclusivo GD - Campos Deloitte | D21: 2. Campo | E21: lt002_instrument | F21: INTRBSNSS_ADJ_COD | G21: 3. Em Análise | H21: 8. Por Iniciar | I21: =+$I$9/25 -> 2.56 | J21: =+$J$9/25 -> 0.32 | K21: =SUM(Q21:CA21) -> 0.5 | L21: 0.0625 | R21: 0.5
B22: GD | C22: Exclusivo GD - Campos Deloitte | D22: 2. Campo | E22: lt002_instrument | F22: COD_SOC_DSTNTN | G22: 3. Em Análise | H22: 8. Por Iniciar | I22: =+$I$9/25 -> 2.56 | J22: =+$J$9/25 -> 0.32 | K22: =SUM(Q22:CA22) -> 0.5 | L22: 0.0625 | R22: 0.5
B23: GD | C23: Exclusivo GD - Campos Deloitte | D23: 2. Campo | E23: lt002_instrument | F23: BSNSS_AREA_DSTNTN | G23: 2. Concluído | H23: 8. Por Iniciar | I23: =+$I$9/25 -> 2.56 | J23: =+$J$9/25 -> 0.32 | K23: =SUM(Q23:CA23) -> 0.5 | L23: 0.0625 | R23: 0.5
B24: GD | C24: Exclusivo GD - Campos Deloitte | D24: 2. Campo | E24: lt002_instrument | F24: AVRG_BLNC_OFF_BLNC | G24: 2. Concluído | H24: 2. Concluído | I24: =+$I$9/25 -> 2.56 | J24: =+$J$9/25 -> 0.32 | K24: =SUM(Q24:CA24) -> 0.5 | L24: 0.0625 | R24: 0.5
B25: GD | C25: Exclusivo GD - Campos Deloitte | D25: 2. Campo | E25: lt002_instrument | F25: INTRNL_TRNSFR_RT_OFF_BLNC | G25: 2. Concluído | H25: 4. Validação da especificação | I25: =+$I$9/25 -> 2.56 | J25: =+$J$9/25 -> 0.32 | K25: =SUM(Q25:CA25) -> 0.5 | L25: 0.0625 | R25: 0.5
B26: GD | C26: Exclusivo GD - Campos Deloitte | D26: 2. Campo | E26: lt002_instrument | F26: GRSS_CMMSSN_INCM_OFF_BLNC | G26: 2. Concluído | H26: 4. Validação da especificação | I26: =+$I$9/25 -> 2.56 | J26: =+$J$9/25 -> 0.32 | K26: =SUM(Q26:CA26) -> 0.5 | L26: 0.0625 | R26: 0.5
B27: GD | C27: Exclusivo GD - Campos Deloitte | D27: 2. Campo | E27: lt002_instrument | F27: GRSS_CMMSSN_EXPNS_OFF_BLNC | G27: 2. Concluído | H27: 2. Concluído | I27: =+$I$9/25 -> 2.56 | J27: =+$J$9/25 -> 0.32 | K27: =SUM(Q27:CA27) -> 0 | L27: 0.0625
B28: GD | C28: Exclusivo GD - Campos Deloitte | D28: 2. Campo | E28: lt002_instrument | F28: RWA_OFF_BLNC | G28: 2. Concluído | H28: 4. Validação da especificação | I28: =+$I$9/25 -> 2.56 | J28: =+$J$9/25 -> 0.32 | K28: =SUM(Q28:CA28) -> 0 | L28: 0.0625
B29: GD | C29: Exclusivo GD - Campos Deloitte | D29: 2. Campo | E29: lt002_instrument | F29: GRSS_INTRST_EXPNS | G29: 2. Concluído | H29: 2. Concluído | I29: =+$I$9/25 -> 2.56 | J29: =+$J$9/25 -> 0.32 | K29: =SUM(Q29:CA29) -> 0 | L29: 0.0625
B30: GD | C30: Exclusivo GD - Campos Deloitte | D30: 2. Campo | E30: lt002_instrument | F30: NT_LN_LSS_PRVSN_OFF_BLNC | G30: 2. Concluído | H30: 2. Concluído | I30: =+$I$9/25 -> 2.56 | J30: =+$J$9/25 -> 0.32 | K30: =SUM(Q30:CA30) -> 0 | L30: 0.0625
B31: GD | C31: Exclusivo GD - Campos Deloitte | D31: 2. Campo | E31: lt002_instrument | F31: GRSS_INTRST_INCM_CCRR | G31: 2. Concluído | H31: 8. Por Iniciar | I31: =+$I$9/25 -> 2.56 | J31: =+$J$9/25 -> 0.32 | K31: =SUM(Q31:CA31) -> 0 | L31: 0.0625
B32: GD | C32: Exclusivo GD - Campos Deloitte | D32: 2. Campo | E32: lt002_instrument | F32: GRSS_INTRST_EXPNS_CCRR | G32: 2. Concluído | H32: 8. Por Iniciar | I32: =+$I$9/25 -> 2.56 | J32: =+$J$9/25 -> 0.32 | K32: =SUM(Q32:CA32) -> 0 | L32: 0.0625
B33: GD | C33: Exclusivo GD - Campos Deloitte | D33: 2. Campo | E33: lt002_instrument | F33: GRSS_CMMSSN_INCM_CCRR | G33: 2. Concluído | H33: 8. Por Iniciar | I33: =+$I$9/25 -> 2.56 | J33: =+$J$9/25 -> 0.32 | K33: =SUM(Q33:CA33) -> 0 | L33: 0.0625
B34: GD | C34: Exclusivo GD - Campos Deloitte | D34: 2. Campo | E34: lt002_instrument | F34: GRSS_CMMSSN_EXPNS_CCRR | G34: 2. Concluído | H34: 8. Por Iniciar | I34: =+$I$9/25 -> 2.56 | J34: =+$J$9/25 -> 0.32 | K34: =SUM(Q34:CA34) -> 0 | L34: 0.0625
B35: GD | C35: Exclusivo GD - Campos Deloitte | D35: 2. Campo | E35: lt002_instrument | F35: GNS_FNNCL_TRNSCTN_EXCHNG_CCRR | G35: 2. Concluído | H35: 8. Por Iniciar
B36: GD | C36: Exclusivo GD - Campos Deloitte | D36: 2. Campo | E36: lt002_instrument | F36: BSNSS_AREA_CCRR | G36: 2. Concluído | H36: 8. Por Iniciar
B37: GD | C37: Exclusivo GD - Campos Deloitte | D37: 2. Campo | E37: lt002_instrument | F37: GRSS_CMMSSN_INCM_OFF_BLNC_CCRR | G37: 2. Concluído | H37: 8. Por Iniciar
B38: GD | C38: Exclusivo GD - Campos Deloitte | D38: 2. Campo | E38: lt002_instrument | F38: GRSS_CMMSSN_EXPNS_OFF_BLNC_CCRR | G38: 2. Concluído | H38: 8. Por Iniciar
B39: GD | C39: Exclusivo GD - Campos Deloitte | D39: 2. Campo | E39: lt002_instrument | F39: FLG_INSTRMNT_CNCLLD | G39: 0. Cancelado | H39: 0. Cancelado
B40: GD | C40: Exclusivo GD - Campos Deloitte | D40: 2. Campo | E40: lt824_assoc_kpi_gd | F40: ambito | G40: 2. Concluído | H40: 3. Em Análise
B41: GD | C41: Exclusivo GD - Campos Deloitte | D41: 2. Campo | E41: lt824_assoc_kpi_gd | F41: tipo_conta_local | G41: 2. Concluído | H41: 3. Em Análise
B42: GD | C42: Exclusivo GD - Campos Deloitte | D42: 2. Campo | E42: lt824_assoc_kpi_gd | F42: valor_gd | G42: 2. Concluído | H42: 3. Em Análise
B43: GD | C43: Exclusivo GD - Campos Deloitte | D43: 2. Campo | E43: lt824_assoc_kpi_gd | F43: kpi | G43: 2. Concluído | H43: 3. Em Análise
B44: GD | C44: Exclusivo GD - Campos Deloitte | D44: 2. Campo | E44: lt824_assoc_kpi_gd | F44: ordem | G44: 2. Concluído | H44: 3. Em Análise
B45: GD | C45: Exclusivo GD - Campos Deloitte | D45: 2. Campo | E45: lt824_assoc_kpi_gd | F45: ref_date | G45: 2. Concluído | H45: 3. Em Análise
...

Sheet Macro_Plano_2025_v1
V6: 2 corresponde a 1 dia de trabalho
V7: 49 dias
N8: Janeiro | R8: Fevereiro | U8: Março
C9: ID | D9: Atividade | G9: Status | H9: # Campos | I9: Duração (semana) | J9: Duração (horas) | L9: 45660 | M9: =L9+7 -> 45667 | N9: =M9+7 -> 45674 | O9: =N9+7 -> 45681 | P9: =O9+7 -> 45688 | Q9: =P9+7 -> 45695 | R9: =Q9+7 -> 45702 | S9: =R9+7 -> 45709 | T9: =S9+7 -> 45716 | ... V9: =U9+7 -> 45730
C11: 0. | D11: Gestão Projeto | H11: n.a. | J11: =SUM(L11:V11)*8 -> 41.6 | L11: =0.1*2 -> 0.2 | M11: =0.1*5 -> 0.5 | N11: =0.1*5 -> 0.5 | O11: =0.1*5 -> 0.5 | P11: =0.1*5 -> 0.5 | Q11: =0.1*5 -> 0.5 | R11: =0.1*5 -> 0.5 | S11: =0.1*5 -> 0.5 | T11: =0.1*5 -> 0.5 | ... V11: =0.1*5 -> 0.5
C13: 1. | D13: Set-Up | H13: n.a. | J13: =SUM(L13:M13)*8 -> 32 | L13: 4
C15: 2. | D15: Assessment ao Green Dashboard (Especificação Atual) | H15: n.a. | J15: =SUM(L15:V15)*8 -> 64 | M15: 8
C17: 3. | D17: Testes regressivos aos campos concluidos do GD (âmbito projeto anterior) | H17: =COUNTA(E18:E40) -> 23 | I17: =SUM(I18:I40) -> #VALUE! | J17: =SUM(J18:J40) -> #VALUE! | M17: 2 | N17: =8.25 -> 8.25
B18: =D18&"_"&E18 -> INSTRUMENT_COD_SOC | C18: 3.1. | D18: INSTRUMENT | E18: COD_SOC | I18: =J18/8/5 -> #VALUE! | J18: =SUMIF([1]Aux!B:B,Macro_Plano_2025_v1!B18,[1]Aux!I:I)+SUMIF([1]Aux!B:B,Macro_Plano_2025_v1!B18,[1]Aux!O:O) -> #VALUE! | M18: =J18/8 -> #VALUE!
B19: =D19&"_"&E19 -> INSTRUMENT_SUBPORTFOLIO_ID | C19: 3.2. | D19: INSTRUMENT | E19: SUBPORTFOLIO_ID | I19: =J19/8/5 -> #VALUE! | J19: =SUMIF([1]Aux!B:B,Macro_Plano_2025_v1!B19,[1]Aux!I:I)+SUMIF([1]Aux!B:B,Macro_Plano_2025_v1!B19,[1]Aux!O:O) -> #VALUE! | M19: =J19/8 -> #VALUE!
B20: =D20&"_"&E20 -> INSTRUMENT_DT_RFRNC | C20: 3.3. | D20: INSTRUMENT | E20: DT_RFRNC | I20: =J20/8/5 -> #VALUE! | J20: =SUMIF([1]Aux!B:B,Macro_Plano_2025_v1!B20,[1]Aux!I:I)+SUMIF([1]Aux!B:B,Macro_Plano_2025_v1!B20,[1]Aux!O:O) -> #VALUE! | M20: =J20/8 -> #VALUE!
B21: =D21&"_"&E21 -> INSTRUMENT_DFLT_STTS_INSTRMNT | C21: 3.4. | D21: INSTRUMENT | E21: DFLT_STTS_INSTRMNT | I21: =J21/8/5 -> #VALUE! | J21: =SUMIF([1]Aux!B:B,Macro_Plano_2025_v1!B21,[1]Aux!I:I)+SUMIF([1]Aux!B:B,Macro_Plano_2025_v1!B21,[1]Aux!O:O) -> #VALUE! | M21: =J21/8 -> #VALUE!
B22: =D22&"_"&E22 -> INSTRUMENT_IMPRMNT_STTS | C22: 3.5. | D22: INSTRUMENT | E22: IMPRMNT_STTS | I22: =J22/8/5 -> #VALUE! | J22: =SUMIF([1]Aux!B:B,Macro_Plano_2025_v1!B22,[1]Aux!I:I)+SUMIF([1]Aux!B:B,Macro_Plano_2025_v1!B22,[1]Aux!O:O) -> #VALUE! | M22: =M17-SUM(M18:M21) -> #VALUE! | N22: =(J22/8)-M22 -> #VALUE!
B23: =D23&"_"&E23 -> INSTRUMENT_PRFRMNG_STTS | C23: 3.6. | D23: INSTRUMENT | E23: PRFRMNG_STTS | I23: =J23/8/5 -> #VALUE! | J23: =SUMIF([1]Aux!B:B,Macro_Plano_2025_v1!B23,[1]Aux!I:I)+SUMIF([1]Aux!B:B,Macro_Plano_2025_v1!B23,[1]Aux!O:O) -> #VALUE! | N23: =J23/8 -> #VALUE!
B24: =D24&"_"&E24 -> INSTRUMENT_TYP_INSTRMNT | C24: 3.7. | D24: INSTRUMENT | E24: TYP_INSTRMNT | I24: =J24/8/5 -> #VALUE! | J24: =SUMIF([1]Aux!B:B,Macro_Plano_2025_v1!B24,[1]Aux!I:I)+SUMIF([1]Aux!B:B,Macro_Plano_2025_v1!B24,[1]Aux!O:O) -> #VALUE! | N24: =J24/8 -> #VALUE!
B25: =D25&"_"&E25 -> INSTRUMENT_GRSS_CRRYNG_AMNT_INSTRMNT | C25: 3.8. | D25: INSTRUMENT | E25: GRSS_CRRYNG_AMNT_INSTRMNT | I25: =J25/8/5 -> #VALUE! | J25: =SUMIF([1]Aux!B:B,Macro_Plano_2025_v1!B25,[1]Aux!I:I)+SUMIF([1]Aux!B:B,Macro_Plano_2025_v1!B25,[1]Aux!O:O) -> #VALUE! | N25: =J25/8 -> #VALUE!
B26: =D26&"_"&E26 -> INSTRUMENT_ACCMLTD_CHNGS_FV_CR_INSTRMNT | C26: 3.9. | D26: INSTRUMENT | E26: ACCMLTD_CHNGS_FV_CR_INSTRMNT | I26: =J26/8/5 -> #VALUE! | J26: =SUMIF([1]Aux!B:B,Macro_Plano_2025_v1!B26,[1]Aux!I:I)+SUMIF([1]Aux!B:B,Macro_Plano_2025_v1!B26,[1]Aux!O:O) -> #VALUE! | N26: =J26/8 -> #VALUE!
B27: =D27&"_"&E27 -> INSTRUMENT_ACCNTNG_CLSSFCTN | C27: 3.10. | D27: INSTRUMENT | E27: ACCNTNG_CLSSFCTN | I27: =J27/8/5 -> #VALUE! | J27: =SUMIF([1]Aux!B:B,Macro_Plano_2025_v1!B27,[1]Aux!I:I)+SUMIF([1]Aux!B:B,Macro_Plano_2025_v1!B27,[1]Aux!O:O) -> #VALUE! | N27: =J27/8 -> #VALUE!
B28: =D28&"_"&E28 -> INSTRUMENT_OFF_BLNC_SHT_AMNT_INSTRMNT | C28: 3.11. | D28: INSTRUMENT | E28: OFF_BLNC_SHT_AMNT_INSTRMNT | I28: =J28/8/5 -> #VALUE! | J28: =SUMIF([1]Aux!B:B,Macro_Plano_2025_v1!B28,[1]Aux!I:I)+SUMIF([1]Aux!B:B,Macro_Plano_2025_v1!B28,[1]Aux!O:O) -> #VALUE! | N28: =J28/8 -> #VALUE!
B29: =D29&"_"&E29 -> INSTRUMENT_PRVSNS_OFF_BLNC_SHT | C29: 3.12. | D29: INSTRUMENT | E29: PRVSNS_OFF_BLNC_SHT | I29: =J29/8/5 -> #VALUE! | J29: =SUMIF([1]Aux!B:B,Macro_Plano_2025_v1!B29,[1]Aux!I:I)+SUMIF([1]Aux!B:B,Macro_Plano_2025_v1!B29,[1]Aux!O:O) -> #VALUE! | N29: =J29/8 -> #VALUE!
B30: =D30&"_"&E30 -> INSTRUMENT_RWA | C30: 3.13. | D30: INSTRUMENT | E30: RWA | I30: =J30/8/5 -> #VALUE! | J30: =SUMIF([1]Aux!B:B,Macro_Plano_2025_v1!B30,[1]Aux!I:I)+SUMIF([1]Aux!B:B,Macro_Plano_2025_v1!B30,[1]Aux!O:O) -> #VALUE! | N30: =J30/8 -> #VALUE!
B31: =D31&"_"&E31 -> INSTRUMENT_ACCMLTD_IMPRMNT_INSTRMNT | C31: 3.14. | D31: INSTRUMENT | E31: ACCMLTD_IMPRMNT_INSTRMNT | I31: =J31/8/5 -> #VALUE! | J31: =SUMIF([1]Aux!B:B,Macro_Plano_2025_v1!B31,[1]Aux!I:I)+SUMIF([1]Aux!B:B,Macro_Plano_2025_v1!B31,[1]Aux!O:O) -> #VALUE! | N31: =J31/8 -> #VALUE!
B32: =D32&"_"&E32 -> INSTRUMENT_COD_SOC_INTRGRP | C32: 3.15. | D32: INSTRUMENT | E32: COD_SOC_INTRGRP | I32: =J32/8/5 -> #VALUE! | J32: =SUMIF([1]Aux!B:B,Macro_Plano_2025_v1!B32,[1]Aux!I:I)+SUMIF([1]Aux!B:B,Macro_Plano_2025_v1!B32,[1]Aux!O:O) -> #VALUE! | N32: =J32/8 -> #VALUE!
B33: =D33&"_"&E33 -> INSTRUMENT_LCL_INSTMRNT_ID | C33: 3.16. | D33: INSTRUMENT | E33: LCL_INSTMRNT_ID | I33: =J33/8/5 -> #VALUE! | J33: =SUMIF([1]Aux!B:B,Macro_Plano_2025_v1!B33,[1]Aux!I:I)+SUMIF([1]Aux!B:B,Macro_Plano_2025_v1!B33,[1]Aux!O:O) -> #VALUE! | N33: =J33/8 -> #VALUE!
B34: =D34&"_"&E34 -> INSTRUMENT_FLG_INTRBSNSS | C34: 3.17. | D34: INSTRUMENT | E34: FLG_INTRBSNSS | I34: =J34/8/5 -> #VALUE! | J34: =SUMIF([1]Aux!B:B,Macro_Plano_2025_v1!B34,[1]Aux!I:I)+SUMIF([1]Aux!B:B,Macro_Plano_2025_v1!B34,[1]Aux!O:O) -> #VALUE! | N34: =J34/8 -> #VALUE!
... B40: =D40&"_"&E40 -> INSTRUMENT_RWA_OFF_BLNC | C40: 3.23. | D40: INSTRUMENT | E40: RWA_OFF_BLNC | I40: =J40/8/5 -> #VALUE! | J40: =SUMIF([1]Aux!B:B,Macro_Plano_2025_v1!B40,[1]Aux!I:I)+SUMIF([1]Aux!B:B,Macro_Plano_2025_v1!B40,[1]Aux!O:O) -> #VALUE! | N40: =J40/8 -> #VALUE!
C42: 4. | D42: Re-especificações e especificação de novos requisitos | H42: =COUNTA(E43:E56) -> 14 | I42: =+SUM(I43:I56) -> #VALUE! | J42: =SUM(J43:J56) -> #VALUE! | N42: 1.75 | O42: 0.125
B43: =D43&"_"&E43 -> INSTRUMENT_CCF | C43: 4.1. | D43: INSTRUMENT | E43: CCF | I43: =J43/8/5 -> #VALUE! | J43: =SUMIF([1]Aux!B:B,Macro_Plano_2025_v1!B43,[1]Aux!H:H) -> #VALUE! | N43: =J43/8 -> #VALUE!
B44: =D44&"_"&E44 -> INSTRUMENT_EAD | C44: 4.2. | D44: INSTRUMENT | E44: EAD | I44: =J44/8/5 -> #VALUE! | J44: =SUMIF([1]Aux!B:B,Macro_Plano_2025_v1!B44,[1]Aux!H:H) -> #VALUE! | N44: =J44/8 -> #VALUE!
B45: =D45&"_"&E45 -> INSTRUMENT_TYP_OFF_BLNC_PRDCT | C45: 4.3. | D45: INSTRUMENT | E45: TYP_OFF_BLNC_PRDCT | I45: =J45/8/5 -> #VALUE! | J45: =SUMIF([1]Aux!B:B,Macro_Plano_2025_v1!B45,[1]Aux!H:H) -> #VALUE! | N45: =J45/8 -> #VALUE!
B46: =D46&"_"&E46 -> INSTR_PROTECTION_COD_SOC | C46: 4.4. | D46: INSTR_PROTECTION | E46: COD_SOC | I46: =J46/8/5 -> #VALUE! | J46: =SUMIF([1]Aux!B:B,Macro_Plano_2025_v1!B46,[1]Aux!H:H) -> #VALUE! | N46: =J46/8 -> #VALUE!
B47: =D47&"_"&E47 -> INSTR_PROTECTION_DT_RFRNC | C47: 4.5. | D47: INSTR_PROTECTION | E47: DT_RFRNC | I47: =J47/8/5 -> #VALUE! | J47: =SUMIF([1]Aux!B:B,Macro_Plano_2025_v1!B47,[1]Aux!H:H) -> #VALUE! | N47: =J47/8 -> #VALUE!
B48: =D48&"_"&E48 -> INSTR_PROTECTION_INSTRMNT_ID | C48: 4.6. | D48: INSTR_PROTECTION | E48: INSTRMNT_ID | I48: =J48/8/5 -> #VALUE! | J48: =SUMIF([1]Aux!B:B,Macro_Plano_2025_v1!B48,[1]Aux!H:H) -> #VALUE! | N48: =J48/8 -> #VALUE!
B49: =D49&"_"&E49 -> INSTR_PROTECTION_PRTCTN_ID | C49: 4.7. | D49: INSTR_PROTECTION | E49: PRTCTN_ID | I49: =J49/8/5 -> #VALUE! | J49: =SUMIF([1]Aux!B:B,Macro_Plano_2025_v1!B49,[1]Aux!H:H) -> #VALUE! | N49: =J49/8 -> #VALUE!
B50: =D50&"_"&E50 -> PROTECTION_COD_SOC | C50: 4.8. | D50: PROTECTION | E50: COD_SOC | I50: =J50/8/5 -> #VALUE! | J50: =SUMIF([1]Aux!B:B,Macro_Plano_2025_v1!B50,[1]Aux!H:H) -> #VALUE! | N50: =J50/8 -> #VALUE!
B51: =D51&"_"&E51 -> PROTECTION_DT_RFRNC | C51: 4.9. | D51: PROTECTION | E51: DT_RFRNC | I51: =J51/8/5 -> #VALUE! | J51: =SUMIF([1]Aux!B:B,Macro_Plano_2025_v1!B51,[1]Aux!H:H) -> #VALUE! | N51: =J51/8 -> #VALUE!
B52: =D52&"_"&E52 -> PROTECTION_PRTCTN_ID | C52: 4.10 | D52: PROTECTION | E52: PRTCTN_ID | I52: =J52/8/5 -> #VALUE! | J52: =SUMIF([1]Aux!B:B,Macro_Plano_2025_v1!B52,[1]Aux!H:H) -> #VALUE! | N52: =J52/8 -> #VALUE!
B53: =D53&"_"&E53 -> PROTECTION_TYP_PRTCTN | C53: 4.11. | D53: PROTECTION | E53: TYP_PRTCTN | I53: =J53/8/5 -> #VALUE! | J53: =SUMIF([1]Aux!B:B,Macro_Plano_2025_v1!B53,[1]Aux!H:H) -> #VALUE! | N53: =J53/8 -> #VALUE!
B54: =D54&"_"&E54 -> PROTECTION_PRTCTN_VL | C54: 4.12. | D54: PROTECTION | E54: PRTCTN_VL | I54: =J54/8/5 -> #VALUE! | J54: =SUMIF([1]Aux!B:B,Macro_Plano_2025_v1!B54,[1]Aux!H:H) -> #VALUE! | N54: =J54/8 -> #VALUE!
B55: =D55&"_"&E55 -> PROTECTION_FLG_ELCTRC_VHCL | C55: 4.13. | D55: PROTECTION | E55: FLG_ELCTRC_VHCL | I55: =J55/8/5 -> #VALUE! | J55: =SUMIF([1]Aux!B:B,Macro_Plano_2025_v1!B55,[1]Aux!H:H) -> #VALUE! | N55: =J55/8 -> #VALUE!
...

Sheet Sheet1
B2: Campos Assessment (especificação DTT) | G2: Testes Regressivos (campos concluídos Neyond) | M2: Re-especificações e especificação de novos requisitos | Q2: Simulação/ Testes aos Campos
C3: =COUNTA(C6:C43) -> 38 | H3: =COUNTA(H6:H28) -> 23 | N3: =COUNTA(N6:N19) -> 14 | R3: =COUNTA(R6:R50) -> 45
B5: Tabela | C5: Campo | D5: Status | E5: Notas | G5: Tabela | H5: Campo | I5: Existe na especificação da DTT? | J5: Next Step | K5: Notas | M5: Tabela | N5: Campo | O5: Next Steps | Q5: Tabela | R5: Campo | S5: Existe DTT? | T5: Existe Neyond anterior? | U5: Existe nova especificação? | V5: Notas
B6: lt002_instrument | C6: AVRG_BLNC | D6: 2. Concluído | G6: lt002_instrument | H6: COD_SOC | I6: {=_xlfn.IFNA(IF(INDEX($B$6:$C$43,MATCH(1,(G6=$B$6:$B$43)*(H6=$C$6:$C$43),0),2)=H6,"Sim","Não"),"Não")} -> Não | J6: Validar a qualidade do campo através do teste regressivo | M6: lt002_instrument | N6: CCF | O6: Fazer a especificação do campo | Q6: lt002_instrument | R6: INSTRMNT_ID | S6: {=INDEX($B$6:$C$43,MATCH(1,(Q6=$B$6:$B$43)*(R6=$C$6:$C$43),0),2)} -> #N/A | T6: {=INDEX($G$6:$H$28,MATCH(1,(Q6=$G$6:$G$28)*(R6=$H$6:$H$28),0),2)} -> #N/A | U6: {=INDEX($M$6:$N$19,MATCH(1,(Q6=$M$6:$M$19)*(R6=$N$6:$N$19),0),2)} -> #N/A
B7: lt002_instrument | C7: NW_BSNSS | D7: 8. Por Iniciar | G7: lt002_instrument | H7: SUBPORTFOLIO_ID | I7: {=_xlfn.IFNA(IF(INDEX($B$6:$C$43,MATCH(1,(G7=$B$6:$B$43)*(H7=$C$6:$C$43),0),2)=H7,"Sim","Não"),"Não")} -> Não | J7: Validar a qualidade do campo através do teste regressivo | M7: lt002_instrument | N7: EAD | O7: Fazer a especificação do campo | Q7: lt002_instrument | R7: CCF | S7: {=INDEX($B$6:$C$43,MATCH(1,(Q7=$B$6:$B$43)*(R7=$C$6:$C$43),0),2)} -> #N/A | T7: {=INDEX($G$6:$H$28,MATCH(1,(Q7=$G$6:$G$28)*(R7=$H$6:$H$28),0),2)} -> #N/A | U7: {=INDEX($M$6:$N$19,MATCH(1,(Q7=$M$6:$M$19)*(R7=$N$6:$N$19),0),2)} -> CCF
B8: lt002_instrument | C8: GRSS_INTRST_INCM | D8: 4. Validação da especificação | G8: lt002_instrument | H8: DT_RFRNC | I8: {=_xlfn.IFNA(IF(INDEX($B$6:$C$43,MATCH(1,(G8=$B$6:$B$43)*(H8=$C$6:$C$43),0),2)=H8,"Sim","Não"),"Não")} -> Não | J8: Validar a qualidade do campo através do teste regressivo | M8: lt002_instrument | N8: TYP_OFF_BLNC_PRDCT | O8: Fazer a especificação do campo | Q8: lt002_instrument | R8: EAD | S8: {=INDEX($B$6:$C$43,MATCH(1,(Q8=$B$6:$B$43)*(R8=$C$6:$C$43),0),2)} -> #N/A | T8: {=INDEX($G$6:$H$28,MATCH(1,(Q8=$G$6:$G$28)*(R8=$H$6:$H$28),0),2)} -> #N/A | U8: {=INDEX($M$6:$N$19,MATCH(1,(Q8=$M$6:$M$19)*(R8=$N$6:$N$19),0),2)} -> EAD
B9: lt002_instrument | C9: GRSS_CMMSSN_INCM | D9: 4. Validação da especificação | G9: lt002_instrument | H9: DFLT_STTS_INSTRMNT | I9: {=_xlfn.IFNA(IF(INDEX($B$6:$C$43,MATCH(1,(G9=$B$6:$B$43)*(H9=$C$6:$C$43),0),2)=H9,"Sim","Não"),"Não")} -> Não | J9: Validar a qualidade do campo através do teste regressivo | M9: lt006_instr_protection | N9: COD_SOC | O9: Fazer a especificação do campo | Q9: lt002_instrument | R9: AVRG_BLNC | S9: {=INDEX($B$6:$C$43,MATCH(1,(Q9=$B$6:$B$43)*(R9=$C$6:$C$43),0),2)} -> AVRG_BLNC | T9: {=INDEX($G$6:$H$28,MATCH(1,(Q9=$G$6:$G$28)*(R9=$H$6:$H$28),0),2)} -> #N/A | U9: {=INDEX($M$6:$N$19,MATCH(1,(Q9=$M$6:$M$19)*(R9=$N$6:$N$19),0),2)} -> #N/A
B10: lt002_instrument | C10: INTRNL_TRNSFR_RT | D10: 2. Concluído | G10: lt002_instrument | H10: IMPRMNT_STTS | I10: {=_xlfn.IFNA(IF(INDEX($B$6:$C$43,MATCH(1,(G10=$B$6:$B$43)*(H10=$C$6:$C$43),0),2)=H10,"Sim","Não"),"Não")} -> Não | J10: Validar a qualidade do campo através do teste regressivo | M10: lt006_instr_protection | N10: DT_RFRNC | O10: Fazer a especificação do campo | Q10: lt002_instrument | R10: NW_BSNSS | S10: {=INDEX($B$6:$C$43,MATCH(1,(Q10=$B$6:$B$43)*(R10=$C$6:$C$43),0),2)} -> NW_BSNSS | T10: {=INDEX($G$6:$H$28,MATCH(1,(Q10=$G$6:$G$28)*(R10=$H$6:$H$28),0),2)} -> #N/A | U10: {=INDEX($M$6:$N$19,MATCH(1,(Q10=$M$6:$M$19)*(R10=$N$6:$N$19),0),2)} -> #N/A
B11: lt002_instrument | C11: NT_LN_LSS_PRVSN | D11: 2. Concluído | G11: lt002_instrument | H11: PRFRMNG_STTS | I11: {=_xlfn.IFNA(IF(INDEX($B$6:$C$43,MATCH(1,(G11=$B$6:$B$43)*(H11=$C$6:$C$43),0),2)=H11,"Sim","Não"),"Não")} -> Não | J11: Validar a qualidade do campo através do teste regressivo | M11: lt006_instr_protection | N11: INSTRMNT_ID | O11: Fazer a especificação do campo | Q11: lt002_instrument | R11: GRSS_INTRST_INCM | S11: {=INDEX($B$6:$C$43,MATCH(1,(Q11=$B$6:$B$43)*(R11=$C$6:$C$43),0),2)} -> GRSS_INTRST_INCM | T11: {=INDEX($G$6:$H$28,MATCH(1,(Q11=$G$6:$G$28)*(R11=$H$6:$H$28),0),2)} -> #N/A | U11: {=INDEX($M$6:$N$19,MATCH(1,(Q11=$M$6:$M$19)*(R11=$N$6:$N$19),0),2)} -> #N/A
B12: lt002_instrument | C12: BSNSS_AREA | D12: 8. Por Iniciar | G12: lt002_instrument | H12: TYP_INSTRMNT | I12: {=_xlfn.IFNA(IF(INDEX($B$6:$C$43,MATCH(1,(G12=$B$6:$B$43)*(H12=$C$6:$C$43),0),2)=H12,"Sim","Não"),"Não")} -> Não | J12: Validar a qualidade do campo através do teste regressivo | M12: lt006_instr_protection | N12: PRTCTN_ID | O12: Fazer a especificação do campo | Q12: lt002_instrument | R12: GRSS_CMMSSN_INCM | S12: {=INDEX($B$6:$C$43,MATCH(1,(Q12=$B$6:$B$43)*(R12=$C$6:$C$43),0),2)} -> GRSS_CMMSSN_INCM | T12: {=INDEX($G$6:$H$28,MATCH(1,(Q12=$G$6:$G$28)*(R12=$H$6:$H$28),0),2)} -> #N/A | U12: {=INDEX($M$6:$N$19,MATCH(1,(Q12=$M$6:$M$19)*(R12=$N$6:$N$19),0),2)} -> #N/A
B13: lt002_instrument | C13: MNGMNT_PRDCT | D13: 2. Concluído | G13: lt002_instrument | H13: GRSS_CRRYNG_AMNT_INSTRMNT | I13: {=_xlfn.IFNA(IF(INDEX($B$6:$C$43,MATCH(1,(G13=$B$6:$B$43)*(H13=$C$6:$C$43),0),2)=H13,"Sim","Não"),"Não")} -> Não | J13: Validar a qualidade do campo através do teste regressivo | M13: lt004_protection | N13: COD_SOC | O13: Fazer a especificação do campo | Q13: lt002_instrument | R13: INTRNL_TRNSFR_RT | S13: {=INDEX($B$6:$C$43,MATCH(1,(Q13=$B$6:$B$43)*(R13=$C$6:$C$43),0),2)} -> INTRNL_TRNSFR_RT | T13: {=INDEX($G$6:$H$28,MATCH(1,(Q13=$G$6:$G$28)*(R13=$H$6:$H$28),0),2)} -> #N/A | U13: {=INDEX($M$6:$N$19,MATCH(1,(Q13=$M$6:$M$19)*(R13=$N$6:$N$19),0),2)} -> #N/A
B14: lt002_instrument | C14: GRSS_CMMSSN_EXPNS | D14: 2. Concluído | G14: lt002_instrument | H14: ACCMLTD_CHNGS_FV_CR_INSTRMNT | I14: {=_xlfn.IFNA(IF(INDEX($B$6:$C$43,MATCH(1,(G14=$B$6:$B$43)*(H14=$C$6:$C$43),0),2)=H14,"Sim","Não"),"Não")} -> Não | J14: Validar a qualidade do campo através do teste regressivo | M14: lt004_protection | N14: DT_RFRNC | O14: Fazer a especificação do campo | Q14: lt002_instrument | R14: NT_LN_LSS_PRVSN | S14: {=INDEX($B$6:$C$43,MATCH(1,(Q14=$B$6:$B$43)*(R14=$C$6:$C$43),0),2)} -> NT_LN_LSS_PRVSN | T14: {=INDEX($G$6:$H$28,MATCH(1,(Q14=$G$6:$G$28)*(R14=$H$6:$H$28),0),2)} -> #N/A | U14: {=INDEX($M$6:$N$19,MATCH(1,(Q14=$M$6:$M$19)*(R14=$N$6:$N$19),0),2)} -> #N/A
B15: lt002_instrument | C15: GNS_FNNCL_TRNSCTN_EXCHNG_DFFRNCS | D15: 2. Concluído | G15: lt002_instrument | H15: ACCNTNG_CLSSFCTN | I15: {=_xlfn.IFNA(IF(INDEX($B$6:$C$43,MATCH(1,(G15=$B$6:$B$43)*(H15=$C$6:$C$43),0),2)=H15,"Sim","Não"),"Não")} -> Não | J15: Validar a qualidade do campo através do teste regressivo | M15: lt004_protection | N15: PRTCTN_ID | O15: Fazer a especificação do campo | Q15: lt002_instrument | R15: BSNSS_AREA | S15: {=INDEX($B$6:$C$43,MATCH(1,(Q15=$B$6:$B$43)*(R15=$C$6:$C$43),0),2)} -> BSNSS_AREA | T15: {=INDEX($G$6:$H$28,MATCH(1,(Q15=$G$6:$G$28)*(R15=$H$6:$H$28),0),2)} -> #N/A | U15: {=INDEX($M$6:$N$19,MATCH(1,(Q15=$M$6:$M$19)*(R15=$N$6:$N$19),0),2)} -> #N/A
B16: lt002_instrument | C16: FLG_INTRBSNSS | D16: 8. Por Iniciar | G16: lt002_instrument | H16: OFF_BLNC_SHT_AMNT_INSTRMNT | I16: {=_xlfn.IFNA(IF(INDEX($B$6:$C$43,MATCH(1,(G16=$B$6:$B$43)*(H16=$C$6:$C$43),0),2)=H16,"Sim","Não"),"Não")} -> Não | J16: Validar a qualidade do campo através do teste regressivo | M16: lt004_protection | N16: TYP_PRTCTN | O16: Fazer a especificação do campo | Q16: lt002_instrument | R16: MNGMNT_PRDCT | S16: {=INDEX($B$6:$C$43,MATCH(1,(Q16=$B$6:$B$43)*(R16=$C$6:$C$43),0),2)} -> MNGMNT_PRDCT | T16: {=INDEX($G$6:$H$28,MATCH(1,(Q16=$G$6:$G$28)*(R16=$H$6:$H$28),0),2)} -> #N/A | U16: {=INDEX($M$6:$N$19,MATCH(1,(Q16=$M$6:$M$19)*(R16=$N$6:$N$19),0),2)} -> #N/A
B17: lt002_instrument | C17: INTRBSNSS_ADJ_COD | D17: 8. Por Iniciar | G17: lt002_instrument | H17: PRVSNS_OFF_BLNC_SHT | I17: {=_xlfn.IFNA(IF(INDEX($B$6:$C$43,MATCH(1,(G17=$B$6:$B$43)*(H17=$C$6:$C$43),0),2)=H17,"Sim","Não"),"Não")} -> Não | J17: Validar a qualidade do campo através do teste regressivo | M17: lt004_protection | N17: PRTCTN_VL | O17: Fazer a especificação do campo | Q17: lt002_instrument | R17: GRSS_CMMSSN_EXPNS | S17: {=INDEX($B$6:$C$43,MATCH(1,(Q17=$B$6:$B$43)*(R17=$C$6:$C$43),0),2)} -> GRSS_CMMSSN_EXPNS | T17: {=INDEX($G$6:$H$28,MATCH(1,(Q17=$G$6:$G$28)*(R17=$H$6:$H$28),0),2)} -> #N/A | U17: {=INDEX($M$6:$N$19,MATCH(1,(Q17=$M$6:$M$19)*(R17=$N$6:$N$19),0),2)} -> #N/A
B18: lt002_instrument | C18: COD_SOC_DSTNTN | D18: 8. Por Iniciar | G18: lt002_instrument | H18: RWA | I18: {=_xlfn.IFNA(IF(INDEX($B$6:$C$43,MATCH(1,(G18=$B$6:$B$43)*(H18=$C$6:$C$43),0),2)=H18,"Sim","Não"),"Não")} -> Não | J18: Validar a qualidade do campo através do teste regressivo | L18: falar com mafalda do leasing | M18: lt004_protection | N18: FLG_ELCTRC_VHCL | O18: Fazer a especificação do campo | Q18: lt002_instrument | R18: GNS_FNNCL_TRNSCTN_EXCHNG_DFFRNCS | S18: {=INDEX($B$6:$C$43,MATCH(1,(Q18=$B$6:$B$43)*(R18=$C$6:$C$43),0),2)} -> GNS_FNNCL_TRNSCTN_EXCHNG_DFFRNCS | T18: {=INDEX($G$6:$H$28,MATCH(1,(Q18=$G$6:$G$28)*(R18=$H$6:$H$28),0),2)} -> #N/A | U18: {=INDEX($M$6:$N$19,MATCH(1,(Q18=$M$6:$M$19)*(R18=$N$6:$N$19),0),2)} -> #N/A
B19: lt002_instrument | C19: BSNSS_AREA_DSTNTN | D19: 8. Por Iniciar | G19: lt002_instrument | H19: ACCMLTD_IMPRMNT_INSTRMNT | I19: {=_xlfn.IFNA(IF(INDEX($B$6:$C$43,MATCH(1,(G19=$B$6:$B$43)*(H19=$C$6:$C$43),0),2)=H19,"Sim","Não"),"Não")} -> Não | J19: Validar a qualidade do campo através do teste regressivo | M19: lt007_instr_activity | N19: PRCNTG_ACTVTY | O19: Fazer a especificação do campo | Q19: lt002_instrument | R19: AVRG_BLNC_OFF_BLNC | S19: {=INDEX($B$6:$C$43,MATCH(1,(Q19=$B$6:$B$43)*(R19=$C$6:$C$43),0),2)} -> AVRG_BLNC_OFF_BLNC | T19: {=INDEX($G$6:$H$28,MATCH(1,(Q19=$G$6:$G$28)*(R19=$H$6:$H$28),0),2)} -> #N/A | U19: {=INDEX($M$6:$N$19,MATCH(1,(Q19=$M$6:$M$19)*(R19=$N$6:$N$19),0),2)} -> #N/A
B20: lt002_instrument | C20: AVRG_BLNC_OFF_BLNC | D20: 2. Concluído | G20: lt002_instrument | H20: COD_SOC_INTRGRP | I20: {=_xlfn.IFNA(IF(INDEX($B$6:$C$43,MATCH(1,(G20=$B$6:$B$43)*(H20=$C$6:$C$43),0),2)=H20,"Sim","Não"),"Não")} -> Não | J20: Validar a qualidade do campo através do teste regressivo | M20: lt002_instrument | N20: CNCLLD_INSTRMNT_STTS | O20: Fazer a especificação do campo | Q20: lt002_instrument | R20: GRSS_CMMSSN_INCM_OFF_BLNC | S20: {=INDEX($B$6:$C$43,MATCH(1,(Q20=$B$6:$B$43)*(R20=$C$6:$C$43),0),2)} -> GRSS_CMMSSN_INCM_OFF_BLNC | T20: {=INDEX($G$6:$H$28,MATCH(1,(Q20=$G$6:$G$28)*(R20=$H$6:$H$28),0),2)} -> #N/A | U20: {=INDEX($M$6:$N$19,MATCH(1,(Q20=$M$6:$M$19)*(R20=$N$6:$N$19),0),2)} -> #N/A
B21: lt002_instrument | C21: INTRNL_TRNSFR_RT_OFF_BLNC | D21: 4. Validação da especificação | G21: lt002_instrument | H21: LCL_INSTMRNT_ID | I21: {=_xlfn.IFNA(IF(INDEX($B$6:$C$43,MATCH(1,(G21=$B$6:$B$43)*(H21=$C$6:$C$43),0),2)=H21,"Sim","Não"),"Não")} -> Não | J21: Validar a qualidade do campo através do teste regressivo | L21: ver c/ JB e HF | M21: lt007_instr_activity | N21: SSTNBL_INDCTR | O21: Fazer a especificação do campo, capitalizar info do Pilar 3, e necessário desagregar por linhas | P21: colocar em curso a especificação | Q21: lt002_instrument | R21: GRSS_CMMSSN_EXPNS_OFF_BLNC | S21: {=INDEX($B$6:$C$43,MATCH(1,(Q21=$B$6:$B$43)*(R21=$C$6:$C$43),0),2)} -> GRSS_CMMSSN_EXPNS_OFF_BLNC | T21: {=INDEX($G$6:$H$28,MATCH(1,(Q21=$G$6:$G$28)*(R21=$H$6:$H$28),0),2)} -> #N/A | U21: {=INDEX($M$6:$N$19,MATCH(1,(Q21=$M$6:$M$19)*(R21=$N$6:$N$19),0),2)} -> #N/A
B22: lt002_instrument | C22: GRSS_CMMSSN_INCM_OFF_BLNC | D22: 4. Validação da especificação | G22: lt002_instrument | H22: FLG_INTRBSNSS | I22: {=_xlfn.IFNA(IF(INDEX($B$6:$C$43,MATCH(1,(G22=$B$6:$B$43)*(H22=$C$6:$C$43),0),2)=H22,"Sim","Não"),"Não")} -> Sim | J22: Revalidar especificação --> validar a qualidade do campo através do teste regressivo | K22: A aguardar feedback da equipa anterior da Neyond | L22: ver c/ JB e HF | M22: lt007_instr_activity | N22: SSTNBL_CTGRY | O22: Fazer a especificação do campo, capitalizar info do Pilar 3, e necessário desagregar por linhas | P22: colocar em curso a especificação | Q22: lt002_instrument | R22: GRSS_INTRST_EXPNS | S22: {=INDEX($B$6:$C$43,MATCH(1,(Q22=$B$6:$B$43)*(R22=$C$6:$C$43),0),2)} -> GRSS_INTRST_EXPNS | T22: {=INDEX($G$6:$H$28,MATCH(1,(Q22=$G$6:$G$28)*(R22=$H$6:$H$28),0),2)} -> #N/A | U22: {=INDEX($M$6:$N$19,MATCH(1,(Q22=$M$6:$M$19)*(R22=$N$6:$N$19),0),2)} -> #N/A
B23: lt002_instrument | C23: GRSS_CMMSSN_EXPNS_OFF_BLNC | D23: 2. Concluído | G23: lt002_instrument | H23: INTRBSNSS_ADJ_COD | I23: {=_xlfn.IFNA(IF(INDEX($B$6:$C$43,MATCH(1,(G23=$B$6:$B$43)*(H23=$C$6:$C$43),0),2)=H23,"Sim","Não"),"Não")} -> Sim | J23: Revalidar especificação --> validar a qualidade do campo através do teste regressivo | K23: A aguardar feedback da equipa anterior da Neyond | Q23: lt002_instrument | R23: NT_LN_LSS_PRVSN_OFF_BLNC | S23: {=INDEX($B$6:$C$43,MATCH(1,(Q23=$B$6:$B$43)*(R23=$C$6:$C$43),0),2)} -> NT_LN_LSS_PRVSN_OFF_BLNC | T23: {=INDEX($G$6:$H$28,MATCH(1,(Q23=$G$6:$G$28)*(R23=$H$6:$H$28),0),2)} -> #N/A | U23: {=INDEX($M$6:$N$19,MATCH(1,(Q23=$M$6:$M$19)*(R23=$N$6:$N$19),0),2)} -> #N/A
B24: lt002_instrument | C24: RWA_OFF_BLNC | D24: 4. Validação da especificação | G24: lt002_instrument | H24: COD_SOC_DSTNTN | I24: {=_xlfn.IFNA(IF(INDEX($B$6:$C$43,MATCH(1,(G24=$B$6:$B$43)*(H24=$C$6:$C$43),0),2)=H24,"Sim","Não"),"Não")} -> Sim | J24: Revalidar especificação --> validar a qualidade do campo através do teste regressivo | K24: A aguardar feedback da equipa anterior da Neyond | Q24: lt002_instrument | R24: GRSS_INTRST_INCM_CCRR | S24: {=INDEX($B$6:$C$43,MATCH(1,(Q24=$B$6:$B$43)*(R24=$C$6:$C$43),0),2)} -> GRSS_INTRST_INCM_CCRR | T24: {=INDEX($G$6:$H$28,MATCH(1,(Q24=$G$6:$G$28)*(R24=$H$6:$H$28),0),2)} -> #N/A | U24: {=INDEX($M$6:$N$19,MATCH(1,(Q24=$M$6:$M$19)*(R24=$N$6:$N$19),0),2)} -> #N/A
B25: lt002_instrument | C25: GRSS_INTRST_EXPNS | D25: 2. Concluído | G25: lt002_instrument | H25: BSNSS_AREA_DSTNTN | I25: {=_xlfn.IFNA(IF(INDEX($B$6:$C$43,MATCH(1,(G25=$B$6:$B$43)*(H25=$C$6:$C$43),0),2)=H25,"Sim","Não"),"Não")} -> Sim | J25: Revalidar especificação --> validar a qualidade do campo através do teste regressivo | Q25: lt002_instrument | R25: GRSS_INTRST_EXPNS_CCRR | S25: {=INDEX($B$6:$C$43,MATCH(1,(Q25=$B$6:$B$43)*(R25=$C$6:$C$43),0),2)} -> GRSS_INTRST_EXPNS_CCRR | T25: {=INDEX($G$6:$H$28,MATCH(1,(Q25=$G$6:$G$28)*(R25=$H$6:$H$28),0),2)} -> #N/A | U25: {=INDEX($M$6:$N$19,MATCH(1,(Q25=$M$6:$M$19)*(R25=$N$6:$N$19),0),2)} -> #N/A
B26: lt002_instrument | C26: NT_LN_LSS_PRVSN_OFF_BLNC | D26: 2. Concluído | G26: lt002_instrument | H26: INTRNL_TRNSFR_RT_OFF_BLNC | I26: {=_xlfn.IFNA(IF(INDEX($B$6:$C$43,MATCH(1,(G26=$B$6:$B$43)*(H26=$C$6:$C$43),0),2)=H26,"Sim","Não"),"Não")} -> Sim | J26: Revalidar especificação --> validar a qualidade do campo através do teste regressivo | K26: Especificação validada com CdG. | Q26: lt002_instrument | R26: GRSS_CMMSSN_INCM_CCRR | S26: {=INDEX($B$6:$C$43,MATCH(1,(Q26=$B$6:$B$43)*(R26=$C$6:$C$43),0),2)} -> GRSS_CMMSSN_INCM_CCRR | T26: {=INDEX($G$6:$H$28,MATCH(1,(Q26=$G$6:$G$28)*(R26=$H$6:$H$28),0),2)} -> #N/A | U26: {=INDEX($M$6:$N$19,MATCH(1,(Q26=$M$6:$M$19)*(R26=$N$6:$N$19),0),2)} -> #N/A
B27: lt002_instrument | C27: GRSS_INTRST_INCM_CCRR | D27: 8. Por Iniciar | G27: lt002_instrument | H27: IDCMB | I27: {=_xlfn.IFNA(IF(INDEX($B$6:$C$43,MATCH(1,(G27=$B$6:$B$43)*(H27=$C$6:$C$43),0),2)=H27,"Sim","Não"),"Não")} -> Não | J27: Validar a qualidade do campo através do teste regressivo | Q27: lt002_instrument | R27: GRSS_CMMSSN_EXPNS_CCRR | S27: {=INDEX($B$6:$C$43,MATCH(1,(Q27=$B$6:$B$43)*(R27=$C$6:$C$43),0),2)} -> GRSS_CMMSSN_EXPNS_CCRR | T27: {=INDEX($G$6:$H$28,MATCH(1,(Q27=$G$6:$G$28)*(R27=$H$6:$H$28),0),2)} -> #N/A | U27: {=INDEX($M$6:$N$19,MATCH(1,(Q27=$M$6:$M$19)*(R27=$N$6:$N$19),0),2)} -> #N/A
B28: lt002_instrument | C28: GRSS_INTRST_EXPNS_CCRR | D28: 8. Por Iniciar | G28: lt002_instrument | H28: RWA_OFF_BLNC | I28: {=_xlfn.IFNA(IF(INDEX($B$6:$C$43,MATCH(1,(G28=$B$6:$B$43)*(H28=$C$6:$C$43),0),2)=H28,"Sim","Não"),"Não")} -> Sim | J28: Revalidar especificação --> validar a qualidade do campo através do teste regressivo | K28: Especificação validada com CdG. | Q28: lt002_instrument | R28: GNS_FNNCL_TRNSCTN_EXCHNG_CCRR | S28: {=INDEX($B$6:$C$43,MATCH(1,(Q28=$B$6:$B$43)*(R28=$C$6:$C$43),0),2)} -> GNS_FNNCL_TRNSCTN_EXCHNG_CCRR | T28: {=INDEX($G$6:$H$28,MATCH(1,(Q28=$G$6:$G$28)*(R28=$H$6:$H$28),0),2)} -> #N/A | U28: {=INDEX($M$6:$N$19,MATCH(1,(Q28=$M$6:$M$19)*(R28=$N$6:$N$19),0),2)} -> #N/A
B29: lt002_instrument | C29: GRSS_CMMSSN_INCM_CCRR | D29: 8. Por Iniciar | Q29: lt002_instrument | R29: BSNSS_AREA_CCRR | S29: {=INDEX($B$6:$C$43,MATCH(1,(Q29=$B$6:$B$43)*(R29=$C$6:$C$43),0),2)} -> BSNSS_AREA_CCRR | T29: {=INDEX($G$6:$H$28,MATCH(1,(Q29=$G$6:$G$28)*(R29=$H$6:$H$28),0),2)} -> #N/A | U29: {=INDEX($M$6:$N$19,MATCH(1,(Q29=$M$6:$M$19)*(R29=$N$6:$N$19),0),2)} -> #N/A
B30: lt002_instrument | C30: GRSS_CMMSSN_EXPNS_CCRR | D30: 8. Por Iniciar | Q30: lt002_instrument | R30: GRSS_CMMSSN_INCM_OFF_BLNC_CCRR | S30: {=INDEX($B$6:$C$43,MATCH(1,(Q30=$B$6:$B$43)*(R30=$C$6:$C$43),0),2)} -> GRSS_CMMSSN_INCM_OFF_BLNC_CCRR | T30: {=INDEX($G$6:$H$28,MATCH(1,(Q30=$G$6:$G$28)*(R30=$H$6:$H$28),0),2)} -> #N/A | U30: {=INDEX($M$6:$N$19,MATCH(1,(Q30=$M$6:$M$19)*(R30=$N$6:$N$19),0),2)} -> #N/A
B31: lt002_instrument | C31: GNS_FNNCL_TRNSCTN_EXCHNG_CCRR | D31: 8. Por Iniciar | Q31: lt002_instrument | R31: GRSS_CMMSSN_EXPNS_OFF_BLNC_CCRR | S31: {=INDEX($B$6:$C$43,MATCH(1,(Q31=$B$6:$B$43)*(R31=$C$6:$C$43),0),2)} -> GRSS_CMMSSN_EXPNS_OFF_BLNC_CCRR | T31: {=INDEX($G$6:$H$28,MATCH(1,(Q31=$G$6:$G$28)*(R31=$H$6:$H$28),0),2)} -> #N/A | U31: {=INDEX($M$6:$N$19,MATCH(1,(Q31=$M$6:$M$19)*(R31=$N$6:$N$19),0),2)} -> #N/A
B32: lt002_instrument | C32: BSNSS_AREA_CCRR | D32: 8. Por Iniciar | Q32: lt002_instrument | R32: CNCLLD_INSTRMNT_STTS | S32: {=INDEX($B$6:$C$43,MATCH(1,(Q32=$B$6:$B$43)*(R32=$C$6:$C$43),0),2)} -> #N/A | T32: {=INDEX($G$6:$H$28,MATCH(1,(Q32=$G$6:$G$28)*(R32=$H$6:$H$28),0),2)} -> #N/A | U32: {=INDEX($M$6:$N$19,MATCH(1,(Q32=$M$6:$M$19)*(R32=$N$6:$N$19),0),2)} -> #N/A | V32: Campo que mudou de nome
B33: lt002_instrument | C33: GRSS_CMMSSN_INCM_OFF_BLNC_CCRR | D33: 8. Por Iniciar | Q33: lt002_instrument | R33: TYP_OFF_BLNC_PRDCT | S33: {=INDEX($B$6:$C$43,MATCH(1,(Q33=$B$6:$B$43)*(R33=$C$6:$C$43),0),2)} -> #N/A | T33: {=INDEX($G$6:$H$28,MATCH(1,(Q33=$G$6:$G$28)*(R33=$H$6:$H$28),0),2)} -> #N/A | U33: {=INDEX($M$6:$N$19,MATCH(1,(Q33=$M$6:$M$19)*(R33=$N$6:$N$19),0),2)} -> TYP_OFF_BLNC_PRDCT
B34: lt002_instrument | C34: GRSS_CMMSSN_EXPNS_OFF_BLNC_CCRR | D34: 8. Por Iniciar | Q34: lt006_instr_protection | R34: COD_SOC | S34: {=INDEX($B$6:$C$43,MATCH(1,(Q34=$B$6:$B$43)*(R34=$C$6:$C$43),0),2)} -> #N/A | T34: {=INDEX($G$6:$H$28,MATCH(1,(Q34=$G$6:$G$28)*(R34=$H$6:$H$28),0),2)} -> #N/A | U34: {=INDEX($M$6:$N$19,MATCH(1,(Q34=$M$6:$M$19)*(R34=$N$6:$N$19),0),2)} -> COD_SOC
B35: lt002_instrument | C35: FLG_INSTRMNT_CNCLLD | D35: 0. Cancelado | E35: Novo nome "CNCLLD_INSTRMNT_STTS", e passou de ser um campo Y/N para uma code list | Q35: lt006_instr_protection | R35: DT_RFRNC | S35: {=INDEX($B$6:$C$43,MATCH(1,(Q35=$B$6:$B$43)*(R35=$C$6:$C$43),0),2)} -> #N/A | T35: {=INDEX($G$6:$H$28,MATCH(1,(Q35=$G$6:$G$28)*(R35=$H$6:$H$28),0),2)} -> #N/A | U35: {=INDEX($M$6:$N$19,MATCH(1,(Q35=$M$6:$M$19)*(R35=$N$6:$N$19),0),2)} -> DT_RFRNC
B36: lt824_assoc_kpi_gd | C36: ambito | D36: 3. Em Análise | Q36: lt006_instr_protection | R36: INSTRMNT_ID | S36: {=INDEX($B$6:$C$43,MATCH(1,(Q36=$B$6:$B$43)*(R36=$C$6:$C$43),0),2)} -> #N/A | T36: {=INDEX($G$6:$H$28,MATCH(1,(Q36=$G$6:$G$28)*(R36=$H$6:$H$28),0),2)} -> #N/A | U36: {=INDEX($M$6:$N$19,MATCH(1,(Q36=$M$6:$M$19)*(R36=$N$6:$N$19),0),2)} -> INSTRMNT_ID
B37: lt824_assoc_kpi_gd | C37: tipo_conta_local | D37: 3. Em Análise | Q37: lt006_instr_protection | R37: PRTCTN_ID | S37: {=INDEX($B$6:$C$43,MATCH(1,(Q37=$B$6:$B$43)*(R37=$C$6:$C$43),0),2)} -> #N/A | T37: {=INDEX($G$6:$H$28,MATCH(1,(Q37=$G$6:$G$28)*(R37=$H$6:$H$28),0),2)} -> #N/A | U37: {=INDEX($M$6:$N$19,MATCH(1,(Q37=$M$6:$M$19)*(R37=$N$6:$N$19),0),2)} -> PRTCTN_ID
B38: lt824_assoc_kpi_gd | C38: valor_gd | D38: 3. Em Análise | Q38: lt006_instr_protection | R38: TYP_RLTN | S38: {=INDEX($B$6:$C$43,MATCH(1,(Q38=$B$6:$B$43)*(R38=$C$6:$C$43),0),2)} -> #N/A | T38: {=INDEX($G$6:$H$28,MATCH(1,(Q38=$G$6:$G$28)*(R38=$H$6:$H$28),0),2)} -> #N/A | U38: {=INDEX($M$6:$N$19,MATCH(1,(Q38=$M$6:$M$19)*(R38=$N$6:$N$19),0),2)} -> #N/A
B39: lt824_assoc_kpi_gd | C39: kpi | D39: 3. Em Análise | Q39: lt004_protection | R39: COD_SOC | S39: {=INDEX($B$6:$C$43,MATCH(1,(Q39=$B$6:$B$43)*(R39=$C$6:$C$43),0),2)} -> #N/A | T39: {=INDEX($G$6:$H$28,MATCH(1,(Q39=$G$6:$G$28)*(R39=$H$6:$H$28),0),2)} -> #N/A | U39: {=INDEX($M$6:$N$19,MATCH(1,(Q39=$M$6:$M$19)*(R39=$N$6:$N$19),0),2)} -> COD_SOC
B40: lt824_assoc_kpi_gd | C40: ordem | D40: 3. Em Análise | Q40: lt004_protection | R40: DT_RFRNC | S40: {=INDEX($B$6:$C$43,MATCH(1,(Q40=$B$6:$B$43)*(R40=$C$6:$C$43),0),2)} -> #N/A | T40: {=INDEX($G$6:$H$28,MATCH(1,(Q40=$G$6:$G$28)*(R40=$H$6:$H$28),0),2)} -> #N/A | U40: {=INDEX($M$6:$N$19,MATCH(1,(Q40=$M$6:$M$19)*(R40=$N$6:$N$19),0),2)} -> DT_RFRNC
B41: lt824_assoc_kpi_gd | C41: ref_date | D41: 3. Em Análise | Q41: lt004_protection | R41: PRTCTN_ID | S41: {=INDEX($B$6:$C$43,MATCH(1,(Q41=$B$6:$B$43)*(R41=$C$6:$C$43),0),2)} -> #N/A | T41: {=INDEX($G$6:$H$28,MATCH(1,(Q41=$G$6:$G$28)*(R41=$H$6:$H$28),0),2)} -> #N/A | U41: {=INDEX($M$6:$N$19,MATCH(1,(Q41=$M$6:$M$19)*(R41=$N$6:$N$19),0),2)} -> PRTCTN_ID
B42: lt002_instrument | C42: SSTNBL_INDCTR | D42: 0. Cancelado | E42: Passou para a lt007_instr_activity; capitalizar a info do projeto Pilar 3 | Q42: lt004_protection | R42: TYP_PRTCTN | S42: {=INDEX($B$6:$C$43,MATCH(1,(Q42=$B$6:$B$43)*(R42=$C$6:$C$43),0),2)} -> #N/A | T42: {=INDEX($G$6:$H$28,MATCH(1,(Q42=$G$6:$G$28)*(R42=$H$6:$H$28),0),2)} -> #N/A | U42: {=INDEX($M$6:$N$19,MATCH(1,(Q42=$M$6:$M$19)*(R42=$N$6:$N$19),0),2)} -> TYP_PRTCTN
...

Sheet Auxiliar_GD
B7: Tipo de Teste | C7: Descrição
B8: 1. Universo | C8: Validação do universo
B9: 2. Campo | C9: Validação à informação do campo
B11: Categoria | C11: Descrição | D11: # Campos
B12: Assessment | C12: Validação da especificação efetuada pela Deloitte | D12: 25
B13: Testes Regressivos Campos Concluídos | C13: Testes regressivos aos campos já concluídos
B14: Testes Implementação Campos Novos | C14: Testes aos novos campos de forma a garantir a correta implementação
B15: Testes Regressivos Campos Novos | C15: Testes regressivos de forma a garantir que os novos campos não impactaram outros
B17: Status para Assessment - Campos especificados anteriormente pela Deloitte
B19: Status | C19: Descrição | D19: Owner
B20: 0. Cancelado | C20: Campo cancelado | D20: N/A
B21: 1. Fora de âmbito | C21: Campo não se encontra no âmbito do projeto | D21: N/A
B22: 2. Concluído | C22: Especificação do campo validada com CdG | D22: N/A
B23: 3. Em Análise | C23: Campo em análise pela equipa Neyond | D23: Neyond
