Workbook
Name _1.2.1: MacroPlano!$C$25:$C$31
Name _1.2.2: MacroPlano!$C$25
Name _1.2.3: MacroPlano!$C$26
Name _1.2.4: MacroPlano!$C$27
Name _1.2.5: MacroPlano!$C$28
Name _1.2.6: MacroPlano!$C$29
Name _1.2.7: MacroPlano!$C$30
Name _1.2.8: MacroPlano!$C$31
Name asefadf: #REF!
Name bn: #REF!
Name INTRNL_TRNSFR_RT: MacroPlano!$C$25:$C$31

Sheet 1. Status Resumo
B6: Sumário Executivo | 17/jan a 22/jan
B8: - Envio da documentação (word e excel) com a proposta de especificação to-be do 1º package de campos (20 campos do assessment inicial) para implementação por parte de IT. - Início da análise ao universo que deve ser considerado como contratos intramês. - Especificação dos campos comuns com PM, e atualização da documentação em conformidade.
B15: 1. Assesment | G15: Bens Imóveis - Input | H15: Bens Imóveis - Output | I15: Modelo Verde - Input | J15: Modelo Verde - Output | K15: Pilar III
C18: Resumo | H18: Status (campos) | K18: 45672 | L18: 45679 | M18: % | O18: Highlights
H19: 0. Cancelado | K19: =COUNTIFS('2. Status Detalhe Campos'!$H:$H,'1. Status Resumo'!$H19,'2. Status Detalhe Campos'!$C:$C,"Assessment") -> 3 | L19: =COUNTIFS('2. Status Detalhe Campos'!$G:$G,'1. Status Resumo'!$H19,'2. Status Detalhe Campos'!$C:$C,"Assessment") -> 3 | M19: =L19/$L$25 -> 0.078947368 | O19: Dos 38 campos em âmbito do Assessment inicial, temos: • 3 campos cancelados: - LG_INSTRMNT_CNCLLD: passou a chamar-se CNCLLD_INSTRMNT_STTS e deixou de ser um campo de sim/não e passou a ser uma code list; - SSTNBL_INDCTR: campo continua a existir mas mudou de tabela (passou da lt002_instrument para a lt007_instr_activity); - SSTNBL_CTGRY: campo continua a existir mas mudou de tabela (passou da lt002_instrument para a lt007_instr_activity) • 35 campos concluídos: especificação validada com CdG.
H20: 1. Fora de âmbito | K20: =COUNTIFS('2. Status Detalhe Campos'!$H:$H,'1. Status Resumo'!$H20,'2. Status Detalhe Campos'!$C:$C,"Assessment") -> 0 | L20: =COUNTIFS('2. Status Detalhe Campos'!$G:$G,'1. Status Resumo'!$H20,'2. Status Detalhe Campos'!$C:$C,"Assessment") -> 0 | M20: =L20/$L$25 -> 0
H21: 2. Concluído | K21: =COUNTIFS('2. Status Detalhe Campos'!$H:$H,'1. Status Resumo'!$H21,'2. Status Detalhe Campos'!$C:$C,"Assessment") -> 31 | L21: =COUNTIFS('2. Status Detalhe Campos'!$G:$G,'1. Status Resumo'!$H21,'2. Status Detalhe Campos'!$C:$C,"Assessment") -> 35 | M21: =L21/$L$25 -> 0.92105263
H22: 3. Em Análise | K22: =COUNTIFS('2. Status Detalhe Campos'!$H:$H,'1. Status Resumo'!$H22,'2. Status Detalhe Campos'!$C:$C,"Assessment") -> 3 | L22: =COUNTIFS('2. Status Detalhe Campos'!$G:$G,'1. Status Resumo'!$H22,'2. Status Detalhe Campos'!$C:$C,"Assessment") -> 0 | M22: =L22/$L$25 -> 0
H23: 4. Validação da especificação | K23: =COUNTIFS('2. Status Detalhe Campos'!$H:$H,'1. Status Resumo'!$H23,'2. Status Detalhe Campos'!$C:$C,"Assessment") -> 1 | L23: =COUNTIFS('2. Status Detalhe Campos'!$G:$G,'1. Status Resumo'!$H23,'2. Status Detalhe Campos'!$C:$C,"Assessment") -> 0 | M23: =L23/$L$25 -> 0
H24: 5. Por Iniciar | K24: =COUNTIFS('2. Status Detalhe Campos'!$H:$H,'1. Status Resumo'!$H24,'2. Status Detalhe Campos'!$C:$C,"Assessment") -> 0 | L24: =COUNTIFS('2. Status Detalhe Campos'!$G:$G,'1. Status Resumo'!$H24,'2. Status Detalhe Campos'!$C:$C,"Assessment") -> 0 | M24: =L24/$L$25 -> 0
H25: Total | K25: =SUM(K19:K24) -> 38 | L25: =SUM(L19:L24) -> 38 | M25: =L25/$L$25 -> 1
C30: Detalhe por Tabela
B41: 2. Re-especificação / Especificação
C44: Resumo | H44: Status (campos) | K44: 45679 | L44: 45693 | M44: % | O44: Highlights
H45: 0. Cancelado | K45: =COUNTIFS('2. Status Detalhe Campos'!$H:$H,'1. Status Resumo'!$H45,'2. Status Detalhe Campos'!$C:$C,"Re-especificação / Especificação") -> 0 | L45: =COUNTIFS('2. Status Detalhe Campos'!$G:$G,'1. Status Resumo'!$H45,'2. Status Detalhe Campos'!$C:$C,"Re-especificação / Especificação") -> 0 | M45: =L45/$L$51 -> 0 | O45: Dos 75 campos, temos: • 39 campos concluídos: - 13 campos previamente definidos pela Deloitte, para os quais a sua especificação foi validada com a equipa de CdG, posteriormente atualizada e enviada à equipa de IT. - 4 campos especificados pela equipa anterior. - 22 campos especificados em linha com o que se encontra implementado em âmbito PM. • 14 campos em especificação: - Dos quais, 8 campos são comuns com o Pilar 3 e já nos encontramos em sinergias com a equipa. - 6 campos referentes à tabela de parametrização lt824. • 12 campos em processo de validação de especificação. • 10 campos por iniciar.
H46: 1. Concluído | K46: =COUNTIFS('2. Status Detalhe Campos'!$H:$H,'1. Status Resumo'!$H46,'2. Status Detalhe Campos'!$C:$C,"Re-especificação / Especificação") -> 49 | L46: =COUNTIFS('2. Status Detalhe Campos'!$G:$G,'1. Status Resumo'!$H46,'2. Status Detalhe Campos'!$C:$C,"Re-especificação / Especificação") -> 38 | M46: =L46/$L$51 -> 0.50666667
H47: 2. Em Especificação/Re-especificação | K47: =COUNTIFS('2. Status Detalhe Campos'!$H:$H,'1. Status Resumo'!$H47,'2. Status Detalhe Campos'!$C:$C,"Re-especificação / Especificação") -> 18 | L47: =COUNTIFS('2. Status Detalhe Campos'!$G:$G,'1. Status Resumo'!$H47,'2. Status Detalhe Campos'!$C:$C,"Re-especificação / Especificação") -> 14 | M47: =L47/$L$51 -> 0.18666667
H48: 3. Pendente de outros desenvolvimentos/validações | K48: =COUNTIFS('2. Status Detalhe Campos'!$H:$H,'1. Status Resumo'!$H48,'2. Status Detalhe Campos'!$C:$C,"Re-especificação / Especificação") -> 0 | L48: =COUNTIFS('2. Status Detalhe Campos'!$G:$G,'1. Status Resumo'!$H48,'2. Status Detalhe Campos'!$C:$C,"Re-especificação / Especificação") -> 0 | M48: =L48/$L$51 -> 0
H49: 4. Validação da especificação | K49: =COUNTIFS('2. Status Detalhe Campos'!$H:$H,'1. Status Resumo'!$H49,'2. Status Detalhe Campos'!$C:$C,"Re-especificação / Especificação") -> 0 | L49: =COUNTIFS('2. Status Detalhe Campos'!$G:$G,'1. Status Resumo'!$H49,'2. Status Detalhe Campos'!$C:$C,"Re-especificação / Especificação") -> 12 | M49: =L49/$L$51 -> 0.16
H50: 5. Por Iniciar | K50: =COUNTIFS('2. Status Detalhe Campos'!$H:$H,'1. Status Resumo'!$H50,'2. Status Detalhe Campos'!$C:$C,"Re-especificação / Especificação") -> 7 | L50: =COUNTIFS('2. Status Detalhe Campos'!$G:$G,'1. Status Resumo'!$H50,'2. Status Detalhe Campos'!$C:$C,"Re-especificação / Especificação") -> 11 | M50: =L50/$L$51 -> 0.14666667
H51: Total 1 | K51: =SUM(K45:K50) -> 74 | L51: =SUM(L45:L50) -> 75 | M51: =L51/$L$51 -> 1
H52: 1 No âmbito do projeto, o total de campos é 68. No entanto, a tabela reflete 75 campos uma vez que estão a ser incluidos os campos referentes à lt824 (tabela de parametrização).
H54: Nota: Existe um aumento no número total de campos uma vez que foi adicionado um novo campo ao âmbito GD de acordo com o novo Guia Corporativo.
C56: Detalhe por Tabela

Sheet 2. Status Detalhe Campos
B6: Âmbito | C6: Categoria | D6: Tipo de teste | E6: Tabela | F6: Campo | G6: Status Atual | H6: Status Anterior | I6: Observações | J6: Data de Pedido correção/esclarecimento | K6: Data de correção prevista | L6: Data de correção efetiva | M6: Data Prevista de Re-especificação | N6: Data Prevista de Teste
A7: =E7&F7 -> lt002_instrumentAVRG_BLNC | B7: Green Dashboard | C7: Assessment | D7: {=INDEX('3. Plano_Detalhado'!$A$10:$H$197,MATCH(1,($E7='3. Plano_Detalhado'!$E$10:$E$197)*($F7='3. Plano_Detalhado'!$F$10:$F$197)*($C7='3. Plano_Detalhado'!$A$10:$A$197),0),4)} -> 2. Campo | E7: lt002_instrument | F7: AVRG_BLNC | G7: {=IF(INDEX('3. Plano_Detalhado'!$A$10:$H$197,MATCH(1,($E7='3. Plano_Detalhado'!$E$10:$E$197)*($F7='3. Plano_Detalhado'!$F$10:$F$197)*($C7='3. Plano_Detalhado'!$A$10:$A$197),0),7)="","",INDEX('3. Plano_Detalhado'!$A$10:$H$197,MATCH(1,($E7='3. Plano_Detalhado'!$E$10:$E$197)*($F7='3. Plano_Detalhado'!$F$10:$F$197)*($C7='3. Plano_Detalhado'!$A$10:$A$197),0),7))} -> 2. Concluído | H7: {=IF(INDEX('3. Plano_Detalhado'!$A$10:$H$197,MATCH(1,($E7='3. Plano_Detalhado'!$E$10:$E$197)*($F7='3. Plano_Detalhado'!$F$10:$F$197)*($C7='3. Plano_Detalhado'!$A$10:$A$197),0),8)="","",INDEX('3. Plano_Detalhado'!$A$10:$H$197,MATCH(1,($E7='3. Plano_Detalhado'!$E$10:$E$197)*($F7='3. Plano_Detalhado'!$F$10:$F$197)*($C7='3. Plano_Detalhado'!$A$10:$A$197),0),8))} -> 2. Concluído | I7: {=IF(INDEX('3. Plano_Detalhado'!$A$10:$Q$196,MATCH(1,($E7='3. Plano_Detalhado'!$E$10:$E$196)*($F7='3. Plano_Detalhado'!$F$10:$F$196)*($C7='3. Plano_Detalhado'!$A$10:$A$196),0),17)="","",INDEX('3. Plano_Detalhado'!$A$10:$Q$196,MATCH(1,($E7='3. Plano_Detalhado'!$E$10:$E$196)*($F7='3. Plano_Detalhado'!$F$10:$F$196)*($C7='3. Plano_Detalhado'!$A$10:$A$196),0),17))}
A8: =E8&F8 -> lt002_instrumentNW_BSNSS | B8: Green Dashboard | C8: Assessment | D8: {=INDEX('3. Plano_Detalhado'!$A$10:$H$197,MATCH(1,($E8='3. Plano_Detalhado'!$E$10:$E$197)*($F8='3. Plano_Detalhado'!$F$10:$F$197)*($C8='3. Plano_Detalhado'!$A$10:$A$197),0),4)} -> 2. Campo | E8: lt002_instrument | F8: NW_BSNSS | G8: {=IF(INDEX('3. Plano_Detalhado'!$A$10:$H$197,MATCH(1,($E8='3. Plano_Detalhado'!$E$10:$E$197)*($F8='3. Plano_Detalhado'!$F$10:$F$197)*($C8='3. Plano_Detalhado'!$A$10:$A$197),0),7)="","",INDEX('3. Plano_Detalhado'!$A$10:$H$197,MATCH(1,($E8='3. Plano_Detalhado'!$E$10:$E$197)*($F8='3. Plano_Detalhado'!$F$10:$F$197)*($C8='3. Plano_Detalhado'!$A$10:$A$197),0),7))} -> 2. Concluído | H8: {=IF(INDEX('3. Plano_Detalhado'!$A$10:$H$197,MATCH(1,($E8='3. Plano_Detalhado'!$E$10:$E$197)*($F8='3. Plano_Detalhado'!$F$10:$F$197)*($C8='3. Plano_Detalhado'!$A$10:$A$197),0),8)="","",INDEX('3. Plano_Detalhado'!$A$10:$H$197,MATCH(1,($E8='3. Plano_Detalhado'!$E$10:$E$197)*($F8='3. Plano_Detalhado'!$F$10:$F$197)*($C8='3. Plano_Detalhado'!$A$10:$A$197),0),8))} -> 4. Validação da especificação | I8: {=IF(INDEX('3. Plano_Detalhado'!$A$10:$Q$196,MATCH(1,($E8='3. Plano_Detalhado'!$E$10:$E$196)*($F8='3. Plano_Detalhado'!$F$10:$F$196)*($C8='3. Plano_Detalhado'!$A$10:$A$196),0),17)="","",INDEX('3. Plano_Detalhado'!$A$10:$Q$196,MATCH(1,($E8='3. Plano_Detalhado'!$E$10:$E$196)*($F8='3. Plano_Detalhado'!$F$10:$F$196)*($C8='3. Plano_Detalhado'!$A$10:$A$196),0),17))}
A9: =E9&F9 -> lt002_instrumentGRSS_INTRST_INCM | B9: Green Dashboard | C9: Assessment | D9: {=INDEX('3. Plano_Detalhado'!$A$10:$H$197,MATCH(1,($E9='3. Plano_Detalhado'!$E$10:$E$197)*($F9='3. Plano_Detalhado'!$F$10:$F$197)*($C9='3. Plano_Detalhado'!$A$10:$A$197),0),4)} -> 2. Campo | E9: lt002_instrument | F9: GRSS_INTRST_INCM | G9: {=IF(INDEX('3. Plano_Detalhado'!$A$10:$H$197,MATCH(1,($E9='3. Plano_Detalhado'!$E$10:$E$197)*($F9='3. Plano_Detalhado'!$F$10:$F$197)*($C9='3. Plano_Detalhado'!$A$10:$A$197),0),7)="","",INDEX('3. Plano_Detalhado'!$A$10:$H$197,MATCH(1,($E9='3. Plano_Detalhado'!$E$10:$E$197)*($F9='3. Plano_Detalhado'!$F$10:$F$197)*($C9='3. Plano_Detalhado'!$A$10:$A$197),0),7))} -> 2. Concluído | H9: {=IF(INDEX('3. Plano_Detalhado'!$A$10:$H$197,MATCH(1,($E9='3. Plano_Detalhado'!$E$10:$E$197)*($F9='3. Plano_Detalhado'!$F$10:$F$197)*($C9='3. Plano_Detalhado'!$A$10:$A$197),0),8)="","",INDEX('3. Plano_Detalhado'!$A$10:$H$197,MATCH(1,($E9='3. Plano_Detalhado'!$E$10:$E$197)*($F9='3. Plano_Detalhado'!$F$10:$F$197)*($C9='3. Plano_Detalhado'!$A$10:$A$197),0),8))} -> 2. Concluído | I9: {=IF(INDEX('3. Plano_Detalhado'!$A$10:$Q$196,MATCH(1,($E9='3. Plano_Detalhado'!$E$10:$E$196)*($F9='3. Plano_Detalhado'!$F$10:$F$196)*($C9='3. Plano_Detalhado'!$A$10:$A$196),0),17)="","",INDEX('3. Plano_Detalhado'!$A$10:$Q$196,MATCH(1,($E9='3. Plano_Detalhado'!$E$10:$E$196)*($F9='3. Plano_Detalhado'!$F$10:$F$196)*($C9='3. Plano_Detalhado'!$A$10:$A$196),0),17))}
A10: =E10&F10 -> lt002_instrumentGRSS_CMMSSN_INCM | B10: Green Dashboard | C10: Assessment | D10: {=INDEX('3. Plano_Detalhado'!$A$10:$H$197,MATCH(1,($E10='3. Plano_Detalhado'!$E$10:$E$197)*($F10='3. Plano_Detalhado'!$F$10:$F$197)*($C10='3. Plano_Detalhado'!$A$10:$A$197),0),4)} -> 2. Campo | E10: lt002_instrument | F10: GRSS_CMMSSN_INCM | G10: {=IF(INDEX('3. Plano_Detalhado'!$A$10:$H$197,MATCH(1,($E10='3. Plano_Detalhado'!$E$10:$E$197)*($F10='3. Plano_Detalhado'!$F$10:$F$197)*($C10='3. Plano_Detalhado'!$A$10:$A$197),0),7)="","",INDEX('3. Plano_Detalhado'!$A$10:$H$197,MATCH(1,($E10='3. Plano_Detalhado'!$E$10:$E$197)*($F10='3. Plano_Detalhado'!$F$10:$F$197)*($C10='3. Plano_Detalhado'!$A$10:$A$197),0),7))} -> 2. Concluído | H10: {=IF(INDEX('3. Plano_Detalhado'!$A$10:$H$197,MATCH(1,($E10='3. Plano_Detalhado'!$E$10:$E$197)*($F10='3. Plano_Detalhado'!$F$10:$F$197)*($C10='3. Plano_Detalhado'!$A$10:$A$197),0),8)="","",INDEX('3. Plano_Detalhado'!$A$10:$H$197,MATCH(1,($E10='3. Plano_Detalhado'!$E$10:$E$197)*($F10='3. Plano_Detalhado'!$F$10:$F$197)*($C10='3. Plano_Detalhado'!$A$10:$A$197),0),8))} -> 2. Concluído | I10: {=IF(INDEX('3. Plano_Detalhado'!$A$10:$Q$196,MATCH(1,($E10='3. Plano_Detalhado'!$E$10:$E$196)*($F10='3. Plano_Detalhado'!$F$10:$F$196)*($C10='3. Plano_Detalhado'!$A$10:$A$196),0),17)="","",INDEX('3. Plano_Detalhado'!$A$10:$Q$196,MATCH(1,($E10='3. Plano_Detalhado'!$E$10:$E$196)*($F10='3. Plano_Detalhado'!$F$10:$F$196)*($C10='3. Plano_Detalhado'!$A$10:$A$196),0),17))}
A11: =E11&F11 -> lt002_instrumentINTRNL_TRNSFR_RT | B11: Green Dashboard | C11: Assessment | D11: {=INDEX('3. Plano_Detalhado'!$A$10:$H$197,MATCH(1,($E11='3. Plano_Detalhado'!$E$10:$E$197)*($F11='3. Plano_Detalhado'!$F$10:$F$197)*($C11='3. Plano_Detalhado'!$A$10:$A$197),0),4)} -> 2. Campo | E11: lt002_instrument | F11: INTRNL_TRNSFR_RT | G11: {=IF(INDEX('3. Plano_Detalhado'!$A$10:$H$197,MATCH(1,($E11='3. Plano_Detalhado'!$E$10:$E$197)*($F11='3. Plano_Detalhado'!$F$10:$F$197)*($C11='3. Plano_Detalhado'!$A$10:$A$197),0),7)="","",INDEX('3. Plano_Detalhado'!$A$10:$H$197,MATCH(1,($E11='3. Plano_Detalhado'!$E$10:$E$197)*($F11='3. Plano_Detalhado'!$F$10:$F$197)*($C11='3. Plano_Detalhado'!$A$10:$A$197),0),7))} -> 2. Concluído | H11: {=IF(INDEX('3. Plano_Detalhado'!$A$10:$H$197,MATCH(1,($E11='3. Plano_Detalhado'!$E$10:$E$197)*($F11='3. Plano_Detalhado'!$F$10:$F$197)*($C11='3. Plano_Detalhado'!$A$10:$A$197),0),8)="","",INDEX('3. Plano_Detalhado'!$A$10:$H$197,MATCH(1,($E11='3. Plano_Detalhado'!$E$10:$E$197)*($F11='3. Plano_Detalhado'!$F$10:$F$197)*($C11='3. Plano_Detalhado'!$A$10:$A$197),0),8))} -> 2. Concluído | I11: {=IF(INDEX('3. Plano_Detalhado'!$A$10:$Q$196,MATCH(1,($E11='3. Plano_Detalhado'!$E$10:$E$196)*($F11='3. Plano_Detalhado'!$F$10:$F$196)*($C11='3. Plano_Detalhado'!$A$10:$A$196),0),17)="","",INDEX('3. Plano_Detalhado'!$A$10:$Q$196,MATCH(1,($E11='3. Plano_Detalhado'!$E$10:$E$196)*($F11='3. Plano_Detalhado'!$F$10:$F$196)*($C11='3. Plano_Detalhado'!$A$10:$A$196),0),17))}
A12: =E12&F12 -> lt002_instrumentNT_LN_LSS_PRVSN | B12: Green Dashboard | C12: Assessment | D12: {=INDEX('3. Plano_Detalhado'!$A$10:$H$197,MATCH(1,($E12='3. Plano_Detalhado'!$E$10:$E$197)*($F12='3. Plano_Detalhado'!$F$10:$F$197)*($C12='3. Plano_Detalhado'!$A$10:$A$197),0),4)} -> 2. Campo | E12: lt002_instrument | F12: NT_LN_LSS_PRVSN | G12: {=IF(INDEX('3. Plano_Detalhado'!$A$10:$H$197,MATCH(1,($E12='3. Plano_Detalhado'!$E$10:$E$197)*($F12='3. Plano_Detalhado'!$F$10:$F$197)*($C12='3. Plano_Detalhado'!$A$10:$A$197),0),7)="","",INDEX('3. Plano_Detalhado'!$A$10:$H$197,MATCH(1,($E12='3. Plano_Detalhado'!$E$10:$E$197)*($F12='3. Plano_Detalhado'!$F$10:$F$197)*($C12='3. Plano_Detalhado'!$A$10:$A$197),0),7))} -> 2. Concluído | H12: {=IF(INDEX('3. Plano_Detalhado'!$A$10:$H$197,MATCH(1,($E12='3. Plano_Detalhado'!$E$10:$E$197)*($F12='3. Plano_Detalhado'!$F$10:$F$197)*($C12='3. Plano_Detalhado'!$A$10:$A$197),0),8)="","",INDEX('3. Plano_Detalhado'!$A$10:$H$197,MATCH(1,($E12='3. Plano_Detalhado'!$E$10:$E$197)*($F12='3. Plano_Detalhado'!$F$10:$F$197)*($C12='3. Plano_Detalhado'!$A$10:$A$197),0),8))} -> 2. Concluído | I12: {=IF(INDEX('3. Plano_Detalhado'!$A$10:$Q$196,MATCH(1,($E12='3. Plano_Detalhado'!$E$10:$E$196)*($F12='3. Plano_Detalhado'!$F$10:$F$196)*($C12='3. Plano_Detalhado'!$A$10:$A$196),0),17)="","",INDEX('3. Plano_Detalhado'!$A$10:$Q$196,MATCH(1,($E12='3. Plano_Detalhado'!$E$10:$E$196)*($F12='3. Plano_Detalhado'!$F$10:$F$196)*($C12='3. Plano_Detalhado'!$A$10:$A$196),0),17))}
A13: =E13&F13 -> lt002_instrumentBSNSS_AREA | B13: Green Dashboard | C13: Assessment | D13: {=INDEX('3. Plano_Detalhado'!$A$10:$H$197,MATCH(1,($E13='3. Plano_Detalhado'!$E$10:$E$197)*($F13='3. Plano_Detalhado'!$F$10:$F$197)*($C13='3. Plano_Detalhado'!$A$10:$A$197),0),4)} -> 2. Campo | E13: lt002_instrument | F13: BSNSS_AREA | G13: {=IF(INDEX('3. Plano_Detalhado'!$A$10:$H$197,MATCH(1,($E13='3. Plano_Detalhado'!$E$10:$E$197)*($F13='3. Plano_Detalhado'!$F$10:$F$197)*($C13='3. Plano_Detalhado'!$A$10:$A$197),0),7)="","",INDEX('3. Plano_Detalhado'!$A$10:$H$197,MATCH(1,($E13='3. Plano_Detalhado'!$E$10:$E$197)*($F13='3. Plano_Detalhado'!$F$10:$F$197)*($C13='3. Plano_Detalhado'!$A$10:$A$197),0),7))} -> 2. Concluído | H13: {=IF(INDEX('3. Plano_Detalhado'!$A$10:$H$197,MATCH(1,($E13='3. Plano_Detalhado'!$E$10:$E$197)*($F13='3. Plano_Detalhado'!$F$10:$F$197)*($C13='3. Plano_Detalhado'!$A$10:$A$197),0),8)="","",INDEX('3. Plano_Detalhado'!$A$10:$H$197,MATCH(1,($E13='3. Plano_Detalhado'!$E$10:$E$197)*($F13='3. Plano_Detalhado'!$F$10:$F$197)*($C13='3. Plano_Detalhado'!$A$10:$A$197),0),8))} -> 2. Concluído | I13: {=IF(INDEX('3. Plano_Detalhado'!$A$10:$Q$196,MATCH(1,($E13='3. Plano_Detalhado'!$E$10:$E$196)*($F13='3. Plano_Detalhado'!$F$10:$F$196)*($C13='3. Plano_Detalhado'!$A$10:$A$196),0),17)="","",INDEX('3. Plano_Detalhado'!$A$10:$Q$196,MATCH(1,($E13='3. Plano_Detalhado'!$E$10:$E$196)*($F13='3. Plano_Detalhado'!$F$10:$F$196)*($C13='3. Plano_Detalhado'!$A$10:$A$196),0),17))}
A14: =E14&F14 -> lt002_instrumentMNGMNT_PRDCT | B14: Green Dashboard | C14: Assessment | D14: {=INDEX('3. Plano_Detalhado'!$A$10:$H$197,MATCH(1,($E14='3. Plano_Detalhado'!$E$10:$E$197)*($F14='3. Plano_Detalhado'!$F$10:$F$197)*($C14='3. Plano_Detalhado'!$A$10:$A$197),0),4)} -> 2. Campo | E14: lt002_instrument | F14: MNGMNT_PRDCT | G14: {=IF(INDEX('3. Plano_Detalhado'!$A$10:$H$197,MATCH(1,($E14='3. Plano_Detalhado'!$E$10:$E$197)*($F14='3. Plano_Detalhado'!$F$10:$F$197)*($C14='3. Plano_Detalhado'!$A$10:$A$197),0),7)="","",INDEX('3. Plano_Detalhado'!$A$10:$H$197,MATCH(1,($E14='3. Plano_Detalhado'!$E$10:$E$197)*($F14='3. Plano_Detalhado'!$F$10:$F$197)*($C14='3. Plano_Detalhado'!$A$10:$A$197),0),7))} -> 2. Concluído | H14: {=IF(INDEX('3. Plano_Detalhado'!$A$10:$H$197,MATCH(1,($E14='3. Plano_Detalhado'!$E$10:$E$197)*($F14='3. Plano_Detalhado'!$F$10:$F$197)*($C14='3. Plano_Detalhado'!$A$10:$A$197),0),8)="","",INDEX('3. Plano_Detalhado'!$A$10:$H$197,MATCH(1,($E14='3. Plano_Detalhado'!$E$10:$E$197)*($F14='3. Plano_Detalhado'!$F$10:$F$197)*($C14='3. Plano_Detalhado'!$A$10:$A$197),0),8))} -> 2. Concluído | I14: {=IF(INDEX('3. Plano_Detalhado'!$A$10:$Q$196,MATCH(1,($E14='3. Plano_Detalhado'!$E$10:$E$196)*($F14='3. Plano_Detalhado'!$F$10:$F$196)*($C14='3. Plano_Detalhado'!$A$10:$A$196),0),17)="","",INDEX('3. Plano_Detalhado'!$A$10:$Q$196,MATCH(1,($E14='3. Plano_Detalhado'!$E$10:$E$196)*($F14='3. Plano_Detalhado'!$F$10:$F$196)*($C14='3. Plano_Detalhado'!$A$10:$A$196),0),17))}
A15: =E15&F15 -> lt002_instrumentGRSS_CMMSSN_EXPNS | B15: Green Dashboard | C15: Assessment | D15: {=INDEX('3. Plano_Detalhado'!$A$10:$H$197,MATCH(1,($E15='3. Plano_Detalhado'!$E$10:$E$197)*($F15='3. Plano_Detalhado'!$F$10:$F$197)*($C15='3. Plano_Detalhado'!$A$10:$A$197),0),4)} -> 2. Campo | E15: lt002_instrument | F15: GRSS_CMMSSN_EXPNS | G15: {=IF(INDEX('3. Plano_Detalhado'!$A$10:$H$197,MATCH(1,($E15='3. Plano_Detalhado'!$E$10:$E$197)*($F15='3. Plano_Detalhado'!$F$10:$F$197)*($C15='3. Plano_Detalhado'!$A$10:$A$197),0),7)="","",INDEX('3. Plano_Detalhado'!$A$10:$H$197,MATCH(1,($E15='3. Plano_Detalhado'!$E$10:$E$197)*($F15='3. Plano_Detalhado'!$F$10:$F$197)*($C15='3. Plano_Detalhado'!$A$10:$A$197),0),7))} -> 2. Concluído | H15: {=IF(INDEX('3. Plano_Detalhado'!$A$10:$H$197,MATCH(1,($E15='3. Plano_Detalhado'!$E$10:$E$197)*($F15='3. Plano_Detalhado'!$F$10:$F$197)*($C15='3. Plano_Detalhado'!$A$10:$A$197),0),8)="","",INDEX('3. Plano_Detalhado'!$A$10:$H$197,MATCH(1,($E15='3. Plano_Detalhado'!$E$10:$E$197)*($F15='3. Plano_Detalhado'!$F$10:$F$197)*($C15='3. Plano_Detalhado'!$A$10:$A$197),0),8))} -> 2. Concluído | I15: {=IF(INDEX('3. Plano_Detalhado'!$A$10:$Q$196,MATCH(1,($E15='3. Plano_Detalhado'!$E$10:$E$196)*($F15='3. Plano_Detalhado'!$F$10:$F$196)*($C15='3. Plano_Detalhado'!$A$10:$A$196),0),17)="","",INDEX('3. Plano_Detalhado'!$A$10:$Q$196,MATCH(1,($E15='3. Plano_Detalhado'!$E$10:$E$196)*($F15='3. Plano_Detalhado'!$F$10:$F$196)*($C15='3. Plano_Detalhado'!$A$10:$A$196),0),17))}
A16: =E16&F16 -> lt002_instrumentGNS_FNNCL_TRNSCTN_EXCHNG_DFFRNCS | B16: Green Dashboard | C16: Assessment | D16: {=INDEX('3. Plano_Detalhado'!$A$10:$H$197,MATCH(1,($E16='3. Plano_Detalhado'!$E$10:$E$197)*($F16='3. Plano_Detalhado'!$F$10:$F$197)*($C16='3. Plano_Detalhado'!$A$10:$A$197),0),4)} -> 2. Campo | E16: lt002_instrument | F16: GNS_FNNCL_TRNSCTN_EXCHNG_DFFRNCS | G16: {=IF(INDEX('3. Plano_Detalhado'!$A$10:$H$197,MATCH(1,($E16='3. Plano_Detalhado'!$E$10:$E$197)*($F16='3. Plano_Detalhado'!$F$10:$F$197)*($C16='3. Plano_Detalhado'!$A$10:$A$197),0),7)="","",INDEX('3. Plano_Detalhado'!$A$10:$H$197,MATCH(1,($E16='3. Plano_Detalhado'!$E$10:$E$197)*($F16='3. Plano_Detalhado'!$F$10:$F$197)*($C16='3. Plano_Detalhado'!$A$10:$A$197),0),7))} -> 2. Concluído | H16: {=IF(INDEX('3. Plano_Detalhado'!$A$10:$H$197,MATCH(1,($E16='3. Plano_Detalhado'!$E$10:$E$197)*($F16='3. Plano_Detalhado'!$F$10:$F$197)*($C16='3. Plano_Detalhado'!$A$10:$A$197),0),8)="","",INDEX('3. Plano_Detalhado'!$A$10:$H$197,MATCH(1,($E16='3. Plano_Detalhado'!$E$10:$E$197)*($F16='3. Plano_Detalhado'!$F$10:$F$197)*($C16='3. Plano_Detalhado'!$A$10:$A$197),0),8))} -> 2. Concluído | I16: {=IF(INDEX('3. Plano_Detalhado'!$A$10:$Q$196,MATCH(1,($E16='3. Plano_Detalhado'!$E$10:$E$196)*($F16='3. Plano_Detalhado'!$F$10:$F$196)*($C16='3. Plano_Detalhado'!$A$10:$A$196),0),17)="","",INDEX('3. Plano_Detalhado'!$A$10:$Q$196,MATCH(1,($E16='3. Plano_Detalhado'!$E$10:$E$196)*($F16='3. Plano_Detalhado'!$F$10:$F$196)*($C16='3. Plano_Detalhado'!$A$10:$A$196),0),17))}
A17: =E17&F17 -> lt002_instrumentFLG_INTRBSNSS | B17: Green Dashboard | C17: Assessment | D17: {=INDEX('3. Plano_Detalhado'!$A$10:$H$197,MATCH(1,($E17='3. Plano_Detalhado'!$E$10:$E$197)*($F17='3. Plano_Detalhado'!$F$10:$F$197)*($C17='3. Plano_Detalhado'!$A$10:$A$197),0),4)} -> 2. Campo | E17: lt002_instrument | F17: FLG_INTRBSNSS | G17: {=IF(INDEX('3. Plano_Detalhado'!$A$10:$H$197,MATCH(1,($E17='3. Plano_Detalhado'!$E$10:$E$197)*($F17='3. Plano_Detalhado'!$F$10:$F$197)*($C17='3. Plano_Detalhado'!$A$10:$A$197),0),7)="","",INDEX('3. Plano_Detalhado'!$A$10:$H$197,MATCH(1,($E17='3. Plano_Detalhado'!$E$10:$E$197)*($F17='3. Plano_Detalhado'!$F$10:$F$197)*($C17='3. Plano_Detalhado'!$A$10:$A$197),0),7))} -> 2. Concluído | H17: {=IF(INDEX('3. Plano_Detalhado'!$A$10:$H$197,MATCH(1,($E17='3. Plano_Detalhado'!$E$10:$E$197)*($F17='3. Plano_Detalhado'!$F$10:$F$197)*($C17='3. Plano_Detalhado'!$A$10:$A$197),0),8)="","",INDEX('3. Plano_Detalhado'!$A$10:$H$197,MATCH(1,($E17='3. Plano_Detalhado'!$E$10:$E$197)*($F17='3. Plano_Detalhado'!$F$10:$F$197)*($C17='3. Plano_Detalhado'!$A$10:$A$197),0),8))} -> 3. Em Análise | I17: {=IF(INDEX('3. Plano_Detalhado'!$A$10:$Q$196,MATCH(1,($E17='3. Plano_Detalhado'!$E$10:$E$196)*($F17='3. Plano_Detalhado'!$F$10:$F$196)*($C17='3. Plano_Detalhado'!$A$10:$A$196),0),17)="","",INDEX('3. Plano_Detalhado'!$A$10:$Q$196,MATCH(1,($E17='3. Plano_Detalhado'!$E$10:$E$196)*($F17='3. Plano_Detalhado'!$F$10:$F$196)*($C17='3. Plano_Detalhado'!$A$10:$A$196),0),17))}
A18: =E18&F18 -> lt002_instrumentINTRBSNSS_ADJ_COD | B18: Green Dashboard | C18: Assessment | D18: {=INDEX('3. Plano_Detalhado'!$A$10:$H$197,MATCH(1,($E18='3. Plano_Detalhado'!$E$10:$E$197)*($F18='3. Plano_Detalhado'!$F$10:$F$197)*($C18='3. Plano_Detalhado'!$A$10:$A$197),0),4)} -> 2. Campo | E18: lt002_instrument | F18: INTRBSNSS_ADJ_COD | G18: {=IF(INDEX('3. Plano_Detalhado'!$A$10:$H$197,MATCH(1,($E18='3. Plano_Detalhado'!$E$10:$E$197)*($F18='3. Plano_Detalhado'!$F$10:$F$197)*($C18='3. Plano_Detalhado'!$A$10:$A$197),0),7)="","",INDEX('3. Plano_Detalhado'!$A$10:$H$197,MATCH(1,($E18='3. Plano_Detalhado'!$E$10:$E$197)*($F18='3. Plano_Detalhado'!$F$10:$F$197)*($C18='3. Plano_Detalhado'!$A$10:$A$197),0),7))} -> 2. Concluído | H18: {=IF(INDEX('3. Plano_Detalhado'!$A$10:$H$197,MATCH(1,($E18='3. Plano_Detalhado'!$E$10:$E$197)*($F18='3. Plano_Detalhado'!$F$10:$F$197)*($C18='3. Plano_Detalhado'!$A$10:$A$197),0),8)="","",INDEX('3. Plano_Detalhado'!$A$10:$H$197,MATCH(1,($E18='3. Plano_Detalhado'!$E$10:$E$197)*($F18='3. Plano_Detalhado'!$F$10:$F$197)*($C18='3. Plano_Detalhado'!$A$10:$A$197),0),8))} -> 3. Em Análise | I18: {=IF(INDEX('3. Plano_Detalhado'!$A$10:$Q$196,MATCH(1,($E18='3. Plano_Detalhado'!$E$10:$E$196)*($F18='3. Plano_Detalhado'!$F$10:$F$196)*($C18='3. Plano_Detalhado'!$A$10:$A$196),0),17)="","",INDEX('3. Plano_Detalhado'!$A$10:$Q$196,MATCH(1,($E18='3. Plano_Detalhado'!$E$10:$E$196)*($F18='3. Plano_Detalhado'!$F$10:$F$196)*($C18='3. Plano_Detalhado'!$A$10:$A$196),0),17))}
... A31: =E31&F31 -> lt002_instrumentGRSS_CMMSSN_EXPNS_CCRR | B31: Green Dashboard | C31: Assessment | D31: {=INDEX('3. Plano_Detalhado'!$A$10:$H$197,MATCH(1,($E31='3. Plano_Detalhado'!$E$10:$E$197)*($F31='3. Plano_Detalhado'!$F$10:$F$197)*($C31='3. Plano_Detalhado'!$A$10:$A$197),0),4)} -> 2. Campo | E31: lt002_instrument | F31: GRSS_CMMSSN_EXPNS_CCRR | G31: {=IF(INDEX('3. Plano_Detalhado'!$A$10:$H$197,MATCH(1,($E31='3. Plano_Detalhado'!$E$10:$E$197)*($F31='3. Plano_Detalhado'!$F$10:$F$197)*($C31='3. Plano_Detalhado'!$A$10:$A$197),0),7)="","",INDEX('3. Plano_Detalhado'!$A$10:$H$197,MATCH(1,($E31='3. Plano_Detalhado'!$E$10:$E$197)*($F31='3. Plano_Detalhado'!$F$10:$F$197)*($C31='3. Plano_Detalhado'!$A$10:$A$197),0),7))} -> 2. Concluído | H31: {=IF(INDEX('3. Plano_Detalhado'!$A$10:$H$197,MATCH(1,($E31='3. Plano_Detalhado'!$E$10:$E$197)*($F31='3. Plano_Detalhado'!$F$10:$F$197)*($C31='3. Plano_Detalhado'!$A$10:$A$197),0),8)="","",INDEX('3. Plano_Detalhado'!$A$10:$H$197,MATCH(1,($E31='3. Plano_Detalhado'!$E$10:$E$197)*($F31='3. Plano_Detalhado'!$F$10:$F$197)*($C31='3. Plano_Detalhado'!$A$10:$A$197),0),8))} -> 2. Concluído | I31: {=IF(INDEX('3. Plano_Detalhado'!$A$10:$Q$196,MATCH(1,($E31='3. Plano_Detalhado'!$E$10:$E$196)*($F31='3. Plano_Detalhado'!$F$10:$F$196)*($C31='3. Plano_Detalhado'!$A$10:$A$196),0),17)="","",INDEX('3. Plano_Detalhado'!$A$10:$Q$196,MATCH(1,($E31='3. Plano_Detalhado'!$E$10:$E$196)*($F31='3. Plano_Detalhado'!$F$10:$F$196)*($C31='3. Plano_Detalhado'!$A$10:$A$196),0),17))}
B32: Green Dashboard | C32: Assessment | D32: {=INDEX('3. Plano_Detalhado'!$A$10:$H$197,MATCH(1,($E32='3. Plano_Detalhado'!$E$10:$E$197)*($F32='3. Plano_Detalhado'!$F$10:$F$197)*($C32='3. Plano_Detalhado'!$A$10:$A$197),0),4)} -> 2. Campo | E32: lt002_instrument | F32: GNS_FNNCL_TRNSCTN_EXCHNG_CCRR | G32: {=IF(INDEX('3. Plano_Detalhado'!$A$10:$H$197,MATCH(1,($E32='3. Plano_Detalhado'!$E$10:$E$197)*($F32='3. Plano_Detalhado'!$F$10:$F$197)*($C32='3. Plano_Detalhado'!$A$10:$A$197),0),7)="","",INDEX('3. Plano_Detalhado'!$A$10:$H$197,MATCH(1,($E32='3. Plano_Detalhado'!$E$10:$E$197)*($F32='3. Plano_Detalhado'!$F$10:$F$197)*($C32='3. Plano_Detalhado'!$A$10:$A$197),0),7))} -> 2. Concluído | H32: {=IF(INDEX('3. Plano_Detalhado'!$A$10:$H$197,MATCH(1,($E32='3. Plano_Detalhado'!$E$10:$E$197)*($F32='3. Plano_Detalhado'!$F$10:$F$197)*($C32='3. Plano_Detalhado'!$A$10:$A$197),0),8)="","",INDEX('3. Plano_Detalhado'!$A$10:$H$197,MATCH(1,($E32='3. Plano_Detalhado'!$E$10:$E$197)*($F32='3. Plano_Detalhado'!$F$10:$F$197)*($C32='3. Plano_Detalhado'!$A$10:$A$197),0),8))} -> 2. Concluído | I32: {=IF(INDEX('3. Plano_Detalhado'!$A$10:$Q$196,MATCH(1,($E32='3. Plano_Detalhado'!$E$10:$E$196)*($F32='3. Plano_Detalhado'!$F$10:$F$196)*($C32='3. Plano_Detalhado'!$A$10:$A$196),0),17)="","",INDEX('3. Plano_Detalhado'!$A$10:$Q$196,MATCH(1,($E32='3. Plano_Detalhado'!$E$10:$E$196)*($F32='3. Plano_Detalhado'!$F$10:$F$196)*($C32='3. Plano_Detalhado'!$A$10:$A$196),0),17))}
B33: Green Dashboard | C33: Assessment | D33: {=INDEX('3. Plano_Detalhado'!$A$10:$H$197,MATCH(1,($E33='3. Plano_Detalhado'!$E$10:$E$197)*($F33='3. Plano_Detalhado'!$F$10:$F$197)*($C33='3. Plano_Detalhado'!$A$10:$A$197),0),4)} -> 2. Campo | E33: lt002_instrument | F33: BSNSS_AREA_CCRR | G33: {=IF(INDEX('3. Plano_Detalhado'!$A$10:$H$197,MATCH(1,($E33='3. Plano_Detalhado'!$E$10:$E$197)*($F33='3. Plano_Detalhado'!$F$10:$F$197)*($C33='3. Plano_Detalhado'!$A$10:$A$197),0),7)="","",INDEX('3. Plano_Detalhado'!$A$10:$H$197,MATCH(1,($E33='3. Plano_Detalhado'!$E$10:$E$197)*($F33='3. Plano_Detalhado'!$F$10:$F$197)*($C33='3. Plano_Detalhado'!$A$10:$A$197),0),7))} -> 2. Concluído | H33: {=IF(INDEX('3. Plano_Detalhado'!$A$10:$H$197,MATCH(1,($E33='3. Plano_Detalhado'!$E$10:$E$197)*($F33='3. Plano_Detalhado'!$F$10:$F$197)*($C33='3. Plano_Detalhado'!$A$10:$A$197),0),8)="","",INDEX('3. Plano_Detalhado'!$A$10:$H$197,MATCH(1,($E33='3. Plano_Detalhado'!$E$10:$E$197)*($F33='3. Plano_Detalhado'!$F$10:$F$197)*($C33='3. Plano_Detalhado'!$A$10:$A$197),0),8))} -> 2. Concluído | I33: {=IF(INDEX('3. Plano_Detalhado'!$A$10:$Q$196,MATCH(1,($E33='3. Plano_Detalhado'!$E$10:$E$196)*($F33='3. Plano_Detalhado'!$F$10:$F$196)*($C33='3. Plano_Detalhado'!$A$10:$A$196),0),17)="","",INDEX('3. Plano_Detalhado'!$A$10:$Q$196,MATCH(1,($E33='3. Plano_Detalhado'!$E$10:$E$196)*($F33='3. Plano_Detalhado'!$F$10:$F$196)*($C33='3. Plano_Detalhado'!$A$10:$A$196),0),17))}
B34: Green Dashboard | C34: Assessment | D34: {=INDEX('3. Plano_Detalhado'!$A$10:$H$197,MATCH(1,($E34='3. Plano_Detalhado'!$E$10:$E$197)*($F34='3. Plano_Detalhado'!$F$10:$F$197)*($C34='3. Plano_Detalhado'!$A$10:$A$197),0),4)} -> 2. Campo | E34: lt002_instrument | F34: GRSS_CMMSSN_INCM_OFF_BLNC_CCRR | G34: {=IF(INDEX('3. Plano_Detalhado'!$A$10:$H$197,MATCH(1,($E34='3. Plano_Detalhado'!$E$10:$E$197)*($F34='3. Plano_Detalhado'!$F$10:$F$197)*($C34='3. Plano_Detalhado'!$A$10:$A$197),0),7)="","",INDEX('3. Plano_Detalhado'!$A$10:$H$197,MATCH(1,($E34='3. Plano_Detalhado'!$E$10:$E$197)*($F34='3. Plano_Detalhado'!$F$10:$F$197)*($C34='3. Plano_Detalhado'!$A$10:$A$197),0),7))} -> 2. Concluído | H34: {=IF(INDEX('3. Plano_Detalhado'!$A$10:$H$197,MATCH(1,($E34='3. Plano_Detalhado'!$E$10:$E$197)*($F34='3. Plano_Detalhado'!$F$10:$F$197)*($C34='3. Plano_Detalhado'!$A$10:$A$197),0),8)="","",INDEX('3. Plano_Detalhado'!$A$10:$H$197,MATCH(1,($E34='3. Plano_Detalhado'!$E$10:$E$197)*($F34='3. Plano_Detalhado'!$F$10:$F$197)*($C34='3. Plano_Detalhado'!$A$10:$A$197),0),8))} -> 2. Concluído | I34: {=IF(INDEX('3. Plano_Detalhado'!$A$10:$Q$196,MATCH(1,($E34='3. Plano_Detalhado'!$E$10:$E$196)*($F34='3. Plano_Detalhado'!$F$10:$F$196)*($C34='3. Plano_Detalhado'!$A$10:$A$196),0),17)="","",INDEX('3. Plano_Detalhado'!$A$10:$Q$196,MATCH(1,($E34='3. Plano_Detalhado'!$E$10:$E$196)*($F34='3. Plano_Detalhado'!$F$10:$F$196)*($C34='3. Plano_Detalhado'!$A$10:$A$196),0),17))}
B35: Green Dashboard | C35: Assessment | D35: {=INDEX('3. Plano_Detalhado'!$A$10:$H$197,MATCH(1,($E35='3. Plano_Detalhado'!$E$10:$E$197)*($F35='3. Plano_Detalhado'!$F$10:$F$197)*($C35='3. Plano_Detalhado'!$A$10:$A$197),0),4)} -> 2. Campo | E35: lt002_instrument | F35: GRSS_CMMSSN_EXPNS_OFF_BLNC_CCRR | G35: {=IF(INDEX('3. Plano_Detalhado'!$A$10:$H$197,MATCH(1,($E35='3. Plano_Detalhado'!$E$10:$E$197)*($F35='3. Plano_Detalhado'!$F$10:$F$197)*($C35='3. Plano_Detalhado'!$A$10:$A$197),0),7)="","",INDEX('3. Plano_Detalhado'!$A$10:$H$197,MATCH(1,($E35='3. Plano_Detalhado'!$E$10:$E$197)*($F35='3. Plano_Detalhado'!$F$10:$F$197)*($C35='3. Plano_Detalhado'!$A$10:$A$197),0),7))} -> 2. Concluído | H35: {=IF(INDEX('3. Plano_Detalhado'!$A$10:$H$197,MATCH(1,($E35='3. Plano_Detalhado'!$E$10:$E$197)*($F35='3. Plano_Detalhado'!$F$10:$F$197)*($C35='3. Plano_Detalhado'!$A$10:$A$197),0),8)="","",INDEX('3. Plano_Detalhado'!$A$10:$H$197,MATCH(1,($E35='3. Plano_Detalhado'!$E$10:$E$197)*($F35='3. Plano_Detalhado'!$F$10:$F$197)*($C35='3. Plano_Detalhado'!$A$10:$A$197),0),8))} -> 2. Concluído | I35: {=IF(INDEX('3. Plano_Detalhado'!$A$10:$Q$196,MATCH(1,($E35='3. Plano_Detalhado'!$E$10:$E$196)*($F35='3. Plano_Detalhado'!$F$10:$F$196)*($C35='3. Plano_Detalhado'!$A$10:$A$196),0),17)="","",INDEX('3. Plano_Detalhado'!$A$10:$Q$196,MATCH(1,($E35='3. Plano_Detalhado'!$E$10:$E$196)*($F35='3. Plano_Detalhado'!$F$10:$F$196)*($C35='3. Plano_Detalhado'!$A$10:$A$196),0),17))}
B36: Green Dashboard | C36: Assessment | D36: {=INDEX('3. Plano_Detalhado'!$A$10:$H$197,MATCH(1,($E36='3. Plano_Detalhado'!$E$10:$E$197)*($F36='3. Plano_Detalhado'!$F$10:$F$197)*($C36='3. Plano_Detalhado'!$A$10:$A$197),0),4)} -> 2. Campo | E36: lt002_instrument | F36: FLG_INSTRMNT_CNCLLD | G36: {=IF(INDEX('3. Plano_Detalhado'!$A$10:$H$197,MATCH(1,($E36='3. Plano_Detalhado'!$E$10:$E$197)*($F36='3. Plano_Detalhado'!$F$10:$F$197)*($C36='3. Plano_Detalhado'!$A$10:$A$197),0),7)="","",INDEX('3. Plano_Detalhado'!$A$10:$H$197,MATCH(1,($E36='3. Plano_Detalhado'!$E$10:$E$197)*($F36='3. Plano_Detalhado'!$F$10:$F$197)*($C36='3. Plano_Detalhado'!$A$10:$A$197),0),7))} -> 0. Cancelado | H36: {=IF(INDEX('3. Plano_Detalhado'!$A$10:$H$197,MATCH(1,($E36='3. Plano_Detalhado'!$E$10:$E$197)*($F36='3. Plano_Detalhado'!$F$10:$F$197)*($C36='3. Plano_Detalhado'!$A$10:$A$197),0),8)="","",INDEX('3. Plano_Detalhado'!$A$10:$H$197,MATCH(1,($E36='3. Plano_Detalhado'!$E$10:$E$197)*($F36='3. Plano_Detalhado'!$F$10:$F$197)*($C36='3. Plano_Detalhado'!$A$10:$A$197),0),8))} -> 0. Cancelado | I36: {=IF(INDEX('3. Plano_Detalhado'!$A$10:$Q$196,MATCH(1,($E36='3. Plano_Detalhado'!$E$10:$E$196)*($F36='3. Plano_Detalhado'!$F$10:$F$196)*($C36='3. Plano_Detalhado'!$A$10:$A$196),0),17)="","",INDEX('3. Plano_Detalhado'!$A$10:$Q$196,MATCH(1,($E36='3. Plano_Detalhado'!$E$10:$E$196)*($F36='3. Plano_Detalhado'!$F$10:$F$196)*($C36='3. Plano_Detalhado'!$A$10:$A$196),0),17))}
B37: Green Dashboard | C37: Assessment | D37: {=INDEX('3. Plano_Detalhado'!$A$10:$H$197,MATCH(1,($E37='3. Plano_Detalhado'!$E$10:$E$197)*($F37='3. Plano_Detalhado'!$F$10:$F$197)*($C37='3. Plano_Detalhado'!$A$10:$A$197),0),4)} -> 2. Campo | E37: lt824_assoc_kpi_gd | F37: ambito | G37: {=IF(INDEX('3. Plano_Detalhado'!$A$10:$H$197,MATCH(1,($E37='3. Plano_Detalhado'!$E$10:$E$197)*($F37='3. Plano_Detalhado'!$F$10:$F$197)*($C37='3. Plano_Detalhado'!$A$10:$A$197),0),7)="","",INDEX('3. Plano_Detalhado'!$A$10:$H$197,MATCH(1,($E37='3. Plano_Detalhado'!$E$10:$E$197)*($F37='3. Plano_Detalhado'!$F$10:$F$197)*($C37='3. Plano_Detalhado'!$A$10:$A$197),0),7))} -> 2. Concluído | H37: {=IF(INDEX('3. Plano_Detalhado'!$A$10:$H$197,MATCH(1,($E37='3. Plano_Detalhado'!$E$10:$E$197)*($F37='3. Plano_Detalhado'!$F$10:$F$197)*($C37='3. Plano_Detalhado'!$A$10:$A$197),0),8)="","",INDEX('3. Plano_Detalhado'!$A$10:$H$197,MATCH(1,($E37='3. Plano_Detalhado'!$E$10:$E$197)*($F37='3. Plano_Detalhado'!$F$10:$F$197)*($C37='3. Plano_Detalhado'!$A$10:$A$197),0),8))} -> 2. Concluído | I37: {=IF(INDEX('3. Plano_Detalhado'!$A$10:$Q$196,MATCH(1,($E37='3. Plano_Detalhado'!$E$10:$E$196)*($F37='3. Plano_Detalhado'!$F$10:$F$196)*($C37='3. Plano_Detalhado'!$A$10:$A$196),0),17)="","",INDEX('3. Plano_Detalhado'!$A$10:$Q$196,MATCH(1,($E37='3. Plano_Detalhado'!$E$10:$E$196)*($F37='3. Plano_Detalhado'!$F$10:$F$196)*($C37='3. Plano_Detalhado'!$A$10:$A$196),0),17))}
B38: Green Dashboard | C38: Assessment | D38: {=INDEX('3. Plano_Detalhado'!$A$10:$H$197,MATCH(1,($E38='3. Plano_Detalhado'!$E$10:$E$197)*($F38='3. Plano_Detalhado'!$F$10:$F$197)*($C38='3. Plano_Detalhado'!$A$10:$A$197),0),4)} -> 2. Campo | E38: lt824_assoc_kpi_gd | F38: tipo_conta_local | G38: {=IF(INDEX('3. Plano_Detalhado'!$A$10:$H$197,MATCH(1,($E38='3. Plano_Detalhado'!$E$10:$E$197)*($F38='3. Plano_Detalhado'!$F$10:$F$197)*($C38='3. Plano_Detalhado'!$A$10:$A$197),0),7)="","",INDEX('3. Plano_Detalhado'!$A$10:$H$197,MATCH(1,($E38='3. Plano_Detalhado'!$E$10:$E$197)*($F38='3. Plano_Detalhado'!$F$10:$F$197)*($C38='3. Plano_Detalhado'!$A$10:$A$197),0),7))} -> 2. Concluído | H38: {=IF(INDEX('3. Plano_Detalhado'!$A$10:$H$197,MATCH(1,($E38='3. Plano_Detalhado'!$E$10:$E$197)*($F38='3. Plano_Detalhado'!$F$10:$F$197)*($C38='3. Plano_Detalhado'!$A$10:$A$197),0),8)="","",INDEX('3. Plano_Detalhado'!$A$10:$H$197,MATCH(1,($E38='3. Plano_Detalhado'!$E$10:$E$197)*($F38='3. Plano_Detalhado'!$F$10:$F$197)*($C38='3. Plano_Detalhado'!$A$10:$A$197),0),8))} -> 2. Concluído | I38: {=IF(INDEX('3. Plano_Detalhado'!$A$10:$Q$196,MATCH(1,($E38='3. Plano_Detalhado'!$E$10:$E$196)*($F38='3. Plano_Detalhado'!$F$10:$F$196)*($C38='3. Plano_Detalhado'!$A$10:$A$196),0),17)="","",INDEX('3. Plano_Detalhado'!$A$10:$Q$196,MATCH(1,($E38='3. Plano_Detalhado'!$E$10:$E$196)*($F38='3. Plano_Detalhado'!$F$10:$F$196)*($C38='3. Plano_Detalhado'!$A$10:$A$196),0),17))}
B39: Green Dashboard | C39: Assessment | D39: {=INDEX('3. Plano_Detalhado'!$A$10:$H$197,MATCH(1,($E39='3. Plano_Detalhado'!$E$10:$E$197)*($F39='3. Plano_Detalhado'!$F$10:$F$197)*($C39='3. Plano_Detalhado'!$A$10:$A$197),0),4)} -> 2. Campo | E39: lt824_assoc_kpi_gd | F39: valor_gd | G39: {=IF(INDEX('3. Plano_Detalhado'!$A$10:$H$197,MATCH(1,($E39='3. Plano_Detalhado'!$E$10:$E$197)*($F39='3. Plano_Detalhado'!$F$10:$F$197)*($C39='3. Plano_Detalhado'!$A$10:$A$197),0),7)="","",INDEX('3. Plano_Detalhado'!$A$10:$H$197,MATCH(1,($E39='3. Plano_Detalhado'!$E$10:$E$197)*($F39='3. Plano_Detalhado'!$F$10:$F$197)*($C39='3. Plano_Detalhado'!$A$10:$A$197),0),7))} -> 2. Concluído | H39: {=IF(INDEX('3. Plano_Detalhado'!$A$10:$H$197,MATCH(1,($E39='3. Plano_Detalhado'!$E$10:$E$197)*($F39='3. Plano_Detalhado'!$F$10:$F$197)*($C39='3. Plano_Detalhado'!$A$10:$A$197),0),8)="","",INDEX('3. Plano_Detalhado'!$A$10:$H$197,MATCH(1,($E39='3. Plano_Detalhado'!$E$10:$E$197)*($F39='3. Plano_Detalhado'!$F$10:$F$197)*($C39='3. Plano_Detalhado'!$A$10:$A$197),0),8))} -> 2. Concluído | I39: {=IF(INDEX('3. Plano_Detalhado'!$A$10:$Q$196,MATCH(1,($E39='3. Plano_Detalhado'!$E$10:$E$196)*($F39='3. Plano_Detalhado'!$F$10:$F$196)*($C39='3. Plano_Detalhado'!$A$10:$A$196),0),17)="","",INDEX('3. Plano_Detalhado'!$A$10:$Q$196,MATCH(1,($E39='3. Plano_Detalhado'!$E$10:$E$196)*($F39='3. Plano_Detalhado'!$F$10:$F$196)*($C39='3. Plano_Detalhado'!$A$10:$A$196),0),17))}
B40: Green Dashboard | C40: Assessment | D40: {=INDEX('3. Plano_Detalhado'!$A$10:$H$197,MATCH(1,($E40='3. Plano_Detalhado'!$E$10:$E$197)*($F40='3. Plano_Detalhado'!$F$10:$F$197)*($C40='3. Plano_Detalhado'!$A$10:$A$197),0),4)} -> 2. Campo | E40: lt824_assoc_kpi_gd | F40: kpi | G40: {=IF(INDEX('3. Plano_Detalhado'!$A$10:$H$197,MATCH(1,($E40='3. Plano_Detalhado'!$E$10:$E$197)*($F40='3. Plano_Detalhado'!$F$10:$F$197)*($C40='3. Plano_Detalhado'!$A$10:$A$197),0),7)="","",INDEX('3. Plano_Detalhado'!$A$10:$H$197,MATCH(1,($E40='3. Plano_Detalhado'!$E$10:$E$197)*($F40='3. Plano_Detalhado'!$F$10:$F$197)*($C40='3. Plano_Detalhado'!$A$10:$A$197),0),7))} -> 2. Concluído | H40: {=IF(INDEX('3. Plano_Detalhado'!$A$10:$H$197,MATCH(1,($E40='3. Plano_Detalhado'!$E$10:$E$197)*($F40='3. Plano_Detalhado'!$F$10:$F$197)*($C40='3. Plano_Detalhado'!$A$10:$A$197),0),8)="","",INDEX('3. Plano_Detalhado'!$A$10:$H$197,MATCH(1,($E40='3. Plano_Detalhado'!$E$10:$E$197)*($F40='3. Plano_Detalhado'!$F$10:$F$197)*($C40='3. Plano_Detalhado'!$A$10:$A$197),0),8))} -> 2. Concluído | I40: {=IF(INDEX('3. Plano_Detalhado'!$A$10:$Q$196,MATCH(1,($E40='3. Plano_Detalhado'!$E$10:$E$196)*($F40='3. Plano_Detalhado'!$F$10:$F$196)*($C40='3. Plano_Detalhado'!$A$10:$A$196),0),17)="","",INDEX('3. Plano_Detalhado'!$A$10:$Q$196,MATCH(1,($E40='3. Plano_Detalhado'!$E$10:$E$196)*($F40='3. Plano_Detalhado'!$F$10:$F$196)*($C40='3. Plano_Detalhado'!$A$10:$A$196),0),17))}
B41: Green Dashboard | C41: Assessment | D41: {=INDEX('3. Plano_Detalhado'!$A$10:$H$197,MATCH(1,($E41='3. Plano_Detalhado'!$E$10:$E$197)*($F41='3. Plano_Detalhado'!$F$10:$F$197)*($C41='3. Plano_Detalhado'!$A$10:$A$197),0),4)} -> 2. Campo | E41: lt824_assoc_kpi_gd | F41: ordem | G41: {=IF(INDEX('3. Plano_Detalhado'!$A$10:$H$197,MATCH(1,($E41='3. Plano_Detalhado'!$E$10:$E$197)*($F41='3. Plano_Detalhado'!$F$10:$F$197)*($C41='3. Plano_Detalhado'!$A$10:$A$197),0),7)="","",INDEX('3. Plano_Detalhado'!$A$10:$H$197,MATCH(1,($E41='3. Plano_Detalhado'!$E$10:$E$197)*($F41='3. Plano_Detalhado'!$F$10:$F$197)*($C41='3. Plano_Detalhado'!$A$10:$A$197),0),7))} -> 2. Concluído | H41: {=IF(INDEX('3. Plano_Detalhado'!$A$10:$H$197,MATCH(1,($E41='3. Plano_Detalhado'!$E$10:$E$197)*($F41='3. Plano_Detalhado'!$F$10:$F$197)*($C41='3. Plano_Detalhado'!$A$10:$A$197),0),8)="","",INDEX('3. Plano_Detalhado'!$A$10:$H$197,MATCH(1,($E41='3. Plano_Detalhado'!$E$10:$E$197)*($F41='3. Plano_Detalhado'!$F$10:$F$197)*($C41='3. Plano_Detalhado'!$A$10:$A$197),0),8))} -> 2. Concluído | I41: {=IF(INDEX('3. Plano_Detalhado'!$A$10:$Q$196,MATCH(1,($E41='3. Plano_Detalhado'!$E$10:$E$196)*($F41='3. Plano_Detalhado'!$F$10:$F$196)*($C41='3. Plano_Detalhado'!$A$10:$A$196),0),17)="","",INDEX('3. Plano_Detalhado'!$A$10:$Q$196,MATCH(1,($E41='3. Plano_Detalhado'!$E$10:$E$196)*($F41='3. Plano_Detalhado'!$F$10:$F$196)*($C41='3. Plano_Detalhado'!$A$10:$A$196),0),17))}
B42: Green Dashboard | C42: Assessment | D42: {=INDEX('3. Plano_Detalhado'!$A$10:$H$197,MATCH(1,($E42='3. Plano_Detalhado'!$E$10:$E$197)*($F42='3. Plano_Detalhado'!$F$10:$F$197)*($C42='3. Plano_Detalhado'!$A$10:$A$197),0),4)} -> 2. Campo | E42: lt824_assoc_kpi_gd | F42: ref_date | G42: {=IF(INDEX('3. Plano_Detalhado'!$A$10:$H$197,MATCH(1,($E42='3. Plano_Detalhado'!$E$10:$E$197)*($F42='3. Plano_Detalhado'!$F$10:$F$197)*($C42='3. Plano_Detalhado'!$A$10:$A$197),0),7)="","",INDEX('3. Plano_Detalhado'!$A$10:$H$197,MATCH(1,($E42='3. Plano_Detalhado'!$E$10:$E$197)*($F42='3. Plano_Detalhado'!$F$10:$F$197)*($C42='3. Plano_Detalhado'!$A$10:$A$197),0),7))} -> 2. Concluído | H42: {=IF(INDEX('3. Plano_Detalhado'!$A$10:$H$197,MATCH(1,($E42='3. Plano_Detalhado'!$E$10:$E$197)*($F42='3. Plano_Detalhado'!$F$10:$F$197)*($C42='3. Plano_Detalhado'!$A$10:$A$197),0),8)="","",INDEX('3. Plano_Detalhado'!$A$10:$H$197,MATCH(1,($E42='3. Plano_Detalhado'!$E$10:$E$197)*($F42='3. Plano_Detalhado'!$F$10:$F$197)*($C42='3. Plano_Detalhado'!$A$10:$A$197),0),8))} -> 2. Concluído | I42: {=IF(INDEX('3. Plano_Detalhado'!$A$10:$Q$196,MATCH(1,($E42='3. Plano_Detalhado'!$E$10:$E$196)*($F42='3. Plano_Detalhado'!$F$10:$F$196)*($C42='3. Plano_Detalhado'!$A$10:$A$196),0),17)="","",INDEX('3. Plano_Detalhado'!$A$10:$Q$196,MATCH(1,($E42='3. Plano_Detalhado'!$E$10:$E$196)*($F42='3. Plano_Detalhado'!$F$10:$F$196)*($C42='3. Plano_Detalhado'!$A$10:$A$196),0),17))}
B43: Green Dashboard | C43: Assessment | D43: {=INDEX('3. Plano_Detalhado'!$A$10:$H$197,MATCH(1,($E43='3. Plano_Detalhado'!$E$10:$E$197)*($F43='3. Plano_Detalhado'!$F$10:$F$197)*($C43='3. Plano_Detalhado'!$A$10:$A$197),0),4)} -> 2. Campo | E43: lt002_instrument | F43: SSTNBL_INDCTR | G43: {=IF(INDEX('3. Plano_Detalhado'!$A$10:$H$197,MATCH(1,($E43='3. Plano_Detalhado'!$E$10:$E$197)*($F43='3. Plano_Detalhado'!$F$10:$F$197)*($C43='3. Plano_Detalhado'!$A$10:$A$197),0),7)="","",INDEX('3. Plano_Detalhado'!$A$10:$H$197,MATCH(1,($E43='3. Plano_Detalhado'!$E$10:$E$197)*($F43='3. Plano_Detalhado'!$F$10:$F$197)*($C43='3. Plano_Detalhado'!$A$10:$A$197),0),7))} -> 0. Cancelado | H43: {=IF(INDEX('3. Plano_Detalhado'!$A$10:$H$197,MATCH(1,($E43='3. Plano_Detalhado'!$E$10:$E$197)*($F43='3. Plano_Detalhado'!$F$10:$F$197)*($C43='3. Plano_Detalhado'!$A$10:$A$197),0),8)="","",INDEX('3. Plano_Detalhado'!$A$10:$H$197,MATCH(1,($E43='3. Plano_Detalhado'!$E$10:$E$197)*($F43='3. Plano_Detalhado'!$F$10:$F$197)*($C43='3. Plano_Detalhado'!$A$10:$A$197),0),8))} -> 0. Cancelado | I43: {=IF(INDEX('3. Plano_Detalhado'!$A$10:$Q$196,MATCH(1,($E43='3. Plano_Detalhado'!$E$10:$E$196)*($F43='3. Plano_Detalhado'!$F$10:$F$196)*($C43='3. Plano_Detalhado'!$A$10:$A$196),0),17)="","",INDEX('3. Plano_Detalhado'!$A$10:$Q$196,MATCH(1,($E43='3. Plano_Detalhado'!$E$10:$E$196)*($F43='3. Plano_Detalhado'!$F$10:$F$196)*($C43='3. Plano_Detalhado'!$A$10:$A$196),0),17))}
... B187: Green Dashboard | C187: Simulação / Testes | D187: {=INDEX('3. Plano_Detalhado'!$A$10:$H$197,MATCH(1,($E187='3. Plano_Detalhado'!$E$10:$E$197)*($F187='3. Plano_Detalhado'!$F$10:$F$197)*($C187='3. Plano_Detalhado'!$A$10:$A$197),0),4)} -> 2. Campo | E187: lt007_instr_activity | F187: INSTRMNT_ID | G187: {=IF(INDEX('3. Plano_Detalhado'!$A$10:$H$197,MATCH(1,($E187='3. Plano_Detalhado'!$E$10:$E$197)*($F187='3. Plano_Detalhado'!$F$10:$F$197)*($C187='3. Plano_Detalhado'!$A$10:$A$197),0),7)="","",INDEX('3. Plano_Detalhado'!$A$10:$H$197,MATCH(1,($E187='3. Plano_Detalhado'!$E$10:$E$197)*($F187='3. Plano_Detalhado'!$F$10:$F$197)*($C187='3. Plano_Detalhado'!$A$10:$A$197),0),7))} | H187: {=IF(INDEX('3. Plano_Detalhado'!$A$10:$H$197,MATCH(1,($E187='3. Plano_Detalhado'!$E$10:$E$197)*($F187='3. Plano_Detalhado'!$F$10:$F$197)*($C187='3. Plano_Detalhado'!$A$10:$A$197),0),8)="","",INDEX('3. Plano_Detalhado'!$A$10:$H$197,MATCH(1,($E187='3. Plano_Detalhado'!$E$10:$E$197)*($F187='3. Plano_Detalhado'!$F$10:$F$197)*($C187='3. Plano_Detalhado'!$A$10:$A$197),0),8))} | I187: {=IF(INDEX('3. Plano_Detalhado'!$A$10:$Q$196,MATCH(1,($E187='3. Plano_Detalhado'!$E$10:$E$196)*($F187='3. Plano_Detalhado'!$F$10:$F$196)*($C187='3. Plano_Detalhado'!$A$10:$A$196),0),17)="","",INDEX('3. Plano_Detalhado'!$A$10:$Q$196,MATCH(1,($E187='3. Plano_Detalhado'!$E$10:$E$196)*($F187='3. Plano_Detalhado'!$F$10:$F$196)*($C187='3. Plano_Detalhado'!$A$10:$A$196),0),17))}

Sheet 3. Plano_Detalhado
R7: Janeiro | AN7: Fevereiro | BH7: Março
B8: Âmbito | C8: Sub-âmbito | D8: Tipo de teste | E8: Tabela | F8: Campo | G8: Status Atual | H8: Status Anterior | I8: Alteração no Guia Corporativo | J8: Horas previstas | K8: Dias | L8: Horas efetivas | M8: Dias efetivos | N8: Status Estimado | O8: Status Real | P8: Desvios | Q8: Observações | R8: =R9 -> 45659 | S8: =S9 -> 45660 | T8: =T9 -> 45663 | U8: =U9 -> 45664 | V8: =V9 -> 45665 | W8: =W9 -> 45666 | X8: =X9 -> 45667 | Y8: =Y9 -> 45670 | ... CB8: =CB9 -> 45747
B9: 1. Assessment | J9: =+Macro_Plano_2025_v1!J15 -> 64 | K9: =J9/8 -> 8 | L9: =SUM(L10:L34) -> 6.5 | M9: =SUM(M10:M34) -> 1.5625 | N9: =SUMPRODUCT(N10:N34,J10:J34)/J9 -> 0.04 | O9: =SUMPRODUCT(O10:O34,K10:K34)/K9 -> 0.04 | P9: =O9-N9 -> 0 | R9: 45659 | S9: =WORKDAY(R9,1) -> 45660 | T9: =WORKDAY(S9,1) -> 45663 | U9: =WORKDAY(T9,1) -> 45664 | V9: =WORKDAY(U9,1) -> 45665 | W9: =WORKDAY(V9,1) -> 45666 | X9: =WORKDAY(W9,1) -> 45667 | Y9: =WORKDAY(X9,1) -> 45670 | Z9: =WORKDAY(Y9,1) -> 45671 | ... CB9: =WORKDAY(CA9,1) -> 45747
A10: Assessment | B10: GD | C10: Exclusivo GD - Campos Deloitte | D10: 2. Campo | E10: lt002_instrument | F10: AVRG_BLNC | G10: 2. Concluído | H10: 2. Concluído | J10: =+$J$9/25 -> 2.56 | K10: =+$K$9/25 -> 0.32 | L10: =SUM(R10:CB10) -> 0.5 | M10: =L10/8 -> 0.0625 | N10: =100% -> 1 | O10: =100% -> 1 | P10: =O10-N10 -> 0 | R10: 0.5
A11: Assessment | B11: GD | C11: Exclusivo GD - Campos Deloitte | D11: 2. Campo | E11: lt002_instrument | F11: NW_BSNSS | G11: 2. Concluído | H11: 4. Validação da especificação | J11: =+$J$9/25 -> 2.56 | K11: =+$K$9/25 -> 0.32 | L11: =SUM(R11:CB11) -> 0.5 | M11: 0.0625 | S11: 0.5
A12: Assessment | B12: GD | C12: Exclusivo GD - Campos Deloitte | D12: 2. Campo | E12: lt002_instrument | F12: GRSS_INTRST_INCM | G12: 2. Concluído | H12: 2. Concluído | J12: =+$J$9/25 -> 2.56 | K12: =+$K$9/25 -> 0.32 | L12: =SUM(R12:CB12) -> 0.5 | M12: 0.0625 | T12: 0.5
A13: Assessment | B13: GD | C13: Exclusivo GD - Campos Deloitte | D13: 2. Campo | E13: lt002_instrument | F13: GRSS_CMMSSN_INCM | G13: 2. Concluído | H13: 2. Concluído | J13: =+$J$9/25 -> 2.56 | K13: =+$K$9/25 -> 0.32 | L13: =SUM(R13:CB13) -> 0 | M13: 0.0625
A14: Assessment | B14: GD | C14: Exclusivo GD - Campos Deloitte | D14: 2. Campo | E14: lt002_instrument | F14: INTRNL_TRNSFR_RT | G14: 2. Concluído | H14: 2. Concluído | J14: =+$J$9/25 -> 2.56 | K14: =+$K$9/25 -> 0.32 | L14: =SUM(R14:CB14) -> 1.5 | M14: 0.0625 | S14: 1.5
A15: Assessment | B15: GD | C15: Exclusivo GD - Campos Deloitte | D15: 2. Campo | E15: lt002_instrument | F15: NT_LN_LSS_PRVSN | G15: 2. Concluído | H15: 2. Concluído | J15: =+$J$9/25 -> 2.56 | K15: =+$K$9/25 -> 0.32 | L15: =SUM(R15:CB15) -> 0.5 | M15: 0.0625 | S15: 0.5
A16: Assessment | B16: GD | C16: Exclusivo GD - Campos Deloitte | D16: 2. Campo | E16: lt002_instrument | F16: BSNSS_AREA | G16: 2. Concluído | H16: 2. Concluído | J16: =+$J$9/25 -> 2.56 | K16: =+$K$9/25 -> 0.32 | L16: =SUM(R16:CB16) -> 0 | M16: 0.0625
A17: Assessment | B17: GD | C17: Exclusivo GD - Campos Deloitte | D17: 2. Campo | E17: lt002_instrument | F17: MNGMNT_PRDCT | G17: 2. Concluído | H17: 2. Concluído | J17: =+$J$9/25 -> 2.56 | K17: =+$K$9/25 -> 0.32 | L17: =SUM(R17:CB17) -> 0 | M17: 0.0625
A18: Assessment | B18: GD | C18: Exclusivo GD - Campos Deloitte | D18: 2. Campo | E18: lt002_instrument | F18: GRSS_CMMSSN_EXPNS | G18: 2. Concluído | H18: 2. Concluído | J18: =+$J$9/25 -> 2.56 | K18: =+$K$9/25 -> 0.32 | L18: =SUM(R18:CB18) -> 0 | M18: 0.0625
A19: Assessment | B19: GD | C19: Exclusivo GD - Campos Deloitte | D19: 2. Campo | E19: lt002_instrument | F19: GNS_FNNCL_TRNSCTN_EXCHNG_DFFRNCS | G19: 2. Concluído | H19: 2. Concluído | J19: =+$J$9/25 -> 2.56 | K19: =+$K$9/25 -> 0.32 | L19: =SUM(R19:CB19) -> 0 | M19: 0.0625
A20: Assessment | B20: GD | C20: Exclusivo GD - Campos Deloitte | D20: 2. Campo | E20: lt002_instrument | F20: FLG_INTRBSNSS | G20: 2. Concluído | H20: 3. Em Análise | J20: =+$J$9/25 -> 2.56 | K20: =+$K$9/25 -> 0.32 | L20: =SUM(R20:CB20) -> 0 | M20: 0.0625
A21: Assessment | B21: GD | C21: Exclusivo GD - Campos Deloitte | D21: 2. Campo | E21: lt002_instrument | F21: INTRBSNSS_ADJ_COD | G21: 2. Concluído | H21: 3. Em Análise | J21: =+$J$9/25 -> 2.56 | K21: =+$K$9/25 -> 0.32 | L21: =SUM(R21:CB21) -> 0.5 | M21: 0.0625 | S21: 0.5
A22: Assessment | B22: GD | C22: Exclusivo GD - Campos Deloitte | D22: 2. Campo | E22: lt002_instrument | F22: COD_SOC_DSTNTN | G22: 2. Concluído | H22: 3. Em Análise | J22: =+$J$9/25 -> 2.56 | K22: =+$K$9/25 -> 0.32 | L22: =SUM(R22:CB22) -> 0.5 | M22: 0.0625 | S22: 0.5
A23: Assessment | B23: GD | C23: Exclusivo GD - Campos Deloitte | D23: 2. Campo | E23: lt002_instrument | F23: BSNSS_AREA_DSTNTN | G23: 2. Concluído | H23: 2. Concluído | J23: =+$J$9/25 -> 2.56 | K23: =+$K$9/25 -> 0.32 | L23: =SUM(R23:CB23) -> 0.5 | M23: 0.0625 | S23: 0.5
A24: Assessment | B24: GD | C24: Exclusivo GD - Campos Deloitte | D24: 2. Campo | E24: lt002_instrument | F24: AVRG_BLNC_OFF_BLNC | G24: 2. Concluído | H24: 2. Concluído | J24: =+$J$9/25 -> 2.56 | K24: =+$K$9/25 -> 0.32 | L24: =SUM(R24:CB24) -> 0.5 | M24: 0.0625 | S24: 0.5
A25: Assessment | B25: GD | C25: Exclusivo GD - Campos Deloitte | D25: 2. Campo | E25: lt002_instrument | F25: INTRNL_TRNSFR_RT_OFF_BLNC | G25: 2. Concluído | H25: 2. Concluído | J25: =+$J$9/25 -> 2.56 | K25: =+$K$9/25 -> 0.32 | L25: =SUM(R25:CB25) -> 0.5 | M25: 0.0625 | S25: 0.5
A26: Assessment | B26: GD | C26: Exclusivo GD - Campos Deloitte | D26: 2. Campo | E26: lt002_instrument | F26: GRSS_CMMSSN_INCM_OFF_BLNC | G26: 2. Concluído | H26: 2. Concluído | J26: =+$J$9/25 -> 2.56 | K26: =+$K$9/25 -> 0.32 | L26: =SUM(R26:CB26) -> 0.5 | M26: 0.0625 | S26: 0.5
A27: Assessment | B27: GD | C27: Exclusivo GD - Campos Deloitte | D27: 2. Campo | E27: lt002_instrument | F27: GRSS_CMMSSN_EXPNS_OFF_BLNC | G27: 2. Concluído | H27: 2. Concluído | J27: =+$J$9/25 -> 2.56 | K27: =+$K$9/25 -> 0.32 | L27: =SUM(R27:CB27) -> 0 | M27: 0.0625
A28: Assessment | B28: GD | C28: Exclusivo GD - Campos Deloitte | D28: 2. Campo | E28: lt002_instrument | F28: RWA_OFF_BLNC | G28: 2. Concluído | H28: 2. Concluído | J28: =+$J$9/25 -> 2.56 | K28: =+$K$9/25 -> 0.32 | L28: =SUM(R28:CB28) -> 0 | M28: 0.0625
A29: Assessment | B29: GD | C29: Exclusivo GD - Campos Deloitte | D29: 2. Campo | E29: lt002_instrument | F29: GRSS_INTRST_EXPNS | G29: 2. Concluído | H29: 2. Concluído | J29: =+$J$9/25 -> 2.56 | K29: =+$K$9/25 -> 0.32 | L29: =SUM(R29:CB29) -> 0 | M29: 0.0625
A30: Assessment | B30: GD | C30: Exclusivo GD - Campos Deloitte | D30: 2. Campo | E30: lt002_instrument | F30: NT_LN_LSS_PRVSN_OFF_BLNC | G30: 2. Concluído | H30: 2. Concluído | J30: =+$J$9/25 -> 2.56 | K30: =+$K$9/25 -> 0.32 | L30: =SUM(R30:CB30) -> 0 | M30: 0.0625
A31: Assessment | B31: GD | C31: Exclusivo GD - Campos Deloitte | D31: 2. Campo | E31: lt002_instrument | F31: GRSS_INTRST_INCM_CCRR | G31: 2. Concluído | H31: 2. Concluído | J31: =+$J$9/25 -> 2.56 | K31: =+$K$9/25 -> 0.32 | L31: =SUM(R31:CB31) -> 0 | M31: 0.0625
A32: Assessment | B32: GD | C32: Exclusivo GD - Campos Deloitte | D32: 2. Campo | E32: lt002_instrument | F32: GRSS_INTRST_EXPNS_CCRR | G32: 2. Concluído | H32: 2. Concluído | J32: =+$J$9/25 -> 2.56 | K32: =+$K$9/25 -> 0.32 | L32: =SUM(R32:CB32) -> 0 | M32: 0.0625
A33: Assessment | B33: GD | C33: Exclusivo GD - Campos Deloitte | D33: 2. Campo | E33: lt002_instrument | F33: GRSS_CMMSSN_INCM_CCRR | G33: 2. Concluído | H33: 2. Concluído | J33: =+$J$9/25 -> 2.56 | K33: =+$K$9/25 -> 0.32 | L33: =SUM(R33:CB33) -> 0 | M33: 0.0625
A34: Assessment | B34: GD | C34: Exclusivo GD - Campos Deloitte | D34: 2. Campo | E34: lt002_instrument | F34: GRSS_CMMSSN_EXPNS_CCRR | G34: 2. Concluído | H34: 2. Concluído | J34: =+$J$9/25 -> 2.56 | K34: =+$K$9/25 -> 0.32 | L34: =SUM(R34:CB34) -> 0 | M34: 0.0625
A35: Assessment | B35: GD | C35: Exclusivo GD - Campos Deloitte | D35: 2. Campo | E35: lt002_instrument | F35: GNS_FNNCL_TRNSCTN_EXCHNG_CCRR | G35: 2. Concluído | H35: 2. Concluído
A36: Assessment | B36: GD | C36: Exclusivo GD - Campos Deloitte | D36: 2. Campo | E36: lt002_instrument | F36: BSNSS_AREA_CCRR | G36: 2. Concluído | H36: 2. Concluído
A37: Assessment | B37: GD | C37: Exclusivo GD - Campos Deloitte | D37: 2. Campo | E37: lt002_instrument | F37: GRSS_CMMSSN_INCM_OFF_BLNC_CCRR | G37: 2. Concluído | H37: 2. Concluído
A38: Assessment | B38: GD | C38: Exclusivo GD - Campos Deloitte | D38: 2. Campo | E38: lt002_instrument | F38: GRSS_CMMSSN_EXPNS_OFF_BLNC_CCRR | G38: 2. Concluído | H38: 2. Concluído
A39: Assessment | B39: GD | C39: Exclusivo GD - Campos Deloitte | D39: 2. Campo | E39: lt002_instrument | F39: FLG_INSTRMNT_CNCLLD | G39: 0. Cancelado | H39: 0. Cancelado
A40: Assessment | B40: GD | C40: Exclusivo GD - Campos Deloitte | D40: 2. Campo | E40: lt824_assoc_kpi_gd | F40: ambito | G40: 2. Concluído | H40: 2. Concluído
A41: Assessment | B41: GD | C41: Exclusivo GD - Campos Deloitte | D41: 2. Campo | E41: lt824_assoc_kpi_gd | F41: tipo_conta_local | G41: 2. Concluído | H41: 2. Concluído
A42: Assessment | B42: GD | C42: Exclusivo GD - Campos Deloitte | D42: 2. Campo | E42: lt824_assoc_kpi_gd | F42: valor_gd | G42: 2. Concluído | H42: 2. Concluído
A43: Assessment | B43: GD | C43: Exclusivo GD - Campos Deloitte | D43: 2. Campo | E43: lt824_assoc_kpi_gd | F43: kpi | G43: 2. Concluído | H43: 2. Concluído
A44: Assessment | B44: GD | C44: Exclusivo GD - Campos Deloitte | D44: 2. Campo | E44: lt824_assoc_kpi_gd | F44: ordem | G44: 2. Concluído | H44: 2. Concluído
A45: Assessment | B45: GD | C45: Exclusivo GD - Campos Deloitte | D45: 2. Campo | E45: lt824_assoc_kpi_gd | F45: ref_date | G45: 2. Concluído | H45: 2. Concluído
A46: Assessment | B46: GD | C46: Exclusivo GD - Campos Deloitte | D46: 2. Campo | E46: lt002_instrument | F46: SSTNBL_INDCTR | G46: 0. Cancelado | H46: 0. Cancelado
...

Sheet MacroPlano
B6: MacroPlano | Testes GD
F8: Datas Estimadas | H8: Datas Reais | K8: Semana 1 | M8: Semana 2 | R8: Semana 3 | W8: Semana 4 | AB8: Semana 5 | AG8: Semana 6 | AL8: Semana 7 | AQ8: Semana 8 | AV8: Semana 9 | BA8: Semana 10 | BF8: Semana 11 | BK8: Semana 12
B9: ID | C9: Atividades | D9: Owner | E9: Status | F9: Data Inicio | G9: Data Fim | H9: Data Inicio | I9: Data Fim | K9: 02/jan-03/jan | M9: 06/jan-10/jan | R9: 13/jan-17/jan | W9: 20/jan-24/jan | AB9: 27/jan-31/jan | AG9: 03/fev-07/fev | AL9: 10/fev-14/fev | AQ9: 17/fev-21/fev | AV9: 24/fev-28/fev | BA9: 03/mar-07/mar | BF9: 10/mar-14/mar | BK9: 17/mar-21/mar
B10: 0. | C10: Gestão
B11: 0.1 | C11: Reuniões de PdS | D11: Neyond/CdG/IT | E11: = | F11: 45659 | G11: 45736 | K11: « | P11: « | U11: « | Z11: « | AE11: « | AJ11: « | AO11: « | AT11: « | AY11: « | BD11: « | BI11: « | BN11: «
B13: 1. | C13: Package 1
B14: 1.1 | C14: Definição de requisitos - campos da lt002_instrument | D14: Neyond | E14: = | F14: 45663 | G14: 45678 | I14: 45678 | X14: «
B15: 1.1.1 | C15: INTRNL_TRNSFR_RT | E15: =
B16: 1.1.2 | C16: MNGMNT_PRDCT | E16: =
B17: 1.1.3 | C17: FLG_INTRBSNSS | E17: =
B18: 1.1.4 | C18: INTRBSNSS_ADJ_COD | E18: =
B19: 1.1.5 | C19: COD_SOC_DSTNTN | E19: =
B20: 1.1.6 | C20: BSNSS_AREA_DSTNTN | E20: =
B21: 1.1.7 | C21: INTRNL_TRNSFR_RT_OFF_BLNC | E21: =
B22: 1.1.8 | C22: RWA_OFF_BLNC | E22: =
B23: 1.2 | C23: Simulação dos campos do package 1 | D23: Neyond | E23: = | F23: 45663 | G23: 45737
B24: 1.2.1 | C24: INTRNL_TRNSFR_RT | E24: =
B25: 1.2.2 | C25: MNGMNT_PRDCT | E25: =
B26: 1.2.3 | C26: FLG_INTRBSNSS | E26: =
B27: 1.2.4 | C27: INTRBSNSS_ADJ_COD | E27: =
B28: 1.2.5 | C28: COD_SOC_DSTNTN | E28: =
B29: 1.2.6 | C29: BSNSS_AREA_DSTNTN | E29: =
B30: 1.2.7 | C30: INTRNL_TRNSFR_RT_OFF_BLNC | E30: =
B31: 1.2.8 | C31: RWA_OFF_BLNC | E31: =
B33: 2. | C33: Package 2
B34: 2.1 | C34: Definição de requisitos - campos da lt002_instrument (comum PM e LF) | D34: Neyond | E34: = | F34: 45698 | G34: 45705 | I34: 45705 | AQ34: «
B35: 2.1.1 | C35: CCF | E35: =
B36: 2.1.2 | C36: EAD | E36: =
B37: 2.1.3 | C37: TYP_OFF_BLNC_PRDCT | E37: =
B38: 2.1.4 | C38: COD_SOC | E38: =
B39: 2.1.5 | C39: SUBPORTFOLIO_ID | E39: =
B40: 2.1.6 | C40: DT_RFRNC | E40: =
B41: 2.1.7 | C41: DFLT_STTS_INSTRMNT | E41: =
B42: 2.1.8 | C42: IMPRMNT_STTS | E42: =
B43: 2.1.9 | C43: PRFRMNG_STTS | E43: =
B44: 2.1.10 | C44: TYP_INSTRMNT | E44: =
B45: 2.1.11 | C45: GRSS_CRRYNG_AMNT_INSTRMNT | E45: =
B46: 2.1.12 | C46: ACCMLTD_CHNGS_FV_CR_INSTRMNT | E46: =
... B52: 2.1.18 | C52: COD_SOC_INTRGRP | E52: =
B53: 2.2 | C53: Simulação dos campos do package 2 | D53: Neyond | E53: N/A & TBD | F53: TBD | G53: TBD
...

Sheet MacroPlano - Auxiliar
B2: Sub-âmbito | C2: Tabela | D2: Campo | E2: Fase de Entrega | F2: Data estimada | G2: Necessário simular? | H2: Observações | I2: Next Steps | J2: Status a 06/fev | K2: Altera corporação? | L2: Notas
B3: Exclusivo GD - Campos Deloitte | C3: lt002_instrument | D3: AVRG_BLNC | E3: Package 4 | F3: 45712 | G3: Sim | H3: necessário reenviar | I3: Analisar e ajustar metodologia de cruzamento no word + fazer a simulação | J3: 4. Validação da especificação | K3: Alterar especificação | L3: Email enviado a LCM + CdG no dia 05/fev para validação da especificação.
B4: Exclusivo GD - Campos Deloitte | C4: lt002_instrument | D4: NW_BSNSS | E4: Package 5 | F4: 45719 | G4: Sim | H4: necessário reenviar, falta saber se é para preencher para linhas BA | I4: Atualizar documento word + fazer a simulação | J4: 4. Validação da especificação | K4: Não alterar especificação | L4: Email enviado a LCM + CdG no dia 05/fev para validação da especificação.
B5: Exclusivo GD - Campos Deloitte | C5: lt002_instrument | D5: GRSS_INTRST_INCM | E5: Package 4 | F5: 45712 | G5: Sim | H5: necessário reenviar | I5: Analisar e ajustar metodologia de cruzamento no word + fazer a simulação | J5: 4. Validação da especificação | K5: Alterar especificação | L5: Email enviado a LCM + CdG no dia 05/fev para validação da especificação.
B6: Exclusivo GD - Campos Deloitte | C6: lt002_instrument | D6: GRSS_CMMSSN_INCM | E6: Package 4 | F6: 45712 | G6: Sim | H6: necessário reenviar | I6: Analisar e ajustar metodologia de cruzamento no word + fazer a simulação | J6: 4. Validação da especificação | K6: Alterar especificação | L6: Email enviado a LCM + CdG no dia 05/fev para validação da especificação.
B7: Exclusivo GD - Campos Deloitte | C7: lt002_instrument | D7: INTRNL_TRNSFR_RT | E7: Package 1 | F7: 45678 | G7: Sim | H7: já enviado no word + excel | I7: Fazer a simulação | J7: 1. Concluído | K7: Não alterar especificação | L7: Não alterou para YTD, e vai ser sempre preenchido com o N/A.
