Workbook

Sheet Status
U7: Status Atual | V7: (All)
U9: Row Labels | V9: Count of Categorização
C10: Âmbito (Projeto) | D10: PM | I10: Âmbito (Projeto) | J10: PM | U10: Fora OSI | V10: 119
R11: Potencial de proposta - Campos concluídos, sem melhorias identidicadas, mas com necessidade de documentação | U11: Analisar controlos NOK | V11: 16
C12: Count of Status Atual | J12: OSI VS FORA OSI | R12: Potencial de proposta - Campos com melhorias mais complexas identificadas na OSI ou fora da mesma. | U12: Melhorias estruturais (garantir coerência entre campos) | V12: 14
C13: Status Atual | D13: Fora OSI | E13: OSI | F13: Grand Total | J13: Fora OSI | L13: OSI | N13: Total # | O13: Total % | R13: Quick-win âmbito do projeto em curso | U13: Novo campo | V13: 9
C14: 1. Especificar | D14: 9 | E14: 1 | F14: 10 | I14: Quick Win | J14: # | K14: % | L14: # | M14: % | U14: Necessidade de correção de erros | V14: 5
C15: 2. Alterar especificação | D15: 3 | E15: 14 | F15: 17 | I15: Campo Fechado | J15: 69 | K15: 0.26436782 | L15: 96 | M15: 0.36781609 | N15: 165 | O15: 0.63218391 | U15: Campo concluído, mas sem ou pouca informação na fonte | V15: 10
C16: 3. Pendente de decisão | E16: 2 | F16: 2 | I16: Não | J16: 30 | K16: 0.11494253 | L16: 40 | M16: 0.1532567 | N16: 70 | O16: 0.26819923 | U16: Campo concluido | V16: 65
C17: 4.1 Em implementação - Re-especificação | D17: 1 | F17: 1 | I17: Sim | J17: 3 | K17: 0.011494253 | L17: 23 | M17: 0.088122605 | N17: 26 | O17: 0.099616858 | U17: OSI | V17: 227
C18: 5.1 Em testes - Re-especificação | D18: 4 | E18: 18 | F18: 22 | I18: Grand Total | J18: 102 | K18: 0.3908046 | L18: 159 | M18: 0.6091954 | N18: 261 | O18: 1 | U18: Alteração de especificação por parte do BCE | V18: 8
C19: 5.2 Em testes - Incidência | E19: 3 | F19: 3 | U19: Analisar controlos NOK | V19: 41
C20: 7. Analisar controlos e completude | D20: 16 | E20: 26 | F20: 42 | U20: Melhorias estruturais (garantir coerência entre campos) | V20: 37
C21: 8. Concluído - sem dados | D21: 6 | E21: 1 | F21: 7 | U21: Novo campo | V21: 6
C22: 9. Concluído | D22: 63 | E22: 94 | F22: 157 | U22: Necessidade de correção de erros | V22: 21
C23: Grand Total | D23: 102 | E23: 159 | F23: 261 | U23: Pendente de decisão | V23: 24
U24: Campo concluído, mas sem ou pouca informação na fonte | V24: 2
U25: Campo concluido | V25: 88
U26: Grand Total | V26: 346

Sheet PDS (old)
B8: 2 | C8: Especificação | D8: 11 | E8: Especificação
C9: ORGNL_PRTCTN_VL | E9: Campos Contabilidade
C10: DT_ORGNL_PRTCTN_VL | E10: IMPRMNT_STTS
E11: PRFRMNG_STTS
E12: IMPRMNT_STTS_PRVS
E13: PRFRMNG_STTS_PRVS
E14: DPD_12M_PRFRMNG_STTS
E15: DPD_24M_PRFRMNG_STTS
E16: DPD_PRFRMNG_STTS
E17: DT_IMPRMNT_STTS
E18: DT_IMPRMNT_STTS_PRVS
E19: DT_PRFRMNG_STTS
E20: DT_PRFRMNG_STTS_PRVS
J27: 1. Especificar | K27: 2. Alterar especificação | L27: 3. Pendente de decisão | M27: 4.1 Em implementação - Re-especificação | N27: 4.2 Em implementação - Incidência | O27: 5.1 Em testes - Re-especificação | P27: 5.2 Em testes - Incidência | Q27: 6. Outros Desenvolvimentos | R27: 7. Analisar controlos e completude | S27: 8. Concluído - sem dados | T27: 9. Concluído
I28: Status Atual | J28: =COUNTIF(Detalhe!$L:$L,J27) -> 41 | K28: =COUNTIF(Detalhe!$L:$L,K27) -> 30 | L28: =COUNTIF(Detalhe!$L:$L,L27) -> 2 | M28: =COUNTIF(Detalhe!$L:$L,M27) -> 1 | N28: =COUNTIF(Detalhe!$L:$L,N27) -> 15 | O28: =COUNTIF(Detalhe!$L:$L,O27) -> 6 | P28: =COUNTIF(Detalhe!$L:$L,P27) -> 5 | Q28: =COUNTIF(Detalhe!$L:$L,Q27) -> 0 | ... T28: =COUNTIF(Detalhe!$L:$L,T27) -> 249
I29: Status Inicial (pós OSI) | J29: =COUNTIF(Detalhe!$F:$F,J27) -> 74 | K29: =COUNTIF(Detalhe!$F:$F,K27) -> 42 | L29: =COUNTIF(Detalhe!$F:$F,L27) -> 17 | M29: =COUNTIF(Detalhe!$F:$F,M27) -> 4 | N29: =COUNTIF(Detalhe!$F:$F,N27) -> 0 | O29: =COUNTIF(Detalhe!$F:$F,O27) -> 21 | P29: =COUNTIF(Detalhe!$F:$F,P27) -> 17 | Q29: =COUNTIF(Detalhe!$F:$F,Q27) -> 10 | ... T29: =COUNTIF(Detalhe!$F:$F,T27) -> 151
I30: Variação | J30: {=_xlfn.IFS(J28>J29, "↑",J28<J29, "↓",J28=J29, "=")} -> ↓ | K30: {=_xlfn.IFS(K28>K29, "↑",K28<K29, "↓",K28=K29, "=")} -> ↓ | L30: {=_xlfn.IFS(L28>L29, "↑",L28<L29, "↓",L28=L29, "=")} -> ↓ | M30: {=_xlfn.IFS(M28>M29, "↑",M28<M29, "↓",M28=M29, "=")} -> ↓ | N30: {=_xlfn.IFS(N28>N29, "↑",N28<N29, "↓",N28=N29, "=")} -> ↑ | O30: {=_xlfn.IFS(O28>O29, "↑",O28<O29, "↓",O28=O29, "=")} -> ↓ | P30: {=_xlfn.IFS(P28>P29, "↑",P28<P29, "↓",P28=P29, "=")} -> ↓ | Q30: {=_xlfn.IFS(Q28>Q29, "↑",Q28<Q29, "↓",Q28=Q29, "=")} -> ↓ | ... T30: {=_xlfn.IFS(T28>T29, "↑",T28<T29, "↓",T28=T29, "=")} -> ↑
I31: Progressão | J31: =J28-J29 -> -33 | K31: =K28-K29 -> -12 | L31: =L28-L29 -> -15 | M31: =M28-M29 -> -3 | N31: =N28-N29 -> 15 | O31: =O28-O29 -> -15 | P31: =P28-P29 -> -12 | Q31: =Q28-Q29 -> -10 | ... T31: =T28-T29 -> 98
J34: 3. Pendente de decisão - Identificados temas em OSI nos campos e é necessário identificar cauisticas (pode ficar como está ou ser alterado). Quem toma as decisões são as areas de negócio, porém o Luis poderá dar a decisão final
C35: 45555
B36: Tema | D36: Questão | I36: Decisão
B37: DT_ORGNL_PRTCTN_VL | D37: O campo 'dtvalia_resp_bem' só possuI informação para datas de referências posteriores a 2024-07-31. Como devemos proceder caso seja necessário reportar dados anteriores a Jul.2024? | I37: Manter a especificação com mapeamento após jul.24
B38: ORGNL_PRTCTN_VL | D38: O campo 'mavaliai_resp_bem' só possuI informação para datas de referências posteriores a 2024-07-31. Como devemos proceder caso seja necessário reportar dados anteriores a Jul.2024? | I38: Manter a especificação com mapeamento após jul.24
B39: DT_CNSTRCTN_STTS | D39: Teremos de criar uma tabela auxiliar com o histórico dos estados de construção e mapear para a data mais antiga do estado de construção atual. Uma vez que o MUG tem uma ótica de atualização diária, para o mapeamento e criação desta tabela auxiliar devemos olhar para uma ótica ou mensal? | I39: Criar tabela auxiliar e ir buscar a ref_date. Devemos utilizar uma ótica diária. Analisar controlos por amostragem.
B40: DT_CNSTRCTN_STTS | D40: Caso o bem só tenha um estado desde sempre/ desde que foi recebido como garantia devemos reportar a DT_INCPTN? E caso tenha mais do que um instrumento associado, qual a dt_incptn que devemos utilizar? A mais antiga? | I40: Questionar Corporação: 1) Caso o bem só tenha um estado desde sempre/ desde que foi recebido como garantia qual a data que devemos reportar? 2) A DR_CNSTRCTN_STTS pode ser anterior à DT_INCPTN? Estes casos poderão acontecer caso uma garantia esteja associada a mais do que um contrato.
B41: Campos Contabilidade vs Imparidade | D41: 12 campos com informação de Imparidade, em que a Contabilidade assumiu a ownership uma vez que reporta este dado. Avançamos na re-especificação dos campos utilizando o mapeamento das tabelas de Contabilidade para datas de referência após Dez.22 e a tabela 7_8 de Imparidade para datas anteriores a Dez.22? IMPRMNT_STTS PRFRMNG_STTS IMPRMNT_STTS_PRVS POCI PRFRMNG_STTS_PRVS DPD_12M_PRFRMNG_STTS DPD_24M_PRFRMNG_STTS DPD_PRFRMNG_STTS DT_IMPRMNT_STTS DT_IMPRMNT_STTS_PRVS DT_PRFRMNG_STTS DT_PRFRMNG_STTS_PRVS | I41: Atualmente o campo de stage está a ser populado com informação de Imparidade até Dez.19 e a partir de Jan.20 com informação da FR004. Deste modo, a alteração de especificação prende-se apenas com a alteração da data para Dez.22. Solicitar a Alexandre Gonçalvez que validem os campos após implementação de IT, sem prejuizo dos testes por parte da equipa LT.
B42: Campos Imparidade - Fonte da Verdade | D42: 12 campos de Imparidade. Devemos sugerir mapeamento dos campos tendo em conta a tabela de o David Texugo indicou e enviar para validação? Enviamos um e-mail a solicitar esse mapeamento, mas sem resposta até ao momento. EIR EIR_INCPTN IFRS9_CCF IFRS9_EAD IFRS9_LGD INTRNL_SGMNT_IFRS9 PD_IFRS9_12M_INCPTN PD_IFRS9_12M_RD PD_IFRS9_12M_RD_T1 PD_IFRS9_LFTM_INCPTN PD_IFRS9_RMNNG_LFTM_INCPTN PD_IFRS9_RMNNG_LFTM_RD | I42: Fazer proposta. Segmentar por campos OK e NOK.
B43: PRTCTN_VL | D43: 40 garantias imóveis com valor de proteção a zero, cuja origem são a G39 ou G26. Analisados por Henrique e Susana: 35 casos encontram-se no nosso ficheiro de Erros dos Métodos Indiciários com falta de informação: 33 – Apenas com informação na GP26 1 – Valor de avaliação a zero 1 - % de CI não encontrado para o critério 2 casos são do cliente Vilamoura World – imóvel não identificado 3 casos são do cliente IAD da Madeira e já foram distratados
B44: PRTCTN_VL | D44: 11 Garantias Imóveis cuja origem provêm das CSs, com valor da proteção igual a zero (não são clones). Para quem devemos enviar estes casos para análise?
B45: PRTCTN_VL | D45: 121 Garantias Imóveis com contratos de Leasing associados, cujo valor da proteção é zero (não são clones). Para quem devemos enviar estes casos para análise?
B46: PRTCTN_VL | D46: 1 garantia Financeira, cujo valor da proteção é zero – Caso não está na GT018 para datas posteriores a 2024-05-31. Devíamos retirar da LT os casos com o msldreal a zero (temos 25 casos)?
B47: PRTCTN_VL | D47: 46 casos com data inválidas 0001-01-01 para análise da equipa de leasing.
J49: 4.1 respecificado
J50: 4.2 IT não implementou corretamente
J51: 6. Outros desenvolvimentos - Não podemos avançar no campo por haver necessidade de alguma alteração no campo fonte
J52: 7. Controlos corporativos NOK que necessitam de ser analizados
J53: 8. Campos que não são para mexer
J54: 9. A partir do momento que sobe a CD

Sheet Aux.
B2: Estado | C2: Status Inicial | E2: Status Atual | F2: Status Atual (%) | G2: Progressão
B3: 1. Especificar | C3: =COUNTIFS(Detalhe!F:F,B3,Detalhe!X:X,"PM") -> 10 | D3: =C3/$C$14 -> 0.038314176 | E3: =COUNTIFS(Detalhe!L:L,B3,Detalhe!X:X,"PM") -> 8 | F3: =E3/$E$14 -> 0.030651341 | G3: =E3-C3 -> -2
B4: 2. Alterar especificação | C4: =COUNTIFS(Detalhe!F:F,B4,Detalhe!X:X,"PM") -> 18 | D4: =C4/$C$14 -> 0.068965517 | E4: =COUNTIFS(Detalhe!L:L,B4,Detalhe!X:X,"PM") -> 17 | F4: =E4/$E$14 -> 0.0651341 | G4: =E4-C4 -> -1
B5: 3. Pendente de decisão | C5: =COUNTIFS(Detalhe!F:F,B5,Detalhe!X:X,"PM") -> 11 | D5: =C5/$C$14 -> 0.042145594 | E5: =COUNTIFS(Detalhe!L:L,B5,Detalhe!X:X,"PM") -> 2 | F5: =E5/$E$14 -> 0.0076628352 | G5: =E5-C5 -> -9
B6: 4.1 Em implementação - Re-especificação | C6: =COUNTIFS(Detalhe!F:F,B6,Detalhe!X:X,"PM") -> 4 | D6: =C6/$C$14 -> 0.01532567 | E6: =COUNTIFS(Detalhe!L:L,B6,Detalhe!X:X,"PM") -> 1 | F6: =E6/$E$14 -> 0.0038314176 | G6: =E6-C6 -> -3
B7: 4.2 Em implementação - Incidência | C7: =COUNTIFS(Detalhe!F:F,B7,Detalhe!X:X,"PM") -> 0 | D7: =C7/$C$14 -> 0 | E7: =COUNTIFS(Detalhe!L:L,B7,Detalhe!X:X,"PM") -> 3 | F7: =E7/$E$14 -> 0.011494253 | G7: =E7-C7 -> 3
B8: 5.1 Em testes - Re-especificação | C8: =COUNTIFS(Detalhe!F:F,B8,Detalhe!X:X,"PM") -> 11 | D8: =C8/$C$14 -> 0.042145594 | E8: =COUNTIFS(Detalhe!L:L,B8,Detalhe!X:X,"PM") -> 6 | F8: =E8/$E$14 -> 0.022988506 | G8: =E8-C8 -> -5
B9: 5.2 Em testes - Incidência | C9: =COUNTIFS(Detalhe!F:F,B9,Detalhe!X:X,"PM") -> 11 | D9: =C9/$C$14 -> 0.042145594 | E9: =COUNTIFS(Detalhe!L:L,B9,Detalhe!X:X,"PM") -> 3 | F9: =E9/$E$14 -> 0.011494253 | G9: =E9-C9 -> -8
B10: 6. Outros Desenvolvimentos | C10: =COUNTIFS(Detalhe!F:F,B10,Detalhe!X:X,"PM") -> 0 | D10: =C10/$C$14 -> 0 | E10: =COUNTIFS(Detalhe!L:L,B10,Detalhe!X:X,"PM") -> 0 | F10: =E10/$E$14 -> 0 | G10: =E10-C10 -> 0
B11: 7. Analisar controlos e completude | C11: =COUNTIFS(Detalhe!F:F,B11,Detalhe!X:X,"PM") -> 42 | D11: =C11/$C$14 -> 0.16091954 | E11: =COUNTIFS(Detalhe!L:L,B11,Detalhe!X:X,"PM") -> 43 | F11: =E11/$E$14 -> 0.16475096 | G11: =E11-C11 -> 1
B12: 8. Concluído - sem dados | C12: =COUNTIFS(Detalhe!F:F,B12,Detalhe!X:X,"PM") -> 7 | D12: =C12/$C$14 -> 0.026819923 | E12: =COUNTIFS(Detalhe!L:L,B12,Detalhe!X:X,"PM") -> 7 | F12: =E12/$E$14 -> 0.026819923 | G12: =E12-C12 -> 0
B13: 9. Concluído | C13: =COUNTIFS(Detalhe!F:F,B13,Detalhe!X:X,"PM") -> 147 | D13: =C13/$C$14 -> 0.56321839 | E13: =COUNTIFS(Detalhe!L:L,B13,Detalhe!X:X,"PM") -> 171 | F13: =E13/$E$14 -> 0.65517241 | G13: =E13-C13 -> 24
C14: =SUM(C3:C13) -> 261 | E14: =SUM(E3:E13) -> 261

Sheet PDS
B8: 2 | C8: Especificação | D8: 11 | E8: Especificação
C9: ORGNL_PRTCTN_VL | E9: Campos Contabilidade
C10: DT_ORGNL_PRTCTN_VL | E10: IMPRMNT_STTS
E11: PRFRMNG_STTS
E12: IMPRMNT_STTS_PRVS
E13: PRFRMNG_STTS_PRVS
E14: DPD_12M_PRFRMNG_STTS
E15: DPD_24M_PRFRMNG_STTS
E16: DPD_PRFRMNG_STTS
E17: DT_IMPRMNT_STTS
E18: DT_IMPRMNT_STTS_PRVS
E19: DT_PRFRMNG_STTS
E20: DT_PRFRMNG_STTS_PRVS
J27: 1. Especificar | K27: 2. Alterar especificação | L27: 3. Pendente de decisão | M27: 4.1 Em implementação - Re-especificação | N27: 4.2 Em implementação - Incidência | O27: 5.1 Em testes - Re-especificação | P27: 5.2 Em testes - Incidência | Q27: 6. Outros Desenvolvimentos | R27: 7. Analisar controlos e completude | S27: 8. Concluído - sem dados | T27: 9. Concluído
I28: Status Atual | J28: =COUNTIFS(Detalhe!$L:$L,J27,Detalhe!$X:$X,"PM") -> 8 | K28: =COUNTIFS(Detalhe!$L:$L,K27,Detalhe!$X:$X,"PM") -> 17 | L28: =COUNTIFS(Detalhe!$L:$L,L27,Detalhe!$X:$X,"PM") -> 2 | M28: =COUNTIFS(Detalhe!$L:$L,M27,Detalhe!$X:$X,"PM") -> 1 | N28: =COUNTIFS(Detalhe!$L:$L,N27,Detalhe!$X:$X,"PM") -> 3 | O28: =COUNTIFS(Detalhe!$L:$L,O27,Detalhe!$X:$X,"PM") -> 6 | P28: =COUNTIFS(Detalhe!$L:$L,P27,Detalhe!$X:$X,"PM") -> 3 | Q28: =COUNTIFS(Detalhe!$L:$L,Q27,Detalhe!$X:$X,"PM") -> 0 | ... T28: =COUNTIFS(Detalhe!$L:$L,T27,Detalhe!$X:$X,"PM") -> 171
I29: Status Inicial (pós OSI) | J29: =COUNTIFS(Detalhe!$F:$F,J27,Detalhe!$X:$X,"PM") -> 10 | K29: =COUNTIFS(Detalhe!$F:$F,K27,Detalhe!$X:$X,"PM") -> 18 | L29: =COUNTIFS(Detalhe!$F:$F,L27,Detalhe!$X:$X,"PM") -> 11 | M29: =COUNTIFS(Detalhe!$F:$F,M27,Detalhe!$X:$X,"PM") -> 4 | N29: =COUNTIFS(Detalhe!$F:$F,N27,Detalhe!$X:$X,"PM") -> 0 | O29: =COUNTIFS(Detalhe!$F:$F,O27,Detalhe!$X:$X,"PM") -> 11 | P29: =COUNTIFS(Detalhe!$F:$F,P27,Detalhe!$X:$X,"PM") -> 11 | Q29: =COUNTIFS(Detalhe!$F:$F,Q27,Detalhe!$X:$X,"PM") -> 0 | ... T29: =COUNTIFS(Detalhe!$F:$F,T27,Detalhe!$X:$X,"PM") -> 147
I30: Variação | J30: {=_xlfn.IFS(J28>J29, "↑",J28<J29, "↓",J28=J29, "=")} -> ↓ | K30: {=_xlfn.IFS(K28>K29, "↑",K28<K29, "↓",K28=K29, "=")} -> ↓ | L30: {=_xlfn.IFS(L28>L29, "↑",L28<L29, "↓",L28=L29, "=")} -> ↓ | M30: {=_xlfn.IFS(M28>M29, "↑",M28<M29, "↓",M28=M29, "=")} -> ↓ | N30: {=_xlfn.IFS(N28>N29, "↑",N28<N29, "↓",N28=N29, "=")} -> ↑ | O30: {=_xlfn.IFS(O28>O29, "↑",O28<O29, "↓",O28=O29, "=")} -> ↓ | P30: {=_xlfn.IFS(P28>P29, "↑",P28<P29, "↓",P28=P29, "=")} -> ↓ | Q30: {=_xlfn.IFS(Q28>Q29, "↑",Q28<Q29, "↓",Q28=Q29, "=")} -> = | ... T30: {=_xlfn.IFS(T28>T29, "↑",T28<T29, "↓",T28=T29, "=")} -> ↑
I31: Progressão | J31: =J28-J29 -> -2 | K31: =K28-K29 -> -1 | L31: =L28-L29 -> -9 | M31: =M28-M29 -> -3 | N31: =N28-N29 -> 3 | O31: =O28-O29 -> -5 | P31: =P28-P29 -> -8 | Q31: =Q28-Q29 -> 0 | ... T31: =T28-T29 -> 24
I35: Legenda
I37: 1. Especificar | J37: O campo será especificado pela primeira vez
I38: 2. Alterar especificação | J38: O campo já foi especificado, no entanto foi necessário alterar
I39: 3. Pendente de decisão | J39: Houve algum tema identificado em OSI nos campos e é necessário identificar casuísticas (podendo ficar como está ou ser alterado). Quem toma as decisões são as áreas de negócio, porém o Luis poderá dar a decisão final
I40: 4.1 Em implementação - Re-especificação | J40: O campo já foi re-especificado e está do lado de IT
I41: 4.2 Em implementação - Incidência | J41: O campo já foi re-especificado e entregue, no entanto veio com erros de implementação por parte de IT
I42: 5.1 Em testes - Re-especificação | J42: O campo foi re-especificado e implementado por IT e está em fase de testes
I43: 5.2 Em testes - Incidência | J43: O campo foi re-especificado e implementado por IT, porém foram encontradas incidências que levaram a uma nova fase de testes
I44: 6. Outros Desenvolvimentos | J44: Não podemos avançar no campo por haver necessidade de alguma alteração no campo fonte pendente da área responsável
I45: 7. Analisar controlos e completude | J45: Controlos corporativos NOK que necessitam de ser analizados
I46: 8. Concluído - sem dados | J46: Campos que não são para alterar
I47: 9. Concluído | J47: O campo já subiu a CD

Sheet Detalhe
D2: Quick-win de alta prioridade
D3: Quick-win de média prioridade
C5: TABLE_NAME | D5: COLUMN_NAME | E5: ÂMBITO | F5: Status | G5: Controlos e Completude | H5: Descrição | I5: Detalhe | J5: Quick-win | K5: Data alteração status | L5: Status Atual | M5: Controlos e Completuade atual | N5: Comentários | O5: Data envio para IT | P5: Data Implementação | Q5: Categorização | R5: Structural ECB Loan Tape | S5: Green Dashboard | T5: Pillar III ESG | U5: Green Finance | V5: ESG Risks | W5: Leveraged Finance | X5: Âmbito (Projeto) | Y5: STREAM LF
A6: =C6&"_"&D6 -> INSTRUMENT_ACCMLTD_CHNGS_FV_CR_INSTRMNT | C6: INSTRUMENT | D6: ACCMLTD_CHNGS_FV_CR_INSTRMNT | E6: OSI | F6: 9. Concluído | G6: OK | H6: Concluido, controlos OK | J6: Campo Fechado | K6: 45450 | L6: 9. Concluído | M6: =IF(COUNTIFS(PRO_LT_SCORECARD_FLEX_VALIDATIO!$K:$K, _xlfn.CONCAT(C6,D6), PRO_LT_SCORECARD_FLEX_VALIDATIO!$G:$G, "KO") > 0, "NOK", "OK") -> OK | Q6: Campo concluido | R6: Y | S6: Y | T6: Y | U6: N | V6: N | W6: N | X6: PM | Y6: =_xlfn.IFNA(_xlfn.XLOOKUP(D6,[1]Especificação!$G:$G,[1]Especificação!$C:$C),0) -> 0
A7: =C7&"_"&D7 -> INSTRUMENT_ACCMLTD_IMPRMNT_INSTRMNT | C7: INSTRUMENT | D7: ACCMLTD_IMPRMNT_INSTRMNT | E7: OSI | F7: 9. Concluído | G7: OK | H7: Concluido, controlos OK | J7: Campo Fechado | K7: 45450 | L7: 9. Concluído | M7: =IF(COUNTIFS(PRO_LT_SCORECARD_FLEX_VALIDATIO!$K:$K, _xlfn.CONCAT(C7,D7), PRO_LT_SCORECARD_FLEX_VALIDATIO!$G:$G, "KO") > 0, "NOK", "OK") -> NOK | Q7: Campo concluido | R7: Y | S7: Y | T7: Y | U7: N | V7: N | W7: Y | X7: PM | Y7: =_xlfn.IFNA(_xlfn.XLOOKUP(D7,[1]Especificação!$G:$G,[1]Especificação!$C:$C),0) -> F1. Fora âmbito | Campos concluídos - Sem necessidade de espec.
A8: =C8&"_"&D8 -> INSTRUMENT_ACCMLTD_IMPRMNT_INSTRMNT_PRVS | C8: INSTRUMENT | D8: ACCMLTD_IMPRMNT_INSTRMNT_PRVS | E8: OSI | F8: 5.2 Em testes - Incidência | G8: OK | H8: Campo com incidência. Verificar fonte LT | J8: Sim | K8: 45952 | L8: 7. Analisar controlos e completude | M8: =IF(COUNTIFS(PRO_LT_SCORECARD_FLEX_VALIDATIO!$K:$K, _xlfn.CONCAT(C8,D8), PRO_LT_SCORECARD_FLEX_VALIDATIO!$G:$G, "KO") > 0, "NOK", "OK") -> NOK | N8: 1 Controlo NOK comparação com o Accounting portfolio | P8: 45952 | Q8: Necessidade de correção de erros | R8: Y | S8: N | T8: N | U8: N | V8: N | W8: Y | X8: LF | Y8: =_xlfn.IFNA(_xlfn.XLOOKUP(D8,[1]Especificação!$G:$G,[1]Especificação!$C:$C),0) -> C. Campos em testes ou c/ incidências
A9: =C9&"_"&D9 -> INSTRUMENT_ACCMLTD_WRTFFS_INSTRMNT | C9: INSTRUMENT | D9: ACCMLTD_WRTFFS_INSTRMNT | E9: OSI | F9: 9. Concluído | G9: OK | H9: Concluido, controlos OK | J9: Campo Fechado | K9: 45450 | L9: 9. Concluído | M9: =IF(COUNTIFS(PRO_LT_SCORECARD_FLEX_VALIDATIO!$K:$K, _xlfn.CONCAT(C9,D9), PRO_LT_SCORECARD_FLEX_VALIDATIO!$G:$G, "KO") > 0, "NOK", "OK") -> OK | Q9: Campo concluido | R9: Y | S9: N | T9: N | U9: N | V9: N | W9: Y | X9: PM | Y9: =_xlfn.IFNA(_xlfn.XLOOKUP(D9,[1]Especificação!$G:$G,[1]Especificação!$C:$C),0) -> F1. Fora âmbito | Campos concluídos - Sem necessidade de espec.
A10: =C10&"_"&D10 -> INSTRUMENT_ACCNTNG_CLSSFCTN | C10: INSTRUMENT | D10: ACCNTNG_CLSSFCTN | E10: OSI | F10: 9. Concluído | G10: OK | H10: Concluido, controlos OK | J10: Campo Fechado | K10: 45450 | L10: 9. Concluído | M10: =IF(COUNTIFS(PRO_LT_SCORECARD_FLEX_VALIDATIO!$K:$K, _xlfn.CONCAT(C10,D10), PRO_LT_SCORECARD_FLEX_VALIDATIO!$G:$G, "KO") > 0, "NOK", "OK") -> NOK | Q10: Campo concluido | R10: Y | S10: Y | T10: Y | U10: N | V10: N | W10: Y | X10: PM | Y10: =_xlfn.IFNA(_xlfn.XLOOKUP(D10,[1]Especificação!$G:$G,[1]Especificação!$C:$C),0) -> F1. Fora âmbito | Campos concluídos - Sem necessidade de espec.
A11: =C11&"_"&D11 -> ENTITY_ACCNTNG_FRMWRK_SL | C11: ENTITY | D11: ACCNTNG_FRMWRK_SL | E11: OSI | F11: 2. Alterar especificação | G11: OK | H11: Em especificação (Financial Statments CIB) | I11: Campo implementação, mas com falta de informação para o segmento de clientes CIB | J11: Não | K11: 45450 | L11: 2. Alterar especificação | M11: =IF(COUNTIFS(PRO_LT_SCORECARD_FLEX_VALIDATIO!$K:$K, _xlfn.CONCAT(C11,D11), PRO_LT_SCORECARD_FLEX_VALIDATIO!$G:$G, "KO") > 0, "NOK", "OK") -> OK | Q11: Melhorias estruturais (garantir coerência entre campos) | R11: Y | S11: N | T11: N | U11: N | V11: N | W11: Y | X11: PM & LF | Y11: =_xlfn.IFNA(_xlfn.XLOOKUP(D11,[1]Especificação!$G:$G,[1]Especificação!$C:$C),0) -> F4. Fora âmbito | Re-especificação de campos complexos - Dem. Fin. CIB
A12: =C12&"_"&D12 -> INSTRUMENT_TYP_MRTGG | C12: INSTRUMENT | D12: TYP_MRTGG | E12: OSI | F12: 3. Pendente de decisão | G12: NOK | H12: Alteração da Code list por parte do BCE | J12: Sim | K12: 45568 | L12: 2. Alterar especificação | M12: =IF(COUNTIFS(PRO_LT_SCORECARD_FLEX_VALIDATIO!$K:$K, _xlfn.CONCAT(C12,D12), PRO_LT_SCORECARD_FLEX_VALIDATIO!$G:$G, "KO") > 0, "NOK", "OK") -> NOK | N12: Alterar especificação de acordo com codelist atual. No MUG existem apenas garantias elegiveis para cálculo de capital? Se sim, TYP_MRTGG irá assumir os valores 1, 5 e N/A. Caso contrário assumirá os valores 1, 5, 6 e N/A. | Q12: Alteração de especificação por parte do BCE | R12: Y | S12: N | T12: N | U12: N | V12: N | W12: N | X12: PM | Y12: =_xlfn.IFNA(_xlfn.XLOOKUP(D12,[1]Especificação!$G:$G,[1]Especificação!$C:$C),0) -> 0
A13: =C13&"_"&D13 -> INSTRUMENT_AMNT_D_AT_MTRTY | C13: INSTRUMENT | D13: AMNT_D_AT_MTRTY | E13: OSI | F13: 1. Especificar | G13: NOK | H13: Re-especificar o campo utilizando o código da OSI (código é uma proxy com base no tipo de amortização e na frequência de pagamentos) | J13: Não | K13: 45958 | L13: 9. Concluído | M13: =IF(COUNTIFS(PRO_LT_SCORECARD_FLEX_VALIDATIO!$K:$K, _xlfn.CONCAT(C13,D13), PRO_LT_SCORECARD_FLEX_VALIDATIO!$G:$G, "KO") > 0, "NOK", "OK") -> NOK | P13: 45958 | Q13: Novo campo | R13: Y | S13: N | T13: N | U13: N | V13: N | W13: Y | X13: LF | Y13: =_xlfn.IFNA(_xlfn.XLOOKUP(D13,[1]Especificação!$G:$G,[1]Especificação!$C:$C),0) -> B2. Re-especificação de campos complexos - Resto
A14: =C14&"_"&D14 -> ENTITY_ANNL_TRNVR_LE | C14: ENTITY | D14: ANNL_TRNVR_LE | E14: OSI | F14: 2. Alterar especificação | G14: OK | H14: Em especificação (Financial Statments CIB) | I14: Campo implementação, mas com falta de informação para o segmento de clientes CIB | J14: Não | K14: 45450 | L14: 2. Alterar especificação | M14: =IF(COUNTIFS(PRO_LT_SCORECARD_FLEX_VALIDATIO!$K:$K, _xlfn.CONCAT(C14,D14), PRO_LT_SCORECARD_FLEX_VALIDATIO!$G:$G, "KO") > 0, "NOK", "OK") -> NOK | Q14: Melhorias estruturais (garantir coerência entre campos) | R14: Y | S14: N | T14: Y | U14: N | V14: N | W14: Y | X14: PM & LF | Y14: =_xlfn.IFNA(_xlfn.XLOOKUP(D14,[1]Especificação!$G:$G,[1]Especificação!$C:$C),0) -> F4. Fora âmbito | Re-especificação de campos complexos - Dem. Fin. CIB
A15: =C15&"_"&D15 -> ENTITY_ANNL_TRNVR_LE_BDR | C15: ENTITY | D15: ANNL_TRNVR_LE_BDR | E15: Fora OSI | F15: 9. Concluído | G15: OK | H15: Concluido, controlos OK | J15: Campo Fechado | K15: 45450 | L15: 9. Concluído | M15: =IF(COUNTIFS(PRO_LT_SCORECARD_FLEX_VALIDATIO!$K:$K, _xlfn.CONCAT(C15,D15), PRO_LT_SCORECARD_FLEX_VALIDATIO!$G:$G, "KO") > 0, "NOK", "OK") -> NOK | Q15: Campo concluido | R15: Y | S15: N | T15: N | U15: N | V15: N | W15: N | X15: PM | Y15: =_xlfn.IFNA(_xlfn.XLOOKUP(D15,[1]Especificação!$G:$G,[1]Especificação!$C:$C),0) -> 0
A16: =C16&"_"&D16 -> ENTITY_ANNL_TRNVR_PRVS | C16: ENTITY | D16: ANNL_TRNVR_PRVS | E16: OSI | F16: 2. Alterar especificação | G16: OK | H16: Em especificação (Financial Statments CIB) | I16: Campo implementação, mas com falta de informação para o segmento de clientes CIB | J16: Não | K16: 45450 | L16: 2. Alterar especificação | M16: =IF(COUNTIFS(PRO_LT_SCORECARD_FLEX_VALIDATIO!$K:$K, _xlfn.CONCAT(C16,D16), PRO_LT_SCORECARD_FLEX_VALIDATIO!$G:$G, "KO") > 0, "NOK", "OK") -> NOK | Q16: Melhorias estruturais (garantir coerência entre campos) | R16: Y | S16: N | T16: N | U16: N | V16: N | W16: Y | X16: PM & LF | Y16: =_xlfn.IFNA(_xlfn.XLOOKUP(D16,[1]Especificação!$G:$G,[1]Especificação!$C:$C),0) -> F4. Fora âmbito | Re-especificação de campos complexos - Dem. Fin. CIB
A17: =C17&"_"&D17 -> ENTITY_ANNL_TRNVR_PRVS_BDR | C17: ENTITY | D17: ANNL_TRNVR_PRVS_BDR | E17: Fora OSI | F17: 9. Concluído | G17: OK | H17: Concluido, controlos OK | J17: Campo Fechado | K17: 45450 | L17: 9. Concluído | M17: =IF(COUNTIFS(PRO_LT_SCORECARD_FLEX_VALIDATIO!$K:$K, _xlfn.CONCAT(C17,D17), PRO_LT_SCORECARD_FLEX_VALIDATIO!$G:$G, "KO") > 0, "NOK", "OK") -> OK | Q17: Campo concluido | R17: Y | S17: N | T17: N | U17: N | V17: N | W17: N | X17: PM | Y17: =_xlfn.IFNA(_xlfn.XLOOKUP(D17,[1]Especificação!$G:$G,[1]Especificação!$C:$C),0) -> 0
A18: =C18&"_"&D18 -> INSTRUMENT_ANNLSD_AGRD_RT | C18: INSTRUMENT | D18: ANNLSD_AGRD_RT | E18: OSI | F18: 3. Pendente de decisão | G18: OK | H18: Verificar necessidade de alteração da fonte para fins de reconciliação. Rever Fonte | I18: Rever se devemos utilizar a informação de IFRS9 ou manter a de alm | J18: Sim | K18: 45450 | L18: 3. Pendente de decisão | M18: =IF(COUNTIFS(PRO_LT_SCORECARD_FLEX_VALIDATIO!$K:$K, _xlfn.CONCAT(C18,D18), PRO_LT_SCORECARD_FLEX_VALIDATIO!$G:$G, "KO") > 0, "NOK", "OK") -> NOK | Q18: Pendente de decisão | R18: Y | S18: N | T18: Y | U18: N | V18: N | W18: N | X18: PM | Y18: =_xlfn.IFNA(_xlfn.XLOOKUP(D18,[1]Especificação!$G:$G,[1]Especificação!$C:$C),0) -> 0
A19: =C19&"_"&D19 -> PROTECTION_APPRSL_CRRNCY | C19: PROTECTION | D19: APPRSL_CRRNCY | E19: OSI | F19: 7. Analisar controlos e completude | G19: NOK | H19: Controlos NOK | J19: Não | K19: 45450 | L19: 7. Analisar controlos e completude | M19: =IF(COUNTIFS(PRO_LT_SCORECARD_FLEX_VALIDATIO!$K:$K, _xlfn.CONCAT(C19,D19), PRO_LT_SCORECARD_FLEX_VALIDATIO!$G:$G, "KO") > 0, "NOK", "OK") -> OK | Q19: Analisar controlos NOK | R19: Y | S19: N | T19: N | U19: N | V19: N | W19: N | X19: PM | Y19: =_xlfn.IFNA(_xlfn.XLOOKUP(D19,[1]Especificação!$G:$G,[1]Especificação!$C:$C),0) -> 0
A20: =C20&"_"&D20 -> PROTECTION_APPRSR | C20: PROTECTION | D20: APPRSR | E20: OSI | F20: 7. Analisar controlos e completude | G20: NOK | H20: Controlos NOK | J20: Não | K20: 45450 | L20: 7. Analisar controlos e completude | M20: =IF(COUNTIFS(PRO_LT_SCORECARD_FLEX_VALIDATIO!$K:$K, _xlfn.CONCAT(C20,D20), PRO_LT_SCORECARD_FLEX_VALIDATIO!$G:$G, "KO") > 0, "NOK", "OK") -> OK | Q20: Analisar controlos NOK | R20: Y | S20: N | T20: N | U20: N | V20: N | W20: N | X20: PM | Y20: =_xlfn.IFNA(_xlfn.XLOOKUP(D20,[1]Especificação!$G:$G,[1]Especificação!$C:$C),0) -> 0
A21: =C21&"_"&D21 -> INSTRUMENT_ARRRS_INSTRMNT | C21: INSTRUMENT | D21: ARRRS_INSTRMNT | E21: OSI | F21: 7. Analisar controlos e completude | G21: NOK | H21: Controlos NOK | J21: Não | K21: 45958 | L21: 9. Concluído | M21: =IF(COUNTIFS(PRO_LT_SCORECARD_FLEX_VALIDATIO!$K:$K, _xlfn.CONCAT(C21,D21), PRO_LT_SCORECARD_FLEX_VALIDATIO!$G:$G, "KO") > 0, "NOK", "OK") -> NOK | P21: 45958 | Q21: Analisar controlos NOK | R21: Y | S21: N | T21: N | U21: N | V21: N | W21: Y | X21: LF | Y21: =_xlfn.IFNA(_xlfn.XLOOKUP(D21,[1]Especificação!$G:$G,[1]Especificação!$C:$C),0) -> D. Campos com NOK controlos Corporativos
A22: =C22&"_"&D22 -> INSTRUMENT_ARRRS_INSTRMNT_12M | C22: INSTRUMENT | D22: ARRRS_INSTRMNT_12M | E22: OSI | F22: 7. Analisar controlos e completude | G22: NOK | H22: Controlos NOK | J22: Não | K22: 45450 | L22: 7. Analisar controlos e completude | M22: =IF(COUNTIFS(PRO_LT_SCORECARD_FLEX_VALIDATIO!$K:$K, _xlfn.CONCAT(C22,D22), PRO_LT_SCORECARD_FLEX_VALIDATIO!$G:$G, "KO") > 0, "NOK", "OK") -> NOK | Q22: Analisar controlos NOK | R22: Y | S22: N | T22: N | U22: N | V22: N | W22: N | X22: PM | Y22: =_xlfn.IFNA(_xlfn.XLOOKUP(D22,[1]Especificação!$G:$G,[1]Especificação!$C:$C),0) -> 0
A23: =C23&"_"&D23 -> INSTRUMENT_ASST_SCRT_CLSS | C23: INSTRUMENT | D23: ASST_SCRT_CLSS | E23: Fora OSI | F23: 9. Concluído | G23: OK | H23: Concluido, controlos OK | J23: Campo Fechado | K23: 45450 | L23: 9. Concluído | M23: =IF(COUNTIFS(PRO_LT_SCORECARD_FLEX_VALIDATIO!$K:$K, _xlfn.CONCAT(C23,D23), PRO_LT_SCORECARD_FLEX_VALIDATIO!$G:$G, "KO") > 0, "NOK", "OK") -> OK | Q23: Campo concluido | R23: Y | S23: N | T23: N | U23: N | V23: N | W23: N | X23: PM | Y23: =_xlfn.IFNA(_xlfn.XLOOKUP(D23,[1]Especificação!$G:$G,[1]Especificação!$C:$C),0) -> 0
A24: =C24&"_"&D24 -> INSTRUMENT_BRCHD_CVNNTS | C24: INSTRUMENT | D24: BRCHD_CVNNTS | E24: OSI | F24: 8. Concluído - sem dados | G24: OK | H24: Campo especificado, mas sem dados. Campo marcado com MISS ou NA | J24: Campo Fechado | K24: 45450 | L24: 8. Concluído - sem dados | M24: =IF(COUNTIFS(PRO_LT_SCORECARD_FLEX_VALIDATIO!$K:$K, _xlfn.CONCAT(C24,D24), PRO_LT_SCORECARD_FLEX_VALIDATIO!$G:$G, "KO") > 0, "NOK", "OK") -> OK | Q24: Campo concluído, mas sem ou pouca informação na fonte | R24: Y | S24: N | T24: N | U24: N | V24: N | W24: Y | X24: PM | Y24: =_xlfn.IFNA(_xlfn.XLOOKUP(D24,[1]Especificação!$G:$G,[1]Especificação!$C:$C),0) -> F1. Fora âmbito | Campos concluídos - Sem necessidade de espec.
A25: =C25&"_"&D25 -> ENTITY_CAPEX | C25: ENTITY | D25: CAPEX | E25: OSI | F25: 2. Alterar especificação | G25: OK | H25: Em especificação (Financial Statments CIB) | I25: Campo implementação, mas com falta de informação para o segmento de clientes CIB | J25: Não | K25: 45450 | L25: 2. Alterar especificação | M25: =IF(COUNTIFS(PRO_LT_SCORECARD_FLEX_VALIDATIO!$K:$K, _xlfn.CONCAT(C25,D25), PRO_LT_SCORECARD_FLEX_VALIDATIO!$G:$G, "KO") > 0, "NOK", "OK") -> NOK | Q25: Melhorias estruturais (garantir coerência entre campos) | R25: Y | S25: N | T25: N | U25: N | V25: N | W25: N | X25: PM | Y25: =_xlfn.IFNA(_xlfn.XLOOKUP(D25,[1]Especificação!$G:$G,[1]Especificação!$C:$C),0) -> 0
A26: =C26&"_"&D26 -> ENTITY_CAPEX_PRVS | C26: ENTITY | D26: CAPEX_PRVS | E26: OSI | F26: 2. Alterar especificação | G26: OK | H26: Em especificação (Financial Statments CIB) | I26: Campo implementação, mas com falta de informação para o segmento de clientes CIB | J26: Não | K26: 45450 | L26: 2. Alterar especificação | M26: =IF(COUNTIFS(PRO_LT_SCORECARD_FLEX_VALIDATIO!$K:$K, _xlfn.CONCAT(C26,D26), PRO_LT_SCORECARD_FLEX_VALIDATIO!$G:$G, "KO") > 0, "NOK", "OK") -> NOK | Q26: Melhorias estruturais (garantir coerência entre campos) | R26: Y | S26: N | T26: N | U26: N | V26: N | W26: N | X26: PM | Y26: =_xlfn.IFNA(_xlfn.XLOOKUP(D26,[1]Especificação!$G:$G,[1]Especificação!$C:$C),0) -> 0
A27: =C27&"_"&D27 -> INSTRUMENT_CCF | C27: INSTRUMENT | D27: CCF | E27: OSI | F27: 9. Concluído | G27: OK | H27: Concluido, controlos OK | J27: Campo Fechado | K27: 45450 | L27: 9. Concluído | M27: =IF(COUNTIFS(PRO_LT_SCORECARD_FLEX_VALIDATIO!$K:$K, _xlfn.CONCAT(C27,D27), PRO_LT_SCORECARD_FLEX_VALIDATIO!$G:$G, "KO") > 0, "NOK", "OK") -> NOK | Q27: Campo concluido | R27: Y | S27: Y | T27: N | U27: N | V27: N | W27: Y | X27: PM | Y27: =_xlfn.IFNA(_xlfn.XLOOKUP(D27,[1]Especificação!$G:$G,[1]Especificação!$C:$C),0) -> F1. Fora âmbito | Campos concluídos - Sem necessidade de espec.
A28: =C28&"_"&D28 -> INSTRUMENT_CHNNL_ORGNTN | C28: INSTRUMENT | D28: CHNNL_ORGNTN | E28: Fora OSI | F28: 4.1 Em implementação - Re-especificação | G28: NOK | H28: Aguarda implementação de IT | J28: Não | K28: 45450 | L28: 4.1 Em implementação - Re-especificação | M28: =IF(COUNTIFS(PRO_LT_SCORECARD_FLEX_VALIDATIO!$K:$K, _xlfn.CONCAT(C28,D28), PRO_LT_SCORECARD_FLEX_VALIDATIO!$G:$G, "KO") > 0, "NOK", "OK") -> OK | O28: 45296 | Q28: Melhorias estruturais (garantir coerência entre campos) | R28: Y | S28: N | T28: N | U28: N | V28: N | W28: N | X28: PM | Y28: =_xlfn.IFNA(_xlfn.XLOOKUP(D28,[1]Especificação!$G:$G,[1]Especificação!$C:$C),0) -> 0
A29: =C29&"_"&D29 -> ENTITY_CLLCTN_MD | C29: ENTITY | D29: CLLCTN_MD | E29: Fora OSI | F29: 9. Concluído | G29: OK | H29: Concluido, controlos OK | J29: Campo Fechado | K29: 45450 | L29: 9. Concluído | M29: =IF(COUNTIFS(PRO_LT_SCORECARD_FLEX_VALIDATIO!$K:$K, _xlfn.CONCAT(C29,D29), PRO_LT_SCORECARD_FLEX_VALIDATIO!$G:$G, "KO") > 0, "NOK", "OK") -> NOK | Q29: Campo concluido | R29: Y | S29: N | T29: N | U29: N | V29: N | W29: N | X29: PM | Y29: =_xlfn.IFNA(_xlfn.XLOOKUP(D29,[1]Especificação!$G:$G,[1]Especificação!$C:$C),0) -> 0
A30: =C30&"_"&D30 -> ENTITY_TTL_INTRST_PD | C30: ENTITY | D30: TTL_INTRST_PD | E30: Fora OSI | F30: 2. Alterar especificação | G30: NOK | H30: Em especificação (Amortizações Capital/ Juros) | J30: Não | K30: 45958 | L30: 9. Concluído | M30: =IF(COUNTIFS(PRO_LT_SCORECARD_FLEX_VALIDATIO!$K:$K, _xlfn.CONCAT(C30,D30), PRO_LT_SCORECARD_FLEX_VALIDATIO!$G:$G, "KO") > 0, "NOK", "OK") -> OK | P30: 45958 | Q30: Melhorias estruturais (garantir coerência entre campos) | R30: Y | S30: N | T30: N | U30: N | V30: N | W30: Y | X30: LF | Y30: =_xlfn.IFNA(_xlfn.XLOOKUP(D30,[1]Especificação!$G:$G,[1]Especificação!$C:$C),0) -> B2. Re-especificação de campos complexos - Resto
A31: =C31&"_"&D31 -> INSTRUMENT_CMMTMNT_INCPTN_INSTRMNT | C31: INSTRUMENT | D31: CMMTMNT_INCPTN_INSTRMNT | E31: OSI | F31: 7. Analisar controlos e completude | G31: NOK | H31: Analisar controlos e completude | J31: Não | K31: 45450 | L31: 7. Analisar controlos e completude | M31: =IF(COUNTIFS(PRO_LT_SCORECARD_FLEX_VALIDATIO!$K:$K, _xlfn.CONCAT(C31,D31), PRO_LT_SCORECARD_FLEX_VALIDATIO!$G:$G, "KO") > 0, "NOK", "OK") -> OK | Q31: Analisar controlos NOK | R31: Y | S31: N | T31: N | U31: N | V31: N | W31: N | X31: PM | Y31: =_xlfn.IFNA(_xlfn.XLOOKUP(D31,[1]Especificação!$G:$G,[1]Especificação!$C:$C),0) -> 0
A32: =C32&"_"&D32 -> PROTECTION_RL_ESTT_CLLTRL_LCTN | C32: PROTECTION | D32: RL_ESTT_CLLTRL_LCTN | E32: OSI | F32: 2. Alterar especificação | G32: NOK | H32: Alterados 3 casos. Campo está a devolver PT para todas as proteções, no entanto estas não estão localizadas em PT e alterou-se a localização para os respetivos paises. | J32: Não | K32: 45450 | L32: 2. Alterar especificação | M32: =IF(COUNTIFS(PRO_LT_SCORECARD_FLEX_VALIDATIO!$K:$K, _xlfn.CONCAT(C32,D32), PRO_LT_SCORECARD_FLEX_VALIDATIO!$G:$G, "KO") > 0, "NOK", "OK") -> OK | Q32: Melhorias estruturais (garantir coerência entre campos) | R32: Y | S32: N | T32: Y | U32: N | V32: Y | W32: N | X32: PM | Y32: =_xlfn.IFNA(_xlfn.XLOOKUP(D32,[1]Especificação!$G:$G,[1]Especificação!$C:$C),0) -> 0
A33: =C33&"_"&D33 -> INSTRUMENT_CMPLNT_MRTR_C19_NM | C33: INSTRUMENT | D33: CMPLNT_MRTR_C19_NM | E33: Fora OSI | F33: 9. Concluído | G33: OK | H33: Concluido, controlos OK | J33: Campo Fechado | K33: 45450 | L33: 9. Concluído | M33: =IF(COUNTIFS(PRO_LT_SCORECARD_FLEX_VALIDATIO!$K:$K, _xlfn.CONCAT(C33,D33), PRO_LT_SCORECARD_FLEX_VALIDATIO!$G:$G, "KO") > 0, "NOK", "OK") -> OK | Q33: Campo concluido | R33: Y | S33: N | T33: N | U33: N | V33: N | W33: N | X33: PM | Y33: =_xlfn.IFNA(_xlfn.XLOOKUP(D33,[1]Especificação!$G:$G,[1]Especificação!$C:$C),0) -> 0
A34: =C34&"_"&D34 -> INSTRUMENT_CNSMPTN_FNRP18 | C34: INSTRUMENT | D34: CNSMPTN_FNRP18 | E34: Fora OSI | F34: 9. Concluído | G34: OK | H34: Concluido, controlos OK | J34: Campo Fechado | K34: 45450 | L34: 9. Concluído | M34: =IF(COUNTIFS(PRO_LT_SCORECARD_FLEX_VALIDATIO!$K:$K, _xlfn.CONCAT(C34,D34), PRO_LT_SCORECARD_FLEX_VALIDATIO!$G:$G, "KO") > 0, "NOK", "OK") -> OK | Q34: Campo concluido | R34: Y | S34: N | T34: N | U34: N | V34: N | W34: N | X34: PM | Y34: =_xlfn.IFNA(_xlfn.XLOOKUP(D34,[1]Especificação!$G:$G,[1]Especificação!$C:$C),0) -> 0
A35: =C35&"_"&D35 -> PROTECTION_DT_APPRSL_PRVS | C35: PROTECTION | D35: DT_APPRSL_PRVS | E35: OSI | F35: 5.2 Em testes - Incidência | G35: NOK | H35: Campo com incidência e controlos NOK | I35: 1) Campo com incidência, data igual à data da protection_vl 2) Alteração de formatos MISS | J35: Campo Fechado | K35: 45670 | L35: 9. Concluído | M35: =IF(COUNTIFS(PRO_LT_SCORECARD_FLEX_VALIDATIO!$K:$K, _xlfn.CONCAT(C35,D35), PRO_LT_SCORECARD_FLEX_VALIDATIO!$G:$G, "KO") > 0, "NOK", "OK") -> OK | N35: Alteraração da definição do campo no Guia da Corporação. Campo passou a reportar a data da avaliação completa anterior à data da última avaliação completa. | O35: 45485 | P35: 45646 | Q35: Alteração de especificação por parte do BCE | R35: Y | S35: N | T35: N | U35: N | V35: N | W35: N | X35: PM | Y35: =_xlfn.IFNA(_xlfn.XLOOKUP(D35,[1]Especificação!$G:$G,[1]Especificação!$C:$C),0) -> 0
A36: =C36&"_"&D36 -> INSTRUMENT_CNTRCT_ID | C36: INSTRUMENT | D36: CNTRCT_ID | E36: OSI | F36: 9. Concluído | G36: OK | H36: Concluido, controlos OK | J36: Campo Fechado | K36: 45450 | L36: 9. Concluído | M36: =IF(COUNTIFS(PRO_LT_SCORECARD_FLEX_VALIDATIO!$K:$K, _xlfn.CONCAT(C36,D36), PRO_LT_SCORECARD_FLEX_VALIDATIO!$G:$G, "KO") > 0, "NOK", "OK") -> OK | Q36: Campo concluido | R36: Y | S36: N | T36: N | U36: N | V36: N | W36: N | X36: PM | Y36: =_xlfn.IFNA(_xlfn.XLOOKUP(D36,[1]Especificação!$G:$G,[1]Especificação!$C:$C),0) -> 0
A37: =C37&"_"&D37 -> INSTRUMENT_CNTRCT_ID_BDR | C37: INSTRUMENT | D37: CNTRCT_ID_BDR | E37: Fora OSI | F37: 9. Concluído | G37: OK | H37: Concluido, controlos OK | J37: Campo Fechado | K37: 45450 | L37: 9. Concluído | M37: =IF(COUNTIFS(PRO_LT_SCORECARD_FLEX_VALIDATIO!$K:$K, _xlfn.CONCAT(C37,D37), PRO_LT_SCORECARD_FLEX_VALIDATIO!$G:$G, "KO") > 0, "NOK", "OK") -> OK | Q37: Campo concluido | R37: Y | S37: N | T37: N | U37: N | V37: N | W37: N | X37: PM | Y37: =_xlfn.IFNA(_xlfn.XLOOKUP(D37,[1]Especificação!$G:$G,[1]Especificação!$C:$C),0) -> 0
A38: =C38&"_"&D38 -> ENTITY_CNTRY | C38: ENTITY | D38: CNTRY | E38: OSI | F38: 9. Concluído | G38: OK | H38: Concluido, controlos OK | J38: Campo Fechado | K38: 45958 | L38: 9. Concluído | M38: =IF(COUNTIFS(PRO_LT_SCORECARD_FLEX_VALIDATIO!$K:$K, _xlfn.CONCAT(C38,D38), PRO_LT_SCORECARD_FLEX_VALIDATIO!$G:$G, "KO") > 0, "NOK", "OK") -> OK | P38: 45958 | Q38: Campo concluido | R38: Y | S38: N | T38: Y | U38: N | V38: Y | W38: Y | X38: PM | Y38: =_xlfn.IFNA(_xlfn.XLOOKUP(D38,[1]Especificação!$G:$G,[1]Especificação!$C:$C),0) -> B2. Re-especificação de campos complexos - Resto
A39: =C39&"_"&D39 -> ENTITY_COD_SOC | C39: ENTITY | D39: COD_SOC | E39: OSI | F39: 9. Concluído | G39: OK | H39: Concluido, controlos OK | J39: Campo Fechado | K39: 45450 | L39: 9. Concluído | M39: =IF(COUNTIFS(PRO_LT_SCORECARD_FLEX_VALIDATIO!$K:$K, _xlfn.CONCAT(C39,D39), PRO_LT_SCORECARD_FLEX_VALIDATIO!$G:$G, "KO") > 0, "NOK", "OK") -> OK | Q39: Campo concluido | R39: Y | S39: N | T39: Y | U39: N | V39: Y | W39: Y | X39: PM | Y39: =_xlfn.IFNA(_xlfn.XLOOKUP(D39,[1]Especificação!$G:$G,[1]Especificação!$C:$C),0) -> F1. Fora âmbito | Campos concluídos - Sem necessidade de espec.
A40: =C40&"_"&D40 -> INSTR_ENTITY_COD_SOC | C40: INSTR_ENTITY | D40: COD_SOC | E40: OSI | F40: 9. Concluído | G40: OK | H40: Concluido, controlos OK | J40: Campo Fechado | K40: 45450 | L40: 9. Concluído | M40: =IF(COUNTIFS(PRO_LT_SCORECARD_FLEX_VALIDATIO!$K:$K, _xlfn.CONCAT(C40,D40), PRO_LT_SCORECARD_FLEX_VALIDATIO!$G:$G, "KO") > 0, "NOK", "OK") -> OK | Q40: Campo concluido | R40: Y | S40: N | T40: Y | U40: N | V40: N | W40: Y | X40: PM | Y40: =_xlfn.IFNA(_xlfn.XLOOKUP(D40,[1]Especificação!$G:$G,[1]Especificação!$C:$C),0) -> F1. Fora âmbito | Campos concluídos - Sem necessidade de espec.
A41: =C41&"_"&D41 -> INSTR_PROTECTION_COD_SOC | C41: INSTR_PROTECTION | D41: COD_SOC | E41: OSI | F41: 9. Concluído | G41: OK | H41: Concluido, controlos OK | J41: Campo Fechado | K41: 45450 | L41: 9. Concluído | M41: =IF(COUNTIFS(PRO_LT_SCORECARD_FLEX_VALIDATIO!$K:$K, _xlfn.CONCAT(C41,D41), PRO_LT_SCORECARD_FLEX_VALIDATIO!$G:$G, "KO") > 0, "NOK", "OK") -> OK | Q41: Campo concluido | R41: Y | S41: Y | T41: Y | U41: N | V41: N | W41: N | X41: PM | Y41: =_xlfn.IFNA(_xlfn.XLOOKUP(D41,[1]Especificação!$G:$G,[1]Especificação!$C:$C),0) -> F1. Fora âmbito | Campos concluídos - Sem necessidade de espec.
A42: =C42&"_"&D42 -> INSTRUMENT_COD_SOC | C42: INSTRUMENT | D42: COD_SOC | E42: OSI | F42: 9. Concluído | G42: OK | H42: Concluido, controlos OK | J42: Campo Fechado | K42: 45450 | L42: 9. Concluído | M42: =IF(COUNTIFS(PRO_LT_SCORECARD_FLEX_VALIDATIO!$K:$K, _xlfn.CONCAT(C42,D42), PRO_LT_SCORECARD_FLEX_VALIDATIO!$G:$G, "KO") > 0, "NOK", "OK") -> OK | Q42: Campo concluido | R42: Y | S42: Y | T42: Y | U42: N | V42: Y | W42: Y | X42: PM | Y42: =_xlfn.IFNA(_xlfn.XLOOKUP(D42,[1]Especificação!$G:$G,[1]Especificação!$C:$C),0) -> F1. Fora âmbito | Campos concluídos - Sem necessidade de espec.
...

Sheet Status PM (Campos)
C3: Data | D3: =TODAY() -> 46086
C5: Estado Campos em Produção
C6: Estado dos Campos | D6: # | E6: % | F6: Variação vs PdS anterior
B7: 23 | C7: Campo Fechado | D7: =COUNTIF($G$18:$G$1048576,C7) -> 23 | E7: =D7/$D$12 -> 0.65714286 | F7: =D7-B7 -> 0
B8: 0 | C8: Passagem a Produção | D8: =COUNTIF($G$18:$G$1048576,C8) -> 0 | E8: =D8/$D$12 -> 0 | F8: =D8-B8 -> 0
B9: 8 | C9: Análise de controlos | D9: =COUNTIF($G$18:$G$1048576,C9) -> 8 | E9: =D9/$D$12 -> 0.22857143 | F9: =D9-B9 -> 0
B10: 3 | C10: Análise de consistência | D10: =COUNTIF($G$18:$G$1048576,C10) -> 3 | E10: =D10/$D$12 -> 0.085714286 | F10: =D10-B10 -> 0
B11: 1 | C11: Alterar Especificação | D11: =COUNTIF($G$18:$G$1048576,C11) -> 1 | E11: =D11/$D$12 -> 0.028571429 | F11: =D11-B11 -> 0
C12: Total de Campos da Wallet | D12: =COUNTA(C19:C53) -> 35 | E12: =D12/$D$12 -> 1
C14: REF_DATE | D14: 45838
C15: NOME_PERIMETRO | D15: Individual IDComb
E17: Versão de Produção
B18: ID | C18: Campo | D18: Tipo de Alteração | E18: Teste de Consistência | F18: Controlos Corporativos | G18: Estado do campo | H18: Observações | I18: Next Steps
B19: 1 | C19: FLAG_PME (LT001) | D19: Alteração tabela fonte CT063 para a tabela Business | E19: OK | F19: N/A | G19: Campo Fechado | H19: - | I19: -
B20: 2 | C20: COD_EMPR_PME (LT001) | D20: Alteração tabela fonte CT063 para a tabela Business | E20: OK | F20: N/A | G20: Campo Fechado | H20: - | I20: -
B21: 3 | C21: COMPANY_EXPOSURE | D21: Alterações no ambito de LF | E21: OK | F21: N/A | G21: Campo Fechado | H21: -
B22: 4 | C22: OFF_BLNC_SHT_AMNT_INSTRMNT_PRVS | D22: Reapontamento para campos PRVS do Universo | E22: OK | F22: OK | G22: Campo Fechado | H22: - | I22: -
B23: 4 | C23: ECNMC_ACTVTY | D23: Alterações no ambito de LF | E23: OK | F23: OK | G23: Campo Fechado | H23: -
B24: 5 | C24: PD_EC_INCPTN | D24: Alterações no ambito de LF | E24: OK | F24: OK | G24: Campo Fechado | H24: - | I24: -
B25: 6 | C25: DPD_24M_PRFRMNG_STTS | D25: Nova Especificação | E25: OK | F25: OK | G25: Campo Fechado | H25: Campo com alteração de especificação devido a atualização do Guia Corporativo (Relacionado com o PRFRMNG_STTS_PRVS) | I25: -
B26: 7 | C26: DPD_PRFRMNG_STTS | D26: Nova Especificação | E26: OK | F26: OK | G26: Campo Fechado | H26: Campo com alteração de especificação devido a atualização do Guia Corporativo (Relacionado com o PRFRMNG_STTS_PRVS) | I26: -
B27: 8 | C27: PRFRMNG_STTS_PRVS | D27: Nova Especificação | E27: OK | F27: OK | G27: Campo Fechado | H27: Campo pode sofrer alterações com o tratamento dos NULL já entregue para testagem | I27: -
B28: 9 | C28: SME_FNRP18 | D28: Alteração tabela fonte CT063 para a tabela Business | E28: OK | F28: OK | G28: Campo Fechado | H28: 1.Email enviado ao Nuno e Rafael para proceder alteração do campo de forma a corrigir controlo If "Flag of SMEs" equals 'N', then "Enterprise size Counterparty (LE)" (Main Entity level) cannot equal '2 - Medium enterprise' nor '3 - Small enterprise' nor '4 - Micro enterprise' 2. Rever controlo com Luísa que relaciona a FLAG com o ENTTY | I28: -
B29: 10 | C29: PRFRMNG_STTS_LE | D29: Reapontar para o MN_ENTTY_ID | E29: OK | F29: OK | G29: Campo Fechado | H29: - | I29: -
B30: 11 | C30: DPD_12M_PRFRMNG_STTS | D30: Nova Especificação | E30: OK | F30: OK | G30: Campo Fechado | H30: Alteração de Especificação 11/08/2025 | I30: -
B31: 12 | C31: RRE_FNRP18 | D31: Alteração do nome do campo SUBTIPO_GARANTIA da LT001 para COLATERAL cuja fonte é o COLATERAL da FR011 | E31: OK | F31: OK | G31: Campo Fechado | H31: -
B32: 14 | C32: OTSTNDNG_NMNL_AMNT_INSTRMNT_PRVS | D32: Reapontamento para campos PRVS do Universo | E32: OK | F32: OK - Justificado | G32: Campo Fechado | H32: Existem 9 contratos com valor negativo | I32: -
B33: 15 | C33: LTI | D33: Reapontar para o MN_ENTTY_ID | E33: OK | F33: OK - Justificado | G33: Campo Fechado | H33: "Loan to income (LTI)" shall be larger than 0; Negative values trigger attention | I33: -
B34: 16 | C34: DT_IMPRMNT_STTS_PRVS | D34: Nova Especificação | E34: OK | F34: OK - Justificado | G34: Campo Fechado | H34: Controlo: "Date of impairment status" must be later than 01 January 1970 Justificado | I34: -
B35: 17 | C35: DT_IMPRMNT_STTS | D35: Nova Especificação | E35: OK | F35: OK - Justificado | G35: Campo Fechado | H35: Controlo: "Date of impairment status previous" must be later than 01 January 1970 Justificado | I35: -
B36: 18 | C36: DT_PRFRMNG_STTS_PRVS | D36: Nova Especificação | E36: OK | F36: OK - Justificado | G36: Campo Fechado | H36: "Date of performing status" must be later than 01 January 1970 Justificado | I36: -
B37: 19 | C37: CRE_FNRP18 | D37: Alteração do nome do campo SUBTIPO_GARANTIA da LT001 para COLATERAL cuja fonte é o COLATERAL da FR011 | E37: OK | F37: OK - Justificado | G37: Campo Fechado | H37: JUSTIFICADO CONTROLO NOK: Existem um contrato que está marcado como CRE = Y, mas no LT apenas estão duas garantias pessoais associadas Este contrato que tem uma garantias leasing imobiliario na FR003. Atualmente ainda existe um processo supletivo ao MUG para acautelar leasings imobiliarios e mobiliarios. Como a LT apenas reporta o que está no MUG esta garantias não existe no LT.Existe um projeto em curso onde até final de outubro este processo deixa de existir e toda a informação vem exclusivamente do MUG | I37: -
B38: 20 | C38: OTSTNDNG_NMNL_AMNT_INSTRMNT | D38: Reapontamento para campos PRVS do Universo | E38: OK | F38: OK - Justificado | G38: Campo Fechado | H38: Rever sinal dos campo juros_corridos e juros_corridos_prvs | I38: -
B39: 21 | C39: ENTRPRS_SZ_LE | D39: Alteração tabela fonte CT063 para a tabela Business | E39: OK | F39: OK - Justificado | G39: Campo Fechado | H39: 1 controlo vs PRSN_TYP - Já corrigido a futuro nas Ics para Agosto Controlo que compara o SME_FNRP18 com ENTRPRS_SZ, vai ser discontinuado | I39: Enviar email para riscos ou Nuno Pinheiro
B40: 22 | C40: DT_PRFRMNG_STTS | D40: Nova Especificação | E40: OK | F40: OK - Justificado | G40: Campo Fechado | H40: "Date of previous performing status" must be later than 01 January 1970 Justificado | I40: -
B41: 23 | C41: ORGNL_PRTCTN_VL | D41: Nova Especificação | E41: OK | F41: NOK | G41: Análise de controlos | H41: 1 Controlo NOK - Proteções a zero | I41: Em desenvolvimento com Nuno Alves e equipa do HA
B42: 24 | C42: IMPRMNT_STTS | D42: Nova Especificação | E42: OK | F42: NOK | G42: Análise de controlos | H42: 3 Controlos NOK - Inconsistências entre conceitos de DFLT, STAGE e WATCH LIST 1 Controlo NOK - If "Subportfolio ID" is classified as 'S1 - Stage 1', then "Impairment status" must equal '23 - Stage 1 (IFRS)' | I42: -
B43: 25 | C43: PRFRMNG_STTS | D43: Nova Especificação | E43: OK | F43: NOK | G43: Análise de controlos | H43: 1 Controlo NOK - Inconsistências entre conceitos DFLT e STAGE 1 Controlo ligado a um campo com Incidências (PRTCTN_CLLD) 1 Controlo enviado pela Luísa à corporação (será retirado) | I43: -
... B53: 35 | C53: IFRS9_BHVRL_MTRTY | D53: Nova Especificação | E53: OK | F53: OK | G53: Campo Fechado | H53: - | I53: -

Sheet Caderno Testes
A1: Tabela | B1: Campo | C1: Tipo de teste | D1: Descritivo | E1: Data atualização | F1: Data de referência | G1: Status | H1: Duvidas/comentários | I1: Query
A2: INSTRMNT | B2: RWA_MTHD | C2: Completude | D2: Validar se o número de MISS e N/A | E2: 45460 | F2: 45443 | G2: OK | I2: SELECT rwa_mthd, a.NUM_REGISTOS, a.NUM_REGISTOS/b.NUM_REGISTOS*100 as Perc from (SELECT rwa_mthd , COUNT(*) AS NUM_REGISTOS FROM cd_loan_tapes_bce.LT002_INSTRUMENT WHERE REF_DATE='${date}' AND NOME_PERIMETRO='Individual Corporativo' AND AMBITO = 'PM' AND SEGMENTO = 'ESTR' GROUP BY 1 ) a join ( SELECT COUNT(*) AS NUM_REGISTOS FROM cd_loan_tapes_bce.LT002_INSTRUMENT WHERE REF_DATE='${date}' AND NOME_PERIMETRO='Individual Corporativo' AND AMBITO = 'PM' AND SEGMENTO = 'ESTR' ) b where rwa_mthd in ('99999999999', '11111111111')
A3: INSTRMNT | B3: RWA_MTHD | C3: Desenvolvimento | D3: Validar alteração de formato de 11111111.00 para 11111111 | E3: 45460 | F3: 45443 | G3: OK | I3: SELECT count(*), rwa_mthd FROM cd_loan_tapes_bce.lt002_instrument WHERE 1=1 AND REF_DATE='${date}' AND NOME_PERIMETRO='Individual Corporativo' AND AMBITO = 'PM' AND SEGMENTO = 'ESTR' GROUP BY 2 ORDER BY 1
A4: INSTRMNT | B4: RWA_MTHD | C4: Desenvolvimento | D4: Validar condição de N/A sempre que não existe de consumo de capital | E4: 45460 | F4: 45443 | G4: OK | I4: SELECT DISTINCT EAD, RWA, rwa_mthd, VAL FROM (SELECT DISTINCT INSTRMNT_ID, EAD, RWA, rwa_mthd FROM cd_loan_tapes_bce.LT002_INSTRUMENT WHERE REF_DATE='${date}' AND NOME_PERIMETRO='Individual Corporativo' AND AMBITO = 'PM') LT002 LEFT JOIN (SELECT CHAVE_FR, SUM(flag_cons_cap) AS VAL FROM (SELECT CHAVE_FR, S1EMP, CONTRA1 FROM (SELECT DISTINCT CONCAT(CEMPRESA, CBALCAO,CNUMECTA, ZDEPOSIT) AS CHAVE_MASTER, CONCAT(CEMPRESA_FR, CBALCAO_FR,CNUMECTA_FR, ZDEPOSIT_FR) AS CHAVE_FR FROM cd_captools.KT_CHAVES_FINREP WHERE REF_DATE='${date}') KT_FR INNER JOIN (SELECT DISTINCT CONCAT(CEMPRESA, CBALCAO,CNUMECTA, ZDEPOSIT) AS CHAVE_MASTER, S1EMP, CONTRA1 FROM cd_captools.KT_CHAVES_BDR WHERE REF_DATE='${date}') KT_BDR ON KT_FR.CHAVE_MASTER=KT_BDR.CHAVE_MASTER ) KT LEFT JOIN (SELECT CT013.* FROM (SELECT DISTINCT REF_DATE, id_capital_perimetros, s1emp, contra1, flag_cons_cap FROM cd_captools.ct013_rwa_princ WHERE REF_DATE = '${date}' -- AND flag_cons_cap = 1 AND flag_conc_contab = 1 AND exercicio = "REAL" -- 30-03-2021: Adição de filtro AND subtipo_risco in ('1.1', '1.2', '1.3', '1.4', '1.5', '1.6', '1.7', '1.8', '1.9', '1.13')) CT013 INNER JOIN (SELECT DISTINCT ID_CAPITAL_PERIMETROS, REF_DATE FROM cd_captools.ct020_rwa_per WHERE REF_DATE = '${date}' AND NOME_PERIMETRO='Individual Corporativo') CT020 on CT013.ID_CAPITAL_PERIMETROS=CT020.ID_CAPITAL_PERIMETROS) CAP ON CAP.S1EMP=KT.S1EMP AND CAP.CONTRA1=KT.CONTRA1 GROUP BY 1 ) BASE ON INSTRMNT_ID=CHAVE_FR WHERE VAL=0
A5: INSTRMNT | B5: RWA_MTHD | C5: Controlos | D5: If "RWA" is populated other than default values, then "RWA calculation method" cannot be 'Not applicable' | E5: 45460 | F5: 45443 | G5: OK | I5: SELECT instrmnt_id, ead, rwa, rwa_mthd FROM cd_loan_tapes_bce.lt002_instrument WHERE 1=1 AND REF_DATE='${date}' AND NOME_PERIMETRO='Individual Corporativo' AND AMBITO = 'PM' AND SEGMENTO = 'ESTR' AND rwa NOT IN (99999999999.00, 11111111111.00) and rwa_mthd = 11111111111
A6: INSTRMNT | B6: RWA_MTHD | C6: Controlos | D6: If "RWA" is populated with 'Not applicable', then "RWA calculation method" must be a default value | E6: 45460 | F6: 45443 | G6: OK | I6: SELECT instrmnt_id, ead, rwa, rwa_mthd FROM cd_loan_tapes_bce.lt002_instrument WHERE 1=1 AND REF_DATE='${date}' AND NOME_PERIMETRO='Individual Corporativo' AND AMBITO = 'PM' AND SEGMENTO = 'ESTR' AND rwa = 11111111111.00 and rwa_mthd <> 11111111111
A7: INSTRMNT | B7: RWA_MTHD | C7: Controlos | D7: Validar se o campo está de acordo com a Codelist | E7: 45460 | F7: 45443 | G7: OK | I7: SELECT count(*), rwa_mthd FROM cd_loan_tapes_bce.lt002_instrument WHERE 1=1 AND REF_DATE='${date}' AND NOME_PERIMETRO='Individual Corporativo' AND AMBITO = 'PM' AND SEGMENTO = 'ESTR' GROUP BY 2 ORDER BY 1
A8: INSTRMNT | B8: RWA | C8: Completude | D8: Validar se o número de MISS e N/A | E8: 45460 | F8: 45443 | G8: OK | I8: SELECT rwa, a.NUM_REGISTOS, a.NUM_REGISTOS/b.NUM_REGISTOS*100 as Perc from (SELECT rwa , COUNT(*) AS NUM_REGISTOS FROM cd_loan_tapes_bce.LT002_INSTRUMENT WHERE REF_DATE='${date}' AND NOME_PERIMETRO='Individual Corporativo' AND AMBITO = 'PM' AND SEGMENTO = 'ESTR' GROUP BY 1 ) a join ( SELECT COUNT(*) AS NUM_REGISTOS FROM cd_loan_tapes_bce.LT002_INSTRUMENT WHERE REF_DATE='${date}' AND NOME_PERIMETRO='Individual Corporativo' AND AMBITO = 'PM' AND SEGMENTO = 'ESTR' ) b where rwa in (99999999999, 11111111111)
A9: INSTRMNT | B9: RWA | C9: Desenvolvimento | D9: Validar condição de N/A sempre que não existe de consumo de capital | E9: 45460 | F9: 45443 | G9: OK | I9: SELECT DISTINCT EAD, RWA, rwa_mthd, VAL FROM (SELECT DISTINCT INSTRMNT_ID, EAD, RWA, rwa_mthd FROM cd_loan_tapes_bce.LT002_INSTRUMENT WHERE REF_DATE='${date}' AND NOME_PERIMETRO='Individual Corporativo' AND AMBITO = 'PM') LT002 LEFT JOIN (SELECT CHAVE_FR, SUM(flag_cons_cap) AS VAL FROM (SELECT CHAVE_FR, S1EMP, CONTRA1 FROM (SELECT DISTINCT CONCAT(CEMPRESA, CBALCAO,CNUMECTA, ZDEPOSIT) AS CHAVE_MASTER, CONCAT(CEMPRESA_FR, CBALCAO_FR,CNUMECTA_FR, ZDEPOSIT_FR) AS CHAVE_FR FROM cd_captools.KT_CHAVES_FINREP WHERE REF_DATE='${date}') KT_FR INNER JOIN (SELECT DISTINCT CONCAT(CEMPRESA, CBALCAO,CNUMECTA, ZDEPOSIT) AS CHAVE_MASTER, S1EMP, CONTRA1 FROM cd_captools.KT_CHAVES_BDR WHERE REF_DATE='${date}') KT_BDR ON KT_FR.CHAVE_MASTER=KT_BDR.CHAVE_MASTER ) KT LEFT JOIN (SELECT CT013.* FROM (SELECT DISTINCT REF_DATE, id_capital_perimetros, s1emp, contra1, flag_cons_cap FROM cd_captools.ct013_rwa_princ WHERE REF_DATE = '${date}' -- AND flag_cons_cap = 1 AND flag_conc_contab = 1 AND exercicio = "REAL" -- 30-03-2021: Adição de filtro AND subtipo_risco in ('1.1', '1.2', '1.3', '1.4', '1.5', '1.6', '1.7', '1.8', '1.9', '1.13')) CT013 INNER JOIN (SELECT DISTINCT ID_CAPITAL_PERIMETROS, REF_DATE FROM cd_captools.ct020_rwa_per WHERE REF_DATE = '${date}' AND NOME_PERIMETRO='Individual Corporativo') CT020 on CT013.ID_CAPITAL_PERIMETROS=CT020.ID_CAPITAL_PERIMETROS) CAP ON CAP.S1EMP=KT.S1EMP AND CAP.CONTRA1=KT.CONTRA1 GROUP BY 1 ) BASE ON INSTRMNT_ID=CHAVE_FR WHERE VAL=0
A10: INSTRMNT | B10: RWA | C10: Controlos | D10: Validar formatos | E10: 45460 | F10: 45443 | G10: OK | I10: SELECT count(*), rwa FROM cd_loan_tapes_bce.lt002_instrument WHERE 1=1 AND REF_DATE='${date}' AND NOME_PERIMETRO='Individual Corporativo' AND AMBITO = 'PM' AND SEGMENTO = 'ESTR' GROUP BY 2 ORDER BY 1
A11: INSTRMNT | B11: RWA | C11: Controlos | D11: Validar se não existem valores negativos | E11: 45460 | F11: 45443 | G11: NOK | H11: 1 Contrato com valores negativos | I11: SELECT DISTINCT INSTRMNT_ID, EAD, RWA, rwa_mthd, VAL FROM (SELECT DISTINCT INSTRMNT_ID, EAD, RWA, rwa_mthd FROM cd_loan_tapes_bce.LT002_INSTRUMENT WHERE REF_DATE='${date}' AND NOME_PERIMETRO='Individual Corporativo' AND AMBITO = 'PM' -- AND instrmnt_id = '31000314294093096000000000000000' ) LT002 LEFT JOIN (SELECT CHAVE_FR, SUM(flag_cons_cap) AS VAL FROM (SELECT CHAVE_FR, S1EMP, CONTRA1 FROM (SELECT DISTINCT CONCAT(CEMPRESA, CBALCAO,CNUMECTA, ZDEPOSIT) AS CHAVE_MASTER, CONCAT(CEMPRESA_FR, CBALCAO_FR,CNUMECTA_FR, ZDEPOSIT_FR) AS CHAVE_FR FROM cd_captools.KT_CHAVES_FINREP WHERE REF_DATE='${date}') KT_FR INNER JOIN (SELECT DISTINCT CONCAT(CEMPRESA, CBALCAO,CNUMECTA, ZDEPOSIT) AS CHAVE_MASTER, S1EMP, CONTRA1 FROM cd_captools.KT_CHAVES_BDR WHERE REF_DATE='${date}') KT_BDR ON KT_FR.CHAVE_MASTER=KT_BDR.CHAVE_MASTER ) KT LEFT JOIN (SELECT CT013.* FROM (SELECT DISTINCT REF_DATE, id_capital_perimetros, s1emp, contra1, flag_cons_cap FROM cd_captools.ct013_rwa_princ WHERE REF_DATE = '${date}' -- AND flag_cons_cap = 1 AND flag_conc_contab = 1 AND exercicio = "REAL" -- 30-03-2021: Adição de filtro AND subtipo_risco in ('1.1', '1.2', '1.3', '1.4', '1.5', '1.6', '1.7', '1.8', '1.9', '1.13')) CT013 INNER JOIN (SELECT DISTINCT ID_CAPITAL_PERIMETROS, REF_DATE FROM cd_captools.ct020_rwa_per WHERE REF_DATE = '${date}' AND NOME_PERIMETRO='Individual Corporativo') CT020 on CT013.ID_CAPITAL_PERIMETROS=CT020.ID_CAPITAL_PERIMETROS) CAP ON CAP.S1EMP=KT.S1EMP AND CAP.CONTRA1=KT.CONTRA1 GROUP BY 1 ) BASE ON INSTRMNT_ID=CHAVE_FR WHERE RWA < 0
A12: INSTRMNT | B12: RWA | C12: Controlos | D12: Teste contra a fonte | E12: 45462 | F12: 45443 | G12: OK | H12: A fonte (CT013) tem um valor muito superior, porque existem várias chaves FR para uma chave BDR | I12: SELECT DISTINCT INSTRMNT_ID, S1EMP, CONTRA1, EAD, RWA, rwa_final, ead_final_bruta FROM (SELECT DISTINCT INSTRMNT_ID, CCF, dflt_stts_instrmnt, DPD, EAD, LGD, pd_crr_incptn, pd_crr_rd, pd_crr_rd_t1, RWA, rwa_mthd, spcltv_lndng, crrltn_cffcnt FROM cd_loan_tapes_bce.LT002_INSTRUMENT WHERE REF_DATE='${date}' AND NOME_PERIMETRO='Individual Corporativo' AND AMBITO = 'PM' -- AND instrmnt_id = '31000347000690020000000000000000' ) LT002 INNER JOIN (SELECT CHAVE_FR, KT.S1EMP, KT.CONTRA1, SUM(flag_cons_cap) AS VAL, SUM(RWA_FINAL) AS RWA_FINAL, SUM(ead_final_bruta) AS ead_final_bruta FROM (SELECT CHAVE_FR, S1EMP, CONTRA1 FROM (SELECT DISTINCT CONCAT(CEMPRESA, CBALCAO,CNUMECTA, ZDEPOSIT) AS CHAVE_MASTER, CONCAT(CEMPRESA_FR, CBALCAO_FR,CNUMECTA_FR, ZDEPOSIT_FR) AS CHAVE_FR FROM cd_captools.KT_CHAVES_FINREP WHERE REF_DATE='${date}') KT_FR INNER JOIN (SELECT DISTINCT CONCAT(CEMPRESA, CBALCAO,CNUMECTA, ZDEPOSIT) AS CHAVE_MASTER, S1EMP, CONTRA1 FROM cd_captools.KT_CHAVES_BDR WHERE REF_DATE='${date}') KT_BDR ON KT_FR.CHAVE_MASTER=KT_BDR.CHAVE_MASTER WHERE CHAVE_FR = '31005122428280011667450200000001' OR concat(S1EMP,CONTRA1) = '1814008684' ) KT INNER JOIN (SELECT CT013.* FROM (SELECT REF_DATE, id_capital_perimetros, s1emp, contra1, flag_cons_cap, rwa_final, ead_final_bruta FROM cd_captools.ct013_rwa_princ WHERE REF_DATE = '${date}' -- AND flag_cons_cap = 1 AND flag_conc_contab = 1 AND exercicio = "REAL" -- 30-03-2021: Adição de filtro AND subtipo_risco in ('1.1', '1.2', '1.3', '1.4', '1.5', '1.6', '1.7', '1.8', '1.9', '1.13')) CT013 INNER JOIN (SELECT DISTINCT ID_CAPITAL_PERIMETROS, REF_DATE FROM cd_captools.ct020_rwa_per WHERE REF_DATE = '${date}' AND NOME_PERIMETRO='Individual Corporativo') CT020 on CT013.ID_CAPITAL_PERIMETROS=CT020.ID_CAPITAL_PERIMETROS) CAP ON CAP.S1EMP=KT.S1EMP AND CAP.CONTRA1=KT.CONTRA1 GROUP BY 1,2,3 ) X on CHAVE_FR = INSTRMNT_ID
A13: INSTRMNT | B13: RWA | C13: Controlos | D13: Verificar saldo de capital | E13: 45462 | F13: 45443 | G13: OK | I13: SELECT LT002.instrmnt_id, RWA, EAD, CONCAT(LT001.cempresa,LT001.cbalcao,LT001.cnumecta,LT001.zdeposit) AS CHAVE_FR, NVL(SUM(LT001.msaldo_final),0) AS Saldo_Capital FROM (SELECT cempresa, cbalcao, cnumecta, zdeposit, ccontab_final_cargabal, msaldo_final FROM cd_loan_tapes_bce.lt001_univ_oper WHERE REF_DATE = '${date}' AND NOME_PERIMETRO='Individual Corporativo' AND AMBITO = 'PM' ) LT001 INNER JOIN (SELECT * FROM cd_loan_tapes_bce.kt_chaves_lt WHERE REF_DATE = '${date}' AND NOME_PERIMETRO='Individual Corporativo' AND AMBITO = 'PM' AND segmento = 'ESTR') KT_LT ON CONCAT(LT001.cempresa,LT001.cbalcao,LT001.cnumecta,LT001.zdeposit) = CONCAT(KT_LT.cempresa,KT_LT.cbalcao,KT_LT.cnumecta,KT_LT.zdeposit) INNER JOIN (SELECT instrmnt_id, rwa, ead FROM cd_loan_tapes_bce.lt002_instrument WHERE REF_DATE = '${date}' AND NOME_PERIMETRO='Individual Corporativo' AND AMBITO = 'PM' AND segmento ='ESTR' AND instrmnt_id in ( '310051224282800116674502P0080001', '310051224282800116674502P0070001', '310051224282800116674502P0060001', '31005122428280011667450200000001', '310051224282800116674502P0100001', '310051224282800116674502P0110001', '310051224282800116674502P0020001', '310051224282800116674502P0010001', '310051224282800116674502P0030001', '310051224282800116674502P0090001' ) ) LT002 ON KT_LT.INSTRMNT_ID = LT002.INSTRMNT_ID LEFT JOIN (SELECT * FROM cd_captools.fr802_pl_contas WHERE 1=1 AND REF_DATE = '${date}' AND cod_plano = 'CARGABAL' AND ((tipo_conta IN ('A','P') AND carteira_contabilistica not in('provisoes para compromissos e garantias concedidas', 'outras provisoes') AND composicao_valor <> 'imparidade acumulada' AND bruto_imparidade <> 'imparidade') OR (tipo_conta IN ('EA','EP','M'))) ) FR802 ON FR802.CONTA = LT001.ccontab_final_cargabal LEFT JOIN (SELECT * FROM cd_captools.ct805_matriz_cnt WHERE 1=1 AND REF_DATE = '${date}' AND DOMINIO = 'Capital' AND NOME_PERIMETRO = 'Individual Corporativo' ) CT805 ON FR802.CONTA = CT805.CONTA GROUP BY 1,2,3,4
