Workbook
Name \a: #REF!
Name \a: #REF!
Name \a: #REF!
Name \a: #REF!
Name \b: #REF!
Name \b: #REF!
Name \b: #REF!
Name \b: #REF!
Name \c: #REF!
Name \c: #REF!
Name \c: #REF!
Name \c: #REF!
Name \d: #REF!
Name \d: #REF!
Name \d: #REF!
Name \d: #REF!
Name \e: #REF!
Name \e: #REF!
Name \e: #REF!
Name \e: #REF!
Name \m: #REF!
Name \m: #REF!
Name \m: #REF!
Name \m: #REF!
Name \p: #REF!
Name \p: #REF!
Name \p: #REF!
Name \p: #REF!
Name \q: #REF!
Name \q: #REF!
Name \q: #REF!
Name \q: #REF!
Name \s: #REF!
Name \s: #REF!
Name \s: #REF!
Name \s: #REF!
Name \v: #REF!
Name \v: #REF!
Name \v: #REF!
Name \v: #REF!
Name ___GRUPO_ENVIO: [1]GENMASIVA!$AC$4
Name ___INDEX_SHEET___ASAP_Utilities: #REF!
Name ___INDEX_SHEET___ASAP_Utilities: #REF!
Name ___INDEX_SHEET___ASAP_Utilities: #REF!
Name ___INDEX_SHEET___ASAP_Utilities: #REF!
Name ___PERIODO: [1]GENMASIVA!$AC$2
Name ___td2: #REF!
Name ___td2: #REF!
Name ___td2: #REF!
Name ___td2: #REF!
Name ___td3: #REF!
Name ___td3: #REF!
Name ___td3: #REF!
Name ___td3: #REF!
Name ___td4: #REF!
Name ___td4: #REF!
Name ___td4: #REF!
Name ___td4: #REF!
Name ___ti1: #REF!
Name ___ti1: #REF!

Sheet Comparativos granulares
B8: Métrica | C8: Casuística | D8: Δ Montante vs Tático Dez24
B9: Esg_subsector_name | C9: Alteração da reclassificação do código NACE | D9: 4.2247084e+08
B10: Rest of other financial corporation | C10: Antes era Management firms agora é Rest of other financial corporation | D10: 3.7549691e+08
C11: Antes era Investment firms agora é Rest of other financial corporation | D11: 46973926
B12: Specialised_lending | C12: Alteração na marcação das métricas do modelo verde | D12: 5.2323901e+08
B13: Vazio | C13: Antes era N agora é vazio | D13: 3.7352934e+08
C14: Antes era Y agora é vazio | D14: 1.4970967e+08
B15: European_union | C15: Alteração na marcação do país do colateral | D15: 10855218
B16: Vazio | C16: Antes era EU2 agora é vazio | D16: 101793
B17: EU1 | C17: Antes era EU2 agora é EU1 | D17: 10753425

Sheet Variação - Temp 6 
B8: Template 6. Summary of GAR KPIs (Dezembro 2024 Tático)
C10: KPI | F10: % coverage (over total assets)*
C11: Climate change mitigation | D11: Climate change adaptation | E11: Total (Climate change mitigation + Climate change adaptation)
B12: GAR stock | C12: 0.041475952 | D12: 0 | E12: 0.041475952 | F12: 0.53245883
B13: GAR flow | C13: 0.052277306 | D13: 0 | E13: 0.052277306 | F13: 0.46221054
B14: * % of assets covered by the KPI over banks´ total assets
B16: Template 6. Summary of GAR KPIs (Dezembro 2024 Estrutural)
C18: KPI | F18: % coverage (over total assets)*
C19: Climate change mitigation | D19: Climate change adaptation | E19: Total (Climate change mitigation + Climate change adaptation)
B20: GAR stock | C20: 0.035533578 | D20: 9.3278355e-06 | E20: 0.035542906 | F20: 0.53245976
B21: GAR flow | C21: 0.0431596 | D21: 3.3239501e-05 | E21: 0.04319284 | F21: 0.46187325
B22: * % of assets covered by the KPI over banks´ total assets

Sheet Variação Absoluta - Temp 7
D8: GCA | G8: Eligible - CCM | J8: Aligned - CCM | M8: Specialized Lending - CCM | P8: Transitional - CCM | S8: Enabling - CCM
D9: dez24 estrutural | E9: dez24 tático | F9: ∆ | G9: dez24 estrutural | H9: dez24 tático | I9: ∆ | J9: dez24 estrutural | K9: dez24 tático | L9: ∆ | M9: dez24 estrutural | N9: dez24 tático | O9: ∆ | P9: dez24 estrutural | Q9: dez24 tático | R9: ∆ | S9: dez24 estrutural | T9: dez24 tático | U9: ∆
B10: GAR - Covered assets in both numerator and denominator | C10: Loans and advances, debt securities and equity instruments not HfT eligible for GAR calculation | D10: ='Input dez24_estr - Temp 7'!D17 -> 30461.003 | E10: ='Input dez24_tat - Temp 7'!D17 -> 30461.002 | F10: =D10-E10 -> 0.00062260201 | G10: ='Input dez24_estr - Temp 7'!E17 -> 4052.479 | H10: ='Input dez24_tat - Temp 7'!E17 -> 21828.466 | I10: =G10-H10 -> -17775.987 | J10: ='Input dez24_estr - Temp 7'!F17 -> 1520.0948 | K10: ='Input dez24_tat - Temp 7'!F17 -> 1774.3084 | L10: =J10-K10 -> -254.21358 | M10: ='Input dez24_estr - Temp 7'!G17 -> 0 | N10: ='Input dez24_tat - Temp 7'!G17 -> 0 | O10: =M10-N10 -> 0 | P10: ='Input dez24_estr - Temp 7'!H17 -> 6.5825941 | Q10: ='Input dez24_tat - Temp 7'!H17 -> 6.542314 | R10: =P10-Q10 -> 0.040280099 | S10: ='Input dez24_estr - Temp 7'!I17 -> 288.69908 | T10: ='Input dez24_tat - Temp 7'!I17 -> 280.92405 | U10: =S10-T10 -> 7.7750285
C11: Financial corporations | D11: ='Input dez24_estr - Temp 7'!D18 -> 1699.1528 | E11: ='Input dez24_tat - Temp 7'!D18 -> 1699.1526 | F11: =D11-E11 -> 0.00017941698 | G11: ='Input dez24_estr - Temp 7'!E18 -> 252.37061 | H11: ='Input dez24_tat - Temp 7'!E18 -> 457.76869 | I11: =G11-H11 -> -205.39808 | J11: ='Input dez24_estr - Temp 7'!F18 -> 197.45961 | K11: ='Input dez24_tat - Temp 7'!F18 -> 197.7138 | L11: =J11-K11 -> -0.25419122 | M11: ='Input dez24_estr - Temp 7'!G18 -> 0 | N11: ='Input dez24_tat - Temp 7'!G18 -> 0 | O11: =M11-N11 -> 0 | P11: ='Input dez24_estr - Temp 7'!H18 -> 0.005193432 | Q11: ='Input dez24_tat - Temp 7'!H18 -> 0 | R11: =P11-Q11 -> 0.005193432 | S11: ='Input dez24_estr - Temp 7'!I18 -> 94.439362 | T11: ='Input dez24_tat - Temp 7'!I18 -> 94.223938 | U11: =S11-T11 -> 0.21542372
C12: Credit institutions | D12: ='Input dez24_estr - Temp 7'!D19 -> 169.80569 | E12: ='Input dez24_tat - Temp 7'!D19 -> 169.80569 | F12: =D12-E12 -> 1.000305e-06 | G12: ='Input dez24_estr - Temp 7'!E19 -> 22.036605 | H12: ='Input dez24_tat - Temp 7'!E19 -> 30.294457 | I12: =G12-H12 -> -8.2578519 | J12: ='Input dez24_estr - Temp 7'!F19 -> 0.53051443 | K12: ='Input dez24_tat - Temp 7'!F19 -> 1.084128 | L12: =J12-K12 -> -0.55361357 | M12: ='Input dez24_estr - Temp 7'!G19 -> 0 | N12: ='Input dez24_tat - Temp 7'!G19 -> 0 | O12: =M12-N12 -> 0 | P12: ='Input dez24_estr - Temp 7'!H19 -> 0 | Q12: ='Input dez24_tat - Temp 7'!H19 -> 0 | R12: =P12-Q12 -> 0 | S12: ='Input dez24_estr - Temp 7'!I19 -> 0.049614447 | T12: ='Input dez24_tat - Temp 7'!I19 -> 0.049615 | U12: =S12-T12 -> -5.53063e-07
C13: Loans and advances | D13: ='Input dez24_estr - Temp 7'!D20 -> 169.80569 | E13: ='Input dez24_tat - Temp 7'!D20 -> 169.80569 | F13: =D13-E13 -> 1.000305e-06 | G13: ='Input dez24_estr - Temp 7'!E20 -> 22.036605 | H13: ='Input dez24_tat - Temp 7'!E20 -> 30.294457 | I13: =G13-H13 -> -8.2578519 | J13: ='Input dez24_estr - Temp 7'!F20 -> 0.53051443 | K13: ='Input dez24_tat - Temp 7'!F20 -> 1.084128 | L13: =J13-K13 -> -0.55361357 | M13: ='Input dez24_estr - Temp 7'!G20 -> 0 | N13: ='Input dez24_tat - Temp 7'!G20 -> 0 | O13: =M13-N13 -> 0 | P13: ='Input dez24_estr - Temp 7'!H20 -> 0 | Q13: ='Input dez24_tat - Temp 7'!H20 -> 0 | R13: =P13-Q13 -> 0 | S13: ='Input dez24_estr - Temp 7'!I20 -> 0.049614447 | T13: ='Input dez24_tat - Temp 7'!I20 -> 0.049615 | U13: =S13-T13 -> -5.53063e-07
C14: Debt securities, including UoP | D14: ='Input dez24_estr - Temp 7'!D21 -> 0 | E14: ='Input dez24_tat - Temp 7'!D21 -> 0 | F14: =D14-E14 -> 0 | G14: ='Input dez24_estr - Temp 7'!E21 -> 0 | H14: ='Input dez24_tat - Temp 7'!E21 -> 0 | I14: =G14-H14 -> 0 | J14: ='Input dez24_estr - Temp 7'!F21 -> 0 | K14: ='Input dez24_tat - Temp 7'!F21 -> 0 | L14: =J14-K14 -> 0 | M14: ='Input dez24_estr - Temp 7'!G21 -> 0 | N14: ='Input dez24_tat - Temp 7'!G21 -> 0 | O14: =M14-N14 -> 0 | P14: ='Input dez24_estr - Temp 7'!H21 -> 0 | Q14: ='Input dez24_tat - Temp 7'!H21 -> 0 | R14: =P14-Q14 -> 0 | S14: ='Input dez24_estr - Temp 7'!I21 -> 0 | T14: ='Input dez24_tat - Temp 7'!I21 -> 0 | U14: =S14-T14 -> 0
C15: Equity instruments | D15: ='Input dez24_estr - Temp 7'!D22 -> 0 | E15: ='Input dez24_tat - Temp 7'!D22 -> 0 | F15: =D15-E15 -> 0 | G15: ='Input dez24_estr - Temp 7'!E22 -> 0 | H15: ='Input dez24_tat - Temp 7'!E22 -> 0 | I15: =G15-H15 -> 0 | J15: ='Input dez24_estr - Temp 7'!F22 -> 0 | K15: ='Input dez24_tat - Temp 7'!F22 -> 0 | L15: =J15-K15 -> 0 | P15: ='Input dez24_estr - Temp 7'!H22 -> 0 | Q15: ='Input dez24_tat - Temp 7'!H22 -> 0 | R15: =P15-Q15 -> 0 | S15: ='Input dez24_estr - Temp 7'!I22 -> 0 | T15: ='Input dez24_tat - Temp 7'!I22 -> 0 | U15: =S15-T15 -> 0
C16: Other financial corporations | D16: ='Input dez24_estr - Temp 7'!D23 -> 1529.3471 | E16: ='Input dez24_tat - Temp 7'!D23 -> 1529.347 | F16: =D16-E16 -> 0.00017841668 | G16: ='Input dez24_estr - Temp 7'!E23 -> 230.33401 | H16: ='Input dez24_tat - Temp 7'!E23 -> 427.47423 | I16: =G16-H16 -> -197.14023 | J16: ='Input dez24_estr - Temp 7'!F23 -> 196.92909 | K16: ='Input dez24_tat - Temp 7'!F23 -> 196.62967 | L16: =J16-K16 -> 0.29942235 | M16: ='Input dez24_estr - Temp 7'!G23 -> 0 | N16: ='Input dez24_tat - Temp 7'!G23 -> 0 | O16: =M16-N16 -> 0 | P16: ='Input dez24_estr - Temp 7'!H23 -> 0.005193432 | Q16: ='Input dez24_tat - Temp 7'!H23 -> 0 | R16: =P16-Q16 -> 0.005193432 | S16: ='Input dez24_estr - Temp 7'!I23 -> 94.389747 | T16: ='Input dez24_tat - Temp 7'!I23 -> 94.174323 | U16: =S16-T16 -> 0.21542428
C17: of which investment firms | D17: ='Input dez24_estr - Temp 7'!D24 -> 643.78113 | E17: ='Input dez24_tat - Temp 7'!D24 -> 690.7549 | F17: =D17-E17 -> -46.973768 | G17: ='Input dez24_estr - Temp 7'!E24 -> 214.1777 | H17: ='Input dez24_tat - Temp 7'!E24 -> 319.24039 | I17: =G17-H17 -> -105.06269 | J17: ='Input dez24_estr - Temp 7'!F24 -> 195.506 | K17: ='Input dez24_tat - Temp 7'!F24 -> 195.506 | L17: =J17-K17 -> 1.5886062e-07 | M17: ='Input dez24_estr - Temp 7'!G24 -> 0 | N17: ='Input dez24_tat - Temp 7'!G24 -> 0 | O17: =M17-N17 -> 0 | P17: ='Input dez24_estr - Temp 7'!H24 -> 0 | Q17: ='Input dez24_tat - Temp 7'!H24 -> 0 | R17: =P17-Q17 -> 0 | S17: ='Input dez24_estr - Temp 7'!I24 -> 94.151287 | T17: ='Input dez24_tat - Temp 7'!I24 -> 94.151287 | U17: =S17-T17 -> 6.3430463e-08
C18: Loans and advances | D18: ='Input dez24_estr - Temp 7'!D25 -> 175.71321 | E18: ='Input dez24_tat - Temp 7'!D25 -> 222.68697 | F18: =D18-E18 -> -46.973769 | G18: ='Input dez24_estr - Temp 7'!E25 -> 3.3954957e-05 | H18: ='Input dez24_tat - Temp 7'!E25 -> 105.06273 | I18: =G18-H18 -> -105.06269 | J18: ='Input dez24_estr - Temp 7'!F25 -> 3.0994813e-05 | K18: ='Input dez24_tat - Temp 7'!F25 -> 3.1e-05 | L18: =J18-K18 -> -5.1865162e-09 | M18: ='Input dez24_estr - Temp 7'!G25 -> 0 | N18: ='Input dez24_tat - Temp 7'!G25 -> 0 | O18: =M18-N18 -> 0 | P18: ='Input dez24_estr - Temp 7'!H25 -> 0 | Q18: ='Input dez24_tat - Temp 7'!H25 -> 0 | R18: =P18-Q18 -> 0 | S18: ='Input dez24_estr - Temp 7'!I25 -> 1.4926404e-05 | T18: ='Input dez24_tat - Temp 7'!I25 -> 1.5e-05 | U18: =S18-T18 -> -7.3595953e-08
C19: Debt securities, including UoP | D19: ='Input dez24_estr - Temp 7'!D26 -> 455.12095 | E19: ='Input dez24_tat - Temp 7'!D26 -> 455.12095 | F19: =D19-E19 -> 4.0352603e-07 | G19: ='Input dez24_estr - Temp 7'!E26 -> 214.17767 | H19: ='Input dez24_tat - Temp 7'!E26 -> 214.17767 | I19: =G19-H19 -> -1.7702001e-07 | J19: ='Input dez24_estr - Temp 7'!F26 -> 195.50597 | K19: ='Input dez24_tat - Temp 7'!F26 -> 195.50597 | L19: =J19-K19 -> 1.6404715e-07 | M19: ='Input dez24_estr - Temp 7'!G26 -> 0 | N19: ='Input dez24_tat - Temp 7'!G26 -> 0 | O19: =M19-N19 -> 0 | P19: ='Input dez24_estr - Temp 7'!H26 -> 0 | Q19: ='Input dez24_tat - Temp 7'!H26 -> 0 | R19: =P19-Q19 -> 0 | S19: ='Input dez24_estr - Temp 7'!I26 -> 94.151272 | T19: ='Input dez24_tat - Temp 7'!I26 -> 94.151272 | U19: =S19-T19 -> 1.370264e-07
C20: Equity instruments | D20: ='Input dez24_estr - Temp 7'!D27 -> 12.946969 | E20: ='Input dez24_tat - Temp 7'!D27 -> 12.946969 | F20: =D20-E20 -> -3e-07 | G20: ='Input dez24_estr - Temp 7'!E27 -> 0 | H20: ='Input dez24_tat - Temp 7'!E27 -> 0 | I20: =G20-H20 -> 0 | J20: ='Input dez24_estr - Temp 7'!F27 -> 0 | K20: ='Input dez24_tat - Temp 7'!F27 -> 0 | L20: =J20-K20 -> 0 | P20: ='Input dez24_estr - Temp 7'!H27 -> 0 | Q20: ='Input dez24_tat - Temp 7'!H27 -> 0 | R20: =P20-Q20 -> 0 | S20: ='Input dez24_estr - Temp 7'!I27 -> 0 | T20: ='Input dez24_tat - Temp 7'!I27 -> 0 | U20: =S20-T20 -> 0
C21: of which management companies | D21: ='Input dez24_estr - Temp 7'!D28 -> 5.8180342 | E21: ='Input dez24_tat - Temp 7'!D28 -> 381.31527 | F21: =D21-E21 -> -375.49723 | G21: ='Input dez24_estr - Temp 7'!E28 -> 0.23413979 | H21: ='Input dez24_tat - Temp 7'!E28 -> 38.511539 | I21: =G21-H21 -> -38.277399 | J21: ='Input dez24_estr - Temp 7'!F28 -> 0 | K21: ='Input dez24_tat - Temp 7'!F28 -> 0.186284 | L21: =J21-K21 -> -0.186284 | M21: ='Input dez24_estr - Temp 7'!G28 -> 0 | N21: ='Input dez24_tat - Temp 7'!G28 -> 0 | O21: =M21-N21 -> 0 | P21: ='Input dez24_estr - Temp 7'!H28 -> 0 | Q21: ='Input dez24_tat - Temp 7'!H28 -> 0 | R21: =P21-Q21 -> 0 | S21: ='Input dez24_estr - Temp 7'!I28 -> 0 | T21: ='Input dez24_tat - Temp 7'!I28 -> 0.023035 | U21: =S21-T21 -> -0.023035
C22: Loans and advances | D22: ='Input dez24_estr - Temp 7'!D29 -> 5.8180342 | E22: ='Input dez24_tat - Temp 7'!D29 -> 115.46047 | F22: =D22-E22 -> -109.64244 | G22: ='Input dez24_estr - Temp 7'!E29 -> 0.23413979 | H22: ='Input dez24_tat - Temp 7'!E29 -> 37.271646 | I22: =G22-H22 -> -37.037506 | J22: ='Input dez24_estr - Temp 7'!F29 -> 0 | K22: ='Input dez24_tat - Temp 7'!F29 -> 0 | L22: =J22-K22 -> 0 | M22: ='Input dez24_estr - Temp 7'!G29 -> 0 | N22: ='Input dez24_tat - Temp 7'!G29 -> 0 | O22: =M22-N22 -> 0 | P22: ='Input dez24_estr - Temp 7'!H29 -> 0 | Q22: ='Input dez24_tat - Temp 7'!H29 -> 0 | R22: =P22-Q22 -> 0 | S22: ='Input dez24_estr - Temp 7'!I29 -> 0 | T22: ='Input dez24_tat - Temp 7'!I29 -> 0 | U22: =S22-T22 -> 0
C23: Debt securities, including UoP | D23: ='Input dez24_estr - Temp 7'!D30 -> 0 | E23: ='Input dez24_tat - Temp 7'!D30 -> 265.85479 | F23: =D23-E23 -> -265.85479 | G23: ='Input dez24_estr - Temp 7'!E30 -> 0 | H23: ='Input dez24_tat - Temp 7'!E30 -> 1.239893 | I23: =G23-H23 -> -1.239893 | J23: ='Input dez24_estr - Temp 7'!F30 -> 0 | K23: ='Input dez24_tat - Temp 7'!F30 -> 0.186284 | L23: =J23-K23 -> -0.186284 | M23: ='Input dez24_estr - Temp 7'!G30 -> 0 | N23: ='Input dez24_tat - Temp 7'!G30 -> 0 | O23: =M23-N23 -> 0 | P23: ='Input dez24_estr - Temp 7'!H30 -> 0 | Q23: ='Input dez24_tat - Temp 7'!H30 -> 0 | R23: =P23-Q23 -> 0 | S23: ='Input dez24_estr - Temp 7'!I30 -> 0 | T23: ='Input dez24_tat - Temp 7'!I30 -> 0.023035 | U23: =S23-T23 -> -0.023035
C24: Equity instruments | D24: ='Input dez24_estr - Temp 7'!D31 -> 0 | E24: ='Input dez24_tat - Temp 7'!D31 -> 0 | F24: =D24-E24 -> 0 | G24: ='Input dez24_estr - Temp 7'!E31 -> 0 | H24: ='Input dez24_tat - Temp 7'!E31 -> 0 | I24: =G24-H24 -> 0 | J24: ='Input dez24_estr - Temp 7'!F31 -> 0 | K24: ='Input dez24_tat - Temp 7'!F31 -> 0 | L24: =J24-K24 -> 0 | P24: ='Input dez24_estr - Temp 7'!H31 -> 0 | Q24: ='Input dez24_tat - Temp 7'!H31 -> 0 | R24: =P24-Q24 -> 0 | S24: ='Input dez24_estr - Temp 7'!I31 -> 0 | T24: ='Input dez24_tat - Temp 7'!I31 -> 0 | U24: =S24-T24 -> 0
C25: of which insurance undertakings | D25: ='Input dez24_estr - Temp 7'!D32 -> 52.121426 | E25: ='Input dez24_tat - Temp 7'!D32 -> 52.12143 | F25: =D25-E25 -> -4.455427e-06 | G25: ='Input dez24_estr - Temp 7'!E32 -> 10.773886 | H25: ='Input dez24_tat - Temp 7'!E32 -> 10.773935 | I25: =G25-H25 -> -4.9146811e-05 | J25: ='Input dez24_estr - Temp 7'!F32 -> 0.68190975 | K25: ='Input dez24_tat - Temp 7'!F32 -> 0.681913 | L25: =J25-K25 -> -3.2517396e-06 | M25: ='Input dez24_estr - Temp 7'!G32 -> 0 | N25: ='Input dez24_tat - Temp 7'!G32 -> 0 | O25: =M25-N25 -> 0 | P25: ='Input dez24_estr - Temp 7'!H32 -> 0 | Q25: ='Input dez24_tat - Temp 7'!H32 -> 0 | R25: =P25-Q25 -> 0 | S25: ='Input dez24_estr - Temp 7'!I32 -> 0 | T25: ='Input dez24_tat - Temp 7'!I32 -> 0 | U25: =S25-T25 -> 0
C26: Loans and advances | D26: ='Input dez24_estr - Temp 7'!D33 -> 52.121426 | E26: ='Input dez24_tat - Temp 7'!D33 -> 52.12143 | F26: =D26-E26 -> -4.455427e-06 | G26: ='Input dez24_estr - Temp 7'!E33 -> 10.773886 | H26: ='Input dez24_tat - Temp 7'!E33 -> 10.773935 | I26: =G26-H26 -> -4.9146811e-05 | J26: ='Input dez24_estr - Temp 7'!F33 -> 0.68190975 | K26: ='Input dez24_tat - Temp 7'!F33 -> 0.681913 | L26: =J26-K26 -> -3.2517396e-06 | M26: ='Input dez24_estr - Temp 7'!G33 -> 0 | N26: ='Input dez24_tat - Temp 7'!G33 -> 0 | O26: =M26-N26 -> 0 | P26: ='Input dez24_estr - Temp 7'!H33 -> 0 | Q26: ='Input dez24_tat - Temp 7'!H33 -> 0 | R26: =P26-Q26 -> 0 | S26: ='Input dez24_estr - Temp 7'!I33 -> 0 | T26: ='Input dez24_tat - Temp 7'!I33 -> 0 | U26: =S26-T26 -> 0
C27: Debt securities, including UoP | D27: ='Input dez24_estr - Temp 7'!D34 -> 0 | E27: ='Input dez24_tat - Temp 7'!D34 -> 0 | F27: =D27-E27 -> 0 | G27: ='Input dez24_estr - Temp 7'!E34 -> 0 | H27: ='Input dez24_tat - Temp 7'!E34 -> 0 | I27: =G27-H27 -> 0 | J27: ='Input dez24_estr - Temp 7'!F34 -> 0 | K27: ='Input dez24_tat - Temp 7'!F34 -> 0 | L27: =J27-K27 -> 0 | M27: ='Input dez24_estr - Temp 7'!G34 -> 0 | N27: ='Input dez24_tat - Temp 7'!G34 -> 0 | O27: =M27-N27 -> 0 | P27: ='Input dez24_estr - Temp 7'!H34 -> 0 | Q27: ='Input dez24_tat - Temp 7'!H34 -> 0 | R27: =P27-Q27 -> 0 | S27: ='Input dez24_estr - Temp 7'!I34 -> 0 | T27: ='Input dez24_tat - Temp 7'!I34 -> 0 | U27: =S27-T27 -> 0
C28: Equity instruments | D28: ='Input dez24_estr - Temp 7'!D35 -> 0 | E28: ='Input dez24_tat - Temp 7'!D35 -> 0 | F28: =D28-E28 -> 0 | G28: ='Input dez24_estr - Temp 7'!E35 -> 0 | H28: ='Input dez24_tat - Temp 7'!E35 -> 0 | I28: =G28-H28 -> 0 | J28: ='Input dez24_estr - Temp 7'!F35 -> 0 | K28: ='Input dez24_tat - Temp 7'!F35 -> 0 | L28: =J28-K28 -> 0 | P28: ='Input dez24_estr - Temp 7'!H35 -> 0 | Q28: ='Input dez24_tat - Temp 7'!H35 -> 0 | R28: =P28-Q28 -> 0 | S28: ='Input dez24_estr - Temp 7'!I35 -> 0 | T28: ='Input dez24_tat - Temp 7'!I35 -> 0 | U28: =S28-T28 -> 0
C29: Non-financial corporations (subject to NFRD disclosure obligations) | D29: ='Input dez24_estr - Temp 7'!D36 -> 2103.8656 | E29: ='Input dez24_tat - Temp 7'!D36 -> 2103.8656 | F29: =D29-E29 -> -2.6956113e-06 | G29: ='Input dez24_estr - Temp 7'!E36 -> 416.32749 | H29: ='Input dez24_tat - Temp 7'!E36 -> 467.85656 | I29: =G29-H29 -> -51.529068 | J29: ='Input dez24_estr - Temp 7'!F36 -> 215.43451 | K29: ='Input dez24_tat - Temp 7'!F36 -> 202.04888 | L29: =J29-K29 -> 13.385627 | M29: ='Input dez24_estr - Temp 7'!G36 -> 0 | N29: ='Input dez24_tat - Temp 7'!G36 -> 0 | O29: =M29-N29 -> 0 | P29: ='Input dez24_estr - Temp 7'!H36 -> 0.1757728 | Q29: ='Input dez24_tat - Temp 7'!H36 -> 0.140683 | R29: =P29-Q29 -> 0.035089797 | S29: ='Input dez24_estr - Temp 7'!I36 -> 194.25972 | T29: ='Input dez24_tat - Temp 7'!I36 -> 186.70012 | U29: =S29-T29 -> 7.5596048
C30: Loans and advances | D30: ='Input dez24_estr - Temp 7'!D37 -> 628.62992 | E30: ='Input dez24_tat - Temp 7'!D37 -> 628.62992 | F30: =D30-E30 -> -1.535611e-06 | G30: ='Input dez24_estr - Temp 7'!E37 -> 229.66195 | H30: ='Input dez24_tat - Temp 7'!E37 -> 281.15507 | I30: =G30-H30 -> -51.493121 | J30: ='Input dez24_estr - Temp 7'!F37 -> 43.215987 | K30: ='Input dez24_tat - Temp 7'!F37 -> 29.826419 | L30: =J30-K30 -> 13.389568 | M30: ='Input dez24_estr - Temp 7'!G37 -> 0 | N30: ='Input dez24_tat - Temp 7'!G37 -> 0 | O30: =M30-N30 -> 0 | P30: ='Input dez24_estr - Temp 7'!H37 -> 0.13630925 | Q30: ='Input dez24_tat - Temp 7'!H37 -> 0.101219 | R30: =P30-Q30 -> 0.035090251 | S30: ='Input dez24_estr - Temp 7'!I37 -> 30.905012 | T30: ='Input dez24_tat - Temp 7'!I37 -> 23.345408 | U30: =S30-T30 -> 7.5596044
C31: Debt securities, including UoP | D31: ='Input dez24_estr - Temp 7'!D38 -> 1475.1026 | E31: ='Input dez24_tat - Temp 7'!D38 -> 1475.1026 | F31: =D31-E31 -> -1.16e-06 | G31: ='Input dez24_estr - Temp 7'!E38 -> 186.66553 | H31: ='Input dez24_tat - Temp 7'!E38 -> 186.66554 | I31: =G31-H31 -> -1.537438e-07 | J31: ='Input dez24_estr - Temp 7'!F38 -> 172.21852 | K31: ='Input dez24_tat - Temp 7'!F38 -> 172.21852 | L31: =J31-K31 -> 5.4641873e-09 | M31: ='Input dez24_estr - Temp 7'!G38 -> 0 | N31: ='Input dez24_tat - Temp 7'!G38 -> 0 | O31: =M31-N31 -> 0 | P31: ='Input dez24_estr - Temp 7'!H38 -> 0.039463546 | Q31: ='Input dez24_tat - Temp 7'!H38 -> 0.039464 | R31: =P31-Q31 -> -4.5393811e-07 | S31: ='Input dez24_estr - Temp 7'!I38 -> 163.35471 | T31: ='Input dez24_tat - Temp 7'!I38 -> 163.35471 | U31: =S31-T31 -> 3.7710507e-07
C32: Equity instruments | D32: ='Input dez24_estr - Temp 7'!D39 -> 0.133078 | E32: ='Input dez24_tat - Temp 7'!D39 -> 0.133078 | F32: =D32-E32 -> 0 | G32: ='Input dez24_estr - Temp 7'!E39 -> 0 | H32: ='Input dez24_tat - Temp 7'!E39 -> 0.035947 | I32: =G32-H32 -> -0.035947 | J32: ='Input dez24_estr - Temp 7'!F39 -> 0 | K32: ='Input dez24_tat - Temp 7'!F39 -> 0.003941 | L32: =J32-K32 -> -0.003941 | P32: ='Input dez24_estr - Temp 7'!H39 -> 0 | Q32: ='Input dez24_tat - Temp 7'!H39 -> 0 | R32: =P32-Q32 -> 0 | S32: ='Input dez24_estr - Temp 7'!I39 -> 0 | T32: ='Input dez24_tat - Temp 7'!I39 -> 0 | U32: =S32-T32 -> 0
C33: Households | D33: ='Input dez24_estr - Temp 7'!D40 -> 25740.495 | E33: ='Input dez24_tat - Temp 7'!D40 -> 25740.495 | F33: =D33-E33 -> 0.00044417064 | G33: ='Input dez24_estr - Temp 7'!E40 -> 3383.7809 | H33: ='Input dez24_tat - Temp 7'!E40 -> 20888.456 | I33: =G33-H33 -> -17504.675 | J33: ='Input dez24_estr - Temp 7'!F40 -> 1107.2007 | K33: ='Input dez24_tat - Temp 7'!F40 -> 1374.5457 | L33: =J33-K33 -> -267.34502 | M33: ='Input dez24_estr - Temp 7'!G40 -> 0 | N33: ='Input dez24_tat - Temp 7'!G40 -> 0 | O33: =M33-N33 -> 0 | P33: ='Input dez24_estr - Temp 7'!H40 -> 6.4016279 | Q33: ='Input dez24_tat - Temp 7'!H40 -> 6.401631 | R33: =P33-Q33 -> -3.13e-06 | S33: ='Input dez24_estr - Temp 7'!I40 -> 0 | T33: ='Input dez24_tat - Temp 7'!I40 -> 0 | U33: =S33-T33 -> 0
C34: of which loans collateralised by residential immovable property | D34: ='Input dez24_estr - Temp 7'!D41 -> 23291.653 | E34: ='Input dez24_tat - Temp 7'!D41 -> 23291.653 | F34: =D34-E34 -> 0.00032664973 | G34: ='Input dez24_estr - Temp 7'!E41 -> 3375.4516 | H34: ='Input dez24_tat - Temp 7'!E41 -> 20851.776 | I34: =G34-H34 -> -17476.324 | J34: ='Input dez24_estr - Temp 7'!F41 -> 1100.6838 | K34: ='Input dez24_tat - Temp 7'!F41 -> 1368.1441 | L34: =J34-K34 -> -267.46032 | M34: ='Input dez24_estr - Temp 7'!G41 -> 0 | N34: ='Input dez24_tat - Temp 7'!G41 -> 0 | O34: =M34-N34 -> 0 | P34: ='Input dez24_estr - Temp 7'!H41 -> 0 | Q34: ='Input dez24_tat - Temp 7'!H41 -> 0 | R34: =P34-Q34 -> 0 | S34: ='Input dez24_estr - Temp 7'!I41 -> 0 | T34: ='Input dez24_tat - Temp 7'!I41 -> 0 | U34: =S34-T34 -> 0
C35: of which building renovation loans | D35: ='Input dez24_estr - Temp 7'!D42 -> 0 | E35: ='Input dez24_tat - Temp 7'!D42 -> 56.7458 | F35: =D35-E35 -> -56.7458 | G35: ='Input dez24_estr - Temp 7'!E42 -> 0 | H35: ='Input dez24_tat - Temp 7'!E42 -> 56.7458 | I35: =G35-H35 -> -56.7458 | J35: ='Input dez24_estr - Temp 7'!F42 -> 0 | K35: ='Input dez24_tat - Temp 7'!F42 -> 0 | L35: =J35-K35 -> 0 | M35: ='Input dez24_estr - Temp 7'!G42 -> 0 | N35: ='Input dez24_tat - Temp 7'!G42 -> 0 | O35: =M35-N35 -> 0 | P35: ='Input dez24_estr - Temp 7'!H42 -> 0 | Q35: ='Input dez24_tat - Temp 7'!H42 -> 0 | R35: =P35-Q35 -> 0 | S35: ='Input dez24_estr - Temp 7'!I42 -> 0 | T35: ='Input dez24_tat - Temp 7'!I42 -> 0 | U35: =S35-T35 -> 0
C36: of which motor vehicle loans | D36: ='Input dez24_estr - Temp 7'!D43 -> 6.4016279 | E36: ='Input dez24_tat - Temp 7'!D43 -> 34.588647 | F36: =D36-E36 -> -28.187019 | G36: ='Input dez24_estr - Temp 7'!E43 -> 6.4016279 | H36: ='Input dez24_tat - Temp 7'!E43 -> 34.588647 | I36: =G36-H36 -> -28.187019 | J36: ='Input dez24_estr - Temp 7'!F43 -> 6.4016279 | K36: ='Input dez24_tat - Temp 7'!F43 -> 6.401631 | L36: =J36-K36 -> -3.13e-06 | M36: ='Input dez24_estr - Temp 7'!G43 -> 0 | N36: ='Input dez24_tat - Temp 7'!G43 -> 0 | O36: =M36-N36 -> 0 | P36: ='Input dez24_estr - Temp 7'!H43 -> 6.4016279 | Q36: ='Input dez24_tat - Temp 7'!H43 -> 6.401631 | R36: =P36-Q36 -> -3.13e-06 | S36: ='Input dez24_estr - Temp 7'!I43 -> 0 | T36: ='Input dez24_tat - Temp 7'!I43 -> 0 | U36: =S36-T36 -> 0
C37: Local governments financing | D37: ='Input dez24_estr - Temp 7'!D44 -> 917.48901 | E37: ='Input dez24_tat - Temp 7'!D44 -> 917.48901 | F37: =D37-E37 -> 1.71e-06 | G37: ='Input dez24_estr - Temp 7'!E44 -> 0 | H37: ='Input dez24_tat - Temp 7'!E44 -> 14.385089 | I37: =G37-H37 -> -14.385089 | J37: ='Input dez24_estr - Temp 7'!F44 -> 0 | K37: ='Input dez24_tat - Temp 7'!F44 -> 0 | L37: =J37-K37 -> 0 | M37: ='Input dez24_estr - Temp 7'!G44 -> 0 | N37: ='Input dez24_tat - Temp 7'!G44 -> 0 | O37: =M37-N37 -> 0 | P37: ='Input dez24_estr - Temp 7'!H44 -> 0 | Q37: ='Input dez24_tat - Temp 7'!H44 -> 0 | R37: =P37-Q37 -> 0 | S37: ='Input dez24_estr - Temp 7'!I44 -> 0 | T37: ='Input dez24_tat - Temp 7'!I44 -> 0 | U37: =S37-T37 -> 0
C38: Housing financing | D38: ='Input dez24_estr - Temp 7'!D45 -> 0 | E38: ='Input dez24_tat - Temp 7'!D45 -> 0 | F38: =D38-E38 -> 0 | G38: ='Input dez24_estr - Temp 7'!E45 -> 0 | H38: ='Input dez24_tat - Temp 7'!E45 -> 0 | I38: =G38-H38 -> 0 | J38: ='Input dez24_estr - Temp 7'!F45 -> 0 | K38: ='Input dez24_tat - Temp 7'!F45 -> 0 | L38: =J38-K38 -> 0 | M38: ='Input dez24_estr - Temp 7'!G45 -> 0 | N38: ='Input dez24_tat - Temp 7'!G45 -> 0 | O38: =M38-N38 -> 0 | P38: ='Input dez24_estr - Temp 7'!H45 -> 0 | Q38: ='Input dez24_tat - Temp 7'!H45 -> 0 | R38: =P38-Q38 -> 0 | S38: ='Input dez24_estr - Temp 7'!I45 -> 0 | T38: ='Input dez24_tat - Temp 7'!I45 -> 0 | U38: =S38-T38 -> 0
C39: Other local governments financing | D39: ='Input dez24_estr - Temp 7'!D46 -> 917.48901 | E39: ='Input dez24_tat - Temp 7'!D46 -> 917.48901 | F39: =D39-E39 -> 1.71e-06 | G39: ='Input dez24_estr - Temp 7'!E46 -> 0 | H39: ='Input dez24_tat - Temp 7'!E46 -> 14.385089 | I39: =G39-H39 -> -14.385089 | J39: ='Input dez24_estr - Temp 7'!F46 -> 0 | K39: ='Input dez24_tat - Temp 7'!F46 -> 0 | L39: =J39-K39 -> 0 | M39: ='Input dez24_estr - Temp 7'!G46 -> 0 | N39: ='Input dez24_tat - Temp 7'!G46 -> 0 | O39: =M39-N39 -> 0 | P39: ='Input dez24_estr - Temp 7'!H46 -> 0 | Q39: ='Input dez24_tat - Temp 7'!H46 -> 0 | R39: =P39-Q39 -> 0 | S39: ='Input dez24_estr - Temp 7'!I46 -> 0 | T39: ='Input dez24_tat - Temp 7'!I46 -> 0 | U39: =S39-T39 -> 0
C40: Collateral obtained by taking possession: residential and commercial immovable properties | D40: ='Input dez24_estr - Temp 7'!D47 -> 48.551569 | E40: ='Input dez24_tat - Temp 7'!D47 -> 48.551569 | F40: =D40-E40 -> -2.9000001e-07 | G40: ='Input dez24_estr - Temp 7'!E47 -> 0 | H40: ='Input dez24_tat - Temp 7'!E47 -> 0 | I40: =G40-H40 -> 0 | J40: ='Input dez24_estr - Temp 7'!F47 -> 0 | K40: ='Input dez24_tat - Temp 7'!F47 -> 0 | L40: =J40-K40 -> 0 | M40: ='Input dez24_estr - Temp 7'!G47 -> 0 | N40: ='Input dez24_tat - Temp 7'!G47 -> 0 | O40: =M40-N40 -> 0 | P40: ='Input dez24_estr - Temp 7'!H47 -> 0 | Q40: ='Input dez24_tat - Temp 7'!H47 -> 0 | R40: =P40-Q40 -> 0 | S40: ='Input dez24_estr - Temp 7'!I47 -> 0 | T40: ='Input dez24_tat - Temp 7'!I47 -> 0 | U40: =S40-T40 -> 0
C41: TOTAL GAR ASSETS | D41: ='Input dez24_estr - Temp 7'!D48 -> 30509.554 | E41: ='Input dez24_tat - Temp 7'!D48 -> 30509.554 | F41: =D41-E41 -> 0.00062231201 | G41: ='Input dez24_estr - Temp 7'!E48 -> 4052.479 | H41: ='Input dez24_tat - Temp 7'!E48 -> 21828.466 | I41: =G41-H41 -> -17775.987 | J41: ='Input dez24_estr - Temp 7'!F48 -> 1520.0948 | K41: ='Input dez24_tat - Temp 7'!F48 -> 1774.3084 | L41: =J41-K41 -> -254.21358 | M41: ='Input dez24_estr - Temp 7'!G48 -> 0 | N41: ='Input dez24_tat - Temp 7'!G48 -> 0 | O41: =M41-N41 -> 0 | P41: ='Input dez24_estr - Temp 7'!H48 -> 6.5825941 | Q41: ='Input dez24_tat - Temp 7'!H48 -> 6.542314 | R41: =P41-Q41 -> 0.040280099 | S41: ='Input dez24_estr - Temp 7'!I48 -> 288.69908 | T41: ='Input dez24_tat - Temp 7'!I48 -> 280.92405 | U41: =S41-T41 -> 7.7750285
B42: Assets excluded from the numerator for GAR calculation (covered in the denominator) | C42: EU Non-financial corporations (not subject to NFRD disclosure obligations) | D42: ='Input dez24_estr - Temp 7'!D50 -> 10107.956 | E42: ='Input dez24_tat - Temp 7'!D50 -> 10138.49 | F42: =D42-E42 -> -30.534524
C43: Loans and advances | D43: ='Input dez24_estr - Temp 7'!D51 -> 8777.3175 | E43: ='Input dez24_tat - Temp 7'!D51 -> 8807.8508 | F43: =D43-E43 -> -30.53333
C44: Debt securities | D44: ='Input dez24_estr - Temp 7'!D52 -> 1330.4486 | E44: ='Input dez24_tat - Temp 7'!D52 -> 1330.4498 | F44: =D44-E44 -> -0.0011945467
C45: Equity instruments | D45: ='Input dez24_estr - Temp 7'!D53 -> 0.18943846 | E45: ='Input dez24_tat - Temp 7'!D53 -> 0.189438 | F45: =D45-E45 -> 4.6e-07
C46: Non-EU Non-financial corporations (not subject to NFRD disclosure obligations) | D46: ='Input dez24_estr - Temp 7'!D54 -> 77.806515 | E46: ='Input dez24_tat - Temp 7'!D54 -> 47.372038 | F46: =D46-E46 -> 30.434477
C47: Loans and advances | D47: ='Input dez24_estr - Temp 7'!D55 -> 77.806515 | E47: ='Input dez24_tat - Temp 7'!D55 -> 47.373227 | F47: =D47-E47 -> 30.433288
...

Sheet Input dez24_estr - Temp 7
B8: Template 7 - Mitigating actions: Assets for the calculation of GAR
D10: a | E10: b | F10: c | G10: d | H10: e | I10: f | J10: g | K10: h | L10: i | M10: j | N10: k | O10: l | P10: m | Q10: n | R10: o | S10: p
B11: Million EUR | D11: Disclosure reference date T
D12: Total gross carrying amount | E12: Climate Change Mitigation (CCM) | J12: Climate Change Adaptation (CCA) | O12: TOTAL (CCM + CCA)
E13: Of which towards taxonomy relevant sectors (Taxonomy-eligible) | J13: Of which towards taxonomy relevant sectors (Taxonomy-eligible) | O13: Of which towards taxonomy relevant sectors (Taxonomy-eligible)
F14: Of which environmentally sustainable (Taxonomy-aligned) | K14: Of which environmentally sustainable (Taxonomy-aligned) | P14: Of which environmentally sustainable (Taxonomy-aligned)
G15: Of which specialised lending | H15: Of which transitional | I15: Of which enabling | L15: Of which specialised lending | M15: Of which adaptation | N15: Of which enabling | Q15: Of which specialised lending | R15: Of which transitional/adaptation | S15: Of which enabling
C16: GAR - Covered assets in both numerator and denominator
B17: 1 | C17: Loans and advances, debt securities and equity instruments not HfT eligible for GAR calculation | D17: 30461.003 | E17: 4052.479 | F17: 1520.0948 | G17: 0 | H17: 6.5825941 | I17: 288.69908 | J17: 20.231433 | K17: 0.39903649 | L17: 0 | M17: -0.035956735 | N17: 0.43499322 | O17: 4072.7104 | P17: 1520.4939 | Q17: 0 | R17: 6.5466374 | S17: 289.13408
B18: 2 | C18: Financial corporations | D18: 1699.1528 | E18: 252.37061 | F18: 197.45961 | G18: 0 | H18: 0.005193432 | I18: 94.439362 | J18: 3.5516363 | K18: 0.39903649 | L18: 0 | M18: 0.39803496 | N18: 0.0010015289 | O18: 255.92225 | P18: 197.85864 | Q18: 0 | R18: 0.40322839 | S18: 94.440363
B19: 3 | C19: Credit institutions | D19: 169.80569 | E19: 22.036605 | F19: 0.53051443 | G19: 0 | H19: 0 | I19: 0.049614447 | J19: 0.034860416 | K19: 0 | L19: 0 | M19: 0 | N19: 0 | O19: 22.071466 | P19: 0.53051443 | Q19: 0 | R19: 0 | S19: 0.049614447
B20: 4 | C20: Loans and advances | D20: 169.80569 | E20: 22.036605 | F20: 0.53051443 | G20: 0 | H20: 0 | I20: 0.049614447 | J20: 0.034860416 | L20: 0 | M20: 0 | N20: 0 | O20: 22.071466 | P20: 0.53051443 | Q20: 0 | R20: 0 | S20: 0.049614447
B21: 5 | C21: Debt securities, including UoP | D21: 0 | E21: 0 | F21: 0 | G21: 0 | H21: 0 | I21: 0 | J21: 0 | K21: 0 | L21: 0 | M21: 0 | N21: 0 | O21: 0 | P21: 0 | Q21: 0 | R21: 0 | S21: 0
B22: 6 | C22: Equity instruments | D22: 0 | E22: 0 | F22: 0 | H22: 0 | I22: 0 | J22: 0 | K22: 0 | M22: 0 | N22: 0 | O22: 0 | P22: 0 | Q22: 0 | R22: 0 | S22: 0
B23: 7 | C23: Other financial corporations | D23: 1529.3471 | E23: 230.33401 | F23: 196.92909 | G23: 0 | H23: 0.005193432 | I23: 94.389747 | J23: 3.5167759 | K23: 0 | L23: 0 | M23: -0.0010015289 | N23: 0.0010015289 | O23: 233.85078 | P23: 196.92909 | Q23: 0 | R23: 0.0041919031 | S23: 94.390749
B24: 8 | C24: of which investment firms | D24: 643.78113 | E24: 214.1777 | F24: 195.506 | G24: 0 | H24: 0 | I24: 94.151287 | J24: 0 | K24: 0 | L24: 0 | M24: 0 | N24: 0 | O24: 214.1777 | P24: 195.506 | Q24: 0 | R24: 0 | S24: 94.151287
B25: 9 | C25: Loans and advances | D25: 175.71321 | E25: 3.3954957e-05 | F25: 3.0994813e-05 | G25: 0 | H25: 0 | I25: 1.4926404e-05 | J25: 0 | K25: 0 | L25: 0 | M25: 0 | N25: 0 | O25: 3.3954957e-05 | P25: 3.0994813e-05 | Q25: 0 | R25: 0 | S25: 1.4926404e-05
B26: 10 | C26: Debt securities, including UoP | D26: 455.12095 | E26: 214.17767 | F26: 195.50597 | G26: 0 | H26: 0 | I26: 94.151272 | J26: 0 | K26: 0 | L26: 0 | M26: 0 | N26: 0 | O26: 214.17767 | P26: 195.50597 | Q26: 0 | R26: 0 | S26: 94.151272
B27: 11 | C27: Equity instruments | D27: 12.946969 | E27: 0 | F27: 0 | H27: 0 | I27: 0 | J27: 0 | K27: 0 | M27: 0 | N27: 0 | O27: 0 | P27: 0 | Q27: 0 | R27: 0 | S27: 0
B28: 12 | C28: of which management companies | D28: 5.8180342 | E28: 0.23413979 | F28: 0 | G28: 0 | H28: 0 | I28: 0 | J28: 3.2107926e-06 | K28: 0 | L28: 0 | M28: 0 | N28: 0 | O28: 0.234143 | P28: 0 | Q28: 0 | R28: 0 | S28: 0
B29: 13 | C29: Loans and advances | D29: 5.8180342 | E29: 0.23413979 | F29: 0 | G29: 0 | H29: 0 | I29: 0 | J29: 3.2107926e-06 | K29: 0 | L29: 0 | M29: 0 | N29: 0 | O29: 0.234143 | P29: 0 | Q29: 0 | R29: 0 | S29: 0
B30: 14 | C30: Debt securities, including UoP | D30: 0 | E30: 0 | F30: 0 | G30: 0 | H30: 0 | I30: 0 | J30: 0 | K30: 0 | L30: 0 | M30: 0 | N30: 0 | O30: 0 | P30: 0 | Q30: 0 | R30: 0 | S30: 0
B31: 15 | C31: Equity instruments | D31: 0 | E31: 0 | F31: 0 | H31: 0 | I31: 0 | J31: 0 | K31: 0 | M31: 0 | N31: 0 | O31: 0 | P31: 0 | Q31: 0 | R31: 0 | S31: 0
B32: 16 | C32: of which insurance undertakings | D32: 52.121426 | E32: 10.773886 | F32: 0.68190975 | G32: 0 | H32: 0 | I32: 0 | J32: 3.5109565 | K32: 0 | L32: 0 | M32: 0 | N32: 0 | O32: 14.284842 | P32: 0.68190975 | Q32: 0 | R32: 0 | S32: 0
B33: 17 | C33: Loans and advances | D33: 52.121426 | E33: 10.773886 | F33: 0.68190975 | G33: 0 | H33: 0 | I33: 0 | J33: 3.5109565 | K33: 0 | L33: 0 | M33: 0 | N33: 0 | O33: 14.284842 | P33: 0.68190975 | Q33: 0 | R33: 0 | S33: 0
B34: 18 | C34: Debt securities, including UoP | D34: 0 | E34: 0 | F34: 0 | G34: 0 | H34: 0 | I34: 0 | J34: 0 | K34: 0 | L34: 0 | M34: 0 | N34: 0 | O34: 0 | P34: 0 | Q34: 0 | R34: 0 | S34: 0
B35: 19 | C35: Equity instruments | D35: 0 | E35: 0 | F35: 0 | H35: 0 | I35: 0 | J35: 0 | K35: 0 | M35: 0 | N35: 0 | O35: 0 | P35: 0 | Q35: 0 | R35: 0 | S35: 0
B36: 20 | C36: Non-financial corporations (subject to NFRD disclosure obligations) | D36: 2103.8656 | E36: 416.32749 | F36: 215.43451 | G36: 0 | H36: 0.1757728 | I36: 194.25972 | J36: 16.679797 | K36: 0 | L36: 0 | M36: -0.4339917 | N36: 0.4339917 | O36: 433.00728 | P36: 215.43451 | Q36: 0 | R36: -0.2582189 | S36: 194.69371
B37: 21 | C37: Loans and advances | D37: 628.62992 | E37: 229.66195 | F37: 43.215987 | G37: 0 | H37: 0.13630925 | I37: 30.905012 | J37: 10.077072 | K37: 0 | L37: 0 | M37: -0.042961297 | N37: 0.042961297 | O37: 239.73902 | P37: 43.215987 | Q37: 0 | R37: 0.093347954 | S37: 30.947974
B38: 22 | C38: Debt securities, including UoP | D38: 1475.1026 | E38: 186.66553 | F38: 172.21852 | G38: 0 | H38: 0.039463546 | I38: 163.35471 | J38: 6.6027249 | K38: 0 | L38: 0 | M38: -0.3910304 | N38: 0.3910304 | O38: 193.26826 | P38: 172.21852 | Q38: 0 | R38: -0.35156685 | S38: 163.74574
B39: 23 | C39: Equity instruments | D39: 0.133078 | E39: 0 | F39: 0 | H39: 0 | I39: 0 | J39: 0 | K39: 0 | M39: 0 | N39: 0 | O39: 0 | P39: 0 | Q39: 0 | R39: 0 | S39: 0
B40: 24 | C40: Households | D40: 25740.495 | E40: 3383.7809 | F40: 1107.2007 | G40: 0 | H40: 6.4016279 | I40: 0 | O40: 3383.7809 | P40: 1107.2007 | Q40: 0 | R40: 6.4016279 | S40: 0
B41: 25 | C41: of which loans collateralised by residential immovable property | D41: 23291.653 | E41: 3375.4516 | F41: 1100.6838 | G41: 0 | H41: 0 | I41: 0 | O41: 3375.4516 | P41: 1100.6838 | Q41: 0 | R41: 0 | S41: 0
B42: 26 | C42: of which building renovation loans | D42: 0 | E42: 0 | F42: 0 | G42: 0 | H42: 0 | I42: 0 | O42: 0 | P42: 0 | Q42: 0 | R42: 0 | S42: 0
B43: 27 | C43: of which motor vehicle loans | D43: 6.4016279 | E43: 6.4016279 | F43: 6.4016279 | G43: 0 | H43: 6.4016279 | I43: 0 | O43: 6.4016279 | P43: 6.4016279 | Q43: 0 | R43: 6.4016279 | S43: 0
B44: 28 | C44: Local governments financing | D44: 917.48901 | E44: 0 | F44: 0 | G44: 0 | H44: 0 | I44: 0 | J44: 0 | K44: 0 | L44: 0 | M44: 0 | N44: 0 | O44: 0 | P44: 0 | Q44: 0 | R44: 0 | S44: 0
B45: 29 | C45: Housing financing | D45: 0 | E45: 0 | F45: 0 | G45: 0 | H45: 0 | I45: 0 | J45: 0 | K45: 0 | L45: 0 | M45: 0 | N45: 0 | O45: 0 | P45: 0 | Q45: 0 | R45: 0 | S45: 0
B46: 30 | C46: Other local governments financing | D46: 917.48901 | E46: 0 | F46: 0 | G46: 0 | H46: 0 | I46: 0 | J46: 0 | K46: 0 | L46: 0 | M46: 0 | N46: 0 | O46: 0 | P46: 0 | Q46: 0 | R46: 0 | S46: 0
B47: 31 | C47: Collateral obtained by taking possession: residential and commercial immovable properties | D47: 48.551569 | E47: 0 | F47: 0 | G47: 0 | H47: 0 | I47: 0 | J47: 0 | K47: 0 | L47: 0 | M47: 0 | N47: 0 | O47: 0 | P47: 0 | Q47: 0 | R47: 0 | S47: 0
B48: 32 | C48: TOTAL GAR ASSETS | D48: 30509.554 | E48: 4052.479 | F48: 1520.0948 | G48: 0 | H48: 6.5825941 | I48: 288.69908 | J48: 20.231433 | K48: 0.39903649 | L48: 0 | M48: -0.035956735 | N48: 0.43499322 | O48: 4072.7104 | P48: 1520.4939 | Q48: 0 | R48: 6.5466374 | S48: 289.13408
...

Sheet Input dez24_tat - Temp 7
B8: Template 7 - Mitigating actions: Assets for the calculation of GAR
D10: a | E10: b | F10: c | G10: d | H10: e | I10: f | J10: g | K10: h | L10: i | M10: j | N10: k | O10: l | P10: m | Q10: n | R10: o | S10: p
B11: Million EUR | D11: Disclosure reference date T
D12: Total gross carrying amount | E12: Climate Change Mitigation (CCM) | J12: Climate Change Adaptation (CCA) | O12: TOTAL (CCM + CCA)
E13: Of which towards taxonomy relevant sectors (Taxonomy-eligible) | J13: Of which towards taxonomy relevant sectors (Taxonomy-eligible) | O13: Of which towards taxonomy relevant sectors (Taxonomy-eligible)
F14: Of which environmentally sustainable (Taxonomy-aligned) | K14: Of which environmentally sustainable (Taxonomy-aligned) | P14: Of which environmentally sustainable (Taxonomy-aligned)
G15: Of which specialised lending | H15: Of which transitional | I15: Of which enabling | L15: Of which specialised lending | M15: Of which adaptation | N15: Of which enabling | Q15: Of which specialised lending | R15: Of which transitional/adaptation | S15: Of which enabling
C16: GAR - Covered assets in both numerator and denominator
B17: 1 | C17: Loans and advances, debt securities and equity instruments not HfT eligible for GAR calculation | D17: 30461.002 | E17: 21828.466 | F17: 1774.3084 | G17: 0 | H17: 6.542314 | I17: 280.92405 | J17: 0 | K17: 0 | L17: 0 | M17: 0 | N17: 0 | O17: 21828.466 | P17: 1774.3084 | Q17: 0 | R17: 6.542314 | S17: 280.92405
B18: 2 | C18: Financial corporations | D18: 1699.1526 | E18: 457.76869 | F18: 197.7138 | G18: 0 | H18: 0 | I18: 94.223938 | J18: 0 | K18: 0 | L18: 0 | M18: 0 | N18: 0 | O18: 457.76869 | P18: 197.7138 | Q18: 0 | R18: 0 | S18: 94.223938
B19: 3 | C19: Credit institutions | D19: 169.80569 | E19: 30.294457 | F19: 1.084128 | G19: 0 | H19: 0 | I19: 0.049615 | J19: 0 | K19: 0 | L19: 0 | M19: 0 | N19: 0 | O19: 30.294457 | P19: 1.084128 | Q19: 0 | R19: 0 | S19: 0.049615
B20: 4 | C20: Loans and advances | D20: 169.80569 | E20: 30.294457 | F20: 1.084128 | G20: 0 | H20: 0 | I20: 0.049615 | J20: 0 | L20: 0 | M20: 0 | N20: 0 | O20: 30.294457 | P20: 1.084128 | Q20: 0 | R20: 0 | S20: 0.049615
B21: 5 | C21: Debt securities, including UoP | D21: 0 | E21: 0 | F21: 0 | G21: 0 | H21: 0 | I21: 0 | J21: 0 | K21: 0 | L21: 0 | M21: 0 | N21: 0 | O21: 0 | P21: 0 | Q21: 0 | R21: 0 | S21: 0
B22: 6 | C22: Equity instruments | D22: 0 | E22: 0 | F22: 0 | H22: 0 | I22: 0 | J22: 0 | K22: 0 | M22: 0 | N22: 0 | O22: 0 | P22: 0 | Q22: 0 | R22: 0 | S22: 0
B23: 7 | C23: Other financial corporations | D23: 1529.347 | E23: 427.47423 | F23: 196.62967 | G23: 0 | H23: 0 | I23: 94.174323 | J23: 0 | K23: 0 | L23: 0 | M23: 0 | N23: 0 | O23: 427.47423 | P23: 196.62967 | Q23: 0 | R23: 0 | S23: 94.174323
B24: 8 | C24: of which investment firms | D24: 690.7549 | E24: 319.24039 | F24: 195.506 | G24: 0 | H24: 0 | I24: 94.151287 | J24: 0 | K24: 0 | L24: 0 | M24: 0 | N24: 0 | O24: 319.24039 | P24: 195.506 | Q24: 0 | R24: 0 | S24: 94.151287
B25: 9 | C25: Loans and advances | D25: 222.68697 | E25: 105.06273 | F25: 3.1e-05 | G25: 0 | H25: 0 | I25: 1.5e-05 | J25: 0 | K25: 0 | L25: 0 | M25: 0 | N25: 0 | O25: 105.06273 | P25: 3.1e-05 | Q25: 0 | R25: 0 | S25: 1.5e-05
B26: 10 | C26: Debt securities, including UoP | D26: 455.12095 | E26: 214.17767 | F26: 195.50597 | G26: 0 | H26: 0 | I26: 94.151272 | J26: 0 | K26: 0 | L26: 0 | M26: 0 | N26: 0 | O26: 214.17767 | P26: 195.50597 | Q26: 0 | R26: 0 | S26: 94.151272
B27: 11 | C27: Equity instruments | D27: 12.946969 | E27: 0 | F27: 0 | H27: 0 | I27: 0 | J27: 0 | K27: 0 | M27: 0 | N27: 0 | O27: 0 | P27: 0 | Q27: 0 | R27: 0 | S27: 0
B28: 12 | C28: of which management companies | D28: 381.31527 | E28: 38.511539 | F28: 0.186284 | G28: 0 | H28: 0 | I28: 0.023035 | J28: 0 | K28: 0 | L28: 0 | M28: 0 | N28: 0 | O28: 38.511539 | P28: 0.186284 | Q28: 0 | R28: 0 | S28: 0.023035
B29: 13 | C29: Loans and advances | D29: 115.46047 | E29: 37.271646 | F29: 0 | G29: 0 | H29: 0 | I29: 0 | J29: 0 | K29: 0 | L29: 0 | M29: 0 | N29: 0 | O29: 37.271646 | P29: 0 | Q29: 0 | R29: 0 | S29: 0
B30: 14 | C30: Debt securities, including UoP | D30: 265.85479 | E30: 1.239893 | F30: 0.186284 | G30: 0 | H30: 0 | I30: 0.023035 | J30: 0 | K30: 0 | L30: 0 | M30: 0 | N30: 0 | O30: 1.239893 | P30: 0.186284 | Q30: 0 | R30: 0 | S30: 0.023035
B31: 15 | C31: Equity instruments | D31: 0 | E31: 0 | F31: 0 | H31: 0 | I31: 0 | J31: 0 | K31: 0 | M31: 0 | N31: 0 | O31: 0 | P31: 0 | Q31: 0 | R31: 0 | S31: 0
B32: 16 | C32: of which insurance undertakings | D32: 52.12143 | E32: 10.773935 | F32: 0.681913 | G32: 0 | H32: 0 | I32: 0 | J32: 0 | K32: 0 | L32: 0 | M32: 0 | N32: 0 | O32: 10.773935 | P32: 0.681913 | Q32: 0 | R32: 0 | S32: 0
B33: 17 | C33: Loans and advances | D33: 52.12143 | E33: 10.773935 | F33: 0.681913 | G33: 0 | H33: 0 | I33: 0 | J33: 0 | K33: 0 | L33: 0 | M33: 0 | N33: 0 | O33: 10.773935 | P33: 0.681913 | Q33: 0 | R33: 0 | S33: 0
B34: 18 | C34: Debt securities, including UoP | D34: 0 | E34: 0 | F34: 0 | G34: 0 | H34: 0 | I34: 0 | J34: 0 | K34: 0 | L34: 0 | M34: 0 | N34: 0 | O34: 0 | P34: 0 | Q34: 0 | R34: 0 | S34: 0
B35: 19 | C35: Equity instruments | D35: 0 | E35: 0 | F35: 0 | H35: 0 | I35: 0 | J35: 0 | K35: 0 | M35: 0 | N35: 0 | O35: 0 | P35: 0 | Q35: 0 | R35: 0 | S35: 0
B36: 20 | C36: Non-financial corporations (subject to NFRD disclosure obligations) | D36: 2103.8656 | E36: 467.85656 | F36: 202.04888 | G36: 0 | H36: 0.140683 | I36: 186.70012 | J36: 0 | K36: 0 | L36: 0 | M36: 0 | N36: 0 | O36: 467.85656 | P36: 202.04888 | Q36: 0 | R36: 0.140683 | S36: 186.70012
B37: 21 | C37: Loans and advances | D37: 628.62992 | E37: 281.15507 | F37: 29.826419 | G37: 0 | H37: 0.101219 | I37: 23.345408 | J37: 0 | K37: 0 | L37: 0 | M37: 0 | N37: 0 | O37: 281.15507 | P37: 29.826419 | Q37: 0 | R37: 0.101219 | S37: 23.345408
B38: 22 | C38: Debt securities, including UoP | D38: 1475.1026 | E38: 186.66554 | F38: 172.21852 | G38: 0 | H38: 0.039464 | I38: 163.35471 | J38: 0 | K38: 0 | L38: 0 | M38: 0 | N38: 0 | O38: 186.66554 | P38: 172.21852 | Q38: 0 | R38: 0.039464 | S38: 163.35471
B39: 23 | C39: Equity instruments | D39: 0.133078 | E39: 0.035947 | F39: 0.003941 | H39: 0 | I39: 0 | J39: 0 | K39: 0 | M39: 0 | N39: 0 | O39: 0.035947 | P39: 0.003941 | Q39: 0 | R39: 0 | S39: 0
B40: 24 | C40: Households | D40: 25740.495 | E40: 20888.456 | F40: 1374.5457 | G40: 0 | H40: 6.401631 | I40: 0 | O40: 20888.456 | P40: 1374.5457 | Q40: 0 | R40: 6.401631 | S40: 0
B41: 25 | C41: of which loans collateralised by residential immovable property | D41: 23291.653 | E41: 20851.776 | F41: 1368.1441 | G41: 0 | H41: 0 | I41: 0 | O41: 20851.776 | P41: 1368.1441 | Q41: 0 | R41: 0 | S41: 0
B42: 26 | C42: of which building renovation loans | D42: 56.7458 | E42: 56.7458 | F42: 0 | G42: 0 | H42: 0 | I42: 0 | O42: 56.7458 | P42: 0 | Q42: 0 | R42: 0 | S42: 0
B43: 27 | C43: of which motor vehicle loans | D43: 34.588647 | E43: 34.588647 | F43: 6.401631 | G43: 0 | H43: 6.401631 | I43: 0 | O43: 34.588647 | P43: 6.401631 | Q43: 0 | R43: 6.401631 | S43: 0
B44: 28 | C44: Local governments financing | D44: 917.48901 | E44: 14.385089 | F44: 0 | G44: 0 | H44: 0 | I44: 0 | J44: 0 | K44: 0 | L44: 0 | M44: 0 | N44: 0 | O44: 14.385089 | P44: 0 | Q44: 0 | R44: 0 | S44: 0
B45: 29 | C45: Housing financing | D45: 0 | E45: 0 | F45: 0 | G45: 0 | H45: 0 | I45: 0 | J45: 0 | K45: 0 | L45: 0 | M45: 0 | N45: 0 | O45: 0 | P45: 0 | Q45: 0 | R45: 0 | S45: 0
B46: 30 | C46: Other local governments financing | D46: 917.48901 | E46: 14.385089 | F46: 0 | G46: 0 | H46: 0 | I46: 0 | J46: 0 | K46: 0 | L46: 0 | M46: 0 | N46: 0 | O46: 14.385089 | P46: 0 | Q46: 0 | R46: 0 | S46: 0
B47: 31 | C47: Collateral obtained by taking possession: residential and commercial immovable properties | D47: 48.551569 | E47: 0 | F47: 0 | G47: 0 | H47: 0 | I47: 0 | J47: 0 | K47: 0 | L47: 0 | M47: 0 | N47: 0 | O47: 0 | P47: 0 | Q47: 0 | R47: 0 | S47: 0
B48: 32 | C48: TOTAL GAR ASSETS | D48: 30509.554 | E48: 21828.466 | F48: 1774.3084 | G48: 0 | H48: 6.542314 | I48: 280.92405 | J48: 0 | K48: 0 | L48: 0 | M48: 0 | N48: 0 | O48: 21828.466 | P48: 1774.3084 | Q48: 0 | R48: 6.542314 | S48: 280.92405
...

Sheet Input Dez24_estr - Temp 8
B8: Template 8 - GAR (%)
D10: a | E10: b | F10: c | G10: d | H10: e | I10: f | J10: g | K10: h | L10: i | M10: j | N10: k | O10: l | P10: m | Q10: n | R10: o | S10: p | T10: q | U10: r | V10: s | W10: t | X10: u | Y10: v | Z10: w | AA10: x | AB10: y | AC10: z | AD10: aa | AE10: ab | AF10: ac | AG10: ad | AH10: ae | AI10: af
D11: Disclosure reference date T: KPIs on stock | T11: Disclosure reference date T: KPIs on flows
D12: Climate Change Mitigation (CCM) | I12: Climate Change Adaptation (CCA) | N12: TOTAL (CCM + CCA) | T12: Climate Change Mitigation (CCM) | Y12: Climate Change Adaptation (CCA) | AD12: TOTAL (CCM + CCA)
D13: Proportion of eligible assets funding taxonomy relevant sectors | I13: Proportion of eligible assets funding taxonomy relevant sectors | N13: Proportion of eligible assets funding taxonomy relevant sectors | S13: Proportion of total assets covered | T13: Proportion of new eligible assets funding taxonomy relevant sectors | Y13: Proportion of new eligible assets funding taxonomy relevant sectors | AD13: Proportion of new eligible assets funding taxonomy relevant sectors | AI13: Proportion of total new assets covered
E14: Of which environmentally sustainable | J14: Of which environmentally sustainable | O14: Of which environmentally sustainable | U14: Of which environmentally sustainable | Z14: Of which environmentally sustainable | AE14: Of which environmentally sustainable
C15: % (compared to total covered assets in the denominator) | F15: Of which specialised lending | G15: Of which transitional | H15: Of which enabling | K15: Of which specialised lending | L15: Of which adaptation | M15: Of which enabling | P15: Of which specialised lending | Q15: Of which transitional/adaptation | R15: Of which enabling | V15: Of which specialised lending | W15: Of which transitional | X15: Of which enabling | AA15: Of which specialised lending | AB15: Of which adaptation | AC15: Of which enabling | AF15: Of which specialised lending | AG15: Of which transitional/adaptation | AH15: Of which enabling
B16: 1 | C16: GAR | D16: 0.094730327 | E16: 0.035533578 | F16: 0 | G16: 0.00015387404 | H16: 0.0067485997 | I16: 0.00047292788 | J16: 9.3278355e-06 | K16: 0 | L16: -8.4052091e-07 | M16: 1.0168356e-05 | N16: 0.095203255 | O16: 0.035542906 | P16: 0 | Q16: 0.00015303351 | R16: 0.0067587681 | S16: 0.53245976 | T16: 0.1015034 | U16: 0.0431596 | V16: 0 | W16: 0.00028889404 | X16: 0.022425715 | Y16: 0.00077320413 | Z16: 3.3239501e-05 | AA16: 0 | AB16: -2.1344625e-06 | AC16: 3.5373963e-05 | AD16: 0.1022766 | AE16: 0.04319284 | AF16: 0 | AG16: 0.00028675958 | AH16: 0.022461089 | AI16: 0.46187325
B17: 2 | C17: Loans and advances. debt securities and equity instruments not HfT eligible for GAR calculation | D17: 0.13303827 | E17: 0.04990298 | F17: 0 | G17: 0.00021609906 | H17: 0.0094776618 | I17: 0.00066417489 | J17: 1.3099913e-05 | K17: 0 | L17: -1.1804186e-06 | M17: 1.4280332e-05 | N17: 0.13370244 | O17: 0.04991608 | P17: 0 | Q17: 0.00021491864 | R17: 0.0094919421 | S17: 0.53161243 | T17: 0.15969447 | U17: 0.067902646 | V17: 0 | W17: 0.00045451463 | X17: 0.035282194 | Y17: 0.0012164757 | Z17: 5.2295435e-05 | AA17: 0 | AB17: -3.3581324e-06 | AC17: 5.5653567e-05 | AD17: 0.16091094 | AE17: 0.067954942 | AF17: 0 | AG17: 0.0004511565 | AH17: 0.035337848 | AI17: 0.46180797
B18: 3 | C18: Financial corporations | D18: 0.14852732 | E18: 0.11621062 | F18: 0 | G18: 3.0564832e-06 | H18: 0.055580264 | I18: 0.0020902395 | J18: 0.00023484438 | K18: 0 | L18: 0.00023425495 | M18: 5.8942838e-07 | N18: 0.15061756 | O18: 0.11644547 | P18: 0 | Q18: 0.00023731143 | R18: 0.055580853 | S18: 0.029654006 | T18: 0.25354253 | U18: 0.21445804 | V18: 0 | W18: 0 | X18: 0.10320599 | Y18: 1.6640528e-05 | Z18: 0.00043707538 | AA18: 0 | AB18: 0.00043597838 | AC18: 1.0970015e-06 | AD18: 0.25355917 | AE18: 0.21489512 | AF18: 0 | AG18: 0.00043597838 | AH18: 0.10320708 | AI18: 0.055254653
B19: 4 | C19: Credit institutions | D19: 0.12977542 | E19: 0.0031242441 | F19: 0 | G19: 0 | H19: 0.00029218365 | I19: 0.00020529592 | J19: 0 | K19: 0 | L19: 0 | M19: 0 | N19: 0.12998072 | O19: 0.0031242441 | P19: 0 | Q19: 0 | R19: 0.00029218365 | S19: 0.002963488 | T19: 0.24821162 | U19: 0.0016245511 | V19: 0 | W19: 0 | X19: 0.00079531412 | Y19: 0.0002274792 | Z19: 0 | AA19: 0 | AB19: 0 | AC19: 0 | AD19: 0.2484391 | AE19: 0.0016245511 | AF19: 0 | AG19: 0 | AH19: 0.00079531412 | AI19: 0.0037752854
B20: 5 | C20: Other financial corporations | D20: 0.15060937 | E20: 0.12876677 | F20: 0 | G20: 3.395849e-06 | H20: 0.061718982 | I20: 0.0022995276 | J20: 0 | K20: 0 | L20: -6.5487349e-07 | M20: 6.5487349e-07 | N20: 0.1529089 | O20: 0.12876677 | P20: 0 | Q20: 2.7409755e-06 | R20: 0.061719636 | S20: 0.026690518 | T20: 0.25393347 | U20: 0.23006638 | V20: 0 | W20: 0 | X20: 0.11071637 | Y20: 1.1784851e-06 | Z20: 0 | AA20: 0 | AB20: -1.1774511e-06 | AC20: 1.1774511e-06 | AD20: 0.25393465 | AE20: 0.23006638 | AF20: 0 | AG20: -1.1774511e-06 | AH20: 0.11071754 | AI20: 0.051479368
B21: 6 | C21: of which investment firms | D21: 0.33268714 | E21: 0.30368396 | F21: 0 | G21: 0 | H21: 0.14624735 | I21: 0 | J21: 0 | K21: 0 | L21: 0 | M21: 0 | N21: 0.33268714 | O21: 0.30368396 | P21: 0 | Q21: 0 | R21: 0.14624735 | S21: 0.011235416 | T21: 0.44025989 | U21: 0.40187867 | V21: 0 | W21: 0 | X21: 0.19353572 | Y21: 0 | Z21: 0 | AA21: 0 | AB21: 0 | AC21: 0 | AD21: 0.44025989 | AE21: 0.40187867 | AF21: 0 | AG21: 0 | AH21: 0.19353572 | AI21: 0.029442702
B22: 7 | C22: of which management companies | D22: 0.040243797 | E22: 0 | F22: 0 | G22: 0 | H22: 0 | I22: 5.5186898e-07 | J22: 0 | K22: 0 | L22: 0 | M22: 0 | N22: 0.040244349 | O22: 0 | P22: 0 | Q22: 0 | R22: 0 | S22: 0.00010153767 | T22: 0.10294746 | U22: 0 | V22: 0 | W22: 0 | X22: 0 | Y22: 0 | Z22: 0 | AA22: 0 | AB22: 0 | AC22: 0 | AD22: 0.10294746 | AE22: 0 | AF22: 0 | AG22: 0 | AH22: 0 | AI22: 6.5763073e-05
B23: 8 | C23: of which insurance undertakings | D23: 0.20670743 | E23: 0.013083099 | F23: 0 | G23: 0 | H23: 0 | I23: 0.0673611 | J23: 0 | K23: 0 | L23: 0 | M23: 0 | N23: 0.27406853 | O23: 0.013083099 | P23: 0 | Q23: 0 | R23: 0 | S23: 0.00090963511 | T23: 0.18809679 | U23: 3.1562053e-05 | V23: 0 | W23: 0 | X23: 0 | Y23: 4.8048796e-07 | Z23: 0 | AA23: 0 | AB23: 0 | AC23: 0 | AD23: 0.18809727 | AE23: 3.1562053e-05 | AF23: 0 | AG23: 0 | AH23: 0 | AI23: 0.00011078739
B24: 9 | C24: Non-financial corporations subject to NFRD disclosure obligations | D24: 0.19788692 | E24: 0.10239937 | F24: 0 | G24: 8.3547539e-05 | H24: 0.092334661 | I24: 0.0079281664 | J24: 0 | K24: 0 | L24: -0.00020628299 | M24: 0.00020628299 | N24: 0.20581508 | O24: 0.10239937 | P24: 0 | Q24: -0.00012273545 | R24: 0.092540944 | S24: 0.036717147 | T24: 0.18098569 | U24: 0.11087504 | V24: 0 | W24: 3.2126724e-05 | X24: 0.10296135 | Y24: 0.0054524443 | Z24: 0 | AA24: 0 | AB24: -0.00024926811 | AC24: 0.00024926811 | AD24: 0.18643814 | AE24: 0.11087504 | AF24: 0 | AG24: -0.00021714139 | AH24: 0.10321061 | AI24: 0.10286373
B25: 10 | C25: Households | D25: 0.13145749 | E25: 0.043013963 | F25: 0 | G25: 0.00024869871 | H25: 0 | N25: 0.13145749 | O25: 0.043013963 | P25: 0 | Q25: 0.00024869871 | R25: 0 | S25: 0.44922905 | T25: 0.13881472 | U25: 0.027353731 | V25: 0 | W25: 0.00069739612 | X25: 0 | AD25: 0.13881472 | AE25: 0.027353731 | AF25: 0 | AG25: 0.00069739612 | AH25: 0 | AI25: 0.29623596
B26: 11 | C26: of which loans collateralised by residential immovable property | D26: 0.14492108 | E26: 0.047256576 | F26: 0 | G26: 0 | H26: 0 | N26: 0.14492108 | O26: 0.047256576 | P26: 0 | Q26: 0 | R26: 0 | S26: 0.40649129 | T26: 0.16027756 | U26: 0.030965486 | V26: 0 | W26: 0 | X26: 0 | AD26: 0.16027756 | AE26: 0.030965486 | AF26: 0 | AG26: 0 | AH26: 0 | AI26: 0.25501182
B27: 12 | C27: of which building renovation loans | D27: #DIV/0! | E27: #DIV/0! | F27: #DIV/0! | G27: #DIV/0! | H27: #DIV/0! | N27: #DIV/0! | O27: #DIV/0! | P27: #DIV/0! | Q27: #DIV/0! | R27: #DIV/0! | S27: 0 | T27: #DIV/0! | U27: #DIV/0! | V27: #DIV/0! | W27: #DIV/0! | X27: #DIV/0! | AD27: #DIV/0! | AE27: #DIV/0! | AF27: #DIV/0! | AG27: #DIV/0! | AH27: #DIV/0! | AI27: 0
B28: 13 | C28: of which motor vehicle loans | D28: 1 | E28: 1 | F28: 0 | G28: 1 | H28: 0 | N28: 1 | O28: 1 | P28: 0 | Q28: 1 | R28: 0 | S28: 0.00011172268 | T28: 1 | U28: 1 | V28: 0 | W28: 1 | X28: 0 | AD28: 1 | AE28: 1 | AF28: 0 | AG28: 1 | AH28: 0 | AI28: 0.00020659381
B29: 14 | C29: Local government financing | D29: 0 | E29: 0 | F29: 0 | G29: 0 | H29: 0 | N29: 0 | O29: 0 | P29: 0 | Q29: 0 | R29: 0 | S29: 0.016012229 | T29: 0 | U29: 0 | V29: 0 | W29: 0 | X29: 0 | AD29: 0 | AE29: 0 | AF29: 0 | AG29: 0 | AH29: 0 | AI29: 0.0074536385
B30: 15 | C30: Housing financing | D30: 0 | E30: 0 | F30: 0 | G30: 0 | H30: 0 | N30: 0 | O30: 0 | P30: 0 | Q30: 0 | R30: 0 | S30: 0 | T30: 0 | U30: 0 | V30: 0 | W30: 0 | X30: 0 | AD30: 0 | AE30: 0 | AF30: 0 | AG30: 0 | AH30: 0 | AI30: 0
B31: 16 | C31: Other local governments financing | D31: 0 | E31: 0 | F31: 0 | G31: 0 | H31: 0 | I31: 0 | J31: 0 | K31: 0 | L31: 0 | M31: 0 | N31: 0 | O31: 0 | P31: 0 | Q31: 0 | R31: 0 | S31: 0.016012229 | T31: 0 | U31: 0 | V31: 0 | W31: 0 | X31: 0 | Y31: 0 | Z31: 0 | AA31: 0 | AB31: 0 | AC31: 0 | AD31: 0 | AE31: 0 | AF31: 0 | AG31: 0 | AH31: 0 | AI31: 0.0074536385
B32: 17 | C32: Collateral obtained by taking possession: residential and commercial immovable properties | D32: 0 | E32: 0 | F32: 0 | G32: 0 | H32: 0 | N32: 0 | O32: 0 | P32: 0 | Q32: 0 | R32: 0 | S32: 0.00084733315 | T32: 0 | U32: 0 | V32: 0 | W32: 0 | X32: 0 | AD32: 0 | AE32: 0 | AF32: 0 | AG32: 0 | AH32: 0 | AI32: 6.5278771e-05

Sheet Input Dez24_tat - Temp 8
B8: Template 8 - GAR (%)
D10: a | E10: b | F10: c | G10: d | H10: e | I10: f | J10: g | K10: h | L10: i | M10: j | N10: k | O10: l | P10: m | Q10: n | R10: o | S10: p | T10: q | U10: r | V10: s | W10: t | X10: u | Y10: v | Z10: w | AA10: x | AB10: y | AC10: z | AD10: aa | AE10: ab | AF10: ac | AG10: ad | AH10: ae | AI10: af
D11: Disclosure reference date T: KPIs on stock | T11: Disclosure reference date T: KPIs on flows
D12: Climate Change Mitigation (CCM) | I12: Climate Change Adaptation (CCA) | N12: TOTAL (CCM + CCA) | T12: Climate Change Mitigation (CCM) | Y12: Climate Change Adaptation (CCA) | AD12: TOTAL (CCM + CCA)
D13: Proportion of eligible assets funding taxonomy relevant sectors | I13: Proportion of eligible assets funding taxonomy relevant sectors | N13: Proportion of eligible assets funding taxonomy relevant sectors | S13: Proportion of total assets covered | T13: Proportion of new eligible assets funding taxonomy relevant sectors | Y13: Proportion of new eligible assets funding taxonomy relevant sectors | AD13: Proportion of new eligible assets funding taxonomy relevant sectors | AI13: Proportion of total new assets covered
E14: Of which environmentally sustainable | J14: Of which environmentally sustainable | O14: Of which environmentally sustainable | U14: Of which environmentally sustainable | Z14: Of which environmentally sustainable | AE14: Of which environmentally sustainable
C15: % (compared to total covered assets in the denominator) | F15: Of which specialised lending | G15: Of which transitional | H15: Of which enabling | K15: Of which specialised lending | L15: Of which adaptation | M15: Of which enabling | P15: Of which specialised lending | Q15: Of which transitional/adaptation | R15: Of which enabling | V15: Of which specialised lending | W15: Of which transitional | X15: Of which enabling | AA15: Of which specialised lending | AB15: Of which adaptation | AC15: Of which enabling | AF15: Of which specialised lending | AG15: Of which transitional/adaptation | AH15: Of which enabling
B16: 1 | C16: GAR | D16: 0.51025877 | E16: 0.041475952 | F16: 0 | G16: 0.0001529321 | H16: 0.0065668362 | I16: 0 | J16: 0 | K16: 0 | L16: 0 | M16: 0 | N16: 0.51025877 | O16: 0.041475952 | P16: 0 | Q16: 0.0001529321 | R16: 0.0065668362 | S16: 0.53245883 | T16: 0.35504887 | U16: 0.052277306 | V16: 0 | W16: 0.00028864501 | X16: 0.022406375 | Y16: 0 | Z16: 0 | AA16: 0 | AB16: 0 | AC16: 0 | AD16: 0.35504887 | AE16: 0.052277306 | AF16: 0 | AG16: 0.00028864501 | AH16: 0.022406375 | AI16: 0.46221054
B17: 2 | C17: Loans and advances. debt securities and equity instruments not HfT eligible for GAR calculation | D17: 0.71660368 | E17: 0.058248524 | F17: 0 | G17: 0.00021477672 | H17: 0.0092224167 | I17: 0 | J17: 0 | K17: 0 | L17: 0 | M17: 0 | N17: 0.71660368 | O17: 0.058248524 | P17: 0 | Q17: 0.00021477672 | R17: 0.0092224167 | S17: 0.53161149 | T17: 0.55907764 | U17: 0.082318452 | V17: 0 | W17: 0.00045451481 | X17: 0.035282195 | Y17: 0 | Z17: 0 | AA17: 0 | AB17: 0 | AC17: 0 | AD17: 0.55907764 | AE17: 0.082318452 | AF17: 0 | AG17: 0.00045451481 | AH17: 0.035282195 | AI17: 0.46151854
B18: 3 | C18: Financial corporations | D18: 0.26940999 | E18: 0.11636023 | F18: 0 | G18: 0 | H18: 0.055453486 | I18: 0 | J18: 0 | K18: 0 | L18: 0 | M18: 0 | N18: 0.26940999 | O18: 0.11636023 | P18: 0 | Q18: 0 | R18: 0.055453486 | S18: 0.029653951 | T18: 0.27574116 | U18: 0.2149337 | V18: 0 | W18: 0 | X18: 0.103206 | Y18: 0 | Z18: 0 | AA18: 0 | AB18: 0 | AC18: 0 | AD18: 0.27574116 | AE18: 0.2149337 | AF18: 0 | AG18: 0 | AH18: 0.103206 | AI18: 0.055220018
B19: 4 | C19: Credit institutions | D19: 0.1784066 | E19: 0.006384521 | F19: 0 | G19: 0 | H19: 0.00029218691 | I19: 0 | J19: 0 | K19: 0 | L19: 0 | M19: 0 | N19: 0.1784066 | O19: 0.006384521 | P19: 0 | Q19: 0 | R19: 0.00029218691 | S19: 0.0029634829 | T19: 0.35197617 | U19: 0.0085858461 | V19: 0 | W19: 0 | X19: 0.00079531795 | Y19: 0 | Z19: 0 | AA19: 0 | AB19: 0 | AC19: 0 | AD19: 0.35197617 | AE19: 0.0085858461 | AF19: 0 | AG19: 0 | AH19: 0.00079531795 | AI19: 0.0037729193
B20: 5 | C20: Other financial corporations | D20: 0.27951423 | E20: 0.128571 | F20: 0 | G20: 0 | H20: 0.061578128 | I20: 0 | J20: 0 | K20: 0 | L20: 0 | M20: 0 | N20: 0.27951423 | O20: 0.128571 | P20: 0 | Q20: 0 | R20: 0.061578128 | S20: 0.026690468 | T20: 0.2701504 | U20: 0.2300664 | V20: 0 | W20: 0 | X20: 0.11071638 | Y20: 0 | Z20: 0 | AA20: 0 | AB20: 0 | AC20: 0 | AD20: 0.2701504 | AE20: 0.2300664 | AF20: 0 | AG20: 0 | AH20: 0.11071638 | AI20: 0.051447098
B21: 6 | C21: of which investment firms | D21: 0.46216161 | E21: 0.28303238 | F21: 0 | G21: 0 | H21: 0.13630202 | I21: 0 | J21: 0 | K21: 0 | L21: 0 | M21: 0 | N21: 0.46216161 | O21: 0.28303238 | P21: 0 | Q21: 0 | R21: 0.13630202 | S21: 0.012055192 | T21: 0.44839342 | U21: 0.40187874 | V21: 0 | W21: 0 | X21: 0.19353575 | Y21: 0 | Z21: 0 | AA21: 0 | AB21: 0 | AC21: 0 | AD21: 0.44839342 | AE21: 0.40187874 | AF21: 0 | AG21: 0 | AH21: 0.19353575 | AI21: 0.029424244
