Workbook
Name asefadf: #REF!
Name asefadf: #REF!
Name bn: #REF!
Name bn: #REF!

Sheet Plano
E1: =SUM(F1:W1) -> 144 | F1: =F4*8 -> 8 | G1: =G4*8 -> 8 | H1: =H4*8 -> 8 | I1: =I4*8 -> 8 | J1: =J4*8 -> 8 | K1: =K4*8 -> 8 | L1: =L4*8 -> 8 | M1: =M4*8 -> 8 | ... CG1: =CG4*8 -> 16
E2: VAL | F2: =F3-F4 -> 0 | G2: =G3-G4 -> 0 | H2: =H3-H4 -> 0 | I2: =I3-I4 -> 0 | J2: =J3-J4 -> 0 | K2: =K3-K4 -> 0 | L2: =L3-L4 -> 0 | M2: =M3-M4 -> 0 | ... CG2: =CG3-CG4 -> -2
B3: Semanas | C3: =ROUND(#REF!/8/5,1) -> #REF! | E3: FTE REAIS | F3: =SUM(F10:F44) -> 1 | G3: =SUM(G10:G44) -> 1 | H3: =SUM(H10:H44) -> 1 | I3: =SUM(I10:I44) -> 1 | J3: =SUM(J10:J44) -> 1 | K3: =SUM(K10:K44) -> 1 | L3: =SUM(L10:L44) -> 1 | M3: =SUM(M10:M44) -> 1 | ... CG3: =SUM(CG10:CG44) -> 0
B4: Meses | C4: =C3/4 -> #REF! | E4: FTE ESP. | F4: 1 | G4: 1 | H4: 1 | I4: 1 | J4: 1 | K4: 1 | L4: 1 | M4: 1 | N4: 1 | O4: 1 | P4: 1 | Q4: 1 | R4: 1 | S4: 1 | T4: 1 | U4: 1 | V4: 1 | W4: 1 | X4: 1 | Y4: 1 | Z4: 1 | AA4: 1 | AB4: 1 | AC4: 1 | AD4: 1 | AE4: 1 | AF4: 1 | AG4: 1 | AH4: 1 | AI4: 1 | AJ4: 2 | AK4: 2 | AL4: 2 | AM4: 2 | AN4: 2 | AO4: 1 | AP4: 2 | AQ4: 2 | AR4: 2 | AS4: 2 | AT4: 2 | AU4: 2 | AV4: 2 | AW4: 2 | AX4: 2 | AY4: 2 | AZ4: 2 | BA4: 2 | BB4: 2 | BC4: 2 | BD4: 2 | BE4: 2 | BF4: 2 | BG4: 2 | BH4: 2 | BI4: 2 | BJ4: 2 | BK4: 2 | BL4: 2 | BM4: 2 | BN4: 2 | BO4: 2 | BP4: 2 | BQ4: 2 | BR4: 2 | BS4: 2 | BT4: 2 | BU4: 2 | BV4: 2 | BW4: 2 | BX4: 2 | BY4: 2 | BZ4: 2 | CA4: 2 | CB4: 2 | CC4: 2 | CD4: 2 | CE4: 2 | CF4: 2 | CG4: 2
B5: Meses p/ 2 FTE's | C5: =C4/2 -> #REF!
E6: 45657 | F6: =WORKDAY(E6,1) -> 45658 | G6: =WORKDAY(F6,1) -> 45659 | H6: =WORKDAY(G6,1) -> 45660 | I6: 4 | J6: =WORKDAY(I6,1) -> 5 | K6: =WORKDAY(J6,1) -> 6 | L6: =WORKDAY(K6,1) -> 9 | M6: =WORKDAY(L6,1) -> 10 | N6: =WORKDAY(M6,1) -> 11 | O6: =WORKDAY(N6,1) -> 12 | P6: =WORKDAY(O6,1) -> 13 | Q6: =WORKDAY(P6,1) -> 16 | ... T6: =WORKDAY(S6,1) -> 19
C7: Duração (horas) | D7: Duração (Dias) | E7: VAL | F7: Semana 1 | K7: Semana 2 | P7: Semana 3 | U7: Semana 4 | Z7: Semana 5 | AE7: Semana 6 | AJ7: Semana 7 | AO7: Semana 8 | AT7: Semana 9 | AY7: Semana 10 | BD7: Semana 11 | BI7: Semana 12 | BN7: Semana 13 | BS7: Semana 14 | BX7: Semana 15 | CC7: Semana 16
C8: =C11+C18+C25+C39+#REF!+C33 -> #REF! | D8: =D11+D18+D25+D39+#REF!+D33 -> #REF! | F8: 1 | G8: =F8+1 -> 2 | H8: =G8+1 -> 3 | I8: =H8+1 -> 4 | J8: =I8+1 -> 5 | K8: =J8+1 -> 6 | L8: =K8+1 -> 7 | M8: =L8+1 -> 8 | N8: =M8+1 -> 9 | ... CG8: =CF8+1 -> 80
B9: Gestão Projeto | C9: =D9*8*5 -> 0 | D9: =SUM(F9:I9) -> 0
B10: Gestão Projeto
B11: Preparação dos satélites | C11: 80 | D11: =C11/8 -> 10
B12: Adjudicados | C12: 12 | D12: =C12/8 -> 1.5 | E12: =SUM(F12:CG12)-D12 -> 0 | F12: 1 | G12: 0.5
B13: Gloval - Informação no Modelo de Bens Imóveis | C13: 16 | D13: =C13/8 -> 2 | E13: =SUM(F13:CG13)-D13 -> 0 | G13: 0.5 | H13: 1 | I13: 0.5
B14: Universo Corporativo (IDCOMBs) | C14: 16 | D14: =C14/8 -> 2 | E14: =SUM(F14:CG14)-D14 -> 0 | I14: 0.5 | J14: 1 | K14: 0.5
B15: Métricas Contratos & Clientes | C15: 12 | D15: =C15/8 -> 1.5 | E15: =SUM(F15:CG15)-D15 -> 0 | K15: 0.5 | L15: 1
B16: Métricas Colaterais | C16: 8 | D16: =C16/8 -> 1 | E16: =SUM(F16:CG16)-D16 -> 0 | M16: 1
B17: Repartição de Garantias | C17: 16 | D17: =C17/8 -> 2 | E17: =SUM(F17:CG17)-D17 -> 0 | N17: 1 | O17: 1
B18: Geração dos Satélites Corporativos | C18: 248 | D18: =C18/8 -> 31
B19: Satélite 79 | C19: 22 | D19: =C19/8 -> 2.75 | E19: =SUM(F19:CG19)-D19 -> 0 | P19: 1 | Q19: 1 | R19: 0.75
B20: Satélite 80 (Gran) | C20: 21 | D20: =C20/8 -> 2.625 | E20: =SUM(F20:CG20)-D20 -> 0 | R20: 0.25 | S20: 1 | T20: 1 | U20: 0.375
B21: Satélite 83 (Gran) | C21: 24 | D21: =C21/8 -> 3 | E21: =SUM(F21:CG21)-D21 -> 0 | U21: 0.625 | V21: 1 | W21: 1 | X21: 0.375
B22: Satélite 84 (Gran) | C22: 71 | D22: =C22/8 -> 8.875 | E22: =SUM(F22:CG22)-D22 -> 0 | X22: 0.625 | Y22: 1 | Z22: 1 | AA22: 1 | AB22: 1 | AC22: 1 | AD22: 1 | AE22: 1 | AF22: 1 | AG22: 0.25
B23: Satélite 93 (Gran) | C23: 110 | D23: =C23/8 -> 13.75 | E23: =SUM(F23:CG23)-D23 -> 0 | AG23: 0.75 | AH23: 1 | AI23: 1 | AJ23: 2 | AK23: 2 | AL23: 2 | AM23: 2 | AN23: 2 | AO23: 1
B24: Buffer | C24: =D24*8 -> 352 | D24: 44 | E24: =SUM(F24:CG24)-D24 -> -4.75 | AP24: 2 | AQ24: 2 | AR24: 2 | AS24: 2 | AT24: 2 | AU24: 2 | AV24: 2 | AW24: 2 | AX24: 2 | AY24: 2 | AZ24: 2 | BA24: 2 | BB24: 2 | BC24: 2 | BD24: 2 | BE24: 2 | BF24: 2 | BG24: 2 | BH24: 2 | BI24: 1.25
B25: Validação & testes & Correções | C25: 140 | D25: =C25/8 -> 17.5
B26: Satélite 79 | C26: 12 | D26: =C26/8 -> 1.5 | E26: =SUM(F26:CG26)-D26 -> 0 | BI26: 0.75 | BJ26: 0.75
B27: Satélite 80 (Gran) | C27: 16 | D27: =C27/8 -> 2 | E27: =SUM(F27:CG27)-D27 -> 0 | BJ27: 1.25 | BK27: 0.75
B28: Satélite 83 (Gran) | C28: 16 | D28: =C28/8 -> 2 | E28: =SUM(F28:CG28)-D28 -> 0 | BK28: 1.25 | BL28: 0.75
B29: Satélite 84 (Gran) | C29: 16 | D29: =C29/8 -> 2 | E29: =SUM(F29:CG29)-D29 -> 0 | BL29: 1.25 | BM29: 0.75
B30: Satélite 93 (Gran) | C30: 80 | D30: =C30/8 -> 10 | E30: =SUM(F30:CG30)-D30 -> 0 | BM30: 1.25 | BN30: 2 | BO30: 2 | BP30: 2 | BQ30: 2 | BR30: 0.75
B31: re-testes
B32: Paralelo Dez24 & idnetificação de casuísticas + buffer | C32: 50 | D32: =C32/8 -> 6.25 | E32: =SUM(F32:CG32)-D32 -> 0 | BR32: 1.25 | BS32: 2 | BT32: 2 | BU32: 1
B33: Documentação | C33: 40 | D33: =C33/8 -> 5
B34: Satélite 79 | C34: 8 | D34: =C34/8 -> 1 | E34: =SUM(F34:CG34)-D34 -> 0 | BU34: 1
B35: Satélite 80 (Gran) | C35: 8 | D35: =C35/8 -> 1 | E35: =SUM(F35:CG35)-D35 -> 0 | BV35: 1
B36: Satélite 83 (Gran) | C36: 8 | D36: =C36/8 -> 1 | E36: =SUM(F36:CG36)-D36 -> 0 | BV36: 1
B37: Satélite 84 (Gran) | C37: 8 | D37: =C37/8 -> 1 | E37: =SUM(F37:CG37)-D37 -> 0 | BW37: 1
B38: Satélite 93 (Gran) | C38: 8 | D38: =C38/8 -> 1 | E38: =SUM(F38:CG38)-D38 -> 0 | BW38: 1
B39: Reporte de Jun24 & Conciliações Contabilisticas | C39: 68 | D39: =C39/8 -> 8.5 | E39: =SUM(F39:CG39)-D39 -> -8.5
B40: Satélite 79 | C40: 8 | D40: =C40/8 -> 1 | E40: =SUM(F40:CG40)-D40 -> 0 | BX40: 1
...

Sheet Sheet1
G1: Considerando férias + passagem de conhecimento
B2: Satélite / Template | C2: Deadline s/ paralelo + s/adjudicados | D2: Deadline s/adjudicados - cliente | E2: Ownership | G2: Satélite / Template | H2: Deadline s/ paralelo + s/adjudicados | I2: Deadline s/adjudicados - cliente | J2: Ownership
B3: Satélite 79 | C3: 45763 | E3: HC / RC | G3: Satélite 79 | H3: 45764 | J3: HC / RC
B4: Satélite 80 | C4: 45771 | E4: HC / RC | G4: STE 2 | H4: 45769 | J4: JG / RC
B5: Satélite 83 | C5: 45784 | E5: HC / RC | G5: Satélite 80 | H5: 45770 | J5: HC / RC
B6: Satélite 84 | C6: 45793 | E6: HC / RC | G6: Template 2 | H6: 45775 | J6: JG / RC
B7: Satélite 93 | C7: 45805 | E7: HC / RC | G7: Template 5 | H7: 45782 | J7: JG / RC
B8: Satelite 109 | C8: 45814 | E8: HC / RC | G8: Satélite 84 | H8: 45793 | J8: HF / RC
B9: Template 1 | C9: 45819 | E9: JG / RC | G9: Satélite 83 | H9: 45800 | J9: PN / RC
B10: Template 2 | C10: 45771 | E10: JG / RC | G10: Template 6,7,8,9 | H10: 45793 | J10: JG / RC
B11: Template 4 | C11: 45807 | E11: JG / RC | G11: Satélite 93 | H11: 45807 | J11: HF / RC
B12: Template 5 | C12: 45784 | E12: JG / RC | G12: Template 4 | H12: 45800 | J12: JG / RC
B13: Template 6,7,8,9 | C13: 45800 | E13: JG / RC | G13: Satelite 109 | H13: 45814 | J13: HF / PN / RC
B14: Template 10 | C14: 45835 | E14: JG / RC | G14: Template 1 | H14: 45807 | J14: JG / RC
... B16: STE 2 | C16: 45763 | E16: JG / RC | G16: Template 10 | H16: 45828 | J16: JG / RC

Sheet Plan- Granular
B2: Atividades Propostas
F4: Total (h)
B6: Preparação dos satélites | F6: =SUM(F7:F12) -> 80 | G6: =F6/8 -> 10
B7: Adjudicados | F7: =8*1.5 -> 12
B8: Gloval - Informação no Modelo de Bens Imóveis | F8: =8*2 -> 16 | G8: c/Buffer
B9: Universo Corporativo (IDCOMBs) | F9: =8*2 -> 16
B10: Métricas Contratos & Clientes | F10: =8*1.5 -> 12 | G10: Conseguimos adaptar esta informação, existe muita info que está no MBI
B11: Métricas Colaterais | F11: 8 | G11: Conseguimos adaptar esta informação, existe muita info que está no MBI
B12: Repartição de Garantias | F12: =8*2 -> 16 | G12: Incerto se conseguimos capitalizar
B13: Implementação dos Satélites Corporativos | F13: =F14+F29+F40+F52+F104 -> 248 | G13: =F13/8 -> 31
B14: Satélite 79 | F14: =SUM(F15:F28) -> 22
B15: informing_soc | E15: Baixa | F15: =HLOOKUP(E15,'Matriz de horas'!$E$4:$G$5,2,0) -> 1
B16: counterparty_soc | E16: Baixa | F16: =HLOOKUP(E16,'Matriz de horas'!$E$4:$G$5,2,0) -> 1
B17: adjustment_code | E17: Baixa | F17: =HLOOKUP(E17,'Matriz de horas'!$E$4:$G$5,2,0) -> 1
B18: ccontab_final_idcomb_total (IDCOMB Contabilistico) | E18: Baixa | F18: =HLOOKUP(E18,'Matriz de horas'!$E$4:$G$5,2,0) -> 1
B19: invstmnt_sctr | E19: Baixa | F19: =HLOOKUP(E19,'Matriz de horas'!$E$4:$G$5,2,0) -> 1
B20: flg_excldd_eu_prs_cntrct | E20: Baixa | F20: =HLOOKUP(E20,'Matriz de horas'!$E$4:$G$5,2,0) -> 1
B21: mtrty_esg | E21: Média | F21: =HLOOKUP(E21,'Matriz de horas'!$E$4:$G$5,2,0) -> 3
B22: erpn_unn | E22: Baixa | F22: =HLOOKUP(E22,'Matriz de horas'!$E$4:$G$5,2,0) -> 1
B23: flg_chrnc_physcl_rsk_cntrct | E23: Média | F23: =HLOOKUP(E23,'Matriz de horas'!$E$4:$G$5,2,0) -> 3
B24: flg_act_physcl_rsk_cntrct | E24: Média | F24: =HLOOKUP(E24,'Matriz de horas'!$E$4:$G$5,2,0) -> 3
B25: phscl_rsk_ggrph | E25: Baixa | F25: =HLOOKUP(E25,'Matriz de horas'!$E$4:$G$5,2,0) -> 1
B26: cnael_cntrct | E26: Baixa | F26: =HLOOKUP(E26,'Matriz de horas'!$E$4:$G$5,2,0) -> 1
... B28: exposition | E28: Média | F28: =HLOOKUP(E28,'Matriz de horas'!$E$4:$G$5,2,0) -> 3
B29: Satélite 80 (Gran) | F29: =SUM(F30:F39) -> 21
B30: informing_soc | E30: Baixa | F30: =HLOOKUP(E30,'Matriz de horas'!$E$4:$G$5,2,0) -> 1
B31: counterparty_soc | E31: Baixa | F31: =HLOOKUP(E31,'Matriz de horas'!$E$4:$G$5,2,0) -> 1
B32: adjustment_code | E32: Baixa | F32: =HLOOKUP(E32,'Matriz de horas'!$E$4:$G$5,2,0) -> 1
B33: ccontab_final_idcomb_total | E33: Baixa | F33: =HLOOKUP(E33,'Matriz de horas'!$E$4:$G$5,2,0) -> 1
B34: typ_ep_scr | E34: Média | F34: =HLOOKUP(E34,'Matriz de horas'!$E$4:$G$5,2,0) -> 3
B35: ep_scr | E35: Média | F35: =HLOOKUP(E35,'Matriz de horas'!$E$4:$G$5,2,0) -> 3
B36: typ_epc_lbl | E36: Média | F36: =HLOOKUP(E36,'Matriz de horas'!$E$4:$G$5,2,0) -> 3
B37: epc_lbl | E37: Média | F37: =HLOOKUP(E37,'Matriz de horas'!$E$4:$G$5,2,0) -> 3
B38: exposition | E38: Alta | F38: =HLOOKUP(E38,'Matriz de horas'!$E$4:$G$5,2,0) -> 4
B39: erpn_unn | E39: Baixa | F39: =HLOOKUP(E39,'Matriz de horas'!$E$4:$G$5,2,0) -> 1
B40: Satélite 83 (Gran) | F40: =SUM(F41:F51) -> 24
B41: informing_soc | E41: Baixa | F41: =HLOOKUP(E41,'Matriz de horas'!$E$4:$G$5,2,0) -> 1
B42: counterparty_soc | E42: Baixa | F42: =HLOOKUP(E42,'Matriz de horas'!$E$4:$G$5,2,0) -> 1
B43: adjustment_code | E43: Baixa | F43: =HLOOKUP(E43,'Matriz de horas'!$E$4:$G$5,2,0) -> 1
B44: ccontab_final_idcomb_total | E44: Baixa | F44: =HLOOKUP(E44,'Matriz de horas'!$E$4:$G$5,2,0) -> 1
...

Sheet Matriz de horas
B2: Tipologia de testes
D3: Estimação Horas
B4: Categorização de Testes | C4: Descrição | D4: n.a. | E4: Baixa | F4: Média | G4: Alta
B5: Geração | C5: Simulação da especificação funcional. Suplementarmente, realizar reuniões de validações e esclarecimentos funcionais junto do negócio/owner. | D5: 0 | E5: 1 | F5: 3 | G5: 4
B6: Testes | C6: A partir da simulação realizada, comparar resultados com a implementação de IT. | D6: 0 | E6: 3 | F6: 6 | G6: 8
B7: Identificação de casuísticas | C7: Identificar casuísticas dos paralelos | D7: 0 | E7: 20 | F7: 40 | G7: 60 | H7: =F7/8 -> 5
B8: Re-testes | C8: % dos testes | D8: 0 | E8: 0.3 | F8: 0.3 | G8: 0.3
B10: Pressupostos
B11: Serão realizados testes regressivos semanalmente (com base em reprocessamentos sobre as várias entregas)
B12: Assume-se que 20% dos campos entregues terão incidências/re-especificações de pequenos ajustos e devem ser re-implementados
