Workbook
Name Destino.tipoEscrita.modo: Tabela!$AC$65
Name Destino.volumetria.pre.mediaRegistos: Tabela!$AR$73
Name Destino.volumetria.pre.tamanhoRegisto: Tabela!$AD$73
Name FonteDados.ambientePre: #REF!
Name Governo.basedados: Tabela!$O$27
Name Governo.descricao: Tabela!$C$33
Name Governo.granularidade: Tabela!$R$37
Name Governo.granularidadeOutro: Tabela!$AB$37
Name Governo.isCloud: Tabela!$J$28
Name Governo.isOnPrem: Tabela!$D$28
Name Governo.periodicidade: Tabela!$AL$37
Name Governo.periodicidadeOutro: Tabela!$AV$37
Name Governo.tabela: Tabela!$AI$27
Name Governo.uso: Tabela!$C$37
Name Housekeeping.pre.campo: Tabela!$O$43
Name Housekeeping.pre.dias: Tabela!$I$43
Name Housekeeping.pre.expurgo: Tabela!$E$43
Name Housekeeping.pre.meses: Tabela!$O$46
Name Housekeeping.pre.mesesSN: Tabela!$E$46
Name Housekeeping.pro.campo: Tabela!$AR$43
Name Housekeeping.pro.dias: Tabela!$AL$43
Name Housekeeping.pro.expurgo: Tabela!$AH$43
Name Housekeeping.pro.meses: Tabela!$AR$46
Name Housekeeping.pro.mesesSN: Tabela!$AH$46
Name Planificacao.pre.calendario: Tabela!$D$115
Name Planificacao.pre.periodicidade: Tabela!$Q$115
Name ProfundidadeHistorica.pre.campoRetencao: Tabela!$N$93
Name ProfundidadeHistorica.pre.expurgo: Tabela!$D$93
Name ProfundidadeHistorica.pre.justificacao: Tabela!$Z$93
Name ProfundidadeHistorica.pre.manterUltimoDiaMes: Tabela!$D$96
Name ProfundidadeHistorica.pre.offset: Tabela!$H$93
Name ProfundidadeHistorica.pre.recuperacaoHistorico: Tabela!$D$90
Name ProfundidadeHistorica.pre.recuperacaoJustificacao: Tabela!$N$90
Name Solicitante.area: Tabela!$P$19
Name Solicitante.demand: Tabela!$P$20
Name Solicitante.email: Tabela!$P$18
Name Solicitante.nome: Tabela!$P$16
Name Solicitante.projeto: Tabela!$X$20
Name Solicitante.tipoPedido: Tabela!$P$22
Name WG.nomeA: Tabela!$AE$62
Name WG.nomeCDO: Tabela!$AE$56
Name WG.nomeDS: Tabela!$AE$59
Name WG.nomeSA: Tabela!$AE$65
Name WG.preenchidoPor: Tabela!$AE$53
Name WG.validadoA: Tabela!$X$62
Name WG.validadoArq: Tabela!$X$62
Name WG.validadoCDO: Tabela!$X$56
Name WG.validadoDS: Tabela!$X$59
Name WG.validadoSA: Tabela!$X$65

Sheet Tabela
BC1: VA20231003
C7: PEDIDO DE TABELA APLICACIONAL
C9: Este formulário visa a obtenção da informação necessária para dar seguimento à análise, aprovação e execução de pedidos de novas tabelas aplicacionais no datalake. Nesta pestana deverão ser indicada a informação relacionada com a fonte dos dados, o destino, regras de expurgo e informação de governo. Na pestana seguinte deverão ser indicados os campos. | BH9: Múltiplos | BI9: Eliminatórios | BJ9: S/necessidade
C14: SOLICITANTE
C16: Nome do Solicitante | P16: Luís Pragosa
P17: =IF(OR(ISBLANK(Solicitante.nome),EXACT(Solicitante.nome,"Nome de quem faz o pedido")),"*Obrigatório","")
C18: Email do Solicitante | P18: luis.pragosa@servexternos.santander.pt
C19: Área do Solicitante | P19: Reporting Hub
C20: Identificação do Projecto | P20: P2400555 | X20: Automatização Valuation e Bail-in Data set
C22: Tipo de pedido | P22: Alteração de Tabela
C24: GOVERNO | AC24: em caso de dúvida, contactar CDO
C26: Sistema | O26: Base de Dados | AI26: Tabela
O27: cd_captools | AI27: ct003_univ_cli
D28: X | E28: On Premise | K28: Cloud
C30: =IF(AND(ISBLANK(Governo.isOnPrem),ISBLANK(Governo.isCloud)),"*Obrigatório","") | O30: =IF(OR(ISBLANK(Governo.basedados),EXACT(Governo.basedados,"Nome da Base de Dados")),"*Obrigatório","") | AI30: =IF(OR(ISBLANK(Governo.tabela),EXACT(Governo.tabela,"Nome da Tabela")),"*Obrigatório","")
C32: Descrição
C33: Tabela de clientes do universo
C34: =IF(OR(ISBLANK(Governo.descricao),EXACT(Governo.descricao,"Descrição curta da Tabela")),"*Obrigatório","")
C36: Uso (Consultar pestana Usos) | R36: Granularidade | AL36: Periodicidade
C37: Reporte Externo | R37: Cliente | AB37: Especifique a granularidade | AL37: Mensal | AV37: Especifique a periodicidade
C38: =IF(ISBLANK(Governo.uso),"*Obrigatório","") | R38: =IF(ISBLANK(Governo.granularidade),"*Obrigatório","") | AL38: =IF(ISBLANK(Governo.periodicidade),"*Obrigatório","")
C40: HOUSEKEEPING
C42: PRE | E42: Expurgo | I42: Dias de retenção | O42: Campo de retenção | AF42: PRO | AH42: Expurgo | AL42: Dias de retenção | AR42: Campo de retenção
E44: =IF(ISBLANK(Housekeeping.pre.expurgo),"*Obrigatório","") -> *Obrigatório | I44: =IF(AND(EXACT(Housekeeping.pre.expurgo,"Sim"),ISBLANK(Housekeeping.pre.dias)),"*Obrigatório","") | O44: =IF(AND(EXACT(Housekeeping.pre.expurgo,"Sim"),ISBLANK(Housekeeping.pre.campo)),"*Obrigatório","") | AH44: =IF(ISBLANK(Housekeeping.pro.expurgo),"*Obrigatório","") -> *Obrigatório | AL44: =IF(AND(EXACT(Housekeeping.pro.expurgo,"Sim"),ISBLANK(Housekeeping.pro.dias)),"*Obrigatório","") | AR44: =IF(AND(EXACT(Housekeeping.pro.expurgo,"Sim"),ISBLANK(Housekeeping.pro.campo)),"*Obrigatório","")
E45: Manter fim dos meses | O45: Meses de retenção | AH45: Manter fim dos meses | AR45: Meses de retenção
E47: =IF(AND(EXACT(Housekeeping.pre.expurgo,"Sim"),ISBLANK(Housekeeping.pre.mesesSN)),"*Obrigatório","") | O47: =IF(AND(EXACT(Housekeeping.pre.mesesSN,"Sim"),ISBLANK(Housekeeping.pre.meses)),"*Obrigatório","") | AH47: =IF(AND(EXACT(Housekeeping.pro.expurgo,"Sim"),ISBLANK(Housekeeping.pro.mesesSN)),"*Obrigatório","") | AR47: =IF(AND(EXACT(Housekeeping.pro.mesesSN,"Sim"),ISBLANK(Housekeeping.pro.meses)),"*Obrigatório","")
C49: WORKINGGROUP
AD51: Nome | AT51: Data
C52: Preenchido por:
AE53: Luís Pragosa | AU53: 45664
AE54: =IF(ISBLANK(WG.preenchidoPor),"*Obrigatório","")
C55: Este pedido foi validado previamente por CDO?
X56: Sim | AE56: Luís Capitão-Mor | AU56: 45664
X57: =IF(ISBLANK(WG.validadoCDO),"*Obrigatório","") | AE57: =IF(AND(EXACT(WG.validadoCDO,"Sim"),ISBLANK(WG.nomeCDO)),"*Obrigatório","")
C58: Este pedido foi validado previamente por Data Service?
X59: Não
X60: =IF(ISBLANK(WG.validadoDS),"*Obrigatório","") | AE60: =IF(AND(EXACT(WG.validadoDS,"Sim"),ISBLANK(WG.nomeDS)),"*Obrigatório","")
C61: Este pedido foi validado previamente por Arquitetura?
X62: Não
X63: =IF(ISBLANK(WG.validadoA),"*Obrigatório","") | AE63: =IF(AND(EXACT(WG.validadoA,"Sim"),ISBLANK(WG.nomeA)),"*Obrigatório","")
...

Sheet Campos
C1: Em caso de dúvida no preenchimento contactar cdo@santander.pt
B2: # | C2: Campo | D2: Descrição | E2: Dado Base (consultar pestana dado base)
B3: 1 | C3: zcliente | D3: Número de cliente | E3: Identificador interno do cliente | F3: =IF(OR(COUNTIF('Filtro Dado base'!$A$2:$A$176,Campos!E3)>0,ISBLANK(E3)),"","Dado base inválido")
B4: 2 | C4: ccli_grupo | D4: Código de Cliente Grupo | E4: Identificador interno do cliente | F4: =IF(OR(COUNTIF('Filtro Dado base'!$A$2:$A$176,Campos!E4)>0,ISBLANK(E4)),"","Dado base inválido")
B5: 3 | C5: gcliente | D5: Nome do Cliente | E5: Nome | F5: =IF(OR(COUNTIF('Filtro Dado base'!$A$2:$A$176,Campos!E5)>0,ISBLANK(E5)),"","Dado base inválido")
B6: 4 | C6: iex_cliente | D6: Identificador de Ex-Cliente | E6: Identificador de ex-cliente | F6: =IF(OR(COUNTIF('Filtro Dado base'!$A$2:$A$176,Campos!E6)>0,ISBLANK(E6)),"","Dado base inválido")
B7: 5 | C7: cnum_doc_identif2 | D7: Identificador de Pessoa/Empresa | E7: Código de empresa do contrato | F7: =IF(OR(COUNTIF('Filtro Dado base'!$A$2:$A$176,Campos!E7)>0,ISBLANK(E7)),"","Dado base inválido")
B8: 6 | C8: ccae | D8: Código de Atividade Económica | E8: Sector de atividade do cliente (CAE) da pessoa singular ou coletiva | F8: =IF(OR(COUNTIF('Filtro Dado base'!$A$2:$A$176,Campos!E8)>0,ISBLANK(E8)),"","Dado base inválido")
B9: 7 | C9: dnascimento | D9: Data de Nascimento do Cliente | E9: Data de nascimento | F9: =IF(OR(COUNTIF('Filtro Dado base'!$A$2:$A$176,Campos!E9)>0,ISBLANK(E9)),"","Dado base inválido")
B10: 8 | C10: dconstituicao | D10: Data de Constituição do Cliente | E10: Data de constituição | F10: =IF(OR(COUNTIF('Filtro Dado base'!$A$2:$A$176,Campos!E10)>0,ISBLANK(E10)),"","Dado base inválido")
B11: 9 | C11: cnif_resid | D11: Código NIF no país de Residencia | E11: Identificador da pessoa | F11: =IF(OR(COUNTIF('Filtro Dado base'!$A$2:$A$176,Campos!E11)>0,ISBLANK(E11)),"","Dado base inválido")
B12: 10 | C12: ctipo_doc_identif1 | D12: Código do Tipo do Documento de Identificação | E12: Identificador da pessoa | F12: =IF(OR(COUNTIF('Filtro Dado base'!$A$2:$A$176,Campos!E12)>0,ISBLANK(E12)),"","Dado base inválido")
B13: 11 | C13: cnum_doc_identif1 | D13: Número do Documento de Identificação 1 | E13: Identificador da pessoa | F13: =IF(OR(COUNTIF('Filtro Dado base'!$A$2:$A$176,Campos!E13)>0,ISBLANK(E13)),"","Dado base inválido")
B14: 12 | C14: cpais_doc_identif1 | D14: Código do Pais do Documento de Identificação 1 | E14: Identificador da pessoa | F14: =IF(OR(COUNTIF('Filtro Dado base'!$A$2:$A$176,Campos!E14)>0,ISBLANK(E14)),"","Dado base inválido")
... B47: 45 | C47: origem | D47: Indicação de cliente manual ou automático | E47: Indicadores de cliente | F47: =IF(OR(COUNTIF('Filtro Dado base'!$A$2:$A$176,Campos!E47)>0,ISBLANK(E47)),"","Dado base inválido")
B48: 46 | F48: =IF(OR(COUNTIF('Filtro Dado base'!$A$2:$A$176,Campos!E48)>0,ISBLANK(E48)),"","Dado base inválido")
B49: 47 | F49: =IF(OR(COUNTIF('Filtro Dado base'!$A$2:$A$176,Campos!E49)>0,ISBLANK(E49)),"","Dado base inválido")
B50: 48 | F50: =IF(OR(COUNTIF('Filtro Dado base'!$A$2:$A$176,Campos!E50)>0,ISBLANK(E50)),"","Dado base inválido")
B51: 49 | F51: =IF(OR(COUNTIF('Filtro Dado base'!$A$2:$A$176,Campos!E51)>0,ISBLANK(E51)),"","Dado base inválido")
B52: 50 | F52: =IF(OR(COUNTIF('Filtro Dado base'!$A$2:$A$176,Campos!E52)>0,ISBLANK(E52)),"","Dado base inválido")
B53: 51 | F53: =IF(OR(COUNTIF('Filtro Dado base'!$A$2:$A$176,Campos!E53)>0,ISBLANK(E53)),"","Dado base inválido")
B54: 52 | F54: =IF(OR(COUNTIF('Filtro Dado base'!$A$2:$A$176,Campos!E54)>0,ISBLANK(E54)),"","Dado base inválido")
B55: 53 | F55: =IF(OR(COUNTIF('Filtro Dado base'!$A$2:$A$176,Campos!E55)>0,ISBLANK(E55)),"","Dado base inválido")
B56: 54 | F56: =IF(OR(COUNTIF('Filtro Dado base'!$A$2:$A$176,Campos!E56)>0,ISBLANK(E56)),"","Dado base inválido")
B57: 55 | F57: =IF(OR(COUNTIF('Filtro Dado base'!$A$2:$A$176,Campos!E57)>0,ISBLANK(E57)),"","Dado base inválido")
B58: 56 | F58: =IF(OR(COUNTIF('Filtro Dado base'!$A$2:$A$176,Campos!E58)>0,ISBLANK(E58)),"","Dado base inválido")
B59: 57 | F59: =IF(OR(COUNTIF('Filtro Dado base'!$A$2:$A$176,Campos!E59)>0,ISBLANK(E59)),"","Dado base inválido")
... B172: 170 | F172: =IF(OR(COUNTIF('Filtro Dado base'!$A$2:$A$176,Campos!E172)>0,ISBLANK(E172)),"","Dado base inválido")

Sheet Usos
B1: Usos | D1: Exemplos
B2: Comunicação Interna | C2: Comunicação interna geral | D2: Comunicação da informação interna para os funcionários (logística, publicidade, formação, etc.)
C3: Comunicação interna particular | D3: Comunicação interna direcionada para pessoas específicas
C4: Questionários internos | D4: Inquéritos de compromisso, a avaliação dos cursos de formação, etc.
B5: Comunicação Externa | C5: Comunicação pública | D5: Comunicação a imprensa, acionistas, etc.
C6: Comunicação a organismos públicos e reguladores | D6: Comunicação à CNMV e outros órgãos públicos
C7: Questionários de satisfação | D7: Para os clientes, acionistas e o público em geral
C8: Atenção ao cliente | D8: Chamadas do contact-center sucursais, consultas online, etc.
C9: Comunicação de Marketing e eventos | D9: Anúncios nos meios de comunicação, venda da marca, etc.
C10: Comunicação comercial | D10: Contato com clientes para venda de produtos
C11: Comunicação informativa | D11: Informações aos clientes sobre seus produtos (posições, data de vencimento, etc.)
C12: Comunicação para gestão recuperatória | D12: Contato com os clientes para as tarefas de recuperação de dívida
C13: Comunicação com fornecedores | D13: Gestão da comunicação com os prestadores de serviços
B14: Gestão | C14: Gestão de riscos | D14: Atividades de avaliação, monitorização, gestão e mitigação de riscos.
C15: Gestão financeira | D15: Análise, processamento de informação e tomada de decisões sobre aspetos financeiros e contabilísticos.
C16: Gestão tecnológica | D16: Gestão de Arquitetura tecnológica, controle de acesso, licenças, sistemas de gestão, etc.
C17: Gestão de fornecedores | D17: Homologação de fornecedores, contratos, análise global, etc.
C18: Gestão de empregados e familiares | D18: Gestão de vencimentos, avaliações, promoção, ausências, saúde, fiscalidade, etc.
C19: Gestão de marketing e eventos | D19: Organização de eventos de marketing, culturais e desportivos, gestão de campanhas de marketing, etc.
C20: Gestão de operativa bancaria | D20: Gestão de contratos, transacionais, liquidações, etc.
C21: Gestão de fundos e atividades de investimento | D21: Atividades de gestão de fundos, tesouraria, investimentos, etc.
C22: Gestão de processos judiciais | D22: Gestão de processos judiciais.
C23: Gestão de ativos | D23: Gestão de imóveis, escritórios, acesso físico, etc.
C24: Gestão comercial | D24: Gestão de campanhas comerciais, posicionamento e design de produtos, etc.
C25: Gestão de outros bens e serviços não financeiros | D25: Gestão de outros serviços e atividades (websites de emprego e universidades, portais de empresas, golfe, outros serviços a empregados e ex-empregados, etc.).
C26: Gestão de acionistas | D26: Atividades de gestão de voto dos acionistas, liquidação e pagamento de ações, etc.
... C28: Gestão de incidências externas | D28: Gestão de incidentes com clientes, fornecedores, etc.
B29: Reporte interno | C29: Alta direção | D29: Elaboração de relatórios para a administração (Conselho, unidade, fator, etc.)
C30: Reporte entre áreas | D30: Relatórios para gestão entre áreas, seguimentos, etc.
B31: Reporte externo | C31: Reporte a organismos reguladores e públicos | D31: Relatórios para diferentes reguladores e organismos públicos
C32: Reporte de incidentes de segurança | D32: Comunicação de incidentes de segurança a vários organismos (BCE, CNPD, etc.)
C33: Reporte a organismos privados | D33: Elaboração de outros relatórios para organismos privados (agências de rating, fundos, investidores institucionais, etc.)
B34: Control | C34: Tarefas de control e oversight sobre as atividades do banco ou a serviços prestados ao banco | D34: Elaboração de Dashboards, seguimento de indicadores, etc.
C35: Tarefas de cumprimento | D35: Elaboração de análise de cumprimento regulatório, PBC, etc.
C36: Tarefas de auditoria | D36: Elaboração de relatórios de auditoria, recomendações, etc.
B37: Consolidação | C37: Consolidação e agregação de dados | D37: Tarefas de consolidação financeira, perímetro societário, etc.
B38: Metodologia / Analítica | C38: Análise estatística | D38: Realização de cálculos e análise de caracter estatístico
C39: Criação de cenários e projeções | D39: Elaboração de Cenários económicos, financeiros, projeções, etc.
C40: Criação de modelos | D40: Tarefas de Definição, geração e avaliação de modelos
B41: Análise Estratégica | C41: Análise estratégica | D41: Elaboração da estratégia de negócios global e particular, riscos, tecnologia, de dados, etc.
...

Sheet Dado Base
B1: Semântica | C1: Semântica | D1: Dado Base | E1: Descrição do Dado Base
B2: Pessoas | C2: Dados pessoas singulares ou coletivas | D2: Nome | E2: Nome da pessoa
B3: Pessoas | C3: Dados pessoas singulares ou coletivas | D3: Tipo de pessoa | E3: Define se é uma pessoa singular ou coletiva
B4: Pessoas | C4: Dados pessoas singulares ou coletivas | D4: Identificador da pessoa | E4: Identificador de pessoa
B5: Pessoas | C5: Dados pessoas singulares ou coletivas | D5: Morada da pessoa | E5: Morada da pessoa (morada de residência, morada fiscal, morada identificação pessoal)
B6: Pessoas | C6: Dados pessoas singulares ou coletivas | D6: Sector de atividade do cliente (CAE) da pessoa singular ou coletiva | E6: Código de identificação do setor em que o cliente desempenha a sua atividade, seja trabalhador por conta de outrem ou trabalhador independente. Por exemplo: presta serviços em espaços abertos, transporte de mercadorias, compra e venda grossista, etc. Em Portugal designa-se por CAE.
B7: Pessoas | C7: Dados pessoas singulares ou coletivas | D7: Contacto da pessoa | E7: Contacto da pessoa (telefone, email)
B8: Pessoas | C8: Dados pessoas singulares | D8: Nome de pessoa singular | E8: Nome da pessoa singular
B9: Pessoas | C9: Dados pessoas singulares | D9: Identificador da pessoa singular | E9: Identificador de pessoa (NIF, CC-Cartão Cidadão, BI-Bilhete de Identidade)
B10: Pessoas | C10: Dados pessoas singulares | D10: Morada de pessoa singular | E10: Residência ou morada de correspondência
B11: Pessoas | C11: Dados pessoas singulares | D11: Contacto de pessoa singular | E11: (Telefone, email)
B12: Pessoas | C12: Dados pessoas singulares | D12: País de residência | E12: País de residência do cliente
... B40: Pessoas | C40: Dados pessoas coletivas | D40: Tipo de entidade de negócio | E40: Tipo de sociedade comercial (S.L, L.DA, S.A, etc.)
B41: Pessoas | C41: Dados pessoas coletivas | D41: Outros dados de pessoas coletivas
B42: Pessoas | C42: Dados específicos de clientes | D42: Identificador interno do cliente | E42: Identificador interno do cliente (zcliente, zcligrupo)
B43: Pessoas | C43: Dados específicos de clientes | D43: Setor corporativo de cliente | E43: Classificação interna do setor do cliente que encontra-se no BdP (Banco de Portugal, Caixa Econômica, Comunidades Autônomas, etc.)
B44: Pessoas | C44: Dados específicos de clientes | D44: Segmento do cliente | E44: Segmento de gestão, segmento comercial ou segmento de risco
B45: Pessoas | C45: Dados específicos de clientes | D45: Grupo económico | E45: Identificador do grupo económico
B46: Pessoas | C46: Dados específicos de clientes | D46: Natureza Jurídica | E46: Natureza jurídica do cliente
B47: Pessoas | C47: Dados específicos de clientes | D47: Saldo do cliente | E47: Saldo total do cliente
B48: Pessoas | C48: Dados específicos de clientes | D48: Responsabilidades do cliente | E48: Saldo total de responsabilidade do cliente
B49: Pessoas | C49: Dados específicos de clientes | D49: Saldo insolvente do cliente | E49: Saldo insolvente do cliente
B50: Pessoas | C50: Dados específicos de clientes | D50: Saldo recuperado | E50: Saldo recuperado do cliente
B51: Pessoas | C51: Dados específicos de clientes | D51: Limites do cliente | E51: Valor máximo que pode ser concedido ao cliente pelo Banco Santander
B52: Pessoas | C52: Dados específicos de clientes | D52: Rentabilidade do cliente | E52: Rentabilidade gerada ao nível do cliente, isto é, a diferença entre as entradas de receita e as despesas (por exemplo, rentabilidade por canal, por sucursal, etc.)
B53: Pessoas | C53: Dados específicos de clientes | D53: Avaliação de risco do cliente | E53: Dados para realizar uma avaliação de risco do cliente e avaliação de risco do cliente.
... B176: NA | C176: NA | D176: NA | E176: NA

Sheet Filtro Dado base
A1: Dado Base
A2: Nome
A3: Tipo de pessoa
A4: Identificador da pessoa
A5: Morada da pessoa
A6: Sector de atividade do cliente (CAE) da pessoa singular ou coletiva
A7: Contacto da pessoa
A8: Nome de pessoa singular
A9: Identificador da pessoa singular
A10: Morada de pessoa singular
A11: Contacto de pessoa singular
A12: País de residência
... A176: NA
