Workbook

Sheet PDS
E2: Total | G2: Concluido | I2: Mapeamento com LT fechado, mas parametrização pendente | K2: Novo campo, mapeamento datalake fechado, com necessidade de criar parametrização | M2: Novo campo, mapeamento datalake fechado, sem necessidade de criar parametrização | O2: Novo campo, mapeamento datalake pendente, com necessidade de criar parametrização | Q2: Novo campo, mapeamento datalake pendente, sem necessidade de criar parametrização | S2: Por iniciar
B3: Módulo | C3: Submódulo | D3: Nome do Ficheiro | E3: abs | F3: Total (%) | G3: abs | H3: % | I3: abs | J3: % | K3: abs | L3: % | M3: abs | N3: % | O3: abs | P3: % | Q3: abs | R3: % | S3: abs | T3: %
B4: Exposures to legal persons | C4: Instruments | D4: XXXXX_YYYYMMDD_01_01_leg_instr.csv | E4: =COUNTA(LEGALP_INSTRUMENTS!A3:A27) -> 7 | F4: =SUM(H4,J4,L4,N4,P4,R4,T4) -> 1 | G4: =COUNTIF(LEGALP_INSTRUMENTS!M:M,"Concluido") -> 5 | H4: =G4/E4 -> 0.71428571 | I4: =COUNTIF(LEGALP_INSTRUMENTS!M:M,"Mapeamento com LT fechado, mas parametrização pendente") -> 1 | J4: =I4/E4 -> 0.14285714 | K4: =COUNTIF(LEGALP_INSTRUMENTS!M:M,"Novo campo, mapeamento datalake fechado, com necessidade de criar parametrização") -> 0 | L4: =K4/E4 -> 0 | M4: =COUNTIF(LEGALP_INSTRUMENTS!M:M,"Novo campo, mapeamento datalake fechado, sem necessidade de criar parametrização") -> 0 | N4: =M4/E4 -> 0 | O4: =COUNTIF(LEGALP_INSTRUMENTS!M:M,"Novo campo, mapeamento datalake pendente, com necessidade de criar parametrização") -> 1 | P4: =O4/E4 -> 0.14285714 | Q4: =COUNTIF(LEGALP_INSTRUMENTS!M:M,"Novo campo, mapeamento datalake pendente, sem necessidade de criar parametrização") -> 0 | R4: =Q4/E4 -> 0 | S4: =COUNTIF(LEGALP_INSTRUMENTS!M:M,"Por iniciar") -> 0 | T4: =S4/E4 -> 0
C5: Counterparties | D5: XXXXX_YYYYMMDD_01_02_leg_count.csv | E5: =COUNTA(LEGALP_COUNTERPARTIES!A3:A27) -> 5 | F5: =SUM(H5,J5,L5,N5,P5,R5,T5) -> 1 | G5: =COUNTIF(LEGALP_COUNTERPARTIES!M:M,"Concluido") -> 4 | H5: =G5/E5 -> 0.8 | I5: =COUNTIF(LEGALP_COUNTERPARTIES!M:M,"Mapeamento com LT fechado, mas parametrização pendente") -> 0 | J5: =I5/E5 -> 0 | K5: =COUNTIF(LEGALP_COUNTERPARTIES!M:M,"Novo campo, mapeamento datalake fechado, com necessidade de criar parametrização") -> 0 | L5: =K5/E5 -> 0 | M5: =COUNTIF(LEGALP_COUNTERPARTIES!M:M,"Novo campo, mapeamento datalake fechado, sem necessidade de criar parametrização") -> 0 | N5: =M5/E5 -> 0 | O5: =COUNTIF(LEGALP_COUNTERPARTIES!M:M,"Novo campo, mapeamento datalake pendente, com necessidade de criar parametrização") -> 0 | P5: =O5/E5 -> 0 | Q5: =COUNTIF(LEGALP_COUNTERPARTIES!M:M,"Novo campo, mapeamento datalake pendente, sem necessidade de criar parametrização") -> 0 | R5: =Q5/E5 -> 0 | S5: =COUNTIF(LEGALP_COUNTERPARTIES!M:M,"Por iniciar") -> 1 | T5: =S5/E5 -> 0.2
C6: Protections | D6: XXXXX_YYYYMMDD_01_03_leg_prot.csv | E6: =COUNTA(LEGALP_PROTECTIONS!A3:A18) -> 8 | F6: =SUM(H6,J6,L6,N6,P6,R6,T6) -> 1 | G6: =COUNTIF(LEGALP_PROTECTIONS!M:M,"Concluido") -> 3 | H6: =G6/E6 -> 0.375 | I6: =COUNTIF(LEGALP_PROTECTIONS!M:M,"Mapeamento com LT fechado, mas parametrização pendente") -> 1 | J6: =I6/E6 -> 0.125 | K6: =COUNTIF(LEGALP_PROTECTIONS!M:M,"Novo campo, mapeamento datalake fechado, com necessidade de criar parametrização") -> 0 | L6: =K6/E6 -> 0 | M6: =COUNTIF(LEGALP_PROTECTIONS!M:M,"Novo campo, mapeamento datalake fechado, sem necessidade de criar parametrização") -> 1 | N6: =M6/E6 -> 0.125 | O6: =COUNTIF(LEGALP_PROTECTIONS!M:M,"Novo campo, mapeamento datalake pendente, com necessidade de criar parametrização") -> 1 | P6: =O6/E6 -> 0.125 | Q6: =COUNTIF(LEGALP_PROTECTIONS!M:M,"Novo campo, mapeamento datalake pendente, sem necessidade de criar parametrização") -> 2 | R6: =Q6/E6 -> 0.25 | S6: =COUNTIF(LEGALP_PROTECTIONS!M:M,"Por iniciar") -> 0 | T6: =S6/E6 -> 0
C7: Instrument-Counterparty relation | D7: XXXXX_YYYYMMDD_01_04_leg_instr_count.csv | E7: =COUNTA(LEGALP_INSTRUMENT_COUNTERPARTY!A3:A7) -> 2 | F7: =SUM(H7,J7,L7,N7,P7,R7,T7) -> 1 | G7: =COUNTIF(LEGALP_INSTRUMENT_COUNTERPARTY!M:M,"Concluido") -> 2 | H7: =G7/E7 -> 1 | I7: =COUNTIF(LEGALP_INSTRUMENT_COUNTERPARTY!M:M,"Mapeamento com LT fechado, mas parametrização pendente") -> 0 | J7: =I7/E7 -> 0 | K7: =COUNTIF(LEGALP_INSTRUMENT_COUNTERPARTY!M:M,"Novo campo, mapeamento datalake fechado, com necessidade de criar parametrização") -> 0 | L7: =K7/E7 -> 0 | M7: =COUNTIF(LEGALP_INSTRUMENT_COUNTERPARTY!M:M,"Novo campo, mapeamento datalake fechado, sem necessidade de criar parametrização") -> 0 | N7: =M7/E7 -> 0 | O7: =COUNTIF(LEGALP_INSTRUMENT_COUNTERPARTY!M:M,"Novo campo, mapeamento datalake pendente, com necessidade de criar parametrização") -> 0 | P7: =O7/E7 -> 0 | Q7: =COUNTIF(LEGALP_INSTRUMENT_COUNTERPARTY!M:M,"Novo campo, mapeamento datalake pendente, sem necessidade de criar parametrização") -> 0 | R7: =Q7/E7 -> 0 | S7: =COUNTIF(LEGALP_INSTRUMENT_COUNTERPARTY!M:M,"Por iniciar") -> 0 | T7: =S7/E7 -> 0
C8: Instrument-Protection relation | D8: XXXXX_YYYYMMDD_01_05_leg_instr_prot.csv | E8: =COUNTA(LEGALP_INSTRUMENT_PROTECTION!A3:A10) -> 2 | F8: =SUM(H8,J8,L8,N8,P8,R8,T8) -> 1 | G8: =COUNTIF(LEGALP_INSTRUMENT_PROTECTION!M:M,"Concluido") -> 2 | H8: =G8/E8 -> 1 | I8: =COUNTIF(LEGALP_INSTRUMENT_PROTECTION!M:M,"Mapeamento com LT fechado, mas parametrização pendente") -> 0 | J8: =I8/E8 -> 0 | K8: =COUNTIF(LEGALP_INSTRUMENT_PROTECTION!M:M,"Novo campo, mapeamento datalake fechado, com necessidade de criar parametrização") -> 0 | L8: =K8/E8 -> 0 | M8: =COUNTIF(LEGALP_INSTRUMENT_PROTECTION!M:M,"Novo campo, mapeamento datalake fechado, sem necessidade de criar parametrização") -> 0 | N8: =M8/E8 -> 0 | O8: =COUNTIF(LEGALP_INSTRUMENT_PROTECTION!M:M,"Novo campo, mapeamento datalake pendente, com necessidade de criar parametrização") -> 0 | P8: =O8/E8 -> 0 | Q8: =COUNTIF(LEGALP_INSTRUMENT_PROTECTION!M:M,"Novo campo, mapeamento datalake pendente, sem necessidade de criar parametrização") -> 0 | R8: =Q8/E8 -> 0 | S8: =COUNTIF(LEGALP_INSTRUMENT_PROTECTION!M:M,"Por iniciar") -> 0 | T8: =S8/E8 -> 0
B9: Exposures to natural persons | C9: Instruments | D9: XXXXX_YYYYMMDD_02_01_nat_instr.csv | E9: =COUNTA(NATURALP_INSTRUMENTS!A3:A142) -> 53 | F9: =SUM(H9,J9,L9,N9,P9,R9,T9) -> 1 | G9: =COUNTIF(NATURALP_INSTRUMENTS!M:M,"Concluido") -> 32 | H9: =G9/E9 -> 0.60377358 | I9: =COUNTIF(NATURALP_INSTRUMENTS!M:M,"Mapeamento com LT fechado, mas parametrização pendente") -> 15 | J9: =I9/E9 -> 0.28301887 | K9: =COUNTIF(NATURALP_INSTRUMENTS!M:M,"Novo campo, mapeamento datalake fechado, com necessidade de criar parametrização") -> 1 | L9: =K9/E9 -> 0.018867925 | M9: =COUNTIF(NATURALP_INSTRUMENTS!M:M,"Novo campo, mapeamento datalake fechado, sem necessidade de criar parametrização") -> 0 | N9: =M9/E9 -> 0 | O9: =COUNTIF(NATURALP_INSTRUMENTS!M:M,"Novo campo, mapeamento datalake pendente, com necessidade de criar parametrização") -> 3 | P9: =O9/E9 -> 0.056603774 | Q9: =COUNTIF(NATURALP_INSTRUMENTS!M:M,"Novo campo, mapeamento datalake pendente, sem necessidade de criar parametrização") -> 2 | R9: =Q9/E9 -> 0.037735849 | S9: =COUNTIF(NATURALP_INSTRUMENTS!M:M,"Por iniciar") -> 0 | T9: =S9/E9 -> 0
C10: Counterparties | D10: XXXXX_YYYYMMDD_02_02_nat_count.csv | E10: =COUNTA(NATURALP_COUNTERPARTIES!A3:A29) -> 8 | F10: =SUM(H10,J10,L10,N10,P10,R10,T10) -> 1 | G10: =COUNTIF(NATURALP_COUNTERPARTIES!M:M,"Concluido") -> 6 | H10: =G10/E10 -> 0.75 | I10: =COUNTIF(NATURALP_COUNTERPARTIES!M:M,"Mapeamento com LT fechado, mas parametrização pendente") -> 1 | J10: =I10/E10 -> 0.125 | K10: =COUNTIF(NATURALP_COUNTERPARTIES!M:M,"Novo campo, mapeamento datalake fechado, com necessidade de criar parametrização") -> 0 | L10: =K10/E10 -> 0 | M10: =COUNTIF(NATURALP_COUNTERPARTIES!M:M,"Novo campo, mapeamento datalake fechado, sem necessidade de criar parametrização") -> 0 | N10: =M10/E10 -> 0 | O10: =COUNTIF(NATURALP_COUNTERPARTIES!M:M,"Novo campo, mapeamento datalake pendente, com necessidade de criar parametrização") -> 0 | P10: =O10/E10 -> 0 | Q10: =COUNTIF(NATURALP_COUNTERPARTIES!M:M,"Novo campo, mapeamento datalake pendente, sem necessidade de criar parametrização") -> 0 | R10: =Q10/E10 -> 0 | S10: =COUNTIF(NATURALP_COUNTERPARTIES!M:M,"Por iniciar") -> 1 | T10: =S10/E10 -> 0.125
C11: Protections | D11: XXXXX_YYYYMMDD_02_03_nat_prot.csv | E11: =COUNTA(NATURALP_PROTECTIONS!A3:A27) -> 17 | F11: =SUM(H11,J11,L11,N11,P11,R11,T11) -> 1 | G11: =COUNTIF(NATURALP_PROTECTIONS!M:M,"Concluido") -> 11 | H11: =G11/E11 -> 0.64705882 | I11: =COUNTIF(NATURALP_PROTECTIONS!M:M,"Mapeamento com LT fechado, mas parametrização pendente") -> 3 | J11: =I11/E11 -> 0.17647059 | K11: =COUNTIF(NATURALP_PROTECTIONS!M:M,"Novo campo, mapeamento datalake fechado, com necessidade de criar parametrização") -> 0 | L11: =K11/E11 -> 0 | M11: =COUNTIF(NATURALP_PROTECTIONS!M:M,"Novo campo, mapeamento datalake fechado, sem necessidade de criar parametrização") -> 1 | N11: =M11/E11 -> 0.058823529 | O11: =COUNTIF(NATURALP_PROTECTIONS!M:M,"Novo campo, mapeamento datalake pendente, com necessidade de criar parametrização") -> 0 | P11: =O11/E11 -> 0 | Q11: =COUNTIF(NATURALP_PROTECTIONS!M:M,"Novo campo, mapeamento datalake pendente, sem necessidade de criar parametrização") -> 2 | R11: =Q11/E11 -> 0.11764706 | S11: =COUNTIF(NATURALP_PROTECTIONS!M:M,"Por iniciar") -> 0 | T11: =S11/E11 -> 0
C12: Instrument-Counterparty relation | D12: XXXXX_YYYYMMDD_02_04_nat_instr_count.csv | E12: =COUNTA(NATURALP_INSTRUMENT_COUNTERPART!A3:A9) -> 4 | F12: =SUM(H12,J12,L12,N12,P12,R12,T12) -> 1 | G12: =COUNTIF(NATURALP_INSTRUMENT_COUNTERPART!M:M,"Concluido") -> 3 | H12: =G12/E12 -> 0.75 | I12: =COUNTIF(NATURALP_INSTRUMENT_COUNTERPART!M:M,"Mapeamento com LT fechado, mas parametrização pendente") -> 0 | J12: =I12/E12 -> 0 | K12: =COUNTIF(NATURALP_INSTRUMENT_COUNTERPART!M:M,"Novo campo, mapeamento datalake fechado, com necessidade de criar parametrização") -> 0 | L12: =K12/E12 -> 0 | M12: =COUNTIF(NATURALP_INSTRUMENT_COUNTERPART!M:M,"Novo campo, mapeamento datalake fechado, sem necessidade de criar parametrização") -> 0 | N12: =M12/E12 -> 0 | O12: =COUNTIF(NATURALP_INSTRUMENT_COUNTERPART!M:M,"Novo campo, mapeamento datalake pendente, com necessidade de criar parametrização") -> 1 | P12: =O12/E12 -> 0.25 | Q12: =COUNTIF(NATURALP_INSTRUMENT_COUNTERPART!M:M,"Novo campo, mapeamento datalake pendente, sem necessidade de criar parametrização") -> 0 | R12: =Q12/E12 -> 0 | S12: =COUNTIF(NATURALP_INSTRUMENT_COUNTERPART!M:M,"Por iniciar") -> 0 | T12: =S12/E12 -> 0
C13: Instrument-Protection relation | D13: XXXXX_YYYYMMDD_02_05_nat_instr_prot.csv | E13: =COUNTA(NATURALP_INSTRUMENT_PROTECTION!A3:A12) -> 4 | F13: =SUM(H13,J13,L13,N13,P13,R13,T13) -> 1 | G13: =COUNTIF(NATURALP_INSTRUMENT_PROTECTION!M:M,"Concluido") -> 4 | H13: =G13/E13 -> 1 | I13: =COUNTIF(NATURALP_INSTRUMENT_PROTECTION!M:M,"Mapeamento com LT fechado, mas parametrização pendente") -> 0 | J13: =I13/E13 -> 0 | K13: =COUNTIF(NATURALP_INSTRUMENT_PROTECTION!M:M,"Novo campo, mapeamento datalake fechado, com necessidade de criar parametrização") -> 0 | L13: =K13/E13 -> 0 | M13: =COUNTIF(NATURALP_INSTRUMENT_PROTECTION!M:M,"Novo campo, mapeamento datalake fechado, sem necessidade de criar parametrização") -> 0 | N13: =M13/E13 -> 0 | O13: =COUNTIF(NATURALP_INSTRUMENT_PROTECTION!M:M,"Novo campo, mapeamento datalake pendente, com necessidade de criar parametrização") -> 0 | P13: =O13/E13 -> 0 | Q13: =COUNTIF(NATURALP_INSTRUMENT_PROTECTION!M:M,"Novo campo, mapeamento datalake pendente, sem necessidade de criar parametrização") -> 0 | R13: =Q13/E13 -> 0 | S13: =COUNTIF(NATURALP_INSTRUMENT_PROTECTION!M:M,"Por iniciar") -> 0 | T13: =S13/E13 -> 0
B14: Off-balance sheet exposures | C14: Instruments | D14: XXXXX_YYYYMMDD_03_01_off_instr.csv | E14: =COUNTA(OFFBAL_INSTRUMENTS!A3:A67) -> 27 | F14: =SUM(H14,J14,L14,N14,P14,R14,T14) -> 1 | G14: =COUNTIF(OFFBAL_INSTRUMENTS!M:M,"Concluido") -> 18 | H14: =G14/E14 -> 0.66666667 | I14: =COUNTIF(OFFBAL_INSTRUMENTS!M:M,"Mapeamento com LT fechado, mas parametrização pendente") -> 6 | J14: =I14/E14 -> 0.22222222 | K14: =COUNTIF(OFFBAL_INSTRUMENTS!M:M,"Novo campo, mapeamento datalake fechado, com necessidade de criar parametrização") -> 0 | L14: =K14/E14 -> 0 | M14: =COUNTIF(OFFBAL_INSTRUMENTS!M:M,"Novo campo, mapeamento datalake fechado, sem necessidade de criar parametrização") -> 0 | N14: =M14/E14 -> 0 | O14: =COUNTIF(OFFBAL_INSTRUMENTS!M:M,"Novo campo, mapeamento datalake pendente, com necessidade de criar parametrização") -> 2 | P14: =O14/E14 -> 0.074074074 | Q14: =COUNTIF(OFFBAL_INSTRUMENTS!M:M,"Novo campo, mapeamento datalake pendente, sem necessidade de criar parametrização") -> 1 | R14: =Q14/E14 -> 0.037037037 | S14: =COUNTIF(OFFBAL_INSTRUMENTS!M:M,"Por iniciar") -> 0 | T14: =S14/E14 -> 0
C15: Counterparties | D15: XXXXX_YYYYMMDD_03_02_off_count.csv | E15: =COUNTA(OFFBAL_COUNTERPARTIES!A3:A59) -> 30 | F15: =SUM(H15,J15,L15,N15,P15,R15,T15) -> 1 | G15: =COUNTIF(OFFBAL_COUNTERPARTIES!M:M,"Concluido") -> 12 | H15: =G15/E15 -> 0.4 | I15: =COUNTIF(OFFBAL_COUNTERPARTIES!M:M,"Mapeamento com LT fechado, mas parametrização pendente") -> 5 | J15: =I15/E15 -> 0.16666667 | K15: =COUNTIF(OFFBAL_COUNTERPARTIES!M:M,"Novo campo, mapeamento datalake fechado, com necessidade de criar parametrização") -> 0 | L15: =K15/E15 -> 0 | M15: =COUNTIF(OFFBAL_COUNTERPARTIES!M:M,"Novo campo, mapeamento datalake fechado, sem necessidade de criar parametrização") -> 0 | N15: =M15/E15 -> 0 | O15: =COUNTIF(OFFBAL_COUNTERPARTIES!M:M,"Novo campo, mapeamento datalake pendente, com necessidade de criar parametrização") -> 2 | P15: =O15/E15 -> 0.066666667 | Q15: =COUNTIF(OFFBAL_COUNTERPARTIES!M:M,"Novo campo, mapeamento datalake pendente, sem necessidade de criar parametrização") -> 10 | R15: =Q15/E15 -> 0.33333333 | S15: =COUNTIF(OFFBAL_COUNTERPARTIES!M:M,"Por iniciar") -> 1 | T15: =S15/E15 -> 0.033333333
C16: Protections | D16: XXXXX_YYYYMMDD_03_03_off_prot.csv | E16: =COUNTA(OFFBAL_PROTECTIONS!A3:A27) -> 17 | F16: =SUM(H16,J16,L16,N16,P16,R16,T16) -> 1 | G16: =COUNTIF(OFFBAL_PROTECTIONS!M:M,"Concluido") -> 11 | H16: =G16/E16 -> 0.64705882 | I16: =COUNTIF(OFFBAL_PROTECTIONS!M:M,"Mapeamento com LT fechado, mas parametrização pendente") -> 3 | J16: =I16/E16 -> 0.17647059 | K16: =COUNTIF(OFFBAL_PROTECTIONS!M:M,"Novo campo, mapeamento datalake fechado, com necessidade de criar parametrização") -> 0 | L16: =K16/E16 -> 0 | M16: =COUNTIF(OFFBAL_PROTECTIONS!M:M,"Novo campo, mapeamento datalake fechado, sem necessidade de criar parametrização") -> 1 | N16: =M16/E16 -> 0.058823529 | O16: =COUNTIF(OFFBAL_PROTECTIONS!M:M,"Novo campo, mapeamento datalake pendente, com necessidade de criar parametrização") -> 0 | P16: =O16/E16 -> 0 | Q16: =COUNTIF(OFFBAL_PROTECTIONS!M:M,"Novo campo, mapeamento datalake pendente, sem necessidade de criar parametrização") -> 2 | R16: =Q16/E16 -> 0.11764706 | S16: =COUNTIF(OFFBAL_PROTECTIONS!M:M,"Por iniciar") -> 0 | T16: =S16/E16 -> 0
C17: Instrument-Counterparty relation | D17: XXXXX_YYYYMMDD_03_04_off_instr_count.csv | E17: =COUNTA(OFFBAL_INSTRUMENT_COUNTERPARTY!A3:A8) -> 3 | F17: =SUM(H17,J17,L17,N17,P17,R17,T17) -> 1 | G17: =COUNTIF(OFFBAL_INSTRUMENT_COUNTERPARTY!M:M,"Concluido") -> 3 | H17: =G17/E17 -> 1 | I17: =COUNTIF(OFFBAL_INSTRUMENT_COUNTERPARTY!M:M,"Mapeamento com LT fechado, mas parametrização pendente") -> 0 | J17: =I17/E17 -> 0 | K17: =COUNTIF(OFFBAL_INSTRUMENT_COUNTERPARTY!M:M,"Novo campo, mapeamento datalake fechado, com necessidade de criar parametrização") -> 0 | L17: =K17/E17 -> 0 | M17: =COUNTIF(OFFBAL_INSTRUMENT_COUNTERPARTY!M:M,"Novo campo, mapeamento datalake fechado, sem necessidade de criar parametrização") -> 0 | N17: =M17/E17 -> 0 | O17: =COUNTIF(OFFBAL_INSTRUMENT_COUNTERPARTY!M:M,"Novo campo, mapeamento datalake pendente, com necessidade de criar parametrização") -> 0 | P17: =O17/E17 -> 0 | Q17: =COUNTIF(OFFBAL_INSTRUMENT_COUNTERPARTY!M:M,"Novo campo, mapeamento datalake pendente, sem necessidade de criar parametrização") -> 0 | R17: =Q17/E17 -> 0 | S17: =COUNTIF(OFFBAL_INSTRUMENT_COUNTERPARTY!M:M,"Por iniciar") -> 0 | T17: =S17/E17 -> 0
C18: Instrument-Protection relation | D18: XXXXX_YYYYMMDD_03_05_off_instr_prot.csv | E18: =COUNTA(OFFBAL_INSTRUMENT_PROTECTION!A3:A12) -> 4 | F18: =SUM(H18,J18,L18,N18,P18,R18,T18) -> 1 | G18: =COUNTIF(OFFBAL_INSTRUMENT_PROTECTION!M:M,"Concluido") -> 4 | H18: =G18/E18 -> 1 | I18: =COUNTIF(OFFBAL_INSTRUMENT_PROTECTION!M:M,"Mapeamento com LT fechado, mas parametrização pendente") -> 0 | J18: =I18/E18 -> 0 | K18: =COUNTIF(OFFBAL_INSTRUMENT_PROTECTION!M:M,"Novo campo, mapeamento datalake fechado, com necessidade de criar parametrização") -> 0 | L18: =K18/E18 -> 0 | M18: =COUNTIF(OFFBAL_INSTRUMENT_PROTECTION!M:M,"Novo campo, mapeamento datalake fechado, sem necessidade de criar parametrização") -> 0 | N18: =M18/E18 -> 0 | O18: =COUNTIF(OFFBAL_INSTRUMENT_PROTECTION!M:M,"Novo campo, mapeamento datalake pendente, com necessidade de criar parametrização") -> 0 | P18: =O18/E18 -> 0 | Q18: =COUNTIF(OFFBAL_INSTRUMENT_PROTECTION!M:M,"Novo campo, mapeamento datalake pendente, sem necessidade de criar parametrização") -> 0 | R18: =Q18/E18 -> 0 | S18: =COUNTIF(OFFBAL_INSTRUMENT_PROTECTION!M:M,"Por iniciar") -> 0 | T18: =S18/E18 -> 0
B19: Derivatives | C19: - | D19: XXXXX_YYYYMMDD_04_01_derivatives.csv | E19: =COUNTA(DERIVATIVES!A3:A69) -> 29 | F19: =SUM(H19,J19,L19,N19,P19,R19,T19) -> 1 | G19: =COUNTIF(DERIVATIVES!M:M,"Concluido") -> 0 | H19: =G19/E19 -> 0 | I19: =COUNTIF(DERIVATIVES!M:M,"Mapeamento com LT fechado, mas parametrização pendente") -> 0 | J19: =I19/E19 -> 0 | K19: =COUNTIF(DERIVATIVES!M:M,"Novo campo, mapeamento datalake fechado, com necessidade de criar parametrização") -> 0 | L19: =K19/E19 -> 0 | M19: =COUNTIF(DERIVATIVES!M:M,"Novo campo, mapeamento datalake fechado, sem necessidade de criar parametrização") -> 0 | N19: =M19/E19 -> 0 | O19: =COUNTIF(DERIVATIVES!M:M,"Novo campo, mapeamento datalake pendente, com necessidade de criar parametrização") -> 0 | P19: =O19/E19 -> 0 | Q19: =COUNTIF(DERIVATIVES!M:M,"Novo campo, mapeamento datalake pendente, sem necessidade de criar parametrização") -> 0 | R19: =Q19/E19 -> 0 | S19: =COUNTIF(DERIVATIVES!M:M,"Por iniciar") -> 29 | T19: =S19/E19 -> 1
B20: Debt securities | C20: - | D20: XXXXX_YYYYMMDD_05_01_debtsecurities.csv | E20: =COUNTA(DEBT_SECURITIES!A3:A77) -> 40 | F20: =SUM(H20,J20,L20,N20,P20,R20,T20) -> 1 | G20: =COUNTIF(DEBT_SECURITIES!M:M,"Concluido") -> 14 | H20: =G20/E20 -> 0.35 | I20: =COUNTIF(DEBT_SECURITIES!M:M,"Mapeamento com LT fechado, mas parametrização pendente") -> 25 | J20: =I20/E20 -> 0.625 | K20: =COUNTIF(DEBT_SECURITIES!M:M,"Novo campo, mapeamento datalake fechado, com necessidade de criar parametrização") -> 0 | L20: =K20/E20 -> 0 | M20: =COUNTIF(DEBT_SECURITIES!M:M,"Novo campo, mapeamento datalake fechado, sem necessidade de criar parametrização") -> 0 | N20: =M20/E20 -> 0 | O20: =COUNTIF(DEBT_SECURITIES!M:M,"Novo campo, mapeamento datalake pendente, com necessidade de criar parametrização") -> 0 | P20: =O20/E20 -> 0 | Q20: =COUNTIF(DEBT_SECURITIES!M:M,"Novo campo, mapeamento datalake pendente, sem necessidade de criar parametrização") -> 0 | R20: =Q20/E20 -> 0 | S20: =COUNTIF(DEBT_SECURITIES!M:M,"Por iniciar") -> 1 | T20: =S20/E20 -> 0.025
B21: Equity | C21: - | D21: XXXXX_YYYYMMDD_06_01_equity.csv | E21: =COUNTA(EQUITY_INSTRUMENTS!A3:A35) -> 18 | F21: =SUM(H21,J21,L21,N21,P21,R21,T21) -> 1 | G21: =COUNTIF(EQUITY_INSTRUMENTS!M:M,"Concluido") -> 0 | H21: =G21/E21 -> 0 | I21: =COUNTIF(EQUITY_INSTRUMENTS!M:M,"Mapeamento com LT fechado, mas parametrização pendente") -> 0 | J21: =I21/E21 -> 0 | K21: =COUNTIF(EQUITY_INSTRUMENTS!M:M,"Novo campo, mapeamento datalake fechado, com necessidade de criar parametrização") -> 0 | L21: =K21/E21 -> 0 | M21: =COUNTIF(EQUITY_INSTRUMENTS!M:M,"Novo campo, mapeamento datalake fechado, sem necessidade de criar parametrização") -> 0 | N21: =M21/E21 -> 0 | O21: =COUNTIF(EQUITY_INSTRUMENTS!M:M,"Novo campo, mapeamento datalake pendente, com necessidade de criar parametrização") -> 0 | P21: =O21/E21 -> 0 | Q21: =COUNTIF(EQUITY_INSTRUMENTS!M:M,"Novo campo, mapeamento datalake pendente, sem necessidade de criar parametrização") -> 0 | R21: =Q21/E21 -> 0 | S21: =COUNTIF(EQUITY_INSTRUMENTS!M:M,"Por iniciar") -> 18 | T21: =S21/E21 -> 1
B22: DTAs/DTCs | C22: - | D22: XXXXX_YYYYMMDD_07_01_dtasdtcs.csv | E22: =COUNTA(DTA_DTC!A3:A19) -> 17 | F22: =SUM(H22,J22,L22,N22,P22,R22,T22) -> 1 | G22: =COUNTIF(DTA_DTC!M:M,"Concluido") -> 0 | H22: =G22/E22 -> 0 | I22: =COUNTIF(DTA_DTC!M:M,"Mapeamento com LT fechado, mas parametrização pendente") -> 0 | J22: =I22/E22 -> 0 | K22: =COUNTIF(DTA_DTC!M:M,"Novo campo, mapeamento datalake fechado, com necessidade de criar parametrização") -> 0 | L22: =K22/E22 -> 0 | M22: =COUNTIF(DTA_DTC!M:M,"Novo campo, mapeamento datalake fechado, sem necessidade de criar parametrização") -> 0 | N22: =M22/E22 -> 0 | O22: =COUNTIF(DTA_DTC!M:M,"Novo campo, mapeamento datalake pendente, com necessidade de criar parametrização") -> 0 | P22: =O22/E22 -> 0 | Q22: =COUNTIF(DTA_DTC!M:M,"Novo campo, mapeamento datalake pendente, sem necessidade de criar parametrização") -> 0 | R22: =Q22/E22 -> 0 | S22: =COUNTIF(DTA_DTC!M:M,"Por iniciar") -> 17 | T22: =S22/E22 -> 1
B23: Intangible assets | C23: - | D23: XXXXX_YYYYMMDD_08_01_intangible.csv | E23: =COUNTA(INTANGIBLE_ASSETS!A3:A15) -> 13 | F23: =SUM(H23,J23,L23,N23,P23,R23,T23) -> 1 | G23: =COUNTIF(INTANGIBLE_ASSETS!M:M,"Concluido") -> 0 | H23: =G23/E23 -> 0 | I23: =COUNTIF(INTANGIBLE_ASSETS!M:M,"Mapeamento com LT fechado, mas parametrização pendente") -> 0 | J23: =I23/E23 -> 0 | K23: =COUNTIF(INTANGIBLE_ASSETS!M:M,"Novo campo, mapeamento datalake fechado, com necessidade de criar parametrização") -> 0 | L23: =K23/E23 -> 0 | M23: =COUNTIF(INTANGIBLE_ASSETS!M:M,"Novo campo, mapeamento datalake fechado, sem necessidade de criar parametrização") -> 0 | N23: =M23/E23 -> 0 | O23: =COUNTIF(INTANGIBLE_ASSETS!M:M,"Novo campo, mapeamento datalake pendente, com necessidade de criar parametrização") -> 0 | P23: =O23/E23 -> 0 | Q23: =COUNTIF(INTANGIBLE_ASSETS!M:M,"Novo campo, mapeamento datalake pendente, sem necessidade de criar parametrização") -> 0 | R23: =Q23/E23 -> 0 | S23: =COUNTIF(INTANGIBLE_ASSETS!M:M,"Por iniciar") -> 13 | T23: =S23/E23 -> 1
C24: Total | E24: =SUM(E4:E23) -> 308 | F24: =SUM(H24,J24,L24,N24,P24,R24,T24) -> 1 | G24: =SUM(G4:G23) -> 134 | H24: =G24/E24 -> 0.43506494 | I24: =SUM(I4:I23) -> 60 | J24: =I24/E24 -> 0.19480519 | K24: =SUM(K4:K23) -> 1 | L24: =K24/E24 -> 0.0032467532 | M24: =SUM(M4:M23) -> 3 | N24: =M24/E24 -> 0.0097402597 | O24: =SUM(O4:O23) -> 10 | P24: =O24/E24 -> 0.032467532 | Q24: =SUM(Q4:Q23) -> 19 | R24: =Q24/E24 -> 0.061688312 | S24: =SUM(S4:S23) -> 81 | T24: =S24/E24 -> 0.26298701

Sheet UNIVERSOS
A1: O Report Valuation está dividido em vários Universos. De seguida iremos explicar como separar entre: ‣ LEGAL PERSON; ‣ NATURAL PERSON; ‣ OFF-BALANCE; ‣ DERIVATIVE; ‣ DEBT SECURITIES; ‣ EQUITY INSTRUMENTS
A10: DERIVATIVE | B10: DEBT SECURITIES | C10: EQUITY INSTRUMENTS | D10: OFF-BALANCE | E10: LEGAL PERSON | F10: NATURAL PERSON
A11: Todos os contratos da tabela cd_alm.al011_derivados | B11: Para filtrar este universo de contratos é necessário ligar a tabela cd_captools.ct610_titulos com a tabela cd_captools.ct010_dim_valor (filtrado por id_dimensao = 76) através dos campos "nome_atributo_dim"="tipo_titulo". O universo de DEBT SECURITIES trata-se dos contratos da tabela cd_captools.ct610_titulos cujo campo "cod_atributo_dim" resultante da ligação com a tabela cd_captools.ct010_dim_valor começa por "Inst_Div". | C11: Para filtrar este universo de contratos é necessário ligar a tabela cd_captools.ct610_titulos com a tabela cd_captools.ct010_dim_valor (filtrado por id_dimensao = 76) através dos campos "nome_atributo_dim"="tipo_titulo". O universo de DEBT SECURITIES trata-se dos contratos da tabela cd_captools.ct610_titulos cujo campo "cod_atributo_dim" resultante da ligação com a tabela cd_captools.ct010_dim_valor começa por "Inst_Cap". | D11: Todos os contratos da tabela cd_captools.ct001_univ_saldo cuja ligação com a tabela cd_captools.fr802_pl_contas (cod_plano = "BST_IND") resulte no campo "carteira_contabilistica" = "garantias e compromissos concedidos" e o campo "produto" entre as opções ("compromissos de credito concedidos", "garantias financeiras prestadas", "outras responsabilidades perante terceiros") NOTA: Rever criação da variável "produto_off_bal" com Pedro Mendes, penso que o filtro feito ao campo produto da tabela vds_inp_fr_pl_contas não está retornar o que devia | E11: Todos os clientes (zcliente) da tabela cd_captools.ct003_univ_cli onde o campo "itip_cli" = "J" | F11: Tudo o resto

Sheet LEGAL PERSONS DATA SETS
A1: SRB DATA SET FOR EXPOSURES TO LEGAL PERSONS The AnaCredit database provides very detailed and individual information concerning exposures to legal persons. The SRB Valuation Data Set complements the AnaCredit database and provides data fields on segments, which allows mapping individual exposures with prudential reporting segments (FINREP and COREP), and credit risk data parameters aimed at supporting valuers. The SRB Valuation Data Set also provides data fields on risk parameters provided by banks’ internal risk models, which valuers are able to rely on in order to perform valuations on an aggregated basis, where necessary. Serão produzidos cinco ficheiros de report referentes a Legal Persons: ‣ SRB Instruments Data Set for exposures to legal persons (LEGALP_INSTRUMENTS); ‣ SRB Counterparties Data Set for exposures to legal persons (LEGALP_COUNTERPARTIES); ‣ SRB Protection received Data Set for exposures to legal persons (LEGALP_PROTECTIONS); ‣ SRB Instrument/Counterparty mapping Data Set for exposures to legal persons (LEGALP_INSTRUMENT_COUNTERPARTY); ‣ SRB Instrument/Protection mapping Data Set for exposures to legal persons (LEGALP_INSTRUMENT_PROTECTION);
A2: SRB DATA SET FOR EXPOSURES TO LEGAL PERSONS A base de dados AnaCredit disponibiliza informação muito detalhada e individualizada sobre exposições a pessoas coletivas. O dataset de avaliação do SRB complementa a base de dados AnaCredit e fornece campos de dados por segmentos, o que permite mapear exposições individuais com segmentos de reporte prudencial (FINREP e COREP) e parâmetros de dados de risco de crédito destinados a apoiar os avaliadores. O dataset de avaliação do CUR também fornece campos de dados sobre parâmetros de risco fornecidos pelos modelos de risco internos dos bancos, nos quais os avaliadores podem confiar para realizar avaliações numa base agregada, sempre que necessário. Serão produzidos três ficheiros de report referentes a Legal Persons: ‣ SRB Instruments Data Set for exposures to legal persons (VDS_OUT_LEGALP_INSTRUMENTS); ‣ SRB Counterparties Data Set for exposures to legal persons (VDS_OUT_LEGALP_COUNTERPARTIES); ‣ SRB Protection received Data Set for exposures to legal persons (VDS_OUT_LEGALP_PROTECTIONS).

Sheet LEGALP_INSTRUMENTS
A1: SRB Instruments Data Set for exposures to legal persons
A2: ID | B2: Categoria | C2: Coluna | D2: Tipo de dados | E2: Descrição | F2: Descrição - Português | H2: Mapeamentos Corporação (LT) | I2: Descrição (LT) | J2: Additional Guidance (LT) | L2: Comentários | M2: Estado especificação | O2: Fontes de Informação | P2: Filtros | Q2: Campo | R2: Regras de Preenchimento | S2: Agrupações | U2: Comentários reuniões
A3: V_1 | B3: Identification information | C3: Instrument Identifier | D3: Alphanumeric | E3: An identifier applied to uniquely identify each instrument. Each instrument must have one instrument identifier | F3: Um identificador aplicado para identificar exclusivamente cada instrumento. Cada instrumento deve ter um identificador de instrumento. | H3: INSTRUMENT-INSTRMNT_ID | I3: Instrument ID | J3: An identifier applied by the reporting agent to uniquely identify each instrument under a single contract. Each instrument must have one instrument identifier. This value will not change over time and cannot be used as the instrument identifier for any other instrument under the same contract. Supervised Insitutions are asked to furnish the INSTRMNT_ID with the exact same value as it is reported to AnaCredit (or any similar central credit register). If this is not available, the value shall be reported as it is internally used. If an instrument is not reported to AnaCredit but requested for the purposes of the on-site inspection please provide the bank-internally used value. | L3: INSTRUMENT-INSTRMNT_ID | M3: Concluido | O3: cd_alm.al029_cnt_core_m | P3: ‣ ref_date = data do report | Q3: cempresa | R3: ‣ Concatenação dos campos mencionados anteriormente: cempresa + cbalcao + cnumecta + zdeposit | U3: Após reunião com LCM foi indicado que este campo deveria ser na mesma o cempresa … zeposit mas da tabela fr001/fr004 em vez da al029 isto porque tendo que conciliar com o finrep, faz sentido que tenha a mesma granularidade
Q4: cbalcao
Q5: cnumecta
Q6: zdeposit
A7: V_2 | B7: Identification information | C7: Counterparty Identifier | D7: Alphanumeric | E7: Identifier applied to uniquely identify each counterparty. | F7: Identificador aplicado para identificar exclusivamente cada contraparte | H7: Not applicable: To be reported as "N/A". This information will be availabe in "01_04_leg_instr_count" table | I7: - | J7: - | L7: Not applicable: To be reported as "N/A". This information will be availabe in "01_04_leg_instr_count" table | M7: Concluido | O7: cd_alm.al029_cnt_core_m | P7: ‣ ref_date = data do report | Q7: zcliente | R7: ‣ Direto | U7: Se se alterar o universo trazer o zcliente respetivo
A8: V_3 | B8: Exposure class | C8: CRR Exposure class | D8: String | E8: The exposures classes for the calculation of risk-weighted assets (RWAs) for credit risks are as follows (not applicable when exposures are classified in the CRR trading book as defined in Article 4(1)(86) of Regulation (EU) No 575/2013): Where a bank uses the standardised approach: ‣ Central governments or central banks (SCENGOV) ‣ Regional governments or local authorities (SREGGOV) ‣ Public sector entities (SPUBSEC) ‣ Multilateral development banks (SDEVBAN) ‣ International organisation (SINTORG) ‣ Institutions (SINSTIT) ‣ Corporates (SCORPOR) ‣ Retail (SRETAIL) ‣ Secured by mortgages and immovable property (SSECMOR) ‣ Defaulted (SDEFAUL) ‣ High risk (SHIGHRI) ‣ Covered bonds (SCOVBON) ‣ Items representing securitisation positions ‣ Institutions and corporates with a short term credit assessment (SSHOTER) ‣ Collective investment undertakings (SCOLINV) ‣ Equity (SEQUITY) ‣ Other (SOTHERI) Where a bank uses the IRB approach: ‣ Central governments and central banks (ICENGOV) ‣ Institutions (IINSTIT) ‣ Corporates (ICORPOR) ‣ Retail (IRETAIL) ‣ Equity (IEQUITY) ‣ Items representing securitisation positions ‣ Other non-credit-obligation assets (IOTHERC) | F8: As classes de posições em risco para o cálculo dos ativos ponderados pelo risco (RWA) para riscos de crédito são as seguintes (não aplicável quando as posições em risco são classificadas na carteira de negociação do CRR, conforme definido no artigo 4(1)(86), do Regulamento (UE) No 575 /2013). Informação deriva de uma lista baseada na classificação da facilidade utilizando a classe de risco, conforme descrito no artigo 112 do Regulamento (UE) No 575/2013 para bancos que utilizam a abordagem padrão) e no artigo 147 do Regulamento (UE) No 575/2013 (para bancos que utilizam abordagem baseada em classificações internas (IRB)) Quando um banco utiliza a abordagem padrão: ‣ Central governments or central banks (SCENGOV) ‣ Regional governments or local authorities (SREGGOV) ‣ Public sector entities (SPUBSEC) ‣ Multilateral development banks (SDEVBAN) ‣ International organisation (SINTORG) ‣ Institutions (SINSTIT) ‣ Corporates (SCORPOR) ‣ Retail (SRETAIL) ‣ Secured by mortgages and immovable property (SSECMOR) ‣ Defaulted (SDEFAUL) ‣ High risk (SHIGHRI) ‣ Covered bonds (SCOVBON) ‣ Items representing securitisation positions ‣ Institutions and corporates with a short term credit assessment (SSHOTER) ‣ Collective investment undertakings (SCOLINV) ‣ Equity (SEQUITY) ‣ Other (SOTHERI) Quando um banco utiliza a abordagem IRB: ‣ Central governments and central banks (ICENGOV) ‣ Institutions (IINSTIT) ‣ Corporates (ICORPOR) ‣ Retail (IRETAIL) ‣ Equity (IEQUITY) ‣ Items representing securitisation positions ‣ Other non-credit-obligation assets (IOTHERC) | H8: - | I8: - | J8: - | L8: ‣ Não encontramos no LT -> Confirmar com Nádia Ahmad e Dora Roxo; ‣ Se não existir no LT trazer o segmento_corep_final da ct013, tendo em atenção RWA_mtethod (se for IRB ou STD) ‣ Temos de explorar como ligar o universo lt ao de capital (O) ‣Email de Pedro Mendes com a resposta da Corporação (26/03/2024 17:28) ‣ No LT para calculo do LGD que vem da ct013, quando existe IRB e STD, escolhe-se IRB. Contudo, é preciso clarificar o que se envia quando existem vários segmentos IRB ou também quando existem vários segmentos STD. | M8: Novo campo, mapeamento datalake pendente, com necessidade de criar parametrização | O8: Tabela de parametrização: codemapping | P8: ‣ dd_field_id = "3" | Q8: dd_code | R8: ‣ Tradução do campo "segmento_corep_final" através de uma ligação com o campo "dd_code" para obter o campo: dd_value
Q9: dd_value
O10: cd_captools.ct013_rwa_princ | P10: ‣ ref_date = data do report ‣ flag_cons_cap = 1 ‣ exercicio = 'REAL' | Q10: segmento_corep_final
A11: V_4 | B11: Exposure class | C11: FINREP Exposure class | D11: String | E11: Classification of the facility (exposure class) as defined in ITS 680/2014 Annex V Instructions FINREP (Counterparty breakdown). Options: ‣ Central banks ‣ Central governments ‣ Credit institutions ‣ Other financial corporations ‣ Non-financial corporations ‣ Households | F11: Classificação da instalação (exposure class) conforme definido na ITS 680/2014 Anexo V Instruções FINREP (Counterparty breakdown). Opções: ‣ Central banks ‣ Central governments ‣ Credit institutions ‣ Other financial corporations ‣ Non-financial corporations ‣ Households | H11: - | I11: - | J11: - | L11: INSTRUMENT-INTRNL_SGMNT Segundo LCM cada contrato tem apenas 1 segmento FINREP | M11: Mapeamento com LT fechado, mas parametrização pendente | O11: Tabela de parametrização: codemapping | P11: ‣ dd_field_id = "4" | Q11: dd_code | R11: ‣ Inicialmente para cada combinação dos campos "cempresa", "cbalcao", "cnumecta", "zdeposit" iremos recuperar o MAX(contraparte_i): ‣ Este campo MAX(contraparte_i) será traduzido através de uma ligação com o campo "dd_code" para obter o campo: dd_value | U11: Pragosa diz que o LCM já indicou reapontar a ct081_finrep para a fr004
Q12: dd_value
O13: cd_captools.ct081_finrep | P13: ‣ ref_date = data do report | Q13: cempresa
Q14: cbalcao
Q15: cnumecta
Q16: zdeposit
Q17: contraparte_i
A18: V_5 | B18: Risk parameters | C18: Total Risk Exposure Amount | D18: Numeric (euro) | E18: The total risk exposure amount of the instrument, calculated according to Articles 92(3) and 92(4) of Regulation (EU) No 575/2013 (CRR), where applicable. | F18: O montante total das posições em risco do instrumento, calculado de acordo com o artigo 92(3) e 92(4) do Regulamento (UE) No 575/2013 (CRR), quando aplicável. | H18: INSTRUMENT-RWA | I18: RWA | J18: RWA according to Regulation (EU) No 575/2013. | L18: INSTRUMENT-RWA | M18: Concluido | O18: cd_captools.ct013_rwa_princ | P18: ‣ ref_date = data do report ‣ flag_cons_cap = 1 ‣ exercicio = 'REAL' | Q18: s1emp | R18: ‣ Para cada Instrument Identifier é somada a: ‣ Média do campo "rwa_final" para cada par de campos "s1emp", "contra1" | S18: A agrupação é feita segundo o campo "Instrument Identifier" deste mesmo documento | U18: Dependendo do instrument id indicado, este campo deverá ser a soma do rwa_final
Q19: contra1
Q20: rwa_final
A21: V_6 | B21: Risk parameters | C21: CRR Loss given default | D21: Numeric. Basis points | E21: Current level of the ‘Loss given default’ of the loan, determined in accordance with Articles 161, 164, 179 and 181 of Regulation (EU) No 575/2013. | F21: Nível atual da "Loss given default" do empréstimo, determinado em conformidade com os artigos 161, 164, 179 e 181 do Regulamento (UE) No 575/2013. | H21: INSTRUMENT-LGD | I21: Regulatory LGD | J21: If differences between regulatory and internal LGD exist, use regulatory LGD (according to Regulation (EU) No 575/2013). In particular, in IRB-F use regulatory LGD values. | L21: INSTRUMENT-LGD | M21: Concluido | O21: cd_captools.ct013_rwa_princ | P21: ‣ ref_date = data do report ‣ flag_cons_cap = 1 ‣ exercicio = 'REAL' | Q21: s1emp | R21: ‣ Para cada Instrument Identifier é calculada a: ‣ Média ponderada do campo "lgdfinal" em relação à: ‣ Média do campo "ead_final_bruta" para cada par dos campos "s1emp", "contra1" | S21: A agrupação é feita segundo o campo "Instrument Identifier" deste mesmo documento | U21: Dependendo do instrument id indicado, este campo deverá ser a média ponderada de lgd_final por ead_final_bruta
Q22: contra1
Q23: ead_final_bruta
O24: cd_captools.ct014_rwa_irb | P24: ‣ ref_date = data do report | Q24: lgdfinal
A25: V_7 | B25: Risk parameters | C25: IFRS 9 Loss given default | D25: Numeric. Basis points | E25: Current level of the ‘Loss given default’ of the loan determined for accounting purposes. | F25: Nível atual da "Loss given default" do empréstimo determinado para efeitos contabilísticos. | H25: INSTRUMENT-IFRS9_LGD | I25: IFRS 9 accounting LGD | J25: IFRS 9 accounting Loss Given Default as at reference date for defaulted and non-defaulted exposures. In case the bank models time-depended LGD variable for non-defaulted exposures then 12-month LGD as at reference date regardless the classification as Stage 1 or 2 | L25: INSTRUMENT-IFRS9_LGD | M25: Concluido | O25: cd_captools.ifrs9_out_expected_loss_8_7 | P25: ‣ Apenas são trazidos os "contract_id"s que têm "exec_id_part" correspondente na tabela cd_captools.imcatf046_flag_fecho à data ("cmes") do report | Q25: contract_id | R25: ‣ Para cada Instrument Identifier é calculada a: ‣ Média ponderada do campo "lgd_ifrs9" em relação à: ‣ Média do campo "ead" para cada "contract_id" | S25: A agrupação é feita segundo o campo "Instrument Identifier" deste mesmo documento | U25: Tal como nos anteriores explorar porque é feita a média do ead
Q26: lgd_ifrs9
Q27: ead

Sheet LEGALP_COUNTERPARTIES
A1: SRB Counterparties Data Set for exposures to legal persons
A2: ID | B2: Categoria | C2: Coluna | D2: Tipo de dados | E2: Descrição | F2: Descrição - Português | H2: Mapeamentos Corporação (LT) | I2: Descrição (LT) | J2: Additional Guidance (LT) | L2: Comentários | M2: Estado especificação | O2: Fontes de Informação | P2: Filtros | Q2: Campo | R2: Regras de Preenchimento | S2: Agrupações | T2: Comentários reuniões
A3: V_2 | B3: Identification information | C3: Counterparty Identifier | D3: Alphanumeric | E3: Identifier applied to uniquely identify each counterparty. | F3: Identificador aplicado para identificar exclusivamente cada contraparte. | H3: ENTITY-ENTTY_ID | I3: Entity ID | J3: An identifier applied by the reporting agent to uniquely identify each counterparty. Each counterparty has a unique and exclusive counterparty identifier. This means that this value will not change over time and can never be used as the counterparty identifier for any other counterparty. | L3: ENTITY-ENTTY_ID | M3: Concluido | O3: cd_alm.al029_cnt_core_m | P3: ‣ ref_date = data do report | Q3: zcliente | R3: ‣ Direto | T3: Se se alterar o universo trazer o zcliente respetivo
A4: V_8 | B4: Risk parameters | C4: Current Internal Credit Rating/Scoring | D4: Numeric / alphanumeric | E4: Internal credit rating/scoring issued to the counterparty. | F4: Classificação/pontuação de crédito interna emitida para a contraparte. | H4: ENTITY-INTRNL_RTNG | I4: Internal rating at reference date | J4: Internal rating at the reference date according to Regulation (EU) No 575/2013. Please also add in sheet "Code List" the list of values used, i.e. bank-internal masterscale. | L4: ENTITY-INTRNL_RTNG Segundo o documento "Especificação - BCE Loan Tape - Internal Ratings_v1.4", é referido: "Nível do cliente: deverá ser consultada a tabela CD_CAPTOOLS.JM_CAL_IN_CL;" ou seja, vem do input Capital. | M4: Concluido | O4: cd_loan_tapes_bce.lt003_entity | P4: ‣ ref_date = data do report | Q4: intrnl_rtng | R4: ‣ Para cada Counterparty Identifier é obtido o: MAX(intrnl_rtng) | S4: A agrupação é feita segundo o campo "Counterparty Identifier" deste mesmo documento | T4: Explorar alternativas para ir buscar este campo
A5: V_9 | B5: Risk parameters | C5: External Credit rating | D5: Alphanumeric | E5: External credit rating issued to the counterparty at cut-off date. In case several ratings are assigned, the approach described in Art. 138 of the CRR applies. | F5: Rating de crédito externo emitido para a contraparte na data de corte. Caso sejam atribuídas diversas classificações, aplica-se a abordagem descrita no Art. 138 do CRR. | H5: ENTITY-EXTRNL_RTNG | I5: External rating | J5: External rating at the reference date. | L5: ENTITY-EXTRNL_RTNG | M5: Concluido | O5: cd_loan_tapes_bce.lt003_entity | P5: ‣ ref_date = data do report | Q5: extrnl_rtng | R5: ‣ Para cada Counterparty Identifier é obtido o: MAX(extrnl_rtng) | S5: A agrupação é feita segundo o campo "Counterparty Identifier" deste mesmo documento | T5: Explorar alternativas para ir buscar este campo
A6: V_10 | B6: Risk parameters | C6: IFRS 9 Probability of default/impairment | D6: Numeric. Basis points | E6: The probability of default/impairment is calculated in accordance with the requirements specific to probability of default (PD) estimation as laid down in the accounting framework. If PDs are produced at the instrument level only, the counterparty’s PD is to be reported as the exposure-weighted average PD across the PDs of all instruments of the counterparty. If, for a given counterparty, PDs are estimated for both the counterparty and (some of) the products of the counterparty, it is the counterparty’s PD which is to be reported. | F6: A probabilidade de incumprimento/imparidade é calculada de acordo com os requisitos específicos para a estimativa da probabilidade de incumprimento (PD) definidos no quadro contabilístico. Se as PDs forem produzidas apenas ao nível do instrumento, a PD da contraparte deve ser reportada como a PD média ponderada pela exposição entre as PD de todos os instrumentos da contraparte. Se, para uma determinada contraparte, forem estimadas PDs tanto para a contraparte como para (alguns dos) produtos da contraparte, é a PD da contraparte que deve ser reportada. | H6: ENTITY-PD_IFRS9_12M_RD | I6: 12-month PD at reporting date according to IFRS 9 | J6: 12-month PD at reference date which is used by the bank for computation of stage 1 ECL or for SICR assessment if bank use 12 month proxy for staging. If the PD is calculated on instruments level please provide an EAD weighted average. | L6: No documento de "Feedback Statement in response to the consultation on the SRB valuation data set" tem a seguinte nota sobre este campo: "‘Data Point V_10’, entitled ‘IFRS 9 Probability of default’, refers to PDs used for accounting purposes, being a 12-month PD for stage 1 exposures and a lifetime PD for stage 2 and 3 exposures as per the accounting framework." Email David Texugo (01/04/2024 17:23) Para algumas das operações em Stage 1 deve-se considerar PD lifetime também. Para operações em Stage 1 para as quais não é possível avaliar o SICR via variação de PD/Rating por PD/Rating origem inválido, o cálculo de provisões é lifetime, conforme pode ser verificado no campo loss_type. Com a exceção destas casuísticas, deve-se seguir a lógica que indicas. Adicionalmente Stage 3 deveria ter sempre PD 100%. Aparentemente, faz sentido criar um novo campo ("PD misto" ) na LT002_INSTRUMENT dado que se solicita um "misto" entre a PD 12m e a PD lifetime, assim: -Se stage 1 selecionar PD12M_IFRS9 da tabela BU_IFRS9.IFRS9_OUT_EXPECTED_LOSS_REPORTING (confirmar que neste campo já está incluída a lógica de David Texugo) -Se stage 2 selecionar PD_LT_IFRS9 da tabela BU_IFRS9.IFRS9_OUT_EXPECTED_LOSS_REPORTING -Se stage 3 forçar 1 Sugere-se criar o campo na LT002_INSTRUMENT e não na LT003_ENTITY porque após consultar a a LT003_ENTITY verificámos que existia o campo PD_IFRS9_12M_RD para o qual é usada a LT005_INSTR_ENT para Identificar todos os contratos onde o cliente é o 1º Titular, de seguida para cada cliente aplica-se uma média ponderada da PD em relação ao EAD (porque cada cliente pode ter vários contratos). Assim sugerimos replicar esta lógica para o novo campo "PD misto" adicionado na LT002_INSTRUMENT de forma a poder ser criado também um novo campo "PD misto" na LT003_ENTITY. Nota: Atenção que o campo PD_IFRS9_12M_RD apenas está a ser calculado para os Primeiros Titulares (provavelmente porque em IFRS9 também só calculam para os Primeiros Titulares) | M6: Por iniciar | O6: cd_captools.ct013_rwa_princ | P6: ‣ ref_date = data do report ‣ flag_cons_cap = 1 ‣ exercicio = 'REAL' | Q6: s1emp | R6: ‣ Este campo tem de ser calculado por fases: ‣ 1º - Calculamos o campo auxiliar "ead_final_liquida_grup": ‣ Para cada combinação dos campos "cempresa", "cbalcao", "cnumecta", "zdeposit" iremos SOMAR as: Médias do campo "ead_final_liquida" para cada par dos campos "s1emp", "contra1"; ‣ 2º - Calculamos o campo auxiliar "final_stage_grup": ‣ Para cada combinação dos campos "cempresa", "cbalcao", "cnumecta", "zdeposit" iremos calcular "final_stage" máximo: MAX(final_stage); ‣ 3º - Calculamos o campo auxiliar "pd12m_ifrs9_grup": ‣ Para cada combinação dos campos "cempresa", "cbalcao", "cnumecta", "zdeposit" iremos calcular a média ponderada do campo "pd12m_ifrs9" ao campo "ead": SUM(ead * pd12m_ifrs9) / SUM(ead); ‣ 4º - Calculamos o campo auxiliar "pd_lt_ifrs9_grup": ‣ Para cada combinação dos campos "cempresa", "cbalcao", "cnumecta", "zdeposit" iremos calcular a média ponderada do campo "pd_lt_ifrs9" ao campo "ead": SUM(pd_lt_ifrs9 * ead) / SUM(ead); ‣ 5º - Calculamos o campo auxiliar "pd_ifrs9_grup": ‣ Se final_stage_grup = '1': pd12m_ifrs9_grup; ‣ Caso contrário: pd_lt_ifrs9_grup; ‣ Finalmente para cada Counterparty Identifier calculamos a média ponderada do campo auxiliar "pd_ifrs9_grup" ao campo auxiliar "ead_final_liquida_grup": SUM(pd_ifrs9_grup * ead_final_liquida_grup) / SUM(ead_final_liquida_grup) | S6: A agrupação final é feita segundo o campo "Counterparty Identifier" deste mesmo documento | T6: Esta lógica pode mudar se o Instrument Identifier for redefinido. Explorar também a média do ead_liquida
Q7: contra1
Q8: ead_final_liquida
O9: cd_alm.al029_cnt_core_m | P9: ‣ ref_date = data do report | Q9: cempresa
Q10: cbalcao
Q11: cnumecta
Q12: zdeposit
O13: ifrs9_out_expected_loss_8_7 | P13: ‣ Apenas são trazidos os "contract_id"s que têm "exec_id_part" correspondente na tabela cd_captools.imcatf046_flag_fecho à data ("cmes") do report | Q13: pd12m_ifrs9
Q14: pd_lt_ifrs9
Q15: ead
O16: ifrs9_out_staging_8_7 | P16: ‣ Apenas são trazidos os "contract_id"s que têm "exec_id_part" correspondente na tabela cd_captools.imcatf046_flag_fecho à data ("cmes") do report | Q16: final_stage
A17: V_11 | B17: Risk parameters | C17: Probability of default (others) | D17: Numeric. Basis points | E17: Applicable only to institutions not using CRR IRB models. These institutions should maintain records of probabilities of default or scores provided by scoring/rating models. In the case of PDs produced at the instrument level only, the counterparty’s PD is to be reported as the exposure-weighted average PD across the PDs of all instruments of the counterparty. If, for a given counterparty, PDs are estimated for both the counterparty and (some of) the products of the counterparty, it is the counterparty’s PD which is to be reported. | F17: Aplicável apenas a instituições que não utilizam modelos CRR IRB. Estas instituições devem manter registos das probabilidades de incumprimento ou das pontuações fornecidas pelos modelos de pontuação/rating. No caso de PDs produzidas apenas ao nível do instrumento, a PD da contraparte deve ser relatada como a PD média ponderada pela exposição entre as PDs de todos os instrumentos da contraparte. Se, para uma determinada contraparte, forem estimadas PDs tanto para a contraparte como para (alguns dos) produtos da contraparte, é a PD da contraparte que deve ser reportada. | H17: - | I17: - | J17: - | L17: Este campo é Not Applicable, reportar: 11111111111 | M17: Concluido | O17: N/A | P17: N/A | Q17: N/A | R17: N/A | S17: N/A

Sheet LEGALP_PROTECTIONS
A1: SRB Protection received Data Set for exposures to legal persons
A2: ID | B2: Categoria | C2: Coluna | D2: Tipo de dados | E2: Descrição | F2: Descrição - Português | H2: Mapeamentos Corporação (LT) | I2: Descrição (LT) | J2: Additional Guidance (LT) | L2: Comentários | M2: Estado especificação | O2: Fontes de Informação | P2: Filtros | Q2: Campo | R2: Regras de Preenchimento | S2: Agrupações | T2: Comentários reuniões
A3: V_12 | B3: Identification information | C3: Protection identifier | D3: Alphanumeric | E3: An identifier applied to uniquely identify each protection/collateral used to secure the instrument. | F3: Um identificador aplicado para identificar exclusivamente cada proteção/garantia utilizada para garantir o instrumento. | H3: PROTECTION-PRTCTN_ID | I3: Protection ID | J3: An identifier applied by the reporting agent to uniquely identify each protection used to secure the instrument. Each protection must have one protection identifier. This value will not change over time and cannot be used as the protection identifier for any other protection. | L3: PROTECTION-PRTCTN_ID | M3: Concluido | O3: cd_captools.fr003_colaterais | P3: ‣ ref_date = data do report | Q3: cempresa | R3: ‣ Concatenação dos campos mencionados anteriormente: cempresa + cbalcao_caucao + cnumecta_caucao + zcaucao | T3: Ver se não devemos ir antes às tabelas de garantias (gts)
Q4: cbalcao_caucao
Q5: cnumecta_caucao
Q6: zcaucao
A7: V_1 | B7: Identification information | C7: Instrument Identifier | D7: Alphanumeric | E7: An identifier applied to uniquely identify each instrument. Each instrument must have one instrument identifier. | F7: Um identificador aplicado para identificar exclusivamente cada instrumento. Cada instrumento deve ter um identificador de instrumento. | H7: Not applicable: To be reported as "N/A". This information will be availabe in "01_05_leg_instr_prot" table | I7: - | J7: - | L7: Not applicable: To be reported as "N/A". This information will be availabe in "01_05_leg_instr_prot" table | M7: Concluido | O7: cd_alm.kt_chaves_alm_m | P7: ‣ ref_date = data do report | Q7: cempresa | R7: ‣ Concatenação dos campos mencionados anteriormente: cempresa + cbalcao + cnumecta + zdeposit | T7: Após reunião com LCM foi indicado que este campo deveria ser na mesma o cempresa … zeposit mas da tabela fr001/fr004 em vez da al029 isto porque tendo que conciliar com o finrep, faz sentido que tenha a mesma granularidade
Q8: cbalcao
Q9: cnumecta
Q10: zdeposit
A11: V_187 | B11: Identification information | C11: Type of collateral | D11: String | E11: The AnaCredit item “type of protection” (Section 9.4.3. of the Anacredit Reporting Manual part II - Dataset and data attributes) provides a breakdown of collateral eligible in accordance with the CRR. The proposed breakdown adds several categories. Options: ‣ Gold ‣ Currency and deposits ‣ Securities ‣ Loans ‣ Equity and investment fund shares or units ‣ Credit derivatives ‣ Financial guarantees other than credit derivatives ‣ Trade receivables ‣ Life insurance policies pledged ‣ Residential real estate collateral ‣ Offices and commercial premises ‣ Commercial real estate collateral ‣ Other physical collateral ‣ Other protection ‣ Hotels & entertainment ‣ Infrastructure projects ‣ Factories – warehouses ‣ Equipment & machinery ‣ Automotive ‣ Aircraft ‣ Shipping | F11: O item "type of protection" da AnaCredit (Secção 9.4.3. do Anacredit Reporting Manual parte II - Dataset and data attributes) fornece uma discriminação das garantias elegíveis de acordo com o CRR. A repartição proposta acrescenta diversas categorias. Opções: ‣ Gold ‣ Currency and deposits ‣ Securities ‣ Loans ‣ Equity and investment fund shares or units ‣ Credit derivatives ‣ Financial guarantees other than credit derivatives ‣ Trade receivables ‣ Life insurance policies pledged ‣ Residential real estate collateral ‣ Offices and commercial premises ‣ Commercial real estate collateral ‣ Other physical collateral ‣ Other protection ‣ Hotels & entertainment ‣ Infrastructure projects ‣ Factories – warehouses ‣ Equipment & machinery ‣ Automotive ‣ Aircraft ‣ Shipping | H11: PROTECTION-TYP_PRTCTN | I11: Protection type | J11: Type of protection received, irrespective of its eligibility for credit risk mitigation. | L11: PROTECTION-TYP_PRTCTN | M11: Mapeamento com LT fechado, mas parametrização pendente | O11: Tabela de parametrização: codemapping | P11: ‣ dd_field_id = "187" | Q11: dd_code | R11: ‣ Tradução do campo "typ_prtctn" através de uma ligação com o campo "dd_code" para obter o campo: dd_value
Q12: dd_value
O13: cd_loan_tapes_bce.lt004_protection | P13: ‣ ref_date = data do report | Q13: typ_prtctn
A14: V_14 | B14: Size collateral | C14: Building Area (M2) | D14: Numeric | E14: Building area of the building in square metres. Only applicable to Residential real estate collateral, Offices and commercial premises, Commercial real estate collateral, Hotels & entertainment, Factories – warehouses. | F14: Área de construção do edifício em metros quadrados. Aplicável apenas a Garantias imobiliárias residenciais, Escritórios e instalações comerciais, Garantias imobiliárias comerciais, Hotéis e entretenimento, Fábricas – armazéns. | H14: - | I14: - | J14: - | L14: ‣ Não encontramos no LT -> Confirmar com Nádia Ahmad e Dora Roxo; ‣ Segundo Luís Capitão-Mor, estes campos deverão vir do MUG (Modelo Único de Garantias). ‣ Reunião Alexandre Dionísio Esteves (08-04-2024): 1) Estes campos ainda não existem no MUG. 2) Esta informação existe na GPT32, embora nessa tabela estes campos não sejam de preenchimento obrigatório, como tal, existem GAPs de informação. 3) Foi-nos também comentado que o universo completo de imóveis está na tabela gpt18 os quais não estão 100% mapeados na gpt32. 4) Alexandre irá analisar em detalhe e irá marcar reunião com Luís Capitão-Mor para a semana de 15/04/2024 | M14: Novo campo, mapeamento datalake pendente, sem necessidade de criar parametrização | R14: ‣ Forçado a NULL | T14: É necessário verificar onde existe esta informação (ex: cd_emprestimos.gpt32_bemimove)
A15: V_15 | B15: Size collateral | C15: Land Area (M2) | D15: Numeric | E15: Land area of the property in square metres, including any land surrounding the building(s) on the property that is part of the property. | F15: Área do terreno do imóvel em metros quadrados, incluindo qualquer terreno ao redor do(s) edifício(s) do imóvel que faz parte do imóvel. | H15: - | I15: - | J15: - | L15: ‣ Não encontramos no LT -> Confirmar com Nádia Ahmad e Dora Roxo; ‣ Segundo Luís Capitão-Mor, estes campos deverão vir do MUG (Modelo Único de Garantias). ‣ Reunião Alexandre Dionísio Esteves (08-04-2024): 1) Estes campos ainda não existem no MUG. 2) Esta informação existe na GPT32, embora nessa tabela estes campos não sejam de preenchimento obrigatório, como tal, existem GAPs de informação. 3) Foi-nos também comentado que o universo completo de imóveis está na tabela gpt18 os quais não estão 100% mapeados na gpt32. 4) Alexandre irá analisar em detalhe e irá marcar reunião com Luís Capitão-Mor para a semana de 15/04/2024 | M15: Novo campo, mapeamento datalake pendente, sem necessidade de criar parametrização | R15: ‣ Forçado a NULL
A16: V_16 | B16: Location | C16: Property postcode | D16: Numeric | E16: Postcode where the property is located. Only applicable to Residential real estate collateral, Offices and commercial premises, Commercial real estate collateral, Hotels & entertainment, Factories – warehouses. | F16: Código postal onde o imóvel está localizado. Aplicável apenas a Garantias imobiliárias residenciais, Escritórios e instalações comerciais, Garantias imobiliárias comerciais, Hotéis e entretenimento, Fábricas – armazéns. | H16: PROTECTION-RL_ESTT_PST_CD | I16: Post code / ZIP | J16: Post code / ZIP. | L16: PROTECTION-RL_ESTT_PST_CD | M16: Concluido | O16: cd_loan_tapes_bce.lt004_protection | P16: ‣ ref_date = data do report | Q16: rl_estt_pst_cd | R16: ‣ Direto
A17: V_17 | B17: Lien | C17: Lien position | D17: Numeric | E17: The highest ranking position(s) in relation to the collateral held by the counterparty to secure the facility. If the facility has several liens on one collateral, the highest claim is reported in this data field. | F17: A(s) posição(ões) mais elevada(s) em relação às garantias detidas pela contraparte para garantir a instalação. Se a instalação tiver vários ônus sobre uma garantia, a reivindicação mais alta será relatada neste campo de dados. | H17: - | I17: - | J17: - | L17: ‣ Não encontramos no LT -> Confirmar com Nádia Ahmad e Dora Roxo; [Reunião 2024-04-08] Segundo Luís Capitão-Mor, o Banco só aceita primeiras hipotecas, como tal, este campo deverá ser sempre preenchido com '1'. | M17: Novo campo, mapeamento datalake fechado, sem necessidade de criar parametrização | O17: cd_loan_tapes_bce.lt006_instr_prot | P17: ‣ ref_date = data do report | Q17: thrd_prty_prrty_clms | R17: ‣ Direto | T17: Confirmar se este é o campo correto para recuperar esta informação
A18: V_18 | B18: Collateral characteristics | C18: Detailed type of Shipping collateral | D18: String | E18: Detailed type of collateral received. Applicable only to shipping portfolios. Options: ‣ Bulker (1) ‣ Container (2) ‣ Crude Oil Tanker (3) ‣ Product Tanker (4) ‣ Chemical Tanker (5) ‣ Cruise Ship (6) ‣ Ferry (7) ‣ LPG Carrier (8) ‣ Offshore (9) ‣ Other (10) | F18: Tipo detalhado de garantia recebida. Aplicável apenas a portfólios de remessa. Opções: ‣ Bulker (1) ‣ Container (2) ‣ Crude Oil Tanker (3) ‣ Product Tanker (4) ‣ Chemical Tanker (5) ‣ Cruise Ship (6) ‣ Ferry (7) ‣ LPG Carrier (8) ‣ Offshore (9) ‣ Other (10) | H18: - | I18: - | J18: - | L18: ‣ emaill 22/04/2024 20:17 Rute Ferreira com o Histórico de conversações: - Carmo Rodrigues não conseguiu esclarecer as 3 questões endereçadas. ‣ email 23/04/2024 20:24 de Paulo Oliveira: 1) Não tenho conhecimento que existam shipping portfolios no Banco, confirmas? Pode ser que seja categorizado pelo Banco de outra forma. Asset lending não, mas não descartava que houvesse alguns barcos financiados em leasing nomeadamente para empresas do sector. Perguntava á Leasing. Não sei se não haverá como colateral algum cliente que tenha dado o seu barco de recreio (iate). 2) Se eventualmente existisse uma Empresa que quisesse dar alguma destas opções como colateral, o Banco aceitava? Sim, são activos com valor de mercado. Tal como aceitamos aviões, aceitariamos navios como colateral 3) Em caso afirmativo ao ponto 2), sabes de algum caso em concreto para que possa ir verificar e ver como fica registado no Banco? Não me lembro de nenhum Acho que deveramos ir analisar as empresas de navegação com frota. | M18: Novo campo, mapeamento datalake pendente, com necessidade de criar parametrização | O18: N/A | P18: N/A | Q18: N/A | R18: N/A | S18: N/A | T18: Não existe este genero de operativa

Sheet LEGALP_INSTRUMENT_COUNTERPARTY
A1: SRB Instrument/Counterparty mapping Data Set for exposures to legal persons
A2: ID | B2: Categoria | C2: Coluna | D2: Tipo de dados | E2: Descrição | F2: Descrição - Português | H2: Mapeamentos Corporação (LT) | I2: Descrição (LT) | J2: Additional Guidance (LT) | L2: Comentários | M2: Estado especificação | O2: Fontes de Informação | P2: Filtros | Q2: Campo | R2: Regras de Preenchimento | S2: Agrupações | T2: Comentários reuniões
