Workbook

Sheet Análise Campos BA
B6: 1. Análise do preenchimento dos campos do âmbito GD, tabela instrument para contratos BA
B8: Análise do modo de preenchimento dos campos que têm mais do que uma business area associada. Preencher apenas
B10: Table | C10: Data field | D10: BA principal | E10: Preencher para contratos com sufixo BA? | F10: Observações
B11: lt002_instrument | C11: COD_SOC | D11: Y | E11: Y
B12: lt002_instrument | C12: SUBPORTFOLIO_ID | D12: Y | E12: Preencher com not applicable | F12: passar para N a pedido do LCM
B13: lt002_instrument | C13: DT_RFRNC | D13: Y | E13: Y
B14: lt002_instrument | C14: INSTRMNT_ID | D14: Y | E14: Y
B15: lt002_instrument | C15: DFLT_STTS_INSTRMNT | D15: Y | E15: Preencher com not applicable
B16: lt002_instrument | C16: IMPRMNT_STTS | D16: Y | E16: Preencher com not applicable
B17: lt002_instrument | C17: PRFRMNG_STTS | D17: Y | E17: Preencher com not applicable
B18: lt002_instrument | C18: TYP_INSTRMNT | D18: Y | E18: Preencher com not applicable
B19: lt002_instrument | C19: GRSS_CRRYNG_AMNT_INSTRMNT | D19: Y | E19: Preencher com not applicable
B20: lt002_instrument | C20: ACCMLTD_CHNGS_FV_CR_INSTRMNT | D20: Y | E20: Preencher com not applicable | F20: Campo preenchido como not applicable para linha principal
B21: lt002_instrument | C21: ACCNTNG_CLSSFCTN | D21: Y | E21: Preencher com not applicable
B22: lt002_instrument | C22: CCF | D22: Y | E22: Preencher com not applicable | F22: Campo preenchido como not applicable para linha principal
B23: lt002_instrument | C23: EAD | D23: Y | E23: Preencher com not applicable | F23: Campo preenchido como not applicable para linha principal
B24: lt002_instrument | C24: OFF_BLNC_SHT_AMNT_INSTRMNT | D24: Y | E24: Preencher com not applicable
B25: lt002_instrument | C25: PRVSNS_OFF_BLNC_SHT | D25: Y | E25: Preencher com not applicable
B26: lt002_instrument | C26: RWA | D26: Y | E26: Preencher com not applicable
B27: lt002_instrument | C27: ACCMLTD_IMPRMNT_INSTRMNT | D27: Y | E27: Preencher com not applicable
B28: lt002_instrument | C28: COD_SOC_INTRGRP | D28: Y | E28: Preencher com not applicable | F28: passar para N a pedido do LCM
B29: lt002_instrument | C29: LCL_INSTMRNT_ID | D29: Y | E29: Y
B30: lt002_instrument | C30: AVRG_BLNC | D30: Y | E30: Y
B31: lt002_instrument | C31: NW_BSNSS | D31: Y | E31: Y | F31: confirmar
B32: lt002_instrument | C32: GRSS_INTRST_INCM | D32: Y | E32: Y
B33: lt002_instrument | C33: GRSS_CMMSSN_INCM | D33: Y | E33: Y
B34: lt002_instrument | C34: INTRNL_TRNSFR_RT | D34: Y | E34: Y
B35: lt002_instrument | C35: NT_LN_LSS_PRVSN | D35: Y | E35: Y
B36: lt002_instrument | C36: BSNSS_AREA | D36: Y | E36: Y
B37: lt002_instrument | C37: MNGMNT_PRDCT | D37: Y | E37: Y
B38: lt002_instrument | C38: GRSS_CMMSSN_EXPNS | D38: Y | E38: Y
B39: lt002_instrument | C39: GNS_FNNCL_TRNSCTN_EXCHNG_DFFRNCS | D39: Y | E39: Y
B40: lt002_instrument | C40: FLG_INTRBSNSS | D40: Y | E40: Preencher com not applicable
B41: lt002_instrument | C41: INTRBSNSS_ADJ_COD | D41: Y | E41: Preencher com not applicable | F41: Campo preenchido como not applicable para linha principal
B42: lt002_instrument | C42: COD_SOC_DSTNTN | D42: Y | E42: Preencher com not applicable | F42: Campo preenchido como not applicable para linha principal
B43: lt002_instrument | C43: BSNSS_AREA_DSTNTN | D43: Y | E43: Preencher com not applicable | F43: Campo preenchido como not applicable para linha principal
B44: lt002_instrument | C44: AVRG_BLNC_OFF_BLNC | D44: Y | E44: Y
B45: lt002_instrument | C45: INTRNL_TRNSFR_RT_OFF_BLNC | D45: Y | E45: Preencher com not applicable | F45: Campo preenchido como not applicable para linha principal
B46: lt002_instrument | C46: GRSS_CMMSSN_INCM_OFF_BLNC | D46: Y | E46: Y
B47: lt002_instrument | C47: GRSS_CMMSSN_EXPNS_OFF_BLNC | D47: Y | E47: Y
...

Sheet Email Corp
B3: Table | C3: Data field | D3: Completar los contratos con un sufijo de business area?
B4: INSTRUMENT | C4: COD_SOC | D4: Y | E4: =+VLOOKUP(C4,Auxiliar!$C$2:$D$52,2,FALSE) -> Default value not allowed
B5: INSTRUMENT | C5: SUBPORTFOLIO_ID | D5: N | E5: =+VLOOKUP(C5,Auxiliar!$C$2:$D$52,2,FALSE) -> Default value not allowed
B6: INSTRUMENT | C6: DT_RFRNC | D6: Y | E6: =+VLOOKUP(C6,Auxiliar!$C$2:$D$52,2,FALSE) -> Default value not allowed
B7: INSTRUMENT | C7: INSTRMNT_ID | D7: Y | E7: =+VLOOKUP(C7,Auxiliar!$C$2:$D$52,2,FALSE) -> Default value not allowed
B8: INSTRUMENT | C8: DFLT_STTS_INSTRMNT | D8: N | E8: =+VLOOKUP(C8,Auxiliar!$C$2:$D$52,2,FALSE) -> Default value not allowed
B9: INSTRUMENT | C9: IMPRMNT_STTS | D9: N | E9: =+VLOOKUP(C9,Auxiliar!$C$2:$D$52,2,FALSE) -> 11111111111
B10: INSTRUMENT | C10: PRFRMNG_STTS | D10: N | E10: =+VLOOKUP(C10,Auxiliar!$C$2:$D$52,2,FALSE) -> Default value not allowed
B11: INSTRUMENT | C11: TYP_INSTRMNT | D11: N | E11: =+VLOOKUP(C11,Auxiliar!$C$2:$D$52,2,FALSE) -> Default value not allowed
B12: INSTRUMENT | C12: GRSS_CRRYNG_AMNT_INSTRMNT | D12: N | E12: =+VLOOKUP(C12,Auxiliar!$C$2:$D$52,2,FALSE) -> 11111111111
B13: INSTRUMENT | C13: ACCMLTD_CHNGS_FV_CR_INSTRMNT | D13: N | E13: =+VLOOKUP(C13,Auxiliar!$C$2:$D$52,2,FALSE) -> 11111111111
B14: INSTRUMENT | C14: ACCNTNG_CLSSFCTN | D14: N | E14: =+VLOOKUP(C14,Auxiliar!$C$2:$D$52,2,FALSE) -> 11111111111
B15: INSTRUMENT | C15: CCF | D15: N | E15: =+VLOOKUP(C15,Auxiliar!$C$2:$D$52,2,FALSE) -> 11111111111
... B54: INSTRUMENT | C54: TYP_OFF_BLNC_PRDCT | D54: N | E54: =+VLOOKUP(C54,Auxiliar!$C$2:$D$52,2,FALSE) -> N/A

Sheet Auxiliar
D1: NOT APPLICABLE
B2: INSTRUMENT | C2: AVRG_BLNC_OFF_BLNC | D2: 11111111111
B3: INSTRUMENT | C3: AVRG_BLNC | D3: 11111111111
B4: INSTRUMENT | C4: NW_BSNSS | D4: Default value not allowed
B5: INSTRUMENT | C5: GRSS_INTRST_INCM | D5: 11111111111
B6: INSTRUMENT | C6: GRSS_CMMSSN_INCM | D6: 11111111111
B7: INSTRUMENT | C7: INTRNL_TRNSFR_RT | D7: 11111111111
B8: INSTRUMENT | C8: NT_LN_LSS_PRVSN | D8: 11111111111
B9: INSTRUMENT | C9: BSNSS_AREA | D9: Default value not allowed
B10: INSTRUMENT | C10: MNGMNT_PRDCT | D10: Default value not allowed
B11: INSTRUMENT | C11: GRSS_CMMSSN_EXPNS | D11: 11111111111
B12: INSTRUMENT | C12: GNS_FNNCL_TRNSCTN_EXCHNG_DFFRNCS | D12: 11111111111
B13: INSTRUMENT | C13: FLG_INTRBSNSS | D13: Default value not allowed
B14: INSTRUMENT | C14: INTRBSNSS_ADJ_COD | D14: N/A
B15: INSTRUMENT | C15: COD_SOC_DSTNTN | D15: 00000
B16: INSTRUMENT | C16: BSNSS_AREA_DSTNTN | D16: N/A
B17: INSTRUMENT | C17: INTRNL_TRNSFR_RT_OFF_BLNC | D17: 11111111111
B18: INSTRUMENT | C18: GRSS_CMMSSN_INCM_OFF_BLNC | D18: 11111111111
B19: INSTRUMENT | C19: GRSS_CMMSSN_EXPNS_OFF_BLNC | D19: 11111111111
B20: INSTRUMENT | C20: RWA_OFF_BLNC | D20: Default value not allowed
B21: INSTRUMENT | C21: GRSS_INTRST_EXPNS | D21: 11111111111
B22: INSTRUMENT | C22: NT_LN_LSS_PRVSN_OFF_BLNC | D22: 11111111111
B23: INSTRUMENT | C23: GRSS_INTRST_INCM_CCRR | D23: 11111111111
B24: INSTRUMENT | C24: GRSS_INTRST_EXPNS_CCRR | D24: 11111111111
B25: INSTRUMENT | C25: GRSS_CMMSSN_INCM_CCRR | D25: 11111111111
B26: INSTRUMENT | C26: GRSS_CMMSSN_EXPNS_CCRR | D26: 11111111111
B27: INSTRUMENT | C27: GNS_FNNCL_TRNSCTN_EXCHNG_CCRR | D27: 11111111111
B28: INSTRUMENT | C28: BSNSS_AREA_CCRR | D28: Default value not allowed
B29: INSTRUMENT | C29: GRSS_CMMSSN_INCM_OFF_BLNC_CCRR | D29: 11111111111
B30: INSTRUMENT | C30: GRSS_CMMSSN_EXPNS_OFF_BLNC_CCRR | D30: 11111111111
B31: INSTRUMENT | C31: COD_SOC | D31: Default value not allowed
B32: INSTRUMENT | C32: SUBPORTFOLIO_ID | D32: Default value not allowed
B33: INSTRUMENT | C33: DT_RFRNC | D33: Default value not allowed
B34: INSTRUMENT | C34: INSTRMNT_ID | D34: Default value not allowed
B35: INSTRUMENT | C35: DFLT_STTS_INSTRMNT | D35: Default value not allowed
B36: INSTRUMENT | C36: IMPRMNT_STTS | D36: 11111111111
B37: INSTRUMENT | C37: PRFRMNG_STTS | D37: Default value not allowed
B38: INSTRUMENT | C38: TYP_INSTRMNT | D38: Default value not allowed
B39: INSTRUMENT | C39: GRSS_CRRYNG_AMNT_INSTRMNT | D39: 11111111111
B40: INSTRUMENT | C40: ACCMLTD_CHNGS_FV_CR_INSTRMNT | D40: 11111111111
...
