Workbook
Name _b81494: #REF!
Name Impact_flag: #REF!
Name Index: #REF!
Name IndexArray: #REF!
Name IQ_CH: 110000
Name IQ_CQ: 5000
Name IQ_CY: 10000
Name IQ_DAILY: 500000
Name IQ_FH: 100000
Name IQ_FQ: 500
Name IQ_FY: 1000
Name IQ_LTM: 2000
Name IQ_MONTH: 15000
Name IQ_NTM: 6000
Name IQ_WEEK: 50000
Name IQ_YTD: 3000
Name LatestChange: #REF!
Name LatestPerson: #REF!
Name LatestVersion: #REF!
Name ModelName: #REF!
Name Quality_flag: #REF!
Name Risk_flag: #REF!
Name Status_Checking: #REF!
Name Status_Overall: #REF!
Name Status_Update: #REF!
Name Team: #REF!
Name YesNo: #REF!

Sheet SCIB
B2: BUSINESS LOANS: EMISSIONS CALCULATED FROM SCIB INFO.
E7: To be filled out by HQ
B8: GLCS Code | C8: NACE CODE | D8: Gross Carrying Amount (M€) | E8: SCOPE 1 REPORTED | F8: SCOPE 2 REPORTED | G8: SCOPE 3 REPORTED | H8: Total Debt | I8: Total Equity | J8: SCOPE 1 FINANCED EMISSIONS | K8: SCOPE 2 FINANCED EMISSIONS | L8: SCOPE 3 FINANCED EMISSIONS
B9: IBR00 | C9: 35.11 | D9: 1000 | E9: 11270639 | F9: 1893116 | G9: 55597710 | H9: 51525 | I9: 58114 | J9: 102797.72 | K9: 17266.812 | L9: 507097.93
G25: Dúvidas | H25: SCIB com DQS4 ou DQS5 entra aqui? // Se scope 1 for DQS2, mas scope 3 for DQS5 entra?
B26: *Units need to fill out the columns in red, columns in grey will be filled out by HQ | H26: SCIB pode ser cruzado com input por clei -> Estes casos, assumo o KGL do input corporativo?
G27: Assumption | H27: Não entra emissões calculadas por MVL ou RE, mesmo que o cliente seja SCIB
H28: Nace vou tirar letra e último ponto

Sheet DQS4
B2: BUSINESS LOANS: EMISSIONS ESTIMATED BY PCAF DQS4
E7: To be filled out by HQ
B8: Region | C8: NACE CODE | D8: Gross Carrying Amount (in Million €) | E8: PCAF FACTOR S1 | F8: PCAF FACTOR S2 | G8: PCAF FACTOR S3 | H8: Total Debt (in Million €) | I8: Total Equity (in Million €) | J8: Total Revenue (in Million €) | K8: SCOPE 1 FINANCED EMISSIONS | L8: SCOPE 2 FINANCED EMISSIONS | M8: SCOPE 3 FINANCED EMISSIONS
B9: European Union | C9: 06.10 | D9: 1000 | E9: 1571.88 | F9: 204.756 | G9: 786.716 | H9: 500 | I9: 1000 | J9: 600 | K9: 1.7465333 | L9: 0.22750667 | M9: 0.87412889
B26: *Units need to fill out the columns in red, columns in grey will be filled out by HQ | F26: Dúvidas | G26: DQS4 de MVL e RE entra aqui? Se entrar, puxo valor para debt, equity e revenues, ou vai a zero? | H26: Não entra

Sheet Sheet6
B2: origem_scp1_emss | C2: origem_scp2_emss | D2: origem_scp3_emss
B3: BCL_DQS1_SCIB | C3: BCL_DQS2_SCIB | D3: BCL_DQS1_SCIB
B4: BCL_DQS1_SCIB | C4: BCL_DQS1_SCIB | D4: BCL_DQS1_SCIB
B5: BCL_DQS1_SCIB | C5: BCL_DQS2_SCIB | D5: BCL_DQS4_SCIB
B6: BCL_DQS1_SCIB | C6: BCL_DQS1_SCIB | D6: BCL_DQS4_SCIB
B7: BCL_DQS2_SCIB | C7: BCL_DQS2_SCIB | D7: BCL_DQS4_SCIB
B8: BCL_DQS4_3A | C8: BCL_DQS4_3A | D8: BCL_DQS4_3A
B9: BCL_DQS4_SCIB | C9: BCL_DQS2_SCIB | D9: BCL_DQS4_SCIB
B10: BCL_DQS4_SCIB | C10: BCL_DQS1_SCIB | D10: BCL_DQS4_SCIB
B11: BCL_DQS5_3B | C11: BCL_DQS5_3B | D11: BCL_DQS5_3B
B12: MISS | C12: MISS | D12: Nao Aplicavel
B13: MISS | C13: MISS | D13: MISS
... B29: RE_DQS5_3 | C29: RE_DQS5_3 | D29: Nao Aplicavel

Sheet DQS5
B2: BUSINESS LOANS: EMISSIONS ESTIMATED BY PCAF DQS5
E7: To be filled out by HQ
B8: Region | C8: NACE CODE | D8: Gross Carrying Amount (in Million €) | E8: PCAF FACTOR S1 | F8: PCAF FACTOR S2 | G8: PCAF FACTOR S3 | H8: SCOPE 1 FINANCED EMISSIONS | I8: SCOPE 2 FINANCED EMISSIONS | J8: SCOPE 3 FINANCED EMISSIONS
B9: European Union | C9: 06.10 | D9: 1000 | E9: 1571.88 | F9: 204.756 | G9: 786.716 | H9: 1.7465333 | I9: 0.22750667 | J9: 0.87412889
B26: *Units need to fill out the columns in red, columns in grey will be filled out by HQ

Sheet Auxiliar >>

Sheet 1. Input Junho 2025
A1: ccli_kgl | B1: nome_grupo | C1: isin | D1: clei | E1: scp1_emss | F1: scp2_emss | G1: scp3_emss | H1: score_scp1 | I1: score_scp2 | J1: score_scp3 | K1: ano_info | L1: origem_scp1 | M1: origem_scp2 | N1: origem_scp3 | O1: divida_total | P1: capital_proprio
A2: 3MGRG | B2: 3M | C2: US88579Y1010 | D2: LUZQVYP4VS22CLWDAR65 | E2: 2420000 | F2: 1460000 | G2: 72852902.489811 | H2: 1 | I2: 2 | J2: 4 | K2: 2023 | L2: Reported | M2: Reported | N2: Estimated | O2: 16894.94
A3: 22A2A | B3: A2A | C3: IT0001233417 | D3: 81560076E3944316DB24 | E3: 8882175 | F3: 183507 | G3: 27077885.803923 | H3: 1 | I3: 1 | J3: 4 | K3: 2023 | L3: Reported | M3: Reported | N3: Estimated | O3: 13275
A4: ABBBG | B4: ABB | C4: CH0012221716 | D4: 5493000LKVGOO9PELI61 | E4: 156000 | F4: 305000 | G4: 99031733.625942 | H4: 1 | I4: 1 | J4: 4 | K4: 2023 | L4: Reported | M4: Reported | N4: Estimated | O4: 22259.97
A5: ABTGG | B5: ABBOTT LABORATORIES | C5: US0028241000 | D5: HQD377W2YR662HK5JX27 | E5: 530000 | F5: 476000 | G5: 11963516 | H5: 1 | I5: 1 | J5: 4 | K5: 2023 | L5: Reported | M5: Reported | N5: Estimated | O5: 60807.55
A6: ABVIE | B6: ABBVIE GROUP | C6: US00287Y1091 | D6: FR5LCKFTG8054YNNRU85 | E6: 342607 | F6: 271055 | G6: 8063583.305804 | H6: 1 | I6: 1 | J6: 4 | K6: 2023 | L6: Reported | M6: Reported | N6: Estimated | O6: 68706.87
A7: 5CUMG | B7: ACCIONA | C7: ES0125220311 | D7: 54930002KP75TLLLNO21 | E7: 159652 | F7: 139733 | G7: 15545375.935379 | H7: 1 | I7: 1 | J7: 4 | K7: 2023 | L7: Reported | M7: Reported | N7: Estimated | O7: 18968
A8: 5ACXG | B8: ACCOR | C8: FR0000120404 | D8: 969500QZC2Q0TK11NV07 | E8: 344000 | F8: 2584000 | G8: 2169583.250466 | H8: 1 | I8: 1 | J8: 4 | K8: 2023 | L8: Reported | M8: Reported | N8: Estimated | O8: 9226
A9: ACRXG | B9: ACERINOX | C9: ES0132105018 | D9: 95980020140005582721 | E9: 872253 | F9: 1581947 | G9: 3735287.887073 | H9: 1 | I9: 1 | J9: 4 | K9: 2023 | L9: Reported | M9: Reported | N9: Estimated | O9: 4976
A10: CGYNG | B10: ACS - DRAGADOS | C10: ES0167050915 | D10: 95980020140005558665 | E10: 389195 | F10: 121602 | G10: 10332395 | H10: 1 | I10: 1 | J10: 4 | K10: 2023 | L10: Reported | M10: Reported | N10: Estimated | O10: 10423.53
A11: AB7WK | B11: ADECOAGRO | C11: LU0584671464 | D11: 529900Q00UR5LFELO811 | E11: 171338 | F11: 18643 | G11: 637667.091714 | H11: 4 | I11: 2 | J11: 4 | K11: 2023 | L11: Estimated | M11: Reported | N11: Estimated | O11: 2434.85
A12: AAP5K | B12: ADVANCE AUTO PARTS INC | C12: US00751Y1064 | D12: 529900UCNQ5H9FSL0Y70 | E12: 173157 | F12: 168878 | G12: 6065722.982578 | H12: 1 | I12: 1 | J12: 4 | K12: 2023 | L12: Reported | M12: Reported | N12: Estimated | O12: 6080.94
A13: AENAK | B13: AENA | C13: ES0105046009 | D13: 959800R7QMXKF0NFMT29 | E13: 19976 | F13: 164604 | G13: 3770063.24 | H13: 1 | I13: 1 | J13: 4 | K13: 2023 | L13: Reported | M13: Reported | N13: Estimated | O13: 15527.07
A14: AERCG | B14: AERCAP, GR | C14: NL0000687663 | D14: 549300SZYINBBLJQU475 | E14: 316 | F14: 265 | G14: 52500783.709817 | H14: 2 | I14: 2 | J14: 4 | K14: 2023 | L14: Reported | M14: Reported | N14: Estimated | O14: 60205.55
A15: AEYMX | B15: AEROMEXICO | C15: MX01AE010005 | E15: 3823270 | F15: 4364 | G15: 2012140.983574 | H15: 2 | I15: 1 | J15: 4 | K15: 2023 | L15: Reported | M15: Reported | N15: Estimated | O15: 3562.17
A16: AEPAR | B16: AEROPORTS DE PARIS | C16: FR0010340141 | D16: 969500PJMBSFHYC37989 | E16: 77785 | F16: 70609 | G16: 23315053 | H16: 1 | I16: 1 | J16: 4 | K16: 2023 | L16: Reported | M16: Reported | N16: Estimated | O16: 16225
A17: 5AEBG | B17: AES | C17: US00130H1059 | D17: 2NUNNB7D43COUIRE5295 | E17: 40011490 | F17: 515129 | G17: 2450793.622109 | H17: 2 | I17: 2 | J17: 4 | K17: 2023 | L17: Reported | M17: Reported | N17: Estimated | O17: 37533.09
A18: AGIZG | B18: AGILITY. TRISTAR | C18: KW0EQ0601041 | D18: 549300C16Q6C2NMAI063 | E18: 319009 | F18: 69238 | G18: 662065.568053 | H18: 4 | I18: 2 | J18: 4 | K18: 2023 | L18: Estimated | M18: Reported | N18: Estimated | O18: 11002.93
A19: 0W20G | B19: AIR FRANCE KLM | C19: FR001400J770 | D19: 969500AQW31GYO8JZD66 | E19: 22620100 | F19: 50700 | G19: 9621365.772297 | H19: 1 | I19: 1 | J19: 4 | K19: 2023 | L19: Reported | M19: Reported | N19: Estimated | O19: 15462
A20: ARLCG | B20: AIR LEASE CORPORATION | C20: US00912X3026 | D20: 5493004NW4M4P8TMMK63 | E20: 5599 | F20: 255 | G20: 47954246.865602 | H20: 2 | I20: 2 | J20: 4 | K20: 2023 | L20: Reported | M20: Reported | N20: Estimated | O20: 26702.55
A21: AIRPG | B21: AIR PRODUCTS | C21: US0091581068 | D21: 7QEON6Y1RL5XR3R1W237 | E21: 16800000 | F21: 9700000 | G21: 22395466.965968 | H21: 1 | I21: 1 | J21: 4 | K21: 2023 | L21: Reported | M21: Reported | N21: Estimated | O21: 32457
A22: 00027 | B22: AIR TRANSPORT SERVICES GROUP, GR | C22: US00922R1059 | D22: 5493000F3MSFGIXTQE27 | E22: 1606250.46 | F22: 4653.93 | G22: 720635.723355 | H22: 4 | I22: 4 | J22: 4 | K22: 2023 | L22: Estimated | M22: Estimated | N22: Estimated | O22: 2970.91
A23: 5EEDG | B23: AIRBUS | C23: NL0000235190 | D23: MINO79WLOO247M1IL051 | E23: 554801 | F23: 301809 | G23: 439424869.893171 | H23: 1 | I23: 1 | J23: 4 | K23: 2023 | L23: Reported | M23: Reported | N23: Estimated | O23: 33975
A24: 5B50G | B24: AKZO NOBEL | C24: NL0013267909 | D24: 724500XYIJUGXAA5QD70 | E24: 60130 | F24: 195300 | G24: 14427286.40937 | H24: 1 | I24: 2 | J24: 4 | K24: 2023 | L24: Reported | M24: Reported | N24: Estimated | O24: 10184
A25: ALBEG | B25: ALBEMARLE | C25: US0126531013 | D25: HDBLS2Q6GV1LSKQPBS54 | E25: 617636 | F25: 334379 | G25: 2305424.699118 | H25: 1 | I25: 1 | J25: 4 | K25: 2023 | L25: Reported | M25: Reported | N25: Estimated | O25: 13328.83
A26: DOALG | B26: ALDO | E26: 520 | F26: 5808 | G26: 244653 | H26: 1 | I26: 1 | J26: 1 | K26: 2023 | L26: Reported | M26: Reported | N26: Reported | O26: 385827.61
A27: ALTCG | B27: ALEATICA | C27: MX01AL1C0003 | D27: 529900YI9E9NDAYEDU63 | E27: 11152 | F27: 69862 | G27: 112438.80897 | H27: 4 | I27: 2 | J27: 4 | K27: 2023 | L27: Estimated | M27: Reported | N27: Estimated | O27: 12365.31
A28: ALFAK | B28: ALFA LAVAL, GR | D28: 549300ZEHHN9SLH1F270 | E28: 16004 | F28: 62763 | G28: 31587541 | H28: 1 | I28: 1 | J28: 1 | K28: 2023 | L28: Reported | M28: Reported | N28: Reported | O28: 4875.89
A29: BNYLD | B29: ALGONQUIN POWER | C29: CA0158571053 | D29: 549300K5VIUTJXQL7X75 | E29: 2542820 | F29: 89200 | G29: 5798987.471637 | H29: 1 | I29: 1 | J29: 4 | K29: 2023 | L29: Reported | M29: Reported | N29: Estimated | O29: 12425.84
A30: ALING | B30: ALIANSCE | C30: BRALSOACNOR5 | E30: 21019 | F30: 5801 | G30: 59197 | H30: 1 | I30: 1 | J30: 4 | K30: 2023 | L30: Reported | M30: Reported | N30: Estimated | O30: 3285.49
A31: LBBRP | B31: ALIBABA GROUP? | C31: US01609W1027 | D31: 5493001NTNQJDH60PM02 | E31: 928939 | F31: 5141880 | G31: 18957231.899696 | H31: 1 | I31: 1 | J31: 4 | K31: 2023 | L31: Reported | M31: Reported | N31: Estimated | O31: 173822.81
A32: AGRLG | B32: ALLEGRO | C32: LU2237380790 | D32: 222100VRLXV3FPMG4982 | E32: 1421755 | F32: 21414 | G32: 180170.653572 | H32: 2 | I32: 2 | J32: 4 | K32: 2023 | L32: Reported | M32: Reported | N32: Estimated | O32: 3847.48
A33: LPRGT | B33: ALPARGATAS | C33: BRALPAACNPR7 | D33: 254900LU3422XPKEQJ79 | E33: 17743 | F33: 5528 | G33: 599477.57 | H33: 2 | I33: 2 | J33: 4 | K33: 2023 | L33: Reported | M33: Reported | N33: Estimated | O33: 878.99
A34: GOOGL | B34: ALPHABET INC | C34: US02079K3059 | D34: 5493006MHB84DD0ZWV18 | E34: 91200 | F34: 8045400 | G34: 14356503 | H34: 1 | I34: 1 | J34: 4 | K34: 2023 | L34: Reported | M34: Reported | N34: Estimated | O34: 339978.83
A35: ALPIK | B35: ALPIQ GROUP | D35: 5299006COKGB66PUHW42 | E35: 4722123.57 | F35: 377430.94 | G35: 9546595.544146 | H35: 4 | I35: 4 | J35: 4 | K35: 2023 | L35: Estimated | M35: Estimated | N35: Estimated | O35: 6619.96
A36: GALSG | B36: ALSEA | C36: MXP001391012 | D36: 4469000001BJLPKNUN21 | E36: 82888 | F36: 112932 | G36: 2271523.206893 | H36: 2 | I36: 2 | J36: 4 | K36: 2023 | L36: Reported | M36: Reported | N36: Estimated | O36: 2857
A37: 5AXMH | B37: ALSTOM | C37: FR0010220475 | D37: 96950032TUYMW11FB530 | E37: 93970 | F37: 133651 | G37: 44972826.283037 | H37: 1 | I37: 1 | J37: 4 | K37: 2023 | L37: Reported | M37: Reported | N37: Estimated | O37: 13433
A38: ALTRG | B38: ALTRIA GROUP | C38: US02209S1033 | D38: XSGZFLO9YTNO9VCQV219 | E38: 123892 | F38: 114625 | G38: 4476014 | H38: 1 | I38: 1 | J38: 1 | K38: 2023 | L38: Reported | M38: Reported | N38: Reported | O38: 23991.53
A39: AMNHG | B39: ALUMINUM CORP OF CHINA | C39: CNE1000001T8 | D39: 529900TKZUWQLIQN6T48 | E39: 7780179 | F39: 3721076 | G39: 33656524.357213 | H39: 4 | I39: 2 | J39: 4 | K39: 2023 | L39: Estimated | M39: Reported | N39: Estimated | O39: 23282.15
A40: ALUOG | B40: ALUPAR | C40: BRALUPCDAM15 | E40: 1975 | F40: 226 | G40: 536612.751844 | H40: 2 | I40: 2 | J40: 4 | K40: 2023 | L40: Reported | M40: Reported | N40: Estimated | O40: 3804.48
...

Sheet Sheet5
A1: flag_scib | B1: 1
A3: Row Labels | B3: Sum of total
A4: A | B4: 874.37529
A5: B | B5: 0
A6: C | B6: 480906.46
A7: D | B7: 153229.75
A8: E | B8: 15.84476
A9: F | B9: 12276.503
A10: G | B10: 306817.3
A11: H | B11: 155977.98
A12: I | B12: 309.73441
A13: J | B13: 1154.3638
A14: K | B14: 0
A15: M | B15: 492104.73
... A18: Grand Total | B18: 1606711.9

Sheet AS IS 
A1: bu_esg_work.EMI_FINAN_V3
A2: nace | B2: origem_scp1_emss | C2: origem_scp2_emss | D2: origem_scp3_emss | E2: glcs_code | F2: flag_cliente | G2: flag_scib | H2: montante | I2: total | J2: amount | K2: gesi | L2: gesii | M2: gesiii | N2: divida_tatico | O2: divida_estr | S2: Row Labels | T2: Sum of amount | U2: Sum of gesi | V2: Sum of gesii | W2: Sum of gesiii | X2: Sum of total
A3: A | B3: RE_DQS4_2B | C3: RE_DQS4_2B | D3: Nao Aplicavel | E3: NULL | F3: 0 | G3: 0 | H3: -93149827 | I3: 778636.77 | J3: 93149827 | K3: 122252.17 | L3: 656384.61 | P3: =+O3-N3 -> 0 | R3: A | S3: A | T3: 3.4864756e+08 | U3: 363755.54 | V3: 675360.74 | W3: 97706.477 | X3: 1136822.8 | Y3: =+VLOOKUP(R3,'2. Emissões Reportadas'!A:V,21,FALSE) -> 348.64756 | Z3: =+VLOOKUP(R3,'2. Emissões Reportadas'!A:V,22,FALSE) -> 1136823
A4: A | B4: Nao Aplicavel | C4: MVL_DQS3_2B | D4: Nao Aplicavel | E4: NULL | F4: 0 | G4: 0 | H4: -3076.44 | I4: 0.147255 | J4: 3076.44 | L4: 0.147255 | P4: =+O4-N4 -> 0 | R4: B | S4: B | T4: 14118758 | U4: 12988.756 | V4: 18680.406 | W4: 6071.9934 | X4: 37741.155 | Y4: =+VLOOKUP(R4,'2. Emissões Reportadas'!A:V,21,FALSE) -> 14.118758 | Z4: =+VLOOKUP(R4,'2. Emissões Reportadas'!A:V,22,FALSE) -> 37741
A5: A | B5: MISS | C5: MISS | D5: MISS | E5: NULL | F5: 0 | G5: 0 | H5: -161.91 | I5: 0 | J5: 161.91 | P5: =+O5-N5 -> 0 | R5: C | S5: C | T5: 2.3116558e+09 | U5: 324645.8 | V5: 176346.14 | W5: 1574169.2 | X5: 2075161.1 | Y5: =+VLOOKUP(R5,'2. Emissões Reportadas'!A:V,21,FALSE) -> 2311.661 | Z5: =+VLOOKUP(R5,'2. Emissões Reportadas'!A:V,22,FALSE) -> 2075162
A6: A | B6: BCL_DQS1_SCIB | C6: BCL_DQS1_SCIB | D6: BCL_DQS4_SCIB | E6: GAAMG | F6: 0 | G6: 1 | H6: -1214809.1 | I6: 874.37529 | J6: 1214809.1 | K6: 6.699286 | L6: 77.850486 | M6: 789.82552 | N6: 1030.8 | O6: 1030.8 | P6: =+O6-N6 -> 0 | R6: D | S6: D | T6: 7.3690288e+08 | U6: 206749.94 | V6: 12429.255 | W6: 159753.48 | X6: 378932.67 | Y6: =+VLOOKUP(R6,'2. Emissões Reportadas'!A:V,21,FALSE) -> 736.90288 | Z6: =+VLOOKUP(R6,'2. Emissões Reportadas'!A:V,22,FALSE) -> 378933
A7: A | B7: RE_DQS3_2A | C7: RE_DQS3_2A | D7: Nao Aplicavel | E7: NULL | F7: 0 | G7: 0 | H7: -4653076.8 | I7: 74.365354 | J7: 4653076.8 | K7: 18.832077 | L7: 55.533277 | P7: =+O7-N7 -> 0 | R7: E | S7: E | T7: 88021193 | U7: 10300.257 | V7: 1524.4562 | W7: 10807.973 | X7: 22632.687 | Y7: =+VLOOKUP(R7,'2. Emissões Reportadas'!A:V,21,FALSE) -> 88.021193 | Z7: =+VLOOKUP(R7,'2. Emissões Reportadas'!A:V,22,FALSE) -> 22633
A8: A | B8: MVL_DQS4_3A | C8: MVL_DQS4_3A | D8: Nao Aplicavel | E8: NULL | F8: 0 | G8: 0 | H8: -60827.81 | I8: 3.714809 | J8: 60827.81 | K8: 2.00862 | L8: 1.706189 | P8: =+O8-N8 -> 0 | R8: F | S8: F | T8: 1.052869e+09 | U8: 44584.01 | V8: 25180.914 | W8: 284926.72 | X8: 354691.65 | Y8: =+VLOOKUP(R8,'2. Emissões Reportadas'!A:V,21,FALSE) -> 1052.869 | Z8: =+VLOOKUP(R8,'2. Emissões Reportadas'!A:V,22,FALSE) -> 354692
A9: A | B9: MISS | C9: MISS | D9: Nao Aplicavel | E9: NULL | F9: 0 | G9: 0 | H9: -932603.12 | I9: 0 | J9: 932603.12 | P9: =+O9-N9 -> 0 | R9: G | S9: G | T9: 1.9794221e+09 | U9: 249090.97 | V9: 139306.77 | W9: 1044350.5 | X9: 1432748.3 | Y9: =+VLOOKUP(R9,'2. Emissões Reportadas'!A:V,21,FALSE) -> 1979.4221 | Z9: =+VLOOKUP(R9,'2. Emissões Reportadas'!A:V,22,FALSE) -> 1432748
A10: A | B10: RE_DQS5_3 | C10: RE_DQS5_3 | D10: Nao Aplicavel | E10: NULL | F10: 0 | G10: 0 | H10: -22779304 | I10: 539.52692 | J10: 22779304 | K10: 84.697433 | L10: 454.82949 | P10: =+O10-N10 -> 0 | R10: H | S10: H | T10: 7.8108571e+08 | U10: 322739.65 | V10: 24282.343 | W10: 607039.49 | X10: 954061.49 | Y10: =+VLOOKUP(R10,'2. Emissões Reportadas'!A:V,21,FALSE) -> 781.08571 | Z10: =+VLOOKUP(R10,'2. Emissões Reportadas'!A:V,22,FALSE) -> 954062
A11: A | B11: MVL_DQS3_2B | C11: Nao Aplicavel | D11: Nao Aplicavel | E11: NULL | F11: 0 | G11: 0 | H11: -25286.05 | I11: 1.475289 | J11: 25286.05 | K11: 1.475289 | P11: =+O11-N11 -> 0 | R11: I | S11: I | T11: 1.0632868e+09 | U11: 32368.439 | V11: 70913.038 | W11: 90094.08 | X11: 193375.56 | Y11: =+VLOOKUP(R11,'2. Emissões Reportadas'!A:V,21,FALSE) -> 1063.2868 | Z11: =+VLOOKUP(R11,'2. Emissões Reportadas'!A:V,22,FALSE) -> 193375
A12: A | B12: MVL_DQS3_2B | C12: MVL_DQS3_2B | D12: Nao Aplicavel | E12: NULL | F12: 0 | G12: 0 | H12: -65727.71 | I12: 2.69886 | J12: 65727.71 | K12: 1.278572 | L12: 1.420288 | P12: =+O12-N12 -> 0 | R12: J | S12: J | T12: 1.1295492e+08 | U12: 4628.3249 | V12: 3073.8282 | W12: 18004.536 | X12: 25706.689
A13: A | B13: BCL_DQS5_3B | C13: BCL_DQS5_3B | D13: BCL_DQS5_3B | E13: NULL | F13: 0 | G13: 0 | H13: -33133672 | I13: 60605.678 | J13: 33133672 | K13: 40931.535 | L13: 3135.495 | M13: 16538.649 | P13: =+O13-N13 -> 0 | Q13: 1 | R13: K | S13: K | T13: 3460620 | U13: 115.18347 | V13: 128.90945 | W13: 490.17356 | X13: 734.26648 | Y13: =+VLOOKUP(R13,'2. Emissões Reportadas'!A:V,21,FALSE) -> 3.46062 | Z13: =+VLOOKUP(R13,'2. Emissões Reportadas'!A:V,22,FALSE) -> 734
A14: A | B14: Nao Aplicavel | C14: Nao Aplicavel | D14: Nao Aplicavel | E14: NULL | F14: 0 | G14: 0 | H14: -203068.95 | I14: 0 | J14: 203068.95 | P14: =+O14-N14 -> 0 | R14: L | S14: L | T14: 1.1712311e+09 | U14: 19430.251 | V14: 80937.153 | W14: 14579.583 | X14: 114946.99 | Y14: =+VLOOKUP(R14,'2. Emissões Reportadas'!A:V,21,FALSE) -> 1171.2311 | Z14: =+VLOOKUP(R14,'2. Emissões Reportadas'!A:V,22,FALSE) -> 114947
A15: A | B15: BCL_DQS4_3A | C15: BCL_DQS4_3A | D15: BCL_DQS4_3A | E15: NULL | F15: 0 | G15: 0 | H15: -1.8924206e+08 | I15: 294543.89 | J15: 1.8924206e+08 | K15: 198927.34 | L15: 15238.544 | M15: 80378.003 | P15: =+O15-N15 -> 0 | R15: M | S15: M | T15: 1.97005e+09 | U15: 19976.77 | V15: 58503.304 | W15: 506257.23 | X15: 584737.3 | Z15: 2988.6102 | AA15: 814880
A16: A | B16: Nao Aplicavel | C16: MVL_DQS4_3A | D16: Nao Aplicavel | E16: NULL | F16: 0 | G16: 0 | H16: -561805.37 | I16: 10.606774 | J16: 561805.37 | L16: 10.606774 | P16: =+O16-N16 -> 0 | R16: N | S16: N | T16: 3.5380775e+08 | U16: 35735.338 | V16: 7414.2076 | W16: 50416.713 | X16: 93566.258 | Z16: =+SUM(GETPIVOTDATA("Sum of amount",$S$2,"nace","J"),T15:T23) -> 2.9886102e+09 | AA16: =+SUM(GETPIVOTDATA("Sum of total",$S$2,"nace","J"),X15:X23) -> 814880.63
A17: A | B17: MVL_DQS4_3A | C17: Nao Aplicavel | D17: Nao Aplicavel | E17: NULL | F17: 0 | G17: 0 | H17: -2622249.3 | I17: 1529.5052 | J17: 2622249.3 | K17: 1529.5052 | P17: =+O17-N17 -> 0 | R17: O | S17: O | T17: 25808809 | U17: 796.05705 | V17: 131.55992 | W17: 1440.035 | X17: 2367.6519
A18: B | B18: BCL_DQS4_3A | C18: BCL_DQS4_3A | D18: BCL_DQS4_3A | E18: NULL | F18: 0 | G18: 0 | H18: -11141015 | I18: 15627.024 | J18: 11141015 | K18: 8855.4206 | L18: 1072.3756 | M18: 5699.2273 | P18: =+O18-N18 -> 0 | R18: P | S18: P | T18: 61212833 | U18: 2524.3598 | V18: 2043.8711 | W18: 3561.7427 | X18: 8129.9735
A19: B | B19: MVL_DQS3_2B | C19: Nao Aplicavel | D19: Nao Aplicavel | E19: NULL | F19: 0 | G19: 0 | H19: -2059.5 | I19: 0.303349 | J19: 2059.5 | K19: 0.303349 | P19: =+O19-N19 -> 0 | R19: Q | S19: Q | T19: 2.3290165e+08 | U19: 13379.708 | V19: 6944.3009 | W19: 22193.314 | X19: 42517.323
A20: B | B20: MVL_DQS4_3A | C20: Nao Aplicavel | D20: Nao Aplicavel | E20: NULL | F20: 0 | G20: 0 | H20: -561375.11 | I20: 287.6099 | J20: 561375.11 | K20: 287.6099 | P20: =+O20-N20 -> 0 | R20: R | S20: R | T20: 87565945 | U20: 9507.2266 | V20: 22404.216 | W20: 8885.7629 | X20: 40797.205
A21: B | B21: MISS | C21: MISS | D21: Nao Aplicavel | E21: NULL | F21: 0 | G21: 0 | H21: -171502.45 | I21: 0 | J21: 171502.45 | P21: =+O21-N21 -> 0 | R21: S | S21: S | T21: 37304852 | U21: 2590.9152 | V21: 1280.8358 | W21: 5452.5175 | X21: 9324.2685
A22: B | B22: RE_DQS4_2B | C22: RE_DQS4_2B | D22: Nao Aplicavel | E22: NULL | F22: 0 | G22: 0 | H22: -1082136.2 | I22: 20800.538 | J22: 1082136.2 | K22: 3265.7265 | L22: 17534.811 | P22: =+O22-N22 -> 0 | R22: T | S22: T | T22: 137710.58 | U22: 5.850449 | V22: 1.036039 | W22: 10.620306 | X22: 17.506794
A23: B | B23: RE_DQS5_3 | C23: RE_DQS5_3 | D23: Nao Aplicavel | E23: NULL | F23: 0 | G23: 0 | H23: -30665.63 | I23: 1.894781 | J23: 30665.63 | K23: 0.297451 | L23: 1.59733 | P23: =+O23-N23 -> 0 | R23: U | S23: U | T23: 1.0686572e+08 | U23: 2552.108 | V23: 415.68633 | W23: 4748.663 | X23: 7716.4573
A24: B | B24: Nao Aplicavel | C24: Nao Aplicavel | D24: Nao Aplicavel | E24: NULL | F24: 0 | G24: 0 | H24: -23647.01 | I24: 0 | J24: 23647.01 | P24: =+O24-N24 -> 0 | S24: (blank) | T24: 113017.05 | X24: 0
A25: B | B25: BCL_DQS5_3B | C25: BCL_DQS5_3B | D25: BCL_DQS5_3B | E25: NULL | F25: 0 | G25: 0 | H25: -1030687.4 | I25: 1022.108 | J25: 1030687.4 | K25: 579.20166 | L25: 70.140302 | M25: 372.76605 | P25: =+O25-N25 -> 0 | Q25: 1 | S25: Grand Total | T25: 1.2539425e+10 | U25: 1678465.5 | V25: 1327303 | W25: 4510960.8 | X25: 7516729.3
A26: B | B26: Nao Aplicavel | C26: MVL_DQS4_3A | D26: Nao Aplicavel | E26: NULL | F26: 0 | G26: 0 | H26: -34713.2 | I26: 0.882598 | J26: 34713.2 | L26: 0.882598 | P26: =+O26-N26 -> 0
A27: B | B27: BCL_DQS4_SCIB | C27: BCL_DQS2_SCIB | D27: BCL_DQS4_SCIB | E27: GRSEM | F27: 0 | G27: 1 | H27: -2059.86 | I27: 0 | J27: 2059.86 | K27: 0 | L27: 0 | M27: 0 | N27: 3726.86 | O27: 3726.86 | P27: =+O27-N27 -> 0
A28: B | B28: NULL | C28: NULL | D28: NULL | E28: NULL | F28: 0 | G28: 0 | I28: 0 | P28: =+O28-N28 -> 0
A29: B | B29: RE_DQS3_2A | C29: RE_DQS3_2A | D29: Nao Aplicavel | E29: NULL | F29: 0 | G29: 0 | H29: -38897.24 | I29: 0.795289 | J29: 38897.24 | K29: 0.196588 | L29: 0.598701 | P29: =+O29-N29 -> 0
A30: C | B30: BCL_DQS1_SCIB | C30: BCL_DQS1_SCIB | D30: BCL_DQS1_SCIB | E30: GLACG | F30: 0 | G30: 1 | H30: -205480.95 | I30: 532.66561 | J30: 205480.95 | K30: 18.034452 | L30: 7.783464 | M30: 506.8477 | N30: 43710.6 | O30: 43710.6 | P30: =+O30-N30 -> 0
A31: C | B31: Nao Aplicavel | C31: MVL_DQS4_3A | D31: Nao Aplicavel | E31: NULL | F31: 0 | G31: 0 | H31: -7313055.6 | I31: 147.04918 | J31: 7313055.6 | L31: 147.04918 | P31: =+O31-N31 -> 0
A32: C | B32: BCL_DQS1_SCIB | C32: BCL_DQS1_SCIB | D32: BCL_DQS4_SCIB | E32: SIHOG | F32: 0 | G32: 1 | H32: -33735.81 | I32: 0 | J32: 33735.81 | K32: 0 | L32: 0 | M32: 0 | N32: 312450 | O32: 312450 | P32: =+O32-N32 -> 0
A33: C | B33: BCL_DQS1_SCIB | C33: BCL_DQS1_SCIB | D33: BCL_DQS4_SCIB | E33: IXLZG | F33: 0 | G33: 1 | H33: -2545673.2 | I33: 4523.1687 | J33: 2545673.2 | K33: 21.08 | L33: 84.438296 | M33: 4417.6504 | N33: 2666372 | O33: 2666372 | P33: =+O33-N33 -> 0
A34: C | B34: RE_DQS5_3 | C34: RE_DQS5_3 | D34: Nao Aplicavel | E34: NULL | F34: 0 | G34: 0 | H34: -66716161 | I34: 5907.954 | J34: 66716161 | K34: 927.458 | L34: 4980.496 | P34: =+O34-N34 -> 0
A35: C | B35: BCL_DQS1_SCIB | C35: BCL_DQS1_SCIB | D35: BCL_DQS4_SCIB | E35: SCFRG | F35: 0 | G35: 1 | H35: -13009.35 | I35: 0 | J35: 13009.35 | K35: 0 | L35: 0 | M35: 0 | N35: 222180 | O35: 222180 | P35: =+O35-N35 -> 0
A36: C | B36: BCL_DQS5_3B | C36: BCL_DQS5_3B | D36: BCL_DQS5_3B | E36: NULL | F36: 0 | G36: 0 | H36: -2.6647899e+08 | I36: 125298.09 | J36: 2.6647899e+08 | K36: 15813.03 | L36: 6784.3711 | M36: 102700.69 | P36: =+O36-N36 -> 0 | Q36: 1
A37: C | B37: BCL_DQS1_SCIB | C37: BCL_DQS1_SCIB | D37: BCL_DQS4_SCIB | E37: BIGRG | F37: 0 | G37: 1 | H37: -2833.17 | I37: 0 | J37: 2833.17 | K37: 0 | L37: 0 | M37: 0 | N37: 14618.7 | O37: 14618.7 | P37: =+O37-N37 -> 0
A38: C | B38: BCL_DQS1_SCIB | C38: BCL_DQS1_SCIB | D38: BCL_DQS1_SCIB | E38: NEHOG | F38: 0 | G38: 1 | H38: -4223095.2 | I38: 1305.4462 | J38: 4223095.2 | K38: 42.106805 | L38: 33.965425 | M38: 1229.374 | N38: 22164280 | O38: 22164280 | P38: =+O38-N38 -> 0
A39: C | B39: BCL_DQS1_SCIB | C39: BCL_DQS1_SCIB | D39: BCL_DQS4_SCIB | E39: DSSGG | F39: 0 | G39: 1 | H39: -8255893.3 | I39: 6584.1071 | J39: 8255893.3 | K39: 1380.3138 | L39: 797.68396 | M39: 4406.1094 | N39: 2525839.7 | O39: 2525839.7 | P39: =+O39-N39 -> 0
A40: C | B40: RE_DQS4_2B | C40: RE_DQS4_2B | D40: Nao Aplicavel | E40: UNHOG | F40: 0 | G40: 0 | H40: -16112063 | I40: 771.29462 | J40: 16112063 | K40: 121.08139 | L40: 650.21323 | N40: 54608 | O40: 54608 | P40: =+O40-N40 -> 0
...

Sheet 2. Emissões Reportadas
C2: Template 1: Banking book- Climate Change transition risk: Credit quality of exposures by sector, emissions and residual maturity
C3: Sector/subsector | D3: a | E3: b | F3: c | G3: d | H3: e | I3: f | J3: g | K3: h | L3: i | M3: j | N3: k | O3: l | P3: m | Q3: n | R3: o | S3: p
D4: Gross carrying amount (Mln EUR) | I4: Accumulated impairment, accumulated negative changes in fair value due to credit risk and provisions (Mln EUR) | L4: GHG financed emissions (scope 1, scope 2 and scope 3 emissions of the counterparty) (in tons of CO2 equivalent) | N4: GHG emissions (column i): gross carrying amount percentage of the portfolio derived from company-specific reporting | O4: <= 5 years | P4: > 5 year <= 10 years | Q4: > 10 year <= 20 years | R4: > 20 years | S4: Average weighted maturity
E5: Of which exposures towards companies excluded from EU Paris-aligned Benchmarks in accordance with points (d) to (g) of Article 12.1 and in accordance with Article 12.2 of Climate Benchmark Standards Regulation | F5: Of which environmentally sustainable (CCM) | G5: Of which stage 2 exposures | H5: Of which non-performing exposures | J5: Of which Stage 2 exposures | K5: Of which non-performing exposures | M5: Of which Scope 3 financed emissions
B6: 1 | C6: Exposures towards sectors that highly contribute to climate change* | D6: 9547.246 | E6: 36.816487 | F6: 129.12492 | G6: 853.59693 | H6: 400.68493 | I6: -321.20209 | J6: -43.288942 | K6: -260.53892 | L6: 6701116 | M6: 3889502 | N6: 0.076181585 | O6: 7294.8837 | P6: 1257.2137 | Q6: 931.49854 | R6: 63.650073 | S6: 4 | U6: =+D6 -> 9547.246 | V6: =+L6 -> 6701116
A7: A | B7: 2 | C7: A - Agriculture, forestry and fishing | D7: 348.64756 | E7: 0 | F7: 0.048106 | G7: 45.154885 | H7: 25.925782 | I7: -8.085153 | J7: -2.414584 | K7: -5.03654 | L7: 1136823 | M7: 97707 | N7: 0.0023228981 | O7: 223.55119 | P7: 65.941244 | Q7: 59.155128 | R7: 0 | S7: 5 | U7: =+D7 -> 348.64756 | V7: =+L7 -> 1136823
A8: B | B8: 3 | C8: B - Mining and quarrying | D8: 14.118758 | E8: 0 | F8: 9.2e-05 | G8: 2.018222 | H8: 1.809686 | I8: -1.203046 | J8: -0.116567 | K8: -1.057855 | L8: 37741 | M8: 6072 | N8: 4.8631756e-05 | O8: 13.19721 | P8: 0.921548 | Q8: 0 | R8: 0 | S8: 2 | U8: =+D8 -> 14.118758 | V8: =+L8 -> 37741
A9: B5 | B9: 4 | C9: B.05 - Mining of coal and lignite | D9: 0 | E9: 0 | F9: 0 | G9: 0 | H9: 0 | I9: 0 | J9: 0 | K9: 0 | L9: 0 | M9: 0 | N9: 0 | O9: 0 | P9: 0 | Q9: 0 | R9: 0 | S9: 0 | U9: =+D9 -> 0 | V9: =+L9 -> 0
A10: B6 | B10: 5 | C10: B.06 - Extraction of crude petroleum and natural gas | D10: 0 | E10: 0 | F10: 0 | G10: 0 | H10: 0 | I10: 0 | J10: 0 | K10: 0 | L10: 0 | M10: 0 | N10: 0 | O10: 0 | P10: 0 | Q10: 0 | R10: 0 | S10: 0 | U10: =+D10 -> 0 | V10: =+L10 -> 0
A11: B7 | B11: 6 | C11: B.07 - Mining of metal ores | D11: 0.101846 | E11: 0 | F11: 0 | G11: 0 | H11: 0 | I11: -3.9e-05 | J11: 0 | K11: 0 | L11: 65 | M11: 24 | N11: 0 | O11: 0.101846 | P11: 0 | Q11: 0 | R11: 0 | S11: 0 | U11: =+D11 -> 0.101846 | V11: =+L11 -> 65
A12: B8 | B12: 7 | C12: B.08 - Other mining and quarrying | D12: 13.962026 | E12: 0 | F12: 9.2e-05 | G12: 1.963875 | H12: 1.809156 | I12: -1.201902 | J12: -0.115934 | K12: -1.057384 | L12: 37641 | M12: 6035 | N12: 4.9177677e-05 | O12: 13.040478 | P12: 0.921548 | Q12: 0 | R12: 0 | S12: 2 | U12: =+D12 -> 13.962026 | V12: =+L12 -> 37641
A13: B9 | B13: 8 | C13: B.09 - Mining support service activities | D13: 0.054887 | E13: 0 | F13: 0 | G13: 0.054348 | H13: 0.00053 | I13: -0.001105 | J13: -0.000633 | K13: -0.000471 | L13: 36 | M13: 13 | N13: 0 | O13: 0.054887 | P13: 0 | Q13: 0 | R13: 0 | S13: 2 | U13: =+D13 -> 0.054887 | V13: =+L13 -> 36
A14: C | B14: 9 | C14: C - Manufacturing | D14: 2311.661 | E14: 0.209683 | F14: 10.032239 | G14: 237.21648 | H14: 84.608832 | I14: -74.90135 | J14: -10.927852 | K14: -59.252308 | L14: 2075162 | M14: 1574170 | N14: 0.052647942 | O14: 2089.3961 | P14: 174.11267 | Q14: 48.116587 | R14: 0.035578 | S14: 2 | U14: =+D14 -> 2311.661 | V14: =+L14 -> 2075162
A15: C10 | B15: 10 | C15: C.10 - Manufacture of food products | D15: 314.64138 | E15: 0 | F15: 0 | G15: 31.937245 | H15: 10.73584 | I15: -8.756349 | J15: -1.680093 | K15: -6.235924 | L15: 391597 | M15: 341601 | N15: 0.04795734 | O15: 272.6108 | P15: 25.146231 | Q15: 16.884346 | R15: 0 | S15: 2 | U15: =+D15 -> 314.64138 | V15: =+L15 -> 391597
A16: C11 | B16: 11 | C16: C.11 - Manufacture of beverages | D16: 235.60425 | E16: 0 | F16: 0 | G16: 7.27825 | H16: 0.355556 | I16: -0.963141 | J16: -0.417743 | K16: -0.276624 | L16: 137620 | M16: 104248 | N16: 0.001162014 | O16: 173.30136 | P16: 61.492993 | Q16: 0.809899 | R16: 0 | S16: 2 | U16: =+D16 -> 235.60425 | V16: =+L16 -> 137620
A17: C12 | B17: 12 | C17: C.12 - Manufacture of tobacco products | D17: 3.372252 | E17: 0 | F17: 0 | G17: 0 | H17: 0 | I17: -0.005161 | J17: 0 | K17: 0 | L17: 8560 | M17: 7523 | N17: 0.18258829 | O17: 3.372252 | P17: 0 | Q17: 0 | R17: 0 | S17: 0 | U17: =+D17 -> 3.372252 | V17: =+L17 -> 8560
A18: C13 | B18: 13 | C18: C.13 - Manufacture of textiles | D18: 101.48952 | E18: 0 | F18: 0 | G18: 15.990182 | H18: 4.615805 | I18: -4.895716 | J18: -0.9697 | K18: -3.54194 | L18: 36307 | M18: 29046 | N18: 0 | O18: 97.686888 | P18: 3.369196 | Q18: 0.433435 | R18: 0 | S18: 2 | U18: =+D18 -> 101.48952 | V18: =+L18 -> 36307
... A57: L | B57: 52 | C57: L - Real estate activities | D57: 1171.2311 | E57: 0 | F57: 0 | G57: 103.53666 | H57: 28.048686 | I57: -26.141884 | J57: -5.718605 | K57: -18.83917 | L57: 114947 | M57: 14580 | N57: 0 | O57: 685.24786 | P57: 255.32025 | Q57: 230.53181 | R57: 0.131176 | S57: 6 | U57: =+D57 -> 1171.2311 | V57: =+L57 -> 114947
B58: 53 | C58: Exposures towards sectors other than those that highly contribute to climate change* | D58: 2992.0708 | E58: 351.47054 | F58: 9.760108 | G58: 206.64534 | H58: 50.382795 | I58: -64.724279 | J58: -19.212288 | K58: -38.329482 | L58: 815614 | M58: 621461 | N58: 0.23499639 | O58: 2432.2646 | P58: 354.27076 | Q58: 204.5029 | R58: 1.032553 | S58: 3 | U58: =+D58 -> 2992.0708 | V58: =+L58 -> 815614
A59: K | B59: 54 | C59: K - Financial and insurance activities | D59: 3.46062 | E59: 0 | F59: 5.7e-05 | G59: 0.175923 | H59: 0.050877 | I59: -0.401491 | J59: -0.014942 | K59: -0.037403 | L59: 734 | M59: 490 | N59: 7.9471307e-05 | O59: 2.352348 | P59: 0.627912 | Q59: 0.14648 | R59: 0.33388 | S59: 11 | U59: =+D59 -> 3.46062 | V59: =+L59 -> 734
A60: J, M-U | B60: 55 | C60: Exposures to other sectors (NACE codes J, M - U) | D60: 2988.6102 | E60: 351.47054 | F60: 9.760051 | G60: 206.46942 | H60: 50.331918 | I60: -64.322788 | J60: -19.197346 | K60: -38.292079 | L60: 814880 | M60: 620971 | N60: 0.2352684 | O60: 2429.9122 | P60: 353.64285 | Q60: 204.35642 | R60: 0.698673 | S60: 3 | U60: =+D60 -> 2988.6102 | V60: =+L60 -> 814880
A61: TOTAL | B61: 56 | C61: TOTAL | D61: 12539.317 | E61: 388.28703 | F61: 138.88503 | G61: 1060.2423 | H61: 451.06772 | I61: -385.92637 | J61: -62.50123 | K61: -298.86841 | L61: 7516730 | M61: 4510963 | N61: 0.1140772 | O61: 9727.1483 | P61: 1611.4845 | Q61: 1136.0014 | R61: 64.682626 | S61: 3 | U61: =+D61 -> 12539.317 | V61: =+L61 -> 7516730
C62: * In accordance with the Commission delegated regulation EU) 2020/1818 supplementing regulation (EU) 2016/1011 as regards minimum standards for EU Climate Transition Benchmarks and EU Paris-aligned Benchmarks -Climate Benchmark Standards Regulation - Recital 6: Sectors listed in Sections A to H and Section L of Annex I to Regulation (EC) No 1893/2006
D63: valor bruto | E63: valor bruto | F63: 1 | G63: valor bruto | H63: valor bruto | I63: imparidade | J63: imparidade | K63: imparidade | O63: valor bruto | P63: valor bruto | Q63: valor bruto | R63: valor bruto | S63: valor bruto
E64: excluido | G64: stage 2 | H64: stage 3 | J64: stage 2 | K64: stage 3 | O64: -4 | P64: >5 | Q64: >10 | R64: >20 | S64: -1
P65: <=10 | Q65: <=20 | R65: -3 | S65: -2
R66: -2

Sheet 3. Clientes KGL diferente
B2: CLIENTES SCIB NA NFIN REPORTADA, MAS NA NA NFIN GERADA NO DIA 14/10 NÃO FORAM APANHADOS COMO SCIB
B4: zcliente | C4: ccli_grupo | D4: ccli_kgl | E4: clei | F4: cpais_residencia | G4: valor_mv | H4: ccliente_rst159 | I4: centlegal_rst159 | J4: cgrupo_rst159 | K4: zcliente_ct088 | L4: kgl5_ct071 | M4: ccli_grupo_max_clei | N4: clei_grupo_max_clei | O4: rank_max_clei | P4: zcliente_fr004 | Q4: sum_saldo_fr004 | R4: zcliente_pf | S4: zcliente_pme | T4: fatr_indv_pme | U4: zcliente_contraparte | V4: ref_date_contraparte | W4: contraparte | X4: zcliente_jquest | Y4: ccli_kgl_jquest | Z4: cpty_code_jquest | AA4: cptyparent_code_jquest | AB4: cptylastparent_code_jquest | AC4: clei_trat | AD4: flag_pf
B5: 8029317631 | C5: 0006661442 | D5: 98DF | E5: # | F5: 620 | G5: EU member states | H5: NULL | I5: NULL | J5: NULL | K5: NULL | L5: NULL | M5: NULL | N5: NULL | O5: NULL | P5: 8029317631 | Q5: 136.000000 | R5: NULL | S5: 8029317631 | T5: 20970000.000000 | U5: 8029317631 | V5: 2025-06-30 | W5: outras empresas nao financeiras | X5: 8029317631 | Y5: 98DF | Z5: 98DF | AA5: 98DFG | AB5: PRISA | AC5: # | AD5: N | AE5: =+VLOOKUP(Z5,'1. Input Junho 2025'!$A:$A,1,FALSE) -> #N/A | AF5: =+VLOOKUP(AA5,'1. Input Junho 2025'!$A:$A,1,FALSE) -> #N/A | AG5: =+VLOOKUP(AB5,'1. Input Junho 2025'!$A:$A,1,FALSE) -> PRISA | AH5: =+VLOOKUP(AC5,'1. Input Junho 2025'!$A:$A,1,FALSE) -> #N/A | AI5: =+VLOOKUP(AD5,'1. Input Junho 2025'!$A:$A,1,FALSE) -> #N/A
B6: 8000520483 | C6: 0008485994 | D6: 9SND | E6: # | F6: 620 | G6: EU member states | H6: NULL | I6: NULL | J6: NULL | K6: NULL | L6: NULL | M6: NULL | N6: NULL | O6: NULL | P6: 8000520483 | Q6: 37185.850000 | R6: NULL | S6: 8000520483 | T6: 59693583.300000 | U6: 8000520483 | V6: 2025-06-30 | W6: outras empresas nao financeiras | X6: 8000520483 | Y6: 9SND | Z6: 9SND | AA6: 9SNDG | AB6: 0S30G | AC6: # | AD6: N | AE6: =+VLOOKUP(Z6,'1. Input Junho 2025'!$A:$A,1,FALSE) -> #N/A | AF6: =+VLOOKUP(AA6,'1. Input Junho 2025'!$A:$A,1,FALSE) -> #N/A | AG6: =+VLOOKUP(AB6,'1. Input Junho 2025'!$A:$A,1,FALSE) -> 0S30G | AH6: =+VLOOKUP(AC6,'1. Input Junho 2025'!$A:$A,1,FALSE) -> #N/A | AI6: =+VLOOKUP(AD6,'1. Input Junho 2025'!$A:$A,1,FALSE) -> #N/A
B7: 8001732068 | C7: 0006504946 | D7: D82E | E7: # | F7: 620 | G7: EU member states | H7: NULL | I7: NULL | J7: NULL | K7: NULL | L7: NULL | M7: NULL | N7: NULL | O7: NULL | P7: 8001732068 | Q7: 4905803.860000 | R7: NULL | S7: 8001732068 | T7: 361893280.480000 | U7: 8001732068 | V7: 2025-06-30 | W7: outras empresas nao financeiras | X7: 8001732068 | Y7: D82E | Z7: D82E | AA7: D82EG | AB7: CGYNG | AC7: # | AD7: N | AE7: =+VLOOKUP(Z7,'1. Input Junho 2025'!$A:$A,1,FALSE) -> #N/A | AF7: =+VLOOKUP(AA7,'1. Input Junho 2025'!$A:$A,1,FALSE) -> #N/A | AG7: =+VLOOKUP(AB7,'1. Input Junho 2025'!$A:$A,1,FALSE) -> CGYNG | AH7: =+VLOOKUP(AC7,'1. Input Junho 2025'!$A:$A,1,FALSE) -> #N/A | AI7: =+VLOOKUP(AD7,'1. Input Junho 2025'!$A:$A,1,FALSE) -> #N/A
B8: 8008740708 | C8: 0006656255 | D8: IPR0 | E8: # | F8: 620 | G8: EU member states | H8: NULL | I8: NULL | J8: NULL | K8: NULL | L8: NULL | M8: NULL | N8: NULL | O8: NULL | P8: 8008740708 | Q8: 7369.850000 | R8: NULL | S8: 8008740708 | T8: 25553320.730000 | U8: 8008740708 | V8: 2025-06-30 | W8: outras empresas nao financeiras | X8: 8008740708 | Y8: IPR0 | Z8: IPR0 | AA8: IPR1G | AB8: 5VFRG | AC8: # | AD8: N | AE8: =+VLOOKUP(Z8,'1. Input Junho 2025'!$A:$A,1,FALSE) -> #N/A | AF8: =+VLOOKUP(AA8,'1. Input Junho 2025'!$A:$A,1,FALSE) -> #N/A | AG8: =+VLOOKUP(AB8,'1. Input Junho 2025'!$A:$A,1,FALSE) -> 5VFRG | AH8: =+VLOOKUP(AC8,'1. Input Junho 2025'!$A:$A,1,FALSE) -> #N/A | AI8: =+VLOOKUP(AD8,'1. Input Junho 2025'!$A:$A,1,FALSE) -> #N/A
B9: 8046459070 | C9: 0005301589 | D9: PUNN | E9: # | F9: 620 | G9: EU member states | H9: 8046459070 | I9: PPTCG | J9: PPTCK | K9: NULL | L9: NULL | M9: NULL | N9: NULL | O9: NULL | P9: 8046459070 | Q9: 13493287.050000 | R9: 8046459070 | S9: 8046459070 | T9: 97569351.320000 | U9: 8046459070 | V9: 2025-06-30 | W9: outras empresas nao financeiras | X9: 8046459070 | Y9: PUNN | Z9: PUNN | AA9: PUNNG | AB9: 1500G | AC9: # | AD9: Y | AE9: =+VLOOKUP(Z9,'1. Input Junho 2025'!$A:$A,1,FALSE) -> #N/A | AF9: =+VLOOKUP(AA9,'1. Input Junho 2025'!$A:$A,1,FALSE) -> #N/A | AG9: =+VLOOKUP(AB9,'1. Input Junho 2025'!$A:$A,1,FALSE) -> 1500G | AH9: =+VLOOKUP(AC9,'1. Input Junho 2025'!$A:$A,1,FALSE) -> #N/A | AI9: =+VLOOKUP(AD9,'1. Input Junho 2025'!$A:$A,1,FALSE) -> #N/A
X11: 8029317631 | Y11: PRISA
X12: 8000520483 | Y12: 0S30G
X13: 8001732068 | Y13: CGYNG
X14: 8008740708 | Y14: 5VFRG
X15: 8046459070 | Y15: 1500G

Sheet ANL1
A3: Row Labels | B3: Sum of gesi | C3: Sum of gesii | D3: Sum of gesiii | J3: flag_scib | K3: 1
A4: A | B4: 6.699286 | C4: 77.850486 | D4: 789.82552 | E4: 6.699286 | F4: 77.850486 | G4: 789.82552 | H4: =+SUM(E4,F4,G4) -> 874.37529
A5: C | B5: 48249.317 | C5: 8742.3777 | D5: 423914.77 | E5: 48249.317 | F5: 8742.3777 | G5: 423914.77 | H5: =+SUM(E5,F5,G5) -> 480906.46 | J5: Row Labels | K5: Sum of total
A6: D | B6: 62509.138 | C6: 3712.034 | D6: 87008.577 | E6: 62509.138 | F6: 3712.034 | G6: 87008.577 | H6: =+SUM(E6,F6,G6) -> 153229.75 | J6: A | K6: 874.37529
A7: E | B7: 0.159652 | C7: 0.139733 | D7: 15.545375 | E7: 0.159652 | F7: 0.139733 | G7: 15.545375 | H7: =+SUM(E7,F7,G7) -> 15.84476 | J7: B | K7: 0
A8: F | B8: 461.71584 | C8: 182.0752 | D8: 11632.712 | E8: 461.71584 | F8: 182.0752 | G8: 11632.712 | H8: =+SUM(E8,F8,G8) -> 12276.503 | J8: C | K8: 480906.46
A9: G | B9: 57348.027 | C9: 11987.388 | D9: 237481.88 | E9: 57348.027 | F9: 11987.388 | G9: 237481.88 | H9: =+SUM(E9,F9,G9) -> 306817.3 | J9: D | K9: 153229.75
A10: H | B10: 714.59982 | C10: 606.34077 | D10: 154657.04 | E10: 714.59982 | F10: 606.34077 | G10: 154657.04 | H10: =+SUM(E10,F10,G10) -> 155977.98 | J10: E | K10: 15.84476
A11: I | B11: 2.6 | C11: 1.216982 | D11: 305.91743 | E11: 2.6 | F11: 1.216982 | G11: 305.91743 | H11: =+SUM(E11,F11,G11) -> 309.73441 | J11: F | K11: 12276.503
A12: J | B12: 15.547202 | C12: 140.05209 | D12: 998.76455 | E12: 15.547202 | F12: 140.05209 | G12: 998.76455 | H12: =+SUM(E12,F12,G12) -> 1154.3638 | J12: G | K12: 306817.3
A13: M | B13: 5424.1724 | C13: 22991.281 | D13: 463689.27 | E13: 5424.1724 | F13: 22991.281 | G13: 463689.27 | H13: =+SUM(E13,F13,G13) -> 492104.73 | J13: H | K13: 155977.98
A14: N | B14: 983.67199 | C14: 9.097671 | D14: 1871.8726 | E14: 983.67199 | F14: 9.097671 | G14: 1871.8726 | H14: =+SUM(E14,F14,G14) -> 2864.6423 | J14: I | K14: 309.73441
A15: Q | B15: 84.645315 | C15: 4.223907 | D15: 91.345718 | E15: 84.645315 | F15: 4.223907 | G15: 91.345718 | H15: =+SUM(E15,F15,G15) -> 180.21494 | J15: J | K15: 1154.3638
A16: Grand Total | B16: 175800.29 | C16: 48454.078 | D16: 1382457.5 | E16: 175800.29 | F16: 48454.078 | G16: 1382457.5 | H16: =+SUM(E16,F16,G16) -> 1606711.9 | J16: K | K16: 0
J17: M | K17: 492104.73
J18: N | K18: 2864.6423
J19: Q | K19: 180.21494
J20: Grand Total | K20: 1606711.9
