Workbook
Name IQ_CH: 110000
Name IQ_CQ: 5000
Name IQ_CY: 10000
Name IQ_DAILY: 500000
Name IQ_FH: 100000
Name IQ_FQ: 500
Name IQ_FY: 1000
Name IQ_LTM: 2000
Name IQ_MONTH: 15000
Name IQ_NTM: 6000
Name IQ_WEEK: 50000
Name IQ_YTD: 3000

Sheet Input Hue
A1: stage | B1: contraparte | C1: vb_imp | D1: tipo_colateral | E1: maturity | F1: cod_nace_esg | G1: acute_changes | H1: chronic_changes | I1: flag_physical_risk | J1: amount | K1: aveg_aux
A2: stage 3 | B2: outras empresas nao financeiras | C2: imparidade | D2: Sem Garantia | E2: 4 | F2: A | G2: ACUT2 | H2: CHRO2 | I2: 0 | J2: -15447 | K2: NULL
A3: stage 3 | B3: outras empresas nao financeiras | C3: imparidade | D3: Garantia Comercial | E3: 7 | F3: H | G3: ACUT2 | H3: CHRO2 | I3: 0 | J3: -141088 | K3: NULL
A4: stage 1 | B4: outras empresas nao financeiras | C4: valor bruto | D4: Garantia Comercial | E4: 9 | F4: M | G4: ACUT2 | H4: CHRO2 | I4: 0 | J4: 5590754 | K4: 50316786
A5: stage 1 | B5: outras empresas nao financeiras | C5: imparidade | D5: Sem Garantia | E5: 2 | F5: R | G5: ACUT2 | H5: CHRO2 | I5: 0 | J5: -16276 | K5: NULL
A6: stage 2 | B6: particulares | C6: imparidade | D6: Garantia Residencial | E6: 23 | G6: ACUT1 | H6: CHRO2 | I6: 1 | J6: -38061 | K6: NULL
A7: stage 3 | B7: particulares | C7: valor bruto | D7: Garantia Residencial | E7: 6 | G7: ACUT2 | H7: CHRO2 | I7: 0 | J7: 1899760 | K7: 11398560
A8: stage 1 | B8: outras empresas nao financeiras | C8: imparidade | D8: Garantia Comercial | E8: 16 | F8: M | G8: ACUT2 | H8: CHRO2 | I8: 0 | J8: -781 | K8: NULL
A9: stage 2 | B9: outras empresas nao financeiras | C9: imparidade | D9: Garantia Comercial | E9: 9 | F9: H | G9: ACUT2 | H9: CHRO2 | I9: 0 | J9: -164456 | K9: NULL
A10: stage 1 | B10: outras empresas nao financeiras | C10: valor bruto | D10: Garantia Comercial | E10: 11 | F10: S | G10: ACUT2 | H10: CHRO2 | I10: 0 | J10: 547470 | K10: 6022170
A11: stage 2 | B11: outras empresas nao financeiras | C11: imparidade | D11: Garantia Comercial | E11: 7 | F11: M | G11: ACUT2 | H11: CHRO2 | I11: 0 | J11: -30730 | K11: NULL
A12: stage 1 | B12: outras empresas nao financeiras | C12: valor bruto | D12: Garantia Comercial | E12: 2 | F12: G | G12: ACUT1 | H12: CHRO2 | I12: 1 | J12: 36675 | K12: 73350
A13: stage 1 | B13: outras empresas nao financeiras | C13: valor bruto | D13: Garantia Real | E13: 4 | F13: D | G13: ACUT2 | H13: CHRO2 | I13: 0 | J13: 81782 | K13: 327128
A14: stage 3 | B14: outras empresas nao financeiras | C14: imparidade | D14: Sem Garantia | E14: 0 | F14: I | G14: ACUT2 | H14: CHRO2 | I14: 0 | J14: -233592 | K14: NULL
A15: stage 3 | B15: outras empresas nao financeiras | C15: imparidade | D15: Garantia Comercial | E15: 9 | F15: M | G15: ACUT2 | H15: CHRO2 | I15: 0 | J15: -486869 | K15: NULL
A16: stage 1 | B16: outras empresas nao financeiras | C16: imparidade | D16: Sem Garantia | E16: 4 | F16: C | G16: ACUT2 | H16: CHRO2 | I16: 0 | J16: -305905 | K16: NULL
A17: stage 2 | B17: outras empresas nao financeiras | C17: valor bruto | D17: Sem Garantia | E17: 4 | F17: P | G17: ACUT2 | H17: CHRO2 | I17: 0 | J17: 161367 | K17: 645468
A18: stage 1 | B18: outras empresas nao financeiras | C18: imparidade | D18: Garantia Comercial | E18: 16 | F18: S | G18: ACUT2 | H18: CHRO2 | I18: 0 | J18: -2911 | K18: NULL
A19: stage 3 | B19: particulares | C19: imparidade | D19: Garantia Comercial | E19: 5 | G19: ACUT2 | H19: CHRO2 | I19: 0 | J19: -94624 | K19: NULL
A20: stage 3 | B20: particulares | C20: valor bruto | D20: Garantia Comercial | E20: 30 | G20: ACUT2 | H20: CHRO2 | I20: 0 | J20: 114370 | K20: 3431100
A21: stage 3 | B21: outras empresas nao financeiras | C21: imparidade | D21: Garantia Comercial | E21: 14 | F21: L | G21: ACUT2 | H21: CHRO2 | I21: 0 | J21: -43854 | K21: NULL
A22: stage 1 | B22: outras empresas nao financeiras | C22: valor bruto | D22: Garantia Comercial | E22: 11 | F22: M | G22: ACUT2 | H22: CHRO2 | I22: 0 | J22: 6965247 | K22: 76617717
A23: stage 1 | B23: particulares | C23: valor bruto | D23: Garantia Residencial | E23: 13 | G23: ACUT1 | H23: CHRO1 | I23: 1 | J23: 64123 | K23: 833599
A24: stage 2 | B24: outras empresas nao financeiras | C24: valor bruto | D24: Sem Garantia | E24: 6 | F24: H | G24: ACUT2 | H24: CHRO2 | I24: 0 | J24: 141757 | K24: 850542
A25: stage 2 | B25: outras empresas nao financeiras | C25: imparidade | D25: Garantia Comercial | E25: 10 | F25: G | G25: ACUT2 | H25: CHRO1 | I25: 1 | J25: -5855 | K25: NULL
A26: stage 1 | B26: outras empresas nao financeiras | C26: valor bruto | D26: Garantia Comercial | E26: 0 | F26: G | G26: ACUT2 | H26: CHRO1 | I26: 1 | J26: 19147 | K26: NULL
A27: stage 3 | B27: outras empresas nao financeiras | C27: valor bruto | D27: Garantia Real | E27: 4 | F27: A | G27: ACUT2 | H27: CHRO2 | I27: 0 | J27: 91424 | K27: 365696
A28: stage 3 | B28: outras empresas nao financeiras | C28: imparidade | D28: Garantia Comercial | E28: 13 | F28: N | G28: ACUT2 | H28: CHRO2 | I28: 0 | J28: -215812 | K28: NULL
A29: stage 1 | B29: outras empresas nao financeiras | C29: valor bruto | D29: Garantia Comercial | E29: 2 | F29: P | G29: ACUT2 | H29: CHRO2 | I29: 0 | J29: 196011 | K29: 392022
A30: stage 1 | B30: outras empresas nao financeiras | C30: valor bruto | D30: Garantia Real | E30: 2 | F30: G | G30: ACUT2 | H30: CHRO2 | I30: 0 | J30: 8996895 | K30: 17993790
A31: stage 1 | B31: outras empresas nao financeiras | C31: valor bruto | D31: Garantia Comercial | E31: 11 | F31: C | G31: ACUT2 | H31: CHRO1 | I31: 1 | J31: 4286960 | K31: 47156560
A32: stage 2 | B32: outras empresas nao financeiras | C32: valor bruto | D32: Garantia Real | E32: 3 | F32: Q | G32: ACUT2 | H32: CHRO2 | I32: 0 | J32: 683285 | K32: 2049855
A33: stage 2 | B33: outras empresas nao financeiras | C33: imparidade | D33: Garantia Comercial | E33: 9 | F33: F | G33: ACUT2 | H33: CHRO2 | I33: 0 | J33: -141671 | K33: NULL
A34: stage 1 | B34: particulares | C34: imparidade | D34: Garantia Residencial | E34: 35 | G34: ACUT1 | H34: CHRO2 | I34: 1 | J34: -15447 | K34: NULL
A35: stage 1 | B35: particulares | C35: valor bruto | D35: Garantia Comercial | E35: 6 | G35: ACUT2 | H35: CHRO1 | I35: 1 | J35: 361369 | K35: 2168214
A36: stage 2 | B36: outras empresas nao financeiras | C36: imparidade | D36: Garantia Comercial | E36: 0 | F36: I | G36: ACUT2 | H36: CHRO2 | I36: 0 | J36: -536 | K36: NULL
A37: stage 2 | B37: particulares | C37: valor bruto | D37: Garantia Residencial | E37: 9 | G37: ACUT2 | H37: CHRO1 | I37: 1 | J37: 164928 | K37: 1484352
A38: stage 2 | B38: outras empresas nao financeiras | C38: imparidade | D38: Garantia Comercial | E38: 10 | F38: J | G38: ACUT2 | H38: CHRO2 | I38: 0 | J38: -28274 | K38: NULL
A39: stage 3 | B39: outras empresas nao financeiras | C39: valor bruto | D39: Garantia Real | E39: 2 | F39: L | G39: ACUT2 | H39: CHRO2 | I39: 0 | J39: 30391 | K39: 60782
A40: stage 1 | B40: outras empresas nao financeiras | C40: valor bruto | D40: Garantia Real | E40: -1 | F40: I | G40: ACUT2 | H40: CHRO2 | I40: 0 | J40: 1854842 | K40: NULL
...

Sheet 5.CC Physical risk
C1: Template 5: Banking book - Climate change physical risk: Exposures subject to physical risk
C4: a | D4: b | E4: c | F4: d | G4: e | H4: f | I4: g | J4: h | K4: i | L4: j | M4: k | N4: l | O4: m | P4: n | Q4: o
C5: Variable: Geographical area subject to climate change physical risk - acute and chronic events | D5: Gross carrying amount (Mln EUR)
E6: of which exposures sensitive to impact from climate change physical events
E7: Breakdown by maturity bucket | J7: of which exposures sensitive to impact from chronic climate change events | K7: of which exposures sensitive to impact from acute climate change events | L7: of which exposures sensitive to impact both from chronic and acute climate change events | M7: Of which Stage 2 exposures | N7: Of which non-performing exposures | O7: Accumulated impairment, accumulated negative changes in fair value due to credit risk and provisions
E8: <= 5 years | F8: > 5 year <= 10 years | G8: > 10 year <= 20 years | H8: > 20 years | I8: Average weighted maturity | P8: of which Stage 2 exposures | Q8: Of which non-performing exposures
A9: A | B9: 1 | C9: A - Agriculture, forestry and fishing | D9: =(SUMIFS('Input Hue'!$J:$J,'Input Hue'!$C:$C,'5.CC Physical risk'!$D$24,'Input Hue'!$F:$F,'5.CC Physical risk'!$A9&"*",'Input Hue'!$B:$B,"outras empresas nao financeiras"))/1000000 -> 331.59963 | E9: =(SUMIFS('Input Hue'!$J:$J,'Input Hue'!$I:$I,"1",'Input Hue'!$C:$C,'5.CC Physical risk'!$D$24,'Input Hue'!$F:$F,'5.CC Physical risk'!$A9&"*",'Input Hue'!$B:$B,"outras empresas nao financeiras",'Input Hue'!$E:$E,">=0",'Input Hue'!$E:$E,"<=5") + SUMIFS('Input Hue'!$J:$J,'Input Hue'!$I:$I,"1",'Input Hue'!$C:$C,'5.CC Physical risk'!$D$24,'Input Hue'!$F:$F,'5.CC Physical risk'!$A9&"*",'Input Hue'!$B:$B,"outras empresas nao financeiras",'Input Hue'!$E:$E,"-4") + SUMIFS('Input Hue'!$J:$J,'Input Hue'!$I:$I,"1",'Input Hue'!$C:$C,'5.CC Physical risk'!$D$24,'Input Hue'!$F:$F,'5.CC Physical risk'!$A9&"*",'Input Hue'!$B:$B,"outras empresas nao financeiras",'Input Hue'!$E:$E,"-1"))/1000000 -> 18.782904 | F9: =(SUMIFS('Input Hue'!$J:$J,'Input Hue'!$I:$I,"1",'Input Hue'!$C:$C,'5.CC Physical risk'!$D$24,'Input Hue'!$F:$F,'5.CC Physical risk'!$A9&"*",'Input Hue'!$B:$B,"outras empresas nao financeiras",'Input Hue'!$E:$E,">5",'Input Hue'!$E:$E,"<=10"))/1000000 -> 29.995382 | G9: =(SUMIFS('Input Hue'!$J:$J,'Input Hue'!$I:$I,"1",'Input Hue'!$C:$C,'5.CC Physical risk'!$D$24,'Input Hue'!$F:$F,'5.CC Physical risk'!$A9&"*",'Input Hue'!$B:$B,"outras empresas nao financeiras",'Input Hue'!$E:$E,">10",'Input Hue'!$E:$E,"<=20"))/1000000 -> 51.553634 | H9: =(SUMIFS('Input Hue'!$J:$J,'Input Hue'!$I:$I,"1",'Input Hue'!$C:$C,'5.CC Physical risk'!$D$24,'Input Hue'!$F:$F,'5.CC Physical risk'!$A9&"*",'Input Hue'!$B:$B,"outras empresas nao financeiras",'Input Hue'!$E:$E,">20") + SUMIFS('Input Hue'!$J:$J,'Input Hue'!$I:$I,"1",'Input Hue'!$C:$C,'5.CC Physical risk'!$D$24,'Input Hue'!$F:$F,'5.CC Physical risk'!$A9&"*",'Input Hue'!$B:$B,"outras empresas nao financeiras",'Input Hue'!$E:$E,"-2") + SUMIFS('Input Hue'!$J:$J,'Input Hue'!$I:$I,"1",'Input Hue'!$C:$C,'5.CC Physical risk'!$D$24,'Input Hue'!$F:$F,'5.CC Physical risk'!$A9&"*",'Input Hue'!$B:$B,"outras empresas nao financeiras",'Input Hue'!$E:$E,"-3") + SUMIFS('Input Hue'!$J:$J,'Input Hue'!$I:$I,"1",'Input Hue'!$C:$C,'5.CC Physical risk'!$D$24,'Input Hue'!$F:$F,'5.CC Physical risk'!$A9&"*",'Input Hue'!$B:$B,"outras empresas nao financeiras",'Input Hue'!$E:$E,"-5"))/1000000 -> 0 | I9: =IFERROR(ROUND(SUMIFS('Input Hue'!$K:$K,'Input Hue'!$I:$I,"1",'Input Hue'!$C:$C,'5.CC Physical risk'!$D$24,'Input Hue'!$F:$F,'5.CC Physical risk'!$A9&"*",'Input Hue'!$B:$B,"outras empresas nao financeiras",'Input Hue'!$E:$E,">0") / SUMIFS('Input Hue'!$J:$J,'Input Hue'!$I:$I,"1",'Input Hue'!$C:$C,'5.CC Physical risk'!$D$24,'Input Hue'!$F:$F,'5.CC Physical risk'!$A9&"*",'Input Hue'!$B:$B,"outras empresas nao financeiras",'Input Hue'!$E:$E,">0"),0),0) -> 10 | J9: =(SUMIFS('Input Hue'!$J:$J,'Input Hue'!$I:$I,"1",'Input Hue'!$C:$C,'5.CC Physical risk'!$D$24,'Input Hue'!$F:$F,'5.CC Physical risk'!$A9&"*",'Input Hue'!$B:$B,"outras empresas nao financeiras",'Input Hue'!$G:$G,"<>"&$K$24,'Input Hue'!$H:$H,'5.CC Physical risk'!$J$24))/1000000 -> 99.654562 | K9: =(SUMIFS('Input Hue'!$J:$J,'Input Hue'!$I:$I,"1",'Input Hue'!$C:$C,'5.CC Physical risk'!$D$24,'Input Hue'!$F:$F,'5.CC Physical risk'!$A9&"*",'Input Hue'!$B:$B,"outras empresas nao financeiras",'Input Hue'!$H:$H,"<>"&$J$24,'Input Hue'!$G:$G,'5.CC Physical risk'!$K$24))/1000000 -> 0 | L9: =(SUMIFS('Input Hue'!$J:$J, 'Input Hue'!$I:$I,"1", 'Input Hue'!$C:$C,'5.CC Physical risk'!$D$24, 'Input Hue'!$F:$F,'5.CC Physical risk'!$A9&"*", 'Input Hue'!$B:$B,"outras empresas nao financeiras", 'Input Hue'!$H:$H,'5.CC Physical risk'!$J$24, 'Input Hue'!$G:$G,'5.CC Physical risk'!$K$24))/1000000 -> 0.677358 | M9: =(SUMIFS('Input Hue'!$J:$J, 'Input Hue'!$I:$I,"1", 'Input Hue'!$C:$C,'5.CC Physical risk'!$D$24, 'Input Hue'!$B:$B,"outras empresas nao financeiras", 'Input Hue'!$F:$F,'5.CC Physical risk'!$A9&"*", 'Input Hue'!$A:$A,'5.CC Physical risk'!$M$24))/1000000 -> 4.365008 | N9: =(SUMIFS('Input Hue'!$J:$J, 'Input Hue'!$I:$I,"1", 'Input Hue'!$C:$C,'5.CC Physical risk'!$D$24, 'Input Hue'!$B:$B,"outras empresas nao financeiras", 'Input Hue'!$F:$F,'5.CC Physical risk'!$A9&"*", 'Input Hue'!$A:$A,'5.CC Physical risk'!$N$24))/1000000 -> 1.016776 | O9: =(SUMIFS('Input Hue'!$J:$J, 'Input Hue'!$I:$I,"1", 'Input Hue'!$C:$C,'5.CC Physical risk'!$O$24, 'Input Hue'!$B:$B,"outras empresas nao financeiras", 'Input Hue'!$F:$F,'5.CC Physical risk'!$A9&"*"))/1000000 -> -0.682464 | P9: =(SUMIFS('Input Hue'!$J:$J, 'Input Hue'!$I:$I,"1", 'Input Hue'!$C:$C,'5.CC Physical risk'!$O$24, 'Input Hue'!$B:$B,"outras empresas nao financeiras", 'Input Hue'!$F:$F,'5.CC Physical risk'!$A9&"*", 'Input Hue'!$A:$A,'5.CC Physical risk'!$M$24))/1000000 -> -0.21757 | Q9: =(SUMIFS('Input Hue'!$J:$J, 'Input Hue'!$I:$I,"1", 'Input Hue'!$C:$C,'5.CC Physical risk'!$O$24, 'Input Hue'!$B:$B,"outras empresas nao financeiras", 'Input Hue'!$F:$F,'5.CC Physical risk'!$A9&"*", 'Input Hue'!$A:$A,'5.CC Physical risk'!$N$24))/1000000 -> -0.314496
A10: B | B10: 2 | C10: B - Mining and quarrying | D10: =(SUMIFS('Input Hue'!$J:$J,'Input Hue'!$C:$C,'5.CC Physical risk'!$D$24,'Input Hue'!$F:$F,'5.CC Physical risk'!$A10&"*",'Input Hue'!$B:$B,"outras empresas nao financeiras"))/1000000 -> 14.172405 | E10: =(SUMIFS('Input Hue'!$J:$J,'Input Hue'!$I:$I,"1",'Input Hue'!$C:$C,'5.CC Physical risk'!$D$24,'Input Hue'!$F:$F,'5.CC Physical risk'!$A10&"*",'Input Hue'!$B:$B,"outras empresas nao financeiras",'Input Hue'!$E:$E,">=0",'Input Hue'!$E:$E,"<=5") + SUMIFS('Input Hue'!$J:$J,'Input Hue'!$I:$I,"1",'Input Hue'!$C:$C,'5.CC Physical risk'!$D$24,'Input Hue'!$F:$F,'5.CC Physical risk'!$A10&"*",'Input Hue'!$B:$B,"outras empresas nao financeiras",'Input Hue'!$E:$E,"-4") + SUMIFS('Input Hue'!$J:$J,'Input Hue'!$I:$I,"1",'Input Hue'!$C:$C,'5.CC Physical risk'!$D$24,'Input Hue'!$F:$F,'5.CC Physical risk'!$A10&"*",'Input Hue'!$B:$B,"outras empresas nao financeiras",'Input Hue'!$E:$E,"-1"))/1000000 -> 0.779742 | F10: =(SUMIFS('Input Hue'!$J:$J,'Input Hue'!$I:$I,"1",'Input Hue'!$C:$C,'5.CC Physical risk'!$D$24,'Input Hue'!$F:$F,'5.CC Physical risk'!$A10&"*",'Input Hue'!$B:$B,"outras empresas nao financeiras",'Input Hue'!$E:$E,">5",'Input Hue'!$E:$E,"<=10"))/1000000 -> 0.576054 | G10: =(SUMIFS('Input Hue'!$J:$J,'Input Hue'!$I:$I,"1",'Input Hue'!$C:$C,'5.CC Physical risk'!$D$24,'Input Hue'!$F:$F,'5.CC Physical risk'!$A10&"*",'Input Hue'!$B:$B,"outras empresas nao financeiras",'Input Hue'!$E:$E,">10",'Input Hue'!$E:$E,"<=20"))/1000000 -> 0 | H10: =(SUMIFS('Input Hue'!$J:$J,'Input Hue'!$I:$I,"1",'Input Hue'!$C:$C,'5.CC Physical risk'!$D$24,'Input Hue'!$F:$F,'5.CC Physical risk'!$A10&"*",'Input Hue'!$B:$B,"outras empresas nao financeiras",'Input Hue'!$E:$E,">20") + SUMIFS('Input Hue'!$J:$J,'Input Hue'!$I:$I,"1",'Input Hue'!$C:$C,'5.CC Physical risk'!$D$24,'Input Hue'!$F:$F,'5.CC Physical risk'!$A10&"*",'Input Hue'!$B:$B,"outras empresas nao financeiras",'Input Hue'!$E:$E,"-2") + SUMIFS('Input Hue'!$J:$J,'Input Hue'!$I:$I,"1",'Input Hue'!$C:$C,'5.CC Physical risk'!$D$24,'Input Hue'!$F:$F,'5.CC Physical risk'!$A10&"*",'Input Hue'!$B:$B,"outras empresas nao financeiras",'Input Hue'!$E:$E,"-3") + SUMIFS('Input Hue'!$J:$J,'Input Hue'!$I:$I,"1",'Input Hue'!$C:$C,'5.CC Physical risk'!$D$24,'Input Hue'!$F:$F,'5.CC Physical risk'!$A10&"*",'Input Hue'!$B:$B,"outras empresas nao financeiras",'Input Hue'!$E:$E,"-5"))/1000000 -> 0 | I10: =IFERROR(ROUND(SUMIFS('Input Hue'!$K:$K,'Input Hue'!$I:$I,"1",'Input Hue'!$C:$C,'5.CC Physical risk'!$D$24,'Input Hue'!$F:$F,'5.CC Physical risk'!$A10&"*",'Input Hue'!$B:$B,"outras empresas nao financeiras",'Input Hue'!$E:$E,">0") / SUMIFS('Input Hue'!$J:$J,'Input Hue'!$I:$I,"1",'Input Hue'!$C:$C,'5.CC Physical risk'!$D$24,'Input Hue'!$F:$F,'5.CC Physical risk'!$A10&"*",'Input Hue'!$B:$B,"outras empresas nao financeiras",'Input Hue'!$E:$E,">0"),0),0) -> 4 | J10: =(SUMIFS('Input Hue'!$J:$J,'Input Hue'!$I:$I,"1",'Input Hue'!$C:$C,'5.CC Physical risk'!$D$24,'Input Hue'!$F:$F,'5.CC Physical risk'!$A10&"*",'Input Hue'!$B:$B,"outras empresas nao financeiras",'Input Hue'!$G:$G,"<>"&$K$24,'Input Hue'!$H:$H,'5.CC Physical risk'!$J$24))/1000000 -> 1.355796 | K10: =(SUMIFS('Input Hue'!$J:$J,'Input Hue'!$I:$I,"1",'Input Hue'!$C:$C,'5.CC Physical risk'!$D$24,'Input Hue'!$F:$F,'5.CC Physical risk'!$A10&"*",'Input Hue'!$B:$B,"outras empresas nao financeiras",'Input Hue'!$H:$H,"<>"&$J$24,'Input Hue'!$G:$G,'5.CC Physical risk'!$K$24))/1000000 -> 0 | L10: =(SUMIFS('Input Hue'!$J:$J, 'Input Hue'!$I:$I,"1", 'Input Hue'!$C:$C,'5.CC Physical risk'!$D$24, 'Input Hue'!$F:$F,'5.CC Physical risk'!$A10&"*", 'Input Hue'!$B:$B,"outras empresas nao financeiras", 'Input Hue'!$H:$H,'5.CC Physical risk'!$J$24, 'Input Hue'!$G:$G,'5.CC Physical risk'!$K$24))/1000000 -> 0 | M10: =(SUMIFS('Input Hue'!$J:$J, 'Input Hue'!$I:$I,"1", 'Input Hue'!$C:$C,'5.CC Physical risk'!$D$24, 'Input Hue'!$B:$B,"outras empresas nao financeiras", 'Input Hue'!$F:$F,'5.CC Physical risk'!$A10&"*", 'Input Hue'!$A:$A,'5.CC Physical risk'!$M$24))/1000000 -> 1e-06 | N10: =(SUMIFS('Input Hue'!$J:$J, 'Input Hue'!$I:$I,"1", 'Input Hue'!$C:$C,'5.CC Physical risk'!$D$24, 'Input Hue'!$B:$B,"outras empresas nao financeiras", 'Input Hue'!$F:$F,'5.CC Physical risk'!$A10&"*", 'Input Hue'!$A:$A,'5.CC Physical risk'!$N$24))/1000000 -> 0.770197 | O10: =(SUMIFS('Input Hue'!$J:$J, 'Input Hue'!$I:$I,"1", 'Input Hue'!$C:$C,'5.CC Physical risk'!$O$24, 'Input Hue'!$B:$B,"outras empresas nao financeiras", 'Input Hue'!$F:$F,'5.CC Physical risk'!$A10&"*"))/1000000 -> -0.199802 | P10: =(SUMIFS('Input Hue'!$J:$J, 'Input Hue'!$I:$I,"1", 'Input Hue'!$C:$C,'5.CC Physical risk'!$O$24, 'Input Hue'!$B:$B,"outras empresas nao financeiras", 'Input Hue'!$F:$F,'5.CC Physical risk'!$A10&"*", 'Input Hue'!$A:$A,'5.CC Physical risk'!$M$24))/1000000 -> 0 | Q10: =(SUMIFS('Input Hue'!$J:$J, 'Input Hue'!$I:$I,"1", 'Input Hue'!$C:$C,'5.CC Physical risk'!$O$24, 'Input Hue'!$B:$B,"outras empresas nao financeiras", 'Input Hue'!$F:$F,'5.CC Physical risk'!$A10&"*", 'Input Hue'!$A:$A,'5.CC Physical risk'!$N$24))/1000000 -> -0.198244
A11: C | B11: 3 | C11: C - Manufacturing | D11: =(SUMIFS('Input Hue'!$J:$J,'Input Hue'!$C:$C,'5.CC Physical risk'!$D$24,'Input Hue'!$F:$F,'5.CC Physical risk'!$A11&"*",'Input Hue'!$B:$B,"outras empresas nao financeiras"))/1000000 -> 2168.5504 | E11: =(SUMIFS('Input Hue'!$J:$J,'Input Hue'!$I:$I,"1",'Input Hue'!$C:$C,'5.CC Physical risk'!$D$24,'Input Hue'!$F:$F,'5.CC Physical risk'!$A11&"*",'Input Hue'!$B:$B,"outras empresas nao financeiras",'Input Hue'!$E:$E,">=0",'Input Hue'!$E:$E,"<=5") + SUMIFS('Input Hue'!$J:$J,'Input Hue'!$I:$I,"1",'Input Hue'!$C:$C,'5.CC Physical risk'!$D$24,'Input Hue'!$F:$F,'5.CC Physical risk'!$A11&"*",'Input Hue'!$B:$B,"outras empresas nao financeiras",'Input Hue'!$E:$E,"-4") + SUMIFS('Input Hue'!$J:$J,'Input Hue'!$I:$I,"1",'Input Hue'!$C:$C,'5.CC Physical risk'!$D$24,'Input Hue'!$F:$F,'5.CC Physical risk'!$A11&"*",'Input Hue'!$B:$B,"outras empresas nao financeiras",'Input Hue'!$E:$E,"-1"))/1000000 -> 21.799777 | F11: =(SUMIFS('Input Hue'!$J:$J,'Input Hue'!$I:$I,"1",'Input Hue'!$C:$C,'5.CC Physical risk'!$D$24,'Input Hue'!$F:$F,'5.CC Physical risk'!$A11&"*",'Input Hue'!$B:$B,"outras empresas nao financeiras",'Input Hue'!$E:$E,">5",'Input Hue'!$E:$E,"<=10"))/1000000 -> 38.700755 | G11: =(SUMIFS('Input Hue'!$J:$J,'Input Hue'!$I:$I,"1",'Input Hue'!$C:$C,'5.CC Physical risk'!$D$24,'Input Hue'!$F:$F,'5.CC Physical risk'!$A11&"*",'Input Hue'!$B:$B,"outras empresas nao financeiras",'Input Hue'!$E:$E,">10",'Input Hue'!$E:$E,"<=20"))/1000000 -> 18.556921 | H11: =(SUMIFS('Input Hue'!$J:$J,'Input Hue'!$I:$I,"1",'Input Hue'!$C:$C,'5.CC Physical risk'!$D$24,'Input Hue'!$F:$F,'5.CC Physical risk'!$A11&"*",'Input Hue'!$B:$B,"outras empresas nao financeiras",'Input Hue'!$E:$E,">20") + SUMIFS('Input Hue'!$J:$J,'Input Hue'!$I:$I,"1",'Input Hue'!$C:$C,'5.CC Physical risk'!$D$24,'Input Hue'!$F:$F,'5.CC Physical risk'!$A11&"*",'Input Hue'!$B:$B,"outras empresas nao financeiras",'Input Hue'!$E:$E,"-2") + SUMIFS('Input Hue'!$J:$J,'Input Hue'!$I:$I,"1",'Input Hue'!$C:$C,'5.CC Physical risk'!$D$24,'Input Hue'!$F:$F,'5.CC Physical risk'!$A11&"*",'Input Hue'!$B:$B,"outras empresas nao financeiras",'Input Hue'!$E:$E,"-3") + SUMIFS('Input Hue'!$J:$J,'Input Hue'!$I:$I,"1",'Input Hue'!$C:$C,'5.CC Physical risk'!$D$24,'Input Hue'!$F:$F,'5.CC Physical risk'!$A11&"*",'Input Hue'!$B:$B,"outras empresas nao financeiras",'Input Hue'!$E:$E,"-5"))/1000000 -> 0 | I11: =IFERROR(ROUND(SUMIFS('Input Hue'!$K:$K,'Input Hue'!$I:$I,"1",'Input Hue'!$C:$C,'5.CC Physical risk'!$D$24,'Input Hue'!$F:$F,'5.CC Physical risk'!$A11&"*",'Input Hue'!$B:$B,"outras empresas nao financeiras",'Input Hue'!$E:$E,">0") / SUMIFS('Input Hue'!$J:$J,'Input Hue'!$I:$I,"1",'Input Hue'!$C:$C,'5.CC Physical risk'!$D$24,'Input Hue'!$F:$F,'5.CC Physical risk'!$A11&"*",'Input Hue'!$B:$B,"outras empresas nao financeiras",'Input Hue'!$E:$E,">0"),0),0) -> 8 | J11: =(SUMIFS('Input Hue'!$J:$J,'Input Hue'!$I:$I,"1",'Input Hue'!$C:$C,'5.CC Physical risk'!$D$24,'Input Hue'!$F:$F,'5.CC Physical risk'!$A11&"*",'Input Hue'!$B:$B,"outras empresas nao financeiras",'Input Hue'!$G:$G,"<>"&$K$24,'Input Hue'!$H:$H,'5.CC Physical risk'!$J$24))/1000000 -> 74.807577 | K11: =(SUMIFS('Input Hue'!$J:$J,'Input Hue'!$I:$I,"1",'Input Hue'!$C:$C,'5.CC Physical risk'!$D$24,'Input Hue'!$F:$F,'5.CC Physical risk'!$A11&"*",'Input Hue'!$B:$B,"outras empresas nao financeiras",'Input Hue'!$H:$H,"<>"&$J$24,'Input Hue'!$G:$G,'5.CC Physical risk'!$K$24))/1000000 -> 1.593667 | L11: =(SUMIFS('Input Hue'!$J:$J, 'Input Hue'!$I:$I,"1", 'Input Hue'!$C:$C,'5.CC Physical risk'!$D$24, 'Input Hue'!$F:$F,'5.CC Physical risk'!$A11&"*", 'Input Hue'!$B:$B,"outras empresas nao financeiras", 'Input Hue'!$H:$H,'5.CC Physical risk'!$J$24, 'Input Hue'!$G:$G,'5.CC Physical risk'!$K$24))/1000000 -> 2.656209 | M11: =(SUMIFS('Input Hue'!$J:$J, 'Input Hue'!$I:$I,"1", 'Input Hue'!$C:$C,'5.CC Physical risk'!$D$24, 'Input Hue'!$B:$B,"outras empresas nao financeiras", 'Input Hue'!$F:$F,'5.CC Physical risk'!$A11&"*", 'Input Hue'!$A:$A,'5.CC Physical risk'!$M$24))/1000000 -> 13.923206 | N11: =(SUMIFS('Input Hue'!$J:$J, 'Input Hue'!$I:$I,"1", 'Input Hue'!$C:$C,'5.CC Physical risk'!$D$24, 'Input Hue'!$B:$B,"outras empresas nao financeiras", 'Input Hue'!$F:$F,'5.CC Physical risk'!$A11&"*", 'Input Hue'!$A:$A,'5.CC Physical risk'!$N$24))/1000000 -> 5.435658 | O11: =(SUMIFS('Input Hue'!$J:$J, 'Input Hue'!$I:$I,"1", 'Input Hue'!$C:$C,'5.CC Physical risk'!$O$24, 'Input Hue'!$B:$B,"outras empresas nao financeiras", 'Input Hue'!$F:$F,'5.CC Physical risk'!$A11&"*"))/1000000 -> -3.730347 | P11: =(SUMIFS('Input Hue'!$J:$J, 'Input Hue'!$I:$I,"1", 'Input Hue'!$C:$C,'5.CC Physical risk'!$O$24, 'Input Hue'!$B:$B,"outras empresas nao financeiras", 'Input Hue'!$F:$F,'5.CC Physical risk'!$A11&"*", 'Input Hue'!$A:$A,'5.CC Physical risk'!$M$24))/1000000 -> -0.746707 | Q11: =(SUMIFS('Input Hue'!$J:$J, 'Input Hue'!$I:$I,"1", 'Input Hue'!$C:$C,'5.CC Physical risk'!$O$24, 'Input Hue'!$B:$B,"outras empresas nao financeiras", 'Input Hue'!$F:$F,'5.CC Physical risk'!$A11&"*", 'Input Hue'!$A:$A,'5.CC Physical risk'!$N$24))/1000000 -> -2.842466
A12: D | B12: 4 | C12: D - Electricity, gas, steam and air conditioning supply | D12: =(SUMIFS('Input Hue'!$J:$J,'Input Hue'!$C:$C,'5.CC Physical risk'!$D$24,'Input Hue'!$F:$F,'5.CC Physical risk'!$A12&"*",'Input Hue'!$B:$B,"outras empresas nao financeiras"))/1000000 -> 656.90808 | E12: =(SUMIFS('Input Hue'!$J:$J,'Input Hue'!$I:$I,"1",'Input Hue'!$C:$C,'5.CC Physical risk'!$D$24,'Input Hue'!$F:$F,'5.CC Physical risk'!$A12&"*",'Input Hue'!$B:$B,"outras empresas nao financeiras",'Input Hue'!$E:$E,">=0",'Input Hue'!$E:$E,"<=5") + SUMIFS('Input Hue'!$J:$J,'Input Hue'!$I:$I,"1",'Input Hue'!$C:$C,'5.CC Physical risk'!$D$24,'Input Hue'!$F:$F,'5.CC Physical risk'!$A12&"*",'Input Hue'!$B:$B,"outras empresas nao financeiras",'Input Hue'!$E:$E,"-4") + SUMIFS('Input Hue'!$J:$J,'Input Hue'!$I:$I,"1",'Input Hue'!$C:$C,'5.CC Physical risk'!$D$24,'Input Hue'!$F:$F,'5.CC Physical risk'!$A12&"*",'Input Hue'!$B:$B,"outras empresas nao financeiras",'Input Hue'!$E:$E,"-1"))/1000000 -> 0.842497 | F12: =(SUMIFS('Input Hue'!$J:$J,'Input Hue'!$I:$I,"1",'Input Hue'!$C:$C,'5.CC Physical risk'!$D$24,'Input Hue'!$F:$F,'5.CC Physical risk'!$A12&"*",'Input Hue'!$B:$B,"outras empresas nao financeiras",'Input Hue'!$E:$E,">5",'Input Hue'!$E:$E,"<=10"))/1000000 -> 0 | G12: =(SUMIFS('Input Hue'!$J:$J,'Input Hue'!$I:$I,"1",'Input Hue'!$C:$C,'5.CC Physical risk'!$D$24,'Input Hue'!$F:$F,'5.CC Physical risk'!$A12&"*",'Input Hue'!$B:$B,"outras empresas nao financeiras",'Input Hue'!$E:$E,">10",'Input Hue'!$E:$E,"<=20"))/1000000 -> 0 | H12: =(SUMIFS('Input Hue'!$J:$J,'Input Hue'!$I:$I,"1",'Input Hue'!$C:$C,'5.CC Physical risk'!$D$24,'Input Hue'!$F:$F,'5.CC Physical risk'!$A12&"*",'Input Hue'!$B:$B,"outras empresas nao financeiras",'Input Hue'!$E:$E,">20") + SUMIFS('Input Hue'!$J:$J,'Input Hue'!$I:$I,"1",'Input Hue'!$C:$C,'5.CC Physical risk'!$D$24,'Input Hue'!$F:$F,'5.CC Physical risk'!$A12&"*",'Input Hue'!$B:$B,"outras empresas nao financeiras",'Input Hue'!$E:$E,"-2") + SUMIFS('Input Hue'!$J:$J,'Input Hue'!$I:$I,"1",'Input Hue'!$C:$C,'5.CC Physical risk'!$D$24,'Input Hue'!$F:$F,'5.CC Physical risk'!$A12&"*",'Input Hue'!$B:$B,"outras empresas nao financeiras",'Input Hue'!$E:$E,"-3") + SUMIFS('Input Hue'!$J:$J,'Input Hue'!$I:$I,"1",'Input Hue'!$C:$C,'5.CC Physical risk'!$D$24,'Input Hue'!$F:$F,'5.CC Physical risk'!$A12&"*",'Input Hue'!$B:$B,"outras empresas nao financeiras",'Input Hue'!$E:$E,"-5"))/1000000 -> 0 | I12: =IFERROR(ROUND(SUMIFS('Input Hue'!$K:$K,'Input Hue'!$I:$I,"1",'Input Hue'!$C:$C,'5.CC Physical risk'!$D$24,'Input Hue'!$F:$F,'5.CC Physical risk'!$A12&"*",'Input Hue'!$B:$B,"outras empresas nao financeiras",'Input Hue'!$E:$E,">0") / SUMIFS('Input Hue'!$J:$J,'Input Hue'!$I:$I,"1",'Input Hue'!$C:$C,'5.CC Physical risk'!$D$24,'Input Hue'!$F:$F,'5.CC Physical risk'!$A12&"*",'Input Hue'!$B:$B,"outras empresas nao financeiras",'Input Hue'!$E:$E,">0"),0),0) -> 4 | J12: =(SUMIFS('Input Hue'!$J:$J,'Input Hue'!$I:$I,"1",'Input Hue'!$C:$C,'5.CC Physical risk'!$D$24,'Input Hue'!$F:$F,'5.CC Physical risk'!$A12&"*",'Input Hue'!$B:$B,"outras empresas nao financeiras",'Input Hue'!$G:$G,"<>"&$K$24,'Input Hue'!$H:$H,'5.CC Physical risk'!$J$24))/1000000 -> 0 | K12: =(SUMIFS('Input Hue'!$J:$J,'Input Hue'!$I:$I,"1",'Input Hue'!$C:$C,'5.CC Physical risk'!$D$24,'Input Hue'!$F:$F,'5.CC Physical risk'!$A12&"*",'Input Hue'!$B:$B,"outras empresas nao financeiras",'Input Hue'!$H:$H,"<>"&$J$24,'Input Hue'!$G:$G,'5.CC Physical risk'!$K$24))/1000000 -> 0.842497 | L12: =(SUMIFS('Input Hue'!$J:$J, 'Input Hue'!$I:$I,"1", 'Input Hue'!$C:$C,'5.CC Physical risk'!$D$24, 'Input Hue'!$F:$F,'5.CC Physical risk'!$A12&"*", 'Input Hue'!$B:$B,"outras empresas nao financeiras", 'Input Hue'!$H:$H,'5.CC Physical risk'!$J$24, 'Input Hue'!$G:$G,'5.CC Physical risk'!$K$24))/1000000 -> 0 | M12: =(SUMIFS('Input Hue'!$J:$J, 'Input Hue'!$I:$I,"1", 'Input Hue'!$C:$C,'5.CC Physical risk'!$D$24, 'Input Hue'!$B:$B,"outras empresas nao financeiras", 'Input Hue'!$F:$F,'5.CC Physical risk'!$A12&"*", 'Input Hue'!$A:$A,'5.CC Physical risk'!$M$24))/1000000 -> 0 | N12: =(SUMIFS('Input Hue'!$J:$J, 'Input Hue'!$I:$I,"1", 'Input Hue'!$C:$C,'5.CC Physical risk'!$D$24, 'Input Hue'!$B:$B,"outras empresas nao financeiras", 'Input Hue'!$F:$F,'5.CC Physical risk'!$A12&"*", 'Input Hue'!$A:$A,'5.CC Physical risk'!$N$24))/1000000 -> 0 | O12: =(SUMIFS('Input Hue'!$J:$J, 'Input Hue'!$I:$I,"1", 'Input Hue'!$C:$C,'5.CC Physical risk'!$O$24, 'Input Hue'!$B:$B,"outras empresas nao financeiras", 'Input Hue'!$F:$F,'5.CC Physical risk'!$A12&"*"))/1000000 -> -0.005313 | P12: =(SUMIFS('Input Hue'!$J:$J, 'Input Hue'!$I:$I,"1", 'Input Hue'!$C:$C,'5.CC Physical risk'!$O$24, 'Input Hue'!$B:$B,"outras empresas nao financeiras", 'Input Hue'!$F:$F,'5.CC Physical risk'!$A12&"*", 'Input Hue'!$A:$A,'5.CC Physical risk'!$M$24))/1000000 -> 0 | Q12: =(SUMIFS('Input Hue'!$J:$J, 'Input Hue'!$I:$I,"1", 'Input Hue'!$C:$C,'5.CC Physical risk'!$O$24, 'Input Hue'!$B:$B,"outras empresas nao financeiras", 'Input Hue'!$F:$F,'5.CC Physical risk'!$A12&"*", 'Input Hue'!$A:$A,'5.CC Physical risk'!$N$24))/1000000 -> 0
A13: E | B13: 5 | C13: E - Water supply; sewerage, waste management and remediation activities | D13: =(SUMIFS('Input Hue'!$J:$J,'Input Hue'!$C:$C,'5.CC Physical risk'!$D$24,'Input Hue'!$F:$F,'5.CC Physical risk'!$A13&"*",'Input Hue'!$B:$B,"outras empresas nao financeiras"))/1000000 -> 33.931317 | E13: =(SUMIFS('Input Hue'!$J:$J,'Input Hue'!$I:$I,"1",'Input Hue'!$C:$C,'5.CC Physical risk'!$D$24,'Input Hue'!$F:$F,'5.CC Physical risk'!$A13&"*",'Input Hue'!$B:$B,"outras empresas nao financeiras",'Input Hue'!$E:$E,">=0",'Input Hue'!$E:$E,"<=5") + SUMIFS('Input Hue'!$J:$J,'Input Hue'!$I:$I,"1",'Input Hue'!$C:$C,'5.CC Physical risk'!$D$24,'Input Hue'!$F:$F,'5.CC Physical risk'!$A13&"*",'Input Hue'!$B:$B,"outras empresas nao financeiras",'Input Hue'!$E:$E,"-4") + SUMIFS('Input Hue'!$J:$J,'Input Hue'!$I:$I,"1",'Input Hue'!$C:$C,'5.CC Physical risk'!$D$24,'Input Hue'!$F:$F,'5.CC Physical risk'!$A13&"*",'Input Hue'!$B:$B,"outras empresas nao financeiras",'Input Hue'!$E:$E,"-1"))/1000000 -> 0 | F13: =(SUMIFS('Input Hue'!$J:$J,'Input Hue'!$I:$I,"1",'Input Hue'!$C:$C,'5.CC Physical risk'!$D$24,'Input Hue'!$F:$F,'5.CC Physical risk'!$A13&"*",'Input Hue'!$B:$B,"outras empresas nao financeiras",'Input Hue'!$E:$E,">5",'Input Hue'!$E:$E,"<=10"))/1000000 -> 0 | G13: =(SUMIFS('Input Hue'!$J:$J,'Input Hue'!$I:$I,"1",'Input Hue'!$C:$C,'5.CC Physical risk'!$D$24,'Input Hue'!$F:$F,'5.CC Physical risk'!$A13&"*",'Input Hue'!$B:$B,"outras empresas nao financeiras",'Input Hue'!$E:$E,">10",'Input Hue'!$E:$E,"<=20"))/1000000 -> 0 | H13: =(SUMIFS('Input Hue'!$J:$J,'Input Hue'!$I:$I,"1",'Input Hue'!$C:$C,'5.CC Physical risk'!$D$24,'Input Hue'!$F:$F,'5.CC Physical risk'!$A13&"*",'Input Hue'!$B:$B,"outras empresas nao financeiras",'Input Hue'!$E:$E,">20") + SUMIFS('Input Hue'!$J:$J,'Input Hue'!$I:$I,"1",'Input Hue'!$C:$C,'5.CC Physical risk'!$D$24,'Input Hue'!$F:$F,'5.CC Physical risk'!$A13&"*",'Input Hue'!$B:$B,"outras empresas nao financeiras",'Input Hue'!$E:$E,"-2") + SUMIFS('Input Hue'!$J:$J,'Input Hue'!$I:$I,"1",'Input Hue'!$C:$C,'5.CC Physical risk'!$D$24,'Input Hue'!$F:$F,'5.CC Physical risk'!$A13&"*",'Input Hue'!$B:$B,"outras empresas nao financeiras",'Input Hue'!$E:$E,"-3") + SUMIFS('Input Hue'!$J:$J,'Input Hue'!$I:$I,"1",'Input Hue'!$C:$C,'5.CC Physical risk'!$D$24,'Input Hue'!$F:$F,'5.CC Physical risk'!$A13&"*",'Input Hue'!$B:$B,"outras empresas nao financeiras",'Input Hue'!$E:$E,"-5"))/1000000 -> 0 | I13: =IFERROR(ROUND(SUMIFS('Input Hue'!$K:$K,'Input Hue'!$I:$I,"1",'Input Hue'!$C:$C,'5.CC Physical risk'!$D$24,'Input Hue'!$F:$F,'5.CC Physical risk'!$A13&"*",'Input Hue'!$B:$B,"outras empresas nao financeiras",'Input Hue'!$E:$E,">0") / SUMIFS('Input Hue'!$J:$J,'Input Hue'!$I:$I,"1",'Input Hue'!$C:$C,'5.CC Physical risk'!$D$24,'Input Hue'!$F:$F,'5.CC Physical risk'!$A13&"*",'Input Hue'!$B:$B,"outras empresas nao financeiras",'Input Hue'!$E:$E,">0"),0),0) -> 0 | J13: =(SUMIFS('Input Hue'!$J:$J,'Input Hue'!$I:$I,"1",'Input Hue'!$C:$C,'5.CC Physical risk'!$D$24,'Input Hue'!$F:$F,'5.CC Physical risk'!$A13&"*",'Input Hue'!$B:$B,"outras empresas nao financeiras",'Input Hue'!$G:$G,"<>"&$K$24,'Input Hue'!$H:$H,'5.CC Physical risk'!$J$24))/1000000 -> 0 | K13: =(SUMIFS('Input Hue'!$J:$J,'Input Hue'!$I:$I,"1",'Input Hue'!$C:$C,'5.CC Physical risk'!$D$24,'Input Hue'!$F:$F,'5.CC Physical risk'!$A13&"*",'Input Hue'!$B:$B,"outras empresas nao financeiras",'Input Hue'!$H:$H,"<>"&$J$24,'Input Hue'!$G:$G,'5.CC Physical risk'!$K$24))/1000000 -> 0 | L13: =(SUMIFS('Input Hue'!$J:$J, 'Input Hue'!$I:$I,"1", 'Input Hue'!$C:$C,'5.CC Physical risk'!$D$24, 'Input Hue'!$F:$F,'5.CC Physical risk'!$A13&"*", 'Input Hue'!$B:$B,"outras empresas nao financeiras", 'Input Hue'!$H:$H,'5.CC Physical risk'!$J$24, 'Input Hue'!$G:$G,'5.CC Physical risk'!$K$24))/1000000 -> 0 | M13: =(SUMIFS('Input Hue'!$J:$J, 'Input Hue'!$I:$I,"1", 'Input Hue'!$C:$C,'5.CC Physical risk'!$D$24, 'Input Hue'!$B:$B,"outras empresas nao financeiras", 'Input Hue'!$F:$F,'5.CC Physical risk'!$A13&"*", 'Input Hue'!$A:$A,'5.CC Physical risk'!$M$24))/1000000 -> 0 | N13: =(SUMIFS('Input Hue'!$J:$J, 'Input Hue'!$I:$I,"1", 'Input Hue'!$C:$C,'5.CC Physical risk'!$D$24, 'Input Hue'!$B:$B,"outras empresas nao financeiras", 'Input Hue'!$F:$F,'5.CC Physical risk'!$A13&"*", 'Input Hue'!$A:$A,'5.CC Physical risk'!$N$24))/1000000 -> 0 | O13: =(SUMIFS('Input Hue'!$J:$J, 'Input Hue'!$I:$I,"1", 'Input Hue'!$C:$C,'5.CC Physical risk'!$O$24, 'Input Hue'!$B:$B,"outras empresas nao financeiras", 'Input Hue'!$F:$F,'5.CC Physical risk'!$A13&"*"))/1000000 -> 0 | P13: =(SUMIFS('Input Hue'!$J:$J, 'Input Hue'!$I:$I,"1", 'Input Hue'!$C:$C,'5.CC Physical risk'!$O$24, 'Input Hue'!$B:$B,"outras empresas nao financeiras", 'Input Hue'!$F:$F,'5.CC Physical risk'!$A13&"*", 'Input Hue'!$A:$A,'5.CC Physical risk'!$M$24))/1000000 -> 0 | Q13: =(SUMIFS('Input Hue'!$J:$J, 'Input Hue'!$I:$I,"1", 'Input Hue'!$C:$C,'5.CC Physical risk'!$O$24, 'Input Hue'!$B:$B,"outras empresas nao financeiras", 'Input Hue'!$F:$F,'5.CC Physical risk'!$A13&"*", 'Input Hue'!$A:$A,'5.CC Physical risk'!$N$24))/1000000 -> 0
A14: F | B14: 6 | C14: F - Construction | D14: =(SUMIFS('Input Hue'!$J:$J,'Input Hue'!$C:$C,'5.CC Physical risk'!$D$24,'Input Hue'!$F:$F,'5.CC Physical risk'!$A14&"*",'Input Hue'!$B:$B,"outras empresas nao financeiras"))/1000000 -> 995.02563 | E14: =(SUMIFS('Input Hue'!$J:$J,'Input Hue'!$I:$I,"1",'Input Hue'!$C:$C,'5.CC Physical risk'!$D$24,'Input Hue'!$F:$F,'5.CC Physical risk'!$A14&"*",'Input Hue'!$B:$B,"outras empresas nao financeiras",'Input Hue'!$E:$E,">=0",'Input Hue'!$E:$E,"<=5") + SUMIFS('Input Hue'!$J:$J,'Input Hue'!$I:$I,"1",'Input Hue'!$C:$C,'5.CC Physical risk'!$D$24,'Input Hue'!$F:$F,'5.CC Physical risk'!$A14&"*",'Input Hue'!$B:$B,"outras empresas nao financeiras",'Input Hue'!$E:$E,"-4") + SUMIFS('Input Hue'!$J:$J,'Input Hue'!$I:$I,"1",'Input Hue'!$C:$C,'5.CC Physical risk'!$D$24,'Input Hue'!$F:$F,'5.CC Physical risk'!$A14&"*",'Input Hue'!$B:$B,"outras empresas nao financeiras",'Input Hue'!$E:$E,"-1"))/1000000 -> 4.243803 | F14: =(SUMIFS('Input Hue'!$J:$J,'Input Hue'!$I:$I,"1",'Input Hue'!$C:$C,'5.CC Physical risk'!$D$24,'Input Hue'!$F:$F,'5.CC Physical risk'!$A14&"*",'Input Hue'!$B:$B,"outras empresas nao financeiras",'Input Hue'!$E:$E,">5",'Input Hue'!$E:$E,"<=10"))/1000000 -> 1.741893 | G14: =(SUMIFS('Input Hue'!$J:$J,'Input Hue'!$I:$I,"1",'Input Hue'!$C:$C,'5.CC Physical risk'!$D$24,'Input Hue'!$F:$F,'5.CC Physical risk'!$A14&"*",'Input Hue'!$B:$B,"outras empresas nao financeiras",'Input Hue'!$E:$E,">10",'Input Hue'!$E:$E,"<=20"))/1000000 -> 0.466175 | H14: =(SUMIFS('Input Hue'!$J:$J,'Input Hue'!$I:$I,"1",'Input Hue'!$C:$C,'5.CC Physical risk'!$D$24,'Input Hue'!$F:$F,'5.CC Physical risk'!$A14&"*",'Input Hue'!$B:$B,"outras empresas nao financeiras",'Input Hue'!$E:$E,">20") + SUMIFS('Input Hue'!$J:$J,'Input Hue'!$I:$I,"1",'Input Hue'!$C:$C,'5.CC Physical risk'!$D$24,'Input Hue'!$F:$F,'5.CC Physical risk'!$A14&"*",'Input Hue'!$B:$B,"outras empresas nao financeiras",'Input Hue'!$E:$E,"-2") + SUMIFS('Input Hue'!$J:$J,'Input Hue'!$I:$I,"1",'Input Hue'!$C:$C,'5.CC Physical risk'!$D$24,'Input Hue'!$F:$F,'5.CC Physical risk'!$A14&"*",'Input Hue'!$B:$B,"outras empresas nao financeiras",'Input Hue'!$E:$E,"-3") + SUMIFS('Input Hue'!$J:$J,'Input Hue'!$I:$I,"1",'Input Hue'!$C:$C,'5.CC Physical risk'!$D$24,'Input Hue'!$F:$F,'5.CC Physical risk'!$A14&"*",'Input Hue'!$B:$B,"outras empresas nao financeiras",'Input Hue'!$E:$E,"-5"))/1000000 -> 0 | I14: =IFERROR(ROUND(SUMIFS('Input Hue'!$K:$K,'Input Hue'!$I:$I,"1",'Input Hue'!$C:$C,'5.CC Physical risk'!$D$24,'Input Hue'!$F:$F,'5.CC Physical risk'!$A14&"*",'Input Hue'!$B:$B,"outras empresas nao financeiras",'Input Hue'!$E:$E,">0") / SUMIFS('Input Hue'!$J:$J,'Input Hue'!$I:$I,"1",'Input Hue'!$C:$C,'5.CC Physical risk'!$D$24,'Input Hue'!$F:$F,'5.CC Physical risk'!$A14&"*",'Input Hue'!$B:$B,"outras empresas nao financeiras",'Input Hue'!$E:$E,">0"),0),0) -> 6 | J14: =(SUMIFS('Input Hue'!$J:$J,'Input Hue'!$I:$I,"1",'Input Hue'!$C:$C,'5.CC Physical risk'!$D$24,'Input Hue'!$F:$F,'5.CC Physical risk'!$A14&"*",'Input Hue'!$B:$B,"outras empresas nao financeiras",'Input Hue'!$G:$G,"<>"&$K$24,'Input Hue'!$H:$H,'5.CC Physical risk'!$J$24))/1000000 -> 1.969824 | K14: =(SUMIFS('Input Hue'!$J:$J,'Input Hue'!$I:$I,"1",'Input Hue'!$C:$C,'5.CC Physical risk'!$D$24,'Input Hue'!$F:$F,'5.CC Physical risk'!$A14&"*",'Input Hue'!$B:$B,"outras empresas nao financeiras",'Input Hue'!$H:$H,"<>"&$J$24,'Input Hue'!$G:$G,'5.CC Physical risk'!$K$24))/1000000 -> 3.573172 | L14: =(SUMIFS('Input Hue'!$J:$J, 'Input Hue'!$I:$I,"1", 'Input Hue'!$C:$C,'5.CC Physical risk'!$D$24, 'Input Hue'!$F:$F,'5.CC Physical risk'!$A14&"*", 'Input Hue'!$B:$B,"outras empresas nao financeiras", 'Input Hue'!$H:$H,'5.CC Physical risk'!$J$24, 'Input Hue'!$G:$G,'5.CC Physical risk'!$K$24))/1000000 -> 0.908875 | M14: =(SUMIFS('Input Hue'!$J:$J, 'Input Hue'!$I:$I,"1", 'Input Hue'!$C:$C,'5.CC Physical risk'!$D$24, 'Input Hue'!$B:$B,"outras empresas nao financeiras", 'Input Hue'!$F:$F,'5.CC Physical risk'!$A14&"*", 'Input Hue'!$A:$A,'5.CC Physical risk'!$M$24))/1000000 -> 1.26474 | N14: =(SUMIFS('Input Hue'!$J:$J, 'Input Hue'!$I:$I,"1", 'Input Hue'!$C:$C,'5.CC Physical risk'!$D$24, 'Input Hue'!$B:$B,"outras empresas nao financeiras", 'Input Hue'!$F:$F,'5.CC Physical risk'!$A14&"*", 'Input Hue'!$A:$A,'5.CC Physical risk'!$N$24))/1000000 -> 2.466246 | O14: =(SUMIFS('Input Hue'!$J:$J, 'Input Hue'!$I:$I,"1", 'Input Hue'!$C:$C,'5.CC Physical risk'!$O$24, 'Input Hue'!$B:$B,"outras empresas nao financeiras", 'Input Hue'!$F:$F,'5.CC Physical risk'!$A14&"*"))/1000000 -> -2.49776 | P14: =(SUMIFS('Input Hue'!$J:$J, 'Input Hue'!$I:$I,"1", 'Input Hue'!$C:$C,'5.CC Physical risk'!$O$24, 'Input Hue'!$B:$B,"outras empresas nao financeiras", 'Input Hue'!$F:$F,'5.CC Physical risk'!$A14&"*", 'Input Hue'!$A:$A,'5.CC Physical risk'!$M$24))/1000000 -> -0.03901 | Q14: =(SUMIFS('Input Hue'!$J:$J, 'Input Hue'!$I:$I,"1", 'Input Hue'!$C:$C,'5.CC Physical risk'!$O$24, 'Input Hue'!$B:$B,"outras empresas nao financeiras", 'Input Hue'!$F:$F,'5.CC Physical risk'!$A14&"*", 'Input Hue'!$A:$A,'5.CC Physical risk'!$N$24))/1000000 -> -2.453726
A15: G | B15: 7 | C15: G - Wholesale and retail trade; repair of motor vehicles and motorcycles | D15: =(SUMIFS('Input Hue'!$J:$J,'Input Hue'!$C:$C,'5.CC Physical risk'!$D$24,'Input Hue'!$F:$F,'5.CC Physical risk'!$A15&"*",'Input Hue'!$B:$B,"outras empresas nao financeiras"))/1000000 -> 2070.1135 | E15: =(SUMIFS('Input Hue'!$J:$J,'Input Hue'!$I:$I,"1",'Input Hue'!$C:$C,'5.CC Physical risk'!$D$24,'Input Hue'!$F:$F,'5.CC Physical risk'!$A15&"*",'Input Hue'!$B:$B,"outras empresas nao financeiras",'Input Hue'!$E:$E,">=0",'Input Hue'!$E:$E,"<=5") + SUMIFS('Input Hue'!$J:$J,'Input Hue'!$I:$I,"1",'Input Hue'!$C:$C,'5.CC Physical risk'!$D$24,'Input Hue'!$F:$F,'5.CC Physical risk'!$A15&"*",'Input Hue'!$B:$B,"outras empresas nao financeiras",'Input Hue'!$E:$E,"-4") + SUMIFS('Input Hue'!$J:$J,'Input Hue'!$I:$I,"1",'Input Hue'!$C:$C,'5.CC Physical risk'!$D$24,'Input Hue'!$F:$F,'5.CC Physical risk'!$A15&"*",'Input Hue'!$B:$B,"outras empresas nao financeiras",'Input Hue'!$E:$E,"-1"))/1000000 -> 3.987269 | F15: =(SUMIFS('Input Hue'!$J:$J,'Input Hue'!$I:$I,"1",'Input Hue'!$C:$C,'5.CC Physical risk'!$D$24,'Input Hue'!$F:$F,'5.CC Physical risk'!$A15&"*",'Input Hue'!$B:$B,"outras empresas nao financeiras",'Input Hue'!$E:$E,">5",'Input Hue'!$E:$E,"<=10"))/1000000 -> 6.511786 | G15: =(SUMIFS('Input Hue'!$J:$J,'Input Hue'!$I:$I,"1",'Input Hue'!$C:$C,'5.CC Physical risk'!$D$24,'Input Hue'!$F:$F,'5.CC Physical risk'!$A15&"*",'Input Hue'!$B:$B,"outras empresas nao financeiras",'Input Hue'!$E:$E,">10",'Input Hue'!$E:$E,"<=20"))/1000000 -> 3.410179 | H15: =(SUMIFS('Input Hue'!$J:$J,'Input Hue'!$I:$I,"1",'Input Hue'!$C:$C,'5.CC Physical risk'!$D$24,'Input Hue'!$F:$F,'5.CC Physical risk'!$A15&"*",'Input Hue'!$B:$B,"outras empresas nao financeiras",'Input Hue'!$E:$E,">20") + SUMIFS('Input Hue'!$J:$J,'Input Hue'!$I:$I,"1",'Input Hue'!$C:$C,'5.CC Physical risk'!$D$24,'Input Hue'!$F:$F,'5.CC Physical risk'!$A15&"*",'Input Hue'!$B:$B,"outras empresas nao financeiras",'Input Hue'!$E:$E,"-2") + SUMIFS('Input Hue'!$J:$J,'Input Hue'!$I:$I,"1",'Input Hue'!$C:$C,'5.CC Physical risk'!$D$24,'Input Hue'!$F:$F,'5.CC Physical risk'!$A15&"*",'Input Hue'!$B:$B,"outras empresas nao financeiras",'Input Hue'!$E:$E,"-3") + SUMIFS('Input Hue'!$J:$J,'Input Hue'!$I:$I,"1",'Input Hue'!$C:$C,'5.CC Physical risk'!$D$24,'Input Hue'!$F:$F,'5.CC Physical risk'!$A15&"*",'Input Hue'!$B:$B,"outras empresas nao financeiras",'Input Hue'!$E:$E,"-5"))/1000000 -> 0 | I15: =IFERROR(ROUND(SUMIFS('Input Hue'!$K:$K,'Input Hue'!$I:$I,"1",'Input Hue'!$C:$C,'5.CC Physical risk'!$D$24,'Input Hue'!$F:$F,'5.CC Physical risk'!$A15&"*",'Input Hue'!$B:$B,"outras empresas nao financeiras",'Input Hue'!$E:$E,">0") / SUMIFS('Input Hue'!$J:$J,'Input Hue'!$I:$I,"1",'Input Hue'!$C:$C,'5.CC Physical risk'!$D$24,'Input Hue'!$F:$F,'5.CC Physical risk'!$A15&"*",'Input Hue'!$B:$B,"outras empresas nao financeiras",'Input Hue'!$E:$E,">0"),0),0) -> 8 | J15: =(SUMIFS('Input Hue'!$J:$J,'Input Hue'!$I:$I,"1",'Input Hue'!$C:$C,'5.CC Physical risk'!$D$24,'Input Hue'!$F:$F,'5.CC Physical risk'!$A15&"*",'Input Hue'!$B:$B,"outras empresas nao financeiras",'Input Hue'!$G:$G,"<>"&$K$24,'Input Hue'!$H:$H,'5.CC Physical risk'!$J$24))/1000000 -> 12.534431 | K15: =(SUMIFS('Input Hue'!$J:$J,'Input Hue'!$I:$I,"1",'Input Hue'!$C:$C,'5.CC Physical risk'!$D$24,'Input Hue'!$F:$F,'5.CC Physical risk'!$A15&"*",'Input Hue'!$B:$B,"outras empresas nao financeiras",'Input Hue'!$H:$H,"<>"&$J$24,'Input Hue'!$G:$G,'5.CC Physical risk'!$K$24))/1000000 -> 1.374803 | L15: =(SUMIFS('Input Hue'!$J:$J, 'Input Hue'!$I:$I,"1", 'Input Hue'!$C:$C,'5.CC Physical risk'!$D$24, 'Input Hue'!$F:$F,'5.CC Physical risk'!$A15&"*", 'Input Hue'!$B:$B,"outras empresas nao financeiras", 'Input Hue'!$H:$H,'5.CC Physical risk'!$J$24, 'Input Hue'!$G:$G,'5.CC Physical risk'!$K$24))/1000000 -> 0 | M15: =(SUMIFS('Input Hue'!$J:$J, 'Input Hue'!$I:$I,"1", 'Input Hue'!$C:$C,'5.CC Physical risk'!$D$24, 'Input Hue'!$B:$B,"outras empresas nao financeiras", 'Input Hue'!$F:$F,'5.CC Physical risk'!$A15&"*", 'Input Hue'!$A:$A,'5.CC Physical risk'!$M$24))/1000000 -> 2.342851 | N15: =(SUMIFS('Input Hue'!$J:$J, 'Input Hue'!$I:$I,"1", 'Input Hue'!$C:$C,'5.CC Physical risk'!$D$24, 'Input Hue'!$B:$B,"outras empresas nao financeiras", 'Input Hue'!$F:$F,'5.CC Physical risk'!$A15&"*", 'Input Hue'!$A:$A,'5.CC Physical risk'!$N$24))/1000000 -> 0.477171 | O15: =(SUMIFS('Input Hue'!$J:$J, 'Input Hue'!$I:$I,"1", 'Input Hue'!$C:$C,'5.CC Physical risk'!$O$24, 'Input Hue'!$B:$B,"outras empresas nao financeiras", 'Input Hue'!$F:$F,'5.CC Physical risk'!$A15&"*"))/1000000 -> -0.535255 | P15: =(SUMIFS('Input Hue'!$J:$J, 'Input Hue'!$I:$I,"1", 'Input Hue'!$C:$C,'5.CC Physical risk'!$O$24, 'Input Hue'!$B:$B,"outras empresas nao financeiras", 'Input Hue'!$F:$F,'5.CC Physical risk'!$A15&"*", 'Input Hue'!$A:$A,'5.CC Physical risk'!$M$24))/1000000 -> -0.070458 | Q15: =(SUMIFS('Input Hue'!$J:$J, 'Input Hue'!$I:$I,"1", 'Input Hue'!$C:$C,'5.CC Physical risk'!$O$24, 'Input Hue'!$B:$B,"outras empresas nao financeiras", 'Input Hue'!$F:$F,'5.CC Physical risk'!$A15&"*", 'Input Hue'!$A:$A,'5.CC Physical risk'!$N$24))/1000000 -> -0.443389
A16: H | B16: 8 | C16: H - Transportation and storage | D16: =(SUMIFS('Input Hue'!$J:$J,'Input Hue'!$C:$C,'5.CC Physical risk'!$D$24,'Input Hue'!$F:$F,'5.CC Physical risk'!$A16&"*",'Input Hue'!$B:$B,"outras empresas nao financeiras"))/1000000 -> 774.1598 | E16: =(SUMIFS('Input Hue'!$J:$J,'Input Hue'!$I:$I,"1",'Input Hue'!$C:$C,'5.CC Physical risk'!$D$24,'Input Hue'!$F:$F,'5.CC Physical risk'!$A16&"*",'Input Hue'!$B:$B,"outras empresas nao financeiras",'Input Hue'!$E:$E,">=0",'Input Hue'!$E:$E,"<=5") + SUMIFS('Input Hue'!$J:$J,'Input Hue'!$I:$I,"1",'Input Hue'!$C:$C,'5.CC Physical risk'!$D$24,'Input Hue'!$F:$F,'5.CC Physical risk'!$A16&"*",'Input Hue'!$B:$B,"outras empresas nao financeiras",'Input Hue'!$E:$E,"-4") + SUMIFS('Input Hue'!$J:$J,'Input Hue'!$I:$I,"1",'Input Hue'!$C:$C,'5.CC Physical risk'!$D$24,'Input Hue'!$F:$F,'5.CC Physical risk'!$A16&"*",'Input Hue'!$B:$B,"outras empresas nao financeiras",'Input Hue'!$E:$E,"-1"))/1000000 -> 0.028513 | F16: =(SUMIFS('Input Hue'!$J:$J,'Input Hue'!$I:$I,"1",'Input Hue'!$C:$C,'5.CC Physical risk'!$D$24,'Input Hue'!$F:$F,'5.CC Physical risk'!$A16&"*",'Input Hue'!$B:$B,"outras empresas nao financeiras",'Input Hue'!$E:$E,">5",'Input Hue'!$E:$E,"<=10"))/1000000 -> 0.074909 | G16: =(SUMIFS('Input Hue'!$J:$J,'Input Hue'!$I:$I,"1",'Input Hue'!$C:$C,'5.CC Physical risk'!$D$24,'Input Hue'!$F:$F,'5.CC Physical risk'!$A16&"*",'Input Hue'!$B:$B,"outras empresas nao financeiras",'Input Hue'!$E:$E,">10",'Input Hue'!$E:$E,"<=20"))/1000000 -> 0 | H16: =(SUMIFS('Input Hue'!$J:$J,'Input Hue'!$I:$I,"1",'Input Hue'!$C:$C,'5.CC Physical risk'!$D$24,'Input Hue'!$F:$F,'5.CC Physical risk'!$A16&"*",'Input Hue'!$B:$B,"outras empresas nao financeiras",'Input Hue'!$E:$E,">20") + SUMIFS('Input Hue'!$J:$J,'Input Hue'!$I:$I,"1",'Input Hue'!$C:$C,'5.CC Physical risk'!$D$24,'Input Hue'!$F:$F,'5.CC Physical risk'!$A16&"*",'Input Hue'!$B:$B,"outras empresas nao financeiras",'Input Hue'!$E:$E,"-2") + SUMIFS('Input Hue'!$J:$J,'Input Hue'!$I:$I,"1",'Input Hue'!$C:$C,'5.CC Physical risk'!$D$24,'Input Hue'!$F:$F,'5.CC Physical risk'!$A16&"*",'Input Hue'!$B:$B,"outras empresas nao financeiras",'Input Hue'!$E:$E,"-3") + SUMIFS('Input Hue'!$J:$J,'Input Hue'!$I:$I,"1",'Input Hue'!$C:$C,'5.CC Physical risk'!$D$24,'Input Hue'!$F:$F,'5.CC Physical risk'!$A16&"*",'Input Hue'!$B:$B,"outras empresas nao financeiras",'Input Hue'!$E:$E,"-5"))/1000000 -> 0 | I16: =IFERROR(ROUND(SUMIFS('Input Hue'!$K:$K,'Input Hue'!$I:$I,"1",'Input Hue'!$C:$C,'5.CC Physical risk'!$D$24,'Input Hue'!$F:$F,'5.CC Physical risk'!$A16&"*",'Input Hue'!$B:$B,"outras empresas nao financeiras",'Input Hue'!$E:$E,">0") / SUMIFS('Input Hue'!$J:$J,'Input Hue'!$I:$I,"1",'Input Hue'!$C:$C,'5.CC Physical risk'!$D$24,'Input Hue'!$F:$F,'5.CC Physical risk'!$A16&"*",'Input Hue'!$B:$B,"outras empresas nao financeiras",'Input Hue'!$E:$E,">0"),0),0) -> 6 | J16: =(SUMIFS('Input Hue'!$J:$J,'Input Hue'!$I:$I,"1",'Input Hue'!$C:$C,'5.CC Physical risk'!$D$24,'Input Hue'!$F:$F,'5.CC Physical risk'!$A16&"*",'Input Hue'!$B:$B,"outras empresas nao financeiras",'Input Hue'!$G:$G,"<>"&$K$24,'Input Hue'!$H:$H,'5.CC Physical risk'!$J$24))/1000000 -> 0 | K16: =(SUMIFS('Input Hue'!$J:$J,'Input Hue'!$I:$I,"1",'Input Hue'!$C:$C,'5.CC Physical risk'!$D$24,'Input Hue'!$F:$F,'5.CC Physical risk'!$A16&"*",'Input Hue'!$B:$B,"outras empresas nao financeiras",'Input Hue'!$H:$H,"<>"&$J$24,'Input Hue'!$G:$G,'5.CC Physical risk'!$K$24))/1000000 -> 0.103422 | L16: =(SUMIFS('Input Hue'!$J:$J, 'Input Hue'!$I:$I,"1", 'Input Hue'!$C:$C,'5.CC Physical risk'!$D$24, 'Input Hue'!$F:$F,'5.CC Physical risk'!$A16&"*", 'Input Hue'!$B:$B,"outras empresas nao financeiras", 'Input Hue'!$H:$H,'5.CC Physical risk'!$J$24, 'Input Hue'!$G:$G,'5.CC Physical risk'!$K$24))/1000000 -> 0 | M16: =(SUMIFS('Input Hue'!$J:$J, 'Input Hue'!$I:$I,"1", 'Input Hue'!$C:$C,'5.CC Physical risk'!$D$24, 'Input Hue'!$B:$B,"outras empresas nao financeiras", 'Input Hue'!$F:$F,'5.CC Physical risk'!$A16&"*", 'Input Hue'!$A:$A,'5.CC Physical risk'!$M$24))/1000000 -> 0 | N16: =(SUMIFS('Input Hue'!$J:$J, 'Input Hue'!$I:$I,"1", 'Input Hue'!$C:$C,'5.CC Physical risk'!$D$24, 'Input Hue'!$B:$B,"outras empresas nao financeiras", 'Input Hue'!$F:$F,'5.CC Physical risk'!$A16&"*", 'Input Hue'!$A:$A,'5.CC Physical risk'!$N$24))/1000000 -> 0 | O16: =(SUMIFS('Input Hue'!$J:$J, 'Input Hue'!$I:$I,"1", 'Input Hue'!$C:$C,'5.CC Physical risk'!$O$24, 'Input Hue'!$B:$B,"outras empresas nao financeiras", 'Input Hue'!$F:$F,'5.CC Physical risk'!$A16&"*"))/1000000 -> -0.000152 | P16: =(SUMIFS('Input Hue'!$J:$J, 'Input Hue'!$I:$I,"1", 'Input Hue'!$C:$C,'5.CC Physical risk'!$O$24, 'Input Hue'!$B:$B,"outras empresas nao financeiras", 'Input Hue'!$F:$F,'5.CC Physical risk'!$A16&"*", 'Input Hue'!$A:$A,'5.CC Physical risk'!$M$24))/1000000 -> 0 | Q16: =(SUMIFS('Input Hue'!$J:$J, 'Input Hue'!$I:$I,"1", 'Input Hue'!$C:$C,'5.CC Physical risk'!$O$24, 'Input Hue'!$B:$B,"outras empresas nao financeiras", 'Input Hue'!$F:$F,'5.CC Physical risk'!$A16&"*", 'Input Hue'!$A:$A,'5.CC Physical risk'!$N$24))/1000000 -> 0
A17: L | B17: 9 | C17: L - Real estate activities | D17: =(SUMIFS('Input Hue'!$J:$J,'Input Hue'!$C:$C,'5.CC Physical risk'!$D$24,'Input Hue'!$F:$F,'5.CC Physical risk'!$A17&"*",'Input Hue'!$B:$B,"outras empresas nao financeiras"))/1000000 -> 1252.5448 | E17: =(SUMIFS('Input Hue'!$J:$J,'Input Hue'!$I:$I,"1",'Input Hue'!$C:$C,'5.CC Physical risk'!$D$24,'Input Hue'!$F:$F,'5.CC Physical risk'!$A17&"*",'Input Hue'!$B:$B,"outras empresas nao financeiras",'Input Hue'!$E:$E,">=0",'Input Hue'!$E:$E,"<=5") + SUMIFS('Input Hue'!$J:$J,'Input Hue'!$I:$I,"1",'Input Hue'!$C:$C,'5.CC Physical risk'!$D$24,'Input Hue'!$F:$F,'5.CC Physical risk'!$A17&"*",'Input Hue'!$B:$B,"outras empresas nao financeiras",'Input Hue'!$E:$E,"-4") + SUMIFS('Input Hue'!$J:$J,'Input Hue'!$I:$I,"1",'Input Hue'!$C:$C,'5.CC Physical risk'!$D$24,'Input Hue'!$F:$F,'5.CC Physical risk'!$A17&"*",'Input Hue'!$B:$B,"outras empresas nao financeiras",'Input Hue'!$E:$E,"-1"))/1000000 -> 15.361595 | F17: =(SUMIFS('Input Hue'!$J:$J,'Input Hue'!$I:$I,"1",'Input Hue'!$C:$C,'5.CC Physical risk'!$D$24,'Input Hue'!$F:$F,'5.CC Physical risk'!$A17&"*",'Input Hue'!$B:$B,"outras empresas nao financeiras",'Input Hue'!$E:$E,">5",'Input Hue'!$E:$E,"<=10"))/1000000 -> 2.146628 | G17: =(SUMIFS('Input Hue'!$J:$J,'Input Hue'!$I:$I,"1",'Input Hue'!$C:$C,'5.CC Physical risk'!$D$24,'Input Hue'!$F:$F,'5.CC Physical risk'!$A17&"*",'Input Hue'!$B:$B,"outras empresas nao financeiras",'Input Hue'!$E:$E,">10",'Input Hue'!$E:$E,"<=20"))/1000000 -> 0.143384 | H17: =(SUMIFS('Input Hue'!$J:$J,'Input Hue'!$I:$I,"1",'Input Hue'!$C:$C,'5.CC Physical risk'!$D$24,'Input Hue'!$F:$F,'5.CC Physical risk'!$A17&"*",'Input Hue'!$B:$B,"outras empresas nao financeiras",'Input Hue'!$E:$E,">20") + SUMIFS('Input Hue'!$J:$J,'Input Hue'!$I:$I,"1",'Input Hue'!$C:$C,'5.CC Physical risk'!$D$24,'Input Hue'!$F:$F,'5.CC Physical risk'!$A17&"*",'Input Hue'!$B:$B,"outras empresas nao financeiras",'Input Hue'!$E:$E,"-2") + SUMIFS('Input Hue'!$J:$J,'Input Hue'!$I:$I,"1",'Input Hue'!$C:$C,'5.CC Physical risk'!$D$24,'Input Hue'!$F:$F,'5.CC Physical risk'!$A17&"*",'Input Hue'!$B:$B,"outras empresas nao financeiras",'Input Hue'!$E:$E,"-3") + SUMIFS('Input Hue'!$J:$J,'Input Hue'!$I:$I,"1",'Input Hue'!$C:$C,'5.CC Physical risk'!$D$24,'Input Hue'!$F:$F,'5.CC Physical risk'!$A17&"*",'Input Hue'!$B:$B,"outras empresas nao financeiras",'Input Hue'!$E:$E,"-5"))/1000000 -> 0 | I17: =IFERROR(ROUND(SUMIFS('Input Hue'!$K:$K,'Input Hue'!$I:$I,"1",'Input Hue'!$C:$C,'5.CC Physical risk'!$D$24,'Input Hue'!$F:$F,'5.CC Physical risk'!$A17&"*",'Input Hue'!$B:$B,"outras empresas nao financeiras",'Input Hue'!$E:$E,">0") / SUMIFS('Input Hue'!$J:$J,'Input Hue'!$I:$I,"1",'Input Hue'!$C:$C,'5.CC Physical risk'!$D$24,'Input Hue'!$F:$F,'5.CC Physical risk'!$A17&"*",'Input Hue'!$B:$B,"outras empresas nao financeiras",'Input Hue'!$E:$E,">0"),0),0) -> 5 | J17: =(SUMIFS('Input Hue'!$J:$J,'Input Hue'!$I:$I,"1",'Input Hue'!$C:$C,'5.CC Physical risk'!$D$24,'Input Hue'!$F:$F,'5.CC Physical risk'!$A17&"*",'Input Hue'!$B:$B,"outras empresas nao financeiras",'Input Hue'!$G:$G,"<>"&$K$24,'Input Hue'!$H:$H,'5.CC Physical risk'!$J$24))/1000000 -> 0 | K17: =(SUMIFS('Input Hue'!$J:$J,'Input Hue'!$I:$I,"1",'Input Hue'!$C:$C,'5.CC Physical risk'!$D$24,'Input Hue'!$F:$F,'5.CC Physical risk'!$A17&"*",'Input Hue'!$B:$B,"outras empresas nao financeiras",'Input Hue'!$H:$H,"<>"&$J$24,'Input Hue'!$G:$G,'5.CC Physical risk'!$K$24))/1000000 -> 17.651607 | L17: =(SUMIFS('Input Hue'!$J:$J, 'Input Hue'!$I:$I,"1", 'Input Hue'!$C:$C,'5.CC Physical risk'!$D$24, 'Input Hue'!$F:$F,'5.CC Physical risk'!$A17&"*", 'Input Hue'!$B:$B,"outras empresas nao financeiras", 'Input Hue'!$H:$H,'5.CC Physical risk'!$J$24, 'Input Hue'!$G:$G,'5.CC Physical risk'!$K$24))/1000000 -> 0 | M17: =(SUMIFS('Input Hue'!$J:$J, 'Input Hue'!$I:$I,"1", 'Input Hue'!$C:$C,'5.CC Physical risk'!$D$24, 'Input Hue'!$B:$B,"outras empresas nao financeiras", 'Input Hue'!$F:$F,'5.CC Physical risk'!$A17&"*", 'Input Hue'!$A:$A,'5.CC Physical risk'!$M$24))/1000000 -> 0.067063 | N17: =(SUMIFS('Input Hue'!$J:$J, 'Input Hue'!$I:$I,"1", 'Input Hue'!$C:$C,'5.CC Physical risk'!$D$24, 'Input Hue'!$B:$B,"outras empresas nao financeiras", 'Input Hue'!$F:$F,'5.CC Physical risk'!$A17&"*", 'Input Hue'!$A:$A,'5.CC Physical risk'!$N$24))/1000000 -> 12.449708 | O17: =(SUMIFS('Input Hue'!$J:$J, 'Input Hue'!$I:$I,"1", 'Input Hue'!$C:$C,'5.CC Physical risk'!$O$24, 'Input Hue'!$B:$B,"outras empresas nao financeiras", 'Input Hue'!$F:$F,'5.CC Physical risk'!$A17&"*"))/1000000 -> -12.416869 | P17: =(SUMIFS('Input Hue'!$J:$J, 'Input Hue'!$I:$I,"1", 'Input Hue'!$C:$C,'5.CC Physical risk'!$O$24, 'Input Hue'!$B:$B,"outras empresas nao financeiras", 'Input Hue'!$F:$F,'5.CC Physical risk'!$A17&"*", 'Input Hue'!$A:$A,'5.CC Physical risk'!$M$24))/1000000 -> -0.008592 | Q17: =(SUMIFS('Input Hue'!$J:$J, 'Input Hue'!$I:$I,"1", 'Input Hue'!$C:$C,'5.CC Physical risk'!$O$24, 'Input Hue'!$B:$B,"outras empresas nao financeiras", 'Input Hue'!$F:$F,'5.CC Physical risk'!$A17&"*", 'Input Hue'!$A:$A,'5.CC Physical risk'!$N$24))/1000000 -> -12.400323
A18: Garantia Residencial | B18: 10 | C18: Loans collateralised by residential immovable property | D18: =(SUMIFS('Input Hue'!$J:$J, 'Input Hue'!$C:$C,'5.CC Physical risk'!$D$24, 'Input Hue'!$D:$D,'5.CC Physical risk'!$A18&"*"))/1000000 -> 23291.747 | E18: =(SUMIFS('Input Hue'!$J:$J,'Input Hue'!$I:$I,"1",'Input Hue'!$C:$C,'5.CC Physical risk'!$D$24,'Input Hue'!$D:$D,'5.CC Physical risk'!$A18,'Input Hue'!$E:$E,">=0",'Input Hue'!$E:$E,"<=5") + SUMIFS('Input Hue'!$J:$J,'Input Hue'!$I:$I,"1",'Input Hue'!$C:$C,'5.CC Physical risk'!$D$24,'Input Hue'!$D:$D,'5.CC Physical risk'!$A18,'Input Hue'!$E:$E,"-4") + SUMIFS('Input Hue'!$J:$J,'Input Hue'!$I:$I,"1",'Input Hue'!$C:$C,'5.CC Physical risk'!$D$24,'Input Hue'!$D:$D,'5.CC Physical risk'!$A18,'Input Hue'!$E:$E,"-1"))/1000000 -> 6.052976 | F18: =(SUMIFS('Input Hue'!$J:$J,'Input Hue'!$I:$I,"1",'Input Hue'!$C:$C,'5.CC Physical risk'!$D$24,'Input Hue'!$D:$D,'5.CC Physical risk'!$A18,'Input Hue'!$E:$E,">5",'Input Hue'!$E:$E,"<=10"))/1000000 -> 18.426415 | G18: =(SUMIFS('Input Hue'!$J:$J,'Input Hue'!$I:$I,"1",'Input Hue'!$C:$C,'5.CC Physical risk'!$D$24,'Input Hue'!$D:$D,'5.CC Physical risk'!$A18,'Input Hue'!$E:$E,">10",'Input Hue'!$E:$E,"<=20"))/1000000 -> 61.651435 | H18: =(SUMIFS('Input Hue'!$J:$J,'Input Hue'!$I:$I,"1",'Input Hue'!$C:$C,'5.CC Physical risk'!$D$24,'Input Hue'!$D:$D,'5.CC Physical risk'!$A18,'Input Hue'!$E:$E,">20") + SUMIFS('Input Hue'!$J:$J,'Input Hue'!$I:$I,"1",'Input Hue'!$C:$C,'5.CC Physical risk'!$D$24,'Input Hue'!$D:$D,'5.CC Physical risk'!$A18,'Input Hue'!$E:$E,"-2") + SUMIFS('Input Hue'!$J:$J,'Input Hue'!$I:$I,"1",'Input Hue'!$C:$C,'5.CC Physical risk'!$D$24,'Input Hue'!$D:$D,'5.CC Physical risk'!$A18,'Input Hue'!$E:$E,"-3") + SUMIFS('Input Hue'!$J:$J,'Input Hue'!$I:$I,"1",'Input Hue'!$C:$C,'5.CC Physical risk'!$D$24,'Input Hue'!$D:$D,'5.CC Physical risk'!$A18,'Input Hue'!$E:$E,"-5"))/1000000 -> 324.73496 | I18: =IFERROR(ROUND(SUMIFS('Input Hue'!$K:$K,'Input Hue'!$I:$I,"1",'Input Hue'!$C:$C,'5.CC Physical risk'!$D$24,'Input Hue'!$D:$D,'5.CC Physical risk'!$A18,'Input Hue'!$E:$E,">0") / SUMIFS('Input Hue'!$J:$J,'Input Hue'!$I:$I,"1",'Input Hue'!$C:$C,'5.CC Physical risk'!$D$24,'Input Hue'!$D:$D,'5.CC Physical risk'!$A18,'Input Hue'!$E:$E,">0"),0),0) -> 27 | J18: =(SUMIFS('Input Hue'!$J:$J,'Input Hue'!$I:$I,"1",'Input Hue'!$C:$C,'5.CC Physical risk'!$D$24,'Input Hue'!$D:$D,'5.CC Physical risk'!$A18&"*",'Input Hue'!$H:$H,"CHRO1",'Input Hue'!$G:$G,"ACUT2"))/1000000 -> 65.2391 | K18: =(SUMIFS('Input Hue'!$J:$J,'Input Hue'!$I:$I,"1",'Input Hue'!$C:$C,'5.CC Physical risk'!$D$24,'Input Hue'!$D:$D,'5.CC Physical risk'!$A18&"*",'Input Hue'!$H:$H,"CHRO2",'Input Hue'!$G:$G,"ACUT1"))/1000000 -> 337.67818 | L18: =(SUMIFS('Input Hue'!$J:$J,'Input Hue'!$I:$I,"1",'Input Hue'!$C:$C,'5.CC Physical risk'!$D$24,'Input Hue'!$D:$D,'5.CC Physical risk'!$A18&"*",'Input Hue'!$H:$H,"CHRO1",'Input Hue'!$G:$G,"ACUT1"))/1000000 -> 7.948499 | M18: =SUM(SUMIFS('Input Hue'!$J:$J, 'Input Hue'!$I:$I,"1", 'Input Hue'!$C:$C,'5.CC Physical risk'!$D$24, 'Input Hue'!$D:$D,'5.CC Physical risk'!$A18&"*", 'Input Hue'!$A:$A,'5.CC Physical risk'!$M$24))/1000000 -> 36.087415 | N18: =SUM(SUMIFS('Input Hue'!$J:$J, 'Input Hue'!$I:$I,"1", 'Input Hue'!$C:$C,'5.CC Physical risk'!$D$24, 'Input Hue'!$D:$D,'5.CC Physical risk'!$A18&"*", 'Input Hue'!$A:$A,'5.CC Physical risk'!$N$24))/1000000 -> 6.368013 | O18: =SUM(SUMIFS('Input Hue'!$J:$J, 'Input Hue'!$I:$I,"1", 'Input Hue'!$C:$C,'5.CC Physical risk'!$O$24, 'Input Hue'!$D:$D,'5.CC Physical risk'!$A18))/1000000 -> -3.305494 | P18: =SUM(SUMIFS('Input Hue'!$J:$J, 'Input Hue'!$I:$I,"1", 'Input Hue'!$C:$C,'5.CC Physical risk'!$O$24, 'Input Hue'!$D:$D,'5.CC Physical risk'!$A18&"*", 'Input Hue'!$A:$A,'5.CC Physical risk'!$M$24))/1000000 -> -1.076484 | Q18: =SUM(SUMIFS('Input Hue'!$J:$J, 'Input Hue'!$I:$I,"1", 'Input Hue'!$C:$C,'5.CC Physical risk'!$O$24, 'Input Hue'!$D:$D,'5.CC Physical risk'!$A18&"*", 'Input Hue'!$A:$A,'5.CC Physical risk'!$N$24))/1000000 -> -2.021061
