Workbook

Sheet 1. Status Resumo
D11: Resumo de Testes | L11: Highlights
L12: Resumo semana atual: Equipa de tecnologia disponibilizou um total de 8 campos, bem como a correção de 3 incidências. 1. Certificação B02.00: Foram testados 5 campos disponibilizados pela equipa de IT - 1 da tabela de loan tape e 4 da tabela de output. Adicionalmente, foram re-testadas 3 incidências que foram corrigidas pela equipa de IT (1 da tabela de output e 2 da tabela de loan tape), tendo 2 campos ficado ok e 1 deles manteve-se com incidências. 2. Certificação B05.00: Não foram disponibilizados novos campos por IT na entrega de 16/12. 3. Certificação B90.00: Foram testados 3 campos disponibilizados pela equipa de IT - 1 da tabela de loan tape e 2 da tabela de output. Estes 3 campos mantêm-se com incidências. 4. Controlos: Foram efetuados 18 novos controlos, um deles com incidências. 5. Partilha de incidências: será partilhado formalmente durante o dia de hoje um novo ficheiro de incidências. Próxima semana: - Receção de 2 campos da equipa de IT (entrega a 22 de Dezembro); - Continuação da certificação dos campos da tabela de output para a totalidade do universo; - Continuação da preparação do ficheiro final de controlos em ODBC.
D13: Streams | F13: Semana Atual
F14: Por iniciar | G14: Em curso | H14: Concluído | I14: Com Incidências | J14: Pendente de desenvolv.
C15: A. Novos Campos | D15: B02.00
C16: B1. Re-especificação de campos de Sindicados | D16: Loan Tape | F16: =COUNTIFS('2. Status Detalhe Campos'!B:B,"B02.00",'2. Status Detalhe Campos'!C:C,"Loan Tape",'2. Status Detalhe Campos'!I:I,'1. Status Resumo'!$F$14) -> 0 | G16: =COUNTIFS('2. Status Detalhe Campos'!B:B,"B02.00",'2. Status Detalhe Campos'!C:C,"Loan Tape",'2. Status Detalhe Campos'!I:I,'1. Status Resumo'!$G$14) -> 1 | H16: =COUNTIFS('2. Status Detalhe Campos'!B:B,"B02.00",'2. Status Detalhe Campos'!C:C,"Loan Tape",'2. Status Detalhe Campos'!I:I,'1. Status Resumo'!$H$14) -> 23 | I16: =COUNTIFS('2. Status Detalhe Campos'!B:B,"B02.00",'2. Status Detalhe Campos'!C:C,"Loan Tape",'2. Status Detalhe Campos'!I:I,'1. Status Resumo'!$I$14) -> 6 | J16: =COUNTIFS('2. Status Detalhe Campos'!B:B,"B02.00",'2. Status Detalhe Campos'!C:C,"Loan Tape",'2. Status Detalhe Campos'!I:I,'1. Status Resumo'!$J$14) -> 0 | K16: =SUM(F16:J16) -> 30
C17: B2. Re-especificação de outros campos | D17: Tabela Output | F17: =COUNTIFS('2. Status Detalhe Campos'!B:B,"B02.00",'2. Status Detalhe Campos'!C:C,"Tabela Output",'2. Status Detalhe Campos'!I:I,'1. Status Resumo'!F14) -> 0 | G17: =COUNTIFS('2. Status Detalhe Campos'!B:B,"B02.00",'2. Status Detalhe Campos'!C:C,"Tabela Output",'2. Status Detalhe Campos'!I:I,'1. Status Resumo'!G14) -> 0 | H17: =COUNTIFS('2. Status Detalhe Campos'!B:B,"B02.00",'2. Status Detalhe Campos'!C:C,"Tabela Output",'2. Status Detalhe Campos'!I:I,'1. Status Resumo'!H14) -> 75 | I17: =COUNTIFS('2. Status Detalhe Campos'!B:B,"B02.00",'2. Status Detalhe Campos'!C:C,"Tabela Output",'2. Status Detalhe Campos'!I:I,'1. Status Resumo'!I14) -> 6 | J17: =COUNTIFS('2. Status Detalhe Campos'!B:B,"B02.00",'2. Status Detalhe Campos'!C:C,"Tabela Output",'2. Status Detalhe Campos'!I:I,'1. Status Resumo'!J14) -> 0 | K17: =SUM(F17:J17) -> 81
C18: F4. Fora âmbito | Re-especificação de campos complexos - Dem. Fin. CIB | D18: Total | F18: =SUM(F16:F17) -> 0 | G18: =SUM(G16:G17) -> 1 | H18: =SUM(H16:H17) -> 98 | I18: =SUM(I16:I17) -> 12 | J18: =SUM(J16:J17) -> 0 | K18: =SUM(F18:J18) -> 111
C19: C. Campos em testes ou c/ incidências | D19: B05.00
C20: D. Campos com NOK controlos Corporativos | D20: Loan Tape | F20: =COUNTIFS('2. Status Detalhe Campos'!B:B,"B05.00",'2. Status Detalhe Campos'!C:C,"Loan Tape",'2. Status Detalhe Campos'!I:I,'1. Status Resumo'!F14) -> 0 | G20: =COUNTIFS('2. Status Detalhe Campos'!B:B,"B05.00",'2. Status Detalhe Campos'!C:C,"Loan Tape",'2. Status Detalhe Campos'!I:I,'1. Status Resumo'!G14) -> 0 | H20: =COUNTIFS('2. Status Detalhe Campos'!B:B,"B05.00",'2. Status Detalhe Campos'!C:C,"Loan Tape",'2. Status Detalhe Campos'!I:I,'1. Status Resumo'!H14) -> 4 | I20: =COUNTIFS('2. Status Detalhe Campos'!B:B,"B05.00",'2. Status Detalhe Campos'!C:C,"Loan Tape",'2. Status Detalhe Campos'!I:I,'1. Status Resumo'!I14) -> 0 | J20: =COUNTIFS('2. Status Detalhe Campos'!B:B,"B05.00",'2. Status Detalhe Campos'!C:C,"Loan Tape",'2. Status Detalhe Campos'!I:I,'1. Status Resumo'!J14) -> 1 | K20: =SUM(F20:J20) -> 5
C21: E. Campos com outras possíveis alterações - Dependente de decisões OSI | D21: Tabela Output | F21: =COUNTIFS('2. Status Detalhe Campos'!B:B,"B05.00",'2. Status Detalhe Campos'!C:C,"Tabela Output",'2. Status Detalhe Campos'!I:I,'1. Status Resumo'!F14) -> 0 | G21: =COUNTIFS('2. Status Detalhe Campos'!B:B,"B05.00",'2. Status Detalhe Campos'!C:C,"Tabela Output",'2. Status Detalhe Campos'!I:I,'1. Status Resumo'!G14) -> 0 | H21: =COUNTIFS('2. Status Detalhe Campos'!B:B,"B05.00",'2. Status Detalhe Campos'!C:C,"Tabela Output",'2. Status Detalhe Campos'!I:I,'1. Status Resumo'!H14) -> 14 | I21: =COUNTIFS('2. Status Detalhe Campos'!B:B,"B05.00",'2. Status Detalhe Campos'!C:C,"Tabela Output",'2. Status Detalhe Campos'!I:I,'1. Status Resumo'!I14) -> 0 | J21: =COUNTIFS('2. Status Detalhe Campos'!B:B,"B05.00",'2. Status Detalhe Campos'!C:C,"Tabela Output",'2. Status Detalhe Campos'!I:I,'1. Status Resumo'!J14) -> 1 | K21: =SUM(F21:J21) -> 15
C22: F4. Fora âmbito | Re-especificação de campos complexos - Dem. Fin. CIB | D22: Total | F22: =SUM(F20:F21) -> 0 | G22: =SUM(G20:G21) -> 0 | H22: =SUM(H20:H21) -> 18 | I22: =SUM(I20:I21) -> 0 | J22: =SUM(J20:J21) -> 2 | K22: =SUM(F22:J22) -> 20
C23: F1. Fora âmbito | Campos concluídos - Sem necessidade de espec. | D23: B90.00
C24: F2. Fora âmbito | Campos em testes ou c/ incidências (LT - PM) | D24: Loan Tape | F24: =COUNTIFS('2. Status Detalhe Campos'!B:B,"B90.00",'2. Status Detalhe Campos'!C:C,"Loan Tape",'2. Status Detalhe Campos'!I:I,'1. Status Resumo'!$F$14) -> 0 | G24: =COUNTIFS('2. Status Detalhe Campos'!B:B,"B90.00",'2. Status Detalhe Campos'!C:C,"Loan Tape",'2. Status Detalhe Campos'!I:I,'1. Status Resumo'!$G$14) -> 0 | H24: =COUNTIFS('2. Status Detalhe Campos'!B:B,"B90.00",'2. Status Detalhe Campos'!C:C,"Loan Tape",'2. Status Detalhe Campos'!I:I,'1. Status Resumo'!$H$14) -> 7 | I24: =COUNTIFS('2. Status Detalhe Campos'!B:B,"B90.00",'2. Status Detalhe Campos'!C:C,"Loan Tape",'2. Status Detalhe Campos'!I:I,'1. Status Resumo'!$I$14) -> 4 | J24: =COUNTIFS('2. Status Detalhe Campos'!B:B,"B90.00",'2. Status Detalhe Campos'!C:C,"Loan Tape",'2. Status Detalhe Campos'!I:I,'1. Status Resumo'!$J$14) -> 0 | K24: =SUM(F24:J24) -> 11
C25: F3. Fora âmbito | Fonte manual LF | D25: Tabela Output | F25: =COUNTIFS('2. Status Detalhe Campos'!B:B,"B90.00",'2. Status Detalhe Campos'!C:C,"Tabela Output",'2. Status Detalhe Campos'!I:I,'1. Status Resumo'!$F$14) -> 0 | G25: =COUNTIFS('2. Status Detalhe Campos'!B:B,"B90.00",'2. Status Detalhe Campos'!C:C,"Tabela Output",'2. Status Detalhe Campos'!I:I,'1. Status Resumo'!$G$14) -> 0 | H25: =COUNTIFS('2. Status Detalhe Campos'!B:B,"B90.00",'2. Status Detalhe Campos'!C:C,"Tabela Output",'2. Status Detalhe Campos'!I:I,'1. Status Resumo'!$H$14) -> 7 | I25: =COUNTIFS('2. Status Detalhe Campos'!B:B,"B90.00",'2. Status Detalhe Campos'!C:C,"Tabela Output",'2. Status Detalhe Campos'!I:I,'1. Status Resumo'!$I$14) -> 4 | J25: =COUNTIFS('2. Status Detalhe Campos'!B:B,"B90.00",'2. Status Detalhe Campos'!C:C,"Tabela Output",'2. Status Detalhe Campos'!I:I,'1. Status Resumo'!$J$14) -> 0 | K25: =SUM(F25:J25) -> 11
C26: F4. Fora âmbito | Re-especificação de campos complexos - Dem. Fin. CIB | D26: Total | F26: =SUM(F24:F25) -> 0 | G26: =SUM(G24:G25) -> 0 | H26: =SUM(H24:H25) -> 14 | I26: =SUM(I24:I25) -> 8 | J26: =SUM(J24:J25) -> 0 | K26: =SUM(F26:J26) -> 22
D28: Resumo de Controlos
D30: Streams | F30: Semana Atual
F31: Por iniciar | G31: Em curso | H31: Concluído | I31: Com Incidências | J31: Pendente de desenvolv.
D32: B02.00 | F32: =COUNTIFS('2. Status Detalhe Campos'!$B:$B,$D$32,'2. Status Detalhe Campos'!$C:$C,"Controlos",'2. Status Detalhe Campos'!$I:$I,F$31) -> 0 | G32: =COUNTIFS('2. Status Detalhe Campos'!$B:$B,$D$32,'2. Status Detalhe Campos'!$C:$C,"Controlos",'2. Status Detalhe Campos'!$I:$I,G$31) -> 5 | H32: =COUNTIFS('2. Status Detalhe Campos'!$B:$B,$D$32,'2. Status Detalhe Campos'!$C:$C,"Controlos",'2. Status Detalhe Campos'!$I:$I,H$31) -> 142 | I32: =COUNTIFS('2. Status Detalhe Campos'!$B:$B,$D$32,'2. Status Detalhe Campos'!$C:$C,"Controlos",'2. Status Detalhe Campos'!$I:$I,I$31) -> 9 | J32: =COUNTIFS('2. Status Detalhe Campos'!$B:$B,$D$32,'2. Status Detalhe Campos'!$C:$C,"Controlos",'2. Status Detalhe Campos'!$I:$I,J$31) -> 0 | K32: =SUM(F32:J32) -> 156
D33: B05.00 | F33: =COUNTIFS('2. Status Detalhe Campos'!$B:$B,$D$33,'2. Status Detalhe Campos'!$C:$C,"Controlos",'2. Status Detalhe Campos'!$I:$I,F$31) -> 0 | G33: =COUNTIFS('2. Status Detalhe Campos'!$B:$B,$D$33,'2. Status Detalhe Campos'!$C:$C,"Controlos",'2. Status Detalhe Campos'!$I:$I,G$31) -> 0 | H33: =COUNTIFS('2. Status Detalhe Campos'!$B:$B,$D$33,'2. Status Detalhe Campos'!$C:$C,"Controlos",'2. Status Detalhe Campos'!$I:$I,H$31) -> 15 | I33: =COUNTIFS('2. Status Detalhe Campos'!$B:$B,$D$33,'2. Status Detalhe Campos'!$C:$C,"Controlos",'2. Status Detalhe Campos'!$I:$I,I$31) -> 2 | J33: =COUNTIFS('2. Status Detalhe Campos'!$B:$B,$D$33,'2. Status Detalhe Campos'!$C:$C,"Controlos",'2. Status Detalhe Campos'!$I:$I,J$31) -> 2 | K33: =SUM(F33:J33) -> 19
D34: B90.00 | F34: =COUNTIFS('2. Status Detalhe Campos'!$B:$B,$D$34,'2. Status Detalhe Campos'!$C:$C,"Controlos",'2. Status Detalhe Campos'!$I:$I,F$31) -> 0 | G34: =COUNTIFS('2. Status Detalhe Campos'!$B:$B,$D$34,'2. Status Detalhe Campos'!$C:$C,"Controlos",'2. Status Detalhe Campos'!$I:$I,G$31) -> 0 | H34: =COUNTIFS('2. Status Detalhe Campos'!$B:$B,$D$34,'2. Status Detalhe Campos'!$C:$C,"Controlos",'2. Status Detalhe Campos'!$I:$I,H$31) -> 12 | I34: =COUNTIFS('2. Status Detalhe Campos'!$B:$B,$D$34,'2. Status Detalhe Campos'!$C:$C,"Controlos",'2. Status Detalhe Campos'!$I:$I,I$31) -> 3 | J34: =COUNTIFS('2. Status Detalhe Campos'!$B:$B,$D$34,'2. Status Detalhe Campos'!$C:$C,"Controlos",'2. Status Detalhe Campos'!$I:$I,J$31) -> 0 | K34: =SUM(F34:J34) -> 15
D35: Total | F35: =SUM(F32:F34) -> 0 | G35: =SUM(G32:G34) -> 5 | H35: =SUM(H32:H34) -> 169 | I35: =SUM(I32:I34) -> 14 | J35: =SUM(J32:J34) -> 2 | K35: =SUM(F35:J35) -> 190
D42: B02.00
P45: Highlights
C46: A. Novos Campos | P46: Resumo semana atual: Foram testados 5 campos - 1 da tabela de loan tape e 4 da tabela de output; Tabela de Loan Tape (lt005_instr_ent): - 1 campo com incidências (prtn_amnt_rprtng_entty). Tabela de Output (out_B0200_main_liabilities): Foram testados 4 campos: -2 campos com incidências (0120_otstndng_amnt, 0130_rlvnt_amnt_wdc) -2 campos sem incidências (0090_prtn_amnt_rprtng_entty, 0391_nmbr_scrts_rprtng_entty) Adicionalmente, foram re-testadas 3 incidências que foram corrigidas pela equipa de IT (1 da tabela de output e 2 da tabela de loan tape). 2 destas incidências ficaram corrigidas (ID009 - typ_instrmnt e ID010 - 0140_ntr_lblty) e 1 mantém-se em aberto (ID028- otstndng_prncpl_amnt)
C47: B1. Re-especificação de campos de Sindicados
C48: B2. Re-especificação de outros campos
C50: F4. Fora âmbito | Re-especificação de campos complexos - Dem. Fin. CIB
D59: Status (campos) | E59: 46003 | F59: 46010 | G59: ∆ | J59: Status (campos) | K59: 46003 | L59: 46010 | M59: ∆
D60: Por iniciar | E60: =COUNTIFS('2. Status Detalhe Campos'!B:B,"B02.00",'2. Status Detalhe Campos'!C:C,"Loan Tape",'2. Status Detalhe Campos'!J:J,"Por iniciar") -> 0 | F60: =COUNTIFS('2. Status Detalhe Campos'!B:B,"B02.00",'2. Status Detalhe Campos'!C:C,"Loan Tape",'2. Status Detalhe Campos'!I:I,"Por iniciar") -> 0 | G60: =+F60-E60 -> 0 | H60: =+IF(F60=0,NA(),F60) -> #N/A | J60: Por iniciar | K60: =COUNTIFS('2. Status Detalhe Campos'!B:B,"B02.00",'2. Status Detalhe Campos'!C:C,"Tabela Output",'2. Status Detalhe Campos'!J:J,"Por iniciar") -> 0 | L60: =COUNTIFS('2. Status Detalhe Campos'!B:B,"B02.00",'2. Status Detalhe Campos'!C:C,"Tabela Output",'2. Status Detalhe Campos'!I:I,"Por iniciar") -> 0 | M60: =+L60-K60 -> 0 | N60: =+IF(L60=0,NA(),L60) -> #N/A
D61: Em curso | E61: =COUNTIFS('2. Status Detalhe Campos'!B:B,"B02.00",'2. Status Detalhe Campos'!C:C,"Loan Tape",'2. Status Detalhe Campos'!J:J,"Em curso") -> 2 | F61: =COUNTIFS('2. Status Detalhe Campos'!B:B,"B02.00",'2. Status Detalhe Campos'!C:C,"Loan Tape",'2. Status Detalhe Campos'!I:I,"Em curso") -> 1 | G61: =+F61-E61 -> -1 | H61: =+IF(F61=0,NA(),F61) -> 1 | J61: Em curso | K61: =COUNTIFS('2. Status Detalhe Campos'!B:B,"B02.00",'2. Status Detalhe Campos'!C:C,"Tabela Output",'2. Status Detalhe Campos'!J:J,"Em curso") -> 1 | L61: =COUNTIFS('2. Status Detalhe Campos'!B:B,"B02.00",'2. Status Detalhe Campos'!C:C,"Tabela Output",'2. Status Detalhe Campos'!I:I,"Em curso") -> 0 | M61: =+L61-K61 -> -1 | N61: =+IF(L61=0,NA(),L61) -> #N/A
D62: Concluídos | E62: =COUNTIFS('2. Status Detalhe Campos'!B:B,"B02.00",'2. Status Detalhe Campos'!C:C,"Loan Tape",'2. Status Detalhe Campos'!J:J,"Concluído") -> 21 | F62: =COUNTIFS('2. Status Detalhe Campos'!B:B,"B02.00",'2. Status Detalhe Campos'!C:C,"Loan Tape",'2. Status Detalhe Campos'!I:I,"Concluído") -> 23 | G62: =+F62-E62 -> 2 | H62: =+IF(F62=0,NA(),F62) -> 23 | J62: Concluídos | K62: =COUNTIFS('2. Status Detalhe Campos'!B:B,"B02.00",'2. Status Detalhe Campos'!C:C,"Tabela Output",'2. Status Detalhe Campos'!J:J,"Concluído") -> 72 | L62: =COUNTIFS('2. Status Detalhe Campos'!B:B,"B02.00",'2. Status Detalhe Campos'!C:C,"Tabela Output",'2. Status Detalhe Campos'!I:I,"Concluído") -> 75 | M62: =+L62-K62 -> 3 | N62: =+IF(L62=0,NA(),L62) -> 75
D63: Pendente de desenvolv. | E63: =COUNTIFS('2. Status Detalhe Campos'!B:B,"B02.00",'2. Status Detalhe Campos'!C:C,"Loan Tape",'2. Status Detalhe Campos'!J:J,"Pendente de desenvolv.") -> 1 | F63: =COUNTIFS('2. Status Detalhe Campos'!B:B,"B02.00",'2. Status Detalhe Campos'!C:C,"Loan Tape",'2. Status Detalhe Campos'!I:I,"Pendente de desenvolv.") -> 0 | G63: =+F63-E63 -> -1 | H63: =+IF(F63=0,NA(),F63) -> #N/A | J63: Pendente de desenvolv. | K63: =COUNTIFS('2. Status Detalhe Campos'!B:B,"B02.00",'2. Status Detalhe Campos'!C:C,"Tabela Output",'2. Status Detalhe Campos'!J:J,"Pendente de desenvolv.") -> 4 | L63: =COUNTIFS('2. Status Detalhe Campos'!B:B,"B02.00",'2. Status Detalhe Campos'!C:C,"Tabela Output",'2. Status Detalhe Campos'!I:I,"Pendente de desenvolv.") -> 0 | M63: =+L63-K63 -> -4 | N63: =+IF(L63=0,NA(),L63) -> #N/A
D64: Com Incidências. | E64: =COUNTIFS('2. Status Detalhe Campos'!B:B,"B02.00",'2. Status Detalhe Campos'!C:C,"Loan Tape",'2. Status Detalhe Campos'!J:J,"Com incidências") -> 6 | F64: =COUNTIFS('2. Status Detalhe Campos'!B:B,"B02.00",'2. Status Detalhe Campos'!C:C,"Loan Tape",'2. Status Detalhe Campos'!I:I,"Com incidências") -> 6 | G64: =+F64-E64 -> 0 | H64: =+IF(F64=0,NA(),F64) -> 6 | J64: Com Incidências. | K64: =COUNTIFS('2. Status Detalhe Campos'!B:B,"B02.00",'2. Status Detalhe Campos'!C:C,"Tabela Output",'2. Status Detalhe Campos'!J:J,"Com incidências") -> 4 | L64: =COUNTIFS('2. Status Detalhe Campos'!B:B,"B02.00",'2. Status Detalhe Campos'!C:C,"Tabela Output",'2. Status Detalhe Campos'!I:I,"Com incidências") -> 6 | M64: =+L64-K64 -> 2 | N64: =+IF(L64=0,NA(),L64) -> 6
D65: Total | E65: =SUM(E60:E64) -> 30 | F65: =SUM(F60:F64) -> 30 | G65: =+F65-E65 -> 0 | J65: Total | K65: =SUM(K60:K64) -> 81 | L65: =SUM(L60:L64) -> 81 | M65: =+L65-K65 -> 0
D68: B05.00
P71: Highlights
C72: A. Novos Campos | P72: Resumo semana atual: Sem alterações face à semana anterior, uma vez que não foram disponibilizados novos campos para teste.
C73: B1. Re-especificação de campos de Sindicados
...

Sheet 2. Status Detalhe Campos
A7: XXX | B7: Stream | C7: Sub-stream | D7: Loan Tape/Output Table | E7: Data field | F7: Field Status | G7: Status Especificação | H7: Status Desenvolvimento | I7: Status Atual | J7: Status Anterior | K7: Data entrega IT (real) | L7: Data conclusão | M7: Observações
A8: =+IF(C8="Loan Tape",LEFT(D8,5),B8) -> lt001 | B8: B02.00 | C8: Loan Tape | D8: lt001_univ_oper | E8: FLAG_GAR_INTRG_SAN | F8: Campo já existente no LT | G8: Concluído | H8: =+IF(C8="Controlos","Não aplicável", IFERROR(VLOOKUP(A8&"_"&E8,Testes!A:Z,25,FALSE),"Não aplicável")) -> Concluído | I8: =+IF(C8="Controlos", IFERROR(VLOOKUP(E8,Controlos!B:J,9,FALSE),"Não aplicável"), IFERROR(VLOOKUP(A8&"_"&E8,Testes!A:Z,26,FALSE),"Não aplicável")) -> Em curso | J8: Concluído | N8: =+IF(I8=J8,0,1) -> 1
A9: =+IF(C9="Loan Tape",LEFT(D9,5),B9) -> lt001 | B9: B02.00 | C9: Loan Tape | D9: lt001_univ_oper | E9: FLAG_INST_CAP | F9: Campo já existente no LT | G9: Concluído | H9: =+IF(C9="Controlos","Não aplicável", IFERROR(VLOOKUP(A9&"_"&E9,Testes!A:Z,25,FALSE),"Não aplicável")) -> Concluído | I9: =+IF(C9="Controlos", IFERROR(VLOOKUP(E9,Controlos!B:J,9,FALSE),"Não aplicável"), IFERROR(VLOOKUP(A9&"_"&E9,Testes!A:Z,26,FALSE),"Não aplicável")) -> Concluído | J9: Concluído | N9: =+IF(I9=J9,0,1) -> 0
A10: =+IF(C10="Loan Tape",LEFT(D10,5),B10) -> lt001 | B10: B02.00 | C10: Loan Tape | D10: lt001_univ_oper | E10: FLAG_INST_DIV | F10: Campo já existente no LT | G10: Concluído | H10: =+IF(C10="Controlos","Não aplicável", IFERROR(VLOOKUP(A10&"_"&E10,Testes!A:Z,25,FALSE),"Não aplicável")) -> Concluído | I10: =+IF(C10="Controlos", IFERROR(VLOOKUP(E10,Controlos!B:J,9,FALSE),"Não aplicável"), IFERROR(VLOOKUP(A10&"_"&E10,Testes!A:Z,26,FALSE),"Não aplicável")) -> Concluído | J10: Concluído | N10: =+IF(I10=J10,0,1) -> 0
A11: =+IF(C11="Loan Tape",LEFT(D11,5),B11) -> lt001 | B11: B02.00 | C11: Loan Tape | D11: lt001_univ_oper | E11: FLAG_INST_TITULOS | F11: Campo já existente no LT | G11: Concluído | H11: =+IF(C11="Controlos","Não aplicável", IFERROR(VLOOKUP(A11&"_"&E11,Testes!A:Z,25,FALSE),"Não aplicável")) -> Concluído | I11: =+IF(C11="Controlos", IFERROR(VLOOKUP(E11,Controlos!B:J,9,FALSE),"Não aplicável"), IFERROR(VLOOKUP(A11&"_"&E11,Testes!A:Z,26,FALSE),"Não aplicável")) -> Concluído | J11: Concluído | N11: =+IF(I11=J11,0,1) -> 0
A12: =+IF(C12="Loan Tape",LEFT(D12,5),B12) -> lt002 | B12: B02.00 | C12: Loan Tape | D12: lt002_instrument | E12: accntng_clssfctn | F12: Campo já existente no LT | G12: Concluído | H12: =+IF(C12="Controlos","Não aplicável", IFERROR(VLOOKUP(A12&"_"&E12,Testes!A:Z,25,FALSE),"Não aplicável")) -> Concluído | I12: =+IF(C12="Controlos", IFERROR(VLOOKUP(E12,Controlos!B:J,9,FALSE),"Não aplicável"), IFERROR(VLOOKUP(A12&"_"&E12,Testes!A:Z,26,FALSE),"Não aplicável")) -> Concluído | J12: Concluído | K12: x | N12: =+IF(I12=J12,0,1) -> 0
A13: =+IF(C13="Loan Tape",LEFT(D13,5),B13) -> lt002 | B13: B02.00 | C13: Loan Tape | D13: lt002_instrument | E13: accrd_intrst_instrmnt | F13: Campo já existente no LT - Nova Especificação | G13: Concluído | H13: =+IF(C13="Controlos","Não aplicável", IFERROR(VLOOKUP(A13&"_"&E13,Testes!A:Z,25,FALSE),"Não aplicável")) -> Concluído | I13: =+IF(C13="Controlos", IFERROR(VLOOKUP(E13,Controlos!B:J,9,FALSE),"Não aplicável"), IFERROR(VLOOKUP(A13&"_"&E13,Testes!A:Z,26,FALSE),"Não aplicável")) -> Com incidências | J13: Com incidências | N13: =+IF(I13=J13,0,1) -> 0
A14: =+IF(C14="Loan Tape",LEFT(D14,5),B14) -> lt002 | B14: B02.00 | C14: Loan Tape | D14: lt002_instrument | E14: amnt_scrty_eur | F14: Campo novo no LT | G14: Concluído | H14: =+IF(C14="Controlos","Não aplicável", IFERROR(VLOOKUP(A14&"_"&E14,Testes!A:Z,25,FALSE),"Não aplicável")) -> Concluído | I14: =+IF(C14="Controlos", IFERROR(VLOOKUP(E14,Controlos!B:J,9,FALSE),"Não aplicável"), IFERROR(VLOOKUP(A14&"_"&E14,Testes!A:Z,26,FALSE),"Não aplicável")) -> Concluído | J14: Concluído | N14: =+IF(I14=J14,0,1) -> 0
A15: =+IF(C15="Loan Tape",LEFT(D15,5),B15) -> lt002 | B15: B02.00 | C15: Loan Tape | D15: lt002_instrument | E15: amnt_scrty_fx | F15: Campo novo no LT | G15: Concluído | H15: =+IF(C15="Controlos","Não aplicável", IFERROR(VLOOKUP(A15&"_"&E15,Testes!A:Z,25,FALSE),"Não aplicável")) -> Concluído | I15: =+IF(C15="Controlos", IFERROR(VLOOKUP(E15,Controlos!B:J,9,FALSE),"Não aplicável"), IFERROR(VLOOKUP(A15&"_"&E15,Testes!A:Z,26,FALSE),"Não aplicável")) -> Concluído | J15: Concluído | N15: =+IF(I15=J15,0,1) -> 0
A16: =+IF(C16="Loan Tape",LEFT(D16,5),B16) -> lt002 | B16: B02.00 | C16: Loan Tape | D16: lt002_instrument | E16: crrncy_dnmntn | F16: Campo já existente no LT | G16: Concluído | H16: =+IF(C16="Controlos","Não aplicável", IFERROR(VLOOKUP(A16&"_"&E16,Testes!A:Z,25,FALSE),"Não aplicável")) -> Concluído | I16: =+IF(C16="Controlos", IFERROR(VLOOKUP(E16,Controlos!B:J,9,FALSE),"Não aplicável"), IFERROR(VLOOKUP(A16&"_"&E16,Testes!A:Z,26,FALSE),"Não aplicável")) -> Concluído | J16: Concluído | N16: =+IF(I16=J16,0,1) -> 0
A17: =+IF(C17="Loan Tape",LEFT(D17,5),B17) -> lt002 | B17: B02.00 | C17: Loan Tape | D17: lt002_instrument | E17: crryng_amnt_instrmnt | F17: Campo já existente no LT | G17: Concluído | H17: =+IF(C17="Controlos","Não aplicável", IFERROR(VLOOKUP(A17&"_"&E17,Testes!A:Z,25,FALSE),"Não aplicável")) -> Concluído | I17: =+IF(C17="Controlos", IFERROR(VLOOKUP(E17,Controlos!B:J,9,FALSE),"Não aplicável"), IFERROR(VLOOKUP(A17&"_"&E17,Testes!A:Z,26,FALSE),"Não aplicável")) -> Concluído | J17: Concluído | N17: =+IF(I17=J17,0,1) -> 0
A18: =+IF(C18="Loan Tape",LEFT(D18,5),B18) -> lt002 | B18: B02.00 | C18: Loan Tape | D18: lt002_instrument | E18: csd | F18: Campo novo no LT | G18: Concluído | H18: =+IF(C18="Controlos","Não aplicável", IFERROR(VLOOKUP(A18&"_"&E18,Testes!A:Z,25,FALSE),"Não aplicável")) -> Concluído | I18: =+IF(C18="Controlos", IFERROR(VLOOKUP(E18,Controlos!B:J,9,FALSE),"Não aplicável"), IFERROR(VLOOKUP(A18&"_"&E18,Testes!A:Z,26,FALSE),"Não aplicável")) -> Concluído | J18: Concluído | N18: =+IF(I18=J18,0,1) -> 0
A19: =+IF(C19="Loan Tape",LEFT(D19,5),B19) -> lt002 | B19: B02.00 | C19: Loan Tape | D19: lt002_instrument | E19: csd_lei | F19: Campo novo no LT | G19: Concluído | H19: =+IF(C19="Controlos","Não aplicável", IFERROR(VLOOKUP(A19&"_"&E19,Testes!A:Z,25,FALSE),"Não aplicável")) -> Concluído | I19: =+IF(C19="Controlos", IFERROR(VLOOKUP(E19,Controlos!B:J,9,FALSE),"Não aplicável"), IFERROR(VLOOKUP(A19&"_"&E19,Testes!A:Z,26,FALSE),"Não aplicável")) -> Concluído | J19: Concluído | N19: =+IF(I19=J19,0,1) -> 0
A20: =+IF(C20="Loan Tape",LEFT(D20,5),B20) -> lt002 | B20: B02.00 | C20: Loan Tape | D20: lt002_instrument | E20: dt_incptn | F20: Campo já existente no LT | G20: Concluído | H20: =+IF(C20="Controlos","Não aplicável", IFERROR(VLOOKUP(A20&"_"&E20,Testes!A:Z,25,FALSE),"Não aplicável")) -> Concluído | I20: =+IF(C20="Controlos", IFERROR(VLOOKUP(E20,Controlos!B:J,9,FALSE),"Não aplicável"), IFERROR(VLOOKUP(A20&"_"&E20,Testes!A:Z,26,FALSE),"Não aplicável")) -> Concluído | J20: Concluído | N20: =+IF(I20=J20,0,1) -> 0
A21: =+IF(C21="Loan Tape",LEFT(D21,5),B21) -> lt002 | B21: B02.00 | C21: Loan Tape | D21: lt002_instrument | E21: dt_lgl_fnl_mtrty | F21: Campo já existente no LT | G21: Concluído | H21: =+IF(C21="Controlos","Não aplicável", IFERROR(VLOOKUP(A21&"_"&E21,Testes!A:Z,25,FALSE),"Não aplicável")) -> Concluído | I21: =+IF(C21="Controlos", IFERROR(VLOOKUP(E21,Controlos!B:J,9,FALSE),"Não aplicável"), IFERROR(VLOOKUP(A21&"_"&E21,Testes!A:Z,26,FALSE),"Não aplicável")) -> Com incidências | J21: Com incidências | N21: =+IF(I21=J21,0,1) -> 0
A22: =+IF(C22="Loan Tape",LEFT(D22,5),B22) -> lt002 | B22: B02.00 | C22: Loan Tape | D22: lt002_instrument | E22: dt_nxt_intrst_pymnt | F22: Campo novo no LT | G22: Concluído | H22: =+IF(C22="Controlos","Não aplicável", IFERROR(VLOOKUP(A22&"_"&E22,Testes!A:Z,25,FALSE),"Não aplicável")) -> Concluído | I22: =+IF(C22="Controlos", IFERROR(VLOOKUP(E22,Controlos!B:J,9,FALSE),"Não aplicável"), IFERROR(VLOOKUP(A22&"_"&E22,Testes!A:Z,26,FALSE),"Não aplicável")) -> Com incidências | J22: Com incidências | N22: =+IF(I22=J22,0,1) -> 0
A23: =+IF(C23="Loan Tape",LEFT(D23,5),B23) -> lt002 | B23: B02.00 | C23: Loan Tape | D23: lt002_instrument | E23: elgbl_amnt_own_fnds_indvdl_lvl | F23: Campo novo no LT | G23: Concluído | H23: =+IF(C23="Controlos","Não aplicável", IFERROR(VLOOKUP(A23&"_"&E23,Testes!A:Z,25,FALSE),"Não aplicável")) -> Concluído | I23: =+IF(C23="Controlos", IFERROR(VLOOKUP(E23,Controlos!B:J,9,FALSE),"Não aplicável"), IFERROR(VLOOKUP(A23&"_"&E23,Testes!A:Z,26,FALSE),"Não aplicável")) -> Concluído | J23: Concluído | N23: =+IF(I23=J23,0,1) -> 0
A24: =+IF(C24="Loan Tape",LEFT(D24,5),B24) -> lt002 | B24: B02.00 | C24: Loan Tape | D24: lt002_instrument | E24: governing_law | F24: Campo já existente no LT | G24: Concluído | H24: =+IF(C24="Controlos","Não aplicável", IFERROR(VLOOKUP(A24&"_"&E24,Testes!A:Z,25,FALSE),"Não aplicável")) -> Concluído | I24: =+IF(C24="Controlos", IFERROR(VLOOKUP(E24,Controlos!B:J,9,FALSE),"Não aplicável"), IFERROR(VLOOKUP(A24&"_"&E24,Testes!A:Z,26,FALSE),"Não aplicável")) -> Concluído | J24: Em curso | N24: =+IF(I24=J24,0,1) -> 1
... A30: =+IF(C30="Loan Tape",LEFT(D30,5),B30) -> lt002 | B30: B02.00 | C30: Loan Tape | D30: lt002_instrument | E30: pyng_agnt_lei | F30: Campo novo no LT | G30: Concluído | H30: =+IF(C30="Controlos","Não aplicável", IFERROR(VLOOKUP(A30&"_"&E30,Testes!A:Z,25,FALSE),"Não aplicável")) -> Concluído | I30: =+IF(C30="Controlos", IFERROR(VLOOKUP(E30,Controlos!B:J,9,FALSE),"Não aplicável"), IFERROR(VLOOKUP(A30&"_"&E30,Testes!A:Z,26,FALSE),"Não aplicável")) -> Concluído | J30: Concluído | N30: =+IF(I30=J30,0,1) -> 0
A31: =+IF(C31="Loan Tape",LEFT(D31,5),B31) -> lt002 | B31: B02.00 | C31: Loan Tape | D31: lt002_instrument | E31: rank_insolv | F31: Campo novo no LT | G31: Concluído | H31: =+IF(C31="Controlos","Não aplicável", IFERROR(VLOOKUP(A31&"_"&E31,Testes!A:Z,25,FALSE),"Não aplicável")) -> Concluído | I31: =+IF(C31="Controlos", IFERROR(VLOOKUP(E31,Controlos!B:J,9,FALSE),"Não aplicável"), IFERROR(VLOOKUP(A31&"_"&E31,Testes!A:Z,26,FALSE),"Não aplicável")) -> Concluído | J31: Concluído | K31: x | N31: =+IF(I31=J31,0,1) -> 0
A32: =+IF(C32="Loan Tape",LEFT(D32,5),B32) -> lt002 | B32: B02.00 | C32: Loan Tape | D32: lt002_instrument | E32: trdng_mthd | F32: Em curso | G32: Em curso | H32: =+IF(C32="Controlos","Não aplicável", IFERROR(VLOOKUP(A32&"_"&E32,Testes!A:Z,25,FALSE),"Não aplicável")) -> Concluído | I32: =+IF(C32="Controlos", IFERROR(VLOOKUP(E32,Controlos!B:J,9,FALSE),"Não aplicável"), IFERROR(VLOOKUP(A32&"_"&E32,Testes!A:Z,26,FALSE),"Não aplicável")) -> Concluído | J32: Concluído | N32: =+IF(I32=J32,0,1) -> 0
A33: =+IF(C33="Loan Tape",LEFT(D33,5),B33) -> lt002 | B33: B02.00 | C33: Loan Tape | D33: lt002_instrument | E33: typ_instrmnt | F33: Campo já existente no LT | G33: Concluído | H33: =+IF(C33="Controlos","Não aplicável", IFERROR(VLOOKUP(A33&"_"&E33,Testes!A:Z,25,FALSE),"Não aplicável")) -> Concluído | I33: =+IF(C33="Controlos", IFERROR(VLOOKUP(E33,Controlos!B:J,9,FALSE),"Não aplicável"), IFERROR(VLOOKUP(A33&"_"&E33,Testes!A:Z,26,FALSE),"Não aplicável")) -> Concluído | J33: Com incidências | N33: =+IF(I33=J33,0,1) -> 1
A34: =+IF(C34="Loan Tape",LEFT(D34,5),B34) -> lt002 | B34: B02.00 | C34: Loan Tape | D34: lt002_instrument | E34: typ_own_fnds_indvdl_lvl | F34: Campo novo no LT | G34: Concluído | H34: =+IF(C34="Controlos","Não aplicável", IFERROR(VLOOKUP(A34&"_"&E34,Testes!A:Z,25,FALSE),"Não aplicável")) -> Concluído | I34: =+IF(C34="Controlos", IFERROR(VLOOKUP(E34,Controlos!B:J,9,FALSE),"Não aplicável"), IFERROR(VLOOKUP(A34&"_"&E34,Testes!A:Z,26,FALSE),"Não aplicável")) -> Concluído | J34: Concluído | N34: =+IF(I34=J34,0,1) -> 0
A35: =+IF(C35="Loan Tape",LEFT(D35,5),B35) -> lt003 | B35: B90.00 | C35: Loan Tape | D35: lt003_entity | E35: cntrprty_rsltn_grp | F35: Campo novo no LT | G35: Concluído | H35: =+IF(C35="Controlos","Não aplicável", IFERROR(VLOOKUP(A35&"_"&E35,Testes!A:Z,25,FALSE),"Não aplicável")) -> Concluído | I35: =+IF(C35="Controlos", IFERROR(VLOOKUP(E35,Controlos!B:J,9,FALSE),"Não aplicável"), IFERROR(VLOOKUP(A35&"_"&E35,Testes!A:Z,26,FALSE),"Não aplicável")) -> Com incidências | J35: Pendente de desenvolv. | N35: =+IF(I35=J35,0,1) -> 1
A36: =+IF(C36="Loan Tape",LEFT(D36,5),B36) -> lt003 | B36: B90.00 | C36: Loan Tape | D36: lt003_entity | E36: cntrprty_typ | F36: Por iniciar | G36: Não Concluído | H36: =+IF(C36="Controlos","Não aplicável", IFERROR(VLOOKUP(A36&"_"&E36,Testes!A:Z,25,FALSE),"Não aplicável")) -> Concluído | I36: =+IF(C36="Controlos", IFERROR(VLOOKUP(E36,Controlos!B:J,9,FALSE),"Não aplicável"), IFERROR(VLOOKUP(A36&"_"&E36,Testes!A:Z,26,FALSE),"Não aplicável")) -> Concluído | J36: Concluído | N36: =+IF(I36=J36,0,1) -> 0
A37: =+IF(C37="Loan Tape",LEFT(D37,5),B37) -> lt003 | B37: B90.00 | C37: Loan Tape | D37: lt003_entity | E37: cntry | F37: Em curso | G37: Não Concluído | H37: =+IF(C37="Controlos","Não aplicável", IFERROR(VLOOKUP(A37&"_"&E37,Testes!A:Z,25,FALSE),"Não aplicável")) -> Concluído | I37: =+IF(C37="Controlos", IFERROR(VLOOKUP(E37,Controlos!B:J,9,FALSE),"Não aplicável"), IFERROR(VLOOKUP(A37&"_"&E37,Testes!A:Z,26,FALSE),"Não aplicável")) -> Com incidências | J37: Com incidências | N37: =+IF(I37=J37,0,1) -> 0
A38: =+IF(C38="Loan Tape",LEFT(D38,5),B38) -> lt003 | B38: B90.00 | C38: Loan Tape | D38: lt003_entity | E38: entty_id | F38: Campo já existente no LT | G38: Concluído | H38: =+IF(C38="Controlos","Não aplicável", IFERROR(VLOOKUP(A38&"_"&E38,Testes!A:Z,25,FALSE),"Não aplicável")) -> Concluído | I38: =+IF(C38="Controlos", IFERROR(VLOOKUP(E38,Controlos!B:J,9,FALSE),"Não aplicável"), IFERROR(VLOOKUP(A38&"_"&E38,Testes!A:Z,26,FALSE),"Não aplicável")) -> Concluído | J38: Concluído | N38: =+IF(I38=J38,0,1) -> 0
A39: =+IF(C39="Loan Tape",LEFT(D39,5),B39) -> lt003 | B39: B90.00 | C39: Loan Tape | D39: lt003_entity | E39: entty_nm | F39: Campo já existente no LT | G39: Concluído | H39: =+IF(C39="Controlos","Não aplicável", IFERROR(VLOOKUP(A39&"_"&E39,Testes!A:Z,25,FALSE),"Não aplicável")) -> Concluído | I39: =+IF(C39="Controlos", IFERROR(VLOOKUP(E39,Controlos!B:J,9,FALSE),"Não aplicável"), IFERROR(VLOOKUP(A39&"_"&E39,Testes!A:Z,26,FALSE),"Não aplicável")) -> Com incidências | J39: Com incidências | N39: =+IF(I39=J39,0,1) -> 0
A40: =+IF(C40="Loan Tape",LEFT(D40,5),B40) -> lt003 | B40: B90.00 | C40: Loan Tape | D40: lt003_entity | E40: lei | F40: Campo já existente no LT | G40: Concluído | H40: =+IF(C40="Controlos","Não aplicável", IFERROR(VLOOKUP(A40&"_"&E40,Testes!A:Z,25,FALSE),"Não aplicável")) -> Concluído | I40: =+IF(C40="Controlos", IFERROR(VLOOKUP(E40,Controlos!B:J,9,FALSE),"Não aplicável"), IFERROR(VLOOKUP(A40&"_"&E40,Testes!A:Z,26,FALSE),"Não aplicável")) -> Concluído | J40: Concluído | N40: =+IF(I40=J40,0,1) -> 0
A41: =+IF(C41="Loan Tape",LEFT(D41,5),B41) -> lt003 | B41: B90.00 | C41: Loan Tape | D41: lt003_entity | E41: prsn_typ | F41: Em curso | G41: Não Concluído | H41: =+IF(C41="Controlos","Não aplicável", IFERROR(VLOOKUP(A41&"_"&E41,Testes!A:Z,25,FALSE),"Não aplicável")) -> Concluído | I41: =+IF(C41="Controlos", IFERROR(VLOOKUP(E41,Controlos!B:J,9,FALSE),"Não aplicável"), IFERROR(VLOOKUP(A41&"_"&E41,Testes!A:Z,26,FALSE),"Não aplicável")) -> Com incidências | J41: Com incidências | N41: =+IF(I41=J41,0,1) -> 0
A42: =+IF(C42="Loan Tape",LEFT(D42,5),B42) -> lt004 | B42: B05.00 | C42: Loan Tape | D42: lt004_protection | E42: dt_mtrty_prtctn | F42: Em curso | G42: Não Concluído | H42: =+IF(C42="Controlos","Não aplicável", IFERROR(VLOOKUP(A42&"_"&E42,Testes!A:Z,25,FALSE),"Não aplicável")) -> Concluído | I42: =+IF(C42="Controlos", IFERROR(VLOOKUP(E42,Controlos!B:J,9,FALSE),"Não aplicável"), IFERROR(VLOOKUP(A42&"_"&E42,Testes!A:Z,26,FALSE),"Não aplicável")) -> Concluído | J42: Concluído | N42: =+IF(I42=J42,0,1) -> 0
A43: =+IF(C43="Loan Tape",LEFT(D43,5),B43) -> lt004 | B43: B05.00 | C43: Loan Tape | D43: lt004_protection | E43: flg_scrd | F43: Campo novo no LT | G43: Concluído | H43: =+IF(C43="Controlos","Não aplicável", IFERROR(VLOOKUP(A43&"_"&E43,Testes!A:Z,25,FALSE),"Não aplicável")) -> Não Concluído | I43: =+IF(C43="Controlos", IFERROR(VLOOKUP(E43,Controlos!B:J,9,FALSE),"Não aplicável"), IFERROR(VLOOKUP(A43&"_"&E43,Testes!A:Z,26,FALSE),"Não aplicável")) -> Pendente de desenvolv. | J43: Pendente de desenvolv. | N43: =+IF(I43=J43,0,1) -> 0
... A129: =+IF(C129="Loan Tape",LEFT(D129,5),B129) -> B02.00 | B129: B02.00 | C129: Tabela Output | D129: out_b0200_main_liabilities | E129: 0610_crryng_amnt_ifrs | F129: Campo já existente no LT | G129: Concluído | H129: =+IF(C129="Controlos","Não aplicável", IFERROR(VLOOKUP(A129&"_"&E129,Testes!A:Z,25,FALSE),"Não aplicável")) -> Concluído | I129: =+IF(C129="Controlos", IFERROR(VLOOKUP(E129,Controlos!B:J,9,FALSE),"Não aplicável"), IFERROR(VLOOKUP(A129&"_"&E129,Testes!A:Z,26,FALSE),"Não aplicável")) -> Concluído | J129: Concluído | N129: =+IF(I129=J129,0,1) -> 0
A130: =+IF(C130="Loan Tape",LEFT(D130,5),B130) -> B02.00 | B130: B02.00 | C130: Tabela Output | D130: out_b0200_main_liabilities | E130: 0620_blnc_sht_ifrs | F130: Campo já existente no LT | G130: Concluído | H130: =+IF(C130="Controlos","Não aplicável", IFERROR(VLOOKUP(A130&"_"&E130,Testes!A:Z,25,FALSE),"Não aplicável")) -> Concluído | I130: =+IF(C130="Controlos", IFERROR(VLOOKUP(E130,Controlos!B:J,9,FALSE),"Não aplicável"), IFERROR(VLOOKUP(A130&"_"&E130,Testes!A:Z,26,FALSE),"Não aplicável")) -> Concluído | J130: Concluído | K130: x | N130: =+IF(I130=J130,0,1) -> 0
A131: =+IF(C131="Loan Tape",LEFT(D131,5),B131) -> B02.00 | B131: B02.00 | C131: Tabela Output | D131: out_b0200_main_liabilities | E131: 0630_crrying_amnt_ngaap | F131: Campo não LT (apenas tabela Output) | G131: Concluído | H131: =+IF(C131="Controlos","Não aplicável", IFERROR(VLOOKUP(A131&"_"&E131,Testes!A:Z,25,FALSE),"Não aplicável")) -> Concluído | I131: =+IF(C131="Controlos", IFERROR(VLOOKUP(E131,Controlos!B:J,9,FALSE),"Não aplicável"), IFERROR(VLOOKUP(A131&"_"&E131,Testes!A:Z,26,FALSE),"Não aplicável")) -> Concluído | J131: Concluído | N131: =+IF(I131=J131,0,1) -> 0
A132: =+IF(C132="Loan Tape",LEFT(D132,5),B132) -> B02.00 | B132: B02.00 | C132: Tabela Output | D132: out_b0200_main_liabilities | E132: 0640_blnc_sht_ngaap | F132: Campo não LT (apenas tabela Output) | G132: Concluído | H132: =+IF(C132="Controlos","Não aplicável", IFERROR(VLOOKUP(A132&"_"&E132,Testes!A:Z,25,FALSE),"Não aplicável")) -> Concluído | I132: =+IF(C132="Controlos", IFERROR(VLOOKUP(E132,Controlos!B:J,9,FALSE),"Não aplicável"), IFERROR(VLOOKUP(A132&"_"&E132,Testes!A:Z,26,FALSE),"Não aplicável")) -> Concluído | J132: Concluído | N132: =+IF(I132=J132,0,1) -> 0
A133: =+IF(C133="Loan Tape",LEFT(D133,5),B133) -> B02.00 | B133: B02.00 | C133: Tabela Output | D133: out_b0200_main_liabilities | E133: 5000_flg_shrhldr_not_rsltn_grp | F133: Campo não LT (apenas tabela Output) | G133: Concluído | H133: =+IF(C133="Controlos","Não aplicável", IFERROR(VLOOKUP(A133&"_"&E133,Testes!A:Z,25,FALSE),"Não aplicável")) -> Concluído | I133: =+IF(C133="Controlos", IFERROR(VLOOKUP(E133,Controlos!B:J,9,FALSE),"Não aplicável"), IFERROR(VLOOKUP(A133&"_"&E133,Testes!A:Z,26,FALSE),"Não aplicável")) -> Concluído | J133: Concluído | N133: =+IF(I133=J133,0,1) -> 0
A134: =+IF(C134="Loan Tape",LEFT(D134,5),B134) -> B02.00 | B134: B02.00 | C134: Tabela Output | D134: out_b0200_main_liabilities | E134: 5010_flg_art21_7a_srmr | F134: Campo não LT (apenas tabela Output) | G134: Concluído | H134: =+IF(C134="Controlos","Não aplicável", IFERROR(VLOOKUP(A134&"_"&E134,Testes!A:Z,25,FALSE),"Não aplicável")) -> Concluído | I134: =+IF(C134="Controlos", IFERROR(VLOOKUP(E134,Controlos!B:J,9,FALSE),"Não aplicável"), IFERROR(VLOOKUP(A134&"_"&E134,Testes!A:Z,26,FALSE),"Não aplicável")) -> Concluído | J134: Concluído | N134: =+IF(I134=J134,0,1) -> 0
A135: =+IF(C135="Loan Tape",LEFT(D135,5),B135) -> B02.00 | B135: B02.00 | C135: Controlos | D135: out_b0200_main_liabilities | E135: b0200_frmt_0010_row_nmbr | F135: Não aplicável | G135: Não aplicável | H135: =+IF(C135="Controlos","Não aplicável", IFERROR(VLOOKUP(A135&"_"&E135,Testes!A:Z,25,FALSE),"Não aplicável")) -> Não aplicável | I135: =+IF(C135="Controlos", IFERROR(VLOOKUP(E135,Controlos!B:J,9,FALSE),"Não aplicável"), IFERROR(VLOOKUP(A135&"_"&E135,Testes!A:Z,26,FALSE),"Não aplicável")) -> Concluído | J135: Concluído | N135: =+IF(I135=J135,0,1) -> 0
A136: =+IF(C136="Loan Tape",LEFT(D136,5),B136) -> B02.00 | B136: B02.00 | C136: Controlos | D136: out_b0200_main_liabilities | E136: b0200_frmt_0020_uniq_id | F136: Não aplicável | G136: Não aplicável | H136: =+IF(C136="Controlos","Não aplicável", IFERROR(VLOOKUP(A136&"_"&E136,Testes!A:Z,25,FALSE),"Não aplicável")) -> Não aplicável | I136: =+IF(C136="Controlos", IFERROR(VLOOKUP(E136,Controlos!B:J,9,FALSE),"Não aplicável"), IFERROR(VLOOKUP(A136&"_"&E136,Testes!A:Z,26,FALSE),"Não aplicável")) -> Concluído | J136: Concluído | N136: =+IF(I136=J136,0,1) -> 0
...

Sheet Aux
B7: Field Status
B9: Campo já existente no LT
B10: Campo já existente no LT - Nova Especificação
B11: Campo novo no LT
B12: Campo via Holístico
B13: Campo não LT (apenas tabela Output)
B14: Não aplicável
B15: Em curso
B17: Status Especificação/Desenvolvimento
B18: Em curso
B19: Concluído
B20: Não aplicável
... B29: Pendente de desenvolv.

Sheet Detalhe Especificação -->

Sheet B02.00
A1: B02.00 - Main Liabilities: the tab includes the data points requested at resolution entity (point of entry) level for the implementation of the bail-in tool, or at non resolution entity level (up to the Senior Non-Preferred layer)11 for monitoring and implementing the loss transfer and recapitalisation mechanisms. Generally, the data points in this tab are requested at individual level12. However, some specific data points may be requested at consolidated level on an adhoc basis by the IRT
A2: SRB Instructions | I2: Especificação IT
I3: Fase 1 - Granular (Loan Tape) | N3: Fase 2 - Agregada (Não Loan Tape) | P3: Comentários/Histórico EF
A4: Data Point | B4: ID | C4: Data type | D4: Constrain | E4: Description | F4: Treatment of "Not applicable" (if cell is grey out, input is not expected) | G4: Treatment of "Not available" (if cell is grey out, input is not expected) | I4: Novo campo? | J4: Nome campo | K4: Missing Value (LT804) | L4: Not Applicable Value (LT804) | M4: Regra campo | N4: Nome campo | O4: Regra campo | Q4: Estado Especificação | R4: Estado Desenvolvimento | S4: Necessita de ajuste? (2025-10-31 vs 2025-11-14)
A5: Row number | B5: 0010 | C5: Numeric | D5: Integer | E5: The unique number / primary key to identify the row items (the number must be an integer). | I5: Não | N5: out_b0200_main_liabilities.0010_row_nmbr | O5: Sequenciador a implementar na tabela de output out_b0200_main_liabilities Nota: A cada execução não deverão ser gerados Row numbers diferentes pelo que provisoriamente deverá ser feito um order by instrmnt_id | P5: Reunião 2025-06-16 Luís Capitão-Mor, Pedro Mendes, Luísa Sousa | Q5: Campo não LT (apenas tabela Output) | R5: Concluído | S5: NÃO | T5: =IF(SEARCH(B5,N5,4),"ok","nok") -> ok
A6: Unique internal identification number | B6: 0020 | C6: String | D6: Free text | E6: The unique internal identifier of the instrument/liability. For deposits reported on an aggregate level, please indicate: ▪ ‘NCNP’ for the aggregated not covered not preferential deposits (field c0280 = TRUE); and ▪ ‘NCBP’ for the aggregated not covered but preferential deposits (field c0290 = TRUE). | I6: Não | J6: lt002_instrument.instrmnt_id | L6: {=_xlfn.SWITCH(C6,"Numeric","999999999999999","String","Not applicable","Date","0001-01-01")} -> Not applicable | N6: out_b0200_main_liabilities.0020_uniq_id | O6: lt002_instrument.instrmnt_id | P6: Reunião 2025-06-16 Luís Capitão-Mor, Pedro Mendes, Luísa Sousa | Q6: Campo já existente no LT | R6: Concluído | S6: NÃO | T6: =IF(SEARCH(B6,N6,4),"ok","nok") -> ok
A7: Unique identification number (known to the counterparty) | B7: 0030 | C7: String | D7: Free text | E7: The unique identifier of the instrument/liability that would allow the counterparty to conclude that it will be affected by the potential resolution action, without external third parties being able to identify the creditor. For securities, the ISIN code must be indicated where available (other identifiers need only be provided in the absence of an ISIN). For deposits and other liabilities, the account/contract number should be reported. In the event of multiple tranches (multiple counterparties) of one promissory-note loan (e.g. Schuldscheindarlehen) or a syndicated loan, a unique ID must be allocated to each tranche. For deposits reported on an aggregate level, please indicate: ▪ ‘NCNP’ for the aggregated not covered not preferential deposits (field c0280 = TRUE); and ▪ ‘NCBP’ for the aggregated not covered but preferential deposits (field c0290 = TRUE). | I7: Não | J7: lt002_instrument.isin | L7: {=_xlfn.SWITCH(C7,"Numeric","999999999999999","String","Not applicable","Date","0001-01-01")} -> Not applicable | N7: out_b0200_main_liabilities.0030_uniq_id_knwn_cntrprty | O7: lt002_instrument.isin | P7: Reunião 2025-06-16 Luís Capitão-Mor, Pedro Mendes, Luísa Sousa | Q7: Campo já existente no LT | R7: Concluído | S7: NÃO | T7: =IF(SEARCH(B7,N7,4),"ok","nok") -> ok
A8: Type of the unique identifier (known to the counterparty) | B8: 0040 | C8: String | D8: Free text, but fixed values for specific items | E8: Free text, to indicate what type of identifier has been used in data point c0020, e.g. if the identifier is an ISIN, please input ‘ISIN’; if the identifier is an account number, please input ‘Account number’; if the identifier is a contract number, please input ‘Contract number’. For deposits reported on an aggregate level, please indicate ‘Aggregated’. | I8: Não | N8: out_b0200_main_liabilities.0040_typ_uniq_id_knwn_cntrprty | O8: Valor fixo 'ISIN' | P8: Reunião 2025-06-16 Luís Capitão-Mor, Pedro Mendes, Luísa Sousa: Neste caso não faz sentido criar o campo no Loan Tape quando ele já existe, portanto será criado apenas na tabela output out_b0200_main_liabilities. Caso contrário haveria um princípio de colisão, pois estar-se-ia a repetir conceitos de campos. | Q8: Campo não LT (apenas tabela Output) | R8: Concluído | S8: NÃO | T8: =IF(SEARCH(B8,N8,4),"ok","nok") -> ok
A9: Original amount issued in EUR | B9: 50 | C9: Numeric | D9: 2 decimals | E9: The EUR (counter)value of the total issue size of the instrument, irrespective of the effective issuance dates, i.e. the total nominal amount / face value of a specific liability. For shares, it should reflect the face value / carrying amount of the shares. If a nominal value does not exist, this field is not applicable. This data point is not applicable for cash accounts / saving accounts and deposits reported in aggregated form (Submission A). If a value is reported in a foreign currency (c0060), the amount must additionally be converted into euros and reported in the corresponding EUR field (c0050), using the euro reference exchange rate published by the ECB on the date for which the information is reported40. In the case of foreign currencies for which no euro reference exchange rate is available, a customary market reference rate must be used. If such other customary reference exchange rates are used, a uniform source must be used wherever possible. | F9: Input 999999999999999 | I9: Sim | J9: lt002_instrument.orgnl_amnt_eur | L9: {=_xlfn.SWITCH(C9,"Numeric","999999999999999","String","Not applicable","Date","0001-01-01")} -> 999999999999999 | M9: Se flag_inst_titulos = '1': Obter campo nom_tot_inic da ct610_titulos. Adicionalmente, efetuar conversão via tabela cambios, seguindo a lógica definida nos restantes processos, dado que o campo nom_tot_inic está expresso na moeda original (campo cmoeda). Exemplo de query que utiliza a tabela cambios para converter moeda original em moeda eur (quando é eur a tcmbme é 1 pelo que o valor é igual): SELECT DISTINCT concat(cempresa,cbalcao, cnumecta, zdeposit), (ct610.nom_tot_inic / cambios.tcmbme) AS orgnl_amnt_eur FROM (SELECT cempresa,cbalcao, cnumecta, zdeposit, nom_tot_inic, cmoeda FROM cd_captools.ct610_titulos WHERE ref_date='${ref_date}' and concat(cempresa,cbalcao, cnumecta, zdeposit) IN ( '31641600000000000PTSTOGOM0003000', '31641600005800007PTBSRDOM0037000', '31641600005800007PTSTOCOM0007000', '31641600005800007PTCPP0AM0007000', '31641600000000000PTSTOEOM0021000', '31641600000000000PTSTOHOM0002000', '31641600000000000PTBSREOM0028000', '31641600000000000PTSTOFOM0004000')) ct610 LEFT JOIN (SELECT cmoeda, tcmbme FROM cd_captools.cambios WHERE data_date_part = '${ref_date}' AND dcambio = '${ref_date}' AND zseqcamb = 99 AND ctbcamb = 'F' AND cmarca = 'BT') cambios ON cambios.cmoeda = ct610.cmoeda; Se flag_inst_titulos = '0': Not applicable. O respetivo valor default de Not applicable deverá ser parametrizado na lt804_conf_dflt. | N9: out_b0200_main_liabilities.0050_orgnl_amnt_eur | O9: lt002_instrument.orgnl_amnt_eur | P9: Reunião 2025-08-04 Luís Capitão-Mor, Pedro Mendes, Luísa Sousa | Q9: Campo novo no LT | R9: Concluído | S9: NÃO | T9: =IF(SEARCH(B9,N9,4),"ok","nok") -> ok
A10: Original amount issued in foreign currency | B10: 0060 | C10: Numeric | D10: 2 decimals | E10: Same as c0050 above, but in the foreign currency (where relevant). Please also report the EUR-converted amount in the corresponding EUR field (c0050). This data point is not applicable for cash accounts / savings accounts and deposits reported in aggregated form (Submission A). | F10: Input 999999999999999 | I10: Sim | J10: lt002_instrument.orgnl_amnt_fx | L10: {=_xlfn.SWITCH(C10,"Numeric","999999999999999","String","Not applicable","Date","0001-01-01")} -> 999999999999999 | M10: Se flag_inst_titulos = '1' e se campo cmoeda da ct610_titulos = '978' (eur): Not applicable. O respetivo valor default de Not applicable deverá ser parametrizado na lt804_conf_dflt. Se flag_inst_titulos = '1' e se campo cmoeda da ct610_titulos <> '978' (eur): Obter campo nom_tot_inic da ct610_titulos Se flag_inst_titulos = '0': Not applicable. O respetivo valor default de Not applicable deverá ser parametrizado na lt804_conf_dflt. | N10: out_b0200_main_liabilities.0060_orgnl_amnt_fx | O10: lt002_instrument.orgnl_amnt_fx | P10: Reunião 2025-08-04 Luís Capitão-Mor, Pedro Mendes, Luísa Sousa | Q10: Campo novo no LT | R10: Concluído | S10: NÃO | T10: =IF(SEARCH(B10,N10,4),"ok","nok") -> ok
A11: Contract currency | B11: 0070 | C11: String | D11: 3-letters ISO 4217 | E11: The currency in which the instrument/liability is issued. The currency must be reported with its 3-letter ISO 4217 code. For deposits reported on an aggregate level, please indicate ‘XXX’. | F11: Input "XXX" | I11: Não | J11: lt002_instrument.crrncy_dnmntn | L11: XXX | N11: out_b0200_main_liabilities.0070_cntrct_crrncy | O11: lt002_instrument.crrncy_dnmntn | P11: Reunião 2025-06-16 Luís Capitão-Mor, Pedro Mendes, Luísa Sousa | Q11: Campo já existente no LT | R11: Concluído | S11: NÃO | T11: =IF(SEARCH(B11,N11,4),"ok","nok") -> ok
A12: Outstanding principal amount | B12: 80 | C12: Numeric | D12: 2 decimals | E12: The EUR (counter)value of the outstanding principal amount of the instrument/liability. The difference between the original amount issued and the outstanding principal amount may be due to partial buybacks of the instrument, amortising instruments, etc. The portion of eligible liabilities subscribed by intragroup entities and excluded under Article 27(3)(h) SRMR must be included in the outstanding principal amount. Only claims against other parties must be reported (i.e. excluding the portion held by the entity itself, which must be reported in field c0090). For zero coupon bonds issued at discount (i.e. c0240 = ZCB issued at discount) the final redemption amount should be reported. | I12: Sim | J12: lt005_instr_ent.otstndng_prncpl_amnt | L12: {=_xlfn.SWITCH(C12,"Numeric","999999999999999","String","Not applicable","Date","0001-01-01")} -> 999999999999999 | M12: Se flag_inst_titulos = '1': Passo 1: Verificar para cada "entty_id" (de um determinado "instrmnt_id") da lt005_instr_ent se o mesmo consta no vetor "zcliente_investidor" da ct610_titulos (desse "instrmnt_id"). Se constar, identificar em que posição consta e em seguida obter do vetor "nom_tot_ini_investe" da ct610_titulos o montante que consta nessa posição; Passo 2: Verificar se a soma dos vários "nom_tot_ini_investe" é igual ao "nom_tot_inic", da ct610_titulos -> Se for igual: Não é necessária ação adicional -> Se for diferente: Somar essa diferença no "entty_id" 0000000000 Passo 3: Dado que o "outstanding principal amount" que se pretende é o atual e não o inicial, então terá de se multiplicar os vários "nom_tot_ini_investe" pelo rácio "nom_tot_atual"/"nom_tot_inic", da ct610_titulos. Nota: O Universo do MBDT terá sempre este rácio=1 e portanto o valor inicial será igual ao valor atual, contudo, se existissem titularizações (onde se aplica o conceito de pool factor), o valor inicial seria diferente do valor atual (porque o "pool_factor" seria diferente de 1). Passo 4: Converter o montante obtido para eur pela tabela de cambios (ver query de conversão já definida no campo Original amount issued in EUR (0050)) Se flag_inst_titulos = '0': Not applicable. O respetivo valor default de Not applicable deverá ser parametrizado na lt804_conf_dflt. Na sheet "Aux Campos Montante" consta um exemplo com a aplicação desta lógica. | N12: out_b0200_main_liabilities.0080_otstndng_prncpl_amnt | O12: Soma "otstndng_prncpl_amnt" - Soma "portion_amnt_rprtng_entty", por cada instrmnt_id da lt005_instr_ent Na sheet "Aux Campos Montante" consta um exemplo com a aplicação desta lógica. | P12: Reunião 2025-10-09 Luís Capitão-Mor, Pedro Mendes Reunião 2025-09-22 e 2025-09-18 Luís Capitão-Mor, Pedro Mendes: Segundo Luís Capitão-Mor não se pode utilizar o campo OTSTNDNG_NMNL_AMNT_INSTRMNT da lt002_instrument dado que esse campo é contabilístico (a pedido do guia do BCE) e o SRB não pede contabilístico. Adicionalmente, interpretou-se da definição dada pelo SRB que se pretende retirar as recompras do BST e deve-se incluir o que está no Santander S.A (ou seja não deve se retirar o que está no Santander S.A.). Exemplo 1: Emissão de 1000M eur em que: 100M eur estão recomprados pelo BST 900M eur estão no mercado (e destes 900M eur, 500M eur estão no Santander S.A.) Ou seja, neste exemplo o Outstanding principal amount deverá ser 900M eur. Exemplo 2: Emissão 1000M eur a 95% (abaixo do par), portanto 950M eur. Na contabilidade na data inicial consta Outstanding principal amount=950M eur mas na ct610_titulos constam 1000M eur. Ou seja, o valor contabilístico nem sempre é igual ao não contabilístico. | Q12: Campo novo no LT | R12: Não Concluído | S12: NÃO | T12: =IF(SEARCH(B12,N12,4),"ok","nok") -> ok
A13: Portion of instrument or liability held by the reporting entity | B13: 0090 | C13: Numeric | D13: 2 decimals | E13: The EUR amount related to the portion of the liability held by the reporting entity itself. The amount can either be defined as the principal amount plus accrued interest and fees and charges, or as the relevant portion of fair value held by the reporting entity itself, in the event that field c0250 applies. This data point is only relevant for securities. | F13: Input 999999999999999 | I13: Sim | J13: lt005_instr_ent.prtn_amnt_rprtng_entty | L13: {=_xlfn.SWITCH(C13,"Numeric","999999999999999","String","Not applicable","Date","0001-01-01")} -> 999999999999999 | M13: Se flag_inst_titulos = '1': Verificar para cada "entty_id" (de um determinado "instrmnt_id") da lt005_instr_ent se o mesmo corresponde ao "zcliente_emitente" da ct610_titulos (desse "instrmnt_id"). Se não corresponder: Reportar 0 Se corresponder: Verificar se esse "entty_id" consta no vetor "zcliente_investidor" da ct610_titulos. Se constar: Passo 1: Identificar em que posição consta no vetor "zcliente_investidor" e em seguida obter do vetor "nom_tot_ini_investe" da ct610_titulos o montante que consta nessa posição; Passo 2: Dado que o "Portion of instrument or liability held by the reporting entity" que se pretende é o atual e não o inicial, então terá de se multiplicar o montante obtido no passo anterior pelo rácio "nom_tot_atual"/"nom_tot_inic", da ct610_titulos; Passo 3: Converter para eur pela tabela de cambios (ver query de conversão já definida no campo Original amount issued in EUR (0050)). Se não constar: Reportar 0 Se flag_inst_titulos = '0': Not applicable. O respetivo valor default de Not applicable deverá ser parametrizado na lt804_conf_dflt. Na sheet "Aux Campos Montante" consta um exemplo com a aplicação desta lógica. | N13: out_b0200_main_liabilities.0090_prtn_amnt_rprtng_entty | O13: Soma "prtn_amnt_rprtng_entty", por cada instrmnt_id da lt005_instr_ent Na sheet "Aux Campos Montante" consta um exemplo com a aplicação desta lógica. | P13: Reunião 2025-10-09 Luís Capitão-Mor, Pedro Mendes Reunião 2025-09-22 e 2025-09-18 Luís Capitão-Mor, Pedro Mendes | Q13: Campo novo no LT | R13: Não Concluído | S13: NÃO | T13: =IF(SEARCH(B13,N13,4),"ok","nok") -> ok
A14: Accrued interest | B14: 100 | C14: Numeric | D14: 2 decimals | E14: The EUR (counter)value of the outstanding accrued interest on the instrument. In jurisdictions where accrued interests do not rank pari passu to the principal liability amount, the relevant NRAs have the option to request the reporting of interest accruals on separate line items (41). Only claims against third parties must be reported (i.e. excluding the proportion held by the entity itself, which must be reported in field c0090). In case the field is not applicable (e.g. shares, zero coupon bonds issued at discount), please refer to the specific instructions in the Technical Annex. (41) - In such cases, please refer to the specific reporting example in Annex II, paragraph 3.7. | F14: Input 999999999999999 | G14: Leave blank | I14: Sim | J14: lt002_instrument.accrd_intrst_instrmnt (campo já existente a alterar) lt005_instr_ent.accrd_intrst_instrmnt (campo novo a criar) | L14: {=_xlfn.SWITCH(C14,"Numeric","999999999999999","String","Not applicable","Date","0001-01-01")} -> 999999999999999 | M14: lt002_instrument.accrd_intrst_instrmnt (campo já existente a alterar): O campo accrd_intrst_instrmnt (da lt002_instrument) está atualmente a sair com valor 0 para estes registos de Títulos Passivos (o que não é suposto dado que existem registos que deveriam ter valor). O campo accrd_intrst_instrmnt (da lt002_instrument) alimenta-se do campo juros_corridos (da lt001_univ_oper) e é calculado atualmente da seguinte forma (segundo "Especificação - BCE Loan Tape_20250915 LF + ESTR"): NVL ( SUM(-1*juros_corridos) ,0 ) O campo juros_corridos (da lt001_univ_oper) será calculado da seguinte forma (segundo re-especificação solicitada por Gonçalo Filipe, email 5 de agosto de 2025 12:58): SUM(MSALDO_FINAL) WHERE COD_PLANO = 'BST_IND' AND CCONTAB_FINAL_PCSB NOT LIKE '28%' AND COMPOSICAO_VALOR = 'juros/rendimentos a receber' AND TIPO_CONTA = 'A' AND CARTEIRA_CONTABILISTICA IN ('ativos financeiros ao custo amortizado','ativos financeiros ao justo valor atraves de outro rendimento integral','ativos financeiros ao justo valor atraves de resultados') Constata-se portanto que o campo juros_corridos (da lt001_univ_oper) não contempla atualmente o Passivo (razão pela qual o campo sai com valor 0), pelo que deverá ser adicionada a condição do "OR" abaixo: SUM(MSALDO_FINAL) WHERE ( COD_PLANO = 'BST_IND' AND CCONTAB_FINAL_PCSB NOT LIKE '28%' AND COMPOSICAO_VALOR = 'juros/rendimentos a receber' AND TIPO_CONTA = 'A' AND CARTEIRA_CONTABILISTICA IN ('ativos financeiros ao custo amortizado','ativos financeiros ao justo valor atraves de outro rendimento integral','ativos financeiros ao justo valor atraves de resultados') ) OR ( COD_PLANO = 'BST_IND' AND COMPOSICAO_VALOR = 'juros/encargos a pagar' AND TIPO_CONTA = 'P' AND CARTEIRA_CONTABILISTICA IN ('passivos financeiros ao custo amortizado') ) - Luís Capitão-Mor, Luísa Sousa, Gonçalo Filipe e Dora Roxo não identificaram impacto nesta alteração. lt005_instr_ent.accrd_intrst_instrmnt (campo novo a criar): 'Se flag_inst_titulos = '1': Efetuar exatamente a mesma especificação da lt002_instrument.accrd_intrst_instrmnt mas obtendo o valor por cada "entty_id" (na lt001_univ_oper). Ex: Para o contrato 'A' (cempresa, cbalcao, cnumecta, zdeposit) temos 3 linhas com a seguinte distribuição de juros_corridos na lt001_univ_oper: cempresa+cbalcao+cnumecta+zdeposit= 'A' | zcliente='1' | juros_corridos = 10 cempresa+cbalcao+cnumecta+zdeposit= 'A' | zcliente='2' | juros_corridos = 20 cempresa+cbalcao+cnumecta+zdeposit= 'A' | zcliente='3' | juros_corridos = 30 Atualmente o campo accrd_intrst_instrmnt da lt002_instrument calcula simplesmente a soma dos vários montantes de juros_corridos por contrato, ou seja, na lt002_instrument é apresentado uma única linha: instrmnt_id= 'A' | accrd_intrst_instrmnt = 60 O que se pretende no novo campo accrd_intrst_instrmnt a criar na lt005_instr_ent: instrmnt_id= 'A' | entty_id=1 | accrd_intrst_instrmnt = 10 instrmnt_id= 'A' | entty_id=2 | accrd_intrst_instrmnt = 20 instrmnt_id= 'A' | entty_id=3 | accrd_intrst_instrmnt = 30 Se flag_inst_titulos = '0': Not applicable. O respetivo valor default de Not applicable deverá ser parametrizado na lt804_conf_dflt. | N14: out_b0200_main_liabilities.0100_accrd_intrst_instrmnt | O14: (-1) * Soma "accrd_intrst_instrmnt ", por cada instrmnt_id da lt005_instr_ent Nota: Esta multiplicação por -1, deve-se ao facto de no Loan Tape o campo accrd_intrst_instrmnt apresentar valores negativos (para o caso destes registos de Títulos Passivos) e neste report pretenderem-se valores positivos (segundo Pedro Mendes). Ex: O contrato 31 6416 00000000000 PTBSREOM0028000 (para 2025-06-30) tem saldo de juros +418465.480000 na fr001_univ_saldo e terá +418465.480000 na lt001_univ_oper (após a nova re-especificação do Gonçalo Filipe, atualmente tem -418465.480000) e terá -418465.480000 na lt002_instrument (dada a fórmula NVL ( SUM(-1*juros_corridos) ,0 )). É portanto necessária a multiplicação por -1, ficando assim +418465.480000. Deverá ser feita a multiplicação por -1 e não o valor absoluto (abs), dado que poderá vir a existir algum contrato contra natura. | P14: Reunião 2025-10-09 Luís Capitão-Mor, Pedro Mendes Reunião 2025-09-16 Luís Capitão-Mor, Pedro Mendes, Luísa Sousa | Q14: Campo já existente no LT - Nova Especificação | R14: Concluído | S14: SIM | T14: =IF(SEARCH(B14,N14,4),"ok","nok") -> ok
