Workbook

Sheet Resumo
B2: Row Labels | C2: Count of celemtab
B3: EQUIPAMENTO
B4: 101 | C4: 4
B5: 102 | C5: 15
B6: 103 | C6: 8
B7: 104 | C7: 1
B8: 105 | C8: 1
B9: 106 | C9: 41
B10: 107 | C10: 1
B11: 108 | C11: 4
B12: 109 | C12: 42
B13: 110 | C13: 22
B14: 111 | C14: 3
B15: 112 | C15: 1
... B19: 116 | C19: 6
B20: VIATURA
B21: 201 | C21: 1
B22: 202 | C22: 6
B23: 203 | C23: 19
B24: 204 | C24: 5
B25: 205 | C25: 8
B26: 206 | C26: 9
B27: 207 | C27: 3
B28: 208 | C28: 3
B29: 209 | C29: 3
B30: 210 | C30: 1
B31: 211 | C31: 3
B32: 212 | C32: 1
B33: Grand Total | C33: 219

Sheet 1. TAT (1) - Equip. Lease
B2: TAT 1 - Mapeamento do código TIP_EQP do Lease para NELEMC01 (agregação Viatura/Equipamento) e NELEMC02 (códigos mais agrupadores)
B3: Consultar sheet "1. TAT (2) - Equip. Lease" para mapeamento dos códigos NELEMC02 para descritivo
H4: dados a 31/07/2024
B5: celemtab | C5: gelemtab | D5: Nelemc01 | E5: Nelemc02 | F5: Nelemc03 | H5: Contagem registos | K5: Mapeamento NELEMC02 para descritivos
B6: 10 | C6: EQUIPAMENTO P/ AGRICULTURA E PESCA | D6: EQUIPAMENTO | E6: 101 | H6: 181 | K6: =VLOOKUP(E6,'1. TAT (2) - Equip. Lease'!$B$5:$C$33,2,0) -> Equipamento - Agricultura
B7: 11 | C7: SEMEAR E TRATAR | D7: EQUIPAMENTO | E7: 101 | H7: 8 | K7: =VLOOKUP(E7,'1. TAT (2) - Equip. Lease'!$B$5:$C$33,2,0) -> Equipamento - Agricultura
B8: 12 | C8: COLHEITA | D8: EQUIPAMENTO | E8: 101 | H8: 3 | K8: =VLOOKUP(E8,'1. TAT (2) - Equip. Lease'!$B$5:$C$33,2,0) -> Equipamento - Agricultura
B9: 13 | C9: REGA | D9: EQUIPAMENTO | E9: 101 | H9: 7 | K9: =VLOOKUP(E9,'1. TAT (2) - Equip. Lease'!$B$5:$C$33,2,0) -> Equipamento - Agricultura
B10: 14 | C10: TRANSPORTE S/ MATRICULA | D10: VIATURA | E10: 204 | H10: 0 | K10: =VLOOKUP(E10,'1. TAT (2) - Equip. Lease'!$B$5:$C$33,2,0) -> Viatura - Indefinido
B11: 15 | C11: EQ.AGRICOLA C/ MATRICULA | D11: VIATURA | E11: 201 | H11: 4 | K11: =VLOOKUP(E11,'1. TAT (2) - Equip. Lease'!$B$5:$C$33,2,0) -> Viatura - Agricultura
B12: 17 | C12: MAQ. IND. ALIMENTAR (S/SEGURO) | D12: EQUIPAMENTO | E12: 110 | H12: 3 | K12: =VLOOKUP(E12,'1. TAT (2) - Equip. Lease'!$B$5:$C$33,2,0) -> Equipamento - Indústria
B13: 18 | C13: PESCA | D13: EQUIPAMENTO | E13: 113 | H13: 0 | K13: =VLOOKUP(E13,'1. TAT (2) - Equip. Lease'!$B$5:$C$33,2,0) -> Equipamento - Pecuária
B14: 19 | C14: INST. HIDRAULICAS E DE TRATAMENTO AGUAS | D14: EQUIPAMENTO | E14: 105 | H14: 10 | K14: =VLOOKUP(E14,'1. TAT (2) - Equip. Lease'!$B$5:$C$33,2,0) -> Equipamento - Energia Hidraúl
B15: 20 | C15: EQUIPAMENTO P/ INDUSTRIA TRANSFORMADORA | D15: EQUIPAMENTO | E15: 110 | H15: 128 | K15: =VLOOKUP(E15,'1. TAT (2) - Equip. Lease'!$B$5:$C$33,2,0) -> Equipamento - Indústria
B16: 21 | C16: MAQ. IND. ALIMENTAR | D16: EQUIPAMENTO | E16: 110 | H16: 153 | K16: =VLOOKUP(E16,'1. TAT (2) - Equip. Lease'!$B$5:$C$33,2,0) -> Equipamento - Indústria
B17: 22 | C17: MAQ. IND. TEXTIL, COURO E CALCADO | D17: EQUIPAMENTO | E17: 110 | H17: 253 | K17: =VLOOKUP(E17,'1. TAT (2) - Equip. Lease'!$B$5:$C$33,2,0) -> Equipamento - Indústria
... B224: 999 | C224: OUTROS BAPOP | D224: EQUIPAMENTO | E224: 109 | H224: 0 | K224: =VLOOKUP(E224,'1. TAT (2) - Equip. Lease'!$B$5:$C$33,2,0) -> Equipamento - Indefinido

Sheet 1. TAT (2) - Equip. Lease
B2: TAT 2 - descritivos sobre NELEMC02 da TAT1
B5: celemtab | C5: gelemtab | D5: Nelemc01 | E5: Nelemc02 | F5: Nelemc03
B6: 101 | C6: Equipamento - Agricultura
B7: 102 | C7: Equipamento - Comércio
B8: 103 | C8: Equipamento - Construção
B9: 104 | C9: Equipamento - Energia Éolica
B10: 105 | C10: Equipamento - Energia Hidraúl
B11: 106 | C11: Equipamento - Escritório
B12: 107 | C12: Equipamento - Energia Solar
B13: 108 | C13: Equipamento - Hotelaria
B14: 109 | C14: Equipamento - Indefinido
B15: 110 | C15: Equipamento - Indústria
B16: 111 | C16: Equipamento - Lazer
B17: 112 | C17: Equipamento - Out. Energias Renováveis
... B33: 212 | C33: Viatura - Ferroviário

Sheet 2. Mapeamento a validar
B2: Mapeamento do código TIP_EQP do Lease para Código da Corporação (coluna B)
B5: Código | C5: Descritivo | D5: Tipo Equipamento (gt013) | E5: Descritivo Tipo Equipamento | F5: Comentário
B6: VEH01 | C6: M1 - Vehicles used for the carriage of passengers and comprising not more than eight seats in addition to the driver's seat | D6: 141 | E6: VEICULOS LIGEIROS DE PASSAGEIROS
D7: 203 | E7: CARAVANAS
D8: 241 | E8: VEICULOS LIGEIROS DE PASSAGEIROS
D9: 251 | E9: VEICULOS LIGEIROS DE PASSAGEIROS
D10: 140 | E10: RODOVIÁRIO | F10: Dúvida se fará mais sentido estar mapeado numa outra categoria.
D11: 149 | E11: VIATURA MISTA | F11: Dúvida se fará mais sentido estar mapeado numa outra categoria.
B12: VEH02 | C12: M2 - Vehicles used for the carriage of passengers, comprising more than eight seats in addition to the driver's seat, and having a maximum mass not exceeding 5 tonnes | F12: Sem mapeamento
B13: VEH03 | C13: M3 - Vehicles used for the carriage of passengers, comprising more than eight seats in addition to the driver's seat, and having a maximum mass exceeding 5 tonnes | D13: 143 | E13: VEICULOS PESADOS DE PASSAGEIROS | F13: Dúvida se fará mais sentido estar mapeado para o M2 ou M3. A nossa proposta é M3.
D14: 227 | E14: UNIDADE DE TRANSPORTE | F14: Dúvida se fará mais sentido estar mapeado numa outra categoria.
B15: VEH04 | C15: N1 - Vehicles used for the carriage of goods and having a maximum mass not exceeding 3.5 tonnes | D15: 142 | E15: VEICULOS LIGEIROS DE MERCADORIAS
D16: 252 | E16: COMERCIAIS ATE 1600KG
D17: 253 | E17: COMERCIAIS DE 1601KG A 2600KG
D18: 254 | E18: COMERCIAIS DE 2601KG A 3500KG
D19: 712 | E19: FURGONETA
D20: 713 | E20: FURGÕES
B21: VEH05 | C21: N2 - Vehicles used for the carriage of goods and having a maximum mass exceeding 3.5 tonnes but not exceeding 12 tonnes | D21: 144 | E21: VEICULOS PESADOS DE MERCADORIAS | F21: Dúvida se fará mais sentido estar mapeado para o N2 ou N3. A nossa proposta é N2.
D22: 145 | E22: VEICULOS TRANSPORTES MATERIAS PERIGOSAS | F22: Dúvida se fará mais sentido estar mapeado para o N2 ou N3. A nossa proposta é N2.
B23: VEH06 | C23: N3 - Vehicles used for the carriage of goods and having a maximum mass exceeding 12 tonnes | F23: Sem mapeamento
B24: VEH07 | C24: L1 - A two-wheeled vehicle with an engine cylinder capacity not exceeding 50 cm3 and whatever the means of propulsion a maximum design speed not exceeding 50 km/h | D24: 180 | E24: CICLOMOTOR OU MOTOCICLO ATÉ 50CM3
B25: VEH08 | C25: L2 - A three-wheeled vehicle of any wheel arrangement with an engine cylinder capacity not exceeding 50 cm3 and whatever the means of propulsion a maximum design speed not exceeding 50 km/h | D25: 181 | E25: TRICICLO OU QUADRICICLO ATÉ 50CM3 | F25: No L2 só entram triciclos, mas não existe desagregação.
B26: VEH09 | C26: L3 - A two-wheeled vehicle with an engine cylinder capacity in the case of a thermic engine exceeding 50 cm3 or whatever the means of propulsion a maximum design speed exceeding 50 km/h | D26: 146 | E26: MOTOCICLOS CILINDRADA SUPERIOR A 50CM3
B27: VEH10 | C27: L4 - A vehicle with three wheels asymmetrically arranged in relation to the longitudinal median plane with an engine cylinder capacity in the case of a thermic engine exceeding 50 cm3 or whatever the means of propulsion a maximum design speed exceeding 50 km/h (motor cycles with sidecars) | F27: Sem mapeamento
B28: VEH11 | C28: L5 - A vehicle with three wheels symmetrically arranged in relation to the longitudinal median plane with an engine cylinder capacity in the case of a thermic engine exceeding 50 cm3 or whatever the means of propulsion a maximum design speed exceeding 50 km/h | F28: Sem mapeamento
B29: VEH12 | C29: L6 - A vehicle with four wheels whose unladen mass is not more than 350 kg, not including the mass of the batteries in case of electric vehicles, whose maximum design speed is not more than 45 km/h, and whose engine cylinder capacity does not exceed 50 cm3 for spark (positive) ignition engines, or whose maximum net power output does not exceed 4 kW in the case of other internal combustion engines, or whose maximum continuous rated power does not exceed 4 kW in the case of electric engines. | F29: Sem mapeamento
B30: VEH13 | C30: L7 - A vehicle with four wheels, other than that classified for the category L6, whose unladen mass is not more than 400 kg (550 kg for vehicles intended for carrying goods), not including the mass of batteries in the case of electric vehicles and whose maximum continuous rated power does not exceed 15 kW | F30: Sem mapeamento
B31: VEH14 | C31: O1 - Trailers with a maximum mass not exceeding 0.75 tonnes | F31: Sem mapeamento
B32: VEH15 | C32: O2 - Trailers with a maximum mass exceeding 0.75 tonnes, but not exceeding 3.5 tonnes | D32: 161 | E32: REBOQUE C/MATRICULA P/LIGEIROS PASSAGEIR
D33: 162 | E33: REBOQUE C/MATRICULA P/LIGEIROS MERCADORI
D34: 167 | E34: REBOQUE C/MATRICULA P/TODO TERRENO
B35: VEH16 | C35: O3 - Trailers with a maximum mass exceeding 3.5 tonnes, but not exceeding 10 tonnes | D35: 148 | E35: REBOQUE/SEMI-REBOQUE C/MATRICULA
D36: 171 | E36: REBOQUE C/MATRICULA P/TRACTOR
B37: VEH17 | C37: O4 - Trailers with a maximum mass exceeding 10 tonnes | F37: Sem mapeamento
B38: VEH18 | C38: T - Motorised, wheeled or tracked agricultural or forestry vehicle having at least two axles and a maximum design speed of not less than 6 km/h | D38: 15 | E38: EQ.AGRICOLA C/ MATRICULA | F38: Dúvida se fará mais sentido estar mapeado numa outra categoria.
D39: 152 | E39: EMPILHADOR | F39: Dúvida se fará mais sentido estar mapeado numa outra categoria.
D40: 211 | E40: AUTOGRUA | F40: Dúvida se fará mais sentido estar mapeado numa outra categoria.
D41: 212 | E41: AUTOVARREDORA | F41: Dúvida se fará mais sentido estar mapeado numa outra categoria.
D42: 213 | E42: BOMBA LANCA BETAO | F42: Dúvida se fará mais sentido estar mapeado numa outra categoria.
D43: 214 | E43: CILINDRO COMPACTADOR | F43: Dúvida se fará mais sentido estar mapeado numa outra categoria.
...

Sheet Sheet2
A1: Descritivo Tipo Equipamento
A2: VEICULOS LIGEIROS DE PASSAGEIROS
A3: CARAVANAS
A4: RODOVIÁRIO
A5: VIATURA MISTA
A6: VEICULOS PESADOS DE PASSAGEIROS
A7: UNIDADE DE TRANSPORTE
A8: VEICULOS LIGEIROS DE MERCADORIAS
A9: COMERCIAIS ATE 1600KG
A10: COMERCIAIS DE 1601KG A 2600KG
A11: COMERCIAIS DE 2601KG A 3500KG
A12: FURGONETA
... A203: OUTROS BAPOP

Sheet Sheet1
C5: Equip. - Agricultura | D5: 101 | E5: Agricultura | F5: =D5&" - "&E5 -> 101 - Agricultura | G5: =LEN(F5) -> 17
C6: Equip. - Comércio | D6: =D5+1 -> 102 | E6: Comércio | F6: =D6&" - "&E6 -> 102 - Comércio | G6: =LEN(F6) -> 14
C7: Equip. - Construção | D7: =D6+1 -> 103 | E7: Construção | F7: =D7&" - "&E7 -> 103 - Construção | G7: =LEN(F7) -> 16
C8: Equip. - Energia éolica | D8: =D7+1 -> 104 | E8: En. Éolica | F8: =D8&" - "&E8 -> 104 - En. Éolica | G8: =LEN(F8) -> 16
C9: Equip. - Energia Hidráulica | D9: =D8+1 -> 105 | E9: En. Hidraúl | F9: =D9&" - "&E9 -> 105 - En. Hidraúl | G9: =LEN(F9) -> 17
C10: Equip. - Escritório | D10: =D9+1 -> 106 | E10: Escritório | F10: =D10&" - "&E10 -> 106 - Escritório | G10: =LEN(F10) -> 16
C11: Equip. - Fotovoltaico | D11: =D10+1 -> 107 | E11: En. Solar | F11: =D11&" - "&E11 -> 107 - En. Solar | G11: =LEN(F11) -> 15
C12: Equip. - Hotelaria | D12: =D11+1 -> 108 | E12: Hotelaria | F12: =D12&" - "&E12 -> 108 - Hotelaria | G12: =LEN(F12) -> 15
C13: Equip. - Indefinido | D13: =D12+1 -> 109 | E13: Indefinido | F13: =D13&" - "&E13 -> 109 - Indefinido | G13: =LEN(F13) -> 16
C14: Equip. - Indústria | D14: =D13+1 -> 110 | E14: Indústria | F14: =D14&" - "&E14 -> 110 - Indústria | G14: =LEN(F14) -> 15
C15: Equip. - Lazer | D15: =D14+1 -> 111 | E15: Lazer | F15: =D15&" - "&E15 -> 111 - Lazer | G15: =LEN(F15) -> 11
C16: Equip. - Outras E. Renováveis | D16: =D15+1 -> 112 | E16: Out. E. Ren. | F16: =D16&" - "&E16 -> 112 - Out. E. Ren. | G16: =LEN(F16) -> 18
C17: Equip. - Pecuária | D17: =D16+1 -> 113 | E17: Pecuária | F17: =D17&" - "&E17 -> 113 - Pecuária | G17: =LEN(F17) -> 14
... C20: Equip. - Transporte | D20: =D19+1 -> 116 | E20: Transporte | F20: =D20&" - "&E20 -> 116 - Transporte | G20: =LEN(F20) -> 16
C21: Viatura - Agricultura | D21: 201 | E21: Agricultura | F21: =D21&" - "&E21 -> 201 - Agricultura | G21: =LEN(F21) -> 17
C22: Viatura - Avião | D22: 202 | E22: Avião | F22: =D22&" - "&E22 -> 202 - Avião | G22: =LEN(F22) -> 11
C23: Viatura - Construção | D23: 203 | E23: Construção | F23: =D23&" - "&E23 -> 203 - Construção | G23: =LEN(F23) -> 16
C24: Viatura - Indefinido | D24: 204 | E24: Indefinido | F24: =D24&" - "&E24 -> 204 - Indefinido | G24: =LEN(F24) -> 16
C25: Viatura - Ligeiro mercadorias | D25: 205 | E25: Lig. Merc. | F25: =D25&" - "&E25 -> 205 - Lig. Merc. | G25: =LEN(F25) -> 16
C26: Viatura - Ligeiro passageiros | D26: 206 | E26: Lig. Pass. | F26: =D26&" - "&E26 -> 206 - Lig. Pass. | G26: =LEN(F26) -> 16
C27: Viatura - Maritimo | D27: 207 | E27: Maritimo | F27: =D27&" - "&E27 -> 207 - Maritimo | G27: =LEN(F27) -> 14
C28: Viatura - Motociclo | D28: 208 | E28: Motociclo | F28: =D28&" - "&E28 -> 208 - Motociclo | G28: =LEN(F28) -> 15
C29: Viatura - Pesado mercadorias | D29: 209 | E29: Pes. Merc. | F29: =D29&" - "&E29 -> 209 - Pes. Merc. | G29: =LEN(F29) -> 16
C30: Viatura - Pesado passageiros | D30: 210 | E30: Pes. Pass. | F30: =D30&" - "&E30 -> 210 - Pes. Pass. | G30: =LEN(F30) -> 16
C31: Viatura - Reboque | D31: 211 | E31: Reboque | F31: =D31&" - "&E31 -> 211 - Reboque | G31: =LEN(F31) -> 13
