Workbook
Name balancete: #REF!
Name balancete: #REF!
Name balancete: #REF!
Name bta: #REF!
Name bta: #REF!
Name bta: #REF!
Name CAYMAN: #REF!
Name CAYMAN: #REF!
Name CAYMAN: #REF!
Name cpp: #REF!
Name cpp: #REF!
Name cpp: #REF!
Name IT: [1]LANÇAMENTO!#REF!
Name IT: [1]LANÇAMENTO!#REF!
Name IT: [1]LANÇAMENTO!#REF!
Name madeira: #REF!
Name madeira: #REF!
Name madeira: #REF!

Sheet Controlo Jun24
A1: Stock Adjudicados + Próprios | J1: Stock Dações+Arrematações | S1: Stock Imóveis IFIC
A3: PCI | J3: PCI | S3: PCI
A4: STOCK | J4: STOCK | S4: STOCK
A5: 2740904-2740900 | B5: =+SUMIF('Stock Adjudicados+Próprios'!$AC$2:$AC$610,'Controlo Jun24'!A5,'Stock Adjudicados+Próprios'!$K$2:$K$610) -> 36734072 | D5: 299004-299000 | E5: =+SUMIF('Stock Adjudicados+Próprios'!$AE$2:$AE$610,'Controlo Jun24'!D5,'Stock Adjudicados+Próprios'!$P$2:$P$610) -> 19748332 | J5: 27900 | K5: =+SUMIF('Stock Dações+Arrematações'!$AB$6:$AB$72,'Controlo Jun24'!J5,'Stock Dações+Arrematações'!$G$6:$G$72) -> 103300 | M5: 29910 | N5: =+SUMIF('Stock Dações+Arrematações'!$AD$6:$AD$72,'Controlo Jun24'!M5,'Stock Dações+Arrematações'!$K$6:$K$72) -> 103300 | P5: 29911 | Q5: =+SUMIF('Stock Dações+Arrematações'!$AF$6:$AF$72,'Controlo Jun24'!P5,'Stock Dações+Arrematações'!$U$6:$U$72)+SUMIF('Stock Dações+Arrematações'!$AF$6:$AF$72,'Controlo Jun24'!P5,'Stock Dações+Arrematações'!$W$6:$W$72)+SUMIF('Stock Dações+Arrematações'!$AF$6:$AF$72,'Controlo Jun24'!P5,'Stock Dações+Arrematações'!$X$6:$X$72) -> 0 | S5: 27490 | T5: =+SUMIF('Stock Imoveis IFIC'!$AB$5:$AB$15,'Controlo Jun24'!S5,'Stock Imoveis IFIC'!$I$5:$I$15) -> 695195.86 | V5: 29990 | W5: =+SUMIF('Stock Imoveis IFIC'!$AD$5:$AD$15,'Controlo Jun24'!V5,'Stock Imoveis IFIC'!$T$5:$T$15) -> 25780.41 | Y5: 29992 | Z5: =+SUMIF('Stock Imoveis IFIC'!$AF$5:$AF$15,'Controlo Jun24'!Y5,'Stock Imoveis IFIC'!$S$5:$S$15)+SUMIF('Stock Imoveis IFIC'!$AF$5:$AF$15,'Controlo Jun24'!Y5,'Stock Imoveis IFIC'!$X$5:$X$15)+SUMIF('Stock Imoveis IFIC'!$AF$5:$AF$15,'Controlo Jun24'!Y5,'Stock Imoveis IFIC'!$Y$5:$Y$15) -> 26404.343
A6: 2740900 | B6: =+SUMIF('Stock Adjudicados+Próprios'!$AC$2:$AC$610,'Controlo Jun24'!A6,'Stock Adjudicados+Próprios'!$K$2:$K$610) -> 0 | D6: 299000 | E6: =+SUMIF('Stock Adjudicados+Próprios'!$AE$2:$AE$610,'Controlo Jun24'!D6,'Stock Adjudicados+Próprios'!$P$2:$P$610) -> 0 | G6: 299020 | H6: =+SUMIF('Stock Adjudicados+Próprios'!$AG$2:$AG$610,'Controlo Jun24'!G6,'Stock Adjudicados+Próprios'!$Q$2:$Q$610) -> 2471148.3 | J6: 27901 | K6: =+SUMIF('Stock Dações+Arrematações'!$AB$6:$AB$72,'Controlo Jun24'!J6,'Stock Dações+Arrematações'!$G$6:$G$72) -> 2321762.8 | M6: 29920 | N6: =+SUMIF('Stock Dações+Arrematações'!$AD$6:$AD$72,'Controlo Jun24'!M6,'Stock Dações+Arrematações'!$K$6:$K$72) -> 16968.96 | P6: 29921 | Q6: =+SUMIF('Stock Dações+Arrematações'!$AF$6:$AF$72,'Controlo Jun24'!P6,'Stock Dações+Arrematações'!$U$6:$U$72)+SUMIF('Stock Dações+Arrematações'!$AF$6:$AF$72,'Controlo Jun24'!P6,'Stock Dações+Arrematações'!$W$6:$W$72)+SUMIF('Stock Dações+Arrematações'!$AF$6:$AF$72,'Controlo Jun24'!P6,'Stock Dações+Arrematações'!$X$6:$X$72) -> 661600.41
A7: 2740901 | B7: =+SUMIF('Stock Adjudicados+Próprios'!$AC$2:$AC$610,'Controlo Jun24'!A7,'Stock Adjudicados+Próprios'!$K$2:$K$610) -> 6586461.1 | D7: 299001 | E7: =+SUMIF('Stock Adjudicados+Próprios'!$AE$2:$AE$610,'Controlo Jun24'!D7,'Stock Adjudicados+Próprios'!$P$2:$P$610) -> 1543327.5 | G7: 299021 | H7: =+SUMIF('Stock Adjudicados+Próprios'!$AG$2:$AG$610,'Controlo Jun24'!G7,'Stock Adjudicados+Próprios'!$Q$2:$Q$610) -> 1824999.4
A8: 2740991 | B8: =+SUMIF('Stock Adjudicados+Próprios'!$AC$2:$AC$610,'Controlo Jun24'!A8,'Stock Adjudicados+Próprios'!$K$2:$K$610) -> 10888765 | D8: 299011 | E8: =+SUMIF('Stock Adjudicados+Próprios'!$AE$2:$AE$610,'Controlo Jun24'!D8,'Stock Adjudicados+Próprios'!$P$2:$P$610) -> 4719117.4 | G8: 299031 | H8: =+SUMIF('Stock Adjudicados+Próprios'!$AG$2:$AG$610,'Controlo Jun24'!G8,'Stock Adjudicados+Próprios'!$Q$2:$Q$610) -> 977551.52
A10: BALANCETE | J10: BALANCETE | S10: BALANCETE
A11: 2740900 | B11: 5782650.2 | D11: 299000 | E11: 1106189 | G11: 299020 | H11: 2471148.3 | J11: 27900 | K11: -103299.95 | M11: 29910 | N11: 103300.01 | P11: 29911 | Q11: 0 | S11: 27490 | T11: -695195.86 | V11: 29990 | W11: 25780.4 | Y11: 29992 | Z11: 26404.33
A12: 2740901 | B12: -6586461.1 | D12: 299001 | E12: 1543327.4 | G12: 299021 | H12: 1824999.4 | J12: 27901 | K12: -2321762.8 | M12: 29920 | N12: 16969.03 | P12: 29921 | Q12: 661600.41
A13: 2740904 | B13: -42516722 | D13: 299004 | E13: 18642143
A14: 2740991 | B14: -10888764 | D14: 299011 | E14: 4719117.3 | G14: 299031 | H14: 977551.52
A16: CONTROLO | J16: CONTROLO | S16: CONTROLO
A17: 2740904-2740900 | B17: =+B11+B13+B5+B6 -> 0.010000005 | D17: 299004-299000 | E17: =+E11+E13-E5-E6 -> -0.080000006 | G17: 299020 | H17: =+H11-H6 -> -0.00032713823 | J17: 27900 | K17: =+K11+K5 -> 0.05 | M17: 29910 | N17: =+N11-N5 -> 0.01 | P17: 29911 | Q17: =+Q11-Q5 -> 0 | S17: 27490 | T17: =+T11+T5 -> 0 | V17: 29990 | W17: =+W11-W5 -> -0.01 | Y17: 29992 | Z17: =+Z11-Z5 -> -0.013185
A18: 2740901 | B18: =+B12+B7 -> -0.0048999991 | D18: 299001 | E18: =+E12-E7 -> 0 | G18: 299021 | H18: =+H12-H7 -> -0.0013992353 | J18: 27901 | K18: =+K12+K6 -> 0 | M18: 29920 | N18: =+N12-N6 -> 0.07 | P18: 29921 | Q18: =+Q12-Q6 -> 0.0017664332
A19: 2740991 | B19: =+B14+B8 -> 0.69 | D19: 299011 | E19: =+E14-E8 -> -0.050000001 | G19: 299031 | H19: =+H14-H8 -> -0.0014930691
A22: IFRS | J22: IFRS | S22: IFRS
A23: STOCK | J23: STOCK | S23: STOCK
A24: 19910000 | B24: =+SUMIF('Stock Adjudicados+Próprios'!$AD$2:$AD$610,'Controlo Jun24'!A24,'Stock Adjudicados+Próprios'!$K$2:$K$610) -> 6586461.1 | D24: 19910001 | E24: =+SUMIF('Stock Adjudicados+Próprios'!$AF$2:$AF$610,'Controlo Jun24'!D24,'Stock Adjudicados+Próprios'!$P$2:$P$610)+SUMIF('Stock Adjudicados+Próprios'!$AH$2:$AH$610,'Controlo Jun24'!D24,'Stock Adjudicados+Próprios'!$Q$2:$Q$610) -> 3368326.8 | J24: 199100200 | K24: =+SUMIF('Stock Dações+Arrematações'!$AC$6:$AC$72,'Controlo Jun24'!J24,'Stock Dações+Arrematações'!$G$6:$G$72) -> 103300 | M24: 199100201 | N24: =+SUMIF('Stock Dações+Arrematações'!$AE$6:$AE$72,'Controlo Jun24'!M24,'Stock Dações+Arrematações'!$Z$6:$Z$72) -> 103300 | S24: 199100240 | T24: =+SUMIF('Stock Imoveis IFIC'!$AC$5:$AC$15,'Controlo Jun24'!S24,'Stock Imoveis IFIC'!$I$5:$I$15) -> 695195.86 | V24: 199100241 | W24: =+SUMIF('Stock Imoveis IFIC'!$AE$5:$AE$15,'Controlo Jun24'!V24,'Stock Imoveis IFIC'!$T$5:$T$15)+SUMIF('Stock Imoveis IFIC'!$AE$5:$AE$15,'Controlo Jun24'!V24,'Stock Imoveis IFIC'!$S$5:$S$15)+SUMIF('Stock Imoveis IFIC'!$AE$5:$AE$15,'Controlo Jun24'!V24,'Stock Imoveis IFIC'!$X$5:$X$15)+SUMIF('Stock Imoveis IFIC'!$AE$5:$AE$15,'Controlo Jun24'!V24,'Stock Imoveis IFIC'!$Y$5:$Y$15) -> 52184.753
A25: 1910000 | B25: =+SUMIF('Stock Adjudicados+Próprios'!$AD$2:$AD$610,'Controlo Jun24'!A25,'Stock Adjudicados+Próprios'!$K$2:$K$610) -> 36734072 | D25: 1910008 | E25: =+SUMIF('Stock Adjudicados+Próprios'!$AF$2:$AF$610,'Controlo Jun24'!D25,'Stock Adjudicados+Próprios'!$P$2:$P$610)+SUMIF('Stock Adjudicados+Próprios'!$AH$2:$AH$610,'Controlo Jun24'!D25,'Stock Adjudicados+Próprios'!$Q$2:$Q$610) -> 22219480 | J25: 199100210 | K25: =+SUMIF('Stock Dações+Arrematações'!$AC$6:$AC$72,'Controlo Jun24'!J25,'Stock Dações+Arrematações'!$G$6:$G$72) -> 2321762.8 | M25: 199100211 | N25: =+SUMIF('Stock Dações+Arrematações'!$AE$6:$AE$72,'Controlo Jun24'!M25,'Stock Dações+Arrematações'!$Z$6:$Z$72) -> 678569.37
A26: 19911000 | B26: =+SUMIF('Stock Adjudicados+Próprios'!$AD$2:$AD$610,'Controlo Jun24'!A26,'Stock Adjudicados+Próprios'!$K$2:$K$610) -> 10888765 | D26: 19911001 | E26: =+SUMIF('Stock Adjudicados+Próprios'!$AF$2:$AF$610,'Controlo Jun24'!D26,'Stock Adjudicados+Próprios'!$P$2:$P$610)+SUMIF('Stock Adjudicados+Próprios'!$AH$2:$AH$610,'Controlo Jun24'!D26,'Stock Adjudicados+Próprios'!$Q$2:$Q$610) -> 5696668.9
A28: BALANCETE | J28: BALANCETE | S28: BALANCETE
A29: 19910000 | B29: -6586461.1 | D29: 19910001 | E29: 3368326.8 | J29: 199100200 | K29: -103299.95 | M29: 199100201 | N29: 103300.01 | S29: 199100240 | T29: -695195.86 | V29: 199100241 | W29: 52184.73
A30: 1910000 | B30: -36734072 | D30: 1910008 | E30: 22219480 | J30: 199100210 | K30: -2321762.8 | M30: 199100211 | N30: 678569.44
A31: 19911000 | B31: -10888764 | D31: 19911001 | E31: 5696668.8
A33: CONTROLO | J33: CONTROLO | S33: CONTROLO
A34: 19910000 | B34: =+B24+B29 -> -0.0048999991 | D34: 19910001 | E34: =+E24-E29 -> 0.0013992353 | J34: 199100200 | K34: =+K24+K29 -> 0.05 | M34: 199100201 | N34: =+N29-N24 -> 0.01 | S34: 199100240 | T34: =+T29+T24 -> 0 | V34: 199100241 | W34: =+W29-W24 -> -0.023185
A35: 1910000 | B35: =+B25+B30 -> 0.010000013 | D35: 1910008 | E35: =+E25-E30 -> 0.080327146 | J35: 199100210 | K35: =+K25+K30 -> 0 | M35: 199100211 | N35: =+N30-N25 -> 0.071766433
A36: 19911000 | B36: =+B26+B31 -> 0.69 | D36: 19911001 | E36: =+E26-E31 -> 0.051493069
A38: EQUIVALÊNCIAS
A39: IFRS | B39: CARGABAL
A40: 19910000 | B40: 1605010
A41: 1910000 | B41: 1605010
A42: 19911000 | B42: 160510
A43: 19910001 | B43: 2642300
A44: 1910008 | B44: 2642300
A45: 19911001 | B45: 26423100
A46: 199100200 | B46: 1605010
A47: 199100210 | B47: 1605010
A48: 199100201 | B48: 2642300
...

Sheet Stock Adjudicados+Próprios
A1: Cód. Imóvel | B1: GRD Imovel | C1: Entidade | D1: Concelho - Morada | E1: Devedor | F1: Nº Cliente | G1: Nº do Bem | H1: Classificação | I1: Tipo Imóvel | J1: Dt. Aquisição | K1: V Contab = V Aq | L1: Provisão Mês Ant. | M1: V Contb Liq | N1: Sinais | O1: VV | P1: Provisão Legal | Q1: Provisão Adicional | R1: Dt com Compromisso | S1: % Propriedade | T1: VVR | U1: Empresa_Avaliadora | V1: Dt_Avaliacao | W1: % Provisão | X1: Dação Fomento à Construção | Y1: DFC Estado | Z1: Valor_Mercado | AC1: VC-PCI | AD1: VC-IFRS | AE1: PL-PCI | AF1: PL-IFRS | AG1: PA-PCI | AH1: PA-IFRS
A2: 949 | B2: N | C2: SANTANDER - RECUPERACAO DE CREDITOS | D2: Gois - Rua de Cabril, Nº S/N | E2: ADRIANO COSTA | F2: 653 | H2: Regularização | I2: TERRENO RUSTICO - Outros | J2: 1993-06-09 | K2: 1023.57 | L2: 1023.57 | M2: 0 | N2: 0 | O2: 0 | P2: 1023.57 | Q2: 0 | S2: 75 | T2: 700 | U2: PVW PRICE, VALUE AND WORTH, LDA | V2: 2024-01-10 | W2: 100 | Z2: 900 | AC2: 2740901 | AD2: 19910000 | AE2: 299001 | AF2: 19910001 | AG2: 299021 | AH2: 19910001
A3: 1502 | B3: N | C3: SANTANDER - RECUPERACAO DE CREDITOS | D3: Benavente - BENAVENTE-Arneiro dos Corvos, Lt72 Fr P (Parq.) "P" | E3: Alvaro Ferreira | H3: Compromissos | I3: PARQUEAMENTO - Outros | J3: 1990-10-18 | K3: 18801.15 | L3: 18801.15 | M3: 0 | N3: 12878.53 | O3: 18455.52 | P3: 18801.15 | Q3: 0 | R3: 2005-04-19 | S3: 100 | T3: 55603 | U3: QUALITAS - LISBOA | V3: 2009-04-26 | W3: 100 | X3: DFC | Y3: Construção Terminada | Z3: 72000 | AC3: 2740904-2740900 | AD3: 1910000 | AE3: 299004-299000 | AF3: 1910008 | AG3: 299020 | AH3: 1910008
A4: 1539 | B4: N | C4: SANTANDER - RECUPERACAO DE CREDITOS | D4: Almada - Terras da Costa | E4: Serra & irmãos, Lda. | F4: 8005060840 | H4: Regularização | I4: TERRENO URBANO - Residencial | J4: 1993-02-26 | K4: 54867.77 | L4: 54867.77 | M4: 0 | N4: 0 | O4: 0 | P4: 54867.77 | Q4: 0 | S4: 100 | T4: 0 | W4: 100 | Z4: 0 | AC4: 2740901 | AD4: 19910000 | AE4: 299001 | AF4: 19910001 | AG4: 299021 | AH4: 19910001
A5: 2090 | B5: N | C5: SANTANDER - RECUPERACAO DE CREDITOS | D5: Oleiros - OLEIROS - Admoço, S/N | E5: ÁLVARO ANTUNES SANTOS | F5: 8002820781 | H5: Regularização | I5: MORADIA - Residencial | J5: 2000-12-12 | K5: 72558.425 | L5: 72557.88 | M5: 0.5451 | N5: 0 | O5: 0 | P5: 0 | Q5: 72557.88 | S5: 100 | T5: 77730 | U5: BENEGE - LISBOA | V5: 2024-04-23 | W5: 0 | Z5: 94800 | AC5: 2740901 | AD5: 19910000 | AE5: 299001 | AF5: 19910001 | AG5: 299021 | AH5: 19910001
A6: 2435 | B6: N | C6: SANTANDER - RECUPERACAO DE CREDITOS | D6: Vila Nova De Gaia - Rua Vila D'Este, Nº 54, 1º dto "E" | E6: IMAFIL/FERALMAIA | F6: 9000661226 | H6: Vendas | I6: ESCRITORIO OU ATELIER - Comercial | J6: 2002-03-04 | K6: 19453.12 | L6: 19453.12 | M6: 0 | N6: 0 | O6: 0 | P6: 19453.12 | Q6: 0 | S6: 100 | T6: 44200 | U6: CPU - PORTO | V6: 2024-05-07 | W6: 100 | Z6: 52000 | AC6: 2740904-2740900 | AD6: 1910000 | AE6: 299004-299000 | AF6: 1910008 | AG6: 299020 | AH6: 1910008
A7: 2665 | B7: N | C7: SANTANDER - RECUPERACAO DE CREDITOS | D7: Paredes - Rua Dr. José Leite de Vasconcelos, Nº 2, Piso 1 "G" | E7: Ind. Reunidas do Tâmega, S.A. | F7: 9001737248 | H7: Vendas | I7: GARAGEM - Outros | J7: 2003-08-29 | K7: 30000 | L7: 29562.216 | M7: 437.78 | N7: 0 | O7: 0 | P7: 0 | Q7: 29562.216 | S7: 100 | T7: 82800 | U7: LUSO-ROUX - PORTO | V7: 2024-01-17 | W7: 0 | X7: DFC | Y7: Construção Terminada | Z7: 108500 | AC7: 2740904-2740900 | AD7: 1910000 | AE7: 299004-299000 | AF7: 1910008 | AG7: 299020 | AH7: 1910008
A8: 3221 | B8: N | C8: SANTANDER - RECUPERACAO DE CREDITOS | D8: Avis - AVIS - Rossio - Rua 1º de Maio, 9 | E8: Papelaco Turismo-I Turist. Imob.SA | F8: 9000675239 | H8: Regularização | I8: ARMAZEM - Comercial | J8: 2004-07-27 | K8: 10970.09 | L8: 10970.09 | M8: 0 | N8: 0 | O8: 0 | P8: 10970.09 | Q8: 0 | S8: 100 | T8: 6175 | U8: QUALITAS - LISBOA | V8: 2007-12-12 | W8: 100 | Z8: 8250 | AC8: 2740901 | AD8: 19910000 | AE8: 299001 | AF8: 19910001 | AG8: 299021 | AH8: 19910001
A9: 3301 | B9: N | C9: SANTANDER - RECUPERACAO DE CREDITOS | D9: Sintra - Rua de São João, Nº 33, Armazém B, R/C e 1º andar "B" | E9: Bernardino Braz & Braz, Lda | F9: 9001500575 | H9: Vendas | I9: ARMAZEM - Comercial | J9: 2004-09-15 | K9: 320234.38 | L9: 223863.33 | M9: 96371.05 | N9: 0 | O9: 0 | P9: 0 | Q9: 223863.33 | S9: 100 | T9: 364200 | U9: CUSTO MARGINAL, LDA | V9: 2024-05-21 | W9: 0 | Z9: 425000 | AC9: 2740904-2740900 | AD9: 1910000 | AE9: 299004-299000 | AF9: 1910008 | AG9: 299020 | AH9: 1910008
A10: 5116 | B10: N | C10: SANTANDER - RECUPERACAO DE CREDITOS | D10: Maia - Quinta do Meilão, Lote 31 | E10: Jaime Franklim Romano Fernandes | F10: 9001035124 | H10: Compromissos | I10: MORADIA - Residencial | J10: 2004-08-31 | K10: 34172.58 | L10: 659.53079 | M10: 33513.05 | N10: 14950 | O10: 149500 | P10: 0 | Q10: 659.53079 | R10: 2022-02-18 | S10: 100 | T10: 146790 | U10: BENEGE - PORTO | V10: 2020-06-29 | W10: 0 | Z10: 182750 | AC10: 2740904-2740900 | AD10: 1910000 | AE10: 299004-299000 | AF10: 1910008 | AG10: 299020 | AH10: 1910008
A11: 7346 | B11: GI | C11: SANTANDER - RECUPERACAO DE CREDITOS | D11: Ovar - Trav.Elias Garcia,nº62,2º Dt.Ft., Ap.9 "I" | E11: Construtora Residência, Lda. | F11: 9001832548 | H11: Regularização | I11: FRACCAO HABITACIONAL - Residencial | J11: 2003-08-04 | K11: 124344.2 | L11: 86367.304 | M11: 37976.9 | N11: 0 | O11: 0 | P11: 7894.2 | Q11: 78473.104 | S11: 100 | T11: 116450 | U11: CPU - PORTO | V11: 2024-05-07 | W11: 0 | X11: DFC | Y11: Construção Terminada | Z11: 137000 | AC11: 2740901 | AD11: 19910000 | AE11: 299001 | AF11: 19910001 | AG11: 299021 | AH11: 19910001
A12: 7351 | B12: GI | C12: SANTANDER - RECUPERACAO DE CREDITOS | D12: Ovar - Trav.Elias Garcia,nº62,2ºCt.Esq.Tras., Ap.14 "O" | E12: Construtora Residência, Lda. | F12: 9001832548 | H12: Regularização | I12: FRACCAO HABITACIONAL - Residencial | J12: 2003-08-04 | K12: 156026.3 | L12: 117687.45 | M12: 38338.85 | N12: 0 | O12: 0 | P12: 10931.3 | Q12: 106756.15 | S12: 100 | T12: 145095 | U12: BENEGE - PORTO | V12: 2023-09-15 | W12: 0 | X12: DFC | Y12: Construção Terminada | Z12: 183000 | AC12: 2740901 | AD12: 19910000 | AE12: 299001 | AF12: 19910001 | AG12: 299021 | AH12: 19910001
A13: 7353 | B13: GI | C13: SANTANDER - RECUPERACAO DE CREDITOS | D13: Ovar - Trav.Elias Garcia,nº62,2ºEsq.Tras., Ap.16 "Q" | E13: Construtora Residência, Lda. | F13: 9001832548 | H13: Regularização | I13: FRACCAO HABITACIONAL - Residencial | J13: 2003-08-04 | K13: 115786.62 | L13: 92986.74 | M13: 22799.88 | N13: 0 | O13: 0 | P13: 18036.62 | Q13: 74950.12 | S13: 100 | T13: 97750 | U13: CPU - PORTO | V13: 2024-05-07 | W13: 0 | X13: DFC | Y13: Construção Terminada | Z13: 115000 | AC13: 2740901 | AD13: 19910000 | AE13: 299001 | AF13: 19910001 | AG13: 299021 | AH13: 19910001
A14: 7378 | B14: GI | C14: SANTANDER - RECUPERACAO DE CREDITOS | D14: Ovar - Tv. Elias Garcia,nº112, 4º Dt. Tras., Ap.40 "AR" | E14: Construtora Residência, Lda. | F14: 9001832548 | H14: Regularização | I14: FRACCAO HABITACIONAL - Residencial | J14: 2003-08-04 | K14: 118189.87 | L14: 94615.645 | M14: 23574.23 | N14: 0 | O14: 0 | P14: 20439.87 | Q14: 74175.775 | S14: 100 | T14: 97750 | U14: CPU - PORTO | V14: 2024-05-07 | W14: 0 | X14: DFC | Y14: Construção Terminada | Z14: 115000 | AC14: 2740901 | AD14: 19910000 | AE14: 299001 | AF14: 19910001 | AG14: 299021 | AH14: 19910001
A15: 7383 | B15: GI | C15: SANTANDER - RECUPERACAO DE CREDITOS | D15: Ovar - Tv.Elias Garcia,nº112 4º Esq. Cto., Ap.45 "AX" | E15: Construtora Residência, Lda. | F15: 9001832548 | H15: Regularização | I15: FRACCAO HABITACIONAL - Residencial | J15: 2003-08-04 | K15: 113375.76 | L15: 113375.76 | M15: 0 | N15: 0 | O15: 0 | P15: 6250.76 | Q15: 107125 | S15: 100 | T15: 107125 | U15: BENEGE - PORTO | V15: 2023-09-14 | W15: 0 | X15: DFC | Y15: Construção Terminada | Z15: 128000 | AC15: 2740901 | AD15: 19910000 | AE15: 299001 | AF15: 19910001 | AG15: 299021 | AH15: 19910001
A16: 7400 | B16: GI | C16: SANTANDER - RECUPERACAO DE CREDITOS | D16: Ovar - R. Fundação Pepolim,nº63,2º Ft.,Ap.62 "BP" | E16: Construtora Residência, Lda. | F16: 9001832548 | H16: Regularização | I16: FRACCAO HABITACIONAL - Residencial | J16: 2003-08-04 | K16: 112274.95 | L16: 74937.973 | M16: 37336.98 | N16: 0 | O16: 0 | P16: 2054.95 | Q16: 72883.023 | S16: 100 | T16: 110220 | U16: BENEGE - PORTO | V16: 2024-05-15 | W16: 0 | X16: DFC | Y16: Construção Terminada | Z16: 129800 | AC16: 2740901 | AD16: 19910000 | AE16: 299001 | AF16: 19910001 | AG16: 299021 | AH16: 19910001
A17: 8264 | B17: N | C17: SANTANDER - RECUPERACAO DE CREDITOS | D17: Figueira Da Foz - Rua Dr. Santos Rocha, Nº 70 | E17: Maria Graziela Carriço Alves | F17: 8005478523 | H17: Compromissos | I17: ARMAZEM - Comercial | J17: 2009-05-07 | K17: 42107.6 | L17: 34600.332 | M17: 7507.27 | N17: 765.5 | O17: 7655.01 | P17: 34452.59 | Q17: 147.74169 | R17: 2022-12-16 | S17: 100 | T17: 26500 | U17: LUSO-ROUX - PORTO | V17: 2022-03-17 | W17: 0 | Z17: 32500 | AC17: 2740904-2740900 | AD17: 1910000 | AE17: 299004-299000 | AF17: 1910008 | AG17: 299020 | AH17: 1910008
A18: 12024 | B18: N | C18: SANTANDER - RECUPERACAO DE CREDITOS | D18: Odivelas - Rua Padre João Pinto, Nº 9, 1º FRENTE "E" | E18: Maria Helena Pereira Marques | F18: 2291057587 | G18: 003012936830001 | H18: Regularização | I18: FRACCAO HABITACIONAL - Residencial | J18: 2012-03-27 | K18: 0 | L18: 0 | M18: 0 | N18: 0 | O18: 0 | P18: 0 | Q18: 0 | S18: 100 | T18: 20000 | U18: CUSTO MARGINAL, LDA | V18: 2024-06-18 | W18: 100 | Z18: 25000 | AC18: 2740901 | AD18: 19910000 | AE18: 299001 | AF18: 19910001 | AG18: 299021 | AH18: 19910001
A19: 12230 | B19: N | C19: SANTANDER - RECUPERACAO DE CREDITOS | D19: Abrantes - Rua Dr. António Ferreira Brandão, Nº 23 | E19: Carlos Manuel Silva Ramos | F19: 9001540469 | G19: 003012028190000 | H19: Compromissos | I19: MORADIA - Residencial | J19: 2010-07-08 | K19: 30109.25 | L19: 581.10852 | M19: 29528.14 | N19: 3226.03 | O19: 32260.3 | P19: 0 | Q19: 581.10852 | R19: 2022-12-16 | S19: 100 | T19: 36825 | U19: LUSO-ROUX - LISBOA | V19: 2022-03-03 | W19: 0 | Z19: 45850 | AC19: 2740904-2740900 | AD19: 1910000 | AE19: 299004-299000 | AF19: 1910008 | AG19: 299020 | AH19: 1910008
A20: 15140 | B20: N | C20: SANTANDER - RECUPERACAO DE CREDITOS | D20: Alcobaça - Rua da Jardineira, S/N | E20: Eric Fernandes | F20: 2101093131 | G20: 003013163900000 | H20: Compromissos | I20: MORADIA - Residencial | J20: 2013-04-03 | K20: 146770.77 | L20: 10617.776 | M20: 136152.99 | N20: 13883.25 | O20: 138832.46 | P20: 7938.31 | Q20: 2679.4665 | R20: 2022-12-16 | S20: 100 | T20: 173600 | U20: CUSTO MARGINAL, LDA | V20: 2022-06-17 | W20: 0 | Z20: 215000 | AC20: 2740904-2740900 | AD20: 1910000 | AE20: 299004-299000 | AF20: 1910008 | AG20: 299020 | AH20: 1910008
A21: 15141 | B21: N | C21: SANTANDER - RECUPERACAO DE CREDITOS | D21: Figueira Da Foz - Rua Manuel Ribeiro Varino, Nº 10 | E21: Luis Fernando Ferreira Neves Rodrigues | F21: 9002553621 | G21: 000010845940000 | H21: Regularização | I21: MORADIA - Residencial | J21: 2013-07-11 | K21: 40097 | L21: 13842.701 | M21: 26254.3 | N21: 0 | O21: 0 | P21: 0 | Q21: 13842.701 | S21: 100 | T21: 50970 | U21: LUSO-ROUX - PORTO | V21: 2023-09-20 | W21: 0 | Z21: 69100 | AC21: 2740901 | AD21: 19910000 | AE21: 299001 | AF21: 19910001 | AG21: 299021 | AH21: 19910001
A22: 15226 | B22: N | C22: SANTANDER - RECUPERACAO DE CREDITOS | D22: Figueira Da Foz - Rua das Neves, Nº 9 | E22: Henrique José Fernandes Rato | F22: 2671005640 | G22: 003011880930000 | H22: Compromissos | I22: MORADIA - Residencial | J22: 2013-10-08 | K22: 193629.23 | L22: 24324.781 | M22: 169304.45 | N22: 17263.63 | O22: 172636.33 | P22: 20992.9 | Q22: 3331.8812 | R22: 2022-12-16 | S22: 100 | T22: 180000 | U22: PVW PRICE, VALUE AND WORTH, LDA | V22: 2022-05-06 | W22: 0 | Z22: 211000 | AC22: 2740904-2740900 | AD22: 1910000 | AE22: 299004-299000 | AF22: 1910008 | AG22: 299020 | AH22: 1910008
A23: 15473 | B23: N | C23: SANTANDER - RECUPERACAO DE CREDITOS | D23: Amarante - Travessa de Langeais, Lote 36 | E23: Manuel Paiva - Sociedade Gestão Imobiliária, Lda. | F23: 1700093441 | G23: 009013879970000 | H23: Compromissos | I23: TERRENO URBANO - Residencial | J23: 2013-11-07 | K23: 59044.21 | L23: 18835.51 | M23: 40208.7 | N23: 2572.2 | O23: 105000 | P23: 0 | Q23: 1139.5533 | R23: 2024-06-07 | S23: 100 | T23: 41000 | U23: LUSO-ROUX - PORTO | V23: 2024-04-09 | W23: 0 | Z23: 52300 | AC23: 2740904-2740900 | AD23: 1910000 | AE23: 299004-299000 | AF23: 1910008 | AG23: 299020 | AH23: 1910008
A24: 15474 | B24: N | C24: SANTANDER - RECUPERACAO DE CREDITOS | D24: Amarante - Travessa de Langeais, Lote 37 | E24: Manuel Paiva - Sociedade Gestão Imobiliária, Lda. | F24: 1700093441 | G24: 009013879990000 | H24: Compromissos | I24: TERRENO URBANO - Residencial | J24: 2013-11-07 | K24: 55092.21 | L24: 11941.41 | M24: 43150.8 | N24: 2677.8 | O24: 54390 | P24: 702.21 | Q24: 1049.727 | R24: 2024-06-07 | S24: 100 | T24: 44000 | U24: LUSO-ROUX - PORTO | V24: 2024-04-09 | W24: 0 | Z24: 56200 | AC24: 2740904-2740900 | AD24: 1910000 | AE24: 299004-299000 | AF24: 1910008 | AG24: 299020 | AH24: 1910008
A25: 15975 | B25: N | C25: SANTANDER - RECUPERACAO DE CREDITOS | D25: Miranda Do Corvo - Estrada da Godinhela, S/N | E25: José A. Correia - Comércio Auto, Lda. | F25: 8043537365 | H25: Compromissos | I25: MORADIA - Residencial | J25: 2014-01-22 | K25: 71091.39 | L25: 8720.9 | M25: 62370.49 | N25: 6359.79 | O25: 63597.93 | P25: 7493.46 | Q25: 1227.44 | R25: 2022-12-16 | S25: 100 | T25: 66011.21 | U25: BENEGE - PORTO | V25: 2021-04-29 | W25: 0 | Z25: 97200 | AC25: 2740904-2740900 | AD25: 1910000 | AE25: 299004-299000 | AF25: 1910008 | AG25: 299020 | AH25: 1910008
A26: 16870 | B26: N | C26: SANTANDER - RECUPERACAO DE CREDITOS | D26: Montemor-O-Novo - Rua da Papoila, Nº 2 | E26: Maria Manuela Groginha Carneiro Monteiro Coelho | F26: 9001776713 | G26: 003011093160000 | H26: Compromissos | I26: MORADIA - Residencial | J26: 2015-01-28 | K26: 129819.38 | L26: 2505.514 | M26: 127313.87 | N26: 21519.3 | O26: 215192.99 | P26: 0 | Q26: 2505.514 | R26: 2022-12-16 | S26: 100 | T26: 221760 | U26: LUSO-ROUX - LISBOA | V26: 2022-02-08 | W26: 0 | Z26: 281100 | AC26: 2740904-2740900 | AD26: 1910000 | AE26: 299004-299000 | AF26: 1910008 | AG26: 299020 | AH26: 1910008
A27: 16943 | B27: N | C27: SANTANDER - RECUPERACAO DE CREDITOS | D27: Valongo - Travessa Vasco da Gama, Nº 80 | E27: Maria José Oliveira Santos Silva | F27: 9001515829 | G27: 000010329420000 | H27: Compromissos | I27: MORADIA - Residencial | J27: 2014-12-10 | K27: 159518.63 | L27: 32558.983 | M27: 126959.65 | N27: 12945.82 | O27: 129458.19 | P27: 30060.44 | Q27: 2498.5431 | R27: 2022-12-16 | S27: 100 | T27: 114800 | U27: LUSO-ROUX - PORTO | V27: 2022-05-04 | W27: 0 | Z27: 149000 | AC27: 2740904-2740900 | AD27: 1910000 | AE27: 299004-299000 | AF27: 1910008 | AG27: 299020 | AH27: 1910008
A28: 16976 | B28: N | C28: SANTANDER - RECUPERACAO DE CREDITOS | D28: Torres Novas - Sesmarias S/N | E28: Fernando Miguel Lopes Soares | F28: 9002487933 | G28: 000010902680000 | H28: Compromissos | I28: MORADIA - Residencial | J28: 2014-04-30 | K28: 117420.65 | L28: 2266.2185 | M28: 115154.43 | N28: 16310 | O28: 163100 | P28: 0 | Q28: 2266.2185 | R28: 2022-12-16 | S28: 100 | T28: 186200 | U28: PVW PRICE, VALUE AND WORTH, LDA | V28: 2022-07-01 | W28: 0 | Z28: 216000 | AC28: 2740904-2740900 | AD28: 1910000 | AE28: 299004-299000 | AF28: 1910008 | AG28: 299020 | AH28: 1910008
A29: 17261 | B29: N | C29: SANTANDER - RECUPERACAO DE CREDITOS | D29: Loures - Praceta Barahona Fernandes, Lote B7B, 8º DTO. "Z" | E29: Fábio Soares Oliveira | F29: 7400513068 | G29: 003013229210001 | H29: Compromissos | I29: FRACCAO HABITACIONAL - Residencial | J29: 2013-06-14 | K29: 68269.14 | L29: 1317.5944 | M29: 66951.55 | N29: 14010 | O29: 140100 | P29: 0 | Q29: 1317.5944 | R29: 2022-12-16 | S29: 100 | T29: 84800 | U29: LUSO-ROUX - LISBOA | V29: 2022-03-02 | W29: 0 | Z29: 102500 | AC29: 2740904-2740900 | AD29: 1910000 | AE29: 299004-299000 | AF29: 1910008 | AG29: 299020 | AH29: 1910008
A30: 18072 | B30: N | C30: SANTANDER - RECUPERACAO DE CREDITOS | D30: Moita - Rua Cândido dos Reis, Nº 58 e 60, R/C "A" | E30: Cartario Pinto Construções, S.A. | F30: 3921003830 | H30: Compromissos | I30: LOJA - Comercial | J30: 2016-01-21 | K30: 37557.69 | L30: 3233.19 | M30: 34324.5 | N30: 3500 | O30: 35000 | P30: 2557.69 | Q30: 675.5 | R30: 2024-04-12 | S30: 100 | T30: 28000 | U30: LUSO-ROUX - LISBOA | V30: 2023-07-26 | W30: 0 | Z30: 37000 | AC30: 2740904-2740900 | AD30: 1910000 | AE30: 299004-299000 | AF30: 1910008 | AG30: 299020 | AH30: 1910008
A31: 18101 | B31: N | C31: BANIF | D31: Ponta Delgada - Alameda de Belém, Nº 502 | E31: Fábio Manuel Medeiros Sousa | F31: 2101301937 | G31: 083015001980000 | H31: Regularização | I31: MORADIA - Residencial | J31: 2015-12-23 | K31: 37434.51 | L31: 37434.51 | M31: 0 | N31: 0 | O31: 0 | P31: 37434.51 | Q31: 0 | S31: 50 | T31: 0 | U31: OUTROS | V31: 2020-07-17 | W31: 100 | Z31: 0 | AC31: 2740901 | AD31: 19910000 | AE31: 299001 | AF31: 19910001 | AG31: 299021 | AH31: 19910001
A32: 18102 | B32: N | C32: BANIF | D32: Ponta Delgada - Alameda de Belém, Nº 502 | E32: Ermelinda Graça Santos Francisco | F32: 2101301937 | G32: 083015001980000 | H32: Regularização | I32: MORADIA - Residencial | J32: 2015-12-21 | K32: 36700.5 | L32: 36700.5 | M32: 0 | N32: 0 | O32: 0 | P32: 36700.5 | Q32: 0 | S32: 50 | T32: 0 | U32: OUTROS | V32: 2020-07-17 | W32: 100 | Z32: 0 | AC32: 2740901 | AD32: 19910000 | AE32: 299001 | AF32: 19910001 | AG32: 299021 | AH32: 19910001
A33: 18272 | B33: N | C33: BANIF | D33: Povoação - Pico, S/N | E33: Carlos Miguel Lopes Pereira | F33: 2101323828 | H33: Regularização | I33: TERRENO RUSTICO - Outros | J33: 2015-12-21 | K33: 20545.38 | L33: 20545.38 | M33: 0 | N33: 0 | O33: 0 | P33: 20545.38 | Q33: 0 | S33: 100 | T33: 0 | U33: OUTROS | V33: 2020-07-17 | W33: 100 | Z33: 0 | AC33: 2740901 | AD33: 19910000 | AE33: 299001 | AF33: 19910001 | AG33: 299021 | AH33: 19910001
A34: 18477 | B34: N | C34: BANIF | D34: Ponta Delgada - Rua Pero Garcia, Nº 2-A | E34: Carlos Miguel Lopes Pereira | F34: 2101323828 | G34: 083015103770000 | H34: Regularização | I34: MORADIA - Residencial | J34: 2015-12-21 | K34: 59600 | L34: 59600 | M34: 0 | N34: 0 | O34: 0 | P34: 59600 | Q34: 0 | S34: 50 | T34: 0 | U34: OUTROS | V34: 2020-07-17 | W34: 100 | Z34: 0 | AC34: 2740901 | AD34: 19910000 | AE34: 299001 | AF34: 19910001 | AG34: 299021 | AH34: 19910001
A35: 18481 | B35: N | C35: BANIF | D35: Santarém - Rua Primeiro de Maio, S/N | E35: Helena Isabel Campos Montes Silva | F35: 2100789769 | H35: Compromissos | I35: PREDIO MISTO - OUTROS | J35: 2016-05-16 | K35: 54932.39 | L35: 50587.399 | M35: 4344.99 | N35: 443.05 | O35: 4430.5 | P35: 50501.89 | Q35: 85.50865 | R35: 2022-12-16 | S35: 100 | T35: 19600 | U35: BENEGE - LISBOA | V35: 2022-04-04 | W35: 0 | Z35: 24300 | AC35: 2740904-2740900 | AD35: 1910000 | AE35: 299004-299000 | AF35: 1910008 | AG35: 299020 | AH35: 1910008
A36: 18545 | B36: N | C36: BANIF | D36: Vila Praia Da Vitória - Estrada 25 de Abril, Nº 291-A | E36: Carlos Manuel Rosa Silva | F36: 2101294583 | H36: Regularização | I36: MORADIA - Residencial | J36: 2016-01-21 | K36: 55000 | L36: 55000 | M36: 0 | N36: 0 | O36: 0 | P36: 55000 | Q36: 0 | S36: 100 | T36: 0 | U36: OUTROS | V36: 2020-07-17 | W36: 100 | Z36: 0 | AC36: 2740901 | AD36: 19910000 | AE36: 299001 | AF36: 19910001 | AG36: 299021 | AH36: 19910001
A37: 18558 | B37: N | C37: SANTANDER - RECUPERACAO DE CREDITOS | D37: Carregal Do Sal - Rua Afonso Marques, Nº 54 | E37: Maria João Figueiredo Pina | F37: 7400215696 | G37: 003012384270001 | H37: Compromissos | I37: MORADIA - Residencial | J37: 2016-09-12 | K37: 77552.13 | L37: 1496.7561 | M37: 76055.37 | N37: 10371.39 | O37: 103713.92 | P37: 0 | Q37: 1496.7561 | R37: 2022-12-16 | S37: 100 | T37: 112490 | U37: LUSO-ROUX - PORTO | V37: 2022-07-01 | W37: 0 | Z37: 142600 | AC37: 2740904-2740900 | AD37: 1910000 | AE37: 299004-299000 | AF37: 1910008 | AG37: 299020 | AH37: 1910008
A38: 18656 | B38: N | C38: SANTANDER - RECUPERACAO DE CREDITOS | D38: Sintra - Rua da Reserva Botânica, Nº 25, PISO-3, GA "B" | E38: António José Coelho Almeida | F38: 5100716299 | G38: 000000284170001 | H38: Compromissos | I38: GARAGEM - Outros | J38: 2014-02-24 | K38: 5751.46 | L38: 111.00318 | M38: 5640.46 | N38: 1213.28 | O38: 12132.81 | P38: 0 | Q38: 111.00318 | R38: 2022-12-16 | S38: 100 | T38: 11900 | U38: CUSTO MARGINAL, LDA | V38: 2021-09-27 | W38: 0 | Z38: 14000 | AC38: 2740904-2740900 | AD38: 1910000 | AE38: 299004-299000 | AF38: 1910008 | AG38: 299020 | AH38: 1910008
A39: 18747 | B39: N | C39: BANIF | D39: Santa Cruz - Achadinha do Pico, S/N "B" | E39: Filipe António Perez da Silva | F39: 2100583448 | H39: Compromissos | I39: MORADIA - Residencial | J39: 2016-04-13 | K39: 131619.3 | L39: 2540.2525 | M39: 129079.05 | N39: 14070 | O39: 140700 | P39: 0 | Q39: 2540.2525 | R39: 2022-12-16 | S39: 100 | T39: 141090 | U39: PVW PRICE, VALUE AND WORTH, LDA | V39: 2022-07-27 | W39: 0 | Z39: 171795 | AC39: 2740904-2740900 | AD39: 1910000 | AE39: 299004-299000 | AF39: 1910008 | AG39: 299020 | AH39: 1910008
A40: 18748 | B40: N | C40: BANIF | D40: Santa Cruz - Achadinha do Pico, S/N "C" | E40: Filipe António Perez da Silva | F40: 2100583448 | H40: Compromissos | I40: MORADIA - Residencial | J40: 2016-04-13 | K40: 131619.3 | L40: 2540.2525 | M40: 129079.05 | N40: 15700 | O40: 157000 | P40: 0 | Q40: 2540.2525 | R40: 2022-12-16 | S40: 100 | T40: 135145 | U40: PVW PRICE, VALUE AND WORTH, LDA | V40: 2022-07-27 | W40: 0 | Z40: 164555 | AC40: 2740904-2740900 | AD40: 1910000 | AE40: 299004-299000 | AF40: 1910008 | AG40: 299020 | AH40: 1910008
...

Sheet Stock Dações+Arrematações
R1: 45473
A2: Moeda: 978 | W2: 0.012989005 | X2: 0.0193
A3: Origem | B3: Balcão | C3: Nr. Cliente | D3: GP / TC | E3: Nome Cliente | F3: Entradas | G3: V.Contabilistico | I3: Valor Avaliação | K3: Valor Provisão | M3: Data da Adjudicação | N3: Data do Título | O3: Gestimo | P3: Tipo de Bem | Q3: Morada | R3: LOCALIDADE | S3: Antiguidade | T3: Avaliação | U3: Provisão | V3: % | W3: INSUFICIÊNCIA | X3: CUSTO | Y3: % PROVISÃO | Z3: PROVISÃO
F4: Data | H4: U.O. | I4: Montante | J4: Data | K4: Montante | L4: % | S4: Avaliação | T4: Ajustada | U4: Av.Ajustada | X4: s/ V. Liq | Y4: TOTAL | Z4: TOTAL
G5: =SUM(G6:G42) -> 2425062.8 | I5: =SUM(I6:I42) -> 3089833.1 | K5: =SUM(K6:K42) -> 120268.96 | S5: 45473 | T5: =SUM(T6:T42) -> 2095359 | U5: =SUM(U6:U42) -> 619211.24 | W5: =SUM(W6:W42) -> 10051.416 | X5: =SUM(X6:X42) -> 32337.753 | Z5: =SUM(Z6:Z42) -> 781869.37 | AB5: VC-PCI | AC5: VC-IFRS | AD5: PL-PCI | AE5: PL-IFRS | AF5: PA-PCI | AG5: PA-IFRS
A6: BAPOP | E6: ANTÓNIO MANUEL DIAS PRAXEDES | F6: 42278 | G6: 103300 | H6: 9948 | I6: 0 | K6: 103300 | Y6: 1 | Z6: 103300 | AB6: 27900 | AC6: 199100200 | AD6: 29910 | AE6: 199100201 | AF6: 29911 | AG6: 199100201
A7: BST | B7: 5177 | C7: 8009161420 | E7: António Pinto Almeida Lino | F7: 41614 | G7: 80000 | H7: 6185 | I7: 158330 | J7: 44880 | K7: 0 | M7: 37664 | N7: 0 | O7: 14981 | Q7: Rua Dr. Rafael Duque, 3 - 1º Dtº - Benfica - Lisboa | S7: 1.6246575 | T7: 126664 | U7: 0 | V7: 0 | W7: 1039.1204 | X7: 1523.945 | Y7: 0.032038318 | Z7: 2563.0654 | AB7: 27901 | AC7: 199100210 | AD7: 29920 | AE7: 199100211 | AF7: 29921 | AG7: 199100211
A8: BST | B8: 5275 | C8: 7400168683 | E8: Maria Gorete Santos Serrano | F8: 41607 | G8: 68429.93 | H8: 6185 | I8: 111400 | J8: 45191 | K8: 0 | M8: 41599 | N8: 41599 | O8: 15732 | Q8: Rua dos Ferreiros, 198 e 200 - Funchal | S8: 0.77260274 | T8: 100260 | U8: 0 | V8: 0 | W8: 888.83673 | X8: 1303.5431 | Y8: 0.032038318 | Z8: 2192.3798 | AB8: 27901 | AC8: 199100210 | AD8: 29920 | AE8: 199100211 | AF8: 29921 | AG8: 199100211
A9: BST | B9: 3175 | C9: 2611001226 | D9: RE0151852013 | E9: Manuel Virgilio Oliveira | F9: 41845 | G9: 138191.62 | H9: 6185 | I9: 136201.23 | J9: 42565 | K9: 1990.39 | M9: 41844 | N9: 41844 | Q9: Rua Central de Arcos, 1540 - S. Pedro Fins - Maia | S9: 7.9671233 | T9: 68100.615 | U9: 68100.615 | V9: 0.50720156 | W9: 0 | X9: 1314.3419 | Y9: 0.51671257 | Z9: 71405.347 | AB9: 27901 | AC9: 199100210 | AD9: 29920 | AE9: 199100211 | AF9: 29921 | AG9: 199100211
A10: BST | B10: 387 | C10: 3761002127 | D10: TC7081622010 | E10: Maria Teresa Alves Sousa Cavalheiro | F10: 41845 | G10: 89297.81 | H10: 6185 | I10: 130631.85 | J10: 42559 | K10: 0 | M10: 41373 | N10: 41843 | Q10: Boa Água I , lote 463 - Quinta do Conde - Sesimbra | S10: 7.9835616 | T10: 65315.925 | U10: 23981.885 | V10: 0.26856073 | W10: 0 | X10: 1260.5974 | Y10: 0.28267751 | Z10: 25242.482 | AB10: 27901 | AC10: 199100210 | AD10: 29920 | AE10: 199100211 | AF10: 29921 | AG10: 199100211
A11: BST | B11: 5038 | C11: 7400091336 | D11: TC7057092012 | E11: Manuela Jesus Clemente Sequeira | F11: 41536 | G11: 54508 | H11: 6185 | I11: 126700 | J11: 44525 | K11: 0 | M11: 41521 | N11: 41521 | P11: 1/2 fracção | Q11: Av. Pinhal de Vidal, 14 - Corroios - Seixal | S11: 2.5972603 | T11: 63350 | U11: 0 | V11: 0 | W11: 708.00471 | X11: 1038.3399 | Y11: 0.032038318 | Z11: 1746.3446 | AB11: 27901 | AC11: 199100210 | AD11: 29920 | AE11: 199100211 | AF11: 29921 | AG11: 199100211
A12: BST | B12: 668 | C12: 7400356304 | D12: TC7081642009 | E12: Média One - Multimedia Unipessoal, Lda. | F12: 41943 | G12: 26120.79 | H12: 6185 | I12: 55000 | J12: 45309 | K12: 0 | M12: 41859 | N12: 41890 | Q12: Rua dos Olivais, 108 - Arcos - Anadia | S12: 0.44931507 | T12: 55000 | U12: 0 | V12: 0 | W12: 339.28308 | X12: 497.58308 | Y12: 0.032038318 | Z12: 836.86617 | AB12: 27901 | AC12: 199100210 | AD12: 29920 | AE12: 199100211 | AF12: 29921 | AG12: 199100211
A13: BST | B13: 5251 | C13: 8000237888 | D13: TC7033182007 | E13: Fernando Coutinho Duarte | F13: 42062 | G13: 29640.62 | H13: 6185 | I13: 55000 | J13: 45215 | K13: 0 | M13: 42061 | N13: 42061 | Q13: Burinhosa - Pataias - Alcobaça | S13: 0.70684932 | T13: 49500 | U13: 0 | V13: 0 | W13: 385.00217 | X13: 564.63342 | Y13: 0.032038318 | Z13: 949.6356 | AB13: 27901 | AC13: 199100210 | AD13: 29920 | AE13: 199100211 | AF13: 29921 | AG13: 199100211
A14: BST | B14: 5052 | C14: 8010464178 | E14: Miriam Thelma C R M Pereira Menezes | F14: 41835 | G14: 101096.36 | H14: 6185 | I14: 101096.36 | J14: 41794 | K14: 0 | M14: 41830 | N14: 41830 | P14: Têm Usufruto | Q14: Rua das Oliveiras, Quinta do Brasilieiro, 22 - 1º - Corroios - Seixal | S14: 10.079452 | T14: 50548.18 | U14: 50548.18 | V14: 0.5 | W14: 0 | X14: 975.57987 | Y14: 0.50965 | Z14: 51523.76 | AB14: 27901 | AC14: 199100210 | AD14: 29920 | AE14: 199100211 | AF14: 29921 | AG14: 199100211
A15: BST | B15: 5156 | C15: 8030275314 | E15: Rui Vaz Guerra/Cremilda Maria Mendonça | F15: 41670 | G15: 46361.68 | H15: 6185 | I15: 41938.18 | J15: 42237 | K15: 4423.5 | M15: 41615 | N15: 41659 | Q15: Rua Sacadura Cabral, 1 - Couço - Coruche | S15: 8.8657534 | T15: 20969.09 | U15: 20969.09 | V15: 0.54770642 | W15: 0 | X15: 404.70344 | Y15: 0.55643569 | Z15: 25797.293 | AB15: 27901 | AC15: 199100210 | AD15: 29920 | AE15: 199100211 | AF15: 29921 | AG15: 199100211
A16: BST | B16: 3480 | C16: 9000817157 | D16: TC8034122008 | E16: Manuel Antonio Lopes Jacob | F16: 41089 | G16: 70937 | H16: 6185 | I16: 63752.13 | J16: 42219 | K16: 7184.87 | M16: 41059 | N16: 41059 | Q16: Sitio da Carreira, 72 - Fatela - Fundão | S16: 8.9150685 | T16: 31876.065 | U16: 31876.065 | V16: 0.55064261 | W16: 0 | X16: 615.20805 | Y16: 0.55931521 | Z16: 39676.143 | AB16: 27901 | AC16: 199100210 | AD16: 29920 | AE16: 199100211 | AF16: 29921 | AG16: 199100211
A17: BST | B17: 353 | C17: 9002101516 | E17: Olivio Moreira Cabral | F17: 41512 | G17: 87884 | H17: 6185 | I17: 84688.68 | J17: 42193 | K17: 3195.32 | M17: 41506 | N17: 0 | Q17: Loteamento Marchil, Rua Tomé da Costa, Lt. 16 B - 1º D - Montenegro - Faro | S17: 8.9863014 | T17: 42344.34 | U17: 42344.34 | V17: 0.51817919 | W17: 0 | X17: 817.24576 | Y17: 0.52747833 | Z17: 46356.906 | AB17: 27901 | AC17: 199100210 | AD17: 29920 | AE17: 199100211 | AF17: 29921 | AG17: 199100211
A18: BST | B18: 5152 | C18: 7400469164 | D18: TC7109992011 | E18: Jorge Manuel Lopes Branco Silva | F18: 42184 | G18: 29022.67 | H18: 6185 | I18: 28854.98 | J18: 42663 | K18: 167.69 | M18: 42179 | N18: 0 | Q18: Rua Eça de Queirós, 22 - Almeirim | S18: 7.6986301 | T18: 14427.49 | U18: 14427.49 | V18: 0.50288895 | W18: 0 | X18: 278.45056 | Y18: 0.51248319 | Z18: 14873.631 | AB18: 27901 | AC18: 199100210 | AD18: 29920 | AE18: 199100211 | AF18: 29921 | AG18: 199100211
A19: BST | B19: 5320 | C19: 7400325342 | D19: RE0148162015 | E19: Fernando Antonio Silva | F19: 42185 | G19: 77638.94 | H19: 6185 | I19: 144153.48 | J19: 42150 | K19: 0 | M19: 42184 | N19: 0 | Q19: Pereiras de Cima - Quarteira - Loulé | S19: 9.1041096 | T19: 72076.74 | U19: 5562.2 | V19: 0.071641885 | W19: 0 | X19: 1391.0811 | Y19: 0.089559196 | Z19: 6953.2811 | AB19: 27901 | AC19: 199100210 | AD19: 29920 | AE19: 199100211 | AF19: 29921 | AG19: 199100211
A20: BST | B20: 3510 | C20: 9000507854 | D20: RE0284872013 | E20: Olinda Maria Ormeche Gonçalves/José Luis Alves Costa | F20: 42240 | G20: 45239.56 | H20: 6185 | I20: 45239.56 | J20: 42065 | K20: 0 | M20: 42234 | N20: 42212 | Q20: Aldeia Nova do Barroso-Chã - Montalegre | S20: 9.3369863 | T20: 22619.78 | U20: 22619.78 | V20: 0.5 | W20: 0 | X20: 436.56175 | Y20: 0.50965 | Z20: 23056.342 | AB20: 27901 | AC20: 199100210 | AD20: 29920 | AE20: 199100211 | AF20: 29921 | AG20: 199100211
A21: BST | B21: 352 | C21: 8027577467 | D21: TC0124042014 | E21: Manuel Santos Ferreira | F21: 42397 | G21: 150412.08 | H21: 6185 | I21: 150412.08 | J21: 42314 | K21: 0 | M21: 42341 | N21: 42377 | S21: 8.6547945 | T21: 75206.04 | U21: 75206.04 | V21: 0.5 | W21: 0 | X21: 1451.4766 | Y21: 0.50965 | Z21: 76657.517 | AB21: 27901 | AC21: 199100210 | AD21: 29920 | AE21: 199100211 | AF21: 29921 | AG21: 199100211
A22: BST | B22: 376 | C22: 1700007349 | D22: TC7058462012 | E22: Sérgio Bruno Gallego Mergulhão Considra/Sandra Isabel da Silva Oliveira | F22: 42452 | G22: 62376.07 | H22: 6185 | I22: 121769.67 | J22: 44990 | K22: 0 | M22: 42450 | N22: 42450 | Q22: Rua Sá de Miranda , Lotes 1741,1742 e 1743 , 1º , Quinta do Conde | S22: 1.3232877 | T22: 97415.736 | U22: 0 | V22: 0 | W22: 810.20311 | X22: 1188.2212 | Y22: 0.032038318 | Z22: 1998.4243 | AB22: 27901 | AC22: 199100210 | AD22: 29920 | AE22: 199100211 | AF22: 29921 | AG22: 199100211
A23: BST | B23: 3255 | C23: 9001054885a | D23: RE0141332016 | E23: Carlos Manuel Miranda Teofilo | F23: 42613 | G23: 39497.14 | H23: 6185 | I23: 39497.145 | J23: 42524 | K23: 0 | M23: 42535 | N23: 42608 | Q23: Rua Bartolomeu Dias, 62 - R/c D - Casais do Baleal - Ferrel - Peniche | S23: 8.0794521 | T23: 19748.572 | U23: 19748.568 | V23: 0.49999994 | W23: 0 | X23: 381.14745 | Y23: 0.50964994 | Z23: 20129.715 | AB23: 27901 | AC23: 199100210 | AD23: 29920 | AE23: 199100211 | AF23: 29921 | AG23: 199100211
A24: BST | B24: 8005 | C24: 2100094299 | D24: RE0349132016 | E24: Fernando Alberto Freitas Santos/Maria Liseta Fernandes de Andrade | F24: 42754 | G24: 57711.58 | H24: 6185 | I24: 62200 | J24: 42438 | K24: 0 | M24: 42678 | N24: 42706 | Q24: Sitío da Pedra Nossa Senhora - Campanário - Ribeira Brava - Funchal | S24: 8.3150685 | T24: 31100 | U24: 26611.58 | V24: 0.46111335 | W24: 0 | X24: 600.23 | Y24: 0.47151386 | Z24: 27211.81 | AB24: 27901 | AC24: 199100210 | AD24: 29920 | AE24: 199100211 | AF24: 29921 | AG24: 199100211
A25: BST | B25: 334 | C25: 9002370446 | D25: RE0331722014 | E25: Ana Paula Alberto Jone | F25: 42874 | G25: 51057.28 | H25: 6185 | I25: 51057.28 | J25: 42780 | K25: 0 | M25: 42788 | N25: 42796 | Q25: Rua dos Moínhos, 43 - R/c Esq. - Queluz - Sintra | S25: 7.3780822 | T25: 25528.64 | U25: 25528.64 | V25: 0.5 | W25: 0 | X25: 492.70275 | Y25: 0.50965 | Z25: 26021.343 | AB25: 27901 | AC25: 199100210 | AD25: 29920 | AE25: 199100211 | AF25: 29921 | AG25: 199100211
A26: BST | B26: 391 | C26: 7400258484 | D26: RE0382682013 | E26: Luis Miguel Lourenço Vicente | F26: 42957 | G26: 53685.7 | H26: 6185 | I26: 53685.7 | J26: 42774 | K26: 0 | M26: 42783 | N26: 42837 | Q26: Rua António Espirito Santo, 5 - R/c Dtº - Quinta da Gordalina - Marrazes - Leiria | S26: 7.3945205 | T26: 26842.85 | U26: 26842.85 | V26: 0.5 | W26: 0 | X26: 518.067 | Y26: 0.50965 | Z26: 27360.917 | AB26: 27901 | AC26: 199100210 | AD26: 29920 | AE26: 199100211 | AF26: 29921 | AG26: 199100211
A27: BST | B27: 8710 | C27: 2101349503 | D27: TC9096422009 | E27: Fernando Manuel Medeiros Melo | F27: 43026 | G27: 36200 | H27: 6185 | I27: 39437.79 | J27: 43025 | K27: 0 | M27: 42566 | N27: 42803 | Q27: Rua do Porto Novo, 11 - S. Mateus - Madalena - Horta | S27: 6.7068493 | T27: 19718.895 | U27: 16481.105 | V27: 0.45527914 | W27: 0 | X27: 380.57467 | Y27: 0.46579226 | Z27: 16861.68 | AB27: 27901 | AC27: 199100210 | AD27: 29920 | AE27: 199100211 | AF27: 29921 | AG27: 199100211
A28: BST | B28: 8716 | C28: 2101296342 | D28: TC0348542016 | E28: Acácio Miguel Ponte Silva | F28: 43187 | G28: 42763.68 | H28: 6185 | I28: 45000 | J28: 44679 | K28: 0 | M28: 43136 | N28: 43136 | Q28: Rua da Boa Viagem , nº 49 - Calhetas | S28: 2.1753425 | T28: 22500 | U28: 20263.68 | V28: 0.47385258 | W28: 0 | X28: 434.25 | Y28: 0.48400722 | Z28: 20697.93 | AB28: 27901 | AC28: 199100210 | AD28: 29920 | AE28: 199100211 | AF28: 29921 | AG28: 199100211
A29: BST | B29: 346 | C29: 2100176174 | D29: TC9002242003 | E29: João Júlio Oliveira Costa | F29: 43280 | G29: 96900 | H29: 6185 | I29: 96900 | J29: 43192 | K29: 0 | M29: 43216 | N29: 43249 | Q29: Rua Foros da Amora, 58 - R/c (Estabelecimento Dtº) - Amora - Seixal | S29: 6.2493151 | T29: 48450 | U29: 48450 | V29: 0.5 | W29: 0 | X29: 935.085 | Y29: 0.50965 | Z29: 49385.085 | AB29: 27901 | AC29: 199100210 | AD29: 29920 | AE29: 199100211 | AF29: 29921 | AG29: 199100211
A30: BST | B30: 5463 | C30: 7400374370 | D30: RE0148132018 | E30: Igor Leandro Deep Dantas / Carina Vanessa Santos Vaz Rodrigues | F30: 43494 | G30: 35733.86 | H30: 6185 | I30: 35733.865 | J30: 43256 | K30: 0 | M30: 43383 | N30: 43462 | Q30: Rua São Tomé e Príncepe, 8 - 2º Dtº - Vialonga - V. F. Xira | S30: 6.0739726 | T30: 17866.932 | U30: 17866.928 | V30: 0.49999993 | W30: 0 | X30: 344.8318 | Y30: 0.50964993 | Z30: 18211.759 | AB30: 27901 | AC30: 199100210 | AD30: 29920 | AE30: 199100211 | AF30: 29921 | AG30: 199100211
A31: BST | B31: 5221 | C31: 9001791600 | D31: RE0204242018 | E31: Mara Rute Mendonca Matos | F31: 43829 | G31: 53550 | H31: 6185 | I31: 72400 | J31: 44972 | K31: 0 | M31: 43769 | N31: 43808 | Q31: Rua José Afonso, 1 - R/c Dtº - Moita | S31: 1.3726027 | T31: 57920 | U31: 0 | V31: 0 | W31: 695.56124 | X31: 1020.0907 | Y31: 0.032038318 | Z31: 1715.6519 | AB31: 27901 | AC31: 199100210 | AD31: 29920 | AE31: 199100211 | AF31: 29921 | AG31: 199100211
A32: BST | B32: 3330 | C32: 2101611677 | D32: TC0227672019 | E32: Filipe António Monteiro Dias Benedetto | F32: 44085 | G32: 79884.41 | H32: 6185 | I32: 79884.41 | J32: 43973 | K32: 0 | M32: 44062 | N32: 44062 | Q32: Rua Dr. Fernando Ferreira, 268 - Rates - Póvoa de Varzim | S32: 4.109589 | T32: 39942.205 | U32: 39942.205 | V32: 0.5 | W32: 0 | X32: 770.88456 | Y32: 0.50965 | Z32: 40713.09 | AB32: 27901 | AC32: 199100210 | AD32: 29920 | AE32: 199100211 | AF32: 29921 | AG32: 199100211
A33: BST | B33: 342 | C33: 7400196620 | D33: TC0345092019 | E33: Rui Jorge Araujo de Sousa | F33: 44767 | G33: 46907.19 | H33: 6185 | I33: 46900 | J33: 45216 | K33: 7.19 | M33: 44599 | N33: 44599 | Q33: Rua Direira Nº 143 - Amoreira - Rio de Moinhos - concelho de Abrantes | S33: 0.70410959 | T33: 42210 | U33: 4690 | V33: 0.10013795 | W33: 0 | X33: 814.653 | Y33: 0.11750529 | Z33: 5511.843 | AB33: 27901 | AC33: 199100210 | AD33: 29920 | AE33: 199100211 | AF33: 29921 | AG33: 199100211
A34: BST | B34: 298 | C34: 8004061653 | E34: Vitor Manuel Pimenta Sintra | F34: 44858 | G34: 25923.75 | H34: 6185 | I34: 72979.39 | J34: 44655 | K34: 0 | M34: 42894 | N34: 42907 | Q34: Covas, Vale de Moinho, 1º - Vila Nova de Poiares | S34: 2.2410959 | T34: 36489.695 | U34: 0 | V34: 0 | W34: 336.72373 | X34: 493.82961 | Y34: 0.032038318 | Z34: 830.55334 | AB34: 27901 | AC34: 199100210 | AD34: 29920 | AE34: 199100211 | AF34: 29921 | AG34: 199100211
A35: BANIF | B35: 234 | C35: 2100789953 | D35: TC287672021 | E35: SILVIA MARIA TEIXEIRA BARROS | F35: 45030 | G35: 88552.35 | H35: 6185 | I35: 189831.97 | J35: 44923 | K35: 0 | M35: 44973 | N35: 44973 | Q35: Rua Santa Eufémia, nº 597, Tougues, Vila do Conde | S35: 1.5068493 | T35: 151865.58 | U35: 0 | V35: 0 | W35: 1150.207 | X35: 1686.8614 | Y35: 0.032038318 | Z35: 2837.0683 | AB35: 27901 | AC35: 199100210 | AD35: 29920 | AE35: 199100211 | AF35: 29921 | AG35: 199100211
A36: BST | B36: 3726 | C36: 9002212320 | D36: TC0141772015 | E36: Anabela Rebelo Figueiredo | F36: 45078 | G36: 29543.32 | H36: 6185 | I36: 75650 | J36: 45070 | K36: 0 | M36: 43285 | N36: 43285 | P36: 1/2 Fracção; 1º titular Henrique Manuel Costa Fonseca 9002212370 | Q36: Rua Formosa - Bloco B, nº 66, 8ºS, Guarda | S36: 1.1041096 | T36: 60520 | U36: 0 | V36: 0 | W36: 383.73834 | X36: 562.77993 | Y36: 0.032038318 | Z36: 946.51827 | AB36: 27901 | AC36: 199100210 | AD36: 29920 | AE36: 199100211 | AF36: 29921 | AG36: 199100211
A37: BST | B37: 3585 | C37: 9001811986 | D37: TC0159542022 | E37: António Carlos da Silva Almeida | F37: 45282 | G37: 75495.63 | H37: 6185 | I37: 127500 | J37: 45197 | K37: 0 | M37: 45203 | N37: 45229 | Q37: Rua do Prado - Póvoa do Veado - Reriz | S37: 0.75616438 | T37: 114750 | U37: 0 | V37: 0 | W37: 980.61315 | X37: 1438.1398 | Y37: 0.032038318 | Z37: 2418.753 | AB37: 27901 | AC37: 199100210 | AD37: 29920 | AE37: 199100211 | AF37: 29921 | AG37: 199100211
A38: BST | B38: 338 | C38: 7400403925 | D38: RE0131032022 | E38: Jacinto da Conceição Santos | F38: 45286 | G38: 23699.82 | H38: 6185 | I38: 46257.32 | J38: 45257 | K38: 0 | M38: 45000 | N38: 45133 | Q38: Travessa Gago Coutinho, 6 - Outeiros - Vieira de Leiria | S38: 0.59178082 | T38: 41631.588 | U38: 0 | V38: 0 | W38: 307.83709 | X38: 451.46527 | Y38: 0.032038318 | Z38: 759.30236 | AB38: 27901 | AC38: 199100210 | AD38: 29920 | AE38: 199100211 | AF38: 29921 | AG38: 199100211
A39: BANIF | B39: 5248 | C39: 2101343557a | D39: TC0237512022 | E39: Pedro Oliveira & Filhos, Lda. | F39: 45363 | G39: 130000 | H39: 6185 | I39: 130000 | J39: 45219 | K39: 0 | M39: 45300 | N39: 45300 | Q39: Rua de S. Pedro, nº 63/69, São Pedro - Angra do Heroísmo | S39: 0.69589041 | T39: 117000 | U39: 13000 | V39: 0.1 | W39: 0 | X39: 2258.1 | Y39: 0.11737 | Z39: 15258.1 | AB39: 27901 | AC39: 199100210 | AD39: 29920 | AE39: 199100211 | AF39: 29921 | AG39: 199100211
A40: BANIF | B40: 5248 | C40: 2101343557b | D40: TC0237512022 | E40: Pedro Oliveira & Filhos, Lda. | F40: 45363 | G40: 41500 | H40: 6185 | I40: 41500 | J40: 45219 | K40: 0 | M40: 45300 | N40: 45300 | Q40: Rua do Meio, nº 2A, São Pedro - Angra do Heroísmo | S40: 0.69589041 | T40: 37350 | U40: 4150 | V40: 0.1 | W40: 0 | X40: 720.855 | Y40: 0.11737 | Z40: 4870.855 | AB40: 27901 | AC40: 199100210 | AD40: 29920 | AE40: 199100211 | AF40: 29921 | AG40: 199100211
...

Sheet Stock Imoveis IFIC
A2: IMOVEIS EM STOCK A 30/06/2023 - LEAS4
M3: 45473 | N3: Provisões Regulamentares | X3: 0.013 | Y3: 0.0174
A4: Contrato | B4: Série | C4: Imovel | D4: Securitizado | E4: Cliente | F4: Nome Cliente | G4: Data NL | H4: Imobilizado | I4: ValorNL | J4: Valor Avaliação | K4: Data | L4: Total da Provisão | M4: Antiguidade NLO (dias) | N4: Total de Provisões | O4: ANTIGUIDADE AVALIAÇÃO (em n.º anos) | P4: V.MERCADO | Q4: Avaliação Ajustada | R4: % | S4: Provisão Avaliação Ajustada | T4: PROVISÃO LEGAL | U4: VLIQUIDO | V4: DIFICULDADE DE VENDA | W4: % Cobertura | X4: PERDA ESPERADA | Y4: CUSTO | Z4: TOTAL PROVISÃO | AB4: VC-PCI | AC4: VC-IFRS | AD4: PL-PCI | AE4: PL-IFRS | AF4: PA-PCI | AG4: PA-IFRS
A5: 6902510 | B5: 3049 | C5: 69025101 | D5: N | E5: 452899 | F5: 45 X 24 TRANSF COMERCIO C | G5: 43040 | H5: TER-TAPADA GRANDE F | I5: 30846.26 | J5: 25500 | K5: 42822 | L5: 5346.26 | M5: 2433 | N5: 5346.26 | O5: 7.2630137 | P5: 25500 | Q5: 12750 | R5: 0.5 | S5: 12750 | T5: 5346.26 | U5: 25500 | V5: 0 | W5: 0.58665978 | X5: 0 | Y5: 246.075 | Z5: 18342.335 | AB5: 27490 | AC5: 199100240 | AD5: 29990 | AE5: 199100241 | AF5: 29992 | AG5: 199100241
A6: 6902510 | B6: 3050 | C6: 69025102 | D6: N | E6: 452899 | F6: 45 X 24 TRANSF COMERCIO C | G6: 43040 | H6: HAB-FIAL | I6: 2145.24 | J6: 388.42 | K6: 45443 | L6: 1756.82 | M6: 2433 | N6: 1756.82 | O6: 0.082191781 | P6: 388.42 | Q6: 388.42 | R6: 1 | S6: 0 | T6: 1756.82 | U6: 388.42 | V6: 0 | W6: 0.81893867 | X6: 0 | Y6: 7.496506 | Z6: 1764.3165 | AB6: 27490 | AC6: 199100240 | AD6: 29990 | AE6: 199100241 | AF6: 29992 | AG6: 199100241
A7: 6961494 | B7: 3191 | C7: 6961494 | D7: N | E7: 469056 | F7: RISAN-TECNICA E INDUSTRIA | G7: 43405 | H7: ARM-RUA DA GÂNDARA, | I7: 274353.82 | J7: 434700 | K7: 45443 | L7: 0 | M7: 2068 | N7: 0 | O7: 0.082191781 | P7: 434700 | Q7: 434700 | R7: 1 | S7: 0 | T7: 0 | U7: 274353.82 | V7: 0 | W7: 0 | X7: 0 | Y7: 5295.0287 | Z7: 5295.0287 | AB7: 27490 | AC7: 199100240 | AD7: 29990 | AE7: 199100241 | AF7: 29992 | AG7: 199100241
A8: 1010675 | B8: 3192 | C8: 1010675 | D8: N | E8: 654088 | F8: EUROAVAC INSTALACOES DE A | G8: 44256 | H8: COM-CASAL DE BAIXO | I8: 39594 | J8: 219000 | K8: 45230 | L8: 0 | M8: 1217 | N8: 0 | O8: 0.66575342 | P8: 219000 | Q8: 197100 | R8: 0.9 | S8: 0 | T8: 0 | U8: 39594 | V8: 0 | W8: 0 | X8: 0 | Y8: 764.1642 | Z8: 764.1642 | AB8: 27490 | AC8: 199100240 | AD8: 29990 | AE8: 199100241 | AF8: 29992 | AG8: 199100241
A9: 1010593 | B9: 3377 | C9: 1010593 | D9: N | E9: 639907 | F9: CONTALVIS - CENTRO CONTAB | G9: 44287 | H9: ESC-PRACA D JOAO I | I9: 10080.68 | J9: 124472 | K9: 45230 | L9: 0 | M9: 1186 | N9: 0 | O9: 0.66575342 | P9: 124472 | Q9: 112024.8 | R9: 0.9 | S9: 0 | T9: 0 | U9: 10080.68 | V9: 0 | W9: 0 | X9: 0 | Y9: 194.55712 | Z9: 194.55712 | AB9: 27490 | AC9: 199100240 | AD9: 29990 | AE9: 199100241 | AF9: 29992 | AG9: 199100241
A10: 1010593 | B10: 3378 | C10: 200011390 | D10: N | E10: 639907 | F10: CONTALVIS - CENTRO CONTAB | G10: 44287 | H10: ESC-AV CMDTE AFONSO | I10: 15623.49 | J10: 10000 | K10: 45230 | L10: 5623.49 | M10: 1186 | N10: 5623.49 | O10: 0.66575342 | P10: 10000 | Q10: 9000 | R10: 0.9 | S10: 1000 | T10: 5623.49 | U10: 10000 | V10: 0 | W10: 0.42394433 | X10: 0 | Y10: 173.7 | Z10: 6797.19 | AB10: 27490 | AC10: 199100240 | AD10: 29990 | AE10: 199100241 | AF10: 29992 | AG10: 199100241
A11: 1015824 | B11: 3478 | C11: 1015824 | D11: N | E11: 653494 | F11: BRANQUINHOS FURNACE REPAI | G11: 45108 | H11: ARM-R. DOS LAVADOUR | I11: 69504.28 | J11: 148176 | K11: 45443 | L11: 0 | M11: 365 | N11: 0 | O11: 0.082191781 | P11: 148176 | Q11: 148176 | R11: 1 | S11: 0 | T11: 0 | U11: 69504.28 | V11: 0 | W11: 0 | X11: 0 | Y11: 1341.4326 | Z11: 1341.4326 | AB11: 27490 | AC11: 199100240 | AD11: 29990 | AE11: 199100241 | AF11: 29992 | AG11: 199100241
A12: 1015824 | B12: 3479 | C12: 10158242 | D12: N | E12: 653494 | F12: BRANQUINHOS FURNACE REPAI | G12: 45108 | H12: TER-RUA DOS LAVADOU | I12: 13053.84 | J12: 0 | K12: 0 | L12: 13053.84 | M12: 365 | N12: 13053.84 | O12: 124.58356 | P12: 0 | Q12: 0 | R12: 0 | S12: 0 | T12: 13053.84 | U12: 0 | V12: 0 | W12: 1 | X12: 0 | Y12: 0 | Z12: 13053.84 | AB12: 27490 | AC12: 199100240 | AD12: 29990 | AE12: 199100241 | AF12: 29992 | AG12: 199100241
A13: 6961717 | B13: 3426 | C13: 69617171 | D13: N | E13: 459211 | F13: FERNANDO DA SILVA OLIVEIR | G13: 45444 | H13: HAB-CORGOS DE SANTA | I13: 164774.94 | J13: 236700 | K13: 45443 | L13: 0 | M13: 29 | N13: 0 | O13: 0.082191781 | P13: 236700 | Q13: 236700 | R13: 1 | S13: 0 | T13: 0 | U13: 164774.94 | V13: 0 | W13: 0 | X13: 0 | Y13: 3180.1563 | Z13: 3180.1563 | AB13: 27490 | AC13: 199100240 | AD13: 29990 | AE13: 199100241 | AF13: 29992 | AG13: 199100241
A14: 1000597 | B14: 3480 | C14: 1000597 | D14: N | E14: 506306 | F14: CELEIRO DOS ANIMAIS - REP | G14: 45444 | H14: COM-ESTRADA NACIONA | I14: 75219.31 | J14: 267500 | K14: 45169 | L14: 0 | M14: 29 | N14: 0 | O14: 0.83287671 | P14: 267500 | Q14: 240750 | R14: 0.9 | S14: 0 | T14: 0 | U14: 75219.31 | V14: 0 | W14: 0 | X14: 0 | Y14: 1451.7327 | Z14: 1451.7327 | AB14: 27490 | AC14: 199100240 | AD14: 29990 | AE14: 199100241 | AF14: 29992 | AG14: 199100241
A16: Total Imóveis Recuperados
A18: 10 | H18: Total | I18: =SUM(I5:I17) -> 695195.86 | J18: =SUM(J5:J17) -> 1466436.4 | L18: =SUM(L5:L17) -> 25780.41 | N18: =SUM(N5:N17) -> 25780.41 | P18: =SUM(P5:P17) -> 1466436.4 | Q18: =SUM(Q5:Q17) -> 1391589.2 | S18: =SUM(S5:S17) -> 13750 | T18: =SUM(T5:T17) -> 25780.41 | U18: =SUM(U5:U17) -> 669415.45 | V18: =SUM(V5:V17) -> 0 | X18: =SUM(X5:X17) -> 0 | Y18: =SUM(Y5:Y17) -> 12654.343 | Z18: =SUM(Z5:Z17) -> 52184.753
