Workbook

Sheet T 01.00 a
A1: T 01.00.b - Liability structure - carrying amount
D4: Columns
D5: Households | E5: Micro & SME | F5: Corporates | G5: Institutions | H5: Other financial corporations | J5: Government, central banks & supranationals | K5: Instruments listed on exchange platforms | L5: Others/non-identified | M5: Total
D6: Carrying amount | E6: Carrying amount | F6: Carrying amount | G6: Carrying amount | H6: Carrying amount | I6: Of which Insurance firms & pension funds | J6: Carrying amount | K6: Carrying amount | L6: Carrying amount | M6: Carrying amount | N6: Of which: intragroup | O6: Of which: issuances under non-EU MS jurisdiction/law, excluding intragroup
I7: Carrying amount | N7: Carrying amount | O7: Carrying amount
D8: 0011 | E8: 0021 | F8: 0031 | G8: 0041 | H8: 0051 | I8: 0061 | J8: 0081 | K8: 0091 | L8: 0101 | M8: 0121 | N8: 0131 | O8: 0141
A9: Rows | B9: Liabilities excluded from bail-in | C9: 0100 | D9: =D10+D11+D12+D13+D14+D15+D16+D17+D18+D19+D20 -> 1.9384943e+10 | E9: =E10+E11+E12+E13+E14+E15+E16+E17+E18+E19+E20 -> 2.3350551e+09 | F9: =F10+F11+F12+F13+F14+F15+F16+F17+F18+F19+F20 -> 3.8825771e+08 | G9: =G10+G11+G12+G13+G14+G15+G16+G17+G18+G19+G20 -> 2.1391569e+09 | H9: =H10+H11+H12+H13+H14+H15+H16+H17+H18+H19+H20 -> 3.9249404e+09 | I9: =I10+I11+I12+I13+I14+I15+I16+I17+I18+I19+I20 -> 3.0305582e+08 | J9: =J10+J11+J12+J13+J14+J15+J16+J17+J18+J19+J20 -> 7.7635511e+09 | K9: =K10+K11+K12+K13+K14+K15+K16+K17+K18+K19+K20 -> 0 | L9: =L10+L11+L12+L13+L14+L15+L16+L17+L18+L19+L20 -> 0 | M9: =SUM(D9:L9)-I9 -> 3.5935904e+10 | N9: =N10+N11+N12+N13+N14+N15+N16+N17+N18+N19+N20 -> 9.0358516e+08 | O9: 0
B10: Covered deposits (BRRD art. 44/2/a) | C10: 0110 | D10: =+SUMIFS('T 05.01'!$M:$M,'T 05.01'!$E:$E,"r0110 - Covered deposits (BRRD art. 44/2/a)",'T 05.01'!$F:$F,"c001x - Households")+SUMIFS('T 03.01'!P:P,'T 03.01'!E:E,"r0110 - Covered deposits (BRRD art. 44/2/a)",'T 03.01'!$F:$F,"c001x - Households") -> 1.914788e+10 | E10: =+SUMIFS('T 05.01'!$M:$M,'T 05.01'!$E:$E,"r0110 - Covered deposits (BRRD art. 44/2/a)",'T 05.01'!$F:$F,"c002x - Micro & SME")+SUMIFS('T 03.01'!P:P,'T 03.01'!E:E,"r0110 - Covered deposits (BRRD art. 44/2/a)",'T 03.01'!$F:$F,"c002x - Micro & SME") -> 2.3350551e+09 | F10: =+SUMIFS('T 05.01'!$M:$M,'T 05.01'!$E:$E,"r0110 - Covered deposits (BRRD art. 44/2/a)",'T 05.01'!$F:$F,"c003x - Corporates")+SUMIFS('T 03.01'!P:P,'T 03.01'!E:E,"r0110 - Covered deposits (BRRD art. 44/2/a)",'T 03.01'!$F:$F,"c003x - Corporates") -> 3.8825771e+08 | G10: =+SUMIFS('T 05.01'!$M:$M,'T 05.01'!$E:$E,"r0110 - Covered deposits (BRRD art. 44/2/a)",'T 05.01'!$F:$F,"c004x - Institutions")+SUMIFS('T 03.01'!P:P,'T 03.01'!E:E,"r0110 - Covered deposits (BRRD art. 44/2/a)",'T 03.01'!$F:$F,"c004x - Institutions") -> 0 | H10: =+SUMIFS('T 05.01'!$M:$M,'T 05.01'!$E:$E,"r0110 - Covered deposits (BRRD art. 44/2/a)",'T 05.01'!$F:$F,"c005x - Other financial corporations")+I10+SUMIFS('T 03.01'!P:P,'T 03.01'!E:E,"r0110 - Covered deposits (BRRD art. 44/2/a)",'T 03.01'!$F:$F,"c005x - Other financial corporations") -> 0 | I10: =+SUMIFS('T 05.01'!$M:$M,'T 05.01'!$E:$E,"r0110 - Covered deposits (BRRD art. 44/2/a)",'T 05.01'!$F:$F,"c006x - Insurance firms & pension funds")+SUMIFS('T 03.01'!P:P,'T 03.01'!E:E,"r0110 - Covered deposits (BRRD art. 44/2/a)",'T 03.01'!$F:$F,"c006x - Insurance firms & pension funds") -> 0 | J10: =+SUMIFS('T 05.01'!$M:$M,'T 05.01'!$E:$E,"r0110 - Covered deposits (BRRD art. 44/2/a)",'T 05.01'!$F:$F,"c008x - Government, central banks & supranationals")+SUMIFS('T 03.01'!P:P,'T 03.01'!E:E,"r0110 - Covered deposits (BRRD art. 44/2/a)",'T 03.01'!$F:$F,"c008x - Government, central banks & supranationals") -> 0 | K10: 0 | L10: =+SUMIFS('T 05.01'!$M:$M,'T 05.01'!$E:$E,"r0110 - Covered deposits (BRRD art. 44/2/a)",'T 05.01'!$F:$F,"")+SUMIFS('T 03.01'!P:P,'T 03.01'!E:E,"r0110 - Covered deposits (BRRD art. 44/2/a)",'T 03.01'!$F:$F,"") -> 0 | M10: =SUM(D10:L10)-I10 -> 2.1871193e+10 | N10: =+SUMIF('T 03.01'!E:E,"r0110 - Covered deposits (BRRD art. 44/2/a)",'T 03.01'!P:P) -> 732268.55 | O10: 0 | V10: =+N10+N22+M27 -> 6.6805752e+09
B11: Secured liabilities - collateralized part (BRRD art. 44/2/b) | C11: 0120 | D11: =SUMIF('T 08.00'!$E:$E,"c001x - Households",'T 08.00'!$O:$O)+SUMIFS('T 03.01'!P:P,'T 03.01'!E:E,"r0120 - Secured liabilities - collateralized part (BRRD art. 44/2/b)",'T 03.01'!$F:$F,"c001x - Households")+SUMIFS('T 04.00'!N:N,'T 04.00'!F:F,"c001x - Households",'T 04.00'!E:E,"r0120 - Secured liabilities - collateralized part (BRRD art. 44/2/b)") -> 0 | E11: =SUMIF('T 08.00'!$E:$E,"c002x - Micro & SME",'T 08.00'!$O:$O)+SUMIFS('T 03.01'!P:P,'T 03.01'!E:E,"r0120 - Secured liabilities - collateralized part (BRRD art. 44/2/b)",'T 03.01'!$F:$F,"c002x - Micro & SME")+SUMIFS('T 04.00'!N:N,'T 04.00'!F:F,"c002x - Micro & SME",'T 04.00'!E:E,"r0120 - Secured liabilities - collateralized part (BRRD art. 44/2/b)") -> 0 | F11: =SUMIF('T 08.00'!$E:$E,"c003x - Corporates",'T 08.00'!$O:$O)+SUMIFS('T 03.01'!P:P,'T 03.01'!E:E,"r0120 - Secured liabilities - collateralized part (BRRD art. 44/2/b)",'T 03.01'!$F:$F,"c003x - Corporates")+SUMIFS('T 04.00'!N:N,'T 04.00'!F:F,"c003x - Corporates",'T 04.00'!E:E,"r0120 - Secured liabilities - collateralized part (BRRD art. 44/2/b)") -> 0 | G11: =SUMIF('T 08.00'!$E:$E,"c004x - Institutions",'T 08.00'!$O:$O)+SUMIFS('T 03.01'!P:P,'T 03.01'!E:E,"r0120 - Secured liabilities - collateralized part (BRRD art. 44/2/b)",'T 03.01'!$F:$F,"c004x - Institutions")+SUMIFS('T 04.00'!N:N,'T 04.00'!F:F,"c004x - Institutions",'T 04.00'!E:E,"r0120 - Secured liabilities - collateralized part (BRRD art. 44/2/b)") -> 1.9851326e+09 | H11: =SUMIF('T 08.00'!$E:$E,"c005x - Other financial corporations",'T 08.00'!$O:$O)+I11+SUMIFS('T 03.01'!P:P,'T 03.01'!E:E,"r0120 - Secured liabilities - collateralized part (BRRD art. 44/2/b)",'T 03.01'!$F:$F,"c005x - Other financial corporations")+SUMIFS('T 04.00'!N:N,'T 04.00'!F:F,"c005x - Other financial corporations",'T 04.00'!E:E,"r0120 - Secured liabilities - collateralized part (BRRD art. 44/2/b)") -> 3.0229429e+09 | I11: =SUMIF('T 08.00'!$E:$E,"c006x - Insurance firms & pension funds",'T 08.00'!$O:$O)+SUMIFS('T 03.01'!P:P,'T 03.01'!E:E,"r0120 - Secured liabilities - collateralized part (BRRD art. 44/2/b)",'T 03.01'!$F:$F,"c006x - Insurance firms & pension funds")+SUMIFS('T 04.00'!N:N,'T 04.00'!F:F,"c006x - Insurance firms & pension funds",'T 04.00'!E:E,"r0120 - Secured liabilities - collateralized part (BRRD art. 44/2/b)") -> 0 | J11: =SUMIF('T 08.00'!$E:$E,"c008x - Government, central banks & supranationals",'T 08.00'!$O:$O)+SUMIFS('T 03.01'!P:P,'T 03.01'!E:E,"r0120 - Secured liabilities - collateralized part (BRRD art. 44/2/b)",'T 03.01'!$F:$F,"c008x - Government, central banks & supranationals")+SUMIFS('T 04.00'!N:N,'T 04.00'!F:F,"c008x - Government, central banks & supranationals",'T 04.00'!E:E,"r0120 - Secured liabilities - collateralized part (BRRD art. 44/2/b)") -> 7.410242e+09 | K11: 0 | L11: =SUMIF('T 08.00'!$E:$E,"",'T 08.00'!$O:$O)+SUMIFS('T 03.01'!P:P,'T 03.01'!E:E,"r0120 - Secured liabilities - collateralized part (BRRD art. 44/2/b)",'T 03.01'!$F:$F,"")+SUMIFS('T 04.00'!N:N,'T 04.00'!F:F,"",'T 04.00'!E:E,"r0120 - Secured liabilities - collateralized part (BRRD art. 44/2/b)") -> 0 | M11: =SUM(D11:L11)-I11 -> 1.2418317e+10 | N11: =+SUMIF('T 03.01'!E:E,"r0150 - Institution liabilities < 7 days (BRRD art. 44/2/e)",'T 03.01'!P:P) -> 0 | O11: 0
B12: Client liabilities, if protected in insolvency (BRRD art. 44/2/c) | C12: 0130 | D12: 0 | E12: 0 | F12: 0 | G12: 0 | H12: 0 | I12: 0 | J12: 0 | K12: 0 | L12: 0 | M12: =SUM(D12:L12)-I12 -> 0 | N12: 0 | O12: 0
B13: Fiduciary liabilities, if protected in insolvency (BRRD art. 44/2/d) | C13: 0140 | D13: 0 | E13: 0 | F13: 0 | G13: 0 | H13: 0 | I13: 0 | J13: 0 | K13: 0 | L13: 0 | M13: =SUM(D13:L13)-I13 -> 0 | N13: 0 | O13: 0
B14: Institution liabilities < 7 days (BRRD art. 44/2/e) | C14: 0150 | D14: =+SUMIFS('T 06.01'!$O:$O,'T 06.01'!$E:$E,"r0150 - Institution liabilities < 7 days (BRRD art. 44/2/e)",'T 06.01'!$F:$F,"c001x - Households")+SUMIFS('T 03.01'!P:P,'T 03.01'!E:E,"r0150 - Institution liabilities < 7 days (BRRD art. 44/2/e)",'T 03.01'!$F:$F,"c001x - Households") -> 0 | E14: =+SUMIFS('T 06.01'!$O:$O,'T 06.01'!$E:$E,"r0150 - Institution liabilities < 7 days (BRRD art. 44/2/e)",'T 06.01'!$F:$F,"c002x - Micro & SME")+SUMIFS('T 03.01'!P:P,'T 03.01'!E:E,"r0150 - Institution liabilities < 7 days (BRRD art. 44/2/e)",'T 03.01'!$F:$F,"c002x - Micro & SME") -> 0 | F14: =+SUMIFS('T 06.01'!$O:$O,'T 06.01'!$E:$E,"r0150 - Institution liabilities < 7 days (BRRD art. 44/2/e)",'T 06.01'!$F:$F,"c003x - Corporates")+SUMIFS('T 03.01'!P:P,'T 03.01'!E:E,"r0150 - Institution liabilities < 7 days (BRRD art. 44/2/e)",'T 03.01'!$F:$F,"c003x - Corporates") -> 0 | G14: =+SUMIFS('T 06.01'!$O:$O,'T 06.01'!$E:$E,"r0150 - Institution liabilities < 7 days (BRRD art. 44/2/e)",'T 06.01'!$F:$F,"c004x - Institutions")+SUMIFS('T 03.01'!P:P,'T 03.01'!E:E,"r0150 - Institution liabilities < 7 days (BRRD art. 44/2/e)",'T 03.01'!$F:$F,"c004x - Institutions") -> 1.5312813e+08 | H14: =+SUMIFS('T 06.01'!$O:$O,'T 06.01'!$E:$E,"r0150 - Institution liabilities < 7 days (BRRD art. 44/2/e)",'T 06.01'!$F:$F,"c005x - Other financial corporations")+I14+SUMIFS('T 03.01'!P:P,'T 03.01'!E:E,"r0150 - Institution liabilities < 7 days (BRRD art. 44/2/e)",'T 03.01'!$F:$F,"c005x - Other financial corporations") -> 0 | I14: =+SUMIFS('T 06.01'!$O:$O,'T 06.01'!$E:$E,"r0150 - Institution liabilities < 7 days (BRRD art. 44/2/e)",'T 06.01'!$F:$F,"c006x - Insurance firms & pension funds")+SUMIFS('T 03.01'!P:P,'T 03.01'!E:E,"r0150 - Institution liabilities < 7 days (BRRD art. 44/2/e)",'T 03.01'!$F:$F,"c006x - Insurance firms & pension funds") -> 0 | J14: =+SUMIFS('T 06.01'!$O:$O,'T 06.01'!$E:$E,"r0150 - Institution liabilities < 7 days (BRRD art. 44/2/e)",'T 06.01'!$F:$F,"c008x - Government, central banks & supranationals")+SUMIFS('T 03.01'!P:P,'T 03.01'!E:E,"r0150 - Institution liabilities < 7 days (BRRD art. 44/2/e)",'T 03.01'!$F:$F,"c008x - Government, central banks & supranationals") -> 0 | K14: 0 | L14: =+SUMIFS('T 06.01'!$O:$O,'T 06.01'!$E:$E,"r0150 - Institution liabilities < 7 days (BRRD art. 44/2/e)",'T 06.01'!$F:$F,"")+SUMIFS('T 03.01'!P:P,'T 03.01'!E:E,"r0150 - Institution liabilities < 7 days (BRRD art. 44/2/e)",'T 03.01'!$F:$F,"") -> 0 | M14: =SUM(D14:L14)-I14 -> 1.5312813e+08 | N14: =+SUMIF('T 03.01'!E:E,"r0150 - Institution liabilities < 7 days (BRRD art. 44/2/e)",'T 03.01'!P:P) -> 0 | O14: 0
B15: System (operator) and CCP liabilities < 7 days (BRRD art. 44/2/f) | C15: 0161 | D15: =+SUMIFS('T 06.01'!$O:$O,'T 06.01'!$E:$E,"r0161 - System (operator) and CCP liabilities < 7 days (BRRD art. 44/2/f)",'T 06.01'!$F:$F,"c001x - Households")+SUMIFS('T 03.01'!P:P,'T 03.01'!E:E,"r0161 - System (operator) and CCP liabilities < 7 days (BRRD art. 44/2/f)",'T 03.01'!$F:$F,"c001x - Households") -> 0 | E15: =+SUMIFS('T 06.01'!$O:$O,'T 06.01'!$E:$E,"r0161 - System (operator) and CCP liabilities < 7 days (BRRD art. 44/2/f)",'T 06.01'!$F:$F,"c002x - Micro & SME")+SUMIFS('T 03.01'!P:P,'T 03.01'!E:E,"r0161 - System (operator) and CCP liabilities < 7 days (BRRD art. 44/2/f)",'T 03.01'!$F:$F,"c002x - Micro & SME") -> 0 | F15: =+SUMIFS('T 06.01'!$O:$O,'T 06.01'!$E:$E,"r0161 - System (operator) and CCP liabilities < 7 days (BRRD art. 44/2/f)",'T 06.01'!$F:$F,"c003x - Corporates")+SUMIFS('T 03.01'!P:P,'T 03.01'!E:E,"r0161 - System (operator) and CCP liabilities < 7 days (BRRD art. 44/2/f)",'T 03.01'!$F:$F,"c003x - Corporates") -> 0 | G15: =+SUMIFS('T 06.01'!$O:$O,'T 06.01'!$E:$E,"r0161 - System (operator) and CCP liabilities < 7 days (BRRD art. 44/2/f)",'T 06.01'!$F:$F,"c004x - Institutions")+SUMIFS('T 03.01'!P:P,'T 03.01'!E:E,"r0161 - System (operator) and CCP liabilities < 7 days (BRRD art. 44/2/f)",'T 03.01'!$F:$F,"c004x - Institutions") -> 40810.25 | H15: =+SUMIFS('T 06.01'!$O:$O,'T 06.01'!$E:$E,"r0161 - System (operator) and CCP liabilities < 7 days (BRRD art. 44/2/f)",'T 06.01'!$F:$F,"c005x - Other financial corporations")+I15+SUMIFS('T 03.01'!P:P,'T 03.01'!E:E,"r0161 - System (operator) and CCP liabilities < 7 days (BRRD art. 44/2/f)",'T 03.01'!$F:$F,"c005x - Other financial corporations") -> 0 | I15: =+SUMIFS('T 06.01'!$O:$O,'T 06.01'!$E:$E,"r0161 - System (operator) and CCP liabilities < 7 days (BRRD art. 44/2/f)",'T 06.01'!$F:$F,"c006x - Insurance firms & pension funds")+SUMIFS('T 03.01'!P:P,'T 03.01'!E:E,"r0161 - System (operator) and CCP liabilities < 7 days (BRRD art. 44/2/f)",'T 03.01'!$F:$F,"c006x - Insurance firms & pension funds") -> 0 | J15: =+SUMIFS('T 06.01'!$O:$O,'T 06.01'!$E:$E,"r0161 - System (operator) and CCP liabilities < 7 days (BRRD art. 44/2/f)",'T 06.01'!$F:$F,"c008x - Government, central banks & supranationals")+SUMIFS('T 03.01'!P:P,'T 03.01'!E:E,"r0161 - System (operator) and CCP liabilities < 7 days (BRRD art. 44/2/f)",'T 03.01'!$F:$F,"c008x - Government, central banks & supranationals") -> 0 | K15: 0 | L15: =+SUMIFS('T 06.01'!$O:$O,'T 06.01'!$E:$E,"r0161 - System (operator) and CCP liabilities < 7 days (BRRD art. 44/2/f)",'T 06.01'!$F:$F,"")+SUMIFS('T 03.01'!P:P,'T 03.01'!E:E,"r0161 - System (operator) and CCP liabilities < 7 days (BRRD art. 44/2/f)",'T 03.01'!$F:$F,"") -> 0 | M15: =SUM(D15:L15)-I15 -> 40810.25 | N15: =+SUMIF('T 03.01'!E:E,"r0161 - System (operator) and CCP liabilities < 7 days (BRRD art. 44/2/f)",'T 03.01'!P:P) -> 0 | O15: 0
B16: Employee liabilities (BRRD art. 44/2/g/i) | C16: 0170 | D16: =+SUMIFS('T 09.00'!$M:$M,'T 09.00'!$E:$E,"r0170 - Employee liabilities (BRRD art. 44/2/g/i)",'T 09.00'!$F:$F,"c001x - Households")+SUMIFS('T 03.01'!P:P,'T 03.01'!E:E,"r0170 - Employee liabilities (BRRD art. 44/2/g/i)",'T 03.01'!$F:$F,"c001x - Households") -> 2.3292511e+08 | E16: =+SUMIFS('T 09.00'!$M:$M,'T 09.00'!$E:$E,"r0170 - Employee liabilities (BRRD art. 44/2/g/i)",'T 09.00'!$F:$F,"c002x - Micro & SME")+SUMIFS('T 03.01'!P:P,'T 03.01'!E:E,"r0170 - Employee liabilities (BRRD art. 44/2/g/i)",'T 03.01'!$F:$F,"c002x - Micro & SME") -> 0 | F16: =+SUMIFS('T 09.00'!$M:$M,'T 09.00'!$E:$E,"r0170 - Employee liabilities (BRRD art. 44/2/g/i)",'T 09.00'!$F:$F,"c003x - Corporates")+SUMIFS('T 03.01'!P:P,'T 03.01'!E:E,"r0170 - Employee liabilities (BRRD art. 44/2/g/i)",'T 03.01'!$F:$F,"c003x - Corporates") -> 0 | G16: =+SUMIFS('T 09.00'!$M:$M,'T 09.00'!$E:$E,"r0170 - Employee liabilities (BRRD art. 44/2/g/i)",'T 09.00'!$F:$F,"c004x - Institutions")+SUMIFS('T 03.01'!P:P,'T 03.01'!E:E,"r0170 - Employee liabilities (BRRD art. 44/2/g/i)",'T 03.01'!$F:$F,"c004x - Institutions") -> 0 | H16: =+SUMIFS('T 09.00'!$M:$M,'T 09.00'!$E:$E,"r0170 - Employee liabilities (BRRD art. 44/2/g/i)",'T 09.00'!$F:$F,"c005x - Other financial corporations")+I16+SUMIFS('T 03.01'!P:P,'T 03.01'!E:E,"r0170 - Employee liabilities (BRRD art. 44/2/g/i)",'T 03.01'!$F:$F,"c005x - Other financial corporations") -> 0 | I16: =+SUMIFS('T 09.00'!$M:$M,'T 09.00'!$E:$E,"r0170 - Employee liabilities (BRRD art. 44/2/g/i)",'T 09.00'!$F:$F,"c006x - Insurance firms & pension funds")+SUMIFS('T 03.01'!P:P,'T 03.01'!E:E,"r0170 - Employee liabilities (BRRD art. 44/2/g/i)",'T 03.01'!$F:$F,"c006x - Insurance firms & pension funds") -> 0 | J16: =+SUMIFS('T 09.00'!$M:$M,'T 09.00'!$E:$E,"r0170 - Employee liabilities (BRRD art. 44/2/g/i)",'T 09.00'!$F:$F,"c008x - Government, central banks & supranationals")+SUMIFS('T 03.01'!P:P,'T 03.01'!E:E,"r0170 - Employee liabilities (BRRD art. 44/2/g/i)",'T 03.01'!$F:$F,"c008x - Government, central banks & supranationals") -> 0 | K16: 0 | L16: =+SUMIFS('T 09.00'!$M:$M,'T 09.00'!$E:$E,"r0170 - Employee liabilities (BRRD art. 44/2/g/i)",'T 09.00'!$F:$F,"c010x - Non-identified, not listed on an exchange platform")+SUMIFS('T 03.01'!P:P,'T 03.01'!E:E,"r0170 - Employee liabilities (BRRD art. 44/2/g/i)",'T 03.01'!$F:$F,"") -> 0 | M16: =SUM(D16:L16)-I16 -> 2.3292511e+08 | N16: =+SUMIF('T 03.01'!E:E,"r0170 - Employee liabilities (BRRD art. 44/2/g/i)",'T 03.01'!P:P) -> 0 | O16: 0
B17: Critical service liabilities (BRRD art. 44/2/g/ii) | C17: 0180 | D17: =+SUMIFS('T 06.01'!$O:$O,'T 06.01'!$E:$E,"r0180 - Critical service liabilities (BRRD art. 44/2/g/ii)",'T 06.01'!$F:$F,"c001x - Households")+SUMIFS('T 03.01'!P:P,'T 03.01'!E:E,"r0180 - Critical service liabilities (BRRD art. 44/2/g/ii)",'T 03.01'!$F:$F,"c001x - Households") -> 4137337.4 | E17: =+SUMIFS('T 06.01'!$O:$O,'T 06.01'!$E:$E,"r0180 - Critical service liabilities (BRRD art. 44/2/g/ii)",'T 06.01'!$F:$F,"c002x - Micro & SME")+SUMIFS('T 03.01'!P:P,'T 03.01'!E:E,"r0180 - Critical service liabilities (BRRD art. 44/2/g/ii)",'T 03.01'!$F:$F,"c002x - Micro & SME") -> 0 | F17: =+SUMIFS('T 06.01'!$O:$O,'T 06.01'!$E:$E,"r0180 - Critical service liabilities (BRRD art. 44/2/g/ii)",'T 06.01'!$F:$F,"c003x - Corporates")+SUMIFS('T 03.01'!P:P,'T 03.01'!E:E,"r0180 - Critical service liabilities (BRRD art. 44/2/g/ii)",'T 03.01'!$F:$F,"c003x - Corporates") -> 0 | G17: =+SUMIFS('T 06.01'!$O:$O,'T 06.01'!$E:$E,"r0180 - Critical service liabilities (BRRD art. 44/2/g/ii)",'T 06.01'!$F:$F,"c004x - Institutions")+SUMIFS('T 03.01'!P:P,'T 03.01'!E:E,"r0180 - Critical service liabilities (BRRD art. 44/2/g/ii)",'T 03.01'!$F:$F,"c004x - Institutions") -> 0 | H17: =+SUMIFS('T 06.01'!$O:$O,'T 06.01'!$E:$E,"r0180 - Critical service liabilities (BRRD art. 44/2/g/ii)",'T 06.01'!$F:$F,"c005x - Other financial corporations")+I17+SUMIFS('T 03.01'!P:P,'T 03.01'!E:E,"r0180 - Critical service liabilities (BRRD art. 44/2/g/ii)",'T 03.01'!$F:$F,"c005x - Other financial corporations") -> 0 | I17: =+SUMIFS('T 06.01'!$O:$O,'T 06.01'!$E:$E,"r0180 - Critical service liabilities (BRRD art. 44/2/g/ii)",'T 06.01'!$F:$F,"c006x - Insurance firms & pension funds")+SUMIFS('T 03.01'!P:P,'T 03.01'!E:E,"r0180 - Critical service liabilities (BRRD art. 44/2/g/ii)",'T 03.01'!$F:$F,"c006x - Insurance firms & pension funds") -> 0 | J17: =+SUMIFS('T 06.01'!$O:$O,'T 06.01'!$E:$E,"r0180 - Critical service liabilities (BRRD art. 44/2/g/ii)",'T 06.01'!$F:$F,"c008x - Government, central banks & supranationals")+SUMIFS('T 03.01'!P:P,'T 03.01'!E:E,"r0180 - Critical service liabilities (BRRD art. 44/2/g/ii)",'T 03.01'!$F:$F,"c008x - Government, central banks & supranationals") -> 0 | K17: 0 | L17: =+SUMIFS('T 06.01'!$O:$O,'T 06.01'!$E:$E,"r0180 - Critical service liabilities (BRRD art. 44/2/g/ii)",'T 06.01'!$F:$F,"")+SUMIFS('T 03.01'!P:P,'T 03.01'!E:E,"r0180 - Critical service liabilities (BRRD art. 44/2/g/ii)",'T 03.01'!$F:$F,"") -> 0 | M17: =SUM(D17:L17)-I17 -> 4137337.4 | N17: =+SUMIF('T 03.01'!E:E,"r0180 - Critical service liabilities (BRRD art. 44/2/g/ii)",'T 03.01'!P:P) -> 0 | O17: 0
B18: Tax and social security authorities liabilities, if preferred (BRRD art. 44/2/g/iii) | C18: 0190 | D18: =+SUMIFS('T 06.01'!$O:$O,'T 06.01'!$E:$E,"r0190 - Tax and social security authorities liabilities, if preferred (BRRD art. 44/2/g/iii)",'T 06.01'!$F:$F,"c001x - Households")+SUMIFS('T 03.01'!P:P,'T 03.01'!E:E,"r0190 - Tax and social security authorities liabilities, if preferred (BRRD art. 44/2/g/iii)",'T 03.01'!$F:$F,"c001x - Households") -> 0 | E18: =+SUMIFS('T 06.01'!$O:$O,'T 06.01'!$E:$E,"r0190 - Tax and social security authorities liabilities, if preferred (BRRD art. 44/2/g/iii)",'T 06.01'!$F:$F,"c002x - Micro & SME")+SUMIFS('T 03.01'!P:P,'T 03.01'!E:E,"r0190 - Tax and social security authorities liabilities, if preferred (BRRD art. 44/2/g/iii)",'T 03.01'!$F:$F,"c002x - Micro & SME") -> 0 | F18: =+SUMIFS('T 06.01'!$O:$O,'T 06.01'!$E:$E,"r0190 - Tax and social security authorities liabilities, if preferred (BRRD art. 44/2/g/iii)",'T 06.01'!$F:$F,"c003x - Corporates")+SUMIFS('T 03.01'!P:P,'T 03.01'!E:E,"r0190 - Tax and social security authorities liabilities, if preferred (BRRD art. 44/2/g/iii)",'T 03.01'!$F:$F,"c003x - Corporates") -> 0 | G18: =+SUMIFS('T 06.01'!$O:$O,'T 06.01'!$E:$E,"r0190 - Tax and social security authorities liabilities, if preferred (BRRD art. 44/2/g/iii)",'T 06.01'!$F:$F,"c004x - Institutions")+SUMIFS('T 03.01'!P:P,'T 03.01'!E:E,"r0190 - Tax and social security authorities liabilities, if preferred (BRRD art. 44/2/g/iii)",'T 03.01'!$F:$F,"c004x - Institutions") -> 0 | H18: =+SUMIFS('T 06.01'!$O:$O,'T 06.01'!$E:$E,"r0190 - Tax and social security authorities liabilities, if preferred (BRRD art. 44/2/g/iii)",'T 06.01'!$F:$F,"c005x - Other financial corporations")+I18+SUMIFS('T 03.01'!P:P,'T 03.01'!E:E,"r0190 - Tax and social security authorities liabilities, if preferred (BRRD art. 44/2/g/iii)",'T 03.01'!$F:$F,"c005x - Other financial corporations") -> 0 | I18: =+SUMIFS('T 06.01'!$O:$O,'T 06.01'!$E:$E,"r0190 - Tax and social security authorities liabilities, if preferred (BRRD art. 44/2/g/iii)",'T 06.01'!$F:$F,"c006x - Insurance firms & pension funds")+SUMIFS('T 03.01'!P:P,'T 03.01'!E:E,"r0190 - Tax and social security authorities liabilities, if preferred (BRRD art. 44/2/g/iii)",'T 03.01'!$F:$F,"c006x - Insurance firms & pension funds") -> 0 | J18: =+SUMIFS('T 06.01'!$O:$O,'T 06.01'!$E:$E,"r0190 - Tax and social security authorities liabilities, if preferred (BRRD art. 44/2/g/iii)",'T 06.01'!$F:$F,"c008x - Government, central banks & supranationals")+SUMIFS('T 03.01'!P:P,'T 03.01'!E:E,"r0190 - Tax and social security authorities liabilities, if preferred (BRRD art. 44/2/g/iii)",'T 03.01'!$F:$F,"c008x - Government, central banks & supranationals") -> 3.5330907e+08 | K18: 0 | L18: =+SUMIFS('T 06.01'!$O:$O,'T 06.01'!$E:$E,"r0190 - Tax and social security authorities liabilities, if preferred (BRRD art. 44/2/g/iii)",'T 06.01'!$F:$F,"")+SUMIFS('T 03.01'!P:P,'T 03.01'!E:E,"r0190 - Tax and social security authorities liabilities, if preferred (BRRD art. 44/2/g/iii)",'T 03.01'!$F:$F,"") -> 0 | M18: =SUM(D18:L18)-I18 -> 3.5330907e+08 | N18: =+SUMIF('T 03.01'!E:E,"r0190 - Tax and social security authorities liabilities, if preferred (BRRD art. 44/2/g/iii)",'T 03.01'!P:P) -> 0 | O18: 0
B19: DGS liabilities (BRRD art. 44/2/g/iv) | C19: 0200 | D19: 0 | E19: 0 | F19: 0 | G19: 0 | H19: 0 | I19: 0 | J19: 0 | K19: 0 | L19: 0 | M19: =SUM(D19:L19)-I19 -> 0 | N19: 0 | O19: 0
B20: Liabilities towards other entities of the resolution group (BRRD art. 44/2/h) | C20: 0210 | D20: 0 | E20: 0 | F20: 0 | G20: =SUMIFS('T 03.01'!P:P,'T 03.01'!E:E,"r0210 - Liabilities towards other entities of the resolution group (BRRD art. 44/2/h)",'T 03.01'!$F:$F,"c004x - Institutions") -> 855362.17 | H20: =I20+SUMIFS('T 03.01'!P:P,'T 03.01'!E:E,"r0210 - Liabilities towards other entities of the resolution group (BRRD art. 44/2/h)",'T 03.01'!$F:$F,"c005x - Other financial corporations") -> 9.0199753e+08 | I20: =SUMIFS('T 03.01'!P:P,'T 03.01'!E:E,"r0210 - Liabilities towards other entities of the resolution group (BRRD art. 44/2/h)",'T 03.01'!$F:$F,"c006x - Insurance firms & pension funds") -> 3.0305582e+08 | J20: 0 | K20: 0 | L20: 0 | M20: =SUM(D20:L20)-I20 -> 9.0285289e+08 | N20: =+SUMIF('T 03.01'!E:E,"r0210 - Liabilities towards other entities of the resolution group (BRRD art. 44/2/h)",'T 03.01'!P:P) -> 9.0285289e+08 | O20: 0
B21: Liabilities not excluded from bail-in | C21: 0300 | D21: =+D22+D27+D32+D37+D42+D47+D57+D62+D65+D66 -> 5.3969556e+09 | E21: =+E22+E27+E32+E37+E42+E47+E57+E62+E65+E66 -> 4.8401961e+09 | F21: =+F22+F27+F32+F37+F42+F47+F57+F62+F65+F66 -> 4.3864769e+09 | G21: =+G22+G27+G32+G37+G42+G47+G57+G62+G65+G66 -> 1.0528835e+09 | H21: =+H22+H27+H32+H37+H42+H47+H57+H62+H65+H66 -> 1.5737242e+09 | I21: =+I22+I27+I32+I37+I42+I47+I57+I62+I65+I66 -> 1.1153964e+09 | J21: =+J22+J27+J32+J37+J42+J47+J57+J62+J65+J66 -> 9.0433897e+08 | K21: =+K22+K27+K32+K37+K42+K47+K57+K62+K65+K66 -> 0 | L21: =+L22+L27+L32+L37+L42+L47+L57+L62+L65+L66 -> 3.1330474e+08 | M21: =SUM(D21:L21)-I21 -> 1.846788e+10 | N21: =+N22+N27+N32+N37+N42+N47+N57+N62+N65+N66 -> 8.8703414e+08 | O21: 0
B22: Deposits, not covered but preferential (BRRD art. 108) | C22: 0310 | D22: =SUM(D23:D26) -> 5.3324587e+09 | E22: =SUM(E23:E26) -> 4.8008204e+09 | F22: =SUM(F23:F26) -> 0 | G22: =SUM(G23:G26) -> 0 | H22: =SUM(H23:H26) -> 0 | I22: =SUM(I23:I26) -> 0 | J22: =SUM(J23:J26) -> 0 | K22: =SUM(K23:K26) -> 0 | L22: =SUM(L23:L26) -> 0 | M22: =SUM(D22:L22)-I23 -> 1.0133279e+10 | N22: =SUM(N23:N26) -> 0 | O22: 0
B23: o/w residual maturity <= 1 month | C23: 0311 | D23: =+SUMIFS('T 05.01'!$M:$M,'T 05.01'!$E:$E,"r0310 - Deposits, not covered but preferential (BRRD art. 108)",'T 05.01'!$F:$F,"c001x - Households")+SUMIFS('T 03.01'!P:P,'T 03.01'!E:E,"r0310 - Deposits, not covered but preferential (BRRD art. 108)",'T 03.01'!$F:$F,"c001x - Households") -> 5.3324587e+09 | E23: =+SUMIFS('T 05.01'!$M:$M,'T 05.01'!$E:$E,"r0310 - Deposits, not covered but preferential (BRRD art. 108)",'T 05.01'!$F:$F,"c002x - Micro & SME")+SUMIFS('T 03.01'!P:P,'T 03.01'!E:E,"r0310 - Deposits, not covered but preferential (BRRD art. 108)",'T 03.01'!$F:$F,"c002x - Micro & SME") -> 4.8008204e+09 | F23: =+SUMIFS('T 05.01'!$M:$M,'T 05.01'!$E:$E,"r0310 - Deposits, not covered but preferential (BRRD art. 108)",'T 05.01'!$F:$F,"c003x - Corporates")+SUMIFS('T 03.01'!P:P,'T 03.01'!E:E,"r0310 - Deposits, not covered but preferential (BRRD art. 108)",'T 03.01'!$F:$F,"c003x - Corporates") -> 0 | G23: =+SUMIFS('T 05.01'!$M:$M,'T 05.01'!$E:$E,"r0310 - Deposits, not covered but preferential (BRRD art. 108)",'T 05.01'!$F:$F,"c004x - Institutions")+SUMIFS('T 03.01'!P:P,'T 03.01'!E:E,"r0310 - Deposits, not covered but preferential (BRRD art. 108)",'T 03.01'!$F:$F,"c004x - Institutions") -> 0 | H23: =+SUMIFS('T 05.01'!$M:$M,'T 05.01'!$E:$E,"r0310 - Deposits, not covered but preferential (BRRD art. 108)",'T 05.01'!$F:$F,"c005x - Other financial corporations")+I23+SUMIFS('T 03.01'!P:P,'T 03.01'!E:E,"r0310 - Deposits, not covered but preferential (BRRD art. 108)",'T 03.01'!$F:$F,"c005x - Other financial corporations") -> 0 | I23: =+SUMIFS('T 05.01'!$M:$M,'T 05.01'!$E:$E,"r0310 - Deposits, not covered but preferential (BRRD art. 108)",'T 05.01'!$F:$F,"c006x - Insurance firms & pension funds")+SUMIFS('T 03.01'!P:P,'T 03.01'!E:E,"r0310 - Deposits, not covered but preferential (BRRD art. 108)",'T 03.01'!$F:$F,"c006x - Insurance firms & pension funds") -> 0 | J23: =+SUMIFS('T 05.01'!$M:$M,'T 05.01'!$E:$E,"r0310 - Deposits, not covered but preferential (BRRD art. 108)",'T 05.01'!$F:$F,"c008x - Government, central banks & supranationals")+SUMIFS('T 03.01'!P:P,'T 03.01'!E:E,"r0310 - Deposits, not covered but preferential (BRRD art. 108)",'T 03.01'!$F:$F,"c008x - Government, central banks & supranationals") -> 0 | K23: 0 | L23: =+SUMIFS('T 05.01'!$M:$M,'T 05.01'!$E:$E,"r0310 - Deposits, not covered but preferential (BRRD art. 108)",'T 05.01'!$F:$F,"")+SUMIFS('T 03.01'!P:P,'T 03.01'!E:E,"r0310 - Deposits, not covered but preferential (BRRD art. 108)",'T 03.01'!$F:$F,"") -> 0 | M23: =SUM(D23:L23)-I24 -> 1.0133279e+10 | N23: =+SUMIF('T 03.01'!E:E,"r0310 - Deposits, not covered but preferential (BRRD art. 108)",'T 03.01'!P:P) -> 0 | O23: 0
B24: o/w residual maturity > 1 month < 1 year | C24: 0312 | D24: 0 | E24: 0 | F24: 0 | G24: 0 | H24: 0 | I24: 0 | J24: 0 | K24: 0 | L24: 0 | M24: =SUM(D24:L24)-I24 -> 0 | N24: 0 | O24: 0
B25: o/w residual maturity >= 1 year and < 2 years | C25: 0313 | D25: 0 | E25: 0 | F25: 0 | G25: 0 | H25: 0 | I25: 0 | J25: 0 | K25: 0 | L25: 0 | M25: =SUM(D25:L25)-I25 -> 0 | N25: 0 | O25: 0
B26: o/w residual maturity >= 2 years | C26: 0314 | D26: 0 | E26: 0 | F26: 0 | G26: 0 | H26: 0 | I26: 0 | J26: 0 | K26: 0 | L26: 0 | M26: =SUM(D26:L26)-I26 -> 0 | N26: 0 | O26: 0
B27: Deposits, not covered and not preferential | C27: 0320 | D27: =SUM(D28:D31) -> 0 | E27: =SUM(E28:E31) -> 1834.98 | F27: =SUM(F28:F31) -> 4.3159708e+09 | G27: =SUM(G28:G31) -> 2.3697488e+08 | H27: =SUM(H28:H31) -> 1.2438125e+09 | I27: =SUM(I28:I31) -> 1.1108616e+09 | J27: =SUM(J28:J31) -> 8.8308299e+08 | K27: =SUM(K28:K31) -> 0 | L27: =SUM(L28:L31) -> 0 | M27: =SUM(D27:L27)-I27 -> 6.6798429e+09 | N27: =+SUMIF('T 03.01'!E:E,"r0320 - Deposits, not covered and not preferential",'T 03.01'!P:P)+SUMIF('T 03.01'!E:E,"r0320 - Deposits, not covered and not preferential",'T 03.01'!Q:Q) -> 1.8819345e+08 | O27: 0
B28: o/w residual maturity <= 1 month | C28: 0321 | D28: =+SUMIFS('T 05.01'!$M:$M,'T 05.01'!$E:$E,"r0320 - Deposits, not covered and not preferential",'T 05.01'!$F:$F,"c001x - Households")+SUMIFS('T 03.01'!P:P,'T 03.01'!E:E,"r0320 - Deposits, not covered and not preferential",'T 03.01'!$F:$F,"c001x - Households") -> 0 | E28: =+SUMIFS('T 05.01'!$M:$M,'T 05.01'!$E:$E,"r0320 - Deposits, not covered and not preferential",'T 05.01'!$F:$F,"c002x - Micro & SME")+SUMIFS('T 03.01'!P:P,'T 03.01'!E:E,"r0320 - Deposits, not covered and not preferential",'T 03.01'!$F:$F,"c002x - Micro & SME") -> 1834.98 | F28: =+SUMIFS('T 05.01'!$M:$M,'T 05.01'!$E:$E,"r0320 - Deposits, not covered and not preferential",'T 05.01'!$F:$F,"c003x - Corporates")+SUMIFS('T 03.01'!P:P,'T 03.01'!E:E,"r0320 - Deposits, not covered and not preferential",'T 03.01'!$F:$F,"c003x - Corporates") -> 4.3159708e+09 | G28: =+SUMIFS('T 05.01'!$M:$M,'T 05.01'!$E:$E,"r0320 - Deposits, not covered and not preferential",'T 05.01'!$F:$F,"c004x - Institutions")+SUMIFS('T 03.01'!P:P,'T 03.01'!E:E,"r0320 - Deposits, not covered and not preferential",'T 03.01'!$F:$F,"c004x - Institutions") -> 2.3697488e+08 | H28: =+SUMIFS('T 05.01'!$M:$M,'T 05.01'!$E:$E,"r0320 - Deposits, not covered and not preferential",'T 05.01'!$F:$F,"c005x - Other financial corporations")+I28+SUMIFS('T 03.01'!P:P,'T 03.01'!E:E,"r0320 - Deposits, not covered and not preferential",'T 03.01'!$F:$F,"c005x - Other financial corporations") -> 1.2438125e+09 | I28: =+SUMIFS('T 05.01'!$M:$M,'T 05.01'!$E:$E,"r0320 - Deposits, not covered and not preferential",'T 05.01'!$F:$F,"c006x - Insurance firms & pension funds")+SUMIFS('T 03.01'!P:P,'T 03.01'!E:E,"r0320 - Deposits, not covered and not preferential",'T 03.01'!$F:$F,"c006x - Insurance firms & pension funds") -> 1.1108616e+09 | J28: =+SUMIFS('T 05.01'!$M:$M,'T 05.01'!$E:$E,"r0320 - Deposits, not covered and not preferential",'T 05.01'!$F:$F,"c008x - Government, central banks & supranationals")+SUMIFS('T 03.01'!P:P,'T 03.01'!E:E,"r0320 - Deposits, not covered and not preferential",'T 03.01'!$F:$F,"c008x - Government, central banks & supranationals") -> 8.8308299e+08 | K28: 0 | L28: =+SUMIFS('T 05.01'!$M:$M,'T 05.01'!$E:$E,"r0320 - Deposits, not covered and not preferential",'T 05.01'!$F:$F,"")+SUMIFS('T 03.01'!P:P,'T 03.01'!E:E,"r0320 - Deposits, not covered and not preferential",'T 03.01'!$F:$F,"") -> 0 | M28: =SUM(D28:L28)-I28 -> 6.6798429e+09 | N28: =+SUMIF('T 03.01'!E:E,"r0320 - Deposits, not covered and not preferential",'T 03.01'!P:P) -> 1.9482184e+08 | O28: 0
B29: o/w residual maturity > 1 month < 1 year | C29: 0322 | D29: 0 | E29: 0 | F29: 0 | G29: 0 | H29: 0 | I29: 0 | J29: 0 | K29: 0 | L29: 0 | M29: =SUM(D29:L29)-I29 -> 0 | N29: 0 | O29: 0
B30: o/w residual maturity >= 1 year and < 2 years | C30: 0323 | D30: 0 | E30: 0 | F30: 0 | G30: 0 | H30: 0 | I30: 0 | J30: 0 | K30: 0 | L30: 0 | M30: =SUM(D30:L30)-I30 -> 0 | N30: 0 | O30: 0
B31: o/w residual maturity >= 2 years | C31: 0324 | D31: 0 | E31: 0 | F31: 0 | G31: 0 | H31: 0 | I31: 0 | J31: 0 | K31: 0 | L31: 0 | M31: =SUM(D31:L31)-I31 -> 0 | N31: 0 | O31: 0
B32: Balance sheet liabilities arising from derivatives | C32: 0330 | D32: =SUMIF('T 07.00'!$E:$E,"c001x - Households",'T 07.00'!$R:$R) -> 0 | E32: =SUMIF('T 07.00'!$E:$E,"c002x - Micro & SME",'T 07.00'!$R:$R) -> 146937.32 | F32: =SUMIF('T 07.00'!$E:$E,"c003x - Corporates",'T 07.00'!$R:$R) -> 5065106.2 | G32: =SUMIF('T 07.00'!$E:$E,"c004x - Institutions",'T 07.00'!$R:$R) -> 6.1245005e+08 | H32: =SUMIF('T 07.00'!$E:$E,"c005x - Other financial corporations",'T 07.00'!$R:$R)+I32 -> 2.8177616e+08 | I32: =SUMIF('T 07.00'!$E:$E,"c006x - Insurance firms & pension funds",'T 07.00'!$R:$R) -> 0 | J32: =SUMIF('T 07.00'!$E:$E,"c008x - Government, central banks & supranationals",'T 07.00'!$R:$R) -> 0 | K32: 0 | L32: =SUMIF('T 07.00'!$E:$E,"",'T 07.00'!$R:$R) -> 0 | M32: =SUM(D32:L32)-I32 -> 8.9943825e+08 | N32: =SUMIF('T 07.00'!$O:$O,"TRUE",'T 07.00'!$R:$R) -> 6.406435e+08 | O32: 0
B33: Sum of net liability positions taking into account contractual netting sets, after mark-to-market adjustments, prior to collateral offset | C33: 0331 | D33: =SUMIF('T 07.00'!$E:$E,"c001x - Households",'T 07.00'!$R:$R) -> 0 | E33: =SUMIF('T 07.00'!$E:$E,"c002x - Micro & SME",'T 07.00'!$R:$R) -> 146937.32 | F33: =SUMIF('T 07.00'!$E:$E,"c003x - Corporates",'T 07.00'!$R:$R) -> 5065106.2 | G33: =SUMIF('T 07.00'!$E:$E,"c004x - Institutions",'T 07.00'!$R:$R) -> 6.1245005e+08 | H33: =SUMIF('T 07.00'!$E:$E,"c005x - Other financial corporations",'T 07.00'!$R:$R)+I33 -> 2.8177616e+08 | I33: =SUMIF('T 07.00'!$E:$E,"c006x - Insurance firms & pension funds",'T 07.00'!$R:$R) -> 0 | J33: =SUMIF('T 07.00'!$E:$E,"c008x - Government, central banks & supranationals",'T 07.00'!$R:$R) -> 0 | K33: 0 | L33: =SUMIF('T 07.00'!$E:$E,"",'T 07.00'!$R:$R) -> 0 | M33: =SUM(D33:L33)-I33 -> 8.9943825e+08 | N33: =SUMIF('T 07.00'!O:O,"TRUE",'T 07.00'!$R:$R) -> 6.406435e+08 | O33: 0
B34: Sum of net liability positions taking into account contractual netting sets, after mark-to-market adjustments, post collateral offset | C34: 0332 | D34: =SUMIF('T 07.00'!$E:$E,"c001x - Households",'T 07.00'!$R:$R) -> 0 | E34: =SUMIF('T 07.00'!$E:$E,"c002x - Micro & SME",'T 07.00'!$R:$R) -> 146937.32 | F34: =SUMIF('T 07.00'!$E:$E,"c003x - Corporates",'T 07.00'!$R:$R) -> 5065106.2 | G34: =SUMIF('T 07.00'!$E:$E,"c004x - Institutions",'T 07.00'!$R:$R) -> 6.1245005e+08 | H34: =SUMIF('T 07.00'!$E:$E,"c005x - Other financial corporations",'T 07.00'!$R:$R)+I34 -> 2.8177616e+08 | I34: =SUMIF('T 07.00'!$E:$E,"c006x - Insurance firms & pension funds",'T 07.00'!$R:$R) -> 0 | J34: =SUMIF('T 07.00'!$E:$E,"c008x - Government, central banks & supranationals",'T 07.00'!$R:$R) -> 0 | K34: 0 | L34: =SUMIF('T 07.00'!$E:$E,"",'T 07.00'!$R:$R) -> 0 | M34: =SUM(D34:L34)-I34 -> 8.9943825e+08 | N34: =SUMIF('T 07.00'!O:O,"TRUE",'T 07.00'!$R:$R) -> 6.406435e+08 | O34: 0
B35: Sum of net liability positions taking into account contractual netting sets, after mark-to-market adjustments, post collateral offset, incorporating estimated close-out amounts | C35: 0333 | D35: =SUMIF('T 07.00'!$E:$E,"c001x - Households",'T 07.00'!$R:$R) -> 0 | E35: =SUMIF('T 07.00'!$E:$E,"c002x - Micro & SME",'T 07.00'!$R:$R) -> 146937.32 | F35: =SUMIF('T 07.00'!$E:$E,"c003x - Corporates",'T 07.00'!$R:$R) -> 5065106.2 | G35: =SUMIF('T 07.00'!$E:$E,"c004x - Institutions",'T 07.00'!$R:$R) -> 6.1245005e+08 | H35: =SUMIF('T 07.00'!$E:$E,"c005x - Other financial corporations",'T 07.00'!$R:$R)+I35 -> 2.8177616e+08 | I35: =SUMIF('T 07.00'!$E:$E,"c006x - Insurance firms & pension funds",'T 07.00'!$R:$R) -> 0 | J35: =SUMIF('T 07.00'!$E:$E,"c008x - Government, central banks & supranationals",'T 07.00'!$R:$R) -> 0 | K35: 0 | L35: =SUMIF('T 07.00'!$E:$E,"",'T 07.00'!$R:$R) -> 0 | M35: =SUM(D35:L35)-I35 -> 8.9943825e+08 | N35: =SUMIF('T 07.00'!O:O,"TRUE",'T 07.00'!$R:$R) -> 6.406435e+08 | O35: 0
B36: Sum of net liability positions taking into account prudential netting rules | C36: 0334 | D36: =SUMIF('T 07.00'!$E:$E,"c001x - Households",'T 07.00'!$U:$U) -> 0 | E36: =SUMIF('T 07.00'!$E:$E,"c002x - Micro & SME",'T 07.00'!$U:$U) -> 146937.32 | F36: =SUMIF('T 07.00'!$E:$E,"c003x - Corporates",'T 07.00'!$U:$U) -> 5065106.3 | G36: =SUMIF('T 07.00'!$E:$E,"c004x - Institutions",'T 07.00'!$U:$U) -> 1.7284551e+08 | H36: =SUMIF('T 07.00'!$E:$E,"c005x - Other financial corporations",'T 07.00'!$U:$U)+I36 -> 36658488 | I36: =SUMIF('T 07.00'!$E:$E,"c006x - Insurance firms & pension funds",'T 07.00'!$U:$U) -> 0 | J36: =SUMIF('T 07.00'!$E:$E,"c008x - Government, central banks & supranationals",'T 07.00'!$U:$U) -> 0 | K36: 0 | L36: =SUMIF('T 07.00'!$E:$E,"",'T 07.00'!$U:$U) -> 0 | M36: =SUM(D36:L36)-I36 -> 2.1471605e+08 | N36: =SUMIF('T 07.00'!O:O,"TRUE",'T 07.00'!$U:$U) -> 2.0161074e+08 | O36: 0
B37: Uncollateralized secured liabilities | C37: 0340 | D37: 0 | E37: 0 | F37: 0 | G37: 0 | H37: 0 | I37: 0 | J37: 0 | K37: 0 | L37: 0 | M37: =SUM(D37:L37)-I37 -> 0 | N37: 0 | O37: 0
B38: o/w residual maturity <= 1 month | C38: 0341 | D38: 0 | E38: 0 | F38: 0 | G38: 0 | H38: 0 | I38: 0 | J38: 0 | K38: 0 | L38: 0 | M38: =SUM(D38:L38)-I38 -> 0 | N38: 0 | O38: 0
B39: o/w residual maturity > 1 month < 1 year | C39: 0342 | D39: 0 | E39: 0 | F39: 0 | G39: 0 | H39: 0 | I39: 0 | J39: 0 | K39: 0 | L39: 0 | M39: =SUM(D39:L39)-I39 -> 0 | N39: 0 | O39: 0
B40: o/w residual maturity >= 1 year and < 2 years | C40: 0343 | D40: 0 | E40: 0 | F40: 0 | G40: 0 | H40: 0 | I40: 0 | J40: 0 | K40: 0 | L40: 0 | M40: =SUM(D40:L40)-I40 -> 0 | N40: 0 | O40: 0
B41: o/w residual maturity >= 2 years | C41: 0344 | D41: 0 | E41: 0 | F41: 0 | G41: 0 | H41: 0 | I41: 0 | J41: 0 | K41: 0 | L41: 0 | M41: =SUM(D41:L41)-I41 -> 0 | N41: 0 | O41: 0
B42: Structured notes | C42: 0350 | D42: =SUM(D43:D46) -> 0 | E42: =SUM(E43:E46) -> 0 | F42: =SUM(F43:F46) -> 0 | G42: =SUM(G43:G46) -> 182884000 | H42: =SUM(H43:H46) -> 0 | I42: =SUM(I43:I46) -> 0 | J42: =SUM(J43:J46) -> 0 | K42: =SUM(K43:K46) -> 0 | L42: =SUM(L43:L46) -> 0 | M42: =SUM(D42:L42)-I42 -> 182884000 | N42: =SUM(N43:N46) -> 8209741.6 | O42: =SUM(O43:O46) -> 0
...

Sheet T 01.00 b
A1: T 01.00.b - Liability structure - carrying amount
D4: Columns
D5: Households | E5: Micro & SME | F5: Corporates | G5: Institutions | H5: Other financial corporations | J5: Government, central banks & supranationals | K5: Instruments listed on exchange platforms | L5: Others/non-identified | M5: Total
D6: Carrying amount | E6: Carrying amount | F6: Carrying amount | G6: Carrying amount | H6: Carrying amount | I6: Of which Insurance firms & pension funds | J6: Carrying amount | K6: Carrying amount | L6: Carrying amount | M6: Carrying amount | N6: Of which: intragroup | O6: Of which: issuances under non-EU MS jurisdiction/law, excluding intragroup
I7: Carrying amount | N7: Carrying amount | O7: Carrying amount
D8: 0011 | E8: 0021 | F8: 0031 | G8: 0041 | H8: 0051 | I8: 0061 | J8: 0081 | K8: 0091 | L8: 0101 | M8: 0121 | N8: 0131 | O8: 0141
A9: Rows | B9: Liabilities excluded from bail-in | C9: 0100 | D9: =D10+D11+D12+D13+D14+D15+D16+D17+D18+D19+D20 -> 1.9384943e+10 | E9: =E10+E11+E12+E13+E14+E15+E16+E17+E18+E19+E20 -> 2.3350551e+09 | F9: =F10+F11+F12+F13+F14+F15+F16+F17+F18+F19+F20 -> 3.8825771e+08 | G9: =G10+G11+G12+G13+G14+G15+G16+G17+G18+G19+G20 -> 2.1365971e+09 | H9: =H10+H11+H12+H13+H14+H15+H16+H17+H18+H19+H20 -> 3.9267518e+09 | I9: =I10+I11+I12+I13+I14+I15+I16+I17+I18+I19+I20 -> 3.0369526e+08 | J9: =J10+J11+J12+J13+J14+J15+J16+J17+J18+J19+J20 -> 7.7635511e+09 | K9: =K10+K11+K12+K13+K14+K15+K16+K17+K18+K19+K20 -> 0 | L9: =L10+L11+L12+L13+L14+L15+L16+L17+L18+L19+L20 -> 0 | M9: =SUM(D9:L9)-I9 -> 3.5935156e+10 | N9: =N10+N11+N12+N13+N14+N15+N16+N17+N18+N19+N20 -> 3.9283394e+09 | O9: 0
B10: Covered deposits (BRRD art. 44/2/a) | C10: 0110 | D10: =+SUMIFS('T 05.01'!$M:$M,'T 05.01'!$E:$E,"r0110 - Covered deposits (BRRD art. 44/2/a)",'T 05.01'!$F:$F,"c001x - Households")+SUMIFS('T 05.01'!$N:$N,'T 05.01'!$E:$E,"r0110 - Covered deposits (BRRD art. 44/2/a)",'T 05.01'!$F:$F,"c001x - Households")+SUMIFS('T 03.01'!P:P,'T 03.01'!E:E,"r0110 - Covered deposits (BRRD art. 44/2/a)",'T 03.01'!$F:$F,"c001x - Households")+SUMIFS('T 03.01'!Q:Q,'T 03.01'!E:E,"r0110 - Covered deposits (BRRD art. 44/2/a)",'T 03.01'!$F:$F,"c001x - Households") -> 1.914788e+10 | E10: =+SUMIFS('T 05.01'!$M:$M,'T 05.01'!$E:$E,"r0110 - Covered deposits (BRRD art. 44/2/a)",'T 05.01'!$F:$F,"c002x - Micro & SME")+SUMIFS('T 05.01'!$N:$N,'T 05.01'!$E:$E,"r0110 - Covered deposits (BRRD art. 44/2/a)",'T 05.01'!$F:$F,"c002x - Micro & SME")+SUMIFS('T 03.01'!P:P,'T 03.01'!E:E,"r0110 - Covered deposits (BRRD art. 44/2/a)",'T 03.01'!$F:$F,"c002x - Micro & SME")+SUMIFS('T 03.01'!Q:Q,'T 03.01'!E:E,"r0110 - Covered deposits (BRRD art. 44/2/a)",'T 03.01'!$F:$F,"c002x - Micro & SME") -> 2.3350551e+09 | F10: =+SUMIFS('T 05.01'!$M:$M,'T 05.01'!$E:$E,"r0110 - Covered deposits (BRRD art. 44/2/a)",'T 05.01'!$F:$F,"c003x - Corporates")+SUMIFS('T 05.01'!$N:$N,'T 05.01'!$E:$E,"r0110 - Covered deposits (BRRD art. 44/2/a)",'T 05.01'!$F:$F,"c003x - Corporates")+SUMIFS('T 03.01'!P:P,'T 03.01'!E:E,"r0110 - Covered deposits (BRRD art. 44/2/a)",'T 03.01'!$F:$F,"c003x - Corporates")+SUMIFS('T 03.01'!Q:Q,'T 03.01'!E:E,"r0110 - Covered deposits (BRRD art. 44/2/a)",'T 03.01'!$F:$F,"c003x - Corporates") -> 3.8825771e+08 | G10: =+SUMIFS('T 05.01'!$M:$M,'T 05.01'!$E:$E,"r0110 - Covered deposits (BRRD art. 44/2/a)",'T 05.01'!$F:$F,"c004x - Institutions")+SUMIFS('T 05.01'!$N:$N,'T 05.01'!$E:$E,"r0110 - Covered deposits (BRRD art. 44/2/a)",'T 05.01'!$F:$F,"c004x - Institutions")+SUMIFS('T 03.01'!P:P,'T 03.01'!E:E,"r0110 - Covered deposits (BRRD art. 44/2/a)",'T 03.01'!$F:$F,"c004x - Institutions")+SUMIFS('T 03.01'!Q:Q,'T 03.01'!E:E,"r0110 - Covered deposits (BRRD art. 44/2/a)",'T 03.01'!$F:$F,"c004x - Institutions") -> 0 | H10: =+SUMIFS('T 05.01'!$M:$M,'T 05.01'!$E:$E,"r0110 - Covered deposits (BRRD art. 44/2/a)",'T 05.01'!$F:$F,"c005x - Other financial corporations")+SUMIFS('T 05.01'!$N:$N,'T 05.01'!$E:$E,"r0110 - Covered deposits (BRRD art. 44/2/a)",'T 05.01'!$F:$F,"c005x - Other financial corporations")+I10+SUMIFS('T 03.01'!P:P,'T 03.01'!E:E,"r0110 - Covered deposits (BRRD art. 44/2/a)",'T 03.01'!$F:$F,"c005x - Other financial corporations")+SUMIFS('T 03.01'!Q:Q,'T 03.01'!E:E,"r0110 - Covered deposits (BRRD art. 44/2/a)",'T 03.01'!$F:$F,"c005x - Other financial corporations") -> 0 | I10: =+SUMIFS('T 05.01'!$M:$M,'T 05.01'!$E:$E,"r0110 - Covered deposits (BRRD art. 44/2/a)",'T 05.01'!$F:$F,"c006x - Insurance firms & pension funds")+SUMIFS('T 05.01'!$N:$N,'T 05.01'!$E:$E,"r0110 - Covered deposits (BRRD art. 44/2/a)",'T 05.01'!$F:$F,"c006x - Insurance firms & pension funds")+SUMIFS('T 03.01'!P:P,'T 03.01'!E:E,"r0110 - Covered deposits (BRRD art. 44/2/a)",'T 03.01'!$F:$F,"c006x - Insurance firms & pension funds")+SUMIFS('T 03.01'!Q:Q,'T 03.01'!E:E,"r0110 - Covered deposits (BRRD art. 44/2/a)",'T 03.01'!$F:$F,"c006x - Insurance firms & pension funds") -> 0 | J10: =+SUMIFS('T 05.01'!$M:$M,'T 05.01'!$E:$E,"r0110 - Covered deposits (BRRD art. 44/2/a)",'T 05.01'!$F:$F,"c008x - Government, central banks & supranationals")+SUMIFS('T 05.01'!$N:$N,'T 05.01'!$E:$E,"r0110 - Covered deposits (BRRD art. 44/2/a)",'T 05.01'!$F:$F,"c008x - Government, central banks & supranationals")+SUMIFS('T 03.01'!P:P,'T 03.01'!E:E,"r0110 - Covered deposits (BRRD art. 44/2/a)",'T 03.01'!$F:$F,"c008x - Government, central banks & supranationals")+SUMIFS('T 03.01'!Q:Q,'T 03.01'!E:E,"r0110 - Covered deposits (BRRD art. 44/2/a)",'T 03.01'!$F:$F,"c008x - Government, central banks & supranationals") -> 0 | K10: 0 | L10: =+SUMIFS('T 05.01'!$M:$M,'T 05.01'!$E:$E,"r0110 - Covered deposits (BRRD art. 44/2/a)",'T 05.01'!$F:$F,"")+SUMIFS('T 05.01'!$N:$N,'T 05.01'!$E:$E,"r0110 - Covered deposits (BRRD art. 44/2/a)",'T 05.01'!$F:$F,"")+SUMIFS('T 03.01'!P:P,'T 03.01'!E:E,"r0110 - Covered deposits (BRRD art. 44/2/a)",'T 03.01'!$F:$F,"")+SUMIFS('T 03.01'!Q:Q,'T 03.01'!E:E,"r0110 - Covered deposits (BRRD art. 44/2/a)",'T 03.01'!$F:$F,"") -> 0 | M10: =SUM(D10:L10)-I10 -> 2.1871193e+10 | N10: =+SUMIF('T 03.01'!E:E,"r0110 - Covered deposits (BRRD art. 44/2/a)",'T 03.01'!P:P)+SUMIF('T 03.01'!E:E,"r0110 - Covered deposits (BRRD art. 44/2/a)",'T 03.01'!Q:Q) -> 732268.55 | O10: 0 | V10: =+N10+N22+M27 -> 6.6741117e+09
B11: Secured liabilities - collateralized part (BRRD art. 44/2/b) | C11: 0120 | D11: =SUMIF('T 08.00'!$E:$E,"c001x - Households",'T 08.00'!$O:$O)+SUMIFS('T 03.01'!P:P,'T 03.01'!E:E,"r0120 - Secured liabilities - collateralized part (BRRD art. 44/2/b)",'T 03.01'!$F:$F,"c001x - Households")+SUMIFS('T 03.01'!Q:Q,'T 03.01'!E:E,"r0120 - Secured liabilities - collateralized part (BRRD art. 44/2/b)",'T 03.01'!$F:$F,"c001x - Households")+SUMIFS('T 04.00'!M:M,'T 04.00'!F:F,"c001x - Households",'T 04.00'!E:E,"r0120 - Secured liabilities - collateralized part (BRRD art. 44/2/b)")+SUMIFS('T 04.00'!O:O,'T 04.00'!F:F,"c001x - Households",'T 04.00'!E:E,"r0120 - Secured liabilities - collateralized part (BRRD art. 44/2/b)") -> 0 | E11: =SUMIF('T 08.00'!$E:$E,"c002x - Micro & SME",'T 08.00'!$O:$O)+SUMIFS('T 03.01'!P:P,'T 03.01'!E:E,"r0120 - Secured liabilities - collateralized part (BRRD art. 44/2/b)",'T 03.01'!$F:$F,"c002x - Micro & SME")+SUMIFS('T 03.01'!Q:Q,'T 03.01'!E:E,"r0120 - Secured liabilities - collateralized part (BRRD art. 44/2/b)",'T 03.01'!$F:$F,"c002x - Micro & SME")+SUMIFS('T 04.00'!M:M,'T 04.00'!F:F,"c002x - Micro & SME",'T 04.00'!E:E,"r0120 - Secured liabilities - collateralized part (BRRD art. 44/2/b)")+SUMIFS('T 04.00'!O:O,'T 04.00'!F:F,"c002x - Micro & SME",'T 04.00'!E:E,"r0120 - Secured liabilities - collateralized part (BRRD art. 44/2/b)") -> 0 | F11: =SUMIF('T 08.00'!$E:$E,"c003x - Corporates",'T 08.00'!$O:$O)+SUMIFS('T 03.01'!P:P,'T 03.01'!E:E,"r0120 - Secured liabilities - collateralized part (BRRD art. 44/2/b)",'T 03.01'!$F:$F,"c003x - Corporates")+SUMIFS('T 03.01'!Q:Q,'T 03.01'!E:E,"r0120 - Secured liabilities - collateralized part (BRRD art. 44/2/b)",'T 03.01'!$F:$F,"c003x - Corporates")+SUMIFS('T 04.00'!M:M,'T 04.00'!F:F,"c003x - Corporates",'T 04.00'!E:E,"r0120 - Secured liabilities - collateralized part (BRRD art. 44/2/b)")+SUMIFS('T 04.00'!O:O,'T 04.00'!F:F,"c003x - Corporates",'T 04.00'!E:E,"r0120 - Secured liabilities - collateralized part (BRRD art. 44/2/b)") -> 0 | G11: =SUMIF('T 08.00'!$E:$E,"c004x - Institutions",'T 08.00'!$O:$O)+SUMIFS('T 03.01'!P:P,'T 03.01'!E:E,"r0120 - Secured liabilities - collateralized part (BRRD art. 44/2/b)",'T 03.01'!$F:$F,"c004x - Institutions")+SUMIFS('T 03.01'!Q:Q,'T 03.01'!E:E,"r0120 - Secured liabilities - collateralized part (BRRD art. 44/2/b)",'T 03.01'!$F:$F,"c004x - Institutions")+SUMIFS('T 04.00'!N:N,'T 04.00'!F:F,"c004x - Institutions",'T 04.00'!E:E,"r0120 - Secured liabilities - collateralized part (BRRD art. 44/2/b)")+SUMIFS('T 04.00'!O:O,'T 04.00'!F:F,"c004x - Institutions",'T 04.00'!E:E,"r0120 - Secured liabilities - collateralized part (BRRD art. 44/2/b)") -> 1.9824519e+09 | H11: =SUMIF('T 08.00'!$E:$E,"c005x - Other financial corporations",'T 08.00'!$O:$O)+I11+SUMIFS('T 03.01'!P:P,'T 03.01'!E:E,"r0120 - Secured liabilities - collateralized part (BRRD art. 44/2/b)",'T 03.01'!$F:$F,"c005x - Other financial corporations")+SUMIFS('T 03.01'!Q:Q,'T 03.01'!E:E,"r0120 - Secured liabilities - collateralized part (BRRD art. 44/2/b)",'T 03.01'!$F:$F,"c005x - Other financial corporations")+SUMIFS('T 04.00'!N:N,'T 04.00'!F:F,"c005x - Other financial corporations",'T 04.00'!E:E,"r0120 - Secured liabilities - collateralized part (BRRD art. 44/2/b)")+SUMIFS('T 04.00'!O:O,'T 04.00'!F:F,"c005x - Other financial corporations",'T 04.00'!E:E,"r0120 - Secured liabilities - collateralized part (BRRD art. 44/2/b)") -> 3.0241148e+09 | I11: =SUMIF('T 08.00'!$E:$E,"c006x - Insurance firms & pension funds",'T 08.00'!$O:$O)+SUMIFS('T 03.01'!P:P,'T 03.01'!E:E,"r0120 - Secured liabilities - collateralized part (BRRD art. 44/2/b)",'T 03.01'!$F:$F,"c006x - Insurance firms & pension funds")+SUMIFS('T 03.01'!Q:Q,'T 03.01'!E:E,"r0120 - Secured liabilities - collateralized part (BRRD art. 44/2/b)",'T 03.01'!$F:$F,"c006x - Insurance firms & pension funds")+SUMIFS('T 04.00'!N:N,'T 04.00'!F:F,"c006x - Insurance firms & pension funds",'T 04.00'!E:E,"r0120 - Secured liabilities - collateralized part (BRRD art. 44/2/b)")+SUMIFS('T 04.00'!O:O,'T 04.00'!F:F,"c006x - Insurance firms & pension funds",'T 04.00'!E:E,"r0120 - Secured liabilities - collateralized part (BRRD art. 44/2/b)") -> 0 | J11: =SUMIF('T 08.00'!$E:$E,"c008x - Government, central banks & supranationals",'T 08.00'!$O:$O)+SUMIFS('T 03.01'!P:P,'T 03.01'!E:E,"r0120 - Secured liabilities - collateralized part (BRRD art. 44/2/b)",'T 03.01'!$F:$F,"c008x - Government, central banks & supranationals")+SUMIFS('T 03.01'!Q:Q,'T 03.01'!E:E,"r0120 - Secured liabilities - collateralized part (BRRD art. 44/2/b)",'T 03.01'!$F:$F,"c008x - Government, central banks & supranationals")+SUMIFS('T 04.00'!N:N,'T 04.00'!F:F,"c008x - Government, central banks & supranationals",'T 04.00'!E:E,"r0120 - Secured liabilities - collateralized part (BRRD art. 44/2/b)")+SUMIFS('T 04.00'!O:O,'T 04.00'!F:F,"c008x - Government, central banks & supranationals",'T 04.00'!E:E,"r0120 - Secured liabilities - collateralized part (BRRD art. 44/2/b)") -> 7.410242e+09 | K11: 0 | L11: =SUMIF('T 08.00'!$E:$E,"",'T 08.00'!$O:$O)+SUMIFS('T 03.01'!P:P,'T 03.01'!E:E,"r0120 - Secured liabilities - collateralized part (BRRD art. 44/2/b)",'T 03.01'!$F:$F,"")+SUMIFS('T 03.01'!Q:Q,'T 03.01'!E:E,"r0120 - Secured liabilities - collateralized part (BRRD art. 44/2/b)",'T 03.01'!$F:$F,"")+SUMIFS('T 04.00'!O:O,'T 04.00'!F:F,"",'T 04.00'!E:E,"r0120 - Secured liabilities - collateralized part (BRRD art. 44/2/b)") -> 0 | M11: =SUM(D11:L11)-I11 -> 1.2416809e+10 | N11: =+SUMIF('T 03.01'!E:E,"r0120 - Secured liabilities - collateralized part (BRRD art. 44/2/b)",'T 03.01'!P:P)+SUMIF('T 03.01'!E:E,"r0120 - Secured liabilities - collateralized part (BRRD art. 44/2/b)",'T 03.01'!Q:Q) -> 3.0241148e+09 | O11: 0
B12: Client liabilities, if protected in insolvency (BRRD art. 44/2/c) | C12: 0130 | D12: 0 | E12: 0 | F12: 0 | G12: 0 | H12: 0 | I12: 0 | J12: 0 | K12: 0 | L12: 0 | M12: =SUM(D12:L12)-I12 -> 0 | N12: 0 | O12: 0
B13: Fiduciary liabilities, if protected in insolvency (BRRD art. 44/2/d) | C13: 0140 | D13: 0 | E13: 0 | F13: 0 | G13: 0 | H13: 0 | I13: 0 | J13: 0 | K13: 0 | L13: 0 | M13: =SUM(D13:L13)-I13 -> 0 | N13: 0 | O13: 0
B14: Institution liabilities < 7 days (BRRD art. 44/2/e) | C14: 0150 | D14: =+SUMIFS('T 06.01'!$O:$O,'T 06.01'!$E:$E,"r0150 - Institution liabilities < 7 days (BRRD art. 44/2/e)",'T 06.01'!$F:$F,"c001x - Households")+SUMIFS('T 06.01'!$P:$P,'T 06.01'!$E:$E,"r0150 - Institution liabilities < 7 days (BRRD art. 44/2/e)",'T 06.01'!$F:$F,"c001x - Households")+SUMIFS('T 03.01'!P:P,'T 03.01'!E:E,"r0150 - Institution liabilities < 7 days (BRRD art. 44/2/e)",'T 03.01'!$F:$F,"c001x - Households")+SUMIFS('T 03.01'!Q:Q,'T 03.01'!E:E,"r0150 - Institution liabilities < 7 days (BRRD art. 44/2/e)",'T 03.01'!$F:$F,"c001x - Households") -> 0 | E14: =+SUMIFS('T 06.01'!$O:$O,'T 06.01'!$E:$E,"r0150 - Institution liabilities < 7 days (BRRD art. 44/2/e)",'T 06.01'!$F:$F,"c002x - Micro & SME")+SUMIFS('T 06.01'!$P:$P,'T 06.01'!$E:$E,"r0150 - Institution liabilities < 7 days (BRRD art. 44/2/e)",'T 06.01'!$F:$F,"c002x - Micro & SME")+SUMIFS('T 03.01'!P:P,'T 03.01'!E:E,"r0150 - Institution liabilities < 7 days (BRRD art. 44/2/e)",'T 03.01'!$F:$F,"c002x - Micro & SME")+SUMIFS('T 03.01'!Q:Q,'T 03.01'!E:E,"r0150 - Institution liabilities < 7 days (BRRD art. 44/2/e)",'T 03.01'!$F:$F,"c002x - Micro & SME") -> 0 | F14: =+SUMIFS('T 06.01'!$O:$O,'T 06.01'!$E:$E,"r0150 - Institution liabilities < 7 days (BRRD art. 44/2/e)",'T 06.01'!$F:$F,"c003x - Corporates")+SUMIFS('T 06.01'!$P:$P,'T 06.01'!$E:$E,"r0150 - Institution liabilities < 7 days (BRRD art. 44/2/e)",'T 06.01'!$F:$F,"c003x - Corporates")+SUMIFS('T 03.01'!P:P,'T 03.01'!E:E,"r0150 - Institution liabilities < 7 days (BRRD art. 44/2/e)",'T 03.01'!$F:$F,"c003x - Corporates")+SUMIFS('T 03.01'!Q:Q,'T 03.01'!E:E,"r0150 - Institution liabilities < 7 days (BRRD art. 44/2/e)",'T 03.01'!$F:$F,"c003x - Corporates") -> 0 | G14: =+SUMIFS('T 06.01'!$O:$O,'T 06.01'!$E:$E,"r0150 - Institution liabilities < 7 days (BRRD art. 44/2/e)",'T 06.01'!$F:$F,"c004x - Institutions")+SUMIFS('T 06.01'!$P:$P,'T 06.01'!$E:$E,"r0150 - Institution liabilities < 7 days (BRRD art. 44/2/e)",'T 06.01'!$F:$F,"c004x - Institutions")+SUMIFS('T 03.01'!P:P,'T 03.01'!E:E,"r0150 - Institution liabilities < 7 days (BRRD art. 44/2/e)",'T 03.01'!$F:$F,"c004x - Institutions")+SUMIFS('T 03.01'!Q:Q,'T 03.01'!E:E,"r0150 - Institution liabilities < 7 days (BRRD art. 44/2/e)",'T 03.01'!$F:$F,"c004x - Institutions") -> 1.5324904e+08 | H14: =+SUMIFS('T 06.01'!$O:$O,'T 06.01'!$E:$E,"r0150 - Institution liabilities < 7 days (BRRD art. 44/2/e)",'T 06.01'!$F:$F,"c005x - Other financial corporations")+SUMIFS('T 06.01'!$P:$P,'T 06.01'!$E:$E,"r0150 - Institution liabilities < 7 days (BRRD art. 44/2/e)",'T 06.01'!$F:$F,"c005x - Other financial corporations")+I14+SUMIFS('T 03.01'!P:P,'T 03.01'!E:E,"r0150 - Institution liabilities < 7 days (BRRD art. 44/2/e)",'T 03.01'!$F:$F,"c005x - Other financial corporations")+SUMIFS('T 03.01'!Q:Q,'T 03.01'!E:E,"r0150 - Institution liabilities < 7 days (BRRD art. 44/2/e)",'T 03.01'!$F:$F,"c005x - Other financial corporations") -> 0 | I14: =+SUMIFS('T 06.01'!$O:$O,'T 06.01'!$E:$E,"r0150 - Institution liabilities < 7 days (BRRD art. 44/2/e)",'T 06.01'!$F:$F,"c006x - Insurance firms & pension funds")+SUMIFS('T 06.01'!$P:$P,'T 06.01'!$E:$E,"r0150 - Institution liabilities < 7 days (BRRD art. 44/2/e)",'T 06.01'!$F:$F,"c006x - Insurance firms & pension funds")+SUMIFS('T 03.01'!P:P,'T 03.01'!E:E,"r0150 - Institution liabilities < 7 days (BRRD art. 44/2/e)",'T 03.01'!$F:$F,"c006x - Insurance firms & pension funds")+SUMIFS('T 03.01'!Q:Q,'T 03.01'!E:E,"r0150 - Institution liabilities < 7 days (BRRD art. 44/2/e)",'T 03.01'!$F:$F,"c006x - Insurance firms & pension funds") -> 0 | J14: =+SUMIFS('T 06.01'!$O:$O,'T 06.01'!$E:$E,"r0150 - Institution liabilities < 7 days (BRRD art. 44/2/e)",'T 06.01'!$F:$F,"c008x - Government, central banks & supranationals")+SUMIFS('T 06.01'!$P:$P,'T 06.01'!$E:$E,"r0150 - Institution liabilities < 7 days (BRRD art. 44/2/e)",'T 06.01'!$F:$F,"c008x - Government, central banks & supranationals")+SUMIFS('T 03.01'!P:P,'T 03.01'!E:E,"r0150 - Institution liabilities < 7 days (BRRD art. 44/2/e)",'T 03.01'!$F:$F,"c008x - Government, central banks & supranationals")+SUMIFS('T 03.01'!Q:Q,'T 03.01'!E:E,"r0150 - Institution liabilities < 7 days (BRRD art. 44/2/e)",'T 03.01'!$F:$F,"c008x - Government, central banks & supranationals") -> 0 | K14: 0 | L14: =+SUMIFS('T 06.01'!$O:$O,'T 06.01'!$E:$E,"r0150 - Institution liabilities < 7 days (BRRD art. 44/2/e)",'T 06.01'!$F:$F,"")+SUMIFS('T 06.01'!$P:$P,'T 06.01'!$E:$E,"r0150 - Institution liabilities < 7 days (BRRD art. 44/2/e)",'T 06.01'!$F:$F,"")+SUMIFS('T 03.01'!P:P,'T 03.01'!E:E,"r0150 - Institution liabilities < 7 days (BRRD art. 44/2/e)",'T 03.01'!$F:$F,"")+SUMIFS('T 03.01'!Q:Q,'T 03.01'!E:E,"r0150 - Institution liabilities < 7 days (BRRD art. 44/2/e)",'T 03.01'!$F:$F,"") -> 0 | M14: =SUM(D14:L14)-I14 -> 1.5324904e+08 | N14: =+SUMIF('T 03.01'!E:E,"r0150 - Institution liabilities < 7 days (BRRD art. 44/2/e)",'T 03.01'!P:P)+SUMIF('T 03.01'!E:E,"r0150 - Institution liabilities < 7 days (BRRD art. 44/2/e)",'T 03.01'!Q:Q) -> 0 | O14: 0
