Workbook

Sheet Tabela
BC1: V20211207
C7: PEDIDO DE INGESTA
C9: Este formulário visa a obtenção da informação necessária para dar seguimento à análise, aprovação e execução de pedidos de novas ingestas no datalake. Nesta pestana deverão ser indicada a informação relacionada com a fonte dos dados, o destino, regras de expurgo e informação de governo. Na pestana seguinte deverão ser indicados os campos. O formulário deverá ser enviado para SUPORTEDATALAKE@santander.pt | BH9: Múltiplos | BI9: Eliminatórios | BJ9: S/necessidade
C14: SOLICITANTE
C16: Nome do Solicitante | P16: Marcelo Costa
C17: Email do Solicitante | P17: marcelotiago.costa@servexternos.santander.pt
C18: Área do Solicitante | P18: Reporting Hub
C19: Identificação do Projecto | P19: P2300402 | X19: Datamart Bankware
C21: Tipo de pedido | P21: Nova Ingesta
C23: FONTE DOS DADOS
C25: Tipo de input | P25: Descrição Funcional da Fonte dos Dados
P26: Informação da tabela core do ALM, com todas as origens relevantes para ALM (créditos, depósitos, repos, titulos, inputs manuais, derivados, loan and depos, Papel Comercial, Swaps Cambiais, Money Market)
D27: X | E27: RDB | BH27: =IF(COUNTIF(#REF!,"X")>0,1,0) -> #REF!
E29: Ficheiros SSMM
E31: Ficheiros HOST
P34: Calendário de planificação | AL34: Condição
P35: Mensal | AL35: 12º dia de cada mês o final do mês anterior
C37: RDB
C39: PRE | D39: Servidor (FQDN) | R39: Porta | U39: Tipo BD | AA39: Tipo de carregamento | AH39: Query
AA40: Incremental | AH40: ref_date=ultimo mês carregado
D42: Base de Dados | K42: Schema / Owner | S42: Tabela
D43: Hive | K43: cd_alm | S43: al029_cnt_core_m
C45: PRO | D45: Servidor (FQDN) | R45: Porta | U45: Tipo BD | AA45: Tipo de carregamento | AH45: Query
AA46: Incremental | AH46: ref_date=ultimo mês carregado
D48: Base de Dados | K48: Schema / Owner | S48: Tabela
D49: Hive | K49: cd_alm | S49: al029_cnt_core_m
C52: Ficheiros SSMM
C54: PRE | D54: Servidor (FQDN) | R54: Path | AD54: Nome do Ficheiro | AM54: User | AR54: Header | AU54: Footer | AX54: Copybook
C57: PRO | D57: Servidor (FQDN) | R57: Path | AD57: Nome do Ficheiro | AM57: User | AR57: Header | AU57: Footer | AX57: Copybook
C61: Ficheiros HOST
C63: PRE | D63: Servidor (FQDN) | R63: Nome do ficheiro | AO63: Formato | AR63: Header | AU63: Footer | AX63: Copybook
C66: PRO | D66: Servidor (FQDN) | R66: Nome do ficheiro | AO66: Formato | AR66: Header | AU66: Footer | AX66: Copybook
C71: DESTINO
C73: Sistema | R73: Tabela
R74: al029_cnt_core_m
E75: On Premise | J75: X | K75: Cloud
C78: VOLUMETRIA E PROFUNDIDADE HISTÓRICA (Quantidade de posições distintas da mesma tabela)
C80: Tamanho registo | L80: Média de registos | U80: Partições Landing | AA80: Partições CD | AG80: Justificação (caso haja necessidade de mais de 1 partição)
C81: 53 | L81: 5.250.000 | U81: 1 | AA81: 1
C83: Condições para expurgo (Landing e CD)
...

Sheet Campos
C1: Em caso de dúvida no preenchimento contactar cdo@santander.pt
B2: # | C2: Campo | D2: Descrição | E2: Dado Base (consultar pestana dado base)
B3: 1 | C3: cempresa | D3: Código da empresa | E3: Código de empresa do contrato | F3: =IF(OR(COUNTIF('Filtro Dado base'!$A$2:$A$176,Campos!E3)>0,ISBLANK(E3)),"","Dado base inválido")
B4: 2 | C4: cbalcao | D4: Código de Balcão | E4: Identificador do contrato | F4: =IF(OR(COUNTIF('Filtro Dado base'!$A$2:$A$176,Campos!E4)>0,ISBLANK(E4)),"","Dado base inválido")
B5: 3 | C5: cnumecta | D5: Código do Numero de Conta | E5: Identificador do contrato | F5: =IF(OR(COUNTIF('Filtro Dado base'!$A$2:$A$176,Campos!E5)>0,ISBLANK(E5)),"","Dado base inválido")
B6: 4 | C6: zdeposit | D6: Numero do Depósito | E6: Identificador do contrato | F6: =IF(OR(COUNTIF('Filtro Dado base'!$A$2:$A$176,Campos!E6)>0,ISBLANK(E6)),"","Dado base inválido")
B7: 5 | C7: zcliente | D7: Número de cliente | E7: Identificador interno do cliente | F7: =IF(OR(COUNTIF('Filtro Dado base'!$A$2:$A$176,Campos!E7)>0,ISBLANK(E7)),"","Dado base inválido")
B8: 6 | C8: tipo_balanco | D8: Código Tipo de Balanço | E8: Saldos do contrato | F8: =IF(OR(COUNTIF('Filtro Dado base'!$A$2:$A$176,Campos!E8)>0,ISBLANK(E8)),"","Dado base inválido")
B9: 7 | C9: caplic | D9: Código da Aplicação | E9: Código de aplicação | F9: =IF(OR(COUNTIF('Filtro Dado base'!$A$2:$A$176,Campos!E9)>0,ISBLANK(E9)),"","Dado base inválido")
B10: 8 | C10: cproduto | D10: Código de Produto | E10: Código de produto de contrato | F10: =IF(OR(COUNTIF('Filtro Dado base'!$A$2:$A$176,Campos!E10)>0,ISBLANK(E10)),"","Dado base inválido")
B11: 9 | C11: csubprod | D11: Código de Subproduto | E11: Código de produto de contrato | F11: =IF(OR(COUNTIF('Filtro Dado base'!$A$2:$A$176,Campos!E11)>0,ISBLANK(E11)),"","Dado base inválido")
B12: 10 | C12: ind_capit | D12: Indicador de Capitalização | E12: Indicadores económicos e de mercado | F12: =IF(OR(COUNTIF('Filtro Dado base'!$A$2:$A$176,Campos!E12)>0,ISBLANK(E12)),"","Dado base inválido")
B13: 11 | C13: ind_renov | D13: Indicador de Renovação | E13: Indicadores económicos e de mercado | F13: =IF(OR(COUNTIF('Filtro Dado base'!$A$2:$A$176,Campos!E13)>0,ISBLANK(E13)),"","Dado base inválido")
B14: 12 | C14: prz_renov | D14: Código Prazo de Renovação | E14: Indicadores económicos e de mercado | F14: =IF(OR(COUNTIF('Filtro Dado base'!$A$2:$A$176,Campos!E14)>0,ISBLANK(E14)),"","Dado base inválido")
... B55: 53 | C55: origem | D55: Código origem de registo | E55: Outros dados do contrato | F55: =IF(OR(COUNTIF('Filtro Dado base'!$A$2:$A$176,Campos!E55)>0,ISBLANK(E55)),"","Dado base inválido")
B56: 54 | F56: =IF(OR(COUNTIF('Filtro Dado base'!$A$2:$A$176,Campos!E56)>0,ISBLANK(E56)),"","Dado base inválido")
B57: 55 | F57: =IF(OR(COUNTIF('Filtro Dado base'!$A$2:$A$176,Campos!E57)>0,ISBLANK(E57)),"","Dado base inválido")
B58: 56 | F58: =IF(OR(COUNTIF('Filtro Dado base'!$A$2:$A$176,Campos!E58)>0,ISBLANK(E58)),"","Dado base inválido")
B59: 57 | F59: =IF(OR(COUNTIF('Filtro Dado base'!$A$2:$A$176,Campos!E59)>0,ISBLANK(E59)),"","Dado base inválido")
B60: 58 | F60: =IF(OR(COUNTIF('Filtro Dado base'!$A$2:$A$176,Campos!E60)>0,ISBLANK(E60)),"","Dado base inválido")
B61: 59 | F61: =IF(OR(COUNTIF('Filtro Dado base'!$A$2:$A$176,Campos!E61)>0,ISBLANK(E61)),"","Dado base inválido")
B62: 60 | F62: =IF(OR(COUNTIF('Filtro Dado base'!$A$2:$A$176,Campos!E62)>0,ISBLANK(E62)),"","Dado base inválido")
B63: 61 | F63: =IF(OR(COUNTIF('Filtro Dado base'!$A$2:$A$176,Campos!E63)>0,ISBLANK(E63)),"","Dado base inválido")
B64: 62 | F64: =IF(OR(COUNTIF('Filtro Dado base'!$A$2:$A$176,Campos!E64)>0,ISBLANK(E64)),"","Dado base inválido")
B65: 63 | F65: =IF(OR(COUNTIF('Filtro Dado base'!$A$2:$A$176,Campos!E65)>0,ISBLANK(E65)),"","Dado base inválido")
B66: 64 | F66: =IF(OR(COUNTIF('Filtro Dado base'!$A$2:$A$176,Campos!E66)>0,ISBLANK(E66)),"","Dado base inválido")
B67: 65 | F67: =IF(OR(COUNTIF('Filtro Dado base'!$A$2:$A$176,Campos!E67)>0,ISBLANK(E67)),"","Dado base inválido")
... B172: 170 | F172: =IF(OR(COUNTIF('Filtro Dado base'!$A$2:$A$176,Campos!E172)>0,ISBLANK(E172)),"","Dado base inválido")

Sheet Usos
B1: Usos | D1: Exemplos
B2: Comunicação Interna | C2: Comunicação interna geral | D2: Comunicação da informação interna para os funcionários (logística, publicidade, formação, etc.)
C3: Comunicação interna particular | D3: Comunicação interna direcionada para pessoas específicas
C4: Questionários internos | D4: Inquéritos de compromisso, a avaliação dos cursos de formação, etc.
B5: Comunicação Externa | C5: Comunicação pública | D5: Comunicação a imprensa, acionistas, etc.
C6: Comunicação a organismos públicos e reguladores | D6: Comunicação à CNMV e outros órgãos públicos
C7: Questionários de satisfação | D7: Para os clientes, acionistas e o público em geral
C8: Atenção ao cliente | D8: Chamadas do contact-center sucursais, consultas online, etc.
C9: Comunicação de Marketing e eventos | D9: Anúncios nos meios de comunicação, venda da marca, etc.
C10: Comunicação comercial | D10: Contato com clientes para venda de produtos
C11: Comunicação informativa | D11: Informações aos clientes sobre seus produtos (posições, data de vencimento, etc.)
C12: Comunicação para gestão recuperatória | D12: Contato com os clientes para as tarefas de recuperação de dívida
C13: Comunicação com fornecedores | D13: Gestão da comunicação com os prestadores de serviços
B14: Gestão | C14: Gestão de riscos | D14: Atividades de avaliação, monitorização, gestão e mitigação de riscos.
C15: Gestão financeira | D15: Análise, processamento de informação e tomada de decisões sobre aspetos financeiros e contabilísticos.
C16: Gestão tecnológica | D16: Gestão de Arquitetura tecnológica, controle de acesso, licenças, sistemas de gestão, etc.
C17: Gestão de fornecedores | D17: Homologação de fornecedores, contratos, análise global, etc.
C18: Gestão de empregados e familiares | D18: Gestão de vencimentos, avaliações, promoção, ausências, saúde, fiscalidade, etc.
C19: Gestão de marketing e eventos | D19: Organização de eventos de marketing, culturais e desportivos, gestão de campanhas de marketing, etc.
C20: Gestão de operativa bancaria | D20: Gestão de contratos, transacionais, liquidações, etc.
C21: Gestão de fundos e atividades de investimento | D21: Atividades de gestão de fundos, tesouraria, investimentos, etc.
C22: Gestão de processos judiciais | D22: Gestão de processos judiciais.
C23: Gestão de ativos | D23: Gestão de imóveis, escritórios, acesso físico, etc.
C24: Gestão comercial | D24: Gestão de campanhas comerciais, posicionamento e design de produtos, etc.
C25: Gestão de outros bens e serviços não financeiros | D25: Gestão de outros serviços e atividades (websites de emprego e universidades, portais de empresas, golfe, outros serviços a empregados e ex-empregados, etc.).
C26: Gestão de acionistas | D26: Atividades de gestão de voto dos acionistas, liquidação e pagamento de ações, etc.
... C28: Gestão de incidências externas | D28: Gestão de incidentes com clientes, fornecedores, etc.
B29: Reporte interno | C29: Alta direção | D29: Elaboração de relatórios para a administração (Conselho, unidade, fator, etc.)
C30: Reporte entre áreas | D30: Relatórios para gestão entre áreas, seguimentos, etc.
B31: Reporte externo | C31: Reporte a organismos reguladores e públicos | D31: Relatórios para diferentes reguladores e organismos públicos
C32: Reporte de incidentes de segurança | D32: Comunicação de incidentes de segurança a vários organismos (BCE, CNPD, etc.)
C33: Reporte a organismos privados | D33: Elaboração de outros relatórios para organismos privados (agências de rating, fundos, investidores institucionais, etc.)
B34: Control | C34: Tarefas de control e oversight sobre as atividades do banco ou a serviços prestados ao banco | D34: Elaboração de Dashboards, seguimento de indicadores, etc.
C35: Tarefas de cumprimento | D35: Elaboração de análise de cumprimento regulatório, PBC, etc.
C36: Tarefas de auditoria | D36: Elaboração de relatórios de auditoria, recomendações, etc.
B37: Consolidação | C37: Consolidação e agregação de dados | D37: Tarefas de consolidação financeira, perímetro societário, etc.
B38: Metodologia / Analítica | C38: Análise estatística | D38: Realização de cálculos e análise de caracter estatístico
C39: Criação de cenários e projeções | D39: Elaboração de Cenários económicos, financeiros, projeções, etc.
C40: Criação de modelos | D40: Tarefas de Definição, geração e avaliação de modelos
B41: Análise Estratégica | C41: Análise estratégica | D41: Elaboração da estratégia de negócios global e particular, riscos, tecnologia, de dados, etc.
...

Sheet Dado Base
B1: Semântica | C1: Semântica | D1: Dado Base | E1: Descrição do Dado Base
B2: Pessoas | C2: Dados pessoas singulares ou coletivas | D2: Nome | E2: Nome da pessoa
B3: Pessoas | C3: Dados pessoas singulares ou coletivas | D3: Tipo de pessoa | E3: Define se é uma pessoa singular ou coletiva
B4: Pessoas | C4: Dados pessoas singulares ou coletivas | D4: Identificador da pessoa | E4: Identificador de pessoa
B5: Pessoas | C5: Dados pessoas singulares ou coletivas | D5: Morada da pessoa | E5: Morada da pessoa (morada de residência, morada fiscal, morada identificação pessoal)
B6: Pessoas | C6: Dados pessoas singulares ou coletivas | D6: Sector de atividade do cliente (CAE) da pessoa singular ou coletiva | E6: Código de identificação do setor em que o cliente desempenha a sua atividade, seja trabalhador por conta de outrem ou trabalhador independente. Por exemplo: presta serviços em espaços abertos, transporte de mercadorias, compra e venda grossista, etc. Em Portugal designa-se por CAE.
B7: Pessoas | C7: Dados pessoas singulares ou coletivas | D7: Contacto da pessoa | E7: Contacto da pessoa (telefone, email)
B8: Pessoas | C8: Dados pessoas singulares | D8: Nome de pessoa singular | E8: Nome da pessoa singular
B9: Pessoas | C9: Dados pessoas singulares | D9: Identificador da pessoa singular | E9: Identificador de pessoa (NIF, CC-Cartão Cidadão, BI-Bilhete de Identidade)
B10: Pessoas | C10: Dados pessoas singulares | D10: Morada de pessoa singular | E10: Residência ou morada de correspondência
B11: Pessoas | C11: Dados pessoas singulares | D11: Contacto de pessoa singular | E11: (Telefone, email)
B12: Pessoas | C12: Dados pessoas singulares | D12: País de residência | E12: País de residência do cliente
... B40: Pessoas | C40: Dados pessoas coletivas | D40: Tipo de entidade de negócio | E40: Tipo de sociedade comercial (S.L, L.DA, S.A, etc.)
B41: Pessoas | C41: Dados pessoas coletivas | D41: Outros dados de pessoas coletivas
B42: Pessoas | C42: Dados específicos de clientes | D42: Identificador interno do cliente | E42: Identificador interno do cliente (zcliente, zcligrupo)
B43: Pessoas | C43: Dados específicos de clientes | D43: Setor corporativo de cliente | E43: Classificação interna do setor do cliente que encontra-se no BdP (Banco de Portugal, Caixa Econômica, Comunidades Autônomas, etc.)
B44: Pessoas | C44: Dados específicos de clientes | D44: Segmento do cliente | E44: Segmento de gestão, segmento comercial ou segmento de risco
B45: Pessoas | C45: Dados específicos de clientes | D45: Grupo económico | E45: Identificador do grupo económico
B46: Pessoas | C46: Dados específicos de clientes | D46: Natureza Jurídica | E46: Natureza jurídica do cliente
B47: Pessoas | C47: Dados específicos de clientes | D47: Saldo do cliente | E47: Saldo total do cliente
B48: Pessoas | C48: Dados específicos de clientes | D48: Responsabilidades do cliente | E48: Saldo total de responsabilidade do cliente
B49: Pessoas | C49: Dados específicos de clientes | D49: Saldo insolvente do cliente | E49: Saldo insolvente do cliente
B50: Pessoas | C50: Dados específicos de clientes | D50: Saldo recuperado | E50: Saldo recuperado do cliente
B51: Pessoas | C51: Dados específicos de clientes | D51: Limites do cliente | E51: Valor máximo que pode ser concedido ao cliente pelo Banco Santander
B52: Pessoas | C52: Dados específicos de clientes | D52: Rentabilidade do cliente | E52: Rentabilidade gerada ao nível do cliente, isto é, a diferença entre as entradas de receita e as despesas (por exemplo, rentabilidade por canal, por sucursal, etc.)
B53: Pessoas | C53: Dados específicos de clientes | D53: Avaliação de risco do cliente | E53: Dados para realizar uma avaliação de risco do cliente e avaliação de risco do cliente.
... B176: NA | C176: NA | D176: NA | E176: NA

Sheet Sistemas Origem
B1: Sistema Origem | C1: Logical classification
B2: Sintra / Partenón | C2: Sistema Operacional
B3: Sigom | C3: Sistema Operacional
B4: Lease | C4: Sistema Operacional
B5: Heracles | C5: Sistema Operacional
B6: Peoplesoft | C6: Sistema Operacional
B7: BDR | C7: Sistema Informacional
B8: MIS | C8: Sistema Informacional
B9: Modelica / IFRS9 | C9: Sistema Informacional
B10: IRIS | C10: Sistema Informacional
B11: PRISMA | C11: Sistema Informacional
B12: Datamart ALM | C12: Sistema Informacional
... B23: Fontes Externas | C23: Sistema Informacional
B24: Outro - Contactar CDO

Sheet Filtro Dado base
A1: Dado Base
A2: Nome
A3: Tipo de pessoa
A4: Identificador da pessoa
A5: Morada da pessoa
A6: Sector de atividade do cliente (CAE) da pessoa singular ou coletiva
A7: Contacto da pessoa
A8: Nome de pessoa singular
A9: Identificador da pessoa singular
A10: Morada de pessoa singular
A11: Contacto de pessoa singular
A12: País de residência
... A176: NA
