Workbook
Name asefadf: #REF!
Name asefadf: #REF!
Name asefadf: #REF!
Name bn: '[2]Code List'!#REF!
Name bn: '[3]Code List'!#REF!
Name bn: '[2]Code List'!#REF!
Name Estados: Table7[Estados]
Name Pendências: Table6[Pendências]

Sheet Capa
B4: BCE Loan Tape
B8: Lisboa, | C8: =TODAY() -> 46128

Sheet 1. Metodologia
B5: Metodologia de aplicação de especificação
B7: 1. Enquadramento | G7: O presente documento de especificação é realizado no âmbito do projeto da Loan Tape para o BCE. A metodologia de cálculo prevista neste documento deve considerar, adicionalmente, níveis de aplicação de "Default values" (Not applicable ou Nullable), como explicado no esquema infra.
B9: 2. Níveis de aplicação de "Default Values"
G10: Nível 1. Aplicar os valores Not Applicable aos campos que não são reportados, via regra de report por segmento;
G11: Nível 2. Aplicar os valores Not Applicable aos campos que verificam as regras de negócio identificadas pela corporação;
G12: Nível 3. Aplicar os valores Nullable aos campos que após a aplicação das regras 1 e 2 persistam sem valor ou com valores default provenientes das respetivas origens.
K14: Nível 1 | N14: Nível 2 | Q14: Nível 3
G21: * Regras definidas na coluna "Metodologia de Cálculo (NOT APLICABLE)" nas sheets Entity, Instrument, Instr_Entity, Protection e Instr_Protection do presente documento
G23: Legenda:
H25: Regras a definir no presente documento
H27: Regras a definir no documento "Definição Requisitos Loan Tape", produzido pela área do CDO
G30: Qualquer referência no presente documento aos níveis 1 e 3 deste processo, deve-se consultar o documento "Definição Requisitos Loan Tape"
B33: Notas adicionais | Metodologia de cálculo | G33: Todos os campos devem ser calculados sobre a data de referência em análise/processamento, exceto quando mencionado o contrário. Exemplo: se DT_RFRNC = '2021-12-31' então data de referência na fonte deverá ser DATA_DATE_PART = DT_RFRNC ou REF_DATE = DT_RFRNC
B35: Notas adicionais | Nível 3 - NULLABLE | G35: O valor de default de NULLABLE deve considerar todos os blanks, nulls e campos só com espaços na fonte ou quando determinadas chaves de contratato/cliente/garantia não cruzam com a fonte, exceto quando mencionado o contrário. Exemplos: TRIM(CAMPO_X) = '' então valor da coluna NULLABLE CAMPO_X is NULL então valor da coluna NULLABLE INSTRMNT_ID não existe na fonte (e não está mencionado nada na metodologia de NOT APPLICABLE) então valor da coluna NULLABLE

Sheet LT002_INSTRUMENT
B5: INPUT BCE | S5: INPUT CORPORAÇÃO | AB5: ESPECIFICAÇÃO
B6: TABLE_NAME | C6: COLUMN_NAME | D6: DATA_TYPE | E6: ANACREDIT | F6: CRP | G6: CRE | H6: LF | I6: RRE | J6: Retail SME | K6: Retail Other | L6: DESCRIPTION | M6: Field Definition / Additional Guidance | N6: Field Definition / Additional Guidance (new) | O6: Validação | P6: NULLABLE | Q6: NOT APPLICABLE | R6: Column5 | S6: ORDER | T6: Cash balances and other deposits | U6: General governments | V6: Credit institutions | W6: Other financial corporations | X6: Non financial corporations | Y6: Households | Z6: DEBT SECURITIES | AA6: Column3 | AB6: Schema DL | AC6: Tabela | AD6: Campo | AE6: Metodologia de Cálculo | AF6: Metodologia de Cálculo (NOT APPLICABLE) | AG6: Metodologia de cruzamento | AH6: Column2 | AI6: DT Atualização - Especificação | AJ6: Histórico EF | AK6: Observações Metodologia / Conceito | AL6: CRC/ Anacredit | AM6: Guia Corporativo | AN6: Melhoria | AO6: Revisto | AP6: Temática | AQ6: Área | AR6: Responável área | AS6: Notas Reuniões | AT6: Reunião com LCM | AU6: Alteração EF
A7: =_xlfn.CONCAT(Table2[[#This Row],[TABLE_NAME]],Table2[[#This Row],[COLUMN_NAME]]) -> INSTRUMENTACCMLTD_CHNGS_FV_CR_INSTRMNT | B7: INSTRUMENT | C7: ACCMLTD_CHNGS_FV_CR_INSTRMNT | D7: FLOAT 2 decimal places | E7: Y | F7: Y | G7: N | H7: N | I7: N | J7: N | K7: N | L7: Accumulated changes in fair value due to credit risk | M7: Accumulated changes in fair value due to credit risk in accordance with Part 2.46 of Annex V to Implementing Regulation (EU) No 680/2014. | N7: Accumulated changes in fair value due to credit risk in accordance with Part 2.46 of Annex V to Implementing Regulation (EU) No 680/2014. | O7: TRUE | P7: 99999999999 | Q7: 11111111111 | S7: IN.061 | T7: N | U7: Y | V7: Y | W7: Y | X7: Y | Y7: N | Z7: Y | AB7: FIXO | AC7: FIXO | AD7: FIXO | AE7: 0 | AF7: - Se PRFRMNG_STTS <> '1' - Se ACCNTNG_CLSSFCTN not in ('4','41') | AG7: - | AI7: 45065 | AJ7: 08/11/21: A metodologia de Not Applicable mantém-se igual à versão original (não foi aplicada a metodologia de default values proposta pela corporação). 29/05/2023: Atualização de metodologia de Not Applicable e cálculo. | AK7: Metodologia / Conceito: 1) No mapa F18 o campo está a ser reportado a vazio. Para os instrumentos a "fair value through profit or loss" o GRSS_CRRYNG_AMNT_INSTRMNT = CRRYNG_AMNT_INSTRMNT + ACCMLTD_CHNGS_FV_CR_INSTRMNT 2) Aplicar metodologia de N/A definida pela Corporação; 3) Caso o contrato não cumpra as condições de N/A, deve ser reportado 0, à semelhança do FINREP/NOPER; 4) Não está planeado o FINREP passar a reportar esta informação. Especificado/ Revisto por: Contabilidade (Luisa de Sousa) Guia de conceitos da Corporação: De acordo com o pretendido no Guia. | AL7: Campo: varAcumRC De acordo com o reportado na AnaCredit | AM7: OK | AN7: N | AO7: Y | AP7: Contabilidade | AQ7: CONTABILIDADE | AR7: Rafael Pessoa | AS7: Configuração por subproduto (TAT91 Ctabela 927 e pedir para criar view sobre ela caso não exista) | AU7: 1
A8: =_xlfn.CONCAT(Table2[[#This Row],[TABLE_NAME]],Table2[[#This Row],[COLUMN_NAME]]) -> INSTRUMENTACCMLTD_IMPRMNT_INSTRMNT | B8: INSTRUMENT | C8: ACCMLTD_IMPRMNT_INSTRMNT | D8: FLOAT 2 decimal places | E8: Y | F8: Y | G8: Y | H8: Y | I8: Y | J8: Y | K8: Y | L8: Sum of LLPs and other allowances | M8: The amount of loss allowances that are held against or are allocated to the instrument on the reporting reference date. This data attribute applies to instruments subject to impairment under the applied accounting standard. Under IFRS, the accumulated impairment relates to the following amounts: (i) loss allowance at an amount equal to 12-month expected credit losses; (ii) loss allowance at an amount equal to lifetime expected credit losses. Under nGAAP, the accumulated impairment relates to the following amounts: (i) loss allowance at an amount equal to specific allowances; (ii) loss allowance at an amount equal to general allowances. | N8: The amount of loss allowances that are held against or are allocated to the instrument on the reporting reference date. This data attribute applies to instruments subject to impairment under the applied accounting standard. Under IFRS, the accumulated impairment relates to the following amounts: (i) loss allowance at an amount equal to 12-month expected credit losses; (ii) loss allowance at an amount equal to lifetime expected credit losses. Under nGAAP, the accumulated impairment relates to the following amounts: (i) loss allowance at an amount equal to specific allowances; (ii) loss allowance at an amount equal to general allowances. | O8: TRUE | P8: 99999999999 | Q8: 11111111111 | S8: IN.088 | T8: Y | U8: Y | V8: Y | W8: Y | X8: Y | Y8: Y | Z8: Y | AB8: CD_LOAN_TAPES_BCE | AC8: LT001_UNIV_OPER | AD8: PROVISAO_ON CARTEIRA_CONTABILISTICA | AE8: NVL ( SUM(PROVISAO_ON) ; 0 ) | AF8: Se ACCNTNG_CLSSFCTN IN ('2','4','41') | AG8: 1) Cruzar LT002_INSTRUMENT com LT001_UNIV_OPER para obter o campo PROVISAO_ON: LT002_INSTRUMENT LEFT JOIN (SELECT * FROM LT001_UNIV_OPER GROUP BY CEMPRESA, CBALCAO, CNUMECTA, ZDEPOSIT) ON INSTRMNT_ID = CONCAT(CEMPRESA, CBALCAO, CNUMECTA, ZDEPOSIT) | AI8: 46010 | AJ8: 08/11/21: A metodologia de Not Applicable mantém-se igual à versão original (não foi aplicada a metodologia de default values proposta pela corporação). 30/03/22: Atualização da metodologia de cálculo para prever os novos campos da LT001. 19/12/2025: Atualização da metodologia de NOT APPLICABLE quando ACCNTNG_CLSSFCTN IN ('2','4','41') | AK8: Metodologia / Conceito: 1) Somatório de provisões dentro de balanço que constam no mapa FINREP18/ NOPER. 2) De forma a coniliar com o FINREP, os campos de saldos têm como fonte o universo da LT (Tabela LT001 com as operações por conta contabilistica) que por sua vez tem como fonte a tabela de universo do FINREP (FR001). Especificado/ Revisto por: CDO (Luis Capitão-Mor) Guia de conceitos da Corporação: De acordo com o pretendido no Guia.
A9: =_xlfn.CONCAT(Table2[[#This Row],[TABLE_NAME]],Table2[[#This Row],[COLUMN_NAME]]) -> INSTRUMENTACCMLTD_IMPRMNT_INSTRMNT_PRVS | B9: INSTRUMENT | C9: ACCMLTD_IMPRMNT_INSTRMNT_PRVS | D9: FLOAT 2 decimal places | E9: N | F9: Y | G9: Y | H9: Y | I9: Y | J9: Y | K9: Y | L9: Previous sum of LLPs and other allowances | M9: The amount of loss allowances that are held against or are allocated to the instrument on the date one year before the reporting reference date. This data attribute applies to instruments subject to impairment under the applied accounting standard. Under IFRS, the accumulated impairment relates to the following amounts: (i) loss allowance at an amount equal to 12-month expected credit losses; (ii) loss allowance at an amount equal to lifetime expected credit losses. Under nGAAP, the accumulated impairment relates to the following amounts: (i) loss allowance at an amount equal to specific allowances; (ii) loss allowance at an amount equal to general allowances. | N9: The amount of loss allowances that are held against or are allocated to the instrument on the date one year before the loan tape reporting reference date. This data attribute applies to instruments subject to impairment under the applied accounting standard. Under IFRS, the accumulated impairment relates to the following amounts: (i) loss allowance at an amount equal to 12-month expected credit losses; (ii) loss allowance at an amount equal to lifetime expected credit losses. Under nGAAP, the accumulated impairment relates to the following amounts: (i) loss allowance at an amount equal to specific allowances; (ii) loss allowance at an amount equal to general allowances. | O9: FALSE | P9: 99999999999 | Q9: 11111111111 | S9: IN.089 | T9: Y | U9: Y | V9: Y | W9: Y | X9: Y | Y9: Y | Z9: Y | AB9: CD_LOAN_TAPES_BCE | AC9: LT001_UNIV_OPER | AD9: PROVISAO_ON_PRVS | AE9: NVL ( SUM(PROVISAO_ON_PRVS) ; 0 ) | AF9: - Se a DT_INCPTN > REF_DATE - 1 ANO - Se ACCNTNG_CLSSFCTN IN ('2','4','41') | AG9: 1) Cruzar LT002_INSTRUMENT com LT001_UNIV_OPER para obter o campo PROVISAO_ON_PRVS: LT002_INSTRUMENT LEFT JOIN (SELECT * FROM LT001_UNIV_OPER GROUP BY CEMPRESA, CBALCAO, CNUMECTA, ZDEPOSIT) ON INSTRMNT_ID = CONCAT(CEMPRESA, CBALCAO, CNUMECTA, ZDEPOSIT) | AI9: 46010 | AJ9: 08/11/21: Foram eliminadas da metodologia de Not Applicable as regras" - Se o campo ACCNTNG_CLSSFCTN assumir os valores: '2','4','41'; - Se todas as linhas do contrato na FR802, o campo PRODUTO assumir os valores: 'garantias prestadas','compromissos perante terceiros', 'outras responsabilidades perante terceiros','garantias financeiras prestadas';" 30/03/22: Atualização da metodologia de cálculo para prever os novos campos da LT001 19/12/2025: Foi atualizada a metodologia de cálculo para que o campo apresente o valor da coluna de nullable, até 2022-12-31 15/07/22: Foi anulada a última alteração (apagada a frase "* Reportar valor da coluna NULLABLE até 2022-12-31") 13/01/22: Alteração da metodologia de cálculo e Not Applicable para prever casos em que a REF_DATE de há 1 ano seja menor que a DT_INCPTN 26/06/2025: Criação do campo PROVISAO_ON_PRVS na LT001 e alteração da metodologia de cálculo para prever estes mesmos campos como fonte. O campo é calculado diretamente a partir dos campos do Universo. 02/12/2025: Atualização da metodologia de NOT APPLICABLE quando ACCNTNG_CLSSFCTN IN ('2','4','41') | AK9: Metodologia / Conceito: 1) Somatório de provisões dentro de balanço que constam no mapa FINREP18/ NOPER 1 ano antes da data de referência. 2) De forma a coniliar com o FINREP, os campos de saldos têm como fonte o universo da LT (Tabela LT001 com as operações por conta contabilistica) que por sua vez tem como fonte a tabela de universo do FINREP (FR001). 3) A condição de N/A foi definida de modo a estar de acordo com os controlos corporativos. Independentemente de essa condição não constar no guia corporativo. Especificado/ Revisto por: CDO (Luis Capitão-Mor) Guia de conceitos da Corporação: De acordo com o pretendido no Guia, exceto o reporte da informação à data de inception quando o contrato nasceu entre o ano anterior e a data de reporte. | AL9: N/A | AM9: OK | AN9: N | AO9: Y | AP9: Contabilidade | AQ9: CONTABILIDADE | AR9: Rafael Pessoa | AS9: Em reunião com Luis Capitão Mor e Luísa Reparamos que atual um determinado contrato não existir no ano passado então o valor PRVS deve ser marcado como N/A. No entanto, fomos rever o Granular Tool onde encontramos a seguinte condição: "If the operation was granted between the last reporting and the current one, in this case, it should be reported the amount at the inception date of the transaction." No entanto, nos controlos corporativos temos um controlo que diz caso o contrato não exista no ano anterior o valor a marcar é o de N/A. O Luis sugeriu manter a marcação como N/A, ignorando a condição do GT para que deste modo haja coerência com o controlo e evitemos de criar campos de saldos à data de INCPTN de cada um dos contratos. | AU9: 1
A10: =_xlfn.CONCAT(Table2[[#This Row],[TABLE_NAME]],Table2[[#This Row],[COLUMN_NAME]]) -> INSTRUMENTACCMLTD_WRTFFS_INSTRMNT | B10: INSTRUMENT | C10: ACCMLTD_WRTFFS_INSTRMNT | D10: FLOAT 2 decimal places | E10: Y | F10: Y | G10: Y | H10: Y | I10: Y | J10: Y | K10: Y | L10: Accumulated write-offs | M10: Cumulative amount of principal and past due interest of any debt instrument that the institution is no longer recognising because they are considered uncollectible, independently of the portfolio in which they were included. Write-offs could be caused both by reductions in the carrying amount of financial assets recognised directly in profit or loss and by reductions in the amounts of the allowance accounts for credit losses set off against the carrying amount of financial assets. | N10: Cumulative amount of principal and past due interest of any debt instrument that the institution is no longer recognising because they are considered uncollectible, independently of the portfolio in which they were included. Write-offs could be caused both by reductions in the carrying amount of financial assets recognised directly in profit or loss and by reductions in the amounts of the allowance accounts for credit losses set off against the carrying amount of financial assets. | O10: TRUE | P10: 99999999999 | Q10: 11111111111 | S10: IN.090 | T10: N | U10: Y | V10: Y | W10: Y | X10: Y | Y10: Y | Z10: Y | AB10: CD_CAPTOOLS | AC10: FR001_UNIV_SALDO | AD10: MSALDO_FINAL | AE10: NVL (SUM((-1)*MSALDO_FINAL) ,0 ) WHERE FR001_UNIV_SALDO.[CONTA] = FR802_PL_CONTAS.CONTA AND COD_PLANO = [COD_PLANO] AND COMPOSICAO_VALOR = 'capital abatido' Notas: 1) A variável [CONTA] proveniente da tabela FR001_UNIV_SALDO varia entre CCONTAB_FINAL_IFRS, CCONTAB_FINAL_ST_SGPS, CCONTAB_FINAL_SGPS_CONS, CCONTAB_FINAL_CARGABAL consoante o nome_perimetro calculado. 2) A variável [COD_PLANO] proveniente da tabela FR802_PL_CONTAS varia entre BST_IND, ST_SGPS, SGPS_CONSOLIDADO, CARGABAL consoante o nome_perimetro calculado. | AF10: - | AG10: 1) Cruzar LT002_INSTRUMENT com FR001_UNIV_SALDO para obter os campos MSALDO_FINAL e contas contabílisticas: LT002_INSTRUMENT LEFT JOIN (SELECT * FROM FR001_UNIV_SALDO) ON INSTRMNT_ID = CONCAT(CEMPRESA, CBALCAO, CNUMECTA, ZDEPOSIT) 2) Cruzar os campos obtidos no passo anterior com o plano de contas através da tabela FR802_PL_CONTAS: (SELECT * FROM FR802_PL_CONTAS) ON [CONTA] = CONTA A variável [CONTA] proveniente da tabela FR001_UNIV_SALDO varia entre CCONTAB_FINAL_IFRS, CCONTAB_FINAL_ST_SGPS, CCONTAB_FINAL_SGPS_CONS, CCONTAB_FINAL_CARGABAL consoante o nome_perimetro calculado. | AI10: 44518 | AJ10: 08/11/2021: Metodologia de cálculo em revisão 10/11/2021: Atualização da especificação da metodologia de cálculo. 18/11/2021: Atualização da especificação da metodologia de cálculo (após implementação da parametrização) | AK10: Metodologia / Conceito: 1) Campo deve ser reportado segundo o saldo (FR001_UNIV_SALDO) das contas contabilisticas referentes a capital abatido (presente no campo COMPOSICAO_VALOR da FR802_PL_CONTAS). 2) As contas contabilisticas e COD_PLANO devem ser filtrados de acordo com o perimetro em análise. 3) O valor 'capital abatido' no campo COMPOSICAO_VALOR só entrou em produção em outubro de 2021. Especificado/ Revisto por: Contabilidade (Luisa de Sousa) Guia de conceitos da Corporação: De acordo com o pretendido no Guia. | AL10: Campo: montAbAtv Não está de acordo com o reportado na AnaCredit: A CRC utiliza como fonte de dados as ICs (sem ajustes), não sendo possível conciliar com o reportado pela área da contabilidade. | AM10: OK | AN10: N | AO10: Y | AP10: Contabilidade | AQ10: CONTABILIDADE | AR10: Rafael Pessoa | AS10: 09/11/2021 Reunião LCM: A FR07_ABATIDOS tem os movimentos e não os acumulados. Para o FinRep os Write-offs estão a ir por conta contabilistica, o que poderá causar entropia com os diferentes perimetros (Individual/consolidado). Luisa e Rafael: incluir um atributo para os write-offs na FR802 (plano de contas) enviar email : composição valor - "abatidos" | AU10: 1
A11: =_xlfn.CONCAT(Table2[[#This Row],[TABLE_NAME]],Table2[[#This Row],[COLUMN_NAME]]) -> INSTRUMENTACCNTNG_CLSSFCTN | B11: INSTRUMENT | C11: ACCNTNG_CLSSFCTN | D11: Code List | E11: Y | F11: Y | G11: Y | H11: Y | I11: Y | J11: Y | K11: Y | L11: Accounting portfolio | M11: Accounting portfolio where the instrument is recorded in accordance with the accounting standard – IFRS or national GAAP – under Regulation (EU) 2015/534 (ECB/2015/13) applied by the observed agent’s legal entity. | N11: Accounting portfolio where the instrument is recorded in accordance with the accounting standard – IFRS or national GAAP – under Regulation (EU) 2015/534 (ECB/2015/13) applied by the observed agent’s legal entity. | O11: TRUE | P11: 99999999999 | Q11: 11111111111 | S11: IN.062 | T11: Y | U11: Y | V11: Y | W11: Y | X11: Y | Y11: Y | Z11: Y | AB11: CD_CAPTOOLS CD_LOAN_TAPES_BCE | AC11: LT001_UNIV_OPER LT803_CODIGOS_LT | AD11: CARTEIRA_CONTABILISTICA VALOR_LT | AE11: VALOR_LT WHERE CAMPO_LT = 'ACCNTNG_CLSSFCTN' AND CARTEIRA_CONTABILISTICA = VALOR_ORIGEM Em caso de duplicação de valores por contrato deve ser seguida a sequinte prioritização*: 1) carteira contabilística atribuída às contas dentro do balanço em detrimento das contas fora do balanço (1ºValor_bruto_on, 2ºProvisao_on, 3ºValor_bruto_off, 4ºProvisao_off) 2) carteira contabilística com saldo absoluto superior * O campo deve estar alinhado com o SUBPORTFOLIO_ID | AF11: - | AG11: 1) Cruzar LT002_INSTRUMENT com LT001_UNIV_OPER para obter a carteira contabilistica do contrato: LT002_INSTRUMENT LEFT JOIN (SELECT * FROM LT001_UNIV_OPER) ON INSTRMNT_ID = CONCAT(CEMPRESA, CBALCAO, CNUMECTA, ZDEPOSIT) 2) Cruzar campo obtido no passo anterior com a tabela de parametrização LT803_CODIGOS_LT de modo a obter os códigos permitidos na code list: LEFT JOIN (SELECT * FROM LT803_CODIGOS_LT) ON VALOR_ORIGEM = CARTEIRA_CONTABILISTICA | AI11: 44679 | AJ11: 08/11/21: A metodologia de Not Applicable mantém-se igual à versão original (não foi aplicada a metodologia de default values proposta pela corporação). 29/11/2021: Atualização de nomenclatura da tabela de parametrização - em vez de TABELA_PARAMETRIZACAO, LT803_CODIGOS_LT. Sem impactos a nível de implementação. 28/04/2022: Atualização da metodologia de cálculo (Condição de prioridade das contas dentro do balanço). 15/09/2023: Adição de condições na tabela de parametrização LT803_CODIGOS_LT. Sem impactos a nível de implementação. | AK11: Metodologia / Conceito: 1) Campo deve ser reportado segundo a carteira contabilistica de cada contrato (presente no campo CARTEIRA_CONTABILISTICA da LT001_UNIV_OPER) e parametrizado através da tabela de parametrização LT803_CODIGOS_LT. 2) Denote-se que caso um contrato tenha uma exposição patrimonial e extrapatrimonial, é dada prioridade á patrimonial (metodologia aplicada no campo implementado da tabela LT001_UNIV_OPER). Especificado/ Revisto por: Contabilidade (Rafael Pessoa) Guia de conceitos da Corporação: De acordo com o pretendido no Guia exceto para exposições 100% off-balance, onde não foi especificada nenhuma condição de not aplicable. | AL11: Campo: classContbInst Não está de acordo com o reportado na AnaCredit: Caso um contrato tiver uma exposição patrimonial e extrapatrimonial, a CRC considera um código correspondente a "Não aplicável". Na Loan Tape é dada prioridade à exposição patrimonial. | AM11: NOK - Not aplicable não foi especificada | AN11: N | AO11: Y | AP11: Contabilidade | AQ11: CONTABILIDADE | AR11: Rafael Pessoa | AU11: 1
A12: =_xlfn.CONCAT(Table2[[#This Row],[TABLE_NAME]],Table2[[#This Row],[COLUMN_NAME]]) -> INSTRUMENTACCRD_INTRST_INSTRMNT | B12: INSTRUMENT | C12: ACCRD_INTRST_INSTRMNT | D12: FLOAT 2 decimal places | E12: Y | F12: Y | G12: N | H12: Y | I12: Y | J12: Y | K12: Y | L12: Accrued interest balance as recognised on the balance sheet | M12: The amount of accrued interest on loans at the reporting reference date as defined in Regulation (EU) No 1071/2013 (ECB/2013/33). In accordance with the general principle of accruals accounting, interest receivable on instruments should be subject to on-balance sheet recording as it accrues (i.e. on an accruals basis) rather than when it is actually received (i.e. on a cash basis). | N12: The amount of accrued interest on loans at the reporting reference date as defined in Regulation (EU) No 1071/2013 (ECB/2013/33). In accordance with the general principle of accruals accounting, interest receivable on instruments should be subject to on-balance sheet recording as it accrues (i.e. on an accruals basis) rather than when it is actually received (i.e. on a cash basis). | O12: TRUE | P12: 99999999999 | Q12: 11111111111 | S12: IN.063 | T12: N | U12: Y | V12: Y | W12: Y | X12: Y | Y12: Y | Z12: Y | AB12: CD_LOAN_TAPES_BCE | AC12: LT001_UNIV_OPER KT_CHAVES_LT | AD12: ACCRD_INTRST_INSTRMNT | AE12: NVL ( SUM(-1*JUROS_CORRIDOS) ,0 ) | AF12: - | AG12: 1. CRUZAR LT002_INSTRUMENT COM O TRADUTOR DE CHAVES LOAN TAPE: LT002_INSTRUMENT INNER JOIN KT_CHAVES_LT ON CONCAT(CEMPRESA,CBALCAO,CNUMECTA,ZDEPOSIT)=INSTRMNT_ID 2. CRUZAR COM LT001_UNIV_OPER PARA OBTER O CAMPO ACCRD_INTRST_INSTRMNT: LEFT JOIN (SELECT * FROM LT001_UNIV_OPER GROUP BY CEMPRESA,CBALCAO,CNUMECTA,ZDEPOSIT) ON CONCAT(CEMPRESA,CBALCAO,CNUMECTA,ZDEPOSIT) = CONCAT(CEMPRESA,CBALCAO,CNUMECTA,ZDEPOSIT) | AI12: 45873 | AJ12: 08/11/21: A metodologia de Not Applicable mantém-se igual à versão original (não foi aplicada a metodologia de default values proposta pela corporação). 07/04/2025: Campo passa a ser aprovisionado através da LT001. 04/08/2025: Alterada metodologia de calculo para NVL (SUM(-1*JUROS_CORRIDOS) ,0 ) para manter coerência com restantes campos de saldos | AK12: Metodologia / Conceito: 1) Campo deve ser reportado segundo o saldo (FR001_UNIV_SALDO) das contas contabilisticas referentes a juros/rendimentos a receber (presente no campo COMPOSICAO_VALOR da FR802_PL_CONTAS). 2) Esta tipologia de valor apenas é possível averiguar no plano de contas PCSB. Especificado/ Revisto por: Contabilidade (Luisa de Sousa) Guia de conceitos da Corporação: De acordo com o pretendido no Guia. | AL12: Campo: jurCorr Não está de acordo com o reportado na AnaCredit: A CRC utiliza como fonte de dados as Ics (sem ajustes), não sendo possível conciliar com o reportado pela área da contabilidade. | AM12: OK | AN12: N | AO12: Y | AP12: Contabilidade | AQ12: CONTABILIDADE | AR12: Rafael Pessoa | AS12: Validar esposição dos moyr1060, moyr1061, validar com rafa e tania Usar a CT004 os dias de incumprimento (preciso deste indicador para ir ao moyr?) | AU12: 1
A13: =_xlfn.CONCAT(Table2[[#This Row],[TABLE_NAME]],Table2[[#This Row],[COLUMN_NAME]]) -> INSTRUMENTAMNT_D_AT_MTRTY | B13: INSTRUMENT | C13: AMNT_D_AT_MTRTY | D13: FLOAT 2 decimal places | E13: N | F13: Y | G13: Y | H13: Y | I13: Y | J13: Y | K13: Y | L13: Amount due at the legal final maturity date | M13: Total amount of principal repayment to be paid at the final legal maturity date (i.e. DT_LGL_FNL_MTRTY), i.e. amount of last instalment at maturity date. | N13: Total amount of principal repayment to be paid at the final legal maturity date (i.e. DT_LGL_FNL_MTRTY), i.e. amount of last instalment at maturity date. | O13: TRUE | P13: 99999999999 | Q13: 11111111111 | S13: IN.064 | T13: N | U13: Y | V13: Y | W13: Y | X13: Y | Y13: Y | Z13: N | AB13: CD_LOAN_TAPES_BCE | AC13: LT002_INSTRUMENT | AD13: PYMNT_FRQNCY OTSTNDNG_NMNL_AMNT_INSTRMNT DT_LGL_FNL_MTRTY | AE13: CASE WHEN PYMNT_FRQNCY= '8' THEN OTSTNDNG_NMNL_AMNT_INSTRMNT/(CASE WHEN ROUND(DATEDIFF(DT_LGL_FNL_MTRTY,REF_DATE)/30,0) <= 0 THEN 1 ELSE ROUND(DATEDIFF(DT_LGL_FNL_MTRTY,REF_DATE)/30,0) END) WHEN PYMNT_FRQNCY= '1' THEN OTSTNDNG_NMNL_AMNT_INSTRMNT/(CASE WHEN ROUND(DATEDIFF(DT_LGL_FNL_MTRTY,REF_DATE)/365,0) <= 0 THEN 1 ELSE ROUND(DATEDIFF(DT_LGL_FNL_MTRTY,REF_DATE)/365,0) END) WHEN PYMNT_FRQNCY= '18' THEN OTSTNDNG_NMNL_AMNT_INSTRMNT/(CASE WHEN ROUND(DATEDIFF(DT_LGL_FNL_MTRTY,REF_DATE)/90,0) <= 0 THEN 1 ELSE ROUND(DATEDIFF(DT_LGL_FNL_MTRTY,REF_DATE)/90,0) END) WHEN PYMNT_FRQNCY= '19' THEN OTSTNDNG_NMNL_AMNT_INSTRMNT/(CASE WHEN ROUND(DATEDIFF(DT_LGL_FNL_MTRTY,REF_DATE)/180,0) <= 0 THEN 1 ELSE ROUND(DATEDIFF(DT_LGL_FNL_MTRTY,REF_DATE)/180,0) END) WHEN PYMNT_FRQNCY IN ('4','22') THEN OTSTNDNG_NMNL_AMNT_INSTRMNT END SE PELO MENOS UM DOS CAMPOS FONTE TIVER INFORMADO COM O VALOR DA COLUNA NULLABLE, ENTÃO VALOR DA COLUNA NULLABLE | AF13: SE PELO MENOS UM DOS CAMPOS FONTE TIVER O VALOR DE NOT APPLICABLE | AG13: UTILIZAR OS CAMPOS PYMNT_FRQNCY, OTSTNDNG_NMNL_AMNT_INSTRMNT E DT_LGL_FNL_MTRTY PARA O CÁLCULO | AI13: 45754 | AJ13: 05/07/2023: Adição de condição de metodologia de NOT APPLICABLE 07/04/2025: Utilizou-se uma proxy para o cálculo do campo utilizado a frequência de pagamento - proxy definida com Luis CapitãoMor | AK13: Metodologia / Conceito: 1) Com base nos dados existentes em sistema, apenas é possível calcular a ultima prestação do crédito, i.e. na data de maturidade do contrato, quando os mesmos têm uma amortização do tipo "bullet" (TYP_AMRTSTN = '4'); 2) Para a restante carteira de crédito, assumir o valor da coluna "NULLABLE" 3) Esta informação deve ser aprovisionada apenas para os produtos de Empréstimos, Leasing, Linhas de crédito e Garantias (definidos através do campo TYP_INSTRMNT) - Indicado pela Corporação por e-mail no dia 03/07/2023. Especificado/ Revisto por: CDO (Luis Capitão-Mor) Guia de conceitos da Corporação: De acordo com o pretendido no Guia apenas para contratos com tipo de amortização bullet. | AL13: N/A | AM13: WIP | AN13: Y | AO13: N | AP13: Portfolio Instrumentos | AQ13: PORTFOLIO MANAGER | AR13: Marino Peres | AU13: 1
A14: =_xlfn.CONCAT(Table2[[#This Row],[TABLE_NAME]],Table2[[#This Row],[COLUMN_NAME]]) -> INSTRUMENTANNLSD_AGRD_RT | B14: INSTRUMENT | C14: ANNLSD_AGRD_RT | D14: FLOAT 6 decimal places | E14: Y | F14: Y | G14: Y | H14: N | I14: Y | J14: Y | K14: Y | L14: Interest rate at the reference date | M14: Annualised agreed rate or narrowly defined interest rate at reference date in accordance with Regulation (EU) No 1072/2013 of the European Central Bank (ECB/2013/34). | N14: Annualised agreed rate or narrowly defined interest rate at reference date in accordance with Regulation (EU) No 1072/2013 of the European Central Bank (ECB/2013/34). | O14: TRUE | P14: 99999999999 | Q14: 11111111111 | S14: IN.125 | T14: Y | U14: Y | V14: Y | W14: Y | X14: Y | Y14: Y | Z14: Y | AB14: CD_ALM | AC14: AL029_CNT_CORE_M | AD14: TX_CONTRATO_ACT | AE14: TX_CONTRATO_ACT/100 Se duplicações de chave do universo com chave ALM então: 1. Escolher o registo de ALM que tenha origem <> "MANUAL" 2. Escolher o registo de ALM com mais campos preenchidos 3. Escolher o registo de ALM com maior saldo: (-(MON_CAP_ST1_C0 + MON_CAP_ST1_C1 + MON_CAP_ST1_CO + MON_CAP_ST1_VIVO + MON_CAP_ST2_C0 + MON_CAP_ST2_C1 + MON_CAP_ST2_CO + MON_CAP_ST2_VIVO + MON_CAP_ST3_C0 + MON_CAP_ST3_C1 + MON_CAP_ST3_CO + MON_CAP_ST3_VIVO + MON_JUR_ST1 + MON_JUR_ST1_C0 + MON_JUR_ST1_C1 + MON_JUR_ST1_CO + MON_JUR_ST2 + MON_JUR_ST2_C0 + MON_JUR_ST2_C1 + MON_JUR_ST2_CO + MON_JUR_ST3 + MON_JUR_ST3_C0 + MON_JUR_ST3_C1 + MON_JUR_ST3_CO + MON_COMISSOES + MON_DESPESAS + MON_IMPARID_PATRI + MON_IMPARIDADE_EXTRA + MON_EXTRAPATRI)) | AF14: - | AG14: 1) Replicar passo 1) do campo INTRST_RT_RST_FRQNCY 2) Replicar passo 2) do campo INTRST_RT_RST_FRQNCY 3) Replicar passo 4) do campo INTRST_RT_RST_FRQNCY | AI14: 44672 | AJ14: 04/11/21: A metodologia de Not Applicbale mantém-se igual à versão original (não foi aplicada a metodologia de default values proposta pela corporação). 28/04/2022: Alteração da metodologia de cáclulo para dividir o campo por 100 por forma obter a taxa entre 0 e 1 e adição de campos no cálculo do saldo ALM para eliminar duplicados na duplicação de chaves. | AK14: Metodologia / Conceito: 1) Conceito previsto nas tabelas de ALM 2) Metodologia a aplicar para duplicação de chaves (após cruzamento com tradutores): 2.1. Escolher o registo de ALM que tenha origem <> "MANUAL" 2.2. Escolher o registo de ALM com mais campos preenchidos 2.3. Escolher o registo de ALM com maior saldo Especificado/ Revisto por: Risco de Mercado (Cláudia Correia) Guia de conceitos da Corporação: Análise não realizada. | AL14: Campo: TAA? Não está de acordo com o reportado na AnaCredit: CRC utiliza fonte distinta da ALM. | AM14: Análise não realizada | AN14: N | AO14: Y | AP14: Portfolio Instrumentos | AQ14: RISCO DE MERCADO / ALM | AR14: Cláudia Correia | AS14: [Reunião LCM 07-06]: O Rafael Pessoa indicou-nos que esta informação está a ir a vazio no FinRep pelo que para o Loan Tape também irá a vazio | AU14: 1
A15: =_xlfn.CONCAT(Table2[[#This Row],[TABLE_NAME]],Table2[[#This Row],[COLUMN_NAME]]) -> INSTRUMENTARRRS_INSTRMNT | B15: INSTRUMENT | C15: ARRRS_INSTRMNT | D15: FLOAT 2 decimal places | E15: Y | F15: Y | G15: Y | H15: Y | I15: Y | J15: Y | K15: Y | L15: Total exposure in arrears | M15: Aggregated amount of the principal, interest and any fee payment outstanding at the reporting date, which is contractually due and has not been paid (past due). | N15: Aggregated amount of the principal, interest and any fee payment outstanding at the reporting date, which is contractually due and has not been paid (past due). | O15: TRUE | P15: 99999999999 | Q15: 11111111111 | S15: IN.091 | T15: N | U15: Y | V15: Y | W15: Y | X15: Y | Y15: Y | Z15: Y | AB15: CD_LOAN_TAPES_BCE | AC15: TMP_BCE_LT_MOYR | AD15: ARRRS_INSTRMNT | AE15: NVL(SUM(ARRRS_INSTRMNT),0) | AG15: CONSULTAR DOCUMENTO BS_TABELAS_TEMPORÁRIAS_LOAN_TAPE.XLSX (TMP_BCE_LT_MOYR) UNIVERSO INSTR LEFT JOIN (SELECT * FROM CD_CAPTOOLS.KT_CHAVES_FINREP ON CEMPRESA_FR, CBALCAO_FR, CNUMECTA_FR, ZDEPOSIT_FR) LEFT JOIN (SELECT * FROM TMP_BCE_LT_MOYR WHERE DATA_DATE_PART = REF_DATE) ON CEMPRESA, CBALCAO, CNUMECTA, ZDEPOSIT GROUP BY CEMPRESA_FR, CBALCAO_FR, CNUMECTA_FR, ZDEPOSIT_FR | AI15: 45779 | AJ15: 30/04/2025: Sem necessidade de re-especificação (controlos Corporativos justificados) Reunião Luísa Sousa e Rui Sarroeira: verifica-se que a Contabilidade e CRC reporta apenas contratos vencidos > 30 dias; no entanto, na Loan Tape e FINREP, é considerado default a partir do momento 0 | AK15: Metodologia / Conceito: A informação de reporte de cálculo de contabilidade é apresentada com uma granularidade distinta do universo esperado na Loan Tape para o BCE. Deste modo, são necessários tratamentos ao nível da chave de contabilidade anteriores ao mapeamento com o universo da Loan Tape: Step 1) TMP_BCE_LT_MOYR60: Tratamento da informação de histórico de capital vencido na moeda local - Com o objetivo de manter a coerência com a restante informação reportada, o universo de contratos na tabela MOYR1060 deve resultar dos contratos comuns entre (1) A tabela filtrada pelas seguintes características: csubcart <> 'A' ; csubprod <> 'MOR'; cgrupoic not in ('31','91'), (2) A tabela filtrada pelo máximo das data_date_part, agrupadas pelo último dia do mês; - Com o objetivo de manter a coerência com a restante informação reportada, o universo de contratos na tabela CAMBIOS deve resultar dos contratos comuns entre (1) A tabela filtrada pelas seguintes características: zseqcamb = 99; ctbcamb = 'F' ; camarca = 'BT' ; cdivisa = '0', (2) A tabela filtrada pelo máximo das data_date_part, agrupadas pelo último dia do mês; - Finalmente, de forma a obter o montante de capital em incumprimento, são somadas, por cada chave, as várias relações entre os valores obtidos nos campos MOYR1N60_MSLDIRR e TCMBME das tabelas MOYR1060 e CAMBIOS, respetivamente. Step 2) TMP_BCE_LT_MOYR61: Tratamento da informação de histórico de juros vencidos na moeda local - Com o objetivo de manter a coerência com a restante informação reportada, o universo de contratos na tabela MOYR1061 deve resultar dos contratos comuns entre (1) A tabela filtrada pelas seguintes características: csubcart <> 'A' ; csubprod <> 'MOR'; cgrupoic not in ('31','91'); and not (cnaturic = 'I' and (csubprod <> 'MOR'; clasrisc not in ('0','1'); codprov in ('090','***','111',''))); and not (cnaturic in ('D','M','S'); MOYR1N60_CLASRISC NOT IN ('0','1')), (2) A tabela filtrada pelo máximo das data_date_part, agrupadas pelo último dia do mês; - Com o objetivo de manter a coerência com a restante informação reportada, o universo de contratos na tabela CAMBIOS deve resultar dos contratos comuns entre (1) A tabela filtrada pelas seguintes características: zseqcamb = 99; ctbcamb = 'F' ; camarca = 'BT' ; cdivisa = '0', (2) A tabela filtrada pelo máximo das data_date_part, agrupadas pelo último dia do mês; - Finalmente, de forma a obter o montante de capital em incumprimento, são somadas, por cada chave, as várias relações entre os valores obtidos nos campos MOYR1N61_MSLDIRR e TCMBME das tabelas MOYR1060 e CAMBIOS, respetivamente. Step 3) TMP_BCE_LT_MOYR_IFIC: Tratamento da informação de histórico de capital e juros vencidos na moeda local à data de referência para IFIC - Com o objetivo de manter a coerência com a restante informação reportada, o universo de contratos na tabela CT622_MOYR_IFIC deve resultar dos contratos comuns entre (1) A tabela sem qualquer filtro, (2) A tabela filtrada pelo máximo das ref_date, agrupadas pelo último dia do mês; - Finalmente, de forma a obter o montante de capital e juros em incumprimento, são somadas, por cada chave, os valores obtidos no campo VENCIDO_CTRVLR. Step 4) TMP_BCE_LT_MOYR: Informação de histórico de capital e juros vencidos na moeda local - Universo de contratos a considerar para a informação histórica de capital e juros vencidos com base nas tabelas anteriormente criadas; - Finalmente, de forma a obter o montante de capital e juros em incumprimento, são somadas, por cada chave, os valores que resultem do campo criado nas tabelas anteriores. Especificado/ Revisto por: Contabilidade Guia de conceitos da Corporação: De acordo com o pretendido no Guia. | AL15: 0 | AM15: WIP | AN15: N | AO15: N | AP15: NPE | AQ15: CONTABILIDADE | AR15: Rafael Pessoa | AU15: 1
A16: =_xlfn.CONCAT(Table2[[#This Row],[TABLE_NAME]],Table2[[#This Row],[COLUMN_NAME]]) -> INSTRUMENTARRRS_INSTRMNT_12M | B16: INSTRUMENT | C16: ARRRS_INSTRMNT_12M | D16: FLOAT 2 decimal places | E16: N | F16: Y | G16: N | H16: N | I16: Y | J16: Y | K16: Y | L16: Highest total exposure in arrears in the last 12 months before the reference date | M16: Highest aggregated amount of the principal, interest and any fee payment outstanding at a period of 12 months before the reference date, which is contractually due and has not been paid (past due). | N16: Highest aggregated amount of the principal, interest and any fee payment outstanding at a period of 12 months before the reference date, which is contractually due and has not been paid (past due). | O16: TRUE | P16: 99999999999 | Q16: 11111111111 | S16: IN.092 | T16: N | U16: Y | V16: Y | W16: Y | X16: Y | Y16: Y | Z16: Y | AB16: CD_LOAN_TAPES_BCE | AC16: TMP_BCE_LT_MOYR | AD16: ARRRS_INSTRMNT | AE16: NVL(SUM(ARRRS_INSTRMNT),0) | AF16: - | AG16: Consultar documento BS_Tabelas_Temporárias_Loan_Tape.xlsx (TMP_BCE_LT_MOYR) UNIVERSO INSTR LEFT JOIN (SELECT * FROM CD_CAPTOOLS.KT_CHAVES_FINREP ON CEMPRESA_FR, CBALCAO_FR, CNUMECTA_FR, ZDEPOSIT_FR) LEFT JOIN (SELECT * FROM TMP_BCE_LT_MOYR WHERE DATA_DATE_PART = REF_DATE) ON CEMPRESA, CBALCAO, CNUMECTA, ZDEPOSIT GROUP BY CEMPRESA_FR, CBALCAO_FR, CNUMECTA_FR, ZDEPOSIT_FR | AI16: 44404 | AK16: No caso de não estarem reunidas as condições para apurar o histórico nos últimos 12 meses (Consultar documento BS_Tabelas_Temporárias_Loan_Tape.xlsx), considera-se o valor da coluna "NULLABLE" | AL16: N/A | AM16: WIP | AN16: N | AO16: N | AP16: NPE | AQ16: CONTABILIDADE | AR16: Rafael Pessoa | AS16: ver rsv133 sa1 e sa2 | AU16: 1
A17: =_xlfn.CONCAT(Table2[[#This Row],[TABLE_NAME]],Table2[[#This Row],[COLUMN_NAME]]) -> INSTRUMENTASST_SCRT_CLSS | B17: INSTRUMENT | C17: ASST_SCRT_CLSS | D17: Code List | E17: Y | L17: Asset securitisation class | M17: To be reported if the instrument is a securitisation or covered bond. | N17: To be reported if the instrument is a securitisation or covered bond. | O17: TRUE | P17: 99999999999 | Q17: 11111111111 | S17: IN.155 | T17: N | U17: N | V17: N | W17: N | X17: N | Y17: N | Z17: Y | AB17: CD_LOAN_TAPES_BCE | AC17: TMP_BCE_LT_MOYR | AD17: ARRRS_INSTRMNT | AE17: NVL ( MAX(ARRRS_INSTRMNT), 0) | AF17: - | AG17: Consultar documento BS_Tabelas_Temporárias_Loan_Tape.xlsx (TMP_BCE_LT_MOYR) UNIVERSO INSTR LEFT JOIN (SELECT * FROM CD_CAPTOOLS.KT_CHAVES_FINREP ON CEMPRESA_FR, CBALCAO_FR, CNUMECTA_FR, ZDEPOSIT_FR) LEFT JOIN (SELECT * FROM TMP_BCE_LT_MOYR WHERE DATA_DATE_PART BETWEEN REF_DATE-12MESES AND REF_DATE GROUP BY CEMPRESA, CBALCAO, CNUMECTA, ZDEPOSIT) ON CEMPRESA, CBALCAO, CNUMECTA, ZDEPOSIT GROUP BY CEMPRESA_FR, CBALCAO_FR, CNUMECTA_FR, ZDEPOSIT_FR | AI17: 44602 | AJ17: 04/11/21: A metodologia de Not Applicbale mantém-se igual à versão original (não foi aplicada a metodologia de default values proposta pela corporação). 10/02/2022: Foi adicionado um NVL à metodologia de cálculo. | AK17: Metodologia / Conceito: 1) Campo previsto apenas para títulos. Atualmente não existe no banco os diferentes tipos de titularização previstos pela codelist. Foram apenas mapeadas as tipologias que existem atualmente. Especificado/ Revisto por: CDO (Luís Capitão-Mor) Guia de conceitos da Corporação: Conceito não existente no Guia. | AL17: Atualmente a CRC não reporta informação de debt securities. | AM17: Conceito não existente no Guia | AN17: N | AO17: Y | AP17: Debt Securities | AQ17: RISCO DE MERCADO / ALM | AR17: Cláudia Correia | AU17: 1
A18: =_xlfn.CONCAT(Table2[[#This Row],[TABLE_NAME]],Table2[[#This Row],[COLUMN_NAME]]) -> INSTRUMENTBRCHD_CVNNTS | B18: INSTRUMENT | C18: BRCHD_CVNNTS | D18: VARCHAR2(255) | E18: N | F18: Y | G18: Y | H18: Y | I18: N | J18: N | K18: N | L18: Breached covenants | M18: Breached covenants separated by comma (,). | N18: Breached covenants separated by comma (,). | O18: TRUE | P18: MISS | Q18: N/A | S18: IN.015 | T18: N | U18: Y | V18: Y | W18: Y | X18: Y | Y18: N | Z18: N | AB18: CD_LOAN_TAPES_BCE | AC18: LT604_HOLIS_MAN | AD18: VALOR | AE18: NOTA: PARA TODO O UNIVERSO O CAMPO DEVE SER REPORTADO COM 'N/A' | AF18: - | AG18: - | AI18: 45849 | AJ18: 11/07/25: Alteração da metodologia de cálculo do campo('N/A' ao invés de 'MISS'), de modo a garantir consistência com guidlines Corporativas. Adicionalmente, este campo passa a ser populado através da tabela holística. | AK18: Metodologia / Conceito: 1) Relativamente a papel comercial, os responsáveis por monitorizar o incumprimento das cláusulas dos contratos são os Gestores. Esta monitorização não é realizada através de qualquer sistema de informação. (Daniel Xarepe) 2) Para a restante carteira de crédito, também não existe informação nas bases de dados do Banco. (Luis Bastos) 3) Campo deve ser reportado como "sem informação", i.e., com o valor da coluna NULLABLE. Especificado/ Revisto por: Risco de Crédito + Controlo CIB (Luis Bastos + Daniel Xarepe) Guia de conceitos da Corporação: Análise não realizada. | AL18: N/A | AM18: Análise não realizada | AN18: N | AO18: Y | AP18: Portfolio Instrumentos | AQ18: INFORMAÇÃO DE RISCOS | AR18: Marino Peres | AU18: 1
A19: =_xlfn.CONCAT(Table2[[#This Row],[TABLE_NAME]],Table2[[#This Row],[COLUMN_NAME]]) -> INSTRUMENTCCF | B19: INSTRUMENT | C19: CCF | D19: FLOAT 6 decimal places | E19: N | F19: Y | G19: Y | H19: Y | I19: Y | J19: Y | K19: Y | L19: Credit conversion factor (CCF) according to CRR | M19: Credit conversion factor according to regulation (EU) No 575/2013. | N19: Credit conversion factor according to regulation (EU) No 575/2013. | O19: TRUE | P19: 99999999999 | Q19: 11111111111 | S19: IN.065 | T19: N | U19: Y | V19: Y | W19: Y | X19: Y | Y19: Y | Z19: N | AB19: CD_LOAN_TAPES_BCE | AC19: BCE_LT_INSTR_CAP | AD19: CCF | AE19: CCF | AF19: - Se o campo auxiliar FLG_CONS_CAP=0 (utilizado na definição do universo de capital) | AG19: 1) Cruzar LT002_INSTRUMENT com tabela temporária BCE_LT_INSTR_CAP para o perimetro em análise: LT002_INSTRUMENT LEFT JOIN (SELECT * FROM BCE_LT_INSTR_CAP) ON INSTRMNT_ID = CHAVE_FR Consultar documento BS_Tabelas_Temporárias_Loan_Tape.xlsx (BCE_LT_INSTR_CAP) | AI19: 45915 | AJ19: 27/10/2021 Reunião LCM: Eliminação da regra "'- Se a entidade não pertencer ao universo de Capital (BCE_LT_INSTR_CAP)" na Metodologia de NOT APPLICABLE. 21/12/2023 Reunião LCM: Adição de condições de NOT APPLICABLE na sequência da análise dos controlos da Corporação e completude. 15/09/2025 Reunião LCM: Para o perímetro Individual IDComb na CT020, deve ser filtrada pelo perímetro Individual Corporativo quando a data de referência (REF_DATE) for anterior a 30 de abril de 2025. A partir dessa data (inclusive), deve ser filtrada pelo perímetro Individual IDComb. | AK19: Metodologia / Conceito: A informação de reporte de cálculo de capital é apresentada com uma granularidade distinta do universo esperado na Loan Tape para o BCE. Deste modo, são necessários tratamentos ao nível da chave de capital anteriores ao mapeamento com o universo da Loan Tape: Step 1) TMP_BCE_LT_INSTR_CAP: Tratamento da informação por chave de capital (id_capital_perimetros, s1emp, contra1) - Com o objetivo de fazer face às orientações do BCE relativamente à informação reportada, o universo de contratos da ct013_rwa_princ deve ser filtrado pelas seguintes características: (1) Universo com método de cálculo de capital Standard e IRB - subtipo_risco in (1.1; 1.2; 1.3; 1.4; 1.5; 1.6; 1.7; 1.8; 1.9; 1.13), (2) Universo reportado pelas regulações específicas da área de Capital (ex. COREP) - flag_cons_cap = 1, (3) Universo que concilia contabilisticamente - flag_conc_contab = 1 e (4) exercicio = “REAL”; - De seguida, e uma vez que o mesmo contrato de capital pode ter múltiplos registos e ser calculado em 2 métodos distintos, foram realizadas transformações para os diferentes campos de modo a obter um registo único por chave de capital (nota i); - Finalmente, para cada chave de capital, foram filtrados os id_capital_perimetros que pertencem ao perímetro em análise (através da tabela ct020_rwa_per); Step 2) BCE_LT_INSTR_CAP: Tratamento da informação por chave FINREP (chave_fr = instrmnt_id) - Foi realizado o cruzamento com os tradutores de modo a mapear a chave do Universo da Loan Tape (chave FINREP) com a de capital (obtida no Step 1); - Uma vez que uma chave FINREP pode estar relacionada com múltiplas de capital e vice-versa, foram realizadas transformações para os diferentes campos de modo a obter um registo único por chave FINREP; - Para os campos de atributos, caso um contrato de com chave de finrep esteja relacionado com múltiplas de capital deve ser escolhido o registo de acordo com as seguintes ordens de prioridade: 1º Se a chave FINREP contiver chaves de capital com FLG_IDCTOORI for 1 e 0 escolher registo onde FLG_IDCTOORI = 0; 2º Se a chave FINREP contiver chaves de capital com produtos de estruturas e diferente de estruturas (id_prod = 47) então escolher registo onde id_prod <> 47 (diferente de estruturas) 3º Se a chave FINREP contiver chaves de capital com 2 RWA_MTHD escolher registo onde RWA_MTHD = '1' (IRB) 4º (nota ii) Especificamente sobre o campo CCF (referente à exposição extrapatrimonial): Nota i: Foi calculado o CCF máximo dentro do mesmo método e escolhido o referente ao que foi utilizado em cálculo IRB; Nota ii: Foi calculada a média ponderada pela EAD. Especificado/ Revisto por: Capital + CDO (Susana Arrochinho + Luis Capitão-Mor) Guia de conceitos da Corporação: Não está de acordo com o pretendido no Guia, uma vez que 1) porque a granularidade é diferente entre a BDR e a Loan Tape, os resultados esperados podem diferir (exemplo: para contratos em IRB e STD considera-se o CCF de IRB). Para contratos da Loan Tape que mapeiam para 2 de IRB/STD calcula-se a média ponderada. Adicionalmente, 2), no guia considera-se o valor de not applicable para contratos com exposição 100% patrimonial. | AL19: N/A | AM19: OK | AN19: N | AO19: N - rever se mantemos em tabela temporária ou no DDR (processo) | AP19: Capital | AQ19: CAPITAL | AR19: Helder Gomes | AS19: 1. Enviar e-mail a Jesus a confirmar se existe informação de data na BDR ---> E9952_FECCALI | AU19: 1
A20: =_xlfn.CONCAT(Table2[[#This Row],[TABLE_NAME]],Table2[[#This Row],[COLUMN_NAME]]) -> INSTRUMENTCHNNL_ORGNTN | B20: INSTRUMENT | C20: CHNNL_ORGNTN | D20: Code List | E20: N | F20: N | G20: N | H20: N | I20: Y | J20: Y | K20: Y | L20: Channel of origination | M20: Description of the loan origination channel. | N20: Description of the loan origination channel. | O20: TRUE | P20: 99999999999 | Q20: 11111111111 | S20: IN.016 | T20: N | U20: Y | V20: Y | W20: Y | X20: Y | Y20: Y | Z20: N | AB20: Universo 1 - CD_LOGS Universo 2 - por aplicação de produto de crédito - Consultar documentos word ("Metodologia_Cálculo_CHNLL_ORGNTN" e "Metodologia_Cruzamento_CHNLL_ORGNTN" de Cálculo na pasta 04 - Especificação | AC20: Universo 1 - LOG_OPERATION Universo 2 - por aplicação de produto de crédito - Consultar documentos word ("Metodologia_Cálculo_CHNLL_ORGNTN" e "Metodologia_Cruzamento_CHNLL_ORGNTN" de Cálculo na pasta 04 - Especificação | AD20: - | AE20: Universo 1. Operações CrediSimples CASE WHEN CODIGOINTERACAO = 'CEM08' AND DADO13 = 'Contratado' AND DADO20 = 'NBE' THEN 2 ELSE Valor da coluna Nullable WHERE DATA_DATE_PART<= DT_RFRNC Universo 2. Por aplicação de produto de crédito: Consultar documento word "Metodologia_Cálculo_CHNLL_ORGNTN" Universo 3. Contas DO Consultar documento word "Metodologia_Cálculo_CHNLL_ORGNTN" NOTA: O processo de aprovisionamento deverá corresponder a um NVL (Universo 1, Universo 2, Universo 3) | AF20: - | AG20: NOTA: A tabela LOG_OPERATION deve ser filtrada por todas as DATA_DATE_PART inferiores à data de referência 1) Cruzar LT002_INSTRUMENT com tradutor de chaves FINREP LT002_INSTRUMENT LEFT JOIN (SELECT * FROM KT_CHAVES_FINREP) ON INSTRMNT_ID = CONCAT(CEMPRESA_FR, CBALCAO_FR, CNUMECTA_FR, ZDEPOSIT_FR) 2) Cruzar chave MASTER obtida no passo anterior com tabela LOG_OPERATION para obter campos CODIGOINTERACAO e as colunas necessárias para cada tipo de produto: LEFT JOIN (SELECT * FROM LOG_OPERATION) ON CONCAT(CBALCAO, CNUMECTA, ZDEPOSIT) = CONCAT(DADO15, '000000000000000') Universo 2. Por aplicação de produto de crédito: Consultar documento word "Metodologia_Cálculo_CHNLL_ORGNTN" Universo 3. Contas DO Consultar documento word "Metodologia_Cálculo_CHNLL_ORGNTN" na pasta "04 - Especificação" | AI20: 45303 | AJ20: 12/05/2022: Foi atualizada a especificação 24/06/2022: Foi atualizada a especificação para contemplar as paremetrizações anteriormente realizadas por tabela de parametrização (Sem impactos na implementação). 01/07/2022: Atualização da metodologia de cálculo para inclui condição da data_date_part <= dt_rfrnc 05/01/2023: Especificação para o universo de contratos cujo canal de contratação será definido pelas aplicações de produto de crédito 12/01/2024: Especificação para o universo de contratos não foi preenchido pelos processos anteriores e corresponde a uma DO. | AK20: Metodologia / Conceito: 1) WIP Especificado/ Revisto por: CDO (Luis Capitão-Mor) Guia de conceitos da Corporação: De acordo com o pretendido no Guia. | AL20: N/A | AM20: WIP | AN20: Y | AO20: N | AP20: Portfolio Instrumentos | AQ20: CANAIS | AR20: Ângelo Sarmento | AS20: Notas: Não existe informação centralmente na aplicação de empréstimos. O que podemos fazer? Ir por produto? Qual é a tabela que marca quando se contrata um emprestimo/ deposit/ etc... Pedro Vicente - Área de Canais Angelo Miguel Loureiro Sarmento - Área de Canais Luis Barata ou Cladia Correia - em ALM poderá existir Pedro Vicente/ Angelo Miguel - Todos os contratos de canais empresas são contratados (e cruzar com a informação é complicado porque depende do produto - ex. credito simples é por proposta, mas os restantes teria-se de ver) Romeu Viegas ou Rita Brito Grito Oliveira (Eles dizem que todos os dias enviam a info em Batch e que isto está no DL e tem todos os prdoutos contartados) - Em que tabelas está no DL É necessário ter acesso às schemma e rever os campos com o Ângelo Miguel | AT20: Raquel Ferreira - Existem tabelas na DW que já tratam a informação dos logs | AU20: 1
A21: =_xlfn.CONCAT(Table2[[#This Row],[TABLE_NAME]],Table2[[#This Row],[COLUMN_NAME]]) -> INSTRUMENTCMLTV_RCVRS_SNC_DFLT_INSTRMNT | B21: INSTRUMENT | C21: CMLTV_RCVRS_SNC_DFLT_INSTRMNT | D21: FLOAT 2 decimal places | E21: Y | F21: Y | G21: Y | H21: N | I21: Y | J21: Y | K21: Y | L21: Cumulative recoveries since default | M21: The total amount recovered since the date of default. | N21: The total amount recovered since the date of default. | O21: TRUE | P21: 99999999999 | Q21: 11111111111 | S21: IN.093 | T21: N | U21: Y | V21: Y | W21: Y | X21: Y | Y21: Y | Z21: Y | AB21: FIXO | AC21: FIXO | AD21: FIXO | AE21: Valor da coluna "NULLABLE" | AF21: - Se contrato não está em default (DFLT_STTS_INSTRMNT = '14'). | AG21: - | AI21: 44601 | AJ21: 09/02/2021: Atualização da especificação da metodologia de cálculo. 04/05/2023: Pedido de ingesta JM_ACUMTO_BDI e carregamento de histórico. | AK21: Metodologia / Conceito: 1) Informação de todas as recuperações sobre o contrato desde a entrada em default (apenas aplicável a contratos que estão em default - DFLT_STTS_INSTRMNT <> 14). Esta informação não está disponivel de forma direta em sistema (inclusivamente na área de recuperações). 2) Campo deve ser reportado como "sem informação", i.e., com o valor da coluna NULLABLE; 3) A futuro, devem ser considerados os COPERACS/ OBBs utilizados pela área de contabilidade para descriminar as tipologias de movimentos por contrato: capital, juros, pagamento de seguros, etc. 4) Adicionalmente, deve ser averiguada a possibilidade de utilizar a BDI para reporte desta informação (registo de perdas e recuperações). Especificado/ Revisto por: CDO (Luis Capitão-Mor) Guia de conceitos da Corporação: Não está de acordo com o pretendido no guia. ("All recoveries since the date of default are taken into account, irrespective of their source; for example, this data attribute takes into account any voluntary cash repayments, any proceeds from liquidating collateral, amounts received as a result of calling guarantees, proceeds from selling the instrument, etc., provided that they were received during the period of default”) | AL21: Campo: recAcumIncump Não está de acordo com o reportado na AnaCredit: CRC reporta de acordo com movimentos contabilisticos - somatório do valor dos movimentos vezes (-1) do campo VMOV_PROV da DWT1080_HIST_PROVISOES para os seguintes ‘Tipos de movimento de recuperação com o campo CTIPMOV (CMOT_PROV) = 2,6,7,9,D,E,F; quando o campo IUTILPRV (CUTIL_PROV) = '2 - recuperação'; na tabela TCT63-MMOVIM que na DW está na DWT1080_HIST_PROVISOES. | AM21: WIP | AN21: Y | AO21: N | AP21: Amortizações | AQ21: RECUPERAÇÕES | AR21: Rui Querido | AT21: Notas: OSI: José Duarte: Valor de write-offs (que na prática não são recuperações) Catarina Caroço / Rui querido: Não têm essa informação. Ricardo Lopes da Costa Jorge: Sem resposta | AU21: 1
A22: =_xlfn.CONCAT(Table2[[#This Row],[TABLE_NAME]],Table2[[#This Row],[COLUMN_NAME]]) -> INSTRUMENTCMMTMNT_INCPTN_INSTRMNT | B22: INSTRUMENT | C22: CMMTMNT_INCPTN_INSTRMNT | D22: FLOAT 2 decimal places | E22: Y | F22: Y | G22: Y | H22: N | I22: Y | J22: Y | K22: Y | L22: Commitment amount at inception | M22: Observed agent’s maximum exposure to credit risk on the inception date of the instrument, without taking into account any protection held or other credit enhancements. Total commitment amount on the inception date is established during the approval process and is intended to restrict an observed agent’s amount of credit risk to a given counterparty for the relevant instrument. | N22: Observed agent’s maximum exposure to credit risk on the inception date of the instrument, without taking into account any protection held or other credit enhancements. Total commitment amount on the inception date is established during the approval process and is intended to restrict an observed agent’s amount of credit risk to a given counterparty for the relevant instrument. | O22: TRUE | P22: 99999999999 | Q22: 11111111111 | S22: IN.066 | T22: N | U22: Y | V22: Y | W22: Y | X22: Y | Y22: Y | Z22: N | AB22: CD_LOAN_TAPES_BCE | AC22: BCE_LT_INSTR_MIS | AD22: VTOT_CREDITO_CONTRATADO | AE22: VTOT_CREDITO_CONTRATADO WHERE NOME_PERIMETRO = Perímetro em análise | AF22: - | AG22: 1) Cruzar LT002_INSTRUMENT com tabela temporária BCE_LT_INSTR_MIS para o perimetro em análise: LT002_INSTRUMENT LEFT JOIN (SELECT * FROM BCE_LT_INSTR_MIS) ON INSTRMNT_ID = CHAVE_FR Consultar documento BS_Tabelas_Temporárias_Loan_Tape.xlsx (BCE_LT_INSTR_MIS) | AI22: 44799 | AJ22: 09/02/2022: Atualização da metodologia de cálculo 07/04/2022: Atualização da metodologia de cálculo utilizada para a ponderação do campo decorrente da análise dos controlos do BCE. 26/06/2022: Metodologia idêntica à anterior, mas apontado para uma tabela diferente (CRV004XA1) | AK22: Metodologia / Conceito: 1) Montante em dívida do contrato na data de origem encontra-se disponível na tabela de risco RSTF101_DET_CNT_RSC. (Marino Peres) 2) Uma vez que a chave do contrato nessa tabela é a chave MIS, foi necessária a utilização de um tradutor de chaves (KT_CHAVES_MIS). 3) Adicionalmente, como é possível existirem relações de chaves MIS para FINREP diferentes de 1 para 1 e de modo a não reportar informação duplicada, foi criada uma tabela temporária com o tratamento deste campo (BCE_LT_INSTR_MIS): ponderação do montante proveniente da fonte através dos saldos dos contratos que contém contas contabilísticas do domínio de capital. Este procedimento deve ser realizado para o perímetro em análise. (Luis Capitão-Mor). Especificado/ Revisto por: Portfolio Manager + CDO (Marino Peres + Luis Capitão-Mor) Guia de conceitos da Corporação: Análise não realizada. | AL22: Campo: montIni | AM22: WIP | AN22: Y | AO22: N | AP22: Portfolio Instrumentos | AQ22: INFORMAÇÃO DE RISCOS | AR22: Marino Peres | AU22: 1
A23: =_xlfn.CONCAT(Table2[[#This Row],[TABLE_NAME]],Table2[[#This Row],[COLUMN_NAME]]) -> INSTRUMENTCMMTMNT_INSTRMNT | B23: INSTRUMENT | C23: CMMTMNT_INSTRMNT | D23: FLOAT 2 decimal places | E23: N | F23: Y | G23: Y | H23: N | I23: Y | J23: Y | K23: Y | L23: Commitment amount at reference date | M23: Observed agent’s maximum exposure to credit risk on the reference date of the instrument, without taking into account any protection held or other credit enhancements. Total commitment amount on the reference date is established during the life cycle of the loan and is intended to restrict an observed agent’s amount of credit risk to a given counterparty for the relevant instrument. | N23: Observed agent’s maximum exposure to credit risk on the reference date of the instrument, without taking into account any protection held or other credit enhancements. Total commitment amount on the reference date is established during the life cycle of the loan and is intended to restrict an observed agent’s amount of credit risk to a given counterparty for the relevant instrument. | O23: TRUE | P23: 99999999999 | Q23: 11111111111 | S23: IN.067 | T23: N | U23: Y | V23: Y | W23: Y | X23: Y | Y23: Y | Z23: N | AB23: CD_LOAN_TAPES_BCE | AC23: BCE_LT_INSTR_MIS | AD23: VINICIAL_EMPRESTIMO | AE23: VINICIAL_EMPRESTIMO WHERE NOME_PERIMETRO = Perímetro em análise | AF23: - | AG23: 1) Cruzar LT002_INSTRUMENT com tabela temporária BCE_LT_INSTR_MIS para o perimetro em análise: LT002_INSTRUMENT LEFT JOIN (SELECT * FROM BCE_LT_INSTR_MIS) ON INSTRMNT_ID = CHAVE_FR Consultar documento BS_Tabelas_Temporárias_Loan_Tape.xlsx (BCE_LT_INSTR_MIS) | AI23: 44799 | AJ23: 09/02/2022: Atualização da metodologia de cálculo. 07/04/2022: Atualização da metodologia de cálculo utilizada para a ponderação do campo decorrente da análise dos controlos do BCE. 26/08/2022: Alteração da especificação para reportar o campo VINICIAL_EMPRESTIMO ao invés do campo VRESPONSABILIDADE (especificação anterior do campo CMMTMNT_INCPTN_INSTRMNT) | AK23: Metodologia / Conceito: 1) Montante em dívida do contrato na data de referência encontra-se disponível na tabela de risco RSTF101_DET_CNT_RSC. (Marino Peres) 2) Uma vez que a chave do contrato nessa tabela é a chave MIS, foi necessária a utilização de um tradutor de chaves (KT_CHAVES_MIS). 3) Adicionalmente, como é possível existirem relações de chaves MIS para FINREP diferentes de 1 para 1 e de modo a não reportar informação duplicada, foi criada uma tabela temporária com o tratamento deste campo (BCE_LT_INSTR_MIS): ponderação do montante proveniente da fonte através dos saldos dos contratos que contém contas contabilísticas do domínio de capital. Este procedimento deve ser realizado para o perímetro em análise. (Luis Capitão-Mor). Especificado/ Revisto por: Portfolio Manager + CDO (Marino Peres + Luis Capitão-Mor) Guia de conceitos da Corporação: Análise não realizada. | AL23: N/A | AM23: WIP | AN23: Y | AO23: N | AP23: Portfolio Instrumentos | AQ23: INFORMAÇÃO DE RISCOS | AR23: Marino Peres | AU23: 1
