Workbook

Sheet Input
G1: =+SUBTOTAL(9,G3:G95) -> 149.14122 | H1: =+SUBTOTAL(9,H3:H95) -> 46259640 | J1: WITH PAIS AS ( SELECT UNIV.*,EPC.cfinbem,epc.cgarant_bem, CASE WHEN UNIV.CEMPBEM IS NOT NULL AND UNIV.CKBALBEM IS NOT NULL AND UNIV.CKCTABEM IS NOT NULL AND UNIV.CKREFBEM IS NOT NULL THEN 'Montante Colaterizado' ELSE 'Montante Não Colaterizado' END AS TIPOLOGIA_MONTANTE FROM -- OBTER OS DADOS DA TABELA DE EMISSÕES FINANCIADAS POR IMÓVEL (REAL ESTATE) ( SELECT * FROM BU_CAPTOOLS_WORK.PA_OUT_EMSS_FNCD_RE WHERE REF_DATE = '${REF_DATE}' ) UNIV LEFT JOIN -- LIGAÇÃO COM A TABELA PROPERTY_ENERGY_CERTIFICATE PARA OBTENÇÃO DO CAMPO EPC DO BEM IMÓVEL ( SELECT CEMPBEM ,CKBALBEM ,CKCTABEM ,CKREFBEM ,cgarant_bem ,cfinbem FROM cd_garantias.gt009_bens_imov WHERE REF_DATE = '${REF_DATE}' ) EPC ON UNIV.CEMPBEM = EPC.CEMPBEM AND UNIV.CKBALBEM = EPC.CKBALBEM AND UNIV.CKCTABEM = EPC.CKCTABEM AND UNIV.CKREFBEM = EPC.CKREFBEM ) SELECT CRE_RRE, TIPOLOGIA_MONTANTE, -- origem_scp1_emss, cgarant_bem, cfinbem, SUM(SCP1_EMSS_FNCD+SCP2_EMSS_FNCD) AS EMISSAO, SUM(-AMOUNT) AS AMOUNT FROM PAIS GROUP BY 1,2,3,4 ; select distinct cgarant_bem,descritivo from cd_garantias.gt803_cgarant_bem where ref_date='2024-12-31'
A2: cre_rre | B2: tipologia_montante | C2: cgarant_bem | D2: descritivo_cgarant | E2: cfinbem | F2: descritivo_cfin | G2: emissao | H2: amount
A3: CRE_FC | B3: Montante Colaterizado | C3: 5000 | D3: =+VLOOKUP(C3,cgarant_bem!A:B,2,FALSE) -> Imóveis com finalidade indefinida | E3: 08 | F3: =+VLOOKUP(E3,cfin_bem!A:B,2,FALSE) -> Outras | G3: 504.97555 | H3: 25507805
A4: CRE_OUTRO - Nao Aplicavel | B4: Montante Colaterizado | C4: 5102 | D4: =+VLOOKUP(C4,cgarant_bem!A:B,2,FALSE) -> Imóvel ou Fração p/ Habitação - em construção | E4: 01 | F4: =+VLOOKUP(E4,cfin_bem!A:B,2,FALSE) -> Habitação | G4: 4.6162314 | H4: 1178563.6
A5: Habitacao | B5: Montante Não Colaterizado | C5: NULL | D5: =+VLOOKUP(C5,cgarant_bem!A:B,2,FALSE) -> #N/A | E5: NULL | F5: =+VLOOKUP(E5,cfin_bem!A:B,2,FALSE) -> #N/A | G5: NULL | H5: 36314207
A6: CRE_OUTRO - Nao Aplicavel | B6: Montante Colaterizado | C6: 5000 | D6: =+VLOOKUP(C6,cgarant_bem!A:B,2,FALSE) -> Imóveis com finalidade indefinida | E6: 06 | F6: =+VLOOKUP(E6,cfin_bem!A:B,2,FALSE) -> Estacionamento | G6: NULL | H6: 567.31364
A7: CRE_OUTRO - Nao Aplicavel | B7: Montante Colaterizado | C7: 5204 | D7: =+VLOOKUP(C7,cgarant_bem!A:B,2,FALSE) -> Imóvel p/ Escritório - em construção | E7: 03 | F7: =+VLOOKUP(E7,cfin_bem!A:B,2,FALSE) -> Escritório | G7: 31.39951 | H7: 4672059.2
A8: Habitacao | B8: Montante Colaterizado | C8: 5201 | D8: =+VLOOKUP(C8,cgarant_bem!A:B,2,FALSE) -> Imóvel p/ Comércio | E8: 08 | F8: =+VLOOKUP(E8,cfin_bem!A:B,2,FALSE) -> Outras | G8: 13172.202 | H8: 4663532.5
A9: CRE_FC | B9: Montante Colaterizado | C9: 5212 | D9: =+VLOOKUP(C9,cgarant_bem!A:B,2,FALSE) -> Imóvel p/ Hotel - em construção | E9: 09 | F9: =+VLOOKUP(E9,cfin_bem!A:B,2,FALSE) -> Hotel | G9: 55.623895 | H9: 5758032
A10: CRE_OUTRO - Nao Aplicavel | B10: Montante Colaterizado | C10: 5000 | D10: =+VLOOKUP(C10,cgarant_bem!A:B,2,FALSE) -> Imóveis com finalidade indefinida | E10: 08 | F10: =+VLOOKUP(E10,cfin_bem!A:B,2,FALSE) -> Outras | G10: 754.02181 | H10: 1174119.6
A11: Habitacao | B11: Montante Colaterizado | C11: 5101 | D11: =+VLOOKUP(C11,cgarant_bem!A:B,2,FALSE) -> Imóvel ou Fração p/ Habitação | E11: 01 | F11: =+VLOOKUP(E11,cfin_bem!A:B,2,FALSE) -> Habitação | G11: 355929.45 | H11: 2.2483765e+10
A12: CRE_OUTRO | B12: Montante Colaterizado | C12: 5101 | D12: =+VLOOKUP(C12,cgarant_bem!A:B,2,FALSE) -> Imóvel ou Fração p/ Habitação | E12: 08 | F12: =+VLOOKUP(E12,cfin_bem!A:B,2,FALSE) -> Outras | G12: 862.85985 | H12: 80573799
A13: CRE_OUTRO - Nao Aplicavel | B13: Montante Colaterizado | C13: 5300 | D13: =+VLOOKUP(C13,cgarant_bem!A:B,2,FALSE) -> Terreno com finalidade indefinida | E13: 08 | F13: =+VLOOKUP(E13,cfin_bem!A:B,2,FALSE) -> Outras | G13: 73044.868 | H13: 12939470
A14: CRE_OUTRO - Nao Aplicavel | B14: Montante Colaterizado | C14: 5202 | D14: =+VLOOKUP(C14,cgarant_bem!A:B,2,FALSE) -> Imóvel p/ Comercio - em construção | E14: 02 | F14: =+VLOOKUP(E14,cfin_bem!A:B,2,FALSE) -> Comércio | G14: 342.22572 | H14: 3743679.8
A15: Habitacao | B15: Montante Colaterizado | C15: 5203 | D15: =+VLOOKUP(C15,cgarant_bem!A:B,2,FALSE) -> Imóvel p/ Escritório | E15: 03 | F15: =+VLOOKUP(E15,cfin_bem!A:B,2,FALSE) -> Escritório | G15: 986.00507 | H15: 4097961
A16: CRE_OUTRO - Nao Aplicavel | B16: Montante Colaterizado | C16: 5201 | D16: =+VLOOKUP(C16,cgarant_bem!A:B,2,FALSE) -> Imóvel p/ Comércio | E16: 08 | F16: =+VLOOKUP(E16,cfin_bem!A:B,2,FALSE) -> Outras | G16: 547615.47 | H16: 2.2539056e+08
A17: Habitacao | B17: Montante Colaterizado | C17: 5000 | D17: =+VLOOKUP(C17,cgarant_bem!A:B,2,FALSE) -> Imóveis com finalidade indefinida | E17: 01 | F17: =+VLOOKUP(E17,cfin_bem!A:B,2,FALSE) -> Habitação | G17: 44.086746 | H17: 139036.33
A18: CRE_OUTRO - Nao Aplicavel | B18: Montante Colaterizado | C18: 5207 | D18: =+VLOOKUP(C18,cgarant_bem!A:B,2,FALSE) -> Imóvel p/ Indústria | E18: 05 | F18: =+VLOOKUP(E18,cfin_bem!A:B,2,FALSE) -> Indústria | G18: 16159.768 | H18: 60983691
... A24: CRE_FC | B24: Montante Colaterizado | C24: 5102 | D24: =+VLOOKUP(C24,cgarant_bem!A:B,2,FALSE) -> Imóvel ou Fração p/ Habitação - em construção | E24: 08 | F24: =+VLOOKUP(E24,cfin_bem!A:B,2,FALSE) -> Outras | G24: 31.627215 | H24: 4121575.7
A25: CRE_OUTRO | B25: Montante Colaterizado | C25: 5209 | D25: =+VLOOKUP(C25,cgarant_bem!A:B,2,FALSE) -> Imóvel ou Fração p/ Estacionamento ligados à exploração | E25: 07 | F25: =+VLOOKUP(E25,cfin_bem!A:B,2,FALSE) -> Garagem | G25: NULL | H25: 713371.15
A26: CRE_OUTRO - Nao Aplicavel | B26: Montante Colaterizado | C26: 5209 | D26: =+VLOOKUP(C26,cgarant_bem!A:B,2,FALSE) -> Imóvel ou Fração p/ Estacionamento ligados à exploração | E26: 06 | F26: =+VLOOKUP(E26,cfin_bem!A:B,2,FALSE) -> Estacionamento | G26: NULL | H26: 1117942.5
A27: Habitacao | B27: Montante Colaterizado | C27: 5209 | D27: =+VLOOKUP(C27,cgarant_bem!A:B,2,FALSE) -> Imóvel ou Fração p/ Estacionamento ligados à exploração | E27: 07 | F27: =+VLOOKUP(E27,cfin_bem!A:B,2,FALSE) -> Garagem | G27: NULL | H27: 72297.091
A28: CRE_FC | B28: Montante Colaterizado | C28: 5206 | D28: =+VLOOKUP(C28,cgarant_bem!A:B,2,FALSE) -> Imóvel p/ Armazém - em construção | E28: 04 | F28: =+VLOOKUP(E28,cfin_bem!A:B,2,FALSE) -> Armazém | G28: 95.299966 | H28: 2243162.7
A29: CRE_OUTRO | B29: Montante Colaterizado | C29: 5102 | D29: =+VLOOKUP(C29,cgarant_bem!A:B,2,FALSE) -> Imóvel ou Fração p/ Habitação - em construção | E29: 01 | F29: =+VLOOKUP(E29,cfin_bem!A:B,2,FALSE) -> Habitação | G29: 16.795227 | H29: 4867974.3
A30: CRE_OUTRO - Nao Aplicavel | B30: Montante Colaterizado | C30: 82 | D30: =+VLOOKUP(C30,cgarant_bem!A:B,2,FALSE) -> #N/A | E30: 13 | F30: =+VLOOKUP(E30,cfin_bem!A:B,2,FALSE) -> Agricultura | G30: 2.0459993 | H30: 200118.02
A31: CRE_OUTRO - Nao Aplicavel | B31: Montante Colaterizado | C31: 5000 | D31: =+VLOOKUP(C31,cgarant_bem!A:B,2,FALSE) -> Imóveis com finalidade indefinida | F31: =+VLOOKUP(E31,cfin_bem!A:B,2,FALSE) -> #N/A | G31: 0.62446803 | H31: 0
A32: CRE_OUTRO | B32: Montante Colaterizado | C32: 5212 | D32: =+VLOOKUP(C32,cgarant_bem!A:B,2,FALSE) -> Imóvel p/ Hotel - em construção | E32: 09 | F32: =+VLOOKUP(E32,cfin_bem!A:B,2,FALSE) -> Hotel | G32: 80.384408 | H32: 8387009.3
A33: CRE_OUTRO | B33: Montante Colaterizado | C33: 5201 | D33: =+VLOOKUP(C33,cgarant_bem!A:B,2,FALSE) -> Imóvel p/ Comércio | E33: 02 | F33: =+VLOOKUP(E33,cfin_bem!A:B,2,FALSE) -> Comércio | G33: 9008.2416 | H33: 3.4297694e+08
A34: CRE_FC | B34: Montante Colaterizado | C34: 5201 | D34: =+VLOOKUP(C34,cgarant_bem!A:B,2,FALSE) -> Imóvel p/ Comércio | E34: 02 | F34: =+VLOOKUP(E34,cfin_bem!A:B,2,FALSE) -> Comércio | G34: 640.7085 | H34: 36321032
A35: CRE_OUTRO - Nao Aplicavel | B35: Montante Colaterizado | C35: 5201 | D35: =+VLOOKUP(C35,cgarant_bem!A:B,2,FALSE) -> Imóvel p/ Comércio | F35: =+VLOOKUP(E35,cfin_bem!A:B,2,FALSE) -> #N/A | G35: 553.98941 | H35: 220014.93
A36: CRE_OUTRO - Nao Aplicavel | B36: Montante Colaterizado | C36: 5215 | D36: =+VLOOKUP(C36,cgarant_bem!A:B,2,FALSE) -> Imóvel p/ Saúde | E36: 11 | F36: =+VLOOKUP(E36,cfin_bem!A:B,2,FALSE) -> Saúde | G36: 160.8898 | H36: 26713147
A37: CRE_FC | B37: Montante Colaterizado | C37: 5207 | D37: =+VLOOKUP(C37,cgarant_bem!A:B,2,FALSE) -> Imóvel p/ Indústria | E37: 05 | F37: =+VLOOKUP(E37,cfin_bem!A:B,2,FALSE) -> Indústria | G37: 14.611575 | H37: 73847.51
A38: Habitacao | B38: Montante Colaterizado | C38: 5300 | D38: =+VLOOKUP(C38,cgarant_bem!A:B,2,FALSE) -> Terreno com finalidade indefinida | E38: 08 | F38: =+VLOOKUP(E38,cfin_bem!A:B,2,FALSE) -> Outras | G38: 4001.159 | H38: 1038375.3
A39: CRE_OUTRO - Nao Aplicavel | B39: Montante Colaterizado | C39: 5101 | D39: =+VLOOKUP(C39,cgarant_bem!A:B,2,FALSE) -> Imóvel ou Fração p/ Habitação | E39: 01 | F39: =+VLOOKUP(E39,cfin_bem!A:B,2,FALSE) -> Habitação | G39: 1097.132 | H39: 1.7078205e+08
A40: CRE_OUTRO - Nao Aplicavel | B40: Montante Colaterizado | C40: 5211 | D40: =+VLOOKUP(C40,cgarant_bem!A:B,2,FALSE) -> Imóvel p/ Hotel | E40: 09 | F40: =+VLOOKUP(E40,cfin_bem!A:B,2,FALSE) -> Hotel | G40: 74.588332 | H40: 2424027
A41: CRE_OUTRO | B41: Montante Colaterizado | C41: 5000 | D41: =+VLOOKUP(C41,cgarant_bem!A:B,2,FALSE) -> Imóveis com finalidade indefinida | E41: 08 | F41: =+VLOOKUP(E41,cfin_bem!A:B,2,FALSE) -> Outras | G41: 31.12342 | H41: 2225838.8
A42: CRE_OUTRO | B42: Montante Colaterizado | C42: 5203 | D42: =+VLOOKUP(C42,cgarant_bem!A:B,2,FALSE) -> Imóvel p/ Escritório | E42: 03 | F42: =+VLOOKUP(E42,cfin_bem!A:B,2,FALSE) -> Escritório | G42: 1840.0407 | H42: 49910200
A43: CRE_FC | B43: Montante Não Colaterizado | C43: NULL | D43: =+VLOOKUP(C43,cgarant_bem!A:B,2,FALSE) -> #N/A | E43: NULL | F43: =+VLOOKUP(E43,cfin_bem!A:B,2,FALSE) -> #N/A | G43: NULL | H43: 5556041.2
A44: CRE_OUTRO | B44: Montante Colaterizado | C44: 5213 | D44: =+VLOOKUP(C44,cgarant_bem!A:B,2,FALSE) -> Imóvel p/ Educação | E44: 08 | F44: =+VLOOKUP(E44,cfin_bem!A:B,2,FALSE) -> Outras | G44: 0.012009535 | H44: 194.52
A45: Habitacao | B45: Montante Colaterizado | C45: 5101 | D45: =+VLOOKUP(C45,cgarant_bem!A:B,2,FALSE) -> Imóvel ou Fração p/ Habitação | F45: =+VLOOKUP(E45,cfin_bem!A:B,2,FALSE) -> #N/A | G45: 48.839499 | H45: 33082.685
...

Sheet cgarant_bem
A1: cgarant_bem | B1: descritivo
A2: 5000 | B2: Imóveis com finalidade indefinida
A3: 5101 | B3: Imóvel ou Fração p/ Habitação
A4: 5102 | B4: Imóvel ou Fração p/ Habitação - em construção
A5: 5103 | B5: Imóvel ou Fração p/ Estacionamento em Imo. Residencial
A6: 5104 | B6: Imóvel ou Fração p/ Estacionamento em Imo. Residencial - em construção
A7: 5201 | B7: Imóvel p/ Comércio
A8: 5202 | B8: Imóvel p/ Comercio - em construção
A9: 5203 | B9: Imóvel p/ Escritório
A10: 5204 | B10: Imóvel p/ Escritório - em construção
A11: 5205 | B11: Imóvel p/ Armazém
A12: 5206 | B12: Imóvel p/ Armazém - em construção
A13: 5207 | B13: Imóvel p/ Indústria
... A73: 7515 | B73: Leasing mobiliário - Equipamento - Outras E. Renováveis

Sheet cfin_bem
A1: 01 | B1: Habitação
A2: 02 | B2: Comércio
A3: 03 | B3: Escritório
A4: 04 | B4: Armazém
A5: 05 | B5: Indústria
A6: 06 | B6: Estacionamento
A7: 07 | B7: Garagem
A8: 08 | B8: Outras
A9: 09 | B9: Hotel
A10: 10 | B10: Educação
A11: 11 | B11: Saúde
A12: 12 | B12: Lazer
A13: 13 | B13: Agricultura
A14: 14 | B14: Centro Comercial

Sheet CRE_OUTRO
A1: cre_rre | B1: CRE_OUTRO
A2: tipologia_montante | B2: Montante Colaterizado
A4: Sum of amount | B4: Column Labels
A5: Row Labels | B5: Agricultura | C5: Armazém | D5: Comércio | E5: Escritório | F5: Estacionamento | G5: Garagem | H5: Habitação | I5: Hotel | J5: Indústria | K5: Outras | L5: #N/A | M5: Saúde | N5: Grand Total
A6: Imóveis com finalidade indefinida | K6: 2225838.8 | N6: 2225838.8
A7: Imóvel ou Fração p/ Estacionamento ligados à exploração | F7: 449394.54 | G7: 713371.15 | N7: 1162765.7
A8: Imóvel ou Fração p/ Habitação | H8: 1.85078e+08 | K8: 80573799 | L8: 0 | N8: 2.656518e+08
A9: Imóvel ou Fração p/ Habitação - em construção | H9: 4867974.3 | N9: 4867974.3
A10: Imóvel p/ Armazém | C10: 71573013 | N10: 71573013
A11: Imóvel p/ Armazém - em construção | C11: 597578.97 | N11: 597578.97
A12: Imóvel p/ Comércio | D12: 3.4297694e+08 | K12: 4.2362503e+08 | L12: 18148278 | N12: 7.8475025e+08
A13: Imóvel p/ Comercio - em construção | K13: 1817685.2 | N13: 1817685.2
A14: Imóvel p/ Educação | K14: 194.52 | N14: 194.52
A15: Imóvel p/ Escritório | E15: 49910200 | N15: 49910200
A16: Imóvel p/ Escritório - em construção | E16: 1348820.9 | N16: 1348820.9
A17: Imóvel p/ Hotel | I17: 25187387 | N17: 25187387
A18: Imóvel p/ Hotel - em construção | I18: 8387009.3 | N18: 8387009.3
A19: Imóvel p/ Indústria | J19: 11356426 | N19: 11356426
A20: Imóvel p/ Saúde | M20: 9810905.6 | N20: 9810905.6
A21: Terreno com finalidade indefinida | K21: 2427864.1 | N21: 2427864.1
A22: #N/A | B22: 408890.19 | N22: 408890.19
A23: Grand Total | B23: 408890.19 | C23: 72170592 | D23: 3.4297694e+08 | E23: 51259021 | F23: 449394.54 | G23: 713371.15 | H23: 1.8994598e+08 | I23: 33574396 | J23: 11356426 | K23: 5.1067041e+08 | L23: 18148278 | M23: 9810905.6 | N23: 1.2414846e+09

Sheet MORTGAGE
A1: cre_rre | B1: Habitacao
A2: tipologia_montante | B2: Montante Colaterizado
A4: Sum of amount | B4: Column Labels
A5: Row Labels | B5: Armazém | C5: Comércio | D5: Educação | E5: Escritório | F5: Estacionamento | G5: Garagem | H5: Habitação | I5: Indústria | J5: Outras | K5: #N/A | L5: Saúde | M5: Grand Total
A6: Imóveis com finalidade indefinida | G6: 4169.0201 | H6: 139036.33 | M6: 143205.35
A7: Imóvel ou Fração p/ Estacionamento em Imo. Residencial | F7: 866370.58 | G7: 1202592.6 | M7: 2068963.2
A8: Imóvel ou Fração p/ Estacionamento ligados à exploração | F8: 23359.166 | G8: 72297.091 | M8: 95656.257
A9: Imóvel ou Fração p/ Habitação | H9: 2.2483765e+10 | J9: 31961416 | K9: 33082.685 | M9: 2.251576e+10
A10: Imóvel ou Fração p/ Habitação - em construção | H10: 7.0908512e+08 | J10: 361042.22 | M10: 7.0944616e+08
A11: Imóvel p/ Armazém | B11: 6162600.3 | M11: 6162600.3
A12: Imóvel p/ Comércio | C12: 25863096 | J12: 4663532.5 | K12: 2554.78 | M12: 30529183
A13: Imóvel p/ Comercio - em construção | C13: 64929.65 | M13: 64929.65
A14: Imóvel p/ Educação | D14: 93777.47 | M14: 93777.47
A15: Imóvel p/ Escritório | E15: 4097961 | M15: 4097961
A16: Imóvel p/ Indústria | I16: 168410.06 | M16: 168410.06
A17: Imóvel p/ Saúde | L17: 3640.1 | M17: 3640.1
A18: Terreno com finalidade indefinida | J18: 1038375.3 | K18: 0 | M18: 1038375.3
A19: Grand Total | B19: 6162600.3 | C19: 25928025 | D19: 93777.47 | E19: 4097961 | F19: 889729.74 | G19: 1279058.7 | H19: 2.3192989e+10 | I19: 168410.06 | J19: 38024366 | K19: 35637.465 | L19: 3640.1 | M19: 2.3269672e+10

Sheet Universo
A1: cre_rre | B1: (All)
A2: tipologia_montante | B2: Montante Colaterizado
A4: Sum of amount | B4: Column Labels
A5: Row Labels | B5: Agricultura | C5: Armazém | D5: Comércio | E5: Educação | F5: Escritório | G5: Estacionamento | H5: Garagem | I5: Habitação | J5: Hotel | K5: Indústria | L5: Outras | M5: #N/A | N5: Saúde | O5: Grand Total
A6: Imóveis com finalidade indefinida | G6: 567.31364 | H6: 4169.0201 | I6: 139036.33 | L6: 28907763 | M6: 0 | O6: 29051536
A7: Imóvel ou Fração p/ Estacionamento em Imo. Residencial | G7: 866370.58 | H7: 1202592.6 | O7: 2068963.2
A8: Imóvel ou Fração p/ Estacionamento ligados à exploração | G8: 1743070.2 | H8: 1638242.8 | O8: 3381313
A9: Imóvel ou Fração p/ Habitação | I9: 2.3262233e+10 | L9: 2.0090507e+08 | M9: 108402.57 | O9: 2.3463247e+10
A10: Imóvel ou Fração p/ Habitação - em construção | I10: 7.3207928e+08 | L10: 4806048.4 | O10: 7.3688532e+08
A11: Imóvel p/ Armazém | C11: 3.2039688e+08 | O11: 3.2039688e+08
A12: Imóvel p/ Armazém - em construção | C12: 6064683.2 | O12: 6064683.2
A13: Imóvel p/ Comércio | D13: 6.386573e+08 | L13: 8.8919777e+08 | M13: 18370847 | O13: 1.5462259e+09
A14: Imóvel p/ Comercio - em construção | D14: 7305214.2 | L14: 29623633 | O14: 36928847
A15: Imóvel p/ Educação | E15: 2246612.7 | L15: 194.52 | O15: 2246807.2
A16: Imóvel p/ Escritório | F16: 1.3855224e+08 | O16: 1.3855224e+08
A17: Imóvel p/ Escritório - em construção | F17: 6020880.1 | O17: 6020880.1
A18: Imóvel p/ Hotel | J18: 27611414 | O18: 27611414
A19: Imóvel p/ Hotel - em construção | J19: 14145041 | O19: 14145041
A20: Imóvel p/ Indústria | K20: 72582375 | O20: 72582375
A21: Imóvel p/ Indústria - em construção | K21: 1585102.4 | O21: 1585102.4
A22: Imóvel p/ Saúde | L22: 46.12 | N22: 36527692 | O22: 36527739
A23: Terreno com finalidade indefinida | L23: 16405709 | M23: 15.12 | O23: 16405724
A24: #N/A | B24: 609008.21 | O24: 609008.21
A25: Grand Total | B25: 609008.21 | C25: 3.2646157e+08 | D25: 6.4596252e+08 | E25: 2246612.7 | F25: 1.4457312e+08 | G25: 2610008.1 | H25: 2845004.4 | I25: 2.3994452e+10 | J25: 41756455 | K25: 74167477 | L25: 1.1698462e+09 | M25: 18479265 | N25: 36527692 | O25: 2.6460537e+10

Sheet CRE_OUTRO - Emissões
A1: cre_rre | B1: CRE_OUTRO
A2: tipologia_montante | B2: Montante Colaterizado
A4: Sum of emissao | B4: Column Labels
A5: Row Labels | B5: Agricultura | C5: Armazém | D5: Comércio | E5: Escritório | F5: Estacionamento | G5: Garagem | H5: Habitação | I5: Hotel | J5: Indústria | K5: Outras | L5: #N/A | M5: Saúde | N5: Grand Total
A6: Imóveis com finalidade indefinida | K6: 31.12342 | N6: 31.12342
A7: Imóvel ou Fração p/ Estacionamento ligados à exploração | F7: 0 | G7: 0 | N7: 0
A8: Imóvel ou Fração p/ Habitação | H8: 1093.812 | K8: 862.85985 | L8: 40.391764 | N8: 1997.0636
A9: Imóvel ou Fração p/ Habitação - em construção | H9: 16.795227 | N9: 16.795227
A10: Imóvel p/ Armazém | C10: 5025.0629 | N10: 5025.0629
A11: Imóvel p/ Armazém - em construção | C11: 21.479078 | N11: 21.479078
A12: Imóvel p/ Comércio | D12: 9008.2416 | K12: 65055.736 | L12: 108.74945 | N12: 74172.727
A13: Imóvel p/ Comercio - em construção | K13: 22.194281 | N13: 22.194281
A14: Imóvel p/ Educação | K14: 0.012009535 | N14: 0.012009535
A15: Imóvel p/ Escritório | E15: 1840.0407 | N15: 1840.0407
A16: Imóvel p/ Escritório - em construção | E16: 32.27826 | N16: 32.27826
A17: Imóvel p/ Hotel | I17: 310.85221 | N17: 310.85221
A18: Imóvel p/ Hotel - em construção | I18: 80.384408 | N18: 80.384408
A19: Imóvel p/ Indústria | J19: 2000.4611 | N19: 2000.4611
A20: Imóvel p/ Saúde | M20: 260.5746 | N20: 260.5746
A21: Terreno com finalidade indefinida | K21: 15682.645 | N21: 15682.645
A22: #N/A | B22: 0.010087207 | N22: 0.010087207
A23: Grand Total | B23: 0.010087207 | C23: 5046.542 | D23: 9008.2416 | E23: 1872.3189 | F23: 0 | G23: 0 | H23: 1110.6072 | I23: 391.23662 | J23: 2000.4611 | K23: 81654.57 | L23: 149.14122 | M23: 260.5746 | N23: 101493.7
H24: =+K8 -> 862.85985
H25: =+SUM(H23:H24) -> 1973.467

Sheet MORTGAGE - Emissões
A1: cre_rre | B1: Habitacao
A2: tipologia_montante | B2: Montante Colaterizado
A4: Sum of emissao | B4: Column Labels
A5: Row Labels | B5: Armazém | C5: Comércio | D5: Educação | E5: Escritório | F5: Estacionamento | G5: Garagem | H5: Habitação | I5: Indústria | J5: Outras | K5: #N/A | L5: Saúde | M5: Grand Total
A6: Imóveis com finalidade indefinida | G6: 0 | H6: 44.086746 | M6: 44.086746
A7: Imóvel ou Fração p/ Estacionamento em Imo. Residencial | F7: 0 | G7: 0 | M7: 0
A8: Imóvel ou Fração p/ Estacionamento ligados à exploração | F8: 0 | G8: 0 | M8: 0
A9: Imóvel ou Fração p/ Habitação | H9: 355929.45 | J9: 27055.333 | K9: 48.839499 | M9: 383033.63
A10: Imóvel ou Fração p/ Habitação - em construção | H10: 13717.192 | J10: 19.931031 | M10: 13737.123
A11: Imóvel p/ Armazém | B11: 1284.1378 | M11: 1284.1378
A12: Imóvel p/ Comércio | C12: 5893.7419 | J12: 13172.202 | K12: 152.16434 | M12: 19218.109
A13: Imóvel p/ Comercio - em construção | C13: 0.85197432 | M13: 0.85197432
A14: Imóvel p/ Educação | D14: 9.931413 | M14: 9.931413
A15: Imóvel p/ Escritório | E15: 986.00507 | M15: 986.00507
A16: Imóvel p/ Indústria | I16: 43.465183 | M16: 43.465183
A17: Imóvel p/ Saúde | L17: 2.8573798 | M17: 2.8573798
A18: Terreno com finalidade indefinida | J18: 4001.159 | K18: 27.79985 | M18: 4028.9588
A19: Grand Total | B19: 1284.1378 | C19: 5894.5939 | D19: 9.931413 | E19: 986.00507 | F19: 0 | G19: 0 | H19: 369690.73 | I19: 43.465183 | J19: 44248.626 | K19: 228.80369 | L19: 2.8573798 | M19: 422389.15
