Workbook

Sheet Sheet
A1: dimensao | B1: valor_original | C1: valor_mv | D1: descritivo_mv
A2: regiao | B2: 702 | C2: Advanced economies | D2: Economias Avançadas
A3: regiao | B3: 756 | C3: Advanced economies | D3: Economias Avançadas
A4: regiao | B4: 158 | C4: Advanced economies | D4: Economias Avançadas
A5: regiao | B5: 840 | C5: Advanced economies | D5: Economias Avançadas
A6: regiao | B6: 040 | C6: EU member states | D6: Membros da União Europeia
A7: regiao | B7: 056 | C7: EU member states | D7: Membros da União Europeia
A8: regiao | B8: 100 | C8: EU member states | D8: Membros da União Europeia
A9: regiao | B9: 191 | C9: EU member states | D9: Membros da União Europeia
A10: regiao | B10: 196 | C10: EU member states | D10: Membros da União Europeia
A11: regiao | B11: 344 | C11: Advanced economies | D11: Economias Avançadas
A12: regiao | B12: 352 | C12: Advanced economies | D12: Economias Avançadas
... A96: tipo_veiculo | B96: 7109 | C96: Not applicable | D96: Outros

Sheet Sheet1
A1: tayd91c0_ctabela | B1: tayd91c0_celemtab | C1: tayd91c0_gelemtab | D1: tayd91c0_gelem30 | G1: tayd91c0_htimest | H1: tayd91c0_ckutulmo | I1: tayd91c0_nelemc01 | J1: tayd91c0_nelemc02 | K1: tayd91c0_nelemc03 | L1: tayd91c0_nelemc04 | M1: tayd91c0_nelemc05 | N1: tayd91c0_nelemc06 | O1: tayd91c0_nelemc07 | P1: tayd91c0_nelemc08 | Q1: tayd91c0_nelemc09 | R1: tayd91c0_nelemc10 | S1: tayd91c0_nelemc11 | T1: tayd91c0_nelemc12 | U1: tayd91c0_nelemc13 | V1: tayd91c0_nelemc14 | W1: tayd91c0_nelemc15 | X1: tayd91c0_nelemc16 | Y1: tayd91c0_nelemc17 | Z1: tayd91c0_nelemc18 | AA1: tayd91c0_nelemc19 | AB1: tayd91c0_nelemc20 | AC1: tayd91c0_cempmarc | AD1: data_date_part | AE1: data_timestamp_part
A2: 015 | B2: 004 | C2: AFEGANISTAO | D2: AFGHANISTAN | E2: =+B2 -> 004 | G2: 2023-11-15-17.02.00.263031 | H2: ATHTAT91 | I2: AFG | J2: AFAFS | K2: S H 04 | M2: 5 | Q2: AF | S2: 00000 | U2: S045 | X2: S | Z2: 000 | AA2: 000 S | AB2: S | AD2: 2025-09-24 | AE2: 20250924232237
A3: 015 | B3: 008 | C3: ALBANIA | D3: ALBANIA | E3: =+B3 -> 008 | G3: 2023-11-15-17.02.00.271984 | H3: ATHTAT91 | I3: ALB | J3: ALALS | K3: S H 11 | M3: 4 | P3: S | Q3: AL | S3: 00000 | U3: S012 | W3: N | X3: N | Z3: 000 | AA3: 0280512 S | AB3: S | AD3: 2025-09-24 | AE3: 20250924232237
A4: 015 | B4: 010 | C4: ANTARTICA | D4: ANTARCTICA | E4: =+B4 -> 010 | G4: 2023-11-15-17.02.00.272109 | H4: ATHTAT91 | I4: ATA | J4: AQAQS | K4: H 11 | M4: 5 | Q4: AQ | S4: 00000 | U4: S000 | Z4: 000 | AA4: 000 S | AB4: S | AD4: 2025-09-24 | AE4: 20250924232237
A5: 015 | B5: 012 | C5: ARGELIA | D5: ALGERIA | E5: =+B5 -> 012 | G5: 2023-11-15-17.02.00.272172 | H5: ATHTAT91 | I5: DZA | J5: DZDZS | K5: S H 11 | M5: 5 | Q5: DZ | S5: 00000 | U5: S005 | Y5: SS06S06 | Z5: 000 | AA5: 000 S | AB5: S | AD5: 2025-09-24 | AE5: 20250924232237
A6: 015 | B6: 016 | C6: SAMOA AMERICANAS | D6: AMERICAN SAMOA | E6: =+B6 -> 016 | G6: 2025-09-23-15.54.11.589835 | H6: S612127 | I6: ASM | J6: ASUSS | K6: H 10 | M6: 5 | Q6: AS | S6: 00000 | U6: S045 | W6: N | X6: N SSSSS | Z6: 000 | AA6: 0000000 S | AB6: S | AD6: 2025-09-24 | AE6: 20250924232237
A7: 015 | B7: 020 | C7: ANDORRA | D7: ANDORRA | E7: =+B7 -> 020 | G7: 2023-11-15-17.02.00.276271 | H7: ATHTAT91 | I7: AND | J7: ADADS | K7: S H 10 | M7: 4 | N7: E2 | O7: S | P7: S | Q7: AD | S7: 00000 | T7: 97AD00AD | U7: S000 | W7: N | X7: N SSNS | Y7: SSS06S03 | Z7: 000 | AA7: 0240512 S | AB7: S | AD7: 2025-09-24 | AE7: 20250924232237
A8: 015 | B8: 024 | C8: ANGOLA | D8: ANGOLA | E8: =+B8 -> 024 | G8: 2023-11-15-17.02.00.276376 | H8: ATHTAT91 | I8: AGO | J8: AOAOS | K8: S H 11 | L8: S | M8: 5 | Q8: AO | S8: 00000 | T8: 97AO00AO | U8: S012 | W8: N | X8: N | Y8: SS06S03 | Z8: 000 | AA8: 0000000 S | AB8: NG S | AD8: 2025-09-24 | AE8: 20250924232237
A9: 015 | B9: 028 | C9: ANTIGUA | D9: ANTIGUA AND BARBUDA | E9: =+B9 -> 028 | G9: 2025-09-23-15.54.33.557477 | H9: S612127 | I9: ATG | J9: AGAGS | K9: S H 10 | M9: 5 | Q9: AG | S9: 00000 | U9: S045 | W9: N | X9: N SSSSS | Z9: 000 | AA9: 000 S | AB9: S | AD9: 2025-09-24 | AE9: 20250924232237
A10: 015 | B10: 031 | C10: AZERBEIJAO | D10: AZERBAIJAN | E10: =+B10 -> 031 | G10: 2025-09-23-15.54.54.079953 | H10: S612127 | I10: AZE | J10: AZAZS | K10: S H 11 | M10: 5 | Q10: AZ | S10: 00000 | T10: 97AZ00AZ | U10: S005 | Z10: 000 | AA10: 0280508 S | AB10: S | AD10: 2025-09-24 | AE10: 20250924232237
A11: 015 | B11: 032 | C11: ARGENTINA | D11: ARGENTINA | E11: =+B11 -> 032 | G11: 2023-11-15-17.02.00.276553 | H11: ATHTAT91 | I11: ARG | J11: ARARS | K11: M 14 | L11: S | M11: 5 | N11: A2 | Q11: AR | S11: 00000 | T11: 97AR00AR | U11: S012 | Z11: 000 | AA11: 000 S | AB11: S | AD11: 2025-09-24 | AE11: 20250924232237
A12: 015 | B12: 036 | C12: AUSTRALIA | D12: AUSTRALIA | E12: =+B12 -> 036 | G12: 2023-11-15-17.02.00.276609 | H12: ATHTAT91 | I12: AUS | J12: AUAU | K12: L 15 | M12: 5 | Q12: AU | R12: AU | S12: 00000 | T12: 97AU00AU | U12: 000 | Z12: 000 | AA12: 000 S | AB12: S | AD12: 2025-09-24 | AE12: 20250924232237
A13: 015 | B13: 040 | C13: AUSTRIA | D13: AUSTRIA | E13: =+B13 -> 040 | G13: 2023-11-15-17.02.00.276683 | H13: ATHTAT91 | I13: AUT | J13: ATAT | K13: L 15 | M13: 3 | N13: E1 | O13: CEESS | P13: SS | Q13: AT | R13: AT | S13: 00000 | T13: 97AT00AT | U13: 000 | W13: S | X13: SS | Y13: SSS06S03 | Z13: 000 | AA13: 0200509SS | AB13: S | AD13: 2025-09-24 | AE13: 20250924232237
A14: 015 | B14: 044 | C14: BAHAMAS | D14: BAHAMAS | E14: =+B14 -> 044 | G14: 2025-09-23-15.55.14.829874 | H14: S612127 | I14: BHS | J14: BSBSS | K14: S H 10 | M14: 5 | Q14: BS | S14: 00000 | T14: 97BS00BS | U14: S012 | W14: N | X14: N SSSSS | Z14: 000 | AA14: 000 S | AB14: S | AD14: 2025-09-24 | AE14: 20250924232237
A15: 015 | B15: 048 | C15: BAHREM | D15: BAHRAIN | E15: =+B15 -> 048 | G15: 2025-09-23-15.55.35.482130 | H15: S612127 | I15: BHR | J15: BHBHS | K15: S H 10 | M15: 5 | Q15: BH | S15: 00000 | T15: 97BH00BH | U15: S012 | W15: N | X15: N SSSSS | Y15: SS06S03 | Z15: 000 | AA15: 0220508 S | AB15: S | AD15: 2025-09-24 | AE15: 20250924232237
A16: 015 | B16: 050 | C16: BANGLADESH | D16: BANGLADESH | E16: =+B16 -> 050 | G16: 2023-11-15-17.02.00.276852 | H16: ATHTAT91 | I16: BGD | J16: BDBDS | K16: H 11 | M16: 5 | Q16: BD | S16: 00000 | U16: S012 | Z16: 000 | AA16: 000 S | AB16: S | AD16: 2025-09-24 | AE16: 20250924232237
A17: 015 | B17: 051 | C17: ARMENIA | D17: ARMENIA | E17: =+B17 -> 051 | G17: 2025-09-23-15.56.00.046536 | H17: S612127 | I17: ARM | J17: AMAMS | K17: S H 11 | M17: 5 | Q17: AM | S17: 00000 | U17: S005 | Z17: 000 | AA17: 000 S | AB17: S | AD17: 2025-09-24 | AE17: 20250924232237
A18: 015 | B18: 052 | C18: BARBADOS | D18: BARBADOS | E18: =+B18 -> 052 | G18: 2025-09-23-16.01.39.000464 | H18: S612127 | I18: BRB | J18: BBBBS | K18: S H 09 | M18: 5 | Q18: BB | S18: 00000 | U18: S012 | W18: N | X18: N SSSSS | Y18: SS06S03 | Z18: 000 | AA18: 000 S | AB18: S | AD18: 2025-09-24 | AE18: 20250924232237
A19: 015 | B19: 056 | C19: BELGICA | D19: BELGIUM | E19: =+B19 -> 056 | G19: 2023-11-15-17.02.00.277025 | H19: ATHTAT91 | I19: BEL | J19: BEBE | K19: SL 15 | M19: 3 | N19: E1 | O19: CEESS | P19: SS | Q19: BE | S19: 00000 | T19: 97BE00BE | U19: 000 | W19: S | X19: SS | Y19: SSS06S06 | Z19: 000 | AA19: 0160507SS | AB19: S | AD19: 2025-09-24 | AE19: 20250924232237
A20: 015 | B20: 060 | C20: BERMUDAS | D20: BERMUDA | E20: =+B20 -> 060 | G20: 2023-11-15-17.02.00.277080 | H20: ATHTAT91 | I20: BMU | J20: BMBMS | K20: S H 10 | M20: 5 | Q20: BM | S20: 00000 | T20: 97BM00BM | U20: S000 | W20: N | X20: N SSSSS | Z20: 000 | AA20: 000 S | AB20: S | AD20: 2025-09-24 | AE20: 20250924232237
A21: 015 | B21: 064 | C21: BUTAO | D21: BHUTAN | E21: =+B21 -> 064 | G21: 2023-11-15-17.02.00.277157 | H21: ATHTAT91 | I21: BTN | J21: BTBTS | K21: M 14 | M21: 5 | Q21: BT | S21: 00000 | U21: S012 | Z21: 000 | AA21: 000 S | AB21: S | AD21: 2025-09-24 | AE21: 20250924232237
A22: 015 | B22: 068 | C22: BOLIVIA | D22: BOLIVIA | E22: =+B22 -> 068 | G22: 2023-11-15-17.02.00.277219 | H22: ATHTAT91 | I22: BOL | J22: BOBOS | K22: S H 11 | L22: S | M22: 5 | N22: A2 | Q22: BO | S22: 00000 | T22: 97BO00BO | U22: S045 | W22: N | X22: N SSSSS | Z22: 000 | AA22: 000 S | AB22: S | AD22: 2025-09-24 | AE22: 20250924232237
A23: 015 | B23: 070 | C23: BOSNIA E HERZEGOVINA | D23: BOSNIA AND HERZEGOVINA | E23: =+B23 -> 070 | G23: 2025-09-23-16.02.00.314549 | H23: S612127 | I23: BIH | J23: BABAS | K23: S H 07 | M23: 4 | P23: S | Q23: BA | S23: 00000 | T23: 97BA00BA | U23: S012 | W23: N | X23: N S | Z23: 000 | AA23: 0200510 S | AB23: S | AD23: 2025-09-24 | AE23: 20250924232237
A24: 015 | B24: 072 | C24: BOTSWANA | D24: BOTSWANA | E24: =+B24 -> 072 | G24: 2023-11-15-17.02.00.277349 | H24: ATHTAT91 | I24: BWA | J24: BWBWS | K24: S M 14 | M24: 5 | Q24: BW | S24: 00000 | T24: 97BW00BW | U24: S000 | Z24: 000 | AA24: 000 S | AB24: S | AD24: 2025-09-24 | AE24: 20250924232237
A25: 015 | B25: 074 | C25: BOUVET,ILHA | D25: BOUVET ISLAND | E25: =+B25 -> 074 | G25: 2025-09-23-16.02.21.272426 | H25: S612127 | I25: BVT | J25: BVNOS | K25: H 11 | M25: 5 | P25: S | Q25: BV | S25: 00000 | U25: S045 | W25: N | X25: N | Z25: 000 | AA25: 0150000 S | AB25: S | AD25: 2025-09-24 | AE25: 20250924232237
A26: 015 | B26: 076 | C26: BRASIL | D26: BRAZIL | E26: =+B26 -> 076 | G26: 2025-09-23-16.02.41.182793 | H26: S612127 | I26: BRA | J26: BRBRS | K26: S M 14 | L26: S | M26: 5 | N26: A2 | P26: S | Q26: BR | S26: 00000 | T26: 97BR00BR | U26: S005 | W26: N | X26: N | Y26: SS06S06 | Z26: 000 | AA26: 0290512 S | AB26: NG S | AD26: 2025-09-24 | AE26: 20250924232237
A27: 015 | B27: 084 | C27: BELIZE | D27: BELIZE | E27: =+B27 -> 084 | G27: 2023-11-15-17.02.00.277511 | H27: ATHTAT91 | I27: BLZ | J27: BZBZS | K27: S H 10 | M27: 5 | Q27: BZ | S27: 00000 | T27: 97BZ00BZ | U27: S045 | W27: N | X27: N SSSSS | Z27: 000 | AA27: 000 S | AB27: S | AD27: 2025-09-24 | AE27: 20250924232237
A28: 015 | B28: 086 | C28: OCEANO INDICO,TER. BRIT.DO | D28: BRITISH INDIAN OCEAN TERRITORY | E28: =+B28 -> 086 | G28: 2023-11-15-17.02.00.277582 | H28: ATHTAT91 | I28: IOT | J28: IOIOS | K28: H 11 | M28: 5 | Q28: IO | S28: 00000 | U28: S000 | Z28: 000 | AA28: 000 S | AB28: S | AD28: 2025-09-24 | AE28: 20250924232237
A29: 015 | B29: 090 | C29: SALOMAN,ILHAS | D29: SALOMON ISLANDS | E29: =+B29 -> 090 | G29: 2023-11-15-17.02.00.277643 | H29: ATHTAT91 | I29: SLB | J29: SBSBS | K29: S H 10 | M29: 5 | Q29: SB | S29: 00000 | U29: S012 | W29: N | X29: N SSSSS | Z29: 000 | AA29: 000 S | AB29: S | AD29: 2025-09-24 | AE29: 20250924232237
A30: 015 | B30: 092 | C30: ILHAS VIRGENS (BRITANICAS) | D30: VIRGIN ISLANDS, BRITISH | E30: =+B30 -> 092 | G30: 2023-11-15-17.02.00.277727 | H30: ATHTAT91 | I30: VGB | J30: VG1ZS | K30: S H 10 | M30: 5 | Q30: VG | S30: 00000 | U30: S000 | W30: N | X30: N SSSSS | Y30: S | Z30: 000 | AA30: 0240508 S | AB30: S | AD30: 2025-09-24 | AE30: 20250924232237
A31: 015 | B31: 096 | C31: BRUNEI | D31: BRUNEI DARUSSALAM | E31: =+B31 -> 096 | G31: 2023-11-15-17.02.00.277950 | H31: ATHTAT91 | I31: BRN | J31: BNBNS | K31: S H 10 | M31: 5 | Q31: BN | S31: 00000 | U31: S000 | W31: N | X31: N SSSSS | Z31: 000 | AA31: 000 S | AB31: S | AD31: 2025-09-24 | AE31: 20250924232237
A32: 015 | B32: 100 | C32: BULGARIA | D32: BULGARIA | E32: =+B32 -> 100 | G32: 2023-11-15-17.02.00.278003 | H32: ATHTAT91 | I32: BGR | J32: BGBGS | K32: S M 14 | M32: 4 | N32: E1 | O32: SS | P32: SS | Q32: BG | S32: 00000 | T32: 97BG00BG | U32: S000 | W32: S | X32: N | Y32: SSS06S03 | Z32: 000 | AA32: 0220512SS | AB32: S | AD32: 2025-09-24 | AE32: 20250924232237
A33: 015 | B33: 104 | C33: MYANMAR | D33: MYANMAR | E33: =+B33 -> 104 | G33: 2025-09-23-16.03.00.785500 | H33: S612127 | I33: MMR | J33: MMMMS | K33: H 04 | M33: 5 | Q33: MM | S33: 00000 | U33: S045 | W33: N | X33: N SS SS | Z33: 000 | AA33: 000 S | AB33: S | AD33: 2025-09-24 | AE33: 20250924232237
A34: 015 | B34: 108 | C34: BURUNDI | D34: BURUNDI | E34: =+B34 -> 108 | G34: 2023-11-15-17.02.00.278124 | H34: ATHTAT91 | I34: BDI | J34: BIBIS | K34: H 07 | M34: 5 | Q34: BI | S34: 00000 | U34: S045 | X34: S | Z34: 000 | AA34: 000 S | AB34: S | AD34: 2025-09-24 | AE34: 20250924232237
A35: 015 | B35: 112 | C35: BELARUS | D35: BELARUS | E35: =+B35 -> 112 | G35: 2023-11-15-17.02.00.278182 | H35: ATHTAT91 | I35: BLR | J35: BYBYS | K35: S HR03 | M35: 5 | N35: E3 | P35: S | Q35: BY | S35: 00000 | U35: S045 | X35: S | Z35: 000 | AA35: 0280508 S | AB35: S | AD35: 2025-09-24 | AE35: 20250924232237
A36: 015 | B36: 116 | C36: CAMBODIA | D36: CAMBODIA | E36: =+B36 -> 116 | G36: 2023-11-15-17.02.00.278275 | H36: ATHTAT91 | I36: KHM | J36: KHKHS | K36: S H 09 | M36: 5 | Q36: KH | S36: 00000 | U36: S012 | Z36: 000 | AA36: 000 S | AB36: S | AD36: 2025-09-24 | AE36: 20250924232237
A37: 015 | B37: 120 | C37: CAMAROES | D37: CAMEROON | E37: =+B37 -> 120 | G37: 2025-09-23-16.04.09.334170 | H37: S612127 | I37: CMR | J37: CMCMS | K37: S H 11 | M37: 5 | Q37: CM | S37: 00000 | U37: S012 | Z37: 000 | AA37: 000 S | AB37: S | AD37: 2025-09-24 | AE37: 20250924232237
A38: 015 | B38: 124 | C38: CANADA | D38: CANADA | E38: =+B38 -> 124 | G38: 2023-11-15-17.02.00.278380 | H38: ATHTAT91 | I38: CAN | J38: CACA | K38: L 15 | M38: 5 | N38: A1 | Q38: CA | R38: CC | S38: 00000 | T38: 97CA00CA | U38: 000 | Y38: SS06S03 | Z38: 000 | AA38: 000 S | AB38: S | AD38: 2025-09-24 | AE38: 20250924232237
A39: 015 | B39: 132 | C39: CABO VERDE | D39: CABO VERDE | E39: =+B39 -> 132 | G39: 2023-11-15-17.02.00.278452 | H39: ATHTAT91 | I39: CPV | J39: CVCVS | K39: M 14 | L39: S | M39: 5 | Q39: CV | S39: 00000 | T39: 97CV00CV | U39: S012 | W39: N | X39: N SS S | Y39: SS03S03 | Z39: 000 | AA39: 000 S | AB39: S | AD39: 2025-09-24 | AE39: 20250924232237
A40: 015 | B40: 136 | C40: CAIMANS, ILHAS | D40: CAYMAN ISLANDS | E40: =+B40 -> 136 | G40: 2023-11-15-17.02.00.278506 | H40: ATHTAT91 | I40: CYM | J40: KYKYS | K40: S H 08 | M40: 5 | Q40: KY | S40: 00000 | T40: 97KY00KY | U40: S000 | W40: N | X40: N SSSSS | Y40: S | Z40: 000 | AA40: 000 S | AB40: S | AD40: 2025-09-24 | AE40: 20250924232237
...

Sheet Sheet2
A1: a | C1: s
A2: United States of America | B2: ESTADOS UNIDOS | C2: =+VLOOKUP(A2,Sheet1!D:E,2,FALSE) -> #N/A | D2: =+VLOOKUP(A2,Sheet1!C:E,3,FALSE) -> #N/A | E2: 840 | F2: =+VLOOKUP(E2,Sheet1!B:C,2,FALSE) -> ESTADOS UNIDOS | G2: =+LEFT(F2,1)&LOWER(RIGHT(F2,LEN(F2)-1)) -> Estados unidos
A3: Canada | C3: =+VLOOKUP(A3,Sheet1!D:E,2,FALSE) -> 124 | E3: 124 | F3: =+VLOOKUP(E3,Sheet1!B:C,2,FALSE) -> CANADA | G3: =+LEFT(F3,1)&LOWER(RIGHT(F3,LEN(F3)-1)) -> Canada
A4: Greece | C4: =+VLOOKUP(A4,Sheet1!D:E,2,FALSE) -> 300 | E4: 300 | F4: =+VLOOKUP(E4,Sheet1!B:C,2,FALSE) -> GRECIA | G4: =+LEFT(F4,1)&LOWER(RIGHT(F4,LEN(F4)-1)) -> Grecia
A5: Bulgaria | C5: =+VLOOKUP(A5,Sheet1!D:E,2,FALSE) -> 100 | E5: 100 | F5: =+VLOOKUP(E5,Sheet1!B:C,2,FALSE) -> BULGARIA | G5: =+LEFT(F5,1)&LOWER(RIGHT(F5,LEN(F5)-1)) -> Bulgaria
A6: Lithuania | C6: =+VLOOKUP(A6,Sheet1!D:E,2,FALSE) -> 440 | E6: 440 | F6: =+VLOOKUP(E6,Sheet1!B:C,2,FALSE) -> LITUANIA | G6: =+LEFT(F6,1)&LOWER(RIGHT(F6,LEN(F6)-1)) -> Lituania
A7: Spain | C7: =+VLOOKUP(A7,Sheet1!D:E,2,FALSE) -> 724 | E7: 724 | F7: =+VLOOKUP(E7,Sheet1!B:C,2,FALSE) -> ESPANHA | G7: =+LEFT(F7,1)&LOWER(RIGHT(F7,LEN(F7)-1)) -> Espanha
A8: Portugal | C8: =+VLOOKUP(A8,Sheet1!D:E,2,FALSE) -> 620 | E8: 620 | F8: =+VLOOKUP(E8,Sheet1!B:C,2,FALSE) -> PORTUGAL | G8: =+LEFT(F8,1)&LOWER(RIGHT(F8,LEN(F8)-1)) -> Portugal
A9: Hungary | C9: =+VLOOKUP(A9,Sheet1!D:E,2,FALSE) -> 348 | E9: 348 | F9: =+VLOOKUP(E9,Sheet1!B:C,2,FALSE) -> HUNGRIA | G9: =+LEFT(F9,1)&LOWER(RIGHT(F9,LEN(F9)-1)) -> Hungria
A10: Croatia | C10: =+VLOOKUP(A10,Sheet1!D:E,2,FALSE) -> 191 | E10: 191 | F10: =+VLOOKUP(E10,Sheet1!B:C,2,FALSE) -> CROACIA | G10: =+LEFT(F10,1)&LOWER(RIGHT(F10,LEN(F10)-1)) -> Croacia
A11: Luxembourg | C11: =+VLOOKUP(A11,Sheet1!D:E,2,FALSE) -> 442 | E11: 442 | F11: =+VLOOKUP(E11,Sheet1!B:C,2,FALSE) -> LUXEMBURGO | G11: =+LEFT(F11,1)&LOWER(RIGHT(F11,LEN(F11)-1)) -> Luxemburgo
A12: Finland | C12: =+VLOOKUP(A12,Sheet1!D:E,2,FALSE) -> 246 | E12: 246 | F12: =+VLOOKUP(E12,Sheet1!B:C,2,FALSE) -> FINLANDIA | G12: =+LEFT(F12,1)&LOWER(RIGHT(F12,LEN(F12)-1)) -> Finlandia
A13: Sweden | C13: =+VLOOKUP(A13,Sheet1!D:E,2,FALSE) -> 752 | E13: 752 | F13: =+VLOOKUP(E13,Sheet1!B:C,2,FALSE) -> SUECIA | G13: =+LEFT(F13,1)&LOWER(RIGHT(F13,LEN(F13)-1)) -> Suecia
A14: Romania | C14: =+VLOOKUP(A14,Sheet1!D:E,2,FALSE) -> 642 | E14: 642 | F14: =+VLOOKUP(E14,Sheet1!B:C,2,FALSE) -> ROMENIA | G14: =+LEFT(F14,1)&LOWER(RIGHT(F14,LEN(F14)-1)) -> Romenia
... A33: Brazil | C33: =+VLOOKUP(A33,Sheet1!D:E,2,FALSE) -> 076 | E33: 076 | F33: =+VLOOKUP(E33,Sheet1!B:C,2,FALSE) -> BRASIL | G33: =+LEFT(F33,1)&LOWER(RIGHT(F33,LEN(F33)-1)) -> Brasil
A34: Brunei | B34: BRUNEI | C34: =+VLOOKUP(A34,Sheet1!D:E,2,FALSE) -> #N/A | D34: =+VLOOKUP(A34,Sheet1!C:E,3,FALSE) -> 096 | E34: 096 | F34: =+VLOOKUP(E34,Sheet1!B:C,2,FALSE) -> BRUNEI | G34: =+LEFT(F34,1)&LOWER(RIGHT(F34,LEN(F34)-1)) -> Brunei
A35: Chile | C35: =+VLOOKUP(A35,Sheet1!D:E,2,FALSE) -> 152 | E35: 152 | F35: =+VLOOKUP(E35,Sheet1!B:C,2,FALSE) -> CHILE | G35: =+LEFT(F35,1)&LOWER(RIGHT(F35,LEN(F35)-1)) -> Chile
A36: China | C36: =+VLOOKUP(A36,Sheet1!D:E,2,FALSE) -> 156 | E36: 156 | F36: =+VLOOKUP(E36,Sheet1!B:C,2,FALSE) -> CHINA, REPUBLICA POPULAR DA | G36: =+LEFT(F36,1)&LOWER(RIGHT(F36,LEN(F36)-1)) -> China, republica popular da
A37: Colombia | C37: =+VLOOKUP(A37,Sheet1!D:E,2,FALSE) -> 170 | E37: 170 | F37: =+VLOOKUP(E37,Sheet1!B:C,2,FALSE) -> COLOMBIA | G37: =+LEFT(F37,1)&LOWER(RIGHT(F37,LEN(F37)-1)) -> Colombia
A38: Egypt | C38: =+VLOOKUP(A38,Sheet1!D:E,2,FALSE) -> 818 | E38: 818 | F38: =+VLOOKUP(E38,Sheet1!B:C,2,FALSE) -> EGIPTO | G38: =+LEFT(F38,1)&LOWER(RIGHT(F38,LEN(F38)-1)) -> Egipto
A39: Ghana | C39: =+VLOOKUP(A39,Sheet1!D:E,2,FALSE) -> 288 | E39: 288 | F39: =+VLOOKUP(E39,Sheet1!B:C,2,FALSE) -> GANA | G39: =+LEFT(F39,1)&LOWER(RIGHT(F39,LEN(F39)-1)) -> Gana
A40: Hong Kong | C40: =+VLOOKUP(A40,Sheet1!D:E,2,FALSE) -> 344 | E40: 344 | F40: =+VLOOKUP(E40,Sheet1!B:C,2,FALSE) -> HONG KONG | G40: =+LEFT(F40,1)&LOWER(RIGHT(F40,LEN(F40)-1)) -> Hong kong
A41: India | C41: =+VLOOKUP(A41,Sheet1!D:E,2,FALSE) -> 356 | E41: 356 | F41: =+VLOOKUP(E41,Sheet1!B:C,2,FALSE) -> INDIA | G41: =+LEFT(F41,1)&LOWER(RIGHT(F41,LEN(F41)-1)) -> India
A42: Indonesia | C42: =+VLOOKUP(A42,Sheet1!D:E,2,FALSE) -> 360 | E42: 360 | F42: =+VLOOKUP(E42,Sheet1!B:C,2,FALSE) -> INDONESIA | G42: =+LEFT(F42,1)&LOWER(RIGHT(F42,LEN(F42)-1)) -> Indonesia
A43: Iran | B43: IRAO | C43: =+VLOOKUP(A43,Sheet1!D:E,2,FALSE) -> #N/A | D43: 364 | E43: 364 | F43: =+VLOOKUP(E43,Sheet1!B:C,2,FALSE) -> IRAO | G43: =+LEFT(F43,1)&LOWER(RIGHT(F43,LEN(F43)-1)) -> Irao
A44: Iraq | C44: =+VLOOKUP(A44,Sheet1!D:E,2,FALSE) -> 368 | E44: 368 | F44: =+VLOOKUP(E44,Sheet1!B:C,2,FALSE) -> IRAQUE | G44: =+LEFT(F44,1)&LOWER(RIGHT(F44,LEN(F44)-1)) -> Iraque
A45: Israel | C45: =+VLOOKUP(A45,Sheet1!D:E,2,FALSE) -> 376 | E45: 376 | F45: =+VLOOKUP(E45,Sheet1!B:C,2,FALSE) -> ISRAEL | G45: =+LEFT(F45,1)&LOWER(RIGHT(F45,LEN(F45)-1)) -> Israel
A46: Japan | C46: =+VLOOKUP(A46,Sheet1!D:E,2,FALSE) -> 392 | E46: 392 | F46: =+VLOOKUP(E46,Sheet1!B:C,2,FALSE) -> JAPAO | G46: =+LEFT(F46,1)&LOWER(RIGHT(F46,LEN(F46)-1)) -> Japao
A47: Jordan | C47: =+VLOOKUP(A47,Sheet1!D:E,2,FALSE) -> 400 | E47: 400 | F47: =+VLOOKUP(E47,Sheet1!B:C,2,FALSE) -> JORDANIA | G47: =+LEFT(F47,1)&LOWER(RIGHT(F47,LEN(F47)-1)) -> Jordania
A48: Kazakhstan | C48: =+VLOOKUP(A48,Sheet1!D:E,2,FALSE) -> 398 | E48: 398 | F48: =+VLOOKUP(E48,Sheet1!B:C,2,FALSE) -> KAZAQUISTAO | G48: =+LEFT(F48,1)&LOWER(RIGHT(F48,LEN(F48)-1)) -> Kazaquistao
A49: Kuwait | C49: =+VLOOKUP(A49,Sheet1!D:E,2,FALSE) -> 414 | E49: 414 | F49: =+VLOOKUP(E49,Sheet1!B:C,2,FALSE) -> KOWEIT | G49: =+LEFT(F49,1)&LOWER(RIGHT(F49,LEN(F49)-1)) -> Koweit
A50: Kyrgyzstan | C50: =+VLOOKUP(A50,Sheet1!D:E,2,FALSE) -> 417 | E50: 417 | F50: =+VLOOKUP(E50,Sheet1!B:C,2,FALSE) -> KYRGYZSTAN | G50: =+LEFT(F50,1)&LOWER(RIGHT(F50,LEN(F50)-1)) -> Kyrgyzstan
A51: Lebanon | C51: =+VLOOKUP(A51,Sheet1!D:E,2,FALSE) -> 422 | E51: 422 | F51: =+VLOOKUP(E51,Sheet1!B:C,2,FALSE) -> LIBANO | G51: =+LEFT(F51,1)&LOWER(RIGHT(F51,LEN(F51)-1)) -> Libano
A52: Libya | C52: =+VLOOKUP(A52,Sheet1!D:E,2,FALSE) -> 434 | E52: 434 | F52: =+VLOOKUP(E52,Sheet1!B:C,2,FALSE) -> LIBIA | G52: =+LEFT(F52,1)&LOWER(RIGHT(F52,LEN(F52)-1)) -> Libia
A53: Malaysia | C53: =+VLOOKUP(A53,Sheet1!D:E,2,FALSE) -> 458 | E53: 458 | F53: =+VLOOKUP(E53,Sheet1!B:C,2,FALSE) -> MALASIA | G53: =+LEFT(F53,1)&LOWER(RIGHT(F53,LEN(F53)-1)) -> Malasia
A54: Mauritania | C54: =+VLOOKUP(A54,Sheet1!D:E,2,FALSE) -> 478 | E54: 478 | F54: =+VLOOKUP(E54,Sheet1!B:C,2,FALSE) -> MAURITANIA | G54: =+LEFT(F54,1)&LOWER(RIGHT(F54,LEN(F54)-1)) -> Mauritania
A55: Mexico | C55: =+VLOOKUP(A55,Sheet1!D:E,2,FALSE) -> 484 | E55: 484 | F55: =+VLOOKUP(E55,Sheet1!B:C,2,FALSE) -> MEXICO | G55: =+LEFT(F55,1)&LOWER(RIGHT(F55,LEN(F55)-1)) -> Mexico
... A61: Pakistan | C61: =+VLOOKUP(A61,Sheet1!D:E,2,FALSE) -> 586 | E61: 586 | F61: =+VLOOKUP(E61,Sheet1!B:C,2,FALSE) -> PAQUISTAO | G61: =+LEFT(F61,1)&LOWER(RIGHT(F61,LEN(F61)-1)) -> Paquistao
A62: Palestine | B62: PALESTINE STATE OFF | C62: =+VLOOKUP(A62,Sheet1!D:E,2,FALSE) -> #N/A | D62: =+VLOOKUP(A62,Sheet1!C:E,3,FALSE) -> #N/A | E62: 275 | F62: =+VLOOKUP(E62,Sheet1!B:C,2,FALSE) -> PALESTINE STATE OFF | G62: =+LEFT(F62,1)&LOWER(RIGHT(F62,LEN(F62)-1)) -> Palestine state off
A63: Philippines | C63: =+VLOOKUP(A63,Sheet1!D:E,2,FALSE) -> 608 | E63: 608 | F63: =+VLOOKUP(E63,Sheet1!B:C,2,FALSE) -> FILIPINAS | G63: =+LEFT(F63,1)&LOWER(RIGHT(F63,LEN(F63)-1)) -> Filipinas
...
