Workbook

Sheet Proposta
B2: 1. Definição do campo CNCLLD_INSTRMNT_STTS
B4: A coluna "Ordem" indica a ordem pela qual a regra (Coluna F) seria aplicada de forma a classificar os contratos nos códigos respetivos.
C7: As-is | F7: Sugestão to-be pós reunião 04/fev
B8: Código | C8: Descritivo | D8: Definição Guia Corporativo (20/09/2024) | E8: Regra implementada | F8: Descritivo | G8: Definição Guia Corporativo (24/01/2025) | H8: Regra | I8: Ordem
B9: N | C9: Not cancelled | D9: Instruments that have not been terminated during the month of the reporting reference date. | E9: Contratos que se encontram na FR001. | F9: Not cancelled | G9: Instrumentos que no han terminado a lo largo del año hasta la fecha de referencia del informe. | H9: Contratos que se encontram na FR001 | I9: 1
B10: I | C10: Intermittent instrument | D10: This is an instrument that is reported in one period, then not reported in the next period (but the instrument is not cancelled) and then again is reported in the next period. This case happens sometimes in specific products (e.g. revoving products, current accounts, etc.) | E10: Quando cumprir as condições para ser cancelado1 e for produto DO ou cartões (com base no ckmetamis). | F10: Intermittent instrument | G10: Estos son instrumentos que aparecen y desaparecen en distintos periodos del reporting pero no están cancelados, es decir, el instrumento se informa en un periodo, luego no se informa en el siguiente periodo (pero el instrumento no se cancela) y luego se vuelve a informar en el siguiente periodo. Este caso ocurre a veces en productos específicos (por ejemplo, productos revolving, cuentas corrientes, etc.) | H10: - | I10: -
B11: M | C11: Intramonth cancelled instrument | D11: These are instruments that are originated and terminated during the same month of the reporting reference date | E11: O universo criado com o sufixo da bsnn_area, deve ser reportado com a flag CNCLLD_INSTRMNT_STTS = “M”. | F11: Interannual cancelled instrument | G11: Estos son instrumentos que se originan y terminan a lo largo del año de la fecha de referencia del reporting. | H11: Contratos que não se encontram na FR001 e apresentam data de inicio (DINIOPER) no ano de referencia e data de fim (DVNCOPER) no mês da data de reporte. | I11: 2
B12: C | C12: Cancelled | D12: Units should report as cancelled all the instruments that have been terminated during the month of the reporting reference date and that are not reported as CNCLLD_INSTRMNT_STTS = ‘M’ or ‘I’. | E12: Quando cumprir as condições para ser cancelado1 e não for produto DO ou cartões (com base no ckmetamis). | F12: Cancelled | G12: Las unidades deben informar los instrumentos que han terminado a lo largo del año de reporte hasta la fecha de referencia del reporting y que no se informen como CNCLLD_INSTRMNT_STTS = 'M' o 'I'. | H12: Contratos que não se encontram na FR001 e apresentam data de fim (DVNCOPER) anterior ao ano da data de reporte. | I12: 3
B14: 1Condições para ser considerado cancelado:

Sheet Campos
B2: 2. Análise dos campos a preencher para contratos cancelados
B4: "Instrument cancelled" inclui os casos para os quais o campo CNCLLD_INSTRMNT_STTS in (M, C e I)
E5: Sugestão to-be pré reunião 04/fev | H5: Sugestão to-be pós reunião 04/fev
B6: Table | C6: Data field | D6: Instrument cancelled (this column only applies to report the instrument and instrument activity tables) | E6: C | F6: M | G6: I | H6: C + M | I6: Observações
B7: lt002_instrument | C7: COD_SOC | D7: Y | E7: Y | F7: Y | G7: Y | H7: Y
B8: lt002_instrument | C8: SUBPORTFOLIO_ID | D8: Y | E8: Y | F8: Y | G8: Y | H8: N
B9: lt002_instrument | C9: DT_RFRNC | D9: Y | E9: Y | F9: Y | G9: Y | H9: Y
B10: lt002_instrument | C10: INSTRMNT_ID | D10: Y | E10: Y | F10: Y | G10: Y | H10: Y
B11: lt002_instrument | C11: DFLT_STTS_INSTRMNT | D11: Y | E11: N | F11: N | G11: Y | H11: N | I11: Situação de default do instrumento à data do reporte de acordo com o NDD
B12: lt002_instrument | C12: IMPRMNT_STTS | D12: Y | E12: N | F12: N | G12: Y | H12: N
B13: lt002_instrument | C13: PRFRMNG_STTS | D13: Y | E13: N | F13: N | G13: Y | H13: N
B14: lt002_instrument | C14: TYP_INSTRMNT | D14: Y | E14: Y | F14: Y | G14: Y | H14: N | I14: FC: acho que deviamos discutir este
B15: lt002_instrument | C15: GRSS_CRRYNG_AMNT_INSTRMNT | D15: Y | E15: N | F15: N | G15: Y | H15: N
B16: lt002_instrument | C16: ACCMLTD_CHNGS_FV_CR_INSTRMNT | D16: Y | E16: N | F16: N | G16: Y | H16: N
B17: lt002_instrument | C17: ACCNTNG_CLSSFCTN | D17: Y | E17: N | F17: N | G17: Y | H17: N
B18: lt002_instrument | C18: OFF_BLNC_SHT_AMNT_INSTRMNT | D18: Y | E18: N | F18: N | G18: Y | H18: N
B19: lt002_instrument | C19: PRVSNS_OFF_BLNC_SHT | D19: Y | E19: N | F19: N | G19: Y | H19: N
B20: lt002_instrument | C20: RWA | D20: Y | E20: N | F20: N | G20: Y | H20: N
B21: lt002_instrument | C21: ACCMLTD_IMPRMNT_INSTRMNT | D21: Y | E21: N | F21: N | G21: Y | H21: N
B22: lt002_instrument | C22: COD_SOC_INTRGRP | D22: Y | E22: Y | F22: Y | G22: Y | H22: N
B23: lt002_instrument | C23: LCL_INSTMRNT_ID | D23: Y | E23: Y | F23: Y | G23: Y | H23: Y
B24: lt002_instrument | C24: AVRG_BLNC | D24: Y | E24: ? | F24: Y | G24: Y | H24: Y
B25: lt002_instrument | C25: NW_BSNSS | D25: Y | E25: Y | F25: Y | G25: Y | H25: Y | I25: Confirmar com corporação
B26: lt002_instrument | C26: GRSS_INTRST_INCM | D26: Y | E26: Y | F26: Y | G26: Y | H26: Y
B27: lt002_instrument | C27: GRSS_CMMSSN_INCM | D27: Y | E27: Y | F27: Y | G27: Y | H27: Y
B28: lt002_instrument | C28: INTRNL_TRNSFR_RT | D28: Y | E28: Y | F28: Y | G28: Y | H28: Y
B29: lt002_instrument | C29: NT_LN_LSS_PRVSN | D29: Y | E29: N | F29: N | G29: Y | H29: Y | I29: FC: acho que deviamos discutir este
B30: lt002_instrument | C30: BSNSS_AREA | D30: Y | E30: Y | F30: Y | G30: Y | H30: Y
B31: lt002_instrument | C31: MNGMNT_PRDCT | D31: Y | E31: Y | F31: Y | G31: Y | H31: Y
B32: lt002_instrument | C32: GRSS_CMMSSN_EXPNS | D32: Y | E32: Y | F32: Y | G32: Y | H32: Y
B33: lt002_instrument | C33: GNS_FNNCL_TRNSCTN_EXCHNG_DFFRNCS | D33: Y | E33: N | F33: N | G33: Y | H33: Y
B34: lt002_instrument | C34: FLG_INTRBSNSS | D34: Y | E34: Y | F34: Y | G34: Y | H34: N | I34: Sempre preenchido com "N"
B35: lt002_instrument | C35: INTRBSNSS_ADJ_COD | D35: Y | E35: N | F35: N | G35: N | H35: N | I35: Preenchido com o not applicable
B36: lt002_instrument | C36: COD_SOC_DSTNTN | D36: Y | E36: N | F36: N | G36: N | H36: N | I36: Preenchido com o not applicable
B37: lt002_instrument | C37: BSNSS_AREA_DSTNTN | D37: Y | E37: N | F37: N | G37: N | H37: N | I37: Preenchido com o not applicable
B38: lt002_instrument | C38: AVRG_BLNC_OFF_BLNC | D38: Y | E38: ? | F38: Y | G38: Y | H38: Y
B39: lt002_instrument | C39: INTRNL_TRNSFR_RT_OFF_BLNC | D39: Y | E39: N | F39: N | G39: N | H39: N | I39: Preenchido com o not applicable
B40: lt002_instrument | C40: GRSS_CMMSSN_INCM_OFF_BLNC | D40: Y | E40: Y | F40: Y | G40: Y | H40: Y
B41: lt002_instrument | C41: GRSS_CMMSSN_EXPNS_OFF_BLNC | D41: Y | E41: Y | F41: Y | G41: Y | H41: Y
B42: lt002_instrument | C42: RWA_OFF_BLNC | D42: Y | E42: N | F42: N | G42: Y | H42: N
...

Sheet Email 
D2: Guia Corporativo | E2: Sugestão to-be
B3: Table | C3: Data field | D3: Instrument cancelled (this column only applies to report the instrument and instrument activity tables) | E3: M + C
B4: lt002_instrument | C4: COD_SOC | D4: Y | E4: Y | F4: =+VLOOKUP(C4,Auxiliar!$C$4:$D$54,2,FALSE) -> Default value not allowed
B5: lt002_instrument | C5: SUBPORTFOLIO_ID | D5: Y | E5: N | F5: =+VLOOKUP(C5,Auxiliar!$C$4:$D$54,2,FALSE) -> Default value not allowed
B6: lt002_instrument | C6: DT_RFRNC | D6: Y | E6: Y | F6: =+VLOOKUP(C6,Auxiliar!$C$4:$D$54,2,FALSE) -> Default value not allowed
B7: lt002_instrument | C7: INSTRMNT_ID | D7: Y | E7: Y | F7: =+VLOOKUP(C7,Auxiliar!$C$4:$D$54,2,FALSE) -> Default value not allowed
B8: lt002_instrument | C8: DFLT_STTS_INSTRMNT | D8: Y | E8: N | F8: =+VLOOKUP(C8,Auxiliar!$C$4:$D$54,2,FALSE) -> Default value not allowed
B9: lt002_instrument | C9: IMPRMNT_STTS | D9: Y | E9: N | F9: =+VLOOKUP(C9,Auxiliar!$C$4:$D$54,2,FALSE) -> 11111111111
B10: lt002_instrument | C10: PRFRMNG_STTS | D10: Y | E10: N | F10: =+VLOOKUP(C10,Auxiliar!$C$4:$D$54,2,FALSE) -> Default value not allowed
B11: lt002_instrument | C11: TYP_INSTRMNT | D11: Y | E11: N | F11: =+VLOOKUP(C11,Auxiliar!$C$4:$D$54,2,FALSE) -> Default value not allowed
B12: lt002_instrument | C12: GRSS_CRRYNG_AMNT_INSTRMNT | D12: Y | E12: N | F12: =+VLOOKUP(C12,Auxiliar!$C$4:$D$54,2,FALSE) -> 11111111111
B13: lt002_instrument | C13: ACCMLTD_CHNGS_FV_CR_INSTRMNT | D13: Y | E13: N | F13: =+VLOOKUP(C13,Auxiliar!$C$4:$D$54,2,FALSE) -> 11111111111
B14: lt002_instrument | C14: ACCNTNG_CLSSFCTN | D14: Y | E14: N | F14: =+VLOOKUP(C14,Auxiliar!$C$4:$D$54,2,FALSE) -> 11111111111
B15: lt002_instrument | C15: OFF_BLNC_SHT_AMNT_INSTRMNT | D15: Y | E15: N | F15: =+VLOOKUP(C15,Auxiliar!$C$4:$D$54,2,FALSE) -> 11111111111
... B52: lt002_instrument | C52: TYP_OFF_BLNC_PRDCT | D52: Y | E52: N | F52: =+VLOOKUP(C52,Auxiliar!$C$4:$D$54,2,FALSE) -> N/A
B53: lt007_instr_activity | C53: COD_SOC | D53: Y | E53: Y | F53: Default value not allowed
B54: lt007_instr_activity | C54: DT_RFRNC | D54: Y | E54: Y | F54: Default value not allowed
B55: lt007_instr_activity | C55: INSTRMNT_ID | D55: Y | E55: Y | F55: Default value not allowed
B56: lt007_instr_activity | C56: SSTNBL_CTGRY | D56: Y | E56: Y | F56: Default value not allowed
B57: lt007_instr_activity | C57: PRCNTG_ACTVTY | D57: Y | E57: N | F57: Default value not allowed
B58: lt007_instr_activity | C58: SSTNBL_INDCTR | D58: Y | E58: Y | F58: Default value not allowed

Sheet Auxiliar
D3: NOT APPLICABLE
B4: INSTRUMENT | C4: AVRG_BLNC_OFF_BLNC | D4: 11111111111
B5: INSTRUMENT | C5: AVRG_BLNC | D5: 11111111111
B6: INSTRUMENT | C6: NW_BSNSS | D6: Default value not allowed
B7: INSTRUMENT | C7: GRSS_INTRST_INCM | D7: 11111111111
B8: INSTRUMENT | C8: GRSS_CMMSSN_INCM | D8: 11111111111
B9: INSTRUMENT | C9: INTRNL_TRNSFR_RT | D9: 11111111111
B10: INSTRUMENT | C10: NT_LN_LSS_PRVSN | D10: 11111111111
B11: INSTRUMENT | C11: BSNSS_AREA | D11: Default value not allowed
B12: INSTRUMENT | C12: MNGMNT_PRDCT | D12: Default value not allowed
B13: INSTRUMENT | C13: GRSS_CMMSSN_EXPNS | D13: 11111111111
B14: INSTRUMENT | C14: GNS_FNNCL_TRNSCTN_EXCHNG_DFFRNCS | D14: 11111111111
B15: INSTRUMENT | C15: FLG_INTRBSNSS | D15: Default value not allowed
B16: INSTRUMENT | C16: INTRBSNSS_ADJ_COD | D16: N/A
B17: INSTRUMENT | C17: COD_SOC_DSTNTN | D17: 00000
B18: INSTRUMENT | C18: BSNSS_AREA_DSTNTN | D18: N/A
B19: INSTRUMENT | C19: INTRNL_TRNSFR_RT_OFF_BLNC | D19: 11111111111
B20: INSTRUMENT | C20: GRSS_CMMSSN_INCM_OFF_BLNC | D20: 11111111111
B21: INSTRUMENT | C21: GRSS_CMMSSN_EXPNS_OFF_BLNC | D21: 11111111111
B22: INSTRUMENT | C22: RWA_OFF_BLNC | D22: Default value not allowed
B23: INSTRUMENT | C23: GRSS_INTRST_EXPNS | D23: 11111111111
B24: INSTRUMENT | C24: NT_LN_LSS_PRVSN_OFF_BLNC | D24: 11111111111
B25: INSTRUMENT | C25: GRSS_INTRST_INCM_CCRR | D25: 11111111111
B26: INSTRUMENT | C26: GRSS_INTRST_EXPNS_CCRR | D26: 11111111111
B27: INSTRUMENT | C27: GRSS_CMMSSN_INCM_CCRR | D27: 11111111111
B28: INSTRUMENT | C28: GRSS_CMMSSN_EXPNS_CCRR | D28: 11111111111
B29: INSTRUMENT | C29: GNS_FNNCL_TRNSCTN_EXCHNG_CCRR | D29: 11111111111
B30: INSTRUMENT | C30: BSNSS_AREA_CCRR | D30: Default value not allowed
B31: INSTRUMENT | C31: GRSS_CMMSSN_INCM_OFF_BLNC_CCRR | D31: 11111111111
B32: INSTRUMENT | C32: GRSS_CMMSSN_EXPNS_OFF_BLNC_CCRR | D32: 11111111111
B33: INSTRUMENT | C33: COD_SOC | D33: Default value not allowed
B34: INSTRUMENT | C34: SUBPORTFOLIO_ID | D34: Default value not allowed
B35: INSTRUMENT | C35: DT_RFRNC | D35: Default value not allowed
B36: INSTRUMENT | C36: INSTRMNT_ID | D36: Default value not allowed
B37: INSTRUMENT | C37: DFLT_STTS_INSTRMNT | D37: Default value not allowed
B38: INSTRUMENT | C38: IMPRMNT_STTS | D38: 11111111111
B39: INSTRUMENT | C39: PRFRMNG_STTS | D39: Default value not allowed
B40: INSTRUMENT | C40: TYP_INSTRMNT | D40: Default value not allowed
B41: INSTRUMENT | C41: GRSS_CRRYNG_AMNT_INSTRMNT | D41: 11111111111
B42: INSTRUMENT | C42: ACCMLTD_CHNGS_FV_CR_INSTRMNT | D42: 11111111111
...
