Workbook
Name IQ_CH: 110000
Name IQ_CQ: 5000
Name IQ_CY: 10000
Name IQ_DAILY: 500000
Name IQ_FH: 100000
Name IQ_FQ: 500
Name IQ_FY: 1000
Name IQ_LTM: 2000
Name IQ_MONTH: 15000
Name IQ_NTM: 6000
Name IQ_WEEK: 50000
Name IQ_YTD: 3000

Sheet 0_ReadMe
B1: Instructions: ICAAP Template
B3: · Only provide the information and data that are internally available - do not change or produce internal numbers for the sole purpose of filling in the template.
B4: · Please use your risk quantifications and your internal capital from the economic ICAAP perspective to fill-in the template.
B5: · Only use risk categories and sub-categories as they are used by you internally; broken down in accordance with the level of granularity you apply internally; and according to your internal definitions (including internal definitions of trading and banking book under the economic perspective if such separation is used by the bank).
B6: · Pre-defined sub-categories in the drop-down menu aim at accommodating as many banks’ practices as possible. For example, some sub-categories are available under different risk types in the template (e.g. insurance participation or residual value risks are also available in the credit risk category although they can be expected to be reported under other risk categories). Accordingly, the availability or non-availability of a sub-category does not imply that a certain risk taxonomy can be considered more or less in line with ECB ICAAP expectation. The underlying list of risks is neither exhaustive nor mandatory. Rather, please provide and follow in any case your internal risk taxonomies.
B7: · The expectation is that all material risks are identified and taken into account in the ICAAP (according to Principle 4 of the ECB guide on ICAAP). · `Inter-risk concentration’ (row 74) has been pre-selected for all banks because such concentrations across risk types can be a severe threat to banks’ continuation. Experience shows that a considerable number of banks do not systematically consider such concentrations. The pre-selection of this category is meant to remind banks of the importance of such concentrations. This row is aimed at collecting information on the size and the treatment of inter-risk concentration effects. The figures entered in column 1.5 can only be positive, i.e. increasing the risk amount overall. If a bank quantifies both inter-risk concentrations and inter-risk diversification (row 87), then it should provide figures for both categories on a gross basis, i.e. figures should not be netted in the template. If no figure is quantified by the bank, these cells should be left blank. · In their risk inventory, institutions are expected to take into account the underlying risks, where material, stemming from their financial and non-financial participations, subsidiaries and other connected entities (see par. 65 of ECB ICAAP Guide). In a proportionate way, banks are expected to look beyond participation risks and identify, understand and quantify significant underlying risks, and take them into account in its internal risk taxonomy, regardless of whether the entities concerned are included in the prudential perimeter or not (see par. 66 of ECB ICAAP Guide).
B8: · Please check the risk categories and sub-categories provided in the drop-down lists and insert information to the extent possible in separate rows for all sub-categories that are captured by your internal risk quantifications. If a sub-category from a drop-down list is captured by your ICAAP, but you do not quantify it separately, please follow the guidance on "Columns 1.5 and 1.6" below.
B9: · Please map your internal risk (sub-)categories to risk (sub-)categories as suggested in the drop-down lists, where applicable. If it is not possible to map an internal (sub-)category, use "other" sub-categories from the drop down list or, if it is not part of any listed risk category, use the "other risks" rows. It should be noted that the (sub-)categories proposed in the template do not represent a complete taxonomy with full coverage and without overlap. However, institutions are expected to avoid overlap between their selected (sub-)categories, i.e. the total ICAAP figure should be the sum of the reported figures for (sub-)categories.
B10: · If a cell is not applicable to the institution, please leave it blank (do not use "NA" or the Excel function NA()).
B11: · Only yellow cells can be filled in.
B12: · Please do not rename the sheets of the template and do not change the format.
B13: · Please note that there is a general validation rule in place in CASPER that requires all expected data points to be reported. If any expected data points are missing, regardless of the specific cases, the validation rule will be triggered. In the event that you have not reported an expected data point due to it not applying or due to specific circumstances, you are required to provide a comment in the discussion tab in CASPER explaining the reason for not reporting that specific data point.
... B44: · This example is purely indicative and based on a hypothetical case. Some specifics might not apply in all cases.

Sheet 0_Identification
B2: General information - ICAAP Template
B5: Country: (two letter ISO code)
B7: Bank code: (RIAD MFI code)
B9: Bank LEI code:
B11: Bank name:
B13: Reference date: T (dd/mm/yyyy)
B15: Level of consolidation:
B17: Comments:

Sheet 1_ICAAPrisk+cap
B3: ICAAP Template - Information on internal risk categories and internal capital | S3: yes
S4: no
B6: Risk Categories | D6: ICAAP information
B7: 1.1 Risk categories | C7: 1.2 Risk sub-category | D7: 1.3 Name of internal risk category as currently covered in ICAAP | E7: 1.4 Short description of internal risk category | F7: 1.5 ICAAP figure - internal capital needed (one-year view) in EUR | G7: 1.6 Included in other risk category / sub-category | H7: 1.7 Have there been material changes in scope or quantification methodology for this risk category / sub-category since the last reporting date? (yes/no) | I7: 1.8 Link to the internal documentation on the quantification methodology | J7: 1.9 Further explanation
C8: 010 | D8: 020 | E8: 030 | F8: 040 | G8: 050 | H8: 060 | I8: 070 | J8: 080
B9: Credit risk | C9: Total | F9: =SUM(F10:F24) -> 0
L10: =AND(ISNUMBER($F10), OR(AND($C10='Drop-down lists '!$B$23,$F10<0), AND(AND($C10<>'Drop-down lists '!$B$23, $C10<>""),$F10>0))) -> FALSE
L11: =AND(ISNUMBER($F11), OR(AND($C11='Drop-down lists '!$B$23,$F11<0), AND(AND($C11<>'Drop-down lists '!$B$23, $C11<>""),$F11>0))) -> FALSE
L12: =AND(ISNUMBER($F12), OR(AND($C12='Drop-down lists '!$B$23,$F12<0), AND(AND($C12<>'Drop-down lists '!$B$23, $C12<>""),$F12>0))) -> FALSE
L13: =AND(ISNUMBER($F13), OR(AND($C13='Drop-down lists '!$B$23,$F13<0), AND(AND($C13<>'Drop-down lists '!$B$23, $C13<>""),$F13>0))) -> FALSE
L14: =AND(ISNUMBER($F14), OR(AND($C14='Drop-down lists '!$B$23,$F14<0), AND(AND($C14<>'Drop-down lists '!$B$23, $C14<>""),$F14>0))) -> FALSE
L15: =AND(ISNUMBER($F15), OR(AND($C15='Drop-down lists '!$B$23,$F15<0), AND(AND($C15<>'Drop-down lists '!$B$23, $C15<>""),$F15>0))) -> FALSE
L16: =AND(ISNUMBER($F16), OR(AND($C16='Drop-down lists '!$B$23,$F16<0), AND(AND($C16<>'Drop-down lists '!$B$23, $C16<>""),$F16>0))) -> FALSE
L17: =AND(ISNUMBER($F17), OR(AND($C17='Drop-down lists '!$B$23,$F17<0), AND(AND($C17<>'Drop-down lists '!$B$23, $C17<>""),$F17>0))) -> FALSE
L18: =AND(ISNUMBER($F18), OR(AND($C18='Drop-down lists '!$B$23,$F18<0), AND(AND($C18<>'Drop-down lists '!$B$23, $C18<>""),$F18>0))) -> FALSE
L19: =AND(ISNUMBER($F19), OR(AND($C19='Drop-down lists '!$B$23,$F19<0), AND(AND($C19<>'Drop-down lists '!$B$23, $C19<>""),$F19>0))) -> FALSE
L20: =AND(ISNUMBER($F20), OR(AND($C20='Drop-down lists '!$B$23,$F20<0), AND(AND($C20<>'Drop-down lists '!$B$23, $C20<>""),$F20>0))) -> FALSE
L21: =AND(ISNUMBER($F21), OR(AND($C21='Drop-down lists '!$B$23,$F21<0), AND(AND($C21<>'Drop-down lists '!$B$23, $C21<>""),$F21>0))) -> FALSE
... L24: =AND(ISNUMBER($F24), OR(AND($C24='Drop-down lists '!$B$23,$F24<0), AND(AND($C24<>'Drop-down lists '!$B$23, $C24<>""),$F24>0))) -> FALSE
B25: Market risk | C25: Total | F25: =SUM(F26:F40) -> 0
L26: =AND(ISNUMBER($F26), OR(AND($C26='Drop-down lists '!$B$23,$F26<0), AND(AND($C26<>'Drop-down lists '!$B$23, $C26<>""),$F26>0))) -> FALSE
L27: =AND(ISNUMBER($F27), OR(AND($C27='Drop-down lists '!$B$23,$F27<0), AND(AND($C27<>'Drop-down lists '!$B$23, $C27<>""),$F27>0))) -> FALSE
L28: =AND(ISNUMBER($F28), OR(AND($C28='Drop-down lists '!$B$23,$F28<0), AND(AND($C28<>'Drop-down lists '!$B$23, $C28<>""),$F28>0))) -> FALSE
L29: =AND(ISNUMBER($F29), OR(AND($C29='Drop-down lists '!$B$23,$F29<0), AND(AND($C29<>'Drop-down lists '!$B$23, $C29<>""),$F29>0))) -> FALSE
L30: =AND(ISNUMBER($F30), OR(AND($C30='Drop-down lists '!$B$23,$F30<0), AND(AND($C30<>'Drop-down lists '!$B$23, $C30<>""),$F30>0))) -> FALSE
L31: =AND(ISNUMBER($F31), OR(AND($C31='Drop-down lists '!$B$23,$F31<0), AND(AND($C31<>'Drop-down lists '!$B$23, $C31<>""),$F31>0))) -> FALSE
L32: =AND(ISNUMBER($F32), OR(AND($C32='Drop-down lists '!$B$23,$F32<0), AND(AND($C32<>'Drop-down lists '!$B$23, $C32<>""),$F32>0))) -> FALSE
L33: =AND(ISNUMBER($F33), OR(AND($C33='Drop-down lists '!$B$23,$F33<0), AND(AND($C33<>'Drop-down lists '!$B$23, $C33<>""),$F33>0))) -> FALSE
L34: =AND(ISNUMBER($F34), OR(AND($C34='Drop-down lists '!$B$23,$F34<0), AND(AND($C34<>'Drop-down lists '!$B$23, $C34<>""),$F34>0))) -> FALSE
L35: =AND(ISNUMBER($F35), OR(AND($C35='Drop-down lists '!$B$23,$F35<0), AND(AND($C35<>'Drop-down lists '!$B$23, $C35<>""),$F35>0))) -> FALSE
L36: =AND(ISNUMBER($F36), OR(AND($C36='Drop-down lists '!$B$23,$F36<0), AND(AND($C36<>'Drop-down lists '!$B$23, $C36<>""),$F36>0))) -> FALSE
L37: =AND(ISNUMBER($F37), OR(AND($C37='Drop-down lists '!$B$23,$F37<0), AND(AND($C37<>'Drop-down lists '!$B$23, $C37<>""),$F37>0))) -> FALSE
... L40: =AND(ISNUMBER($F40), OR(AND($C40='Drop-down lists '!$B$23,$F40<0), AND(AND($C40<>'Drop-down lists '!$B$23, $C40<>""),$F40>0))) -> FALSE
B41: IRRBB & CSRBB | C41: Total | F41: =SUM(F42:F56) -> 0
L42: =AND(ISNUMBER($F42), OR(AND($C42='Drop-down lists '!$B$23,$F42<0), AND(AND($C42<>'Drop-down lists '!$B$23, $C42<>""),$F42>0))) -> FALSE
L43: =AND(ISNUMBER($F43), OR(AND($C43='Drop-down lists '!$B$23,$F43<0), AND(AND($C43<>'Drop-down lists '!$B$23, $C43<>""),$F43>0))) -> FALSE
L44: =AND(ISNUMBER($F44), OR(AND($C44='Drop-down lists '!$B$23,$F44<0), AND(AND($C44<>'Drop-down lists '!$B$23, $C44<>""),$F44>0))) -> FALSE
L45: =AND(ISNUMBER($F45), OR(AND($C45='Drop-down lists '!$B$23,$F45<0), AND(AND($C45<>'Drop-down lists '!$B$23, $C45<>""),$F45>0))) -> FALSE
L46: =AND(ISNUMBER($F46), OR(AND($C46='Drop-down lists '!$B$23,$F46<0), AND(AND($C46<>'Drop-down lists '!$B$23, $C46<>""),$F46>0))) -> FALSE
L47: =AND(ISNUMBER($F47), OR(AND($C47='Drop-down lists '!$B$23,$F47<0), AND(AND($C47<>'Drop-down lists '!$B$23, $C47<>""),$F47>0))) -> FALSE
...

Sheet 2_Example
B3: ICAAP Template - Information on internal risk categories and internal capital | S3: yes
S4: no
B6: SSM risk map | D6: ICAAP information
B7: 1.1 Risk categories | C7: 1.2 Risk sub-category | D7: 1.3 Name of internal risk category as currently covered in ICAAP | E7: 1.4 Short description of internal risk category | F7: 1.5 ICAAP figure - internal capital needed (one-year view) in EUR | G7: 1.6 Included in other risk category / sub-category | H7: 1.7 Have there been material changes in scope or quantification methodology for this risk category / sub-category since the last reporting date? (yes/no) | I7: 1.8 Link to the internal documentation on the quantification methodology | J7: 1.9 Further explanation
B8: Credit risk | C8: Total | F8: =SUM(F9:F20) -> 319900000
C9: Credit risk (not broken down into sub-categories) | D9: Credit risk | E9: Covers default and residual risk | F9: 300000000 | G9: no | H9: no | I9: Document 2, as defined in Reader's manual, pp. 101-105.
C10: Credit concentration risk | D10: Concentration risk | E10: Includes single name concentration risk and sectoral concentration risk | F10: 7000000 | G10: no | H10: yes | I10: Document 2, as defined in Reader's manual, pp. 151-155. | J10: The granularity of the definition of economic sectors changed from 11 GICS sectors to 24 GICS industry groups.
C11: FX lending risk | D11: FX lending risk | E11: Current or prospective risk to the institution’s earnings and own funds arising from FX lending to unhedged borrowers. | F11: 850000 | G11: no | H11: no | I11: Document 2, as defined in Reader's manual, pp. 181-185.
C12: Securitisation risk | D12: Credit risk from securitisations | E12: Covers risks arising from securitisation transactions in relation to which the credit institutions are investor, originator or sponsor, including reputational risks such as those which arise in relation to complex structures or products. | F12: 2150000 | G12: no | H12: no | I12: Document 2, as defined in Reader's manual, pp. 196-200.
C13: Country risk (includes transfer & other risks) | D13: Country risk | E13: Covers transfer risk, sovereign intervention risk and collective debtor risk | F13: 1200000 | G13: no | H13: no | I13: Document 2, as defined in Reader's manual, pp. 261-265.
C14: Counterparty risk | D14: Counterparty credit risk and settlement risk | E14: Includes settlement and delivery risk. | F14: 6000000 | G14: no | H14: no | I14: Document 2, as defined in Reader's manual, pp. 301-307.
C15: Other (1) | D15: Specialised lending | E15: Covers risk stemming from the profitability of the asset or of the project financed | F15: 1400000 | G15: no | H15: no | I15: Document 2, as defined in Reader's manual, pp. 376-380.
C16: other (2) | D16: step-in risk | E16: Covers risk of losses from credit enhancements provided to structured vehicules | F16: 1300000 | G16: no | H16: no | I16: Document 2, as defined in Reader's manual, pp. 390-395.
C17: Default risk | D17: Doesn't correspond to an internal risk category currently covered in ICAAP. | E17: Included in credit risk | G17: C1 | H17: no
C18: Settlement and delivery risk | D18: Doesn't correspond to an internal risk category currently covered in ICAAP. | E18: Included in counterparty credit risk and settlement risk | G18: C6 | H18: no
C19: Residual risk | D19: Doesn't correspond to an internal risk category currently covered in ICAAP. | E19: Included in credit risk | G19: C1 | H19: no
B21: Market risk | C21: Total | F21: =SUM(F22:F31) -> 73800000
C22: Market risk (not broken down into sub-categories) | D22: Market risk - Other | E22: Includes market concentration risk and migration risk | F22: 5000000 | G22: no | H22: no | I22: Document 2, as defined in Reader's manual, pp. 500-505.
C23: Interest rate risk | D23: Interest rate risk | E23: The risk of loss on financial instruments from changes in interest rates | F23: 28000000 | G23: no | H23: no | I23: Document 2, as defined in Reader's manual, pp. 401-410.
C24: Equity risk | D24: Equity risk | E24: The risk of loss on financial instruments from changes in the value of equities | F24: 7000000 | G24: no | H24: no | I24: Document 2, as defined in Reader's manual, pp. 410-415.
C25: Structural FX risk | D25: Structural FX risk | E25: Risk arising from equity held that has been deployed in offshore branches and subsidiaries in a currency other than the parent undertaking’s reporting currency | F25: 7500000 | G25: no | H25: no | I25: Document 2, as defined in Reader's manual, pp. 420-425.
C26: Credit spread risk | D26: Credit spread risk | E26: Risk arising from changes in the market value of debt financial instruments due to fluctuations in their credit spread | F26: 17500000 | G26: no | H26: no | I26: Document 2, as defined in Reader's manual, pp. 430-435.
C27: credit valuation adjustment risk | D27: Credit Valuation Adjustment (CVA) | E27: Risk stemming from adjustment to the mid-market valuation of the portfolio of transactions with a counterparty which reflects the current market value of the credit risk of the counterparty to the institution but not the current market value of the credit risk of the institution to the counterparty. | F27: 3800000 | G27: no | H27: yes | I27: Document 2, as defined in Reader's manual, pp. 435-438. | J27: Methodology for calculation of default probabilities updated
C28: FX market risk | D28: FX risk | E28: The risk of losses arising from changes in FX rates | F28: 4000000 | G28: no | H28: no | I28: Document 2, as defined in Reader's manual, pp. 440-445.
C29: Commodity risk | D29: Commodities risk | E29: The risk of losses arising from changes in the prices of physical commodities or financial instruments linked to commodities | F29: 1000000 | G29: no | H29: no | I29: Document 2, as defined in Reader's manual, pp. 450-454.
C30: market risk concentration | D30: Doesn't correspond to an internal risk category as currently covered in ICAAP. | E30: Included in market risk | G30: M1 | H30: no
B32: Operational risk | C32: Total | F32: =SUM(F33:F45) -> 101000000
C33: Operational risk (not broken down into sub-categories) | D33: Operational risk | E33: Covers operational risk as in CRR, broken down into Basel event types | G33: no | H33: yes | I33: Document 12 (see Reader's manual)
C34: Reputational risk | D34: Reputational risk | E34: Risk of loss resulting from damage to a firm's reputation. Not part of operational risk category. | G34: X2 | H34: no
C35: Business disruption and system failures | D35: Business disruption and system failures | E35: Follows Basel definition. Includes ICT risk. | F35: 20000000 | G35: no | H35: yes | I35: Section 2 (ICT risk) in document 12 (see Reader's manual)
C36: Clients, products and business practices | D36: Clients, products and business practices | E36: Follows Basel definition. Includes conduct risk. | F36: 40000000 | G36: no | H36: yes | I36: Document 12 (see Reader's manual)
C37: Damage to physical assets | D37: Damage to physical assets | E37: Follows Basel definition | F37: 1000000 | G37: no | H37: yes | I37: Document 12 (see Reader's manual)
C38: employment practices and workplace safety | D38: Employment practices and workplace safety | E38: Follows Basel definition | F38: 2000000 | G38: no | H38: yes | I38: Document 12 (see Reader's manual)
C39: Execution, delivery and process management | D39: Execution, delivery and process management | E39: Follows Basel definition | F39: 30000000 | G39: no | H39: yes | I39: Document 12 (see Reader's manual)
C40: External fraud | D40: External fraud | E40: Follows Basel definition | F40: 5000000 | G40: no | H40: yes | I40: Document 12 (see Reader's manual)
C41: Internal fraud | D41: Internal fraud | E41: Follows Basel definition | F41: 2000000 | G41: no | H41: yes | I41: Document 12 (see Reader's manual)
C42: other (1) | D42: restitution risk | E42: Covers the risk of potential obligations to compensate/reimburse clients for the value of financial instruments held under custody, where those assets are lost by a third party over the network of sub-custodians at which the bank may have delegated the safekeeping. | F42: 1000000 | G42: no | H42: yes | I42: Document 12 (see Reader's manual)
C43: Conduct risk | D43: Conduct risk | E43: Follows EBA SREP GL definition | G43: O4 | H43: no
C44: Information and communication (ICT) risk | D44: ICT Risk | E44: Follows EBA SREP GL definition | G44: O3 | H44: no
B46: Interest rate risk in the banking book | C46: Total | F46: =SUM(F47:F51) -> 10000000
...

Sheet Drop-down lists 
B1: Sub-category (Column C) | C1: Included in (Column G)
A2: credit risk | B2: credit risk (not broken down into sub-categories) | C2: no
A3: credit risk | B3: default risk | C3: C1
A4: credit risk | B4: settlement and delivery risk | C4: C2
A5: credit risk | B5: migration risk | C5: C3
A6: credit risk | B6: dilution risk | C6: C4
A7: credit risk | B7: credit concentration risk (not broken down) | C7: C5
A8: credit risk | B8: sectoral concentration risk | C8: C6
A9: credit risk | B9: single name concentration risk | C9: C7
A10: credit risk | B10: geographical concentration risk | C10: C8
A11: credit risk | B11: collateral concentration risk | C11: C9
A12: credit risk | B12: other participation/equity risk | C12: C10
A13: credit risk | B13: country risk (includes transfer & other risks) | C13: C11
... A32: credit risk | B32: other (7) | C32: M15
C33: M14
A34: market risk | B34: market risk (not broken down into sub-categories) | C34: M15
A35: market risk | B35: interest rate risk | C35: I1
A36: market risk | B36: credit spread risk (not broken down) | C36: I2 | D36: to be deleted
A37: market risk | B37: credit spread risk in the trading book | C37: I3
A38: market risk | B38: credit spread risk in the banking book | C38: I4 | D38: to be deleted
A39: market risk | B39: equity risk (not broken down) | C39: I5
A40: market risk | B40: equity risk in the trading book | C40: I6
A41: market risk | B41: equity risk in the banking book | C41: I7
A42: market risk | B42: default (and migration) risk | C42: I8
A43: market risk | B43: FX risk | C43: I9
A44: market risk | B44: commodity risk | C44: I10
A45: market risk | B45: credit valuation adjustment risk | C45: I11
A46: market risk | B46: structural FX risk | C46: I12
A47: market risk | B47: market risk concentration | C47: I13
A48: market risk | B48: market liquidity risk / hard to replace derivatives | C48: I14
A49: market risk | B49: valuation risk | C49: I15
A50: market risk | B50: basis risk | C50: O1
... A61: market risk | B61: other (7) | C61: O12
C62: O13
A63: IRRBB | B63: IRRBB (not broken down into sub-categories) | C63: O14
A64: IRRBB | B64: basis risk | C64: O15
A65: IRRBB | B65: option risk | C65: X1
A66: IRRBB | B66: gap risk | C66: X2
A67: IRRBB | B67: credit spread risk (not broken down) | C67: X13
A68: IRRBB | B68: credit spread risk in the banking book | C68: X14
...
