Workbook
Name BM: #REF!
Name BM: #REF!
Name IQ_CH: 110000
Name IQ_CQ: 5000
Name IQ_CY: 10000
Name IQ_DAILY: 500000
Name IQ_FH: 100000
Name IQ_FQ: 500
Name IQ_FY: 1000
Name IQ_LTM: 2000
Name IQ_MONTH: 15000
Name IQ_NTM: 6000
Name IQ_WEEK: 50000
Name IQ_YTD: 3000

Sheet Comparativos granulares
B8: Métrica | C8: Casuística | D8: Montante
B9: EPC_label | C9: Atualização dos certificados tabela da property | D9: 3.3673329e+08
B10: A | C10: Antes era B agora é A | D10: 8201154.9
C11: Antes era C agora é A | D11: 27617020
C12: Antes era D agora é A | D12: 33051637
C13: Antes era E agora é A | D13: 15249718
C14: Antes era F agora é A | D14: 14576645
C15: Antes era G agora é A | D15: 130808.94
B16: B | C16: Antes era A agora é B | D16: 7101374.7 | E16: atualizações GLOVAL
C17: Antes era C agora é B | D17: 43621693
C18: Antes era D agora é B | D18: 19951302
C19: Antes era E agora é B | D19: 10045173
C20: Antes era F agora é B | D20: 6835478.8
C21: Antes era G agora é B | D21: 433251.01
B22: C | C22: Antes era A agora é C | D22: 3973022.5 | E22: atualizações GLOVAL
C23: Antes era B agora é C | D23: 7609426.8 | E23: atualizações GLOVAL
C24: Antes era D agora é C | D24: 27387869
C25: Antes era E agora é C | D25: 8798801.5
C26: Antes era F agora é C | D26: 3136828
C27: Antes era G agora é C | D27: 239684.33
B28: D | C28: Antes era A agora é D | D28: 3401058.3 | E28: atualizações GLOVAL
C29: Antes era B agora é D | D29: 3964789.4 | E29: atualizações GLOVAL
C30: Antes era C agora é D | D30: 29827746 | E30: atualizações GLOVAL
C31: Antes era E agora é D | D31: 6667194.2
C32: Antes era F agora é D | D32: 2844654.7
C33: Antes era G agora é D | D33: 105618.16
C34: Antes era 'Sem dados' agora é D | D34: 33194.76
B35: E | C35: Antes era A agora é E | D35: 1420013.4 | E35: atualizações GLOVAL
C36: Antes era B agora é E | D36: 1869955.9 | E36: atualizações GLOVAL
C37: Antes era C agora é E | D37: 14013342 | E37: atualizações GLOVAL
C38: Antes era D agora é E | D38: 14850420 | E38: atualizações GLOVAL
C39: Antes era F agora é E | D39: 3556949.5
C40: Antes era G agora é E | D40: 0
B41: F | C41: Antes era A agora é F | D41: 623482.33 | E41: atualizações GLOVAL
C42: Antes era B agora é F | D42: 1344742.6 | E42: atualizações GLOVAL
C43: Antes era C agora é F | D43: 3670791.2 | E43: atualizações GLOVAL
C44: Antes era D agora é F | D44: 5571150.1 | E44: atualizações GLOVAL
C45: Antes era E agora é F | D45: 3869773.7 | E45: atualizações GLOVAL
C46: Antes era G agora é F | D46: 0
B47: G | C47: Antes era A agora é G | D47: 0
...

Sheet Variação 
C8: Exposição | F8: 0; <= 100 | I8: > 100; <= 200 | L8: > 200; <= 300 | O8: > 300; <= 400 | R8: > 400; <= 500 | U8: > 500 | X8: Without EP score of collateral | AA8: A | AD8: B | AG8: C | AJ8: D | AM8: E | AP8: F | AS8: G | AV8: Without EPC label of collateral
C9: 45748 | D9: 45627 | E9: ∆ | F9: 45748 | G9: 45627 | H9: ∆ | I9: 45748 | J9: 45627 | K9: ∆ | L9: 45748 | M9: 45627 | N9: ∆ | O9: 45748 | P9: 45627 | Q9: ∆ | R9: 45748 | S9: 45627 | T9: ∆ | U9: 45748 | V9: 45627 | W9: ∆ | X9: 45748 | Y9: 45627 | Z9: ∆ | AA9: 45748 | AB9: 45627 | AC9: ∆ | AD9: 45748 | AE9: 45627 | AF9: ∆ | AG9: 45748 | AH9: 45627 | AI9: ∆ | AJ9: 45748 | AK9: 45627 | AL9: ∆ | AM9: 45748 | AN9: 45627 | AO9: ∆ | AP9: 45748 | AQ9: 45627 | AR9: ∆ | AS9: 45748 | AT9: 45627 | AU9: ∆ | AV9: 45748 | AW9: 45627 | AX9: ∆
B10: Total EU area | X10: =+Paralelo!K8 -> 26833996951 | Y10: =+'Dez24'!K8 -> 26904628045 | Z10: =+X10-Y10 -> -70631094
B11: Of which Loans collateralised by commercial immovable property | X11: =+Paralelo!K9 -> 3564429222 | Y11: =+'Dez24'!K9 -> 3564429222 | Z11: =+X11-Y11 -> 0
B12: Of which Loans collateralised by residential immovable property | X12: =+Paralelo!K10 -> 23269567729 | Y12: =+'Dez24'!K10 -> 23291747256 | Z12: =+X12-Y12 -> -22179527
B13: Of which Collateral obtained by taking possession: residential and commercial immovable properties | X13: =+Paralelo!K11 -> 0 | Y13: =+'Dez24'!K11 -> 48451567 | Z13: =+X13-Y13 -> -48451567
B14: Of which Level of energy efficiency (EP score in kWh/m² and EPC label of collateral) estimated | X14: =+Paralelo!K12 -> 17628362545 | Y14: =+'Dez24'!K12 -> 26640639426 | Z14: =+X14-Y14 -> -9012276881 | AA14: =+Paralelo!M12 -> 912719513 | AB14: =+'Dez24'!M12 -> 909357093 | AC14: =+AA14-AB14 -> 3362420 | AD14: =+Paralelo!N12 -> 1493358008 | AE14: =+'Dez24'!N12 -> 1469962966 | AF14: =+AD14-AE14 -> 23395042 | AG14: =+Paralelo!O12 -> 4770592268 | AH14: =+'Dez24'!O12 -> 4878396765 | AI14: =+AG14-AH14 -> -107804497 | AJ14: =+Paralelo!P12 -> 3804989795 | AK14: =+'Dez24'!P12 -> 3891419413 | AL14: =+AJ14-AK14 -> -86429618 | AM14: =+Paralelo!Q12 -> 1672617824 | AN14: =+'Dez24'!Q12 -> 1696602496 | AO14: =+AM14-AN14 -> -23984672 | AP14: =+Paralelo!R12 -> 1033539249 | AQ14: =+'Dez24'!R12 -> 1057337985 | AR14: =+AP14-AQ14 -> -23798736 | AS14: =+Paralelo!S12 -> 61456770 | AT14: =+'Dez24'!S12 -> 62105713 | AU14: =+AS14-AT14 -> -648943
B15: Commercial immovable property
B16: Average loan-to-value of loans collateralised by commercial immovable property, weighted by gross carrying amount | C16: =+Paralelo!$D$14 -> 0.45543762 | D16: =+'Dez24'!$D$14 -> 0.46997457 | E16: =+C16-D16 -> -0.014536944 | F16: =+Paralelo!$E$14 -> 0.38192858 | G16: =+'Dez24'!$E$14 -> 0.40328706 | H16: =+F16-G16 -> -0.021358478 | I16: =+Paralelo!$F$14 -> 0.44969859 | J16: =+'Dez24'!$F$14 -> 0.46534077 | K16: =+I16-J16 -> -0.015642176 | L16: =+Paralelo!$G$14 -> 0.4286435 | M16: =+'Dez24'!$G$14 -> 0.44767855 | N16: =+L16-M16 -> -0.019035056 | O16: =+Paralelo!$H$14 -> 0.41724982 | P16: =+'Dez24'!$H$14 -> 0.40152229 | Q16: =+O16-P16 -> 0.01572753 | R16: =+Paralelo!$I$14 -> 0.58404534 | S16: =+'Dez24'!$I$14 -> 0 | T16: =+R16-S16 -> 0.58404534 | U16: =+Paralelo!$J$14 -> 0.65668062 | V16: =+'Dez24'!$J$14 -> 0.61601421 | W16: =+U16-V16 -> 0.040666418 | X16: =+Paralelo!$K$14 -> 0.68649151 | Y16: =+'Dez24'!$K$14 -> 0.92138853 | Z16: =+X16-Y16 -> -0.23489702 | AA16: =+Paralelo!$M$14 -> 0.43265102 | AB16: =+'Dez24'!$M$14 -> 0.45207886 | AC16: =+AA16-AB16 -> -0.019427836 | AD16: =+Paralelo!$N$14 -> 0.43230476 | AE16: =+'Dez24'!$N$14 -> 0.45168511 | AF16: =+AD16-AE16 -> -0.019380345 | AG16: =+Paralelo!$O$14 -> 0.42620868 | AH16: =+'Dez24'!$O$14 -> 0.43313838 | AI16: =+AG16-AH16 -> -0.0069296993 | AJ16: =+Paralelo!$P$14 -> 0.42359258 | AK16: =+'Dez24'!$P$14 -> 0.43993453 | AL16: =+AJ16-AK16 -> -0.016341954 | AM16: =+Paralelo!$Q$14 -> 0.43230476 | AN16: =+'Dez24'!$Q$14 -> 0.43461203 | AO16: =+AM16-AN16 -> -0.0023072654 | AP16: =+Paralelo!$R$14 -> 0.44550017 | AQ16: =+'Dez24'!$R$14 -> 0.45661269 | AR16: =+AP16-AQ16 -> -0.011112518 | AS16: =+Paralelo!$S$14 -> 0.39862966 | AT16: =+'Dez24'!$S$14 -> 0.39797725 | AU16: =+AS16-AT16 -> 0.00065241045 | AV16: =+Paralelo!$T$14 -> 0.45395554 | AW16: =+'Dez24'!$T$14 -> 0.47123285 | AX16: =+AV16-AW16 -> -0.017277311
B17: GCA of loans collateralised by commercial immovable property with 80% < loan-to-value < 100%, weighted by GCA | C17: =+Paralelo!$D$15 -> 277438276 | D17: =+'Dez24'!$D$15 -> 275118888 | E17: =+C17-D17 -> 2319388 | F17: =+Paralelo!$E$15 -> 45561405 | G17: =+'Dez24'!$E$15 -> 51322505 | H17: =+F17-G17 -> -5761100 | I17: =+Paralelo!$F$15 -> 50866219 | J17: =+'Dez24'!$F$15 -> 55866006 | K17: =+I17-J17 -> -4999787 | L17: =+Paralelo!$G$15 -> 16936161 | M17: =+'Dez24'!$G$15 -> 17076962 | N17: =+L17-M17 -> -140801 | O17: =+Paralelo!$H$15 -> 0 | P17: =+'Dez24'!$H$15 -> 0 | Q17: =+O17-P17 -> 0 | R17: =+Paralelo!$I$15 -> 0 | S17: =+'Dez24'!$I$15 -> 0 | T17: =+R17-S17 -> 0 | U17: =+Paralelo!$J$15 -> 6137138 | V17: =+'Dez24'!$J$15 -> 0 | W17: =+U17-V17 -> 6137138 | X17: =+Paralelo!$K$15 -> 157937353 | Y17: =+'Dez24'!$K$15 -> 150853414 | Z17: =+X17-Y17 -> 7083939 | AA17: =+Paralelo!$M$15 -> 5510927 | AB17: =+'Dez24'!$M$15 -> 5510926 | AC17: =+AA17-AB17 -> 1 | AD17: =+Paralelo!$N$15 -> 23806369 | AE17: =+'Dez24'!$N$15 -> 23806368 | AF17: =+AD17-AE17 -> 1 | AG17: =+Paralelo!$O$15 -> 40609871 | AH17: =+'Dez24'!$O$15 -> 38671716 | AI17: =+AG17-AH17 -> 1938155 | AJ17: =+Paralelo!$P$15 -> 33268865 | AK17: =+'Dez24'!$P$15 -> 32887631 | AL17: =+AJ17-AK17 -> 381234 | AM17: =+Paralelo!$Q$15 -> 9085878 | AN17: =+'Dez24'!$Q$15 -> 9882022 | AO17: =+AM17-AN17 -> -796144 | AP17: =+Paralelo!$R$15 -> 13406658 | AQ17: =+'Dez24'!$R$15 -> 13406659 | AR17: =+AP17-AQ17 -> -1 | AS17: =+Paralelo!$S$15 -> 100151 | AT17: =+'Dez24'!$S$15 -> 100151 | AU17: =+AS17-AT17 -> 0 | AV17: =+Paralelo!$T$15 -> 247077170 | AW17: =+'Dez24'!$T$15 -> 245553926 | AX17: =+AV17-AW17 -> 1523244
B18: GCA of loans collateralised by commercial immovable property with loan-to-value >= 100%, weighted by GCA | C18: =+Paralelo!$D$16 -> 112936651 | D18: =+'Dez24'!$D$16 -> 112936650 | E18: =+C18-D18 -> 1 | F18: =+Paralelo!$E$16 -> 15834570 | G18: =+'Dez24'!$E$16 -> 16023049 | H18: =+F18-G18 -> -188479 | I18: =+Paralelo!$F$16 -> 51110836 | J18: =+'Dez24'!$F$16 -> 51110836 | K18: =+I18-J18 -> 0 | L18: =+Paralelo!$G$16 -> 751176 | M18: =+'Dez24'!$G$16 -> 751176 | N18: =+L18-M18 -> 0 | O18: =+Paralelo!$H$16 -> 0 | P18: =+'Dez24'!$H$16 -> 0 | Q18: =+O18-P18 -> 0 | R18: =+Paralelo!$I$16 -> 0 | S18: =+'Dez24'!$I$16 -> 0 | T18: =+R18-S18 -> 0 | U18: =+Paralelo!$J$16 -> 0 | V18: =+'Dez24'!$J$16 -> 0 | W18: =+U18-V18 -> 0 | X18: =+Paralelo!$K$16 -> 45240069 | Y18: =+'Dez24'!$K$16 -> 45051589 | Z18: =+X18-Y18 -> 188480 | AA18: =+Paralelo!$M$16 -> 1516403 | AB18: =+'Dez24'!$M$16 -> 1516403 | AC18: =+AA18-AB18 -> 0 | AD18: =+Paralelo!$N$16 -> 1993693 | AE18: =+'Dez24'!$N$16 -> 1993693 | AF18: =+AD18-AE18 -> 0 | AG18: =+Paralelo!$O$16 -> 51888935 | AH18: =+'Dez24'!$O$16 -> 51888934 | AI18: =+AG18-AH18 -> 1 | AJ18: =+Paralelo!$P$16 -> 9962786 | AK18: =+'Dez24'!$P$16 -> 9962787 | AL18: =+AJ18-AK18 -> -1 | AM18: =+Paralelo!$Q$16 -> 1939744 | AN18: =+'Dez24'!$Q$16 -> 1939744 | AO18: =+AM18-AN18 -> 0 | AP18: =+Paralelo!$R$16 -> 583500 | AQ18: =+'Dez24'!$R$16 -> 583500 | AR18: =+AP18-AQ18 -> 0 | AS18: =+Paralelo!$S$16 -> 0 | AT18: =+'Dez24'!$S$16 -> 0 | AU18: =+AS18-AT18 -> 0 | AV18: =+Paralelo!$T$16 -> 112164532 | AW18: =+'Dez24'!$T$16 -> 112164532 | AX18: =+AV18-AW18 -> 0
B19: Average residual maturity in years of loans collateralised by commercial immovable property, weighted by gross carrying amount | C19: =+Paralelo!$D$17 -> 7.5421303 | D19: =+'Dez24'!$D$17 -> 7.6255904 | E19: =+C19-D19 -> -0.083460017 | F19: =+Paralelo!$E$17 -> 8.4231814 | G19: =+'Dez24'!$E$17 -> 8.5248242 | H19: =+F19-G19 -> -0.10164277 | I19: =+Paralelo!$F$17 -> 7.316536 | J19: =+'Dez24'!$F$17 -> 7.4335823 | K19: =+I19-J19 -> -0.11704629 | L19: =+Paralelo!$G$17 -> 8.1143234 | M19: =+'Dez24'!$G$17 -> 8.0975237 | N19: =+L19-M19 -> 0.016799764 | O19: =+Paralelo!$H$17 -> 6.8086628 | P19: =+'Dez24'!$H$17 -> 7.100953 | Q19: =+O19-P19 -> -0.29229018 | R19: =+Paralelo!$I$17 -> 16.060535 | S19: =+'Dez24'!$I$17 -> 0 | T19: =+R19-S19 -> 16.060535 | U19: =+Paralelo!$J$17 -> 14.005843 | V19: =+'Dez24'!$J$17 -> 13.43357 | W19: =+U19-V19 -> 0.57227264 | X19: =+Paralelo!$K$17 -> 5.4342255 | Y19: =+'Dez24'!$K$17 -> 3.4342193 | Z19: =+X19-Y19 -> 2.0000062 | AA19: =+Paralelo!$M$17 -> 8.911819 | AB19: =+'Dez24'!$M$17 -> 8.8913271 | AC19: =+AA19-AB19 -> 0.020491936 | AD19: =+Paralelo!$N$17 -> 8.2793787 | AE19: =+'Dez24'!$N$17 -> 8.2613012 | AF19: =+AD19-AE19 -> 0.018077469 | AG19: =+Paralelo!$O$17 -> 7.6479249 | AH19: =+'Dez24'!$O$17 -> 7.8487831 | AI19: =+AG19-AH19 -> -0.20085824 | AJ19: =+Paralelo!$P$17 -> 7.1858983 | AK19: =+'Dez24'!$P$17 -> 7.2437994 | AL19: =+AJ19-AK19 -> -0.057901141 | AM19: =+Paralelo!$Q$17 -> 7.5200788 | AN19: =+'Dez24'!$Q$17 -> 7.5716358 | AO19: =+AM19-AN19 -> -0.051557036 | AP19: =+Paralelo!$R$17 -> 9.0296118 | AQ19: =+'Dez24'!$R$17 -> 8.8052862 | AR19: =+AP19-AQ19 -> 0.22432564 | AS19: =+Paralelo!$S$17 -> 8.185014 | AT19: =+'Dez24'!$S$17 -> 8.1605416 | AU19: =+AS19-AT19 -> 0.024472456 | AV19: =+Paralelo!$T$17 -> 7.4180472 | AW19: =+'Dez24'!$T$17 -> 7.5023073 | AX19: =+AV19-AW19 -> -0.084260154
B20: GCA of loans collateralised by commercial immovable property with Residual maturity < 5 years, weighted by GCA | C20: =+Paralelo!$D$18 -> 1390218741 | D20: =+'Dez24'!$D$18 -> 1183222362 | E20: =+C20-D20 -> 206996379 | F20: =+Paralelo!$E$18 -> 458047307 | G20: =+'Dez24'!$E$18 -> 413468115 | H20: =+F20-G20 -> 44579192 | I20: =+Paralelo!$F$18 -> 595574069 | J20: =+'Dez24'!$F$18 -> 541877528 | K20: =+I20-J20 -> 53696541 | L20: =+Paralelo!$G$18 -> 61131967 | M20: =+'Dez24'!$G$18 -> 45380592 | N20: =+L20-M20 -> 15751375 | O20: =+Paralelo!$H$18 -> 2869003 | P20: =+'Dez24'!$H$18 -> 2349194 | Q20: =+O20-P20 -> 519809 | R20: =+Paralelo!$I$18 -> 10 | S20: =+'Dez24'!$I$18 -> 0 | T20: =+R20-S20 -> 10 | U20: =+Paralelo!$J$18 -> 1185682 | V20: =+'Dez24'!$J$18 -> 0 | W20: =+U20-V20 -> 1185682 | X20: =+Paralelo!$K$18 -> 271410703 | Y20: =+'Dez24'!$K$18 -> 180146933 | Z20: =+X20-Y20 -> 91263770 | AA20: =+Paralelo!$M$18 -> 156270700 | AB20: =+'Dez24'!$M$18 -> 151485056 | AC20: =+AA20-AB20 -> 4785644 | AD20: =+Paralelo!$N$18 -> 121921206 | AE20: =+'Dez24'!$N$18 -> 107327488 | AF20: =+AD20-AE20 -> 14593718 | AG20: =+Paralelo!$O$18 -> 523364849 | AH20: =+'Dez24'!$O$18 -> 397018770 | AI20: =+AG20-AH20 -> 126346079 | AJ20: =+Paralelo!$P$18 -> 253308997 | AK20: =+'Dez24'!$P$18 -> 216481708 | AL20: =+AJ20-AK20 -> 36827289 | AM20: =+Paralelo!$Q$18 -> 110767765 | AN20: =+'Dez24'!$Q$18 -> 94764387 | AO20: =+AM20-AN20 -> 16003378 | AP20: =+Paralelo!$R$18 -> 38248745 | AQ20: =+'Dez24'!$R$18 -> 34331087 | AR20: =+AP20-AQ20 -> 3917658 | AS20: =+Paralelo!$S$18 -> 1865995 | AT20: =+'Dez24'!$S$18 -> 1666932 | AU20: =+AS20-AT20 -> 199063 | AV20: =+Paralelo!$T$18 -> 1235387933 | AW20: =+'Dez24'!$T$18 -> 1043767893 | AX20: =+AV20-AW20 -> 191620040
B21: Average interest rate of new business flow on commercial immovable property, weighted by gross carrying amount | C21: =+Paralelo!$D$19 -> 0.048694173 | D21: =+'Dez24'!$D$19 -> 0.047536663 | E21: =+C21-D21 -> 0.0011575097 | F21: =+Paralelo!$E$19 -> 0.048607545 | G21: =+'Dez24'!$E$19 -> 0.048279996 | H21: =+F21-G21 -> 0.00032754898 | I21: =+Paralelo!$F$19 -> 0.048492773 | J21: =+'Dez24'!$F$19 -> 0.047475723 | K21: =+I21-J21 -> 0.0010170506 | L21: =+Paralelo!$G$19 -> 0.04461362 | M21: =+'Dez24'!$G$19 -> 0.044981419 | N21: =+L21-M21 -> -0.00036779868 | O21: =+Paralelo!$H$19 -> 0.05 | P21: =+'Dez24'!$H$19 -> 0.05 | Q21: =+O21-P21 -> 0 | R21: =+Paralelo!$I$19 -> 0.042224242 | S21: =+'Dez24'!$I$19 -> 0 | T21: =+R21-S21 -> 0.042224242 | U21: =+Paralelo!$J$19 -> 0.041089406 | V21: =+'Dez24'!$J$19 -> 0.03 | W21: =+U21-V21 -> 0.011089406 | X21: =+Paralelo!$K$19 -> 0.05351058 | Y21: =+'Dez24'!$K$19 -> 0.045699596 | Z21: =+X21-Y21 -> 0.0078109839 | AA21: =+Paralelo!$M$19 -> 0.055090035 | AB21: =+'Dez24'!$M$19 -> 0.052369992 | AC21: =+AA21-AB21 -> 0.0027200436 | AD21: =+Paralelo!$N$19 -> 0.047188345 | AE21: =+'Dez24'!$N$19 -> 0.048858355 | AF21: =+AD21-AE21 -> -0.0016700104 | AG21: =+Paralelo!$O$19 -> 0.048707857 | AH21: =+'Dez24'!$O$19 -> 0.046243475 | AI21: =+AG21-AH21 -> 0.0024643822 | AJ21: =+Paralelo!$P$19 -> 0.04875154 | AK21: =+'Dez24'!$P$19 -> 0.047540026 | AL21: =+AJ21-AK21 -> 0.001211514 | AM21: =+Paralelo!$Q$19 -> 0.049233857 | AN21: =+'Dez24'!$Q$19 -> 0.049106103 | AO21: =+AM21-AN21 -> 0.00012775467 | AP21: =+Paralelo!$R$19 -> 0.044064114 | AQ21: =+'Dez24'!$R$19 -> 0.044522594 | AR21: =+AP21-AQ21 -> -0.00045847977 | AS21: =+Paralelo!$S$19 -> 0.049075319 | AT21: =+'Dez24'!$S$19 -> 0.04907532 | AU21: =+AS21-AT21 -> -6.0701427e-10 | AV21: =+Paralelo!$T$19 -> 0.048294501 | AW21: =+'Dez24'!$T$19 -> 0.047031287 | AX21: =+AV21-AW21 -> 0.0012632145
B22: Residential immovable property
B23: Average loan-to-value of loans collateralised by residential immovable property, weighted by gross carrying amount | C23: =+Paralelo!$D$21 -> 0.59149761 | D23: =+'Dez24'!$D$21 -> 0.59642081 | E23: =+C23-D23 -> -0.0049231969 | F23: =+Paralelo!$E$21 -> 0.53590104 | G23: =+'Dez24'!$E$21 -> 0.58900891 | H23: =+F23-G23 -> -0.053107871 | I23: =+Paralelo!$F$21 -> 0.53987482 | J23: =+'Dez24'!$F$21 -> 0.604522 | K23: =+I23-J23 -> -0.064647186 | L23: =+Paralelo!$G$21 -> 0.55633899 | M23: =+'Dez24'!$G$21 -> 0.59615719 | N23: =+L23-M23 -> -0.0398182 | O23: =+Paralelo!$H$21 -> 0.60189163 | P23: =+'Dez24'!$H$21 -> 0.59307509 | Q23: =+O23-P23 -> 0.0088165339 | R23: =+Paralelo!$I$21 -> 0.66231878 | S23: =+'Dez24'!$I$21 -> 0.63729207 | T23: =+R23-S23 -> 0.02502671 | U23: =+Paralelo!$J$21 -> 0.65618755 | V23: =+'Dez24'!$J$21 -> 0 | W23: =+U23-V23 -> 0.65618755 | X23: =+Paralelo!$K$21 -> 0.67370955 | Y23: =+'Dez24'!$K$21 -> 1.19 | Z23: =+X23-Y23 -> -0.51629045 | AA23: =+Paralelo!$M$21 -> 0.59386127 | AB23: =+'Dez24'!$M$21 -> 0.59877778 | AC23: =+AA23-AB23 -> -0.0049165135 | AD23: =+Paralelo!$N$21 -> 0.58770996 | AE23: =+'Dez24'!$N$21 -> 0.59205062 | AF23: =+AD23-AE23 -> -0.0043406573 | AG23: =+Paralelo!$O$21 -> 0.58674821 | AH23: =+'Dez24'!$O$21 -> 0.59137571 | AI23: =+AG23-AH23 -> -0.0046275053 | AJ23: =+Paralelo!$P$21 -> 0.59150376 | AK23: =+'Dez24'!$P$21 -> 0.59633043 | AL23: =+AJ23-AK23 -> -0.0048266719 | AM23: =+Paralelo!$Q$21 -> 0.60208842 | AN23: =+'Dez24'!$Q$21 -> 0.60648428 | AO23: =+AM23-AN23 -> -0.0043958639 | AP23: =+Paralelo!$R$21 -> 0.58331325 | AQ23: =+'Dez24'!$R$21 -> 0.58844538 | AR23: =+AP23-AQ23 -> -0.0051321318 | AS23: =+Paralelo!$S$21 -> 0.50906698 | AT23: =+'Dez24'!$S$21 -> 0.51775781 | AU23: =+AS23-AT23 -> -0.0086908327 | AV23: =+Paralelo!$T$21 -> 0.52311623 | AW23: =+'Dez24'!$T$21 -> 0.53053654 | AX23: =+AV23-AW23 -> -0.0074203158
B24: GCA of loans collateralised by residential immovable property with 80% < loan-to-value < 100%, weighted by GCA | C24: =+Paralelo!$D$22 -> 2903026477 | D24: =+'Dez24'!$D$22 -> 2642244925 | E24: =+C24-D24 -> 260781552 | F24: =+Paralelo!$E$22 -> 457743389 | G24: =+'Dez24'!$E$22 -> 1269208423 | H24: =+F24-G24 -> -811465034 | I24: =+Paralelo!$F$22 -> 335746347 | J24: =+'Dez24'!$F$22 -> 1093983475 | K24: =+I24-J24 -> -758237128 | L24: =+Paralelo!$G$22 -> 152349621 | M24: =+'Dez24'!$G$22 -> 256692714 | N24: =+L24-M24 -> -104343093 | O24: =+Paralelo!$H$22 -> 35238417 | P24: =+'Dez24'!$H$22 -> 21607301 | Q24: =+O24-P24 -> 13631116 | R24: =+Paralelo!$I$22 -> 11739632 | S24: =+'Dez24'!$I$22 -> 177470 | T24: =+R24-S24 -> 11562162 | U24: =+Paralelo!$J$22 -> 13963158 | V24: =+'Dez24'!$J$22 -> 0 | W24: =+U24-V24 -> 13963158 | X24: =+Paralelo!$K$22 -> 1896245913 | Y24: =+'Dez24'!$K$22 -> 575543 | Z24: =+X24-Y24 -> 1895670370 | AA24: =+Paralelo!$M$22 -> 273288008 | AB24: =+'Dez24'!$M$22 -> 239160777 | AC24: =+AA24-AB24 -> 34127231 | AD24: =+Paralelo!$N$22 -> 297990927 | AE24: =+'Dez24'!$N$22 -> 265770981 | AF24: =+AD24-AE24 -> 32219946 | AG24: =+Paralelo!$O$22 -> 820913205 | AH24: =+'Dez24'!$O$22 -> 753333577 | AI24: =+AG24-AH24 -> 67579628 | AJ24: =+Paralelo!$P$22 -> 865581085 | AK24: =+'Dez24'!$P$22 -> 790830773 | AL24: =+AJ24-AK24 -> 74750312 | AM24: =+Paralelo!$Q$22 -> 445111127 | AN24: =+'Dez24'!$Q$22 -> 409065725 | AO24: =+AM24-AN24 -> 36045402 | AP24: =+Paralelo!$R$22 -> 197438763 | AQ24: =+'Dez24'!$R$22 -> 181520054 | AR24: =+AP24-AQ24 -> 15918709 | AS24: =+Paralelo!$S$22 -> 2241514 | AT24: =+'Dez24'!$S$22 -> 2112079 | AU24: =+AS24-AT24 -> 129435 | AV24: =+Paralelo!$T$22 -> 558661121 | AW24: =+'Dez24'!$T$22 -> 525759048 | AX24: =+AV24-AW24 -> 32902073
B25: GCA of loans collateralised by residential immovable property with loan-to-value >= 100%, weighted by GCA | C25: =+Paralelo!$D$23 -> 166880464 | D25: =+'Dez24'!$D$23 -> 173597963 | E25: =+C25-D25 -> -6717499 | F25: =+Paralelo!$E$23 -> 62045513 | G25: =+'Dez24'!$E$23 -> 63882179 | H25: =+F25-G25 -> -1836666 | I25: =+Paralelo!$F$23 -> 37344300 | J25: =+'Dez24'!$F$23 -> 45861794 | K25: =+I25-J25 -> -8517494 | L25: =+Paralelo!$G$23 -> 22985207 | M25: =+'Dez24'!$G$23 -> 27512482 | N25: =+L25-M25 -> -4527275 | O25: =+Paralelo!$H$23 -> 555330 | P25: =+'Dez24'!$H$23 -> 1205374 | Q25: =+O25-P25 -> -650044 | R25: =+Paralelo!$I$23 -> 123162 | S25: =+'Dez24'!$I$23 -> 0 | T25: =+R25-S25 -> 123162 | U25: =+Paralelo!$J$23 -> 374294 | V25: =+'Dez24'!$J$23 -> 0 | W25: =+U25-V25 -> 374294 | X25: =+Paralelo!$K$23 -> 43452658 | Y25: =+'Dez24'!$K$23 -> 35136135 | Z25: =+X25-Y25 -> 8316523 | AA25: =+Paralelo!$M$23 -> 18693699 | AB25: =+'Dez24'!$M$23 -> 17446381 | AC25: =+AA25-AB25 -> 1247318 | AD25: =+Paralelo!$N$23 -> 14544457 | AE25: =+'Dez24'!$N$23 -> 14474462 | AF25: =+AD25-AE25 -> 69995 | AG25: =+Paralelo!$O$23 -> 23234457 | AH25: =+'Dez24'!$O$23 -> 24938011 | AI25: =+AG25-AH25 -> -1703554 | AJ25: =+Paralelo!$P$23 -> 36184016 | AK25: =+'Dez24'!$P$23 -> 37757787 | AL25: =+AJ25-AK25 -> -1573771 | AM25: =+Paralelo!$Q$23 -> 20987922 | AN25: =+'Dez24'!$Q$23 -> 22348533 | AO25: =+AM25-AN25 -> -1360611 | AP25: =+Paralelo!$R$23 -> 19734204 | AQ25: =+'Dez24'!$R$23 -> 21322546 | AR25: =+AP25-AQ25 -> -1588342 | AS25: =+Paralelo!$S$23 -> 43300 | AT25: =+'Dez24'!$S$23 -> 174109 | AU25: =+AS25-AT25 -> -130809 | AV25: =+Paralelo!$T$23 -> 138789125 | AW25: =+'Dez24'!$T$23 -> 147381314 | AX25: =+AV25-AW25 -> -8592189
B26: Average residual maturity in years of loans collateralised by residential immovable property, weighted by gross carrying amount | C26: =+Paralelo!$D$24 -> 27.012236 | D26: =+'Dez24'!$D$24 -> 27.366577 | E26: =+C26-D26 -> -0.35434136 | F26: =+Paralelo!$E$24 -> 24.418805 | G26: =+'Dez24'!$E$24 -> 27.317604 | H26: =+F26-G26 -> -2.8987989 | I26: =+Paralelo!$F$24 -> 24.08959 | J26: =+'Dez24'!$F$24 -> 27.535314 | K26: =+I26-J26 -> -3.4457238 | L26: =+Paralelo!$G$24 -> 24.690553 | M26: =+'Dez24'!$G$24 -> 26.994035 | N26: =+L26-M26 -> -2.3034821 | O26: =+Paralelo!$H$24 -> 27.5455 | P26: =+'Dez24'!$H$24 -> 26.929073 | Q26: =+O26-P26 -> 0.61642743 | R26: =+Paralelo!$I$24 -> 30.97428 | S26: =+'Dez24'!$I$24 -> 28.46458 | T26: =+R26-S26 -> 2.5097004 | U26: =+Paralelo!$J$24 -> 30.86586 | V26: =+'Dez24'!$J$24 -> 0 | W26: =+U26-V26 -> 30.86586 | X26: =+Paralelo!$K$24 -> 31.243197 | Y26: =+'Dez24'!$K$24 -> 29.379292 | Z26: =+X26-Y26 -> 1.8639046 | AA26: =+Paralelo!$M$24 -> 28.931343 | AB26: =+'Dez24'!$M$24 -> 29.016112 | AC26: =+AA26-AB26 -> -0.0847697 | AD26: =+Paralelo!$N$24 -> 27.462671 | AE26: =+'Dez24'!$N$24 -> 27.784625 | AF26: =+AD26-AE26 -> -0.32195394 | AG26: =+Paralelo!$O$24 -> 26.380029 | AH26: =+'Dez24'!$O$24 -> 26.810737 | AI26: =+AG26-AH26 -> -0.43070791 | AJ26: =+Paralelo!$P$24 -> 26.849405 | AK26: =+'Dez24'!$P$24 -> 27.205923 | AL26: =+AJ26-AK26 -> -0.35651857 | AM26: =+Paralelo!$Q$24 -> 27.115961 | AN26: =+'Dez24'!$Q$24 -> 27.507257 | AO26: =+AM26-AN26 -> -0.39129574 | AP26: =+Paralelo!$R$24 -> 26.602832 | AQ26: =+'Dez24'!$R$24 -> 27.074318 | AR26: =+AP26-AQ26 -> -0.47148645 | AS26: =+Paralelo!$S$24 -> 22.239707 | AT26: =+'Dez24'!$S$24 -> 23.121179 | AU26: =+AS26-AT26 -> -0.88147209 | AV26: =+Paralelo!$T$24 -> 23.021301 | AW26: =+'Dez24'!$T$24 -> 23.755874 | AX26: =+AV26-AW26 -> -0.73457311
B27: GCA of loans collateralised by residential immovable property with Residual maturity < 5 years, weighted by GCA | C27: =+Paralelo!$D$25 -> 208148076 | D27: =+'Dez24'!$D$25 -> 157552749 | E27: =+C27-D27 -> 50595327 | F27: =+Paralelo!$E$25 -> 102491286 | G27: =+'Dez24'!$E$25 -> 83988083 | H27: =+F27-G27 -> 18503203 | I27: =+Paralelo!$F$25 -> 70270905 | J27: =+'Dez24'!$F$25 -> 53946461 | K27: =+I27-J27 -> 16324444 | L27: =+Paralelo!$G$25 -> 24492586 | M27: =+'Dez24'!$G$25 -> 17940362 | N27: =+L27-M27 -> 6552224 | O27: =+Paralelo!$H$25 -> 2142109 | P27: =+'Dez24'!$H$25 -> 1527615 | Q27: =+O27-P27 -> 614494 | R27: =+Paralelo!$I$25 -> 52750 | S27: =+'Dez24'!$I$25 -> 0 | T27: =+R27-S27 -> 52750 | U27: =+Paralelo!$J$25 -> 35919 | V27: =+'Dez24'!$J$25 -> 0 | W27: =+U27-V27 -> 35919 | X27: =+Paralelo!$K$25 -> 8662521 | Y27: =+'Dez24'!$K$25 -> 150227 | Z27: =+X27-Y27 -> 8512294 | AA27: =+Paralelo!$M$25 -> 11396671 | AB27: =+'Dez24'!$M$25 -> 9029183 | AC27: =+AA27-AB27 -> 2367488 | AD27: =+Paralelo!$N$25 -> 18821034 | AE27: =+'Dez24'!$N$25 -> 14260766 | AF27: =+AD27-AE27 -> 4560268 | AG27: =+Paralelo!$O$25 -> 66538762 | AH27: =+'Dez24'!$O$25 -> 51655711 | AI27: =+AG27-AH27 -> 14883051 | AJ27: =+Paralelo!$P$25 -> 62086336 | AK27: =+'Dez24'!$P$25 -> 46673044 | AL27: =+AJ27-AK27 -> 15413292 | AM27: =+Paralelo!$Q$25 -> 30200816 | AN27: =+'Dez24'!$Q$25 -> 21776715 | AO27: =+AM27-AN27 -> 8424101 | AP27: =+Paralelo!$R$25 -> 17874367 | AQ27: =+'Dez24'!$R$25 -> 13286953 | AR27: =+AP27-AQ27 -> 4587414 | AS27: =+Paralelo!$S$25 -> 968632 | AT27: =+'Dez24'!$S$25 -> 694768 | AU27: =+AS27-AT27 -> 273864 | AV27: =+Paralelo!$T$25 -> 189061201 | AW27: =+'Dez24'!$T$25 -> 143990169 | AX27: =+AV27-AW27 -> 45071032
B28: Average interest rate of new business flow on residential immovable property, weighted by gross carrying amount | C28: =+Paralelo!$D$26 -> 0.030209596 | D28: =+'Dez24'!$D$26 -> 0.031590755 | E28: =+C28-D28 -> -0.0013811589 | F28: =+Paralelo!$E$26 -> 0.030204837 | G28: =+'Dez24'!$E$26 -> 0.031615664 | H28: =+F28-G28 -> -0.0014108273 | I28: =+Paralelo!$F$26 -> 0.030162869 | J28: =+'Dez24'!$F$26 -> 0.031588493 | K28: =+I28-J28 -> -0.0014256241 | L28: =+Paralelo!$G$26 -> 0.030189149 | M28: =+'Dez24'!$G$26 -> 0.031488838 | N28: =+L28-M28 -> -0.0012996892 | O28: =+Paralelo!$H$26 -> 0.030192223 | P28: =+'Dez24'!$H$26 -> 0.031479723 | Q28: =+O28-P28 -> -0.0012874996 | R28: =+Paralelo!$I$26 -> 0.030048663 | S28: =+'Dez24'!$I$26 -> 0.032649728 | T28: =+R28-S28 -> -0.0026010656 | U28: =+Paralelo!$J$26 -> 0.03023893 | V28: =+'Dez24'!$J$26 -> 0 | W28: =+U28-V28 -> 0.03023893 | X28: =+Paralelo!$K$26 -> 0.030236442 | Y28: =+'Dez24'!$K$26 -> 0.033100973 | Z28: =+X28-Y28 -> -0.0028645311 | AA28: =+Paralelo!$M$26 -> 0.030185616 | AB28: =+'Dez24'!$M$26 -> 0.031632927 | AC28: =+AA28-AB28 -> -0.0014473108 | AD28: =+Paralelo!$N$26 -> 0.030169772 | AE28: =+'Dez24'!$N$26 -> 0.031666316 | AF28: =+AD28-AE28 -> -0.0014965443 | AG28: =+Paralelo!$O$26 -> 0.030242347 | AH28: =+'Dez24'!$O$26 -> 0.031571743 | AI28: =+AG28-AH28 -> -0.001329396 | AJ28: =+Paralelo!$P$26 -> 0.030190767 | AK28: =+'Dez24'!$P$26 -> 0.031577349 | AL28: =+AJ28-AK28 -> -0.0013865817 | AM28: =+Paralelo!$Q$26 -> 0.030195164 | AN28: =+'Dez24'!$Q$26 -> 0.03154715 | AO28: =+AM28-AN28 -> -0.0013519856 | AP28: =+Paralelo!$R$26 -> 0.030275266 | AQ28: =+'Dez24'!$R$26 -> 0.031609937 | AR28: =+AP28-AQ28 -> -0.0013346702 | AS28: =+Paralelo!$S$26 -> 0.030183925 | AT28: =+'Dez24'!$S$26 -> 0.03018392 | AU28: =+AS28-AT28 -> 4.3594635e-09 | AV28: =+Paralelo!$T$26 -> 0.030257715 | AW28: =+'Dez24'!$T$26 -> 0.031695991 | AX28: =+AV28-AW28 -> -0.001438276
B29: Total non-EU area | X29: =+Paralelo!K27 -> 22179545 | Y29: =+'Dez24'!K27 -> 0 | Z29: =+X29-Y29 -> 22179545
B30: Of which Loans collateralised by commercial immovable property | X30: =+Paralelo!K28 -> 0 | Y30: =+'Dez24'!K28 -> 0 | Z30: =+X30-Y30 -> 0
B31: Of which Loans collateralised by residential immovable property | X31: =+Paralelo!K29 -> 22179545 | Y31: =+'Dez24'!K29 -> 0 | Z31: =+X31-Y31 -> 22179545
B32: Of which Collateral obtained by taking possession: residential and commercial immovable properties | X32: =+Paralelo!K30 -> 0 | Y32: =+'Dez24'!K30 -> 0 | Z32: =+X32-Y32 -> 0
B33: Of which Level of energy efficiency (EP score in kWh/m² and EPC label of collateral) estimated | X33: =+Paralelo!K31 -> 18383467 | Y33: =+'Dez24'!K31 -> 0 | Z33: =+X33-Y33 -> 18383467 | AA33: =+Paralelo!$M$31 -> 327837 | AB33: =+'Dez24'!$M$31 -> 0 | AC33: =+AA33-AB33 -> 327837 | AD33: =+Paralelo!$N$31 -> 129287 | AE33: =+'Dez24'!$N$31 -> 0 | AF33: =+AD33-AE33 -> 129287 | AG33: =+Paralelo!$O$31 -> 285851 | AH33: =+'Dez24'!$O$31 -> 0 | AI33: =+AG33-AH33 -> 285851 | AJ33: =+Paralelo!$P$31 -> 725757 | AK33: =+'Dez24'!$P$31 -> 0 | AL33: =+AJ33-AK33 -> 725757 | AM33: =+Paralelo!$Q$31 -> 514126 | AN33: =+'Dez24'!$Q$31 -> 0 | AO33: =+AM33-AN33 -> 514126 | AP33: =+Paralelo!$R$31 -> 363749 | AQ33: =+'Dez24'!$R$31 -> 0 | AR33: =+AP33-AQ33 -> 363749 | AS33: =+Paralelo!$S$31 -> 0 | AT33: =+'Dez24'!$S$31 -> 0 | AU33: =+AS33-AT33 -> 0
B34: Commercial immovable property
B35: Average loan-to-value of loans collateralised by commercial immovable property, weighted by gross carrying amount | C35: =+Paralelo!$D$33 -> 0 | D35: =+'Dez24'!$D$33 -> 0 | E35: =+C35-D35 -> 0 | F35: =+Paralelo!$E$33 -> 0 | G35: =+'Dez24'!$E$33 -> 0 | H35: =+F35-G35 -> 0 | I35: =+Paralelo!$F$33 -> 0 | J35: =+'Dez24'!$F$33 -> 0 | K35: =+I35-J35 -> 0 | L35: =+Paralelo!$G$33 -> 0 | M35: =+'Dez24'!$G$33 -> 0 | N35: =+L35-M35 -> 0 | O35: =+Paralelo!$H$33 -> 0 | P35: =+'Dez24'!$H$33 -> 0 | Q35: =+O35-P35 -> 0 | R35: =+Paralelo!$I$33 -> 0 | S35: =+'Dez24'!$I$33 -> 0 | T35: =+R35-S35 -> 0 | U35: =+Paralelo!$J$33 -> 0 | V35: =+'Dez24'!$J$33 -> 0 | W35: =+U35-V35 -> 0 | X35: =+Paralelo!$K$33 -> 0 | Y35: =+'Dez24'!$K$33 -> 0 | Z35: =+X35-Y35 -> 0 | AA35: =+Paralelo!$M$33 -> 0 | AB35: =+'Dez24'!$M$33 -> 0 | AC35: =+AA35-AB35 -> 0 | AD35: =+Paralelo!$N$33 -> 0 | AE35: =+'Dez24'!$N$33 -> 0 | AF35: =+AD35-AE35 -> 0 | AG35: =+Paralelo!$O$33 -> 0 | AH35: =+'Dez24'!$O$33 -> 0 | AI35: =+AG35-AH35 -> 0 | AJ35: =+Paralelo!$P$33 -> 0 | AK35: =+'Dez24'!$P$33 -> 0 | AL35: =+AJ35-AK35 -> 0 | AM35: =+Paralelo!$Q$33 -> 0 | AN35: =+'Dez24'!$Q$33 -> 0 | AO35: =+AM35-AN35 -> 0 | AP35: =+Paralelo!$R$33 -> 0 | AQ35: =+'Dez24'!$R$33 -> 0 | AR35: =+AP35-AQ35 -> 0 | AS35: =+Paralelo!$S$33 -> 0 | AT35: =+'Dez24'!$S$33 -> 0 | AU35: =+AS35-AT35 -> 0 | AV35: =+Paralelo!$T$33 -> 0 | AW35: =+'Dez24'!$T$33 -> 0 | AX35: =+AV35-AW35 -> 0
B36: GCA of loans collateralised by commercial immovable property with 80% < loan-to-value < 100%, weighted by GCA | C36: =+Paralelo!$D$34 -> 0 | D36: =+'Dez24'!$D$34 -> 0 | E36: =+C36-D36 -> 0 | F36: =+Paralelo!$E$34 -> 0 | G36: =+'Dez24'!$E$34 -> 0 | H36: =+F36-G36 -> 0 | I36: =+Paralelo!$F$34 -> 0 | J36: =+'Dez24'!$F$34 -> 0 | K36: =+I36-J36 -> 0 | L36: =+Paralelo!$G$34 -> 0 | M36: =+'Dez24'!$G$34 -> 0 | N36: =+L36-M36 -> 0 | O36: =+Paralelo!$H$34 -> 0 | P36: =+'Dez24'!$H$34 -> 0 | Q36: =+O36-P36 -> 0 | R36: =+Paralelo!$I$34 -> 0 | S36: =+'Dez24'!$I$34 -> 0 | T36: =+R36-S36 -> 0 | U36: =+Paralelo!$J$34 -> 0 | V36: =+'Dez24'!$J$34 -> 0 | W36: =+U36-V36 -> 0 | X36: =+Paralelo!$K$34 -> 0 | Y36: =+'Dez24'!$K$34 -> 0 | Z36: =+X36-Y36 -> 0 | AA36: =+Paralelo!$M$34 -> 0 | AB36: =+'Dez24'!$M$34 -> 0 | AC36: =+AA36-AB36 -> 0 | AD36: =+Paralelo!$N$34 -> 0 | AE36: =+'Dez24'!$N$34 -> 0 | AF36: =+AD36-AE36 -> 0 | AG36: =+Paralelo!$O$34 -> 0 | AH36: =+'Dez24'!$O$34 -> 0 | AI36: =+AG36-AH36 -> 0 | AJ36: =+Paralelo!$P$34 -> 0 | AK36: =+'Dez24'!$P$34 -> 0 | AL36: =+AJ36-AK36 -> 0 | AM36: =+Paralelo!$Q$34 -> 0 | AN36: =+'Dez24'!$Q$34 -> 0 | AO36: =+AM36-AN36 -> 0 | AP36: =+Paralelo!$R$34 -> 0 | AQ36: =+'Dez24'!$R$34 -> 0 | AR36: =+AP36-AQ36 -> 0 | AS36: =+Paralelo!$S$34 -> 0 | AT36: =+'Dez24'!$S$34 -> 0 | AU36: =+AS36-AT36 -> 0 | AV36: =+Paralelo!$T$34 -> 0 | AW36: =+'Dez24'!$T$34 -> 0 | AX36: =+AV36-AW36 -> 0
B37: GCA of loans collateralised by commercial immovable property with loan-to-value >= 100%, weighted by GCA | C37: =+Paralelo!$D$35 -> 0 | D37: =+'Dez24'!$D$35 -> 0 | E37: =+C37-D37 -> 0 | F37: =+Paralelo!$E$35 -> 0 | G37: =+'Dez24'!$E$35 -> 0 | H37: =+F37-G37 -> 0 | I37: =+Paralelo!$F$35 -> 0 | J37: =+'Dez24'!$F$35 -> 0 | K37: =+I37-J37 -> 0 | L37: =+Paralelo!$G$35 -> 0 | M37: =+'Dez24'!$G$35 -> 0 | N37: =+L37-M37 -> 0 | O37: =+Paralelo!$H$35 -> 0 | P37: =+'Dez24'!$H$35 -> 0 | Q37: =+O37-P37 -> 0 | R37: =+Paralelo!$I$35 -> 0 | S37: =+'Dez24'!$I$35 -> 0 | T37: =+R37-S37 -> 0 | U37: =+Paralelo!$J$35 -> 0 | V37: =+'Dez24'!$J$35 -> 0 | W37: =+U37-V37 -> 0 | X37: =+Paralelo!$K$35 -> 0 | Y37: =+'Dez24'!$K$35 -> 0 | Z37: =+X37-Y37 -> 0 | AA37: =+Paralelo!$M$35 -> 0 | AB37: =+'Dez24'!$M$35 -> 0 | AC37: =+AA37-AB37 -> 0 | AD37: =+Paralelo!$N$35 -> 0 | AE37: =+'Dez24'!$N$35 -> 0 | AF37: =+AD37-AE37 -> 0 | AG37: =+Paralelo!$O$35 -> 0 | AH37: =+'Dez24'!$O$35 -> 0 | AI37: =+AG37-AH37 -> 0 | AJ37: =+Paralelo!$P$35 -> 0 | AK37: =+'Dez24'!$P$35 -> 0 | AL37: =+AJ37-AK37 -> 0 | AM37: =+Paralelo!$Q$35 -> 0 | AN37: =+'Dez24'!$Q$35 -> 0 | AO37: =+AM37-AN37 -> 0 | AP37: =+Paralelo!$R$35 -> 0 | AQ37: =+'Dez24'!$R$35 -> 0 | AR37: =+AP37-AQ37 -> 0 | AS37: =+Paralelo!$S$35 -> 0 | AT37: =+'Dez24'!$S$35 -> 0 | AU37: =+AS37-AT37 -> 0 | AV37: =+Paralelo!$T$35 -> 0 | AW37: =+'Dez24'!$T$35 -> 0 | AX37: =+AV37-AW37 -> 0
B38: Average residual maturity in years of loans collateralised by commercial immovable property, weighted by gross carrying amount | C38: =+Paralelo!$D$36 -> 0 | D38: =+'Dez24'!$D$36 -> 0 | E38: =+C38-D38 -> 0 | F38: =+Paralelo!$E$36 -> 0 | G38: =+'Dez24'!$E$36 -> 0 | H38: =+F38-G38 -> 0 | I38: =+Paralelo!$F$36 -> 0 | J38: =+'Dez24'!$F$36 -> 0 | K38: =+I38-J38 -> 0 | L38: =+Paralelo!$G$36 -> 0 | M38: =+'Dez24'!$G$36 -> 0 | N38: =+L38-M38 -> 0 | O38: =+Paralelo!$H$36 -> 0 | P38: =+'Dez24'!$H$36 -> 0 | Q38: =+O38-P38 -> 0 | R38: =+Paralelo!$I$36 -> 0 | S38: =+'Dez24'!$I$36 -> 0 | T38: =+R38-S38 -> 0 | U38: =+Paralelo!$J$36 -> 0 | V38: =+'Dez24'!$J$36 -> 0 | W38: =+U38-V38 -> 0 | X38: =+Paralelo!$K$36 -> 0 | Y38: =+'Dez24'!$K$36 -> 0 | Z38: =+X38-Y38 -> 0 | AA38: =+Paralelo!$M$36 -> 0 | AB38: =+'Dez24'!$M$36 -> 0 | AC38: =+AA38-AB38 -> 0 | AD38: =+Paralelo!$N$36 -> 0 | AE38: =+'Dez24'!$N$36 -> 0 | AF38: =+AD38-AE38 -> 0 | AG38: =+Paralelo!$O$36 -> 0 | AH38: =+'Dez24'!$O$36 -> 0 | AI38: =+AG38-AH38 -> 0 | AJ38: =+Paralelo!$P$36 -> 0 | AK38: =+'Dez24'!$P$36 -> 0 | AL38: =+AJ38-AK38 -> 0 | AM38: =+Paralelo!$Q$36 -> 0 | AN38: =+'Dez24'!$Q$36 -> 0 | AO38: =+AM38-AN38 -> 0 | AP38: =+Paralelo!$R$36 -> 0 | AQ38: =+'Dez24'!$R$36 -> 0 | AR38: =+AP38-AQ38 -> 0 | AS38: =+Paralelo!$S$36 -> 0 | AT38: =+'Dez24'!$S$36 -> 0 | AU38: =+AS38-AT38 -> 0 | AV38: =+Paralelo!$T$36 -> 0 | AW38: =+'Dez24'!$T$36 -> 0 | AX38: =+AV38-AW38 -> 0
B39: GCA of loans collateralised by commercial immovable property with Residual maturity < 5 years, weighted by GCA | C39: =+Paralelo!$D$37 -> 0 | D39: =+'Dez24'!$D$37 -> 0 | E39: =+C39-D39 -> 0 | F39: =+Paralelo!$E$37 -> 0 | G39: =+'Dez24'!$E$37 -> 0 | H39: =+F39-G39 -> 0 | I39: =+Paralelo!$F$37 -> 0 | J39: =+'Dez24'!$F$37 -> 0 | K39: =+I39-J39 -> 0 | L39: =+Paralelo!$G$37 -> 0 | M39: =+'Dez24'!$G$37 -> 0 | N39: =+L39-M39 -> 0 | O39: =+Paralelo!$H$37 -> 0 | P39: =+'Dez24'!$H$37 -> 0 | Q39: =+O39-P39 -> 0 | R39: =+Paralelo!$I$37 -> 0 | S39: =+'Dez24'!$I$37 -> 0 | T39: =+R39-S39 -> 0 | U39: =+Paralelo!$J$37 -> 0 | V39: =+'Dez24'!$J$37 -> 0 | W39: =+U39-V39 -> 0 | X39: =+Paralelo!$K$37 -> 0 | Y39: =+'Dez24'!$K$37 -> 0 | Z39: =+X39-Y39 -> 0 | AA39: =+Paralelo!$M$37 -> 0 | AB39: =+'Dez24'!$M$37 -> 0 | AC39: =+AA39-AB39 -> 0 | AD39: =+Paralelo!$N$37 -> 0 | AE39: =+'Dez24'!$N$37 -> 0 | AF39: =+AD39-AE39 -> 0 | AG39: =+Paralelo!$O$37 -> 0 | AH39: =+'Dez24'!$O$37 -> 0 | AI39: =+AG39-AH39 -> 0 | AJ39: =+Paralelo!$P$37 -> 0 | AK39: =+'Dez24'!$P$37 -> 0 | AL39: =+AJ39-AK39 -> 0 | AM39: =+Paralelo!$Q$37 -> 0 | AN39: =+'Dez24'!$Q$37 -> 0 | AO39: =+AM39-AN39 -> 0 | AP39: =+Paralelo!$R$37 -> 0 | AQ39: =+'Dez24'!$R$37 -> 0 | AR39: =+AP39-AQ39 -> 0 | AS39: =+Paralelo!$S$37 -> 0 | AT39: =+'Dez24'!$S$37 -> 0 | AU39: =+AS39-AT39 -> 0 | AV39: =+Paralelo!$T$37 -> 0 | AW39: =+'Dez24'!$T$37 -> 0 | AX39: =+AV39-AW39 -> 0
B40: Average interest rate of new business flow on commercial immovable property, weighted by gross carrying amount | C40: =+Paralelo!$D$38 -> 0 | D40: =+'Dez24'!$D$38 -> 0 | E40: =+C40-D40 -> 0 | F40: =+Paralelo!$E$38 -> 0 | G40: =+'Dez24'!$E$38 -> 0 | H40: =+F40-G40 -> 0 | I40: =+Paralelo!$F$38 -> 0 | J40: =+'Dez24'!$F$38 -> 0 | K40: =+I40-J40 -> 0 | L40: =+Paralelo!$G$38 -> 0 | M40: =+'Dez24'!$G$38 -> 0 | N40: =+L40-M40 -> 0 | O40: =+Paralelo!$H$38 -> 0 | P40: =+'Dez24'!$H$38 -> 0 | Q40: =+O40-P40 -> 0 | R40: =+Paralelo!$I$38 -> 0 | S40: =+'Dez24'!$I$38 -> 0 | T40: =+R40-S40 -> 0 | U40: =+Paralelo!$J$38 -> 0 | V40: =+'Dez24'!$J$38 -> 0 | W40: =+U40-V40 -> 0 | X40: =+Paralelo!$K$38 -> 0 | Y40: =+'Dez24'!$K$38 -> 0 | Z40: =+X40-Y40 -> 0 | AA40: =+Paralelo!$M$38 -> 0 | AB40: =+'Dez24'!$M$38 -> 0 | AC40: =+AA40-AB40 -> 0 | AD40: =+Paralelo!$N$38 -> 0 | AE40: =+'Dez24'!$N$38 -> 0 | AF40: =+AD40-AE40 -> 0 | AG40: =+Paralelo!$O$38 -> 0 | AH40: =+'Dez24'!$O$38 -> 0 | AI40: =+AG40-AH40 -> 0 | AJ40: =+Paralelo!$P$38 -> 0 | AK40: =+'Dez24'!$P$38 -> 0 | AL40: =+AJ40-AK40 -> 0 | AM40: =+Paralelo!$Q$38 -> 0 | AN40: =+'Dez24'!$Q$38 -> 0 | AO40: =+AM40-AN40 -> 0 | AP40: =+Paralelo!$R$38 -> 0 | AQ40: =+'Dez24'!$R$38 -> 0 | AR40: =+AP40-AQ40 -> 0 | AS40: =+Paralelo!$S$38 -> 0 | AT40: =+'Dez24'!$S$38 -> 0 | AU40: =+AS40-AT40 -> 0 | AV40: =+Paralelo!$T$38 -> 0 | AW40: =+'Dez24'!$T$38 -> 0 | AX40: =+AV40-AW40 -> 0
B41: Residential immovable property
B42: Average loan-to-value of loans collateralised by residential immovable property, weighted by gross carrying amount | C42: =+Paralelo!$D$40 -> 0.68794187 | D42: =+'Dez24'!$D$40 -> 0 | E42: =+C42-D42 -> 0.68794187 | F42: =+Paralelo!$E$40 -> 0.63314264 | G42: =+'Dez24'!$E$40 -> 0 | H42: =+F42-G42 -> 0.63314264 | I42: =+Paralelo!$F$40 -> 0.66684164 | J42: =+'Dez24'!$F$40 -> 0 | K42: =+I42-J42 -> 0.66684164 | L42: =+Paralelo!$G$40 -> 0.63087478 | M42: =+'Dez24'!$G$40 -> 0 | N42: =+L42-M42 -> 0.63087478 | O42: =+Paralelo!$H$40 -> 0.64688966 | P42: =+'Dez24'!$H$40 -> 0 | Q42: =+O42-P42 -> 0.64688966 | R42: =+Paralelo!$I$40 -> 0.67460338 | S42: =+'Dez24'!$I$40 -> 0 | T42: =+R42-S42 -> 0.67460338 | U42: =+Paralelo!$J$40 -> 0.79924913 | V42: =+'Dez24'!$J$40 -> 0 | W42: =+U42-V42 -> 0.79924913 | X42: =+Paralelo!$K$40 -> 0.9094253 | Y42: =+'Dez24'!$K$40 -> 0 | Z42: =+X42-Y42 -> 0.9094253 | AA42: =+Paralelo!$M$40 -> 0.60421091 | AB42: =+'Dez24'!$M$40 -> 0 | AC42: =+AA42-AB42 -> 0.60421091 | AD42: =+Paralelo!$N$40 -> 0.64865362 | AE42: =+'Dez24'!$N$40 -> 0 | AF42: =+AD42-AE42 -> 0.64865362 | AG42: =+Paralelo!$O$40 -> 0.71208031 | AH42: =+'Dez24'!$O$40 -> 0 | AI42: =+AG42-AH42 -> 0.71208031 | AJ42: =+Paralelo!$P$40 -> 0.68036322 | AK42: =+'Dez24'!$P$40 -> 0 | AL42: =+AJ42-AK42 -> 0.68036322 | AM42: =+Paralelo!$Q$40 -> 0.64478617 | AN42: =+'Dez24'!$Q$40 -> 0 | AO42: =+AM42-AN42 -> 0.64478617 | AP42: =+Paralelo!$R$40 -> 0.57533064 | AQ42: =+'Dez24'!$R$40 -> 0 | AR42: =+AP42-AQ42 -> 0.57533064 | AS42: =+Paralelo!$S$40 -> 0 | AT42: =+'Dez24'!$S$40 -> 0 | AU42: =+AS42-AT42 -> 0 | AV42: =+Paralelo!$T$40 -> 0.66245149 | AW42: =+'Dez24'!$T$40 -> 0 | AX42: =+AV42-AW42 -> 0.66245149
B43: GCA of loans collateralised by residential immovable property with 80% < loan-to-value < 100%, weighted by GCA | C43: =+Paralelo!$D$41 -> 3442772 | D43: =+'Dez24'!$D$41 -> 0 | E43: =+C43-D43 -> 3442772 | F43: =+Paralelo!$E$41 -> 382575 | G43: =+'Dez24'!$E$41 -> 0 | H43: =+F43-G43 -> 382575 | I43: =+Paralelo!$F$41 -> 1361812 | J43: =+'Dez24'!$F$41 -> 0 | K43: =+I43-J43 -> 1361812 | L43: =+Paralelo!$G$41 -> 890429 | M43: =+'Dez24'!$G$41 -> 0 | N43: =+L43-M43 -> 890429 | O43: =+Paralelo!$H$41 -> 122439 | P43: =+'Dez24'!$H$41 -> 0 | Q43: =+O43-P43 -> 122439 | R43: =+Paralelo!$I$41 -> 0 | S43: =+'Dez24'!$I$41 -> 0 | T43: =+R43-S43 -> 0 | U43: =+Paralelo!$J$41 -> 103313 | V43: =+'Dez24'!$J$41 -> 0 | W43: =+U43-V43 -> 103313 | X43: =+Paralelo!$K$41 -> 582204 | Y43: =+'Dez24'!$K$41 -> 0 | Z43: =+X43-Y43 -> 582204 | AA43: =+Paralelo!$M$41 -> 209267 | AB43: =+'Dez24'!$M$41 -> 0 | AC43: =+AA43-AB43 -> 209267 | AD43: =+Paralelo!$N$41 -> 0 | AE43: =+'Dez24'!$N$41 -> 0 | AF43: =+AD43-AE43 -> 0 | AG43: =+Paralelo!$O$41 -> 1289551 | AH43: =+'Dez24'!$O$41 -> 0 | AI43: =+AG43-AH43 -> 1289551 | AJ43: =+Paralelo!$P$41 -> 925506 | AK43: =+'Dez24'!$P$41 -> 0 | AL43: =+AJ43-AK43 -> 925506 | AM43: =+Paralelo!$Q$41 -> 1018448 | AN43: =+'Dez24'!$Q$41 -> 0 | AO43: =+AM43-AN43 -> 1018448 | AP43: =+Paralelo!$R$41 -> 0 | AQ43: =+'Dez24'!$R$41 -> 0 | AR43: =+AP43-AQ43 -> 0 | AS43: =+Paralelo!$S$41 -> 0 | AT43: =+'Dez24'!$S$41 -> 0 | AU43: =+AS43-AT43 -> 0 | AV43: =+Paralelo!$T$41 -> 0 | AW43: =+'Dez24'!$T$41 -> 0 | AX43: =+AV43-AW43 -> 0
B44: GCA of loans collateralised by residential immovable property with loan-to-value >= 100%, weighted by GCA | C44: =+Paralelo!$D$42 -> 1671560 | D44: =+'Dez24'!$D$42 -> 0 | E44: =+C44-D44 -> 1671560 | F44: =+Paralelo!$E$42 -> 0 | G44: =+'Dez24'!$E$42 -> 0 | H44: =+F44-G44 -> 0 | I44: =+Paralelo!$F$42 -> 0 | J44: =+'Dez24'!$F$42 -> 0 | K44: =+I44-J44 -> 0 | L44: =+Paralelo!$G$42 -> 0 | M44: =+'Dez24'!$G$42 -> 0 | N44: =+L44-M44 -> 0 | O44: =+Paralelo!$H$42 -> 0 | P44: =+'Dez24'!$H$42 -> 0 | Q44: =+O44-P44 -> 0 | R44: =+Paralelo!$I$42 -> 0 | S44: =+'Dez24'!$I$42 -> 0 | T44: =+R44-S44 -> 0 | U44: =+Paralelo!$J$42 -> 0 | V44: =+'Dez24'!$J$42 -> 0 | W44: =+U44-V44 -> 0 | X44: =+Paralelo!$K$42 -> 1671560 | Y44: =+'Dez24'!$K$42 -> 0 | Z44: =+X44-Y44 -> 1671560 | AA44: =+Paralelo!$M$42 -> 0 | AB44: =+'Dez24'!$M$42 -> 0 | AC44: =+AA44-AB44 -> 0 | AD44: =+Paralelo!$N$42 -> 0 | AE44: =+'Dez24'!$N$42 -> 0 | AF44: =+AD44-AE44 -> 0 | AG44: =+Paralelo!$O$42 -> 0 | AH44: =+'Dez24'!$O$42 -> 0 | AI44: =+AG44-AH44 -> 0 | AJ44: =+Paralelo!$P$42 -> 0 | AK44: =+'Dez24'!$P$42 -> 0 | AL44: =+AJ44-AK44 -> 0 | AM44: =+Paralelo!$Q$42 -> 0 | AN44: =+'Dez24'!$Q$42 -> 0 | AO44: =+AM44-AN44 -> 0 | AP44: =+Paralelo!$R$42 -> 0 | AQ44: =+'Dez24'!$R$42 -> 0 | AR44: =+AP44-AQ44 -> 0 | AS44: =+Paralelo!$S$42 -> 0 | AT44: =+'Dez24'!$S$42 -> 0 | AU44: =+AS44-AT44 -> 0 | AV44: =+Paralelo!$T$42 -> 1671560 | AW44: =+'Dez24'!$T$42 -> 0 | AX44: =+AV44-AW44 -> 1671560
B45: Average residual maturity in years of loans collateralised by residential immovable property, weighted by gross carrying amount | C45: =+Paralelo!$D$43 -> 28.932399 | D45: =+'Dez24'!$D$43 -> 0 | E45: =+C45-D45 -> 28.932399 | F45: =+Paralelo!$E$43 -> 26.843539 | G45: =+'Dez24'!$E$43 -> 0 | H45: =+F45-G45 -> 26.843539 | I45: =+Paralelo!$F$43 -> 30.690954 | J45: =+'Dez24'!$F$43 -> 0 | K45: =+I45-J45 -> 30.690954 | L45: =+Paralelo!$G$43 -> 31.696234 | M45: =+'Dez24'!$G$43 -> 0 | N45: =+L45-M45 -> 31.696234 | O45: =+Paralelo!$H$43 -> 29.063306 | P45: =+'Dez24'!$H$43 -> 0 | Q45: =+O45-P45 -> 29.063306 | R45: =+Paralelo!$I$43 -> 33.996708 | S45: =+'Dez24'!$I$43 -> 0 | T45: =+R45-S45 -> 33.996708 | U45: =+Paralelo!$J$43 -> 32.903645 | V45: =+'Dez24'!$J$43 -> 0 | W45: =+U45-V45 -> 32.903645 | X45: =+Paralelo!$K$43 -> 30.798623 | Y45: =+'Dez24'!$K$43 -> 0 | Z45: =+X45-Y45 -> 30.798623 | AA45: =+Paralelo!$M$43 -> 29.745327 | AB45: =+'Dez24'!$M$43 -> 0 | AC45: =+AA45-AB45 -> 29.745327 | AD45: =+Paralelo!$N$43 -> 27.140883 | AE45: =+'Dez24'!$N$43 -> 0 | AF45: =+AD45-AE45 -> 27.140883 | AG45: =+Paralelo!$O$43 -> 28.273428 | AH45: =+'Dez24'!$O$43 -> 0 | AI45: =+AG45-AH45 -> 28.273428 | AJ45: =+Paralelo!$P$43 -> 31.771031 | AK45: =+'Dez24'!$P$43 -> 0 | AL45: =+AJ45-AK45 -> 31.771031 | AM45: =+Paralelo!$Q$43 -> 33.271777 | AN45: =+'Dez24'!$Q$43 -> 0 | AO45: =+AM45-AN45 -> 33.271777 | AP45: =+Paralelo!$R$43 -> 24.711852 | AQ45: =+'Dez24'!$R$43 -> 0 | AR45: =+AP45-AQ45 -> 24.711852 | AS45: =+Paralelo!$S$43 -> 0 | AT45: =+'Dez24'!$S$43 -> 0 | AU45: =+AS45-AT45 -> 0 | AV45: =+Paralelo!$T$43 -> 21.992527 | AW45: =+'Dez24'!$T$43 -> 0 | AX45: =+AV45-AW45 -> 21.992527
B46: GCA of loans collateralised by residential immovable property with Residual maturity < 5 years, weighted by GCA | C46: =+Paralelo!$D$44 -> 234502 | D46: =+'Dez24'!$D$44 -> 0 | E46: =+C46-D46 -> 234502 | F46: =+Paralelo!$E$44 -> 101484 | G46: =+'Dez24'!$E$44 -> 0 | H46: =+F46-G46 -> 101484 | I46: =+Paralelo!$F$44 -> 53941 | J46: =+'Dez24'!$F$44 -> 0 | K46: =+I46-J46 -> 53941 | L46: =+Paralelo!$G$44 -> 79077 | M46: =+'Dez24'!$G$44 -> 0 | N46: =+L46-M46 -> 79077 | O46: =+Paralelo!$H$44 -> 0 | P46: =+'Dez24'!$H$44 -> 0 | Q46: =+O46-P46 -> 0 | R46: =+Paralelo!$I$44 -> 0 | S46: =+'Dez24'!$I$44 -> 0 | T46: =+R46-S46 -> 0 | U46: =+Paralelo!$J$44 -> 0 | V46: =+'Dez24'!$J$44 -> 0 | W46: =+U46-V46 -> 0 | X46: =+Paralelo!$K$44 -> 0 | Y46: =+'Dez24'!$K$44 -> 0 | Z46: =+X46-Y46 -> 0 | AA46: =+Paralelo!$M$44 -> 17292 | AB46: =+'Dez24'!$M$44 -> 0 | AC46: =+AA46-AB46 -> 17292 | AD46: =+Paralelo!$N$44 -> 8149 | AE46: =+'Dez24'!$N$44 -> 0 | AF46: =+AD46-AE46 -> 8149 | AG46: =+Paralelo!$O$44 -> 76043 | AH46: =+'Dez24'!$O$44 -> 0 | AI46: =+AG46-AH46 -> 76043 | AJ46: =+Paralelo!$P$44 -> 14649 | AK46: =+'Dez24'!$P$44 -> 0 | AL46: =+AJ46-AK46 -> 14649 | AM46: =+Paralelo!$Q$44 -> 75423 | AN46: =+'Dez24'!$Q$44 -> 0 | AO46: =+AM46-AN46 -> 75423 | AP46: =+Paralelo!$R$44 -> 42946 | AQ46: =+'Dez24'!$R$44 -> 0 | AR46: =+AP46-AQ46 -> 42946 | AS46: =+Paralelo!$S$44 -> 0 | AT46: =+'Dez24'!$S$44 -> 0 | AU46: =+AS46-AT46 -> 0 | AV46: =+Paralelo!$T$44 -> 234502 | AW46: =+'Dez24'!$T$44 -> 0 | AX46: =+AV46-AW46 -> 234502
B47: Average interest rate of new business flow on residential immovable property, weighted by gross carrying amount | C47: =+Paralelo!$D$45 -> 0.030039575 | D47: =+'Dez24'!$D$45 -> 0 | E47: =+C47-D47 -> 0.030039575 | F47: =+Paralelo!$E$45 -> 0.03 | G47: =+'Dez24'!$E$45 -> 0 | H47: =+F47-G47 -> 0.03 | I47: =+Paralelo!$F$45 -> 0.03 | J47: =+'Dez24'!$F$45 -> 0 | K47: =+I47-J47 -> 0.03 | L47: =+Paralelo!$G$45 -> 0.03 | M47: =+'Dez24'!$G$45 -> 0 | N47: =+L47-M47 -> 0.03 | O47: =+Paralelo!$H$45 -> 0.030877799 | P47: =+'Dez24'!$H$45 -> 0 | Q47: =+O47-P47 -> 0.030877799 | R47: =+Paralelo!$I$45 -> 0.03 | S47: =+'Dez24'!$I$45 -> 0 | T47: =+R47-S47 -> 0.03 | U47: =+Paralelo!$J$45 -> 0.03 | V47: =+'Dez24'!$J$45 -> 0 | W47: =+U47-V47 -> 0.03 | X47: =+Paralelo!$K$45 -> 0.030009934 | Y47: =+'Dez24'!$K$45 -> 0 | Z47: =+X47-Y47 -> 0.030009934 | AA47: =+Paralelo!$M$45 -> 0.03 | AB47: =+'Dez24'!$M$45 -> 0 | AC47: =+AA47-AB47 -> 0.03 | AD47: =+Paralelo!$N$45 -> 0.03 | AE47: =+'Dez24'!$N$45 -> 0 | AF47: =+AD47-AE47 -> 0.03 | AG47: =+Paralelo!$O$45 -> 0.03 | AH47: =+'Dez24'!$O$45 -> 0 | AI47: =+AG47-AH47 -> 0.03 | AJ47: =+Paralelo!$P$45 -> 0.03 | AK47: =+'Dez24'!$P$45 -> 0 | AL47: =+AJ47-AK47 -> 0.03 | AM47: =+Paralelo!$Q$45 -> 0.03 | AN47: =+'Dez24'!$Q$45 -> 0 | AO47: =+AM47-AN47 -> 0.03 | AP47: =+Paralelo!$R$45 -> 0.030596546 | AQ47: =+'Dez24'!$R$45 -> 0 | AR47: =+AP47-AQ47 -> 0.030596546 | AS47: =+Paralelo!$S$45 -> 0 | AT47: =+'Dez24'!$S$45 -> 0 | AU47: =+AS47-AT47 -> 0 | AV47: =+Paralelo!$T$45 -> 0.03069774 | AW47: =+'Dez24'!$T$45 -> 0 | AX47: =+AV47-AW47 -> 0.03069774

Sheet Input >>

Sheet Paralelo
M1: 1-REAL | N1: 1-REAL | O1: 1-REAL | P1: 1-REAL | Q1: 1-REAL | R1: 1-REAL | S1: 1-REAL | T1: Sem dados | U1: 7-SIN DATO
C2: Template 2: Banking book - Climate change transition risk: Loans collateralised by immovable property - Energy efficiency of the collateral | D2: EU-area | M2: SANTANDER | N2: SANTANDER | O2: SANTANDER | P2: SANTANDER | Q2: SANTANDER | R2: SANTANDER | S2: SANTANDER
D3: Non EU-area | E3: menor_100 | F3: menor_200 | G3: menor_300 | H3: menor_400 | I3: menor_500 | J3: maior_500 | M3: NULL | N3: NULL | O3: NULL | P3: NULL | Q3: NULL | R3: NULL | S3: NULL
D4: a | E4: b | F4: c | G4: d | H4: e | I4: f | J4: g | K4: h | L4: i | M4: j | N4: k | O4: l | P4: m | Q4: n | R4: o | S4: p | T4: q | U4: r
C5: Counterparty sector | D5: Total gross carrying amount (EUR) - except averages
E6: Level of energy efficiency (EP score in kWh/m² of collateral) | K6: Without EP score in kWh/m² of collateral | M6: Level of energy efficiency (EPC label of collateral) | T6: Without EPC label of collateral
E7: 0; <= 100 | F7: > 100; <= 200 | G7: > 200; <= 300 | H7: > 300; <= 400 | I7: > 400; <= 500 | J7: > 500 | L7: Of which level of energy efficiency (EP score in kWh/m² of collateral) estimated [%] | M7: A | N7: B | O7: C | P7: D | Q7: E | R7: F | S7: G | U7: Of which level of energy efficiency (EPC label of collateral) estimated [%]
B8: 1 | C8: Total EU area | D8: 26904628052 | E8: 13857398217 | F8: 10225191670 | G8: 2367207611 | H8: 188210984 | I8: 1110820 | J8: 1520131 | K8: 26833996951 | L8: 0.65694136 | M8: 1671450621 | N8: 1784964004 | O8: 3299985281 | P8: 3275367846 | Q8: 1823456758 | R8: 817219326 | S8: 2979175 | T8: 14229205041 | U8: 0.96628417
A9: Garantia Comercial | B9: 2 | C9: Of which Loans collateralised by commercial immovable property | D9: 3564429225 | E9: 1309576605 | F9: 1805186626 | G9: 215606343 | H9: 9019911 | I9: 10 | J9: 1520131 | K9: 3564429222 | L9: 0.87828641 | M9: 76726507 | N9: 162195592 | O9: 106266201 | P9: 75884761 | Q9: 35911971 | R9: 33117264 | S9: 712814 | T9: 3073614115 | U9: 0.92698917
A10: Garantia Residencial | B10: 3 | C10: Of which Loans collateralised by residential immovable property | D10: 23291747260 | E10: 12529955185 | F10: 8394660368 | G10: 2149729104 | H10: 178979591 | I10: 1110810 | J10: 0 | K10: 23269567729 | L10: 0.62303576 | M10: 1594724114 | N10: 1622641829 | O10: 3193277712 | P10: 3199195678 | Q10: 1787281853 | R10: 783445089 | S10: 2266361 | T10: 11108914624 | U10: 0.98121635
A11: Stock | B11: 4 | C11: Of which Collateral obtained by taking possession: residential and commercial immovable properties | D11: 48451567 | E11: 17866427 | F11: 25344676 | G11: 1872164 | H11: 211482 | I11: 0 | J11: 0 | K11: 0 | L11: 0 | M11: 0 | N11: 126583 | O11: 441368 | P11: 287407 | Q11: 262934 | R11: 656973 | S11: 0 | T11: 46676302 | U11: 0
A12: Sem dados | B12: 5 | C12: Of which Level of energy efficiency (EP score in kWh/m² and EPC label of collateral) estimated | D12: 26640639433 | E12: 13857398217 | F12: 10225191670 | G12: 2367207611 | H12: 188210984 | I12: 1110820 | J12: 1520131 | K12: 17628362545 | L12: 1 | M12: 912719513 | N12: 1493358008 | O12: 4770592268 | P12: 3804989795 | Q12: 1672617824 | R12: 1033539249 | S12: 61456770 | T12: 13965712418 | U12: 0.98450212
C13: Commercial immovable property
B14: 6 | C14: Average loan-to-value of loans collateralised by commercial immovable property, weighted by gross carrying amount | D14: 0.45543762 | E14: 0.38192858 | F14: 0.44969859 | G14: 0.4286435 | H14: 0.41724982 | I14: 0.58404534 | J14: 0.65668062 | K14: 0.68649151 | M14: 0.43265102 | N14: 0.43230476 | O14: 0.42620868 | P14: 0.42359258 | Q14: 0.43230476 | R14: 0.44550017 | S14: 0.39862966 | T14: 0.45395554
B15: 7 | C15: GCA of loans collateralised by commercial immovable property with 80% < loan-to-value < 100%, weighted by GCA | D15: 277438276 | E15: 45561405 | F15: 50866219 | G15: 16936161 | H15: 0 | I15: 0 | J15: 6137138 | K15: 157937353 | M15: 5510927 | N15: 23806369 | O15: 40609871 | P15: 33268865 | Q15: 9085878 | R15: 13406658 | S15: 100151 | T15: 247077170
B16: 8 | C16: GCA of loans collateralised by commercial immovable property with loan-to-value >= 100%, weighted by GCA | D16: 112936651 | E16: 15834570 | F16: 51110836 | G16: 751176 | H16: 0 | I16: 0 | J16: 0 | K16: 45240069 | M16: 1516403 | N16: 1993693 | O16: 51888935 | P16: 9962786 | Q16: 1939744 | R16: 583500 | S16: 0 | T16: 112164532
B17: 9 | C17: Average residual maturity in years of loans collateralised by commercial immovable property, weighted by gross carrying amount | D17: 7.5421303 | E17: 8.4231814 | F17: 7.316536 | G17: 8.1143234 | H17: 6.8086628 | I17: 16.060535 | J17: 14.005843 | K17: 5.4342255 | M17: 8.911819 | N17: 8.2793787 | O17: 7.6479249 | P17: 7.1858983 | Q17: 7.5200788 | R17: 9.0296118 | S17: 8.185014 | T17: 7.4180472
B18: 10 | C18: GCA of loans collateralised by commercial immovable property with Residual maturity < 5 years, weighted by GCA | D18: 1390218741 | E18: 458047307 | F18: 595574069 | G18: 61131967 | H18: 2869003 | I18: 10 | J18: 1185682 | K18: 271410703 | M18: 156270700 | N18: 121921206 | O18: 523364849 | P18: 253308997 | Q18: 110767765 | R18: 38248745 | S18: 1865995 | T18: 1235387933
B19: 11 | C19: Average interest rate of new business flow on commercial immovable property, weighted by gross carrying amount | D19: 0.048694173 | E19: 0.048607545 | F19: 0.048492773 | G19: 0.04461362 | H19: 0.05 | I19: 0.042224242 | J19: 0.041089406 | K19: 0.05351058 | M19: 0.055090035 | N19: 0.047188345 | O19: 0.048707857 | P19: 0.04875154 | Q19: 0.049233857 | R19: 0.044064114 | S19: 0.049075319 | T19: 0.048294501
C20: Residential immovable property
B21: 12 | C21: Average loan-to-value of loans collateralised by residential immovable property, weighted by gross carrying amount | D21: 0.59149761 | E21: 0.53590104 | F21: 0.53987482 | G21: 0.55633899 | H21: 0.60189163 | I21: 0.66231878 | J21: 0.65618755 | K21: 0.67370955 | M21: 0.59386127 | N21: 0.58770996 | O21: 0.58674821 | P21: 0.59150376 | Q21: 0.60208842 | R21: 0.58331325 | S21: 0.50906698 | T21: 0.52311623
B22: 13 | C22: GCA of loans collateralised by residential immovable property with 80% < loan-to-value < 100%, weighted by GCA | D22: 2903026477 | E22: 457743389 | F22: 335746347 | G22: 152349621 | H22: 35238417 | I22: 11739632 | J22: 13963158 | K22: 1896245913 | M22: 273288008 | N22: 297990927 | O22: 820913205 | P22: 865581085 | Q22: 445111127 | R22: 197438763 | S22: 2241514 | T22: 558661121
B23: 14 | C23: GCA of loans collateralised by residential immovable property with loan-to-value >= 100%, weighted by GCA | D23: 166880464 | E23: 62045513 | F23: 37344300 | G23: 22985207 | H23: 555330 | I23: 123162 | J23: 374294 | K23: 43452658 | M23: 18693699 | N23: 14544457 | O23: 23234457 | P23: 36184016 | Q23: 20987922 | R23: 19734204 | S23: 43300 | T23: 138789125
B24: 15 | C24: Average residual maturity in years of loans collateralised by residential immovable property, weighted by gross carrying amount | D24: 27.012236 | E24: 24.418805 | F24: 24.08959 | G24: 24.690553 | H24: 27.5455 | I24: 30.97428 | J24: 30.86586 | K24: 31.243197 | M24: 28.931343 | N24: 27.462671 | O24: 26.380029 | P24: 26.849405 | Q24: 27.115961 | R24: 26.602832 | S24: 22.239707 | T24: 23.021301
B25: 16 | C25: GCA of loans collateralised by residential immovable property with Residual maturity < 5 years, weighted by GCA | D25: 208148076 | E25: 102491286 | F25: 70270905 | G25: 24492586 | H25: 2142109 | I25: 52750 | J25: 35919 | K25: 8662521 | M25: 11396671 | N25: 18821034 | O25: 66538762 | P25: 62086336 | Q25: 30200816 | R25: 17874367 | S25: 968632 | T25: 189061201
B26: 17 | C26: Average interest rate of new business flow on residential immovable property, weighted by gross carrying amount | D26: 0.030209596 | E26: 0.030204837 | F26: 0.030162869 | G26: 0.030189149 | H26: 0.030192223 | I26: 0.030048663 | J26: 0.03023893 | K26: 0.030236442 | M26: 0.030185616 | N26: 0.030169772 | O26: 0.030242347 | P26: 0.030190767 | Q26: 0.030195164 | R26: 0.030275266 | S26: 0.030183925 | T26: 0.030257715
B27: 18 | C27: Total non-EU area | D27: 0 | E27: 0 | F27: 0 | G27: 0 | H27: 0 | I27: 0 | J27: 0 | K27: 22179545 | L27: 0.8288478 | M27: 0 | N27: 0 | O27: 0 | P27: 0 | Q27: 0 | R27: 0 | S27: 0 | T27: 0 | U27: 0
B28: 19 | C28: Of which Loans collateralised by commercial immovable property | D28: 0 | E28: 0 | F28: 0 | G28: 0 | H28: 0 | I28: 0 | J28: 0 | K28: 0 | L28: 0 | M28: 0 | N28: 0 | O28: 0 | P28: 0 | Q28: 0 | R28: 0 | S28: 0 | T28: 0 | U28: 0
B29: 20 | C29: Of which Loans collateralised by residential immovable property | D29: 0 | E29: 0 | F29: 0 | G29: 0 | H29: 0 | I29: 0 | J29: 0 | K29: 22179545 | L29: 0.8288478 | M29: 0 | N29: 0 | O29: 0 | P29: 0 | Q29: 0 | R29: 0 | S29: 0 | T29: 0 | U29: 0
B30: 21 | C30: Of which Collateral obtained by taking possession: residential and commercial immovable properties | D30: 0 | E30: 0 | F30: 0 | G30: 0 | H30: 0 | I30: 0 | J30: 0 | K30: 0 | L30: 0 | M30: 0 | N30: 0 | O30: 0 | P30: 0 | Q30: 0 | R30: 0 | S30: 0 | T30: 0 | U30: 0
B31: 22 | C31: Of which Level of energy efficiency (EP score in kWh/m² and EPC label of collateral) estimated | D31: 0 | E31: 0 | F31: 0 | G31: 0 | H31: 0 | I31: 0 | J31: 0 | K31: 18383467 | L31: 1 | M31: 327837 | N31: 129287 | O31: 285851 | P31: 725757 | Q31: 514126 | R31: 363749 | S31: 0 | T31: 0 | U31: 0
C32: Commercial immovable property
B33: 23 | C33: Average loan-to-value of loans collateralised by commercial immovable property, weighted by gross carrying amount | D33: 0 | E33: 0 | F33: 0 | G33: 0 | H33: 0 | I33: 0 | J33: 0 | K33: 0 | M33: 0 | N33: 0 | O33: 0 | P33: 0 | Q33: 0 | R33: 0 | S33: 0 | T33: 0
B34: 24 | C34: GCA of loans collateralised by commercial immovable property with 80% < loan-to-value < 100%, weighted by GCA | D34: 0 | E34: 0 | F34: 0 | G34: 0 | H34: 0 | I34: 0 | J34: 0 | K34: 0 | M34: 0 | N34: 0 | O34: 0 | P34: 0 | Q34: 0 | R34: 0 | S34: 0 | T34: 0
B35: 25 | C35: GCA of loans collateralised by commercial immovable property with loan-to-value >= 100%, weighted by GCA | D35: 0 | E35: 0 | F35: 0 | G35: 0 | H35: 0 | I35: 0 | J35: 0 | K35: 0 | M35: 0 | N35: 0 | O35: 0 | P35: 0 | Q35: 0 | R35: 0 | S35: 0 | T35: 0
B36: 26 | C36: Average residual maturity in years of loans collateralised by commercial immovable property, weighted by gross carrying amount | D36: 0 | E36: 0 | F36: 0 | G36: 0 | H36: 0 | I36: 0 | J36: 0 | K36: 0 | M36: 0 | N36: 0 | O36: 0 | P36: 0 | Q36: 0 | R36: 0 | S36: 0 | T36: 0
B37: 27 | C37: GCA of loans collateralised by commercial immovable property with Residual maturity < 5 years, weighted by GCA | D37: 0 | E37: 0 | F37: 0 | G37: 0 | H37: 0 | I37: 0 | J37: 0 | K37: 0 | M37: 0 | N37: 0 | O37: 0 | P37: 0 | Q37: 0 | R37: 0 | S37: 0 | T37: 0
B38: 28 | C38: Average interest rate of new business flow on commercial immovable property, weighted by gross carrying amount | D38: 0 | E38: 0 | F38: 0 | G38: 0 | H38: 0 | I38: 0 | J38: 0 | K38: 0 | M38: 0 | N38: 0 | O38: 0 | P38: 0 | Q38: 0 | R38: 0 | S38: 0 | T38: 0
C39: Residential immovable property
B40: 29 | C40: Average loan-to-value of loans collateralised by residential immovable property, weighted by gross carrying amount | D40: 0.68794187 | E40: 0.63314264 | F40: 0.66684164 | G40: 0.63087478 | H40: 0.64688966 | I40: 0.67460338 | J40: 0.79924913 | K40: 0.9094253 | M40: 0.60421091 | N40: 0.64865362 | O40: 0.71208031 | P40: 0.68036322 | Q40: 0.64478617 | R40: 0.57533064 | S40: 0 | T40: 0.66245149
...

Sheet Dez24
M1: 1-REAL | N1: 1-REAL | O1: 1-REAL | P1: 1-REAL | Q1: 1-REAL | R1: 1-REAL | S1: 1-REAL | T1: Sem dados | U1: 7-SIN DATO
C2: Template 2: Banking book - Climate change transition risk: Loans collateralised by immovable property - Energy efficiency of the collateral | M2: SANTANDER | N2: SANTANDER | O2: SANTANDER | P2: SANTANDER | Q2: SANTANDER | R2: SANTANDER | S2: SANTANDER
E3: menor_100 | F3: menor_200 | G3: menor_300 | H3: menor_400 | I3: menor_500 | J3: maior_500 | M3: NULL | N3: NULL | O3: NULL | P3: NULL | Q3: NULL | R3: NULL | S3: NULL
D4: a | E4: b | F4: c | G4: d | H4: e | I4: f | J4: g | K4: h | L4: i | M4: j | N4: k | O4: l | P4: m | Q4: n | R4: o | S4: p | T4: q | U4: r
C5: Counterparty sector | D5: Total gross carrying amount (EUR) - except averages
E6: Level of energy efficiency (EP score in kWh/m² of collateral) | K6: Without EP score in kWh/m² of collateral | M6: Level of energy efficiency (EPC label of collateral) | T6: Without EPC label of collateral
E7: 0; <= 100 | F7: > 100; <= 200 | G7: > 200; <= 300 | H7: > 300; <= 400 | I7: > 400; <= 500 | J7: > 500 | L7: Of which level of energy efficiency (EP score in kWh/m² of collateral) estimated [%] | M7: A | N7: B | O7: C | P7: D | Q7: E | R7: F | S7: G | U7: Of which level of energy efficiency (EPC label of collateral) estimated [%]
B8: 1 | C8: Total EU area | D8: 26904628052 | E8: 13857398217 | F8: 10225191670 | G8: 2367207611 | H8: 188210984 | I8: 1110820 | J8: 1520131 | K8: 26904628045 | L8: 0.99018798 | M8: 1671450621 | N8: 1784964004 | O8: 3299985281 | P8: 3275367846 | Q8: 1823456758 | R8: 817219326 | S8: 2979175 | T8: 14229205041 | U8: 0.98145783
A9: Garantia Comercial | B9: 2 | C9: Of which Loans collateralised by commercial immovable property | D9: 3564429225 | E9: 1309576605 | F9: 1805186626 | G9: 215606343 | H9: 9019911 | I9: 10 | J9: 1520131 | K9: 3564429222 | L9: 0.93729162 | M9: 76726507 | N9: 162195592 | O9: 106266201 | P9: 75884761 | Q9: 35911971 | R9: 33117264 | S9: 712814 | T9: 3073614115 | U9: 0.92727751
A10: Garantia Residencial | B10: 3 | C10: Of which Loans collateralised by residential immovable property | D10: 23291747260 | E10: 12529955185 | F10: 8394660368 | G10: 2149729104 | H10: 178979591 | I10: 1110810 | J10: 0 | K10: 23291747256 | L10: 0.99839805 | M10: 1594724114 | N10: 1622641829 | O10: 3193277712 | P10: 3199195678 | Q10: 1787281853 | R10: 783445089 | S10: 2266361 | T10: 11108914624 | U10: 0.99666213
