Workbook

Sheet PDS
G1: Estado especificação | U1: Estado desenvolvimento
E2: Total | G2: Concluído | I2: Mapeamento com LT fechado, mas parametrização pendente | K2: Novo campo, mapeamento datalake fechado, com necessidade de criar parametrização | M2: Novo campo, mapeamento datalake fechado, sem necessidade de criar parametrização | O2: Novo campo, mapeamento datalake pendente, com necessidade de criar parametrização | Q2: Novo campo, mapeamento datalake pendente, sem necessidade de criar parametrização | S2: Por iniciar | U2: Concluído | W2: Em desenvolvimento | Y2: Aguarda desenvolvimento de outras equipas | AA2: Por especificar
B3: Módulo | C3: Submódulo | D3: Nome do Ficheiro | E3: abs | F3: % | G3: abs | H3: % | I3: abs | J3: % | K3: abs | L3: % | M3: abs | N3: % | O3: abs | P3: % | Q3: abs | R3: % | S3: abs | T3: % | U3: abs | V3: % | W3: abs | X3: % | Y3: abs | Z3: % | AA3: abs | AB3: %
B4: Exposures to legal persons | C4: Instruments | D4: XXXXX_YYYYMMDD_01_01_leg_instr.csv | E4: =COUNTA(LEGALP_INSTRUMENTS!A3:A27) -> 7 | F4: =SUM(H4,J4,L4,N4,P4,R4,T4) -> 1 | G4: =COUNTIF(LEGALP_INSTRUMENTS!O:O,"Concluído") -> 7 | H4: =G4/E4 -> 1 | I4: =COUNTIF(LEGALP_INSTRUMENTS!O:O,"Mapeamento com LT fechado, mas parametrização pendente") -> 0 | J4: =I4/E4 -> 0 | K4: =COUNTIF(LEGALP_INSTRUMENTS!O:O,"Novo campo, mapeamento datalake fechado, com necessidade de criar parametrização") -> 0 | L4: =K4/E4 -> 0 | M4: =COUNTIF(LEGALP_INSTRUMENTS!O:O,"Novo campo, mapeamento datalake fechado, sem necessidade de criar parametrização") -> 0 | N4: =M4/E4 -> 0 | O4: =COUNTIF(LEGALP_INSTRUMENTS!O:O,"Novo campo, mapeamento datalake pendente, com necessidade de criar parametrização") -> 0 | P4: =O4/E4 -> 0 | Q4: =COUNTIF(LEGALP_INSTRUMENTS!O:O,"Novo campo, mapeamento datalake pendente, sem necessidade de criar parametrização") -> 0 | R4: =Q4/E4 -> 0 | S4: =COUNTIF(LEGALP_INSTRUMENTS!O:O,"Por iniciar") -> 0 | T4: =S4/E4 -> 0 | U4: =COUNTIF(LEGALP_INSTRUMENTS!P:P,"Concluído") -> 7 | V4: =U4/E4 -> 1 | W4: =COUNTIF(LEGALP_INSTRUMENTS!P:P,"Em desenvolvimento") -> 0 | X4: =W4/E4 -> 0 | Y4: =COUNTIF(LEGALP_INSTRUMENTS!P:P,"Aguarda desenvolvimento de outras equipas") -> 0 | Z4: =Y4/E4 -> 0 | AA4: =COUNTIF(LEGALP_INSTRUMENTS!P:P,"Por especificar") -> 0 | AB4: =AA4/E4 -> 0
C5: Counterparties | D5: XXXXX_YYYYMMDD_01_02_leg_count.csv | E5: =COUNTA(LEGALP_COUNTERPARTIES!A3:A27) -> 5 | F5: =SUM(H5,J5,L5,N5,P5,R5,T5) -> 1 | G5: =COUNTIF(LEGALP_COUNTERPARTIES!O:O,"Concluído") -> 5 | H5: =G5/E5 -> 1 | I5: =COUNTIF(LEGALP_COUNTERPARTIES!O:O,"Mapeamento com LT fechado, mas parametrização pendente") -> 0 | J5: =I5/E5 -> 0 | K5: =COUNTIF(LEGALP_COUNTERPARTIES!O:O,"Novo campo, mapeamento datalake fechado, com necessidade de criar parametrização") -> 0 | L5: =K5/E5 -> 0 | M5: =COUNTIF(LEGALP_COUNTERPARTIES!O:O,"Novo campo, mapeamento datalake fechado, sem necessidade de criar parametrização") -> 0 | N5: =M5/E5 -> 0 | O5: =COUNTIF(LEGALP_COUNTERPARTIES!O:O,"Novo campo, mapeamento datalake pendente, com necessidade de criar parametrização") -> 0 | P5: =O5/E5 -> 0 | Q5: =COUNTIF(LEGALP_COUNTERPARTIES!O:O,"Novo campo, mapeamento datalake pendente, sem necessidade de criar parametrização") -> 0 | R5: =Q5/E5 -> 0 | S5: =COUNTIF(LEGALP_COUNTERPARTIES!O:O,"Por iniciar") -> 0 | T5: =S5/E5 -> 0 | U5: =COUNTIF(LEGALP_COUNTERPARTIES!P:P,"Concluído") -> 5 | V5: =U5/E5 -> 1 | W5: =COUNTIF(LEGALP_COUNTERPARTIES!P:P,"Em desenvolvimento") -> 0 | X5: =W5/E5 -> 0 | Y5: =COUNTIF(LEGALP_COUNTERPARTIES!P:P,"Aguarda desenvolvimento de outras equipas") -> 0 | Z5: =Y5/E5 -> 0 | AA5: =COUNTIF(LEGALP_COUNTERPARTIES!P:P,"Por especificar") -> 0 | AB5: =AA5/E5 -> 0
C6: Protections | D6: XXXXX_YYYYMMDD_01_03_leg_prot.csv | E6: =COUNTA(LEGALP_PROTECTIONS!A3:A18) -> 8 | F6: =SUM(H6,J6,L6,N6,P6,R6,T6) -> 1 | G6: =COUNTIF(LEGALP_PROTECTIONS!O:O,"Concluído") -> 8 | H6: =G6/E6 -> 1 | I6: =COUNTIF(LEGALP_PROTECTIONS!O:O,"Mapeamento com LT fechado, mas parametrização pendente") -> 0 | J6: =I6/E6 -> 0 | K6: =COUNTIF(LEGALP_PROTECTIONS!O:O,"Novo campo, mapeamento datalake fechado, com necessidade de criar parametrização") -> 0 | L6: =K6/E6 -> 0 | M6: =COUNTIF(LEGALP_PROTECTIONS!O:O,"Novo campo, mapeamento datalake fechado, sem necessidade de criar parametrização") -> 0 | N6: =M6/E6 -> 0 | O6: =COUNTIF(LEGALP_PROTECTIONS!O:O,"Novo campo, mapeamento datalake pendente, com necessidade de criar parametrização") -> 0 | P6: =O6/E6 -> 0 | Q6: =COUNTIF(LEGALP_PROTECTIONS!O:O,"Novo campo, mapeamento datalake pendente, sem necessidade de criar parametrização") -> 0 | R6: =Q6/E6 -> 0 | S6: =COUNTIF(LEGALP_PROTECTIONS!O:O,"Por iniciar") -> 0 | T6: =S6/E6 -> 0 | U6: =COUNTIF(LEGALP_PROTECTIONS!P:P,"Concluído") -> 8 | V6: =U6/E6 -> 1 | W6: =COUNTIF(LEGALP_PROTECTIONS!P:P,"Em desenvolvimento") -> 0 | X6: =W6/E6 -> 0 | Y6: =COUNTIF(LEGALP_PROTECTIONS!P:P,"Aguarda desenvolvimento de outras equipas") -> 0 | Z6: =Y6/E6 -> 0 | AA6: =COUNTIF(LEGALP_PROTECTIONS!P:P,"Por especificar") -> 0 | AB6: =AA6/E6 -> 0
C7: Instrument-Counterparty relation | D7: XXXXX_YYYYMMDD_01_04_leg_instr_count.csv | E7: =COUNTA(LEGALP_INSTRUMENT_COUNTERPARTY!A3:A7) -> 2 | F7: =SUM(H7,J7,L7,N7,P7,R7,T7) -> 1 | G7: =COUNTIF(LEGALP_INSTRUMENT_COUNTERPARTY!O:O,"Concluído") -> 2 | H7: =G7/E7 -> 1 | I7: =COUNTIF(LEGALP_INSTRUMENT_COUNTERPARTY!O:O,"Mapeamento com LT fechado, mas parametrização pendente") -> 0 | J7: =I7/E7 -> 0 | K7: =COUNTIF(LEGALP_INSTRUMENT_COUNTERPARTY!O:O,"Novo campo, mapeamento datalake fechado, com necessidade de criar parametrização") -> 0 | L7: =K7/E7 -> 0 | M7: =COUNTIF(LEGALP_INSTRUMENT_COUNTERPARTY!O:O,"Novo campo, mapeamento datalake fechado, sem necessidade de criar parametrização") -> 0 | N7: =M7/E7 -> 0 | O7: =COUNTIF(LEGALP_INSTRUMENT_COUNTERPARTY!O:O,"Novo campo, mapeamento datalake pendente, com necessidade de criar parametrização") -> 0 | P7: =O7/E7 -> 0 | Q7: =COUNTIF(LEGALP_INSTRUMENT_COUNTERPARTY!O:O,"Novo campo, mapeamento datalake pendente, sem necessidade de criar parametrização") -> 0 | R7: =Q7/E7 -> 0 | S7: =COUNTIF(LEGALP_INSTRUMENT_COUNTERPARTY!O:O,"Por iniciar") -> 0 | T7: =S7/E7 -> 0 | U7: =COUNTIF(LEGALP_INSTRUMENT_COUNTERPARTY!P:P,"Concluído") -> 2 | V7: =U7/E7 -> 1 | W7: =COUNTIF(LEGALP_INSTRUMENT_COUNTERPARTY!P:P,"Em desenvolvimento") -> 0 | X7: =W7/E7 -> 0 | Y7: =COUNTIF(LEGALP_INSTRUMENT_COUNTERPARTY!P:P,"Aguarda desenvolvimento de outras equipas") -> 0 | Z7: =Y7/E7 -> 0 | AA7: =COUNTIF(LEGALP_INSTRUMENT_COUNTERPARTY!P:P,"Por especificar") -> 0 | AB7: =AA7/E7 -> 0
C8: Instrument-Protection relation | D8: XXXXX_YYYYMMDD_01_05_leg_instr_prot.csv | E8: =COUNTA(LEGALP_INSTRUMENT_PROTECTION!A3:A10) -> 2 | F8: =SUM(H8,J8,L8,N8,P8,R8,T8) -> 1 | G8: =COUNTIF(LEGALP_INSTRUMENT_PROTECTION!O:O,"Concluído") -> 2 | H8: =G8/E8 -> 1 | I8: =COUNTIF(LEGALP_INSTRUMENT_PROTECTION!O:O,"Mapeamento com LT fechado, mas parametrização pendente") -> 0 | J8: =I8/E8 -> 0 | K8: =COUNTIF(LEGALP_INSTRUMENT_PROTECTION!O:O,"Novo campo, mapeamento datalake fechado, com necessidade de criar parametrização") -> 0 | L8: =K8/E8 -> 0 | M8: =COUNTIF(LEGALP_INSTRUMENT_PROTECTION!O:O,"Novo campo, mapeamento datalake fechado, sem necessidade de criar parametrização") -> 0 | N8: =M8/E8 -> 0 | O8: =COUNTIF(LEGALP_INSTRUMENT_PROTECTION!O:O,"Novo campo, mapeamento datalake pendente, com necessidade de criar parametrização") -> 0 | P8: =O8/E8 -> 0 | Q8: =COUNTIF(LEGALP_INSTRUMENT_PROTECTION!O:O,"Novo campo, mapeamento datalake pendente, sem necessidade de criar parametrização") -> 0 | R8: =Q8/E8 -> 0 | S8: =COUNTIF(LEGALP_INSTRUMENT_PROTECTION!O:O,"Por iniciar") -> 0 | T8: =S8/E8 -> 0 | U8: =COUNTIF(LEGALP_INSTRUMENT_PROTECTION!P:P,"Concluído") -> 2 | V8: =U8/E8 -> 1 | W8: =COUNTIF(LEGALP_INSTRUMENT_PROTECTION!P:P,"Em desenvolvimento") -> 0 | X8: =W8/E8 -> 0 | Y8: =COUNTIF(LEGALP_INSTRUMENT_PROTECTION!P:P,"Aguarda desenvolvimento de outras equipas") -> 0 | Z8: =Y8/E8 -> 0 | AA8: =COUNTIF(LEGALP_INSTRUMENT_PROTECTION!P:P,"Por especificar") -> 0 | AB8: =AA8/E8 -> 0
B9: Exposures to natural persons | C9: Instruments | D9: XXXXX_YYYYMMDD_02_01_nat_instr.csv | E9: =COUNTA(NATURALP_INSTRUMENTS!A3:A142) -> 53 | F9: =SUM(H9,J9,L9,N9,P9,R9,T9) -> 1 | G9: =COUNTIF(NATURALP_INSTRUMENTS!P:P,"Concluído") -> 53 | H9: =G9/E9 -> 1 | I9: =COUNTIF(NATURALP_INSTRUMENTS!P:P,"Mapeamento com LT fechado, mas parametrização pendente") -> 0 | J9: =I9/E9 -> 0 | K9: =COUNTIF(NATURALP_INSTRUMENTS!P:P,"Novo campo, mapeamento datalake fechado, com necessidade de criar parametrização") -> 0 | L9: =K9/E9 -> 0 | M9: =COUNTIF(NATURALP_INSTRUMENTS!P:P,"Novo campo, mapeamento datalake fechado, sem necessidade de criar parametrização") -> 0 | N9: =M9/E9 -> 0 | O9: =COUNTIF(NATURALP_INSTRUMENTS!P:P,"Novo campo, mapeamento datalake pendente, com necessidade de criar parametrização") -> 0 | P9: =O9/E9 -> 0 | Q9: =COUNTIF(NATURALP_INSTRUMENTS!P:P,"Novo campo, mapeamento datalake pendente, sem necessidade de criar parametrização") -> 0 | R9: =Q9/E9 -> 0 | S9: =COUNTIF(NATURALP_INSTRUMENTS!P:P,"Por iniciar") -> 0 | T9: =S9/E9 -> 0 | U9: =COUNTIF(NATURALP_INSTRUMENTS!Q:Q,"Concluído") -> 53 | V9: =U9/E9 -> 1 | W9: =COUNTIF(NATURALP_INSTRUMENTS!Q:Q,"Em desenvolvimento") -> 0 | X9: =W9/E9 -> 0 | Y9: =COUNTIF(NATURALP_INSTRUMENTS!Q:Q,"Aguarda desenvolvimento de outras equipas") -> 0 | Z9: =Y9/E9 -> 0 | AA9: =COUNTIF(NATURALP_INSTRUMENTS!Q:Q,"Por especificar") -> 0 | AB9: =AA9/E9 -> 0
C10: Counterparties | D10: XXXXX_YYYYMMDD_02_02_nat_count.csv | E10: =COUNTA(NATURALP_COUNTERPARTIES!A3:A29) -> 8 | F10: =SUM(H10,J10,L10,N10,P10,R10,T10) -> 1 | G10: =COUNTIF(NATURALP_COUNTERPARTIES!O:O,"Concluído") -> 8 | H10: =G10/E10 -> 1 | I10: =COUNTIF(NATURALP_COUNTERPARTIES!O:O,"Mapeamento com LT fechado, mas parametrização pendente") -> 0 | J10: =I10/E10 -> 0 | K10: =COUNTIF(NATURALP_COUNTERPARTIES!O:O,"Novo campo, mapeamento datalake fechado, com necessidade de criar parametrização") -> 0 | L10: =K10/E10 -> 0 | M10: =COUNTIF(NATURALP_COUNTERPARTIES!O:O,"Novo campo, mapeamento datalake fechado, sem necessidade de criar parametrização") -> 0 | N10: =M10/E10 -> 0 | O10: =COUNTIF(NATURALP_COUNTERPARTIES!O:O,"Novo campo, mapeamento datalake pendente, com necessidade de criar parametrização") -> 0 | P10: =O10/E10 -> 0 | Q10: =COUNTIF(NATURALP_COUNTERPARTIES!O:O,"Novo campo, mapeamento datalake pendente, sem necessidade de criar parametrização") -> 0 | R10: =Q10/E10 -> 0 | S10: =COUNTIF(NATURALP_COUNTERPARTIES!O:O,"Por iniciar") -> 0 | T10: =S10/E10 -> 0 | U10: =COUNTIF(NATURALP_COUNTERPARTIES!P:P,"Concluído") -> 8 | V10: =U10/E10 -> 1 | W10: =COUNTIF(NATURALP_COUNTERPARTIES!P:P,"Em desenvolvimento") -> 0 | X10: =W10/E10 -> 0 | Y10: =COUNTIF(NATURALP_COUNTERPARTIES!P:P,"Aguarda desenvolvimento de outras equipas") -> 0 | Z10: =Y10/E10 -> 0 | AA10: =COUNTIF(NATURALP_COUNTERPARTIES!P:P,"Por especificar") -> 0 | AB10: =AA10/E10 -> 0
C11: Protections | D11: XXXXX_YYYYMMDD_02_03_nat_prot.csv | E11: =COUNTA(NATURALP_PROTECTIONS!A3:A27) -> 17 | F11: =SUM(H11,J11,L11,N11,P11,R11,T11) -> 1 | G11: =COUNTIF(NATURALP_PROTECTIONS!O:O,"Concluído") -> 17 | H11: =G11/E11 -> 1 | I11: =COUNTIF(NATURALP_PROTECTIONS!O:O,"Mapeamento com LT fechado, mas parametrização pendente") -> 0 | J11: =I11/E11 -> 0 | K11: =COUNTIF(NATURALP_PROTECTIONS!O:O,"Novo campo, mapeamento datalake fechado, com necessidade de criar parametrização") -> 0 | L11: =K11/E11 -> 0 | M11: =COUNTIF(NATURALP_PROTECTIONS!O:O,"Novo campo, mapeamento datalake fechado, sem necessidade de criar parametrização") -> 0 | N11: =M11/E11 -> 0 | O11: =COUNTIF(NATURALP_PROTECTIONS!O:O,"Novo campo, mapeamento datalake pendente, com necessidade de criar parametrização") -> 0 | P11: =O11/E11 -> 0 | Q11: =COUNTIF(NATURALP_PROTECTIONS!O:O,"Novo campo, mapeamento datalake pendente, sem necessidade de criar parametrização") -> 0 | R11: =Q11/E11 -> 0 | S11: =COUNTIF(NATURALP_PROTECTIONS!O:O,"Por iniciar") -> 0 | T11: =S11/E11 -> 0 | U11: =COUNTIF(NATURALP_PROTECTIONS!P:P,"Concluído") -> 17 | V11: =U11/E11 -> 1 | W11: =COUNTIF(NATURALP_PROTECTIONS!P:P,"Em desenvolvimento") -> 0 | X11: =W11/E11 -> 0 | Y11: =COUNTIF(NATURALP_PROTECTIONS!P:P,"Aguarda desenvolvimento de outras equipas") -> 0 | Z11: =Y11/E11 -> 0 | AA11: =COUNTIF(NATURALP_PROTECTIONS!P:P,"Por especificar") -> 0 | AB11: =AA11/E11 -> 0
C12: Instrument-Counterparty relation | D12: XXXXX_YYYYMMDD_02_04_nat_instr_count.csv | E12: =COUNTA(NATURALP_INSTRUMENT_COUNTERPART!A3:A9) -> 4 | F12: =SUM(H12,J12,L12,N12,P12,R12,T12) -> 1 | G12: =COUNTIF(NATURALP_INSTRUMENT_COUNTERPART!P:P,"Concluído") -> 4 | H12: =G12/E12 -> 1 | I12: =COUNTIF(NATURALP_INSTRUMENT_COUNTERPART!P:P,"Mapeamento com LT fechado, mas parametrização pendente") -> 0 | J12: =I12/E12 -> 0 | K12: =COUNTIF(NATURALP_INSTRUMENT_COUNTERPART!P:P,"Novo campo, mapeamento datalake fechado, com necessidade de criar parametrização") -> 0 | L12: =K12/E12 -> 0 | M12: =COUNTIF(NATURALP_INSTRUMENT_COUNTERPART!P:P,"Novo campo, mapeamento datalake fechado, sem necessidade de criar parametrização") -> 0 | N12: =M12/E12 -> 0 | O12: =COUNTIF(NATURALP_INSTRUMENT_COUNTERPART!P:P,"Novo campo, mapeamento datalake pendente, com necessidade de criar parametrização") -> 0 | P12: =O12/E12 -> 0 | Q12: =COUNTIF(NATURALP_INSTRUMENT_COUNTERPART!P:P,"Novo campo, mapeamento datalake pendente, sem necessidade de criar parametrização") -> 0 | R12: =Q12/E12 -> 0 | S12: =COUNTIF(NATURALP_INSTRUMENT_COUNTERPART!P:P,"Por iniciar") -> 0 | T12: =S12/E12 -> 0 | U12: =COUNTIF(NATURALP_INSTRUMENT_COUNTERPART!Q:Q,"Concluído") -> 4 | V12: =U12/E12 -> 1 | W12: =COUNTIF(NATURALP_INSTRUMENT_COUNTERPART!Q:Q,"Em desenvolvimento") -> 0 | X12: =W12/E12 -> 0 | Y12: =COUNTIF(NATURALP_INSTRUMENT_COUNTERPART!Q:Q,"Aguarda desenvolvimento de outras equipas") -> 0 | Z12: =Y12/E12 -> 0 | AA12: =COUNTIF(NATURALP_INSTRUMENT_COUNTERPART!Q:Q,"Por especificar") -> 0 | AB12: =AA12/E12 -> 0
C13: Instrument-Protection relation | D13: XXXXX_YYYYMMDD_02_05_nat_instr_prot.csv | E13: =COUNTA(NATURALP_INSTRUMENT_PROTECTION!A3:A12) -> 4 | F13: =SUM(H13,J13,L13,N13,P13,R13,T13) -> 1 | G13: =COUNTIF(NATURALP_INSTRUMENT_PROTECTION!O:O,"Concluído") -> 4 | H13: =G13/E13 -> 1 | I13: =COUNTIF(NATURALP_INSTRUMENT_PROTECTION!O:O,"Mapeamento com LT fechado, mas parametrização pendente") -> 0 | J13: =I13/E13 -> 0 | K13: =COUNTIF(NATURALP_INSTRUMENT_PROTECTION!O:O,"Novo campo, mapeamento datalake fechado, com necessidade de criar parametrização") -> 0 | L13: =K13/E13 -> 0 | M13: =COUNTIF(NATURALP_INSTRUMENT_PROTECTION!O:O,"Novo campo, mapeamento datalake fechado, sem necessidade de criar parametrização") -> 0 | N13: =M13/E13 -> 0 | O13: =COUNTIF(NATURALP_INSTRUMENT_PROTECTION!O:O,"Novo campo, mapeamento datalake pendente, com necessidade de criar parametrização") -> 0 | P13: =O13/E13 -> 0 | Q13: =COUNTIF(NATURALP_INSTRUMENT_PROTECTION!O:O,"Novo campo, mapeamento datalake pendente, sem necessidade de criar parametrização") -> 0 | R13: =Q13/E13 -> 0 | S13: =COUNTIF(NATURALP_INSTRUMENT_PROTECTION!O:O,"Por iniciar") -> 0 | T13: =S13/E13 -> 0 | U13: =COUNTIF(NATURALP_INSTRUMENT_PROTECTION!P:P,"Concluído") -> 4 | V13: =U13/E13 -> 1 | W13: =COUNTIF(NATURALP_INSTRUMENT_PROTECTION!P:P,"Em desenvolvimento") -> 0 | X13: =W13/E13 -> 0 | Y13: =COUNTIF(NATURALP_INSTRUMENT_PROTECTION!P:P,"Aguarda desenvolvimento de outras equipas") -> 0 | Z13: =Y13/E13 -> 0 | AA13: =COUNTIF(NATURALP_INSTRUMENT_PROTECTION!P:P,"Por especificar") -> 0 | AB13: =AA13/E13 -> 0
B14: Off-balance sheet exposures | C14: Instruments | D14: XXXXX_YYYYMMDD_03_01_off_instr.csv | E14: =COUNTA(OFFBAL_INSTRUMENTS!A3:A67) -> 27 | F14: =SUM(H14,J14,L14,N14,P14,R14,T14) -> 1 | G14: =COUNTIF(OFFBAL_INSTRUMENTS!O:O,"Concluído") -> 27 | H14: =G14/E14 -> 1 | I14: =COUNTIF(OFFBAL_INSTRUMENTS!O:O,"Mapeamento com LT fechado, mas parametrização pendente") -> 0 | J14: =I14/E14 -> 0 | K14: =COUNTIF(OFFBAL_INSTRUMENTS!O:O,"Novo campo, mapeamento datalake fechado, com necessidade de criar parametrização") -> 0 | L14: =K14/E14 -> 0 | M14: =COUNTIF(OFFBAL_INSTRUMENTS!O:O,"Novo campo, mapeamento datalake fechado, sem necessidade de criar parametrização") -> 0 | N14: =M14/E14 -> 0 | O14: =COUNTIF(OFFBAL_INSTRUMENTS!O:O,"Novo campo, mapeamento datalake pendente, com necessidade de criar parametrização") -> 0 | P14: =O14/E14 -> 0 | Q14: =COUNTIF(OFFBAL_INSTRUMENTS!O:O,"Novo campo, mapeamento datalake pendente, sem necessidade de criar parametrização") -> 0 | R14: =Q14/E14 -> 0 | S14: =COUNTIF(OFFBAL_INSTRUMENTS!O:O,"Por iniciar") -> 0 | T14: =S14/E14 -> 0 | U14: =COUNTIF(OFFBAL_INSTRUMENTS!P:P,"Concluído") -> 27 | V14: =U14/E14 -> 1 | W14: =COUNTIF(OFFBAL_INSTRUMENTS!P:P,"Em desenvolvimento") -> 0 | X14: =W14/E14 -> 0 | Y14: =COUNTIF(OFFBAL_INSTRUMENTS!P:P,"Aguarda desenvolvimento de outras equipas") -> 0 | Z14: =Y14/E14 -> 0 | AA14: =COUNTIF(OFFBAL_INSTRUMENTS!P:P,"Por especificar") -> 0 | AB14: =AA14/E14 -> 0
C15: Counterparties | D15: XXXXX_YYYYMMDD_03_02_off_count.csv | E15: =COUNTA(OFFBAL_COUNTERPARTIES!A3:A59) -> 30 | F15: =SUM(H15,J15,L15,N15,P15,R15,T15) -> 1 | G15: =COUNTIF(OFFBAL_COUNTERPARTIES!O:O,"Concluído") -> 30 | H15: =G15/E15 -> 1 | I15: =COUNTIF(OFFBAL_COUNTERPARTIES!O:O,"Mapeamento com LT fechado, mas parametrização pendente") -> 0 | J15: =I15/E15 -> 0 | K15: =COUNTIF(OFFBAL_COUNTERPARTIES!O:O,"Novo campo, mapeamento datalake fechado, com necessidade de criar parametrização") -> 0 | L15: =K15/E15 -> 0 | M15: =COUNTIF(OFFBAL_COUNTERPARTIES!O:O,"Novo campo, mapeamento datalake fechado, sem necessidade de criar parametrização") -> 0 | N15: =M15/E15 -> 0 | O15: =COUNTIF(OFFBAL_COUNTERPARTIES!O:O,"Novo campo, mapeamento datalake pendente, com necessidade de criar parametrização") -> 0 | P15: =O15/E15 -> 0 | Q15: =COUNTIF(OFFBAL_COUNTERPARTIES!O:O,"Novo campo, mapeamento datalake pendente, sem necessidade de criar parametrização") -> 0 | R15: =Q15/E15 -> 0 | S15: =COUNTIF(OFFBAL_COUNTERPARTIES!O:O,"Por iniciar") -> 0 | T15: =S15/E15 -> 0 | U15: =COUNTIF(OFFBAL_COUNTERPARTIES!P:P,"Concluído") -> 30 | V15: =U15/E15 -> 1 | W15: =COUNTIF(OFFBAL_COUNTERPARTIES!P:P,"Em desenvolvimento") -> 0 | X15: =W15/E15 -> 0 | Y15: =COUNTIF(OFFBAL_COUNTERPARTIES!P:P,"Aguarda desenvolvimento de outras equipas") -> 0 | Z15: =Y15/E15 -> 0 | AA15: =COUNTIF(OFFBAL_COUNTERPARTIES!P:P,"Por especificar") -> 0 | AB15: =AA15/E15 -> 0
C16: Protections | D16: XXXXX_YYYYMMDD_03_03_off_prot.csv | E16: =COUNTA(OFFBAL_PROTECTIONS!A3:A27) -> 17 | F16: =SUM(H16,J16,L16,N16,P16,R16,T16) -> 1 | G16: =COUNTIF(OFFBAL_PROTECTIONS!O:O,"Concluído") -> 17 | H16: =G16/E16 -> 1 | I16: =COUNTIF(OFFBAL_PROTECTIONS!O:O,"Mapeamento com LT fechado, mas parametrização pendente") -> 0 | J16: =I16/E16 -> 0 | K16: =COUNTIF(OFFBAL_PROTECTIONS!O:O,"Novo campo, mapeamento datalake fechado, com necessidade de criar parametrização") -> 0 | L16: =K16/E16 -> 0 | M16: =COUNTIF(OFFBAL_PROTECTIONS!O:O,"Novo campo, mapeamento datalake fechado, sem necessidade de criar parametrização") -> 0 | N16: =M16/E16 -> 0 | O16: =COUNTIF(OFFBAL_PROTECTIONS!O:O,"Novo campo, mapeamento datalake pendente, com necessidade de criar parametrização") -> 0 | P16: =O16/E16 -> 0 | Q16: =COUNTIF(OFFBAL_PROTECTIONS!O:O,"Novo campo, mapeamento datalake pendente, sem necessidade de criar parametrização") -> 0 | R16: =Q16/E16 -> 0 | S16: =COUNTIF(OFFBAL_PROTECTIONS!O:O,"Por iniciar") -> 0 | T16: =S16/E16 -> 0 | U16: =COUNTIF(OFFBAL_PROTECTIONS!P:P,"Concluído") -> 17 | V16: =U16/E16 -> 1 | W16: =COUNTIF(OFFBAL_PROTECTIONS!P:P,"Em desenvolvimento") -> 0 | X16: =W16/E16 -> 0 | Y16: =COUNTIF(OFFBAL_PROTECTIONS!P:P,"Aguarda desenvolvimento de outras equipas") -> 0 | Z16: =Y16/E16 -> 0 | AA16: =COUNTIF(OFFBAL_PROTECTIONS!P:P,"Por especificar") -> 0 | AB16: =AA16/E16 -> 0
C17: Instrument-Counterparty relation | D17: XXXXX_YYYYMMDD_03_04_off_instr_count.csv | E17: =COUNTA(OFFBAL_INSTRUMENT_COUNTERPARTY!A3:A8) -> 3 | F17: =SUM(H17,J17,L17,N17,P17,R17,T17) -> 1 | G17: =COUNTIF(OFFBAL_INSTRUMENT_COUNTERPARTY!O:O,"Concluído") -> 3 | H17: =G17/E17 -> 1 | I17: =COUNTIF(OFFBAL_INSTRUMENT_COUNTERPARTY!O:O,"Mapeamento com LT fechado, mas parametrização pendente") -> 0 | J17: =I17/E17 -> 0 | K17: =COUNTIF(OFFBAL_INSTRUMENT_COUNTERPARTY!O:O,"Novo campo, mapeamento datalake fechado, com necessidade de criar parametrização") -> 0 | L17: =K17/E17 -> 0 | M17: =COUNTIF(OFFBAL_INSTRUMENT_COUNTERPARTY!O:O,"Novo campo, mapeamento datalake fechado, sem necessidade de criar parametrização") -> 0 | N17: =M17/E17 -> 0 | O17: =COUNTIF(OFFBAL_INSTRUMENT_COUNTERPARTY!O:O,"Novo campo, mapeamento datalake pendente, com necessidade de criar parametrização") -> 0 | P17: =O17/E17 -> 0 | Q17: =COUNTIF(OFFBAL_INSTRUMENT_COUNTERPARTY!O:O,"Novo campo, mapeamento datalake pendente, sem necessidade de criar parametrização") -> 0 | R17: =Q17/E17 -> 0 | S17: =COUNTIF(OFFBAL_INSTRUMENT_COUNTERPARTY!O:O,"Por iniciar") -> 0 | T17: =S17/E17 -> 0 | U17: =COUNTIF(OFFBAL_INSTRUMENT_COUNTERPARTY!P:P,"Concluído") -> 3 | V17: =U17/E17 -> 1 | W17: =COUNTIF(OFFBAL_INSTRUMENT_COUNTERPARTY!P:P,"Em desenvolvimento") -> 0 | X17: =W17/E17 -> 0 | Y17: =COUNTIF(OFFBAL_INSTRUMENT_COUNTERPARTY!P:P,"Aguarda desenvolvimento de outras equipas") -> 0 | Z17: =Y17/E17 -> 0 | AA17: =COUNTIF(OFFBAL_INSTRUMENT_COUNTERPARTY!P:P,"Por especificar") -> 0 | AB17: =AA17/E17 -> 0
C18: Instrument-Protection relation | D18: XXXXX_YYYYMMDD_03_05_off_instr_prot.csv | E18: =COUNTA(OFFBAL_INSTRUMENT_PROTECTION!A3:A12) -> 4 | F18: =SUM(H18,J18,L18,N18,P18,R18,T18) -> 1 | G18: =COUNTIF(OFFBAL_INSTRUMENT_PROTECTION!O:O,"Concluído") -> 4 | H18: =G18/E18 -> 1 | I18: =COUNTIF(OFFBAL_INSTRUMENT_PROTECTION!O:O,"Mapeamento com LT fechado, mas parametrização pendente") -> 0 | J18: =I18/E18 -> 0 | K18: =COUNTIF(OFFBAL_INSTRUMENT_PROTECTION!O:O,"Novo campo, mapeamento datalake fechado, com necessidade de criar parametrização") -> 0 | L18: =K18/E18 -> 0 | M18: =COUNTIF(OFFBAL_INSTRUMENT_PROTECTION!O:O,"Novo campo, mapeamento datalake fechado, sem necessidade de criar parametrização") -> 0 | N18: =M18/E18 -> 0 | O18: =COUNTIF(OFFBAL_INSTRUMENT_PROTECTION!O:O,"Novo campo, mapeamento datalake pendente, com necessidade de criar parametrização") -> 0 | P18: =O18/E18 -> 0 | Q18: =COUNTIF(OFFBAL_INSTRUMENT_PROTECTION!O:O,"Novo campo, mapeamento datalake pendente, sem necessidade de criar parametrização") -> 0 | R18: =Q18/E18 -> 0 | S18: =COUNTIF(OFFBAL_INSTRUMENT_PROTECTION!O:O,"Por iniciar") -> 0 | T18: =S18/E18 -> 0 | U18: =COUNTIF(OFFBAL_INSTRUMENT_PROTECTION!P:P,"Concluído") -> 4 | V18: =U18/E18 -> 1 | W18: =COUNTIF(OFFBAL_INSTRUMENT_PROTECTION!P:P,"Em desenvolvimento") -> 0 | X18: =W18/E18 -> 0 | Y18: =COUNTIF(OFFBAL_INSTRUMENT_PROTECTION!P:P,"Aguarda desenvolvimento de outras equipas") -> 0 | Z18: =Y18/E18 -> 0 | AA18: =COUNTIF(OFFBAL_INSTRUMENT_PROTECTION!P:P,"Por especificar") -> 0 | AB18: =AA18/E18 -> 0
B19: Derivatives | C19: Instruments | D19: XXXXX_YYYYMMDD_04_01_derivatives.csv | E19: =COUNTA(DERIVATIVES!A3:A69) -> 29 | F19: =SUM(H19,J19,L19,N19,P19,R19,T19) -> 1 | G19: =COUNTIF(DERIVATIVES!O:O,"Concluído") -> 29 | H19: =G19/E19 -> 1 | I19: =COUNTIF(DERIVATIVES!O:O,"Mapeamento com LT fechado, mas parametrização pendente") -> 0 | J19: =I19/E19 -> 0 | K19: =COUNTIF(DERIVATIVES!O:O,"Novo campo, mapeamento datalake fechado, com necessidade de criar parametrização") -> 0 | L19: =K19/E19 -> 0 | M19: =COUNTIF(DERIVATIVES!O:O,"Novo campo, mapeamento datalake fechado, sem necessidade de criar parametrização") -> 0 | N19: =M19/E19 -> 0 | O19: =COUNTIF(DERIVATIVES!O:O,"Novo campo, mapeamento datalake pendente, com necessidade de criar parametrização") -> 0 | P19: =O19/E19 -> 0 | Q19: =COUNTIF(DERIVATIVES!O:O,"Novo campo, mapeamento datalake pendente, sem necessidade de criar parametrização") -> 0 | R19: =Q19/E19 -> 0 | S19: =COUNTIF(DERIVATIVES!O:O,"Por iniciar") -> 0 | T19: =S19/E19 -> 0 | U19: =COUNTIF(DERIVATIVES!P:P,"Concluído") -> 29 | V19: =U19/E19 -> 1 | W19: =COUNTIF(DERIVATIVES!P:P,"Em desenvolvimento") -> 0 | X19: =W19/E19 -> 0 | Y19: =COUNTIF(DERIVATIVES!P:P,"Aguarda desenvolvimento de outras equipas") -> 0 | Z19: =Y19/E19 -> 0 | AA19: =COUNTIF(DERIVATIVES!P:P,"Por especificar") -> 0 | AB19: =AA19/E19 -> 0
B20: Debt securities | C20: Instruments | D20: XXXXX_YYYYMMDD_05_01_debtsecurities.csv | E20: =COUNTA(DEBT_SECURITIES!A3:A77) -> 40 | F20: =SUM(H20,J20,L20,N20,P20,R20,T20) -> 1 | G20: =COUNTIF(DEBT_SECURITIES!O:O,"Concluído") -> 40 | H20: =G20/E20 -> 1 | I20: =COUNTIF(DEBT_SECURITIES!O:O,"Mapeamento com LT fechado, mas parametrização pendente") -> 0 | J20: =I20/E20 -> 0 | K20: =COUNTIF(DEBT_SECURITIES!O:O,"Novo campo, mapeamento datalake fechado, com necessidade de criar parametrização") -> 0 | L20: =K20/E20 -> 0 | M20: =COUNTIF(DEBT_SECURITIES!O:O,"Novo campo, mapeamento datalake fechado, sem necessidade de criar parametrização") -> 0 | N20: =M20/E20 -> 0 | O20: =COUNTIF(DEBT_SECURITIES!O:O,"Novo campo, mapeamento datalake pendente, com necessidade de criar parametrização") -> 0 | P20: =O20/E20 -> 0 | Q20: =COUNTIF(DEBT_SECURITIES!O:O,"Novo campo, mapeamento datalake pendente, sem necessidade de criar parametrização") -> 0 | R20: =Q20/E20 -> 0 | S20: =COUNTIF(DEBT_SECURITIES!O:O,"Por iniciar") -> 0 | T20: =S20/E20 -> 0 | U20: =COUNTIF(DEBT_SECURITIES!P:P,"Concluído") -> 40 | V20: =U20/E20 -> 1 | W20: =COUNTIF(DEBT_SECURITIES!P:P,"Em desenvolvimento") -> 0 | X20: =W20/E20 -> 0 | Y20: =COUNTIF(DEBT_SECURITIES!P:P,"Aguarda desenvolvimento de outras equipas") -> 0 | Z20: =Y20/E20 -> 0 | AA20: =COUNTIF(DEBT_SECURITIES!P:P,"Por especificar") -> 0 | AB20: =AA20/E20 -> 0
B21: Equity | C21: Instruments | D21: XXXXX_YYYYMMDD_06_01_equity.csv | E21: =COUNTA(EQUITY_INSTRUMENTS!A3:A35) -> 18 | F21: =SUM(H21,J21,L21,N21,P21,R21,T21) -> 1 | G21: =COUNTIF(EQUITY_INSTRUMENTS!O:O,"Concluído") -> 18 | H21: =G21/E21 -> 1 | I21: =COUNTIF(EQUITY_INSTRUMENTS!O:O,"Mapeamento com LT fechado, mas parametrização pendente") -> 0 | J21: =I21/E21 -> 0 | K21: =COUNTIF(EQUITY_INSTRUMENTS!O:O,"Novo campo, mapeamento datalake fechado, com necessidade de criar parametrização") -> 0 | L21: =K21/E21 -> 0 | M21: =COUNTIF(EQUITY_INSTRUMENTS!O:O,"Novo campo, mapeamento datalake fechado, sem necessidade de criar parametrização") -> 0 | N21: =M21/E21 -> 0 | O21: =COUNTIF(EQUITY_INSTRUMENTS!O:O,"Novo campo, mapeamento datalake pendente, com necessidade de criar parametrização") -> 0 | P21: =O21/E21 -> 0 | Q21: =COUNTIF(EQUITY_INSTRUMENTS!O:O,"Novo campo, mapeamento datalake pendente, sem necessidade de criar parametrização") -> 0 | R21: =Q21/E21 -> 0 | S21: =COUNTIF(EQUITY_INSTRUMENTS!O:O,"Por iniciar") -> 0 | T21: =S21/E21 -> 0 | U21: =COUNTIF(EQUITY_INSTRUMENTS!P:P,"Concluído") -> 18 | V21: =U21/E21 -> 1 | W21: =COUNTIF(EQUITY_INSTRUMENTS!P:P,"Em desenvolvimento") -> 0 | X21: =W21/E21 -> 0 | Y21: =COUNTIF(EQUITY_INSTRUMENTS!P:P,"Aguarda desenvolvimento de outras equipas") -> 0 | Z21: =Y21/E21 -> 0 | AA21: =COUNTIF(EQUITY_INSTRUMENTS!P:P,"Por especificar") -> 0 | AB21: =AA21/E21 -> 0
B22: DTAs/DTCs | C22: - | D22: XXXXX_YYYYMMDD_07_01_dtasdtcs.csv | E22: =COUNTA(DTA_DTC!A3:A19) -> 17 | F22: =SUM(H22,J22,L22,N22,P22,R22,T22) -> 1 | G22: =COUNTIF(DTA_DTC!M:M,"Concluído") -> 17 | H22: =G22/E22 -> 1 | I22: =COUNTIF(DTA_DTC!M:M,"Mapeamento com LT fechado, mas parametrização pendente") -> 0 | J22: =I22/E22 -> 0 | K22: =COUNTIF(DTA_DTC!M:M,"Novo campo, mapeamento datalake fechado, com necessidade de criar parametrização") -> 0 | L22: =K22/E22 -> 0 | M22: =COUNTIF(DTA_DTC!M:M,"Novo campo, mapeamento datalake fechado, sem necessidade de criar parametrização") -> 0 | N22: =M22/E22 -> 0 | O22: =COUNTIF(DTA_DTC!M:M,"Novo campo, mapeamento datalake pendente, com necessidade de criar parametrização") -> 0 | P22: =O22/E22 -> 0 | Q22: =COUNTIF(DTA_DTC!M:M,"Novo campo, mapeamento datalake pendente, sem necessidade de criar parametrização") -> 0 | R22: =Q22/E22 -> 0 | S22: =COUNTIF(DTA_DTC!M:M,"Por iniciar") -> 0 | T22: =S22/E22 -> 0 | U22: =COUNTIF(DTA_DTC!N:N,"Concluído") -> 17 | V22: =U22/E22 -> 1 | W22: =COUNTIF(DTA_DTC!N:N,"Mapeamento com LT fechado, mas parametrização pendente") -> 0 | X22: =W22/E22 -> 0 | Y22: =COUNTIF(DTA_DTC!N:N,"Novo campo, mapeamento datalake fechado, com necessidade de criar parametrização") -> 0 | Z22: =Y22/E22 -> 0 | AA22: =COUNTIF(DTA_DTC!N:N,"Novo campo, mapeamento datalake fechado, sem necessidade de criar parametrização") -> 0 | AB22: =AA22/E22 -> 0 | AC22: Produzido manualmente pela Contabilidade
B23: Intangible assets | C23: - | D23: XXXXX_YYYYMMDD_08_01_intangible.csv | E23: =COUNTA(INTANGIBLE_ASSETS!A3:A15) -> 13 | F23: =SUM(H23,J23,L23,N23,P23,R23,T23) -> 1 | G23: =COUNTIF(INTANGIBLE_ASSETS!M:M,"Concluído") -> 13 | H23: =G23/E23 -> 1 | I23: =COUNTIF(INTANGIBLE_ASSETS!M:M,"Mapeamento com LT fechado, mas parametrização pendente") -> 0 | J23: =I23/E23 -> 0 | K23: =COUNTIF(INTANGIBLE_ASSETS!M:M,"Novo campo, mapeamento datalake fechado, com necessidade de criar parametrização") -> 0 | L23: =K23/E23 -> 0 | M23: =COUNTIF(INTANGIBLE_ASSETS!M:M,"Novo campo, mapeamento datalake fechado, sem necessidade de criar parametrização") -> 0 | N23: =M23/E23 -> 0 | O23: =COUNTIF(INTANGIBLE_ASSETS!M:M,"Novo campo, mapeamento datalake pendente, com necessidade de criar parametrização") -> 0 | P23: =O23/E23 -> 0 | Q23: =COUNTIF(INTANGIBLE_ASSETS!M:M,"Novo campo, mapeamento datalake pendente, sem necessidade de criar parametrização") -> 0 | R23: =Q23/E23 -> 0 | S23: =COUNTIF(INTANGIBLE_ASSETS!M:M,"Por iniciar") -> 0 | T23: =S23/E23 -> 0 | U23: =COUNTIF(INTANGIBLE_ASSETS!N:N,"Concluído") -> 13 | V23: =U23/E23 -> 1 | W23: =COUNTIF(INTANGIBLE_ASSETS!N:N,"Mapeamento com LT fechado, mas parametrização pendente") -> 0 | X23: =W23/E23 -> 0 | Y23: =COUNTIF(INTANGIBLE_ASSETS!N:N,"Novo campo, mapeamento datalake fechado, com necessidade de criar parametrização") -> 0 | Z23: =Y23/E23 -> 0 | AA23: =COUNTIF(INTANGIBLE_ASSETS!N:N,"Novo campo, mapeamento datalake fechado, sem necessidade de criar parametrização") -> 0 | AB23: =AA23/E23 -> 0 | AC23: Produzido manualmente pela Contabilidade
C24: Total | E24: =SUM(E4:E23) -> 308 | F24: =SUM(H24,J24,L24,N24,P24,R24,T24) -> 1 | G24: =SUM(G4:G23) -> 308 | H24: =G24/E24 -> 1 | I24: =SUM(I4:I23) -> 0 | J24: =I24/E24 -> 0 | K24: =SUM(K4:K23) -> 0 | L24: =K24/E24 -> 0 | M24: =SUM(M4:M23) -> 0 | N24: =M24/E24 -> 0 | O24: =SUM(O4:O23) -> 0 | P24: =O24/E24 -> 0 | Q24: =SUM(Q4:Q23) -> 0 | R24: =Q24/E24 -> 0 | S24: =SUM(S4:S23) -> 0 | T24: =S24/E24 -> 0 | U24: =SUM(U4:U23) -> 308 | V24: =U24/SUM(E4:E23) -> 1 | W24: =SUM(W4:W23) -> 0 | X24: =W24/SUM(E4:E23) -> 0 | Y24: =SUM(Y4:Y23) -> 0 | Z24: =Y24/SUM(E4:E23) -> 0 | AA24: =SUM(AA4:AA23) -> 0 | AB24: =AA24/SUM(E4:E23) -> 0

Sheet PDS - Desenvolvimento
B2: Table | C2: Table | D2: Exclusivo Report Valuation | E2: Exposures to legal persons | F2: Exposures to natural persons | G2: Off-balance sheet exposures | H2: Derivatives | I2: Debt securities | J2: Equity | K2: Estado Dev
B3: INSTRUMENT | C3: INSTRMNT_ID | E3: x | F3: x | G3: x | I3: x | J3: x | K3: Concluído
B4: INSTRUMENT | C4: CNTRCT_ID | F4: x | G4: x | K4: Concluído
B5: INSTRUMENT | C5: CRRNCY_DNMNTN | F5: x | I5: x | K5: Concluído
B6: INSTRUMENT | C6: DT_INCPTN | F6: x | I6: x | K6: Concluído
B7: INSTRUMENT | C7: OBSRVD_AGNT_ID | F7: x | G7: x | K7: Concluído
B8: INSTRUMENT | C8: OTSTNDNG_NMNL_AMNT_INSTRMNT | E8: carteira | F8: x | K8: Concluído
B9: INSTRUMENT | C9: PRDCT | H9: x | K9: Concluído
B10: INSTRUMENT | C10: DFLT_STTS_INSTRMNT | F10: x | G10: x | K10: Concluído
B11: INSTRUMENT | C11: CPN_CRRNCY | I11: x | K11: Concluído
B12: INSTRUMENT | C12: DT_DFLT_STTS_INSTRMNT | F12: x | G12: x | K12: Concluído
B13: INSTRUMENT | C13: DT_END_INTRST_ONLY | F13: x | K13: Concluído
B14: INSTRUMENT | C14: DT_FRBRNC_STTS | F14: x | G14: x | K14: Concluído
B15: INSTRUMENT | C15: DT_PRFRMNG_STTS | F15: x | G15: x | K15: Concluído
B16: INSTRUMENT | C16: FRBRNC_STTS_INSTRMNT | F16: x | G16: x | K16: Concluído
B17: INSTRUMENT | C17: IMPRMNT_STTS | F17: x | G17: x | K17: Concluído
B18: INSTRUMENT | C18: INTRNL_RTNG | K18: Concluído
B19: INSTRUMENT | C19: INTRNL_SGMNT | E19: x | F19: x | G19: x | K19: Concluído
B20: INSTRUMENT | C20: PRFRMNG_STTS | F20: x | G20: x | I20: x | K20: Concluído
B21: INSTRUMENT | C21: TYP_AMRTSTN | F21: x | K21: Concluído
B22: INSTRUMENT | C22: TYP_INSTRMNT | F22: x | K22: Concluído
B23: INSTRUMENT | C23: TYP_INTRST_RT | F23: x | I23: x | K23: Concluído
B24: INSTRUMENT | C24: GRSS_CRRYNG_AMNT_INSTRMNT | H24: x | K24: Concluído
B25: INSTRUMENT | C25: ACCMLTD_CHNGS_FV_CR_INSTRMNT | F25: x | K25: Concluído
B26: INSTRUMENT | C26: ACCNTNG_CLSSFCTN | F26: x | H26: x | I26: x | J26: x | K26: Concluído
B27: INSTRUMENT | C27: ACCRD_INTRST_INSTRMNT | F27: x | K27: Concluído
B28: INSTRUMENT | C28: CCF | G28: x | K28: Concluído
B29: INSTRUMENT | C29: CMMTMNT_INCPTN_INSTRMNT | F29: x | K29: Concluído
B30: INSTRUMENT | C30: CRRYNG_AMNT_INSTRMNT | F30: x | K30: Concluído
B31: INSTRUMENT | C31: DT_LGL_FNL_MTRTY | F31: x | G31: x | I31: x | K31: Concluído
B32: INSTRUMENT | C32: DT_NXT_INTRST_RT_RST | F32: x | K32: Concluído
B33: INSTRUMENT | C33: OFF_BLNC_SHT_AMNT_INSTRMNT | F33: x | G33: x | K33: Concluído
B34: INSTRUMENT | C34: PRVSNS_OFF_BLNC_SHT | F34: x | K34: Concluído
B35: INSTRUMENT | C35: PYMNT_FRQNCY | F35: x | I35: x | K35: Concluído
B36: INSTRUMENT | C36: RWA | E36: x | F36: x | G36: x | H36: x | I36: x | J36: x | K36: Concluído
B37: INSTRUMENT | C37: ACCMLTD_IMPRMNT_INSTRMNT | F37: x | G37: x | K37: Concluído
B38: INSTRUMENT | C38: ACCMLTD_WRTFFS_INSTRMNT | F38: x | K38: Concluído
B39: INSTRUMENT | C39: ARRRS_INSTRMNT | F39: x | G39: x | K39: Concluído
B40: INSTRUMENT | C40: CMLTV_RCVRS_SNC_DFLT_INSTRMNT | F40: x | K40: Concluído
B41: INSTRUMENT | C41: DT_PST_D | F41: x | G41: x | K41: Concluído
...

Sheet Filtros dos Segmentos
A1: • Exposures to legal persons: tipo_conta='A' e instrumento_financeiro='credito concedido e outros ativos financeiros' e contraparte <> ‘particulares’ e contraparte_i <> ‘particulares’ e carteira_contabilistica <> 'ativos nao correntes detidos para venda' • Exposures to natural persons: tipo_conta='A' e instrumento_financeiro='credito concedido e outros ativos financeiros' e contraparte = ‘particulares’ e contraparte_i = ‘particulares’ e carteira_contabilistica <> 'ativos nao correntes detidos para venda' • Off-balance sheet exposures: tipo_conta='EA' • Derivatives: instrumento_financeiro='derivados’ e tipo_conta in ('A', 'P') • Debt securities: tipo_conta='A' e instrumento_financeiro='instrumentos de divida' • Equity: tipo_conta='A' e instrumento_financeiro='instrumentos de capital' e carteira_contabilistica <> 'ativos nao correntes detidos para venda' Nota: Após a definição inicial com Pedro Mendes e Contabilidade, no processo de validações foi identificado que teriam de ser aplicados mais filtros do que os previstos inicialmente (email Francisco de Mesquita Gouveia 15/01/2025 19:06). Os filtros apresentados acima já refletem essas alterações

Sheet LEGAL PERSONS DATA SETS
A1: SRB DATA SET FOR EXPOSURES TO LEGAL PERSONS The AnaCredit database provides very detailed and individual information concerning exposures to legal persons. The SRB Valuation Data Set complements the AnaCredit database and provides data fields on segments, which allows mapping individual exposures with prudential reporting segments (FINREP and COREP), and credit risk data parameters aimed at supporting valuers. The SRB Valuation Data Set also provides data fields on risk parameters provided by banks’ internal risk models, which valuers are able to rely on in order to perform valuations on an aggregated basis, where necessary. Serão produzidos cinco ficheiros de report referentes a Legal Persons: ‣ SRB Instruments Data Set for exposures to legal persons (LEGALP_INSTRUMENTS); ‣ SRB Counterparties Data Set for exposures to legal persons (LEGALP_COUNTERPARTIES); ‣ SRB Protection received Data Set for exposures to legal persons (LEGALP_PROTECTIONS); ‣ SRB Instrument/Counterparty mapping Data Set for exposures to legal persons (LEGALP_INSTRUMENT_COUNTERPARTY); ‣ SRB Instrument/Protection mapping Data Set for exposures to legal persons (LEGALP_INSTRUMENT_PROTECTION);
A2: SRB DATA SET FOR EXPOSURES TO LEGAL PERSONS A base de dados AnaCredit disponibiliza informação muito detalhada e individualizada sobre exposições a pessoas coletivas. O dataset de avaliação do SRB complementa a base de dados AnaCredit e fornece campos de dados por segmentos, o que permite mapear exposições individuais com segmentos de reporte prudencial (FINREP e COREP) e parâmetros de dados de risco de crédito destinados a apoiar os avaliadores. O dataset de avaliação do CUR também fornece campos de dados sobre parâmetros de risco fornecidos pelos modelos de risco internos dos bancos, nos quais os avaliadores podem confiar para realizar avaliações numa base agregada, sempre que necessário. Serão produzidos três ficheiros de report referentes a Legal Persons: ‣ SRB Instruments Data Set for exposures to legal persons (VDS_OUT_LEGALP_INSTRUMENTS); ‣ SRB Counterparties Data Set for exposures to legal persons (VDS_OUT_LEGALP_COUNTERPARTIES); ‣ SRB Protection received Data Set for exposures to legal persons (VDS_OUT_LEGALP_PROTECTIONS).

Sheet LEGALP_INSTRUMENTS
A1: Instruções SRB | H1: Mapeamento efetuado pela Corporação e respetiva Descrição Loan Tape (LT) | L1: Análise IT | T1: Implementação Deloitte (OLD)
A2: ID | B2: Categoria | C2: Coluna | D2: Tipo de dados | E2: Descrição | F2: Descrição - Português | H2: Mapeamentos Corporação (LT) | I2: Descrição (LT) | J2: Additional Guidance (LT) | L2: Novo campo na tabela LT002? | M2: Nome do campo no ficheiro | N2: Mapeamento LT / Comentários IT | O2: Estado especificação | P2: Estado desenvolvimento | Q2: Data da última alteração do Estado desenvolvimento | R2: Tipo de Tarefa para a estimativa | T2: Fontes de Informação | U2: Filtros | V2: Campo | W2: Regras de Preenchimento | X2: Agrupações | Z2: Comentários reuniões
A3: V_1 | B3: Identification information | C3: Instrument Identifier | D3: Alphanumeric | E3: An identifier applied to uniquely identify each instrument. Each instrument must have one instrument identifier | F3: Um identificador aplicado para identificar exclusivamente cada instrumento. Cada instrumento deve ter um identificador de instrumento. | H3: INSTRUMENT-INSTRMNT_ID | I3: Instrument ID | J3: An identifier applied by the reporting agent to uniquely identify each instrument under a single contract. Each instrument must have one instrument identifier. This value will not change over time and cannot be used as the instrument identifier for any other instrument under the same contract. Supervised Insitutions are asked to furnish the INSTRMNT_ID with the exact same value as it is reported to AnaCredit (or any similar central credit register). If this is not available, the value shall be reported as it is internally used. If an instrument is not reported to AnaCredit but requested for the purposes of the on-site inspection please provide the bank-internally used value. | L3: NÃO | M3: instrument_id | N3: LT002_INSTRUMENT.INSTRMNT_ID | O3: Concluído | P3: ='PDS - Desenvolvimento'!$K$3 -> Concluído | Q3: 45608 | R3: Concluído | T3: cd_alm.al029_cnt_core_m | U3: ‣ ref_date = data do report | V3: cempresa | W3: ‣ Concatenação dos campos mencionados anteriormente: cempresa + cbalcao + cnumecta + zdeposit | Z3: Após reunião com LCM foi indicado que este campo deveria ser na mesma o cempresa … zeposit mas da tabela fr001/fr004 em vez da al029 isto porque tendo que conciliar com o finrep, faz sentido que tenha a mesma granularidade
V4: cbalcao
V5: cnumecta
V6: zdeposit
A7: V_2 | B7: Identification information | C7: Counterparty Identifier | D7: Alphanumeric | E7: Identifier applied to uniquely identify each counterparty. | F7: Identificador aplicado para identificar exclusivamente cada contraparte | H7: Not applicable: To be reported as "N/A". This information will be availabe in "01_04_leg_instr_count" table | I7: - | J7: - | L7: SIM | M7: counterparty_id | N7: Mapeamento LT: Not Applicable: Reportar 'N/A' Comentários IT: Este campo constará no ficheiro "01_04_leg_instr_count" | O7: Concluído | P7: ='PDS - Desenvolvimento'!$K$77 -> Concluído | Q7: 45608 | R7: Alterações ao Motor LT - Novos Campos: Definição Fechada / Dados existem no Datalake | T7: cd_alm.al029_cnt_core_m | U7: ‣ ref_date = data do report | V7: zcliente | W7: ‣ Direto | Z7: Se se alterar o universo trazer o zcliente respetivo
A8: V_3 | B8: Exposure class | C8: CRR Exposure class | D8: String | E8: The exposures classes for the calculation of risk-weighted assets (RWAs) for credit risks are as follows (not applicable when exposures are classified in the CRR trading book as defined in Article 4(1)(86) of Regulation (EU) No 575/2013): Where a bank uses the standardised approach: ‣ Central governments or central banks (SCENGOV) ‣ Regional governments or local authorities (SREGGOV) ‣ Public sector entities (SPUBSEC) ‣ Multilateral development banks (SDEVBAN) ‣ International organisation (SINTORG) ‣ Institutions (SINSTIT) ‣ Corporates (SCORPOR) ‣ Retail (SRETAIL) ‣ Secured by mortgages and immovable property (SSECMOR) ‣ Defaulted (SDEFAUL) ‣ High risk (SHIGHRI) ‣ Covered bonds (SCOVBON) ‣ Items representing securitisation positions ‣ Institutions and corporates with a short term credit assessment (SSHOTER) ‣ Collective investment undertakings (SCOLINV) ‣ Equity (SEQUITY) ‣ Other (SOTHERI) Where a bank uses the IRB approach: ‣ Central governments and central banks (ICENGOV) ‣ Institutions (IINSTIT) ‣ Corporates (ICORPOR) ‣ Retail (IRETAIL) ‣ Equity (IEQUITY) ‣ Items representing securitisation positions ‣ Other non-credit-obligation assets (IOTHERC) | F8: As classes de posições em risco para o cálculo dos ativos ponderados pelo risco (RWA) para riscos de crédito são as seguintes (não aplicável quando as posições em risco são classificadas na carteira de negociação do CRR, conforme definido no artigo 4(1)(86), do Regulamento (UE) No 575 /2013). Informação deriva de uma lista baseada na classificação da facilidade utilizando a classe de risco, conforme descrito no artigo 112 do Regulamento (UE) No 575/2013 para bancos que utilizam a abordagem padrão) e no artigo 147 do Regulamento (UE) No 575/2013 (para bancos que utilizam abordagem baseada em classificações internas (IRB)) Quando um banco utiliza a abordagem padrão: ‣ Central governments or central banks (SCENGOV) ‣ Regional governments or local authorities (SREGGOV) ‣ Public sector entities (SPUBSEC) ‣ Multilateral development banks (SDEVBAN) ‣ International organisation (SINTORG) ‣ Institutions (SINSTIT) ‣ Corporates (SCORPOR) ‣ Retail (SRETAIL) ‣ Secured by mortgages and immovable property (SSECMOR) ‣ Defaulted (SDEFAUL) ‣ High risk (SHIGHRI) ‣ Covered bonds (SCOVBON) ‣ Items representing securitisation positions ‣ Institutions and corporates with a short term credit assessment (SSHOTER) ‣ Collective investment undertakings (SCOLINV) ‣ Equity (SEQUITY) ‣ Other (SOTHERI) Quando um banco utiliza a abordagem IRB: ‣ Central governments and central banks (ICENGOV) ‣ Institutions (IINSTIT) ‣ Corporates (ICORPOR) ‣ Retail (IRETAIL) ‣ Equity (IEQUITY) ‣ Items representing securitisation positions ‣ Other non-credit-obligation assets (IOTHERC) | H8: - | I8: - | J8: - | L8: SIM | M8: crr_exposure_class | N8: Mapeamento LT: ‣ Utilizar o campo "segmento_corep_final" da tabela ct013_rwa_princ; Nota: Os códigos "segmento_corep_final" seguem sempre a mesma estrutura, começam com um caracter que identifica se é IRB (I_...) ou Standard (S_...) e de seguida um numérico (ex. I_3.1, I_5.1, S_1.0). ‣ Para o mesmo contrato este campo pode retornar vários códigos "segmento_corep_final" distintos, de seguida estão os passos que permitem resolver esta ambiguidade: 1. Deve seguir a lógica do campo RWA_MTHD, de momento a lógica é, se existir IRB e Standard então trazer informação relativa a IRB; 2. Se mesmo aplicando o passo 1 ainda existirem vários códigos "segmento_corep_final" distintos (vários códigos IRB ou vários códigos Standard) então: recuperar o código "segmento_corep_final" com o menor numérico associado. Exemplo: O contrato A tem associados os seguintes códigos "segmento_corep_final" distintos: I_3.1, I_5.1, S_1.0: 1. Remover o Standard: I_3.1, I_5.1; 2. Ficar com o menor numérico: I_3.1. ‣ Necessário criar nova parametrização na tabela lt831_param_conceitos, podendo a mesma ser consultada neste documento na sheet 'LT831' filtrando por tabela_conceito = 'LT002_INSTRUMENT' e campo_conceito = 'CRR_EXPOSURE_CLASS' ‣ Reportar ‘N/A’ se campo flag_cons_cap=0 da tabela cd_captools.ct013_rwa_princ Comentários IT: '‣ Proposta: Consumir o campo "segmento_corep_final" da tabela ct013_rwa_princ, tendo em atenção que se tem de manter a lógica aplicada no campo LT "RWA_MTHD" (se for IRB ou Standard), para resolver os casos em que para o mesmo contrato temos mais do que segmento corep (IRB e Standard). Nota existem contratos que têm mais do que um segmento corep IRB ou Standard ou seja tem de haver uma lógica de selecionar o mais significativo pois só podemos reportar um valor neste campo). ‣ No Loan Tape para cálculo do LGD que vem da ct013_rwa_princ, quando existe IRB e STD, escolhe-se IRB. ‣ Segundo Email de Pedro Mendes com a resposta da Corporação (26/03/2024 17:28), no caso de existir mais do que 1 CRR Exposure class para o mesmo contrato, é permitido reportar o mais significativo dos dois por valor ou os dois separados por “,” colocando o mais significativo primeiro. ‣ Analisar documento 'BS_Tabelas_Temporárias_Loan_Tape.xlsx' para consultar as regras de seleção aplicadas no campo RWA_MTHD. ‣ Reunião Pedro Mendes, Luís Capitão-Mor 05-11-2024: Foi definida a regra para este campo, como dito anteriormente: - Deve seguir a lógica do campo RWA_MTHD, de momento a lógica é, se existir IRB e Standard então trazer informação relativa a IRB; - Para os casos em que temos mais do que um "segmento_corep_final" IRB ou Standard, foram propostas duas soluções, uma seria utilizar o campo "EAD_FINAL_BRUTA" também da tabela ct013_rwa_pric como fator de peso, recuperando o "segmento_corep_final" associado ao maior "EAD_FINAL_BRUTA" (mais significativo). A segunda solução, mais simples, seria simplesmente recuperar o código "segmento_corep_final" com a numeração mais baixa, por exemplo se um contrato tiver os códigos "segmento_corep_final" I_3.1, I_5.1 ficamos apenas com o I_3.1. Optou-se pela segunda solução. ‣ Query que demonstra que para um contrato FINREP pode haver mais do que um 'segmento_corep_final' tanto para a approach 'IRB' como para a 'Standard': SELECT contract_id_fr, --ct013.s1emp,ct013.contra1, GROUP_CONCAT(DISTINCT ct013.segmento_corep_final) as segmento_corep_final_conc, --GROUP_CONCAT(ct013.segmento_corep_final) as segmento_corep_final_conc, --GROUP_CONCAT(CAST(ct013.ead_final_bruta AS STRING)) as ead_final_bruta_conc, COUNT(*) as cnt, COUNT(DISTINCT ct013.segmento_corep_final) as cnt_dist FROM ( SELECT fr004.contract_id_fr, s1emp, contra1 FROM ( SELECT DISTINCT CONCAT(cempresa,cbalcao,cnumecta,zdeposit) as contract_id_fr FROM cd_captools.fr004_cto WHERE ref_date = '2024-08-31' ) as fr004 --6211142 LEFT JOIN ( SELECT CONCAT(cempresa_fr,cbalcao_fr,cnumecta_fr,zdeposit_fr) as contract_id_fr, CONCAT(cempresa,cbalcao,cnumecta,zdeposit) as contract_id_ct FROM cd_captools.kt_chaves_finrep WHERE ref_date = '2024-08-31' ) as chaves_finrep ON chaves_finrep.contract_id_fr = fr004.contract_id_fr --6211142 LEFT JOIN ( SELECT s1emp, contra1, CONCAT(cempresa,cbalcao,cnumecta,zdeposit) as contract_id_ct FROM cd_captools.kt_chaves_bdr WHERE ref_date = '2024-08-31' ) as chaves_bdr ON chaves_bdr.contract_id_ct = chaves_finrep.contract_id_ct --2046835 WHERE chaves_bdr.contract_id_ct IS NOT NULL GROUP BY contract_id_fr, s1emp, contra1 ) as core --2046835 DIST fr --2047298 nº total LEFT JOIN ( SELECT s1emp, contra1, segmento_corep_final, ead_final_bruta FROM cd_captools.ct013_rwa_princ WHERE ref_date = '2024-08-31' ) as ct013 ON core.s1emp = ct013.s1emp AND core.contra1 = ct013.contra1 WHERE ct013.s1emp IS NOT NULL GROUP BY contract_id_fr --GROUP BY ct013.s1emp, ct013.contra1 ORDER BY cnt_dist DESC | O8: Concluído | P8: ='PDS - Desenvolvimento'!$K$81 -> Concluído | Q8: 45674 | R8: Alterações ao Motor LT - Novos Campos: Definição Incompleta / Dados existem no Datalake | T8: Tabela de parametrização: codemapping | U8: ‣ dd_field_id = "3" | V8: dd_code | W8: ‣ Tradução do campo "segmento_corep_final" através de uma ligação com o campo "dd_code" para obter o campo: dd_value
V9: dd_value
T10: cd_captools.ct013_rwa_princ | U10: ‣ ref_date = data do report ‣ flag_cons_cap = 1 ‣ exercicio = 'REAL' | V10: segmento_corep_final
A11: V_4 | B11: Exposure class | C11: FINREP Exposure class | D11: String | E11: Classification of the facility (exposure class) as defined in ITS 680/2014 Annex V Instructions FINREP (Counterparty breakdown). Options: ‣ Central banks ‣ Central governments ‣ Credit institutions ‣ Other financial corporations ‣ Non-financial corporations ‣ Households | F11: Classificação da instalação (exposure class) conforme definido na ITS 680/2014 Anexo V Instruções FINREP (Counterparty breakdown). Opções: ‣ Central banks ‣ Central governments ‣ Credit institutions ‣ Other financial corporations ‣ Non-financial corporations ‣ Households | H11: - | I11: - | J11: - | L11: NÃO | M11: finrep_exposure_class | N11: LT002_INSTRUMENT.INTRNL_SGMNT ‣ Necessário criar novas parametrizaçôes nas tabelas lt829_regras_conversao e lt830_conversoes, podendo as mesmas ser consultadas neste documento nas sheets: ‣ LT829 - filtrando por campo_conceito = 'INTRNL_SGMNT' e regra_conversao = '1'; ‣ LT830 - filtrando por segmento = 'Exposures to legal persons' e campo_conceito = 'INTRNL_SGMNT'. | O11: Concluído | P11: ='PDS - Desenvolvimento'!$K$19 -> Concluído | Q11: 45665 | R11: Concluído | T11: Tabela de parametrização: codemapping | U11: ‣ dd_field_id = "4" | V11: dd_code | W11: ‣ Inicialmente para cada combinação dos campos "cempresa", "cbalcao", "cnumecta", "zdeposit" iremos recuperar o MAX(contraparte_i): ‣ Este campo MAX(contraparte_i) será traduzido através de uma ligação com o campo "dd_code" para obter o campo: dd_value | Z11: Pragosa diz que o LCM já indicou reapontar a ct081_finrep para a fr004
V12: dd_value
T13: cd_captools.ct081_finrep | U13: ‣ ref_date = data do report | V13: cempresa
V14: cbalcao
V15: cnumecta
V16: zdeposit
V17: contraparte_i
A18: V_5 | B18: Risk parameters | C18: Total Risk Exposure Amount | D18: Numeric (euro) | E18: The total risk exposure amount of the instrument, calculated according to Articles 92(3) and 92(4) of Regulation (EU) No 575/2013 (CRR), where applicable. | F18: O montante total das posições em risco do instrumento, calculado de acordo com o artigo 92(3) e 92(4) do Regulamento (UE) No 575/2013 (CRR), quando aplicável. | H18: INSTRUMENT-RWA | I18: RWA | J18: RWA according to Regulation (EU) No 575/2013. | L18: NÃO | M18: total_risk_exposure_amount | N18: LT002_INSTRUMENT.RWA | O18: Concluído | P18: ='PDS - Desenvolvimento'!$K$36 -> Concluído | Q18: 45608 | R18: Concluído | T18: cd_captools.ct013_rwa_princ | U18: ‣ ref_date = data do report ‣ flag_cons_cap = 1 ‣ exercicio = 'REAL' | V18: s1emp | W18: ‣ Para cada Instrument Identifier é somada a: ‣ Média do campo "rwa_final" para cada par de campos "s1emp", "contra1" | X18: A agrupação é feita segundo o campo "Instrument Identifier" deste mesmo documento | Z18: Dependendo do instrument id indicado, este campo deverá ser a soma do rwa_final
V19: contra1
V20: rwa_final
A21: V_6 | B21: Risk parameters | C21: CRR Loss given default | D21: Numeric. Basis points | E21: Current level of the ‘Loss given default’ of the loan, determined in accordance with Articles 161, 164, 179 and 181 of Regulation (EU) No 575/2013. | F21: Nível atual da "Loss given default" do empréstimo, determinado em conformidade com os artigos 161, 164, 179 e 181 do Regulamento (UE) No 575/2013. | H21: INSTRUMENT-LGD | I21: Regulatory LGD | J21: If differences between regulatory and internal LGD exist, use regulatory LGD (according to Regulation (EU) No 575/2013). In particular, in IRB-F use regulatory LGD values. | L21: NÃO | M21: crr_loss_given_default | N21: LT002_INSTRUMENT.LGD | O21: Concluído | P21: ='PDS - Desenvolvimento'!$K$44 -> Concluído | Q21: 45608 | R21: Concluído | T21: cd_captools.ct013_rwa_princ | U21: ‣ ref_date = data do report ‣ flag_cons_cap = 1 ‣ exercicio = 'REAL' | V21: s1emp | W21: ‣ Para cada Instrument Identifier é calculada a: ‣ Média ponderada do campo "lgdfinal" em relação à: ‣ Média do campo "ead_final_bruta" para cada par dos campos "s1emp", "contra1" | X21: A agrupação é feita segundo o campo "Instrument Identifier" deste mesmo documento | Z21: Dependendo do instrument id indicado, este campo deverá ser a média ponderada de lgd_final por ead_final_bruta
V22: contra1
V23: ead_final_bruta
T24: cd_captools.ct014_rwa_irb | U24: ‣ ref_date = data do report | V24: lgdfinal
A25: V_7 | B25: Risk parameters | C25: IFRS 9 Loss given default | D25: Numeric. Basis points | E25: Current level of the ‘Loss given default’ of the loan determined for accounting purposes. | F25: Nível atual da "Loss given default" do empréstimo determinado para efeitos contabilísticos. | H25: INSTRUMENT-IFRS9_LGD | I25: IFRS 9 accounting LGD | J25: IFRS 9 accounting Loss Given Default as at reference date for defaulted and non-defaulted exposures. In case the bank models time-depended LGD variable for non-defaulted exposures then 12-month LGD as at reference date regardless the classification as Stage 1 or 2 | L25: NÃO | M25: ifrs9_loss_given_default | N25: LT002_INSTRUMENT.IFRS9_LGD | O25: Concluído | P25: ='PDS - Desenvolvimento'!$K$43 -> Concluído | Q25: 45608 | R25: Concluído | T25: cd_captools.ifrs9_out_expected_loss_8_7 | U25: ‣ Apenas são trazidos os "contract_id"s que têm "exec_id_part" correspondente na tabela cd_captools.imcatf046_flag_fecho à data ("cmes") do report | V25: contract_id | W25: ‣ Para cada Instrument Identifier é calculada a: ‣ Média ponderada do campo "lgd_ifrs9" em relação à: ‣ Média do campo "ead" para cada "contract_id" | X25: A agrupação é feita segundo o campo "Instrument Identifier" deste mesmo documento | Z25: Tal como nos anteriores explorar porque é feita a média do ead
V26: lgd_ifrs9
V27: ead

Sheet LEGALP_COUNTERPARTIES
A1: Instruções SRB | H1: Mapeamento efetuado pela Corporação e respetiva Descrição Loan Tape (LT) | L1: Análise IT | T1: Implementação Deloitte (OLD)
A2: ID | B2: Categoria | C2: Coluna | D2: Tipo de dados | E2: Descrição | F2: Descrição - Português | H2: Mapeamentos Corporação (LT) | I2: Descrição (LT) | J2: Additional Guidance (LT) | L2: Novo campo na tabela LT003? | M2: Nome do campo no ficheiro | N2: Mapeamento LT / Comentários IT | O2: Estado especificação | P2: Estado desenvolvimento | Q2: Data da última alteração do Estado desenvolvimento | R2: Tipo de Tarefa para a estimativa | T2: Fontes de Informação | U2: Filtros | V2: Campo | W2: Regras de Preenchimento | X2: Agrupações | Y2: Comentários reuniões
A3: V_2 | B3: Identification information | C3: Counterparty Identifier | D3: Alphanumeric | E3: Identifier applied to uniquely identify each counterparty. | F3: Identificador aplicado para identificar exclusivamente cada contraparte. | H3: ENTITY-ENTTY_ID | I3: Entity ID | J3: An identifier applied by the reporting agent to uniquely identify each counterparty. Each counterparty has a unique and exclusive counterparty identifier. This means that this value will not change over time and can never be used as the counterparty identifier for any other counterparty. | L3: NÃO | M3: counterparty_id | N3: LT003_ENTITY.ENTTY_ID | O3: Concluído | P3: ='PDS - Desenvolvimento'!$K$113 -> Concluído | Q3: 45608 | R3: Concluído | T3: cd_alm.al029_cnt_core_m | U3: ‣ ref_date = data do report | V3: zcliente | W3: ‣ Direto | Y3: Se se alterar o universo trazer o zcliente respetivo
A4: V_8 | B4: Risk parameters | C4: Current Internal Credit Rating/Scoring | D4: Numeric / alphanumeric | E4: Internal credit rating/scoring issued to the counterparty. | F4: Classificação/pontuação de crédito interna emitida para a contraparte. | H4: ENTITY-INTRNL_RTNG | I4: Internal rating at reference date | J4: Internal rating at the reference date according to Regulation (EU) No 575/2013. Please also add in sheet "Code List" the list of values used, i.e. bank-internal masterscale. | L4: NÃO | M4: internal_credit_rating | N4: LT003_ENTITY.INTRNL_RTNG ‣ Luís Capitão-Mor solicitou que se confirme que este campo no Loan Tape tem origem no input de Capital. Segundo o documento "Especificação - BCE Loan Tape - Internal Ratings_v1.4", é referido: "Nível do cliente: deverá ser consultada a tabela CD_CAPTOOLS.JM_CAL_IN_CL;" ou seja, confirma-se que tem origem no input de Capital. | O4: Concluído | P4: ='PDS - Desenvolvimento'!$K$124 -> Concluído | Q4: 45608 | R4: Concluído | T4: cd_loan_tapes_bce.lt003_entity | U4: ‣ ref_date = data do report | V4: intrnl_rtng | W4: ‣ Para cada Counterparty Identifier é obtido o: MAX(intrnl_rtng) | X4: A agrupação é feita segundo o campo "Counterparty Identifier" deste mesmo documento | Y4: Explorar alternativas para ir buscar este campo
A5: V_9 | B5: Risk parameters | C5: External Credit rating | D5: Alphanumeric | E5: External credit rating issued to the counterparty at cut-off date. In case several ratings are assigned, the approach described in Art. 138 of the CRR applies. | F5: Rating de crédito externo emitido para a contraparte na data de corte. Caso sejam atribuídas diversas classificações, aplica-se a abordagem descrita no Art. 138 do CRR. | H5: ENTITY-EXTRNL_RTNG | I5: External rating | J5: External rating at the reference date. | L5: NÃO | M5: external_credit_rating | N5: LT003_ENTITY.EXTRNL_RTNG | O5: Concluído | P5: ='PDS - Desenvolvimento'!$K$123 -> Concluído | Q5: 45608 | R5: Concluído | T5: cd_loan_tapes_bce.lt003_entity | U5: ‣ ref_date = data do report | V5: extrnl_rtng | W5: ‣ Para cada Counterparty Identifier é obtido o: MAX(extrnl_rtng) | X5: A agrupação é feita segundo o campo "Counterparty Identifier" deste mesmo documento | Y5: Explorar alternativas para ir buscar este campo
