Workbook

Sheet 1. Análise
B7: 1A. Análise Ficheiros (# de registos)
B9: Steps do processo | C9: Dez 24 | D9: Jun 24 | E9: Dez 23 | F9: Jun 23 | G9: Dez 22 | H9: Jun 22 | J9: Ficheiros carregados no DL: - bu_esg_work.gloval_jun22 (292.710 registos) - bu_esg_work.gloval_recebido_jun22 (292.710 registos) - bu_esg_work.gloval_dez22 (12.990 registos) - bu_esg_work.gloval_jun23 (174.698 registos: Entrega 1 + Atualizações (entrega 3)) - bu_esg_work.gloval_envio_jun23 (9.818 registos) - bu_esg_work.gloval_dez23 (146.884 registos: Entrega 1 + Entrega 2 + Atualizações (entrega 3)) - bu_esg_work.dez23_atu_v2 (3.126 registos: Atualizações) - bu_esg_work.gloval_jun24 (153.818 registos: Entrega 1 + Entrega 2 + Atualizações (entrega 3)) - bu_esg_work.gloval_dez24 (151.674 registos: Entrega 1 + Entrega 2 + Atualizações (entrega 3)) Chaves Gloval Duplicadas Detalhe na sheet 1A_Aux1 (na sheet 1A_Aux2 encontra-se a análise dos dados duplicados enviados a Jun22) Chaves Duplicadas (entre envios) Detalhe na sheet 1A_Aux3 - 88 Chaves Gloval enviadas em Dezembro de 2022 e em Junho de 2023 - 19 Chaves Gloval enviadas em Junho de 2023 e em Dezembro de 2023 - 1 Chave Gloval enviada em Junho de 2022 e em Junho de 2024
B10: Dados enviados | C10: 16048 | D10: 20206 | E10: 11011 | F10: 9818
B11: Envio 1 | C11: 16029 | D11: 20172 | E11: 10956 | F11: 9818
B12: Envio 2 | C12: 19 | D12: 34 | E12: 55
B13: Dados recebidos | C13: 16048 | D13: 20206 | E13: 11011 | F13: 9818 | G13: 12990 | H13: 292710
B14: Entrega 1 | C14: 16029 | D14: 20172 | E14: 10956 | F14: 9818 | G14: 12990 | H14: 292710
B15: Entrega 2 | C15: 19 | D15: 34 | E15: 55
B16: Atualizações | C16: 135626 | D16: 133612 | E16: 138999 | F16: 164880
B17: Chaves Gloval Duplicadas | C17: 0 | D17: 115 | E17: 72 | F17: 128 | G17: 0 | H17: 152
B18: Entrega 1 | C18: 0 | D18: 0 | E18: 0 | F18: 0 | G18: 0 | H18: 152
B19: Entrega 2 | C19: 0 | D19: 0 | E19: 0
B20: Atualizações | C20: 0 | D20: 115 | E20: 72 | F20: 128
B21: Chaves Duplicadas (entre envios) | D21: 1 | E21: 19 | F21: 88
B23: 2A. Análise Tradutor Chaves - DL (# de registos)
B25: Steps do processo | C25: Dez 24 | D25: Jun 24 | E25: Dez 23 | F25: Jun 23 | G25: Dez 22 | H25: Jun 22 | J25: Tabela em análise bu_esg_work.kt_chave_gloval Análise Detalhe na sheet 2A_Aux1 - 1 Chave que no ficheiro aparece em Jun/22 e no tradutor em Jun/24: 3E9D07AE57E8272A1F390338ACFB0B5109270C31B43B499CC43E4FD1BFEC9D64 - 1.075 Chaves que aparecem no ficheiro mas nunca aparecem no tradutor.
B26: Dados recebidos | C26: 16048 | D26: 20206 | E26: 11011 | F26: 9818 | G26: 11915 | H26: 292557
B27: Chave Gloval enviada | C27: 16048 | D27: 20206 | E27: 11011 | F27: 9818 | G27: 11915 | H27: 292557
B28: Conciliação das chaves | C28: OK | D28: OK | E28: OK | F28: OK | G28: NOK | H28: NOK
B29: Verificação (com 1A) | C29: 0 | D29: 0 | E29: 0 | F29: 0 | G29: =+G13-G26 -> 1075 | H29: =+H13-H17-H26 -> 1
B31: 2B. Análise Tradutor Chaves - Duplicados
B33: Steps do processo | C33: Dez 24 | D33: Jun 24 | E33: Dez 23 | F33: Jun 23 | G33: Dez 22 | H33: Jun 22 | J33: Relação entre Chave Gloval e Chave Banco - 1 Chave NOK: 147B723F2C37A7F36304C30DF4EBFB7F55C513E191C88AB1B1DA0DDA7DCF7952 --> 000016530870000000000000000000 --> 000016530870000000000001005746 Chaves Gloval Duplicadas (entre envios) Detalhe na sheet 2B_Aux1
B34: Relação entre Chave Gloval e Chave Banco | C34: OK | D34: OK | E34: OK | F34: OK | G34: OK | H34: NOK
B35: # de Registos | C35: 0 | D35: 0 | E35: 0 | F35: 0 | G35: 0 | H35: 1
B36: Chaves Duplicadas (entre envios) | C36: OK | D36: OK | E36: NOK | F36: NOK | G36: OK | H36: OK
B37: # de Registos | C37: 0 | D37: 0 | E37: 19 | F37: 88 | G37: 0 | H37: 0
B39: 2C. Análise Tradutor Chaves - Obtenção do CEMPBEM
B41: Steps do processo | C41: Dez 24 | D41: Jun 24 | E41: Dez 23 | F41: Jun 23 | G41: Dez 22 | H41: Jun 22 | J41: Chaves Gloval Duplicadas (entre envios) Detalhe na sheet 2C_Aux1
B42: Relação entre Chave Banco e MUG (ou MBI) | C42: OK | D42: OK | E42: OK | F42: OK | G42: NOK | H42: NOK
B43: # de Registos | C43: 0 | D43: 0 | E43: 0 | F43: 0 | G43: 7 | H43: 6933
B45: 3. Dados a importar (após tratamentos)
B47: Steps do processo | C47: Dez 24 | D47: Jun 24 | E47: Dez 23 | F47: Jun 23 | G47: Dez 22 | H47: Jun 22 | J47: Tabelas criadas no DL
B48: Envios | C48: OK | D48: OK | E48: OK | F48: OK | G48: NOK | H48: NOK
B49: Atualizações | C49: 0 | D49: 0 | E49: 0 | F49: 0 | G49: 7 | H49: 6933

Sheet 2. Pressupostos 
B7: Em detrimento da análise aos ficheiros da Gloval (sheet "1. Análise") foram considerados os seguintes pressupostos em função dos temas identificados.
B9: ID | C9: Rácio | D9: Tabela importada no front-end | E9: # de Registos | F9: Issue detetado | G9: Medida de resolução
B10: #1 | C10: Aplicado a todos os rácios. | D10: Não aplicável | E10: Não aplicável | F10: Chaves internas do Banco (detalhe nas sheet 2C_Aux1). | G10: 1. Para a obtenção das chaves internas do Banco foram consideradas as relações (variávies chave_banco_atual e chave_gloval_enviada) presentes no tradutor de chaves (bu_esg_work.kt_chave_gloval) com os seguintes tratamentos: ▪ cempbem - Cruzamento do tradutor de chaves com o MUG e MBI para identificar o cempbem (não foi possivel cruzar 6.940 imóveis, como pressuposto foi considerado '31' / detalhe na sheet 2C_Aux1) ▪ ckbalbem - Se o tamanho da chave for 30 então foram considerados os primeiros 4 digitos da chave_banco_atual. ▪ ckctabem - Se o tamanho da chave for 30 então foram considerados os 11 digitos da chave_banco_atual após a posição 5. ▪ ckrefbem - Se o tamanho da chave for 30 então foram considerados os 15 digitos da chave_banco_atual após a posição 16. 2. Para as relações não presentes no tradutor de chaves foram consideras as relaçoes presentes na tabela bu_esg_work.envio_gloval_dez22_v2 (1.075 chaves / detalhe na sheet 2A_Aux1). Denote-se que nesta tabela estas chaves estão assinaladas com a flag de adjudicados. 3. Para todas as chaves com tamanho diferente de 30 (1.200 chaves / detalhe na sheet 3_Aux2) foram consideradas as variaveis cempbem, ckctabem e ckrefbem a null (carregado a vazio no font-end) e a variável ckbalbem com a chave. Denote-se que os adjudicados foram alvo deste tratamento e por este motivo (aquando a integração destas chaves nos sistemas do Banco) será necessário a revisão das mesmas nos ficheiros carregados no front-end. 4. Para a chave Gloval 147B723F2C37A7F36304C30DF4EBFB7F55C513E191C88AB1B1DA0DDA7DCF7952 foi considerada a chave banco 000016530870000000000000000000 em virtude de apenas esta constar no MUG (a chave 000016530870000000000001005746 foi desvinculada desta chave Gloval).
B11: #2 | C11: Junho de 2022 | D11: BU_ESG_WORK.GLOVAL_TRAT_JUN22 | E11: 292710 | F11: 152 Chaves Gloval duplicadas no envio (detalhe na sheet 1A_Aux2). | G11: Foram carregadas as 152 chaves no front-end. Destas 152 chaves apenas 1 chave tem impacto no processo de aprovisionamento da tabela de output de certificados, uma vez que, os valores recebidos pela Gloval são distintos (na tabela de output é realizado o tratamento destes casos de modo a escolher o pior registo (abordagem conservadora)).
B12: #3 | C12: Dezembro de 2022 | D12: BU_ESG_WORK.GLOVAL_TRAT_DEZ22 | E12: 12990 | F12: 1.075 Chaves sem cruzamento com o Tradutor de Chaves (detalhe na sheet 1A_Aux2). | G12: Foram consideradas as chaves internas do banco presentes na tabela bu_esg_work.envio_gloval_dez22_v2. Denote-se que estes imóveis incidiram no tratatamento descrito no ID #1.
B13: #4 | C13: Junho de 2023 | D13: BU_ESG_WORK.GLOVAL_TRAT_JUN23 | E13: 9818 | F13: 88 Chaves Gloval enviadas em 2 rácios distintos (consideradas no rácio de Dezembro de 2022 e no rácio de Dezembro de 2023 (detalhe na sheet 1A_Aux3)). | G13: Foram carregadas as 88 chaves no front-end. Para estas 88 chaves o processo de aprovisionamento da tabela de output de certificados ignora os dados recebidos da Gloval no rácio de Dezembro de 2022, exceto: ▪ 6 chaves (detalhe na sheet 3_Aux1) - Estas chaves foram enviadas em Dezembro de 2022 e em Junho de 2023. No entanto, em Junho de 2023 a Gloval enviou a atualização destas 6 chaves (considerado nos registos do ID #5), e por conseguinte, o processo de aprovisionamento da tabela de output de certificados irá considerar o valor desta atualização ao invés dos dados recebidos associados ao envio de Junho de 2023.
B14: #5 | C14: Junho de 2023 - Atualizações | D14: BU_ESG_WORK.GLOVAL_TRAT_JUN23_ATU | E14: 164753 | F14: 128 Chaves Gloval duplicadas (detalhe na sheet 1A_Aux1). | G14: Das 128 chaves Gloval (que corresponde a 256 linhas no ficheiro de origem) foram carregadas no front-end: ▪ 127 chaves Gloval apenas com 1 linha (uma vez que os dados recebidos pela Gloval foram iguais) ▪ 1 chave Gloval com 2 linhas (uma vez que os dados recebidos pela Gloval foram diferentes) - Para este caso o processo de aprovisionamento da tabela de output de certificados considera o pior registo (abordagem conservadora) - detalhe na sheet 3_Aux1. Denote-se que todas estas chaves correspondem as chaves que foram enviadas 2x no rácio de Junho de 2022.
B15: #6 | C15: Dezembro de 2023 | D15: BU_ESG_WORK.GLOVAL_TRAT_DEZ23 | E15: 11011 | F15: 19 Chaves Gloval enviadas em 2 rácios distintos (consideradas no rácio de Junho de 2023 e no rácio de Dezembro de 2023 (detalhe na sheet 1A_Aux3)). | G15: Foram carregadas as 19 chaves no front-end. Para estas 19 chaves o processo de aprovisionamento da tabela de output de certificados ignora os dados recebidos da Gloval no rácio de Junho de 2023.
B16: #7 | C16: Dezembro de 2023 - Atualizações | D16: BU_ESG_WORK.GLOVAL_TRAT_DEZ23_ATU | E16: 138928 | F16: 72 Chaves Gloval duplicadas (detalhe na sheet 1A_Aux1). | G16: Das 72 chaves Gloval (que corresponde a 144 linhas no ficheiro de origem) foram carregadas no front-end: ▪ 71 chaves Gloval apenas com 1 linha (uma vez que os dados recebidos pela Gloval foram iguais) ▪ 1 chave Gloval com 2 linhas (uma vez que os dados recebidos pela Gloval foram diferentes) - Para este caso o processo de aprovisionamento da tabela de output de certificados considera o pior registo (abordagem conservadora) - detalhe na sheet 3_Aux1. Denote-se que todas estas chaves correspondem as chaves que foram enviadas 2x no rácio de Junho de 2022. A chave Gloval com 2 valores distintos é a mesma chave identificada na atualização de Junho de 2023.
B17: #8 | C17: Junho de 2024 | D17: BU_ESG_WORK.GLOVAL_TRAT_JUN24 | E17: 20206 | F17: 1 Chave Gloval enviada em 2 rácios distintos (consideradas no rácio de Junho de 2022 e no rácio de Junho de 2024 (detalhe na sheet 1A_Aux3)). | G17: Foi carregado esta chave no front-end. Para esta chave o processo de aprovisionamento da tabela de output de certificados ignora os dados recebidos da Gloval no rácio de Junho de 2022.
B18: #9 | C18: Junho de 2024 - Atualizações | D18: BU_ESG_WORK.GLOVAL_TRAT_JUN24_ATU | E18: 133498 | F18: 115 Chaves Gloval duplicadas (detalhe na sheet 1A_Aux1). | G18: Das 115 chaves Gloval (que corresponde a 144 linhas no ficheiro de origem) foram carregadas no front-end: ▪ 114 chaves Gloval apenas com 1 linha (uma vez que os dados recebidos pela Gloval foram iguais) ▪ 1 chave Gloval com 2 linhas (uma vez que os dados recebidos pela Gloval foram diferentes) - Para este caso o processo de aprovisionamento da tabela de output de certificados considera o pior registo (abordagem conservadora) - detalhe na sheet 3_Aux1. Denote-se que todas estas chaves correspondem as chaves que foram enviadas 2x no rácio de Junho de 2022. A chave Gloval com 2 valores distintos é a mesma chave identificada na atualização de Junho de 2023.
B19: #10 | C19: Dezembro de 2024 | D19: BU_ESG_WORK.GLOVAL_TRAT_DEZ24 | E19: 16048 | F19: Não aplicável | G19: Não aplicável
B20: #11 | C20: Dezembro de 2024 - Atualizações | D20: BU_ESG_WORK.GLOVAL_TRAT_DEZ24_ATU | E20: 135626 | F20: Não aplicável | G20: Não aplicável

Sheet 3. Incidências >>
F48: Chave interna do Banco (detalhe nas sheet 2C_Aux1) | J48: Como ponto de partida para obtanção da chave interna do Banco foi considerado o tradutor de chaves presente no DL com os seguintes tratamentos: ▪ cempbem - Cruzamento do tradutor de chaves com o MUG e MBI para identificar o CEMBEM (não foi possivel cruzar 6.940 imóveis e para este foi considerado '31') ▪ ckbalbem - Se o tamanho da chave for 30 então foi considerado os primeiros 4 digitos da chave_banco_atual. ▪ ckctabem - Se o tamanho da chave for 30 então foram considerados os 11 digitos da chave_banco_atual após a posição 5. ▪ ckrefbem - Se o tamanho da chave for 30 então foram considerados os 15 digitos da chave_banco_atual após a posição 16. Todas as chaves com o tamnho diferente de 30 (adjudicados) foram consideradas as variaveis cempbem, ckctabem e ckrefbem a null e a variável ckbalbem com a chave.
B49: 2. Rácio Junho de 2022 | F49: 152 Chaves Gloval duplicadas no envio (detalhe na sheet 1A_Aux2)
B50: 3. Rácio Dezembro de 2022 | F50: 1.075 Chaves sem cruzamento com o Tradutor de Chaves (detalhe na sheet 1A_Aux2)

Sheet 1A_Aux1
B2: Chaves Gloval Duplicadas (# de registos) | C2: =+COUNTIF($C$4:$C$155,"Sim") -> 152 | D2: =+COUNTIF($D$4:$D$155,"Sim") -> 128 | E2: =+COUNTIF($E$4:$E$155,"Sim") -> 72 | F2: =+COUNTIF($F$4:$F$155,"Sim") -> 115
B3: CHAVE_GLOVAL | C3: JUNHO DE 2022 | D3: JUNHO DE 23 | E3: DEZEMBRO DE 23 | F3: JUNHO DE 24
B4: 38026D1FDF52EA1B39A13A4F0B2A015FCA67E873CD96D8D0FF49C00FEA193641 | C4: Sim | D4: Sim | E4: Sim | F4: Sim
B5: 147B723F2C37A7F36304C30DF4EBFB7F55C513E191C88AB1B1DA0DDA7DCF7952 | C5: Sim | D5: Sim | E5: Não | F5: Não
B6: 686BFDF1AAF0B98ADB7EC8B6D093BEA3936AD861FBCAF36643C9FD7E71C951AA | C6: Sim | D6: Sim | E6: Sim | F6: Sim
B7: 1C5E30DF11D101C67E5B0F79960497F7547501981D9EEFA39090B05AC5DFF576 | C7: Sim | D7: Sim | E7: Sim | F7: Sim
B8: 3126FE706251B1DDFC0A98B7A28E96AD6B58FCD37C1F114846EE0C27FA3DD3D9 | C8: Sim | D8: Sim | E8: Sim | F8: Sim
B9: 9A1E45754A598E1B41BF858488766399EAFD154CA68CA6F6B7A88C13C8423E3D | C9: Sim | D9: Sim | E9: Não | F9: Sim
B10: A357883D729C432D922CDB7572FA0622374430051614621355FC475CB018E905 | C10: Sim | D10: Sim | E10: Não | F10: Sim
B11: EACF9288096347477FEE5FEAAB586E63E5E1B44D4D228608B927445E63D40E40 | C11: Sim | D11: Sim | E11: Não | F11: Sim
B12: BF0EC9A069B55B0CBCAFD7A96377932A5DAC1FB9D5CC72AEDD85E0A5F3F2E2AE | C12: Sim | D12: Não | E12: Não | F12: Não
B13: EDA34BBE02FF77E84F4CBA005F712B76D852AB49692992F78AE452CD1978043C | C13: Sim | D13: Sim | E13: Não | F13: Não
B14: E1F1D80B32E4E30B072DCB107649D56AD0A7A75F4A613339712E85FAF9FFD9B0 | C14: Sim | D14: Sim | E14: Sim | F14: Sim
... B155: 30B8270FE7A5ADD99AA087FF0B13AC6E19C3355F4A133838A1C15F0C0176A1EF | C155: Sim | D155: Sim | E155: Sim | F155: Sim

Sheet 1A_Aux2
B2: 1. DADOS AUX=1 | AR2: 2. DADOS AUX=2 | CH2: 3. Validação
CH3: =+SUM(CH5:CH156) -> 0 | CI3: =+SUM(CI5:CI156) -> 0 | CJ3: =+SUM(CJ5:CJ156) -> 1 | CK3: =+SUM(CK5:CK156) -> 0 | CL3: =+SUM(CL5:CL156) -> 1 | CM3: =+SUM(CM5:CM156) -> 1 | CN3: =+SUM(CN5:CN156) -> 2 | CO3: =+SUM(CO5:CO156) -> 0 | ... DO3: =+SUM(DO5:DO156) -> 82 | DR3: =+SUM(DR5:DR156) -> 82 | DU3: =+SUM(DU5:DU156) -> 0 | DV3: =+SUM(DV5:DV156) -> 0 | DW3: =+SUM(DW5:DW156) -> 1 | DX3: =+SUM(DX5:DX156) -> 1
B4: chave_banco | C4: chave_gloval | D4: codigo_distrito | E4: nombre_distrito | F4: codigo_concejo | G4: nombre_concejo | H4: codigo_freguesia | I4: nombre_freguesia | J4: localidade | K4: tipo_via | L4: nombre_tipo_via | M4: nombre_via | N4: numero_via | O4: lote | P4: urbanizacion | Q4: caglurb | R4: resto_direccion | S4: latitud | T4: longitud | U4: codigo_postal | V4: subcodigo_postal | W4: assuperficie_util | X4: anio_construccion | Y4: tipo_inmueble_habitacao | Z4: piso_apartamento | AA4: casa_unifamiliar | AB4: tipo_inmueble_comercio_servicos | AC4: nome_conservatoria | AD4: cod_conservatoria | AE4: registro_conservatoria | AF4: art_matriciais | AG4: fraccao_autonoma | AH4: finalidade_bem | AI4: class_gpt31 | AJ4: class_stclim | AK4: conf_stclim | AL4: fiabilidad | AM4: clase_energetica | AN4: emisiones | AO4: consumos | AP4: AUX | AR4: chave_banco | AS4: chave_gloval | AT4: codigo_distrito | AU4: nombre_distrito | AV4: codigo_concejo | AW4: nombre_concejo | AX4: codigo_freguesia | AY4: nombre_freguesia | AZ4: localidade | BA4: tipo_via | BB4: nombre_tipo_via | BC4: nombre_via | BD4: numero_via | BE4: lote | BF4: urbanizacion | BG4: caglurb | BH4: resto_direccion | BI4: latitud | BJ4: longitud | BK4: codigo_postal | BL4: subcodigo_postal | BM4: assuperficie_util | BN4: anio_construccion | BO4: tipo_inmueble_habitacao | BP4: piso_apartamento | BQ4: casa_unifamiliar | BR4: tipo_inmueble_comercio_servicos | BS4: nome_conservatoria | BT4: cod_conservatoria | BU4: registro_conservatoria | BV4: art_matriciais | BW4: fraccao_autonoma | BX4: finalidade_bem | BY4: class_gpt31 | BZ4: class_stclim | CA4: conf_stclim | CB4: fiabilidad | CC4: clase_energetica | CD4: emisiones | CE4: consumos | CF4: AUX | CH4: chave_gloval | CI4: codigo_distrito | CJ4: nombre_distrito | CK4: codigo_concejo | CL4: nombre_concejo | CM4: codigo_freguesia | CN4: nombre_freguesia | CO4: localidade | CP4: tipo_via | CQ4: nombre_tipo_via | CR4: nombre_via | CS4: numero_via | CT4: lote | CU4: urbanizacion | CV4: caglurb | CW4: resto_direccion | CX4: latitud | CY4: longitud | CZ4: codigo_postal | DA4: subcodigo_postal | DB4: assuperficie_util | DC4: anio_construccion | DD4: tipo_inmueble_habitacao | DE4: piso_apartamento | DF4: casa_unifamiliar | DG4: tipo_inmueble_comercio_servicos | DH4: nome_conservatoria | DI4: cod_conservatoria | DJ4: registro_conservatoria | DK4: art_matriciais | DL4: fraccao_autonoma | DM4: finalidade_bem | DN4: class_gpt31 | DO4: class_stclim | DP4: aux_1 | DQ4: aux_2 | DR4: conf_stclim | DS4: aux_1 | DT4: aux_2 | DU4: fiabilidad | DV4: clase_energetica | DW4: emisiones | DX4: consumos | DY4: DIFERENÇAS | DZ4: BLANKS AUX1 | EA4: BLANKS AUX2 | EB4: AUX | EC4: COMENTÁRIO NYD
C5: 04F692D4253F3BA1E5009AD93B0012A2D4323296E57CA4B81FC3A72D9BC1F9F5 | D5: 110000 | E5: LISBOA | F5: 110600 | G5: LISBOA | H5: 110623 | I5: NOSSA SENHORA DE FÁTIMA | J5: LISBOA | K5: 02 | L5: AVENIDA | M5: REPÚBLICA | N5: 77 A | Q5: AVENIDA | R5: 2948 A | U5: 1050 | V5: 243 | W5: 4515 | X5: 2000 | Y5: 0 | Z5: 0 | AA5: 0 | AB5: 0 | AD5: 000 | AE5: 0000000 | AF5: 1491 CRP 2948 | AG5: 1491 2948 A | AH5: OUTRAS | AJ5: C | AK5: 4-MEDIA | AL5: 2-MUY ALTA | AM5: A | AN5: 6,02 | AO5: 21,4 | AP5: 1 | AS5: 04F692D4253F3BA1E5009AD93B0012A2D4323296E57CA4B81FC3A72D9BC1F9F5 | AT5: 110000 | AU5: LISBOA | AV5: 110600 | AW5: LISBOA | AX5: 110623 | AY5: NOSSA SENHORA DE FÁTIMA | AZ5: LISBOA | BA5: 02 | BB5: AVENIDA | BC5: REPÚBLICA | BD5: 77 A | BG5: AVENIDA | BH5: 2948 A | BK5: 1050 | BL5: 243 | BM5: 4515 | BN5: 2000 | BO5: 0 | BP5: 0 | BQ5: 0 | BR5: 0 | BU5: 0000000 | BV5: 1491 CRP 2948 | BW5: 1491 2948 A | BX5: OUTRAS | CB5: 2-MUY ALTA | CC5: A | CD5: 6,02 | CE5: 21,4 | CF5: 2 | CH5: =+IF(C5=AS5,0,1) -> 0 | CI5: =+IF(D5=AT5,0,1) -> 0 | CJ5: =+IF(E5=AU5,0,1) -> 0 | CK5: =+IF(F5=AV5,0,1) -> 0 | CL5: =+IF(G5=AW5,0,1) -> 0 | CM5: =+IF(H5=AX5,0,1) -> 0 | CN5: =+IF(I5=AY5,0,1) -> 0 | CO5: =+IF(J5=AZ5,0,1) -> 0 | ... DO5: =+IF(AJ5=BZ5,0,1) -> 1 | DP5: =+AJ5 -> C | DQ5: =+BZ5 -> 0 | DR5: =+IF(AK5=CA5,0,1) -> 1 | DS5: =+AK5 -> 4-MEDIA | DT5: =+CA5 -> 0 | DU5: =+IF(AL5=CB5,0,1) -> 0 | DV5: =+IF(AM5=CC5,0,1) -> 0 | DW5: =+IF(AN5=CD5,0,1) -> 0 | DX5: =+IF(AO5=CE5,0,1) -> 0 | DY5: =+SUM(CH5:DO5,DR5,DU5:DX5) -> 3 | DZ5: =+COUNTBLANK(C5:AO5) -> 6 | EA5: =+COUNTBLANK(AS5:CE5) -> 9 | EB5: =+IF(AND(DZ5=EA5,DY5=0),"IGUAL CAMPOS PREENCH",IF(DZ5<=EA5,"AUX 1 COM + CAMPOS PREENC OU IGUAL","AUX 2 COM + CAMPOS PREENC")) -> AUX 1 COM + CAMPOS PREENC OU IGUAL | EC5: Diferenças nos registos enviados & Sem diferenças nos dados recebidos
B6: 0032174229700000 | C6: 059ECC5BF64D0E9A5A38BC5FA9DD53509B1800CEC6D194496622D1395BF482DD | D6: 080000 | E6: FARO | F6: 080400 | G6: CASTRO MARIM | H6: 080402 | I6: CASTRO MARIM | J6: FERNAO GIL | K6: 16 | L6: LUGAR | M6: FERNAO GIL | N6: . | Q6: LUGAR | U6: 8950 | V6: 326 | W6: 143 | Y6: 1 | Z6: 0 | AA6: 0 | AB6: 0 | AF6: U2885 R156 SECCAO DZ | AH6: HABITACAO | AL6: 5-MEDIA BAJA | AM6: C | AN6: 16,73 | AO6: 59,53 | AP6: 1 | AS6: 059ECC5BF64D0E9A5A38BC5FA9DD53509B1800CEC6D194496622D1395BF482DD | AT6: 080000 | AU6: FARO | AV6: 080400 | AW6: CASTRO MARIM | AX6: 080402 | AY6: CASTRO MARIM | AZ6: FERNAO GIL | BA6: 16 | BB6: LUGAR | BC6: FERNAO GIL | BD6: . | BG6: LUGAR | BK6: 8950 | BL6: 326 | BM6: 143 | BO6: 1 | BP6: 0 | BQ6: 0 | BR6: 0 | BV6: U2885 R156 SECCAO DZ | BX6: HABITACAO | CB6: 5-MEDIA BAJA | CC6: C | CD6: 16,73 | CE6: 59,53 | CF6: 2 | CH6: =+IF(C6=AS6,0,1) -> 0 | CI6: =+IF(D6=AT6,0,1) -> 0 | CJ6: =+IF(E6=AU6,0,1) -> 0 | CK6: =+IF(F6=AV6,0,1) -> 0 | CL6: =+IF(G6=AW6,0,1) -> 0 | CM6: =+IF(H6=AX6,0,1) -> 0 | CN6: =+IF(I6=AY6,0,1) -> 0 | CO6: =+IF(J6=AZ6,0,1) -> 0 | ... DO6: =+IF(AJ6=BZ6,0,1) -> 0 | DP6: =+AJ6 -> 0 | DQ6: =+BZ6 -> 0 | DR6: =+IF(AK6=CA6,0,1) -> 0 | DS6: =+AK6 -> 0 | DT6: =+CA6 -> 0 | DU6: =+IF(AL6=CB6,0,1) -> 0 | DV6: =+IF(AM6=CC6,0,1) -> 0 | DW6: =+IF(AN6=CD6,0,1) -> 0 | DX6: =+IF(AO6=CE6,0,1) -> 0 | DY6: =+SUM(CH6:DO6,DR6,DU6:DX6) -> 0 | DZ6: =+COUNTBLANK(C6:AO6) -> 13 | EA6: =+COUNTBLANK(AS6:CE6) -> 13 | EB6: =+IF(AND(DZ6=EA6,DY6=0),"IGUAL CAMPOS PREENCH",IF(DZ6<=EA6,"AUX 1 COM + CAMPOS PREENC OU IGUAL","AUX 2 COM + CAMPOS PREENC")) -> IGUAL CAMPOS PREENCH | EC6: Registo duplicado (todos os campos iguais) & Sem diferenças nos dados recebidos
C7: 067D9CEEB7482643D1D9733B1603AA74F34F2196795343192479A7B41B946118 | D7: 080000 | E7: FARO | F7: 080600 | G7: LAGOA (ALGARVE) | H7: 080602 | I7: FERRAGUDO | J7: VALE AREIA-FERRAGUDO | K7: 06 | L7: URBANIZACAO | M7: ANGRINHA | N7: 3 | O7: 3 | Q7: LARGO | R7: 2º - APT 3 | U7: 8400 | W7: 124 | Y7: 1 | Z7: 0 | AA7: 0 | AB7: 0 | AF7: 3077 E 3444 | AH7: HABITACAO | AJ7: D | AK7: 5-MEDIA BAJA | AL7: 3-ALTA | AM7: C | AN7: 18,26 | AO7: 65,2 | AP7: 1 | AR7: 0090172090200000 | AS7: 067D9CEEB7482643D1D9733B1603AA74F34F2196795343192479A7B41B946118 | AT7: 080000 | AU7: FARO | AV7: 080600 | AW7: LAGOA (ALGARVE) | AX7: 080602 | AY7: FERRAGUDO | AZ7: VALE AREIA-FERRAGUDO | BA7: 06 | BB7: URBANIZACAO | BC7: ANGRINHA | BD7: 3 | BE7: 3 | BG7: LARGO | BH7: 2º - APT 3 | BK7: 8400 | BM7: 124 | BO7: 1 | BP7: 0 | BQ7: 0 | BR7: 0 | BV7: 3077 E 3444 | BX7: HABITACAO | BZ7: D | CA7: 5-MEDIA BAJA | CB7: 3-ALTA | CC7: C | CD7: 18,26 | CE7: 65,2 | CF7: 2 | CH7: =+IF(C7=AS7,0,1) -> 0 | CI7: =+IF(D7=AT7,0,1) -> 0 | CJ7: =+IF(E7=AU7,0,1) -> 0 | CK7: =+IF(F7=AV7,0,1) -> 0 | CL7: =+IF(G7=AW7,0,1) -> 0 | CM7: =+IF(H7=AX7,0,1) -> 0 | CN7: =+IF(I7=AY7,0,1) -> 0 | CO7: =+IF(J7=AZ7,0,1) -> 0 | ... DO7: =+IF(AJ7=BZ7,0,1) -> 0 | DP7: =+AJ7 -> D | DQ7: =+BZ7 -> D | DR7: =+IF(AK7=CA7,0,1) -> 0 | DS7: =+AK7 -> 5-MEDIA BAJA | DT7: =+CA7 -> 5-MEDIA BAJA | DU7: =+IF(AL7=CB7,0,1) -> 0 | DV7: =+IF(AM7=CC7,0,1) -> 0 | DW7: =+IF(AN7=CD7,0,1) -> 0 | DX7: =+IF(AO7=CE7,0,1) -> 0 | DY7: =+SUM(CH7:DO7,DR7,DU7:DX7) -> 0 | DZ7: =+COUNTBLANK(C7:AO7) -> 10 | EA7: =+COUNTBLANK(AS7:CE7) -> 10 | EB7: =+IF(AND(DZ7=EA7,DY7=0),"IGUAL CAMPOS PREENCH",IF(DZ7<=EA7,"AUX 1 COM + CAMPOS PREENC OU IGUAL","AUX 2 COM + CAMPOS PREENC")) -> IGUAL CAMPOS PREENCH | EC7: Registo duplicado (todos os campos iguais) & Sem diferenças nos dados recebidos
C8: 0DDE9301ADAB1F37BF7173A035E74C370ED90C0F071BF5D77C9DF55C63BB97E5 | D8: 140000 | E8: SANTARÉM | F8: 141100 | G8: FERREIRA DO ZEZERE | H8: 141101 | I8: ÁGUAS BELAS | J8: BELA VISTA | U8: 2240 | W8: 0 | X8: 1950 | Y8: 0 | Z8: 0 | AA8: 0 | AB8: 1 | AE8: 0000000 | AF8: 000002041 - | AH8: ARMAZEM | AL8: 5-MEDIA BAJA | AM8: D | AN8: 44 | AO8: 153,05 | AP8: 1 | AR8: 0632160836300000 | AS8: 0DDE9301ADAB1F37BF7173A035E74C370ED90C0F071BF5D77C9DF55C63BB97E5 | AT8: 140000 | AU8: SANTARÉM | AV8: 141100 | AW8: FERREIRA DO ZEZERE | AX8: 141101 | AY8: ÁGUAS BELAS | AZ8: BELA VISTA | BK8: 2240 | BM8: 0 | BN8: 1950 | BO8: 0 | BP8: 0 | BQ8: 0 | BR8: 1 | BU8: 0000000 | BV8: 000002041 - | BX8: ARMAZEM | BZ8: F | CA8: 5-MEDIA BAJA | CB8: 5-MEDIA BAJA | CC8: D | CD8: 44 | CE8: 153,05 | CF8: 2 | CH8: =+IF(C8=AS8,0,1) -> 0 | CI8: =+IF(D8=AT8,0,1) -> 0 | CJ8: =+IF(E8=AU8,0,1) -> 0 | CK8: =+IF(F8=AV8,0,1) -> 0 | CL8: =+IF(G8=AW8,0,1) -> 0 | CM8: =+IF(H8=AX8,0,1) -> 0 | CN8: =+IF(I8=AY8,0,1) -> 0 | CO8: =+IF(J8=AZ8,0,1) -> 0 | ... DO8: =+IF(AJ8=BZ8,0,1) -> 1 | DP8: =+AJ8 -> 0 | DQ8: =+BZ8 -> F | DR8: =+IF(AK8=CA8,0,1) -> 1 | DS8: =+AK8 -> 0 | DT8: =+CA8 -> 5-MEDIA BAJA | DU8: =+IF(AL8=CB8,0,1) -> 0 | DV8: =+IF(AM8=CC8,0,1) -> 0 | DW8: =+IF(AN8=CD8,0,1) -> 0 | DX8: =+IF(AO8=CE8,0,1) -> 0 | DY8: =+SUM(CH8:DO8,DR8,DU8:DX8) -> 2 | DZ8: =+COUNTBLANK(C8:AO8) -> 17 | EA8: =+COUNTBLANK(AS8:CE8) -> 15 | EB8: =+IF(AND(DZ8=EA8,DY8=0),"IGUAL CAMPOS PREENCH",IF(DZ8<=EA8,"AUX 1 COM + CAMPOS PREENC OU IGUAL","AUX 2 COM + CAMPOS PREENC")) -> AUX 2 COM + CAMPOS PREENC | EC8: Diferenças nos registos enviados & Sem diferenças nos dados recebidos
C9: 0F605F4FDEEC30C6966611ECEB3261AB517FB7208F19BF1B1CBD1845FB51F313 | D9: 060000 | E9: COIMBRA | F9: 060300 | G9: COIMBRA | H9: 060302 | I9: COIMBRA (ALMEDINA) | J9: COIMBRA | K9: 01 | L9: RUA | M9: DO BRASIL | N9: 1 | Q9: RUA | U9: 3030 | V9: 175 | W9: 3623 | Y9: 0 | Z9: 0 | AA9: 0 | AB9: 0 | AF9: 1475 | AH9: OUTRAS | AL9: 2-MUY ALTA | AM9: E | AN9: 56,86 | AO9: 203,42 | AP9: 1 | AR9: 0090169506000000 | AS9: 0F605F4FDEEC30C6966611ECEB3261AB517FB7208F19BF1B1CBD1845FB51F313 | AT9: 060000 | AU9: COIMBRA | AV9: 060300 | AW9: COIMBRA | AX9: 060302 | AY9: COIMBRA (ALMEDINA) | AZ9: COIMBRA | BA9: 01 | BB9: RUA | BC9: DO BRASIL | BD9: 1 | BG9: RUA | BK9: 3030 | BL9: 175 | BM9: 3623 | BO9: 0 | BP9: 0 | BQ9: 0 | BR9: 0 | BV9: 1475 | BX9: OUTRAS | BZ9: C | CA9: 4-MEDIA | CB9: 2-MUY ALTA | CC9: E | CD9: 56,86 | CE9: 203,42 | CF9: 2 | CH9: =+IF(C9=AS9,0,1) -> 0 | CI9: =+IF(D9=AT9,0,1) -> 0 | CJ9: =+IF(E9=AU9,0,1) -> 0 | CK9: =+IF(F9=AV9,0,1) -> 0 | CL9: =+IF(G9=AW9,0,1) -> 0 | CM9: =+IF(H9=AX9,0,1) -> 0 | CN9: =+IF(I9=AY9,0,1) -> 0 | CO9: =+IF(J9=AZ9,0,1) -> 0 | ... DO9: =+IF(AJ9=BZ9,0,1) -> 1 | DP9: =+AJ9 -> 0 | DQ9: =+BZ9 -> C | DR9: =+IF(AK9=CA9,0,1) -> 1 | DS9: =+AK9 -> 0 | DT9: =+CA9 -> 4-MEDIA | DU9: =+IF(AL9=CB9,0,1) -> 0 | DV9: =+IF(AM9=CC9,0,1) -> 0 | DW9: =+IF(AN9=CD9,0,1) -> 0 | DX9: =+IF(AO9=CE9,0,1) -> 0 | DY9: =+SUM(CH9:DO9,DR9,DU9:DX9) -> 2 | DZ9: =+COUNTBLANK(C9:AO9) -> 13 | EA9: =+COUNTBLANK(AS9:CE9) -> 11 | EB9: =+IF(AND(DZ9=EA9,DY9=0),"IGUAL CAMPOS PREENCH",IF(DZ9<=EA9,"AUX 1 COM + CAMPOS PREENC OU IGUAL","AUX 2 COM + CAMPOS PREENC")) -> AUX 2 COM + CAMPOS PREENC | EC9: Diferenças nos registos enviados & Sem diferenças nos dados recebidos
B10: 0032163519700000 | C10: 13AE3EF16776ABE28CDCE355E6F732AB14E9006CEDD57CC819ECBAABC5CA42AF | D10: 120000 | E10: PORTALEGRE | F10: 120300 | G10: AVIS | H10: 120302 | I10: ALDEIA VELHA | J10: ALDEIA VELHA | K10: 24 | L10: CANADA | M10: HERDADE DO MONTE NOVO | N10: NA | Q10: CANADA | U10: 7480 | V10: 051 | W10: 772 | Y10: 1 | Z10: 0 | AA10: 0 | AB10: 0 | AF10: 1 SEC. A E A1 178 | AH10: HABITACAO | AJ10: E | AK10: 5-MEDIA BAJA | AL10: 5-MEDIA BAJA | AM10: E | AN10: 53,92 | AO10: 193,15 | AP10: 1 | AS10: 13AE3EF16776ABE28CDCE355E6F732AB14E9006CEDD57CC819ECBAABC5CA42AF | AT10: 120000 | AU10: PORTALEGRE | AV10: 120300 | AW10: AVIS | AX10: 120302 | AY10: ALDEIA VELHA | AZ10: ALDEIA VELHA | BA10: 24 | BB10: CANADA | BC10: HERDADE DO MONTE NOVO | BD10: NA | BG10: CANADA | BK10: 7480 | BL10: 051 | BM10: 772 | BO10: 1 | BP10: 0 | BQ10: 0 | BR10: 0 | BV10: 1 SEC. A E A1 178 | BX10: HABITACAO | CB10: 5-MEDIA BAJA | CC10: E | CD10: 53,92 | CE10: 193,15 | CF10: 2 | CH10: =+IF(C10=AS10,0,1) -> 0 | CI10: =+IF(D10=AT10,0,1) -> 0 | CJ10: =+IF(E10=AU10,0,1) -> 0 | CK10: =+IF(F10=AV10,0,1) -> 0 | CL10: =+IF(G10=AW10,0,1) -> 0 | CM10: =+IF(H10=AX10,0,1) -> 0 | CN10: =+IF(I10=AY10,0,1) -> 0 | CO10: =+IF(J10=AZ10,0,1) -> 0 | ... DO10: =+IF(AJ10=BZ10,0,1) -> 1 | DP10: =+AJ10 -> E | DQ10: =+BZ10 -> 0 | DR10: =+IF(AK10=CA10,0,1) -> 1 | DS10: =+AK10 -> 5-MEDIA BAJA | DT10: =+CA10 -> 0 | DU10: =+IF(AL10=CB10,0,1) -> 0 | DV10: =+IF(AM10=CC10,0,1) -> 0 | DW10: =+IF(AN10=CD10,0,1) -> 0 | DX10: =+IF(AO10=CE10,0,1) -> 0 | DY10: =+SUM(CH10:DO10,DR10,DU10:DX10) -> 2 | DZ10: =+COUNTBLANK(C10:AO10) -> 11 | EA10: =+COUNTBLANK(AS10:CE10) -> 13 | EB10: =+IF(AND(DZ10=EA10,DY10=0),"IGUAL CAMPOS PREENCH",IF(DZ10<=EA10,"AUX 1 COM + CAMPOS PREENC OU IGUAL","AUX 2 COM + CAMPOS PREENC")) -> AUX 1 COM + CAMPOS PREENC OU IGUAL | EC10: Diferenças nos registos enviados & Sem diferenças nos dados recebidos
C11: 147B723F2C37A7F36304C30DF4EBFB7F55C513E191C88AB1B1DA0DDA7DCF7952 | D11: 110000 | E11: LISBOA | F11: 111600 | G11: ODIVELAS | H11: 111600 | I11: ODIVELAS | J11: CANECAS | K11: 24 | L11: CANADA | M11: R.JOSE VIANA,LT.11 A R/C ESQ,LOJA B | Q11: CANADA | R11: B | U11: 1685 | V11: 043 | W11: 0 | Y11: 0 | Z11: 0 | AA11: 0 | AB11: 1 | AF11: 4217 | AH11: COMERCIO | AL11: 4-MEDIA | AM11: E | AN11: 46,48 | AO11: 162,86 | AP11: 1 | AS11: 147B723F2C37A7F36304C30DF4EBFB7F55C513E191C88AB1B1DA0DDA7DCF7952 | AT11: 110000 | AU11: LISBOA | AV11: 111600 | AW11: ODIVELAS | AZ11: CANECAS | BA11: 24 | BB11: CANADA | BC11: R.JOSE VIANA,LT.11 A R/C ESQ,LOJA B | BG11: CANADA | BK11: 1685 | BL11: 043 | BM11: 0 | BO11: 0 | BP11: 0 | BQ11: 0 | BR11: 1 | BS11: CONS REGISTO PREDIAL DE ODIVELAS | BT11: ODIV | BV11: 4217 | BW11: B | BX11: COMERCIO | CB11: 4-MEDIA | CC11: E | CD11: 46,48 | CE11: 162,86 | CF11: 2 | CH11: =+IF(C11=AS11,0,1) -> 0 | CI11: =+IF(D11=AT11,0,1) -> 0 | CJ11: =+IF(E11=AU11,0,1) -> 0 | CK11: =+IF(F11=AV11,0,1) -> 0 | CL11: =+IF(G11=AW11,0,1) -> 0 | CM11: =+IF(H11=AX11,0,1) -> 1 | CN11: =+IF(I11=AY11,0,1) -> 1 | CO11: =+IF(J11=AZ11,0,1) -> 0 | ... DO11: =+IF(AJ11=BZ11,0,1) -> 0 | DP11: =+AJ11 -> 0 | DQ11: =+BZ11 -> 0 | DR11: =+IF(AK11=CA11,0,1) -> 0 | DS11: =+AK11 -> 0 | DT11: =+CA11 -> 0 | DU11: =+IF(AL11=CB11,0,1) -> 0 | DV11: =+IF(AM11=CC11,0,1) -> 0 | DW11: =+IF(AN11=CD11,0,1) -> 0 | DX11: =+IF(AO11=CE11,0,1) -> 0 | DY11: =+SUM(CH11:DO11,DR11,DU11:DX11) -> 6 | DZ11: =+COUNTBLANK(C11:AO11) -> 13 | EA11: =+COUNTBLANK(AS11:CE11) -> 13 | EB11: =+IF(AND(DZ11=EA11,DY11=0),"IGUAL CAMPOS PREENCH",IF(DZ11<=EA11,"AUX 1 COM + CAMPOS PREENC OU IGUAL","AUX 2 COM + CAMPOS PREENC")) -> AUX 1 COM + CAMPOS PREENC OU IGUAL | EC11: Diferenças nos registos enviados & Sem diferenças nos dados recebidos
C12: 14B4C236717B8D8B9B231B45E4F8ED57463C910D534AB35AC873CAE083B68CA7 | D12: 180000 | E12: VISEU | F12: 180500 | G12: LAMEGO | H12: 180510 | I12: LALIM | J12: LALIM | K12: 08 | L12: QUINTA | M12: DOS MELOS/ QUINTA DO TERREIRO | N12: S/N | Q12: QUINTA | U12: 5100 | V12: 550 | W12: 1424 | X12: 0001 | Y12: 0 | Z12: 0 | AA12: 0 | AB12: 0 | AF12: R=541U=1002,2003,949 | AH12: OUTRAS | AL12: 5-MEDIA BAJA | AM12: D | AN12: 40,81 | AO12: 145,83 | AP12: 1 | AR12: 0032145956900000 | AS12: 14B4C236717B8D8B9B231B45E4F8ED57463C910D534AB35AC873CAE083B68CA7 | AT12: 180000 | AU12: VISEU | AV12: 180500 | AW12: LAMEGO | AX12: 180510 | AY12: LALIM | AZ12: LALIM | BA12: 08 | BB12: QUINTA | BC12: DOS MELOS/ QUINTA DO TERREIRO | BD12: S/N | BG12: QUINTA | BK12: 5100 | BL12: 550 | BM12: 1424 | BN12: 0001 | BO12: 0 | BP12: 0 | BQ12: 0 | BR12: 0 | BV12: R=541U=1002,2003,949 | BX12: OUTRAS | BZ12: F | CA12: 5-MEDIA BAJA | CB12: 5-MEDIA BAJA | CC12: D | CD12: 40,81 | CE12: 145,83 | CF12: 2 | CH12: =+IF(C12=AS12,0,1) -> 0 | CI12: =+IF(D12=AT12,0,1) -> 0 | CJ12: =+IF(E12=AU12,0,1) -> 0 | CK12: =+IF(F12=AV12,0,1) -> 0 | CL12: =+IF(G12=AW12,0,1) -> 0 | CM12: =+IF(H12=AX12,0,1) -> 0 | CN12: =+IF(I12=AY12,0,1) -> 0 | CO12: =+IF(J12=AZ12,0,1) -> 0 | ... DO12: =+IF(AJ12=BZ12,0,1) -> 1 | DP12: =+AJ12 -> 0 | DQ12: =+BZ12 -> F | DR12: =+IF(AK12=CA12,0,1) -> 1 | DS12: =+AK12 -> 0 | DT12: =+CA12 -> 5-MEDIA BAJA | DU12: =+IF(AL12=CB12,0,1) -> 0 | DV12: =+IF(AM12=CC12,0,1) -> 0 | DW12: =+IF(AN12=CD12,0,1) -> 0 | DX12: =+IF(AO12=CE12,0,1) -> 0 | DY12: =+SUM(CH12:DO12,DR12,DU12:DX12) -> 2 | DZ12: =+COUNTBLANK(C12:AO12) -> 12 | EA12: =+COUNTBLANK(AS12:CE12) -> 10 | EB12: =+IF(AND(DZ12=EA12,DY12=0),"IGUAL CAMPOS PREENCH",IF(DZ12<=EA12,"AUX 1 COM + CAMPOS PREENC OU IGUAL","AUX 2 COM + CAMPOS PREENC")) -> AUX 2 COM + CAMPOS PREENC | EC12: Diferenças nos registos enviados & Sem diferenças nos dados recebidos
C13: 153272274E7E370673A26E325BDE3F09886D81CD3CFFBA25A3BCC4914177CF0F | D13: 140000 | E13: SANTARÉM | F13: 140500 | G13: BENAVENTE | H13: 140503 | I13: SANTO ESTÉVÃO | J13: SANTO ESTEVAO | K13: 01 | L13: RUA | M13: MANUEL MARTINS ALVES | N13: 42 | Q13: RUA | U13: 2130 | V13: 121 | W13: 415 | Y13: 0 | Z13: 0 | AA13: 0 | AB13: 1 | AF13: 1092, CRP 26622 | AH13: COMERCIO | AL13: 3-ALTA | AM13: B- | AN13: 54,81 | AO13: 195,26 | AP13: 1 | AR13: 0032174208500000 | AS13: 153272274E7E370673A26E325BDE3F09886D81CD3CFFBA25A3BCC4914177CF0F | AT13: 140000 | AU13: SANTARÉM | AV13: 140500 | AW13: BENAVENTE | AX13: 140503 | AY13: SANTO ESTÉVÃO | AZ13: SANTO ESTEVAO | BA13: 01 | BB13: RUA | BC13: MANUEL MARTINS ALVES | BD13: 42 | BG13: RUA | BK13: 2130 | BL13: 121 | BM13: 415 | BO13: 0 | BP13: 0 | BQ13: 0 | BR13: 1 | BV13: 1092, CRP 26622 | BX13: COMERCIO | CB13: 3-ALTA | CC13: B- | CD13: 54,81 | CE13: 195,26 | CF13: 2 | CH13: =+IF(C13=AS13,0,1) -> 0 | CI13: =+IF(D13=AT13,0,1) -> 0 | CJ13: =+IF(E13=AU13,0,1) -> 0 | CK13: =+IF(F13=AV13,0,1) -> 0 | CL13: =+IF(G13=AW13,0,1) -> 0 | CM13: =+IF(H13=AX13,0,1) -> 0 | CN13: =+IF(I13=AY13,0,1) -> 0 | CO13: =+IF(J13=AZ13,0,1) -> 0 | ... DO13: =+IF(AJ13=BZ13,0,1) -> 0 | DP13: =+AJ13 -> 0 | DQ13: =+BZ13 -> 0 | DR13: =+IF(AK13=CA13,0,1) -> 0 | DS13: =+AK13 -> 0 | DT13: =+CA13 -> 0 | DU13: =+IF(AL13=CB13,0,1) -> 0 | DV13: =+IF(AM13=CC13,0,1) -> 0 | DW13: =+IF(AN13=CD13,0,1) -> 0 | DX13: =+IF(AO13=CE13,0,1) -> 0 | DY13: =+SUM(CH13:DO13,DR13,DU13:DX13) -> 0 | DZ13: =+COUNTBLANK(C13:AO13) -> 13 | EA13: =+COUNTBLANK(AS13:CE13) -> 13 | EB13: =+IF(AND(DZ13=EA13,DY13=0),"IGUAL CAMPOS PREENCH",IF(DZ13<=EA13,"AUX 1 COM + CAMPOS PREENC OU IGUAL","AUX 2 COM + CAMPOS PREENC")) -> IGUAL CAMPOS PREENCH | EC13: Registo duplicado (todos os campos iguais) & Sem diferenças nos dados recebidos
B14: 0832151796300000 | C14: 15331653E4F7C182018F115CBD8621CEE46E0E7E06D410273545E507BED2384D | D14: 310000 | E14: ILHA DA MADEIRA | F14: 310300 | G14: FUNCHAL | H14: 310310 | I14: FUNCHAL (SE) | J14: SE | K14: 01 | L14: RUA | M14: RUA FERNAO ORNELAS 28 A 36 | N14: 000000 | Q14: RUA | R14: 0000871 | U14: 9050 | V14: 021 | W14: 957 | X14: 1955 | Y14: 0 | Z14: 0 | AA14: 0 | AB14: 1 | AF14: 955 | AH14: COMERCIO | AJ14: D | AK14: 5-MEDIA BAJA | AL14: 5-MEDIA BAJA | AM14: E | AN14: 46,11 | AO14: 90,3 | AP14: 1 | AS14: 15331653E4F7C182018F115CBD8621CEE46E0E7E06D410273545E507BED2384D | AT14: 310000 | AU14: ILHA DA MADEIRA | AV14: 310300 | AW14: FUNCHAL | AX14: 310310 | AY14: FUNCHAL (SE) | AZ14: SE | BA14: 01 | BB14: RUA | BC14: RUA FERNAO ORNELAS 28 A 36 | BD14: 000000 | BG14: RUA | BH14: 0000871 | BK14: 9050 | BL14: 021 | BM14: 957 | BN14: 1955 | BO14: 0 | BP14: 0 | BQ14: 0 | BR14: 1 | BV14: 955 | BX14: COMERCIO | CB14: 5-MEDIA BAJA | CC14: E | CD14: 46,11 | CE14: 90,3 | CF14: 2 | CH14: =+IF(C14=AS14,0,1) -> 0 | CI14: =+IF(D14=AT14,0,1) -> 0 | CJ14: =+IF(E14=AU14,0,1) -> 0 | CK14: =+IF(F14=AV14,0,1) -> 0 | CL14: =+IF(G14=AW14,0,1) -> 0 | CM14: =+IF(H14=AX14,0,1) -> 0 | CN14: =+IF(I14=AY14,0,1) -> 0 | CO14: =+IF(J14=AZ14,0,1) -> 0 | ... DO14: =+IF(AJ14=BZ14,0,1) -> 1 | DP14: =+AJ14 -> D | DQ14: =+BZ14 -> 0 | DR14: =+IF(AK14=CA14,0,1) -> 1 | DS14: =+AK14 -> 5-MEDIA BAJA | DT14: =+CA14 -> 0 | DU14: =+IF(AL14=CB14,0,1) -> 0 | DV14: =+IF(AM14=CC14,0,1) -> 0 | DW14: =+IF(AN14=CD14,0,1) -> 0 | DX14: =+IF(AO14=CE14,0,1) -> 0 | DY14: =+SUM(CH14:DO14,DR14,DU14:DX14) -> 2 | DZ14: =+COUNTBLANK(C14:AO14) -> 9 | EA14: =+COUNTBLANK(AS14:CE14) -> 11 | EB14: =+IF(AND(DZ14=EA14,DY14=0),"IGUAL CAMPOS PREENCH",IF(DZ14<=EA14,"AUX 1 COM + CAMPOS PREENC OU IGUAL","AUX 2 COM + CAMPOS PREENC")) -> AUX 1 COM + CAMPOS PREENC OU IGUAL | EC14: Diferenças nos registos enviados & Sem diferenças nos dados recebidos
C15: 1538E071C4B711D5724E54F56F53DDF97E59F0C093CD5F0A2A8666580BFBED18 | D15: 200000 | E15: HORTA | F15: 200500 | G15: MADALENA | H15: 200504 | I15: MADALENA | J15: MADALENA | K15: 02 | L15: AVENIDA | M15: AV. PADRE NUNES DA ROSA | N15: 000000 | Q15: AVENIDA | R15: 0001759 | U15: 9950 | V15: 302 | W15: 1815 | X15: 1986 | Y15: 0 | Z15: 0 | AA15: 0 | AB15: 0 | AC15: CONSERV.MACHICO | AD15: 145 | AE15: 0001759 | AF15: 1162 | AG15: PREDIO | AH15: OUTRAS | AL15: 5-MEDIA BAJA | AM15: F | AN15: 83,33 | AO15: 292,46 | AP15: 1 | AR15: 0832151471300000 | AS15: 1538E071C4B711D5724E54F56F53DDF97E59F0C093CD5F0A2A8666580BFBED18 | AT15: 200000 | AU15: HORTA | AV15: 200500 | AW15: MADALENA | AX15: 200504 | AY15: MADALENA | AZ15: MADALENA | BA15: 02 | BB15: AVENIDA | BC15: AV. PADRE NUNES DA ROSA | BD15: 000000 | BG15: AVENIDA | BH15: 0001759 | BK15: 9950 | BL15: 302 | BM15: 1815 | BN15: 1986 | BO15: 0 | BP15: 0 | BQ15: 0 | BR15: 0 | BS15: CONSERV.MACHICO | BT15: 145 | BU15: 0001759 | BV15: 1162 | BW15: PREDIO | BX15: OUTRAS | BZ15: E | CA15: 5-MEDIA BAJA | CB15: 5-MEDIA BAJA | CC15: F | CD15: 83,33 | CE15: 292,46 | CF15: 2 | CH15: =+IF(C15=AS15,0,1) -> 0 | CI15: =+IF(D15=AT15,0,1) -> 0 | CJ15: =+IF(E15=AU15,0,1) -> 0 | CK15: =+IF(F15=AV15,0,1) -> 0 | CL15: =+IF(G15=AW15,0,1) -> 0 | CM15: =+IF(H15=AX15,0,1) -> 0 | CN15: =+IF(I15=AY15,0,1) -> 0 | CO15: =+IF(J15=AZ15,0,1) -> 0 | ... DO15: =+IF(AJ15=BZ15,0,1) -> 1 | DP15: =+AJ15 -> 0 | DQ15: =+BZ15 -> E | DR15: =+IF(AK15=CA15,0,1) -> 1 | DS15: =+AK15 -> 0 | DT15: =+CA15 -> 5-MEDIA BAJA | DU15: =+IF(AL15=CB15,0,1) -> 0 | DV15: =+IF(AM15=CC15,0,1) -> 0 | DW15: =+IF(AN15=CD15,0,1) -> 0 | DX15: =+IF(AO15=CE15,0,1) -> 0 | DY15: =+SUM(CH15:DO15,DR15,DU15:DX15) -> 2 | DZ15: =+COUNTBLANK(C15:AO15) -> 7 | EA15: =+COUNTBLANK(AS15:CE15) -> 5 | EB15: =+IF(AND(DZ15=EA15,DY15=0),"IGUAL CAMPOS PREENCH",IF(DZ15<=EA15,"AUX 1 COM + CAMPOS PREENC OU IGUAL","AUX 2 COM + CAMPOS PREENC")) -> AUX 2 COM + CAMPOS PREENC | EC15: Diferenças nos registos enviados & Sem diferenças nos dados recebidos
C16: 15AB245B1BD23A3472CE070AE294BC50A6A16A1CB397675B691FB3EB04D8338D | D16: 170000 | E16: VILA REAL | F16: 171300 | G16: VILA POUCA DE AGUIAR | H16: 171311 | I16: TELOES | J16: FERREIRINHO | K16: 16 | L16: LUGAR | M16: FERREIRINHO ESTRADA MUNICIPAL CM | N16: 1165 | Q16: LUGAR | U16: 5450 | V16: 283 | W16: 578 | Y16: 0 | Z16: 0 | AA16: 0 | AB16: 0 | AF16: 1868 | AH16: OUTRAS | AL16: 5-MEDIA BAJA | AM16: G | AN16: 88,62 | AO16: 308,48 | AP16: 1 | AR16: 0032168223300000 | AS16: 15AB245B1BD23A3472CE070AE294BC50A6A16A1CB397675B691FB3EB04D8338D | AT16: 170000 | AU16: VILA REAL | AV16: 171300 | AW16: VILA POUCA DE AGUIAR | AX16: 171311 | AY16: TELOES | AZ16: FERREIRINHO | BA16: 16 | BB16: LUGAR | BC16: FERREIRINHO ESTRADA MUNICIPAL CM | BD16: 1165 | BG16: LUGAR | BK16: 5450 | BL16: 283 | BM16: 578 | BO16: 0 | BP16: 0 | BQ16: 0 | BR16: 0 | BV16: 1868 | BX16: OUTRAS | CB16: 5-MEDIA BAJA | CC16: G | CD16: 88,62 | CE16: 308,48 | CF16: 2 | CH16: =+IF(C16=AS16,0,1) -> 0 | CI16: =+IF(D16=AT16,0,1) -> 0 | CJ16: =+IF(E16=AU16,0,1) -> 0 | CK16: =+IF(F16=AV16,0,1) -> 0 | CL16: =+IF(G16=AW16,0,1) -> 0 | CM16: =+IF(H16=AX16,0,1) -> 0 | CN16: =+IF(I16=AY16,0,1) -> 0 | CO16: =+IF(J16=AZ16,0,1) -> 0 | ... DO16: =+IF(AJ16=BZ16,0,1) -> 0 | DP16: =+AJ16 -> 0 | DQ16: =+BZ16 -> 0 | DR16: =+IF(AK16=CA16,0,1) -> 0 | DS16: =+AK16 -> 0 | DT16: =+CA16 -> 0 | DU16: =+IF(AL16=CB16,0,1) -> 0 | DV16: =+IF(AM16=CC16,0,1) -> 0 | DW16: =+IF(AN16=CD16,0,1) -> 0 | DX16: =+IF(AO16=CE16,0,1) -> 0 | DY16: =+SUM(CH16:DO16,DR16,DU16:DX16) -> 0 | DZ16: =+COUNTBLANK(C16:AO16) -> 13 | EA16: =+COUNTBLANK(AS16:CE16) -> 13 | EB16: =+IF(AND(DZ16=EA16,DY16=0),"IGUAL CAMPOS PREENCH",IF(DZ16<=EA16,"AUX 1 COM + CAMPOS PREENC OU IGUAL","AUX 2 COM + CAMPOS PREENC")) -> IGUAL CAMPOS PREENCH | EC16: Registo duplicado (todos os campos iguais) & Sem diferenças nos dados recebidos
B17: 0632161455800000 | C17: 1A61B0B54F93318400F0FA0040016BD8DEB2664D126BA3E71F9B68784F191D22 | D17: 110000 | E17: LISBOA | F17: 110600 | G17: LISBOA | H17: 110618 | I17: LUMIAR | J17: TELHEIRAS | K17: 01 | L17: RUA | M17: PROF PINTO PEIXOTO | N17: 2 | Q17: RUA | U17: 1600 | V17: 820 | W17: 11 | X17: 1997 | Y17: 1 | Z17: 0 | AA17: 0 | AB17: 0 | AF17: 000N/A-JS - | AH17: ESTACIONAMENTO | AJ17: C | AK17: 5-MEDIA BAJA | AL17: 2-MUY ALTA | AM17: E | AN17: 47,97 | AO17: 171,42 | AP17: 1 | AS17: 1A61B0B54F93318400F0FA0040016BD8DEB2664D126BA3E71F9B68784F191D22 | AT17: 110000 | AU17: LISBOA | AV17: 110600 | AW17: LISBOA | AX17: 110618 | AY17: LUMIAR | AZ17: TELHEIRAS | BA17: 01 | BB17: RUA | BC17: PROF PINTO PEIXOTO | BD17: 2 | BG17: RUA | BK17: 1600 | BL17: 820 | BM17: 11 | BN17: 1997 | BO17: 1 | BP17: 0 | BQ17: 0 | BR17: 0 | BV17: 000N/A-JS - | BX17: ESTACIONAMENTO | CB17: 2-MUY ALTA | CC17: E | CD17: 47,97 | CE17: 171,42 | CF17: 2 | CH17: =+IF(C17=AS17,0,1) -> 0 | CI17: =+IF(D17=AT17,0,1) -> 0 | CJ17: =+IF(E17=AU17,0,1) -> 0 | CK17: =+IF(F17=AV17,0,1) -> 0 | CL17: =+IF(G17=AW17,0,1) -> 0 | CM17: =+IF(H17=AX17,0,1) -> 0 | CN17: =+IF(I17=AY17,0,1) -> 0 | CO17: =+IF(J17=AZ17,0,1) -> 0 | ... DO17: =+IF(AJ17=BZ17,0,1) -> 1 | DP17: =+AJ17 -> C | DQ17: =+BZ17 -> 0 | DR17: =+IF(AK17=CA17,0,1) -> 1 | DS17: =+AK17 -> 5-MEDIA BAJA | DT17: =+CA17 -> 0 | DU17: =+IF(AL17=CB17,0,1) -> 0 | DV17: =+IF(AM17=CC17,0,1) -> 0 | DW17: =+IF(AN17=CD17,0,1) -> 0 | DX17: =+IF(AO17=CE17,0,1) -> 0 | DY17: =+SUM(CH17:DO17,DR17,DU17:DX17) -> 2 | DZ17: =+COUNTBLANK(C17:AO17) -> 10 | EA17: =+COUNTBLANK(AS17:CE17) -> 12 | EB17: =+IF(AND(DZ17=EA17,DY17=0),"IGUAL CAMPOS PREENCH",IF(DZ17<=EA17,"AUX 1 COM + CAMPOS PREENC OU IGUAL","AUX 2 COM + CAMPOS PREENC")) -> AUX 1 COM + CAMPOS PREENC OU IGUAL | EC17: Diferenças nos registos enviados & Sem diferenças nos dados recebidos
B18: 0032177918700000 | C18: 1B81C5E59089BB5BF26CC4C39E2AC8117FB29EB8FAF13EF3F10180FD346876C3 | D18: 030000 | E18: BRAGA | F18: 030800 | G18: GUIMARAES | H18: 030823 | I18: GUARDIZELA | J18: GUARDIZELA | K18: 01 | L18: RUA | M18: PARQUE DESPORTIVO | N18: SN | Q18: RUA | U18: 4765 | V18: 474 | W18: 3140 | Y18: 0 | Z18: 0 | AA18: 0 | AB18: 1 | AF18: 1599 | AH18: INDUSTRIA | AL18: 5-MEDIA BAJA | AM18: B | AN18: 31,84 | AO18: 113,96 | AP18: 1 | AS18: 1B81C5E59089BB5BF26CC4C39E2AC8117FB29EB8FAF13EF3F10180FD346876C3 | AT18: 030000 | AU18: BRAGA | AV18: 030800 | AW18: GUIMARAES | AX18: 030823 | AY18: GUARDIZELA | AZ18: GUARDIZELA | BA18: 01 | BB18: RUA | BC18: PARQUE DESPORTIVO | BD18: SN | BG18: RUA | BK18: 4765 | BL18: 474 | BM18: 3140 | BO18: 0 | BP18: 0 | BQ18: 0 | BR18: 1 | BV18: 1599 | BX18: INDUSTRIA | CB18: 5-MEDIA BAJA | CC18: B | CD18: 31,84 | CE18: 113,96 | CF18: 2 | CH18: =+IF(C18=AS18,0,1) -> 0 | CI18: =+IF(D18=AT18,0,1) -> 0 | CJ18: =+IF(E18=AU18,0,1) -> 0 | CK18: =+IF(F18=AV18,0,1) -> 0 | CL18: =+IF(G18=AW18,0,1) -> 0 | CM18: =+IF(H18=AX18,0,1) -> 0 | CN18: =+IF(I18=AY18,0,1) -> 0 | CO18: =+IF(J18=AZ18,0,1) -> 0 | ... DO18: =+IF(AJ18=BZ18,0,1) -> 0 | DP18: =+AJ18 -> 0 | DQ18: =+BZ18 -> 0 | DR18: =+IF(AK18=CA18,0,1) -> 0 | DS18: =+AK18 -> 0 | DT18: =+CA18 -> 0 | DU18: =+IF(AL18=CB18,0,1) -> 0 | DV18: =+IF(AM18=CC18,0,1) -> 0 | DW18: =+IF(AN18=CD18,0,1) -> 0 | DX18: =+IF(AO18=CE18,0,1) -> 0 | DY18: =+SUM(CH18:DO18,DR18,DU18:DX18) -> 0 | DZ18: =+COUNTBLANK(C18:AO18) -> 13 | EA18: =+COUNTBLANK(AS18:CE18) -> 13 | EB18: =+IF(AND(DZ18=EA18,DY18=0),"IGUAL CAMPOS PREENCH",IF(DZ18<=EA18,"AUX 1 COM + CAMPOS PREENC OU IGUAL","AUX 2 COM + CAMPOS PREENC")) -> IGUAL CAMPOS PREENCH | EC18: Registo duplicado (todos os campos iguais) & Sem diferenças nos dados recebidos
B19: 0090167041700000 | C19: 1B83F1101317B1FB8481DB719F9EC2BB9C289898E165B0C3F82FB8428E226649 | D19: 110000 | E19: LISBOA | F19: 110600 | G19: LISBOA | H19: 110627 | I19: SACRAMENTO | J19: ROSSIO | K19: 01 | L19: RUA | M19: PRIMEIRO DE DEZEMBRO | N19: 87 | Q19: RUA | U19: 1200 | V19: 358 | W19: 44 | Y19: 0 | Z19: 0 | AA19: 0 | AB19: 1 | AF19: "CPU 608, CRP 26 - ""B""" | AH19: COMERCIO | AJ19: D | AK19: 5-MEDIA BAJA | AL19: 5-MEDIA BAJA | AM19: C | AN19: 46,78 | AO19: 166,85 | AP19: 1 | AS19: 1B83F1101317B1FB8481DB719F9EC2BB9C289898E165B0C3F82FB8428E226649 | AT19: 110000 | AU19: LISBOA | AV19: 110600 | AW19: LISBOA | AX19: 110627 | AY19: SACRAMENTO | AZ19: ROSSIO | BA19: 01 | BB19: RUA | BC19: PRIMEIRO DE DEZEMBRO | BD19: 87 | BG19: RUA | BK19: 1200 | BL19: 358 | BM19: 44 | BO19: 0 | BP19: 0 | BQ19: 0 | BR19: 1 | BV19: "CPU 608, CRP 26 - ""B""" | BX19: COMERCIO | CB19: 5-MEDIA BAJA | CC19: C | CD19: 46,78 | CE19: 166,85 | CF19: 2 | CH19: =+IF(C19=AS19,0,1) -> 0 | CI19: =+IF(D19=AT19,0,1) -> 0 | CJ19: =+IF(E19=AU19,0,1) -> 0 | CK19: =+IF(F19=AV19,0,1) -> 0 | CL19: =+IF(G19=AW19,0,1) -> 0 | CM19: =+IF(H19=AX19,0,1) -> 0 | CN19: =+IF(I19=AY19,0,1) -> 0 | CO19: =+IF(J19=AZ19,0,1) -> 0 | ... DO19: =+IF(AJ19=BZ19,0,1) -> 1 | DP19: =+AJ19 -> D | DQ19: =+BZ19 -> 0 | DR19: =+IF(AK19=CA19,0,1) -> 1 | DS19: =+AK19 -> 5-MEDIA BAJA | DT19: =+CA19 -> 0 | DU19: =+IF(AL19=CB19,0,1) -> 0 | DV19: =+IF(AM19=CC19,0,1) -> 0 | DW19: =+IF(AN19=CD19,0,1) -> 0 | DX19: =+IF(AO19=CE19,0,1) -> 0 | DY19: =+SUM(CH19:DO19,DR19,DU19:DX19) -> 2 | DZ19: =+COUNTBLANK(C19:AO19) -> 11 | EA19: =+COUNTBLANK(AS19:CE19) -> 13 | EB19: =+IF(AND(DZ19=EA19,DY19=0),"IGUAL CAMPOS PREENCH",IF(DZ19<=EA19,"AUX 1 COM + CAMPOS PREENC OU IGUAL","AUX 2 COM + CAMPOS PREENC")) -> AUX 1 COM + CAMPOS PREENC OU IGUAL | EC19: Diferenças nos registos enviados & Sem diferenças nos dados recebidos
C20: 1BD8EAF47520159507244DD03A0BBD07E257B0627C20521B4E78AC614871C348 | D20: 030000 | E20: BRAGA | F20: 030300 | G20: BRAGA | H20: 030314 | I20: FERREIROS | J20: FERREIROS | K20: 01 | L20: RUA | M20: DAS AUSTRALIAS | N20: 6 | Q20: LARGO | U20: 4700 | V20: 001 | W20: 1000 | X20: 2002 | Y20: 0 | Z20: 0 | AA20: 0 | AB20: 1 | AF20: 1008 | AH20: ARMAZEM | AJ20: C | AK20: 5-MEDIA BAJA | AL20: 5-MEDIA BAJA | AM20: C | AN20: 31,07 | AO20: 111,29 | AP20: 1 | AR20: 0032171713500000 | AS20: 1BD8EAF47520159507244DD03A0BBD07E257B0627C20521B4E78AC614871C348 | AT20: 030000 | AU20: BRAGA | AV20: 030300 | AW20: BRAGA | AX20: 030314 | AY20: FERREIROS | AZ20: FERREIROS | BA20: 01 | BB20: RUA | BC20: DAS AUSTRALIAS | BD20: 6 | BG20: LARGO | BK20: 4700 | BL20: 001 | BM20: 1000 | BN20: 2002 | BO20: 0 | BP20: 0 | BQ20: 0 | BR20: 1 | BV20: 1008 | BX20: ARMAZEM | BZ20: C | CA20: 5-MEDIA BAJA | CB20: 5-MEDIA BAJA | CC20: C | CD20: 31,07 | CE20: 111,29 | CF20: 2 | CH20: =+IF(C20=AS20,0,1) -> 0 | CI20: =+IF(D20=AT20,0,1) -> 0 | CJ20: =+IF(E20=AU20,0,1) -> 0 | CK20: =+IF(F20=AV20,0,1) -> 0 | CL20: =+IF(G20=AW20,0,1) -> 0 | CM20: =+IF(H20=AX20,0,1) -> 0 | CN20: =+IF(I20=AY20,0,1) -> 0 | CO20: =+IF(J20=AZ20,0,1) -> 0 | ... DO20: =+IF(AJ20=BZ20,0,1) -> 0 | DP20: =+AJ20 -> C | DQ20: =+BZ20 -> C | DR20: =+IF(AK20=CA20,0,1) -> 0 | DS20: =+AK20 -> 5-MEDIA BAJA | DT20: =+CA20 -> 5-MEDIA BAJA | DU20: =+IF(AL20=CB20,0,1) -> 0 | DV20: =+IF(AM20=CC20,0,1) -> 0 | DW20: =+IF(AN20=CD20,0,1) -> 0 | DX20: =+IF(AO20=CE20,0,1) -> 0 | DY20: =+SUM(CH20:DO20,DR20,DU20:DX20) -> 0 | DZ20: =+COUNTBLANK(C20:AO20) -> 10 | EA20: =+COUNTBLANK(AS20:CE20) -> 10 | EB20: =+IF(AND(DZ20=EA20,DY20=0),"IGUAL CAMPOS PREENCH",IF(DZ20<=EA20,"AUX 1 COM + CAMPOS PREENC OU IGUAL","AUX 2 COM + CAMPOS PREENC")) -> IGUAL CAMPOS PREENCH | EC20: Registo duplicado (todos os campos iguais) & Sem diferenças nos dados recebidos
C21: 1C5E30DF11D101C67E5B0F79960497F7547501981D9EEFA39090B05AC5DFF576 | D21: 080000 | E21: FARO | F21: 080100 | G21: ALBUFEIRA | H21: 080101 | I21: ALBUFEIRA | J21: VARZEA DA ORADA | K21: 01 | L21: RUA | M21: MARINA ALBUFEIRA LOTE 4 | N21: 000000 | Q21: RUA | R21: 0012228 | U21: 8200 | V21: 000 | W21: 98 | X21: 2009 | Y21: 0 | Z21: 0 | AA21: 0 | AB21: 0 | AH21: OUTRAS | AL21: 5-MEDIA BAJA | AM21: E | AN21: 37,72 | AO21: 135 | AP21: 1 | AR21: 0832149937800000 | AS21: 1C5E30DF11D101C67E5B0F79960497F7547501981D9EEFA39090B05AC5DFF576 | AT21: 080000 | AU21: FARO | AV21: 080100 | AW21: ALBUFEIRA | AX21: 080101 | AY21: ALBUFEIRA | AZ21: VARZEA DA ORADA | BA21: 01 | BB21: RUA | BC21: MARINA ALBUFEIRA LOTE 4 | BD21: 000000 | BG21: RUA | BH21: 0012228 | BK21: 8200 | BL21: 000 | BM21: 98 | BN21: 2009 | BO21: 0 | BP21: 0 | BQ21: 0 | BR21: 0 | BX21: OUTRAS | BZ21: C | CA21: 4-MEDIA | CB21: 5-MEDIA BAJA | CC21: E | CD21: 37,72 | CE21: 135 | CF21: 2 | CH21: =+IF(C21=AS21,0,1) -> 0 | CI21: =+IF(D21=AT21,0,1) -> 0 | CJ21: =+IF(E21=AU21,0,1) -> 0 | CK21: =+IF(F21=AV21,0,1) -> 0 | CL21: =+IF(G21=AW21,0,1) -> 0 | CM21: =+IF(H21=AX21,0,1) -> 0 | CN21: =+IF(I21=AY21,0,1) -> 0 | CO21: =+IF(J21=AZ21,0,1) -> 0 | ... DO21: =+IF(AJ21=BZ21,0,1) -> 1 | DP21: =+AJ21 -> 0 | DQ21: =+BZ21 -> C | DR21: =+IF(AK21=CA21,0,1) -> 1 | DS21: =+AK21 -> 0 | DT21: =+CA21 -> 4-MEDIA | DU21: =+IF(AL21=CB21,0,1) -> 0 | DV21: =+IF(AM21=CC21,0,1) -> 0 | DW21: =+IF(AN21=CD21,0,1) -> 0 | DX21: =+IF(AO21=CE21,0,1) -> 0 | DY21: =+SUM(CH21:DO21,DR21,DU21:DX21) -> 2 | DZ21: =+COUNTBLANK(C21:AO21) -> 12 | EA21: =+COUNTBLANK(AS21:CE21) -> 10 | EB21: =+IF(AND(DZ21=EA21,DY21=0),"IGUAL CAMPOS PREENCH",IF(DZ21<=EA21,"AUX 1 COM + CAMPOS PREENC OU IGUAL","AUX 2 COM + CAMPOS PREENC")) -> AUX 2 COM + CAMPOS PREENC | EC21: Diferenças nos registos enviados & Sem diferenças nos dados recebidos
B22: 0632161442300000 | C22: 2130118936472A7A11E6CAF4D09486C0F5CB0CD6FC3BC845568FBFC7F3CD0FB2 | D22: 100000 | E22: LEIRIA | F22: 100900 | G22: LEIRIA | H22: 100912 | I22: LEIRIA | J22: AROEIRA | U22: 2425 | W22: 580 | X22: 2000 | Y22: 0 | Z22: 0 | AA22: 0 | AB22: 1 | AF22: 000006380 - | AH22: ARMAZEM | AJ22: D | AK22: 5-MEDIA BAJA | AL22: 5-MEDIA BAJA | AM22: D | AN22: 33,93 | AO22: 121,5 | AP22: 1 | AS22: 2130118936472A7A11E6CAF4D09486C0F5CB0CD6FC3BC845568FBFC7F3CD0FB2 | AT22: 100000 | AU22: LEIRIA | AV22: 100900 | AW22: LEIRIA | AX22: 100912 | AY22: LEIRIA | AZ22: AROEIRA | BK22: 2425 | BM22: 580 | BN22: 2000 | BO22: 0 | BP22: 0 | BQ22: 0 | BR22: 1 | BV22: 000006380 - | BX22: ARMAZEM | CB22: 5-MEDIA BAJA | CC22: D | CD22: 33,93 | CE22: 121,5 | CF22: 2 | CH22: =+IF(C22=AS22,0,1) -> 0 | CI22: =+IF(D22=AT22,0,1) -> 0 | CJ22: =+IF(E22=AU22,0,1) -> 0 | CK22: =+IF(F22=AV22,0,1) -> 0 | CL22: =+IF(G22=AW22,0,1) -> 0 | CM22: =+IF(H22=AX22,0,1) -> 0 | CN22: =+IF(I22=AY22,0,1) -> 0 | CO22: =+IF(J22=AZ22,0,1) -> 0 | ... DO22: =+IF(AJ22=BZ22,0,1) -> 1 | DP22: =+AJ22 -> D | DQ22: =+BZ22 -> 0 | DR22: =+IF(AK22=CA22,0,1) -> 1 | DS22: =+AK22 -> 5-MEDIA BAJA | DT22: =+CA22 -> 0 | DU22: =+IF(AL22=CB22,0,1) -> 0 | DV22: =+IF(AM22=CC22,0,1) -> 0 | DW22: =+IF(AN22=CD22,0,1) -> 0 | DX22: =+IF(AO22=CE22,0,1) -> 0 | DY22: =+SUM(CH22:DO22,DR22,DU22:DX22) -> 2 | DZ22: =+COUNTBLANK(C22:AO22) -> 16 | EA22: =+COUNTBLANK(AS22:CE22) -> 18 | EB22: =+IF(AND(DZ22=EA22,DY22=0),"IGUAL CAMPOS PREENCH",IF(DZ22<=EA22,"AUX 1 COM + CAMPOS PREENC OU IGUAL","AUX 2 COM + CAMPOS PREENC")) -> AUX 1 COM + CAMPOS PREENC OU IGUAL | EC22: Diferenças nos registos enviados & Sem diferenças nos dados recebidos
C23: 2134E6DACC3AE819D70338C9C6668948FD1F6EB4644EB7266A2902B198C84B17 | D23: 430000 | E23: ILHA TERCEIRA-AÇORES | F23: 430200 | G23: VILA PRAIA DA VITÓRIA | H23: 430208 | I23: PRAIA DA VITÓRIA (SANTA CRUZ) | J23: PRAIA DA VITORIA SANTA CRUZ | K23: 24 | L23: CANADA | M23: CRUZ DO MARCO, RIBEIRA STO ANTONIO | N23: NA | Q23: CANADA | U23: 9760 | V23: 500 | W23: 1 | Y23: 0 | Z23: 0 | AA23: 0 | AB23: 0 | AD23: 999 | AH23: OUTRAS | AL23: 5-MEDIA BAJA | AM23: D | AN23: 32,97 | AO23: 64,54 | AP23: 1 | AS23: 2134E6DACC3AE819D70338C9C6668948FD1F6EB4644EB7266A2902B198C84B17 | AT23: 430000 | AU23: ILHA TERCEIRA-AÇORES | AV23: 430200 | AW23: VILA PRAIA DA VITÓRIA | AX23: 430208 | AY23: PRAIA DA VITÓRIA (SANTA CRUZ) | AZ23: PRAIA DA VITORIA SANTA CRUZ | BA23: 24 | BB23: CANADA | BC23: CRUZ DO MARCO, RIBEIRA STO ANTONIO | BD23: NA | BG23: CANADA | BK23: 9760 | BL23: 500 | BM23: 1 | BO23: 0 | BP23: 0 | BQ23: 0 | BR23: 0 | BV23: 3799 | BX23: OUTRAS | CB23: 5-MEDIA BAJA | CC23: D | CD23: 32,97 | CE23: 64,54 | CF23: 2 | CH23: =+IF(C23=AS23,0,1) -> 0 | CI23: =+IF(D23=AT23,0,1) -> 0 | CJ23: =+IF(E23=AU23,0,1) -> 0 | CK23: =+IF(F23=AV23,0,1) -> 0 | CL23: =+IF(G23=AW23,0,1) -> 0 | CM23: =+IF(H23=AX23,0,1) -> 0 | CN23: =+IF(I23=AY23,0,1) -> 0 | CO23: =+IF(J23=AZ23,0,1) -> 0 | ... DO23: =+IF(AJ23=BZ23,0,1) -> 0 | DP23: =+AJ23 -> 0 | DQ23: =+BZ23 -> 0 | DR23: =+IF(AK23=CA23,0,1) -> 0 | DS23: =+AK23 -> 0 | DT23: =+CA23 -> 0 | DU23: =+IF(AL23=CB23,0,1) -> 0 | DV23: =+IF(AM23=CC23,0,1) -> 0 | DW23: =+IF(AN23=CD23,0,1) -> 0 | DX23: =+IF(AO23=CE23,0,1) -> 0 | DY23: =+SUM(CH23:DO23,DR23,DU23:DX23) -> 2 | DZ23: =+COUNTBLANK(C23:AO23) -> 13 | EA23: =+COUNTBLANK(AS23:CE23) -> 13 | EB23: =+IF(AND(DZ23=EA23,DY23=0),"IGUAL CAMPOS PREENCH",IF(DZ23<=EA23,"AUX 1 COM + CAMPOS PREENC OU IGUAL","AUX 2 COM + CAMPOS PREENC")) -> AUX 1 COM + CAMPOS PREENC OU IGUAL | EC23: Diferenças nos registos enviados & Sem diferenças nos dados recebidos
B24: 0090164040300000 | C24: 226F896BBC1056D468F3379DDC35DC996B5B9DBABE24EE4FCB203C4636866FDE | D24: 130000 | E24: PORTO | F24: 131200 | G24: PORTO | H24: 131204 | I24: CEDOFEITA | J24: PORTO | K24: 01 | L24: RUA | M24: DO BONJARDIM | N24: 401 | Q24: RUA | U24: 4000 | V24: 010 | W24: 17079 | Y24: 0 | Z24: 0 | AA24: 0 | AB24: 0 | AF24: 9842, CRP 1196 | AH24: OUTRAS | AJ24: D | AK24: 4-MEDIA | AL24: 4-MEDIA | AM24: C | AN24: 29,76 | AO24: 105,83 | AP24: 1 | AS24: 226F896BBC1056D468F3379DDC35DC996B5B9DBABE24EE4FCB203C4636866FDE | AT24: 130000 | AU24: PORTO | AV24: 131200 | AW24: PORTO | AX24: 131204 | AY24: CEDOFEITA | AZ24: PORTO | BA24: 01 | BB24: RUA | BC24: DO BONJARDIM | BD24: 401 | BG24: RUA | BK24: 4000 | BL24: 010 | BM24: 17079 | BO24: 0 | BP24: 0 | BQ24: 0 | BR24: 0 | BV24: 9842, CRP 1196 | BX24: OUTRAS | CB24: 4-MEDIA | CC24: C | CD24: 29,76 | CE24: 105,83 | CF24: 2 | CH24: =+IF(C24=AS24,0,1) -> 0 | CI24: =+IF(D24=AT24,0,1) -> 0 | CJ24: =+IF(E24=AU24,0,1) -> 0 | CK24: =+IF(F24=AV24,0,1) -> 0 | CL24: =+IF(G24=AW24,0,1) -> 0 | CM24: =+IF(H24=AX24,0,1) -> 0 | CN24: =+IF(I24=AY24,0,1) -> 0 | CO24: =+IF(J24=AZ24,0,1) -> 0 | ... DO24: =+IF(AJ24=BZ24,0,1) -> 1 | DP24: =+AJ24 -> D | DQ24: =+BZ24 -> 0 | DR24: =+IF(AK24=CA24,0,1) -> 1 | DS24: =+AK24 -> 4-MEDIA | DT24: =+CA24 -> 0 | DU24: =+IF(AL24=CB24,0,1) -> 0 | DV24: =+IF(AM24=CC24,0,1) -> 0 | DW24: =+IF(AN24=CD24,0,1) -> 0 | DX24: =+IF(AO24=CE24,0,1) -> 0 | DY24: =+SUM(CH24:DO24,DR24,DU24:DX24) -> 2 | DZ24: =+COUNTBLANK(C24:AO24) -> 11 | EA24: =+COUNTBLANK(AS24:CE24) -> 13 | EB24: =+IF(AND(DZ24=EA24,DY24=0),"IGUAL CAMPOS PREENCH",IF(DZ24<=EA24,"AUX 1 COM + CAMPOS PREENC OU IGUAL","AUX 2 COM + CAMPOS PREENC")) -> AUX 1 COM + CAMPOS PREENC OU IGUAL | EC24: Diferenças nos registos enviados & Sem diferenças nos dados recebidos
C25: 248030C59E972331FDC3901958C918B76C7EFD8766D8828934B28ABA1FFDE615 | D25: 010000 | E25: AVEIRO | F25: 010900 | G25: FEIRA | H25: 010902 | I25: ARRIFANA | J25: ARRIFANA | K25: 01 | L25: RUA | M25: TERRAS STA MARIA | N25: 1845 | Q25: RUA | U25: 3700 | V25: 400 | W25: 125 | X25: 1970 | Y25: 1 | Z25: 1 | AA25: 0 | AB25: 0 | AF25: 0003048-B - | AH25: HABITACAO | AL25: 3-ALTA | AM25: F | AN25: 67,53 | AO25: 241,14 | AP25: 1 | AR25: 0632161338300000 | AS25: 248030C59E972331FDC3901958C918B76C7EFD8766D8828934B28ABA1FFDE615 | AT25: 010000 | AU25: AVEIRO | AV25: 010900 | AW25: FEIRA | AX25: 010902 | AY25: ARRIFANA | AZ25: ARRIFANA | BA25: 01 | BB25: RUA | BC25: TERRAS STA MARIA | BD25: 1845 | BG25: RUA | BK25: 3700 | BL25: 400 | BM25: 125 | BN25: 1970 | BO25: 1 | BP25: 1 | BQ25: 0 | BR25: 0 | BV25: 0003048-B - | BX25: HABITACAO | CB25: 3-ALTA | CC25: F | CD25: 67,53 | CE25: 241,14 | CF25: 2 | CH25: =+IF(C25=AS25,0,1) -> 0 | CI25: =+IF(D25=AT25,0,1) -> 0 | CJ25: =+IF(E25=AU25,0,1) -> 0 | CK25: =+IF(F25=AV25,0,1) -> 0 | CL25: =+IF(G25=AW25,0,1) -> 0 | CM25: =+IF(H25=AX25,0,1) -> 0 | CN25: =+IF(I25=AY25,0,1) -> 0 | CO25: =+IF(J25=AZ25,0,1) -> 0 | ... DO25: =+IF(AJ25=BZ25,0,1) -> 0 | DP25: =+AJ25 -> 0 | DQ25: =+BZ25 -> 0 | DR25: =+IF(AK25=CA25,0,1) -> 0 | DS25: =+AK25 -> 0 | DT25: =+CA25 -> 0 | DU25: =+IF(AL25=CB25,0,1) -> 0 | DV25: =+IF(AM25=CC25,0,1) -> 0 | DW25: =+IF(AN25=CD25,0,1) -> 0 | DX25: =+IF(AO25=CE25,0,1) -> 0 | DY25: =+SUM(CH25:DO25,DR25,DU25:DX25) -> 0 | DZ25: =+COUNTBLANK(C25:AO25) -> 12 | EA25: =+COUNTBLANK(AS25:CE25) -> 12 | EB25: =+IF(AND(DZ25=EA25,DY25=0),"IGUAL CAMPOS PREENCH",IF(DZ25<=EA25,"AUX 1 COM + CAMPOS PREENC OU IGUAL","AUX 2 COM + CAMPOS PREENC")) -> IGUAL CAMPOS PREENCH | EC25: Registo duplicado (todos os campos iguais) & Sem diferenças nos dados recebidos
C26: 26DE055FB23D4226EAB9251A982B6EF37F811FD49E06F2FFB7F8983AECEA1178 | D26: 310000 | E26: ILHA DA MADEIRA | F26: 310300 | G26: FUNCHAL | H26: 310307 | I26: S. MARTINHO | J26: S. MARTINHO | K26: 09 | L26: ESTRADA | M26: MONUMENTAL - HOTEL BAIA AZUL | N26: . | Q26: ESTRADA | U26: 9000 | V26: 001 | W26: 7034 | Y26: 0 | Z26: 0 | AA26: 0 | AB26: 0 | AF26: ART. 3718, CRP 1842 | AH26: OUTRAS | AL26: 4-MEDIA | AM26: C | AN26: 16,43 | AO26: 32,21 | AP26: 1 | AR26: 0032145088800000 | AS26: 26DE055FB23D4226EAB9251A982B6EF37F811FD49E06F2FFB7F8983AECEA1178 | AT26: 310000 | AU26: ILHA DA MADEIRA | AV26: 310300 | AW26: FUNCHAL | AX26: 310307 | AY26: S. MARTINHO | AZ26: S. MARTINHO | BA26: 09 | BB26: ESTRADA | BC26: MONUMENTAL - HOTEL BAIA AZUL | BD26: . | BG26: ESTRADA | BK26: 9000 | BL26: 001 | BM26: 7034 | BO26: 0 | BP26: 0 | BQ26: 0 | BR26: 0 | BV26: ART. 3718, CRP 1842 | BX26: OUTRAS | BZ26: C | CA26: 5-MEDIA BAJA | CB26: 4-MEDIA | CC26: C | CD26: 16,43 | CE26: 32,21 | CF26: 2 | CH26: =+IF(C26=AS26,0,1) -> 0 | CI26: =+IF(D26=AT26,0,1) -> 0 | CJ26: =+IF(E26=AU26,0,1) -> 0 | CK26: =+IF(F26=AV26,0,1) -> 0 | CL26: =+IF(G26=AW26,0,1) -> 0 | CM26: =+IF(H26=AX26,0,1) -> 0 | CN26: =+IF(I26=AY26,0,1) -> 0 | CO26: =+IF(J26=AZ26,0,1) -> 0 | ... DO26: =+IF(AJ26=BZ26,0,1) -> 1 | DP26: =+AJ26 -> 0 | DQ26: =+BZ26 -> C | DR26: =+IF(AK26=CA26,0,1) -> 1 | DS26: =+AK26 -> 0 | DT26: =+CA26 -> 5-MEDIA BAJA | DU26: =+IF(AL26=CB26,0,1) -> 0 | DV26: =+IF(AM26=CC26,0,1) -> 0 | DW26: =+IF(AN26=CD26,0,1) -> 0 | DX26: =+IF(AO26=CE26,0,1) -> 0 | DY26: =+SUM(CH26:DO26,DR26,DU26:DX26) -> 2 | DZ26: =+COUNTBLANK(C26:AO26) -> 13 | EA26: =+COUNTBLANK(AS26:CE26) -> 11 | EB26: =+IF(AND(DZ26=EA26,DY26=0),"IGUAL CAMPOS PREENCH",IF(DZ26<=EA26,"AUX 1 COM + CAMPOS PREENC OU IGUAL","AUX 2 COM + CAMPOS PREENC")) -> AUX 2 COM + CAMPOS PREENC | EC26: Diferenças nos registos enviados & Sem diferenças nos dados recebidos
