Workbook
Name acumulad: [1]Portada!$C$22
Name ECms: [2]ECms!$C$3:$AA$1154
Name ECmsAcum: [2]ECms!$AC$3:$AZ$1154
Name EManuais: [3]EManuais!$C$3:$AA$61
Name EManuaisAcum: [3]EManuais!$AC$3:$AZ$61
Name ENeg: [2]ENeg!$C$3:$AA$777
Name ENegAcum: [2]ENeg!$AC$3:$AZ$777
Name ERnd: [3]ERnd!$C$3:$AA$622
Name ERndAcum: [3]ERnd!$AC$3:$AZ$622
Name ERsc: [3]ERsc!$C$3:$AA$31
Name ERscAcum: [3]ERsc!$AC$3:$AZ$31
Name EssLatest: "112002"
Name EssOptions: "A1100000000120000000001100020_010010"
Name EVE: [3]EVE!$C$3:$AA$7
Name MES_ACTUAL: [4]Portada!$C$22
Name OCms: [2]OCms!$C$3:$AA$1154
Name OCmsAcum: [2]OCms!$AC$3:$AZ$1154
Name OManuais: [3]OManuais!$C$3:$AA$61
Name OManuaisAcum: [3]OManuais!$AC$3:$AZ$61
Name ONeg: [2]ONeg!$C$3:$AA$777
Name ONegAcum: [2]ONeg!$AC$3:$AZ$777
Name ORnd: [3]ORnd!$C$3:$AA$622
Name ORndAcum: [3]ORnd!$AC$3:$AZ$622
Name ORsc: [3]ORsc!$C$3:$AA$31
Name ORscAcum: [3]ORsc!$AC$3:$AZ$31
Name OVE: [3]OVE!$C$3:$AA$7
Name RRPPMM_ML: [5]AVANCEPAIS!$A$15:$D$30
Name RRPPMMUS: [5]AVANCEPAIS!$C$5:$C$9
Name ver: [1]Portada!$C$22

Sheet QUERY_FOR_TRNSTRANSPOSED_0008
F1: =SUBTOTAL(9,F5:F1234) -> 4.9752306e+08 | G1: =SUBTOTAL(9,G5:G1234) -> 4.7685326e+08 | H1: =SUBTOTAL(9,H5:H1234) -> 20669750 | I1: =SUBTOTAL(9,I5:I1234) -> 20669795 | L1: =I1-H1 -> 45 | M1: =SUBTOTAL(9,M5:M1234) -> 1.5552561e+08
I2: =F1245+F1248+F1251 -> 20343268 | L2: =I1-I2 -> 326526.57
A4: METACOM | C4: COPERAC | D4: CONTA | E4: CONTA IFRS | F4: TOTAL_MIS 2024 Ajustado | G4: TOTAL_CONTABILIDADE 2024 | H4: MIS_vs_CONTABILIDADE | J4: Análise | L4: Produtos Fora da Contabilidade | M4: Valor | O4: Classificação Financeiras / Não Financeiras | P4: Classe Contas Contabilisticas | Q4: OREX | R4: GG | S4: RO | T4: Reclassificadas Margem
A5: AA1000 | B5: =VLOOKUP(A5,'[6]Fin vs NFin'!$A$4:$B$568,2,FALSE) -> !Manutenção Empresa | C5: 046 | D5: 825942 | E5: =VLOOKUP(D5,[6]Arvore!$N$8:$Q$6855,4,FALSE) -> 51950 | F5: 4418012.9 | G5: 4418052.6 | H5: -39.658411 | I5: -39.658411 | O5: =VLOOKUP(QUERY_FOR_TRNSTRANSPOSED_0008!A5,'[6]Fin vs NFin'!$A$4:$F$568,6,FALSE) -> Não Financeiras | P5: =LEFT(D5,2) -> 82
A6: AA1100 | B6: =VLOOKUP(A6,'[6]Fin vs NFin'!$A$4:$B$568,2,FALSE) -> !Manutenção Particulares | C6: 24L | D6: 825942 | E6: =VLOOKUP(D6,[6]Arvore!$N$8:$Q$6855,4,FALSE) -> 51950 | F6: 343483.76 | G6: 342992.18 | H6: 491.58 | I6: =SUM(H6:H7) -> 4.08 | O6: =VLOOKUP(QUERY_FOR_TRNSTRANSPOSED_0008!A6,'[6]Fin vs NFin'!$A$4:$F$568,6,FALSE) -> Não Financeiras | P6: =LEFT(D6,2) -> 82
A7: AA1100 | B7: =VLOOKUP(A7,'[6]Fin vs NFin'!$A$4:$B$568,2,FALSE) -> !Manutenção Particulares | C7: 41H | D7: 825942 | E7: =VLOOKUP(D7,[6]Arvore!$N$8:$Q$6855,4,FALSE) -> 51950 | F7: 175672.28 | G7: 176159.78 | H7: -487.5 | O7: =VLOOKUP(QUERY_FOR_TRNSTRANSPOSED_0008!A7,'[6]Fin vs NFin'!$A$4:$F$568,6,FALSE) -> Não Financeiras | P7: =LEFT(D7,2) -> 82
A8: AA1150 | B8: =VLOOKUP(A8,'[6]Fin vs NFin'!$A$4:$B$568,2,FALSE) -> !Manut.Client.Nat.Financ. | C8: CTM | D8: 825942 | E8: =VLOOKUP(D8,[6]Arvore!$N$8:$Q$6855,4,FALSE) -> 51950 | F8: -12680.77 | G8: -12680.77 | H8: 1.8189894e-12 | I8: 1.8189894e-12 | O8: =VLOOKUP(QUERY_FOR_TRNSTRANSPOSED_0008!A8,'[6]Fin vs NFin'!$A$4:$F$568,6,FALSE) -> Não Financeiras | P8: =LEFT(D8,2) -> 82
A9: AA1190 | B9: =VLOOKUP(A9,'[6]Fin vs NFin'!$A$4:$B$568,2,FALSE) -> !Manutenção Outras | C9: 2AE | D9: 825933 | E9: =VLOOKUP(D9,[6]Arvore!$N$8:$Q$6855,4,FALSE) -> 512010 | F9: 88299.76 | G9: 66554.64 | H9: 21745.12 | I9: -7.2759576e-12 | O9: =VLOOKUP(QUERY_FOR_TRNSTRANSPOSED_0008!A9,'[6]Fin vs NFin'!$A$4:$F$568,6,FALSE) -> Não Financeiras | P9: =LEFT(D9,2) -> 82
A10: AA1190 | B10: =VLOOKUP(A10,'[6]Fin vs NFin'!$A$4:$B$568,2,FALSE) -> !Manutenção Outras | C10: 2AG | D10: 825933 | E10: =VLOOKUP(D10,[6]Arvore!$N$8:$Q$6855,4,FALSE) -> 512010 | F10: 16984 | G10: 38729.12 | H10: -21745.12 | O10: =VLOOKUP(QUERY_FOR_TRNSTRANSPOSED_0008!A10,'[6]Fin vs NFin'!$A$4:$F$568,6,FALSE) -> Não Financeiras | P10: =LEFT(D10,2) -> 82
A11: AA1190 | B11: =VLOOKUP(A11,'[6]Fin vs NFin'!$A$4:$B$568,2,FALSE) -> !Manutenção Outras | C11: 8NY | D11: 825942 | E11: =VLOOKUP(D11,[6]Arvore!$N$8:$Q$6855,4,FALSE) -> 51950 | F11: -24 | G11: -24 | H11: 0 | O11: =VLOOKUP(QUERY_FOR_TRNSTRANSPOSED_0008!A11,'[6]Fin vs NFin'!$A$4:$F$568,6,FALSE) -> Não Financeiras | P11: =LEFT(D11,2) -> 82
A12: AA1190 | B12: =VLOOKUP(A12,'[6]Fin vs NFin'!$A$4:$B$568,2,FALSE) -> !Manutenção Outras | C12: VFF | D12: 825942 | E12: =VLOOKUP(D12,[6]Arvore!$N$8:$Q$6855,4,FALSE) -> 51950 | F12: -2.2 | G12: -2.2 | H12: 0 | O12: =VLOOKUP(QUERY_FOR_TRNSTRANSPOSED_0008!A12,'[6]Fin vs NFin'!$A$4:$F$568,6,FALSE) -> Não Financeiras | P12: =LEFT(D12,2) -> 82
A13: AA1200 | B13: =VLOOKUP(A13,'[6]Fin vs NFin'!$A$4:$B$568,2,FALSE) -> !Extractos | C13: !NY | D13: 89223 | E13: =VLOOKUP(D13,[6]Arvore!$N$8:$Q$6855,4,FALSE) -> 55083 | F13: 19485.59 | G13: 19560.91 | H13: -75.32 | I13: -2.1884716e-12 | O13: =VLOOKUP(QUERY_FOR_TRNSTRANSPOSED_0008!A13,'[6]Fin vs NFin'!$A$4:$F$568,6,FALSE) -> Não Financeiras | P13: =LEFT(D13,2) -> 89 | Q13: =VLOOKUP(D13,[6]Mapeamento!$A$38:$C$497,3,FALSE) -> OREX
A14: AA1200 | B14: =VLOOKUP(A14,'[6]Fin vs NFin'!$A$4:$B$568,2,FALSE) -> !Extractos | C14: 3EX | D14: 89223 | E14: =VLOOKUP(D14,[6]Arvore!$N$8:$Q$6855,4,FALSE) -> 55083 | F14: 68.08 | G14: 40.92 | H14: 27.16 | O14: =VLOOKUP(QUERY_FOR_TRNSTRANSPOSED_0008!A14,'[6]Fin vs NFin'!$A$4:$F$568,6,FALSE) -> Não Financeiras | P14: =LEFT(D14,2) -> 89 | Q14: =VLOOKUP(D14,[6]Mapeamento!$A$38:$C$497,3,FALSE) -> OREX
A15: AA1200 | B15: =VLOOKUP(A15,'[6]Fin vs NFin'!$A$4:$B$568,2,FALSE) -> !Extractos | C15: 8NW | D15: 89223 | E15: =VLOOKUP(D15,[6]Arvore!$N$8:$Q$6855,4,FALSE) -> 55083 | F15: -11.16 | G15: -111.6 | H15: 100.44 | O15: =VLOOKUP(QUERY_FOR_TRNSTRANSPOSED_0008!A15,'[6]Fin vs NFin'!$A$4:$F$568,6,FALSE) -> Não Financeiras | P15: =LEFT(D15,2) -> 89 | Q15: =VLOOKUP(D15,[6]Mapeamento!$A$38:$C$497,3,FALSE) -> OREX
A16: AA1200 | B16: =VLOOKUP(A16,'[6]Fin vs NFin'!$A$4:$B$568,2,FALSE) -> !Extractos | C16: 8P2 | D16: 89223 | E16: =VLOOKUP(D16,[6]Arvore!$N$8:$Q$6855,4,FALSE) -> 55083 | F16: 109.6 | G16: 109.6 | H16: 0 | O16: =VLOOKUP(QUERY_FOR_TRNSTRANSPOSED_0008!A16,'[6]Fin vs NFin'!$A$4:$F$568,6,FALSE) -> Não Financeiras | P16: =LEFT(D16,2) -> 89 | Q16: =VLOOKUP(D16,[6]Mapeamento!$A$38:$C$497,3,FALSE) -> OREX
A17: AA1200 | B17: =VLOOKUP(A17,'[6]Fin vs NFin'!$A$4:$B$568,2,FALSE) -> !Extractos | C17: EX1 | D17: 89223 | E17: =VLOOKUP(D17,[6]Arvore!$N$8:$Q$6855,4,FALSE) -> 55083 | F17: 23301.72 | G17: 23354 | H17: -52.28 | O17: =VLOOKUP(QUERY_FOR_TRNSTRANSPOSED_0008!A17,'[6]Fin vs NFin'!$A$4:$F$568,6,FALSE) -> Não Financeiras | P17: =LEFT(D17,2) -> 89 | Q17: =VLOOKUP(D17,[6]Mapeamento!$A$38:$C$497,3,FALSE) -> OREX
A18: AA1300 | B18: =VLOOKUP(A18,'[6]Fin vs NFin'!$A$4:$B$568,2,FALSE) -> !Levantamento Balcão | C18: !OX | D18: 825979 | E18: =VLOOKUP(D18,[6]Arvore!$N$8:$Q$6855,4,FALSE) -> 5194 | F18: 754692 | G18: 760932 | H18: -6240 | I18: 0 | O18: =VLOOKUP(QUERY_FOR_TRNSTRANSPOSED_0008!A18,'[6]Fin vs NFin'!$A$4:$F$568,6,FALSE) -> Não Financeiras | P18: =LEFT(D18,2) -> 82
A19: AA1300 | B19: =VLOOKUP(A19,'[6]Fin vs NFin'!$A$4:$B$568,2,FALSE) -> !Levantamento Balcão | C19: 8NP | D19: 825979 | E19: =VLOOKUP(D19,[6]Arvore!$N$8:$Q$6855,4,FALSE) -> 5194 | F19: -36 | G19: -318 | H19: 282 | O19: =VLOOKUP(QUERY_FOR_TRNSTRANSPOSED_0008!A19,'[6]Fin vs NFin'!$A$4:$F$568,6,FALSE) -> Não Financeiras | P19: =LEFT(D19,2) -> 82
A20: AA1300 | B20: =VLOOKUP(A20,'[6]Fin vs NFin'!$A$4:$B$568,2,FALSE) -> !Levantamento Balcão | C20: AVB | D20: 825979 | E20: =VLOOKUP(D20,[6]Arvore!$N$8:$Q$6855,4,FALSE) -> 5194 | F20: -783.3 | G20: -6741.3 | H20: 5958 | O20: =VLOOKUP(QUERY_FOR_TRNSTRANSPOSED_0008!A20,'[6]Fin vs NFin'!$A$4:$F$568,6,FALSE) -> Não Financeiras | P20: =LEFT(D20,2) -> 82
A21: AA1310 | B21: =VLOOKUP(A21,'[6]Fin vs NFin'!$A$4:$B$568,2,FALSE) -> !Depósitos ao Balcão | C21: 3MM | D21: 825949 | E21: =VLOOKUP(D21,[6]Arvore!$N$8:$Q$6855,4,FALSE) -> 51959 | F21: 54189.8 | G21: 13584.66 | H21: 40605.14 | I21: -4.5474735e-13 | O21: =VLOOKUP(QUERY_FOR_TRNSTRANSPOSED_0008!A21,'[6]Fin vs NFin'!$A$4:$F$568,6,FALSE) -> Não Financeiras | P21: =LEFT(D21,2) -> 82
A22: AA1310 | B22: =VLOOKUP(A22,'[6]Fin vs NFin'!$A$4:$B$568,2,FALSE) -> !Depósitos ao Balcão | C22: 3MN | D22: 825949 | E22: =VLOOKUP(D22,[6]Arvore!$N$8:$Q$6855,4,FALSE) -> 51959 | F22: 20294.25 | G22: 60052.25 | H22: -39758 | O22: =VLOOKUP(QUERY_FOR_TRNSTRANSPOSED_0008!A22,'[6]Fin vs NFin'!$A$4:$F$568,6,FALSE) -> Não Financeiras | P22: =LEFT(D22,2) -> 82
A23: AA1310 | B23: =VLOOKUP(A23,'[6]Fin vs NFin'!$A$4:$B$568,2,FALSE) -> !Depósitos ao Balcão | C23: 3MO | D23: 825949 | E23: =VLOOKUP(D23,[6]Arvore!$N$8:$Q$6855,4,FALSE) -> 51959 | F23: 1755.36 | G23: 2602.5 | H23: -847.14 | O23: =VLOOKUP(QUERY_FOR_TRNSTRANSPOSED_0008!A23,'[6]Fin vs NFin'!$A$4:$F$568,6,FALSE) -> Não Financeiras | P23: =LEFT(D23,2) -> 82
A24: AA1410 | B24: =VLOOKUP(A24,'[6]Fin vs NFin'!$A$4:$B$568,2,FALSE) -> !Cms Gestão Contas Part. | C24: 23L | D24: 825946 | E24: =VLOOKUP(D24,[6]Arvore!$N$8:$Q$6855,4,FALSE) -> 51959 | F24: 51940781 | G24: 52749148 | H24: -808367.67 | I24: =SUM(H24:H26) -> -310.20794 | O24: =VLOOKUP(QUERY_FOR_TRNSTRANSPOSED_0008!A24,'[6]Fin vs NFin'!$A$4:$F$568,6,FALSE) -> Não Financeiras | P24: =LEFT(D24,2) -> 82
A25: AA1410 | B25: =VLOOKUP(A25,'[6]Fin vs NFin'!$A$4:$B$568,2,FALSE) -> !Cms Gestão Contas Part. | C25: 23O | D25: 825946 | E25: =VLOOKUP(D25,[6]Arvore!$N$8:$Q$6855,4,FALSE) -> 51959 | F25: 944096.42 | G25: 934724 | H25: 9372.42 | O25: =VLOOKUP(QUERY_FOR_TRNSTRANSPOSED_0008!A25,'[6]Fin vs NFin'!$A$4:$F$568,6,FALSE) -> Não Financeiras | P25: =LEFT(D25,2) -> 82
A26: AA1410 | B26: =VLOOKUP(A26,'[6]Fin vs NFin'!$A$4:$B$568,2,FALSE) -> !Cms Gestão Contas Part. | C26: CTP | D26: 825946 | E26: =VLOOKUP(D26,[6]Arvore!$N$8:$Q$6855,4,FALSE) -> 51959 | F26: 29055771 | G26: 28257086 | H26: 798685.04 | O26: =VLOOKUP(QUERY_FOR_TRNSTRANSPOSED_0008!A26,'[6]Fin vs NFin'!$A$4:$F$568,6,FALSE) -> Não Financeiras | P26: =LEFT(D26,2) -> 82
A27: AA1420 | B27: =VLOOKUP(A27,'[6]Fin vs NFin'!$A$4:$B$568,2,FALSE) -> !Cms Gestão Contas Neg. | C27: !PE | D27: 825943 | E27: =VLOOKUP(D27,[6]Arvore!$N$8:$Q$6855,4,FALSE) -> 51950 | F27: 20166320 | G27: 20274230 | H27: -107910.26 | I27: =SUM(H27:H30) -> 0.3833667 | O27: =VLOOKUP(QUERY_FOR_TRNSTRANSPOSED_0008!A27,'[6]Fin vs NFin'!$A$4:$F$568,6,FALSE) -> Não Financeiras | P27: =LEFT(D27,2) -> 82
A28: AA1420 | B28: =VLOOKUP(A28,'[6]Fin vs NFin'!$A$4:$B$568,2,FALSE) -> !Cms Gestão Contas Neg. | C28: 23K | D28: 825943 | E28: =VLOOKUP(D28,[6]Arvore!$N$8:$Q$6855,4,FALSE) -> 51950 | F28: 763 | G28: -98741.66 | H28: 99504.66 | O28: =VLOOKUP(QUERY_FOR_TRNSTRANSPOSED_0008!A28,'[6]Fin vs NFin'!$A$4:$F$568,6,FALSE) -> Não Financeiras | P28: =LEFT(D28,2) -> 82
A29: AA1420 | B29: =VLOOKUP(A29,'[6]Fin vs NFin'!$A$4:$B$568,2,FALSE) -> !Cms Gestão Contas Neg. | C29: 23R | D29: 825943 | E29: =VLOOKUP(D29,[6]Arvore!$N$8:$Q$6855,4,FALSE) -> 51950 | F29: 1625 | G29: 1625 | H29: 0 | O29: =VLOOKUP(QUERY_FOR_TRNSTRANSPOSED_0008!A29,'[6]Fin vs NFin'!$A$4:$F$568,6,FALSE) -> Não Financeiras | P29: =LEFT(D29,2) -> 82
A30: AA1420 | B30: =VLOOKUP(A30,'[6]Fin vs NFin'!$A$4:$B$568,2,FALSE) -> !Cms Gestão Contas Neg. | C30: EGE | D30: 825943 | E30: =VLOOKUP(D30,[6]Arvore!$N$8:$Q$6855,4,FALSE) -> 51950 | F30: -786.51 | G30: -9192.4934 | H30: 8405.9834 | O30: =VLOOKUP(QUERY_FOR_TRNSTRANSPOSED_0008!A30,'[6]Fin vs NFin'!$A$4:$F$568,6,FALSE) -> Não Financeiras | P30: =LEFT(D30,2) -> 82
A31: AA1431 | B31: =VLOOKUP(A31,'[6]Fin vs NFin'!$A$4:$B$568,2,FALSE) -> !Domiciliações/Cash Back | C31: BBE | D31: 71904011 | E31: =VLOOKUP(D31,[6]Arvore!$N$8:$Q$6855,4,FALSE) -> 4161599 | F31: -5908506.9 | G31: -5908506.9 | H31: 9.3132257e-10 | I31: 9.3132257e-10 | O31: =VLOOKUP(QUERY_FOR_TRNSTRANSPOSED_0008!A31,'[6]Fin vs NFin'!$A$4:$F$568,6,FALSE) -> Não Financeiras | P31: =LEFT(D31,2) -> 71
A32: AA1432 | B32: =VLOOKUP(A32,'[6]Fin vs NFin'!$A$4:$B$568,2,FALSE) -> !Gasolina/Cash Back | C32: BBB | D32: 71904010 | E32: =VLOOKUP(D32,[6]Arvore!$N$8:$Q$6855,4,FALSE) -> 4161599 | F32: -872953.72 | G32: -872302.87 | H32: -650.85 | I32: =SUM(H32:H36) -> -2.0941116e-10 | O32: =VLOOKUP(QUERY_FOR_TRNSTRANSPOSED_0008!A32,'[6]Fin vs NFin'!$A$4:$F$568,6,FALSE) -> Não Financeiras | P32: =LEFT(D32,2) -> 71
A33: AA1432 | B33: =VLOOKUP(A33,'[6]Fin vs NFin'!$A$4:$B$568,2,FALSE) -> !Gasolina/Cash Back | C33: BBC | D33: 71904013 | E33: =VLOOKUP(D33,[6]Arvore!$N$8:$Q$6855,4,FALSE) -> 4161599 | F33: -869701.57 | G33: -869701.57 | H33: -1.1641532e-10 | O33: =VLOOKUP(QUERY_FOR_TRNSTRANSPOSED_0008!A33,'[6]Fin vs NFin'!$A$4:$F$568,6,FALSE) -> Não Financeiras | P33: =LEFT(D33,2) -> 71
A34: AA1432 | B34: =VLOOKUP(A34,'[6]Fin vs NFin'!$A$4:$B$568,2,FALSE) -> !Gasolina/Cash Back | C34: BBX | D34: 71904013 | E34: =VLOOKUP(D34,[6]Arvore!$N$8:$Q$6855,4,FALSE) -> 4161599 | F34: -1419.15 | G34: -2070 | H34: 650.85 | O34: =VLOOKUP(QUERY_FOR_TRNSTRANSPOSED_0008!A34,'[6]Fin vs NFin'!$A$4:$F$568,6,FALSE) -> Não Financeiras | P34: =LEFT(D34,2) -> 71
A35: AA1432 | B35: =VLOOKUP(A35,'[6]Fin vs NFin'!$A$4:$B$568,2,FALSE) -> !Gasolina/Cash Back | C35: ONL | D35: 71904010 | E35: =VLOOKUP(D35,[6]Arvore!$N$8:$Q$6855,4,FALSE) -> 4161599 | F35: 257305.22 | G35: 257305.22 | H35: 0 | O35: =VLOOKUP(QUERY_FOR_TRNSTRANSPOSED_0008!A35,'[6]Fin vs NFin'!$A$4:$F$568,6,FALSE) -> Não Financeiras | P35: =LEFT(D35,2) -> 71
A36: AA1432 | B36: =VLOOKUP(A36,'[6]Fin vs NFin'!$A$4:$B$568,2,FALSE) -> !Gasolina/Cash Back | C36: ONL | D36: 71904013 | E36: =VLOOKUP(D36,[6]Arvore!$N$8:$Q$6855,4,FALSE) -> 4161599 | F36: 602249.57 | G36: 602249.57 | H36: 0 | O36: =VLOOKUP(QUERY_FOR_TRNSTRANSPOSED_0008!A36,'[6]Fin vs NFin'!$A$4:$F$568,6,FALSE) -> Não Financeiras | P36: =LEFT(D36,2) -> 71
A37: AA1433 | B37: =VLOOKUP(A37,'[6]Fin vs NFin'!$A$4:$B$568,2,FALSE) -> !Cross Segment/Cash Back | C37: S9K | D37: 71904015 | E37: =VLOOKUP(D37,[6]Arvore!$N$8:$Q$6855,4,FALSE) -> 4198 | F37: -10862.54 | G37: -10862.54 | H37: 0 | I37: 0 | O37: =VLOOKUP(QUERY_FOR_TRNSTRANSPOSED_0008!A37,'[6]Fin vs NFin'!$A$4:$F$568,6,FALSE) -> Não Financeiras | P37: =LEFT(D37,2) -> 71
A38: AA1434 | B38: =VLOOKUP(A38,'[6]Fin vs NFin'!$A$4:$B$568,2,FALSE) -> !IMI/Cash Back | C38: BBI | D38: 71904018 | E38: =VLOOKUP(D38,[6]Arvore!$N$8:$Q$6855,4,FALSE) -> 4161599 | F38: -1239134.9 | G38: -1239134.9 | H38: -2.3283064e-10 | I38: 0 | O38: =VLOOKUP(QUERY_FOR_TRNSTRANSPOSED_0008!A38,'[6]Fin vs NFin'!$A$4:$F$568,6,FALSE) -> Não Financeiras | P38: =LEFT(D38,2) -> 71
A39: AA1480 | B39: =VLOOKUP(A39,'[6]Fin vs NFin'!$A$4:$B$568,2,FALSE) -> !Tramitação Manual | C39: LD6 | D39: 8251212 | E39: =VLOOKUP(D39,[6]Arvore!$N$8:$Q$6855,4,FALSE) -> 5151212 | F39: 2333970.4 | G39: 2333970.4 | H39: 0 | I39: 0 | O39: =VLOOKUP(QUERY_FOR_TRNSTRANSPOSED_0008!A39,'[6]Fin vs NFin'!$A$4:$F$568,6,FALSE) -> Não Financeiras | P39: =LEFT(D39,2) -> 82
A40: AA1490 | B40: =VLOOKUP(A40,'[6]Fin vs NFin'!$A$4:$B$568,2,FALSE) -> !Outras DO | C40: !67 | D40: 825945 | E40: =VLOOKUP(D40,[6]Arvore!$N$8:$Q$6855,4,FALSE) -> 51959 | F40: 32704.88 | G40: 32742.32 | H40: -37.44 | I40: 342371.99 | O40: =VLOOKUP(QUERY_FOR_TRNSTRANSPOSED_0008!A40,'[6]Fin vs NFin'!$A$4:$F$568,6,FALSE) -> Não Financeiras | P40: =LEFT(D40,2) -> 82
A41: AA1490 | B41: =VLOOKUP(A41,'[6]Fin vs NFin'!$A$4:$B$568,2,FALSE) -> !Outras DO | C41: 38A | D41: 71904081 | E41: =VLOOKUP(D41,[6]Arvore!$N$8:$Q$6855,4,FALSE) -> 4198 | F41: 2011.68 | G41: 2011.68 | H41: 2.2737368e-13 | O41: =VLOOKUP(QUERY_FOR_TRNSTRANSPOSED_0008!A41,'[6]Fin vs NFin'!$A$4:$F$568,6,FALSE) -> Não Financeiras | P41: =LEFT(D41,2) -> 71
...
