Workbook
Name RefDateCell: '1. Dashboard'!$D$12

Sheet Instruções
B6: Instruções
C8: 1.
C9: 2.
C10: 3.

Sheet Param_RefDate
A1: Param_RefDate
A2: 2025-10-31

Sheet 1. Dashboard
B6: 1 Dashboard
B9: Controlos Reporte Bail-in
C12: Data de referência | D12: 2025-10-31
D15: MENU 1 | G15: MENU 2 | J15: NAVEGADOR
D18: TABELAS OUTPUT | G18: Processo (HUE vs CSV) | J18: Processo (HUE vs CSV)
D20: 1. Gerar Controlos | E20: [BOTÃO] | G20: 1. Gerar Controlos | H20: [BOTÃO] | J20: 1. Detalhe controlos às tabelas output | L20: [LINK]
J22: 2. Detalhe controlos ao processo (CSV) | L22: [LINK]
H29: DASHBOARD
C32: 1. Tabelas Output
C34: Mapa | D34: Total (#) | E34: OK (#) | F34: OK (%) | G34: NOK Justificados(#) | H34: NOK Justificados (%) | I34: NOK (#) | J34: NOK (%)
C35: B02.00 | D35: =+SUM(D36,D40) -> 304 | E35: =+SUM(E36,E40) -> 258 | F35: =IFERROR(E35/D35,0) -> 0.84868421 | G35: =+SUM(G36,G40) -> 8 | H35: =IFERROR(G35/D35,0) -> 0.026315789 | I35: =+SUM(I36,I40) -> 33 | J35: =IFERROR(I35/D35,0) -> 0.10855263
C36: Regulamentares (SRB) | D36: =+SUM(D37:D39) -> 156 | E36: =+SUM(E37:E39) -> 134 | F36: =IFERROR(E36/D36,0) -> 0.85897436 | G36: =+SUM(G37:G39) -> 6 | H36: =IFERROR(G36/D36,0) -> 0.038461538 | I36: =+SUM(I37:I39) -> 11 | J36: =IFERROR(I36/D36,0) -> 0.070512821
C37: High severity | D37: =+COUNTIFS('2.1. Regulamentares'!G:G,'1. Dashboard'!$C$35,'2.1. Regulamentares'!F:F,"h") -> 63 | E37: =+COUNTIFS('2.1. Regulamentares'!G:G,'1. Dashboard'!$C$35,'2.1. Regulamentares'!F:F,"h",'2.1. Regulamentares'!C:C,"=0") -> 53 | F37: =IFERROR(E37/D37,0) -> 0.84126984 | G37: =+COUNTIFS('2.1. Regulamentares'!G:G,'1. Dashboard'!$C$35,'2.1. Regulamentares'!F:F,"h",'2.1. Regulamentares'!C:C,">0",'2.1. Regulamentares'!I:I,"<>") -> 0 | H37: =IFERROR(G37/D37,0) -> 0 | I37: =+COUNTIFS('2.1. Regulamentares'!G:G,'1. Dashboard'!$C$35,'2.1. Regulamentares'!F:F,"h",'2.1. Regulamentares'!C:C,">0",'2.1. Regulamentares'!I:I,"") -> 5 | J37: =IFERROR(I37/D37,0) -> 0.079365079
C38: Warnings | D38: =+COUNTIFS('2.1. Regulamentares'!G:G,'1. Dashboard'!$C$35,'2.1. Regulamentares'!F:F,"w") -> 12 | E38: =+COUNTIFS('2.1. Regulamentares'!G:G,'1. Dashboard'!$C$35,'2.1. Regulamentares'!F:F,"w",'2.1. Regulamentares'!C:C,"=0") -> 11 | F38: =IFERROR(E38/D38,0) -> 0.91666667 | G38: =+COUNTIFS('2.1. Regulamentares'!G:G,'1. Dashboard'!$C$35,'2.1. Regulamentares'!F:F,"w",'2.1. Regulamentares'!C:C,">0",'2.1. Regulamentares'!I:I,"<>") -> 0 | H38: =IFERROR(G38/D38,0) -> 0 | I38: =+COUNTIFS('2.1. Regulamentares'!G:G,'1. Dashboard'!$C$35,'2.1. Regulamentares'!F:F,"w",'2.1. Regulamentares'!C:C,">0",'2.1. Regulamentares'!I:I,"") -> 1 | J38: =IFERROR(I38/D38,0) -> 0.083333333
C39: Formatos | D39: =+COUNTIFS('2.1. Regulamentares'!G:G,'1. Dashboard'!$C$35,'2.1. Regulamentares'!F:F,"f") -> 81 | E39: =+COUNTIFS('2.1. Regulamentares'!G:G,'1. Dashboard'!$C$35,'2.1. Regulamentares'!F:F,"f",'2.1. Regulamentares'!C:C,"=0") -> 70 | F39: =IFERROR(E39/D39,0) -> 0.86419753 | G39: =+COUNTIFS('2.1. Regulamentares'!G:G,'1. Dashboard'!$C$35,'2.1. Regulamentares'!F:F,"f",'2.1. Regulamentares'!C:C,">0",'2.1. Regulamentares'!I:I,"<>") -> 6 | H39: =IFERROR(G39/D39,0) -> 0.074074074 | I39: =+COUNTIFS('2.1. Regulamentares'!G:G,'1. Dashboard'!$C$35,'2.1. Regulamentares'!F:F,"f",'2.1. Regulamentares'!C:C,">0",'2.1. Regulamentares'!I:I,"") -> 5 | J39: =IFERROR(I39/D39,0) -> 0.061728395
C40: Outros | D40: =+SUM(D41:D44) -> 148 | E40: =+SUM(E41:E44) -> 124 | F40: =IFERROR(E40/D40,0) -> 0.83783784 | G40: =+SUM(G41:G44) -> 2 | H40: =IFERROR(G40/D40,0) -> 0.013513514 | I40: =+SUM(I41:I44) -> 22 | J40: =IFERROR(I40/D40,0) -> 0.14864865
C41: Validade (Missings/NULLS) | D41: =+COUNTIFS('2.2. Outros'!H:H,'1. Dashboard'!$C$35,'2.2. Outros'!D:D,"Validade") -> 73 | E41: =+COUNTIFS('2.2. Outros'!H:H,'1. Dashboard'!$C$35,'2.2. Outros'!D:D,"Validade",'2.2. Outros'!F:F,"0") -> 70 | F41: =IFERROR(E41/D41,0) -> 0.95890411 | G41: =+COUNTIFS('2.2. Outros'!H:H,'1. Dashboard'!$C$35,'2.2. Outros'!D:D,"Validade",'2.2. Outros'!F:F,"<>0",'2.2. Outros'!I:I,"<>") -> 1 | H41: =IFERROR(G41/D41,0) -> 0.01369863 | I41: =+COUNTIFS('2.2. Outros'!H:H,'1. Dashboard'!$C$35,'2.2. Outros'!D:D,"Validade",'2.2. Outros'!F:F,"<>0",'2.2. Outros'!I:I,"") -> 2 | J41: =IFERROR(I41/D41,0) -> 0.02739726
C42: Not applicables | D42: =+COUNTIFS('2.2. Outros'!H:H,'1. Dashboard'!$C$35,'2.2. Outros'!D:D,"Not applicable") -> 73 | E42: =+COUNTIFS('2.2. Outros'!H:H,'1. Dashboard'!$C$35,'2.2. Outros'!D:D,"Not applicable",'2.2. Outros'!F:F,"0") -> 52 | F42: =IFERROR(E42/D42,0) -> 0.71232877 | G42: =+COUNTIFS('2.2. Outros'!H:H,'1. Dashboard'!$C$35,'2.2. Outros'!D:D,"Not applicable",'2.2. Outros'!F:F,"<>0",'2.2. Outros'!I:I,"<>") -> 1 | H42: =IFERROR(G42/D42,0) -> 0.01369863 | I42: =+COUNTIFS('2.2. Outros'!H:H,'1. Dashboard'!$C$35,'2.2. Outros'!D:D,"Not applicable",'2.2. Outros'!F:F,"<>0",'2.2. Outros'!I:I,"") -> 20 | J42: =IFERROR(I42/D42,0) -> 0.2739726
C43: Duplicados | D43: =+COUNTIFS('2.2. Outros'!H:H,'1. Dashboard'!$C$35,'2.2. Outros'!D:D,"Duplicados") -> 1 | E43: =+COUNTIFS('2.2. Outros'!H:H,'1. Dashboard'!$C$35,'2.2. Outros'!D:D,"Duplicados",'2.2. Outros'!F:F,"0") -> 1 | F43: =IFERROR(E43/D43,0) -> 1 | G43: =+COUNTIFS('2.2. Outros'!H:H,'1. Dashboard'!$C$35,'2.2. Outros'!D:D,"Duplicados",'2.2. Outros'!F:F,"<>0",'2.2. Outros'!I:I,"<>") -> 0 | H43: =IFERROR(G43/D43,0) -> 0 | I43: =+COUNTIFS('2.2. Outros'!H:H,'1. Dashboard'!$C$35,'2.2. Outros'!D:D,"Duplicados",'2.2. Outros'!F:F,"<>0",'2.2. Outros'!I:I,"") -> 0 | J43: =IFERROR(I43/D43,0) -> 0
C44: Integridade entre tabelas | D44: =+COUNTIFS('2.2. Outros'!H:H,'1. Dashboard'!$C$35,'2.2. Outros'!D:D,"Integridade") -> 1 | E44: =+COUNTIFS('2.2. Outros'!H:H,'1. Dashboard'!$C$35,'2.2. Outros'!D:D,"Integridade",'2.2. Outros'!F:F,"0") -> 1 | F44: =IFERROR(E44/D44,0) -> 1 | G44: =+COUNTIFS('2.2. Outros'!H:H,'1. Dashboard'!$C$35,'2.2. Outros'!D:D,"Integridade",'2.2. Outros'!F:F,"<>0",'2.2. Outros'!I:I,"<>") -> 0 | H44: =IFERROR(G44/D44,0) -> 0 | I44: =+COUNTIFS('2.2. Outros'!H:H,'1. Dashboard'!$C$35,'2.2. Outros'!D:D,"Integridade",'2.2. Outros'!F:F,"<>0",'2.2. Outros'!I:I,"") -> 0 | J44: =IFERROR(I44/D44,0) -> 0
C45: B05.00 | D45: =+SUM(D46,D50) -> 20 | E45: =+SUM(E46,E50) -> 17 | F45: =IFERROR(E45/D45,0) -> 0.85 | G45: =+SUM(G46,G50) -> 2 | H45: =IFERROR(G45/D45,0) -> 0.1 | I45: =+SUM(I46,I50) -> 1 | J45: =IFERROR(I45/D45,0) -> 0.05
C46: Regulamentares (SRB) | D46: =+SUM(D47:D49) -> 19 | E46: =+SUM(E47:E49) -> 16 | F46: =IFERROR(E46/D46,0) -> 0.84210526 | G46: =+SUM(G47:G49) -> 2 | H46: =IFERROR(G46/D46,0) -> 0.10526316 | I46: =+SUM(I47:I49) -> 1 | J46: =IFERROR(I46/D46,0) -> 0.052631579
C47: High severity | D47: =+COUNTIFS('2.1. Regulamentares'!G:G,$C$45,'2.1. Regulamentares'!F:F,"h") -> 5 | E47: =+COUNTIFS('2.1. Regulamentares'!G:G,$C$45,'2.1. Regulamentares'!F:F,"h",'2.1. Regulamentares'!C:C,"=0") -> 4 | F47: =IFERROR(E47/D47,0) -> 0.8 | G47: =+COUNTIFS('2.1. Regulamentares'!G:G,$C$45,'2.1. Regulamentares'!F:F,"h",'2.1. Regulamentares'!C:C,">0",'2.1. Regulamentares'!I:I,"<>") -> 0 | H47: =IFERROR(G47/D47,0) -> 0 | I47: =+COUNTIFS('2.1. Regulamentares'!G:G,$C$45,'2.1. Regulamentares'!F:F,"h",'2.1. Regulamentares'!C:C,">0",'2.1. Regulamentares'!I:I,"") -> 1 | J47: =IFERROR(I47/D47,0) -> 0.2
C48: Warnings | D48: =+COUNTIFS('2.1. Regulamentares'!G:G,$C$45,'2.1. Regulamentares'!F:F,"w") -> 0 | E48: =+COUNTIFS('2.1. Regulamentares'!G:G,$C$45,'2.1. Regulamentares'!F:F,"w",'2.1. Regulamentares'!C:C,"=0") -> 0 | F48: =IFERROR(E48/D48,0) -> 0 | G48: =+COUNTIFS('2.1. Regulamentares'!G:G,$C$45,'2.1. Regulamentares'!F:F,"w",'2.1. Regulamentares'!C:C,">0",'2.1. Regulamentares'!I:I,"<>") -> 0 | H48: =IFERROR(G48/D48,0) -> 0 | I48: =+COUNTIFS('2.1. Regulamentares'!G:G,$C$45,'2.1. Regulamentares'!F:F,"w",'2.1. Regulamentares'!C:C,">0",'2.1. Regulamentares'!I:I,"") -> 0 | J48: =IFERROR(I48/D48,0) -> 0
C49: Formatos | D49: =+COUNTIFS('2.1. Regulamentares'!G:G,$C$45,'2.1. Regulamentares'!F:F,"f") -> 14 | E49: =+COUNTIFS('2.1. Regulamentares'!G:G,$C$45,'2.1. Regulamentares'!F:F,"f",'2.1. Regulamentares'!C:C,"=0") -> 12 | F49: =IFERROR(E49/D49,0) -> 0.85714286 | G49: =+COUNTIFS('2.1. Regulamentares'!G:G,$C$45,'2.1. Regulamentares'!F:F,"f",'2.1. Regulamentares'!C:C,">0",'2.1. Regulamentares'!I:I,"<>") -> 2 | H49: =IFERROR(G49/D49,0) -> 0.14285714 | I49: =+COUNTIFS('2.1. Regulamentares'!G:G,$C$45,'2.1. Regulamentares'!F:F,"f",'2.1. Regulamentares'!C:C,">0",'2.1. Regulamentares'!I:I,"") -> 0 | J49: =IFERROR(I49/D49,0) -> 0
C50: Outros | D50: =+SUM(D51:D54) -> 1 | E50: =+SUM(E51:E54) -> 1 | F50: =IFERROR(E50/D50,0) -> 1 | G50: =+SUM(G51:G54) -> 0 | H50: =IFERROR(G50/D50,0) -> 0 | I50: =+SUM(I51:I54) -> 0 | J50: =IFERROR(I50/D50,0) -> 0
C51: Validade (Missings/NULLS) | D51: =+COUNTIFS('2.2. Outros'!H:H,$C$45,'2.2. Outros'!D:D,"Validade") -> 0 | E51: =+COUNTIFS('2.2. Outros'!H:H,$C$45,'2.2. Outros'!D:D,"Validade",'2.2. Outros'!F:F,"0") -> 0 | F51: =IFERROR(E51/D51,0) -> 0 | G51: =+COUNTIFS('2.2. Outros'!H:H,$C$45,'2.2. Outros'!D:D,"Validade",'2.2. Outros'!F:F,"<>0",'2.2. Outros'!I:I,"<>") -> 0 | H51: =IFERROR(G51/D51,0) -> 0 | I51: =+COUNTIFS('2.2. Outros'!H:H,$C$45,'2.2. Outros'!D:D,"Validade",'2.2. Outros'!F:F,"<>0",'2.2. Outros'!I:I,"") -> 0 | J51: =IFERROR(I51/D51,0) -> 0
C52: Not applicables | D52: =+COUNTIFS('2.2. Outros'!H:H,$C$45,'2.2. Outros'!D:D,"Not applicable") -> 0 | E52: =+COUNTIFS('2.2. Outros'!H:H,$C$45,'2.2. Outros'!D:D,"Not applicable",'2.2. Outros'!F:F,"0") -> 0 | F52: =IFERROR(E52/D52,0) -> 0 | G52: =+COUNTIFS('2.2. Outros'!H:H,$C$45,'2.2. Outros'!D:D,"Not applicable",'2.2. Outros'!F:F,"<>0",'2.2. Outros'!I:I,"<>") -> 0 | H52: =IFERROR(G52/D52,0) -> 0 | I52: =+COUNTIFS('2.2. Outros'!H:H,$C$45,'2.2. Outros'!D:D,"Not applicable",'2.2. Outros'!F:F,"<>0",'2.2. Outros'!I:I,"") -> 0 | J52: =IFERROR(I52/D52,0) -> 0
C53: Duplicados | D53: =+COUNTIFS('2.2. Outros'!H:H,$C$45,'2.2. Outros'!D:D,"Duplicados") -> 0 | E53: =+COUNTIFS('2.2. Outros'!H:H,$C$45,'2.2. Outros'!D:D,"Duplicados",'2.2. Outros'!F:F,"0") -> 0 | F53: =IFERROR(E53/D53,0) -> 0 | G53: =+COUNTIFS('2.2. Outros'!H:H,$C$45,'2.2. Outros'!D:D,"Duplicados",'2.2. Outros'!F:F,"<>0",'2.2. Outros'!I:I,"<>") -> 0 | H53: =IFERROR(G53/D53,0) -> 0 | I53: =+COUNTIFS('2.2. Outros'!H:H,$C$45,'2.2. Outros'!D:D,"Duplicados",'2.2. Outros'!F:F,"<>0",'2.2. Outros'!I:I,"") -> 0 | J53: =IFERROR(I53/D53,0) -> 0
C54: Integridade entre tabelas | D54: =+COUNTIFS('2.2. Outros'!H:H,$C$45,'2.2. Outros'!D:D,"Integridade") -> 1 | E54: =+COUNTIFS('2.2. Outros'!H:H,$C$45,'2.2. Outros'!D:D,"Integridade",'2.2. Outros'!F:F,"0") -> 1 | F54: =IFERROR(E54/D54,0) -> 1 | G54: =+COUNTIFS('2.2. Outros'!H:H,$C$45,'2.2. Outros'!D:D,"Integridade",'2.2. Outros'!F:F,"<>0",'2.2. Outros'!I:I,"<>") -> 0 | H54: =IFERROR(G54/D54,0) -> 0 | I54: =+COUNTIFS('2.2. Outros'!H:H,$C$45,'2.2. Outros'!D:D,"Integridade",'2.2. Outros'!F:F,"<>0",'2.2. Outros'!I:I,"") -> 0 | J54: =IFERROR(I54/D54,0) -> 0
C55: B90.00 | D55: =+SUM(D56,D60) -> 16 | E55: =+SUM(E56,E60) -> 13 | F55: =IFERROR(E55/D55,0) -> 0.8125 | G55: =+SUM(G56,G60) -> 2 | H55: =IFERROR(G55/D55,0) -> 0.125 | I55: =+SUM(I56,I60) -> 1 | J55: =IFERROR(I55/D55,0) -> 0.0625
C56: Regulamentares (SRB) | D56: =+SUM(D57:D59) -> 15 | E56: =+SUM(E57:E59) -> 12 | F56: =IFERROR(E56/D56,0) -> 0.8 | G56: =+SUM(G57:G59) -> 2 | H56: =IFERROR(G56/D56,0) -> 0.13333333 | I56: =+SUM(I57:I59) -> 1 | J56: =IFERROR(I56/D56,0) -> 0.066666667
C57: High severity | D57: =+COUNTIFS('2.1. Regulamentares'!G:G,$C$55,'2.1. Regulamentares'!F:F,"h") -> 4 | E57: =+COUNTIFS('2.1. Regulamentares'!G:G,$C$55,'2.1. Regulamentares'!F:F,"h",'2.1. Regulamentares'!C:C,"=0") -> 2 | F57: =IFERROR(E57/D57,0) -> 0.5 | G57: =+COUNTIFS('2.1. Regulamentares'!G:G,$C$55,'2.1. Regulamentares'!F:F,"h",'2.1. Regulamentares'!C:C,">0",'2.1. Regulamentares'!I:I,"<>") -> 1 | H57: =IFERROR(G57/D57,0) -> 0.25 | I57: =+COUNTIFS('2.1. Regulamentares'!G:G,$C$55,'2.1. Regulamentares'!F:F,"h",'2.1. Regulamentares'!C:C,">0",'2.1. Regulamentares'!I:I,"") -> 1 | J57: =IFERROR(I57/D57,0) -> 0.25
C58: Warnings | D58: =+COUNTIFS('2.1. Regulamentares'!G:G,$C$55,'2.1. Regulamentares'!F:F,"w") -> 0 | E58: =+COUNTIFS('2.1. Regulamentares'!G:G,$C$55,'2.1. Regulamentares'!F:F,"w",'2.1. Regulamentares'!C:C,"=0") -> 0 | F58: =IFERROR(E58/D58,0) -> 0 | G58: =+COUNTIFS('2.1. Regulamentares'!G:G,$C$55,'2.1. Regulamentares'!F:F,"w",'2.1. Regulamentares'!C:C,">0",'2.1. Regulamentares'!I:I,"<>") -> 0 | H58: =IFERROR(G58/D58,0) -> 0 | I58: =+COUNTIFS('2.1. Regulamentares'!G:G,$C$55,'2.1. Regulamentares'!F:F,"w",'2.1. Regulamentares'!C:C,">0",'2.1. Regulamentares'!I:I,"") -> 0 | J58: =IFERROR(I58/D58,0) -> 0
C59: Formatos | D59: =+COUNTIFS('2.1. Regulamentares'!G:G,$C$55,'2.1. Regulamentares'!F:F,"f") -> 11 | E59: =+COUNTIFS('2.1. Regulamentares'!G:G,$C$55,'2.1. Regulamentares'!F:F,"f",'2.1. Regulamentares'!C:C,"=0") -> 10 | F59: =IFERROR(E59/D59,0) -> 0.90909091 | G59: =+COUNTIFS('2.1. Regulamentares'!G:G,$C$55,'2.1. Regulamentares'!F:F,"f",'2.1. Regulamentares'!C:C,">0",'2.1. Regulamentares'!I:I,"<>") -> 1 | H59: =IFERROR(G59/D59,0) -> 0.090909091 | I59: =+COUNTIFS('2.1. Regulamentares'!G:G,$C$55,'2.1. Regulamentares'!F:F,"f",'2.1. Regulamentares'!C:C,">0",'2.1. Regulamentares'!I:I,"") -> 0 | J59: =IFERROR(I59/D59,0) -> 0
C60: Outros | D60: =+SUM(D61:D64) -> 1 | E60: =+SUM(E61:E64) -> 1 | F60: =IFERROR(E60/D60,0) -> 1 | G60: =+SUM(G61:G64) -> 0 | H60: =IFERROR(G60/D60,0) -> 0 | I60: =+SUM(I61:I64) -> 0 | J60: =IFERROR(I60/D60,0) -> 0
C61: Validade (Missings/NULLS) | D61: =+COUNTIFS('2.2. Outros'!H:H,$C$55,'2.2. Outros'!D:D,"Validade") -> 0 | E61: =+COUNTIFS('2.2. Outros'!H:H,$C$55,'2.2. Outros'!D:D,"Validade",'2.2. Outros'!F:F,"0") -> 0 | F61: =IFERROR(E61/D61,0) -> 0 | G61: =+COUNTIFS('2.2. Outros'!H:H,$C$55,'2.2. Outros'!D:D,"Validade",'2.2. Outros'!F:F,"<>0",'2.2. Outros'!I:I,"<>") -> 0 | H61: =IFERROR(G61/D61,0) -> 0 | I61: =+COUNTIFS('2.2. Outros'!H:H,$C$55,'2.2. Outros'!D:D,"Validade",'2.2. Outros'!F:F,"<>0",'2.2. Outros'!I:I,"") -> 0 | J61: =IFERROR(I61/D61,0) -> 0
C62: Not applicables | D62: =+COUNTIFS('2.2. Outros'!H:H,$C$55,'2.2. Outros'!D:D,"Not applicable") -> 0 | E62: =+COUNTIFS('2.2. Outros'!H:H,$C$55,'2.2. Outros'!D:D,"Not applicable",'2.2. Outros'!F:F,"0") -> 0 | F62: =IFERROR(E62/D62,0) -> 0 | G62: =+COUNTIFS('2.2. Outros'!H:H,$C$55,'2.2. Outros'!D:D,"Not applicable",'2.2. Outros'!F:F,"<>0",'2.2. Outros'!I:I,"<>") -> 0 | H62: =IFERROR(G62/D62,0) -> 0 | I62: =+COUNTIFS('2.2. Outros'!H:H,$C$55,'2.2. Outros'!D:D,"Not applicable",'2.2. Outros'!F:F,"<>0",'2.2. Outros'!I:I,"") -> 0 | J62: =IFERROR(I62/D62,0) -> 0
C63: Duplicados | D63: =+COUNTIFS('2.2. Outros'!H:H,$C$55,'2.2. Outros'!D:D,"Duplicados") -> 0 | E63: =+COUNTIFS('2.2. Outros'!H:H,$C$55,'2.2. Outros'!D:D,"Duplicados",'2.2. Outros'!F:F,"0") -> 0 | F63: =IFERROR(E63/D63,0) -> 0 | G63: =+COUNTIFS('2.2. Outros'!H:H,$C$55,'2.2. Outros'!D:D,"Duplicados",'2.2. Outros'!F:F,"<>0",'2.2. Outros'!I:I,"<>") -> 0 | H63: =IFERROR(G63/D63,0) -> 0 | I63: =+COUNTIFS('2.2. Outros'!H:H,$C$55,'2.2. Outros'!D:D,"Duplicados",'2.2. Outros'!F:F,"<>0",'2.2. Outros'!I:I,"") -> 0 | J63: =IFERROR(I63/D63,0) -> 0
C64: Integridade entre tabelas | D64: =+COUNTIFS('2.2. Outros'!H:H,$C$55,'2.2. Outros'!D:D,"Integridade") -> 1 | E64: =+COUNTIFS('2.2. Outros'!H:H,$C$55,'2.2. Outros'!D:D,"Integridade",'2.2. Outros'!F:F,"0") -> 1 | F64: =IFERROR(E64/D64,0) -> 1 | G64: =+COUNTIFS('2.2. Outros'!H:H,$C$55,'2.2. Outros'!D:D,"Integridade",'2.2. Outros'!F:F,"<>0",'2.2. Outros'!I:I,"<>") -> 0 | H64: =IFERROR(G64/D64,0) -> 0 | I64: =+COUNTIFS('2.2. Outros'!H:H,$C$55,'2.2. Outros'!D:D,"Integridade",'2.2. Outros'!F:F,"<>0",'2.2. Outros'!I:I,"") -> 0 | J64: =IFERROR(I64/D64,0) -> 0
...

Sheet 2. Inputs -->

Sheet Query1
B6: 2.1. Controlos Regulamentares
B9: ref_date | C9: cod_kpi | D9: tipologia_teste | E9: descrição | F9: tabela | G9: campo | H9: num_reg | I9: num_reg_dif | J9: detalhe
B10: 2025-10-31 | C10: MIS_B0200_C0010 | D10: MISSINGS | E10: Validar que não existem registos por preencher (Missings) | F10: BU_LOANTAPE_WORK.OUT_B0200_MAIN_LIABILITIES | G10: 0010_ROW_NMBR | H10: 8 | I10: 0
B11: 2025-10-31 | C11: MIS_B0200_C0020 | D11: MISSINGS | E11: Validar que não existem registos por preencher (Missings) | F11: BU_LOANTAPE_WORK.OUT_B0200_MAIN_LIABILITIES | G11: 0020_UNIQ_ID | H11: 8 | I11: 0
B12: 2025-10-31 | C12: MIS_B0200_C0030 | D12: MISSINGS | E12: Validar que não existem registos por preencher (Missings) | F12: BU_LOANTAPE_WORK.OUT_B0200_MAIN_LIABILITIES | G12: 0030_UNIQ_ID_KNWN_CNTRPRTY | H12: 8 | I12: 0
B13: 2025-10-31 | C13: MIS_B0200_C0040 | D13: MISSINGS | E13: Validar que não existem registos por preencher (Missings) | F13: BU_LOANTAPE_WORK.OUT_B0200_MAIN_LIABILITIES | G13: 0040_TYP_UNIQ_ID_KNWN_CNTRPRTY | H13: 8 | I13: 0
B14: 2025-10-31 | C14: MIS_B0200_C0050 | D14: MISSINGS | E14: Validar que não existem registos por preencher (Missings) | F14: BU_LOANTAPE_WORK.OUT_B0200_MAIN_LIABILITIES | G14: 0050_ORGNL_AMNT_EUR | H14: 8 | I14: 0
B15: 2025-10-31 | C15: MIS_B0200_C0060 | D15: MISSINGS | E15: Validar que não existem registos por preencher (Missings) | F15: BU_LOANTAPE_WORK.OUT_B0200_MAIN_LIABILITIES | G15: 0060_ORGNL_AMNT_FX | H15: 8 | I15: 0
B16: 2025-10-31 | C16: MIS_B0200_C0070 | D16: MISSINGS | E16: Validar que não existem registos por preencher (Missings) | F16: BU_LOANTAPE_WORK.OUT_B0200_MAIN_LIABILITIES | G16: 0070_CNTRCT_CRRNCY | H16: 8 | I16: 0
B17: 2025-10-31 | C17: MIS_B0200_C0080 | D17: MISSINGS | E17: Validar que não existem registos por preencher (Missings) | F17: BU_LOANTAPE_WORK.OUT_B0200_MAIN_LIABILITIES | G17: 0080_OTSTNDNG_PRNCPL_AMNT | H17: 8 | I17: 8 | J17: 31641600000000000PTBSREOM0028000; 31641600000000000PTSTOEOM0021000; 31641600000000000PTSTOFOM0004000; 31641600000000000PTSTOGOM0003000; 31641600000000000PTSTOHOM0002000; 31641600005800007PTBSRDOM0037000; 31641600005800007PTCPP0AM0007000; 31641600005800007PTSTOCOM0007000
B18: 2025-10-31 | C18: MIS_B0200_C0090 | D18: MISSINGS | E18: Validar que não existem registos por preencher (Missings) | F18: BU_LOANTAPE_WORK.OUT_B0200_MAIN_LIABILITIES | G18: 0090_PRTN_AMNT_RPRTNG_ENTTY | H18: 8 | I18: 8 | J18: 31641600000000000PTBSREOM0028000; 31641600000000000PTSTOEOM0021000; 31641600000000000PTSTOFOM0004000; 31641600000000000PTSTOGOM0003000; 31641600000000000PTSTOHOM0002000; 31641600005800007PTBSRDOM0037000; 31641600005800007PTCPP0AM0007000; 31641600005800007PTSTOCOM0007000
B19: 2025-10-31 | C19: MIS_B0200_C0100 | D19: MISSINGS | E19: Validar que não existem registos por preencher (Missings) | F19: BU_LOANTAPE_WORK.OUT_B0200_MAIN_LIABILITIES | G19: 0100_ACCRD_INTRST_INSTRMNT | H19: 8 | I19: 0
B20: 2025-10-31 | C20: MIS_B0200_C0110 | D20: MISSINGS | E20: Validar que não existem registos por preencher (Missings) | F20: BU_LOANTAPE_WORK.OUT_B0200_MAIN_LIABILITIES | G20: 0110_APPLCBL_FEES_CHARGES | H20: 8 | I20: 0
B21: 2025-10-31 | C21: MIS_B0200_C0120 | D21: MISSINGS | E21: Validar que não existem registos por preencher (Missings) | F21: BU_LOANTAPE_WORK.OUT_B0200_MAIN_LIABILITIES | G21: 0120_OTSTNDNG_AMNT | H21: 8 | I21: 8 | J21: 31641600000000000PTBSREOM0028000; 31641600000000000PTSTOEOM0021000; 31641600000000000PTSTOFOM0004000; 31641600000000000PTSTOGOM0003000; 31641600000000000PTSTOHOM0002000; 31641600005800007PTBSRDOM0037000; 31641600005800007PTCPP0AM0007000; 31641600005800007PTSTOCOM0007000
B22: 2025-10-31 | C22: MIS_B0200_C0130 | D22: MISSINGS | E22: Validar que não existem registos por preencher (Missings) | F22: BU_LOANTAPE_WORK.OUT_B0200_MAIN_LIABILITIES | G22: 0130_RLVNT_AMNT_WDC | H22: 8 | I22: 8 | J22: 31641600000000000PTBSREOM0028000; 31641600000000000PTSTOEOM0021000; 31641600000000000PTSTOFOM0004000; 31641600000000000PTSTOGOM0003000; 31641600000000000PTSTOHOM0002000; 31641600005800007PTBSRDOM0037000; 31641600005800007PTCPP0AM0007000; 31641600005800007PTSTOCOM0007000
B23: 2025-10-31 | C23: MIS_B0200_C0140 | D23: MISSINGS | E23: Validar que não existem registos por preencher (Missings) | F23: BU_LOANTAPE_WORK.OUT_B0200_MAIN_LIABILITIES | G23: 0140_NTR_LBLTY | H23: 8 | I23: 0
B24: 2025-10-31 | C24: MIS_B0200_C0141 | D24: MISSINGS | E24: Validar que não existem registos por preencher (Missings) | F24: BU_LOANTAPE_WORK.OUT_B0200_MAIN_LIABILITIES | G24: 0141_NTR_LBLTY_OTHR | H24: 8 | I24: 0
B25: 2025-10-31 | C25: MIS_B0200_C0150 | D25: MISSINGS | E25: Validar que não existem registos por preencher (Missings) | F25: BU_LOANTAPE_WORK.OUT_B0200_MAIN_LIABILITIES | G25: 0150_FLG_STRCTRLLY_SBRDNTD | H25: 8 | I25: 0
B26: 2025-10-31 | C26: MIS_B0200_C0160 | D26: MISSINGS | E26: Validar que não existem registos por preencher (Missings) | F26: BU_LOANTAPE_WORK.OUT_B0200_MAIN_LIABILITIES | G26: 0160_RANK_INSOLV | H26: 8 | I26: 0
B27: 2025-10-31 | C27: MIS_B0200_C0161 | D27: MISSINGS | E27: Validar que não existem registos por preencher (Missings) | F27: BU_LOANTAPE_WORK.OUT_B0200_MAIN_LIABILITIES | G27: 0161_CNTRCTL_SBRDNTN | H27: 8 | I27: 0
B28: 2025-10-31 | C28: MIS_B0200_C0162 | D28: MISSINGS | E28: Validar que não existem registos por preencher (Missings) | F28: BU_LOANTAPE_WORK.OUT_B0200_MAIN_LIABILITIES | G28: 0162_BAIL_IN_CASCADE | H28: 8 | I28: 0
B29: 2025-10-31 | C29: MIS_B0200_C0170 | D29: MISSINGS | E29: Validar que não existem registos por preencher (Missings) | F29: BU_LOANTAPE_WORK.OUT_B0200_MAIN_LIABILITIES | G29: 0170_DT_INCPTN | H29: 8 | I29: 0
B30: 2025-10-31 | C30: MIS_B0200_C0180 | D30: MISSINGS | E30: Validar que não existem registos por preencher (Missings) | F30: BU_LOANTAPE_WORK.OUT_B0200_MAIN_LIABILITIES | G30: 0180_DT_NXT_INTRST_PYMNT | H30: 8 | I30: 0
B31: 2025-10-31 | C31: MIS_B0200_C0190 | D31: MISSINGS | E31: Validar que não existem registos por preencher (Missings) | F31: BU_LOANTAPE_WORK.OUT_B0200_MAIN_LIABILITIES | G31: 0190_DT_NXT_RDMPTN_PYMNT | H31: 8 | I31: 0
B32: 2025-10-31 | C32: MIS_B0200_C0200 | D32: MISSINGS | E32: Validar que não existem registos por preencher (Missings) | F32: BU_LOANTAPE_WORK.OUT_B0200_MAIN_LIABILITIES | G32: 0200_DT_ERLST_RDMPTN | H32: 8 | I32: 0
B33: 2025-10-31 | C33: MIS_B0200_C0210 | D33: MISSINGS | E33: Validar que não existem registos por preencher (Missings) | F33: BU_LOANTAPE_WORK.OUT_B0200_MAIN_LIABILITIES | G33: 0210_DT_LGL_FNL_MTRTY | H33: 8 | I33: 0
B34: 2025-10-31 | C34: MIS_B0200_C0220 | D34: MISSINGS | E34: Validar que não existem registos por preencher (Missings) | F34: BU_LOANTAPE_WORK.OUT_B0200_MAIN_LIABILITIES | G34: 0220_GOVERNING_LAW | H34: 8 | I34: 0
... B51: 2025-10-31 | C51: MIS_B0200_C0380 | D51: MISSINGS | E51: Validar que não existem registos por preencher (Missings) | F51: BU_LOANTAPE_WORK.OUT_B0200_MAIN_LIABILITIES | G51: 0380_AMNT_SCRTY_FX | H51: 8 | I51: 0
B52: 2025-10-31 | C52: MIS_B0200_C0390 | D52: MISSINGS | E52: Validar que não existem registos por preencher (Missings) | F52: BU_LOANTAPE_WORK.OUT_B0200_MAIN_LIABILITIES | G52: 0390_NMBR_SCRTS_NOT_RPRTNG_ENTTY | H52: 8 | I52: 8 | J52: 31641600000000000PTBSREOM0028000; 31641600000000000PTSTOEOM0021000; 31641600000000000PTSTOFOM0004000; 31641600000000000PTSTOGOM0003000; 31641600000000000PTSTOHOM0002000; 31641600005800007PTBSRDOM0037000; 31641600005800007PTCPP0AM0007000; 31641600005800007PTSTOCOM0007000
B53: 2025-10-31 | C53: MIS_B0200_C0391 | D53: MISSINGS | E53: Validar que não existem registos por preencher (Missings) | F53: BU_LOANTAPE_WORK.OUT_B0200_MAIN_LIABILITIES | G53: 0391_NMBR_SCRTS_RPRTNG_ENTTY | H53: 8 | I53: 8 | J53: 31641600000000000PTBSREOM0028000; 31641600000000000PTSTOEOM0021000; 31641600000000000PTSTOFOM0004000; 31641600000000000PTSTOGOM0003000; 31641600000000000PTSTOHOM0002000; 31641600005800007PTBSRDOM0037000; 31641600005800007PTCPP0AM0007000; 31641600005800007PTSTOCOM0007000
B54: 2025-10-31 | C54: MIS_B0200_C0400 | D54: MISSINGS | E54: Validar que não existem registos por preencher (Missings) | F54: BU_LOANTAPE_WORK.OUT_B0200_MAIN_LIABILITIES | G54: 0400_ACCRD_INTRST_SCRTY | H54: 8 | I54: 8 | J54: 31641600000000000PTBSREOM0028000; 31641600000000000PTSTOEOM0021000; 31641600000000000PTSTOFOM0004000; 31641600000000000PTSTOGOM0003000; 31641600000000000PTSTOHOM0002000; 31641600005800007PTBSRDOM0037000; 31641600005800007PTCPP0AM0007000; 31641600005800007PTSTOCOM0007000
B55: 2025-10-31 | C55: MIS_B0200_C0410 | D55: MISSINGS | E55: Validar que não existem registos por preencher (Missings) | F55: BU_LOANTAPE_WORK.OUT_B0200_MAIN_LIABILITIES | G55: 0410_FEES_CHARGES_SCRTY | H55: 8 | I55: 0
B56: 2025-10-31 | C56: MIS_B0200_C0420 | D56: MISSINGS | E56: Validar que não existem registos por preencher (Missings) | F56: BU_LOANTAPE_WORK.OUT_B0200_MAIN_LIABILITIES | G56: 0420_FV_AMNT_SCRTY | H56: 8 | I56: 0
B57: 2025-10-31 | C57: MIS_B0200_C0430 | D57: MISSINGS | E57: Validar que não existem registos por preencher (Missings) | F57: BU_LOANTAPE_WORK.OUT_B0200_MAIN_LIABILITIES | G57: 0430_PRNCPL_AMNT_GLBL_NT_EUR | H57: 8 | I57: 0
B58: 2025-10-31 | C58: MIS_B0200_C0431 | D58: MISSINGS | E58: Validar que não existem registos por preencher (Missings) | F58: BU_LOANTAPE_WORK.OUT_B0200_MAIN_LIABILITIES | G58: 0431_PRNCPL_AMNT_GLBL_NT_FX | H58: 8 | I58: 0
B59: 2025-10-31 | C59: MIS_B0200_C0440 | D59: MISSINGS | E59: Validar que não existem registos por preencher (Missings) | F59: BU_LOANTAPE_WORK.OUT_B0200_MAIN_LIABILITIES | G59: 0440_NTR_GLBL_NT | H59: 8 | I59: 0
B60: 2025-10-31 | C60: MIS_B0200_C0450 | D60: MISSINGS | E60: Validar que não existem registos por preencher (Missings) | F60: BU_LOANTAPE_WORK.OUT_B0200_MAIN_LIABILITIES | G60: 0450_CRRNT_POOL_FCTR | H60: 8 | I60: 0
B61: 2025-10-31 | C61: MIS_B0200_C0460 | D61: MISSINGS | E61: Validar que não existem registos por preencher (Missings) | F61: BU_LOANTAPE_WORK.OUT_B0200_MAIN_LIABILITIES | G61: 0460_CSD | H61: 8 | I61: 0
B62: 2025-10-31 | C62: MIS_B0200_C0461 | D62: MISSINGS | E62: Validar que não existem registos por preencher (Missings) | F62: BU_LOANTAPE_WORK.OUT_B0200_MAIN_LIABILITIES | G62: 0461_CSD_LEI | H62: 8 | I62: 0
B63: 2025-10-31 | C63: MIS_B0200_C0462 | D63: MISSINGS | E63: Validar que não existem registos por preencher (Missings) | F63: BU_LOANTAPE_WORK.OUT_B0200_MAIN_LIABILITIES | G63: 0462_CSD_OTHR | H63: 8 | I63: 0
...

Sheet 2.1. Regulamentares
B6: 2.1. Controlos Regulamentares
B8: Controlo | C8: Issues | D8: Detalhe | E8: Tipo | F8: High Severity (H)/ Warning (W) | G8: Table | H8: Field | I8: Justificação
B9: b0200_lvl1_h_0010_row_nmbr | C9: 0 | E9: =+MID(B9,7,4) -> lvl1 | F9: =IF(LEFT(E9,3)="lvl",MID(B9,12,1),"f") -> h | G9: =+LEFT(B9,3)&"."&MID(B9,4,2) -> b02.00 | H9: =IF(LEFT(E9,3)="lvl",IF(OR(RIGHT(B9,2)="_1",RIGHT(B9,2)="_2"),MID(B9,14,LEN(B9)-15), MID(B9,14,LEN(B9))),MID(B9,12,LEN(B9))) -> 0010_row_nmbr
B10: b0200_lvl1_h_0030_uniq_id_knwn_cntrprty | C10: 0 | E10: =+MID(B10,7,4) -> lvl1 | F10: =IF(LEFT(E10,3)="lvl",MID(B10,12,1),"f") -> h | G10: =+LEFT(B10,3)&"."&MID(B10,4,2) -> b02.00 | H10: =IF(LEFT(E10,3)="lvl",IF(OR(RIGHT(B10,2)="_1",RIGHT(B10,2)="_2"),MID(B10,14,LEN(B10)-15), MID(B10,14,LEN(B10))),MID(B10,12,LEN(B10))) -> 0030_uniq_id_knwn_cntrprty
B11: b0200_lvl1_h_0040_typ_uniq_id_knwn_cntrprty | C11: 0 | E11: =+MID(B11,7,4) -> lvl1 | F11: =IF(LEFT(E11,3)="lvl",MID(B11,12,1),"f") -> h | G11: =+LEFT(B11,3)&"."&MID(B11,4,2) -> b02.00 | H11: =IF(LEFT(E11,3)="lvl",IF(OR(RIGHT(B11,2)="_1",RIGHT(B11,2)="_2"),MID(B11,14,LEN(B11)-15), MID(B11,14,LEN(B11))),MID(B11,12,LEN(B11))) -> 0040_typ_uniq_id_knwn_cntrprty
B12: b0200_lvl1_h_0070_cntrct_crrncy | C12: 0 | E12: =+MID(B12,7,4) -> lvl1 | F12: =IF(LEFT(E12,3)="lvl",MID(B12,12,1),"f") -> h | G12: =+LEFT(B12,3)&"."&MID(B12,4,2) -> b02.00 | H12: =IF(LEFT(E12,3)="lvl",IF(OR(RIGHT(B12,2)="_1",RIGHT(B12,2)="_2"),MID(B12,14,LEN(B12)-15), MID(B12,14,LEN(B12))),MID(B12,12,LEN(B12))) -> 0070_cntrct_crrncy
B13: b0200_lvl1_h_0080_otstndng_prncpl_amnt | C13: 0 | E13: =+MID(B13,7,4) -> lvl1 | F13: =IF(LEFT(E13,3)="lvl",MID(B13,12,1),"f") -> h | G13: =+LEFT(B13,3)&"."&MID(B13,4,2) -> b02.00 | H13: =IF(LEFT(E13,3)="lvl",IF(OR(RIGHT(B13,2)="_1",RIGHT(B13,2)="_2"),MID(B13,14,LEN(B13)-15), MID(B13,14,LEN(B13))),MID(B13,12,LEN(B13))) -> 0080_otstndng_prncpl_amnt
B14: b0200_lvl1_w_0080_otstndng_prncpl_amnt | C14: 0 | E14: =+MID(B14,7,4) -> lvl1 | F14: =IF(LEFT(E14,3)="lvl",MID(B14,12,1),"f") -> w | G14: =+LEFT(B14,3)&"."&MID(B14,4,2) -> b02.00 | H14: =IF(LEFT(E14,3)="lvl",IF(OR(RIGHT(B14,2)="_1",RIGHT(B14,2)="_2"),MID(B14,14,LEN(B14)-15), MID(B14,14,LEN(B14))),MID(B14,12,LEN(B14))) -> 0080_otstndng_prncpl_amnt
B15: b0200_lvl1_h_0090_prtn_amnt_rprtng_entty | C15: 0 | E15: =+MID(B15,7,4) -> lvl1 | F15: =IF(LEFT(E15,3)="lvl",MID(B15,12,1),"f") -> h | G15: =+LEFT(B15,3)&"."&MID(B15,4,2) -> b02.00 | H15: =IF(LEFT(E15,3)="lvl",IF(OR(RIGHT(B15,2)="_1",RIGHT(B15,2)="_2"),MID(B15,14,LEN(B15)-15), MID(B15,14,LEN(B15))),MID(B15,12,LEN(B15))) -> 0090_prtn_amnt_rprtng_entty
B16: b0200_lvl1_h_0100_accrd_intrst_instrmnt | C16: 0 | E16: =+MID(B16,7,4) -> lvl1 | F16: =IF(LEFT(E16,3)="lvl",MID(B16,12,1),"f") -> h | G16: =+LEFT(B16,3)&"."&MID(B16,4,2) -> b02.00 | H16: =IF(LEFT(E16,3)="lvl",IF(OR(RIGHT(B16,2)="_1",RIGHT(B16,2)="_2"),MID(B16,14,LEN(B16)-15), MID(B16,14,LEN(B16))),MID(B16,12,LEN(B16))) -> 0100_accrd_intrst_instrmnt
B17: b0200_lvl1_w_0100_accrd_intrst_instrmnt | C17: 0 | E17: =+MID(B17,7,4) -> lvl1 | F17: =IF(LEFT(E17,3)="lvl",MID(B17,12,1),"f") -> w | G17: =+LEFT(B17,3)&"."&MID(B17,4,2) -> b02.00 | H17: =IF(LEFT(E17,3)="lvl",IF(OR(RIGHT(B17,2)="_1",RIGHT(B17,2)="_2"),MID(B17,14,LEN(B17)-15), MID(B17,14,LEN(B17))),MID(B17,12,LEN(B17))) -> 0100_accrd_intrst_instrmnt
B18: b0200_lvl1_h_0120_otstndng_amnt | C18: 0 | E18: =+MID(B18,7,4) -> lvl1 | F18: =IF(LEFT(E18,3)="lvl",MID(B18,12,1),"f") -> h | G18: =+LEFT(B18,3)&"."&MID(B18,4,2) -> b02.00 | H18: =IF(LEFT(E18,3)="lvl",IF(OR(RIGHT(B18,2)="_1",RIGHT(B18,2)="_2"),MID(B18,14,LEN(B18)-15), MID(B18,14,LEN(B18))),MID(B18,12,LEN(B18))) -> 0120_otstndng_amnt
B19: b0200_lvl1_w_0120_otstndng_amnt | C19: 8 | E19: =+MID(B19,7,4) -> lvl1 | F19: =IF(LEFT(E19,3)="lvl",MID(B19,12,1),"f") -> w | G19: =+LEFT(B19,3)&"."&MID(B19,4,2) -> b02.00 | H19: =IF(LEFT(E19,3)="lvl",IF(OR(RIGHT(B19,2)="_1",RIGHT(B19,2)="_2"),MID(B19,14,LEN(B19)-15), MID(B19,14,LEN(B19))),MID(B19,12,LEN(B19))) -> 0120_otstndng_amnt
B20: b0200_lvl1_h_0130_rlvnt_amnt_wdc | C20: 8 | E20: =+MID(B20,7,4) -> lvl1 | F20: =IF(LEFT(E20,3)="lvl",MID(B20,12,1),"f") -> h | G20: =+LEFT(B20,3)&"."&MID(B20,4,2) -> b02.00 | H20: =IF(LEFT(E20,3)="lvl",IF(OR(RIGHT(B20,2)="_1",RIGHT(B20,2)="_2"),MID(B20,14,LEN(B20)-15), MID(B20,14,LEN(B20))),MID(B20,12,LEN(B20))) -> 0130_rlvnt_amnt_wdc
... B97: b0200_frmt_0140_ntr_lblty | C97: 4 | E97: =+MID(B97,7,4) -> frmt | F97: =IF(LEFT(E97,3)="lvl",MID(B97,12,1),"f") -> f | G97: =+LEFT(B97,3)&"."&MID(B97,4,2) -> b02.00 | H97: =IF(LEFT(E97,3)="lvl",IF(OR(RIGHT(B97,2)="_1",RIGHT(B97,2)="_2"),MID(B97,14,LEN(B97)-15), MID(B97,14,LEN(B97))),MID(B97,12,LEN(B97))) -> 0140_ntr_lblty
B98: b0200_frmt_0141_ntr_lblty_othr | C98: 8 | E98: =+MID(B98,7,4) -> frmt | F98: =IF(LEFT(E98,3)="lvl",MID(B98,12,1),"f") -> f | G98: =+LEFT(B98,3)&"."&MID(B98,4,2) -> b02.00 | H98: =IF(LEFT(E98,3)="lvl",IF(OR(RIGHT(B98,2)="_1",RIGHT(B98,2)="_2"),MID(B98,14,LEN(B98)-15), MID(B98,14,LEN(B98))),MID(B98,12,LEN(B98))) -> 0141_ntr_lblty_othr | I98: Valor fixo 'Not applicable' no campo Nature of the liability (if other), uma vez que todos os registos são considerados no campo Nature of the liability como "Title of ownership" ou "Registered Bond", não existinto "other".
B99: b0200_frmt_0150_flg_strctrlly_sbrdntd | C99: 8 | E99: =+MID(B99,7,4) -> frmt | F99: =IF(LEFT(E99,3)="lvl",MID(B99,12,1),"f") -> f | G99: =+LEFT(B99,3)&"."&MID(B99,4,2) -> b02.00 | H99: =IF(LEFT(E99,3)="lvl",IF(OR(RIGHT(B99,2)="_1",RIGHT(B99,2)="_2"),MID(B99,14,LEN(B99)-15), MID(B99,14,LEN(B99))),MID(B99,12,LEN(B99))) -> 0150_flg_strctrlly_sbrdntd | I99: Valor fixo 'Not applicable' de acordo com o Anexo III - considerado não aplicável para non-resolution entities.
B100: b0200_frmt_0160_rank_insolv | C100: 0 | E100: =+MID(B100,7,4) -> frmt | F100: =IF(LEFT(E100,3)="lvl",MID(B100,12,1),"f") -> f | G100: =+LEFT(B100,3)&"."&MID(B100,4,2) -> b02.00 | H100: =IF(LEFT(E100,3)="lvl",IF(OR(RIGHT(B100,2)="_1",RIGHT(B100,2)="_2"),MID(B100,14,LEN(B100)-15), MID(B100,14,LEN(B100))),MID(B100,12,LEN(B100))) -> 0160_rank_insolv
B101: b0200_frmt_0161_cntrctl_sbrdntn | C101: 0 | E101: =+MID(B101,7,4) -> frmt | F101: =IF(LEFT(E101,3)="lvl",MID(B101,12,1),"f") -> f | G101: =+LEFT(B101,3)&"."&MID(B101,4,2) -> b02.00 | H101: =IF(LEFT(E101,3)="lvl",IF(OR(RIGHT(B101,2)="_1",RIGHT(B101,2)="_2"),MID(B101,14,LEN(B101)-15), MID(B101,14,LEN(B101))),MID(B101,12,LEN(B101))) -> 0161_cntrctl_sbrdntn
B102: b0200_frmt_0162_bail_in_cascade | C102: 0 | E102: =+MID(B102,7,4) -> frmt | F102: =IF(LEFT(E102,3)="lvl",MID(B102,12,1),"f") -> f | G102: =+LEFT(B102,3)&"."&MID(B102,4,2) -> b02.00 | H102: =IF(LEFT(E102,3)="lvl",IF(OR(RIGHT(B102,2)="_1",RIGHT(B102,2)="_2"),MID(B102,14,LEN(B102)-15), MID(B102,14,LEN(B102))),MID(B102,12,LEN(B102))) -> 0162_bail_in_cascade
B103: b0200_frmt_0170_dt_incptn | C103: 0 | E103: =+MID(B103,7,4) -> frmt | F103: =IF(LEFT(E103,3)="lvl",MID(B103,12,1),"f") -> f | G103: =+LEFT(B103,3)&"."&MID(B103,4,2) -> b02.00 | H103: =IF(LEFT(E103,3)="lvl",IF(OR(RIGHT(B103,2)="_1",RIGHT(B103,2)="_2"),MID(B103,14,LEN(B103)-15), MID(B103,14,LEN(B103))),MID(B103,12,LEN(B103))) -> 0170_dt_incptn
B104: b0200_frmt_0180_dt_nxt_intrst_pymnt | C104: 8 | E104: =+MID(B104,7,4) -> frmt | F104: =IF(LEFT(E104,3)="lvl",MID(B104,12,1),"f") -> f | G104: =+LEFT(B104,3)&"."&MID(B104,4,2) -> b02.00 | H104: =IF(LEFT(E104,3)="lvl",IF(OR(RIGHT(B104,2)="_1",RIGHT(B104,2)="_2"),MID(B104,14,LEN(B104)-15), MID(B104,14,LEN(B104))),MID(B104,12,LEN(B104))) -> 0180_dt_nxt_intrst_pymnt
B105: b0200_frmt_0190_dt_nxt_rdmptn_pymnt | C105: 0 | E105: =+MID(B105,7,4) -> frmt | F105: =IF(LEFT(E105,3)="lvl",MID(B105,12,1),"f") -> f | G105: =+LEFT(B105,3)&"."&MID(B105,4,2) -> b02.00 | H105: =IF(LEFT(E105,3)="lvl",IF(OR(RIGHT(B105,2)="_1",RIGHT(B105,2)="_2"),MID(B105,14,LEN(B105)-15), MID(B105,14,LEN(B105))),MID(B105,12,LEN(B105))) -> 0190_dt_nxt_rdmptn_pymnt
B106: b0200_frmt_0200_dt_erlst_rdmptn | C106: 0 | E106: =+MID(B106,7,4) -> frmt | F106: =IF(LEFT(E106,3)="lvl",MID(B106,12,1),"f") -> f | G106: =+LEFT(B106,3)&"."&MID(B106,4,2) -> b02.00 | H106: =IF(LEFT(E106,3)="lvl",IF(OR(RIGHT(B106,2)="_1",RIGHT(B106,2)="_2"),MID(B106,14,LEN(B106)-15), MID(B106,14,LEN(B106))),MID(B106,12,LEN(B106))) -> 0200_dt_erlst_rdmptn
B107: b0200_frmt_0210_dt_lgl_fnl_mtrty | C107: 0 | E107: =+MID(B107,7,4) -> frmt | F107: =IF(LEFT(E107,3)="lvl",MID(B107,12,1),"f") -> f | G107: =+LEFT(B107,3)&"."&MID(B107,4,2) -> b02.00 | H107: =IF(LEFT(E107,3)="lvl",IF(OR(RIGHT(B107,2)="_1",RIGHT(B107,2)="_2"),MID(B107,14,LEN(B107)-15), MID(B107,14,LEN(B107))),MID(B107,12,LEN(B107))) -> 0210_dt_lgl_fnl_mtrty
B108: b0200_frmt_0220_governing_law | C108: 0 | E108: =+MID(B108,7,4) -> frmt | F108: =IF(LEFT(E108,3)="lvl",MID(B108,12,1),"f") -> f | G108: =+LEFT(B108,3)&"."&MID(B108,4,2) -> b02.00 | H108: =IF(LEFT(E108,3)="lvl",IF(OR(RIGHT(B108,2)="_1",RIGHT(B108,2)="_2"),MID(B108,14,LEN(B108)-15), MID(B108,14,LEN(B108))),MID(B108,12,LEN(B108))) -> 0220_governing_law
B109: b0200_frmt_0230_bail_in_rcgntn_cls | C109: 0 | E109: =+MID(B109,7,4) -> frmt | F109: =IF(LEFT(E109,3)="lvl",MID(B109,12,1),"f") -> f | G109: =+LEFT(B109,3)&"."&MID(B109,4,2) -> b02.00 | H109: =IF(LEFT(E109,3)="lvl",IF(OR(RIGHT(B109,2)="_1",RIGHT(B109,2)="_2"),MID(B109,14,LEN(B109)-15), MID(B109,14,LEN(B109))),MID(B109,12,LEN(B109))) -> 0230_bail_in_rcgntn_cls
B110: b0200_frmt_0240_zero_coupon | C110: 0 | E110: =+MID(B110,7,4) -> frmt | F110: =IF(LEFT(E110,3)="lvl",MID(B110,12,1),"f") -> f | G110: =+LEFT(B110,3)&"."&MID(B110,4,2) -> b02.00 | H110: =IF(LEFT(E110,3)="lvl",IF(OR(RIGHT(B110,2)="_1",RIGHT(B110,2)="_2"),MID(B110,14,LEN(B110)-15), MID(B110,14,LEN(B110))),MID(B110,12,LEN(B110))) -> 0240_zero_coupon
B111: b0200_frmt_0250_strctrd_prdct | C111: 0 | E111: =+MID(B111,7,4) -> frmt | F111: =IF(LEFT(E111,3)="lvl",MID(B111,12,1),"f") -> f | G111: =+LEFT(B111,3)&"."&MID(B111,4,2) -> b02.00 | H111: =IF(LEFT(E111,3)="lvl",IF(OR(RIGHT(B111,2)="_1",RIGHT(B111,2)="_2"),MID(B111,14,LEN(B111)-15), MID(B111,14,LEN(B111))),MID(B111,12,LEN(B111))) -> 0250_strctrd_prdct
... B119: b0200_frmt_0330_amnt_unclltrlzd | C119: 0 | E119: =+MID(B119,7,4) -> frmt | F119: =IF(LEFT(E119,3)="lvl",MID(B119,12,1),"f") -> f | G119: =+LEFT(B119,3)&"."&MID(B119,4,2) -> b02.00 | H119: =IF(LEFT(E119,3)="lvl",IF(OR(RIGHT(B119,2)="_1",RIGHT(B119,2)="_2"),MID(B119,14,LEN(B119)-15), MID(B119,14,LEN(B119))),MID(B119,12,LEN(B119))) -> 0330_amnt_unclltrlzd
B120: b0200_frmt_0340_id_clltrl | C120: 8 | E120: =+MID(B120,7,4) -> frmt | F120: =IF(LEFT(E120,3)="lvl",MID(B120,12,1),"f") -> f | G120: =+LEFT(B120,3)&"."&MID(B120,4,2) -> b02.00 | H120: =IF(LEFT(E120,3)="lvl",IF(OR(RIGHT(B120,2)="_1",RIGHT(B120,2)="_2"),MID(B120,14,LEN(B120)-15), MID(B120,14,LEN(B120))),MID(B120,12,LEN(B120))) -> 0340_id_clltrl | I120: Valor fixo 'Not applicable' de acordo com o Anexo III - considerado não aplicável para non-resolution entities.
B121: b0200_frmt_0350_typ_clltrl | C121: 0 | E121: =+MID(B121,7,4) -> frmt | F121: =IF(LEFT(E121,3)="lvl",MID(B121,12,1),"f") -> f | G121: =+LEFT(B121,3)&"."&MID(B121,4,2) -> b02.00 | H121: =IF(LEFT(E121,3)="lvl",IF(OR(RIGHT(B121,2)="_1",RIGHT(B121,2)="_2"),MID(B121,14,LEN(B121)-15), MID(B121,14,LEN(B121))),MID(B121,12,LEN(B121))) -> 0350_typ_clltrl
B122: b0200_frmt_0351_typ_clltrl_othr | C122: 8 | E122: =+MID(B122,7,4) -> frmt | F122: =IF(LEFT(E122,3)="lvl",MID(B122,12,1),"f") -> f | G122: =+LEFT(B122,3)&"."&MID(B122,4,2) -> b02.00 | H122: =IF(LEFT(E122,3)="lvl",IF(OR(RIGHT(B122,2)="_1",RIGHT(B122,2)="_2"),MID(B122,14,LEN(B122)-15), MID(B122,14,LEN(B122))),MID(B122,12,LEN(B122))) -> 0351_typ_clltrl_othr | I122: Valor fixo 'Not applicable' de acordo com o Anexo III - considerado não aplicável para non-resolution entities.
B123: b0200_frmt_0360_trdng_mthd | C123: 0 | E123: =+MID(B123,7,4) -> frmt | F123: =IF(LEFT(E123,3)="lvl",MID(B123,12,1),"f") -> f | G123: =+LEFT(B123,3)&"."&MID(B123,4,2) -> b02.00 | H123: =IF(LEFT(E123,3)="lvl",IF(OR(RIGHT(B123,2)="_1",RIGHT(B123,2)="_2"),MID(B123,14,LEN(B123)-15), MID(B123,14,LEN(B123))),MID(B123,12,LEN(B123))) -> 0360_trdng_mthd
B124: b0200_frmt_0370_amnt_scrty_eur | C124: 0 | E124: =+MID(B124,7,4) -> frmt | F124: =IF(LEFT(E124,3)="lvl",MID(B124,12,1),"f") -> f | G124: =+LEFT(B124,3)&"."&MID(B124,4,2) -> b02.00 | H124: =IF(LEFT(E124,3)="lvl",IF(OR(RIGHT(B124,2)="_1",RIGHT(B124,2)="_2"),MID(B124,14,LEN(B124)-15), MID(B124,14,LEN(B124))),MID(B124,12,LEN(B124))) -> 0370_amnt_scrty_eur
B125: b0200_frmt_0380_amnt_scrty_fx | C125: 0 | E125: =+MID(B125,7,4) -> frmt | F125: =IF(LEFT(E125,3)="lvl",MID(B125,12,1),"f") -> f | G125: =+LEFT(B125,3)&"."&MID(B125,4,2) -> b02.00 | H125: =IF(LEFT(E125,3)="lvl",IF(OR(RIGHT(B125,2)="_1",RIGHT(B125,2)="_2"),MID(B125,14,LEN(B125)-15), MID(B125,14,LEN(B125))),MID(B125,12,LEN(B125))) -> 0380_amnt_scrty_fx
B126: b0200_frmt_0390_nmbr_scrts_not_rprtng_entty | C126: 0 | E126: =+MID(B126,7,4) -> frmt | F126: =IF(LEFT(E126,3)="lvl",MID(B126,12,1),"f") -> f | G126: =+LEFT(B126,3)&"."&MID(B126,4,2) -> b02.00 | H126: =IF(LEFT(E126,3)="lvl",IF(OR(RIGHT(B126,2)="_1",RIGHT(B126,2)="_2"),MID(B126,14,LEN(B126)-15), MID(B126,14,LEN(B126))),MID(B126,12,LEN(B126))) -> 0390_nmbr_scrts_not_rprtng_entty
B127: b0200_frmt_0391_nmbr_scrts_rprtng_entty | C127: 8 | E127: =+MID(B127,7,4) -> frmt | F127: =IF(LEFT(E127,3)="lvl",MID(B127,12,1),"f") -> f | G127: =+LEFT(B127,3)&"."&MID(B127,4,2) -> b02.00 | H127: =IF(LEFT(E127,3)="lvl",IF(OR(RIGHT(B127,2)="_1",RIGHT(B127,2)="_2"),MID(B127,14,LEN(B127)-15), MID(B127,14,LEN(B127))),MID(B127,12,LEN(B127))) -> 0391_nmbr_scrts_rprtng_entty
B128: b0200_frmt_0400_accrd_intrst_scrty | C128: 0 | E128: =+MID(B128,7,4) -> frmt | F128: =IF(LEFT(E128,3)="lvl",MID(B128,12,1),"f") -> f | G128: =+LEFT(B128,3)&"."&MID(B128,4,2) -> b02.00 | H128: =IF(LEFT(E128,3)="lvl",IF(OR(RIGHT(B128,2)="_1",RIGHT(B128,2)="_2"),MID(B128,14,LEN(B128)-15), MID(B128,14,LEN(B128))),MID(B128,12,LEN(B128))) -> 0400_accrd_intrst_scrty
B129: b0200_frmt_0410_fees_charges_scrty | C129: 0 | E129: =+MID(B129,7,4) -> frmt | F129: =IF(LEFT(E129,3)="lvl",MID(B129,12,1),"f") -> f | G129: =+LEFT(B129,3)&"."&MID(B129,4,2) -> b02.00 | H129: =IF(LEFT(E129,3)="lvl",IF(OR(RIGHT(B129,2)="_1",RIGHT(B129,2)="_2"),MID(B129,14,LEN(B129)-15), MID(B129,14,LEN(B129))),MID(B129,12,LEN(B129))) -> 0410_fees_charges_scrty
...

Sheet 2.2. Outros
B6: 2.2. Outros Controlos
B8: TABELA | C8: CAMPO | D8: TIPOLOGIA_TESTE | E8: NUM_REG | F8: NUM_REG_DIF | G8: DETALHE | H8: Table | I8: Justificação
B9: BU_LOANTAPE_WORK.OUT_B0200_MAIN_LIABILITIES | C9: 0010_ROW_NMBR | D9: VALIDADE | E9: 8 | F9: 0 | H9: =MID(B9,22,3)&"."&MID(B9,25,2) -> B02.00
B10: BU_LOANTAPE_WORK.OUT_B0200_MAIN_LIABILITIES | C10: 0010_ROW_NMBR | D10: NOT APPLICABLE | E10: 8 | F10: 0 | H10: =MID(B10,22,3)&"."&MID(B10,25,2) -> B02.00
B11: BU_LOANTAPE_WORK.OUT_B0200_MAIN_LIABILITIES | C11: 0020_UNIQ_ID | D11: VALIDADE | E11: 8 | F11: 0 | H11: =MID(B11,22,3)&"."&MID(B11,25,2) -> B02.00
B12: BU_LOANTAPE_WORK.OUT_B0200_MAIN_LIABILITIES | C12: 0020_UNIQ_ID | D12: NOT APPLICABLE | E12: 8 | F12: 0 | H12: =MID(B12,22,3)&"."&MID(B12,25,2) -> B02.00
B13: BU_LOANTAPE_WORK.OUT_B0200_MAIN_LIABILITIES | C13: 0030_UNIQ_ID_KNWN_CNTRPRTY | D13: VALIDADE | E13: 8 | F13: 0 | H13: =MID(B13,22,3)&"."&MID(B13,25,2) -> B02.00
B14: BU_LOANTAPE_WORK.OUT_B0200_MAIN_LIABILITIES | C14: 0030_UNIQ_ID_KNWN_CNTRPRTY | D14: NOT APPLICABLE | E14: 8 | F14: 0 | H14: =MID(B14,22,3)&"."&MID(B14,25,2) -> B02.00
B15: BU_LOANTAPE_WORK.OUT_B0200_MAIN_LIABILITIES | C15: 0040_TYP_UNIQ_ID_KNWN_CNTRPRTY | D15: VALIDADE | E15: 8 | F15: 0 | H15: =MID(B15,22,3)&"."&MID(B15,25,2) -> B02.00
B16: BU_LOANTAPE_WORK.OUT_B0200_MAIN_LIABILITIES | C16: 0040_TYP_UNIQ_ID_KNWN_CNTRPRTY | D16: NOT APPLICABLE | E16: 8 | F16: 0 | H16: =MID(B16,22,3)&"."&MID(B16,25,2) -> B02.00
B17: BU_LOANTAPE_WORK.OUT_B0200_MAIN_LIABILITIES | C17: 0050_ORGNL_AMNT_EUR | D17: VALIDADE | E17: 8 | F17: 0 | H17: =MID(B17,22,3)&"."&MID(B17,25,2) -> B02.00
B18: BU_LOANTAPE_WORK.OUT_B0200_MAIN_LIABILITIES | C18: 0050_ORGNL_AMNT_EUR | D18: NOT APPLICABLE | E18: 8 | F18: 0 | H18: =MID(B18,22,3)&"."&MID(B18,25,2) -> B02.00
B19: BU_LOANTAPE_WORK.OUT_B0200_MAIN_LIABILITIES | C19: 0060_ORGNL_AMNT_FX | D19: VALIDADE | E19: 8 | F19: 0 | H19: =MID(B19,22,3)&"."&MID(B19,25,2) -> B02.00 | I19: TESTE
B20: BU_LOANTAPE_WORK.OUT_B0200_MAIN_LIABILITIES | C20: 0060_ORGNL_AMNT_FX | D20: NOT APPLICABLE | E20: 8 | F20: 0 | H20: =MID(B20,22,3)&"."&MID(B20,25,2) -> B02.00
B21: BU_LOANTAPE_WORK.OUT_B0200_MAIN_LIABILITIES | C21: 0070_CNTRCT_CRRNCY | D21: VALIDADE | E21: 8 | F21: 0 | H21: =MID(B21,22,3)&"."&MID(B21,25,2) -> B02.00
B22: BU_LOANTAPE_WORK.OUT_B0200_MAIN_LIABILITIES | C22: 0070_CNTRCT_CRRNCY | D22: NOT APPLICABLE | E22: 8 | F22: 0 | H22: =MID(B22,22,3)&"."&MID(B22,25,2) -> B02.00
B23: BU_LOANTAPE_WORK.OUT_B0200_MAIN_LIABILITIES | C23: 0100_ACCRD_INTRST_INSTRMNT | D23: VALIDADE | E23: 8 | F23: 0 | H23: =MID(B23,22,3)&"."&MID(B23,25,2) -> B02.00
B24: BU_LOANTAPE_WORK.OUT_B0200_MAIN_LIABILITIES | C24: 0100_ACCRD_INTRST_INSTRMNT | D24: NOT APPLICABLE | E24: 8 | F24: 0 | H24: =MID(B24,22,3)&"."&MID(B24,25,2) -> B02.00
B25: BU_LOANTAPE_WORK.OUT_B0200_MAIN_LIABILITIES | C25: 0110_APPLCBL_FEES_CHARGES | D25: VALIDADE | E25: 8 | F25: 0 | H25: =MID(B25,22,3)&"."&MID(B25,25,2) -> B02.00
B26: BU_LOANTAPE_WORK.OUT_B0200_MAIN_LIABILITIES | C26: 0110_APPLCBL_FEES_CHARGES | D26: NOT APPLICABLE | E26: 8 | F26: 0 | H26: =MID(B26,22,3)&"."&MID(B26,25,2) -> B02.00
B27: BU_LOANTAPE_WORK.OUT_B0200_MAIN_LIABILITIES | C27: 0140_NTR_LBLTY | D27: VALIDADE | E27: 8 | F27: 0 | H27: =MID(B27,22,3)&"."&MID(B27,25,2) -> B02.00
B28: BU_LOANTAPE_WORK.OUT_B0200_MAIN_LIABILITIES | C28: 0140_NTR_LBLTY | D28: NOT APPLICABLE | E28: 8 | F28: 0 | H28: =MID(B28,22,3)&"."&MID(B28,25,2) -> B02.00
B29: BU_LOANTAPE_WORK.OUT_B0200_MAIN_LIABILITIES | C29: 0141_NTR_LBLTY_OTHR | D29: VALIDADE | E29: 8 | F29: 0 | H29: =MID(B29,22,3)&"."&MID(B29,25,2) -> B02.00
B30: BU_LOANTAPE_WORK.OUT_B0200_MAIN_LIABILITIES | C30: 0141_NTR_LBLTY_OTHR | D30: NOT APPLICABLE | E30: 8 | F30: 8 | H30: =MID(B30,22,3)&"."&MID(B30,25,2) -> B02.00
B31: BU_LOANTAPE_WORK.OUT_B0200_MAIN_LIABILITIES | C31: 0150_FLG_STRCTRLLY_SBRDNTD | D31: VALIDADE | E31: 8 | F31: 0 | H31: =MID(B31,22,3)&"."&MID(B31,25,2) -> B02.00
... B33: BU_LOANTAPE_WORK.OUT_B0200_MAIN_LIABILITIES | C33: 0160_RANK_INSOLV | D33: VALIDADE | E33: 8 | F33: 0 | H33: =MID(B33,22,3)&"."&MID(B33,25,2) -> B02.00
B34: BU_LOANTAPE_WORK.OUT_B0200_MAIN_LIABILITIES | C34: 0160_RANK_INSOLV | D34: NOT APPLICABLE | E34: 8 | F34: 0 | H34: =MID(B34,22,3)&"."&MID(B34,25,2) -> B02.00 | I34: TESTE
B35: BU_LOANTAPE_WORK.OUT_B0200_MAIN_LIABILITIES | C35: 0161_CNTRCTL_SBRDNTN | D35: VALIDADE | E35: 8 | F35: 0 | H35: =MID(B35,22,3)&"."&MID(B35,25,2) -> B02.00
B36: BU_LOANTAPE_WORK.OUT_B0200_MAIN_LIABILITIES | C36: 0161_CNTRCTL_SBRDNTN | D36: NOT APPLICABLE | E36: 8 | F36: 0 | H36: =MID(B36,22,3)&"."&MID(B36,25,2) -> B02.00
B37: BU_LOANTAPE_WORK.OUT_B0200_MAIN_LIABILITIES | C37: 0162_BAIL_IN_CASCADE | D37: VALIDADE | E37: 8 | F37: 0 | H37: =MID(B37,22,3)&"."&MID(B37,25,2) -> B02.00
B38: BU_LOANTAPE_WORK.OUT_B0200_MAIN_LIABILITIES | C38: 0162_BAIL_IN_CASCADE | D38: NOT APPLICABLE | E38: 8 | F38: 0 | H38: =MID(B38,22,3)&"."&MID(B38,25,2) -> B02.00
B39: BU_LOANTAPE_WORK.OUT_B0200_MAIN_LIABILITIES | C39: 0170_DT_INCPTN | D39: VALIDADE | E39: 8 | F39: 0 | H39: =MID(B39,22,3)&"."&MID(B39,25,2) -> B02.00
B40: BU_LOANTAPE_WORK.OUT_B0200_MAIN_LIABILITIES | C40: 0170_DT_INCPTN | D40: NOT APPLICABLE | E40: 8 | F40: 0 | H40: =MID(B40,22,3)&"."&MID(B40,25,2) -> B02.00
B41: BU_LOANTAPE_WORK.OUT_B0200_MAIN_LIABILITIES | C41: 0180_DT_NXT_INTRST_PYMNT | D41: VALIDADE | E41: 8 | F41: 8 | H41: =MID(B41,22,3)&"."&MID(B41,25,2) -> B02.00
B42: BU_LOANTAPE_WORK.OUT_B0200_MAIN_LIABILITIES | C42: 0180_DT_NXT_INTRST_PYMNT | D42: NOT APPLICABLE | E42: 8 | F42: 0 | H42: =MID(B42,22,3)&"."&MID(B42,25,2) -> B02.00
B43: BU_LOANTAPE_WORK.OUT_B0200_MAIN_LIABILITIES | C43: 0190_DT_NXT_RDMPTN_PYMNT | D43: VALIDADE | E43: 8 | F43: 0 | H43: =MID(B43,22,3)&"."&MID(B43,25,2) -> B02.00
B44: BU_LOANTAPE_WORK.OUT_B0200_MAIN_LIABILITIES | C44: 0190_DT_NXT_RDMPTN_PYMNT | D44: NOT APPLICABLE | E44: 8 | F44: 3 | H44: =MID(B44,22,3)&"."&MID(B44,25,2) -> B02.00
B45: BU_LOANTAPE_WORK.OUT_B0200_MAIN_LIABILITIES | C45: 0200_DT_ERLST_RDMPTN | D45: VALIDADE | E45: 8 | F45: 0 | H45: =MID(B45,22,3)&"."&MID(B45,25,2) -> B02.00
B46: BU_LOANTAPE_WORK.OUT_B0200_MAIN_LIABILITIES | C46: 0200_DT_ERLST_RDMPTN | D46: NOT APPLICABLE | E46: 8 | F46: 8 | H46: =MID(B46,22,3)&"."&MID(B46,25,2) -> B02.00
... B127: BU_LOANTAPE_WORK.OUT_B0200_MAIN_LIABILITIES | C127: 0540_ELGBL_AMNT_OWN_FNDS_IND_LVL | D127: VALIDADE | E127: 8 | F127: 0 | H127: =MID(B127,22,3)&"."&MID(B127,25,2) -> B02.00
...

Sheet 2.2. Outros - TESTE
B6: 2.2. Outros Controlos
B8: TABELA | C8: CAMPO | D8: TIPOLOGIA_TESTE | E8: NUM_REG | F8: NUM_REG_DIF | G8: DETALHE | H8: Table | I8: Justificação

Sheet 2.3. Processo
B6: 2.3. Controlos de Processo (HUE vs CSV)
C8: B02.00
C9: Tabela HUE | G9: Tabela CSV | K9: Controlos
C11: CAMPO 1 | D11: CAMPO 2 | E11: CAMPO 3 | G11: CAMPO 1 | H11: CAMPO 2 | I11: CAMPO 3 | K11: =+C11=G11 -> TRUE | L11: =+D11=H11 -> TRUE | M11: =+E11=I11 -> TRUE
C12: Valor 1 | D12: Valor 2 | E12: Valor 3 | G12: Valor 1 | H12: Valor 2 | I12: Valor 3 | K12: =+C12=G12 -> TRUE | L12: =+D12=H12 -> TRUE | M12: =+E12=I12 -> TRUE
C13: Valor 1 | D13: Valor 2 | E13: Valor 3 | G13: Valor 1 | H13: Valor 2 | I13: Valor 3 | K13: =+C13=G13 -> TRUE | L13: =+D13=H13 -> TRUE | M13: =+E13=I13 -> TRUE
C15: B50.00
C16: Tabela HUE | G16: Tabela CSV | K16: Controlos
C18: CAMPO 1 | D18: CAMPO 2 | E18: CAMPO 3 | G18: CAMPO 1 | H18: CAMPO 2 | I18: CAMPO 3 | K18: =+C18=G18 -> TRUE | L18: =+D18=H18 -> TRUE | M18: =+E18=I18 -> TRUE
C19: Valor 1 | D19: Valor 2 | E19: Valor 3 | G19: Valor 1 | H19: Valor 2 | I19: Valor 3 | K19: =+C19=G19 -> TRUE | L19: =+D19=H19 -> TRUE | M19: =+E19=I19 -> TRUE
C20: Valor 1 | D20: Valor 2 | E20: Valor 3 | G20: Valor 1 | H20: Valor 2 | I20: Valor 3 | K20: =+C20=G20 -> TRUE | L20: =+D20=H20 -> TRUE | M20: =+E20=I20 -> TRUE
C22: B90.00
C23: Tabela HUE | G23: Tabela CSV | K23: Controlos
C25: CAMPO 1 | D25: CAMPO 2 | E25: CAMPO 3 | G25: CAMPO 1 | H25: CAMPO 2 | I25: CAMPO 3 | K25: =+C25=G25 -> TRUE | L25: =+D25=H25 -> TRUE | M25: =+E25=I25 -> TRUE
C26: Valor 1 | D26: Valor 2 | E26: Valor 3 | G26: Valor 1 | H26: Valor 2 | I26: Valor 3 | K26: =+C26=G26 -> TRUE | L26: =+D26=H26 -> TRUE | M26: =+E26=I26 -> TRUE
C27: Valor 1 | D27: Valor 2 | E27: Valor 3 | G27: Valor 1 | H27: Valor 2 | I27: Valor 3 | K27: =+C27=G27 -> TRUE | L27: =+D27=H27 -> TRUE | M27: =+E27=I27 -> TRUE
