Workbook
Name RefDateCell: '1. Dashboard'!$D$12

Sheet Instruções
B6: Instruções
C8: 1.
C9: 2.
C10: 3.

Sheet Param_RefDate
A1: Param_RefDate
A2: 2025-10-31

Sheet 1. Dashboard
B6: 1 Dashboard
B9: Controlos Reporte Bail-in
C12: Data de referência | D12: 2025-10-31
D15: MENU 1 | G15: MENU 2 | J15: NAVEGADOR
D18: TABELAS OUTPUT | G18: Processo (HUE vs CSV) | J18: Processo (HUE vs CSV)
D20: 1. Gerar Controlos | E20: [BOTÃO] | G20: 1. Gerar Controlos | H20: [BOTÃO] | J20: 1. Detalhe controlos às tabelas output | L20: [LINK]
J22: 2. Detalhe controlos ao processo (CSV) | L22: [LINK]
H29: DASHBOARD
C32: 1. Reconciliação
C59: 2. Tabelas Output
G61: NOK
C62: Mapa | D62: Total (#) | E62: OK (#) | F62: OK (%) | G62: Justificados(#) | H62: Justificados (%) | I62: Não Justificados(#) | J62: Não Justificados (%)
C63: B02.00 | D63: =+SUM(D64,D68) -> 233 | E63: =+SUM(E64,E68) -> 203 | F63: =IFERROR(E63/D63,0) -> 0.87124464 | G63: =+SUM(G64,G68) -> 6 | H63: =IFERROR(G63/D63,0) -> 0.025751073 | I63: =+SUM(I64,I68) -> 24 | J63: =IFERROR(I63/D63,0) -> 0.10300429
C64: Regulamentares (SRB) | D64: =+SUM(D65:D67) -> 151 | E64: =+SUM(E65:E67) -> 128 | F64: =IFERROR(E64/D64,0) -> 0.84768212 | G64: =+SUM(G65:G67) -> 6 | H64: =IFERROR(G64/D64,0) -> 0.039735099 | I64: =+SUM(I65:I67) -> 17 | J64: =IFERROR(I64/D64,0) -> 0.11258278
C65: High severity | D65: =+COUNTIFS('2.1. Controlos'!J:J,"BU_LOANTAPE_WORK.OUT_B0200_MAIN_LIABILITIES",'2.1. Controlos'!C:C,"H") -> 58 | E65: =+COUNTIFS('2.1. Controlos'!J:J,"BU_LOANTAPE_WORK.OUT_B0200_MAIN_LIABILITIES",'2.1. Controlos'!C:C,"H",'2.1. Controlos'!M:M,0) -> 52 | F65: =IFERROR(E65/D65,0) -> 0.89655172 | G65: =+COUNTIFS('2.1. Controlos'!J:J,"BU_LOANTAPE_WORK.OUT_B0200_MAIN_LIABILITIES",'2.1. Controlos'!C:C,"H",'2.1. Controlos'!M:M,">0",'2.1. Controlos'!P:P,"<>") -> 0 | H65: =IFERROR(G65/D65,0) -> 0 | I65: =+COUNTIFS('2.1. Controlos'!J:J,"BU_LOANTAPE_WORK.OUT_B0200_MAIN_LIABILITIES",'2.1. Controlos'!C:C,"H",'2.1. Controlos'!M:M,">0",'2.1. Controlos'!P:P,"") -> 6 | J65: =IFERROR(I65/D65,0) -> 0.10344828
C66: Warnings | D66: =+COUNTIFS('2.1. Controlos'!J:J,"BU_LOANTAPE_WORK.OUT_B0200_MAIN_LIABILITIES",'2.1. Controlos'!C:C,"W") -> 12 | E66: =+COUNTIFS('2.1. Controlos'!J:J,"BU_LOANTAPE_WORK.OUT_B0200_MAIN_LIABILITIES",'2.1. Controlos'!C:C,"W",'2.1. Controlos'!M:M,0) -> 10 | F66: =IFERROR(E66/D66,0) -> 0.83333333 | G66: =+COUNTIFS('2.1. Controlos'!J:J,"BU_LOANTAPE_WORK.OUT_B0200_MAIN_LIABILITIES",'2.1. Controlos'!C:C,"W",'2.1. Controlos'!M:M,">0",'2.1. Controlos'!P:P,"<>") -> 0 | H66: =IFERROR(G66/D66,0) -> 0 | I66: =+COUNTIFS('2.1. Controlos'!J:J,"BU_LOANTAPE_WORK.OUT_B0200_MAIN_LIABILITIES",'2.1. Controlos'!C:C,"W",'2.1. Controlos'!M:M,">0",'2.1. Controlos'!P:P,"") -> 2 | J66: =IFERROR(I66/D66,0) -> 0.16666667
C67: Formatos | D67: =+COUNTIFS('2.1. Controlos'!J:J,"BU_LOANTAPE_WORK.OUT_B0200_MAIN_LIABILITIES",'2.1. Controlos'!C:C,"F") -> 81 | E67: =+COUNTIFS('2.1. Controlos'!J:J,"BU_LOANTAPE_WORK.OUT_B0200_MAIN_LIABILITIES",'2.1. Controlos'!C:C,"F",'2.1. Controlos'!M:M,0) -> 66 | F67: =IFERROR(E67/D67,0) -> 0.81481481 | G67: =+COUNTIFS('2.1. Controlos'!J:J,"BU_LOANTAPE_WORK.OUT_B0200_MAIN_LIABILITIES",'2.1. Controlos'!C:C,"F",'2.1. Controlos'!M:M,">0",'2.1. Controlos'!P:P,"<>") -> 6 | H67: =IFERROR(G67/D67,0) -> 0.074074074 | I67: =+COUNTIFS('2.1. Controlos'!J:J,"BU_LOANTAPE_WORK.OUT_B0200_MAIN_LIABILITIES",'2.1. Controlos'!C:C,"F",'2.1. Controlos'!M:M,">0",'2.1. Controlos'!P:P,"") -> 9 | J67: =IFERROR(I67/D67,0) -> 0.11111111
C68: Outros | D68: =+SUM(D69:D72) -> 82 | E68: =+SUM(E69:E72) -> 75 | F68: =IFERROR(E68/D68,0) -> 0.91463415 | G68: =+SUM(G69:G72) -> 0 | H68: =IFERROR(G68/D68,0) -> 0 | I68: =+SUM(I69:I72) -> 7 | J68: =IFERROR(I68/D68,0) -> 0.085365854
C69: Validade (Missings/NULLS) | D69: =+COUNTIFS('2.1. Controlos'!J:J,"BU_LOANTAPE_WORK.OUT_B0200_MAIN_LIABILITIES",'2.1. Controlos'!H:H,"MISSINGS") -> 81 | E69: =+COUNTIFS('2.1. Controlos'!J:J,"BU_LOANTAPE_WORK.OUT_B0200_MAIN_LIABILITIES",'2.1. Controlos'!H:H,"MISSINGS",'2.1. Controlos'!M:M,0) -> 74 | F69: =IFERROR(E69/D69,0) -> 0.91358025 | G69: =+COUNTIFS('2.1. Controlos'!J:J,"BU_LOANTAPE_WORK.OUT_B0200_MAIN_LIABILITIES",'2.1. Controlos'!H:H,"MISSINGS",'2.1. Controlos'!M:M,">0",'2.1. Controlos'!P:P,"<>") -> 0 | H69: =IFERROR(G69/D69,0) -> 0 | I69: =+COUNTIFS('2.1. Controlos'!J:J,"BU_LOANTAPE_WORK.OUT_B0200_MAIN_LIABILITIES",'2.1. Controlos'!H:H,"MISSINGS",'2.1. Controlos'!M:M,">0",'2.1. Controlos'!P:P,"") -> 7 | J69: =IFERROR(I69/D69,0) -> 0.086419753
C70: Not applicables | F70: =IFERROR(E70/D70,0) -> 0 | H70: =IFERROR(G70/D70,0) -> 0 | J70: =IFERROR(I70/D70,0) -> 0
C71: Duplicados | D71: =+COUNTIFS('2.1. Controlos'!J:J,"BU_LOANTAPE_WORK.OUT_B0200_MAIN_LIABILITIES",'2.1. Controlos'!H:H,"DUPLICADOS") -> 1 | E71: =+COUNTIFS('2.1. Controlos'!J:J,"BU_LOANTAPE_WORK.OUT_B0200_MAIN_LIABILITIES",'2.1. Controlos'!H:H,"DUPLICADOS",'2.1. Controlos'!M:M,0) -> 1 | F71: =IFERROR(E71/D71,0) -> 1 | G71: =+COUNTIFS('2.1. Controlos'!J:J,"BU_LOANTAPE_WORK.OUT_B0200_MAIN_LIABILITIES",'2.1. Controlos'!H:H,"DUPLICADOS",'2.1. Controlos'!M:M,">0",'2.1. Controlos'!P:P,"<>") -> 0 | H71: =IFERROR(G71/D71,0) -> 0 | I71: =+COUNTIFS('2.1. Controlos'!J:J,"BU_LOANTAPE_WORK.OUT_B0200_MAIN_LIABILITIES",'2.1. Controlos'!H:H,"DUPLICADOS",'2.1. Controlos'!M:M,">0",'2.1. Controlos'!P:P,"") -> 0 | J71: =IFERROR(I71/D71,0) -> 0
C72: Integridade entre tabelas | F72: =IFERROR(E72/D72,0) -> 0 | H72: =IFERROR(G72/D72,0) -> 0 | J72: =IFERROR(I72/D72,0) -> 0
C73: B05.00 | D73: =+SUM(D74,D78) -> 36 | E73: =+SUM(E74,E78) -> 32 | F73: =IFERROR(E73/D73,0) -> 0.88888889 | G73: =+SUM(G74,G78) -> 2 | H73: =IFERROR(G73/D73,0) -> 0.055555556 | I73: =+SUM(I74,I78) -> 2 | J73: =IFERROR(I73/D73,0) -> 0.055555556
C74: Regulamentares (SRB) | D74: =+SUM(D75:D77) -> 20 | E74: =+SUM(E75:E77) -> 17 | F74: =IFERROR(E74/D74,0) -> 0.85 | G74: =+SUM(G75:G77) -> 2 | H74: =IFERROR(G74/D74,0) -> 0.1 | I74: =+SUM(I75:I77) -> 1 | J74: =IFERROR(I74/D74,0) -> 0.05
C75: High severity | D75: =+COUNTIFS('2.1. Controlos'!J:J,"BU_LOANTAPE_WORK.OUT_B0500_GUARANTEES",'2.1. Controlos'!C:C,"H") -> 5 | E75: =+COUNTIFS('2.1. Controlos'!J:J,"BU_LOANTAPE_WORK.OUT_B0500_GUARANTEES",'2.1. Controlos'!C:C,"H",'2.1. Controlos'!M:M,0) -> 4 | F75: =IFERROR(E75/D75,0) -> 0.8 | G75: =+COUNTIFS('2.1. Controlos'!J:J,"BU_LOANTAPE_WORK.OUT_B0500_GUARANTEES",'2.1. Controlos'!C:C,"H",'2.1. Controlos'!M:M,">0",'2.1. Controlos'!P:P,"<>") -> 0 | H75: =IFERROR(G75/D75,0) -> 0 | I75: =+COUNTIFS('2.1. Controlos'!J:J,"BU_LOANTAPE_WORK.OUT_B0500_GUARANTEES",'2.1. Controlos'!C:C,"H",'2.1. Controlos'!M:M,">0",'2.1. Controlos'!P:P,"") -> 1 | J75: =IFERROR(I75/D75,0) -> 0.2
C76: Warnings | D76: =+COUNTIFS('2.1. Controlos'!J:J,"BU_LOANTAPE_WORK.OUT_B0500_GUARANTEES",'2.1. Controlos'!C:C,"W") -> 0 | E76: =+COUNTIFS('2.1. Controlos'!J:J,"BU_LOANTAPE_WORK.OUT_B0500_GUARANTEES",'2.1. Controlos'!C:C,"W",'2.1. Controlos'!M:M,0) -> 0 | F76: =IFERROR(E76/D76,0) -> 0 | G76: =+COUNTIFS('2.1. Controlos'!J:J,"BU_LOANTAPE_WORK.OUT_B0500_GUARANTEES",'2.1. Controlos'!C:C,"W",'2.1. Controlos'!M:M,">0",'2.1. Controlos'!P:P,"<>") -> 0 | H76: =IFERROR(G76/D76,0) -> 0 | I76: =+COUNTIFS('2.1. Controlos'!J:J,"BU_LOANTAPE_WORK.OUT_B0500_GUARANTEES",'2.1. Controlos'!C:C,"W",'2.1. Controlos'!M:M,">0",'2.1. Controlos'!P:P,"") -> 0 | J76: =IFERROR(I76/D76,0) -> 0
C77: Formatos | D77: =+COUNTIFS('2.1. Controlos'!J:J,"BU_LOANTAPE_WORK.OUT_B0500_GUARANTEES",'2.1. Controlos'!C:C,"F") -> 15 | E77: =+COUNTIFS('2.1. Controlos'!J:J,"BU_LOANTAPE_WORK.OUT_B0500_GUARANTEES",'2.1. Controlos'!C:C,"F",'2.1. Controlos'!M:M,0) -> 13 | F77: =IFERROR(E77/D77,0) -> 0.86666667 | G77: =+COUNTIFS('2.1. Controlos'!J:J,"BU_LOANTAPE_WORK.OUT_B0500_GUARANTEES",'2.1. Controlos'!C:C,"F",'2.1. Controlos'!M:M,">0",'2.1. Controlos'!P:P,"<>") -> 2 | H77: =IFERROR(G77/D77,0) -> 0.13333333 | I77: =+COUNTIFS('2.1. Controlos'!J:J,"BU_LOANTAPE_WORK.OUT_B0500_GUARANTEES",'2.1. Controlos'!C:C,"F",'2.1. Controlos'!M:M,">0",'2.1. Controlos'!P:P,"") -> 0 | J77: =IFERROR(I77/D77,0) -> 0
C78: Outros | D78: =+SUM(D79:D82) -> 16 | E78: =+SUM(E79:E82) -> 15 | F78: =IFERROR(E78/D78,0) -> 0.9375 | G78: =+SUM(G79:G82) -> 0 | H78: =IFERROR(G78/D78,0) -> 0 | I78: =+SUM(I79:I82) -> 1 | J78: =IFERROR(I78/D78,0) -> 0.0625
C79: Validade (Missings/NULLS) | D79: =+COUNTIFS('2.1. Controlos'!J:J,"BU_LOANTAPE_WORK.OUT_B0500_GUARANTEES",'2.1. Controlos'!H:H,"MISSINGS") -> 15 | E79: =+COUNTIFS('2.1. Controlos'!J:J,"BU_LOANTAPE_WORK.OUT_B0500_GUARANTEES",'2.1. Controlos'!H:H,"MISSINGS",'2.1. Controlos'!M:M,0) -> 14 | F79: =IFERROR(E79/D79,0) -> 0.93333333 | G79: =+COUNTIFS('2.1. Controlos'!J:J,"BU_LOANTAPE_WORK.OUT_B0500_GUARANTEES",'2.1. Controlos'!H:H,"MISSINGS",'2.1. Controlos'!M:M,">0",'2.1. Controlos'!P:P,"<>") -> 0 | H79: =IFERROR(G79/D79,0) -> 0 | I79: =+COUNTIFS('2.1. Controlos'!J:J,"BU_LOANTAPE_WORK.OUT_B0500_GUARANTEES",'2.1. Controlos'!H:H,"MISSINGS",'2.1. Controlos'!M:M,">0",'2.1. Controlos'!P:P,"") -> 1 | J79: =IFERROR(I79/D79,0) -> 0.066666667
C80: Not applicables | F80: =IFERROR(E80/D80,0) -> 0 | H80: =IFERROR(G80/D80,0) -> 0 | J80: =IFERROR(I80/D80,0) -> 0
C81: Duplicados | D81: =+COUNTIFS('2.1. Controlos'!J:J,"BU_LOANTAPE_WORK.OUT_B0500_GUARANTEES",'2.1. Controlos'!H:H,"DUPLICADOS") -> 1 | E81: =+COUNTIFS('2.1. Controlos'!J:J,"BU_LOANTAPE_WORK.OUT_B0500_GUARANTEES",'2.1. Controlos'!H:H,"DUPLICADOS",'2.1. Controlos'!M:M,0) -> 1 | F81: =IFERROR(E81/D81,0) -> 1 | G81: =+COUNTIFS('2.1. Controlos'!J:J,"BU_LOANTAPE_WORK.OUT_B0500_GUARANTEES",'2.1. Controlos'!H:H,"DUPLICADOS",'2.1. Controlos'!M:M,">0",'2.1. Controlos'!P:P,"<>") -> 0 | H81: =IFERROR(G81/D81,0) -> 0 | I81: =+COUNTIFS('2.1. Controlos'!J:J,"BU_LOANTAPE_WORK.OUT_B0500_GUARANTEES",'2.1. Controlos'!H:H,"DUPLICADOS",'2.1. Controlos'!M:M,">0",'2.1. Controlos'!P:P,"") -> 0 | J81: =IFERROR(I81/D81,0) -> 0
C82: Integridade entre tabelas | F82: =IFERROR(E82/D82,0) -> 0 | H82: =IFERROR(G82/D82,0) -> 0 | J82: =IFERROR(I82/D82,0) -> 0
C83: B90.00 | D83: =+SUM(D84,D88) -> 27 | E83: =+SUM(E84,E88) -> 20 | F83: =IFERROR(E83/D83,0) -> 0.74074074 | G83: =+SUM(G84,G88) -> 2 | H83: =IFERROR(G83/D83,0) -> 0.074074074 | I83: =+SUM(I84,I88) -> 5 | J83: =IFERROR(I83/D83,0) -> 0.18518519
C84: Regulamentares (SRB) | D84: =+SUM(D85:D87) -> 15 | E84: =+SUM(E85:E87) -> 11 | F84: =IFERROR(E84/D84,0) -> 0.73333333 | G84: =+SUM(G85:G87) -> 2 | H84: =IFERROR(G84/D84,0) -> 0.13333333 | I84: =+SUM(I85:I87) -> 2 | J84: =IFERROR(I84/D84,0) -> 0.13333333
C85: High severity | D85: =+COUNTIFS('2.1. Controlos'!J:J,"BU_LOANTAPE_WORK.OUT_B9000_COUNTERPARTIES",'2.1. Controlos'!C:C,"H") -> 4 | E85: =+COUNTIFS('2.1. Controlos'!J:J,"BU_LOANTAPE_WORK.OUT_B9000_COUNTERPARTIES",'2.1. Controlos'!C:C,"H",'2.1. Controlos'!M:M,0) -> 2 | F85: =IFERROR(E85/D85,0) -> 0.5 | G85: =+COUNTIFS('2.1. Controlos'!J:J,"BU_LOANTAPE_WORK.OUT_B9000_COUNTERPARTIES",'2.1. Controlos'!C:C,"H",'2.1. Controlos'!M:M,">0",'2.1. Controlos'!P:P,"<>") -> 1 | H85: =IFERROR(G85/D85,0) -> 0.25 | I85: =+COUNTIFS('2.1. Controlos'!J:J,"BU_LOANTAPE_WORK.OUT_B9000_COUNTERPARTIES",'2.1. Controlos'!C:C,"H",'2.1. Controlos'!M:M,">0",'2.1. Controlos'!P:P,"") -> 1 | J85: =IFERROR(I85/D85,0) -> 0.25
C86: Warnings | D86: =+COUNTIFS('2.1. Controlos'!J:J,"BU_LOANTAPE_WORK.OUT_B9000_COUNTERPARTIES",'2.1. Controlos'!C:C,"W") -> 0 | E86: =+COUNTIFS('2.1. Controlos'!J:J,"BU_LOANTAPE_WORK.OUT_B9000_COUNTERPARTIES",'2.1. Controlos'!C:C,"W",'2.1. Controlos'!M:M,0) -> 0 | F86: =IFERROR(E86/D86,0) -> 0 | G86: =+COUNTIFS('2.1. Controlos'!J:J,"BU_LOANTAPE_WORK.OUT_B9000_COUNTERPARTIES",'2.1. Controlos'!C:C,"W",'2.1. Controlos'!M:M,">0",'2.1. Controlos'!P:P,"<>") -> 0 | H86: =IFERROR(G86/D86,0) -> 0 | I86: =+COUNTIFS('2.1. Controlos'!J:J,"BU_LOANTAPE_WORK.OUT_B9000_COUNTERPARTIES",'2.1. Controlos'!C:C,"W",'2.1. Controlos'!M:M,">0",'2.1. Controlos'!P:P,"") -> 0 | J86: =IFERROR(I86/D86,0) -> 0
C87: Formatos | D87: =+COUNTIFS('2.1. Controlos'!J:J,"BU_LOANTAPE_WORK.OUT_B9000_COUNTERPARTIES",'2.1. Controlos'!C:C,"F") -> 11 | E87: =+COUNTIFS('2.1. Controlos'!J:J,"BU_LOANTAPE_WORK.OUT_B9000_COUNTERPARTIES",'2.1. Controlos'!C:C,"F",'2.1. Controlos'!M:M,0) -> 9 | F87: =IFERROR(E87/D87,0) -> 0.81818182 | G87: =+COUNTIFS('2.1. Controlos'!J:J,"BU_LOANTAPE_WORK.OUT_B9000_COUNTERPARTIES",'2.1. Controlos'!C:C,"F",'2.1. Controlos'!M:M,">0",'2.1. Controlos'!P:P,"<>") -> 1 | H87: =IFERROR(G87/D87,0) -> 0.090909091 | I87: =+COUNTIFS('2.1. Controlos'!J:J,"BU_LOANTAPE_WORK.OUT_B9000_COUNTERPARTIES",'2.1. Controlos'!C:C,"F",'2.1. Controlos'!M:M,">0",'2.1. Controlos'!P:P,"") -> 1 | J87: =IFERROR(I87/D87,0) -> 0.090909091
C88: Outros | D88: =+SUM(D89:D92) -> 12 | E88: =+SUM(E89:E92) -> 9 | F88: =IFERROR(E88/D88,0) -> 0.75 | G88: =+SUM(G89:G92) -> 0 | H88: =IFERROR(G88/D88,0) -> 0 | I88: =+SUM(I89:I92) -> 3 | J88: =IFERROR(I88/D88,0) -> 0.25
C89: Validade (Missings/NULLS) | D89: =+COUNTIFS('2.1. Controlos'!J:J,"BU_LOANTAPE_WORK.OUT_B9000_COUNTERPARTIES",'2.1. Controlos'!H:H,"MISSINGS") -> 11 | E89: =+COUNTIFS('2.1. Controlos'!J:J,"BU_LOANTAPE_WORK.OUT_B9000_COUNTERPARTIES",'2.1. Controlos'!H:H,"MISSINGS",'2.1. Controlos'!M:M,0) -> 8 | F89: =IFERROR(E89/D89,0) -> 0.72727273 | G89: =+COUNTIFS('2.1. Controlos'!J:J,"BU_LOANTAPE_WORK.OUT_B9000_COUNTERPARTIES",'2.1. Controlos'!H:H,"MISSINGS",'2.1. Controlos'!M:M,">0",'2.1. Controlos'!P:P,"<>") -> 0 | H89: =IFERROR(G89/D89,0) -> 0 | I89: =+COUNTIFS('2.1. Controlos'!J:J,"BU_LOANTAPE_WORK.OUT_B9000_COUNTERPARTIES",'2.1. Controlos'!H:H,"MISSINGS",'2.1. Controlos'!M:M,">0",'2.1. Controlos'!P:P,"") -> 3 | J89: =IFERROR(I89/D89,0) -> 0.27272727
C90: Not applicables | F90: =IFERROR(E90/D90,0) -> 0 | H90: =IFERROR(G90/D90,0) -> 0 | J90: =IFERROR(I90/D90,0) -> 0
...

Sheet 2. Inputs -->

Sheet 2.1. Controlos
F6: 2.1. Controlos
B8: AUX_TAB | C8: AUX_SEVERITY | F8: ref_date | G8: cod_kpi | H8: tipologia_teste | I8: descrição | J8: tabela | K8: campo | L8: num_reg | M8: num_reg_dif | N8: detalhe | P8: Justificação
B9: =+IF(LEFT(MID(Controlos[[#This Row],[tabela]],22,5),1)="B",MID(Controlos[[#This Row],[tabela]],22,5),MID(Controlos[[#This Row],[tabela]],18,5)) -> B0200 | C9: =+IF(Controlos[[#This Row],[tipologia_teste]]="REGULAMENTAR",IF(LEFT(Controlos[[#This Row],[cod_kpi]],1)="v",IF(LEFT(Controlos[[#This Row],[descrição]],6)="Alerta","W","H"),"F"),0) -> 0 | F9: 2025-10-31 | G9: MIS_B0200_C0010 | H9: MISSINGS | I9: Validar que não existem registos por preencher (Missings) | J9: BU_LOANTAPE_WORK.OUT_B0200_MAIN_LIABILITIES | K9: 0010_ROW_NMBR | L9: 8 | M9: 0
B10: =+IF(LEFT(MID(Controlos[[#This Row],[tabela]],22,5),1)="B",MID(Controlos[[#This Row],[tabela]],22,5),MID(Controlos[[#This Row],[tabela]],18,5)) -> B0200 | C10: =+IF(Controlos[[#This Row],[tipologia_teste]]="REGULAMENTAR",IF(LEFT(Controlos[[#This Row],[cod_kpi]],1)="v",IF(LEFT(Controlos[[#This Row],[descrição]],6)="Alerta","W","H"),"F"),0) -> 0 | F10: 2025-10-31 | G10: MIS_B0200_C0020 | H10: MISSINGS | I10: Validar que não existem registos por preencher (Missings) | J10: BU_LOANTAPE_WORK.OUT_B0200_MAIN_LIABILITIES | K10: 0020_UNIQ_ID | L10: 8 | M10: 0
B11: =+IF(LEFT(MID(Controlos[[#This Row],[tabela]],22,5),1)="B",MID(Controlos[[#This Row],[tabela]],22,5),MID(Controlos[[#This Row],[tabela]],18,5)) -> B0200 | C11: =+IF(Controlos[[#This Row],[tipologia_teste]]="REGULAMENTAR",IF(LEFT(Controlos[[#This Row],[cod_kpi]],1)="v",IF(LEFT(Controlos[[#This Row],[descrição]],6)="Alerta","W","H"),"F"),0) -> 0 | F11: 2025-10-31 | G11: MIS_B0200_C0030 | H11: MISSINGS | I11: Validar que não existem registos por preencher (Missings) | J11: BU_LOANTAPE_WORK.OUT_B0200_MAIN_LIABILITIES | K11: 0030_UNIQ_ID_KNWN_CNTRPRTY | L11: 8 | M11: 0
B12: =+IF(LEFT(MID(Controlos[[#This Row],[tabela]],22,5),1)="B",MID(Controlos[[#This Row],[tabela]],22,5),MID(Controlos[[#This Row],[tabela]],18,5)) -> B0200 | C12: =+IF(Controlos[[#This Row],[tipologia_teste]]="REGULAMENTAR",IF(LEFT(Controlos[[#This Row],[cod_kpi]],1)="v",IF(LEFT(Controlos[[#This Row],[descrição]],6)="Alerta","W","H"),"F"),0) -> 0 | F12: 2025-10-31 | G12: MIS_B0200_C0040 | H12: MISSINGS | I12: Validar que não existem registos por preencher (Missings) | J12: BU_LOANTAPE_WORK.OUT_B0200_MAIN_LIABILITIES | K12: 0040_TYP_UNIQ_ID_KNWN_CNTRPRTY | L12: 8 | M12: 0
B13: =+IF(LEFT(MID(Controlos[[#This Row],[tabela]],22,5),1)="B",MID(Controlos[[#This Row],[tabela]],22,5),MID(Controlos[[#This Row],[tabela]],18,5)) -> B0200 | C13: =+IF(Controlos[[#This Row],[tipologia_teste]]="REGULAMENTAR",IF(LEFT(Controlos[[#This Row],[cod_kpi]],1)="v",IF(LEFT(Controlos[[#This Row],[descrição]],6)="Alerta","W","H"),"F"),0) -> 0 | F13: 2025-10-31 | G13: MIS_B0200_C0050 | H13: MISSINGS | I13: Validar que não existem registos por preencher (Missings) | J13: BU_LOANTAPE_WORK.OUT_B0200_MAIN_LIABILITIES | K13: 0050_ORGNL_AMNT_EUR | L13: 8 | M13: 0
B14: =+IF(LEFT(MID(Controlos[[#This Row],[tabela]],22,5),1)="B",MID(Controlos[[#This Row],[tabela]],22,5),MID(Controlos[[#This Row],[tabela]],18,5)) -> B0200 | C14: =+IF(Controlos[[#This Row],[tipologia_teste]]="REGULAMENTAR",IF(LEFT(Controlos[[#This Row],[cod_kpi]],1)="v",IF(LEFT(Controlos[[#This Row],[descrição]],6)="Alerta","W","H"),"F"),0) -> 0 | F14: 2025-10-31 | G14: MIS_B0200_C0060 | H14: MISSINGS | I14: Validar que não existem registos por preencher (Missings) | J14: BU_LOANTAPE_WORK.OUT_B0200_MAIN_LIABILITIES | K14: 0060_ORGNL_AMNT_FX | L14: 8 | M14: 0
B15: =+IF(LEFT(MID(Controlos[[#This Row],[tabela]],22,5),1)="B",MID(Controlos[[#This Row],[tabela]],22,5),MID(Controlos[[#This Row],[tabela]],18,5)) -> B0200 | C15: =+IF(Controlos[[#This Row],[tipologia_teste]]="REGULAMENTAR",IF(LEFT(Controlos[[#This Row],[cod_kpi]],1)="v",IF(LEFT(Controlos[[#This Row],[descrição]],6)="Alerta","W","H"),"F"),0) -> 0 | F15: 2025-10-31 | G15: MIS_B0200_C0070 | H15: MISSINGS | I15: Validar que não existem registos por preencher (Missings) | J15: BU_LOANTAPE_WORK.OUT_B0200_MAIN_LIABILITIES | K15: 0070_CNTRCT_CRRNCY | L15: 8 | M15: 0
B16: =+IF(LEFT(MID(Controlos[[#This Row],[tabela]],22,5),1)="B",MID(Controlos[[#This Row],[tabela]],22,5),MID(Controlos[[#This Row],[tabela]],18,5)) -> B0200 | C16: =+IF(Controlos[[#This Row],[tipologia_teste]]="REGULAMENTAR",IF(LEFT(Controlos[[#This Row],[cod_kpi]],1)="v",IF(LEFT(Controlos[[#This Row],[descrição]],6)="Alerta","W","H"),"F"),0) -> 0 | F16: 2025-10-31 | G16: MIS_B0200_C0080 | H16: MISSINGS | I16: Validar que não existem registos por preencher (Missings) | J16: BU_LOANTAPE_WORK.OUT_B0200_MAIN_LIABILITIES | K16: 0080_OTSTNDNG_PRNCPL_AMNT | L16: 8 | M16: 8 | N16: 31641600000000000PTBSREOM0028000; 31641600000000000PTSTOEOM0021000; 31641600000000000PTSTOFOM0004000; 31641600000000000PTSTOGOM0003000; 31641600000000000PTSTOHOM0002000; 31641600005800007PTBSRDOM0037000; 31641600005800007PTCPP0AM0007000; 31641600005800007PTSTOCOM0007000
B17: =+IF(LEFT(MID(Controlos[[#This Row],[tabela]],22,5),1)="B",MID(Controlos[[#This Row],[tabela]],22,5),MID(Controlos[[#This Row],[tabela]],18,5)) -> B0200 | C17: =+IF(Controlos[[#This Row],[tipologia_teste]]="REGULAMENTAR",IF(LEFT(Controlos[[#This Row],[cod_kpi]],1)="v",IF(LEFT(Controlos[[#This Row],[descrição]],6)="Alerta","W","H"),"F"),0) -> 0 | F17: 2025-10-31 | G17: MIS_B0200_C0090 | H17: MISSINGS | I17: Validar que não existem registos por preencher (Missings) | J17: BU_LOANTAPE_WORK.OUT_B0200_MAIN_LIABILITIES | K17: 0090_PRTN_AMNT_RPRTNG_ENTTY | L17: 8 | M17: 8 | N17: 31641600000000000PTBSREOM0028000; 31641600000000000PTSTOEOM0021000; 31641600000000000PTSTOFOM0004000; 31641600000000000PTSTOGOM0003000; 31641600000000000PTSTOHOM0002000; 31641600005800007PTBSRDOM0037000; 31641600005800007PTCPP0AM0007000; 31641600005800007PTSTOCOM0007000
B18: =+IF(LEFT(MID(Controlos[[#This Row],[tabela]],22,5),1)="B",MID(Controlos[[#This Row],[tabela]],22,5),MID(Controlos[[#This Row],[tabela]],18,5)) -> B0200 | C18: =+IF(Controlos[[#This Row],[tipologia_teste]]="REGULAMENTAR",IF(LEFT(Controlos[[#This Row],[cod_kpi]],1)="v",IF(LEFT(Controlos[[#This Row],[descrição]],6)="Alerta","W","H"),"F"),0) -> 0 | F18: 2025-10-31 | G18: MIS_B0200_C0100 | H18: MISSINGS | I18: Validar que não existem registos por preencher (Missings) | J18: BU_LOANTAPE_WORK.OUT_B0200_MAIN_LIABILITIES | K18: 0100_ACCRD_INTRST_INSTRMNT | L18: 8 | M18: 0
B19: =+IF(LEFT(MID(Controlos[[#This Row],[tabela]],22,5),1)="B",MID(Controlos[[#This Row],[tabela]],22,5),MID(Controlos[[#This Row],[tabela]],18,5)) -> B0200 | C19: =+IF(Controlos[[#This Row],[tipologia_teste]]="REGULAMENTAR",IF(LEFT(Controlos[[#This Row],[cod_kpi]],1)="v",IF(LEFT(Controlos[[#This Row],[descrição]],6)="Alerta","W","H"),"F"),0) -> 0 | F19: 2025-10-31 | G19: MIS_B0200_C0110 | H19: MISSINGS | I19: Validar que não existem registos por preencher (Missings) | J19: BU_LOANTAPE_WORK.OUT_B0200_MAIN_LIABILITIES | K19: 0110_APPLCBL_FEES_CHARGES | L19: 8 | M19: 0
B20: =+IF(LEFT(MID(Controlos[[#This Row],[tabela]],22,5),1)="B",MID(Controlos[[#This Row],[tabela]],22,5),MID(Controlos[[#This Row],[tabela]],18,5)) -> B0200 | C20: =+IF(Controlos[[#This Row],[tipologia_teste]]="REGULAMENTAR",IF(LEFT(Controlos[[#This Row],[cod_kpi]],1)="v",IF(LEFT(Controlos[[#This Row],[descrição]],6)="Alerta","W","H"),"F"),0) -> 0 | F20: 2025-10-31 | G20: MIS_B0200_C0120 | H20: MISSINGS | I20: Validar que não existem registos por preencher (Missings) | J20: BU_LOANTAPE_WORK.OUT_B0200_MAIN_LIABILITIES | K20: 0120_OTSTNDNG_AMNT | L20: 8 | M20: 8 | N20: 31641600000000000PTBSREOM0028000; 31641600000000000PTSTOEOM0021000; 31641600000000000PTSTOFOM0004000; 31641600000000000PTSTOGOM0003000; 31641600000000000PTSTOHOM0002000; 31641600005800007PTBSRDOM0037000; 31641600005800007PTCPP0AM0007000; 31641600005800007PTSTOCOM0007000
B21: =+IF(LEFT(MID(Controlos[[#This Row],[tabela]],22,5),1)="B",MID(Controlos[[#This Row],[tabela]],22,5),MID(Controlos[[#This Row],[tabela]],18,5)) -> B0200 | C21: =+IF(Controlos[[#This Row],[tipologia_teste]]="REGULAMENTAR",IF(LEFT(Controlos[[#This Row],[cod_kpi]],1)="v",IF(LEFT(Controlos[[#This Row],[descrição]],6)="Alerta","W","H"),"F"),0) -> 0 | F21: 2025-10-31 | G21: MIS_B0200_C0130 | H21: MISSINGS | I21: Validar que não existem registos por preencher (Missings) | J21: BU_LOANTAPE_WORK.OUT_B0200_MAIN_LIABILITIES | K21: 0130_RLVNT_AMNT_WDC | L21: 8 | M21: 8 | N21: 31641600000000000PTBSREOM0028000; 31641600000000000PTSTOEOM0021000; 31641600000000000PTSTOFOM0004000; 31641600000000000PTSTOGOM0003000; 31641600000000000PTSTOHOM0002000; 31641600005800007PTBSRDOM0037000; 31641600005800007PTCPP0AM0007000; 31641600005800007PTSTOCOM0007000
B22: =+IF(LEFT(MID(Controlos[[#This Row],[tabela]],22,5),1)="B",MID(Controlos[[#This Row],[tabela]],22,5),MID(Controlos[[#This Row],[tabela]],18,5)) -> B0200 | C22: =+IF(Controlos[[#This Row],[tipologia_teste]]="REGULAMENTAR",IF(LEFT(Controlos[[#This Row],[cod_kpi]],1)="v",IF(LEFT(Controlos[[#This Row],[descrição]],6)="Alerta","W","H"),"F"),0) -> 0 | F22: 2025-10-31 | G22: MIS_B0200_C0140 | H22: MISSINGS | I22: Validar que não existem registos por preencher (Missings) | J22: BU_LOANTAPE_WORK.OUT_B0200_MAIN_LIABILITIES | K22: 0140_NTR_LBLTY | L22: 8 | M22: 0
B23: =+IF(LEFT(MID(Controlos[[#This Row],[tabela]],22,5),1)="B",MID(Controlos[[#This Row],[tabela]],22,5),MID(Controlos[[#This Row],[tabela]],18,5)) -> B0200 | C23: =+IF(Controlos[[#This Row],[tipologia_teste]]="REGULAMENTAR",IF(LEFT(Controlos[[#This Row],[cod_kpi]],1)="v",IF(LEFT(Controlos[[#This Row],[descrição]],6)="Alerta","W","H"),"F"),0) -> 0 | F23: 2025-10-31 | G23: MIS_B0200_C0141 | H23: MISSINGS | I23: Validar que não existem registos por preencher (Missings) | J23: BU_LOANTAPE_WORK.OUT_B0200_MAIN_LIABILITIES | K23: 0141_NTR_LBLTY_OTHR | L23: 8 | M23: 0
B24: =+IF(LEFT(MID(Controlos[[#This Row],[tabela]],22,5),1)="B",MID(Controlos[[#This Row],[tabela]],22,5),MID(Controlos[[#This Row],[tabela]],18,5)) -> B0200 | C24: =+IF(Controlos[[#This Row],[tipologia_teste]]="REGULAMENTAR",IF(LEFT(Controlos[[#This Row],[cod_kpi]],1)="v",IF(LEFT(Controlos[[#This Row],[descrição]],6)="Alerta","W","H"),"F"),0) -> 0 | F24: 2025-10-31 | G24: MIS_B0200_C0150 | H24: MISSINGS | I24: Validar que não existem registos por preencher (Missings) | J24: BU_LOANTAPE_WORK.OUT_B0200_MAIN_LIABILITIES | K24: 0150_FLG_STRCTRLLY_SBRDNTD | L24: 8 | M24: 0
B25: =+IF(LEFT(MID(Controlos[[#This Row],[tabela]],22,5),1)="B",MID(Controlos[[#This Row],[tabela]],22,5),MID(Controlos[[#This Row],[tabela]],18,5)) -> B0200 | C25: =+IF(Controlos[[#This Row],[tipologia_teste]]="REGULAMENTAR",IF(LEFT(Controlos[[#This Row],[cod_kpi]],1)="v",IF(LEFT(Controlos[[#This Row],[descrição]],6)="Alerta","W","H"),"F"),0) -> 0 | F25: 2025-10-31 | G25: MIS_B0200_C0160 | H25: MISSINGS | I25: Validar que não existem registos por preencher (Missings) | J25: BU_LOANTAPE_WORK.OUT_B0200_MAIN_LIABILITIES | K25: 0160_RANK_INSOLV | L25: 8 | M25: 0
B26: =+IF(LEFT(MID(Controlos[[#This Row],[tabela]],22,5),1)="B",MID(Controlos[[#This Row],[tabela]],22,5),MID(Controlos[[#This Row],[tabela]],18,5)) -> B0200 | C26: =+IF(Controlos[[#This Row],[tipologia_teste]]="REGULAMENTAR",IF(LEFT(Controlos[[#This Row],[cod_kpi]],1)="v",IF(LEFT(Controlos[[#This Row],[descrição]],6)="Alerta","W","H"),"F"),0) -> 0 | F26: 2025-10-31 | G26: MIS_B0200_C0161 | H26: MISSINGS | I26: Validar que não existem registos por preencher (Missings) | J26: BU_LOANTAPE_WORK.OUT_B0200_MAIN_LIABILITIES | K26: 0161_CNTRCTL_SBRDNTN | L26: 8 | M26: 0
B27: =+IF(LEFT(MID(Controlos[[#This Row],[tabela]],22,5),1)="B",MID(Controlos[[#This Row],[tabela]],22,5),MID(Controlos[[#This Row],[tabela]],18,5)) -> B0200 | C27: =+IF(Controlos[[#This Row],[tipologia_teste]]="REGULAMENTAR",IF(LEFT(Controlos[[#This Row],[cod_kpi]],1)="v",IF(LEFT(Controlos[[#This Row],[descrição]],6)="Alerta","W","H"),"F"),0) -> 0 | F27: 2025-10-31 | G27: MIS_B0200_C0162 | H27: MISSINGS | I27: Validar que não existem registos por preencher (Missings) | J27: BU_LOANTAPE_WORK.OUT_B0200_MAIN_LIABILITIES | K27: 0162_BAIL_IN_CASCADE | L27: 8 | M27: 0
B28: =+IF(LEFT(MID(Controlos[[#This Row],[tabela]],22,5),1)="B",MID(Controlos[[#This Row],[tabela]],22,5),MID(Controlos[[#This Row],[tabela]],18,5)) -> B0200 | C28: =+IF(Controlos[[#This Row],[tipologia_teste]]="REGULAMENTAR",IF(LEFT(Controlos[[#This Row],[cod_kpi]],1)="v",IF(LEFT(Controlos[[#This Row],[descrição]],6)="Alerta","W","H"),"F"),0) -> 0 | F28: 2025-10-31 | G28: MIS_B0200_C0170 | H28: MISSINGS | I28: Validar que não existem registos por preencher (Missings) | J28: BU_LOANTAPE_WORK.OUT_B0200_MAIN_LIABILITIES | K28: 0170_DT_INCPTN | L28: 8 | M28: 0
B29: =+IF(LEFT(MID(Controlos[[#This Row],[tabela]],22,5),1)="B",MID(Controlos[[#This Row],[tabela]],22,5),MID(Controlos[[#This Row],[tabela]],18,5)) -> B0200 | C29: =+IF(Controlos[[#This Row],[tipologia_teste]]="REGULAMENTAR",IF(LEFT(Controlos[[#This Row],[cod_kpi]],1)="v",IF(LEFT(Controlos[[#This Row],[descrição]],6)="Alerta","W","H"),"F"),0) -> 0 | F29: 2025-10-31 | G29: MIS_B0200_C0180 | H29: MISSINGS | I29: Validar que não existem registos por preencher (Missings) | J29: BU_LOANTAPE_WORK.OUT_B0200_MAIN_LIABILITIES | K29: 0180_DT_NXT_INTRST_PYMNT | L29: 8 | M29: 0
B30: =+IF(LEFT(MID(Controlos[[#This Row],[tabela]],22,5),1)="B",MID(Controlos[[#This Row],[tabela]],22,5),MID(Controlos[[#This Row],[tabela]],18,5)) -> B0200 | C30: =+IF(Controlos[[#This Row],[tipologia_teste]]="REGULAMENTAR",IF(LEFT(Controlos[[#This Row],[cod_kpi]],1)="v",IF(LEFT(Controlos[[#This Row],[descrição]],6)="Alerta","W","H"),"F"),0) -> 0 | F30: 2025-10-31 | G30: MIS_B0200_C0190 | H30: MISSINGS | I30: Validar que não existem registos por preencher (Missings) | J30: BU_LOANTAPE_WORK.OUT_B0200_MAIN_LIABILITIES | K30: 0190_DT_NXT_RDMPTN_PYMNT | L30: 8 | M30: 0
B31: =+IF(LEFT(MID(Controlos[[#This Row],[tabela]],22,5),1)="B",MID(Controlos[[#This Row],[tabela]],22,5),MID(Controlos[[#This Row],[tabela]],18,5)) -> B0200 | C31: =+IF(Controlos[[#This Row],[tipologia_teste]]="REGULAMENTAR",IF(LEFT(Controlos[[#This Row],[cod_kpi]],1)="v",IF(LEFT(Controlos[[#This Row],[descrição]],6)="Alerta","W","H"),"F"),0) -> 0 | F31: 2025-10-31 | G31: MIS_B0200_C0200 | H31: MISSINGS | I31: Validar que não existem registos por preencher (Missings) | J31: BU_LOANTAPE_WORK.OUT_B0200_MAIN_LIABILITIES | K31: 0200_DT_ERLST_RDMPTN | L31: 8 | M31: 0
B32: =+IF(LEFT(MID(Controlos[[#This Row],[tabela]],22,5),1)="B",MID(Controlos[[#This Row],[tabela]],22,5),MID(Controlos[[#This Row],[tabela]],18,5)) -> B0200 | C32: =+IF(Controlos[[#This Row],[tipologia_teste]]="REGULAMENTAR",IF(LEFT(Controlos[[#This Row],[cod_kpi]],1)="v",IF(LEFT(Controlos[[#This Row],[descrição]],6)="Alerta","W","H"),"F"),0) -> 0 | F32: 2025-10-31 | G32: MIS_B0200_C0210 | H32: MISSINGS | I32: Validar que não existem registos por preencher (Missings) | J32: BU_LOANTAPE_WORK.OUT_B0200_MAIN_LIABILITIES | K32: 0210_DT_LGL_FNL_MTRTY | L32: 8 | M32: 0
B33: =+IF(LEFT(MID(Controlos[[#This Row],[tabela]],22,5),1)="B",MID(Controlos[[#This Row],[tabela]],22,5),MID(Controlos[[#This Row],[tabela]],18,5)) -> B0200 | C33: =+IF(Controlos[[#This Row],[tipologia_teste]]="REGULAMENTAR",IF(LEFT(Controlos[[#This Row],[cod_kpi]],1)="v",IF(LEFT(Controlos[[#This Row],[descrição]],6)="Alerta","W","H"),"F"),0) -> 0 | F33: 2025-10-31 | G33: MIS_B0200_C0220 | H33: MISSINGS | I33: Validar que não existem registos por preencher (Missings) | J33: BU_LOANTAPE_WORK.OUT_B0200_MAIN_LIABILITIES | K33: 0220_GOVERNING_LAW | L33: 8 | M33: 0
... B50: =+IF(LEFT(MID(Controlos[[#This Row],[tabela]],22,5),1)="B",MID(Controlos[[#This Row],[tabela]],22,5),MID(Controlos[[#This Row],[tabela]],18,5)) -> B0200 | C50: =+IF(Controlos[[#This Row],[tipologia_teste]]="REGULAMENTAR",IF(LEFT(Controlos[[#This Row],[cod_kpi]],1)="v",IF(LEFT(Controlos[[#This Row],[descrição]],6)="Alerta","W","H"),"F"),0) -> 0 | F50: 2025-10-31 | G50: MIS_B0200_C0380 | H50: MISSINGS | I50: Validar que não existem registos por preencher (Missings) | J50: BU_LOANTAPE_WORK.OUT_B0200_MAIN_LIABILITIES | K50: 0380_AMNT_SCRTY_FX | L50: 8 | M50: 0
B51: =+IF(LEFT(MID(Controlos[[#This Row],[tabela]],22,5),1)="B",MID(Controlos[[#This Row],[tabela]],22,5),MID(Controlos[[#This Row],[tabela]],18,5)) -> B0200 | C51: =+IF(Controlos[[#This Row],[tipologia_teste]]="REGULAMENTAR",IF(LEFT(Controlos[[#This Row],[cod_kpi]],1)="v",IF(LEFT(Controlos[[#This Row],[descrição]],6)="Alerta","W","H"),"F"),0) -> 0 | F51: 2025-10-31 | G51: MIS_B0200_C0390 | H51: MISSINGS | I51: Validar que não existem registos por preencher (Missings) | J51: BU_LOANTAPE_WORK.OUT_B0200_MAIN_LIABILITIES | K51: 0390_NMBR_SCRTS_NOT_RPRTNG_ENTTY | L51: 8 | M51: 8 | N51: 31641600000000000PTBSREOM0028000; 31641600000000000PTSTOEOM0021000; 31641600000000000PTSTOFOM0004000; 31641600000000000PTSTOGOM0003000; 31641600000000000PTSTOHOM0002000; 31641600005800007PTBSRDOM0037000; 31641600005800007PTCPP0AM0007000; 31641600005800007PTSTOCOM0007000
B52: =+IF(LEFT(MID(Controlos[[#This Row],[tabela]],22,5),1)="B",MID(Controlos[[#This Row],[tabela]],22,5),MID(Controlos[[#This Row],[tabela]],18,5)) -> B0200 | C52: =+IF(Controlos[[#This Row],[tipologia_teste]]="REGULAMENTAR",IF(LEFT(Controlos[[#This Row],[cod_kpi]],1)="v",IF(LEFT(Controlos[[#This Row],[descrição]],6)="Alerta","W","H"),"F"),0) -> 0 | F52: 2025-10-31 | G52: MIS_B0200_C0391 | H52: MISSINGS | I52: Validar que não existem registos por preencher (Missings) | J52: BU_LOANTAPE_WORK.OUT_B0200_MAIN_LIABILITIES | K52: 0391_NMBR_SCRTS_RPRTNG_ENTTY | L52: 8 | M52: 8 | N52: 31641600000000000PTBSREOM0028000; 31641600000000000PTSTOEOM0021000; 31641600000000000PTSTOFOM0004000; 31641600000000000PTSTOGOM0003000; 31641600000000000PTSTOHOM0002000; 31641600005800007PTBSRDOM0037000; 31641600005800007PTCPP0AM0007000; 31641600005800007PTSTOCOM0007000
B53: =+IF(LEFT(MID(Controlos[[#This Row],[tabela]],22,5),1)="B",MID(Controlos[[#This Row],[tabela]],22,5),MID(Controlos[[#This Row],[tabela]],18,5)) -> B0200 | C53: =+IF(Controlos[[#This Row],[tipologia_teste]]="REGULAMENTAR",IF(LEFT(Controlos[[#This Row],[cod_kpi]],1)="v",IF(LEFT(Controlos[[#This Row],[descrição]],6)="Alerta","W","H"),"F"),0) -> 0 | F53: 2025-10-31 | G53: MIS_B0200_C0400 | H53: MISSINGS | I53: Validar que não existem registos por preencher (Missings) | J53: BU_LOANTAPE_WORK.OUT_B0200_MAIN_LIABILITIES | K53: 0400_ACCRD_INTRST_SCRTY | L53: 8 | M53: 8 | N53: 31641600000000000PTBSREOM0028000; 31641600000000000PTSTOEOM0021000; 31641600000000000PTSTOFOM0004000; 31641600000000000PTSTOGOM0003000; 31641600000000000PTSTOHOM0002000; 31641600005800007PTBSRDOM0037000; 31641600005800007PTCPP0AM0007000; 31641600005800007PTSTOCOM0007000
B54: =+IF(LEFT(MID(Controlos[[#This Row],[tabela]],22,5),1)="B",MID(Controlos[[#This Row],[tabela]],22,5),MID(Controlos[[#This Row],[tabela]],18,5)) -> B0200 | C54: =+IF(Controlos[[#This Row],[tipologia_teste]]="REGULAMENTAR",IF(LEFT(Controlos[[#This Row],[cod_kpi]],1)="v",IF(LEFT(Controlos[[#This Row],[descrição]],6)="Alerta","W","H"),"F"),0) -> 0 | F54: 2025-10-31 | G54: MIS_B0200_C0410 | H54: MISSINGS | I54: Validar que não existem registos por preencher (Missings) | J54: BU_LOANTAPE_WORK.OUT_B0200_MAIN_LIABILITIES | K54: 0410_FEES_CHARGES_SCRTY | L54: 8 | M54: 0
B55: =+IF(LEFT(MID(Controlos[[#This Row],[tabela]],22,5),1)="B",MID(Controlos[[#This Row],[tabela]],22,5),MID(Controlos[[#This Row],[tabela]],18,5)) -> B0200 | C55: =+IF(Controlos[[#This Row],[tipologia_teste]]="REGULAMENTAR",IF(LEFT(Controlos[[#This Row],[cod_kpi]],1)="v",IF(LEFT(Controlos[[#This Row],[descrição]],6)="Alerta","W","H"),"F"),0) -> 0 | F55: 2025-10-31 | G55: MIS_B0200_C0420 | H55: MISSINGS | I55: Validar que não existem registos por preencher (Missings) | J55: BU_LOANTAPE_WORK.OUT_B0200_MAIN_LIABILITIES | K55: 0420_FV_AMNT_SCRTY | L55: 8 | M55: 0
B56: =+IF(LEFT(MID(Controlos[[#This Row],[tabela]],22,5),1)="B",MID(Controlos[[#This Row],[tabela]],22,5),MID(Controlos[[#This Row],[tabela]],18,5)) -> B0200 | C56: =+IF(Controlos[[#This Row],[tipologia_teste]]="REGULAMENTAR",IF(LEFT(Controlos[[#This Row],[cod_kpi]],1)="v",IF(LEFT(Controlos[[#This Row],[descrição]],6)="Alerta","W","H"),"F"),0) -> 0 | F56: 2025-10-31 | G56: MIS_B0200_C0430 | H56: MISSINGS | I56: Validar que não existem registos por preencher (Missings) | J56: BU_LOANTAPE_WORK.OUT_B0200_MAIN_LIABILITIES | K56: 0430_PRNCPL_AMNT_GLBL_NT_EUR | L56: 8 | M56: 0
B57: =+IF(LEFT(MID(Controlos[[#This Row],[tabela]],22,5),1)="B",MID(Controlos[[#This Row],[tabela]],22,5),MID(Controlos[[#This Row],[tabela]],18,5)) -> B0200 | C57: =+IF(Controlos[[#This Row],[tipologia_teste]]="REGULAMENTAR",IF(LEFT(Controlos[[#This Row],[cod_kpi]],1)="v",IF(LEFT(Controlos[[#This Row],[descrição]],6)="Alerta","W","H"),"F"),0) -> 0 | F57: 2025-10-31 | G57: MIS_B0200_C0431 | H57: MISSINGS | I57: Validar que não existem registos por preencher (Missings) | J57: BU_LOANTAPE_WORK.OUT_B0200_MAIN_LIABILITIES | K57: 0431_PRNCPL_AMNT_GLBL_NT_FX | L57: 8 | M57: 0
B58: =+IF(LEFT(MID(Controlos[[#This Row],[tabela]],22,5),1)="B",MID(Controlos[[#This Row],[tabela]],22,5),MID(Controlos[[#This Row],[tabela]],18,5)) -> B0200 | C58: =+IF(Controlos[[#This Row],[tipologia_teste]]="REGULAMENTAR",IF(LEFT(Controlos[[#This Row],[cod_kpi]],1)="v",IF(LEFT(Controlos[[#This Row],[descrição]],6)="Alerta","W","H"),"F"),0) -> 0 | F58: 2025-10-31 | G58: MIS_B0200_C0440 | H58: MISSINGS | I58: Validar que não existem registos por preencher (Missings) | J58: BU_LOANTAPE_WORK.OUT_B0200_MAIN_LIABILITIES | K58: 0440_NTR_GLBL_NT | L58: 8 | M58: 0
B59: =+IF(LEFT(MID(Controlos[[#This Row],[tabela]],22,5),1)="B",MID(Controlos[[#This Row],[tabela]],22,5),MID(Controlos[[#This Row],[tabela]],18,5)) -> B0200 | C59: =+IF(Controlos[[#This Row],[tipologia_teste]]="REGULAMENTAR",IF(LEFT(Controlos[[#This Row],[cod_kpi]],1)="v",IF(LEFT(Controlos[[#This Row],[descrição]],6)="Alerta","W","H"),"F"),0) -> 0 | F59: 2025-10-31 | G59: MIS_B0200_C0450 | H59: MISSINGS | I59: Validar que não existem registos por preencher (Missings) | J59: BU_LOANTAPE_WORK.OUT_B0200_MAIN_LIABILITIES | K59: 0450_CRRNT_POOL_FCTR | L59: 8 | M59: 0
B60: =+IF(LEFT(MID(Controlos[[#This Row],[tabela]],22,5),1)="B",MID(Controlos[[#This Row],[tabela]],22,5),MID(Controlos[[#This Row],[tabela]],18,5)) -> B0200 | C60: =+IF(Controlos[[#This Row],[tipologia_teste]]="REGULAMENTAR",IF(LEFT(Controlos[[#This Row],[cod_kpi]],1)="v",IF(LEFT(Controlos[[#This Row],[descrição]],6)="Alerta","W","H"),"F"),0) -> 0 | F60: 2025-10-31 | G60: MIS_B0200_C0460 | H60: MISSINGS | I60: Validar que não existem registos por preencher (Missings) | J60: BU_LOANTAPE_WORK.OUT_B0200_MAIN_LIABILITIES | K60: 0460_CSD | L60: 8 | M60: 0
B61: =+IF(LEFT(MID(Controlos[[#This Row],[tabela]],22,5),1)="B",MID(Controlos[[#This Row],[tabela]],22,5),MID(Controlos[[#This Row],[tabela]],18,5)) -> B0200 | C61: =+IF(Controlos[[#This Row],[tipologia_teste]]="REGULAMENTAR",IF(LEFT(Controlos[[#This Row],[cod_kpi]],1)="v",IF(LEFT(Controlos[[#This Row],[descrição]],6)="Alerta","W","H"),"F"),0) -> 0 | F61: 2025-10-31 | G61: MIS_B0200_C0461 | H61: MISSINGS | I61: Validar que não existem registos por preencher (Missings) | J61: BU_LOANTAPE_WORK.OUT_B0200_MAIN_LIABILITIES | K61: 0461_CSD_LEI | L61: 8 | M61: 0
B62: =+IF(LEFT(MID(Controlos[[#This Row],[tabela]],22,5),1)="B",MID(Controlos[[#This Row],[tabela]],22,5),MID(Controlos[[#This Row],[tabela]],18,5)) -> B0200 | C62: =+IF(Controlos[[#This Row],[tipologia_teste]]="REGULAMENTAR",IF(LEFT(Controlos[[#This Row],[cod_kpi]],1)="v",IF(LEFT(Controlos[[#This Row],[descrição]],6)="Alerta","W","H"),"F"),0) -> 0 | F62: 2025-10-31 | G62: MIS_B0200_C0462 | H62: MISSINGS | I62: Validar que não existem registos por preencher (Missings) | J62: BU_LOANTAPE_WORK.OUT_B0200_MAIN_LIABILITIES | K62: 0462_CSD_OTHR | L62: 8 | M62: 0
...

Sheet 2.1. Regulamentares
B6: 2.1. Controlos Regulamentares
B8: Controlo | C8: Issues | D8: Detalhe | E8: Tipo | F8: High Severity (H)/ Warning (W) | G8: Table | H8: Field | I8: Justificação
B9: b0200_lvl1_h_0010_row_nmbr | C9: 0 | E9: =+MID(B9,7,4) -> lvl1 | F9: =IF(LEFT(E9,3)="lvl",MID(B9,12,1),"f") -> h | G9: =+LEFT(B9,3)&"."&MID(B9,4,2) -> b02.00 | H9: =IF(LEFT(E9,3)="lvl",IF(OR(RIGHT(B9,2)="_1",RIGHT(B9,2)="_2"),MID(B9,14,LEN(B9)-15), MID(B9,14,LEN(B9))),MID(B9,12,LEN(B9))) -> 0010_row_nmbr
B10: b0200_lvl1_h_0030_uniq_id_knwn_cntrprty | C10: 0 | E10: =+MID(B10,7,4) -> lvl1 | F10: =IF(LEFT(E10,3)="lvl",MID(B10,12,1),"f") -> h | G10: =+LEFT(B10,3)&"."&MID(B10,4,2) -> b02.00 | H10: =IF(LEFT(E10,3)="lvl",IF(OR(RIGHT(B10,2)="_1",RIGHT(B10,2)="_2"),MID(B10,14,LEN(B10)-15), MID(B10,14,LEN(B10))),MID(B10,12,LEN(B10))) -> 0030_uniq_id_knwn_cntrprty
B11: b0200_lvl1_h_0040_typ_uniq_id_knwn_cntrprty | C11: 0 | E11: =+MID(B11,7,4) -> lvl1 | F11: =IF(LEFT(E11,3)="lvl",MID(B11,12,1),"f") -> h | G11: =+LEFT(B11,3)&"."&MID(B11,4,2) -> b02.00 | H11: =IF(LEFT(E11,3)="lvl",IF(OR(RIGHT(B11,2)="_1",RIGHT(B11,2)="_2"),MID(B11,14,LEN(B11)-15), MID(B11,14,LEN(B11))),MID(B11,12,LEN(B11))) -> 0040_typ_uniq_id_knwn_cntrprty
B12: b0200_lvl1_h_0070_cntrct_crrncy | C12: 0 | E12: =+MID(B12,7,4) -> lvl1 | F12: =IF(LEFT(E12,3)="lvl",MID(B12,12,1),"f") -> h | G12: =+LEFT(B12,3)&"."&MID(B12,4,2) -> b02.00 | H12: =IF(LEFT(E12,3)="lvl",IF(OR(RIGHT(B12,2)="_1",RIGHT(B12,2)="_2"),MID(B12,14,LEN(B12)-15), MID(B12,14,LEN(B12))),MID(B12,12,LEN(B12))) -> 0070_cntrct_crrncy
B13: b0200_lvl1_h_0080_otstndng_prncpl_amnt | C13: 0 | E13: =+MID(B13,7,4) -> lvl1 | F13: =IF(LEFT(E13,3)="lvl",MID(B13,12,1),"f") -> h | G13: =+LEFT(B13,3)&"."&MID(B13,4,2) -> b02.00 | H13: =IF(LEFT(E13,3)="lvl",IF(OR(RIGHT(B13,2)="_1",RIGHT(B13,2)="_2"),MID(B13,14,LEN(B13)-15), MID(B13,14,LEN(B13))),MID(B13,12,LEN(B13))) -> 0080_otstndng_prncpl_amnt
B14: b0200_lvl1_w_0080_otstndng_prncpl_amnt | C14: 0 | E14: =+MID(B14,7,4) -> lvl1 | F14: =IF(LEFT(E14,3)="lvl",MID(B14,12,1),"f") -> w | G14: =+LEFT(B14,3)&"."&MID(B14,4,2) -> b02.00 | H14: =IF(LEFT(E14,3)="lvl",IF(OR(RIGHT(B14,2)="_1",RIGHT(B14,2)="_2"),MID(B14,14,LEN(B14)-15), MID(B14,14,LEN(B14))),MID(B14,12,LEN(B14))) -> 0080_otstndng_prncpl_amnt
B15: b0200_lvl1_h_0090_prtn_amnt_rprtng_entty | C15: 0 | E15: =+MID(B15,7,4) -> lvl1 | F15: =IF(LEFT(E15,3)="lvl",MID(B15,12,1),"f") -> h | G15: =+LEFT(B15,3)&"."&MID(B15,4,2) -> b02.00 | H15: =IF(LEFT(E15,3)="lvl",IF(OR(RIGHT(B15,2)="_1",RIGHT(B15,2)="_2"),MID(B15,14,LEN(B15)-15), MID(B15,14,LEN(B15))),MID(B15,12,LEN(B15))) -> 0090_prtn_amnt_rprtng_entty
B16: b0200_lvl1_h_0100_accrd_intrst_instrmnt | C16: 0 | E16: =+MID(B16,7,4) -> lvl1 | F16: =IF(LEFT(E16,3)="lvl",MID(B16,12,1),"f") -> h | G16: =+LEFT(B16,3)&"."&MID(B16,4,2) -> b02.00 | H16: =IF(LEFT(E16,3)="lvl",IF(OR(RIGHT(B16,2)="_1",RIGHT(B16,2)="_2"),MID(B16,14,LEN(B16)-15), MID(B16,14,LEN(B16))),MID(B16,12,LEN(B16))) -> 0100_accrd_intrst_instrmnt
B17: b0200_lvl1_w_0100_accrd_intrst_instrmnt | C17: 0 | E17: =+MID(B17,7,4) -> lvl1 | F17: =IF(LEFT(E17,3)="lvl",MID(B17,12,1),"f") -> w | G17: =+LEFT(B17,3)&"."&MID(B17,4,2) -> b02.00 | H17: =IF(LEFT(E17,3)="lvl",IF(OR(RIGHT(B17,2)="_1",RIGHT(B17,2)="_2"),MID(B17,14,LEN(B17)-15), MID(B17,14,LEN(B17))),MID(B17,12,LEN(B17))) -> 0100_accrd_intrst_instrmnt
B18: b0200_lvl1_h_0120_otstndng_amnt | C18: 0 | E18: =+MID(B18,7,4) -> lvl1 | F18: =IF(LEFT(E18,3)="lvl",MID(B18,12,1),"f") -> h | G18: =+LEFT(B18,3)&"."&MID(B18,4,2) -> b02.00 | H18: =IF(LEFT(E18,3)="lvl",IF(OR(RIGHT(B18,2)="_1",RIGHT(B18,2)="_2"),MID(B18,14,LEN(B18)-15), MID(B18,14,LEN(B18))),MID(B18,12,LEN(B18))) -> 0120_otstndng_amnt
B19: b0200_lvl1_w_0120_otstndng_amnt | C19: 8 | E19: =+MID(B19,7,4) -> lvl1 | F19: =IF(LEFT(E19,3)="lvl",MID(B19,12,1),"f") -> w | G19: =+LEFT(B19,3)&"."&MID(B19,4,2) -> b02.00 | H19: =IF(LEFT(E19,3)="lvl",IF(OR(RIGHT(B19,2)="_1",RIGHT(B19,2)="_2"),MID(B19,14,LEN(B19)-15), MID(B19,14,LEN(B19))),MID(B19,12,LEN(B19))) -> 0120_otstndng_amnt
B20: b0200_lvl1_h_0130_rlvnt_amnt_wdc | C20: 8 | E20: =+MID(B20,7,4) -> lvl1 | F20: =IF(LEFT(E20,3)="lvl",MID(B20,12,1),"f") -> h | G20: =+LEFT(B20,3)&"."&MID(B20,4,2) -> b02.00 | H20: =IF(LEFT(E20,3)="lvl",IF(OR(RIGHT(B20,2)="_1",RIGHT(B20,2)="_2"),MID(B20,14,LEN(B20)-15), MID(B20,14,LEN(B20))),MID(B20,12,LEN(B20))) -> 0130_rlvnt_amnt_wdc
... B97: b0200_frmt_0140_ntr_lblty | C97: 4 | E97: =+MID(B97,7,4) -> frmt | F97: =IF(LEFT(E97,3)="lvl",MID(B97,12,1),"f") -> f | G97: =+LEFT(B97,3)&"."&MID(B97,4,2) -> b02.00 | H97: =IF(LEFT(E97,3)="lvl",IF(OR(RIGHT(B97,2)="_1",RIGHT(B97,2)="_2"),MID(B97,14,LEN(B97)-15), MID(B97,14,LEN(B97))),MID(B97,12,LEN(B97))) -> 0140_ntr_lblty
B98: b0200_frmt_0141_ntr_lblty_othr | C98: 8 | E98: =+MID(B98,7,4) -> frmt | F98: =IF(LEFT(E98,3)="lvl",MID(B98,12,1),"f") -> f | G98: =+LEFT(B98,3)&"."&MID(B98,4,2) -> b02.00 | H98: =IF(LEFT(E98,3)="lvl",IF(OR(RIGHT(B98,2)="_1",RIGHT(B98,2)="_2"),MID(B98,14,LEN(B98)-15), MID(B98,14,LEN(B98))),MID(B98,12,LEN(B98))) -> 0141_ntr_lblty_othr | I98: Valor fixo 'Not applicable' no campo Nature of the liability (if other), uma vez que todos os registos são considerados no campo Nature of the liability como "Title of ownership" ou "Registered Bond", não existinto "other".
B99: b0200_frmt_0150_flg_strctrlly_sbrdntd | C99: 8 | E99: =+MID(B99,7,4) -> frmt | F99: =IF(LEFT(E99,3)="lvl",MID(B99,12,1),"f") -> f | G99: =+LEFT(B99,3)&"."&MID(B99,4,2) -> b02.00 | H99: =IF(LEFT(E99,3)="lvl",IF(OR(RIGHT(B99,2)="_1",RIGHT(B99,2)="_2"),MID(B99,14,LEN(B99)-15), MID(B99,14,LEN(B99))),MID(B99,12,LEN(B99))) -> 0150_flg_strctrlly_sbrdntd | I99: Valor fixo 'Not applicable' de acordo com o Anexo III - considerado não aplicável para non-resolution entities.
B100: b0200_frmt_0160_rank_insolv | C100: 0 | E100: =+MID(B100,7,4) -> frmt | F100: =IF(LEFT(E100,3)="lvl",MID(B100,12,1),"f") -> f | G100: =+LEFT(B100,3)&"."&MID(B100,4,2) -> b02.00 | H100: =IF(LEFT(E100,3)="lvl",IF(OR(RIGHT(B100,2)="_1",RIGHT(B100,2)="_2"),MID(B100,14,LEN(B100)-15), MID(B100,14,LEN(B100))),MID(B100,12,LEN(B100))) -> 0160_rank_insolv
B101: b0200_frmt_0161_cntrctl_sbrdntn | C101: 0 | E101: =+MID(B101,7,4) -> frmt | F101: =IF(LEFT(E101,3)="lvl",MID(B101,12,1),"f") -> f | G101: =+LEFT(B101,3)&"."&MID(B101,4,2) -> b02.00 | H101: =IF(LEFT(E101,3)="lvl",IF(OR(RIGHT(B101,2)="_1",RIGHT(B101,2)="_2"),MID(B101,14,LEN(B101)-15), MID(B101,14,LEN(B101))),MID(B101,12,LEN(B101))) -> 0161_cntrctl_sbrdntn
B102: b0200_frmt_0162_bail_in_cascade | C102: 0 | E102: =+MID(B102,7,4) -> frmt | F102: =IF(LEFT(E102,3)="lvl",MID(B102,12,1),"f") -> f | G102: =+LEFT(B102,3)&"."&MID(B102,4,2) -> b02.00 | H102: =IF(LEFT(E102,3)="lvl",IF(OR(RIGHT(B102,2)="_1",RIGHT(B102,2)="_2"),MID(B102,14,LEN(B102)-15), MID(B102,14,LEN(B102))),MID(B102,12,LEN(B102))) -> 0162_bail_in_cascade
B103: b0200_frmt_0170_dt_incptn | C103: 0 | E103: =+MID(B103,7,4) -> frmt | F103: =IF(LEFT(E103,3)="lvl",MID(B103,12,1),"f") -> f | G103: =+LEFT(B103,3)&"."&MID(B103,4,2) -> b02.00 | H103: =IF(LEFT(E103,3)="lvl",IF(OR(RIGHT(B103,2)="_1",RIGHT(B103,2)="_2"),MID(B103,14,LEN(B103)-15), MID(B103,14,LEN(B103))),MID(B103,12,LEN(B103))) -> 0170_dt_incptn
B104: b0200_frmt_0180_dt_nxt_intrst_pymnt | C104: 8 | E104: =+MID(B104,7,4) -> frmt | F104: =IF(LEFT(E104,3)="lvl",MID(B104,12,1),"f") -> f | G104: =+LEFT(B104,3)&"."&MID(B104,4,2) -> b02.00 | H104: =IF(LEFT(E104,3)="lvl",IF(OR(RIGHT(B104,2)="_1",RIGHT(B104,2)="_2"),MID(B104,14,LEN(B104)-15), MID(B104,14,LEN(B104))),MID(B104,12,LEN(B104))) -> 0180_dt_nxt_intrst_pymnt
B105: b0200_frmt_0190_dt_nxt_rdmptn_pymnt | C105: 0 | E105: =+MID(B105,7,4) -> frmt | F105: =IF(LEFT(E105,3)="lvl",MID(B105,12,1),"f") -> f | G105: =+LEFT(B105,3)&"."&MID(B105,4,2) -> b02.00 | H105: =IF(LEFT(E105,3)="lvl",IF(OR(RIGHT(B105,2)="_1",RIGHT(B105,2)="_2"),MID(B105,14,LEN(B105)-15), MID(B105,14,LEN(B105))),MID(B105,12,LEN(B105))) -> 0190_dt_nxt_rdmptn_pymnt
B106: b0200_frmt_0200_dt_erlst_rdmptn | C106: 0 | E106: =+MID(B106,7,4) -> frmt | F106: =IF(LEFT(E106,3)="lvl",MID(B106,12,1),"f") -> f | G106: =+LEFT(B106,3)&"."&MID(B106,4,2) -> b02.00 | H106: =IF(LEFT(E106,3)="lvl",IF(OR(RIGHT(B106,2)="_1",RIGHT(B106,2)="_2"),MID(B106,14,LEN(B106)-15), MID(B106,14,LEN(B106))),MID(B106,12,LEN(B106))) -> 0200_dt_erlst_rdmptn
B107: b0200_frmt_0210_dt_lgl_fnl_mtrty | C107: 0 | E107: =+MID(B107,7,4) -> frmt | F107: =IF(LEFT(E107,3)="lvl",MID(B107,12,1),"f") -> f | G107: =+LEFT(B107,3)&"."&MID(B107,4,2) -> b02.00 | H107: =IF(LEFT(E107,3)="lvl",IF(OR(RIGHT(B107,2)="_1",RIGHT(B107,2)="_2"),MID(B107,14,LEN(B107)-15), MID(B107,14,LEN(B107))),MID(B107,12,LEN(B107))) -> 0210_dt_lgl_fnl_mtrty
B108: b0200_frmt_0220_governing_law | C108: 0 | E108: =+MID(B108,7,4) -> frmt | F108: =IF(LEFT(E108,3)="lvl",MID(B108,12,1),"f") -> f | G108: =+LEFT(B108,3)&"."&MID(B108,4,2) -> b02.00 | H108: =IF(LEFT(E108,3)="lvl",IF(OR(RIGHT(B108,2)="_1",RIGHT(B108,2)="_2"),MID(B108,14,LEN(B108)-15), MID(B108,14,LEN(B108))),MID(B108,12,LEN(B108))) -> 0220_governing_law
B109: b0200_frmt_0230_bail_in_rcgntn_cls | C109: 0 | E109: =+MID(B109,7,4) -> frmt | F109: =IF(LEFT(E109,3)="lvl",MID(B109,12,1),"f") -> f | G109: =+LEFT(B109,3)&"."&MID(B109,4,2) -> b02.00 | H109: =IF(LEFT(E109,3)="lvl",IF(OR(RIGHT(B109,2)="_1",RIGHT(B109,2)="_2"),MID(B109,14,LEN(B109)-15), MID(B109,14,LEN(B109))),MID(B109,12,LEN(B109))) -> 0230_bail_in_rcgntn_cls
B110: b0200_frmt_0240_zero_coupon | C110: 0 | E110: =+MID(B110,7,4) -> frmt | F110: =IF(LEFT(E110,3)="lvl",MID(B110,12,1),"f") -> f | G110: =+LEFT(B110,3)&"."&MID(B110,4,2) -> b02.00 | H110: =IF(LEFT(E110,3)="lvl",IF(OR(RIGHT(B110,2)="_1",RIGHT(B110,2)="_2"),MID(B110,14,LEN(B110)-15), MID(B110,14,LEN(B110))),MID(B110,12,LEN(B110))) -> 0240_zero_coupon
B111: b0200_frmt_0250_strctrd_prdct | C111: 0 | E111: =+MID(B111,7,4) -> frmt | F111: =IF(LEFT(E111,3)="lvl",MID(B111,12,1),"f") -> f | G111: =+LEFT(B111,3)&"."&MID(B111,4,2) -> b02.00 | H111: =IF(LEFT(E111,3)="lvl",IF(OR(RIGHT(B111,2)="_1",RIGHT(B111,2)="_2"),MID(B111,14,LEN(B111)-15), MID(B111,14,LEN(B111))),MID(B111,12,LEN(B111))) -> 0250_strctrd_prdct
... B119: b0200_frmt_0330_amnt_unclltrlzd | C119: 0 | E119: =+MID(B119,7,4) -> frmt | F119: =IF(LEFT(E119,3)="lvl",MID(B119,12,1),"f") -> f | G119: =+LEFT(B119,3)&"."&MID(B119,4,2) -> b02.00 | H119: =IF(LEFT(E119,3)="lvl",IF(OR(RIGHT(B119,2)="_1",RIGHT(B119,2)="_2"),MID(B119,14,LEN(B119)-15), MID(B119,14,LEN(B119))),MID(B119,12,LEN(B119))) -> 0330_amnt_unclltrlzd
B120: b0200_frmt_0340_id_clltrl | C120: 8 | E120: =+MID(B120,7,4) -> frmt | F120: =IF(LEFT(E120,3)="lvl",MID(B120,12,1),"f") -> f | G120: =+LEFT(B120,3)&"."&MID(B120,4,2) -> b02.00 | H120: =IF(LEFT(E120,3)="lvl",IF(OR(RIGHT(B120,2)="_1",RIGHT(B120,2)="_2"),MID(B120,14,LEN(B120)-15), MID(B120,14,LEN(B120))),MID(B120,12,LEN(B120))) -> 0340_id_clltrl | I120: Valor fixo 'Not applicable' de acordo com o Anexo III - considerado não aplicável para non-resolution entities.
B121: b0200_frmt_0350_typ_clltrl | C121: 0 | E121: =+MID(B121,7,4) -> frmt | F121: =IF(LEFT(E121,3)="lvl",MID(B121,12,1),"f") -> f | G121: =+LEFT(B121,3)&"."&MID(B121,4,2) -> b02.00 | H121: =IF(LEFT(E121,3)="lvl",IF(OR(RIGHT(B121,2)="_1",RIGHT(B121,2)="_2"),MID(B121,14,LEN(B121)-15), MID(B121,14,LEN(B121))),MID(B121,12,LEN(B121))) -> 0350_typ_clltrl
B122: b0200_frmt_0351_typ_clltrl_othr | C122: 8 | E122: =+MID(B122,7,4) -> frmt | F122: =IF(LEFT(E122,3)="lvl",MID(B122,12,1),"f") -> f | G122: =+LEFT(B122,3)&"."&MID(B122,4,2) -> b02.00 | H122: =IF(LEFT(E122,3)="lvl",IF(OR(RIGHT(B122,2)="_1",RIGHT(B122,2)="_2"),MID(B122,14,LEN(B122)-15), MID(B122,14,LEN(B122))),MID(B122,12,LEN(B122))) -> 0351_typ_clltrl_othr | I122: Valor fixo 'Not applicable' de acordo com o Anexo III - considerado não aplicável para non-resolution entities.
B123: b0200_frmt_0360_trdng_mthd | C123: 0 | E123: =+MID(B123,7,4) -> frmt | F123: =IF(LEFT(E123,3)="lvl",MID(B123,12,1),"f") -> f | G123: =+LEFT(B123,3)&"."&MID(B123,4,2) -> b02.00 | H123: =IF(LEFT(E123,3)="lvl",IF(OR(RIGHT(B123,2)="_1",RIGHT(B123,2)="_2"),MID(B123,14,LEN(B123)-15), MID(B123,14,LEN(B123))),MID(B123,12,LEN(B123))) -> 0360_trdng_mthd
B124: b0200_frmt_0370_amnt_scrty_eur | C124: 0 | E124: =+MID(B124,7,4) -> frmt | F124: =IF(LEFT(E124,3)="lvl",MID(B124,12,1),"f") -> f | G124: =+LEFT(B124,3)&"."&MID(B124,4,2) -> b02.00 | H124: =IF(LEFT(E124,3)="lvl",IF(OR(RIGHT(B124,2)="_1",RIGHT(B124,2)="_2"),MID(B124,14,LEN(B124)-15), MID(B124,14,LEN(B124))),MID(B124,12,LEN(B124))) -> 0370_amnt_scrty_eur
B125: b0200_frmt_0380_amnt_scrty_fx | C125: 0 | E125: =+MID(B125,7,4) -> frmt | F125: =IF(LEFT(E125,3)="lvl",MID(B125,12,1),"f") -> f | G125: =+LEFT(B125,3)&"."&MID(B125,4,2) -> b02.00 | H125: =IF(LEFT(E125,3)="lvl",IF(OR(RIGHT(B125,2)="_1",RIGHT(B125,2)="_2"),MID(B125,14,LEN(B125)-15), MID(B125,14,LEN(B125))),MID(B125,12,LEN(B125))) -> 0380_amnt_scrty_fx
B126: b0200_frmt_0390_nmbr_scrts_not_rprtng_entty | C126: 0 | E126: =+MID(B126,7,4) -> frmt | F126: =IF(LEFT(E126,3)="lvl",MID(B126,12,1),"f") -> f | G126: =+LEFT(B126,3)&"."&MID(B126,4,2) -> b02.00 | H126: =IF(LEFT(E126,3)="lvl",IF(OR(RIGHT(B126,2)="_1",RIGHT(B126,2)="_2"),MID(B126,14,LEN(B126)-15), MID(B126,14,LEN(B126))),MID(B126,12,LEN(B126))) -> 0390_nmbr_scrts_not_rprtng_entty
B127: b0200_frmt_0391_nmbr_scrts_rprtng_entty | C127: 8 | E127: =+MID(B127,7,4) -> frmt | F127: =IF(LEFT(E127,3)="lvl",MID(B127,12,1),"f") -> f | G127: =+LEFT(B127,3)&"."&MID(B127,4,2) -> b02.00 | H127: =IF(LEFT(E127,3)="lvl",IF(OR(RIGHT(B127,2)="_1",RIGHT(B127,2)="_2"),MID(B127,14,LEN(B127)-15), MID(B127,14,LEN(B127))),MID(B127,12,LEN(B127))) -> 0391_nmbr_scrts_rprtng_entty
B128: b0200_frmt_0400_accrd_intrst_scrty | C128: 0 | E128: =+MID(B128,7,4) -> frmt | F128: =IF(LEFT(E128,3)="lvl",MID(B128,12,1),"f") -> f | G128: =+LEFT(B128,3)&"."&MID(B128,4,2) -> b02.00 | H128: =IF(LEFT(E128,3)="lvl",IF(OR(RIGHT(B128,2)="_1",RIGHT(B128,2)="_2"),MID(B128,14,LEN(B128)-15), MID(B128,14,LEN(B128))),MID(B128,12,LEN(B128))) -> 0400_accrd_intrst_scrty
B129: b0200_frmt_0410_fees_charges_scrty | C129: 0 | E129: =+MID(B129,7,4) -> frmt | F129: =IF(LEFT(E129,3)="lvl",MID(B129,12,1),"f") -> f | G129: =+LEFT(B129,3)&"."&MID(B129,4,2) -> b02.00 | H129: =IF(LEFT(E129,3)="lvl",IF(OR(RIGHT(B129,2)="_1",RIGHT(B129,2)="_2"),MID(B129,14,LEN(B129)-15), MID(B129,14,LEN(B129))),MID(B129,12,LEN(B129))) -> 0410_fees_charges_scrty
...

Sheet 2.2. Outros
B6: 2.2. Outros Controlos
B8: TABELA | C8: CAMPO | D8: TIPOLOGIA_TESTE | E8: NUM_REG | F8: NUM_REG_DIF | G8: DETALHE | H8: Table | I8: Justificação
B9: BU_LOANTAPE_WORK.OUT_B0200_MAIN_LIABILITIES | C9: 0010_ROW_NMBR | D9: VALIDADE | E9: 8 | F9: 0 | H9: =MID(B9,22,3)&"."&MID(B9,25,2) -> B02.00
B10: BU_LOANTAPE_WORK.OUT_B0200_MAIN_LIABILITIES | C10: 0010_ROW_NMBR | D10: NOT APPLICABLE | E10: 8 | F10: 0 | H10: =MID(B10,22,3)&"."&MID(B10,25,2) -> B02.00
B11: BU_LOANTAPE_WORK.OUT_B0200_MAIN_LIABILITIES | C11: 0020_UNIQ_ID | D11: VALIDADE | E11: 8 | F11: 0 | H11: =MID(B11,22,3)&"."&MID(B11,25,2) -> B02.00
B12: BU_LOANTAPE_WORK.OUT_B0200_MAIN_LIABILITIES | C12: 0020_UNIQ_ID | D12: NOT APPLICABLE | E12: 8 | F12: 0 | H12: =MID(B12,22,3)&"."&MID(B12,25,2) -> B02.00
B13: BU_LOANTAPE_WORK.OUT_B0200_MAIN_LIABILITIES | C13: 0030_UNIQ_ID_KNWN_CNTRPRTY | D13: VALIDADE | E13: 8 | F13: 0 | H13: =MID(B13,22,3)&"."&MID(B13,25,2) -> B02.00
B14: BU_LOANTAPE_WORK.OUT_B0200_MAIN_LIABILITIES | C14: 0030_UNIQ_ID_KNWN_CNTRPRTY | D14: NOT APPLICABLE | E14: 8 | F14: 0 | H14: =MID(B14,22,3)&"."&MID(B14,25,2) -> B02.00
B15: BU_LOANTAPE_WORK.OUT_B0200_MAIN_LIABILITIES | C15: 0040_TYP_UNIQ_ID_KNWN_CNTRPRTY | D15: VALIDADE | E15: 8 | F15: 0 | H15: =MID(B15,22,3)&"."&MID(B15,25,2) -> B02.00
B16: BU_LOANTAPE_WORK.OUT_B0200_MAIN_LIABILITIES | C16: 0040_TYP_UNIQ_ID_KNWN_CNTRPRTY | D16: NOT APPLICABLE | E16: 8 | F16: 0 | H16: =MID(B16,22,3)&"."&MID(B16,25,2) -> B02.00
B17: BU_LOANTAPE_WORK.OUT_B0200_MAIN_LIABILITIES | C17: 0050_ORGNL_AMNT_EUR | D17: VALIDADE | E17: 8 | F17: 0 | H17: =MID(B17,22,3)&"."&MID(B17,25,2) -> B02.00
B18: BU_LOANTAPE_WORK.OUT_B0200_MAIN_LIABILITIES | C18: 0050_ORGNL_AMNT_EUR | D18: NOT APPLICABLE | E18: 8 | F18: 0 | H18: =MID(B18,22,3)&"."&MID(B18,25,2) -> B02.00
B19: BU_LOANTAPE_WORK.OUT_B0200_MAIN_LIABILITIES | C19: 0060_ORGNL_AMNT_FX | D19: VALIDADE | E19: 8 | F19: 0 | H19: =MID(B19,22,3)&"."&MID(B19,25,2) -> B02.00 | I19: TESTE
B20: BU_LOANTAPE_WORK.OUT_B0200_MAIN_LIABILITIES | C20: 0060_ORGNL_AMNT_FX | D20: NOT APPLICABLE | E20: 8 | F20: 0 | H20: =MID(B20,22,3)&"."&MID(B20,25,2) -> B02.00
B21: BU_LOANTAPE_WORK.OUT_B0200_MAIN_LIABILITIES | C21: 0070_CNTRCT_CRRNCY | D21: VALIDADE | E21: 8 | F21: 0 | H21: =MID(B21,22,3)&"."&MID(B21,25,2) -> B02.00
B22: BU_LOANTAPE_WORK.OUT_B0200_MAIN_LIABILITIES | C22: 0070_CNTRCT_CRRNCY | D22: NOT APPLICABLE | E22: 8 | F22: 0 | H22: =MID(B22,22,3)&"."&MID(B22,25,2) -> B02.00
B23: BU_LOANTAPE_WORK.OUT_B0200_MAIN_LIABILITIES | C23: 0100_ACCRD_INTRST_INSTRMNT | D23: VALIDADE | E23: 8 | F23: 0 | H23: =MID(B23,22,3)&"."&MID(B23,25,2) -> B02.00
B24: BU_LOANTAPE_WORK.OUT_B0200_MAIN_LIABILITIES | C24: 0100_ACCRD_INTRST_INSTRMNT | D24: NOT APPLICABLE | E24: 8 | F24: 0 | H24: =MID(B24,22,3)&"."&MID(B24,25,2) -> B02.00
B25: BU_LOANTAPE_WORK.OUT_B0200_MAIN_LIABILITIES | C25: 0110_APPLCBL_FEES_CHARGES | D25: VALIDADE | E25: 8 | F25: 0 | H25: =MID(B25,22,3)&"."&MID(B25,25,2) -> B02.00
B26: BU_LOANTAPE_WORK.OUT_B0200_MAIN_LIABILITIES | C26: 0110_APPLCBL_FEES_CHARGES | D26: NOT APPLICABLE | E26: 8 | F26: 0 | H26: =MID(B26,22,3)&"."&MID(B26,25,2) -> B02.00
B27: BU_LOANTAPE_WORK.OUT_B0200_MAIN_LIABILITIES | C27: 0140_NTR_LBLTY | D27: VALIDADE | E27: 8 | F27: 0 | H27: =MID(B27,22,3)&"."&MID(B27,25,2) -> B02.00
B28: BU_LOANTAPE_WORK.OUT_B0200_MAIN_LIABILITIES | C28: 0140_NTR_LBLTY | D28: NOT APPLICABLE | E28: 8 | F28: 0 | H28: =MID(B28,22,3)&"."&MID(B28,25,2) -> B02.00
B29: BU_LOANTAPE_WORK.OUT_B0200_MAIN_LIABILITIES | C29: 0141_NTR_LBLTY_OTHR | D29: VALIDADE | E29: 8 | F29: 0 | H29: =MID(B29,22,3)&"."&MID(B29,25,2) -> B02.00
B30: BU_LOANTAPE_WORK.OUT_B0200_MAIN_LIABILITIES | C30: 0141_NTR_LBLTY_OTHR | D30: NOT APPLICABLE | E30: 8 | F30: 8 | H30: =MID(B30,22,3)&"."&MID(B30,25,2) -> B02.00
B31: BU_LOANTAPE_WORK.OUT_B0200_MAIN_LIABILITIES | C31: 0150_FLG_STRCTRLLY_SBRDNTD | D31: VALIDADE | E31: 8 | F31: 0 | H31: =MID(B31,22,3)&"."&MID(B31,25,2) -> B02.00
... B33: BU_LOANTAPE_WORK.OUT_B0200_MAIN_LIABILITIES | C33: 0160_RANK_INSOLV | D33: VALIDADE | E33: 8 | F33: 0 | H33: =MID(B33,22,3)&"."&MID(B33,25,2) -> B02.00
B34: BU_LOANTAPE_WORK.OUT_B0200_MAIN_LIABILITIES | C34: 0160_RANK_INSOLV | D34: NOT APPLICABLE | E34: 8 | F34: 0 | H34: =MID(B34,22,3)&"."&MID(B34,25,2) -> B02.00 | I34: TESTE
B35: BU_LOANTAPE_WORK.OUT_B0200_MAIN_LIABILITIES | C35: 0161_CNTRCTL_SBRDNTN | D35: VALIDADE | E35: 8 | F35: 0 | H35: =MID(B35,22,3)&"."&MID(B35,25,2) -> B02.00
B36: BU_LOANTAPE_WORK.OUT_B0200_MAIN_LIABILITIES | C36: 0161_CNTRCTL_SBRDNTN | D36: NOT APPLICABLE | E36: 8 | F36: 0 | H36: =MID(B36,22,3)&"."&MID(B36,25,2) -> B02.00
B37: BU_LOANTAPE_WORK.OUT_B0200_MAIN_LIABILITIES | C37: 0162_BAIL_IN_CASCADE | D37: VALIDADE | E37: 8 | F37: 0 | H37: =MID(B37,22,3)&"."&MID(B37,25,2) -> B02.00
B38: BU_LOANTAPE_WORK.OUT_B0200_MAIN_LIABILITIES | C38: 0162_BAIL_IN_CASCADE | D38: NOT APPLICABLE | E38: 8 | F38: 0 | H38: =MID(B38,22,3)&"."&MID(B38,25,2) -> B02.00
B39: BU_LOANTAPE_WORK.OUT_B0200_MAIN_LIABILITIES | C39: 0170_DT_INCPTN | D39: VALIDADE | E39: 8 | F39: 0 | H39: =MID(B39,22,3)&"."&MID(B39,25,2) -> B02.00
B40: BU_LOANTAPE_WORK.OUT_B0200_MAIN_LIABILITIES | C40: 0170_DT_INCPTN | D40: NOT APPLICABLE | E40: 8 | F40: 0 | H40: =MID(B40,22,3)&"."&MID(B40,25,2) -> B02.00
B41: BU_LOANTAPE_WORK.OUT_B0200_MAIN_LIABILITIES | C41: 0180_DT_NXT_INTRST_PYMNT | D41: VALIDADE | E41: 8 | F41: 8 | H41: =MID(B41,22,3)&"."&MID(B41,25,2) -> B02.00
B42: BU_LOANTAPE_WORK.OUT_B0200_MAIN_LIABILITIES | C42: 0180_DT_NXT_INTRST_PYMNT | D42: NOT APPLICABLE | E42: 8 | F42: 0 | H42: =MID(B42,22,3)&"."&MID(B42,25,2) -> B02.00
B43: BU_LOANTAPE_WORK.OUT_B0200_MAIN_LIABILITIES | C43: 0190_DT_NXT_RDMPTN_PYMNT | D43: VALIDADE | E43: 8 | F43: 0 | H43: =MID(B43,22,3)&"."&MID(B43,25,2) -> B02.00
B44: BU_LOANTAPE_WORK.OUT_B0200_MAIN_LIABILITIES | C44: 0190_DT_NXT_RDMPTN_PYMNT | D44: NOT APPLICABLE | E44: 8 | F44: 3 | H44: =MID(B44,22,3)&"."&MID(B44,25,2) -> B02.00
B45: BU_LOANTAPE_WORK.OUT_B0200_MAIN_LIABILITIES | C45: 0200_DT_ERLST_RDMPTN | D45: VALIDADE | E45: 8 | F45: 0 | H45: =MID(B45,22,3)&"."&MID(B45,25,2) -> B02.00
B46: BU_LOANTAPE_WORK.OUT_B0200_MAIN_LIABILITIES | C46: 0200_DT_ERLST_RDMPTN | D46: NOT APPLICABLE | E46: 8 | F46: 8 | H46: =MID(B46,22,3)&"."&MID(B46,25,2) -> B02.00
... B127: BU_LOANTAPE_WORK.OUT_B0200_MAIN_LIABILITIES | C127: 0540_ELGBL_AMNT_OWN_FNDS_IND_LVL | D127: VALIDADE | E127: 8 | F127: 0 | H127: =MID(B127,22,3)&"."&MID(B127,25,2) -> B02.00
...

Sheet 2.3. Processo
B6: 2.3. Controlos de Processo (HUE vs CSV)
C8: B02.00
C9: Tabela HUE | G9: Tabela CSV | K9: Controlos
C11: CAMPO 1 | D11: CAMPO 2 | E11: CAMPO 3 | G11: CAMPO 1 | H11: CAMPO 2 | I11: CAMPO 3 | K11: =+C11=G11 -> TRUE | L11: =+D11=H11 -> TRUE | M11: =+E11=I11 -> TRUE
C12: Valor 1 | D12: Valor 2 | E12: Valor 3 | G12: Valor 1 | H12: Valor 2 | I12: Valor 3 | K12: =+C12=G12 -> TRUE | L12: =+D12=H12 -> TRUE | M12: =+E12=I12 -> TRUE
C13: Valor 1 | D13: Valor 2 | E13: Valor 3 | G13: Valor 1 | H13: Valor 2 | I13: Valor 3 | K13: =+C13=G13 -> TRUE | L13: =+D13=H13 -> TRUE | M13: =+E13=I13 -> TRUE
C15: B50.00
C16: Tabela HUE | G16: Tabela CSV | K16: Controlos
C18: CAMPO 1 | D18: CAMPO 2 | E18: CAMPO 3 | G18: CAMPO 1 | H18: CAMPO 2 | I18: CAMPO 3 | K18: =+C18=G18 -> TRUE | L18: =+D18=H18 -> TRUE | M18: =+E18=I18 -> TRUE
C19: Valor 1 | D19: Valor 2 | E19: Valor 3 | G19: Valor 1 | H19: Valor 2 | I19: Valor 3 | K19: =+C19=G19 -> TRUE | L19: =+D19=H19 -> TRUE | M19: =+E19=I19 -> TRUE
C20: Valor 1 | D20: Valor 2 | E20: Valor 3 | G20: Valor 1 | H20: Valor 2 | I20: Valor 3 | K20: =+C20=G20 -> TRUE | L20: =+D20=H20 -> TRUE | M20: =+E20=I20 -> TRUE
C22: B90.00
C23: Tabela HUE | G23: Tabela CSV | K23: Controlos
C25: CAMPO 1 | D25: CAMPO 2 | E25: CAMPO 3 | G25: CAMPO 1 | H25: CAMPO 2 | I25: CAMPO 3 | K25: =+C25=G25 -> TRUE | L25: =+D25=H25 -> TRUE | M25: =+E25=I25 -> TRUE
C26: Valor 1 | D26: Valor 2 | E26: Valor 3 | G26: Valor 1 | H26: Valor 2 | I26: Valor 3 | K26: =+C26=G26 -> TRUE | L26: =+D26=H26 -> TRUE | M26: =+E26=I26 -> TRUE
