Workbook
Name RefDateCell: '1. Dashboard'!$D$12

Sheet Instruções
B6: Instruções

Sheet Param_RefDate
A1: Param_RefDate
A2: 2025-10-31

Sheet 1. Dashboard
B6: 1 Dashboard
B9: Controlos Reporte Bail-in
C12: Data de referência | D12: 2025-10-31
D15: MENU 1 | G15: MENU 2 | J15: NAVEGADOR
D18: TABELAS OUTPUT | G18: Processo (HUE vs CSV) | J18: Processo (HUE vs CSV)
D20: 2. Gerar Controlos | E20: [BOTÃO] | G20: 2. Gerar Controlos | H20: [BOTÃO] | J20: 1. WIP | L20: [LINK]
D22: 3. Extração dos resultados | E22: [BOTÃO] | G22: 3. Extração dos resultados | H22: [BOTÃO] | J22: 1. WIP | L22: [LINK]
J24: 1. WIP | L24: [LINK]
H31: DASHBOARD
C34: 1. Tabelas Output
C36: Mapa | D36: Total (#) | E36: OK (#) | F36: OK (%) | G36: NOK Justificados(#) | H36: NOK Justificados (%) | I36: NOK (#) | J36: NOK (%)
C37: B02.00 | D37: =+SUM(D38,D42) -> 304 | E37: =+SUM(E38,E42) -> 258 | F37: =IFERROR(E37/D37,0) -> 0.84868421 | G37: =+SUM(G38,G42) -> 8 | H37: =IFERROR(G37/D37,0) -> 0.026315789 | I37: =+SUM(I38,I42) -> 33 | J37: =IFERROR(I37/D37,0) -> 0.10855263
C38: Regulamentares (SRB) | D38: =+SUM(D39:D41) -> 156 | E38: =+SUM(E39:E41) -> 134 | F38: =IFERROR(E38/D38,0) -> 0.85897436 | G38: =+SUM(G39:G41) -> 6 | H38: =IFERROR(G38/D38,0) -> 0.038461538 | I38: =+SUM(I39:I41) -> 11 | J38: =IFERROR(I38/D38,0) -> 0.070512821
C39: High severity | D39: =+COUNTIFS('2.1. Regulamentares'!G:G,'1. Dashboard'!$C$37,'2.1. Regulamentares'!F:F,"h") -> 63 | E39: =+COUNTIFS('2.1. Regulamentares'!G:G,'1. Dashboard'!$C$37,'2.1. Regulamentares'!F:F,"h",'2.1. Regulamentares'!C:C,"=0") -> 53 | F39: =IFERROR(E39/D39,0) -> 0.84126984 | G39: =+COUNTIFS('2.1. Regulamentares'!G:G,'1. Dashboard'!$C$37,'2.1. Regulamentares'!F:F,"h",'2.1. Regulamentares'!C:C,">0",'2.1. Regulamentares'!I:I,"<>") -> 0 | H39: =IFERROR(G39/D39,0) -> 0 | I39: =+COUNTIFS('2.1. Regulamentares'!G:G,'1. Dashboard'!$C$37,'2.1. Regulamentares'!F:F,"h",'2.1. Regulamentares'!C:C,">0",'2.1. Regulamentares'!I:I,"") -> 5 | J39: =IFERROR(I39/D39,0) -> 0.079365079
C40: Warnings | D40: =+COUNTIFS('2.1. Regulamentares'!G:G,'1. Dashboard'!$C$37,'2.1. Regulamentares'!F:F,"w") -> 12 | E40: =+COUNTIFS('2.1. Regulamentares'!G:G,'1. Dashboard'!$C$37,'2.1. Regulamentares'!F:F,"w",'2.1. Regulamentares'!C:C,"=0") -> 11 | F40: =IFERROR(E40/D40,0) -> 0.91666667 | G40: =+COUNTIFS('2.1. Regulamentares'!G:G,'1. Dashboard'!$C$37,'2.1. Regulamentares'!F:F,"w",'2.1. Regulamentares'!C:C,">0",'2.1. Regulamentares'!I:I,"<>") -> 0 | H40: =IFERROR(G40/D40,0) -> 0 | I40: =+COUNTIFS('2.1. Regulamentares'!G:G,'1. Dashboard'!$C$37,'2.1. Regulamentares'!F:F,"w",'2.1. Regulamentares'!C:C,">0",'2.1. Regulamentares'!I:I,"") -> 1 | J40: =IFERROR(I40/D40,0) -> 0.083333333
C41: Formatos | D41: =+COUNTIFS('2.1. Regulamentares'!G:G,'1. Dashboard'!$C$37,'2.1. Regulamentares'!F:F,"f") -> 81 | E41: =+COUNTIFS('2.1. Regulamentares'!G:G,'1. Dashboard'!$C$37,'2.1. Regulamentares'!F:F,"f",'2.1. Regulamentares'!C:C,"=0") -> 70 | F41: =IFERROR(E41/D41,0) -> 0.86419753 | G41: =+COUNTIFS('2.1. Regulamentares'!G:G,'1. Dashboard'!$C$37,'2.1. Regulamentares'!F:F,"f",'2.1. Regulamentares'!C:C,">0",'2.1. Regulamentares'!I:I,"<>") -> 6 | H41: =IFERROR(G41/D41,0) -> 0.074074074 | I41: =+COUNTIFS('2.1. Regulamentares'!G:G,'1. Dashboard'!$C$37,'2.1. Regulamentares'!F:F,"f",'2.1. Regulamentares'!C:C,">0",'2.1. Regulamentares'!I:I,"") -> 5 | J41: =IFERROR(I41/D41,0) -> 0.061728395
C42: Outros | D42: =+SUM(D43:D46) -> 148 | E42: =+SUM(E43:E46) -> 124 | F42: =IFERROR(E42/D42,0) -> 0.83783784 | G42: =+SUM(G43:G46) -> 2 | H42: =IFERROR(G42/D42,0) -> 0.013513514 | I42: =+SUM(I43:I46) -> 22 | J42: =IFERROR(I42/D42,0) -> 0.14864865
C43: Validade (Missings/NULLS) | D43: =+COUNTIFS('2.2. Outros'!H:H,'1. Dashboard'!$C$37,'2.2. Outros'!D:D,"Validade") -> 73 | E43: =+COUNTIFS('2.2. Outros'!H:H,'1. Dashboard'!$C$37,'2.2. Outros'!D:D,"Validade",'2.2. Outros'!F:F,"0") -> 70 | F43: =IFERROR(E43/D43,0) -> 0.95890411 | G43: =+COUNTIFS('2.2. Outros'!H:H,'1. Dashboard'!$C$37,'2.2. Outros'!D:D,"Validade",'2.2. Outros'!F:F,"<>0",'2.2. Outros'!I:I,"<>") -> 1 | H43: =IFERROR(G43/D43,0) -> 0.01369863 | I43: =+COUNTIFS('2.2. Outros'!H:H,'1. Dashboard'!$C$37,'2.2. Outros'!D:D,"Validade",'2.2. Outros'!F:F,"<>0",'2.2. Outros'!I:I,"") -> 2 | J43: =IFERROR(I43/D43,0) -> 0.02739726
C44: Not applicables | D44: =+COUNTIFS('2.2. Outros'!H:H,'1. Dashboard'!$C$37,'2.2. Outros'!D:D,"Not applicable") -> 73 | E44: =+COUNTIFS('2.2. Outros'!H:H,'1. Dashboard'!$C$37,'2.2. Outros'!D:D,"Not applicable",'2.2. Outros'!F:F,"0") -> 52 | F44: =IFERROR(E44/D44,0) -> 0.71232877 | G44: =+COUNTIFS('2.2. Outros'!H:H,'1. Dashboard'!$C$37,'2.2. Outros'!D:D,"Not applicable",'2.2. Outros'!F:F,"<>0",'2.2. Outros'!I:I,"<>") -> 1 | H44: =IFERROR(G44/D44,0) -> 0.01369863 | I44: =+COUNTIFS('2.2. Outros'!H:H,'1. Dashboard'!$C$37,'2.2. Outros'!D:D,"Not applicable",'2.2. Outros'!F:F,"<>0",'2.2. Outros'!I:I,"") -> 20 | J44: =IFERROR(I44/D44,0) -> 0.2739726
C45: Duplicados | D45: =+COUNTIFS('2.2. Outros'!H:H,'1. Dashboard'!$C$37,'2.2. Outros'!D:D,"Duplicados") -> 1 | E45: =+COUNTIFS('2.2. Outros'!H:H,'1. Dashboard'!$C$37,'2.2. Outros'!D:D,"Duplicados",'2.2. Outros'!F:F,"0") -> 1 | F45: =IFERROR(E45/D45,0) -> 1 | G45: =+COUNTIFS('2.2. Outros'!H:H,'1. Dashboard'!$C$37,'2.2. Outros'!D:D,"Duplicados",'2.2. Outros'!F:F,"<>0",'2.2. Outros'!I:I,"<>") -> 0 | H45: =IFERROR(G45/D45,0) -> 0 | I45: =+COUNTIFS('2.2. Outros'!H:H,'1. Dashboard'!$C$37,'2.2. Outros'!D:D,"Duplicados",'2.2. Outros'!F:F,"<>0",'2.2. Outros'!I:I,"") -> 0 | J45: =IFERROR(I45/D45,0) -> 0
C46: Integridade entre tabelas | D46: =+COUNTIFS('2.2. Outros'!H:H,'1. Dashboard'!$C$37,'2.2. Outros'!D:D,"Integridade") -> 1 | E46: =+COUNTIFS('2.2. Outros'!H:H,'1. Dashboard'!$C$37,'2.2. Outros'!D:D,"Integridade",'2.2. Outros'!F:F,"0") -> 1 | F46: =IFERROR(E46/D46,0) -> 1 | G46: =+COUNTIFS('2.2. Outros'!H:H,'1. Dashboard'!$C$37,'2.2. Outros'!D:D,"Integridade",'2.2. Outros'!F:F,"<>0",'2.2. Outros'!I:I,"<>") -> 0 | H46: =IFERROR(G46/D46,0) -> 0 | I46: =+COUNTIFS('2.2. Outros'!H:H,'1. Dashboard'!$C$37,'2.2. Outros'!D:D,"Integridade",'2.2. Outros'!F:F,"<>0",'2.2. Outros'!I:I,"") -> 0 | J46: =IFERROR(I46/D46,0) -> 0
C47: B05.00 | D47: =+SUM(D48,D52) -> 20 | E47: =+SUM(E48,E52) -> 17 | F47: =IFERROR(E47/D47,0) -> 0.85 | G47: =+SUM(G48,G52) -> 2 | H47: =IFERROR(G47/D47,0) -> 0.1 | I47: =+SUM(I48,I52) -> 1 | J47: =IFERROR(I47/D47,0) -> 0.05
C48: Regulamentares (SRB) | D48: =+SUM(D49:D51) -> 19 | E48: =+SUM(E49:E51) -> 16 | F48: =IFERROR(E48/D48,0) -> 0.84210526 | G48: =+SUM(G49:G51) -> 2 | H48: =IFERROR(G48/D48,0) -> 0.10526316 | I48: =+SUM(I49:I51) -> 1 | J48: =IFERROR(I48/D48,0) -> 0.052631579
C49: High severity | D49: =+COUNTIFS('2.1. Regulamentares'!G:G,$C$47,'2.1. Regulamentares'!F:F,"h") -> 5 | E49: =+COUNTIFS('2.1. Regulamentares'!G:G,$C$47,'2.1. Regulamentares'!F:F,"h",'2.1. Regulamentares'!C:C,"=0") -> 4 | F49: =IFERROR(E49/D49,0) -> 0.8 | G49: =+COUNTIFS('2.1. Regulamentares'!G:G,$C$47,'2.1. Regulamentares'!F:F,"h",'2.1. Regulamentares'!C:C,">0",'2.1. Regulamentares'!I:I,"<>") -> 0 | H49: =IFERROR(G49/D49,0) -> 0 | I49: =+COUNTIFS('2.1. Regulamentares'!G:G,$C$47,'2.1. Regulamentares'!F:F,"h",'2.1. Regulamentares'!C:C,">0",'2.1. Regulamentares'!I:I,"") -> 1 | J49: =IFERROR(I49/D49,0) -> 0.2
C50: Warnings | D50: =+COUNTIFS('2.1. Regulamentares'!G:G,$C$47,'2.1. Regulamentares'!F:F,"w") -> 0 | E50: =+COUNTIFS('2.1. Regulamentares'!G:G,$C$47,'2.1. Regulamentares'!F:F,"w",'2.1. Regulamentares'!C:C,"=0") -> 0 | F50: =IFERROR(E50/D50,0) -> 0 | G50: =+COUNTIFS('2.1. Regulamentares'!G:G,$C$47,'2.1. Regulamentares'!F:F,"w",'2.1. Regulamentares'!C:C,">0",'2.1. Regulamentares'!I:I,"<>") -> 0 | H50: =IFERROR(G50/D50,0) -> 0 | I50: =+COUNTIFS('2.1. Regulamentares'!G:G,$C$47,'2.1. Regulamentares'!F:F,"w",'2.1. Regulamentares'!C:C,">0",'2.1. Regulamentares'!I:I,"") -> 0 | J50: =IFERROR(I50/D50,0) -> 0
C51: Formatos | D51: =+COUNTIFS('2.1. Regulamentares'!G:G,$C$47,'2.1. Regulamentares'!F:F,"f") -> 14 | E51: =+COUNTIFS('2.1. Regulamentares'!G:G,$C$47,'2.1. Regulamentares'!F:F,"f",'2.1. Regulamentares'!C:C,"=0") -> 12 | F51: =IFERROR(E51/D51,0) -> 0.85714286 | G51: =+COUNTIFS('2.1. Regulamentares'!G:G,$C$47,'2.1. Regulamentares'!F:F,"f",'2.1. Regulamentares'!C:C,">0",'2.1. Regulamentares'!I:I,"<>") -> 2 | H51: =IFERROR(G51/D51,0) -> 0.14285714 | I51: =+COUNTIFS('2.1. Regulamentares'!G:G,$C$47,'2.1. Regulamentares'!F:F,"f",'2.1. Regulamentares'!C:C,">0",'2.1. Regulamentares'!I:I,"") -> 0 | J51: =IFERROR(I51/D51,0) -> 0
C52: Outros | D52: =+SUM(D53:D56) -> 1 | E52: =+SUM(E53:E56) -> 1 | F52: =IFERROR(E52/D52,0) -> 1 | G52: =+SUM(G53:G56) -> 0 | H52: =IFERROR(G52/D52,0) -> 0 | I52: =+SUM(I53:I56) -> 0 | J52: =IFERROR(I52/D52,0) -> 0
C53: Validade (Missings/NULLS) | D53: =+COUNTIFS('2.2. Outros'!H:H,$C$47,'2.2. Outros'!D:D,"Validade") -> 0 | E53: =+COUNTIFS('2.2. Outros'!H:H,$C$47,'2.2. Outros'!D:D,"Validade",'2.2. Outros'!F:F,"0") -> 0 | F53: =IFERROR(E53/D53,0) -> 0 | G53: =+COUNTIFS('2.2. Outros'!H:H,$C$47,'2.2. Outros'!D:D,"Validade",'2.2. Outros'!F:F,"<>0",'2.2. Outros'!I:I,"<>") -> 0 | H53: =IFERROR(G53/D53,0) -> 0 | I53: =+COUNTIFS('2.2. Outros'!H:H,$C$47,'2.2. Outros'!D:D,"Validade",'2.2. Outros'!F:F,"<>0",'2.2. Outros'!I:I,"") -> 0 | J53: =IFERROR(I53/D53,0) -> 0
C54: Not applicables | D54: =+COUNTIFS('2.2. Outros'!H:H,$C$47,'2.2. Outros'!D:D,"Not applicable") -> 0 | E54: =+COUNTIFS('2.2. Outros'!H:H,$C$47,'2.2. Outros'!D:D,"Not applicable",'2.2. Outros'!F:F,"0") -> 0 | F54: =IFERROR(E54/D54,0) -> 0 | G54: =+COUNTIFS('2.2. Outros'!H:H,$C$47,'2.2. Outros'!D:D,"Not applicable",'2.2. Outros'!F:F,"<>0",'2.2. Outros'!I:I,"<>") -> 0 | H54: =IFERROR(G54/D54,0) -> 0 | I54: =+COUNTIFS('2.2. Outros'!H:H,$C$47,'2.2. Outros'!D:D,"Not applicable",'2.2. Outros'!F:F,"<>0",'2.2. Outros'!I:I,"") -> 0 | J54: =IFERROR(I54/D54,0) -> 0
C55: Duplicados | D55: =+COUNTIFS('2.2. Outros'!H:H,$C$47,'2.2. Outros'!D:D,"Duplicados") -> 0 | E55: =+COUNTIFS('2.2. Outros'!H:H,$C$47,'2.2. Outros'!D:D,"Duplicados",'2.2. Outros'!F:F,"0") -> 0 | F55: =IFERROR(E55/D55,0) -> 0 | G55: =+COUNTIFS('2.2. Outros'!H:H,$C$47,'2.2. Outros'!D:D,"Duplicados",'2.2. Outros'!F:F,"<>0",'2.2. Outros'!I:I,"<>") -> 0 | H55: =IFERROR(G55/D55,0) -> 0 | I55: =+COUNTIFS('2.2. Outros'!H:H,$C$47,'2.2. Outros'!D:D,"Duplicados",'2.2. Outros'!F:F,"<>0",'2.2. Outros'!I:I,"") -> 0 | J55: =IFERROR(I55/D55,0) -> 0
C56: Integridade entre tabelas | D56: =+COUNTIFS('2.2. Outros'!H:H,$C$47,'2.2. Outros'!D:D,"Integridade") -> 1 | E56: =+COUNTIFS('2.2. Outros'!H:H,$C$47,'2.2. Outros'!D:D,"Integridade",'2.2. Outros'!F:F,"0") -> 1 | F56: =IFERROR(E56/D56,0) -> 1 | G56: =+COUNTIFS('2.2. Outros'!H:H,$C$47,'2.2. Outros'!D:D,"Integridade",'2.2. Outros'!F:F,"<>0",'2.2. Outros'!I:I,"<>") -> 0 | H56: =IFERROR(G56/D56,0) -> 0 | I56: =+COUNTIFS('2.2. Outros'!H:H,$C$47,'2.2. Outros'!D:D,"Integridade",'2.2. Outros'!F:F,"<>0",'2.2. Outros'!I:I,"") -> 0 | J56: =IFERROR(I56/D56,0) -> 0
C57: B90.00 | D57: =+SUM(D58,D62) -> 16 | E57: =+SUM(E58,E62) -> 13 | F57: =IFERROR(E57/D57,0) -> 0.8125 | G57: =+SUM(G58,G62) -> 2 | H57: =IFERROR(G57/D57,0) -> 0.125 | I57: =+SUM(I58,I62) -> 1 | J57: =IFERROR(I57/D57,0) -> 0.0625
C58: Regulamentares (SRB) | D58: =+SUM(D59:D61) -> 15 | E58: =+SUM(E59:E61) -> 12 | F58: =IFERROR(E58/D58,0) -> 0.8 | G58: =+SUM(G59:G61) -> 2 | H58: =IFERROR(G58/D58,0) -> 0.13333333 | I58: =+SUM(I59:I61) -> 1 | J58: =IFERROR(I58/D58,0) -> 0.066666667
C59: High severity | D59: =+COUNTIFS('2.1. Regulamentares'!G:G,$C$57,'2.1. Regulamentares'!F:F,"h") -> 4 | E59: =+COUNTIFS('2.1. Regulamentares'!G:G,$C$57,'2.1. Regulamentares'!F:F,"h",'2.1. Regulamentares'!C:C,"=0") -> 2 | F59: =IFERROR(E59/D59,0) -> 0.5 | G59: =+COUNTIFS('2.1. Regulamentares'!G:G,$C$57,'2.1. Regulamentares'!F:F,"h",'2.1. Regulamentares'!C:C,">0",'2.1. Regulamentares'!I:I,"<>") -> 1 | H59: =IFERROR(G59/D59,0) -> 0.25 | I59: =+COUNTIFS('2.1. Regulamentares'!G:G,$C$57,'2.1. Regulamentares'!F:F,"h",'2.1. Regulamentares'!C:C,">0",'2.1. Regulamentares'!I:I,"") -> 1 | J59: =IFERROR(I59/D59,0) -> 0.25
C60: Warnings | D60: =+COUNTIFS('2.1. Regulamentares'!G:G,$C$57,'2.1. Regulamentares'!F:F,"w") -> 0 | E60: =+COUNTIFS('2.1. Regulamentares'!G:G,$C$57,'2.1. Regulamentares'!F:F,"w",'2.1. Regulamentares'!C:C,"=0") -> 0 | F60: =IFERROR(E60/D60,0) -> 0 | G60: =+COUNTIFS('2.1. Regulamentares'!G:G,$C$57,'2.1. Regulamentares'!F:F,"w",'2.1. Regulamentares'!C:C,">0",'2.1. Regulamentares'!I:I,"<>") -> 0 | H60: =IFERROR(G60/D60,0) -> 0 | I60: =+COUNTIFS('2.1. Regulamentares'!G:G,$C$57,'2.1. Regulamentares'!F:F,"w",'2.1. Regulamentares'!C:C,">0",'2.1. Regulamentares'!I:I,"") -> 0 | J60: =IFERROR(I60/D60,0) -> 0
C61: Formatos | D61: =+COUNTIFS('2.1. Regulamentares'!G:G,$C$57,'2.1. Regulamentares'!F:F,"f") -> 11 | E61: =+COUNTIFS('2.1. Regulamentares'!G:G,$C$57,'2.1. Regulamentares'!F:F,"f",'2.1. Regulamentares'!C:C,"=0") -> 10 | F61: =IFERROR(E61/D61,0) -> 0.90909091 | G61: =+COUNTIFS('2.1. Regulamentares'!G:G,$C$57,'2.1. Regulamentares'!F:F,"f",'2.1. Regulamentares'!C:C,">0",'2.1. Regulamentares'!I:I,"<>") -> 1 | H61: =IFERROR(G61/D61,0) -> 0.090909091 | I61: =+COUNTIFS('2.1. Regulamentares'!G:G,$C$57,'2.1. Regulamentares'!F:F,"f",'2.1. Regulamentares'!C:C,">0",'2.1. Regulamentares'!I:I,"") -> 0 | J61: =IFERROR(I61/D61,0) -> 0
C62: Outros | D62: =+SUM(D63:D66) -> 1 | E62: =+SUM(E63:E66) -> 1 | F62: =IFERROR(E62/D62,0) -> 1 | G62: =+SUM(G63:G66) -> 0 | H62: =IFERROR(G62/D62,0) -> 0 | I62: =+SUM(I63:I66) -> 0 | J62: =IFERROR(I62/D62,0) -> 0
C63: Validade (Missings/NULLS) | D63: =+COUNTIFS('2.2. Outros'!H:H,$C$57,'2.2. Outros'!D:D,"Validade") -> 0 | E63: =+COUNTIFS('2.2. Outros'!H:H,$C$57,'2.2. Outros'!D:D,"Validade",'2.2. Outros'!F:F,"0") -> 0 | F63: =IFERROR(E63/D63,0) -> 0 | G63: =+COUNTIFS('2.2. Outros'!H:H,$C$57,'2.2. Outros'!D:D,"Validade",'2.2. Outros'!F:F,"<>0",'2.2. Outros'!I:I,"<>") -> 0 | H63: =IFERROR(G63/D63,0) -> 0 | I63: =+COUNTIFS('2.2. Outros'!H:H,$C$57,'2.2. Outros'!D:D,"Validade",'2.2. Outros'!F:F,"<>0",'2.2. Outros'!I:I,"") -> 0 | J63: =IFERROR(I63/D63,0) -> 0
C64: Not applicables | D64: =+COUNTIFS('2.2. Outros'!H:H,$C$57,'2.2. Outros'!D:D,"Not applicable") -> 0 | E64: =+COUNTIFS('2.2. Outros'!H:H,$C$57,'2.2. Outros'!D:D,"Not applicable",'2.2. Outros'!F:F,"0") -> 0 | F64: =IFERROR(E64/D64,0) -> 0 | G64: =+COUNTIFS('2.2. Outros'!H:H,$C$57,'2.2. Outros'!D:D,"Not applicable",'2.2. Outros'!F:F,"<>0",'2.2. Outros'!I:I,"<>") -> 0 | H64: =IFERROR(G64/D64,0) -> 0 | I64: =+COUNTIFS('2.2. Outros'!H:H,$C$57,'2.2. Outros'!D:D,"Not applicable",'2.2. Outros'!F:F,"<>0",'2.2. Outros'!I:I,"") -> 0 | J64: =IFERROR(I64/D64,0) -> 0
C65: Duplicados | D65: =+COUNTIFS('2.2. Outros'!H:H,$C$57,'2.2. Outros'!D:D,"Duplicados") -> 0 | E65: =+COUNTIFS('2.2. Outros'!H:H,$C$57,'2.2. Outros'!D:D,"Duplicados",'2.2. Outros'!F:F,"0") -> 0 | F65: =IFERROR(E65/D65,0) -> 0 | G65: =+COUNTIFS('2.2. Outros'!H:H,$C$57,'2.2. Outros'!D:D,"Duplicados",'2.2. Outros'!F:F,"<>0",'2.2. Outros'!I:I,"<>") -> 0 | H65: =IFERROR(G65/D65,0) -> 0 | I65: =+COUNTIFS('2.2. Outros'!H:H,$C$57,'2.2. Outros'!D:D,"Duplicados",'2.2. Outros'!F:F,"<>0",'2.2. Outros'!I:I,"") -> 0 | J65: =IFERROR(I65/D65,0) -> 0
...

Sheet 2. Inputs -->

Sheet 2.1. Regulamentares
B6: 2.1. Controlos Regulamentares
B8: Controlo | C8: Issues | D8: Detalhe | E8: Tipo | F8: High Severity (H)/ Warning (W) | G8: Table | H8: Field | I8: Justificação
B9: b0200_lvl1_h_0010_row_nmbr | C9: 0 | E9: =+MID(B9,7,4) -> lvl1 | F9: =IF(LEFT(E9,3)="lvl",MID(B9,12,1),"f") -> h | G9: =+LEFT(B9,3)&"."&MID(B9,4,2) -> b02.00 | H9: =IF(LEFT(E9,3)="lvl",IF(OR(RIGHT(B9,2)="_1",RIGHT(B9,2)="_2"),MID(B9,14,LEN(B9)-15), MID(B9,14,LEN(B9))),MID(B9,12,LEN(B9))) -> 0010_row_nmbr
B10: b0200_lvl1_h_0030_uniq_id_knwn_cntrprty | C10: 0 | E10: =+MID(B10,7,4) -> lvl1 | F10: =IF(LEFT(E10,3)="lvl",MID(B10,12,1),"f") -> h | G10: =+LEFT(B10,3)&"."&MID(B10,4,2) -> b02.00 | H10: =IF(LEFT(E10,3)="lvl",IF(OR(RIGHT(B10,2)="_1",RIGHT(B10,2)="_2"),MID(B10,14,LEN(B10)-15), MID(B10,14,LEN(B10))),MID(B10,12,LEN(B10))) -> 0030_uniq_id_knwn_cntrprty
B11: b0200_lvl1_h_0040_typ_uniq_id_knwn_cntrprty | C11: 0 | E11: =+MID(B11,7,4) -> lvl1 | F11: =IF(LEFT(E11,3)="lvl",MID(B11,12,1),"f") -> h | G11: =+LEFT(B11,3)&"."&MID(B11,4,2) -> b02.00 | H11: =IF(LEFT(E11,3)="lvl",IF(OR(RIGHT(B11,2)="_1",RIGHT(B11,2)="_2"),MID(B11,14,LEN(B11)-15), MID(B11,14,LEN(B11))),MID(B11,12,LEN(B11))) -> 0040_typ_uniq_id_knwn_cntrprty
B12: b0200_lvl1_h_0070_cntrct_crrncy | C12: 0 | E12: =+MID(B12,7,4) -> lvl1 | F12: =IF(LEFT(E12,3)="lvl",MID(B12,12,1),"f") -> h | G12: =+LEFT(B12,3)&"."&MID(B12,4,2) -> b02.00 | H12: =IF(LEFT(E12,3)="lvl",IF(OR(RIGHT(B12,2)="_1",RIGHT(B12,2)="_2"),MID(B12,14,LEN(B12)-15), MID(B12,14,LEN(B12))),MID(B12,12,LEN(B12))) -> 0070_cntrct_crrncy
B13: b0200_lvl1_h_0080_otstndng_prncpl_amnt | C13: 0 | E13: =+MID(B13,7,4) -> lvl1 | F13: =IF(LEFT(E13,3)="lvl",MID(B13,12,1),"f") -> h | G13: =+LEFT(B13,3)&"."&MID(B13,4,2) -> b02.00 | H13: =IF(LEFT(E13,3)="lvl",IF(OR(RIGHT(B13,2)="_1",RIGHT(B13,2)="_2"),MID(B13,14,LEN(B13)-15), MID(B13,14,LEN(B13))),MID(B13,12,LEN(B13))) -> 0080_otstndng_prncpl_amnt
B14: b0200_lvl1_w_0080_otstndng_prncpl_amnt | C14: 0 | E14: =+MID(B14,7,4) -> lvl1 | F14: =IF(LEFT(E14,3)="lvl",MID(B14,12,1),"f") -> w | G14: =+LEFT(B14,3)&"."&MID(B14,4,2) -> b02.00 | H14: =IF(LEFT(E14,3)="lvl",IF(OR(RIGHT(B14,2)="_1",RIGHT(B14,2)="_2"),MID(B14,14,LEN(B14)-15), MID(B14,14,LEN(B14))),MID(B14,12,LEN(B14))) -> 0080_otstndng_prncpl_amnt
B15: b0200_lvl1_h_0090_prtn_amnt_rprtng_entty | C15: 0 | E15: =+MID(B15,7,4) -> lvl1 | F15: =IF(LEFT(E15,3)="lvl",MID(B15,12,1),"f") -> h | G15: =+LEFT(B15,3)&"."&MID(B15,4,2) -> b02.00 | H15: =IF(LEFT(E15,3)="lvl",IF(OR(RIGHT(B15,2)="_1",RIGHT(B15,2)="_2"),MID(B15,14,LEN(B15)-15), MID(B15,14,LEN(B15))),MID(B15,12,LEN(B15))) -> 0090_prtn_amnt_rprtng_entty
B16: b0200_lvl1_h_0100_accrd_intrst_instrmnt | C16: 0 | E16: =+MID(B16,7,4) -> lvl1 | F16: =IF(LEFT(E16,3)="lvl",MID(B16,12,1),"f") -> h | G16: =+LEFT(B16,3)&"."&MID(B16,4,2) -> b02.00 | H16: =IF(LEFT(E16,3)="lvl",IF(OR(RIGHT(B16,2)="_1",RIGHT(B16,2)="_2"),MID(B16,14,LEN(B16)-15), MID(B16,14,LEN(B16))),MID(B16,12,LEN(B16))) -> 0100_accrd_intrst_instrmnt
B17: b0200_lvl1_w_0100_accrd_intrst_instrmnt | C17: 0 | E17: =+MID(B17,7,4) -> lvl1 | F17: =IF(LEFT(E17,3)="lvl",MID(B17,12,1),"f") -> w | G17: =+LEFT(B17,3)&"."&MID(B17,4,2) -> b02.00 | H17: =IF(LEFT(E17,3)="lvl",IF(OR(RIGHT(B17,2)="_1",RIGHT(B17,2)="_2"),MID(B17,14,LEN(B17)-15), MID(B17,14,LEN(B17))),MID(B17,12,LEN(B17))) -> 0100_accrd_intrst_instrmnt
B18: b0200_lvl1_h_0120_otstndng_amnt | C18: 0 | E18: =+MID(B18,7,4) -> lvl1 | F18: =IF(LEFT(E18,3)="lvl",MID(B18,12,1),"f") -> h | G18: =+LEFT(B18,3)&"."&MID(B18,4,2) -> b02.00 | H18: =IF(LEFT(E18,3)="lvl",IF(OR(RIGHT(B18,2)="_1",RIGHT(B18,2)="_2"),MID(B18,14,LEN(B18)-15), MID(B18,14,LEN(B18))),MID(B18,12,LEN(B18))) -> 0120_otstndng_amnt
B19: b0200_lvl1_w_0120_otstndng_amnt | C19: 8 | E19: =+MID(B19,7,4) -> lvl1 | F19: =IF(LEFT(E19,3)="lvl",MID(B19,12,1),"f") -> w | G19: =+LEFT(B19,3)&"."&MID(B19,4,2) -> b02.00 | H19: =IF(LEFT(E19,3)="lvl",IF(OR(RIGHT(B19,2)="_1",RIGHT(B19,2)="_2"),MID(B19,14,LEN(B19)-15), MID(B19,14,LEN(B19))),MID(B19,12,LEN(B19))) -> 0120_otstndng_amnt
B20: b0200_lvl1_h_0130_rlvnt_amnt_wdc | C20: 8 | E20: =+MID(B20,7,4) -> lvl1 | F20: =IF(LEFT(E20,3)="lvl",MID(B20,12,1),"f") -> h | G20: =+LEFT(B20,3)&"."&MID(B20,4,2) -> b02.00 | H20: =IF(LEFT(E20,3)="lvl",IF(OR(RIGHT(B20,2)="_1",RIGHT(B20,2)="_2"),MID(B20,14,LEN(B20)-15), MID(B20,14,LEN(B20))),MID(B20,12,LEN(B20))) -> 0130_rlvnt_amnt_wdc
... B28: b0200_lvl1_h_0210_dt_lgl_fnl_mtrty | C28: 0 | E28: =+MID(B28,7,4) -> lvl1 | F28: =IF(LEFT(E28,3)="lvl",MID(B28,12,1),"f") -> h | G28: =+LEFT(B28,3)&"."&MID(B28,4,2) -> b02.00 | H28: =IF(LEFT(E28,3)="lvl",IF(OR(RIGHT(B28,2)="_1",RIGHT(B28,2)="_2"),MID(B28,14,LEN(B28)-15), MID(B28,14,LEN(B28))),MID(B28,12,LEN(B28))) -> 0210_dt_lgl_fnl_mtrty
B29: b0200_lvl1_h_0220_governing_law | C29: 0 | D29: sem erro'; 'sem erro'; 'sem erro';'sem erro' | E29: =+MID(B29,7,4) -> lvl1 | F29: =IF(LEFT(E29,3)="lvl",MID(B29,12,1),"f") -> h | G29: =+LEFT(B29,3)&"."&MID(B29,4,2) -> b02.00 | H29: =IF(LEFT(E29,3)="lvl",IF(OR(RIGHT(B29,2)="_1",RIGHT(B29,2)="_2"),MID(B29,14,LEN(B29)-15), MID(B29,14,LEN(B29))),MID(B29,12,LEN(B29))) -> 0220_governing_law
B30: b0200_lvl1_h_0250_strctrd_prdct | C30: 0 | E30: =+MID(B30,7,4) -> lvl1 | F30: =IF(LEFT(E30,3)="lvl",MID(B30,12,1),"f") -> h | G30: =+LEFT(B30,3)&"."&MID(B30,4,2) -> b02.00 | H30: =IF(LEFT(E30,3)="lvl",IF(OR(RIGHT(B30,2)="_1",RIGHT(B30,2)="_2"),MID(B30,14,LEN(B30)-15), MID(B30,14,LEN(B30))),MID(B30,12,LEN(B30))) -> 0250_strctrd_prdct
B31: b0200_lvl1_w_0260_grntd_min_amnt_strctrd_prdct | C31: 0 | E31: =+MID(B31,7,4) -> lvl1 | F31: =IF(LEFT(E31,3)="lvl",MID(B31,12,1),"f") -> w | G31: =+LEFT(B31,3)&"."&MID(B31,4,2) -> b02.00 | H31: =IF(LEFT(E31,3)="lvl",IF(OR(RIGHT(B31,2)="_1",RIGHT(B31,2)="_2"),MID(B31,14,LEN(B31)-15), MID(B31,14,LEN(B31))),MID(B31,12,LEN(B31))) -> 0260_grntd_min_amnt_strctrd_prdct
B32: b0200_lvl1_h_0270_fv_amnt_strctrd_prdct | C32: 0 | E32: =+MID(B32,7,4) -> lvl1 | F32: =IF(LEFT(E32,3)="lvl",MID(B32,12,1),"f") -> h | G32: =+LEFT(B32,3)&"."&MID(B32,4,2) -> b02.00 | H32: =IF(LEFT(E32,3)="lvl",IF(OR(RIGHT(B32,2)="_1",RIGHT(B32,2)="_2"),MID(B32,14,LEN(B32)-15), MID(B32,14,LEN(B32))),MID(B32,12,LEN(B32))) -> 0270_fv_amnt_strctrd_prdct
B33: b0200_lvl1_h_0300_amnt_cvrd_elgbl_dpsts | C33: 0 | E33: =+MID(B33,7,4) -> lvl1 | F33: =IF(LEFT(E33,3)="lvl",MID(B33,12,1),"f") -> h | G33: =+LEFT(B33,3)&"."&MID(B33,4,2) -> b02.00 | H33: =IF(LEFT(E33,3)="lvl",IF(OR(RIGHT(B33,2)="_1",RIGHT(B33,2)="_2"),MID(B33,14,LEN(B33)-15), MID(B33,14,LEN(B33))),MID(B33,12,LEN(B33))) -> 0300_amnt_cvrd_elgbl_dpsts
B34: b0200_lvl1_h_0310_flg_clltrl_agrmnts | C34: 0 | E34: =+MID(B34,7,4) -> lvl1 | F34: =IF(LEFT(E34,3)="lvl",MID(B34,12,1),"f") -> h | G34: =+LEFT(B34,3)&"."&MID(B34,4,2) -> b02.00 | H34: =IF(LEFT(E34,3)="lvl",IF(OR(RIGHT(B34,2)="_1",RIGHT(B34,2)="_2"),MID(B34,14,LEN(B34)-15), MID(B34,14,LEN(B34))),MID(B34,12,LEN(B34))) -> 0310_flg_clltrl_agrmnts
B35: b0200_lvl1_h_0320_amnt_clltrl | C35: 0 | E35: =+MID(B35,7,4) -> lvl1 | F35: =IF(LEFT(E35,3)="lvl",MID(B35,12,1),"f") -> h | G35: =+LEFT(B35,3)&"."&MID(B35,4,2) -> b02.00 | H35: =IF(LEFT(E35,3)="lvl",IF(OR(RIGHT(B35,2)="_1",RIGHT(B35,2)="_2"),MID(B35,14,LEN(B35)-15), MID(B35,14,LEN(B35))),MID(B35,12,LEN(B35))) -> 0320_amnt_clltrl
B36: b0200_lvl1_h_0330_amnt_unclltrlzd | C36: 0 | E36: =+MID(B36,7,4) -> lvl1 | F36: =IF(LEFT(E36,3)="lvl",MID(B36,12,1),"f") -> h | G36: =+LEFT(B36,3)&"."&MID(B36,4,2) -> b02.00 | H36: =IF(LEFT(E36,3)="lvl",IF(OR(RIGHT(B36,2)="_1",RIGHT(B36,2)="_2"),MID(B36,14,LEN(B36)-15), MID(B36,14,LEN(B36))),MID(B36,12,LEN(B36))) -> 0330_amnt_unclltrlzd
B37: b0200_lvl1_h_0350_typ_clltrl | C37: 0 | E37: =+MID(B37,7,4) -> lvl1 | F37: =IF(LEFT(E37,3)="lvl",MID(B37,12,1),"f") -> h | G37: =+LEFT(B37,3)&"."&MID(B37,4,2) -> b02.00 | H37: =IF(LEFT(E37,3)="lvl",IF(OR(RIGHT(B37,2)="_1",RIGHT(B37,2)="_2"),MID(B37,14,LEN(B37)-15), MID(B37,14,LEN(B37))),MID(B37,12,LEN(B37))) -> 0350_typ_clltrl
B38: b0200_lvl1_h_0351_typ_clltrl_othr | C38: 0 | E38: =+MID(B38,7,4) -> lvl1 | F38: =IF(LEFT(E38,3)="lvl",MID(B38,12,1),"f") -> h | G38: =+LEFT(B38,3)&"."&MID(B38,4,2) -> b02.00 | H38: =IF(LEFT(E38,3)="lvl",IF(OR(RIGHT(B38,2)="_1",RIGHT(B38,2)="_2"),MID(B38,14,LEN(B38)-15), MID(B38,14,LEN(B38))),MID(B38,12,LEN(B38))) -> 0351_typ_clltrl_othr
B39: b0200_lvl1_h_0370_amnt_scrty_eur | C39: 0 | E39: =+MID(B39,7,4) -> lvl1 | F39: =IF(LEFT(E39,3)="lvl",MID(B39,12,1),"f") -> h | G39: =+LEFT(B39,3)&"."&MID(B39,4,2) -> b02.00 | H39: =IF(LEFT(E39,3)="lvl",IF(OR(RIGHT(B39,2)="_1",RIGHT(B39,2)="_2"),MID(B39,14,LEN(B39)-15), MID(B39,14,LEN(B39))),MID(B39,12,LEN(B39))) -> 0370_amnt_scrty_eur
B40: b0200_lvl1_w_0370_amnt_scrty_eur | C40: 0 | E40: =+MID(B40,7,4) -> lvl1 | F40: =IF(LEFT(E40,3)="lvl",MID(B40,12,1),"f") -> w | G40: =+LEFT(B40,3)&"."&MID(B40,4,2) -> b02.00 | H40: =IF(LEFT(E40,3)="lvl",IF(OR(RIGHT(B40,2)="_1",RIGHT(B40,2)="_2"),MID(B40,14,LEN(B40)-15), MID(B40,14,LEN(B40))),MID(B40,12,LEN(B40))) -> 0370_amnt_scrty_eur
B41: b0200_lvl1_h_0390_nmbr_scrts_not_rprtng_entty | C41: 0 | E41: =+MID(B41,7,4) -> lvl1 | F41: =IF(LEFT(E41,3)="lvl",MID(B41,12,1),"f") -> h | G41: =+LEFT(B41,3)&"."&MID(B41,4,2) -> b02.00 | H41: =IF(LEFT(E41,3)="lvl",IF(OR(RIGHT(B41,2)="_1",RIGHT(B41,2)="_2"),MID(B41,14,LEN(B41)-15), MID(B41,14,LEN(B41))),MID(B41,12,LEN(B41))) -> 0390_nmbr_scrts_not_rprtng_entty
... B97: b0200_frmt_0140_ntr_lblty | C97: 4 | E97: =+MID(B97,7,4) -> frmt | F97: =IF(LEFT(E97,3)="lvl",MID(B97,12,1),"f") -> f | G97: =+LEFT(B97,3)&"."&MID(B97,4,2) -> b02.00 | H97: =IF(LEFT(E97,3)="lvl",IF(OR(RIGHT(B97,2)="_1",RIGHT(B97,2)="_2"),MID(B97,14,LEN(B97)-15), MID(B97,14,LEN(B97))),MID(B97,12,LEN(B97))) -> 0140_ntr_lblty
B98: b0200_frmt_0141_ntr_lblty_othr | C98: 8 | E98: =+MID(B98,7,4) -> frmt | F98: =IF(LEFT(E98,3)="lvl",MID(B98,12,1),"f") -> f | G98: =+LEFT(B98,3)&"."&MID(B98,4,2) -> b02.00 | H98: =IF(LEFT(E98,3)="lvl",IF(OR(RIGHT(B98,2)="_1",RIGHT(B98,2)="_2"),MID(B98,14,LEN(B98)-15), MID(B98,14,LEN(B98))),MID(B98,12,LEN(B98))) -> 0141_ntr_lblty_othr | I98: Valor fixo 'Not applicable' no campo Nature of the liability (if other), uma vez que todos os registos são considerados no campo Nature of the liability como "Title of ownership" ou "Registered Bond", não existinto "other".
B99: b0200_frmt_0150_flg_strctrlly_sbrdntd | C99: 8 | E99: =+MID(B99,7,4) -> frmt | F99: =IF(LEFT(E99,3)="lvl",MID(B99,12,1),"f") -> f | G99: =+LEFT(B99,3)&"."&MID(B99,4,2) -> b02.00 | H99: =IF(LEFT(E99,3)="lvl",IF(OR(RIGHT(B99,2)="_1",RIGHT(B99,2)="_2"),MID(B99,14,LEN(B99)-15), MID(B99,14,LEN(B99))),MID(B99,12,LEN(B99))) -> 0150_flg_strctrlly_sbrdntd | I99: Valor fixo 'Not applicable' de acordo com o Anexo III - considerado não aplicável para non-resolution entities.
B100: b0200_frmt_0160_rank_insolv | C100: 0 | E100: =+MID(B100,7,4) -> frmt | F100: =IF(LEFT(E100,3)="lvl",MID(B100,12,1),"f") -> f | G100: =+LEFT(B100,3)&"."&MID(B100,4,2) -> b02.00 | H100: =IF(LEFT(E100,3)="lvl",IF(OR(RIGHT(B100,2)="_1",RIGHT(B100,2)="_2"),MID(B100,14,LEN(B100)-15), MID(B100,14,LEN(B100))),MID(B100,12,LEN(B100))) -> 0160_rank_insolv
B101: b0200_frmt_0161_cntrctl_sbrdntn | C101: 0 | E101: =+MID(B101,7,4) -> frmt | F101: =IF(LEFT(E101,3)="lvl",MID(B101,12,1),"f") -> f | G101: =+LEFT(B101,3)&"."&MID(B101,4,2) -> b02.00 | H101: =IF(LEFT(E101,3)="lvl",IF(OR(RIGHT(B101,2)="_1",RIGHT(B101,2)="_2"),MID(B101,14,LEN(B101)-15), MID(B101,14,LEN(B101))),MID(B101,12,LEN(B101))) -> 0161_cntrctl_sbrdntn
B102: b0200_frmt_0162_bail_in_cascade | C102: 0 | E102: =+MID(B102,7,4) -> frmt | F102: =IF(LEFT(E102,3)="lvl",MID(B102,12,1),"f") -> f | G102: =+LEFT(B102,3)&"."&MID(B102,4,2) -> b02.00 | H102: =IF(LEFT(E102,3)="lvl",IF(OR(RIGHT(B102,2)="_1",RIGHT(B102,2)="_2"),MID(B102,14,LEN(B102)-15), MID(B102,14,LEN(B102))),MID(B102,12,LEN(B102))) -> 0162_bail_in_cascade
B103: b0200_frmt_0170_dt_incptn | C103: 0 | E103: =+MID(B103,7,4) -> frmt | F103: =IF(LEFT(E103,3)="lvl",MID(B103,12,1),"f") -> f | G103: =+LEFT(B103,3)&"."&MID(B103,4,2) -> b02.00 | H103: =IF(LEFT(E103,3)="lvl",IF(OR(RIGHT(B103,2)="_1",RIGHT(B103,2)="_2"),MID(B103,14,LEN(B103)-15), MID(B103,14,LEN(B103))),MID(B103,12,LEN(B103))) -> 0170_dt_incptn
B104: b0200_frmt_0180_dt_nxt_intrst_pymnt | C104: 8 | E104: =+MID(B104,7,4) -> frmt | F104: =IF(LEFT(E104,3)="lvl",MID(B104,12,1),"f") -> f | G104: =+LEFT(B104,3)&"."&MID(B104,4,2) -> b02.00 | H104: =IF(LEFT(E104,3)="lvl",IF(OR(RIGHT(B104,2)="_1",RIGHT(B104,2)="_2"),MID(B104,14,LEN(B104)-15), MID(B104,14,LEN(B104))),MID(B104,12,LEN(B104))) -> 0180_dt_nxt_intrst_pymnt
B105: b0200_frmt_0190_dt_nxt_rdmptn_pymnt | C105: 0 | E105: =+MID(B105,7,4) -> frmt | F105: =IF(LEFT(E105,3)="lvl",MID(B105,12,1),"f") -> f | G105: =+LEFT(B105,3)&"."&MID(B105,4,2) -> b02.00 | H105: =IF(LEFT(E105,3)="lvl",IF(OR(RIGHT(B105,2)="_1",RIGHT(B105,2)="_2"),MID(B105,14,LEN(B105)-15), MID(B105,14,LEN(B105))),MID(B105,12,LEN(B105))) -> 0190_dt_nxt_rdmptn_pymnt
B106: b0200_frmt_0200_dt_erlst_rdmptn | C106: 0 | E106: =+MID(B106,7,4) -> frmt | F106: =IF(LEFT(E106,3)="lvl",MID(B106,12,1),"f") -> f | G106: =+LEFT(B106,3)&"."&MID(B106,4,2) -> b02.00 | H106: =IF(LEFT(E106,3)="lvl",IF(OR(RIGHT(B106,2)="_1",RIGHT(B106,2)="_2"),MID(B106,14,LEN(B106)-15), MID(B106,14,LEN(B106))),MID(B106,12,LEN(B106))) -> 0200_dt_erlst_rdmptn
B107: b0200_frmt_0210_dt_lgl_fnl_mtrty | C107: 0 | E107: =+MID(B107,7,4) -> frmt | F107: =IF(LEFT(E107,3)="lvl",MID(B107,12,1),"f") -> f | G107: =+LEFT(B107,3)&"."&MID(B107,4,2) -> b02.00 | H107: =IF(LEFT(E107,3)="lvl",IF(OR(RIGHT(B107,2)="_1",RIGHT(B107,2)="_2"),MID(B107,14,LEN(B107)-15), MID(B107,14,LEN(B107))),MID(B107,12,LEN(B107))) -> 0210_dt_lgl_fnl_mtrty
B108: b0200_frmt_0220_governing_law | C108: 0 | E108: =+MID(B108,7,4) -> frmt | F108: =IF(LEFT(E108,3)="lvl",MID(B108,12,1),"f") -> f | G108: =+LEFT(B108,3)&"."&MID(B108,4,2) -> b02.00 | H108: =IF(LEFT(E108,3)="lvl",IF(OR(RIGHT(B108,2)="_1",RIGHT(B108,2)="_2"),MID(B108,14,LEN(B108)-15), MID(B108,14,LEN(B108))),MID(B108,12,LEN(B108))) -> 0220_governing_law
...

Sheet 2.2. Outros
B6: 2.2. Outros Controlos
B8: TABELA | C8: CAMPO | D8: TIPOLOGIA_TESTE | E8: NUM_REG | F8: NUM_REG_DIF | G8: DETALHE | H8: Table | I8: Justificação
B9: BU_LOANTAPE_WORK.OUT_B0200_MAIN_LIABILITIES | C9: 0010_ROW_NMBR | D9: VALIDADE | E9: 8 | F9: 0 | H9: =MID(B9,22,3)&"."&MID(B9,25,2) -> B02.00
B10: BU_LOANTAPE_WORK.OUT_B0200_MAIN_LIABILITIES | C10: 0010_ROW_NMBR | D10: NOT APPLICABLE | E10: 8 | F10: 0 | H10: =MID(B10,22,3)&"."&MID(B10,25,2) -> B02.00
B11: BU_LOANTAPE_WORK.OUT_B0200_MAIN_LIABILITIES | C11: 0020_UNIQ_ID | D11: VALIDADE | E11: 8 | F11: 0 | H11: =MID(B11,22,3)&"."&MID(B11,25,2) -> B02.00
B12: BU_LOANTAPE_WORK.OUT_B0200_MAIN_LIABILITIES | C12: 0020_UNIQ_ID | D12: NOT APPLICABLE | E12: 8 | F12: 0 | H12: =MID(B12,22,3)&"."&MID(B12,25,2) -> B02.00
B13: BU_LOANTAPE_WORK.OUT_B0200_MAIN_LIABILITIES | C13: 0030_UNIQ_ID_KNWN_CNTRPRTY | D13: VALIDADE | E13: 8 | F13: 0 | H13: =MID(B13,22,3)&"."&MID(B13,25,2) -> B02.00
B14: BU_LOANTAPE_WORK.OUT_B0200_MAIN_LIABILITIES | C14: 0030_UNIQ_ID_KNWN_CNTRPRTY | D14: NOT APPLICABLE | E14: 8 | F14: 0 | H14: =MID(B14,22,3)&"."&MID(B14,25,2) -> B02.00
B15: BU_LOANTAPE_WORK.OUT_B0200_MAIN_LIABILITIES | C15: 0040_TYP_UNIQ_ID_KNWN_CNTRPRTY | D15: VALIDADE | E15: 8 | F15: 0 | H15: =MID(B15,22,3)&"."&MID(B15,25,2) -> B02.00
B16: BU_LOANTAPE_WORK.OUT_B0200_MAIN_LIABILITIES | C16: 0040_TYP_UNIQ_ID_KNWN_CNTRPRTY | D16: NOT APPLICABLE | E16: 8 | F16: 0 | H16: =MID(B16,22,3)&"."&MID(B16,25,2) -> B02.00
B17: BU_LOANTAPE_WORK.OUT_B0200_MAIN_LIABILITIES | C17: 0050_ORGNL_AMNT_EUR | D17: VALIDADE | E17: 8 | F17: 0 | H17: =MID(B17,22,3)&"."&MID(B17,25,2) -> B02.00
B18: BU_LOANTAPE_WORK.OUT_B0200_MAIN_LIABILITIES | C18: 0050_ORGNL_AMNT_EUR | D18: NOT APPLICABLE | E18: 8 | F18: 0 | H18: =MID(B18,22,3)&"."&MID(B18,25,2) -> B02.00
B19: BU_LOANTAPE_WORK.OUT_B0200_MAIN_LIABILITIES | C19: 0060_ORGNL_AMNT_FX | D19: VALIDADE | E19: 8 | F19: 0 | H19: =MID(B19,22,3)&"."&MID(B19,25,2) -> B02.00 | I19: TESTE
B20: BU_LOANTAPE_WORK.OUT_B0200_MAIN_LIABILITIES | C20: 0060_ORGNL_AMNT_FX | D20: NOT APPLICABLE | E20: 8 | F20: 0 | H20: =MID(B20,22,3)&"."&MID(B20,25,2) -> B02.00
B21: BU_LOANTAPE_WORK.OUT_B0200_MAIN_LIABILITIES | C21: 0070_CNTRCT_CRRNCY | D21: VALIDADE | E21: 8 | F21: 0 | H21: =MID(B21,22,3)&"."&MID(B21,25,2) -> B02.00
B22: BU_LOANTAPE_WORK.OUT_B0200_MAIN_LIABILITIES | C22: 0070_CNTRCT_CRRNCY | D22: NOT APPLICABLE | E22: 8 | F22: 0 | H22: =MID(B22,22,3)&"."&MID(B22,25,2) -> B02.00
B23: BU_LOANTAPE_WORK.OUT_B0200_MAIN_LIABILITIES | C23: 0100_ACCRD_INTRST_INSTRMNT | D23: VALIDADE | E23: 8 | F23: 0 | H23: =MID(B23,22,3)&"."&MID(B23,25,2) -> B02.00
B24: BU_LOANTAPE_WORK.OUT_B0200_MAIN_LIABILITIES | C24: 0100_ACCRD_INTRST_INSTRMNT | D24: NOT APPLICABLE | E24: 8 | F24: 0 | H24: =MID(B24,22,3)&"."&MID(B24,25,2) -> B02.00
B25: BU_LOANTAPE_WORK.OUT_B0200_MAIN_LIABILITIES | C25: 0110_APPLCBL_FEES_CHARGES | D25: VALIDADE | E25: 8 | F25: 0 | H25: =MID(B25,22,3)&"."&MID(B25,25,2) -> B02.00
B26: BU_LOANTAPE_WORK.OUT_B0200_MAIN_LIABILITIES | C26: 0110_APPLCBL_FEES_CHARGES | D26: NOT APPLICABLE | E26: 8 | F26: 0 | H26: =MID(B26,22,3)&"."&MID(B26,25,2) -> B02.00
B27: BU_LOANTAPE_WORK.OUT_B0200_MAIN_LIABILITIES | C27: 0140_NTR_LBLTY | D27: VALIDADE | E27: 8 | F27: 0 | H27: =MID(B27,22,3)&"."&MID(B27,25,2) -> B02.00
B28: BU_LOANTAPE_WORK.OUT_B0200_MAIN_LIABILITIES | C28: 0140_NTR_LBLTY | D28: NOT APPLICABLE | E28: 8 | F28: 0 | H28: =MID(B28,22,3)&"."&MID(B28,25,2) -> B02.00
B29: BU_LOANTAPE_WORK.OUT_B0200_MAIN_LIABILITIES | C29: 0141_NTR_LBLTY_OTHR | D29: VALIDADE | E29: 8 | F29: 0 | H29: =MID(B29,22,3)&"."&MID(B29,25,2) -> B02.00
B30: BU_LOANTAPE_WORK.OUT_B0200_MAIN_LIABILITIES | C30: 0141_NTR_LBLTY_OTHR | D30: NOT APPLICABLE | E30: 8 | F30: 8 | H30: =MID(B30,22,3)&"."&MID(B30,25,2) -> B02.00
B31: BU_LOANTAPE_WORK.OUT_B0200_MAIN_LIABILITIES | C31: 0150_FLG_STRCTRLLY_SBRDNTD | D31: VALIDADE | E31: 8 | F31: 0 | H31: =MID(B31,22,3)&"."&MID(B31,25,2) -> B02.00
... B33: BU_LOANTAPE_WORK.OUT_B0200_MAIN_LIABILITIES | C33: 0160_RANK_INSOLV | D33: VALIDADE | E33: 8 | F33: 0 | H33: =MID(B33,22,3)&"."&MID(B33,25,2) -> B02.00
B34: BU_LOANTAPE_WORK.OUT_B0200_MAIN_LIABILITIES | C34: 0160_RANK_INSOLV | D34: NOT APPLICABLE | E34: 8 | F34: 0 | H34: =MID(B34,22,3)&"."&MID(B34,25,2) -> B02.00 | I34: TESTE
B35: BU_LOANTAPE_WORK.OUT_B0200_MAIN_LIABILITIES | C35: 0161_CNTRCTL_SBRDNTN | D35: VALIDADE | E35: 8 | F35: 0 | H35: =MID(B35,22,3)&"."&MID(B35,25,2) -> B02.00
B36: BU_LOANTAPE_WORK.OUT_B0200_MAIN_LIABILITIES | C36: 0161_CNTRCTL_SBRDNTN | D36: NOT APPLICABLE | E36: 8 | F36: 0 | H36: =MID(B36,22,3)&"."&MID(B36,25,2) -> B02.00
B37: BU_LOANTAPE_WORK.OUT_B0200_MAIN_LIABILITIES | C37: 0162_BAIL_IN_CASCADE | D37: VALIDADE | E37: 8 | F37: 0 | H37: =MID(B37,22,3)&"."&MID(B37,25,2) -> B02.00
B38: BU_LOANTAPE_WORK.OUT_B0200_MAIN_LIABILITIES | C38: 0162_BAIL_IN_CASCADE | D38: NOT APPLICABLE | E38: 8 | F38: 0 | H38: =MID(B38,22,3)&"."&MID(B38,25,2) -> B02.00
B39: BU_LOANTAPE_WORK.OUT_B0200_MAIN_LIABILITIES | C39: 0170_DT_INCPTN | D39: VALIDADE | E39: 8 | F39: 0 | H39: =MID(B39,22,3)&"."&MID(B39,25,2) -> B02.00
B40: BU_LOANTAPE_WORK.OUT_B0200_MAIN_LIABILITIES | C40: 0170_DT_INCPTN | D40: NOT APPLICABLE | E40: 8 | F40: 0 | H40: =MID(B40,22,3)&"."&MID(B40,25,2) -> B02.00
B41: BU_LOANTAPE_WORK.OUT_B0200_MAIN_LIABILITIES | C41: 0180_DT_NXT_INTRST_PYMNT | D41: VALIDADE | E41: 8 | F41: 8 | H41: =MID(B41,22,3)&"."&MID(B41,25,2) -> B02.00
B42: BU_LOANTAPE_WORK.OUT_B0200_MAIN_LIABILITIES | C42: 0180_DT_NXT_INTRST_PYMNT | D42: NOT APPLICABLE | E42: 8 | F42: 0 | H42: =MID(B42,22,3)&"."&MID(B42,25,2) -> B02.00
B43: BU_LOANTAPE_WORK.OUT_B0200_MAIN_LIABILITIES | C43: 0190_DT_NXT_RDMPTN_PYMNT | D43: VALIDADE | E43: 8 | F43: 0 | H43: =MID(B43,22,3)&"."&MID(B43,25,2) -> B02.00
B44: BU_LOANTAPE_WORK.OUT_B0200_MAIN_LIABILITIES | C44: 0190_DT_NXT_RDMPTN_PYMNT | D44: NOT APPLICABLE | E44: 8 | F44: 3 | H44: =MID(B44,22,3)&"."&MID(B44,25,2) -> B02.00
B45: BU_LOANTAPE_WORK.OUT_B0200_MAIN_LIABILITIES | C45: 0200_DT_ERLST_RDMPTN | D45: VALIDADE | E45: 8 | F45: 0 | H45: =MID(B45,22,3)&"."&MID(B45,25,2) -> B02.00
B46: BU_LOANTAPE_WORK.OUT_B0200_MAIN_LIABILITIES | C46: 0200_DT_ERLST_RDMPTN | D46: NOT APPLICABLE | E46: 8 | F46: 8 | H46: =MID(B46,22,3)&"."&MID(B46,25,2) -> B02.00
... B127: BU_LOANTAPE_WORK.OUT_B0200_MAIN_LIABILITIES | C127: 0540_ELGBL_AMNT_OWN_FNDS_IND_LVL | D127: VALIDADE | E127: 8 | F127: 0 | H127: =MID(B127,22,3)&"."&MID(B127,25,2) -> B02.00
...

Sheet Query1
A2: ref_date | B2: cod_kpi | C2: tipologia_teste | D2: descrição | E2: tabela | F2: campo | G2: num_reg | H2: num_reg_dif | I2: detalhe
A3: 2025-10-31 | B3: DUP_B0200_C0020 | C3: DUPLICADOS | D3: Validar a inexistência de registos duplicados | E3: BU_LOANTAPE_WORK.OUT_B0200_MAIN_LIABILITIES | F3: 0020_UNIQ_ID | G3: 8 | H3: 0
A4: 2025-10-31 | B4: DUP_B0500_C0020 | C4: DUPLICADOS | D4: Validar a inexistência de registos duplicados | E4: BU_LOANTAPE_WORK.OUT_B0500_GUARANTEES | F4: 0020_UNIQ_ID_GUARANTEE | G4: 4730 | H4: 0
A5: 2025-10-31 | B5: DUP_B9000_C0020_C0070 | C5: DUPLICADOS | D5: Validar a inexistência de registos duplicados | E5: BU_LOANTAPE_WORK.OUT_B9000_COUNTERPARTIES | F5: 0020_UNIQ_ID_KNWN_CNTRPRTY, 0070_CNTRPRTY_ID | G5: 4740 | H5: 0

Sheet 2.2. Outros - TESTE
B6: 2.2. Outros Controlos
B8: TABELA | C8: CAMPO | D8: TIPOLOGIA_TESTE | E8: NUM_REG | F8: NUM_REG_DIF | G8: DETALHE | H8: Table | I8: Justificação

Sheet 2.3. Processo
B6: 2.3. Controlos de Processo (HUE vs CSV)
