Workbook

Sheet 0. Instruções
B6: 0. Instruções
B8: Projeto | D8: Testes GD & Pilar 3
B9: Âmbito | D9: Análise dos campo da Loan Tape Pilar III
B11: Para a validação dos campos da Loan Tape Pilar III é necessário percorrer os seguintes steps:
B14: 1. Atualizar o script de simulação com o campo em análise.
B15: 1.1. Verificar a especificação do campo em análise. Se aplicável, verificar se é necessário reportar valor para ajustes.
B16: 1.2. Montar a simulação do campo tendo atenção aos seguintes pormenores:
B17: a) Não vamos fazer JOIN com a tabela de parametrização (LT803). Em alternativa, montamos um CASE WHEN ou importamos a parametrização.
B18: b) Para operações de ajustes verificar se o campo deve reportar valor.
B19: c) Se for necessário aplicar algum filtro (ou tratamento) que não está na especificação deixar um comentário no código.
B20: d) Garantir que não existem duplicados e deixar no código o número de registos de cada LEFT JOIN.
B21: 2. Executar no HUE (em HIVE) o CREATE TABLE do script de simulação.
B22: 3. Executar no HUE o script de controlo de universo.
B23: a) O número de registos em comum tem de ser igual ao número de registos do teste de coerência. Caso tenhamos registos que não são comuns é necessário ver exemplos para ver o que está a acontecer.
B24: 4. Verificar com IT o nome da tabela a testar e filtros. Caso seja necessário, atualizar as tabelas infra:
C26: Nome da Tabela | D26: Tabela Loan Tape Pilar 3 | E26: Tabela Simulada | F26: Chave 1 | G26: Chave 2
C27: Entity | D27: lt003_entity | E27: LT003_ENTTY_P3_NOV24 | F27: entty_id
C28: Instrument | D28: lt002_instrument | E28: LT002_INSTRUMENT_P3_NOV24 | F28: instrmnt_id
C29: Protection | D29: lt004_protection | E29: LT004_PROTECTION_P3_NOV24 | F29: prtctn_id
C30: Instr_Ent | D30: lt005_instr_ent | F30: instrmnt_id | G30: entty_id
C31: Instr_Prot | D31: lt006_instr_prot | F31: instrmnt_id | G31: prtctn_id
C33: Schema Loan Tape Pilar 3 | D33: bu_loantape_work
C34: Schema Simulada | D34: bu_loantape_work
C35: nome_perimetro | D35: Individual Corporativo
C36: segmento | D36: ESTR
C37: ambito (Pilar 3) | D37: PILAR3
C38: ambito (PM) | D38: PM
C39: entidade | D39: 00100
C40: Filtro Loan Tape Pilar 3 | D40: =+"ref_date='${ref_date}'"&" AND "&C35&"='"&D35&"' AND "&C36&"='"&D36&"' AND ambito='"&D37&"'" -> ref_date='${ref_date}' AND nome_perimetro='Individual Corporativo' AND segmento='ESTR' AND ambito='PILAR3'
B42: 5. Executar no HUE a bateria de testes da sheet 2. Script para o campo em análise
B43: a) Analisar resultados. Caso no teste de coerência conste diferenças é necessário ver exemplos. Deixo abaixo uma query de exemplo:
C45: SELECT *
C46: FROM
C47: (SELECT instrmnt_id,
C48: LNS_CLLTRLZD_CLSSFCTN
C49: FROM BU_LOANTAPE_WORK.LT002_INSTRUMENT
C50: WHERE ref_date='${ref_date}'
C51: AND nome_perimetro='Individual Corporativo'
C52: AND segmento='ESTR'
C53: AND ambito='PILAR3')X
...

Sheet 1. Status
H6: 1. Status dos Testes
H8: REF_DATE | I8: 45596
B9: Auxiliar
B10: Coerência | C10: Validade | D10: Caracteres Especiais | E10: Missings | F10: Not applicable | H10: Tabela | I10: Campo | J10: Testes Corridos (#) | K10: Número de Registos ID1. (#) | L10: ID Exec. 1. | M10: 1. Erros de Coerência (#) | N10: Número de Registos ID2&9 (#) | O10: ID Exec. 2 | P10: 2. Erros de Valores Admitidos (#) | Q10: ID Exec. 3. | R10: 3. Erros de Caract. Especiais (#) | S10: ID Exec. 4. | T10: 4. Registos com Missing (#) | U10: ID Exec. 5. | V10: 5. Registos com N/A (#) | W10: 6. Valor Mínimo | X10: 7. Valor Máximo | Y10: Comentário | Z10: Status
A11: =+H11&I11&$I$8 -> ENTITYNACE_ESG45596 | B11: {=+MAX(IF('ID1&5'!A:A='1. Status'!A11&'1. Status'!$B$10,'ID1&5'!K:K))} -> 0 | C11: {=+MAX(IF('ID1&5'!A:A='1. Status'!A11&'1. Status'!$C$10,'ID1&5'!K:K))} -> 0 | D11: {=+MAX(IF('ID1&5'!A:A='1. Status'!A11&'1. Status'!$D$10,'ID1&5'!K:K))} -> 0 | E11: {=+MAX(IF('ID1&5'!A:A='1. Status'!A11&'1. Status'!$E$10,'ID1&5'!K:K))} -> 0 | F11: {=+MAX(IF('ID1&5'!A:A='1. Status'!A11&'1. Status'!$F$10,'ID1&5'!K:K))} -> 0 | H11: ENTITY | I11: NACE_ESG | J11: =+COUNTIF('ID1&5'!G:G,'1. Status'!I11) -> 5 | K11: =+IFERROR(VLOOKUP(CONCATENATE(A11,$B$10,B11),'ID1&5'!B:J,8,FALSE),"-") -> - | L11: =+IFERROR(VLOOKUP(B11,'ID1&5'!K:L,2,FALSE),"-") -> - | M11: =+IFERROR(VLOOKUP(CONCATENATE(A11,$B$10,B11),'ID1&5'!B:J,9,FALSE),"-") -> - | N11: =+IFERROR(VLOOKUP(CONCATENATE(A11,$C$10,C11),'ID1&5'!B:J,8,FALSE),"-") -> - | O11: =+IFERROR(VLOOKUP(C11,'ID1&5'!K:L,2,FALSE),"-") -> - | P11: =+IFERROR(VLOOKUP(CONCATENATE(A11,$C$10,C11),'ID1&5'!B:J,9,FALSE),"-") -> - | Q11: =+IFERROR(VLOOKUP(D11,'ID1&5'!K:L,2,FALSE),"-") -> - | R11: =+IFERROR(VLOOKUP(CONCATENATE(A11,$D$10,D11),'ID1&5'!B:J,9,FALSE),"-") -> - | S11: =+IFERROR(VLOOKUP(E11,'ID1&5'!K:L,2,FALSE),"-") -> - | T11: =+IFERROR(VLOOKUP(CONCATENATE(A11,$E$10,E11),'ID1&5'!B:J,9,FALSE),"-") -> - | U11: =+IFERROR(VLOOKUP(F11,'ID1&5'!K:L,2,FALSE),"-") -> - | V11: =+IFERROR(VLOOKUP(CONCATENATE(A11,$F$10,F11),'ID1&5'!B:J,9,FALSE),"-") -> - | W11: =+IFERROR(VLOOKUP(A11,'ID6&7'!A:I,9,FALSE),"-") -> - | X11: =+IFERROR(VLOOKUP(A11,'ID6&7'!A:J,10,FALSE),"-") -> - | Z11: =+IF(J11=0,"Por iniciar",IF(OR(K11="-",M11="-",P11="-",R11="-",T11="-",V11="-"),"Em testes",IF(AND(M11=0,P11=0,R11=0,T11<>K11,V11<>K11),"OK","NOK"))) -> Em testes
A12: =+H12&I12&$I$8 -> ENTITYTXNMY_ELGBL_CAPEX_CCM45596 | B12: {=+MAX(IF('ID1&5'!A:A='1. Status'!A12&'1. Status'!$B$10,'ID1&5'!K:K))} -> 9 | C12: {=+MAX(IF('ID1&5'!A:A='1. Status'!A12&'1. Status'!$C$10,'ID1&5'!K:K))} -> 9 | D12: {=+MAX(IF('ID1&5'!A:A='1. Status'!A12&'1. Status'!$D$10,'ID1&5'!K:K))} -> 9 | E12: {=+MAX(IF('ID1&5'!A:A='1. Status'!A12&'1. Status'!$E$10,'ID1&5'!K:K))} -> 9 | F12: {=+MAX(IF('ID1&5'!A:A='1. Status'!A12&'1. Status'!$F$10,'ID1&5'!K:K))} -> 9 | H12: ENTITY | I12: TXNMY_ELGBL_CAPEX_CCM | J12: =+COUNTIF('ID1&5'!G:G,'1. Status'!I12) -> 5 | K12: =+IFERROR(VLOOKUP(CONCATENATE(A12,$B$10,B12),'ID1&5'!B:J,8,FALSE),"-") -> 1117455 | L12: =+IFERROR(VLOOKUP(B12,'ID1&5'!K:L,2,FALSE),"-") -> 2024-12-10 12:15:23.230637000 | M12: =+IFERROR(VLOOKUP(CONCATENATE(A12,$B$10,B12),'ID1&5'!B:J,9,FALSE),"-") -> 0 | N12: =+IFERROR(VLOOKUP(CONCATENATE(A12,$C$10,C12),'ID1&5'!B:J,8,FALSE),"-") -> 1117487 | O12: =+IFERROR(VLOOKUP(C12,'ID1&5'!K:L,2,FALSE),"-") -> 2024-12-10 12:15:23.230637000 | P12: =+IFERROR(VLOOKUP(CONCATENATE(A12,$C$10,C12),'ID1&5'!B:J,9,FALSE),"-") -> 0 | Q12: =+IFERROR(VLOOKUP(D12,'ID1&5'!K:L,2,FALSE),"-") -> 2024-12-10 12:15:23.230637000 | R12: =+IFERROR(VLOOKUP(CONCATENATE(A12,$D$10,D12),'ID1&5'!B:J,9,FALSE),"-") -> 0 | S12: =+IFERROR(VLOOKUP(E12,'ID1&5'!K:L,2,FALSE),"-") -> 2024-12-10 12:15:23.230637000 | T12: =+IFERROR(VLOOKUP(CONCATENATE(A12,$E$10,E12),'ID1&5'!B:J,9,FALSE),"-") -> 79452 | U12: =+IFERROR(VLOOKUP(F12,'ID1&5'!K:L,2,FALSE),"-") -> 2024-12-10 12:15:23.230637000 | V12: =+IFERROR(VLOOKUP(CONCATENATE(A12,$F$10,F12),'ID1&5'!B:J,9,FALSE),"-") -> 1037626 | W12: =+IFERROR(VLOOKUP(A12,'ID6&7'!A:I,9,FALSE),"-") -> 0.000000 | X12: =+IFERROR(VLOOKUP(A12,'ID6&7'!A:J,10,FALSE),"-") -> 100.000000 | Z12: =+IF(J12=0,"Por iniciar",IF(OR(K12="-",M12="-",P12="-",R12="-",T12="-",V12="-"),"Em testes",IF(AND(M12=0,P12=0,R12=0,T12<>K12,V12<>K12),"OK","NOK"))) -> OK
A13: =+H13&I13&$I$8 -> ENTITYTXNMY_ELGBL_TRNVR_CCM45596 | B13: {=+MAX(IF('ID1&5'!A:A='1. Status'!A13&'1. Status'!$B$10,'ID1&5'!K:K))} -> 9 | C13: {=+MAX(IF('ID1&5'!A:A='1. Status'!A13&'1. Status'!$C$10,'ID1&5'!K:K))} -> 9 | D13: {=+MAX(IF('ID1&5'!A:A='1. Status'!A13&'1. Status'!$D$10,'ID1&5'!K:K))} -> 9 | E13: {=+MAX(IF('ID1&5'!A:A='1. Status'!A13&'1. Status'!$E$10,'ID1&5'!K:K))} -> 9 | F13: {=+MAX(IF('ID1&5'!A:A='1. Status'!A13&'1. Status'!$F$10,'ID1&5'!K:K))} -> 9 | H13: ENTITY | I13: TXNMY_ELGBL_TRNVR_CCM | J13: =+COUNTIF('ID1&5'!G:G,'1. Status'!I13) -> 5 | K13: =+IFERROR(VLOOKUP(CONCATENATE(A13,$B$10,B13),'ID1&5'!B:J,8,FALSE),"-") -> 1117455 | L13: =+IFERROR(VLOOKUP(B13,'ID1&5'!K:L,2,FALSE),"-") -> 2024-12-10 12:15:23.230637000 | M13: =+IFERROR(VLOOKUP(CONCATENATE(A13,$B$10,B13),'ID1&5'!B:J,9,FALSE),"-") -> 2 | N13: =+IFERROR(VLOOKUP(CONCATENATE(A13,$C$10,C13),'ID1&5'!B:J,8,FALSE),"-") -> 1117487 | O13: =+IFERROR(VLOOKUP(C13,'ID1&5'!K:L,2,FALSE),"-") -> 2024-12-10 12:15:23.230637000 | P13: =+IFERROR(VLOOKUP(CONCATENATE(A13,$C$10,C13),'ID1&5'!B:J,9,FALSE),"-") -> 0 | Q13: =+IFERROR(VLOOKUP(D13,'ID1&5'!K:L,2,FALSE),"-") -> 2024-12-10 12:15:23.230637000 | R13: =+IFERROR(VLOOKUP(CONCATENATE(A13,$D$10,D13),'ID1&5'!B:J,9,FALSE),"-") -> 0 | S13: =+IFERROR(VLOOKUP(E13,'ID1&5'!K:L,2,FALSE),"-") -> 2024-12-10 12:15:23.230637000 | T13: =+IFERROR(VLOOKUP(CONCATENATE(A13,$E$10,E13),'ID1&5'!B:J,9,FALSE),"-") -> 79311 | U13: =+IFERROR(VLOOKUP(F13,'ID1&5'!K:L,2,FALSE),"-") -> 2024-12-10 12:15:23.230637000 | V13: =+IFERROR(VLOOKUP(CONCATENATE(A13,$F$10,F13),'ID1&5'!B:J,9,FALSE),"-") -> 1037626 | W13: =+IFERROR(VLOOKUP(A13,'ID6&7'!A:I,9,FALSE),"-") -> 0.000000 | X13: =+IFERROR(VLOOKUP(A13,'ID6&7'!A:J,10,FALSE),"-") -> 100.000000 | Y13: 29/11: Estes 2 casos é devido ao arredondamento a 6º casa decimal (7400296972 e 8007799082) | Z13: OK
A14: =+H14&I14&$I$8 -> ENTITYTXNMY_ELGBL_CAPEX_CCA45596 | B14: {=+MAX(IF('ID1&5'!A:A='1. Status'!A14&'1. Status'!$B$10,'ID1&5'!K:K))} -> 9 | C14: {=+MAX(IF('ID1&5'!A:A='1. Status'!A14&'1. Status'!$C$10,'ID1&5'!K:K))} -> 9 | D14: {=+MAX(IF('ID1&5'!A:A='1. Status'!A14&'1. Status'!$D$10,'ID1&5'!K:K))} -> 9 | E14: {=+MAX(IF('ID1&5'!A:A='1. Status'!A14&'1. Status'!$E$10,'ID1&5'!K:K))} -> 9 | F14: {=+MAX(IF('ID1&5'!A:A='1. Status'!A14&'1. Status'!$F$10,'ID1&5'!K:K))} -> 9 | H14: ENTITY | I14: TXNMY_ELGBL_CAPEX_CCA | J14: =+COUNTIF('ID1&5'!G:G,'1. Status'!I14) -> 5 | K14: =+IFERROR(VLOOKUP(CONCATENATE(A14,$B$10,B14),'ID1&5'!B:J,8,FALSE),"-") -> 1117455 | L14: =+IFERROR(VLOOKUP(B14,'ID1&5'!K:L,2,FALSE),"-") -> 2024-12-10 12:15:23.230637000 | M14: =+IFERROR(VLOOKUP(CONCATENATE(A14,$B$10,B14),'ID1&5'!B:J,9,FALSE),"-") -> 0 | N14: =+IFERROR(VLOOKUP(CONCATENATE(A14,$C$10,C14),'ID1&5'!B:J,8,FALSE),"-") -> 1117487 | O14: =+IFERROR(VLOOKUP(C14,'ID1&5'!K:L,2,FALSE),"-") -> 2024-12-10 12:15:23.230637000 | P14: =+IFERROR(VLOOKUP(CONCATENATE(A14,$C$10,C14),'ID1&5'!B:J,9,FALSE),"-") -> 0 | Q14: =+IFERROR(VLOOKUP(D14,'ID1&5'!K:L,2,FALSE),"-") -> 2024-12-10 12:15:23.230637000 | R14: =+IFERROR(VLOOKUP(CONCATENATE(A14,$D$10,D14),'ID1&5'!B:J,9,FALSE),"-") -> 0 | S14: =+IFERROR(VLOOKUP(E14,'ID1&5'!K:L,2,FALSE),"-") -> 2024-12-10 12:15:23.230637000 | T14: =+IFERROR(VLOOKUP(CONCATENATE(A14,$E$10,E14),'ID1&5'!B:J,9,FALSE),"-") -> 79452 | U14: =+IFERROR(VLOOKUP(F14,'ID1&5'!K:L,2,FALSE),"-") -> 2024-12-10 12:15:23.230637000 | V14: =+IFERROR(VLOOKUP(CONCATENATE(A14,$F$10,F14),'ID1&5'!B:J,9,FALSE),"-") -> 1037626 | W14: =+IFERROR(VLOOKUP(A14,'ID6&7'!A:I,9,FALSE),"-") -> 0.000000 | X14: =+IFERROR(VLOOKUP(A14,'ID6&7'!A:J,10,FALSE),"-") -> 78.600000 | Z14: =+IF(J14=0,"Por iniciar",IF(OR(K14="-",M14="-",P14="-",R14="-",T14="-",V14="-"),"Em testes",IF(AND(M14=0,P14=0,R14=0,T14<>K14,V14<>K14),"OK","NOK"))) -> OK
A15: =+H15&I15&$I$8 -> ENTITYTXNMY_ELGBL_TRNVR_CCA45596 | B15: {=+MAX(IF('ID1&5'!A:A='1. Status'!A15&'1. Status'!$B$10,'ID1&5'!K:K))} -> 9 | C15: {=+MAX(IF('ID1&5'!A:A='1. Status'!A15&'1. Status'!$C$10,'ID1&5'!K:K))} -> 9 | D15: {=+MAX(IF('ID1&5'!A:A='1. Status'!A15&'1. Status'!$D$10,'ID1&5'!K:K))} -> 9 | E15: {=+MAX(IF('ID1&5'!A:A='1. Status'!A15&'1. Status'!$E$10,'ID1&5'!K:K))} -> 9 | F15: {=+MAX(IF('ID1&5'!A:A='1. Status'!A15&'1. Status'!$F$10,'ID1&5'!K:K))} -> 9 | H15: ENTITY | I15: TXNMY_ELGBL_TRNVR_CCA | J15: =+COUNTIF('ID1&5'!G:G,'1. Status'!I15) -> 5 | K15: =+IFERROR(VLOOKUP(CONCATENATE(A15,$B$10,B15),'ID1&5'!B:J,8,FALSE),"-") -> 1117455 | L15: =+IFERROR(VLOOKUP(B15,'ID1&5'!K:L,2,FALSE),"-") -> 2024-12-10 12:15:23.230637000 | M15: =+IFERROR(VLOOKUP(CONCATENATE(A15,$B$10,B15),'ID1&5'!B:J,9,FALSE),"-") -> 0 | N15: =+IFERROR(VLOOKUP(CONCATENATE(A15,$C$10,C15),'ID1&5'!B:J,8,FALSE),"-") -> 1117487 | O15: =+IFERROR(VLOOKUP(C15,'ID1&5'!K:L,2,FALSE),"-") -> 2024-12-10 12:15:23.230637000 | P15: =+IFERROR(VLOOKUP(CONCATENATE(A15,$C$10,C15),'ID1&5'!B:J,9,FALSE),"-") -> 0 | Q15: =+IFERROR(VLOOKUP(D15,'ID1&5'!K:L,2,FALSE),"-") -> 2024-12-10 12:15:23.230637000 | R15: =+IFERROR(VLOOKUP(CONCATENATE(A15,$D$10,D15),'ID1&5'!B:J,9,FALSE),"-") -> 0 | S15: =+IFERROR(VLOOKUP(E15,'ID1&5'!K:L,2,FALSE),"-") -> 2024-12-10 12:15:23.230637000 | T15: =+IFERROR(VLOOKUP(CONCATENATE(A15,$E$10,E15),'ID1&5'!B:J,9,FALSE),"-") -> 79311 | U15: =+IFERROR(VLOOKUP(F15,'ID1&5'!K:L,2,FALSE),"-") -> 2024-12-10 12:15:23.230637000 | V15: =+IFERROR(VLOOKUP(CONCATENATE(A15,$F$10,F15),'ID1&5'!B:J,9,FALSE),"-") -> 1037626 | W15: =+IFERROR(VLOOKUP(A15,'ID6&7'!A:I,9,FALSE),"-") -> 0.000000 | X15: =+IFERROR(VLOOKUP(A15,'ID6&7'!A:J,10,FALSE),"-") -> 100.000000 | Z15: =+IF(J15=0,"Por iniciar",IF(OR(K15="-",M15="-",P15="-",R15="-",T15="-",V15="-"),"Em testes",IF(AND(M15=0,P15=0,R15=0,T15<>K15,V15<>K15),"OK","NOK"))) -> OK
A16: =+H16&I16&$I$8 -> ENTITYENBLNG_CAPEX_CCM45596 | B16: {=+MAX(IF('ID1&5'!A:A='1. Status'!A16&'1. Status'!$B$10,'ID1&5'!K:K))} -> 9 | C16: {=+MAX(IF('ID1&5'!A:A='1. Status'!A16&'1. Status'!$C$10,'ID1&5'!K:K))} -> 9 | D16: {=+MAX(IF('ID1&5'!A:A='1. Status'!A16&'1. Status'!$D$10,'ID1&5'!K:K))} -> 9 | E16: {=+MAX(IF('ID1&5'!A:A='1. Status'!A16&'1. Status'!$E$10,'ID1&5'!K:K))} -> 9 | F16: {=+MAX(IF('ID1&5'!A:A='1. Status'!A16&'1. Status'!$F$10,'ID1&5'!K:K))} -> 9 | H16: ENTITY | I16: ENBLNG_CAPEX_CCM | J16: =+COUNTIF('ID1&5'!G:G,'1. Status'!I16) -> 5 | K16: =+IFERROR(VLOOKUP(CONCATENATE(A16,$B$10,B16),'ID1&5'!B:J,8,FALSE),"-") -> 1117455 | L16: =+IFERROR(VLOOKUP(B16,'ID1&5'!K:L,2,FALSE),"-") -> 2024-12-10 12:15:23.230637000 | M16: =+IFERROR(VLOOKUP(CONCATENATE(A16,$B$10,B16),'ID1&5'!B:J,9,FALSE),"-") -> 0 | N16: =+IFERROR(VLOOKUP(CONCATENATE(A16,$C$10,C16),'ID1&5'!B:J,8,FALSE),"-") -> 1117487 | O16: =+IFERROR(VLOOKUP(C16,'ID1&5'!K:L,2,FALSE),"-") -> 2024-12-10 12:15:23.230637000 | P16: =+IFERROR(VLOOKUP(CONCATENATE(A16,$C$10,C16),'ID1&5'!B:J,9,FALSE),"-") -> 0 | Q16: =+IFERROR(VLOOKUP(D16,'ID1&5'!K:L,2,FALSE),"-") -> 2024-12-10 12:15:23.230637000 | R16: =+IFERROR(VLOOKUP(CONCATENATE(A16,$D$10,D16),'ID1&5'!B:J,9,FALSE),"-") -> 0 | S16: =+IFERROR(VLOOKUP(E16,'ID1&5'!K:L,2,FALSE),"-") -> 2024-12-10 12:15:23.230637000 | T16: =+IFERROR(VLOOKUP(CONCATENATE(A16,$E$10,E16),'ID1&5'!B:J,9,FALSE),"-") -> 79452 | U16: =+IFERROR(VLOOKUP(F16,'ID1&5'!K:L,2,FALSE),"-") -> 2024-12-10 12:15:23.230637000 | V16: =+IFERROR(VLOOKUP(CONCATENATE(A16,$F$10,F16),'ID1&5'!B:J,9,FALSE),"-") -> 1037626 | W16: =+IFERROR(VLOOKUP(A16,'ID6&7'!A:I,9,FALSE),"-") -> 0.000000 | X16: =+IFERROR(VLOOKUP(A16,'ID6&7'!A:J,10,FALSE),"-") -> 78.400000 | Z16: =+IF(J16=0,"Por iniciar",IF(OR(K16="-",M16="-",P16="-",R16="-",T16="-",V16="-"),"Em testes",IF(AND(M16=0,P16=0,R16=0,T16<>K16,V16<>K16),"OK","NOK"))) -> OK
A17: =+H17&I17&$I$8 -> ENTITYENBLNG_CAPEX_CCA45596 | B17: {=+MAX(IF('ID1&5'!A:A='1. Status'!A17&'1. Status'!$B$10,'ID1&5'!K:K))} -> 9 | C17: {=+MAX(IF('ID1&5'!A:A='1. Status'!A17&'1. Status'!$C$10,'ID1&5'!K:K))} -> 9 | D17: {=+MAX(IF('ID1&5'!A:A='1. Status'!A17&'1. Status'!$D$10,'ID1&5'!K:K))} -> 9 | E17: {=+MAX(IF('ID1&5'!A:A='1. Status'!A17&'1. Status'!$E$10,'ID1&5'!K:K))} -> 9 | F17: {=+MAX(IF('ID1&5'!A:A='1. Status'!A17&'1. Status'!$F$10,'ID1&5'!K:K))} -> 9 | H17: ENTITY | I17: ENBLNG_CAPEX_CCA | J17: =+COUNTIF('ID1&5'!G:G,'1. Status'!I17) -> 5 | K17: =+IFERROR(VLOOKUP(CONCATENATE(A17,$B$10,B17),'ID1&5'!B:J,8,FALSE),"-") -> 1117455 | L17: =+IFERROR(VLOOKUP(B17,'ID1&5'!K:L,2,FALSE),"-") -> 2024-12-10 12:15:23.230637000 | M17: =+IFERROR(VLOOKUP(CONCATENATE(A17,$B$10,B17),'ID1&5'!B:J,9,FALSE),"-") -> 0 | N17: =+IFERROR(VLOOKUP(CONCATENATE(A17,$C$10,C17),'ID1&5'!B:J,8,FALSE),"-") -> 1117487 | O17: =+IFERROR(VLOOKUP(C17,'ID1&5'!K:L,2,FALSE),"-") -> 2024-12-10 12:15:23.230637000 | P17: =+IFERROR(VLOOKUP(CONCATENATE(A17,$C$10,C17),'ID1&5'!B:J,9,FALSE),"-") -> 0 | Q17: =+IFERROR(VLOOKUP(D17,'ID1&5'!K:L,2,FALSE),"-") -> 2024-12-10 12:15:23.230637000 | R17: =+IFERROR(VLOOKUP(CONCATENATE(A17,$D$10,D17),'ID1&5'!B:J,9,FALSE),"-") -> 0 | S17: =+IFERROR(VLOOKUP(E17,'ID1&5'!K:L,2,FALSE),"-") -> 2024-12-10 12:15:23.230637000 | T17: =+IFERROR(VLOOKUP(CONCATENATE(A17,$E$10,E17),'ID1&5'!B:J,9,FALSE),"-") -> 79452 | U17: =+IFERROR(VLOOKUP(F17,'ID1&5'!K:L,2,FALSE),"-") -> 2024-12-10 12:15:23.230637000 | V17: =+IFERROR(VLOOKUP(CONCATENATE(A17,$F$10,F17),'ID1&5'!B:J,9,FALSE),"-") -> 1037626 | W17: =+IFERROR(VLOOKUP(A17,'ID6&7'!A:I,9,FALSE),"-") -> 0.000000 | X17: =+IFERROR(VLOOKUP(A17,'ID6&7'!A:J,10,FALSE),"-") -> 2.100000 | Z17: =+IF(J17=0,"Por iniciar",IF(OR(K17="-",M17="-",P17="-",R17="-",T17="-",V17="-"),"Em testes",IF(AND(M17=0,P17=0,R17=0,T17<>K17,V17<>K17),"OK","NOK"))) -> OK
A18: =+H18&I18&$I$8 -> ENTITYTRNSTNL_CAPEX45596 | B18: {=+MAX(IF('ID1&5'!A:A='1. Status'!A18&'1. Status'!$B$10,'ID1&5'!K:K))} -> 9 | C18: {=+MAX(IF('ID1&5'!A:A='1. Status'!A18&'1. Status'!$C$10,'ID1&5'!K:K))} -> 9 | D18: {=+MAX(IF('ID1&5'!A:A='1. Status'!A18&'1. Status'!$D$10,'ID1&5'!K:K))} -> 9 | E18: {=+MAX(IF('ID1&5'!A:A='1. Status'!A18&'1. Status'!$E$10,'ID1&5'!K:K))} -> 9 | F18: {=+MAX(IF('ID1&5'!A:A='1. Status'!A18&'1. Status'!$F$10,'ID1&5'!K:K))} -> 9 | H18: ENTITY | I18: TRNSTNL_CAPEX | J18: =+COUNTIF('ID1&5'!G:G,'1. Status'!I18) -> 5 | K18: =+IFERROR(VLOOKUP(CONCATENATE(A18,$B$10,B18),'ID1&5'!B:J,8,FALSE),"-") -> 1117455 | L18: =+IFERROR(VLOOKUP(B18,'ID1&5'!K:L,2,FALSE),"-") -> 2024-12-10 12:15:23.230637000 | M18: =+IFERROR(VLOOKUP(CONCATENATE(A18,$B$10,B18),'ID1&5'!B:J,9,FALSE),"-") -> 0 | N18: =+IFERROR(VLOOKUP(CONCATENATE(A18,$C$10,C18),'ID1&5'!B:J,8,FALSE),"-") -> 1117487 | O18: =+IFERROR(VLOOKUP(C18,'ID1&5'!K:L,2,FALSE),"-") -> 2024-12-10 12:15:23.230637000 | P18: =+IFERROR(VLOOKUP(CONCATENATE(A18,$C$10,C18),'ID1&5'!B:J,9,FALSE),"-") -> 0 | Q18: =+IFERROR(VLOOKUP(D18,'ID1&5'!K:L,2,FALSE),"-") -> 2024-12-10 12:15:23.230637000 | R18: =+IFERROR(VLOOKUP(CONCATENATE(A18,$D$10,D18),'ID1&5'!B:J,9,FALSE),"-") -> 0 | S18: =+IFERROR(VLOOKUP(E18,'ID1&5'!K:L,2,FALSE),"-") -> 2024-12-10 12:15:23.230637000 | T18: =+IFERROR(VLOOKUP(CONCATENATE(A18,$E$10,E18),'ID1&5'!B:J,9,FALSE),"-") -> 79452 | U18: =+IFERROR(VLOOKUP(F18,'ID1&5'!K:L,2,FALSE),"-") -> 2024-12-10 12:15:23.230637000 | V18: =+IFERROR(VLOOKUP(CONCATENATE(A18,$F$10,F18),'ID1&5'!B:J,9,FALSE),"-") -> 1037626 | W18: =+IFERROR(VLOOKUP(A18,'ID6&7'!A:I,9,FALSE),"-") -> 0.000000 | X18: =+IFERROR(VLOOKUP(A18,'ID6&7'!A:J,10,FALSE),"-") -> 14.325843 | Z18: =+IF(J18=0,"Por iniciar",IF(OR(K18="-",M18="-",P18="-",R18="-",T18="-",V18="-"),"Em testes",IF(AND(M18=0,P18=0,R18=0,T18<>K18,V18<>K18),"OK","NOK"))) -> OK
A19: =+H19&I19&$I$8 -> ENTITYPURE_CAPEX_CCM45596 | B19: {=+MAX(IF('ID1&5'!A:A='1. Status'!A19&'1. Status'!$B$10,'ID1&5'!K:K))} -> 9 | C19: {=+MAX(IF('ID1&5'!A:A='1. Status'!A19&'1. Status'!$C$10,'ID1&5'!K:K))} -> 9 | D19: {=+MAX(IF('ID1&5'!A:A='1. Status'!A19&'1. Status'!$D$10,'ID1&5'!K:K))} -> 9 | E19: {=+MAX(IF('ID1&5'!A:A='1. Status'!A19&'1. Status'!$E$10,'ID1&5'!K:K))} -> 9 | F19: {=+MAX(IF('ID1&5'!A:A='1. Status'!A19&'1. Status'!$F$10,'ID1&5'!K:K))} -> 9 | H19: ENTITY | I19: PURE_CAPEX_CCM | J19: =+COUNTIF('ID1&5'!G:G,'1. Status'!I19) -> 5 | K19: =+IFERROR(VLOOKUP(CONCATENATE(A19,$B$10,B19),'ID1&5'!B:J,8,FALSE),"-") -> 1117455 | L19: =+IFERROR(VLOOKUP(B19,'ID1&5'!K:L,2,FALSE),"-") -> 2024-12-10 12:15:23.230637000 | M19: =+IFERROR(VLOOKUP(CONCATENATE(A19,$B$10,B19),'ID1&5'!B:J,9,FALSE),"-") -> 0 | N19: =+IFERROR(VLOOKUP(CONCATENATE(A19,$C$10,C19),'ID1&5'!B:J,8,FALSE),"-") -> 1117487 | O19: =+IFERROR(VLOOKUP(C19,'ID1&5'!K:L,2,FALSE),"-") -> 2024-12-10 12:15:23.230637000 | P19: =+IFERROR(VLOOKUP(CONCATENATE(A19,$C$10,C19),'ID1&5'!B:J,9,FALSE),"-") -> 0 | Q19: =+IFERROR(VLOOKUP(D19,'ID1&5'!K:L,2,FALSE),"-") -> 2024-12-10 12:15:23.230637000 | R19: =+IFERROR(VLOOKUP(CONCATENATE(A19,$D$10,D19),'ID1&5'!B:J,9,FALSE),"-") -> 0 | S19: =+IFERROR(VLOOKUP(E19,'ID1&5'!K:L,2,FALSE),"-") -> 2024-12-10 12:15:23.230637000 | T19: =+IFERROR(VLOOKUP(CONCATENATE(A19,$E$10,E19),'ID1&5'!B:J,9,FALSE),"-") -> 79452 | U19: =+IFERROR(VLOOKUP(F19,'ID1&5'!K:L,2,FALSE),"-") -> 2024-12-10 12:15:23.230637000 | V19: =+IFERROR(VLOOKUP(CONCATENATE(A19,$F$10,F19),'ID1&5'!B:J,9,FALSE),"-") -> 1037626 | W19: =+IFERROR(VLOOKUP(A19,'ID6&7'!A:I,9,FALSE),"-") -> 0.000000 | X19: =+IFERROR(VLOOKUP(A19,'ID6&7'!A:J,10,FALSE),"-") -> 96.000000 | Z19: =+IF(J19=0,"Por iniciar",IF(OR(K19="-",M19="-",P19="-",R19="-",T19="-",V19="-"),"Em testes",IF(AND(M19=0,P19=0,R19=0,T19<>K19,V19<>K19),"OK","NOK"))) -> OK
A20: =+H20&I20&$I$8 -> ENTITYPURE_CAPEX_CCA45596 | B20: {=+MAX(IF('ID1&5'!A:A='1. Status'!A20&'1. Status'!$B$10,'ID1&5'!K:K))} -> 9 | C20: {=+MAX(IF('ID1&5'!A:A='1. Status'!A20&'1. Status'!$C$10,'ID1&5'!K:K))} -> 9 | D20: {=+MAX(IF('ID1&5'!A:A='1. Status'!A20&'1. Status'!$D$10,'ID1&5'!K:K))} -> 9 | E20: {=+MAX(IF('ID1&5'!A:A='1. Status'!A20&'1. Status'!$E$10,'ID1&5'!K:K))} -> 9 | F20: {=+MAX(IF('ID1&5'!A:A='1. Status'!A20&'1. Status'!$F$10,'ID1&5'!K:K))} -> 9 | H20: ENTITY | I20: PURE_CAPEX_CCA | J20: =+COUNTIF('ID1&5'!G:G,'1. Status'!I20) -> 5 | K20: =+IFERROR(VLOOKUP(CONCATENATE(A20,$B$10,B20),'ID1&5'!B:J,8,FALSE),"-") -> 1117455 | L20: =+IFERROR(VLOOKUP(B20,'ID1&5'!K:L,2,FALSE),"-") -> 2024-12-10 12:15:23.230637000 | M20: =+IFERROR(VLOOKUP(CONCATENATE(A20,$B$10,B20),'ID1&5'!B:J,9,FALSE),"-") -> 0 | N20: =+IFERROR(VLOOKUP(CONCATENATE(A20,$C$10,C20),'ID1&5'!B:J,8,FALSE),"-") -> 1117487 | O20: =+IFERROR(VLOOKUP(C20,'ID1&5'!K:L,2,FALSE),"-") -> 2024-12-10 12:15:23.230637000 | P20: =+IFERROR(VLOOKUP(CONCATENATE(A20,$C$10,C20),'ID1&5'!B:J,9,FALSE),"-") -> 0 | Q20: =+IFERROR(VLOOKUP(D20,'ID1&5'!K:L,2,FALSE),"-") -> 2024-12-10 12:15:23.230637000 | R20: =+IFERROR(VLOOKUP(CONCATENATE(A20,$D$10,D20),'ID1&5'!B:J,9,FALSE),"-") -> 0 | S20: =+IFERROR(VLOOKUP(E20,'ID1&5'!K:L,2,FALSE),"-") -> 2024-12-10 12:15:23.230637000 | T20: =+IFERROR(VLOOKUP(CONCATENATE(A20,$E$10,E20),'ID1&5'!B:J,9,FALSE),"-") -> 79452 | U20: =+IFERROR(VLOOKUP(F20,'ID1&5'!K:L,2,FALSE),"-") -> 2024-12-10 12:15:23.230637000 | V20: =+IFERROR(VLOOKUP(CONCATENATE(A20,$F$10,F20),'ID1&5'!B:J,9,FALSE),"-") -> 1037626 | W20: =+IFERROR(VLOOKUP(A20,'ID6&7'!A:I,9,FALSE),"-") -> 0.000000 | X20: =+IFERROR(VLOOKUP(A20,'ID6&7'!A:J,10,FALSE),"-") -> 0.000000 | Z20: =+IF(J20=0,"Por iniciar",IF(OR(K20="-",M20="-",P20="-",R20="-",T20="-",V20="-"),"Em testes",IF(AND(M20=0,P20=0,R20=0,T20<>K20,V20<>K20),"OK","NOK"))) -> OK
A21: =+H21&I21&$I$8 -> ENTITYENBLNG_TRNVR_CCM45596 | B21: {=+MAX(IF('ID1&5'!A:A='1. Status'!A21&'1. Status'!$B$10,'ID1&5'!K:K))} -> 9 | C21: {=+MAX(IF('ID1&5'!A:A='1. Status'!A21&'1. Status'!$C$10,'ID1&5'!K:K))} -> 9 | D21: {=+MAX(IF('ID1&5'!A:A='1. Status'!A21&'1. Status'!$D$10,'ID1&5'!K:K))} -> 9 | E21: {=+MAX(IF('ID1&5'!A:A='1. Status'!A21&'1. Status'!$E$10,'ID1&5'!K:K))} -> 9 | F21: {=+MAX(IF('ID1&5'!A:A='1. Status'!A21&'1. Status'!$F$10,'ID1&5'!K:K))} -> 9 | H21: ENTITY | I21: ENBLNG_TRNVR_CCM | J21: =+COUNTIF('ID1&5'!G:G,'1. Status'!I21) -> 5 | K21: =+IFERROR(VLOOKUP(CONCATENATE(A21,$B$10,B21),'ID1&5'!B:J,8,FALSE),"-") -> 1117455 | L21: =+IFERROR(VLOOKUP(B21,'ID1&5'!K:L,2,FALSE),"-") -> 2024-12-10 12:15:23.230637000 | M21: =+IFERROR(VLOOKUP(CONCATENATE(A21,$B$10,B21),'ID1&5'!B:J,9,FALSE),"-") -> 0 | N21: =+IFERROR(VLOOKUP(CONCATENATE(A21,$C$10,C21),'ID1&5'!B:J,8,FALSE),"-") -> 1117487 | O21: =+IFERROR(VLOOKUP(C21,'ID1&5'!K:L,2,FALSE),"-") -> 2024-12-10 12:15:23.230637000 | P21: =+IFERROR(VLOOKUP(CONCATENATE(A21,$C$10,C21),'ID1&5'!B:J,9,FALSE),"-") -> 0 | Q21: =+IFERROR(VLOOKUP(D21,'ID1&5'!K:L,2,FALSE),"-") -> 2024-12-10 12:15:23.230637000 | R21: =+IFERROR(VLOOKUP(CONCATENATE(A21,$D$10,D21),'ID1&5'!B:J,9,FALSE),"-") -> 0 | S21: =+IFERROR(VLOOKUP(E21,'ID1&5'!K:L,2,FALSE),"-") -> 2024-12-10 12:15:23.230637000 | T21: =+IFERROR(VLOOKUP(CONCATENATE(A21,$E$10,E21),'ID1&5'!B:J,9,FALSE),"-") -> 79311 | U21: =+IFERROR(VLOOKUP(F21,'ID1&5'!K:L,2,FALSE),"-") -> 2024-12-10 12:15:23.230637000 | V21: =+IFERROR(VLOOKUP(CONCATENATE(A21,$F$10,F21),'ID1&5'!B:J,9,FALSE),"-") -> 1037626 | W21: =+IFERROR(VLOOKUP(A21,'ID6&7'!A:I,9,FALSE),"-") -> 0.000000 | X21: =+IFERROR(VLOOKUP(A21,'ID6&7'!A:J,10,FALSE),"-") -> 63.500000 | Z21: =+IF(J21=0,"Por iniciar",IF(OR(K21="-",M21="-",P21="-",R21="-",T21="-",V21="-"),"Em testes",IF(AND(M21=0,P21=0,R21=0,T21<>K21,V21<>K21),"OK","NOK"))) -> OK
A22: =+H22&I22&$I$8 -> ENTITYENBLNG_TRNVR_CCA45596 | B22: {=+MAX(IF('ID1&5'!A:A='1. Status'!A22&'1. Status'!$B$10,'ID1&5'!K:K))} -> 9 | C22: {=+MAX(IF('ID1&5'!A:A='1. Status'!A22&'1. Status'!$C$10,'ID1&5'!K:K))} -> 9 | D22: {=+MAX(IF('ID1&5'!A:A='1. Status'!A22&'1. Status'!$D$10,'ID1&5'!K:K))} -> 9 | E22: {=+MAX(IF('ID1&5'!A:A='1. Status'!A22&'1. Status'!$E$10,'ID1&5'!K:K))} -> 9 | F22: {=+MAX(IF('ID1&5'!A:A='1. Status'!A22&'1. Status'!$F$10,'ID1&5'!K:K))} -> 9 | H22: ENTITY | I22: ENBLNG_TRNVR_CCA | J22: =+COUNTIF('ID1&5'!G:G,'1. Status'!I22) -> 5 | K22: =+IFERROR(VLOOKUP(CONCATENATE(A22,$B$10,B22),'ID1&5'!B:J,8,FALSE),"-") -> 1117455 | L22: =+IFERROR(VLOOKUP(B22,'ID1&5'!K:L,2,FALSE),"-") -> 2024-12-10 12:15:23.230637000 | M22: =+IFERROR(VLOOKUP(CONCATENATE(A22,$B$10,B22),'ID1&5'!B:J,9,FALSE),"-") -> 0 | N22: =+IFERROR(VLOOKUP(CONCATENATE(A22,$C$10,C22),'ID1&5'!B:J,8,FALSE),"-") -> 1117487 | O22: =+IFERROR(VLOOKUP(C22,'ID1&5'!K:L,2,FALSE),"-") -> 2024-12-10 12:15:23.230637000 | P22: =+IFERROR(VLOOKUP(CONCATENATE(A22,$C$10,C22),'ID1&5'!B:J,9,FALSE),"-") -> 0 | Q22: =+IFERROR(VLOOKUP(D22,'ID1&5'!K:L,2,FALSE),"-") -> 2024-12-10 12:15:23.230637000 | R22: =+IFERROR(VLOOKUP(CONCATENATE(A22,$D$10,D22),'ID1&5'!B:J,9,FALSE),"-") -> 0 | S22: =+IFERROR(VLOOKUP(E22,'ID1&5'!K:L,2,FALSE),"-") -> 2024-12-10 12:15:23.230637000 | T22: =+IFERROR(VLOOKUP(CONCATENATE(A22,$E$10,E22),'ID1&5'!B:J,9,FALSE),"-") -> 79311 | U22: =+IFERROR(VLOOKUP(F22,'ID1&5'!K:L,2,FALSE),"-") -> 2024-12-10 12:15:23.230637000 | V22: =+IFERROR(VLOOKUP(CONCATENATE(A22,$F$10,F22),'ID1&5'!B:J,9,FALSE),"-") -> 1037626 | W22: =+IFERROR(VLOOKUP(A22,'ID6&7'!A:I,9,FALSE),"-") -> 0.000000 | X22: =+IFERROR(VLOOKUP(A22,'ID6&7'!A:J,10,FALSE),"-") -> 5.590234 | Z22: =+IF(J22=0,"Por iniciar",IF(OR(K22="-",M22="-",P22="-",R22="-",T22="-",V22="-"),"Em testes",IF(AND(M22=0,P22=0,R22=0,T22<>K22,V22<>K22),"OK","NOK"))) -> OK
A23: =+H23&I23&$I$8 -> ENTITYTRNSTNL_TRNVR45596 | B23: {=+MAX(IF('ID1&5'!A:A='1. Status'!A23&'1. Status'!$B$10,'ID1&5'!K:K))} -> 9 | C23: {=+MAX(IF('ID1&5'!A:A='1. Status'!A23&'1. Status'!$C$10,'ID1&5'!K:K))} -> 9 | D23: {=+MAX(IF('ID1&5'!A:A='1. Status'!A23&'1. Status'!$D$10,'ID1&5'!K:K))} -> 9 | E23: {=+MAX(IF('ID1&5'!A:A='1. Status'!A23&'1. Status'!$E$10,'ID1&5'!K:K))} -> 9 | F23: {=+MAX(IF('ID1&5'!A:A='1. Status'!A23&'1. Status'!$F$10,'ID1&5'!K:K))} -> 9 | H23: ENTITY | I23: TRNSTNL_TRNVR | J23: =+COUNTIF('ID1&5'!G:G,'1. Status'!I23) -> 5 | K23: =+IFERROR(VLOOKUP(CONCATENATE(A23,$B$10,B23),'ID1&5'!B:J,8,FALSE),"-") -> 1117455 | L23: =+IFERROR(VLOOKUP(B23,'ID1&5'!K:L,2,FALSE),"-") -> 2024-12-10 12:15:23.230637000 | M23: =+IFERROR(VLOOKUP(CONCATENATE(A23,$B$10,B23),'ID1&5'!B:J,9,FALSE),"-") -> 0 | N23: =+IFERROR(VLOOKUP(CONCATENATE(A23,$C$10,C23),'ID1&5'!B:J,8,FALSE),"-") -> 1117487 | O23: =+IFERROR(VLOOKUP(C23,'ID1&5'!K:L,2,FALSE),"-") -> 2024-12-10 12:15:23.230637000 | P23: =+IFERROR(VLOOKUP(CONCATENATE(A23,$C$10,C23),'ID1&5'!B:J,9,FALSE),"-") -> 0 | Q23: =+IFERROR(VLOOKUP(D23,'ID1&5'!K:L,2,FALSE),"-") -> 2024-12-10 12:15:23.230637000 | R23: =+IFERROR(VLOOKUP(CONCATENATE(A23,$D$10,D23),'ID1&5'!B:J,9,FALSE),"-") -> 0 | S23: =+IFERROR(VLOOKUP(E23,'ID1&5'!K:L,2,FALSE),"-") -> 2024-12-10 12:15:23.230637000 | T23: =+IFERROR(VLOOKUP(CONCATENATE(A23,$E$10,E23),'ID1&5'!B:J,9,FALSE),"-") -> 79311 | U23: =+IFERROR(VLOOKUP(F23,'ID1&5'!K:L,2,FALSE),"-") -> 2024-12-10 12:15:23.230637000 | V23: =+IFERROR(VLOOKUP(CONCATENATE(A23,$F$10,F23),'ID1&5'!B:J,9,FALSE),"-") -> 1037626 | W23: =+IFERROR(VLOOKUP(A23,'ID6&7'!A:I,9,FALSE),"-") -> 0.000000 | X23: =+IFERROR(VLOOKUP(A23,'ID6&7'!A:J,10,FALSE),"-") -> 45.652640 | Z23: =+IF(J23=0,"Por iniciar",IF(OR(K23="-",M23="-",P23="-",R23="-",T23="-",V23="-"),"Em testes",IF(AND(M23=0,P23=0,R23=0,T23<>K23,V23<>K23),"OK","NOK"))) -> OK
A24: =+H24&I24&$I$8 -> ENTITYPURE_TRNVR_CCM45596 | B24: {=+MAX(IF('ID1&5'!A:A='1. Status'!A24&'1. Status'!$B$10,'ID1&5'!K:K))} -> 9 | C24: {=+MAX(IF('ID1&5'!A:A='1. Status'!A24&'1. Status'!$C$10,'ID1&5'!K:K))} -> 9 | D24: {=+MAX(IF('ID1&5'!A:A='1. Status'!A24&'1. Status'!$D$10,'ID1&5'!K:K))} -> 9 | E24: {=+MAX(IF('ID1&5'!A:A='1. Status'!A24&'1. Status'!$E$10,'ID1&5'!K:K))} -> 9 | F24: {=+MAX(IF('ID1&5'!A:A='1. Status'!A24&'1. Status'!$F$10,'ID1&5'!K:K))} -> 9 | H24: ENTITY | I24: PURE_TRNVR_CCM | J24: =+COUNTIF('ID1&5'!G:G,'1. Status'!I24) -> 5 | K24: =+IFERROR(VLOOKUP(CONCATENATE(A24,$B$10,B24),'ID1&5'!B:J,8,FALSE),"-") -> 1117455 | L24: =+IFERROR(VLOOKUP(B24,'ID1&5'!K:L,2,FALSE),"-") -> 2024-12-10 12:15:23.230637000 | M24: =+IFERROR(VLOOKUP(CONCATENATE(A24,$B$10,B24),'ID1&5'!B:J,9,FALSE),"-") -> 0 | N24: =+IFERROR(VLOOKUP(CONCATENATE(A24,$C$10,C24),'ID1&5'!B:J,8,FALSE),"-") -> 1117487 | O24: =+IFERROR(VLOOKUP(C24,'ID1&5'!K:L,2,FALSE),"-") -> 2024-12-10 12:15:23.230637000 | P24: =+IFERROR(VLOOKUP(CONCATENATE(A24,$C$10,C24),'ID1&5'!B:J,9,FALSE),"-") -> 0 | Q24: =+IFERROR(VLOOKUP(D24,'ID1&5'!K:L,2,FALSE),"-") -> 2024-12-10 12:15:23.230637000 | R24: =+IFERROR(VLOOKUP(CONCATENATE(A24,$D$10,D24),'ID1&5'!B:J,9,FALSE),"-") -> 0 | S24: =+IFERROR(VLOOKUP(E24,'ID1&5'!K:L,2,FALSE),"-") -> 2024-12-10 12:15:23.230637000 | T24: =+IFERROR(VLOOKUP(CONCATENATE(A24,$E$10,E24),'ID1&5'!B:J,9,FALSE),"-") -> 79311 | U24: =+IFERROR(VLOOKUP(F24,'ID1&5'!K:L,2,FALSE),"-") -> 2024-12-10 12:15:23.230637000 | V24: =+IFERROR(VLOOKUP(CONCATENATE(A24,$F$10,F24),'ID1&5'!B:J,9,FALSE),"-") -> 1037626 | W24: =+IFERROR(VLOOKUP(A24,'ID6&7'!A:I,9,FALSE),"-") -> 0.000000 | X24: =+IFERROR(VLOOKUP(A24,'ID6&7'!A:J,10,FALSE),"-") -> 49.000000 | Z24: =+IF(J24=0,"Por iniciar",IF(OR(K24="-",M24="-",P24="-",R24="-",T24="-",V24="-"),"Em testes",IF(AND(M24=0,P24=0,R24=0,T24<>K24,V24<>K24),"OK","NOK"))) -> OK
A25: =+H25&I25&$I$8 -> ENTITYPURE_TRNVR_CCA45596 | B25: {=+MAX(IF('ID1&5'!A:A='1. Status'!A25&'1. Status'!$B$10,'ID1&5'!K:K))} -> 9 | C25: {=+MAX(IF('ID1&5'!A:A='1. Status'!A25&'1. Status'!$C$10,'ID1&5'!K:K))} -> 9 | D25: {=+MAX(IF('ID1&5'!A:A='1. Status'!A25&'1. Status'!$D$10,'ID1&5'!K:K))} -> 9 | E25: {=+MAX(IF('ID1&5'!A:A='1. Status'!A25&'1. Status'!$E$10,'ID1&5'!K:K))} -> 9 | F25: {=+MAX(IF('ID1&5'!A:A='1. Status'!A25&'1. Status'!$F$10,'ID1&5'!K:K))} -> 9 | H25: ENTITY | I25: PURE_TRNVR_CCA | J25: =+COUNTIF('ID1&5'!G:G,'1. Status'!I25) -> 5 | K25: =+IFERROR(VLOOKUP(CONCATENATE(A25,$B$10,B25),'ID1&5'!B:J,8,FALSE),"-") -> 1117455 | L25: =+IFERROR(VLOOKUP(B25,'ID1&5'!K:L,2,FALSE),"-") -> 2024-12-10 12:15:23.230637000 | M25: =+IFERROR(VLOOKUP(CONCATENATE(A25,$B$10,B25),'ID1&5'!B:J,9,FALSE),"-") -> 0 | N25: =+IFERROR(VLOOKUP(CONCATENATE(A25,$C$10,C25),'ID1&5'!B:J,8,FALSE),"-") -> 1117487 | O25: =+IFERROR(VLOOKUP(C25,'ID1&5'!K:L,2,FALSE),"-") -> 2024-12-10 12:15:23.230637000 | P25: =+IFERROR(VLOOKUP(CONCATENATE(A25,$C$10,C25),'ID1&5'!B:J,9,FALSE),"-") -> 0 | Q25: =+IFERROR(VLOOKUP(D25,'ID1&5'!K:L,2,FALSE),"-") -> 2024-12-10 12:15:23.230637000 | R25: =+IFERROR(VLOOKUP(CONCATENATE(A25,$D$10,D25),'ID1&5'!B:J,9,FALSE),"-") -> 0 | S25: =+IFERROR(VLOOKUP(E25,'ID1&5'!K:L,2,FALSE),"-") -> 2024-12-10 12:15:23.230637000 | T25: =+IFERROR(VLOOKUP(CONCATENATE(A25,$E$10,E25),'ID1&5'!B:J,9,FALSE),"-") -> 79311 | U25: =+IFERROR(VLOOKUP(F25,'ID1&5'!K:L,2,FALSE),"-") -> 2024-12-10 12:15:23.230637000 | V25: =+IFERROR(VLOOKUP(CONCATENATE(A25,$F$10,F25),'ID1&5'!B:J,9,FALSE),"-") -> 1037626 | W25: =+IFERROR(VLOOKUP(A25,'ID6&7'!A:I,9,FALSE),"-") -> 0.000000 | X25: =+IFERROR(VLOOKUP(A25,'ID6&7'!A:J,10,FALSE),"-") -> 0.000000 | Z25: =+IF(J25=0,"Por iniciar",IF(OR(K25="-",M25="-",P25="-",R25="-",T25="-",V25="-"),"Em testes",IF(AND(M25=0,P25=0,R25=0,T25<>K25,V25<>K25),"OK","NOK"))) -> OK
... A32: =+H32&I32&$I$8 -> ENTITYFLG_CHRNC_PHYSCL_RSK45596 | B32: {=+MAX(IF('ID1&5'!A:A='1. Status'!A32&'1. Status'!$B$10,'ID1&5'!K:K))} -> 0 | C32: {=+MAX(IF('ID1&5'!A:A='1. Status'!A32&'1. Status'!$C$10,'ID1&5'!K:K))} -> 0 | D32: {=+MAX(IF('ID1&5'!A:A='1. Status'!A32&'1. Status'!$D$10,'ID1&5'!K:K))} -> 0 | E32: {=+MAX(IF('ID1&5'!A:A='1. Status'!A32&'1. Status'!$E$10,'ID1&5'!K:K))} -> 0 | F32: {=+MAX(IF('ID1&5'!A:A='1. Status'!A32&'1. Status'!$F$10,'ID1&5'!K:K))} -> 0 | H32: ENTITY | I32: FLG_CHRNC_PHYSCL_RSK | J32: =+COUNTIF('ID1&5'!G:G,'1. Status'!I32) -> 5 | K32: =+IFERROR(VLOOKUP(CONCATENATE(A32,$B$10,B32),'ID1&5'!B:J,8,FALSE),"-") -> - | L32: =+IFERROR(VLOOKUP(B32,'ID1&5'!K:L,2,FALSE),"-") -> - | M32: =+IFERROR(VLOOKUP(CONCATENATE(A32,$B$10,B32),'ID1&5'!B:J,9,FALSE),"-") -> - | N32: =+IFERROR(VLOOKUP(CONCATENATE(A32,$C$10,C32),'ID1&5'!B:J,8,FALSE),"-") -> - | O32: =+IFERROR(VLOOKUP(C32,'ID1&5'!K:L,2,FALSE),"-") -> - | P32: =+IFERROR(VLOOKUP(CONCATENATE(A32,$C$10,C32),'ID1&5'!B:J,9,FALSE),"-") -> - | Q32: =+IFERROR(VLOOKUP(D32,'ID1&5'!K:L,2,FALSE),"-") -> - | R32: =+IFERROR(VLOOKUP(CONCATENATE(A32,$D$10,D32),'ID1&5'!B:J,9,FALSE),"-") -> - | S32: =+IFERROR(VLOOKUP(E32,'ID1&5'!K:L,2,FALSE),"-") -> - | T32: =+IFERROR(VLOOKUP(CONCATENATE(A32,$E$10,E32),'ID1&5'!B:J,9,FALSE),"-") -> - | U32: =+IFERROR(VLOOKUP(F32,'ID1&5'!K:L,2,FALSE),"-") -> - | V32: =+IFERROR(VLOOKUP(CONCATENATE(A32,$F$10,F32),'ID1&5'!B:J,9,FALSE),"-") -> - | W32: =+IFERROR(VLOOKUP(A32,'ID6&7'!A:I,9,FALSE),"-") -> - | X32: =+IFERROR(VLOOKUP(A32,'ID6&7'!A:J,10,FALSE),"-") -> - | Z32: =+IF(J32=0,"Por iniciar",IF(OR(K32="-",M32="-",P32="-",R32="-",T32="-",V32="-"),"Em testes",IF(AND(M32=0,P32=0,R32=0,T32<>K32,V32<>K32),"OK","NOK"))) -> Em testes
A33: =+H33&I33&$I$8 -> ENTITYPST_CD45596 | B33: {=+MAX(IF('ID1&5'!A:A='1. Status'!A33&'1. Status'!$B$10,'ID1&5'!K:K))} -> 1 | C33: {=+MAX(IF('ID1&5'!A:A='1. Status'!A33&'1. Status'!$C$10,'ID1&5'!K:K))} -> 1 | D33: {=+MAX(IF('ID1&5'!A:A='1. Status'!A33&'1. Status'!$D$10,'ID1&5'!K:K))} -> 1 | E33: {=+MAX(IF('ID1&5'!A:A='1. Status'!A33&'1. Status'!$E$10,'ID1&5'!K:K))} -> 1 | F33: {=+MAX(IF('ID1&5'!A:A='1. Status'!A33&'1. Status'!$F$10,'ID1&5'!K:K))} -> 1 | H33: ENTITY | I33: PST_CD | J33: =+COUNTIF('ID1&5'!G:G,'1. Status'!I33) -> 5 | K33: =+IFERROR(VLOOKUP(CONCATENATE(A33,$B$10,B33),'ID1&5'!B:J,8,FALSE),"-") -> 1113839 | L33: =+IFERROR(VLOOKUP(B33,'ID1&5'!K:L,2,FALSE),"-") -> 2024-11-08 12:06:55.054517000 | M33: =+IFERROR(VLOOKUP(CONCATENATE(A33,$B$10,B33),'ID1&5'!B:J,9,FALSE),"-") -> 0 | N33: =+IFERROR(VLOOKUP(CONCATENATE(A33,$C$10,C33),'ID1&5'!B:J,8,FALSE),"-") -> 1113801 | O33: =+IFERROR(VLOOKUP(C33,'ID1&5'!K:L,2,FALSE),"-") -> 2024-11-08 12:06:55.054517000 | P33: =+IFERROR(VLOOKUP(CONCATENATE(A33,$C$10,C33),'ID1&5'!B:J,9,FALSE),"-") -> 0 | Q33: =+IFERROR(VLOOKUP(D33,'ID1&5'!K:L,2,FALSE),"-") -> 2024-11-08 12:06:55.054517000 | R33: =+IFERROR(VLOOKUP(CONCATENATE(A33,$D$10,D33),'ID1&5'!B:J,9,FALSE),"-") -> 0 | S33: =+IFERROR(VLOOKUP(E33,'ID1&5'!K:L,2,FALSE),"-") -> 2024-11-08 12:06:55.054517000 | T33: =+IFERROR(VLOOKUP(CONCATENATE(A33,$E$10,E33),'ID1&5'!B:J,9,FALSE),"-") -> 29 | U33: =+IFERROR(VLOOKUP(F33,'ID1&5'!K:L,2,FALSE),"-") -> 2024-11-08 12:06:55.054517000 | V33: =+IFERROR(VLOOKUP(CONCATENATE(A33,$F$10,F33),'ID1&5'!B:J,9,FALSE),"-") -> 0 | W33: =+IFERROR(VLOOKUP(A33,'ID6&7'!A:I,9,FALSE),"-") -> - | X33: =+IFERROR(VLOOKUP(A33,'ID6&7'!A:J,10,FALSE),"-") -> - | Y33: 08/11 - Os testes foram corridos para a data de referência 30/09/2024. | Z33: =+IF(J33=0,"Por iniciar",IF(OR(K33="-",M33="-",P33="-",R33="-",T33="-",V33="-"),"Em testes",IF(AND(M33=0,P33=0,R33=0,T33<>K33,V33<>K33),"OK","NOK"))) -> OK
A34: =+H34&I34&$I$8 -> ENTITYESG_SBSCTR45596 | B34: {=+MAX(IF('ID1&5'!A:A='1. Status'!A34&'1. Status'!$B$10,'ID1&5'!K:K))} -> 7 | C34: {=+MAX(IF('ID1&5'!A:A='1. Status'!A34&'1. Status'!$C$10,'ID1&5'!K:K))} -> 0 | D34: {=+MAX(IF('ID1&5'!A:A='1. Status'!A34&'1. Status'!$D$10,'ID1&5'!K:K))} -> 0 | E34: {=+MAX(IF('ID1&5'!A:A='1. Status'!A34&'1. Status'!$E$10,'ID1&5'!K:K))} -> 0 | F34: {=+MAX(IF('ID1&5'!A:A='1. Status'!A34&'1. Status'!$F$10,'ID1&5'!K:K))} -> 0 | H34: ENTITY | I34: ESG_SBSCTR | J34: =+COUNTIF('ID1&5'!G:G,'1. Status'!I34) -> 6 | K34: =+IFERROR(VLOOKUP(CONCATENATE(A34,$B$10,B34),'ID1&5'!B:J,8,FALSE),"-") -> 1117455 | L34: =+IFERROR(VLOOKUP(B34,'ID1&5'!K:L,2,FALSE),"-") -> 2024-12-09 23:51:42.406642000 | M34: =+IFERROR(VLOOKUP(CONCATENATE(A34,$B$10,B34),'ID1&5'!B:J,9,FALSE),"-") -> 104 | N34: =+IFERROR(VLOOKUP(CONCATENATE(A34,$C$10,C34),'ID1&5'!B:J,8,FALSE),"-") -> - | O34: =+IFERROR(VLOOKUP(C34,'ID1&5'!K:L,2,FALSE),"-") -> - | P34: =+IFERROR(VLOOKUP(CONCATENATE(A34,$C$10,C34),'ID1&5'!B:J,9,FALSE),"-") -> - | Q34: =+IFERROR(VLOOKUP(D34,'ID1&5'!K:L,2,FALSE),"-") -> - | R34: =+IFERROR(VLOOKUP(CONCATENATE(A34,$D$10,D34),'ID1&5'!B:J,9,FALSE),"-") -> - | S34: =+IFERROR(VLOOKUP(E34,'ID1&5'!K:L,2,FALSE),"-") -> - | T34: =+IFERROR(VLOOKUP(CONCATENATE(A34,$E$10,E34),'ID1&5'!B:J,9,FALSE),"-") -> - | U34: =+IFERROR(VLOOKUP(F34,'ID1&5'!K:L,2,FALSE),"-") -> - | V34: =+IFERROR(VLOOKUP(CONCATENATE(A34,$F$10,F34),'ID1&5'!B:J,9,FALSE),"-") -> - | W34: =+IFERROR(VLOOKUP(A34,'ID6&7'!A:I,9,FALSE),"-") -> ESGS1 | X34: =+IFERROR(VLOOKUP(A34,'ID6&7'!A:J,10,FALSE),"-") -> ESGS5 | Z34: =+IF(J34=0,"Por iniciar",IF(OR(K34="-",M34="-",P34="-",R34="-",T34="-",V34="-"),"Em testes",IF(AND(M34=0,P34=0,R34=0,T34<>K34,V34<>K34),"OK","NOK"))) -> Em testes
A35: =+H35&I35&$I$8 -> ENTITYTTL_LBLTY45596 | B35: {=+MAX(IF('ID1&5'!A:A='1. Status'!A35&'1. Status'!$B$10,'ID1&5'!K:K))} -> 7 | C35: {=+MAX(IF('ID1&5'!A:A='1. Status'!A35&'1. Status'!$C$10,'ID1&5'!K:K))} -> 0 | D35: {=+MAX(IF('ID1&5'!A:A='1. Status'!A35&'1. Status'!$D$10,'ID1&5'!K:K))} -> 0 | E35: {=+MAX(IF('ID1&5'!A:A='1. Status'!A35&'1. Status'!$E$10,'ID1&5'!K:K))} -> 0 | F35: {=+MAX(IF('ID1&5'!A:A='1. Status'!A35&'1. Status'!$F$10,'ID1&5'!K:K))} -> 0 | H35: ENTITY | I35: TTL_LBLTY | J35: =+COUNTIF('ID1&5'!G:G,'1. Status'!I35) -> 6 | K35: =+IFERROR(VLOOKUP(CONCATENATE(A35,$B$10,B35),'ID1&5'!B:J,8,FALSE),"-") -> 1117455 | L35: =+IFERROR(VLOOKUP(B35,'ID1&5'!K:L,2,FALSE),"-") -> 2024-12-09 23:51:42.406642000 | M35: =+IFERROR(VLOOKUP(CONCATENATE(A35,$B$10,B35),'ID1&5'!B:J,9,FALSE),"-") -> 124 | N35: =+IFERROR(VLOOKUP(CONCATENATE(A35,$C$10,C35),'ID1&5'!B:J,8,FALSE),"-") -> - | O35: =+IFERROR(VLOOKUP(C35,'ID1&5'!K:L,2,FALSE),"-") -> - | P35: =+IFERROR(VLOOKUP(CONCATENATE(A35,$C$10,C35),'ID1&5'!B:J,9,FALSE),"-") -> - | Q35: =+IFERROR(VLOOKUP(D35,'ID1&5'!K:L,2,FALSE),"-") -> - | R35: =+IFERROR(VLOOKUP(CONCATENATE(A35,$D$10,D35),'ID1&5'!B:J,9,FALSE),"-") -> - | S35: =+IFERROR(VLOOKUP(E35,'ID1&5'!K:L,2,FALSE),"-") -> - | T35: =+IFERROR(VLOOKUP(CONCATENATE(A35,$E$10,E35),'ID1&5'!B:J,9,FALSE),"-") -> - | U35: =+IFERROR(VLOOKUP(F35,'ID1&5'!K:L,2,FALSE),"-") -> - | V35: =+IFERROR(VLOOKUP(CONCATENATE(A35,$F$10,F35),'ID1&5'!B:J,9,FALSE),"-") -> - | W35: =+IFERROR(VLOOKUP(A35,'ID6&7'!A:I,9,FALSE),"-") -> - | X35: =+IFERROR(VLOOKUP(A35,'ID6&7'!A:J,10,FALSE),"-") -> - | Z35: =+IF(J35=0,"Por iniciar",IF(OR(K35="-",M35="-",P35="-",R35="-",T35="-",V35="-"),"Em testes",IF(AND(M35=0,P35=0,R35=0,T35<>K35,V35<>K35),"OK","NOK"))) -> Em testes
A36: =+H36&I36&$I$8 -> ENTITYISIN45596 | B36: {=+MAX(IF('ID1&5'!A:A='1. Status'!A36&'1. Status'!$B$10,'ID1&5'!K:K))} -> 7 | C36: {=+MAX(IF('ID1&5'!A:A='1. Status'!A36&'1. Status'!$C$10,'ID1&5'!K:K))} -> 0 | D36: {=+MAX(IF('ID1&5'!A:A='1. Status'!A36&'1. Status'!$D$10,'ID1&5'!K:K))} -> 0 | E36: {=+MAX(IF('ID1&5'!A:A='1. Status'!A36&'1. Status'!$E$10,'ID1&5'!K:K))} -> 0 | F36: {=+MAX(IF('ID1&5'!A:A='1. Status'!A36&'1. Status'!$F$10,'ID1&5'!K:K))} -> 0 | H36: ENTITY | I36: ISIN | J36: =+COUNTIF('ID1&5'!G:G,'1. Status'!I36) -> 6 | K36: =+IFERROR(VLOOKUP(CONCATENATE(A36,$B$10,B36),'ID1&5'!B:J,8,FALSE),"-") -> 1117455 | L36: =+IFERROR(VLOOKUP(B36,'ID1&5'!K:L,2,FALSE),"-") -> 2024-12-09 23:51:42.406642000 | M36: =+IFERROR(VLOOKUP(CONCATENATE(A36,$B$10,B36),'ID1&5'!B:J,9,FALSE),"-") -> 14 | N36: =+IFERROR(VLOOKUP(CONCATENATE(A36,$C$10,C36),'ID1&5'!B:J,8,FALSE),"-") -> - | O36: =+IFERROR(VLOOKUP(C36,'ID1&5'!K:L,2,FALSE),"-") -> - | P36: =+IFERROR(VLOOKUP(CONCATENATE(A36,$C$10,C36),'ID1&5'!B:J,9,FALSE),"-") -> - | Q36: =+IFERROR(VLOOKUP(D36,'ID1&5'!K:L,2,FALSE),"-") -> - | R36: =+IFERROR(VLOOKUP(CONCATENATE(A36,$D$10,D36),'ID1&5'!B:J,9,FALSE),"-") -> - | S36: =+IFERROR(VLOOKUP(E36,'ID1&5'!K:L,2,FALSE),"-") -> - | T36: =+IFERROR(VLOOKUP(CONCATENATE(A36,$E$10,E36),'ID1&5'!B:J,9,FALSE),"-") -> - | U36: =+IFERROR(VLOOKUP(F36,'ID1&5'!K:L,2,FALSE),"-") -> - | V36: =+IFERROR(VLOOKUP(CONCATENATE(A36,$F$10,F36),'ID1&5'!B:J,9,FALSE),"-") -> - | W36: =+IFERROR(VLOOKUP(A36,'ID6&7'!A:I,9,FALSE),"-") -> - | X36: =+IFERROR(VLOOKUP(A36,'ID6&7'!A:J,10,FALSE),"-") -> - | Z36: =+IF(J36=0,"Por iniciar",IF(OR(K36="-",M36="-",P36="-",R36="-",T36="-",V36="-"),"Em testes",IF(AND(M36=0,P36=0,R36=0,T36<>K36,V36<>K36),"OK","NOK"))) -> Em testes
A37: =+H37&I37&$I$8 -> ENTITYGRP_ANNL_TRNVR_LE45596 | B37: {=+MAX(IF('ID1&5'!A:A='1. Status'!A37&'1. Status'!$B$10,'ID1&5'!K:K))} -> 8 | C37: {=+MAX(IF('ID1&5'!A:A='1. Status'!A37&'1. Status'!$C$10,'ID1&5'!K:K))} -> 8 | D37: {=+MAX(IF('ID1&5'!A:A='1. Status'!A37&'1. Status'!$D$10,'ID1&5'!K:K))} -> 8 | E37: {=+MAX(IF('ID1&5'!A:A='1. Status'!A37&'1. Status'!$E$10,'ID1&5'!K:K))} -> 8 | F37: {=+MAX(IF('ID1&5'!A:A='1. Status'!A37&'1. Status'!$F$10,'ID1&5'!K:K))} -> 8 | H37: ENTITY | I37: GRP_ANNL_TRNVR_LE | J37: =+COUNTIF('ID1&5'!G:G,'1. Status'!I37) -> 10 | K37: =+IFERROR(VLOOKUP(CONCATENATE(A37,$B$10,B37),'ID1&5'!B:J,8,FALSE),"-") -> 1117455 | L37: =+IFERROR(VLOOKUP(B37,'ID1&5'!K:L,2,FALSE),"-") -> 2024-12-10 12:03:41.044650000 | M37: =+IFERROR(VLOOKUP(CONCATENATE(A37,$B$10,B37),'ID1&5'!B:J,9,FALSE),"-") -> 0 | N37: =+IFERROR(VLOOKUP(CONCATENATE(A37,$C$10,C37),'ID1&5'!B:J,8,FALSE),"-") -> 1117487 | O37: =+IFERROR(VLOOKUP(C37,'ID1&5'!K:L,2,FALSE),"-") -> 2024-12-10 12:03:41.044650000 | P37: =+IFERROR(VLOOKUP(CONCATENATE(A37,$C$10,C37),'ID1&5'!B:J,9,FALSE),"-") -> 0 | Q37: =+IFERROR(VLOOKUP(D37,'ID1&5'!K:L,2,FALSE),"-") -> 2024-12-10 12:03:41.044650000 | R37: =+IFERROR(VLOOKUP(CONCATENATE(A37,$D$10,D37),'ID1&5'!B:J,9,FALSE),"-") -> 0 | S37: =+IFERROR(VLOOKUP(E37,'ID1&5'!K:L,2,FALSE),"-") -> 2024-12-10 12:03:41.044650000 | T37: =+IFERROR(VLOOKUP(CONCATENATE(A37,$E$10,E37),'ID1&5'!B:J,9,FALSE),"-") -> 77252 | U37: =+IFERROR(VLOOKUP(F37,'ID1&5'!K:L,2,FALSE),"-") -> 2024-12-10 12:03:41.044650000 | V37: =+IFERROR(VLOOKUP(CONCATENATE(A37,$F$10,F37),'ID1&5'!B:J,9,FALSE),"-") -> 1037356 | W37: =+IFERROR(VLOOKUP(A37,'ID6&7'!A:I,9,FALSE),"-") -> 0.00 | X37: =+IFERROR(VLOOKUP(A37,'ID6&7'!A:J,10,FALSE),"-") -> 58991300000.00 | Z37: =+IF(J37=0,"Por iniciar",IF(OR(K37="-",M37="-",P37="-",R37="-",T37="-",V37="-"),"Em testes",IF(AND(M37=0,P37=0,R37=0,T37<>K37,V37<>K37),"OK","NOK"))) -> OK
A38: =+H38&I38&$I$8 -> ENTITYGRP_TTL_LBLTY45596 | B38: {=+MAX(IF('ID1&5'!A:A='1. Status'!A38&'1. Status'!$B$10,'ID1&5'!K:K))} -> 0 | C38: {=+MAX(IF('ID1&5'!A:A='1. Status'!A38&'1. Status'!$C$10,'ID1&5'!K:K))} -> 0 | D38: {=+MAX(IF('ID1&5'!A:A='1. Status'!A38&'1. Status'!$D$10,'ID1&5'!K:K))} -> 0 | E38: {=+MAX(IF('ID1&5'!A:A='1. Status'!A38&'1. Status'!$E$10,'ID1&5'!K:K))} -> 0 | F38: {=+MAX(IF('ID1&5'!A:A='1. Status'!A38&'1. Status'!$F$10,'ID1&5'!K:K))} -> 0 | H38: ENTITY | I38: GRP_TTL_LBLTY | J38: =+COUNTIF('ID1&5'!G:G,'1. Status'!I38) -> 5 | K38: =+IFERROR(VLOOKUP(CONCATENATE(A38,$B$10,B38),'ID1&5'!B:J,8,FALSE),"-") -> - | L38: =+IFERROR(VLOOKUP(B38,'ID1&5'!K:L,2,FALSE),"-") -> - | M38: =+IFERROR(VLOOKUP(CONCATENATE(A38,$B$10,B38),'ID1&5'!B:J,9,FALSE),"-") -> - | N38: =+IFERROR(VLOOKUP(CONCATENATE(A38,$C$10,C38),'ID1&5'!B:J,8,FALSE),"-") -> - | O38: =+IFERROR(VLOOKUP(C38,'ID1&5'!K:L,2,FALSE),"-") -> - | P38: =+IFERROR(VLOOKUP(CONCATENATE(A38,$C$10,C38),'ID1&5'!B:J,9,FALSE),"-") -> - | Q38: =+IFERROR(VLOOKUP(D38,'ID1&5'!K:L,2,FALSE),"-") -> - | R38: =+IFERROR(VLOOKUP(CONCATENATE(A38,$D$10,D38),'ID1&5'!B:J,9,FALSE),"-") -> - | S38: =+IFERROR(VLOOKUP(E38,'ID1&5'!K:L,2,FALSE),"-") -> - | T38: =+IFERROR(VLOOKUP(CONCATENATE(A38,$E$10,E38),'ID1&5'!B:J,9,FALSE),"-") -> - | U38: =+IFERROR(VLOOKUP(F38,'ID1&5'!K:L,2,FALSE),"-") -> - | V38: =+IFERROR(VLOOKUP(CONCATENATE(A38,$F$10,F38),'ID1&5'!B:J,9,FALSE),"-") -> - | W38: =+IFERROR(VLOOKUP(A38,'ID6&7'!A:I,9,FALSE),"-") -> - | X38: =+IFERROR(VLOOKUP(A38,'ID6&7'!A:J,10,FALSE),"-") -> - | Z38: =+IF(J38=0,"Por iniciar",IF(OR(K38="-",M38="-",P38="-",R38="-",T38="-",V38="-"),"Em testes",IF(AND(M38=0,P38=0,R38=0,T38<>K38,V38<>K38),"OK","NOK"))) -> Em testes
A39: =+H39&I39&$I$8 -> ENTITYFLG_GRP_NFRD_APPLCBLTY45596 | B39: {=+MAX(IF('ID1&5'!A:A='1. Status'!A39&'1. Status'!$B$10,'ID1&5'!K:K))} -> 0 | C39: {=+MAX(IF('ID1&5'!A:A='1. Status'!A39&'1. Status'!$C$10,'ID1&5'!K:K))} -> 0 | D39: {=+MAX(IF('ID1&5'!A:A='1. Status'!A39&'1. Status'!$D$10,'ID1&5'!K:K))} -> 0 | E39: {=+MAX(IF('ID1&5'!A:A='1. Status'!A39&'1. Status'!$E$10,'ID1&5'!K:K))} -> 0 | F39: {=+MAX(IF('ID1&5'!A:A='1. Status'!A39&'1. Status'!$F$10,'ID1&5'!K:K))} -> 0 | H39: ENTITY | I39: FLG_GRP_NFRD_APPLCBLTY | J39: =+COUNTIF('ID1&5'!G:G,'1. Status'!I39) -> 5 | K39: =+IFERROR(VLOOKUP(CONCATENATE(A39,$B$10,B39),'ID1&5'!B:J,8,FALSE),"-") -> - | L39: =+IFERROR(VLOOKUP(B39,'ID1&5'!K:L,2,FALSE),"-") -> - | M39: =+IFERROR(VLOOKUP(CONCATENATE(A39,$B$10,B39),'ID1&5'!B:J,9,FALSE),"-") -> - | N39: =+IFERROR(VLOOKUP(CONCATENATE(A39,$C$10,C39),'ID1&5'!B:J,8,FALSE),"-") -> - | O39: =+IFERROR(VLOOKUP(C39,'ID1&5'!K:L,2,FALSE),"-") -> - | P39: =+IFERROR(VLOOKUP(CONCATENATE(A39,$C$10,C39),'ID1&5'!B:J,9,FALSE),"-") -> - | Q39: =+IFERROR(VLOOKUP(D39,'ID1&5'!K:L,2,FALSE),"-") -> - | R39: =+IFERROR(VLOOKUP(CONCATENATE(A39,$D$10,D39),'ID1&5'!B:J,9,FALSE),"-") -> - | S39: =+IFERROR(VLOOKUP(E39,'ID1&5'!K:L,2,FALSE),"-") -> - | T39: =+IFERROR(VLOOKUP(CONCATENATE(A39,$E$10,E39),'ID1&5'!B:J,9,FALSE),"-") -> - | U39: =+IFERROR(VLOOKUP(F39,'ID1&5'!K:L,2,FALSE),"-") -> - | V39: =+IFERROR(VLOOKUP(CONCATENATE(A39,$F$10,F39),'ID1&5'!B:J,9,FALSE),"-") -> - | W39: =+IFERROR(VLOOKUP(A39,'ID6&7'!A:I,9,FALSE),"-") -> - | X39: =+IFERROR(VLOOKUP(A39,'ID6&7'!A:J,10,FALSE),"-") -> - | Z39: =+IF(J39=0,"Por iniciar",IF(OR(K39="-",M39="-",P39="-",R39="-",T39="-",V39="-"),"Em testes",IF(AND(M39=0,P39=0,R39=0,T39<>K39,V39<>K39),"OK","NOK"))) -> Em testes
A40: =+H40&I40&$I$8 -> ENTITYGRP_EMSSNS_SCP145596 | B40: {=+MAX(IF('ID1&5'!A:A='1. Status'!A40&'1. Status'!$B$10,'ID1&5'!K:K))} -> 0 | C40: {=+MAX(IF('ID1&5'!A:A='1. Status'!A40&'1. Status'!$C$10,'ID1&5'!K:K))} -> 0 | D40: {=+MAX(IF('ID1&5'!A:A='1. Status'!A40&'1. Status'!$D$10,'ID1&5'!K:K))} -> 0 | E40: {=+MAX(IF('ID1&5'!A:A='1. Status'!A40&'1. Status'!$E$10,'ID1&5'!K:K))} -> 0 | F40: {=+MAX(IF('ID1&5'!A:A='1. Status'!A40&'1. Status'!$F$10,'ID1&5'!K:K))} -> 0 | H40: ENTITY | I40: GRP_EMSSNS_SCP1 | J40: =+COUNTIF('ID1&5'!G:G,'1. Status'!I40) -> 5 | K40: =+IFERROR(VLOOKUP(CONCATENATE(A40,$B$10,B40),'ID1&5'!B:J,8,FALSE),"-") -> - | L40: =+IFERROR(VLOOKUP(B40,'ID1&5'!K:L,2,FALSE),"-") -> - | M40: =+IFERROR(VLOOKUP(CONCATENATE(A40,$B$10,B40),'ID1&5'!B:J,9,FALSE),"-") -> - | N40: =+IFERROR(VLOOKUP(CONCATENATE(A40,$C$10,C40),'ID1&5'!B:J,8,FALSE),"-") -> - | O40: =+IFERROR(VLOOKUP(C40,'ID1&5'!K:L,2,FALSE),"-") -> - | P40: =+IFERROR(VLOOKUP(CONCATENATE(A40,$C$10,C40),'ID1&5'!B:J,9,FALSE),"-") -> - | Q40: =+IFERROR(VLOOKUP(D40,'ID1&5'!K:L,2,FALSE),"-") -> - | R40: =+IFERROR(VLOOKUP(CONCATENATE(A40,$D$10,D40),'ID1&5'!B:J,9,FALSE),"-") -> - | S40: =+IFERROR(VLOOKUP(E40,'ID1&5'!K:L,2,FALSE),"-") -> - | T40: =+IFERROR(VLOOKUP(CONCATENATE(A40,$E$10,E40),'ID1&5'!B:J,9,FALSE),"-") -> - | U40: =+IFERROR(VLOOKUP(F40,'ID1&5'!K:L,2,FALSE),"-") -> - | V40: =+IFERROR(VLOOKUP(CONCATENATE(A40,$F$10,F40),'ID1&5'!B:J,9,FALSE),"-") -> - | W40: =+IFERROR(VLOOKUP(A40,'ID6&7'!A:I,9,FALSE),"-") -> - | X40: =+IFERROR(VLOOKUP(A40,'ID6&7'!A:J,10,FALSE),"-") -> - | Z40: =+IF(J40=0,"Por iniciar",IF(OR(K40="-",M40="-",P40="-",R40="-",T40="-",V40="-"),"Em testes",IF(AND(M40=0,P40=0,R40=0,T40<>K40,V40<>K40),"OK","NOK"))) -> Em testes
A41: =+H41&I41&$I$8 -> ENTITYGRP_EMSSNS_SCP245596 | B41: {=+MAX(IF('ID1&5'!A:A='1. Status'!A41&'1. Status'!$B$10,'ID1&5'!K:K))} -> 0 | C41: {=+MAX(IF('ID1&5'!A:A='1. Status'!A41&'1. Status'!$C$10,'ID1&5'!K:K))} -> 0 | D41: {=+MAX(IF('ID1&5'!A:A='1. Status'!A41&'1. Status'!$D$10,'ID1&5'!K:K))} -> 0 | E41: {=+MAX(IF('ID1&5'!A:A='1. Status'!A41&'1. Status'!$E$10,'ID1&5'!K:K))} -> 0 | F41: {=+MAX(IF('ID1&5'!A:A='1. Status'!A41&'1. Status'!$F$10,'ID1&5'!K:K))} -> 0 | H41: ENTITY | I41: GRP_EMSSNS_SCP2 | J41: =+COUNTIF('ID1&5'!G:G,'1. Status'!I41) -> 5 | K41: =+IFERROR(VLOOKUP(CONCATENATE(A41,$B$10,B41),'ID1&5'!B:J,8,FALSE),"-") -> - | L41: =+IFERROR(VLOOKUP(B41,'ID1&5'!K:L,2,FALSE),"-") -> - | M41: =+IFERROR(VLOOKUP(CONCATENATE(A41,$B$10,B41),'ID1&5'!B:J,9,FALSE),"-") -> - | N41: =+IFERROR(VLOOKUP(CONCATENATE(A41,$C$10,C41),'ID1&5'!B:J,8,FALSE),"-") -> - | O41: =+IFERROR(VLOOKUP(C41,'ID1&5'!K:L,2,FALSE),"-") -> - | P41: =+IFERROR(VLOOKUP(CONCATENATE(A41,$C$10,C41),'ID1&5'!B:J,9,FALSE),"-") -> - | Q41: =+IFERROR(VLOOKUP(D41,'ID1&5'!K:L,2,FALSE),"-") -> - | R41: =+IFERROR(VLOOKUP(CONCATENATE(A41,$D$10,D41),'ID1&5'!B:J,9,FALSE),"-") -> - | S41: =+IFERROR(VLOOKUP(E41,'ID1&5'!K:L,2,FALSE),"-") -> - | T41: =+IFERROR(VLOOKUP(CONCATENATE(A41,$E$10,E41),'ID1&5'!B:J,9,FALSE),"-") -> - | U41: =+IFERROR(VLOOKUP(F41,'ID1&5'!K:L,2,FALSE),"-") -> - | V41: =+IFERROR(VLOOKUP(CONCATENATE(A41,$F$10,F41),'ID1&5'!B:J,9,FALSE),"-") -> - | W41: =+IFERROR(VLOOKUP(A41,'ID6&7'!A:I,9,FALSE),"-") -> - | X41: =+IFERROR(VLOOKUP(A41,'ID6&7'!A:J,10,FALSE),"-") -> - | Z41: =+IF(J41=0,"Por iniciar",IF(OR(K41="-",M41="-",P41="-",R41="-",T41="-",V41="-"),"Em testes",IF(AND(M41=0,P41=0,R41=0,T41<>K41,V41<>K41),"OK","NOK"))) -> Em testes
A42: =+H42&I42&$I$8 -> ENTITYGRP_EMSSNS_SCP345596 | B42: {=+MAX(IF('ID1&5'!A:A='1. Status'!A42&'1. Status'!$B$10,'ID1&5'!K:K))} -> 0 | C42: {=+MAX(IF('ID1&5'!A:A='1. Status'!A42&'1. Status'!$C$10,'ID1&5'!K:K))} -> 0 | D42: {=+MAX(IF('ID1&5'!A:A='1. Status'!A42&'1. Status'!$D$10,'ID1&5'!K:K))} -> 0 | E42: {=+MAX(IF('ID1&5'!A:A='1. Status'!A42&'1. Status'!$E$10,'ID1&5'!K:K))} -> 0 | F42: {=+MAX(IF('ID1&5'!A:A='1. Status'!A42&'1. Status'!$F$10,'ID1&5'!K:K))} -> 0 | H42: ENTITY | I42: GRP_EMSSNS_SCP3 | J42: =+COUNTIF('ID1&5'!G:G,'1. Status'!I42) -> 5 | K42: =+IFERROR(VLOOKUP(CONCATENATE(A42,$B$10,B42),'ID1&5'!B:J,8,FALSE),"-") -> - | L42: =+IFERROR(VLOOKUP(B42,'ID1&5'!K:L,2,FALSE),"-") -> - | M42: =+IFERROR(VLOOKUP(CONCATENATE(A42,$B$10,B42),'ID1&5'!B:J,9,FALSE),"-") -> - | N42: =+IFERROR(VLOOKUP(CONCATENATE(A42,$C$10,C42),'ID1&5'!B:J,8,FALSE),"-") -> - | O42: =+IFERROR(VLOOKUP(C42,'ID1&5'!K:L,2,FALSE),"-") -> - | P42: =+IFERROR(VLOOKUP(CONCATENATE(A42,$C$10,C42),'ID1&5'!B:J,9,FALSE),"-") -> - | Q42: =+IFERROR(VLOOKUP(D42,'ID1&5'!K:L,2,FALSE),"-") -> - | R42: =+IFERROR(VLOOKUP(CONCATENATE(A42,$D$10,D42),'ID1&5'!B:J,9,FALSE),"-") -> - | S42: =+IFERROR(VLOOKUP(E42,'ID1&5'!K:L,2,FALSE),"-") -> - | T42: =+IFERROR(VLOOKUP(CONCATENATE(A42,$E$10,E42),'ID1&5'!B:J,9,FALSE),"-") -> - | U42: =+IFERROR(VLOOKUP(F42,'ID1&5'!K:L,2,FALSE),"-") -> - | V42: =+IFERROR(VLOOKUP(CONCATENATE(A42,$F$10,F42),'ID1&5'!B:J,9,FALSE),"-") -> - | W42: =+IFERROR(VLOOKUP(A42,'ID6&7'!A:I,9,FALSE),"-") -> - | X42: =+IFERROR(VLOOKUP(A42,'ID6&7'!A:J,10,FALSE),"-") -> - | Z42: =+IF(J42=0,"Por iniciar",IF(OR(K42="-",M42="-",P42="-",R42="-",T42="-",V42="-"),"Em testes",IF(AND(M42=0,P42=0,R42=0,T42<>K42,V42<>K42),"OK","NOK"))) -> Em testes
A43: =+H43&I43&$I$8 -> PROTECTIONTYP_EP_SCR45596 | B43: {=+MAX(IF('ID1&5'!A:A='1. Status'!A43&'1. Status'!$B$10,'ID1&5'!K:K))} -> 4 | C43: {=+MAX(IF('ID1&5'!A:A='1. Status'!A43&'1. Status'!$C$10,'ID1&5'!K:K))} -> 4 | D43: {=+MAX(IF('ID1&5'!A:A='1. Status'!A43&'1. Status'!$D$10,'ID1&5'!K:K))} -> 4 | E43: {=+MAX(IF('ID1&5'!A:A='1. Status'!A43&'1. Status'!$E$10,'ID1&5'!K:K))} -> 4 | F43: {=+MAX(IF('ID1&5'!A:A='1. Status'!A43&'1. Status'!$F$10,'ID1&5'!K:K))} -> 4 | H43: PROTECTION | I43: TYP_EP_SCR | J43: =+COUNTIF('ID1&5'!G:G,'1. Status'!I43) -> 5 | K43: =+IFERROR(VLOOKUP(CONCATENATE(A43,$B$10,B43),'ID1&5'!B:J,8,FALSE),"-") -> 475803 | L43: =+IFERROR(VLOOKUP(B43,'ID1&5'!K:L,2,FALSE),"-") -> 2024-12-04 18:14:01.919760000 | M43: =+IFERROR(VLOOKUP(CONCATENATE(A43,$B$10,B43),'ID1&5'!B:J,9,FALSE),"-") -> 0 | N43: =+IFERROR(VLOOKUP(CONCATENATE(A43,$C$10,C43),'ID1&5'!B:J,8,FALSE),"-") -> 475803 | O43: =+IFERROR(VLOOKUP(C43,'ID1&5'!K:L,2,FALSE),"-") -> 2024-12-04 18:14:01.919760000 | P43: =+IFERROR(VLOOKUP(CONCATENATE(A43,$C$10,C43),'ID1&5'!B:J,9,FALSE),"-") -> 0 | Q43: =+IFERROR(VLOOKUP(D43,'ID1&5'!K:L,2,FALSE),"-") -> 2024-12-04 18:14:01.919760000 | R43: =+IFERROR(VLOOKUP(CONCATENATE(A43,$D$10,D43),'ID1&5'!B:J,9,FALSE),"-") -> 0 | S43: =+IFERROR(VLOOKUP(E43,'ID1&5'!K:L,2,FALSE),"-") -> 2024-12-04 18:14:01.919760000 | T43: =+IFERROR(VLOOKUP(CONCATENATE(A43,$E$10,E43),'ID1&5'!B:J,9,FALSE),"-") -> 0 | U43: =+IFERROR(VLOOKUP(F43,'ID1&5'!K:L,2,FALSE),"-") -> 2024-12-04 18:14:01.919760000 | V43: =+IFERROR(VLOOKUP(CONCATENATE(A43,$F$10,F43),'ID1&5'!B:J,9,FALSE),"-") -> 201682 | W43: =+IFERROR(VLOOKUP(A43,'ID6&7'!A:I,9,FALSE),"-") -> EPSD2 | X43: =+IFERROR(VLOOKUP(A43,'ID6&7'!A:J,10,FALSE),"-") -> EPSD2 | Z43: =+IF(J43=0,"Por iniciar",IF(OR(K43="-",M43="-",P43="-",R43="-",T43="-",V43="-"),"Em testes",IF(AND(M43=0,P43=0,R43=0,T43<>K43,V43<>K43),"OK","NOK"))) -> OK
A44: =+H44&I44&$I$8 -> PROTECTIONEP_SCR45596 | B44: {=+MAX(IF('ID1&5'!A:A='1. Status'!A44&'1. Status'!$B$10,'ID1&5'!K:K))} -> 0 | C44: {=+MAX(IF('ID1&5'!A:A='1. Status'!A44&'1. Status'!$C$10,'ID1&5'!K:K))} -> 0 | D44: {=+MAX(IF('ID1&5'!A:A='1. Status'!A44&'1. Status'!$D$10,'ID1&5'!K:K))} -> 0 | E44: {=+MAX(IF('ID1&5'!A:A='1. Status'!A44&'1. Status'!$E$10,'ID1&5'!K:K))} -> 0 | F44: {=+MAX(IF('ID1&5'!A:A='1. Status'!A44&'1. Status'!$F$10,'ID1&5'!K:K))} -> 0 | H44: PROTECTION | I44: EP_SCR | J44: =+COUNTIF('ID1&5'!G:G,'1. Status'!I44) -> 0 | K44: =+IFERROR(VLOOKUP(CONCATENATE(A44,$B$10,B44),'ID1&5'!B:J,8,FALSE),"-") -> - | L44: =+IFERROR(VLOOKUP(B44,'ID1&5'!K:L,2,FALSE),"-") -> - | M44: =+IFERROR(VLOOKUP(CONCATENATE(A44,$B$10,B44),'ID1&5'!B:J,9,FALSE),"-") -> - | N44: =+IFERROR(VLOOKUP(CONCATENATE(A44,$C$10,C44),'ID1&5'!B:J,8,FALSE),"-") -> - | O44: =+IFERROR(VLOOKUP(C44,'ID1&5'!K:L,2,FALSE),"-") -> - | P44: =+IFERROR(VLOOKUP(CONCATENATE(A44,$C$10,C44),'ID1&5'!B:J,9,FALSE),"-") -> - | Q44: =+IFERROR(VLOOKUP(D44,'ID1&5'!K:L,2,FALSE),"-") -> - | R44: =+IFERROR(VLOOKUP(CONCATENATE(A44,$D$10,D44),'ID1&5'!B:J,9,FALSE),"-") -> - | S44: =+IFERROR(VLOOKUP(E44,'ID1&5'!K:L,2,FALSE),"-") -> - | T44: =+IFERROR(VLOOKUP(CONCATENATE(A44,$E$10,E44),'ID1&5'!B:J,9,FALSE),"-") -> - | U44: =+IFERROR(VLOOKUP(F44,'ID1&5'!K:L,2,FALSE),"-") -> - | V44: =+IFERROR(VLOOKUP(CONCATENATE(A44,$F$10,F44),'ID1&5'!B:J,9,FALSE),"-") -> - | W44: =+IFERROR(VLOOKUP(A44,'ID6&7'!A:I,9,FALSE),"-") -> EPSC1 | X44: =+IFERROR(VLOOKUP(A44,'ID6&7'!A:J,10,FALSE),"-") -> EPSC7 | Z44: =+IF(J44=0,"Por iniciar",IF(OR(K44="-",M44="-",P44="-",R44="-",T44="-",V44="-"),"Em testes",IF(AND(M44=0,P44=0,R44=0,T44<>K44,V44<>K44),"OK","NOK"))) -> Por iniciar
A45: =+H45&I45&$I$8 -> PROTECTIONTYP_EPC_LBL45596 | B45: {=+MAX(IF('ID1&5'!A:A='1. Status'!A45&'1. Status'!$B$10,'ID1&5'!K:K))} -> 0 | C45: {=+MAX(IF('ID1&5'!A:A='1. Status'!A45&'1. Status'!$C$10,'ID1&5'!K:K))} -> 0 | D45: {=+MAX(IF('ID1&5'!A:A='1. Status'!A45&'1. Status'!$D$10,'ID1&5'!K:K))} -> 0 | E45: {=+MAX(IF('ID1&5'!A:A='1. Status'!A45&'1. Status'!$E$10,'ID1&5'!K:K))} -> 0 | F45: {=+MAX(IF('ID1&5'!A:A='1. Status'!A45&'1. Status'!$F$10,'ID1&5'!K:K))} -> 0 | H45: PROTECTION | I45: TYP_EPC_LBL | J45: =+COUNTIF('ID1&5'!G:G,'1. Status'!I45) -> 5 | K45: =+IFERROR(VLOOKUP(CONCATENATE(A45,$B$10,B45),'ID1&5'!B:J,8,FALSE),"-") -> - | L45: =+IFERROR(VLOOKUP(B45,'ID1&5'!K:L,2,FALSE),"-") -> - | M45: =+IFERROR(VLOOKUP(CONCATENATE(A45,$B$10,B45),'ID1&5'!B:J,9,FALSE),"-") -> - | N45: =+IFERROR(VLOOKUP(CONCATENATE(A45,$C$10,C45),'ID1&5'!B:J,8,FALSE),"-") -> - | O45: =+IFERROR(VLOOKUP(C45,'ID1&5'!K:L,2,FALSE),"-") -> - | P45: =+IFERROR(VLOOKUP(CONCATENATE(A45,$C$10,C45),'ID1&5'!B:J,9,FALSE),"-") -> - | Q45: =+IFERROR(VLOOKUP(D45,'ID1&5'!K:L,2,FALSE),"-") -> - | R45: =+IFERROR(VLOOKUP(CONCATENATE(A45,$D$10,D45),'ID1&5'!B:J,9,FALSE),"-") -> - | S45: =+IFERROR(VLOOKUP(E45,'ID1&5'!K:L,2,FALSE),"-") -> - | T45: =+IFERROR(VLOOKUP(CONCATENATE(A45,$E$10,E45),'ID1&5'!B:J,9,FALSE),"-") -> - | U45: =+IFERROR(VLOOKUP(F45,'ID1&5'!K:L,2,FALSE),"-") -> - | V45: =+IFERROR(VLOOKUP(CONCATENATE(A45,$F$10,F45),'ID1&5'!B:J,9,FALSE),"-") -> - | W45: =+IFERROR(VLOOKUP(A45,'ID6&7'!A:I,9,FALSE),"-") -> - | X45: =+IFERROR(VLOOKUP(A45,'ID6&7'!A:J,10,FALSE),"-") -> - | Z45: =+IF(J45=0,"Por iniciar",IF(OR(K45="-",M45="-",P45="-",R45="-",T45="-",V45="-"),"Em testes",IF(AND(M45=0,P45=0,R45=0,T45<>K45,V45<>K45),"OK","NOK"))) -> Em testes
... A54: =+H54&I54&$I$8 -> PROTECTIONFLG_CHRNC_PHYSCL_RSK45596 | B54: {=+MAX(IF('ID1&5'!A:A='1. Status'!A54&'1. Status'!$B$10,'ID1&5'!K:K))} -> 0 | C54: {=+MAX(IF('ID1&5'!A:A='1. Status'!A54&'1. Status'!$C$10,'ID1&5'!K:K))} -> 0 | D54: {=+MAX(IF('ID1&5'!A:A='1. Status'!A54&'1. Status'!$D$10,'ID1&5'!K:K))} -> 0 | E54: {=+MAX(IF('ID1&5'!A:A='1. Status'!A54&'1. Status'!$E$10,'ID1&5'!K:K))} -> 0 | F54: {=+MAX(IF('ID1&5'!A:A='1. Status'!A54&'1. Status'!$F$10,'ID1&5'!K:K))} -> 0 | H54: PROTECTION | I54: FLG_CHRNC_PHYSCL_RSK | J54: =+COUNTIF('ID1&5'!G:G,'1. Status'!I54) -> 5 | K54: =+IFERROR(VLOOKUP(CONCATENATE(A54,$B$10,B54),'ID1&5'!B:J,8,FALSE),"-") -> - | L54: =+IFERROR(VLOOKUP(B54,'ID1&5'!K:L,2,FALSE),"-") -> - | M54: =+IFERROR(VLOOKUP(CONCATENATE(A54,$B$10,B54),'ID1&5'!B:J,9,FALSE),"-") -> - | N54: =+IFERROR(VLOOKUP(CONCATENATE(A54,$C$10,C54),'ID1&5'!B:J,8,FALSE),"-") -> - | O54: =+IFERROR(VLOOKUP(C54,'ID1&5'!K:L,2,FALSE),"-") -> - | P54: =+IFERROR(VLOOKUP(CONCATENATE(A54,$C$10,C54),'ID1&5'!B:J,9,FALSE),"-") -> - | Q54: =+IFERROR(VLOOKUP(D54,'ID1&5'!K:L,2,FALSE),"-") -> - | R54: =+IFERROR(VLOOKUP(CONCATENATE(A54,$D$10,D54),'ID1&5'!B:J,9,FALSE),"-") -> - | S54: =+IFERROR(VLOOKUP(E54,'ID1&5'!K:L,2,FALSE),"-") -> - | T54: =+IFERROR(VLOOKUP(CONCATENATE(A54,$E$10,E54),'ID1&5'!B:J,9,FALSE),"-") -> - | U54: =+IFERROR(VLOOKUP(F54,'ID1&5'!K:L,2,FALSE),"-") -> - | V54: =+IFERROR(VLOOKUP(CONCATENATE(A54,$F$10,F54),'ID1&5'!B:J,9,FALSE),"-") -> - | W54: =+IFERROR(VLOOKUP(A54,'ID6&7'!A:I,9,FALSE),"-") -> N | X54: =+IFERROR(VLOOKUP(A54,'ID6&7'!A:J,10,FALSE),"-") -> N | Z54: =+IF(J54=0,"Por iniciar",IF(OR(K54="-",M54="-",P54="-",R54="-",T54="-",V54="-"),"Em testes",IF(AND(M54=0,P54=0,R54=0,T54<>K54,V54<>K54),"OK","NOK"))) -> Em testes
