Workbook
Name IQ_CH: 110000
Name IQ_CQ: 5000
Name IQ_CY: 10000
Name IQ_DAILY: 500000
Name IQ_FH: 100000
Name IQ_FQ: 500
Name IQ_FY: 1000
Name IQ_LTM: 2000
Name IQ_MONTH: 15000
Name IQ_NTM: 6000
Name IQ_WEEK: 50000
Name IQ_YTD: 3000

Sheet Input
A1: stage | B1: contraparte | C1: vb_imp | D1: excluded_paris | E1: maturity | F1: cod_nace_esg | G1: asci | H1: gesi | I1: asc2 | J1: gesii | K1: asciii | L1: gesiii | M1: flag_nfrd | N1: sustainable_ccm | O1: aveg_aux
A2: stage 1 | B2: outras empresas nao financeiras | C2: valor bruto | D2: nao excluido | E2: -1 | F2: S95.1.2 | G2: 1016.75 | H2: 24190.19 | I2: 1016.75 | J2: 13150.05 | K2: 1016.75 | L2: 215389.98 | M2: NULL | N2: 0 | O2: NULL
A3: stage 3 | B3: outras empresas nao financeiras | C3: imparidade | D3: nao excluido | E3: 6 | F3: M72.1.9 | G3: -45227.58 | H3: NULL | I3: -45227.58 | J3: NULL | K3: -45227.58 | L3: NULL | M3: NULL | N3: 0 | O3: NULL
A4: stage 3 | B4: outras empresas nao financeiras | C4: imparidade | D4: nao excluido | E4: -1 | F4: C10.7.2 | G4: -6582.51 | H4: NULL | I4: -6582.51 | J4: NULL | K4: -6582.51 | L4: NULL | M4: NULL | N4: 0 | O4: NULL
A5: stage 2 | B5: outras empresas nao financeiras | C5: imparidade | D5: nao excluido | E5: 1 | F5: A1.2.2 | G5: -650.63 | H5: NULL | I5: -650.63 | J5: NULL | K5: -650.63 | L5: NULL | M5: NULL | N5: 0 | O5: NULL
A6: stage 1 | B6: outras empresas nao financeiras | C6: valor bruto | D6: nao excluido | E6: -1 | F6: C12.0.0 | G6: 2023937.8 | H6: -4.5296116e+08 | I6: 2023937.8 | J6: -3.0797176e+08 | K6: 2023937.8 | L6: -5.5201068e+09 | M6: NULL | N6: 0 | O6: NULL
A7: stage 2 | B7: outras empresas nao financeiras | C7: imparidade | D7: nao excluido | E7: 11 | F7: F41.2.0 | G7: -7213.06 | H7: NULL | I7: -7213.06 | J7: NULL | K7: -7213.06 | L7: NULL | M7: NULL | N7: 0 | O7: NULL
A8: stage 3 | B8: outras empresas nao financeiras | C8: imparidade | D8: nao excluido | E8: -1 | F8: C32.1.3 | G8: -634.77 | H8: NULL | I8: -634.77 | J8: NULL | K8: -634.77 | L8: NULL | M8: NULL | N8: 0 | O8: NULL
A9: stage 2 | B9: outras empresas nao financeiras | C9: imparidade | D9: nao excluido | E9: 11 | F9: G47.1.1 | G9: -1413.36 | H9: NULL | I9: -1413.36 | J9: NULL | K9: -1413.36 | L9: NULL | M9: NULL | N9: 0 | O9: NULL
A10: stage 2 | B10: outras empresas nao financeiras | C10: valor bruto | D10: nao excluido | E10: -1 | F10: N77.3.3 | G10: 0.03 | H10: 0.03 | I10: 0.03 | J10: 0.01 | K10: 0.03 | L10: 0.16 | M10: NULL | N10: 0 | O10: NULL
A11: stage 3 | B11: outras empresas nao financeiras | C11: imparidade | D11: nao excluido | E11: -4 | F11: C11.0.5 | G11: -57429.97 | H11: NULL | I11: -57429.97 | J11: NULL | K11: -57429.97 | L11: NULL | M11: NULL | N11: 0 | O11: NULL
A12: stage 3 | B12: outras empresas nao financeiras | C12: valor bruto | D12: nao excluido | E12: 7 | F12: G46.1.7 | G12: 255009.21 | H12: -46680025 | I12: 255009.21 | J12: -22172600 | K12: 255009.21 | L12: -2.1235607e+08 | M12: NULL | N12: 0 | O12: 1785064.5
A13: stage 2 | B13: outras empresas nao financeiras | C13: valor bruto | D13: nao excluido | E13: -1 | F13: F43.3.2 | G13: 817428.58 | H13: -36963441 | I13: 817428.58 | J13: -5193862.8 | K13: 817428.58 | L13: -2.8744477e+08 | M13: NULL | N13: 0 | O13: NULL
A14: stage 1 | B14: outras empresas nao financeiras | C14: imparidade | D14: nao excluido | E14: 3 | F14: C11.0.2 | G14: -21085.89 | H14: NULL | I14: -21085.89 | J14: NULL | K14: -21085.89 | L14: NULL | M14: NULL | N14: -497.69 | O14: NULL
A15: stage 3 | B15: outras empresas nao financeiras | C15: imparidade | D15: nao excluido | E15: -1 | F15: C26.5.1 | G15: -394.14 | H15: NULL | I15: -394.14 | J15: NULL | K15: -394.14 | L15: NULL | M15: NULL | N15: 0 | O15: NULL
A16: stage 3 | B16: outras empresas nao financeiras | C16: imparidade | D16: nao excluido | E16: -4 | F16: P85.2.0 | G16: -331.75 | H16: NULL | I16: -331.75 | J16: NULL | K16: -331.75 | L16: NULL | M16: NULL | N16: 0 | O16: NULL
A17: stage 3 | B17: outras empresas nao financeiras | C17: imparidade | D17: nao excluido | E17: 2 | F17: F42.2.2 | G17: -12037.6 | H17: NULL | I17: -12037.6 | J17: NULL | K17: -12037.6 | L17: NULL | M17: NULL | N17: 0 | O17: NULL
A18: stage 2 | B18: outras empresas nao financeiras | C18: valor bruto | D18: nao excluido | E18: -1 | F18: G46.5.2 | G18: 503658.26 | H18: -21408138 | I18: 503658.26 | J18: -10168677 | K18: 503658.26 | L18: -97389583 | M18: NULL | N18: 0 | O18: NULL
A19: stage 3 | B19: outras empresas nao financeiras | C19: imparidade | D19: nao excluido | E19: 17 | F19: H49.4.1 | G19: -52150.69 | H19: NULL | I19: -52150.69 | J19: NULL | K19: -52150.69 | L19: NULL | M19: NULL | N19: 0 | O19: NULL
A20: stage 2 | B20: outras empresas nao financeiras | C20: imparidade | D20: nao excluido | E20: 12 | F20: P85.1.0 | G20: -9655.93 | H20: NULL | I20: -9655.93 | J20: NULL | K20: -9655.93 | L20: NULL | M20: NULL | N20: 0 | O20: NULL
A21: stage 2 | B21: outras empresas nao financeiras | C21: valor bruto | D21: nao excluido | E21: 1 | F21: F43.3.4 | G21: 86295.61 | H21: -10814986 | I21: 86295.61 | J21: -1519651.6 | K21: 86295.61 | L21: -84102317 | M21: NULL | N21: 0 | O21: 86295.61
A22: stage 2 | B22: outras empresas nao financeiras | C22: valor bruto | D22: nao excluido | E22: 1 | F22: M73.1.1 | G22: 246121.47 | H22: -4575491.9 | I22: 246121.47 | J22: -2055558.9 | K22: 246121.47 | L22: -25628566 | M22: NULL | N22: 0 | O22: 246121.47
A23: stage 1 | B23: outras empresas nao financeiras | C23: imparidade | D23: nao excluido | E23: 0 | F23: N82.9.9 | G23: -36.82 | H23: NULL | I23: -36.82 | J23: NULL | K23: -36.82 | L23: NULL | M23: 1 | N23: -5.93 | O23: NULL
A24: stage 3 | B24: outras empresas nao financeiras | C24: valor bruto | D24: nao excluido | E24: -1 | F24: G47.6.2 | G24: 107475.31 | H24: -3065562.1 | I24: 107475.31 | J24: -1456122.9 | K24: 107475.31 | L24: -13945881 | M24: NULL | N24: 0 | O24: NULL
A25: stage 2 | B25: outras empresas nao financeiras | C25: imparidade | D25: nao excluido | E25: 12 | F25: G47.2.2 | G25: -1276.69 | H25: NULL | I25: -1276.69 | J25: NULL | K25: -1276.69 | L25: NULL | M25: NULL | N25: 0 | O25: NULL
A26: stage 1 | B26: outras empresas nao financeiras | C26: imparidade | D26: nao excluido | E26: -1 | F26: F41.1.0 | G26: -7714.96 | H26: NULL | I26: -7714.96 | J26: NULL | K26: -7714.96 | L26: NULL | M26: NULL | N26: 0 | O26: NULL
A27: stage 2 | B27: outras empresas nao financeiras | C27: valor bruto | D27: nao excluido | E27: 4 | F27: G46.3.9 | G27: 162283.11 | H27: -13185232 | I27: 162283.11 | J27: -6262870.2 | K27: 162283.11 | L27: -59982073 | M27: NULL | N27: 0 | O27: 649132.44
A28: stage 2 | B28: outras empresas nao financeiras | C28: imparidade | D28: nao excluido | E28: 9 | F28: Q86.9.0 | G28: -6953.81 | H28: NULL | I28: -6953.81 | J28: NULL | K28: -6953.81 | L28: NULL | M28: NULL | N28: 0 | O28: NULL
A29: stage 1 | B29: outras empresas nao financeiras | C29: imparidade | D29: nao excluido | E29: 2 | F29: G45.2.0 | G29: -16139.42 | H29: NULL | I29: -16139.42 | J29: NULL | K29: -16139.42 | L29: NULL | M29: NULL | N29: 0 | O29: NULL
A30: stage 1 | B30: outras empresas nao financeiras | C30: imparidade | D30: nao excluido | E30: -1 | F30: C24.3.3 | G30: -1.88 | H30: NULL | I30: -1.88 | J30: NULL | K30: -1.88 | L30: NULL | M30: NULL | N30: 0 | O30: NULL
A31: stage 1 | B31: outras empresas nao financeiras | C31: valor bruto | D31: nao excluido | E31: 1 | F31: I56.3.0 | G31: 3520666.2 | H31: -3.2993002e+08 | I31: 3520666.2 | J31: -1.5671429e+08 | K31: 3520666.2 | L31: -1.5009124e+09 | M31: NULL | N31: 0 | O31: 3520666.2
A32: stage 1 | B32: outras empresas nao financeiras | C32: imparidade | D32: nao excluido | E32: 5 | F32: A1.1.3 | G32: -1959.59 | H32: NULL | I32: -1959.59 | J32: NULL | K32: -1959.59 | L32: NULL | M32: NULL | N32: 0 | O32: NULL
A33: stage 1 | B33: outras empresas nao financeiras | C33: valor bruto | D33: nao excluido | E33: 6 | F33: C11.0.2 | G33: 3026399.7 | H33: -1.0414971e+08 | I33: 3026399.7 | J33: -70812186 | K33: 3026399.7 | L33: -1.2692424e+09 | M33: NULL | N33: 0 | O33: 18158398
A34: stage 1 | B34: outras empresas nao financeiras | C34: imparidade | D34: nao excluido | E34: 1 | F34: G47.2.4 | G34: -77.11 | H34: NULL | I34: -77.11 | J34: NULL | K34: -77.11 | L34: NULL | M34: NULL | N34: 0 | O34: NULL
A35: stage 2 | B35: outras empresas nao financeiras | C35: imparidade | D35: nao excluido | E35: -1 | F35: G46.3.6 | G35: -5702.18 | H35: NULL | I35: -5702.18 | J35: NULL | K35: -5702.18 | L35: NULL | M35: NULL | N35: 0 | O35: NULL
A36: stage 1 | B36: outras empresas nao financeiras | C36: imparidade | D36: nao excluido | E36: 9 | F36: F41.2.0 | G36: -4226.32 | H36: NULL | I36: -4226.32 | J36: NULL | K36: -4226.32 | L36: NULL | M36: NULL | N36: 0 | O36: NULL
A37: stage 1 | B37: outras empresas nao financeiras | C37: imparidade | D37: nao excluido | E37: 8 | F37: J62.0.9 | G37: -113.33 | H37: NULL | I37: -113.33 | J37: NULL | K37: -113.33 | L37: NULL | M37: NULL | N37: 0 | O37: NULL
A38: stage 1 | B38: outras empresas nao financeiras | C38: imparidade | D38: nao excluido | E38: -1 | F38: C28.2.9 | G38: -1529.15 | H38: NULL | I38: -1529.15 | J38: NULL | K38: -1529.15 | L38: NULL | M38: NULL | N38: 0 | O38: NULL
A39: stage 1 | B39: outras empresas nao financeiras | C39: valor bruto | D39: nao excluido | E39: 10 | F39: C32.9.9 | G39: 105596.43 | H39: -3.23 | I39: 105596.43 | J39: -17.37 | K39: 105596.43 | L39: NULL | M39: NULL | N39: 0 | O39: 1055964.3
A40: stage 1 | B40: outras empresas nao financeiras | C40: valor bruto | D40: nao excluido | E40: 6 | F40: F43.3.9 | G40: 140849.42 | H40: -2.46 | I40: 140849.42 | J40: -13.2 | K40: 140849.42 | L40: NULL | M40: NULL | N40: 0 | O40: 845096.52
...

Sheet 1.CC Transition risk-Banking b.
C2: Template 1: Banking book- Climate Change transition risk: Credit quality of exposures by sector, emissions and residual maturity
C3: Sector/subsector | D3: a | E3: b | F3: c | G3: d | H3: e | I3: f | J3: g | K3: h | L3: i | M3: j | N3: k | O3: l | P3: m | Q3: n | R3: o | S3: p
D4: Gross carrying amount (Mln EUR) | I4: Accumulated impairment, accumulated negative changes in fair value due to credit risk and provisions (Mln EUR) | L4: GHG financed emissions (scope 1, scope 2 and scope 3 emissions of the counterparty) (in tons of CO2 equivalent) | N4: GHG emissions (column i): gross carrying amount percentage of the portfolio derived from company-specific reporting | O4: <= 5 years | P4: > 5 year <= 10 years | Q4: > 10 year <= 20 years | R4: > 20 years | S4: Average weighted maturity
E5: Of which exposures towards companies excluded from EU Paris-aligned Benchmarks in accordance with points (d) to (g) of Article 12.1 and in accordance with Article 12.2 of Climate Benchmark Standards Regulation | F5: Of which environmentally sustainable (CCM) | G5: Of which stage 2 exposures | H5: Of which non-performing exposures | J5: Of which Stage 2 exposures | K5: Of which non-performing exposures | M5: Of which Scope 3 financed emissions
B6: 1 | C6: Exposures towards sectors that highly contribute to climate change* | D6: =D7+D8+D14+D39+D44+D45+D49+D50+D56+D57 -> 9111163681 | E6: =E7+E8+E14+E39+E44+E45+E49+E50+E56+E57 -> 75506660 | F6: =F7+F8+F14+F39+F44+F45+F49+F50+F56+F57 -> 0 | G6: =G7+G8+G14+G39+G44+G45+G49+G50+G56+G57 -> 855706527 | H6: =H7+H8+H14+H39+H44+H45+H49+H50+H56+H57 -> 410780539 | I6: =I7+I8+I14+I39+I44+I45+I49+I50+I56+I57 -> -308011446 | J6: =J7+J8+J14+J39+J44+J45+J49+J50+J56+J57 -> -48058964 | K6: =K7+K8+K14+K39+K44+K45+K49+K50+K56+K57 -> -239182941 | ... R6: =R7+R8+R14+R39+R44+R45+R49+R50+R56+R57 -> 64385951 | S6: =ROUND((SUMIFS(Input!$O:$O,Input!$F:$F,"A*",Input!$C:$C,'1.CC Transition risk-Banking b.'!S$63,Input!$E:$E,">0") + SUMIFS(Input!$O:$O,Input!$F:$F,"B*",Input!$C:$C,'1.CC Transition risk-Banking b.'!S$63,Input!$E:$E,">0") +SUMIFS(Input!$O:$O,Input!$F:$F,"C*",Input!$C:$C,'1.CC Transition risk-Banking b.'!S$63,Input!$E:$E,">0") +SUMIFS(Input!$O:$O,Input!$F:$F,"D*",Input!$C:$C,'1.CC Transition risk-Banking b.'!S$63,Input!$E:$E,">0") +SUMIFS(Input!$O:$O,Input!$F:$F,"E*",Input!$C:$C,'1.CC Transition risk-Banking b.'!S$63,Input!$E:$E,">0") +SUMIFS(Input!$O:$O,Input!$F:$F,"F*",Input!$C:$C,'1.CC Transition risk-Banking b.'!S$63,Input!$E:$E,">0") +SUMIFS(Input!$O:$O,Input!$F:$F,"G*",Input!$C:$C,'1.CC Transition risk-Banking b.'!S$63,Input!$E:$E,">0") +SUMIFS(Input!$O:$O,Input!$F:$F,"H*",Input!$C:$C,'1.CC Transition risk-Banking b.'!S$63,Input!$E:$E,">0") +SUMIFS(Input!$O:$O,Input!$F:$F,"I*",Input!$C:$C,'1.CC Transition risk-Banking b.'!S$63,Input!$E:$E,">0") +SUMIFS(Input!$O:$O,Input!$F:$F,"L*",Input!$C:$C,'1.CC Transition risk-Banking b.'!S$63,Input!$E:$E,">0"))/'1.CC Transition risk-Banking b.'!D6,0) -> 4
A7: A | B7: 2 | C7: A - Agriculture, forestry and fishing | D7: =ROUND(SUMIFS(Input!$G:$G,Input!$F:$F,'1.CC Transition risk-Banking b.'!$A7&"*",Input!$C:$C,'1.CC Transition risk-Banking b.'!$D$63),0) -> 320725763 | E7: =ROUND(SUMIFS(Input!$G:$G,Input!$F:$F,'1.CC Transition risk-Banking b.'!$A7&"*",Input!$C:$C,'1.CC Transition risk-Banking b.'!$E$63,Input!$D:$D,'1.CC Transition risk-Banking b.'!$E$64),0) -> 0 | F7: =ROUND(SUMIFS(Input!$N:$N,Input!$F:$F,'1.CC Transition risk-Banking b.'!$A7&"*",Input!$C:$C,'1.CC Transition risk-Banking b.'!$E$63,Input!$M:$M,'1.CC Transition risk-Banking b.'!$F$63),0) -> 0 | G7: =ROUND(SUMIFS(Input!$G:$G,Input!$F:$F,'1.CC Transition risk-Banking b.'!$A7&"*",Input!$C:$C,'1.CC Transition risk-Banking b.'!$G$63,Input!$A:$A,'1.CC Transition risk-Banking b.'!$G$64),0) -> 37981693 | H7: =ROUND(SUMIFS(Input!$G:$G,Input!$F:$F,'1.CC Transition risk-Banking b.'!$A7&"*",Input!$C:$C,'1.CC Transition risk-Banking b.'!$H$63,Input!$A:$A,'1.CC Transition risk-Banking b.'!$H$64),0) -> 24669209 | I7: =ROUND(SUMIFS(Input!$G:$G,Input!$F:$F,'1.CC Transition risk-Banking b.'!$A7&"*",Input!$C:$C,'1.CC Transition risk-Banking b.'!$I$63),0) -> -7224882 | J7: =ROUND(SUMIFS(Input!$G:$G,Input!$F:$F,'1.CC Transition risk-Banking b.'!$A7&"*",Input!$C:$C,'1.CC Transition risk-Banking b.'!$J$63,Input!$A:$A,'1.CC Transition risk-Banking b.'!$J$64),0) -> -2078722 | K7: =ROUND(SUMIFS(Input!$G:$G,Input!$F:$F,'1.CC Transition risk-Banking b.'!$A7&"*",Input!$C:$C,'1.CC Transition risk-Banking b.'!$K$63,Input!$A:$A,'1.CC Transition risk-Banking b.'!$K$64),0) -> -4261071 | L7: =ROUND(SUMIFS(Input!$H:$H,Input!$F:$F,'1.CC Transition risk-Banking b.'!$A7&"*") + SUMIFS(Input!$J:$J,Input!$F:$F,'1.CC Transition risk-Banking b.'!$A7&"*") +SUMIFS(Input!$L:$L,Input!$F:$F,'1.CC Transition risk-Banking b.'!$A7&"*"),0) -> -891302349047 | M7: =ROUND(SUMIFS(Input!$L:$L,Input!$F:$F,'1.CC Transition risk-Banking b.'!$A7&"*"),0) -> -243401221158 | N7: =SUMIFS(Input!$G:$G,Input!$F:$F,'1.CC Transition risk-Banking b.'!$A7&"*",Input!$H:$H,"<>0,0",Input!$J:$J,"<>0,0",Input!$L:$L,"<>0,0")/SUM(Input!$G:$G) -> 0.026104812 | O7: =ROUND(SUMIFS(Input!$G:$G,Input!$F:$F,'1.CC Transition risk-Banking b.'!$A7&"*",Input!$C:$C,'1.CC Transition risk-Banking b.'!O$63,Input!$E:$E,">=0",Input!$E:$E,"<=5") + SUMIFS(Input!$G:$G,Input!$F:$F,'1.CC Transition risk-Banking b.'!$A7&"*",Input!$C:$C,'1.CC Transition risk-Banking b.'!O$63,Input!$E:$E,"-4") + SUMIFS(Input!$G:$G,Input!$F:$F,'1.CC Transition risk-Banking b.'!$A7&"*",Input!$C:$C,'1.CC Transition risk-Banking b.'!O$63,Input!$E:$E,"-1"),0) -> 206066280 | P7: =ROUND(SUMIFS(Input!$G:$G,Input!$F:$F,'1.CC Transition risk-Banking b.'!$A7&"*",Input!$C:$C,'1.CC Transition risk-Banking b.'!P$63,Input!$E:$E,">5",Input!$E:$E,"<=10"),0) -> 58212723 | Q7: =ROUND(SUMIFS(Input!$G:$G,Input!$F:$F,'1.CC Transition risk-Banking b.'!$A7&"*",Input!$C:$C,'1.CC Transition risk-Banking b.'!Q$63,Input!$E:$E,">10",Input!$E:$E,"<=20"),0) -> 56446759 | R7: =ROUND(SUMIFS(Input!$G:$G,Input!$F:$F,'1.CC Transition risk-Banking b.'!$A7&"*",Input!$C:$C,'1.CC Transition risk-Banking b.'!R$63,Input!$E:$E,">20") + SUMIFS(Input!$G:$G,Input!$F:$F,'1.CC Transition risk-Banking b.'!$A7&"*",Input!$C:$C,'1.CC Transition risk-Banking b.'!R$63,Input!$E:$E,"-2") + SUMIFS(Input!$G:$G,Input!$F:$F,'1.CC Transition risk-Banking b.'!$A7&"*",Input!$C:$C,'1.CC Transition risk-Banking b.'!R$63,Input!$E:$E,"-3"),0) -> 0 | S7: =ROUND(IFERROR(SUMIFS(Input!$O:$O,Input!$F:$F,'1.CC Transition risk-Banking b.'!$A7&"*",Input!$C:$C,'1.CC Transition risk-Banking b.'!S$63,Input!$E:$E,">0")/'1.CC Transition risk-Banking b.'!$D7,0),0) -> 5
A8: B | B8: 3 | C8: B - Mining and quarrying | D8: =ROUND(SUMIFS(Input!$G:$G,Input!$F:$F,'1.CC Transition risk-Banking b.'!$A8&"*",Input!$C:$C,'1.CC Transition risk-Banking b.'!$D$63),0) -> 11344013 | E8: =ROUND(SUMIFS(Input!$G:$G,Input!$F:$F,'1.CC Transition risk-Banking b.'!$A8&"*",Input!$C:$C,'1.CC Transition risk-Banking b.'!$E$63,Input!$D:$D,'1.CC Transition risk-Banking b.'!$E$64),0) -> 0 | F8: =ROUND(SUMIFS(Input!$N:$N,Input!$F:$F,'1.CC Transition risk-Banking b.'!$A8&"*",Input!$C:$C,'1.CC Transition risk-Banking b.'!$E$63,Input!$M:$M,'1.CC Transition risk-Banking b.'!$F$63),0) -> 0 | G8: =ROUND(SUMIFS(Input!$G:$G,Input!$F:$F,'1.CC Transition risk-Banking b.'!$A8&"*",Input!$C:$C,'1.CC Transition risk-Banking b.'!$G$63,Input!$A:$A,'1.CC Transition risk-Banking b.'!$G$64),0) -> 1443978 | H8: =ROUND(SUMIFS(Input!$G:$G,Input!$F:$F,'1.CC Transition risk-Banking b.'!$A8&"*",Input!$C:$C,'1.CC Transition risk-Banking b.'!$H$63,Input!$A:$A,'1.CC Transition risk-Banking b.'!$H$64),0) -> 1796872 | I8: =ROUND(SUMIFS(Input!$G:$G,Input!$F:$F,'1.CC Transition risk-Banking b.'!$A8&"*",Input!$C:$C,'1.CC Transition risk-Banking b.'!$I$63),0) -> -1400921 | J8: =ROUND(SUMIFS(Input!$G:$G,Input!$F:$F,'1.CC Transition risk-Banking b.'!$A8&"*",Input!$C:$C,'1.CC Transition risk-Banking b.'!$J$63,Input!$A:$A,'1.CC Transition risk-Banking b.'!$J$64),0) -> -101810 | K8: =ROUND(SUMIFS(Input!$G:$G,Input!$F:$F,'1.CC Transition risk-Banking b.'!$A8&"*",Input!$C:$C,'1.CC Transition risk-Banking b.'!$K$63,Input!$A:$A,'1.CC Transition risk-Banking b.'!$K$64),0) -> -1266405 | L8: =ROUND(SUMIFS(Input!$H:$H,Input!$F:$F,'1.CC Transition risk-Banking b.'!$A8&"*") + SUMIFS(Input!$J:$J,Input!$F:$F,'1.CC Transition risk-Banking b.'!$A8&"*") +SUMIFS(Input!$L:$L,Input!$F:$F,'1.CC Transition risk-Banking b.'!$A8&"*"),0) -> -7328120516 | M8: =ROUND(SUMIFS(Input!$L:$L,Input!$F:$F,'1.CC Transition risk-Banking b.'!$A8&"*"),0) -> -2672585656 | N8: =SUMIFS(Input!$G:$G,Input!$F:$F,'1.CC Transition risk-Banking b.'!$A8&"*",Input!$H:$H,"<>0,0",Input!$J:$J,"<>0,0",Input!$L:$L,"<>0,0")/SUM(Input!$G:$G) -> 0.00087215533 | O8: =ROUND(SUMIFS(Input!$G:$G,Input!$F:$F,'1.CC Transition risk-Banking b.'!$A8&"*",Input!$C:$C,'1.CC Transition risk-Banking b.'!O$63,Input!$E:$E,">=0",Input!$E:$E,"<=5") + SUMIFS(Input!$G:$G,Input!$F:$F,'1.CC Transition risk-Banking b.'!$A8&"*",Input!$C:$C,'1.CC Transition risk-Banking b.'!O$63,Input!$E:$E,"-4") + SUMIFS(Input!$G:$G,Input!$F:$F,'1.CC Transition risk-Banking b.'!$A8&"*",Input!$C:$C,'1.CC Transition risk-Banking b.'!O$63,Input!$E:$E,"-1"),0) -> 10438796 | P8: =ROUND(SUMIFS(Input!$G:$G,Input!$F:$F,'1.CC Transition risk-Banking b.'!$A8&"*",Input!$C:$C,'1.CC Transition risk-Banking b.'!P$63,Input!$E:$E,">5",Input!$E:$E,"<=10"),0) -> 905217 | Q8: =ROUND(SUMIFS(Input!$G:$G,Input!$F:$F,'1.CC Transition risk-Banking b.'!$A8&"*",Input!$C:$C,'1.CC Transition risk-Banking b.'!Q$63,Input!$E:$E,">10",Input!$E:$E,"<=20"),0) -> 0 | R8: =ROUND(SUMIFS(Input!$G:$G,Input!$F:$F,'1.CC Transition risk-Banking b.'!$A8&"*",Input!$C:$C,'1.CC Transition risk-Banking b.'!R$63,Input!$E:$E,">20") + SUMIFS(Input!$G:$G,Input!$F:$F,'1.CC Transition risk-Banking b.'!$A8&"*",Input!$C:$C,'1.CC Transition risk-Banking b.'!R$63,Input!$E:$E,"-2") + SUMIFS(Input!$G:$G,Input!$F:$F,'1.CC Transition risk-Banking b.'!$A8&"*",Input!$C:$C,'1.CC Transition risk-Banking b.'!R$63,Input!$E:$E,"-3"),0) -> 0 | S8: =ROUND(IFERROR(SUMIFS(Input!$O:$O,Input!$F:$F,'1.CC Transition risk-Banking b.'!$A8&"*",Input!$C:$C,'1.CC Transition risk-Banking b.'!S$63,Input!$E:$E,">0")/'1.CC Transition risk-Banking b.'!$D8,0),0) -> 2
A9: B5 | B9: 4 | C9: B.05 - Mining of coal and lignite | D9: =ROUND(SUMIFS(Input!$G:$G,Input!$F:$F,'1.CC Transition risk-Banking b.'!$A9&"*",Input!$C:$C,'1.CC Transition risk-Banking b.'!$D$63),0) -> 0 | E9: =ROUND(SUMIFS(Input!$G:$G,Input!$F:$F,'1.CC Transition risk-Banking b.'!$A9&"*",Input!$C:$C,'1.CC Transition risk-Banking b.'!$E$63,Input!$D:$D,'1.CC Transition risk-Banking b.'!$E$64),0) -> 0 | F9: =ROUND(SUMIFS(Input!$N:$N,Input!$F:$F,'1.CC Transition risk-Banking b.'!$A9&"*",Input!$C:$C,'1.CC Transition risk-Banking b.'!$E$63,Input!$M:$M,'1.CC Transition risk-Banking b.'!$F$63),0) -> 0 | G9: =ROUND(SUMIFS(Input!$G:$G,Input!$F:$F,'1.CC Transition risk-Banking b.'!$A9&"*",Input!$C:$C,'1.CC Transition risk-Banking b.'!$G$63,Input!$A:$A,'1.CC Transition risk-Banking b.'!$G$64),0) -> 0 | H9: =ROUND(SUMIFS(Input!$G:$G,Input!$F:$F,'1.CC Transition risk-Banking b.'!$A9&"*",Input!$C:$C,'1.CC Transition risk-Banking b.'!$H$63,Input!$A:$A,'1.CC Transition risk-Banking b.'!$H$64),0) -> 0 | I9: =ROUND(SUMIFS(Input!$G:$G,Input!$F:$F,'1.CC Transition risk-Banking b.'!$A9&"*",Input!$C:$C,'1.CC Transition risk-Banking b.'!$I$63),0) -> 0 | J9: =ROUND(SUMIFS(Input!$G:$G,Input!$F:$F,'1.CC Transition risk-Banking b.'!$A9&"*",Input!$C:$C,'1.CC Transition risk-Banking b.'!$J$63,Input!$A:$A,'1.CC Transition risk-Banking b.'!$J$64),0) -> 0 | K9: =ROUND(SUMIFS(Input!$G:$G,Input!$F:$F,'1.CC Transition risk-Banking b.'!$A9&"*",Input!$C:$C,'1.CC Transition risk-Banking b.'!$K$63,Input!$A:$A,'1.CC Transition risk-Banking b.'!$K$64),0) -> 0 | L9: =ROUND(SUMIFS(Input!$H:$H,Input!$F:$F,'1.CC Transition risk-Banking b.'!$A9&"*") + SUMIFS(Input!$J:$J,Input!$F:$F,'1.CC Transition risk-Banking b.'!$A9&"*") +SUMIFS(Input!$L:$L,Input!$F:$F,'1.CC Transition risk-Banking b.'!$A9&"*"),0) -> 0 | M9: =ROUND(SUMIFS(Input!$L:$L,Input!$F:$F,'1.CC Transition risk-Banking b.'!$A9&"*"),0) -> 0 | N9: =SUMIFS(Input!$G:$G,Input!$F:$F,'1.CC Transition risk-Banking b.'!$A9&"*",Input!$H:$H,"<>0,0",Input!$J:$J,"<>0,0",Input!$L:$L,"<>0,0")/SUM(Input!$G:$G) -> 0 | O9: =ROUND(SUMIFS(Input!$G:$G,Input!$F:$F,'1.CC Transition risk-Banking b.'!$A9&"*",Input!$C:$C,'1.CC Transition risk-Banking b.'!O$63,Input!$E:$E,">=0",Input!$E:$E,"<=5") + SUMIFS(Input!$G:$G,Input!$F:$F,'1.CC Transition risk-Banking b.'!$A9&"*",Input!$C:$C,'1.CC Transition risk-Banking b.'!O$63,Input!$E:$E,"-4") + SUMIFS(Input!$G:$G,Input!$F:$F,'1.CC Transition risk-Banking b.'!$A9&"*",Input!$C:$C,'1.CC Transition risk-Banking b.'!O$63,Input!$E:$E,"-1"),0) -> 0 | P9: =ROUND(SUMIFS(Input!$G:$G,Input!$F:$F,'1.CC Transition risk-Banking b.'!$A9&"*",Input!$C:$C,'1.CC Transition risk-Banking b.'!P$63,Input!$E:$E,">5",Input!$E:$E,"<=10"),0) -> 0 | Q9: =ROUND(SUMIFS(Input!$G:$G,Input!$F:$F,'1.CC Transition risk-Banking b.'!$A9&"*",Input!$C:$C,'1.CC Transition risk-Banking b.'!Q$63,Input!$E:$E,">10",Input!$E:$E,"<=20"),0) -> 0 | R9: =ROUND(SUMIFS(Input!$G:$G,Input!$F:$F,'1.CC Transition risk-Banking b.'!$A9&"*",Input!$C:$C,'1.CC Transition risk-Banking b.'!R$63,Input!$E:$E,">20") + SUMIFS(Input!$G:$G,Input!$F:$F,'1.CC Transition risk-Banking b.'!$A9&"*",Input!$C:$C,'1.CC Transition risk-Banking b.'!R$63,Input!$E:$E,"-2") + SUMIFS(Input!$G:$G,Input!$F:$F,'1.CC Transition risk-Banking b.'!$A9&"*",Input!$C:$C,'1.CC Transition risk-Banking b.'!R$63,Input!$E:$E,"-3"),0) -> 0 | S9: =ROUND(IFERROR(SUMIFS(Input!$O:$O,Input!$F:$F,'1.CC Transition risk-Banking b.'!$A9&"*",Input!$C:$C,'1.CC Transition risk-Banking b.'!S$63,Input!$E:$E,">0")/'1.CC Transition risk-Banking b.'!$D9,0),0) -> 0
A10: B6 | B10: 5 | C10: B.06 - Extraction of crude petroleum and natural gas | D10: =ROUND(SUMIFS(Input!$G:$G,Input!$F:$F,'1.CC Transition risk-Banking b.'!$A10&"*",Input!$C:$C,'1.CC Transition risk-Banking b.'!$D$63),0) -> 0 | E10: =ROUND(SUMIFS(Input!$G:$G,Input!$F:$F,'1.CC Transition risk-Banking b.'!$A10&"*",Input!$C:$C,'1.CC Transition risk-Banking b.'!$E$63,Input!$D:$D,'1.CC Transition risk-Banking b.'!$E$64),0) -> 0 | F10: =ROUND(SUMIFS(Input!$N:$N,Input!$F:$F,'1.CC Transition risk-Banking b.'!$A10&"*",Input!$C:$C,'1.CC Transition risk-Banking b.'!$E$63,Input!$M:$M,'1.CC Transition risk-Banking b.'!$F$63),0) -> 0 | G10: =ROUND(SUMIFS(Input!$G:$G,Input!$F:$F,'1.CC Transition risk-Banking b.'!$A10&"*",Input!$C:$C,'1.CC Transition risk-Banking b.'!$G$63,Input!$A:$A,'1.CC Transition risk-Banking b.'!$G$64),0) -> 0 | H10: =ROUND(SUMIFS(Input!$G:$G,Input!$F:$F,'1.CC Transition risk-Banking b.'!$A10&"*",Input!$C:$C,'1.CC Transition risk-Banking b.'!$H$63,Input!$A:$A,'1.CC Transition risk-Banking b.'!$H$64),0) -> 0 | I10: =ROUND(SUMIFS(Input!$G:$G,Input!$F:$F,'1.CC Transition risk-Banking b.'!$A10&"*",Input!$C:$C,'1.CC Transition risk-Banking b.'!$I$63),0) -> 0 | J10: =ROUND(SUMIFS(Input!$G:$G,Input!$F:$F,'1.CC Transition risk-Banking b.'!$A10&"*",Input!$C:$C,'1.CC Transition risk-Banking b.'!$J$63,Input!$A:$A,'1.CC Transition risk-Banking b.'!$J$64),0) -> 0 | K10: =ROUND(SUMIFS(Input!$G:$G,Input!$F:$F,'1.CC Transition risk-Banking b.'!$A10&"*",Input!$C:$C,'1.CC Transition risk-Banking b.'!$K$63,Input!$A:$A,'1.CC Transition risk-Banking b.'!$K$64),0) -> 0 | L10: =ROUND(SUMIFS(Input!$H:$H,Input!$F:$F,'1.CC Transition risk-Banking b.'!$A10&"*") + SUMIFS(Input!$J:$J,Input!$F:$F,'1.CC Transition risk-Banking b.'!$A10&"*") +SUMIFS(Input!$L:$L,Input!$F:$F,'1.CC Transition risk-Banking b.'!$A10&"*"),0) -> 0 | M10: =ROUND(SUMIFS(Input!$L:$L,Input!$F:$F,'1.CC Transition risk-Banking b.'!$A10&"*"),0) -> 0 | N10: =SUMIFS(Input!$G:$G,Input!$F:$F,'1.CC Transition risk-Banking b.'!$A10&"*",Input!$H:$H,"<>0,0",Input!$J:$J,"<>0,0",Input!$L:$L,"<>0,0")/SUM(Input!$G:$G) -> 0 | O10: =ROUND(SUMIFS(Input!$G:$G,Input!$F:$F,'1.CC Transition risk-Banking b.'!$A10&"*",Input!$C:$C,'1.CC Transition risk-Banking b.'!O$63,Input!$E:$E,">=0",Input!$E:$E,"<=5") + SUMIFS(Input!$G:$G,Input!$F:$F,'1.CC Transition risk-Banking b.'!$A10&"*",Input!$C:$C,'1.CC Transition risk-Banking b.'!O$63,Input!$E:$E,"-4") + SUMIFS(Input!$G:$G,Input!$F:$F,'1.CC Transition risk-Banking b.'!$A10&"*",Input!$C:$C,'1.CC Transition risk-Banking b.'!O$63,Input!$E:$E,"-1"),0) -> 0 | P10: =ROUND(SUMIFS(Input!$G:$G,Input!$F:$F,'1.CC Transition risk-Banking b.'!$A10&"*",Input!$C:$C,'1.CC Transition risk-Banking b.'!P$63,Input!$E:$E,">5",Input!$E:$E,"<=10"),0) -> 0 | Q10: =ROUND(SUMIFS(Input!$G:$G,Input!$F:$F,'1.CC Transition risk-Banking b.'!$A10&"*",Input!$C:$C,'1.CC Transition risk-Banking b.'!Q$63,Input!$E:$E,">10",Input!$E:$E,"<=20"),0) -> 0 | R10: =ROUND(SUMIFS(Input!$G:$G,Input!$F:$F,'1.CC Transition risk-Banking b.'!$A10&"*",Input!$C:$C,'1.CC Transition risk-Banking b.'!R$63,Input!$E:$E,">20") + SUMIFS(Input!$G:$G,Input!$F:$F,'1.CC Transition risk-Banking b.'!$A10&"*",Input!$C:$C,'1.CC Transition risk-Banking b.'!R$63,Input!$E:$E,"-2") + SUMIFS(Input!$G:$G,Input!$F:$F,'1.CC Transition risk-Banking b.'!$A10&"*",Input!$C:$C,'1.CC Transition risk-Banking b.'!R$63,Input!$E:$E,"-3"),0) -> 0 | S10: =ROUND(IFERROR(SUMIFS(Input!$O:$O,Input!$F:$F,'1.CC Transition risk-Banking b.'!$A10&"*",Input!$C:$C,'1.CC Transition risk-Banking b.'!S$63,Input!$E:$E,">0")/'1.CC Transition risk-Banking b.'!$D10,0),0) -> 0
A11: B7 | B11: 6 | C11: B.07 - Mining of metal ores | D11: =ROUND(SUMIFS(Input!$G:$G,Input!$F:$F,'1.CC Transition risk-Banking b.'!$A11&"*",Input!$C:$C,'1.CC Transition risk-Banking b.'!$D$63),0) -> 141472 | E11: =ROUND(SUMIFS(Input!$G:$G,Input!$F:$F,'1.CC Transition risk-Banking b.'!$A11&"*",Input!$C:$C,'1.CC Transition risk-Banking b.'!$E$63,Input!$D:$D,'1.CC Transition risk-Banking b.'!$E$64),0) -> 0 | F11: =ROUND(SUMIFS(Input!$N:$N,Input!$F:$F,'1.CC Transition risk-Banking b.'!$A11&"*",Input!$C:$C,'1.CC Transition risk-Banking b.'!$E$63,Input!$M:$M,'1.CC Transition risk-Banking b.'!$F$63),0) -> 0 | G11: =ROUND(SUMIFS(Input!$G:$G,Input!$F:$F,'1.CC Transition risk-Banking b.'!$A11&"*",Input!$C:$C,'1.CC Transition risk-Banking b.'!$G$63,Input!$A:$A,'1.CC Transition risk-Banking b.'!$G$64),0) -> 0 | H11: =ROUND(SUMIFS(Input!$G:$G,Input!$F:$F,'1.CC Transition risk-Banking b.'!$A11&"*",Input!$C:$C,'1.CC Transition risk-Banking b.'!$H$63,Input!$A:$A,'1.CC Transition risk-Banking b.'!$H$64),0) -> 0 | I11: =ROUND(SUMIFS(Input!$G:$G,Input!$F:$F,'1.CC Transition risk-Banking b.'!$A11&"*",Input!$C:$C,'1.CC Transition risk-Banking b.'!$I$63),0) -> -135 | J11: =ROUND(SUMIFS(Input!$G:$G,Input!$F:$F,'1.CC Transition risk-Banking b.'!$A11&"*",Input!$C:$C,'1.CC Transition risk-Banking b.'!$J$63,Input!$A:$A,'1.CC Transition risk-Banking b.'!$J$64),0) -> 0 | K11: =ROUND(SUMIFS(Input!$G:$G,Input!$F:$F,'1.CC Transition risk-Banking b.'!$A11&"*",Input!$C:$C,'1.CC Transition risk-Banking b.'!$K$63,Input!$A:$A,'1.CC Transition risk-Banking b.'!$K$64),0) -> 0 | L11: =ROUND(SUMIFS(Input!$H:$H,Input!$F:$F,'1.CC Transition risk-Banking b.'!$A11&"*") + SUMIFS(Input!$J:$J,Input!$F:$F,'1.CC Transition risk-Banking b.'!$A11&"*") +SUMIFS(Input!$L:$L,Input!$F:$F,'1.CC Transition risk-Banking b.'!$A11&"*"),0) -> -941502 | M11: =ROUND(SUMIFS(Input!$L:$L,Input!$F:$F,'1.CC Transition risk-Banking b.'!$A11&"*"),0) -> -343369 | N11: =SUMIFS(Input!$G:$G,Input!$F:$F,'1.CC Transition risk-Banking b.'!$A11&"*",Input!$H:$H,"<>0,0",Input!$J:$J,"<>0,0",Input!$L:$L,"<>0,0")/SUM(Input!$G:$G) -> 1.2397297e-05 | O11: =ROUND(SUMIFS(Input!$G:$G,Input!$F:$F,'1.CC Transition risk-Banking b.'!$A11&"*",Input!$C:$C,'1.CC Transition risk-Banking b.'!O$63,Input!$E:$E,">=0",Input!$E:$E,"<=5") + SUMIFS(Input!$G:$G,Input!$F:$F,'1.CC Transition risk-Banking b.'!$A11&"*",Input!$C:$C,'1.CC Transition risk-Banking b.'!O$63,Input!$E:$E,"-4") + SUMIFS(Input!$G:$G,Input!$F:$F,'1.CC Transition risk-Banking b.'!$A11&"*",Input!$C:$C,'1.CC Transition risk-Banking b.'!O$63,Input!$E:$E,"-1"),0) -> 141472 | P11: =ROUND(SUMIFS(Input!$G:$G,Input!$F:$F,'1.CC Transition risk-Banking b.'!$A11&"*",Input!$C:$C,'1.CC Transition risk-Banking b.'!P$63,Input!$E:$E,">5",Input!$E:$E,"<=10"),0) -> 0 | Q11: =ROUND(SUMIFS(Input!$G:$G,Input!$F:$F,'1.CC Transition risk-Banking b.'!$A11&"*",Input!$C:$C,'1.CC Transition risk-Banking b.'!Q$63,Input!$E:$E,">10",Input!$E:$E,"<=20"),0) -> 0 | R11: =ROUND(SUMIFS(Input!$G:$G,Input!$F:$F,'1.CC Transition risk-Banking b.'!$A11&"*",Input!$C:$C,'1.CC Transition risk-Banking b.'!R$63,Input!$E:$E,">20") + SUMIFS(Input!$G:$G,Input!$F:$F,'1.CC Transition risk-Banking b.'!$A11&"*",Input!$C:$C,'1.CC Transition risk-Banking b.'!R$63,Input!$E:$E,"-2") + SUMIFS(Input!$G:$G,Input!$F:$F,'1.CC Transition risk-Banking b.'!$A11&"*",Input!$C:$C,'1.CC Transition risk-Banking b.'!R$63,Input!$E:$E,"-3"),0) -> 0 | S11: =ROUND(IFERROR(SUMIFS(Input!$O:$O,Input!$F:$F,'1.CC Transition risk-Banking b.'!$A11&"*",Input!$C:$C,'1.CC Transition risk-Banking b.'!S$63,Input!$E:$E,">0")/'1.CC Transition risk-Banking b.'!$D11,0),0) -> 0
A12: B8 | B12: 7 | C12: B.08 - Other mining and quarrying | D12: =ROUND(SUMIFS(Input!$G:$G,Input!$F:$F,'1.CC Transition risk-Banking b.'!$A12&"*",Input!$C:$C,'1.CC Transition risk-Banking b.'!$D$63),0) -> 11125977 | E12: =ROUND(SUMIFS(Input!$G:$G,Input!$F:$F,'1.CC Transition risk-Banking b.'!$A12&"*",Input!$C:$C,'1.CC Transition risk-Banking b.'!$E$63,Input!$D:$D,'1.CC Transition risk-Banking b.'!$E$64),0) -> 0 | F12: =ROUND(SUMIFS(Input!$N:$N,Input!$F:$F,'1.CC Transition risk-Banking b.'!$A12&"*",Input!$C:$C,'1.CC Transition risk-Banking b.'!$E$63,Input!$M:$M,'1.CC Transition risk-Banking b.'!$F$63),0) -> 0 | G12: =ROUND(SUMIFS(Input!$G:$G,Input!$F:$F,'1.CC Transition risk-Banking b.'!$A12&"*",Input!$C:$C,'1.CC Transition risk-Banking b.'!$G$63,Input!$A:$A,'1.CC Transition risk-Banking b.'!$G$64),0) -> 1367902 | H12: =ROUND(SUMIFS(Input!$G:$G,Input!$F:$F,'1.CC Transition risk-Banking b.'!$A12&"*",Input!$C:$C,'1.CC Transition risk-Banking b.'!$H$63,Input!$A:$A,'1.CC Transition risk-Banking b.'!$H$64),0) -> 1796392 | I12: =ROUND(SUMIFS(Input!$G:$G,Input!$F:$F,'1.CC Transition risk-Banking b.'!$A12&"*",Input!$C:$C,'1.CC Transition risk-Banking b.'!$I$63),0) -> -1399364 | J12: =ROUND(SUMIFS(Input!$G:$G,Input!$F:$F,'1.CC Transition risk-Banking b.'!$A12&"*",Input!$C:$C,'1.CC Transition risk-Banking b.'!$J$63,Input!$A:$A,'1.CC Transition risk-Banking b.'!$J$64),0) -> -100796 | K12: =ROUND(SUMIFS(Input!$G:$G,Input!$F:$F,'1.CC Transition risk-Banking b.'!$A12&"*",Input!$C:$C,'1.CC Transition risk-Banking b.'!$K$63,Input!$A:$A,'1.CC Transition risk-Banking b.'!$K$64),0) -> -1265998 | L12: =ROUND(SUMIFS(Input!$H:$H,Input!$F:$F,'1.CC Transition risk-Banking b.'!$A12&"*") + SUMIFS(Input!$J:$J,Input!$F:$F,'1.CC Transition risk-Banking b.'!$A12&"*") +SUMIFS(Input!$L:$L,Input!$F:$F,'1.CC Transition risk-Banking b.'!$A12&"*"),0) -> -7278338393 | M12: =ROUND(SUMIFS(Input!$L:$L,Input!$F:$F,'1.CC Transition risk-Banking b.'!$A12&"*"),0) -> -2654429950 | N12: =SUMIFS(Input!$G:$G,Input!$F:$F,'1.CC Transition risk-Banking b.'!$A12&"*",Input!$H:$H,"<>0,0",Input!$J:$J,"<>0,0",Input!$L:$L,"<>0,0")/SUM(Input!$G:$G) -> 0.00085316694 | O12: =ROUND(SUMIFS(Input!$G:$G,Input!$F:$F,'1.CC Transition risk-Banking b.'!$A12&"*",Input!$C:$C,'1.CC Transition risk-Banking b.'!O$63,Input!$E:$E,">=0",Input!$E:$E,"<=5") + SUMIFS(Input!$G:$G,Input!$F:$F,'1.CC Transition risk-Banking b.'!$A12&"*",Input!$C:$C,'1.CC Transition risk-Banking b.'!O$63,Input!$E:$E,"-4") + SUMIFS(Input!$G:$G,Input!$F:$F,'1.CC Transition risk-Banking b.'!$A12&"*",Input!$C:$C,'1.CC Transition risk-Banking b.'!O$63,Input!$E:$E,"-1"),0) -> 10220760 | P12: =ROUND(SUMIFS(Input!$G:$G,Input!$F:$F,'1.CC Transition risk-Banking b.'!$A12&"*",Input!$C:$C,'1.CC Transition risk-Banking b.'!P$63,Input!$E:$E,">5",Input!$E:$E,"<=10"),0) -> 905217 | Q12: =ROUND(SUMIFS(Input!$G:$G,Input!$F:$F,'1.CC Transition risk-Banking b.'!$A12&"*",Input!$C:$C,'1.CC Transition risk-Banking b.'!Q$63,Input!$E:$E,">10",Input!$E:$E,"<=20"),0) -> 0 | R12: =ROUND(SUMIFS(Input!$G:$G,Input!$F:$F,'1.CC Transition risk-Banking b.'!$A12&"*",Input!$C:$C,'1.CC Transition risk-Banking b.'!R$63,Input!$E:$E,">20") + SUMIFS(Input!$G:$G,Input!$F:$F,'1.CC Transition risk-Banking b.'!$A12&"*",Input!$C:$C,'1.CC Transition risk-Banking b.'!R$63,Input!$E:$E,"-2") + SUMIFS(Input!$G:$G,Input!$F:$F,'1.CC Transition risk-Banking b.'!$A12&"*",Input!$C:$C,'1.CC Transition risk-Banking b.'!R$63,Input!$E:$E,"-3"),0) -> 0 | S12: =ROUND(IFERROR(SUMIFS(Input!$O:$O,Input!$F:$F,'1.CC Transition risk-Banking b.'!$A12&"*",Input!$C:$C,'1.CC Transition risk-Banking b.'!S$63,Input!$E:$E,">0")/'1.CC Transition risk-Banking b.'!$D12,0),0) -> 2
A13: B9 | B13: 8 | C13: B.09 - Mining support service activities | D13: =ROUND(SUMIFS(Input!$G:$G,Input!$F:$F,'1.CC Transition risk-Banking b.'!$A13&"*",Input!$C:$C,'1.CC Transition risk-Banking b.'!$D$63),0) -> 76564 | E13: =ROUND(SUMIFS(Input!$G:$G,Input!$F:$F,'1.CC Transition risk-Banking b.'!$A13&"*",Input!$C:$C,'1.CC Transition risk-Banking b.'!$E$63,Input!$D:$D,'1.CC Transition risk-Banking b.'!$E$64),0) -> 0 | F13: =ROUND(SUMIFS(Input!$N:$N,Input!$F:$F,'1.CC Transition risk-Banking b.'!$A13&"*",Input!$C:$C,'1.CC Transition risk-Banking b.'!$E$63,Input!$M:$M,'1.CC Transition risk-Banking b.'!$F$63),0) -> 0 | G13: =ROUND(SUMIFS(Input!$G:$G,Input!$F:$F,'1.CC Transition risk-Banking b.'!$A13&"*",Input!$C:$C,'1.CC Transition risk-Banking b.'!$G$63,Input!$A:$A,'1.CC Transition risk-Banking b.'!$G$64),0) -> 76076 | H13: =ROUND(SUMIFS(Input!$G:$G,Input!$F:$F,'1.CC Transition risk-Banking b.'!$A13&"*",Input!$C:$C,'1.CC Transition risk-Banking b.'!$H$63,Input!$A:$A,'1.CC Transition risk-Banking b.'!$H$64),0) -> 480 | I13: =ROUND(SUMIFS(Input!$G:$G,Input!$F:$F,'1.CC Transition risk-Banking b.'!$A13&"*",Input!$C:$C,'1.CC Transition risk-Banking b.'!$I$63),0) -> -1422 | J13: =ROUND(SUMIFS(Input!$G:$G,Input!$F:$F,'1.CC Transition risk-Banking b.'!$A13&"*",Input!$C:$C,'1.CC Transition risk-Banking b.'!$J$63,Input!$A:$A,'1.CC Transition risk-Banking b.'!$J$64),0) -> -1014 | K13: =ROUND(SUMIFS(Input!$G:$G,Input!$F:$F,'1.CC Transition risk-Banking b.'!$A13&"*",Input!$C:$C,'1.CC Transition risk-Banking b.'!$K$63,Input!$A:$A,'1.CC Transition risk-Banking b.'!$K$64),0) -> -408 | L13: =ROUND(SUMIFS(Input!$H:$H,Input!$F:$F,'1.CC Transition risk-Banking b.'!$A13&"*") + SUMIFS(Input!$J:$J,Input!$F:$F,'1.CC Transition risk-Banking b.'!$A13&"*") +SUMIFS(Input!$L:$L,Input!$F:$F,'1.CC Transition risk-Banking b.'!$A13&"*"),0) -> -48840622 | M13: =ROUND(SUMIFS(Input!$L:$L,Input!$F:$F,'1.CC Transition risk-Banking b.'!$A13&"*"),0) -> -17812337 | N13: =SUMIFS(Input!$G:$G,Input!$F:$F,'1.CC Transition risk-Banking b.'!$A13&"*",Input!$H:$H,"<>0,0",Input!$J:$J,"<>0,0",Input!$L:$L,"<>0,0")/SUM(Input!$G:$G) -> 6.5910913e-06 | O13: =ROUND(SUMIFS(Input!$G:$G,Input!$F:$F,'1.CC Transition risk-Banking b.'!$A13&"*",Input!$C:$C,'1.CC Transition risk-Banking b.'!O$63,Input!$E:$E,">=0",Input!$E:$E,"<=5") + SUMIFS(Input!$G:$G,Input!$F:$F,'1.CC Transition risk-Banking b.'!$A13&"*",Input!$C:$C,'1.CC Transition risk-Banking b.'!O$63,Input!$E:$E,"-4") + SUMIFS(Input!$G:$G,Input!$F:$F,'1.CC Transition risk-Banking b.'!$A13&"*",Input!$C:$C,'1.CC Transition risk-Banking b.'!O$63,Input!$E:$E,"-1"),0) -> 76564 | P13: =ROUND(SUMIFS(Input!$G:$G,Input!$F:$F,'1.CC Transition risk-Banking b.'!$A13&"*",Input!$C:$C,'1.CC Transition risk-Banking b.'!P$63,Input!$E:$E,">5",Input!$E:$E,"<=10"),0) -> 0 | Q13: =ROUND(SUMIFS(Input!$G:$G,Input!$F:$F,'1.CC Transition risk-Banking b.'!$A13&"*",Input!$C:$C,'1.CC Transition risk-Banking b.'!Q$63,Input!$E:$E,">10",Input!$E:$E,"<=20"),0) -> 0 | R13: =ROUND(SUMIFS(Input!$G:$G,Input!$F:$F,'1.CC Transition risk-Banking b.'!$A13&"*",Input!$C:$C,'1.CC Transition risk-Banking b.'!R$63,Input!$E:$E,">20") + SUMIFS(Input!$G:$G,Input!$F:$F,'1.CC Transition risk-Banking b.'!$A13&"*",Input!$C:$C,'1.CC Transition risk-Banking b.'!R$63,Input!$E:$E,"-2") + SUMIFS(Input!$G:$G,Input!$F:$F,'1.CC Transition risk-Banking b.'!$A13&"*",Input!$C:$C,'1.CC Transition risk-Banking b.'!R$63,Input!$E:$E,"-3"),0) -> 0 | S13: =ROUND(IFERROR(SUMIFS(Input!$O:$O,Input!$F:$F,'1.CC Transition risk-Banking b.'!$A13&"*",Input!$C:$C,'1.CC Transition risk-Banking b.'!S$63,Input!$E:$E,">0")/'1.CC Transition risk-Banking b.'!$D13,0),0) -> 2
A14: C | B14: 9 | C14: C - Manufacturing | D14: =ROUND(SUMIFS(Input!$G:$G,Input!$F:$F,'1.CC Transition risk-Banking b.'!$A14&"*",Input!$C:$C,'1.CC Transition risk-Banking b.'!$D$63),0) -> 2094850423 | E14: =ROUND(SUMIFS(Input!$G:$G,Input!$F:$F,'1.CC Transition risk-Banking b.'!$A14&"*",Input!$C:$C,'1.CC Transition risk-Banking b.'!$E$63,Input!$D:$D,'1.CC Transition risk-Banking b.'!$E$64),0) -> 68395 | F14: =ROUND(SUMIFS(Input!$N:$N,Input!$F:$F,'1.CC Transition risk-Banking b.'!$A14&"*",Input!$C:$C,'1.CC Transition risk-Banking b.'!$E$63,Input!$M:$M,'1.CC Transition risk-Banking b.'!$F$63),0) -> 0 | G14: =ROUND(SUMIFS(Input!$G:$G,Input!$F:$F,'1.CC Transition risk-Banking b.'!$A14&"*",Input!$C:$C,'1.CC Transition risk-Banking b.'!$G$63,Input!$A:$A,'1.CC Transition risk-Banking b.'!$G$64),0) -> 221943903 | H14: =ROUND(SUMIFS(Input!$G:$G,Input!$F:$F,'1.CC Transition risk-Banking b.'!$A14&"*",Input!$C:$C,'1.CC Transition risk-Banking b.'!$H$63,Input!$A:$A,'1.CC Transition risk-Banking b.'!$H$64),0) -> 76175853 | I14: =ROUND(SUMIFS(Input!$G:$G,Input!$F:$F,'1.CC Transition risk-Banking b.'!$A14&"*",Input!$C:$C,'1.CC Transition risk-Banking b.'!$I$63),0) -> -72098161 | J14: =ROUND(SUMIFS(Input!$G:$G,Input!$F:$F,'1.CC Transition risk-Banking b.'!$A14&"*",Input!$C:$C,'1.CC Transition risk-Banking b.'!$J$63,Input!$A:$A,'1.CC Transition risk-Banking b.'!$J$64),0) -> -12014859 | K14: =ROUND(SUMIFS(Input!$G:$G,Input!$F:$F,'1.CC Transition risk-Banking b.'!$A14&"*",Input!$C:$C,'1.CC Transition risk-Banking b.'!$K$63,Input!$A:$A,'1.CC Transition risk-Banking b.'!$K$64),0) -> -54583787 | L14: =ROUND(SUMIFS(Input!$H:$H,Input!$F:$F,'1.CC Transition risk-Banking b.'!$A14&"*") + SUMIFS(Input!$J:$J,Input!$F:$F,'1.CC Transition risk-Banking b.'!$A14&"*") +SUMIFS(Input!$L:$L,Input!$F:$F,'1.CC Transition risk-Banking b.'!$A14&"*"),0) -> 451920967322 | M14: =ROUND(SUMIFS(Input!$L:$L,Input!$F:$F,'1.CC Transition risk-Banking b.'!$A14&"*"),0) -> 457247822901 | N14: =SUMIFS(Input!$G:$G,Input!$F:$F,'1.CC Transition risk-Banking b.'!$A14&"*",Input!$H:$H,"<>0,0",Input!$J:$J,"<>0,0",Input!$L:$L,"<>0,0")/SUM(Input!$G:$G) -> 0.16903076 | O14: =ROUND(SUMIFS(Input!$G:$G,Input!$F:$F,'1.CC Transition risk-Banking b.'!$A14&"*",Input!$C:$C,'1.CC Transition risk-Banking b.'!O$63,Input!$E:$E,">=0",Input!$E:$E,"<=5") + SUMIFS(Input!$G:$G,Input!$F:$F,'1.CC Transition risk-Banking b.'!$A14&"*",Input!$C:$C,'1.CC Transition risk-Banking b.'!O$63,Input!$E:$E,"-4") + SUMIFS(Input!$G:$G,Input!$F:$F,'1.CC Transition risk-Banking b.'!$A14&"*",Input!$C:$C,'1.CC Transition risk-Banking b.'!O$63,Input!$E:$E,"-1"),0) -> 1856402161 | P14: =ROUND(SUMIFS(Input!$G:$G,Input!$F:$F,'1.CC Transition risk-Banking b.'!$A14&"*",Input!$C:$C,'1.CC Transition risk-Banking b.'!P$63,Input!$E:$E,">5",Input!$E:$E,"<=10"),0) -> 191379780 | Q14: =ROUND(SUMIFS(Input!$G:$G,Input!$F:$F,'1.CC Transition risk-Banking b.'!$A14&"*",Input!$C:$C,'1.CC Transition risk-Banking b.'!Q$63,Input!$E:$E,">10",Input!$E:$E,"<=20"),0) -> 47032904 | R14: =ROUND(SUMIFS(Input!$G:$G,Input!$F:$F,'1.CC Transition risk-Banking b.'!$A14&"*",Input!$C:$C,'1.CC Transition risk-Banking b.'!R$63,Input!$E:$E,">20") + SUMIFS(Input!$G:$G,Input!$F:$F,'1.CC Transition risk-Banking b.'!$A14&"*",Input!$C:$C,'1.CC Transition risk-Banking b.'!R$63,Input!$E:$E,"-2") + SUMIFS(Input!$G:$G,Input!$F:$F,'1.CC Transition risk-Banking b.'!$A14&"*",Input!$C:$C,'1.CC Transition risk-Banking b.'!R$63,Input!$E:$E,"-3"),0) -> 35578 | S14: =ROUND(IFERROR(SUMIFS(Input!$O:$O,Input!$F:$F,'1.CC Transition risk-Banking b.'!$A14&"*",Input!$C:$C,'1.CC Transition risk-Banking b.'!S$63,Input!$E:$E,">0")/'1.CC Transition risk-Banking b.'!$D14,0),0) -> 2
A15: C10 | B15: 10 | C15: C.10 - Manufacture of food products | D15: =ROUND(SUMIFS(Input!$G:$G,Input!$F:$F,'1.CC Transition risk-Banking b.'!$A15&"*",Input!$C:$C,'1.CC Transition risk-Banking b.'!$D$63),0) -> 331487917 | E15: =ROUND(SUMIFS(Input!$G:$G,Input!$F:$F,'1.CC Transition risk-Banking b.'!$A15&"*",Input!$C:$C,'1.CC Transition risk-Banking b.'!$E$63,Input!$D:$D,'1.CC Transition risk-Banking b.'!$E$64),0) -> 0 | F15: =ROUND(SUMIFS(Input!$N:$N,Input!$F:$F,'1.CC Transition risk-Banking b.'!$A15&"*",Input!$C:$C,'1.CC Transition risk-Banking b.'!$E$63,Input!$M:$M,'1.CC Transition risk-Banking b.'!$F$63),0) -> 0 | G15: =ROUND(SUMIFS(Input!$G:$G,Input!$F:$F,'1.CC Transition risk-Banking b.'!$A15&"*",Input!$C:$C,'1.CC Transition risk-Banking b.'!$G$63,Input!$A:$A,'1.CC Transition risk-Banking b.'!$G$64),0) -> 34779456 | H15: =ROUND(SUMIFS(Input!$G:$G,Input!$F:$F,'1.CC Transition risk-Banking b.'!$A15&"*",Input!$C:$C,'1.CC Transition risk-Banking b.'!$H$63,Input!$A:$A,'1.CC Transition risk-Banking b.'!$H$64),0) -> 9265776 | I15: =ROUND(SUMIFS(Input!$G:$G,Input!$F:$F,'1.CC Transition risk-Banking b.'!$A15&"*",Input!$C:$C,'1.CC Transition risk-Banking b.'!$I$63),0) -> -8340009 | J15: =ROUND(SUMIFS(Input!$G:$G,Input!$F:$F,'1.CC Transition risk-Banking b.'!$A15&"*",Input!$C:$C,'1.CC Transition risk-Banking b.'!$J$63,Input!$A:$A,'1.CC Transition risk-Banking b.'!$J$64),0) -> -2077334 | K15: =ROUND(SUMIFS(Input!$G:$G,Input!$F:$F,'1.CC Transition risk-Banking b.'!$A15&"*",Input!$C:$C,'1.CC Transition risk-Banking b.'!$K$63,Input!$A:$A,'1.CC Transition risk-Banking b.'!$K$64),0) -> -5277566 | L15: =ROUND(SUMIFS(Input!$H:$H,Input!$F:$F,'1.CC Transition risk-Banking b.'!$A15&"*") + SUMIFS(Input!$J:$J,Input!$F:$F,'1.CC Transition risk-Banking b.'!$A15&"*") +SUMIFS(Input!$L:$L,Input!$F:$F,'1.CC Transition risk-Banking b.'!$A15&"*"),0) -> 1482877105382 | M15: =ROUND(SUMIFS(Input!$L:$L,Input!$F:$F,'1.CC Transition risk-Banking b.'!$A15&"*"),0) -> 1260455606750 | N15: =SUMIFS(Input!$G:$G,Input!$F:$F,'1.CC Transition risk-Banking b.'!$A15&"*",Input!$H:$H,"<>0,0",Input!$J:$J,"<>0,0",Input!$L:$L,"<>0,0")/SUM(Input!$G:$G) -> 0.028186809 | O15: =ROUND(SUMIFS(Input!$G:$G,Input!$F:$F,'1.CC Transition risk-Banking b.'!$A15&"*",Input!$C:$C,'1.CC Transition risk-Banking b.'!O$63,Input!$E:$E,">=0",Input!$E:$E,"<=5") + SUMIFS(Input!$G:$G,Input!$F:$F,'1.CC Transition risk-Banking b.'!$A15&"*",Input!$C:$C,'1.CC Transition risk-Banking b.'!O$63,Input!$E:$E,"-4") + SUMIFS(Input!$G:$G,Input!$F:$F,'1.CC Transition risk-Banking b.'!$A15&"*",Input!$C:$C,'1.CC Transition risk-Banking b.'!O$63,Input!$E:$E,"-1"),0) -> 293734088 | P15: =ROUND(SUMIFS(Input!$G:$G,Input!$F:$F,'1.CC Transition risk-Banking b.'!$A15&"*",Input!$C:$C,'1.CC Transition risk-Banking b.'!P$63,Input!$E:$E,">5",Input!$E:$E,"<=10"),0) -> 18580063 | Q15: =ROUND(SUMIFS(Input!$G:$G,Input!$F:$F,'1.CC Transition risk-Banking b.'!$A15&"*",Input!$C:$C,'1.CC Transition risk-Banking b.'!Q$63,Input!$E:$E,">10",Input!$E:$E,"<=20"),0) -> 19173766 | R15: =ROUND(SUMIFS(Input!$G:$G,Input!$F:$F,'1.CC Transition risk-Banking b.'!$A15&"*",Input!$C:$C,'1.CC Transition risk-Banking b.'!R$63,Input!$E:$E,">20") + SUMIFS(Input!$G:$G,Input!$F:$F,'1.CC Transition risk-Banking b.'!$A15&"*",Input!$C:$C,'1.CC Transition risk-Banking b.'!R$63,Input!$E:$E,"-2") + SUMIFS(Input!$G:$G,Input!$F:$F,'1.CC Transition risk-Banking b.'!$A15&"*",Input!$C:$C,'1.CC Transition risk-Banking b.'!R$63,Input!$E:$E,"-3"),0) -> 0 | S15: =ROUND(IFERROR(SUMIFS(Input!$O:$O,Input!$F:$F,'1.CC Transition risk-Banking b.'!$A15&"*",Input!$C:$C,'1.CC Transition risk-Banking b.'!S$63,Input!$E:$E,">0")/'1.CC Transition risk-Banking b.'!$D15,0),0) -> 2
A16: C11 | B16: 11 | C16: C.11 - Manufacture of beverages | D16: =ROUND(SUMIFS(Input!$G:$G,Input!$F:$F,'1.CC Transition risk-Banking b.'!$A16&"*",Input!$C:$C,'1.CC Transition risk-Banking b.'!$D$63),0) -> 207277488 | E16: =ROUND(SUMIFS(Input!$G:$G,Input!$F:$F,'1.CC Transition risk-Banking b.'!$A16&"*",Input!$C:$C,'1.CC Transition risk-Banking b.'!$E$63,Input!$D:$D,'1.CC Transition risk-Banking b.'!$E$64),0) -> 0 | F16: =ROUND(SUMIFS(Input!$N:$N,Input!$F:$F,'1.CC Transition risk-Banking b.'!$A16&"*",Input!$C:$C,'1.CC Transition risk-Banking b.'!$E$63,Input!$M:$M,'1.CC Transition risk-Banking b.'!$F$63),0) -> 0 | G16: =ROUND(SUMIFS(Input!$G:$G,Input!$F:$F,'1.CC Transition risk-Banking b.'!$A16&"*",Input!$C:$C,'1.CC Transition risk-Banking b.'!$G$63,Input!$A:$A,'1.CC Transition risk-Banking b.'!$G$64),0) -> 7491394 | H16: =ROUND(SUMIFS(Input!$G:$G,Input!$F:$F,'1.CC Transition risk-Banking b.'!$A16&"*",Input!$C:$C,'1.CC Transition risk-Banking b.'!$H$63,Input!$A:$A,'1.CC Transition risk-Banking b.'!$H$64),0) -> 396421 | I16: =ROUND(SUMIFS(Input!$G:$G,Input!$F:$F,'1.CC Transition risk-Banking b.'!$A16&"*",Input!$C:$C,'1.CC Transition risk-Banking b.'!$I$63),0) -> -1107363 | J16: =ROUND(SUMIFS(Input!$G:$G,Input!$F:$F,'1.CC Transition risk-Banking b.'!$A16&"*",Input!$C:$C,'1.CC Transition risk-Banking b.'!$J$63,Input!$A:$A,'1.CC Transition risk-Banking b.'!$J$64),0) -> -450906 | K16: =ROUND(SUMIFS(Input!$G:$G,Input!$F:$F,'1.CC Transition risk-Banking b.'!$A16&"*",Input!$C:$C,'1.CC Transition risk-Banking b.'!$K$63,Input!$A:$A,'1.CC Transition risk-Banking b.'!$K$64),0) -> -302535 | L16: =ROUND(SUMIFS(Input!$H:$H,Input!$F:$F,'1.CC Transition risk-Banking b.'!$A16&"*") + SUMIFS(Input!$J:$J,Input!$F:$F,'1.CC Transition risk-Banking b.'!$A16&"*") +SUMIFS(Input!$L:$L,Input!$F:$F,'1.CC Transition risk-Banking b.'!$A16&"*"),0) -> -686236020474 | M16: =ROUND(SUMIFS(Input!$L:$L,Input!$F:$F,'1.CC Transition risk-Banking b.'!$A16&"*"),0) -> -603105708595 | N16: =SUMIFS(Input!$G:$G,Input!$F:$F,'1.CC Transition risk-Banking b.'!$A16&"*",Input!$H:$H,"<>0,0",Input!$J:$J,"<>0,0",Input!$L:$L,"<>0,0")/SUM(Input!$G:$G) -> 0.01016754 | O16: =ROUND(SUMIFS(Input!$G:$G,Input!$F:$F,'1.CC Transition risk-Banking b.'!$A16&"*",Input!$C:$C,'1.CC Transition risk-Banking b.'!O$63,Input!$E:$E,">=0",Input!$E:$E,"<=5") + SUMIFS(Input!$G:$G,Input!$F:$F,'1.CC Transition risk-Banking b.'!$A16&"*",Input!$C:$C,'1.CC Transition risk-Banking b.'!O$63,Input!$E:$E,"-4") + SUMIFS(Input!$G:$G,Input!$F:$F,'1.CC Transition risk-Banking b.'!$A16&"*",Input!$C:$C,'1.CC Transition risk-Banking b.'!O$63,Input!$E:$E,"-1"),0) -> 137853215 | P16: =ROUND(SUMIFS(Input!$G:$G,Input!$F:$F,'1.CC Transition risk-Banking b.'!$A16&"*",Input!$C:$C,'1.CC Transition risk-Banking b.'!P$63,Input!$E:$E,">5",Input!$E:$E,"<=10"),0) -> 68582633 | Q16: =ROUND(SUMIFS(Input!$G:$G,Input!$F:$F,'1.CC Transition risk-Banking b.'!$A16&"*",Input!$C:$C,'1.CC Transition risk-Banking b.'!Q$63,Input!$E:$E,">10",Input!$E:$E,"<=20"),0) -> 841641 | R16: =ROUND(SUMIFS(Input!$G:$G,Input!$F:$F,'1.CC Transition risk-Banking b.'!$A16&"*",Input!$C:$C,'1.CC Transition risk-Banking b.'!R$63,Input!$E:$E,">20") + SUMIFS(Input!$G:$G,Input!$F:$F,'1.CC Transition risk-Banking b.'!$A16&"*",Input!$C:$C,'1.CC Transition risk-Banking b.'!R$63,Input!$E:$E,"-2") + SUMIFS(Input!$G:$G,Input!$F:$F,'1.CC Transition risk-Banking b.'!$A16&"*",Input!$C:$C,'1.CC Transition risk-Banking b.'!R$63,Input!$E:$E,"-3"),0) -> 0 | S16: =ROUND(IFERROR(SUMIFS(Input!$O:$O,Input!$F:$F,'1.CC Transition risk-Banking b.'!$A16&"*",Input!$C:$C,'1.CC Transition risk-Banking b.'!S$63,Input!$E:$E,">0")/'1.CC Transition risk-Banking b.'!$D16,0),0) -> 3
A17: C12 | B17: 12 | C17: C.12 - Manufacture of tobacco products | D17: =ROUND(SUMIFS(Input!$G:$G,Input!$F:$F,'1.CC Transition risk-Banking b.'!$A17&"*",Input!$C:$C,'1.CC Transition risk-Banking b.'!$D$63),0) -> 2924771 | E17: =ROUND(SUMIFS(Input!$G:$G,Input!$F:$F,'1.CC Transition risk-Banking b.'!$A17&"*",Input!$C:$C,'1.CC Transition risk-Banking b.'!$E$63,Input!$D:$D,'1.CC Transition risk-Banking b.'!$E$64),0) -> 0 | F17: =ROUND(SUMIFS(Input!$N:$N,Input!$F:$F,'1.CC Transition risk-Banking b.'!$A17&"*",Input!$C:$C,'1.CC Transition risk-Banking b.'!$E$63,Input!$M:$M,'1.CC Transition risk-Banking b.'!$F$63),0) -> 0 | G17: =ROUND(SUMIFS(Input!$G:$G,Input!$F:$F,'1.CC Transition risk-Banking b.'!$A17&"*",Input!$C:$C,'1.CC Transition risk-Banking b.'!$G$63,Input!$A:$A,'1.CC Transition risk-Banking b.'!$G$64),0) -> 0 | H17: =ROUND(SUMIFS(Input!$G:$G,Input!$F:$F,'1.CC Transition risk-Banking b.'!$A17&"*",Input!$C:$C,'1.CC Transition risk-Banking b.'!$H$63,Input!$A:$A,'1.CC Transition risk-Banking b.'!$H$64),0) -> 0 | I17: =ROUND(SUMIFS(Input!$G:$G,Input!$F:$F,'1.CC Transition risk-Banking b.'!$A17&"*",Input!$C:$C,'1.CC Transition risk-Banking b.'!$I$63),0) -> -10149 | J17: =ROUND(SUMIFS(Input!$G:$G,Input!$F:$F,'1.CC Transition risk-Banking b.'!$A17&"*",Input!$C:$C,'1.CC Transition risk-Banking b.'!$J$63,Input!$A:$A,'1.CC Transition risk-Banking b.'!$J$64),0) -> 0 | K17: =ROUND(SUMIFS(Input!$G:$G,Input!$F:$F,'1.CC Transition risk-Banking b.'!$A17&"*",Input!$C:$C,'1.CC Transition risk-Banking b.'!$K$63,Input!$A:$A,'1.CC Transition risk-Banking b.'!$K$64),0) -> 0 | L17: =ROUND(SUMIFS(Input!$H:$H,Input!$F:$F,'1.CC Transition risk-Banking b.'!$A17&"*") + SUMIFS(Input!$J:$J,Input!$F:$F,'1.CC Transition risk-Banking b.'!$A17&"*") +SUMIFS(Input!$L:$L,Input!$F:$F,'1.CC Transition risk-Banking b.'!$A17&"*"),0) -> 67680230179 | M17: =ROUND(SUMIFS(Input!$L:$L,Input!$F:$F,'1.CC Transition risk-Banking b.'!$A17&"*"),0) -> 59480933226 | N17: =SUMIFS(Input!$G:$G,Input!$F:$F,'1.CC Transition risk-Banking b.'!$A17&"*",Input!$H:$H,"<>0,0",Input!$J:$J,"<>0,0",Input!$L:$L,"<>0,0")/SUM(Input!$G:$G) -> 0.00025565521 | O17: =ROUND(SUMIFS(Input!$G:$G,Input!$F:$F,'1.CC Transition risk-Banking b.'!$A17&"*",Input!$C:$C,'1.CC Transition risk-Banking b.'!O$63,Input!$E:$E,">=0",Input!$E:$E,"<=5") + SUMIFS(Input!$G:$G,Input!$F:$F,'1.CC Transition risk-Banking b.'!$A17&"*",Input!$C:$C,'1.CC Transition risk-Banking b.'!O$63,Input!$E:$E,"-4") + SUMIFS(Input!$G:$G,Input!$F:$F,'1.CC Transition risk-Banking b.'!$A17&"*",Input!$C:$C,'1.CC Transition risk-Banking b.'!O$63,Input!$E:$E,"-1"),0) -> 2924771 | P17: =ROUND(SUMIFS(Input!$G:$G,Input!$F:$F,'1.CC Transition risk-Banking b.'!$A17&"*",Input!$C:$C,'1.CC Transition risk-Banking b.'!P$63,Input!$E:$E,">5",Input!$E:$E,"<=10"),0) -> 0 | Q17: =ROUND(SUMIFS(Input!$G:$G,Input!$F:$F,'1.CC Transition risk-Banking b.'!$A17&"*",Input!$C:$C,'1.CC Transition risk-Banking b.'!Q$63,Input!$E:$E,">10",Input!$E:$E,"<=20"),0) -> 0 | R17: =ROUND(SUMIFS(Input!$G:$G,Input!$F:$F,'1.CC Transition risk-Banking b.'!$A17&"*",Input!$C:$C,'1.CC Transition risk-Banking b.'!R$63,Input!$E:$E,">20") + SUMIFS(Input!$G:$G,Input!$F:$F,'1.CC Transition risk-Banking b.'!$A17&"*",Input!$C:$C,'1.CC Transition risk-Banking b.'!R$63,Input!$E:$E,"-2") + SUMIFS(Input!$G:$G,Input!$F:$F,'1.CC Transition risk-Banking b.'!$A17&"*",Input!$C:$C,'1.CC Transition risk-Banking b.'!R$63,Input!$E:$E,"-3"),0) -> 0 | S17: =ROUND(IFERROR(SUMIFS(Input!$O:$O,Input!$F:$F,'1.CC Transition risk-Banking b.'!$A17&"*",Input!$C:$C,'1.CC Transition risk-Banking b.'!S$63,Input!$E:$E,">0")/'1.CC Transition risk-Banking b.'!$D17,0),0) -> 0
A18: C13 | B18: 13 | C18: C.13 - Manufacture of textiles | D18: =ROUND(SUMIFS(Input!$G:$G,Input!$F:$F,'1.CC Transition risk-Banking b.'!$A18&"*",Input!$C:$C,'1.CC Transition risk-Banking b.'!$D$63),0) -> 108615628 | E18: =ROUND(SUMIFS(Input!$G:$G,Input!$F:$F,'1.CC Transition risk-Banking b.'!$A18&"*",Input!$C:$C,'1.CC Transition risk-Banking b.'!$E$63,Input!$D:$D,'1.CC Transition risk-Banking b.'!$E$64),0) -> 0 | F18: =ROUND(SUMIFS(Input!$N:$N,Input!$F:$F,'1.CC Transition risk-Banking b.'!$A18&"*",Input!$C:$C,'1.CC Transition risk-Banking b.'!$E$63,Input!$M:$M,'1.CC Transition risk-Banking b.'!$F$63),0) -> 0 | G18: =ROUND(SUMIFS(Input!$G:$G,Input!$F:$F,'1.CC Transition risk-Banking b.'!$A18&"*",Input!$C:$C,'1.CC Transition risk-Banking b.'!$G$63,Input!$A:$A,'1.CC Transition risk-Banking b.'!$G$64),0) -> 16418215 | H18: =ROUND(SUMIFS(Input!$G:$G,Input!$F:$F,'1.CC Transition risk-Banking b.'!$A18&"*",Input!$C:$C,'1.CC Transition risk-Banking b.'!$H$63,Input!$A:$A,'1.CC Transition risk-Banking b.'!$H$64),0) -> 2860603 | I18: =ROUND(SUMIFS(Input!$G:$G,Input!$F:$F,'1.CC Transition risk-Banking b.'!$A18&"*",Input!$C:$C,'1.CC Transition risk-Banking b.'!$I$63),0) -> -4058046 | J18: =ROUND(SUMIFS(Input!$G:$G,Input!$F:$F,'1.CC Transition risk-Banking b.'!$A18&"*",Input!$C:$C,'1.CC Transition risk-Banking b.'!$J$63,Input!$A:$A,'1.CC Transition risk-Banking b.'!$J$64),0) -> -1171639 | K18: =ROUND(SUMIFS(Input!$G:$G,Input!$F:$F,'1.CC Transition risk-Banking b.'!$A18&"*",Input!$C:$C,'1.CC Transition risk-Banking b.'!$K$63,Input!$A:$A,'1.CC Transition risk-Banking b.'!$K$64),0) -> -2402417 | L18: =ROUND(SUMIFS(Input!$H:$H,Input!$F:$F,'1.CC Transition risk-Banking b.'!$A18&"*") + SUMIFS(Input!$J:$J,Input!$F:$F,'1.CC Transition risk-Banking b.'!$A18&"*") +SUMIFS(Input!$L:$L,Input!$F:$F,'1.CC Transition risk-Banking b.'!$A18&"*"),0) -> -32782773402 | M18: =ROUND(SUMIFS(Input!$L:$L,Input!$F:$F,'1.CC Transition risk-Banking b.'!$A18&"*"),0) -> -29721390031 | N18: =SUMIFS(Input!$G:$G,Input!$F:$F,'1.CC Transition risk-Banking b.'!$A18&"*",Input!$H:$H,"<>0,0",Input!$J:$J,"<>0,0",Input!$L:$L,"<>0,0")/SUM(Input!$G:$G) -> 0.0091710002 | O18: =ROUND(SUMIFS(Input!$G:$G,Input!$F:$F,'1.CC Transition risk-Banking b.'!$A18&"*",Input!$C:$C,'1.CC Transition risk-Banking b.'!O$63,Input!$E:$E,">=0",Input!$E:$E,"<=5") + SUMIFS(Input!$G:$G,Input!$F:$F,'1.CC Transition risk-Banking b.'!$A18&"*",Input!$C:$C,'1.CC Transition risk-Banking b.'!O$63,Input!$E:$E,"-4") + SUMIFS(Input!$G:$G,Input!$F:$F,'1.CC Transition risk-Banking b.'!$A18&"*",Input!$C:$C,'1.CC Transition risk-Banking b.'!O$63,Input!$E:$E,"-1"),0) -> 102478778 | P18: =ROUND(SUMIFS(Input!$G:$G,Input!$F:$F,'1.CC Transition risk-Banking b.'!$A18&"*",Input!$C:$C,'1.CC Transition risk-Banking b.'!P$63,Input!$E:$E,">5",Input!$E:$E,"<=10"),0) -> 3999929 | Q18: =ROUND(SUMIFS(Input!$G:$G,Input!$F:$F,'1.CC Transition risk-Banking b.'!$A18&"*",Input!$C:$C,'1.CC Transition risk-Banking b.'!Q$63,Input!$E:$E,">10",Input!$E:$E,"<=20"),0) -> 2136921 | R18: =ROUND(SUMIFS(Input!$G:$G,Input!$F:$F,'1.CC Transition risk-Banking b.'!$A18&"*",Input!$C:$C,'1.CC Transition risk-Banking b.'!R$63,Input!$E:$E,">20") + SUMIFS(Input!$G:$G,Input!$F:$F,'1.CC Transition risk-Banking b.'!$A18&"*",Input!$C:$C,'1.CC Transition risk-Banking b.'!R$63,Input!$E:$E,"-2") + SUMIFS(Input!$G:$G,Input!$F:$F,'1.CC Transition risk-Banking b.'!$A18&"*",Input!$C:$C,'1.CC Transition risk-Banking b.'!R$63,Input!$E:$E,"-3"),0) -> 0 | S18: =ROUND(IFERROR(SUMIFS(Input!$O:$O,Input!$F:$F,'1.CC Transition risk-Banking b.'!$A18&"*",Input!$C:$C,'1.CC Transition risk-Banking b.'!S$63,Input!$E:$E,">0")/'1.CC Transition risk-Banking b.'!$D18,0),0) -> 2
