Workbook
Name _Toc51154475: 'B01.00'!#REF!
Name _Toc51154476: 'B01.00'!#REF!
Name _Toc51154477: 'B01.00'!#REF!
Name _Toc51154478: 'B01.00'!#REF!
Name _Toc51154479: 'B01.00'!#REF!
Name _Toc51154480: 'B01.00'!#REF!
Name _Toc51154482: 'B01.00'!#REF!
Name _Toc51154483: 'B01.00'!#REF!
Name _Toc51154484: 'B01.00'!#REF!
Name _Toc51154485: 'B01.00'!#REF!

Sheet B99.00 - Identification of the 
A1: B01.00 - Aggregate view: this tab includes information on an aggregate level for capital and liability items, including liabilities mandatorily excluded from the bail-in that are necessary to inform a preliminary NCWO assessment and the computation of conversion rates in accordance with Article 50 BRRD and EBA/GL/2017/03.
A2: Instruções SRB | I2: Análise IT
A3: Data Point | B3: ID | C3: Data type | D3: Type of constrain | E3: Description | F3: Treatment of "Not applicable" (if cell is grey out, input is not expected) | G3: Treatment of "Not available" (if cell is grey out, input is not expected) | I3: Desdodrável? | J3: Novo campo na tabela LT002? | K3: Mapeamento | L3: Description LT | M3: Field Definition LT | N3: Estado especificação
A4: Name of Legal Entity | B4: 0010 | C4: String | D4: Free text | E4: Free-form text identification of the incorporation name of the entity for which the table is reported. Please state the official name as listed in corporate registry, including the indication of the company form.
A5: LEI of Legal Entity | B5: 0020 | C5: String | D5: Free text | E5: The unique LEI code for the entity, in line with the requirements of EMIR or the Dodd-Frank Act, for which the report is submitted. In the absence of an LEI, the ECB Monetary Financial Institutions unique Identifier (MFIID) of the entity for use in RIAD (Register of Institutions and Affiliates Database) should be used. In the absence of both such identifiers, a local identifier must be used.
A6: Country of incorporation_x000D_ | B6: 0030 | C6: String | D6: ISO 3166-1 | E6: The ISO 3166-1 alpha-2 code of the country of incorporation of the entity._x000D_
A7: Name of the ultimate parent entity | B7: 0040 | C7: String | D7: Free text | E7: Free-form text identification of the incorporation name of the ultimate parent entity of the reporting entity, considered globally as the highest level of consolidation of the group. Please state the official name as listed in corporate registry, including the indication of the incorporation form.
A8: LEI of the ultimate parent entity | B8: 0041 | C8: String | D8: Free text | E8: The unique LEI code for the ultimate parent entity, in line with the requirements of EMIR or the Dodd-Frank Act, for which the report is submitted. In the absence of an LEI, the ECB Monetary Financial Institutions unique Identifier (MFI ID) of the entity for use in RIAD should be used. In the absence of both such identifiers, a local identifier must be used.
A9: Name of the Resolution Entity | B9: 0050 | C9: String | D9: Free text | E9: Free-form text identification of the incorporation name of the resolution entity (POE) of the reporting entity. Please state the official name as listed in corporate registry, including the indication of the incorporation form. If data point c0060 is ‘Resolution Entity’, the entry in this field must be the same as in data point c0010.
A10: LEI of the Resolution Entity | B10: 0051 | C10: String | D10: Free text | E10: The unique LEI code for the entity, in line with the requirements of EMIR or the Dodd-Frank Act, for which the report is submitted. In the absence of an LEI, the ECB Monetary Financial Institutions unique Identifier (MFIID) of the entity for use in RIAD should be used. In the absence of both such identifiers, a local identifier must be used. If data point c0060 is ‘Resolution Entity’, the entry in this field must the same as in data point c0020.
A11: Reporting entity type | B11: 0060 | C11: String | D11: Drop-down | E11: Status of the entity as indicated in the resolution plan. Please indicate either ‘Resolution Entity’ or ‘NonResolution Entity’.
A12: Reference date | B12: 0070 | C12: Date | D12: yyyy-mm-dd hh:mm:ss | E12: Reference date of the reported data in format: yyyy-mm-dd hh:mm:ss._x000D_
A13: Reported currency | B13: 0080 | C13: String | D13: 3-letters ISO 4217 | E13: The currency in which the report is submitted. The currency must be reported with its 3-letter ISO 4217 code. If the currency is not EUR, all the references to EUR throughout the Guidance and the template34 must be interpreted as being requested in local currency.
A14: EUR exchange rate_x000D_ | B14: 0090 | C14: Numeric | D14: 4 decimals | E14: The euro exchange rate used if a non-EUR currency is reported in data point r0080.

Sheet PDS
B1: PDS Especificação | N1: PDS Desenvolvimento
D2: Concluídos | J2: Não Concluídos | N2: Concluídos | O2: Não Concluídos
B3: Ficheiro | C3: Count | D3: Campo já existente no LT | E3: Campo já existente no LT - Nova Especificação | F3: Campo novo no LT | G3: Campo via Holístico | H3: Campo não LT (apenas tabela Output) | I3: Count | J3: Em curso | K3: Por iniciar | L3: Count | N3: Count | O3: Count
B4: B01.00-Aggregate view | C4: =COUNTA('B01.00'!A5:A10) -> 6 | D4: =COUNTIF('B01.00'!Q5:Q10,"Campo já existente no LT") -> 0 | E4: =COUNTIF('B01.00'!Q5:Q10,"Campo já existente no LT - Nova Especificação") -> 0 | F4: =COUNTIF('B01.00'!Q5:Q10,"Campo novo no LT") -> 0 | G4: =COUNTIF('B01.00'!Q5:Q10,"Campo via Holístico") -> 0 | H4: =COUNTIF('B01.00'!Q:Q,"Campo não LT (apenas tabela Output)") -> 0 | I4: =SUM(D4:H4) -> 0 | J4: =COUNTIF('B01.00'!Q5:Q10,"Em curso") -> 0 | K4: =COUNTIF('B01.00'!Q5:Q10,"Por iniciar") -> 6 | L4: =SUM(J4:K4) -> 6 | N4: =COUNTIF('B01.00'!R5:R10,"Concluído") -> 0 | O4: =COUNTIF('B01.00'!R5:R10,"Não Concluído") -> 6
B5: B02.00-Main Liabilities | C5: =COUNTA('B02.00'!A5:A85) -> 81 | D5: =COUNTIF('B02.00'!Q5:Q85,"Campo já existente no LT") -> 9 | E5: =COUNTIF('B02.00'!Q5:Q85,"Campo já existente no LT - Nova Especificação") -> 1 | F5: =COUNTIF('B02.00'!Q5:Q85,"Campo novo no LT") -> 15 | G5: =COUNTIF('B02.00'!Q5:Q85,"Campo via Holístico") -> 0 | H5: =COUNTIF('B02.00'!Q:Q,"Campo não LT (apenas tabela Output)") -> 56 | I5: =SUM(D5:H5) -> 81 | J5: =COUNTIF('B02.00'!Q5:Q85,"Em curso") -> 0 | K5: =COUNTIF('B02.00'!Q5:Q85,"Por iniciar") -> 0 | L5: =SUM(J5:K5) -> 0 | N5: =COUNTIF('B02.00'!R:R,"Concluído") -> 81 | O5: =COUNTIF('B02.00'!R:R,"Não Concluído") -> 0
B6: B05.00-Guarantees | C6: =COUNTA('B05.00'!A5:A19) -> 15 | D6: =COUNTIF('B05.00'!Q5:Q19,"Campo já existente no LT") -> 3 | E6: =COUNTIF('B05.00'!Q5:Q19,"Campo já existente no LT - Nova Especificação") -> 0 | F6: =COUNTIF('B05.00'!Q5:Q19,"Campo novo no LT") -> 1 | G6: =COUNTIF('B05.00'!Q5:Q19,"Campo via Holístico") -> 0 | H6: =COUNTIF('B05.00'!Q:Q,"Campo não LT (apenas tabela Output)") -> 11 | I6: =SUM(D6:H6) -> 15 | J6: =COUNTIF('B05.00'!Q5:Q19,"Em curso") -> 0 | K6: =COUNTIF('B05.00'!Q5:Q19,"Por iniciar") -> 0 | L6: =SUM(J6:K6) -> 0 | N6: =COUNTIF('B05.00'!R:R,"Concluído") -> 15 | O6: =COUNTIF('B05.00'!R:R,"Não Concluído") -> 0
B7: B90.00-Counterparties | C7: =COUNTA('B90.00'!A5:A15) -> 11 | D7: =COUNTIF('B90.00'!Q5:Q15,"Campo já existente no LT") -> 4 | E7: =COUNTIF('B90.00'!Q5:Q15,"Campo já existente no LT - Nova Especificação") -> 0 | F7: =COUNTIF('B90.00'!Q5:Q15,"Campo novo no LT") -> 2 | G7: =COUNTIF('B90.00'!Q5:Q15,"Campo via Holístico") -> 0 | H7: =COUNTIF('B90.00'!Q5:Q15,"Campo não LT (apenas tabela Output)") -> 5 | I7: =SUM(D7:H7) -> 11 | J7: =COUNTIF('B90.00'!Q5:Q15,"Em curso") -> 0 | K7: =COUNTIF('B90.00'!Q5:Q15,"Por iniciar") -> 0 | L7: =SUM(J7:K7) -> 0 | N7: =COUNTIF('B90.00'!R5:R15,"Concluído") -> 11 | O7: =COUNTIF('B90.00'!R5:R15,"Não Concluído") -> 0
B8: Total | C8: =SUM(C4:C7) -> 113 | D8: =SUM(D4:D7) -> 16 | E8: =SUM(E4:E7) -> 1 | F8: =SUM(F4:F7) -> 18 | G8: =SUM(G4:G7) -> 0 | H8: =SUM(H4:H7) -> 72 | I8: =SUM(D8:H8) -> 107 | J8: =SUM(J4:J7) -> 0 | K8: =SUM(K4:K7) -> 6 | L8: =SUM(J8:K8) -> 6 | N8: =SUM(N4:N7) -> 107 | O8: =SUM(O4:O7) -> 6
I9: =(I8/C8) -> 0.94690265 | L9: =L8/C8 -> 0.053097345 | N9: =N8/C8 -> 0.94690265 | O9: =O8/C8 -> 0.053097345

Sheet Notas LT002
A1: O Bail-in constará na Tabela LT002 em que:
A2: - Os campos desdobráveis (os que têm mais do que 1 valor para o mesmo contrato) terão os valores separados por ;? O separador de campos num CSV já é ; pelo que se deveria selecionar outro separador.
A3: - Terão de se identificar os campos desdobráveis
A4: - Existem campos que não estão preparados para desdobrar (Gross carrying amount)
A5: Se em algum momento a Corporação/SRB exigirem o desdobramento, terá depois se efetuar um desenvolvimento que pega no vetor e faz o desdobramento
A7: Temos 3 tipos de campos:
A8: - Os que já existem atualmente no LT e que vão que ter que ser desdobrados -> vamos ter de alterar estes campos para poderem desdobrar (G) dado que não se quer criar campos novos iguais mas que desdobrem
A9: - Os que vão manter o valor (ou seja o valor repete-se) e que não são vetores -> não tem de se fazer nada
A10: - Os que são desdobráveis
A13: LT002 As Is
A14: contrato | B14: GCA
A15: 32023234234234300 | B15: 30000
A17: LT002 Intermédia
A18: contrato | B18: zcliente | C18: segmento_xpto | D18: GCA
A19: 32023234234234300 | B19: 123 | C19: A | D19: 30000
A20: 32023234234234300 | B20: 123 | C20: B | D20: 30000
A21: 32023234234234300 | B21: 1234 | C21: C | D21: 30000
A23: LT002 To Be
A24: contrato | B24: zcliente | C24: segmento_xpto | D24: GCA
A25: 32023234234234300 | B25: 123;123;1234 | C25: A;B;C | D25: 30000
A27: Se for preciso abrir no futuro:
A28: contrato | B28: zcliente | C28: segmento_xpto | D28: GCA
A29: 32023234234234300 | B29: 123 | C29: A | D29: 10000
A30: 32023234234234300 | B30: 123 | C30: B | D30: 10000
A31: 32023234234234300 | B31: 1234 | C31: C | D31: 10000

Sheet Notas Financeira
A1: # | B1: Comentário | C1: Data set
A2: 1 | B2: Terá de atacar as tabelas fazendo o filtro para passivo com exceção do Data point 5 que tem uma parte de extrapatrimonial | C2: TODOS
A3: =+A2+1 -> 2 | B3: Os depósitos de clientes terá de ser feito um cruzamento com a tabela do FGD (FG001_FGD no cap tools). Os depósitos depois são divididos entre cobertos e não cobertos sendo que têm tratamento diferente consoante o caso. | C3: TODOS
A4: =+A3+1 -> 3 | B4: Para a parte das emissões de títulos, a ligação entre a AL029/AL030 e a CT610 deverá ser feita por ISIN/ZDEPOSIT | C4: 1. DATA POINTS FOR IDENTIFICATION

Sheet Diagrama_Estrutura_Accionista
A3: FALSE

Sheet B01.00
A1: B01.00 - Aggregate view: this tab includes information on an aggregate level for capital and liability items, including liabilities mandatorily excluded from the bail-in that are necessary to inform a preliminary NCWO assessment and the computation of conversion rates in accordance with Article 50 BRRD and EBA/GL/2017/03.
A2: SRB Instructions | I2: Especificação IT | S2: lt833_agreg_campos
I3: Fase 1 - Granular (Loan Tape) | N3: Fase 2 - Agregada (Não Loan Tape) | P3: Comentários/Histórico EF | Q3: Estado Especificação | R3: Estado Desenvolvimento
A4: Data Point | B4: ID | C4: Data type | D4: Constrain | E4: Description | F4: Treatment of "Not applicable" (if cell is grey out, input is not expected) | G4: Treatment of "Not available" (if cell is grey out, input is not expected) | I4: Novo campo? | J4: Nome campo | K4: Missing Value (LT804) | L4: Not Applicable Value (LT804) | M4: Regra campo | N4: Nome campo | O4: Regra campo | S4: tabela_condicao | T4: campo_condicao | U4: valor_condicao | V4: tabela_origem | W4: campo_origem | X4: campo_destino | Y4: campo_exp | Z4: acao | AA4: ckutulmo | AB4: htimest | AC4: ambito | AD4: segmento | AE4: segmento_agregado | AF4: ref_date | AG4: cod_visao | AH4: Estado preenchimento
A5: Row number | B5: 0010 | C5: Numeric | D5: Integer | E5: The unique number / primary key to identify the row items (the number must be an integer). | I5: Não | N5: out_b0100_aggregate_view.0010_row_nmbr | O5: Sequenciador a implementar na tabela de output out_b0100_aggregate_view Nota: A cada execução não deverão ser gerados Row numbers diferentes pelo que provisoriamente deverá ser feito um order by Insolvency ranking desc (alinhado com o exemplo apresentado no documento 2024-11-05_Annex-II_Facilitating-Instructions_0.pdf - páginas 30 e 31) | Q5: Por iniciar | R5: Não Concluído | X5: 1 | Y5: 0010 | Z5: SEQUENCIA | AC5: SRB | AE5: B0100 | AG5: 1 | AH5: Concluido
A6: Insolvency ranking | B6: 0020 | C6: String | D6: Free text | E6: The corresponding insolvency ranking of the instrument. Numeric value (e.g. integer of 1 or more). | I6: Não | N6: out_b0100_aggregate_view.0020_rank_insolv | O6: out_b0200_main_liabilities.0160_rank_insolv | Q6: Por iniciar | R6: Não Concluído | S6: lt002_instrument | T6: ind_univ | U6: B0200 | V6: lt002_instrument | W6: inslvncy_rnkng | X6: 2 | Y6: 0020 | Z6: AGRUPAR | AC6: SRB | AE6: B0100 | AG6: 1 | AH6: Concluido
A7: Category | B7: 0030 | C7: String | D7: Drop-down | E7: Please indicate the liability category only for the following items: title of ownership, reserves, liabilities eligible for bail-in, and liabilities that must be excluded from the bail-in in accordance with Article 44(2) of the BRRD, as per the following drop-down values: • Covered deposits (BRRD art. 44/2/a) • Secured liabilities - collateralized part (BRRD art. 44/2/b) • Client liabilities, if protected in insolvency (BRRD art. 44/2/c) • Fiduciary liabilities, if protected in insolvency (BRRD art. 44/2/d) • Institution liabilities < 7 days (BRRD art. 44/2/e) • System (operator) and CCP liabilities < 7 days (BRRD art. 44/2/f) • Employee liabilities (BRRD art. 44/2/g/i) • Critical service liabilities (BRRD art. 44/2/g/ii) • Tax and social security authorities liabilities, if preferred (BRRD art. 44/2/g/iii) • DGS liabilities (BRRD art. 44/2/g/iv) • Liabilities towards other entities of the resolution group (BRRD art. 44/2/h) • Liabilities eligible for bail-in • Other equity items • Title of ownership | I7: Não | N7: out_b0100_aggregate_view.0030_lblty_ctgry | O7: Na out_b0200_main_liabilities existe o campo 0140_ntr_lblty (que se alimenta do campo lt002_instrument.typ_instrmnt passando por uma parametrização na LT829). Este campo foi parametrizado para possibilitar 2 valores: 1005 (Debt Securities) -> Registered Bond 2006 (Equity) -> Title of ownership Possíveis Soluções: 1) Criar novo campo lt002_instrument.lblty_ctgry que se alimentaria de uma parametrização a criar na lt831_param_conceitos com base no campo lt002_instrument.typ_instrmnt (e depois a tabela final out_b0100_aggregate_view alimentaria-se deste campo): 1005 (Debt Securities) -> Liabilities eligible for bail-in?? 2006 (Equity) -> Title of ownership ver sheet "LT831" 2) Não criar novo campo lt002_instrument.lblty_ctgry, criar apenas o conceito na lt831_param_conceitos com base no 0140_ntr_lblty da out_b0200_main_liabilities (e depois a tabela final out_b0100_aggregate_view alimentaria-se deste conceito) Registered Bond -> Liabilities eligible for bail-in?? Title of ownership -> Title of ownership ver sheet "LT831" Nota: Preenchia-se 'AUX' no campo 'tabela_conceito' da LT831, dado que não é possível efetuar o upload naLT831 sem preencher o campo 'tabela_conceito' (é apresentado erro). Isto para evitar que o campo fique Hard-coded na tabela final out_b0100_aggregate_view: CASE WHEN 0140_ntr_lblty='Title of ownership' THEN 'Title of ownership' WHEN 0140_ntr_lblty='Registered Bond' THEN 'Liabilities eligible for bail-in' ELSE '' END AS 0030_lblty_ctgry | Q7: Por iniciar | R7: Não Concluído | S7: lt002_instrument | T7: ind_univ | U7: B0200 | V7: lt002_instrument | W7: ctgry | X7: 3 | Y7: 0030 | Z7: AGRUPAR | AC7: SRB | AE7: B0100 | AG7: 1 | AH7: Concluido
A8: Counterparty type | B8: 0040 | C8: String | D8: Drop-down | E8: Please refer to data point {B90.00;c0070}. This data point is relevant only for liabilities that must be excluded from bail-in in accordance with Article 27(3) SRMR. Hence, it should not be reported for: • Liabilities eligible for bail-in • Other equity items • Title of ownership | I8: Não | N8: out_b0100_aggregate_view.0040_cntrprty_typ | O8: É referido que este campo não deve ser reportado para: • Liabilities eligible for bail-in • Other equity items • Title of ownership Dado que o universo de contratos do MBDT do BST "encaixam" precisamente nestes 3 valores (a confirmar com Pedro Mendes), então não deveremos reportar este campo, certo? Em caso afirmativo, reportar Valor fixo 'Not applicable' de acordo com o exemplo apresentado no documento 2024-11-05_Annex-II_Facilitating-Instructions_0.pdf - páginas 30 (campo preenchido a vazio) e 31 (campo preenchido com 'Not applicable'). Caso o entendimento anterior esteja incorreto, ou seja se o campo for para reportar, é referido Please refer to data point {B90.00;c0070}. Contudo, esta info está errada dado que o Counterparty type é o campo c0080 (e não o c0070) da B90.00. Adicionalmente verifica-se no documento Annex I - Minimum Bail-in Data Template (MBDT) tables a presença da combo box com o valores possíveis do campo c0080 | Q8: Por iniciar | R8: Não Concluído | S8: lt002_instrument | T8: ind_univ | U8: B0200 | V8: lt002_instrument | W8: intrnl_sgmnt | X8: 4 | Y8: 0040 | Z8: AGRUPAR | AC8: SRB | AE8: B0100 | AG8: 1 | AH8: Concluido
A9: Relevant amount for Bail-in/WDC | B9: 0050 | C9: Numeric | D9: 2 decimals | E9: Please refer to data field {B02.00;c0130}. For derivatives, please refer to data field {B03.00;c0110}. For SFTs, please refer to data field {B04.00;c0080}. Liabilities mandatorily excluded from bail-in in accordance with Article 44(2)(h) BRRD shall be reported in the corresponding row item (i.e. not as “liabilities eligible for bail-in”). | F9: Input "Not applicable" | I9: Não | N9: out_b0100_aggregate_view.0050_rlvnt_amnt_wdc | O9: out_b0200_main_liabilities.0130_rlvnt_amnt_wdc | Q9: Por iniciar | R9: Não Concluído | S9: lt002_instrument | T9: ind_univ | U9: B0200 | V9: lt005_instr_ent | W9: grss_crryng_amnt_instrmnt | X9: 5 | Y9: 0050 | Z9: SOMAR | AC9: SRB | AE9: B0100 | AG9: 1 | AH9: Concluido
A10: Amount excluded from Bail-in/WDC | B10: 0060 | C10: Numeric | D10: 2 decimals | E10: Indicate the outstanding amount mandatorily excluded from bail-in in accordance with Article 27(3) SRMR. | I10: Não | N10: out_b0100_aggregate_view.0060_amnt_excldd_wdc | O10: Valor fixo 0? | Q10: Por iniciar | R10: Não Concluído | S10: lt002_instrument | T10: ind_univ | U10: B0200 | V10: lt005_instr_ent | W10: otstndng_amnt_excldd | X10: 6 | Y10: 0060 | Z10: SOMAR | AC10: SRB | AE10: B0100 | AG10: 1 | AH10: Concluido

Sheet lt834_agreg_segmento
A1: lt834_agreg_segmento
A2: ind_univ | B2: ckutulmo | C2: htimest | D2: ambito | E2: segmento | F2: segmento_agregado | G2: ref_date | H2: cod_visao
A3: B0200 | D3: SRB | F3: B0100 | H3: 1
A4: B0200 | D4: SRB | F4: B0200 | H4: 1
A5: B0500 | D5: SRB | F5: B0500 | H5: 1
D6: SRB | F6: B9000 | H6: 1
A8: Notas:
A9: Não se preenche o ind_unvi da última linha pois aplica-se a todos os registos. Dado que queremos todas as Contrapartes, quer as do Passivo (Títulos) quer do Ativo (Garantias).
A10: O ind_univ vai ser traduzido na lt829/lt830 para responder ao campo "Tab of origin" (Se ind_univ=Passivo reportar B0200; Se ind_univ=Ativo reportar B0500). Como tal, nesta tabela têm de constar o valor já traduzido (que é o valor final que vai aparecer na LT002)
A11: Luís Capitão-Mor referiu que a tabela tem de estar preparada também para receber IN ('X',''Y,'Z') apesar de não ser preciso no âmbito do Bail-in

Sheet B02.00
A1: B02.00 - Main Liabilities: the tab includes the data points requested at resolution entity (point of entry) level for the implementation of the bail-in tool, or at non resolution entity level (up to the Senior Non-Preferred layer)11 for monitoring and implementing the loss transfer and recapitalisation mechanisms. Generally, the data points in this tab are requested at individual level12. However, some specific data points may be requested at consolidated level on an adhoc basis by the IRT
A2: SRB Instructions | I2: Especificação IT
I3: Fase 1 - Granular (Loan Tape) | N3: Fase 2 - Agregada (Não Loan Tape) | P3: Comentários/Histórico EF
A4: Data Point | B4: ID | C4: Data type | D4: Constrain | E4: Description | F4: Treatment of "Not applicable" (if cell is grey out, input is not expected) | G4: Treatment of "Not available" (if cell is grey out, input is not expected) | I4: Novo campo? | J4: Nome campo | K4: Missing Value (LT804) | L4: Not Applicable Value (LT804) | M4: Regra campo | N4: Nome campo | O4: Regra campo | Q4: Estado Especificação | R4: Estado Desenvolvimento | S4: Necessita de ajuste? (2025-10-31 vs 2025-11-14)
A5: Row number | B5: 0010 | C5: Numeric | D5: Integer | E5: The unique number / primary key to identify the row items (the number must be an integer). | I5: Não | N5: out_b0200_main_liabilities.0010_row_nmbr | O5: Sequenciador a implementar na tabela de output out_b0200_main_liabilities Nota: A cada execução não deverão ser gerados Row numbers diferentes pelo que provisoriamente deverá ser feito um order by instrmnt_id | P5: Reunião 2025-06-16 Luís Capitão-Mor, Pedro Mendes, Luísa Sousa | Q5: Campo não LT (apenas tabela Output) | R5: Concluído | S5: NÃO | T5: =IF(SEARCH(B5,N5,4),"ok","nok") -> ok
A6: Unique internal identification number | B6: 0020 | C6: String | D6: Free text | E6: The unique internal identifier of the instrument/liability. For deposits reported on an aggregate level, please indicate: ▪ ‘NCNP’ for the aggregated not covered not preferential deposits (field c0280 = TRUE); and ▪ ‘NCBP’ for the aggregated not covered but preferential deposits (field c0290 = TRUE). | I6: Não | J6: lt002_instrument.instrmnt_id | L6: {=_xlfn.SWITCH(C6,"Numeric","999999999999999","String","Not applicable","Date","0001-01-01")} -> Not applicable | N6: out_b0200_main_liabilities.0020_uniq_id | O6: lt002_instrument.instrmnt_id | P6: Reunião 2025-06-16 Luís Capitão-Mor, Pedro Mendes, Luísa Sousa | Q6: Campo já existente no LT | R6: Concluído | S6: NÃO | T6: =IF(SEARCH(B6,N6,4),"ok","nok") -> ok
A7: Unique identification number (known to the counterparty) | B7: 0030 | C7: String | D7: Free text | E7: The unique identifier of the instrument/liability that would allow the counterparty to conclude that it will be affected by the potential resolution action, without external third parties being able to identify the creditor. For securities, the ISIN code must be indicated where available (other identifiers need only be provided in the absence of an ISIN). For deposits and other liabilities, the account/contract number should be reported. In the event of multiple tranches (multiple counterparties) of one promissory-note loan (e.g. Schuldscheindarlehen) or a syndicated loan, a unique ID must be allocated to each tranche. For deposits reported on an aggregate level, please indicate: ▪ ‘NCNP’ for the aggregated not covered not preferential deposits (field c0280 = TRUE); and ▪ ‘NCBP’ for the aggregated not covered but preferential deposits (field c0290 = TRUE). | I7: Não | J7: lt002_instrument.isin | L7: {=_xlfn.SWITCH(C7,"Numeric","999999999999999","String","Not applicable","Date","0001-01-01")} -> Not applicable | N7: out_b0200_main_liabilities.0030_uniq_id_knwn_cntrprty | O7: lt002_instrument.isin | P7: Reunião 2025-06-16 Luís Capitão-Mor, Pedro Mendes, Luísa Sousa | Q7: Campo já existente no LT | R7: Concluído | S7: NÃO | T7: =IF(SEARCH(B7,N7,4),"ok","nok") -> ok
A8: Type of the unique identifier (known to the counterparty) | B8: 0040 | C8: String | D8: Free text, but fixed values for specific items | E8: Free text, to indicate what type of identifier has been used in data point c0020, e.g. if the identifier is an ISIN, please input ‘ISIN’; if the identifier is an account number, please input ‘Account number’; if the identifier is a contract number, please input ‘Contract number’. For deposits reported on an aggregate level, please indicate ‘Aggregated’. | I8: Não | N8: out_b0200_main_liabilities.0040_typ_uniq_id_knwn_cntrprty | O8: Valor fixo 'ISIN' | P8: Reunião 2025-06-16 Luís Capitão-Mor, Pedro Mendes, Luísa Sousa: Neste caso não faz sentido criar o campo no Loan Tape quando ele já existe, portanto será criado apenas na tabela output out_b0200_main_liabilities. Caso contrário haveria um princípio de colisão, pois estar-se-ia a repetir conceitos de campos. | Q8: Campo não LT (apenas tabela Output) | R8: Concluído | S8: NÃO | T8: =IF(SEARCH(B8,N8,4),"ok","nok") -> ok
A9: Original amount issued in EUR | B9: 50 | C9: Numeric | D9: 2 decimals | E9: The EUR (counter)value of the total issue size of the instrument, irrespective of the effective issuance dates, i.e. the total nominal amount / face value of a specific liability. For shares, it should reflect the face value / carrying amount of the shares. If a nominal value does not exist, this field is not applicable. This data point is not applicable for cash accounts / saving accounts and deposits reported in aggregated form (Submission A). If a value is reported in a foreign currency (c0060), the amount must additionally be converted into euros and reported in the corresponding EUR field (c0050), using the euro reference exchange rate published by the ECB on the date for which the information is reported40. In the case of foreign currencies for which no euro reference exchange rate is available, a customary market reference rate must be used. If such other customary reference exchange rates are used, a uniform source must be used wherever possible. | F9: Input 999999999999999 | I9: Sim | J9: lt002_instrument.orgnl_amnt_eur | L9: {=_xlfn.SWITCH(C9,"Numeric","999999999999999","String","Not applicable","Date","0001-01-01")} -> 999999999999999 | M9: Se flag_inst_titulos = '1': Obter campo nom_tot_inic da ct610_titulos. Adicionalmente, efetuar conversão via tabela cambios, seguindo a lógica definida nos restantes processos, dado que o campo nom_tot_inic está expresso na moeda original (campo cmoeda). Exemplo de query que utiliza a tabela cambios para converter moeda original em moeda eur (quando é eur a tcmbme é 1 pelo que o valor é igual): SELECT DISTINCT concat(cempresa,cbalcao, cnumecta, zdeposit), (ct610.nom_tot_inic / cambios.tcmbme) AS orgnl_amnt_eur FROM (SELECT cempresa,cbalcao, cnumecta, zdeposit, nom_tot_inic, cmoeda FROM cd_captools.ct610_titulos WHERE ref_date='${ref_date}' and concat(cempresa,cbalcao, cnumecta, zdeposit) IN ( '31641600000000000PTSTOGOM0003000', '31641600005800007PTBSRDOM0037000', '31641600005800007PTSTOCOM0007000', '31641600005800007PTCPP0AM0007000', '31641600000000000PTSTOEOM0021000', '31641600000000000PTSTOHOM0002000', '31641600000000000PTBSREOM0028000', '31641600000000000PTSTOFOM0004000')) ct610 LEFT JOIN (SELECT cmoeda, tcmbme FROM cd_captools.cambios WHERE data_date_part = '${ref_date}' AND dcambio = '${ref_date}' AND zseqcamb = 99 AND ctbcamb = 'F' AND cmarca = 'BT') cambios ON cambios.cmoeda = ct610.cmoeda; Se flag_inst_titulos = '0': Not applicable. O respetivo valor default de Not applicable deverá ser parametrizado na lt804_conf_dflt. | N9: out_b0200_main_liabilities.0050_orgnl_amnt_eur | O9: lt002_instrument.orgnl_amnt_eur | P9: Reunião 2025-08-04 Luís Capitão-Mor, Pedro Mendes, Luísa Sousa | Q9: Campo novo no LT | R9: Concluído | S9: NÃO | T9: =IF(SEARCH(B9,N9,4),"ok","nok") -> ok
A10: Original amount issued in foreign currency | B10: 0060 | C10: Numeric | D10: 2 decimals | E10: Same as c0050 above, but in the foreign currency (where relevant). Please also report the EUR-converted amount in the corresponding EUR field (c0050). This data point is not applicable for cash accounts / savings accounts and deposits reported in aggregated form (Submission A). | F10: Input 999999999999999 | I10: Sim | J10: lt002_instrument.orgnl_amnt_fx | L10: {=_xlfn.SWITCH(C10,"Numeric","999999999999999","String","Not applicable","Date","0001-01-01")} -> 999999999999999 | M10: Se flag_inst_titulos = '1' e se campo cmoeda da ct610_titulos = '978' (eur): Not applicable. O respetivo valor default de Not applicable deverá ser parametrizado na lt804_conf_dflt. Se flag_inst_titulos = '1' e se campo cmoeda da ct610_titulos <> '978' (eur): Obter campo nom_tot_inic da ct610_titulos Se flag_inst_titulos = '0': Not applicable. O respetivo valor default de Not applicable deverá ser parametrizado na lt804_conf_dflt. | N10: out_b0200_main_liabilities.0060_orgnl_amnt_fx | O10: lt002_instrument.orgnl_amnt_fx | P10: Reunião 2025-08-04 Luís Capitão-Mor, Pedro Mendes, Luísa Sousa | Q10: Campo novo no LT | R10: Concluído | S10: NÃO | T10: =IF(SEARCH(B10,N10,4),"ok","nok") -> ok
A11: Contract currency | B11: 0070 | C11: String | D11: 3-letters ISO 4217 | E11: The currency in which the instrument/liability is issued. The currency must be reported with its 3-letter ISO 4217 code. For deposits reported on an aggregate level, please indicate ‘XXX’. | F11: Input "XXX" | I11: Não | J11: lt002_instrument.crrncy_dnmntn | L11: XXX | N11: out_b0200_main_liabilities.0070_cntrct_crrncy | O11: lt002_instrument.crrncy_dnmntn | P11: Reunião 2025-06-16 Luís Capitão-Mor, Pedro Mendes, Luísa Sousa | Q11: Campo já existente no LT | R11: Concluído | S11: NÃO | T11: =IF(SEARCH(B11,N11,4),"ok","nok") -> ok
A12: Outstanding principal amount | B12: 80 | C12: Numeric | D12: 2 decimals | E12: The EUR (counter)value of the outstanding principal amount of the instrument/liability. The difference between the original amount issued and the outstanding principal amount may be due to partial buybacks of the instrument, amortising instruments, etc. The portion of eligible liabilities subscribed by intragroup entities and excluded under Article 27(3)(h) SRMR must be included in the outstanding principal amount. Only claims against other parties must be reported (i.e. excluding the portion held by the entity itself, which must be reported in field c0090). For zero coupon bonds issued at discount (i.e. c0240 = ZCB issued at discount) the final redemption amount should be reported. | I12: Sim | J12: lt005_instr_ent.otstndng_prncpl_amnt | L12: {=_xlfn.SWITCH(C12,"Numeric","999999999999999","String","Not applicable","Date","0001-01-01")} -> 999999999999999 | M12: Se flag_inst_titulos = '1': Passo 1: Verificar para cada "entty_id" (de um determinado "instrmnt_id") da lt005_instr_ent se o mesmo consta no vetor "zcliente_investidor" da ct610_titulos (desse "instrmnt_id"). Se constar, identificar em que posição consta e em seguida obter do vetor "nom_tot_ini_investe" da ct610_titulos o montante que consta nessa posição; Passo 2: Verificar se a soma dos vários "nom_tot_ini_investe" é igual ao "nom_tot_inic", da ct610_titulos -> Se for igual: Não é necessária ação adicional -> Se for diferente: Somar essa diferença no "entty_id" 0000000000 Passo 3: Dado que o "outstanding principal amount" que se pretende é o atual e não o inicial, então terá de se multiplicar os vários "nom_tot_ini_investe" pelo rácio "nom_tot_atual"/"nom_tot_inic", da ct610_titulos. Nota: O Universo do MBDT terá sempre este rácio=1 e portanto o valor inicial será igual ao valor atual, contudo, se existissem titularizações (onde se aplica o conceito de pool factor), o valor inicial seria diferente do valor atual (porque o "pool_factor" seria diferente de 1). Passo 4: Converter o montante obtido para eur pela tabela de cambios (ver query de conversão já definida no campo Original amount issued in EUR (0050)) Se flag_inst_titulos = '0': Not applicable. O respetivo valor default de Not applicable deverá ser parametrizado na lt804_conf_dflt. Na sheet "Aux Campos Montante" consta um exemplo com a aplicação desta lógica. | N12: out_b0200_main_liabilities.0080_otstndng_prncpl_amnt | O12: Soma "otstndng_prncpl_amnt" - Soma "portion_amnt_rprtng_entty", por cada instrmnt_id da lt005_instr_ent Na sheet "Aux Campos Montante" consta um exemplo com a aplicação desta lógica. | P12: Reunião 2025-10-09 Luís Capitão-Mor, Pedro Mendes Reunião 2025-09-22 e 2025-09-18 Luís Capitão-Mor, Pedro Mendes: Segundo Luís Capitão-Mor não se pode utilizar o campo OTSTNDNG_NMNL_AMNT_INSTRMNT da lt002_instrument dado que esse campo é contabilístico (a pedido do guia do BCE) e o SRB não pede contabilístico. Adicionalmente, interpretou-se da definição dada pelo SRB que se pretende retirar as recompras do BST e deve-se incluir o que está no Santander S.A (ou seja não deve se retirar o que está no Santander S.A.). Exemplo 1: Emissão de 1000M eur em que: 100M eur estão recomprados pelo BST 900M eur estão no mercado (e destes 900M eur, 500M eur estão no Santander S.A.) Ou seja, neste exemplo o Outstanding principal amount deverá ser 900M eur. Exemplo 2: Emissão 1000M eur a 95% (abaixo do par), portanto 950M eur. Na contabilidade na data inicial consta Outstanding principal amount=950M eur mas na ct610_titulos constam 1000M eur. Ou seja, o valor contabilístico nem sempre é igual ao não contabilístico. | Q12: Campo novo no LT | R12: Concluído | S12: NÃO | T12: =IF(SEARCH(B12,N12,4),"ok","nok") -> ok
A13: Portion of instrument or liability held by the reporting entity | B13: 0090 | C13: Numeric | D13: 2 decimals | E13: The EUR amount related to the portion of the liability held by the reporting entity itself. The amount can either be defined as the principal amount plus accrued interest and fees and charges, or as the relevant portion of fair value held by the reporting entity itself, in the event that field c0250 applies. This data point is only relevant for securities. | F13: Input 999999999999999 | I13: Sim | J13: lt005_instr_ent.prtn_amnt_rprtng_entty | L13: {=_xlfn.SWITCH(C13,"Numeric","999999999999999","String","Not applicable","Date","0001-01-01")} -> 999999999999999 | M13: Se flag_inst_titulos = '1': Verificar para cada "entty_id" (de um determinado "instrmnt_id") da lt005_instr_ent se o mesmo corresponde ao "zcliente_emitente" da ct610_titulos (desse "instrmnt_id"). Se não corresponder: Reportar 0 Se corresponder: Verificar se esse "entty_id" consta no vetor "zcliente_investidor" da ct610_titulos. Se constar: Passo 1: Identificar em que posição consta no vetor "zcliente_investidor" e em seguida obter do vetor "nom_tot_ini_investe" da ct610_titulos o montante que consta nessa posição; Passo 2: Dado que o "Portion of instrument or liability held by the reporting entity" que se pretende é o atual e não o inicial, então terá de se multiplicar o montante obtido no passo anterior pelo rácio "nom_tot_atual"/"nom_tot_inic", da ct610_titulos; Passo 3: Converter para eur pela tabela de cambios (ver query de conversão já definida no campo Original amount issued in EUR (0050)). Se não constar: Reportar 0 Se flag_inst_titulos = '0': Not applicable. O respetivo valor default de Not applicable deverá ser parametrizado na lt804_conf_dflt. Na sheet "Aux Campos Montante" consta um exemplo com a aplicação desta lógica. | N13: out_b0200_main_liabilities.0090_prtn_amnt_rprtng_entty | O13: Soma "prtn_amnt_rprtng_entty", por cada instrmnt_id da lt005_instr_ent Na sheet "Aux Campos Montante" consta um exemplo com a aplicação desta lógica. | P13: Reunião 2025-10-09 Luís Capitão-Mor, Pedro Mendes Reunião 2025-09-22 e 2025-09-18 Luís Capitão-Mor, Pedro Mendes | Q13: Campo novo no LT | R13: Concluído | S13: NÃO | T13: =IF(SEARCH(B13,N13,4),"ok","nok") -> ok
A14: Accrued interest | B14: 100 | C14: Numeric | D14: 2 decimals | E14: The EUR (counter)value of the outstanding accrued interest on the instrument. In jurisdictions where accrued interests do not rank pari passu to the principal liability amount, the relevant NRAs have the option to request the reporting of interest accruals on separate line items (41). Only claims against third parties must be reported (i.e. excluding the proportion held by the entity itself, which must be reported in field c0090). In case the field is not applicable (e.g. shares, zero coupon bonds issued at discount), please refer to the specific instructions in the Technical Annex. (41) - In such cases, please refer to the specific reporting example in Annex II, paragraph 3.7. | F14: Input 999999999999999 | G14: Leave blank | I14: Sim | J14: lt002_instrument.accrd_intrst_instrmnt (campo já existente a alterar) lt005_instr_ent.accrd_intrst_instrmnt (campo novo a criar) | L14: {=_xlfn.SWITCH(C14,"Numeric","999999999999999","String","Not applicable","Date","0001-01-01")} -> 999999999999999 | M14: lt002_instrument.accrd_intrst_instrmnt (campo já existente a alterar): O campo accrd_intrst_instrmnt (da lt002_instrument) está atualmente a sair com valor 0 para estes registos de Títulos Passivos (o que não é suposto dado que existem registos que deveriam ter valor). O campo accrd_intrst_instrmnt (da lt002_instrument) alimenta-se do campo juros_corridos (da lt001_univ_oper) e é calculado atualmente da seguinte forma (segundo "Especificação - BCE Loan Tape_20250915 LF + ESTR"): NVL ( SUM(-1*juros_corridos) ,0 ) O campo juros_corridos (da lt001_univ_oper) será calculado da seguinte forma (segundo re-especificação solicitada por Gonçalo Filipe, email 5 de agosto de 2025 12:58): SUM(MSALDO_FINAL) WHERE COD_PLANO = 'BST_IND' AND CCONTAB_FINAL_PCSB NOT LIKE '28%' AND COMPOSICAO_VALOR = 'juros/rendimentos a receber' AND TIPO_CONTA = 'A' AND CARTEIRA_CONTABILISTICA IN ('ativos financeiros ao custo amortizado','ativos financeiros ao justo valor atraves de outro rendimento integral','ativos financeiros ao justo valor atraves de resultados') Constata-se portanto que o campo juros_corridos (da lt001_univ_oper) não contempla atualmente o Passivo (razão pela qual o campo sai com valor 0), pelo que deverá ser adicionada a condição do "OR" abaixo: SUM(MSALDO_FINAL) WHERE ( COD_PLANO = 'BST_IND' AND CCONTAB_FINAL_PCSB NOT LIKE '28%' AND COMPOSICAO_VALOR = 'juros/rendimentos a receber' AND TIPO_CONTA = 'A' AND CARTEIRA_CONTABILISTICA IN ('ativos financeiros ao custo amortizado','ativos financeiros ao justo valor atraves de outro rendimento integral','ativos financeiros ao justo valor atraves de resultados') ) OR ( COD_PLANO = 'BST_IND' AND COMPOSICAO_VALOR = 'juros/encargos a pagar' AND TIPO_CONTA = 'P' AND CARTEIRA_CONTABILISTICA IN ('passivos financeiros ao custo amortizado') ) - Luís Capitão-Mor, Luísa Sousa, Gonçalo Filipe e Dora Roxo não identificaram impacto nesta alteração. lt005_instr_ent.accrd_intrst_instrmnt (campo novo a criar): 'Se flag_inst_titulos = '1': Efetuar exatamente a mesma especificação da lt002_instrument.accrd_intrst_instrmnt mas obtendo o valor por cada "entty_id" (na lt001_univ_oper). Ex: Para o contrato 'A' (cempresa, cbalcao, cnumecta, zdeposit) temos 3 linhas com a seguinte distribuição de juros_corridos na lt001_univ_oper: cempresa+cbalcao+cnumecta+zdeposit= 'A' | zcliente='1' | juros_corridos = 10 cempresa+cbalcao+cnumecta+zdeposit= 'A' | zcliente='2' | juros_corridos = 20 cempresa+cbalcao+cnumecta+zdeposit= 'A' | zcliente='3' | juros_corridos = 30 Atualmente o campo accrd_intrst_instrmnt da lt002_instrument calcula simplesmente a soma dos vários montantes de juros_corridos por contrato, ou seja, na lt002_instrument é apresentado uma única linha: instrmnt_id= 'A' | accrd_intrst_instrmnt = 60 O que se pretende no novo campo accrd_intrst_instrmnt a criar na lt005_instr_ent: instrmnt_id= 'A' | entty_id=1 | accrd_intrst_instrmnt = 10 instrmnt_id= 'A' | entty_id=2 | accrd_intrst_instrmnt = 20 instrmnt_id= 'A' | entty_id=3 | accrd_intrst_instrmnt = 30 Se flag_inst_titulos = '0': Not applicable. O respetivo valor default de Not applicable deverá ser parametrizado na lt804_conf_dflt. | N14: out_b0200_main_liabilities.0100_accrd_intrst_instrmnt | O14: (-1) * Soma "accrd_intrst_instrmnt ", por cada instrmnt_id da lt005_instr_ent Nota: Esta multiplicação por -1, deve-se ao facto de no Loan Tape o campo accrd_intrst_instrmnt apresentar valores negativos (para o caso destes registos de Títulos Passivos) e neste report pretenderem-se valores positivos (segundo Pedro Mendes). Ex: O contrato 31 6416 00000000000 PTBSREOM0028000 (para 2025-06-30) tem saldo de juros +418465.480000 na fr001_univ_saldo e terá +418465.480000 na lt001_univ_oper (após a nova re-especificação do Gonçalo Filipe, atualmente tem -418465.480000) e terá -418465.480000 na lt002_instrument (dada a fórmula NVL ( SUM(-1*juros_corridos) ,0 )). É portanto necessária a multiplicação por -1, ficando assim +418465.480000. Deverá ser feita a multiplicação por -1 e não o valor absoluto (abs), dado que poderá vir a existir algum contrato contra natura. | P14: Reunião 2025-10-09 Luís Capitão-Mor, Pedro Mendes Reunião 2025-09-16 Luís Capitão-Mor, Pedro Mendes, Luísa Sousa | Q14: Campo já existente no LT - Nova Especificação | R14: Concluído | S14: SIM | T14: =IF(SEARCH(B14,N14,4),"ok","nok") -> ok
A15: Applicable fees and charges | B15: 110 | C15: Numeric | D15: 2 decimals | E15: Total EUR amount of applicable fees and charges (e.g. contractual fees for late payments) linked to the instrument, if the fee or charge is payable and due, but not yet settled with the counterparty as of the request date. This is to the extent that the fee or charge is not covered within the outstanding principal amount, the accrued interest or a separate liability. Fees and charges do not include agios or fees in conjunction with the listing of an instrument. Only claims against third parties must be reported (i.e. excluding the proportion held by the entity itself, which must be reported in field c0090). In case the field is not applicable (e.g. shares), please refer to the specific instructions in the Technical Annex. | F15: Input 999999999999999 | G15: Leave blank | I15: Não | N15: out_b0200_main_liabilities.0110_applcbl_fees_charges | O15: Valor fixo 0 | P15: Reunião 2025-09-22 Luís Capitão-Mor, Pedro Mendes, Luísa Sousa Solução 1: Dado que o BST não tem comissões que ainda não tenham sido pagas/liquidadas (not yet settled) neste Universo de Títulos, reportar neste campo valor fixo 0 na tabela final (out_b0200_main_liabilities). Segundo Pedro Mendes, nem sequer existem comissões iniciais neste Universo de Títulos dado que é tudo feito internamente ou com o Banco Santander S.A.. Solução 2: Trazer as comissões periodificadas da Contabilidade, contudo, essas comissões periodificadas podem ter sido pagas ou não, pelo que não é exatamente o que o SRB pede, dado que o SRB refere que quer as não pagas. Esta solução implicaria criar um campo novo no Loan Tape e trazer um conceito que não é o que o SRB solicita. Adicionalmente o resultado deste campo seria um conjunto vazio para este Universo de Títulos. Solução 3: Criar um campo novo na ct610_titulos. Contudo, este campo seria dinâmico pelo que também não seria uma boa solução. Dadas as soluções apresentadas, optou-se pela solução 1. OLD: Reunião 31/10/2024 Luís Capitão-Mor, Pedro Mendes: Segundo Luís Capitão-Mor, Pedro Mendes, este campo aplica-se aos custos periodificados do banco (ainda não pagos, que estão pendentes de pagar) nas emissões que o Banco faz de covered bonds, seniores,... (estão no Passivo do Banco), tem de se pagar aos Advogados, etc. Naturalmente, este campo não se aplica a Depósitos. Ações solicitadas por Luís Capitão-Mor: - Agendar reunião com Rafael Pessoa/Carlos Fernandes para ver onde constam estes custos na fr802 (devem ter uma conta contabilistica), levando para a reunião 2 exemplos de covered bonds: 1) Identificar esses 2 exemplos para uma data mais recente; 2) Verificar na ct001 quais as contas PCSB (uma conta 50%) e IFRS associadas; 3) Verificar se para essas contas consta na composicao_valor ou noutro campo da fr802 a indicação de comissão ou despesa 4) Verificar se esta comissão ficou ou não incluida no gross carrying amount (provavelmente foi incluido). 5) Verificar na fr004 se já existe lá este conceito de comissão (só seria para adicionar na fr004 caso fosse um conceito que faça sentido para a contabilidade) 6) Tabela de conceitos ct872 (tem os conceitos com base em campos da fr802): criar nesta tabela o conceito caso ele não exista. | Q15: Campo não LT (apenas tabela Output) | R15: Concluído | S15: NÃO | T15: =IF(SEARCH(B15,N15,4),"ok","nok") -> ok
A16: Outstanding amount | B16: 0120 | C16: Numeric | D16: 2 decimals | E16: Total EUR value of the outstanding amount of the instrument/deposit held by the counterparty, calculated as the sum of the amounts reported in data points c0080, c0100 and c0110 (where applicable). The amount is in fact the aggregate of the outstanding principal amount plus, if applicable, interest accrued up to the reference date, and fees and charges, irrespective of whether and to what extent the relevant principal, interest or fee-and-charge liability was already due as at the reference date and whether it is required to be recognised as a liability item in the relevant entity’s balance sheet drawn up in accordance with the applicable accounting principles. In jurisdictions where accrued interest may not rank pari passu to the liability amount, the relevant NRA may request the reporting of interest accruals on separate line items. | F16: Input 999999999999999 | I16: Não | N16: out_b0200_main_liabilities.0120_otstndng_amnt | O16: Soma dos 3 campos acima (0080, 0100 e 0110 ): Outstanding principal amount + Accrued interest + Applicable fees and charges | P16: Reunião 2025-10-09 Luís Capitão-Mor, Pedro Mendes Reunião 2025-09-22 Luís Capitão-Mor, Pedro Mendes, Luísa Sousa: Tem de se ter presente que neste campo vamos somar o "Outstanding principal amount" (que não é contabilístico, vem da ct610_titulos) com o "Accrued interest" (que é contabilístico) e com o "Applicable fees and charges" (que é contabilístico). Ou seja, 2 campos vão-se buscar à Contabilidade mas 1 campo não se vai buscar à Contabilidade, o que não é totalmente coerente. Contudo, não se vê tema dado que o SRB não refere que este campo tem de "bater" com a Contabilidade. | Q16: Campo não LT (apenas tabela Output) | R16: Concluído | S16: SIM | T16: =IF(SEARCH(B16,N16,4),"ok","nok") -> ok
A17: Relevant amount for Bail-in/WDC | B17: 0130 | C17: Numeric | D17: 2 decimals | E17: Total EUR value of the amount eligible for write-down / conversion. Pursuant to Article 48(1) BRRD, resolution authorities shall exercise the write-down and conversion powers in accordance with the cascade set out in letters (a) to (e) of Article 48(1) BRRD. Article 48(2) BRRD further provides that "when applying the write down or conversion powers, resolution authorities shall allocate the losses [...] by reducing the principal amount of, or outstanding amount payable in respect of, those shares or other instruments of ownership and bail-inable liabilities to the same extent pro rata to their value (42) […]". The portion of eligible liabilities subscribed by intragroup entities and excluded under Article 27(3)(h) SRMR must not be reported as part of the relevant amount for bail-in / WDC. When determining the relevant amount for bail-in, entities shall take into account national laws that transpose the BRRD. If those provisions do not provide complete and clear guidance for determining the relevant amount for bail-in, careful consideration should in general be given to how the item in question is dealt with under applicable insolvency legislation43. Furthermore, the contractual terms governing each liability might provide additional insight when performing this assessment. For debt instruments with embedded derivatives, the following list of items shall be considered: ▪ Any contractually defined floor or cap to the final redemption amount. ▪ Any contractually defined early termination amount, if such amount is deemed to represent the investor’s claim in insolvency/resolution. ▪ The performance of the underlying, whenever it impacts the repayment of the principal amount. ▪ The contractual provisions ruling the payment of interests, to assess whether the accrued component can be properly determined and is relevant for bail-in purposes. ▪ The inclusion of an Article 12c(2)(b) SRMR clause. ▪ Any element relevant to Article 12c(2)(a) SRMR. ▪ Any settlement/close out costs. ▪ Any other term, condition, rule, mechanism or element affecting the making, timing and amount of any kind of payment owed to the holders of the debt instruments with embedded derivatives (please specify). Without prejudice to the considerations above, in principle: • the relevant amount for bail-in is defined as the outstanding amount (including accrued interest and fees, when applicable) less any existing components subject to exemptions according to Article 27(3) SRMR (e.g. covered share for bail-inable deposits indicated in data point c0300), or other factors affecting the conversion amount (e.g. safeguards under Articles 76 to 80 BRRD, as applicable); • for zero coupon bonds issued at discount (i.e. c0240 = ZCB issued at discount), the amount to be reported is the amortised face value (i.e. initially paid up amount plus accrued component of the discount) plus any applicable fees and charges (c0110); and • for structured instruments, the amount reported in field c0270 minus the value of the collateral (if given) should in principle be considered the relevant amount. In case of products where the derivative component is only affecting the coupon payment (i.e. c0250 = Only structured coupon), please refer to the points above.applicable insolvency legislation43. Furthermore, the contractual terms governing each liability might provide additional insight when performing this assessment. For debt instruments with embedded derivatives, the following list of items shall be considered: ▪ Any contractually defined floor or cap to the final redemption amount. ▪ Any contractually defined early termination amount, if such amount is deemed to represent the investor’s claim in insolvency/resolution. ▪ The performance of the underlying, whenever it impacts the repayment of the principal amount. ▪ The contractual provisions ruling the payment of interests, to assess whether the accrued component can be properly determined and is relevant for bail-in purposes. ▪ The inclusion of an Article 12c(2)(b) SRMR clause. ▪ Any element relevant to Article 12c(2)(a) SRMR. ▪ Any settlement/close out costs. ▪ Any other term, condition, rule, mechanism or element affecting the making, timing and amount of any kind of payment owed to the holders of the debt instruments with embedded derivatives (please specify). Without prejudice to the considerations above, in principle: • the relevant amount for bail-in is defined as the outstanding amount (including accrued interest and fees, when applicable) less any existing components subject to exemptions according to Article 27(3) SRMR (e.g. covered share for bail-inable deposits indicated in data point c0300), or other factors affecting the conversion amount (e.g. safeguards under Articles 76 to 80 BRRD, as applicable); • for zero coupon bonds issued at discount (i.e. c0240 = ZCB issued at discount), the amount to be reported is the amortised face value (i.e. initially paid up amount plus accrued component of the discount) plus any applicable fees and charges (c0110); and • for structured instruments, the amount reported in field c0270 minus the value of the collateral (if given) should in principle be considered the relevant amount. In case of products where the derivative component is only affecting the coupon payment (i.e. c0250 = Only structured coupon), please refer to the points above. In jurisdictions where accrued interest may not rank pari passu to the liability amount, the relevant NRA may request the reporting of interest accruals on separate line items. Own holdings (identified in field c0090) should be deducted. (42) - For the definition of ‘value’, please refer to EBA Q&A 2017_3629 (https://www.eba.europa.eu/single-rule-book-qa/- /qna/view/publicId/2017_3629). | I17: Não | N17: out_b0200_main_liabilities.0130_rlvnt_amnt_wdc | O17: Reportar Outstanding amount (0120) | P17: Reunião 2025-09-24 Luís Capitão-Mor, Pedro Mendes: Segundo Pedro Mendes, neste campo deve reportar-se o mesmo que é reportado no Outstanding amount (0120). O Outstanding amount (0120) é a Soma de 3 campos: Outstanding principal amount (0080) + Accrued interest (0100) + Applicable fees and charges (0110). Não se deve reportar o Outstanding principal amount (0040) dado que não contém juros, e segundo Pedro Mendes em caso de resolução os juros devem ser considerados (apesar de na definição não ser referido pelo SRB que se pretende juros), como tal, deve apontar-se para o Outstanding amount (0120), que contém juros. O Outstanding amount (0120) também contém Applicable fees and charges (0110), mas esse campo conterá valor fixo 0. | Q17: Campo não LT (apenas tabela Output) | R17: Concluído | S17: SIM | T17: =IF(SEARCH(B17,N17,4),"ok","nok") -> ok
A18: Nature of the liability | B18: 0140 | C18: String | D18: Drop-down | E18: The corresponding category of the instrument/liability. Value to be chosen from the following drop-down list: • Registered Bond • Bearer Bond • Borrower Note Loan • Certificate of Deposit / Commercial paper • Title of ownership44 • Cash account/saving account45 • Term deposit46 • Loan • Bill of exchange • Other For deposits reported on an aggregated level (Submission A), please indicate ‘Other’. | I18: Não | J18: lt002_instrument.typ_instrmnt | L18: {=_xlfn.SWITCH(C18,"Numeric","999999999999999","String","Not applicable","Date","0001-01-01")} -> Not applicable | M18: Necessário criar novas parametrizações nas tabelas lt829_regras_conversao e lt830_conversoes, podendo as mesmas ser consultadas neste documento nas sheets: LT829 - filtrando por campo_conceito = 'TYP_INSTRMNT' e regra_conversao = '2'; LT830 - filtrando por segmento = 'ESTR' e campo_conceito = 'TYP_INSTRMNT'. | N18: out_b0200_main_liabilities.0140_ntr_lblty | O18: lt002_instrument.typ_instrmnt | P18: Parametrizações da lt829_regras_conversao e da lt830_conversoes validadas com Luísa Sousa em 2025-08-13. Adicionalmente, acrescentou-se na lt831_param_conceitos uma nova linha com instrmnt_fncr='titulos de divida emitidos' a mapear para o valor_destino='1005' dado que estes registos estavam a ser preenchidos com typ_instrmnt= '2020' (ou seja, 'Other'). Reunião 2025-07-25 Luís Capitão-Mor, Luísa Sousa | Q18: Campo já existente no LT | R18: Concluído | S18: NÃO | T18: =IF(SEARCH(B18,N18,4),"ok","nok") -> ok
A19: Nature of the liability (if other) | B19: 0141 | C19: String | D19: Free text | E19: Free text. If ‘Other’ is selected in field c0140, include a meaningful description of the nature of the liability. | I19: Não | N19: out_b0200_main_liabilities.0141_ntr_lblty_othr | O19: Valor fixo 'Not applicable' | P19: Email Pedro Mendes 12/01/2026 17:20: Considerou-se que o campo "Nature of the liability" (c0140) terá sempre um valor diferente de 'Other' e por conseguinte o campo "Nature of the liability (if other)" nunca terá valor. Como tal, sugere-se o preenchimento deste campo com valor fixo 'Not applicable'. Reunião 2025-07-25 Luís Capitão-Mor, Luísa Sousa | Q19: Campo não LT (apenas tabela Output) | R19: Concluído | S19: NÃO | T19: =IF(SEARCH(B19,N19,4),"ok","nok") -> ok
A20: Structurally subordinated | B20: 0150 | C20: String | D20: TRUE / FALSE boolean | E20: Indicate whether the instrument is considered structurally subordinated (i.e. groups with a HoldCo/OpCo structure). The value to be reported is a TRUE/FALSE Boolean. | I20: Não | N20: out_b0200_main_liabilities.0150_flg_strctrlly_sbrdntd | O20: Valor fixo 'Not applicable' | P20: Reunião 2025-06-23 Luís Capitão-Mor, Pedro Mendes, Luísa Sousa: Segundo o anexo III, este campo deve, em princípio, ser considerado não aplicável para non-resolution entities. Pedro Mendes enviou email dia 24-06 confirmando que este campo é não aplicável. "Sim, confirmo que todos os campos são não aplicáveis." | Q20: Campo não LT (apenas tabela Output) | R20: Concluído | S20: NÃO | T20: =IF(SEARCH(B20,N20,4),"ok","nok") -> ok
A21: Insolvency ranking | B21: 0160 | C21: Numeric | D21: Integer | E21: The corresponding insolvency ranking of the instrument. Numeric value (e.g. integer of 1 or more). | I21: Sim | J21: lt002_instrument.rank_insolv | L21: {=_xlfn.SWITCH(C21,"Numeric","999999999999999","String","Not applicable","Date","0001-01-01")} -> 999999999999999 | M21: Se flag_inst_titulos = '1': Obter rank_insolv da ct610_titulos; Se flag_inst_titulos = '0': Não preencher | N21: out_b0200_main_liabilities.0160_rank_insolv | O21: lt002_instrument.rank_insolv | P21: Reunião 2025-06-20 Luís Capitão-Mor, Pedro Mendes, Luísa Sousa | Q21: Campo novo no LT | R21: Concluído | S21: NÃO | T21: =IF(SEARCH(B21,N21,4),"ok","nok") -> ok
A22: Contractual subordination | B22: 0161 | C22: Numeric | D22: 2 decimals | E22: Numeric sequence to indicate whether an instrument/liability is subordinated within the same insolvency rank as a result of its own contractual terms. The inclusion of these contractual terms should duly consider paragraph 141 of the EBA report on the monitoring of Additional Tier 1 (AT1) instruments of European Union (EU) institutions47, as well as any country-specific provision in this regard. The value of the field must be indicated using the corresponding insolvency ranking to which the instrument pertains and the numeric sequence of its contractual subordination, separated by a dot (e.g. two instruments in insolvency rank 2 subordinated to each other will have this field set to 2.01 and 2.02). Please refer to the specific reporting example (Annex II, paragraph 3.6). | F22: Input 999999999999999 | I22: Não | N22: out_b0200_main_liabilities.0161_cntrctl_sbrdntn | O22: Valor fixo 999999999999999 | P22: Reunião 2025-07-31 Luís Capitão-Mor, Pedro Mendes: Segundo Pedro Mendes, este campo é not applicable porque na nossa operativa as emissões têm sempre o mesmo grau de subordinação dentro do mesmo ranking. Ou seja, por exemplo no caso do ranking 4 não teremos 4.01, 4.02, 4.03 dado que é tudo ranking 4. | Q22: Campo não LT (apenas tabela Output) | R22: Concluído | S22: NÃO | T22: =IF(SEARCH(B22,N22,4),"ok","nok") -> ok
A23: Bail-in cascade | B23: 162 | C23: String | D23: Fixed values | E23: (Alpha)numeric sequence to indicate the order of write-down and conversion pursuant to Article 48 BRRD. If the priority order of this cascade differs from the one stemming from the insolvency ranking reported in field c0160, please refer to the relevant Country Annex or to the specific instructions provided by the relevant NRA/IRT. When allowed under the applicable national law, institutions must reflect in this sequence the order provided by the applicable contractual subordination. Please refer to the specific reporting example (Annex II, paragraph 3.6). The bail-in cascade assigned to secured liabilities shall always be the one applicable to the (potentially) unsecured part of the liability based on the current internal valuation of the collateral by the bank. | I23: Não | J23: lt002_instrument.rank_insolv | L23: {=_xlfn.SWITCH(C23,"Numeric","999999999999999","String","Not applicable","Date","0001-01-01")} -> Not applicable | N23: out_b0200_main_liabilities.0162_bail_in_cascade | O23: lt002_instrument.rank_insolv | P23: Reunião 2025-07-30 Luís Capitão-Mor, Pedro Mendes, Luísa Sousa: No caso de Portugal o bail-in cascade é igual ao ranking de insolvência. | Q23: Campo não LT (apenas tabela Output) | R23: Concluído | S23: NÃO | T23: =IF(SEARCH(B23,N23,4),"ok","nok") -> ok
