Workbook

Sheet 1. Status Resumo
B6: Sumário Executivo |11 de outubro a 18 de outubro
B8: 1. Implementação em ambiente de Produção das tabelas já testadas e certificadas. A partir de dia 24 já será possível testar a tabela de input da Gloval. 2. Não existiram desenvolvimentos no âmito do Modelo Verde. 3. Foram concluídos 9 campos, permitindo fechar a 3ª tabela da Loan Tape Pilar III. Adicionalmente, foram fechadas as re-especificações de 12 campos.
B22: 1. Modelo de Bens Imóveis | G22: Bens Imóveis - Input | H22: Bens Imóveis - Output
C25: Resumo | G25: Detalhe por Tabela | P25: Status (campos) | T25: 45576 | U25: =T25+7 -> 45583 | V25: ∆ | X25: Highlights
P26: 0. Cancelado | T26: =COUNTIFS('2. Status Detalhe Campos'!$H$7:$H$615,'1. Status Resumo'!$P26,'2. Status Detalhe Campos'!$C$7:$C$615,'1. Status Resumo'!$G$22,'2. Status Detalhe Campos'!$D$7:$D$615,"2. Campo")+COUNTIFS('2. Status Detalhe Campos'!$H$7:$H$615,'1. Status Resumo'!$P26,'2. Status Detalhe Campos'!$C$7:$C$615,'1. Status Resumo'!$H$22,'2. Status Detalhe Campos'!$D$7:$D$615,"2. Campo") -> 10 | U26: =COUNTIFS('2. Status Detalhe Campos'!$G$7:$G$615,'1. Status Resumo'!$P26,'2. Status Detalhe Campos'!$C$7:$C$615,'1. Status Resumo'!$G$22,'2. Status Detalhe Campos'!$D$7:$D$615,"2. Campo")+COUNTIFS('2. Status Detalhe Campos'!$G$7:$G$615,'1. Status Resumo'!$P26,'2. Status Detalhe Campos'!$C$7:$C$615,'1. Status Resumo'!$H$22,'2. Status Detalhe Campos'!$D$7:$D$615,"2. Campo") -> 10 | V26: =U26-T26 -> 0 | X26: 1. Partilha de ajustes à especificação do campo EPC da tabela de Certificados. 2. Datas de entrega de Tecnologia: - Entrada em produção (das 4 tabelas certificadas): 17/10/2024 - Disponibilização do carrgamento de input da Gloval (via front de Upload de Ficheiros): 24/10/2024 - Disponibilização da tabela de output de Certificados Energéticos (com as 4 fontes de informação): 11/11/2024 - Disponibilização de funcionalidades de Pedido de informação para a Gloval: 28/11/2024
P27: 1. Concluído | T27: =COUNTIFS('2. Status Detalhe Campos'!$H$7:$H$615,'1. Status Resumo'!$P27,'2. Status Detalhe Campos'!$C$7:$C$615,'1. Status Resumo'!$G$22,'2. Status Detalhe Campos'!$D$7:$D$615,"2. Campo")+COUNTIFS('2. Status Detalhe Campos'!$H$7:$H$615,'1. Status Resumo'!$P27,'2. Status Detalhe Campos'!$C$7:$C$615,'1. Status Resumo'!$H$22,'2. Status Detalhe Campos'!$D$7:$D$615,"2. Campo") -> 124 | U27: =COUNTIFS('2. Status Detalhe Campos'!$G$7:$G$615,'1. Status Resumo'!$P27,'2. Status Detalhe Campos'!$C$7:$C$615,'1. Status Resumo'!$G$22,'2. Status Detalhe Campos'!$D$7:$D$615,"2. Campo")+COUNTIFS('2. Status Detalhe Campos'!$G$7:$G$615,'1. Status Resumo'!$P27,'2. Status Detalhe Campos'!$C$7:$C$615,'1. Status Resumo'!$H$22,'2. Status Detalhe Campos'!$D$7:$D$615,"2. Campo") -> 124 | V27: =U27-T27 -> 0
P28: 2.1 Em Teste | T28: =COUNTIFS('2. Status Detalhe Campos'!$H$7:$H$615,'1. Status Resumo'!$P28,'2. Status Detalhe Campos'!$C$7:$C$615,'1. Status Resumo'!$G$22,'2. Status Detalhe Campos'!$D$7:$D$615,"2. Campo")+COUNTIFS('2. Status Detalhe Campos'!$H$7:$H$615,'1. Status Resumo'!$P28,'2. Status Detalhe Campos'!$C$7:$C$615,'1. Status Resumo'!$H$22,'2. Status Detalhe Campos'!$D$7:$D$615,"2. Campo") -> 0 | U28: =COUNTIFS('2. Status Detalhe Campos'!$G$7:$G$615,'1. Status Resumo'!$P28,'2. Status Detalhe Campos'!$C$7:$C$615,'1. Status Resumo'!$G$22,'2. Status Detalhe Campos'!$D$7:$D$615,"2. Campo")+COUNTIFS('2. Status Detalhe Campos'!$G$7:$G$615,'1. Status Resumo'!$P28,'2. Status Detalhe Campos'!$C$7:$C$615,'1. Status Resumo'!$H$22,'2. Status Detalhe Campos'!$D$7:$D$615,"2. Campo") -> 0 | V28: =U28-T28 -> 0
D29: ="# "&U35 -> # 168 | P29: 2.2 Em Re-especificação | T29: =COUNTIFS('2. Status Detalhe Campos'!$H$7:$H$615,'1. Status Resumo'!$P29,'2. Status Detalhe Campos'!$C$7:$C$615,'1. Status Resumo'!$G$22,'2. Status Detalhe Campos'!$D$7:$D$615,"2. Campo")+COUNTIFS('2. Status Detalhe Campos'!$H$7:$H$615,'1. Status Resumo'!$P29,'2. Status Detalhe Campos'!$C$7:$C$615,'1. Status Resumo'!$H$22,'2. Status Detalhe Campos'!$D$7:$D$615,"2. Campo") -> 0 | U29: =COUNTIFS('2. Status Detalhe Campos'!$G$7:$G$615,'1. Status Resumo'!$P29,'2. Status Detalhe Campos'!$C$7:$C$615,'1. Status Resumo'!$G$22,'2. Status Detalhe Campos'!$D$7:$D$615,"2. Campo")+COUNTIFS('2. Status Detalhe Campos'!$G$7:$G$615,'1. Status Resumo'!$P29,'2. Status Detalhe Campos'!$C$7:$C$615,'1. Status Resumo'!$H$22,'2. Status Detalhe Campos'!$D$7:$D$615,"2. Campo") -> 0 | V29: =U29-T29 -> 0
P30: 3. Pendente de outros desenvolvimentos | T30: =COUNTIFS('2. Status Detalhe Campos'!$H$7:$H$615,'1. Status Resumo'!$P30,'2. Status Detalhe Campos'!$C$7:$C$615,'1. Status Resumo'!$G$22,'2. Status Detalhe Campos'!$D$7:$D$615,"2. Campo")+COUNTIFS('2. Status Detalhe Campos'!$H$7:$H$615,'1. Status Resumo'!$P30,'2. Status Detalhe Campos'!$C$7:$C$615,'1. Status Resumo'!$H$22,'2. Status Detalhe Campos'!$D$7:$D$615,"2. Campo") -> 0 | U30: =COUNTIFS('2. Status Detalhe Campos'!$G$7:$G$615,'1. Status Resumo'!$P30,'2. Status Detalhe Campos'!$C$7:$C$615,'1. Status Resumo'!$G$22,'2. Status Detalhe Campos'!$D$7:$D$615,"2. Campo")+COUNTIFS('2. Status Detalhe Campos'!$G$7:$G$615,'1. Status Resumo'!$P30,'2. Status Detalhe Campos'!$C$7:$C$615,'1. Status Resumo'!$H$22,'2. Status Detalhe Campos'!$D$7:$D$615,"2. Campo") -> 0 | V30: =U30-T30 -> 0
P31: 4. Validação EF | T31: =COUNTIFS('2. Status Detalhe Campos'!$H$7:$H$615,'1. Status Resumo'!$P31,'2. Status Detalhe Campos'!$C$7:$C$615,'1. Status Resumo'!$G$22,'2. Status Detalhe Campos'!$D$7:$D$615,"2. Campo")+COUNTIFS('2. Status Detalhe Campos'!$H$7:$H$615,'1. Status Resumo'!$P31,'2. Status Detalhe Campos'!$C$7:$C$615,'1. Status Resumo'!$H$22,'2. Status Detalhe Campos'!$D$7:$D$615,"2. Campo") -> 0 | U31: =COUNTIFS('2. Status Detalhe Campos'!$G$7:$G$615,'1. Status Resumo'!$P31,'2. Status Detalhe Campos'!$C$7:$C$615,'1. Status Resumo'!$G$22,'2. Status Detalhe Campos'!$D$7:$D$615,"2. Campo")+COUNTIFS('2. Status Detalhe Campos'!$G$7:$G$615,'1. Status Resumo'!$P31,'2. Status Detalhe Campos'!$C$7:$C$615,'1. Status Resumo'!$H$22,'2. Status Detalhe Campos'!$D$7:$D$615,"2. Campo") -> 0 | V31: =U31-T31 -> 0
P32: 5. Em Correção | R32: (incidências) | T32: =COUNTIFS('2. Status Detalhe Campos'!$H$7:$H$615,'1. Status Resumo'!$P32,'2. Status Detalhe Campos'!$C$7:$C$615,'1. Status Resumo'!$G$22,'2. Status Detalhe Campos'!$D$7:$D$615,"2. Campo")+COUNTIFS('2. Status Detalhe Campos'!$H$7:$H$615,'1. Status Resumo'!$P32,'2. Status Detalhe Campos'!$C$7:$C$615,'1. Status Resumo'!$H$22,'2. Status Detalhe Campos'!$D$7:$D$615,"2. Campo") -> 0 | U32: =COUNTIFS('2. Status Detalhe Campos'!$G$7:$G$615,'1. Status Resumo'!$P32,'2. Status Detalhe Campos'!$C$7:$C$615,'1. Status Resumo'!$G$22,'2. Status Detalhe Campos'!$D$7:$D$615,"2. Campo")+COUNTIFS('2. Status Detalhe Campos'!$G$7:$G$615,'1. Status Resumo'!$P32,'2. Status Detalhe Campos'!$C$7:$C$615,'1. Status Resumo'!$H$22,'2. Status Detalhe Campos'!$D$7:$D$615,"2. Campo") -> 0 | V32: =U32-T32 -> 0
P33: 6. Em implementação (re-especificação) | T33: =COUNTIFS('2. Status Detalhe Campos'!$H$7:$H$615,'1. Status Resumo'!$P33,'2. Status Detalhe Campos'!$C$7:$C$615,'1. Status Resumo'!$G$22,'2. Status Detalhe Campos'!$D$7:$D$615,"2. Campo")+COUNTIFS('2. Status Detalhe Campos'!$H$7:$H$615,'1. Status Resumo'!$P33,'2. Status Detalhe Campos'!$C$7:$C$615,'1. Status Resumo'!$H$22,'2. Status Detalhe Campos'!$D$7:$D$615,"2. Campo") -> 34 | U33: =COUNTIFS('2. Status Detalhe Campos'!$G$7:$G$615,'1. Status Resumo'!$P33,'2. Status Detalhe Campos'!$C$7:$C$615,'1. Status Resumo'!$G$22,'2. Status Detalhe Campos'!$D$7:$D$615,"2. Campo")+COUNTIFS('2. Status Detalhe Campos'!$G$7:$G$615,'1. Status Resumo'!$P33,'2. Status Detalhe Campos'!$C$7:$C$615,'1. Status Resumo'!$H$22,'2. Status Detalhe Campos'!$D$7:$D$615,"2. Campo") -> 34 | V33: =U33-T33 -> 0
P34: 7. Por iniciar | T34: =COUNTIFS('2. Status Detalhe Campos'!$H$7:$H$615,'1. Status Resumo'!$P34,'2. Status Detalhe Campos'!$C$7:$C$615,'1. Status Resumo'!$G$22,'2. Status Detalhe Campos'!$D$7:$D$615,"2. Campo")+COUNTIFS('2. Status Detalhe Campos'!$H$7:$H$615,'1. Status Resumo'!$P34,'2. Status Detalhe Campos'!$C$7:$C$615,'1. Status Resumo'!$H$22,'2. Status Detalhe Campos'!$D$7:$D$615,"2. Campo") -> 0 | U34: =COUNTIFS('2. Status Detalhe Campos'!$G$7:$G$615,'1. Status Resumo'!$P34,'2. Status Detalhe Campos'!$C$7:$C$615,'1. Status Resumo'!$G$22,'2. Status Detalhe Campos'!$D$7:$D$615,"2. Campo")+COUNTIFS('2. Status Detalhe Campos'!$G$7:$G$615,'1. Status Resumo'!$P34,'2. Status Detalhe Campos'!$C$7:$C$615,'1. Status Resumo'!$H$22,'2. Status Detalhe Campos'!$D$7:$D$615,"2. Campo") -> 0 | V34: =U34-T34 -> 0
T35: =SUM(T26:T34) -> 168 | U35: =SUM(U26:U34) -> 168
G36: Status (Tabelas) | P36: Status (Universos)
F37: > | G37: Tabela de Bens Imóveis | L37: OK | O37: > | P37: Universo Bens Colateralizados (MUG) | T37: OK
F38: > | G38: Tabelas de Processos Imobiliários | L38: OK | O38: > | P38: Universo Bens Não Colateralizados (GP) | T38: OK
F39: > | G39: Tabela de Traçabilidade Processo -Bem | L39: OK | O39: > | P39: Universo Bens Adjudicados | T39: Não serão testados neste projeto
F40: > | G40: Tabela de Traçabilidade Crédito - Processo | L40: OK
F41: > | G41: Tabela input de Cerificados Energéticos (Gloval) | L41: Em Implementação
F42: > | G42: Tabela Output de Cerificados Energéticos | L42: Em Implementação
B48: 2. Modelo Verde | G48: Modelo Verde - Input | H48: Modelo Verde - Output
C51: Resumo | G51: Detalhe por Tabela | P51: Status (campos) | T51: =T25 -> 45576 | U51: =$U$25 -> 45583 | V51: ∆ | X51: Highlights
P52: 0. Cancelado | T52: =COUNTIFS('2. Status Detalhe Campos'!$H$7:$H$615,'1. Status Resumo'!$P52,'2. Status Detalhe Campos'!$C$7:$C$615,'1. Status Resumo'!$G$48,'2. Status Detalhe Campos'!$D$7:$D$615,"2. Campo")+COUNTIFS('2. Status Detalhe Campos'!$H$7:$H$615,'1. Status Resumo'!$P52,'2. Status Detalhe Campos'!$C$7:$C$615,'1. Status Resumo'!$H$48,'2. Status Detalhe Campos'!$D$7:$D$615,"2. Campo") -> 14 | U52: =COUNTIFS('2. Status Detalhe Campos'!$G$7:$G$615,'1. Status Resumo'!$P52,'2. Status Detalhe Campos'!$C$7:$C$615,'1. Status Resumo'!$G$48,'2. Status Detalhe Campos'!$D$7:$D$615,"2. Campo")+COUNTIFS('2. Status Detalhe Campos'!$G$7:$G$615,'1. Status Resumo'!$P52,'2. Status Detalhe Campos'!$C$7:$C$615,'1. Status Resumo'!$H$48,'2. Status Detalhe Campos'!$D$7:$D$615,"2. Campo") -> 14 | V52: =U52-T52 -> 0 | X52: 1. Campos Em Implementação (re-especificão) ou Em Correção.
P53: 1. Concluído | T53: =COUNTIFS('2. Status Detalhe Campos'!$H$7:$H$615,'1. Status Resumo'!$P53,'2. Status Detalhe Campos'!$C$7:$C$615,'1. Status Resumo'!$G$48,'2. Status Detalhe Campos'!$D$7:$D$615,"2. Campo")+COUNTIFS('2. Status Detalhe Campos'!$H$7:$H$615,'1. Status Resumo'!$P53,'2. Status Detalhe Campos'!$C$7:$C$615,'1. Status Resumo'!$H$48,'2. Status Detalhe Campos'!$D$7:$D$615,"2. Campo") -> 154 | U53: =COUNTIFS('2. Status Detalhe Campos'!$G$7:$G$615,'1. Status Resumo'!$P53,'2. Status Detalhe Campos'!$C$7:$C$615,'1. Status Resumo'!$G$48,'2. Status Detalhe Campos'!$D$7:$D$615,"2. Campo")+COUNTIFS('2. Status Detalhe Campos'!$G$7:$G$615,'1. Status Resumo'!$P53,'2. Status Detalhe Campos'!$C$7:$C$615,'1. Status Resumo'!$H$48,'2. Status Detalhe Campos'!$D$7:$D$615,"2. Campo") -> 154 | V53: =U53-T53 -> 0
P54: 2.1 Em Teste | T54: =COUNTIFS('2. Status Detalhe Campos'!$H$7:$H$615,'1. Status Resumo'!$P54,'2. Status Detalhe Campos'!$C$7:$C$615,'1. Status Resumo'!$G$48,'2. Status Detalhe Campos'!$D$7:$D$615,"2. Campo")+COUNTIFS('2. Status Detalhe Campos'!$H$7:$H$615,'1. Status Resumo'!$P54,'2. Status Detalhe Campos'!$C$7:$C$615,'1. Status Resumo'!$H$48,'2. Status Detalhe Campos'!$D$7:$D$615,"2. Campo") -> 0 | U54: =COUNTIFS('2. Status Detalhe Campos'!$G$7:$G$615,'1. Status Resumo'!$P54,'2. Status Detalhe Campos'!$C$7:$C$615,'1. Status Resumo'!$G$48,'2. Status Detalhe Campos'!$D$7:$D$615,"2. Campo")+COUNTIFS('2. Status Detalhe Campos'!$G$7:$G$615,'1. Status Resumo'!$P54,'2. Status Detalhe Campos'!$C$7:$C$615,'1. Status Resumo'!$H$48,'2. Status Detalhe Campos'!$D$7:$D$615,"2. Campo") -> 0 | V54: =U54-T54 -> 0
D55: ="# "&U61 -> # 245 | P55: 2.2 Em Re-especificação | T55: =COUNTIFS('2. Status Detalhe Campos'!$H$7:$H$615,'1. Status Resumo'!$P55,'2. Status Detalhe Campos'!$C$7:$C$615,'1. Status Resumo'!$G$48,'2. Status Detalhe Campos'!$D$7:$D$615,"2. Campo")+COUNTIFS('2. Status Detalhe Campos'!$H$7:$H$615,'1. Status Resumo'!$P55,'2. Status Detalhe Campos'!$C$7:$C$615,'1. Status Resumo'!$H$48,'2. Status Detalhe Campos'!$D$7:$D$615,"2. Campo") -> 0 | U55: =COUNTIFS('2. Status Detalhe Campos'!$G$7:$G$615,'1. Status Resumo'!$P55,'2. Status Detalhe Campos'!$C$7:$C$615,'1. Status Resumo'!$G$48,'2. Status Detalhe Campos'!$D$7:$D$615,"2. Campo")+COUNTIFS('2. Status Detalhe Campos'!$G$7:$G$615,'1. Status Resumo'!$P55,'2. Status Detalhe Campos'!$C$7:$C$615,'1. Status Resumo'!$H$48,'2. Status Detalhe Campos'!$D$7:$D$615,"2. Campo") -> 0 | V55: =U55-T55 -> 0
P56: 3. Pendente de outros desenvolvimentos | T56: =COUNTIFS('2. Status Detalhe Campos'!$H$7:$H$615,'1. Status Resumo'!$P56,'2. Status Detalhe Campos'!$C$7:$C$615,'1. Status Resumo'!$G$48,'2. Status Detalhe Campos'!$D$7:$D$615,"2. Campo")+COUNTIFS('2. Status Detalhe Campos'!$H$7:$H$615,'1. Status Resumo'!$P56,'2. Status Detalhe Campos'!$C$7:$C$615,'1. Status Resumo'!$H$48,'2. Status Detalhe Campos'!$D$7:$D$615,"2. Campo") -> 0 | U56: =COUNTIFS('2. Status Detalhe Campos'!$G$7:$G$615,'1. Status Resumo'!$P56,'2. Status Detalhe Campos'!$C$7:$C$615,'1. Status Resumo'!$G$48,'2. Status Detalhe Campos'!$D$7:$D$615,"2. Campo")+COUNTIFS('2. Status Detalhe Campos'!$G$7:$G$615,'1. Status Resumo'!$P56,'2. Status Detalhe Campos'!$C$7:$C$615,'1. Status Resumo'!$H$48,'2. Status Detalhe Campos'!$D$7:$D$615,"2. Campo") -> 0 | V56: =U56-T56 -> 0
P57: 4. Validação EF | T57: =COUNTIFS('2. Status Detalhe Campos'!$H$7:$H$615,'1. Status Resumo'!$P57,'2. Status Detalhe Campos'!$C$7:$C$615,'1. Status Resumo'!$G$48,'2. Status Detalhe Campos'!$D$7:$D$615,"2. Campo")+COUNTIFS('2. Status Detalhe Campos'!$H$7:$H$615,'1. Status Resumo'!$P57,'2. Status Detalhe Campos'!$C$7:$C$615,'1. Status Resumo'!$H$48,'2. Status Detalhe Campos'!$D$7:$D$615,"2. Campo") -> 0 | U57: =COUNTIFS('2. Status Detalhe Campos'!$G$7:$G$615,'1. Status Resumo'!$P57,'2. Status Detalhe Campos'!$C$7:$C$615,'1. Status Resumo'!$G$48,'2. Status Detalhe Campos'!$D$7:$D$615,"2. Campo")+COUNTIFS('2. Status Detalhe Campos'!$G$7:$G$615,'1. Status Resumo'!$P57,'2. Status Detalhe Campos'!$C$7:$C$615,'1. Status Resumo'!$H$48,'2. Status Detalhe Campos'!$D$7:$D$615,"2. Campo") -> 0 | V57: =U57-T57 -> 0
P58: 5. Em Correção | R58: (incidências) | T58: =COUNTIFS('2. Status Detalhe Campos'!$H$7:$H$615,'1. Status Resumo'!$P58,'2. Status Detalhe Campos'!$C$7:$C$615,'1. Status Resumo'!$G$48,'2. Status Detalhe Campos'!$D$7:$D$615,"2. Campo")+COUNTIFS('2. Status Detalhe Campos'!$H$7:$H$615,'1. Status Resumo'!$P58,'2. Status Detalhe Campos'!$C$7:$C$615,'1. Status Resumo'!$H$48,'2. Status Detalhe Campos'!$D$7:$D$615,"2. Campo") -> 2 | U58: =COUNTIFS('2. Status Detalhe Campos'!$G$7:$G$615,'1. Status Resumo'!$P58,'2. Status Detalhe Campos'!$C$7:$C$615,'1. Status Resumo'!$G$48,'2. Status Detalhe Campos'!$D$7:$D$615,"2. Campo")+COUNTIFS('2. Status Detalhe Campos'!$G$7:$G$615,'1. Status Resumo'!$P58,'2. Status Detalhe Campos'!$C$7:$C$615,'1. Status Resumo'!$H$48,'2. Status Detalhe Campos'!$D$7:$D$615,"2. Campo") -> 2 | V58: =U58-T58 -> 0
P59: 6. Em implementação (re-especificação) | T59: =COUNTIFS('2. Status Detalhe Campos'!$H$7:$H$615,'1. Status Resumo'!$P59,'2. Status Detalhe Campos'!$C$7:$C$615,'1. Status Resumo'!$G$48,'2. Status Detalhe Campos'!$D$7:$D$615,"2. Campo")+COUNTIFS('2. Status Detalhe Campos'!$H$7:$H$615,'1. Status Resumo'!$P59,'2. Status Detalhe Campos'!$C$7:$C$615,'1. Status Resumo'!$H$48,'2. Status Detalhe Campos'!$D$7:$D$615,"2. Campo") -> 75 | U59: =COUNTIFS('2. Status Detalhe Campos'!$G$7:$G$615,'1. Status Resumo'!$P59,'2. Status Detalhe Campos'!$C$7:$C$615,'1. Status Resumo'!$G$48,'2. Status Detalhe Campos'!$D$7:$D$615,"2. Campo")+COUNTIFS('2. Status Detalhe Campos'!$G$7:$G$615,'1. Status Resumo'!$P59,'2. Status Detalhe Campos'!$C$7:$C$615,'1. Status Resumo'!$H$48,'2. Status Detalhe Campos'!$D$7:$D$615,"2. Campo") -> 75 | V59: =U59-T59 -> 0
P60: 7. Por iniciar | T60: =COUNTIFS('2. Status Detalhe Campos'!$H$7:$H$615,'1. Status Resumo'!$P60,'2. Status Detalhe Campos'!$C$7:$C$615,'1. Status Resumo'!$G$48,'2. Status Detalhe Campos'!$D$7:$D$615,"2. Campo")+COUNTIFS('2. Status Detalhe Campos'!$H$7:$H$615,'1. Status Resumo'!$P60,'2. Status Detalhe Campos'!$C$7:$C$615,'1. Status Resumo'!$H$48,'2. Status Detalhe Campos'!$D$7:$D$615,"2. Campo") -> 0 | U60: =COUNTIFS('2. Status Detalhe Campos'!$G$7:$G$615,'1. Status Resumo'!$P60,'2. Status Detalhe Campos'!$C$7:$C$615,'1. Status Resumo'!$G$48,'2. Status Detalhe Campos'!$D$7:$D$615,"2. Campo")+COUNTIFS('2. Status Detalhe Campos'!$G$7:$G$615,'1. Status Resumo'!$P60,'2. Status Detalhe Campos'!$C$7:$C$615,'1. Status Resumo'!$H$48,'2. Status Detalhe Campos'!$D$7:$D$615,"2. Campo") -> 0 | V60: =U60-T60 -> 0
T61: =SUM(T52:T60) -> 245 | U61: =SUM(U52:U60) -> 245
P63: Status (Universos - Inputs)
O64: > | P64: modesg_inp_risco_fisico | T64: OK
O65: > | P65: modesg_inp_nfrd_alinhamento_tax | T65: OK
O66: > | P66: modesg_inp_km_medios_emss_vcls | T66: OK
O67: > | P67: modesg_inp_emss_vcls | T67: OK
O68: > | P68: modesg_inp_emss_scib | T68: OK
O69: > | P69: modesg_inp_emss_nace | T69: OK
...

Sheet 2. Status Detalhe Campos
B6: Âmbito | C6: Sub-âmbito | D6: Tipo de teste | E6: Tabela | F6: Campo | G6: Status Atual | H6: Status Anterior | I6: Observações | J6: Data de Pedido correção/esclarecimento | K6: Data de correção prevista | L6: Data de correção efetiva | M6: Data Reunião
A7: =E7&F7 -> ENERGY_CERTIFICATE_EST_INPUTn.a. | B7: Pilar III | C7: Bens Imóveis - Input | D7: 1. Universo | E7: ENERGY_CERTIFICATE_EST_INPUT | F7: n.a. | G7: 6. Em implementação (re-especificação) | H7: 6. Em implementação (re-especificação) | I7: Apesar da data de correção ser 28/11 a data que importa é 24/10, uma vez que a última implementação não é relevanta para iniciar os testes à tabela | J7: 45510 | K7: 45624
A8: =E8&F8 -> ENERGY_CERTIFICATE_EST_INPUTPROPERTY_BANK_ID | B8: Pilar III | C8: Bens Imóveis - Input | D8: 2. Campo | E8: ENERGY_CERTIFICATE_EST_INPUT | F8: PROPERTY_BANK_ID | G8: 6. Em implementação (re-especificação) | H8: 6. Em implementação (re-especificação) | I8: Apesar da data de correção ser 28/11 a data que importa é 24/10, uma vez que a última implementação não é relevanta para iniciar os testes à tabela | J8: 45510 | K8: 45624
A9: =E9&F9 -> ENERGY_CERTIFICATE_EST_INPUTENCRYPTED_KEY | B9: Pilar III | C9: Bens Imóveis - Input | D9: 2. Campo | E9: ENERGY_CERTIFICATE_EST_INPUT | F9: ENCRYPTED_KEY | G9: 6. Em implementação (re-especificação) | H9: 6. Em implementação (re-especificação) | I9: Apesar da data de correção ser 28/11 a data que importa é 24/10, uma vez que a última implementação não é relevanta para iniciar os testes à tabela | J9: 45510 | K9: 45624
A10: =E10&F10 -> ENERGY_CERTIFICATE_EST_INPUTPROPERTY_BRANCH_CODE | B10: Pilar III | C10: Bens Imóveis - Input | D10: 2. Campo | E10: ENERGY_CERTIFICATE_EST_INPUT | F10: PROPERTY_BRANCH_CODE | G10: 6. Em implementação (re-especificação) | H10: 6. Em implementação (re-especificação) | I10: Apesar da data de correção ser 28/11 a data que importa é 24/10, uma vez que a última implementação não é relevanta para iniciar os testes à tabela | J10: 45510 | K10: 45624
A11: =E11&F11 -> ENERGY_CERTIFICATE_EST_INPUTPROPERTY_CONTRACT_ID | B11: Pilar III | C11: Bens Imóveis - Input | D11: 2. Campo | E11: ENERGY_CERTIFICATE_EST_INPUT | F11: PROPERTY_CONTRACT_ID | G11: 6. Em implementação (re-especificação) | H11: 6. Em implementação (re-especificação) | I11: Apesar da data de correção ser 28/11 a data que importa é 24/10, uma vez que a última implementação não é relevanta para iniciar os testes à tabela | J11: 45510 | K11: 45624
A12: =E12&F12 -> ENERGY_CERTIFICATE_EST_INPUTPROPERTY_REFERENCE_CODE | B12: Pilar III | C12: Bens Imóveis - Input | D12: 2. Campo | E12: ENERGY_CERTIFICATE_EST_INPUT | F12: PROPERTY_REFERENCE_CODE | G12: 6. Em implementação (re-especificação) | H12: 6. Em implementação (re-especificação) | I12: Apesar da data de correção ser 28/11 a data que importa é 24/10, uma vez que a última implementação não é relevanta para iniciar os testes à tabela | J12: 45510 | K12: 45624
A13: =E13&F13 -> ENERGY_CERTIFICATE_EST_INPUTDATA_EXTRACTION_DATE | B13: Pilar III | C13: Bens Imóveis - Input | D13: 2. Campo | E13: ENERGY_CERTIFICATE_EST_INPUT | F13: DATA_EXTRACTION_DATE | G13: 6. Em implementação (re-especificação) | H13: 6. Em implementação (re-especificação) | I13: Apesar da data de correção ser 28/11 a data que importa é 24/10, uma vez que a última implementação não é relevanta para iniciar os testes à tabela | J13: 45510 | K13: 45624
A14: =E14&F14 -> ENERGY_CERTIFICATE_EST_INPUTEPC | B14: Pilar III | C14: Bens Imóveis - Input | D14: 2. Campo | E14: ENERGY_CERTIFICATE_EST_INPUT | F14: EPC | G14: 6. Em implementação (re-especificação) | H14: 6. Em implementação (re-especificação) | I14: Apesar da data de correção ser 28/11 a data que importa é 24/10, uma vez que a última implementação não é relevanta para iniciar os testes à tabela | J14: 45510 | K14: 45624
A15: =E15&F15 -> ENERGY_CERTIFICATE_EST_INPUTDATA_PROVIDER | B15: Pilar III | C15: Bens Imóveis - Input | D15: 2. Campo | E15: ENERGY_CERTIFICATE_EST_INPUT | F15: DATA_PROVIDER | G15: 6. Em implementação (re-especificação) | H15: 6. Em implementação (re-especificação) | I15: Apesar da data de correção ser 28/11 a data que importa é 24/10, uma vez que a última implementação não é relevanta para iniciar os testes à tabela | J15: 45510 | K15: 45624
A16: =E16&F16 -> ENERGY_CERTIFICATE_EST_INPUTACTUAL_VALUE_IND | B16: Pilar III | C16: Bens Imóveis - Input | D16: 2. Campo | E16: ENERGY_CERTIFICATE_EST_INPUT | F16: ACTUAL_VALUE_IND | G16: 6. Em implementação (re-especificação) | H16: 6. Em implementação (re-especificação) | I16: Apesar da data de correção ser 28/11 a data que importa é 24/10, uma vez que a última implementação não é relevanta para iniciar os testes à tabela | J16: 45510 | K16: 45624
A17: =E17&F17 -> ENERGY_CERTIFICATE_EST_INPUTQUALITY_SCORE | B17: Pilar III | C17: Bens Imóveis - Input | D17: 2. Campo | E17: ENERGY_CERTIFICATE_EST_INPUT | F17: QUALITY_SCORE | G17: 6. Em implementação (re-especificação) | H17: 6. Em implementação (re-especificação) | I17: Apesar da data de correção ser 28/11 a data que importa é 24/10, uma vez que a última implementação não é relevanta para iniciar os testes à tabela | J17: 45510 | K17: 45624
A18: =E18&F18 -> ENERGY_CERTIFICATE_EST_INPUTENERGY_CONSUMPTION_VALUE_YEAR | B18: Pilar III | C18: Bens Imóveis - Input | D18: 2. Campo | E18: ENERGY_CERTIFICATE_EST_INPUT | F18: ENERGY_CONSUMPTION_VALUE_YEAR | G18: 6. Em implementação (re-especificação) | H18: 6. Em implementação (re-especificação) | I18: Apesar da data de correção ser 28/11 a data que importa é 24/10, uma vez que a última implementação não é relevanta para iniciar os testes à tabela | J18: 45510 | K18: 45624
A19: =E19&F19 -> ENERGY_CERTIFICATE_EST_INPUTCARBON_EMISSION_VALUE_YEAR | B19: Pilar III | C19: Bens Imóveis - Input | D19: 2. Campo | E19: ENERGY_CERTIFICATE_EST_INPUT | F19: CARBON_EMISSION_VALUE_YEAR | G19: 6. Em implementação (re-especificação) | H19: 6. Em implementação (re-especificação) | I19: Apesar da data de correção ser 28/11 a data que importa é 24/10, uma vez que a última implementação não é relevanta para iniciar os testes à tabela | J19: 45510 | K19: 45624
A20: =E20&F20 -> PROCESSn.a. | B20: Pilar III | C20: Bens Imóveis - Output | D20: 1. Universo | E20: PROCESS | F20: n.a. | G20: 1. Concluído | H20: 1. Concluído
A21: =E21&F21 -> PROCESSPROCESS_BANK_ID | B21: Pilar III | C21: Bens Imóveis - Output | D21: 2. Campo | E21: PROCESS | F21: PROCESS_BANK_ID | G21: 1. Concluído | H21: 1. Concluído | I21: 26/07/2024: Conclusão de testes ao universo MUG e GP. Adjudicados fora de âmbito deste projeto.
A22: =E22&F22 -> PROCESSPROCESS_BRANCH_CODE | B22: Pilar III | C22: Bens Imóveis - Output | D22: 2. Campo | E22: PROCESS | F22: PROCESS_BRANCH_CODE | G22: 1. Concluído | H22: 1. Concluído | I22: 26/07/2024: Conclusão de testes ao universo MUG e GP. Adjudicados fora de âmbito deste projeto.
A23: =E23&F23 -> PROCESSPROCESS_ACCOUNT_ID | B23: Pilar III | C23: Bens Imóveis - Output | D23: 2. Campo | E23: PROCESS | F23: PROCESS_ACCOUNT_ID | G23: 1. Concluído | H23: 1. Concluído | I23: 26/07/2024: Conclusão de testes ao universo MUG e GP. Adjudicados fora de âmbito deste projeto.
A24: =E24&F24 -> PROCESScod_estd_prcs | B24: Pilar III | C24: Bens Imóveis - Output | D24: 2. Campo | E24: PROCESS | F24: cod_estd_prcs | G24: 0. Cancelado | H24: 0. Cancelado | I24: 19/07/2024: Campo eliminado do Modelo para garantir coerência com MUG
A25: =E25&F25 -> PROCESSGUARANTEE_CODE | B25: Pilar III | C25: Bens Imóveis - Output | D25: 2. Campo | E25: PROCESS | F25: GUARANTEE_CODE | G25: 1. Concluído | H25: 1. Concluído
A26: =E26&F26 -> PROCESSCURRENCY_CODE | B26: Pilar III | C26: Bens Imóveis - Output | D26: 2. Campo | E26: PROCESS | F26: CURRENCY_CODE | G26: 1. Concluído | H26: 1. Concluído | J26: 45512 | K26: 45526
A27: =E27&F27 -> PROCESSPROCESS_CAMPAIGN_CODE | B27: Pilar III | C27: Bens Imóveis - Output | D27: 2. Campo | E27: PROCESS | F27: PROCESS_CAMPAIGN_CODE | G27: 1. Concluído | H27: 1. Concluído
A28: =E28&F28 -> PROCESSPROCESS_PRODUCT_ID | B28: Pilar III | C28: Bens Imóveis - Output | D28: 2. Campo | E28: PROCESS | F28: PROCESS_PRODUCT_ID | G28: 1. Concluído | H28: 1. Concluído
A29: =E29&F29 -> PROCESSPROCESS_SUBPRODUCT_ID | B29: Pilar III | C29: Bens Imóveis - Output | D29: 2. Campo | E29: PROCESS | F29: PROCESS_SUBPRODUCT_ID | G29: 1. Concluído | H29: 1. Concluído
A30: =E30&F30 -> PROCESSGUARANTEE_TYPE_CODE | B30: Pilar III | C30: Bens Imóveis - Output | D30: 2. Campo | E30: PROCESS | F30: GUARANTEE_TYPE_CODE | G30: 1. Concluído | H30: 1. Concluído
A31: =E31&F31 -> PROCESSPROCESS_REFERENCE_CODE | B31: Pilar III | C31: Bens Imóveis - Output | D31: 2. Campo | E31: PROCESS | F31: PROCESS_REFERENCE_CODE | G31: 1. Concluído | H31: 1. Concluído
A32: =E32&F32 -> PROCESSPROCESS_START_DATE | B32: Pilar III | C32: Bens Imóveis - Output | D32: 2. Campo | E32: PROCESS | F32: PROCESS_START_DATE | G32: 1. Concluído | H32: 1. Concluído
A33: =E33&F33 -> PROCESSPROCESS_DUE_DATE | B33: Pilar III | C33: Bens Imóveis - Output | D33: 2. Campo | E33: PROCESS | F33: PROCESS_DUE_DATE | G33: 1. Concluído | H33: 1. Concluído
A34: =E34&F34 -> PROCESSmontante_eur | B34: Pilar III | C34: Bens Imóveis - Output | D34: 2. Campo | E34: PROCESS | F34: montante_eur | G34: 0. Cancelado | H34: 0. Cancelado | I34: 19/07/2024: Campo eliminado do Modelo para garantir coerência com MUG
A35: =E35&F35 -> PROCESSmontante_org | B35: Pilar III | C35: Bens Imóveis - Output | D35: 2. Campo | E35: PROCESS | F35: montante_org | G35: 0. Cancelado | H35: 0. Cancelado | I35: 19/07/2024: Campo eliminado do Modelo para garantir coerência com MUG
A36: =E36&F36 -> PROCESSorigem | B36: Pilar III | C36: Bens Imóveis - Output | D36: 2. Campo | E36: PROCESS | F36: origem | G36: 0. Cancelado | H36: 0. Cancelado | I36: 08/08/2024: Campo eliminado de modo a garantir a coerência com o atualmente realizado no Modelo Único de Garantias.
A37: =E37&F37 -> PROCESSDATA_DATE_PART | B37: Pilar III | C37: Bens Imóveis - Output | D37: 2. Campo | E37: PROCESS | F37: DATA_DATE_PART | G37: 1. Concluído | H37: 1. Concluído
A38: =E38&F38 -> RESPONSIBILITY_PROCESS_RELn.a. | B38: Pilar III | C38: Bens Imóveis - Output | D38: 1. Universo | E38: RESPONSIBILITY_PROCESS_REL | F38: n.a. | G38: 1. Concluído | H38: 1. Concluído
A39: =E39&F39 -> RESPONSIBILITY_PROCESS_RELPROCESS_BANK_ID | B39: Pilar III | C39: Bens Imóveis - Output | D39: 2. Campo | E39: RESPONSIBILITY_PROCESS_REL | F39: PROCESS_BANK_ID | G39: 1. Concluído | H39: 1. Concluído | I39: 26/07/2024: Conclusão de testes ao universo MUG e GP. Adjudicados fora de âmbito deste projeto.
A40: =E40&F40 -> RESPONSIBILITY_PROCESS_RELBANK_ID | B40: Pilar III | C40: Bens Imóveis - Output | D40: 2. Campo | E40: RESPONSIBILITY_PROCESS_REL | F40: BANK_ID | G40: 1. Concluído | H40: 1. Concluído | I40: 26/07/2024: Conclusão de testes ao universo MUG e GP. Adjudicados fora de âmbito deste projeto.
A41: =E41&F41 -> RESPONSIBILITY_PROCESS_RELPROCESS_BRANCH_CODE | B41: Pilar III | C41: Bens Imóveis - Output | D41: 2. Campo | E41: RESPONSIBILITY_PROCESS_REL | F41: PROCESS_BRANCH_CODE | G41: 1. Concluído | H41: 1. Concluído | I41: 26/07/2024: Conclusão de testes ao universo MUG e GP. Adjudicados fora de âmbito deste projeto.
A42: =E42&F42 -> RESPONSIBILITY_PROCESS_RELBRANCH_CODE | B42: Pilar III | C42: Bens Imóveis - Output | D42: 2. Campo | E42: RESPONSIBILITY_PROCESS_REL | F42: BRANCH_CODE | G42: 1. Concluído | H42: 1. Concluído | I42: 26/07/2024: Conclusão de testes ao universo MUG e GP. Adjudicados fora de âmbito deste projeto.
A43: =E43&F43 -> RESPONSIBILITY_PROCESS_RELCONTRACT_ID | B43: Pilar III | C43: Bens Imóveis - Output | D43: 2. Campo | E43: RESPONSIBILITY_PROCESS_REL | F43: CONTRACT_ID | G43: 1. Concluído | H43: 1. Concluído | I43: 26/07/2024: Conclusão de testes ao universo MUG e GP. Adjudicados fora de âmbito deste projeto.
A44: =E44&F44 -> RESPONSIBILITY_PROCESS_RELPROCESS_ACCOUNT_ID | B44: Pilar III | C44: Bens Imóveis - Output | D44: 2. Campo | E44: RESPONSIBILITY_PROCESS_REL | F44: PROCESS_ACCOUNT_ID | G44: 1. Concluído | H44: 1. Concluído | I44: 26/07/2024: Conclusão de testes ao universo MUG e GP. Adjudicados fora de âmbito deste projeto.
A45: =E45&F45 -> RESPONSIBILITY_PROCESS_RELREFERENCE_CODE | B45: Pilar III | C45: Bens Imóveis - Output | D45: 2. Campo | E45: RESPONSIBILITY_PROCESS_REL | F45: REFERENCE_CODE | G45: 1. Concluído | H45: 1. Concluído | I45: 26/07/2024: Conclusão de testes ao universo MUG e GP. Adjudicados fora de âmbito deste projeto.
...

Sheet Plano
Q6: Julho | AN6: Agosto | BJ6: Setembro | CE6: Outubro | DB6: Novembro | DW6: Dezembro
Q7: =Q8 -> 45474 | R7: =R8 -> 45475 | S7: =S8 -> 45476 | T7: =T8 -> 45477 | U7: =U8 -> 45478 | V7: =V8 -> 45481 | W7: =W8 -> 45482 | X7: =X8 -> 45483 | ... ER7: =ER8 -> 45657
B8: Âmbito | C8: Sub-âmbito | D8: Tipo de teste | E8: Tabela | F8: Campo | G8: Status | H8: Status2 | I8: Horas previstas | J8: Dias | K8: Horas efetivas | L8: Dias efetivos | M8: Status Estimado | N8: Status Real | O8: Desvios | P8: Observações | Q8: 45474 | R8: =WORKDAY(Q8,1) -> 45475 | S8: =WORKDAY(R8,1) -> 45476 | T8: =WORKDAY(S8,1) -> 45477 | U8: =WORKDAY(T8,1) -> 45478 | V8: =WORKDAY(U8,1) -> 45481 | W8: =WORKDAY(V8,1) -> 45482 | X8: =WORKDAY(W8,1) -> 45483 | Y8: =WORKDAY(X8,1) -> 45484 | ... ER8: =WORKDAY(EQ8,1) -> 45657
B9: 1. Assessment | I9: 160 | J9: 20 | K9: 160 | L9: 20 | M9: 1 | N9: 1 | O9: 0 | P9: N/A
B10: Pilar III | C10: Bens Imóveis | G10: 7. Por iniciar | I10: 40 | J10: 5 | M10: 1 | N10: 1 | O10: 0 | P10: N/A | AA10: 1 | AB10: 1 | AC10: 1 | AD10: 1 | AE10: 1
B11: Pilar III | C11: Modelo Verde | G11: 7. Por iniciar | I11: 80 | J11: 10 | M11: 1 | N11: 1 | O11: 0 | P11: N/A | V11: 2 | W11: 2 | X11: 2 | Y11: 2 | Z11: 2
B12: Pilar III | C12: LT Pilar III | G12: 7. Por iniciar | I12: 40 | J12: 5 | M12: 1 | N12: 1 | O12: 0 | P12: N/A | AF12: 1 | AG12: 1 | AH12: 1 | AI12: 1 | AJ12: 0.5 | AK12: 0.5
B14: 2. Re-especificação | I14: 120 | J14: 15 | K14: 105.6 | L14: 13.2 | M14: 0.86666667 | N14: 0.88 | O14: 0.013333333 | P14: N/A
B15: Pilar III | C15: Bens Imóveis | G15: 7. Por iniciar | I15: 40 | J15: 5 | M15: 1 | N15: 1 | O15: 0 | P15: N/A | AA15: 0.5 | AF15: 0.5 | AK15: 0.5 | AP15: 0.5 | AU15: 0.5 | AZ15: 0.5 | BE15: 0.5 | BJ15: 0.5 | BO15: 0.5 | BT15: 0.5
B16: Pilar III | C16: Modelo Verde | G16: 7. Por iniciar | I16: 40 | J16: 5 | M16: 1 | N16: 0.95 | O16: -0.05 | P16: - Pendência de atualização da tabela de parametrização (CdG) | AA16: 0.5 | AF16: 0.5 | AK16: 0.5 | AP16: 0.5 | AU16: 0.5 | AZ16: 0.5 | BE16: 0.5 | BJ16: 0.5 | BO16: 0.5 | BT16: 0.5
B17: Pilar III | C17: LT Pilar III | G17: 7. Por iniciar | I17: 40 | J17: 5 | M17: 0.6 | N17: 0.69 | O17: 0.09 | P17: Encontra-se em curso as re-especificações do Pilar III | BO17: 0.5 | BT17: 0.5 | BY17: 0.5 | CD17: 0.5 | CI17: 0.5 | CN17: 0.5 | CS17: 0.5 | CX17: 0.5 | DC17: 0.5
B19: 3. Testes / Re-testes | I19: #REF! | J19: #REF! | K19: #REF! | L19: #REF! | M19: 0.5 | N19: 0.58 | O19: 0.09 | P19: N/A
B20: Pilar III | C20: Bens Imóveis - Input | I20: #REF! | J20: #REF! | K20: #REF! | L20: #REF! | M20: 1 | N20: 0.33 | O20: -0.67 | P20: - Pendência de desenvolvimentos de IT: Tabela da Gloval | AB20: 0.5 | AC20: 0.5 | AG20: 0.5 | AN20: 0.5 | AO20: 0.5 | AP20: 0.5
A21: =E21&F21 | B21: Pilar III | C21: Bens Imóveis - Output | I21: #REF! | J21: #REF! | K21: #REF! | L21: #REF! | M21: 0.85 | N21: 0.71 | O21: -0.14 | P21: - Pendência de desenvolvimentos de IT: Tabela de certificados energéticos. | AK21: 1 | AL21: 1 | AM21: 1 | AN21: 1 | AQ21: 1 | AR21: 1 | AS21: 1 | AT21: 1 | AV21: 1 | AW21: 2 | AY21: 1 | BB21: 1 | BC21: 1 | BD21: 1 | BE21: 1 | BF21: 2 | BG21: 2 | BH21: 2 | BI21: 2 | BJ21: 0.5 | BK21: 2 | BL21: 2 | BM21: 2 | BN21: 2 | BO21: 0.5 | BP21: 2 | BQ21: 2 | BR21: 2 | BS21: 2 | BT21: 1.5 | BU21: 2 | BV21: 2 | BW21: 2 | BX21: 2 | BY21: 2 | BZ21: 2 | CA21: 2 | CB21: 2 | CC21: 2 | CD21: 2 | CE21: 2 | CF21: 2 | CG21: 2 | CH21: 2 | CI21: 2 | CJ21: 2 | CK21: 2 | CL21: 2 | CM21: 2 | CN21: 2 | CO21: 2 | CP21: 2 | CQ21: 2 | CR21: 2 | CS21: 2 | CT21: 2 | CU21: 2 | CV21: 2 | CW21: 1.5
A22: =E22&F22 | B22: Pilar III | C22: Modelo Verde - Input | I22: #REF! | J22: #REF! | K22: #REF! | L22: #REF! | M22: 1 | N22: 0.83 | O22: -0.17 | P22: - Pendência de desenvolvimentos de IT do input da MunichRe e dos desenvolvimentos das alterações na parametrização da marcação verde; - Pendente de envio de nova versão da tabela de parametrização com alteração da estrutura e mapeamento das categorias SFCIS. | AB22: 0.5 | AC22: 0.5 | AD22: 1 | AE22: 1 | AG22: 0.5 | AJ22: 0.5 | AK22: 0.5 | AL22: 2 | AM22: 2 | AN22: 1.5 | AO22: 1.5 | AP22: 1.5 | AQ22: 2 | AR22: 2 | AS22: 2 | AT22: 2 | AU22: 1 | AV22: 1
A23: =E23&F23 | B23: Pilar III | C23: Modelo Verde - Output | I23: #REF! | J23: #REF! | K23: #REF! | L23: #REF! | M23: 0.21 | N23: 0.19 | O23: -0.02 | P23: - Pendente de desenvolvimentos de IT | BU23: 1 | BV23: 1 | BW23: 1 | BX23: 1 | BY23: 0.5 | BZ23: 1 | CA23: 1 | CB23: 1 | CC23: 1 | CD23: 0.5 | CE23: 1 | CF23: 1 | CG23: 1 | CH23: 1 | CI23: 0.5 | CJ23: 1 | CK23: 1 | CL23: 1 | CM23: 1 | CN23: 0.5 | CO23: 1 | CP23: 1 | CQ23: 1 | CR23: 1 | CS23: 0.5 | CT23: 1 | CU23: 1 | CV23: 1 | CW23: 1 | CX23: 2 | CY23: 2 | CZ23: 2 | DA23: 2 | DB23: 2 | DC23: 2 | DD23: 2 | DE23: 2 | DF23: 2 | DG23: 2 | DH23: 2 | DI23: 2 | DJ23: 2 | DK23: 2 | DL23: 2 | DM23: 2 | DN23: 2 | DO23: 2 | DP23: 2 | DQ23: 2 | DR23: 2 | DS23: 2 | DT23: 2 | DU23: 2 | DV23: 2 | DW23: 2 | DX23: 2 | DY23: 2 | DZ23: 2 | EA23: 2 | EB23: 2 | EC23: 2 | ED23: 2 | EE23: 2 | EF23: 2 | EG23: 2 | EH23: 1.5
A24: =E24&F24 | B24: Pilar III | C24: LT Pilar III | I24: #REF! | J24: #REF! | K24: #REF! | L24: #REF! | M24: 0 | N24: 0.37 | O24: 0.37 | P24: - Já foram testados campos da LT Estrutural e uma tabela de parametrização. | CW24: 0.5 | CX24: 0.5 | CY24: 1 | CZ24: 1 | DA24: 1 | DB24: 1 | DC24: 0.5 | DD24: 1 | DE24: 1 | DF24: 1 | DG24: 1 | DH24: 1 | DI24: 1 | DJ24: 1 | DK24: 1 | DL24: 1 | DM24: 1 | DN24: 1 | DO24: 1 | DP24: 1 | DQ24: 1 | DS24: 1 | DT24: 1 | DU24: 1 | DV24: 1 | DW24: 1 | DX24: 1 | DY24: 1 | DZ24: 1 | EA24: 1 | EB24: 1 | EC24: 1 | ED24: 1 | EE24: 1 | EF24: 1 | EG24: 1 | EH24: 1.5 | EI24: 3 | EJ24: 3 | EK24: 3 | EL24: 3
AX25: x
B26: 4. Status Global | J26: #REF! | L26: #REF! | M26: 0.55 | N26: 0.64 | O26: 0.1 | P26: N/A
