Workbook
Name \a: #REF!
Name \a: #REF!
Name \b: #REF!
Name \b: #REF!
Name \c: #REF!
Name \c: #REF!
Name \d: #REF!
Name \d: #REF!
Name \e: #REF!
Name \e: #REF!
Name \m: #REF!
Name \m: #REF!
Name \p: #REF!
Name \p: #REF!
Name \q: #REF!
Name \q: #REF!
Name \s: #REF!
Name \s: #REF!
Name \v: #REF!
Name \v: #REF!
Name ___GRUPO_ENVIO: [1]GENMASIVA!$AC$4
Name ___INDEX_SHEET___ASAP_Utilities: #REF!
Name ___INDEX_SHEET___ASAP_Utilities: #REF!
Name ___PERIODO: [1]GENMASIVA!$AC$2
Name ___td2: #REF!
Name ___td2: #REF!
Name ___td3: #REF!
Name ___td3: #REF!
Name ___td4: #REF!
Name ___td4: #REF!
Name ___ti1: #REF!
Name ___ti1: #REF!
Name ___ti2: #REF!
Name ___ti2: #REF!
Name ___ti3: #REF!
Name ___ti3: #REF!
Name ___ti4: #REF!
Name ___ti4: #REF!
Name ___tp1: #REF!
Name ___tp1: #REF!
Name ___tp2: #REF!
Name ___tp2: #REF!
Name ___tp3: #REF!
Name ___tp3: #REF!
Name ___tp4: #REF!
Name ___tp4: #REF!
Name __td1: #REF!
Name __td1: #REF!
Name __td2: #REF!
Name __td2: #REF!
Name __td3: #REF!
Name __td3: #REF!
Name __td4: #REF!
Name __td4: #REF!
Name __ti1: #REF!
Name __ti1: #REF!
Name __ti2: #REF!
Name __ti2: #REF!
Name __ti3: #REF!
Name __ti3: #REF!

Sheet Sat79 - Ex. Dez 24
B9: informing_soc | C9: counterparty_soc | D9: adjustment_code | E9: comb_code | F9: amount | G9: eu | H9: chro | I9: acut | J9: geo | K9: cnael | L9: nace
B10: 411 | C10: 421 | D10: BI00411 | E10: CONT1;HFS2;B01;MC08;TYVA01;INVS4;MESG4 | F10: 450662960 | G10: EU1 | H10: CHRO2 | I10: ACUT2 | J10: GEO18
B11: 411 | C11: 0 | D11: BI00411 | E11: CONT1;HFS1;B01;MC1005;ORIG4;TYVA02 | F11: -69183 | G11: EU1 | H11: CHRO2 | I11: ACUT1 | J11: GEO3
B12: 411 | C12: 3162 | D12: BI00411 | E12: CONT1;HFS2;B01;MC08;TYVA01;INVS4;MESG4 | F12: 7932813 | G12: EU1 | H12: CHRO2 | I12: ACUT2 | J12: GEO3
B13: 411 | C13: 1333 | D13: BI00411 | E13: CONT1;HFS2;B01;MC08;TYVA01;INVS4;MESG4 | F13: 88691496 | G13: EU1 | H13: CHRO2 | I13: ACUT2 | J13: GEO3
B14: 411 | C14: 0 | D14: BI00411 | E14: CONT1;HFS1;B01;MC1005;ORIG4;TYVA02 | F14: -21085073 | G14: EU1 | H14: CHRO2 | I14: ACUT2 | J14: GEO3
B15: 411 | C15: 421 | D15: BI00411 | E15: CONT1;HFS2;B01;MC08;TYVA01;;MESG4 | F15: -1 | G15: EU1 | H15: CHRO2 | I15: ACUT2 | J15: GEO18
B16: 411 | C16: 442 | D16: BI00411 | E16: CONT1;HFS2;B01;MC08;TYVA01;INVS5;EXC2;MESG4 | F16: 99962303 | G16: EU1 | H16: CHRO2 | I16: ACUT2 | J16: GEO3 | K16: CNAEL6 | L16: NACE06010101
B17: 411 | C17: 0 | D17: BI00411 | E17: CONT1;HFS2;B01;MC06;ACPF5;SC0303;TYVA01;EXC2;MESG4 | F17: 22684 | G17: EU1 | H17: CHRO2 | I17: ACUT2 | J17: GEO3 | K17: CNAEL18 | L17: NACE19010303
B18: 411 | C18: 0 | D18: BI00411 | E18: CONT1;HFS2;B01;MC06;ACPF3;SC0302;TYVA01;MESG4 | F18: 17085832 | G18: EU1 | H18: CHRO2 | I18: ACUT2 | J18: GEO3
B19: 411 | C19: 445 | D19: BI00411 | E19: CONT1;HFS2;B01;MC08;TYVA01;INVS4;MESG4 | F19: 49500 | G19: EU1 | H19: CHRO2 | I19: ACUT2 | J19: GEO3
B20: 411 | C20: 0 | D20: BI00411 | E20: CONT1;HFS2;B01;MC06;ACPF5;SC0303;TYVA01;EXC2;MESG4 | F20: 131176 | G20: EU1 | H20: CHRO2 | I20: ACUT2 | J20: GEO18 | K20: CNAEL11 | L20: NACE12010101
B21: 411 | C21: 442 | D21: BI00411 | E21: CONT1;HFS2;B01;MC08;TYVA02;INVS5;EXC2 | F21: -11000000 | G21: EU1 | H21: CHRO2 | I21: ACUT2 | J21: GEO3 | K21: CNAEL6 | L21: NACE06010101
B22: 411 | C22: 0 | D22: BI00411 | E22: CONT1;HFS2;B01;MC06;ACPF5;SC0302;TYVA01;MESG4 | F22: 2493971 | G22: EU2 | H22: CHRO2 | I22: ACUT2 | J22: GEO2
B23: 411 | C23: 0 | D23: BI00411 | E23: CONT1;HFS2;B01;MC06;ACPF5;SC0303;TYVA01;EXC2;MESG4 | F23: 35578 | G23: EU1 | H23: CHRO2 | I23: ACUT2 | J23: GEO3 | K23: CNAEL3 | L23: NACE03200302
B24: 411 | C24: 0 | D24: BI00411 | E24: CONT1;HFS1;B01;MC1005;ORIG4;TYVA01;MESG4 | F24: 40381801 | G24: EU1 | H24: CHRO2 | I24: ACUT2 | J24: GEO3
B25: 411 | C25: 0 | D25: BI00411 | E25: CONT1;HFS2;B01;MC06;ACPF5;SC0302;TYVA01;MESG4 | F25: 171653011 | G25: EU1 | H25: CHRO2 | I25: ACUT2 | J25: GEO3
B26: 411 | C26: 0 | D26: BI00411 | E26: CONT1;HFS1;B01;MC1005;ORIG4;TYVA01;MESG4 | F26: 278361 | G26: EU1 | H26: CHRO2 | I26: ACUT1 | J26: GEO3

Sheet Sat 79 - Script Esturural
B9: reporting_soc | C9: counterparty_soc | D9: adjustment_code | E9: comb_code | F9: amount | G9: eu | H9: chro | I9: acut | J9: geo | K9: cnael | L9: nace
B10: 411 | C10: 1333 | D10: BI00411 | E10: CONT1;HFS2;B01;MC08;TYVA01;INVS4;MESG4 | F10: 88691496 | G10: EU1 | H10: CHRO2 | I10: ACUT2 | J10: GEO3
B11: 411 | C11: 442 | D11: BI00411 | E11: CONT1;HFS2;B01;MC08;TYVA01;INVS5;EXC2;MESG4 | F11: 99962303 | G11: EU1 | H11: CHRO2 | I11: ACUT2 | J11: GEO3 | K11: CNAEL6 | L11: NACE06010101
B12: 411 | C12: 0 | D12: BI00411 | E12: CONT1;HFS2;B01;MC06;ACPF5;SC0302;TYVA01;MESG4 | F12: 1 | H12: CHRO2 | I12: ACUT2 | J12: GEO19
B13: 411 | C13: 0 | D13: BI00411 | E13: CONT1;HFS1;B01;MC1005;ORIG4;TYVA01;MESG4 | F13: 40660146 | H13: CHRO2 | I13: ACUT2 | J13: GEO19
B14: 411 | C14: 421 | D14: BI00411 | E14: CONT1;HFS2;B01;MC08;TYVA01;MESG4 | F14: -1 | G14: EU1 | H14: CHRO2 | I14: ACUT2 | J14: GEO18
B15: 411 | C15: 0 | D15: BI00411 | E15: CONT1;HFS1;B01;MC1005;ORIG4;TYVA02;MESG4 | F15: -21154251 | H15: CHRO2 | I15: ACUT2 | J15: GEO19
B16: 411 | C16: 0 | D16: BI00411 | E16: CONT1;HFS2;B01;MC06;ACPF5;SC0303;TYVA01;EXC2;MESG4 | F16: 35578 | G16: EU1 | H16: CHRO2 | I16: ACUT2 | J16: GEO3 | K16: CNAEL3 | L16: NACE03200302
B17: 411 | C17: 3162 | D17: BI00411 | E17: CONT1;HFS2;B01;MC08;TYVA01;INVS4;MESG4 | F17: 7932813 | G17: EU1 | H17: CHRO2 | I17: ACUT2 | J17: GEO3
B18: 411 | C18: 445 | D18: BI00411 | E18: CONT1;HFS2;B01;MC08;TYVA01;INVS4;MESG4 | F18: 49500 | G18: EU1 | H18: CHRO2 | I18: ACUT2 | J18: GEO3
B19: 411 | C19: 0 | D19: BI00411 | E19: CONT1;HFS2;B01;MC06;ACPF5;SC0302;TYVA01;MESG4 | F19: 2493971 | G19: EU2 | H19: CHRO2 | I19: ACUT2 | J19: GEO2
B20: 411 | C20: 0 | D20: BI00411 | E20: CONT1;HFS2;B01;MC06;ACPF3;SC0302;TYVA01;MESG4 | F20: 799901 | G20: EU1 | H20: CHRO2 | I20: ACUT2 | J20: GEO3 | L20: NACE11010403
B21: 411 | C21: 0 | D21: BI00411 | E21: CONT1;HFS2;B01;MC06;ACPF5;SC0303;TYVA01;EXC2;MESG4 | F21: 131176 | G21: EU1 | H21: CHRO2 | I21: ACUT2 | J21: GEO18 | K21: CNAEL11 | L21: NACE12010101
B22: 411 | C22: 0 | D22: BI00411 | E22: CONT1;HFS2;B01;MC06;ACPF5;SC0303;TYVA01;EXC2;MESG4 | F22: 22684 | G22: EU1 | H22: CHRO2 | I22: ACUT2 | J22: GEO3 | K22: CNAEL18 | L22: NACE19010303
B23: 411 | C23: 421 | D23: BI00411 | E23: CONT1;HFS2;B01;MC08;TYVA01;INVS4;MESG4 | F23: 450662960 | G23: EU1 | H23: CHRO2 | I23: ACUT2 | J23: GEO18
B24: 411 | C24: 0 | D24: BI00411 | E24: CONT1;HFS2;B01;MC06;ACPF3;SC0302;TYVA01;MESG4 | F24: 11163168 | G24: EU1 | H24: CHRO2 | I24: ACUT2 | J24: GEO3 | L24: NACE11030301
B25: 411 | C25: 442 | D25: BI00411 | E25: CONT1;HFS2;B01;MC08;TYVA02;INVS5;EXC2 | F25: -11000000 | G25: EU1 | H25: CHRO2 | I25: ACUT2 | J25: GEO3 | K25: CNAEL6 | L25: NACE06010101
B26: 411 | C26: 0 | D26: BI00411 | E26: CONT1;HFS2;B01;MC06;ACPF5;SC0302;TYVA01;MESG4 | F26: 171653012 | G26: EU1 | H26: CHRO2 | I26: ACUT2 | J26: GEO3
B27: 411 | C27: 0 | D27: BI00411 | E27: CONT1;HFS2;B01;MC06;ACPF3;SC0302;TYVA01;MESG4 | F27: 5122764 | G27: EU1 | H27: CHRO2 | I27: ACUT2 | J27: GEO3

Sheet Comparativo s adjudicados
B9: informing_soc | C9: counterparty_soc | D9: adjustment_code | E9: comb_code | F9: amount | G9: eu | H9: chro | I9: acut | J9: geo | K9: cnael | L9: nace
B10: 411 | C10: 421 | D10: BI00411 | E10: CONT1;HFS2;B01;MC08;TYVA01;INVS4;MESG4 | F10: 450662960 | G10: EU1 | H10: CHRO2 | I10: ACUT2 | J10: GEO18
B11: 411 | C11: 3162 | D11: BI00411 | E11: CONT1;HFS2;B01;MC08;TYVA01;INVS4;MESG4 | F11: 7932813 | G11: EU1 | H11: CHRO2 | I11: ACUT2 | J11: GEO3
B12: 411 | C12: 1333 | D12: BI00411 | E12: CONT1;HFS2;B01;MC08;TYVA01;INVS4;MESG4 | F12: 88691496 | G12: EU1 | H12: CHRO2 | I12: ACUT2 | J12: GEO3
B13: 411 | C13: 421 | D13: BI00411 | E13: CONT1;HFS2;B01;MC08;TYVA01;MESG4 | F13: -1 | G13: EU1 | H13: CHRO2 | I13: ACUT2 | J13: GEO18
B14: 411 | C14: 442 | D14: BI00411 | E14: CONT1;HFS2;B01;MC08;TYVA01;INVS5;EXC2;MESG4 | F14: 99962303 | G14: EU1 | H14: CHRO2 | I14: ACUT2 | J14: GEO3 | K14: CNAEL6 | L14: NACE06010101
B15: 411 | C15: 0 | D15: BI00411 | E15: CONT1;HFS2;B01;MC06;ACPF5;SC0303;TYVA01;EXC2;MESG4 | F15: 22684 | G15: EU1 | H15: CHRO2 | I15: ACUT2 | J15: GEO3 | K15: CNAEL18 | L15: NACE19010303
B16: 411 | C16: 0 | D16: BI00411 | E16: CONT1;HFS2;B01;MC06;ACPF3;SC0302;TYVA01;MESG4 | F16: 17085832 | G16: EU1 | H16: CHRO2 | I16: ACUT2 | J16: GEO3
B17: 411 | C17: 445 | D17: BI00411 | E17: CONT1;HFS2;B01;MC08;TYVA01;INVS4;MESG4 | F17: 49500 | G17: EU1 | H17: CHRO2 | I17: ACUT2 | J17: GEO3
B18: 411 | C18: 0 | D18: BI00411 | E18: CONT1;HFS2;B01;MC06;ACPF5;SC0303;TYVA01;EXC2;MESG4 | F18: 131176 | G18: EU1 | H18: CHRO2 | I18: ACUT2 | J18: GEO18 | K18: CNAEL11 | L18: NACE12010101
B19: 411 | C19: 442 | D19: BI00411 | E19: CONT1;HFS2;B01;MC08;TYVA02;INVS5;EXC2 | F19: -11000000 | G19: EU1 | H19: CHRO2 | I19: ACUT2 | J19: GEO3 | K19: CNAEL6 | L19: NACE06010101
B20: 411 | C20: 0 | D20: BI00411 | E20: CONT1;HFS2;B01;MC06;ACPF5;SC0302;TYVA01;MESG4 | F20: 2493971 | G20: EU2 | H20: CHRO2 | I20: ACUT2 | J20: GEO2
B21: 411 | C21: 0 | D21: BI00411 | E21: CONT1;HFS2;B01;MC06;ACPF5;SC0303;TYVA01;EXC2;MESG4 | F21: 35578 | G21: EU1 | H21: CHRO2 | I21: ACUT2 | J21: GEO3 | K21: CNAEL3 | L21: NACE03200302
B22: 411 | C22: 0 | D22: BI00411 | E22: CONT1;HFS2;B01;MC06;ACPF5;SC0302;TYVA01;MESG4 | F22: 171653011 | G22: EU1 | H22: CHRO2 | I22: ACUT2 | J22: GEO3
B26: reporting_soc | C26: counterparty_soc | D26: adjustment_code | E26: comb_code | F26: amount | G26: eu | H26: chro | I26: acut | J26: geo | K26: cnael | L26: nace | M26: IDCOMBS vs dez24 | N26: Saldos vs Dez 24 | O26: Casuística Saldo
B27: 411 | C27: 1333 | D27: BI00411 | E27: CONT1;HFS2;B01;MC08;TYVA01;INVS4;MESG4 | F27: 88691496 | G27: EU1 | H27: CHRO2 | I27: ACUT2 | J27: GEO3 | M27: =VLOOKUP(E27,$E$10:$F$22,1,FALSE) -> CONT1;HFS2;B01;MC08;TYVA01;INVS4;MESG4 | N27: =VLOOKUP(F27,$F$10:$G$22,1,FALSE) -> 88691496
B28: 411 | C28: 442 | D28: BI00411 | E28: CONT1;HFS2;B01;MC08;TYVA01;INVS5;EXC2;MESG4 | F28: 99962303 | G28: EU1 | H28: CHRO2 | I28: ACUT2 | J28: GEO3 | K28: CNAEL6 | L28: NACE06010101 | M28: =VLOOKUP(E28,$E$10:$F$22,1,FALSE) -> CONT1;HFS2;B01;MC08;TYVA01;INVS5;EXC2;MESG4 | N28: =VLOOKUP(F28,$F$10:$G$22,1,FALSE) -> 99962303
B29: 411 | C29: 0 | D29: BI00411 | E29: CONT1;HFS2;B01;MC06;ACPF5;SC0302;TYVA01;MESG4 | F29: 1 | H29: CHRO2 | I29: ACUT2 | J29: GEO19 | M29: =VLOOKUP(E29,$E$10:$F$22,1,FALSE) -> CONT1;HFS2;B01;MC06;ACPF5;SC0302;TYVA01;MESG4 | N29: =VLOOKUP(F29,$F$10:$G$22,1,FALSE) -> #N/A | O29: GEO19
B30: 411 | C30: 421 | D30: BI00411 | E30: CONT1;HFS2;B01;MC08;TYVA01;MESG4 | F30: -1 | G30: EU1 | H30: CHRO2 | I30: ACUT2 | J30: GEO18 | M30: =VLOOKUP(E30,$E$10:$F$22,1,FALSE) -> CONT1;HFS2;B01;MC08;TYVA01;MESG4 | N30: =VLOOKUP(F30,$F$10:$G$22,1,FALSE) -> -1
B31: 411 | C31: 0 | D31: BI00411 | E31: CONT1;HFS2;B01;MC06;ACPF5;SC0303;TYVA01;EXC2;MESG4 | F31: 35578 | G31: EU1 | H31: CHRO2 | I31: ACUT2 | J31: GEO3 | K31: CNAEL3 | L31: NACE03200302 | M31: =VLOOKUP(E31,$E$10:$F$22,1,FALSE) -> CONT1;HFS2;B01;MC06;ACPF5;SC0303;TYVA01;EXC2;MESG4 | N31: =VLOOKUP(F31,$F$10:$G$22,1,FALSE) -> 35578
B32: 411 | C32: 3162 | D32: BI00411 | E32: CONT1;HFS2;B01;MC08;TYVA01;INVS4;MESG4 | F32: 7932813 | G32: EU1 | H32: CHRO2 | I32: ACUT2 | J32: GEO3 | M32: =VLOOKUP(E32,$E$10:$F$22,1,FALSE) -> CONT1;HFS2;B01;MC08;TYVA01;INVS4;MESG4 | N32: =VLOOKUP(F32,$F$10:$G$22,1,FALSE) -> 7932813
B33: 411 | C33: 445 | D33: BI00411 | E33: CONT1;HFS2;B01;MC08;TYVA01;INVS4;MESG4 | F33: 49500 | G33: EU1 | H33: CHRO2 | I33: ACUT2 | J33: GEO3 | M33: =VLOOKUP(E33,$E$10:$F$22,1,FALSE) -> CONT1;HFS2;B01;MC08;TYVA01;INVS4;MESG4 | N33: =VLOOKUP(F33,$F$10:$G$22,1,FALSE) -> 49500
B34: 411 | C34: 0 | D34: BI00411 | E34: CONT1;HFS2;B01;MC06;ACPF5;SC0302;TYVA01;MESG4 | F34: 2493971 | G34: EU2 | H34: CHRO2 | I34: ACUT2 | J34: GEO2 | M34: =VLOOKUP(E34,$E$10:$F$22,1,FALSE) -> CONT1;HFS2;B01;MC06;ACPF5;SC0302;TYVA01;MESG4 | N34: =VLOOKUP(F34,$F$10:$G$22,1,FALSE) -> 2493971
B35: 411 | C35: 0 | D35: BI00411 | E35: CONT1;HFS2;B01;MC06;ACPF3;SC0302;TYVA01;MESG4 | F35: 799901 | G35: EU1 | H35: CHRO2 | I35: ACUT2 | J35: GEO3 | L35: NACE11010403 | M35: =VLOOKUP(E35,$E$10:$F$22,1,FALSE) -> CONT1;HFS2;B01;MC06;ACPF3;SC0302;TYVA01;MESG4 | N35: =VLOOKUP(F35,$F$10:$G$22,1,FALSE) -> #N/A | O35: Marcação de NACE vs Vazio
B36: 411 | C36: 0 | D36: BI00411 | E36: CONT1;HFS2;B01;MC06;ACPF5;SC0303;TYVA01;EXC2;MESG4 | F36: 131176 | G36: EU1 | H36: CHRO2 | I36: ACUT2 | J36: GEO18 | K36: CNAEL11 | L36: NACE12010101 | M36: =VLOOKUP(E36,$E$10:$F$22,1,FALSE) -> CONT1;HFS2;B01;MC06;ACPF5;SC0303;TYVA01;EXC2;MESG4 | N36: =VLOOKUP(F36,$F$10:$G$22,1,FALSE) -> 131176
B37: 411 | C37: 0 | D37: BI00411 | E37: CONT1;HFS2;B01;MC06;ACPF5;SC0303;TYVA01;EXC2;MESG4 | F37: 22684 | G37: EU1 | H37: CHRO2 | I37: ACUT2 | J37: GEO3 | K37: CNAEL18 | L37: NACE19010303 | M37: =VLOOKUP(E37,$E$10:$F$22,1,FALSE) -> CONT1;HFS2;B01;MC06;ACPF5;SC0303;TYVA01;EXC2;MESG4 | N37: =VLOOKUP(F37,$F$10:$G$22,1,FALSE) -> 22684
B38: 411 | C38: 421 | D38: BI00411 | E38: CONT1;HFS2;B01;MC08;TYVA01;INVS4;MESG4 | F38: 450662960 | G38: EU1 | H38: CHRO2 | I38: ACUT2 | J38: GEO18 | M38: =VLOOKUP(E38,$E$10:$F$22,1,FALSE) -> CONT1;HFS2;B01;MC08;TYVA01;INVS4;MESG4 | N38: =VLOOKUP(F38,$F$10:$G$22,1,FALSE) -> 450662960
B39: 411 | C39: 0 | D39: BI00411 | E39: CONT1;HFS2;B01;MC06;ACPF3;SC0302;TYVA01;MESG4 | F39: 11163168 | G39: EU1 | H39: CHRO2 | I39: ACUT2 | J39: GEO3 | L39: NACE11030301 | M39: =VLOOKUP(E39,$E$10:$F$22,1,FALSE) -> CONT1;HFS2;B01;MC06;ACPF3;SC0302;TYVA01;MESG4 | N39: =VLOOKUP(F39,$F$10:$G$22,1,FALSE) -> #N/A | O39: Marcação de NACE vs Vazio
B40: 411 | C40: 442 | D40: BI00411 | E40: CONT1;HFS2;B01;MC08;TYVA02;INVS5;EXC2 | F40: -11000000 | G40: EU1 | H40: CHRO2 | I40: ACUT2 | J40: GEO3 | K40: CNAEL6 | L40: NACE06010101 | M40: =VLOOKUP(E40,$E$10:$F$22,1,FALSE) -> CONT1;HFS2;B01;MC08;TYVA02;INVS5;EXC2 | N40: =VLOOKUP(F40,$F$10:$G$22,1,FALSE) -> -11000000
B41: 411 | C41: 0 | D41: BI00411 | E41: CONT1;HFS2;B01;MC06;ACPF5;SC0302;TYVA01;MESG4 | F41: 171653012 | G41: EU1 | H41: CHRO2 | I41: ACUT2 | J41: GEO3 | M41: =VLOOKUP(E41,$E$10:$F$22,1,FALSE) -> CONT1;HFS2;B01;MC06;ACPF5;SC0302;TYVA01;MESG4 | N41: =VLOOKUP(F41,$F$10:$G$22,1,FALSE) -> #N/A | O41: Arredondamentos
B42: 411 | C42: 0 | D42: BI00411 | E42: CONT1;HFS2;B01;MC06;ACPF3;SC0302;TYVA01;MESG4 | F42: 5122764 | G42: EU1 | H42: CHRO2 | I42: ACUT2 | J42: GEO3 | M42: =VLOOKUP(E42,$E$10:$F$22,1,FALSE) -> CONT1;HFS2;B01;MC06;ACPF3;SC0302;TYVA01;MESG4 | N42: =VLOOKUP(F42,$F$10:$G$22,1,FALSE) -> #N/A | O42: Marcação de NACE vs Vazio
B46: evidencia tabela granular exercicio de dez24 a marcar GEO3 em 'outras instituições financeiras'
B47: csatelite | C47: idcomb_satelite | D47: idcomb_fr012 | E47: cempresa_fr012 | F47: cbalcao_fr012 | G47: cnumecta_fr012 | H47: zdeposit_fr012 | I47: cod_ajust | J47: sociedade_contraparte | K47: saldo_fr012 | L47: cempresa_ct | M47: cbalcao_ct | N47: cnumecta_ct | O47: zdeposit_ct | P47: sociedade_contraparte_ct | Q47: idcomb_ct | R47: pcsb_ct | S47: cargabal_ct | T47: ifrs_ct | U47: cod_ajust_ct | V47: saldo_ct | W47: ps_date | X47: dt_rfrnc | Y47: id_corrida | Z47: zcliente | AA47: 28_dt_maturity | AB47: maturity_esg | AC47: flag_maturity | AD47: years_to_maturity | AE47: european_union | AF47: performing_esg | AG47: 22_counterparty_nuts | AH47: 23_counterparty_zipcode | AI47: 14_nace | AJ47: nace_esg_orig | AK47: 12_non_performing | AL47: 17_accumulated_impairment | AM47: 30_stage_ifrs9 | AN47: 51_client_own_funds | AO47: 75_isin | AP47: cpais_residencia | AQ47: 5_collateral_zip_code | AR47: 4_collateral_nuts | AS47: 16_percent_collateral | AT47: 33_counterparty_type | AU47: excluded_paris | AV47: cnael | AW47: nace_esg | AX47: investment_sector | AY47: peso | AZ47: flag_hipotec | BA47: ckbalbem | BB47: ckctabem | BC47: ckrefbem | BD47: amount | BE47: id | BF47: nace_level4 | BG47: zipcode_collateral | BH47: zipcode_counterparty | BI47: nace_esg_aux | BJ47: acute_changes | BK47: chronic_changes | BL47: geo | BM47: saldo_satelite_agrup | BN47: chave
B48: 79 | C48: CONT1;HFS2;B01;MC06;ACPF5;SC0302;TYVA01 | D48: CONT1;HFS2;B01;MC06;PR18;ACPF5;SC0302;ORIG1;ULINK2;TYVA01 | E48: 31 | F48: 6416 | G48: 0 | H48: PTSIB0AM0008000 | I48: BI00411 | J48: 0 | K48: -140000000.000000 | L48: 31 | M48: 6416 | N48: 0 | O48: PTSIB0AM0008000 | Q48: CONT1;HFS2;B01;MC06;PR18;ACPF5;SC0302;ORIG1;ULINK2;TYVA01 | R48: 25701103 | S48: 15313 | T48: 14137 | U48: BI00411 | V48: -71687210.000000 | W48: 45675 | X48: 45657 | Y48: 1 | Z48: 8006098485 | AA48: 2958465 | AB48: MESG4 | AC48: 0 | AD48: NULL | AE48: EU1 | AG48: PT170 | AH48: 1600 | AI48: M70.1.0 | AJ48: K66.2.9 | AK48: no_stage | AL48: 0.000000 | AN48: 141095835.010000 | AO48: PTSIB0AM0008 | AP48: 620 | AQ48: NULL | AR48: NULL | AS48: NULL | AT48: outras instituicoes financeiras | AY48: 1.000000 | AZ48: 0 | BA48: NULL | BB48: NULL | BC48: NULL | BD48: -71687210.000000000000 | BE48: NACE11030203 | BF48: K6629 - Other activities auxiliary to insurance and pension funding | BG48: NULL | BH48: 1600 | BI48: K.66 | BJ48: ACUT2 | BK48: CHRO2 | BL48: GEO3 | BM48: -171653011.480000000000 | BN48: 31641600000000000PTSIB0AM0008000
B49: 79 | C49: CONT1;HFS2;B01;MC06;ACPF5;SC0302;TYVA01 | D49: CONT1;HFS2;B01;MC06;PR18;ACPF5;SC0302;ORIG1;ULINK2;TYVA01 | E49: 31 | F49: 6416 | G49: 0 | H49: PTSIB0AM0008000 | I49: BI00411 | J49: 0 | K49: -140000000.000000 | L49: 31 | M49: 6416 | N49: 0 | O49: PTSIB0AM0008000 | Q49: CONT1;HFS2;B01;MC06;PR18;ACPF5;SC0302;ORIG1;ULINK2;TYVA01 | R49: 4002010 | S49: 15313 | T49: 14130 | U49: BI00411 | V49: -68312790.000000 | W49: 45675 | X49: 45657 | Y49: 1 | Z49: 8006098485 | AA49: 2958465 | AB49: MESG4 | AC49: 0 | AD49: NULL | AE49: EU1 | AG49: PT170 | AH49: 1600 | AI49: M70.1.0 | AJ49: K66.2.9 | AK49: no_stage | AL49: 0.000000 | AN49: 141095835.010000 | AO49: PTSIB0AM0008 | AP49: 620 | AQ49: NULL | AR49: NULL | AS49: NULL | AT49: outras instituicoes financeiras | AY49: 1.000000 | AZ49: 0 | BA49: NULL | BB49: NULL | BC49: NULL | BD49: -68312790.000000000000 | BE49: NACE11030203 | BF49: K6629 - Other activities auxiliary to insurance and pension funding | BG49: NULL | BH49: 1600 | BI49: K.66 | BJ49: ACUT2 | BK49: CHRO2 | BL49: GEO3 | BM49: -171653011.480000000000 | BN49: 31641600000000000PTSIB0AM0008000

Sheet Sat79_dez24
B8: reporting_soc | C8: counterparty_soc | D8: adjustment_code | E8: id_comb | F8: amount | G8: eu | H8: chro | I8: acut | J8: geo | K8: cnael | L8: nace | M8: aveg
B9: 00411 | C9: 00000 | D9: BI00411 | E9: CONT1;HFS2;B01;MC02;ACPF6;SC0303;STAG2;DEFA2;COLL1;TYVA02;FVAD3;PERF1;EXC2 | F9: -22 | G9: EU2 | H9: CHRO2 | I9: ACUT2 | J9: GEO17 | K9: CNAEL7 | L9: NACE07020703
B10: 00411 | C10: 00000 | D10: BI00411 | E10: CONT1;HFS2;B01;MC04;ACPF6;SC0303;STAG1;DEFA2;COLL1;TYVA01;FVAD3;PERF1;EXC2;MESG1 | F10: 4644341 | G10: EU1 | H10: CHRO2 | I10: ACUT2 | J10: GEO3 | K10: CNAEL18 | L10: NACE10040401 | M10: 1
B11: 00411 | C11: 00000 | D11: BI00411 | E11: CONT1;HFS2;B01;MC02;ACPF6;SC0303;STAG1;DEFA2;COLL1;TYVA02;FVAD3;PERF1;EXC2 | F11: -9188 | G11: EU1 | H11: CHRO2 | I11: ACUT2 | J11: GEO3 | K11: CNAEL3 | L11: NACE03140401
B12: 00411 | C12: 00000 | D12: BI00411 | E12: CONT1;HFS2;B01;MC02;ACPF6;SC0303;STAG2;DEFA2;COLL4;TYVA02;FVAD3;PERF1;EXC2 | F12: -121 | G12: EU1 | H12: CHRO1 | I12: ACUT2 | J12: GEO3 | K12: CNAEL3 | L12: NACE03240201
B13: 00411 | C13: 00000 | D13: BI00411 | E13: CONT1;HFS2;B01;MC02;ACPF6;SC0303;STAG1;DEFA2;COLL3;TYVA01;FVAD3;PERF1;EXC2;MESG2 | F13: 118825 | G13: EU1 | H13: CHRO1 | I13: ACUT2 | J13: GEO3 | K13: CNAEL7 | L13: NACE07030505 | M13: 6
B14: 00411 | C14: 00000 | D14: BI00411 | E14: CONT1;HFS2;B01;MC02;ACPF6;SC0303;STAG1;DEFA2;COLL4;TYVA01;FVAD3;PERF1;EXC2;MESG1 | F14: 342170 | G14: EU1 | H14: CHRO2 | I14: ACUT2 | J14: GEO3 | K14: CNAEL12 | L14: NACE13030101 | M14: 3
B15: 00411 | C15: 00000 | D15: BI00411 | E15: CONT1;HFS2;B01;MC02;ACPF6;SC0303;STAG3;DEFA1;COLL4;TYVA02;FVAD3;PERF2;EXC2 | F15: -19996 | G15: EU1 | H15: CHRO2 | I15: ACUT2 | J15: GEO3 | K15: CNAEL16 | L15: NACE17010301
B16: 00411 | C16: 00000 | D16: BI00411 | E16: CONT1;HFS2;B01;MC02;ACPF6;SC0303;STAG1;DEFA2;COLL4;TYVA01;FVAD3;PERF1;EXC2;MESG1 | F16: 55070 | G16: EU1 | H16: CHRO1 | I16: ACUT2 | J16: GEO3 | K16: CNAEL3 | L16: NACE03140802 | M16: 1
B17: 00411 | C17: 00000 | D17: BI00411 | E17: CONT1;HFS2;B01;MC02;ACPF6;SC0303;STAG1;DEFA2;COLL1;TYVA02;FVAD3;PERF1;EXC2 | F17: -2081 | G17: EU1 | H17: CHRO2 | I17: ACUT2 | J17: GEO3 | K17: CNAEL15 | L17: NACE16010601
B18: 00411 | C18: 00000 | D18: BI00411 | E18: CONT1;HFS2;B01;MC02;ACPF6;SC0303;STAG3;DEFA1;COLL3;TYVA01;FVAD3;PERF2;EXC2;MESG1 | F18: 37 | G18: EU1 | H18: CHRO2 | I18: ACUT2 | J18: GEO3 | K18: CNAEL7 | L18: NACE07020701 | M18: 0
B19: 00411 | C19: 00000 | D19: BI00411 | E19: CONT1;HFS2;B01;MC02;ACPF6;SC0303;STAG1;DEFA2;COLL4;TYVA02;FVAD3;PERF1;EXC1 | F19: -9 | G19: EU1 | H19: CHRO2 | I19: ACUT2 | J19: GEO3 | K19: CNAEL12 | L19: NACE13030102
B20: 00411 | C20: 00000 | D20: BI00411 | E20: CONT1;HFS2;B01;MC02;ACPF6;SC0303;STAG3;DEFA1;COLL3;TYVA02;FVAD3;PERF2;EXC2 | F20: -30449 | G20: EU1 | H20: CHRO1 | I20: ACUT2 | J20: GEO3 | K20: CNAEL3 | L20: NACE03040201
B21: 00411 | C21: 00000 | D21: BI00411 | E21: CONT1;HFS2;B01;MC02;ACPF6;SC0303;STAG2;DEFA2;COLL1;TYVA01;FVAD3;PERF1;EXC2;MESG5 | F21: 255474 | G21: EU1 | H21: CHRO2 | I21: ACUT2 | J21: GEO3 | K21: CNAEL6 | L21: NACE06030303
B22: 00411 | C22: 00000 | D22: BI00411 | E22: CONT1;HFS2;B01;MC02;ACPF6;SC0303;STAG2;DEFA2;COLL4;TYVA02;FVAD3;PERF1;EXC2 | F22: -217 | G22: EU1 | H22: CHRO1 | I22: ACUT2 | J22: GEO3 | K22: CNAEL3 | L22: NACE03010103
B23: 00411 | C23: 00000 | D23: BI00411 | E23: CONT1;HFS2;B01;MC02;ACPF6;SC0303;STAG3;DEFA1;COLL3;TYVA02;FVAD3;PERF2;EXC2 | F23: -681 | G23: EU1 | H23: CHRO2 | I23: ACUT2 | J23: GEO3 | K23: CNAEL12 | L23: NACE13060101
B24: 00411 | C24: 00000 | D24: BI00411 | E24: CONT1;HFS2;B01;MC02;ACPF6;SC0303;STAG1;DEFA2;COLL4;TYVA02;FVAD3;PERF1;EXC2 | F24: -4585 | G24: EU1 | H24: CHRO2 | I24: ACUT2 | J24: GEO3 | K24: CNAEL7 | L24: NACE07030708
B25: 00411 | C25: 00000 | D25: BI00411 | E25: CONT1;HFS2;B01;MC02;ACPF6;SC0303;STAG2;DEFA2;COLL4;TYVA01;FVAD3;PERF1;EXC2;MESG1 | F25: 30748 | G25: EU1 | H25: CHRO2 | I25: ACUT2 | J25: GEO3 | K25: CNAEL8 | L25: NACE08040204 | M25: 5
B26: 00411 | C26: 00000 | D26: BI00411 | E26: CONT1;HFS2;B01;MC02;ACPF6;SC0303;STAG2;DEFA2;COLL4;TYVA02;FVAD3;PERF1;EXC2 | F26: -4681 | G26: EU1 | H26: CHRO2 | I26: ACUT2 | J26: GEO3 | K26: CNAEL3 | L26: NACE03110401
B27: 00411 | C27: 00000 | D27: BI00411 | E27: CONT1;HFS2;B01;MC02;ACPF6;SC0303;STAG1;DEFA2;COLL1;TYVA01;FVAD3;PERF1;EXC2;MESG1 | F27: 246120 | G27: EU1 | H27: CHRO2 | I27: ACUT2 | J27: GEO3 | K27: CNAEL10 | L27: NACE10050103 | M27: 2
B28: 00411 | C28: 00000 | D28: BI00411 | E28: CONT1;HFS2;B01;MC02;ACPF6;SC0303;STAG1;DEFA2;COLL1;TYVA01;FVAD3;PERF1;EXC2;MESG1 | F28: 12914804 | G28: EU1 | H28: CHRO2 | I28: ACUT2 | J28: GEO3 | K28: CNAEL10 | L28: NACE10040101 | M28: 1
B29: 00411 | C29: 00000 | D29: BI00411 | E29: CONT1;HFS2;B01;MC02;ACPF6;SC0303;STAG1;DEFA2;COLL1;TYVA01;FVAD3;PERF1;EXC2;MESG1 | F29: 542115 | G29: EU1 | H29: CHRO1 | I29: ACUT2 | J29: GEO3 | K29: CNAEL3 | L29: NACE03160701 | M29: 2
B30: 00411 | C30: 00000 | D30: BI00411 | E30: CONT1;HFS2;B01;MC02;ACPF6;SC0303;STAG2;DEFA2;COLL1;TYVA01;FVAD3;PERF1;EXC2;MESG5 | F30: 66 | G30: EU1 | H30: CHRO2 | I30: ACUT2 | J30: GEO3 | K30: CNAEL3 | L30: NACE03190103
B31: 00411 | C31: 00000 | D31: BI00411 | E31: CONT1;HFS2;B01;MC02;ACPF6;SC0303;STAG1;DEFA2;COLL1;TYVA02;FVAD3;PERF1;EXC2 | F31: -1803 | G31: EU1 | H31: CHRO1 | I31: ACUT2 | J31: GEO3 | K31: CNAEL3 | L31: NACE03170301
B32: 00411 | C32: 00000 | D32: BI00411 | E32: CONT1;HFS2;B01;MC02;ACPF6;SC0303;STAG2;DEFA2;COLL4;TYVA02;FVAD3;PERF1;EXC2 | F32: -2598 | G32: EU1 | H32: CHRO2 | I32: ACUT2 | J32: GEO3 | K32: CNAEL7 | L32: NACE07020204
B33: 00411 | C33: 00000 | D33: BI00411 | E33: CONT1;HFS2;B01;MC02;ACPF6;SC0303;STAG2;DEFA2;COLL1;TYVA01;FVAD3;PERF1;EXC2;MESG1 | F33: 3304605 | G33: EU1 | H33: CHRO1 | I33: ACUT2 | J33: GEO3 | K33: CNAEL3 | L33: NACE03040201 | M33: 2
B34: 00411 | C34: 00000 | D34: BI00411 | E34: CONT1;HFS2;B01;MC02;ACPF6;SC0303;STAG1;DEFA2;COLL1;TYVA02;FVAD3;PERF1;EXC2 | F34: -2351 | G34: EU1 | H34: CHRO1 | I34: ACUT2 | J34: GEO3 | K34: CNAEL6 | L34: NACE06030302
B35: 00411 | C35: 00000 | D35: BI00411 | E35: CONT1;HFS2;B01;MC02;ACPF6;SC0303;STAG3;DEFA1;COLL1;TYVA01;FVAD3;PERF2;EXC2;MESG5 | F35: 1556 | G35: EU1 | H35: CHRO1 | I35: ACUT2 | J35: GEO3 | K35: CNAEL3 | L35: NACE03010703
B36: 00411 | C36: 00000 | D36: BI00411 | E36: CONT1;HFS2;B01;MC02;ACPF6;SC0303;STAG2;DEFA2;COLL1;TYVA01;FVAD3;PERF1;EXC2;MESG2 | F36: 225187 | G36: EU1 | H36: CHRO2 | I36: ACUT2 | J36: GEO3 | K36: CNAEL10 | L36: NACE10020201 | M36: 7
B37: 00411 | C37: 00000 | D37: BI00411 | E37: CONT1;HFS2;B01;MC02;ACPF6;SC0303;STAG1;DEFA2;COLL1;TYVA01;FVAD3;PERF1;EXC2;MESG1 | F37: 5876887 | G37: EU1 | H37: CHRO2 | I37: ACUT2 | J37: GEO3 | K37: CNAEL8 | L37: NACE08040202 | M37: 2
B38: 00411 | C38: 00000 | D38: BI00411 | E38: CONT1;HFS2;B01;MC02;ACPF6;SC0303;STAG2;DEFA2;COLL4;TYVA02;FVAD3;PERF1;EXC2 | F38: -19629 | G38: EU1 | H38: CHRO2 | I38: ACUT2 | J38: GEO3 | K38: CNAEL9 | L38: NACE09010201
B39: 00411 | C39: 00000 | D39: BI00411 | E39: CONT1;HFS2;B01;MC02;ACPF6;SC0303;STAG1;DEFA2;COLL1;TYVA02;FVAD3;PERF1;EXC2 | F39: -16763 | G39: EU1 | H39: CHRO1 | I39: ACUT2 | J39: GEO3 | K39: CNAEL3 | L39: NACE03160803
B40: 00411 | C40: 00000 | D40: BI00411 | E40: CONT1;HFS2;B01;MC02;ACPF6;SC0303;STAG3;DEFA1;COLL1;TYVA01;FVAD3;PERF2;EXC2;MESG5 | F40: 3235 | G40: EU1 | H40: CHRO1 | I40: ACUT2 | J40: GEO3 | K40: CNAEL7 | L40: NACE07030203
B41: 00411 | C41: 00000 | D41: BI00411 | E41: CONT1;HFS2;B01;MC02;ACPF6;SC0303;STAG1;DEFA2;COLL1;TYVA01;FVAD3;PERF1;EXC2;MESG2 | F41: 834339 | G41: EU1 | H41: CHRO2 | I41: ACUT2 | J41: GEO3 | K41: CNAEL9 | L41: NACE09020301 | M41: 7
B42: 00411 | C42: 00000 | D42: BI00411 | E42: CONT1;HFS2;B01;MC02;ACPF6;SC0303;STAG2;DEFA2;COLL4;TYVA02;FVAD3;PERF1;EXC2 | F42: -8 | G42: EU1 | H42: CHRO2 | I42: ACUT2 | J42: GEO3 | K42: CNAEL12 | L42: NACE13040102
B43: 00411 | C43: 00000 | D43: BI00411 | E43: CONT1;HFS2;B01;MC02;ACPF6;SC0303;STAG1;DEFA2;COLL4;TYVA02;FVAD3;PERF1;EXC2 | F43: -1068 | G43: EU1 | H43: CHRO2 | I43: ACUT2 | J43: GEO3 | K43: CNAEL3 | L43: NACE03070101
B44: 00411 | C44: 00000 | D44: BI00411 | E44: CONT1;HFS2;B01;MC02;ACPF6;SC0303;STAG3;DEFA1;COLL4;TYVA01;FVAD3;PERF2;EXC2;MESG1 | F44: 56857 | G44: EU1 | H44: CHRO2 | I44: ACUT2 | J44: GEO3 | K44: CNAEL7 | L44: NACE07020703 | M44: 2
B45: 00411 | C45: 00000 | D45: BI00411 | E45: CONT1;HFS2;B01;MC02;ACPF6;SC0303;STAG2;DEFA2;COLL4;TYVA02;FVAD3;PERF1;EXC2 | F45: -659 | G45: EU1 | H45: CHRO2 | I45: ACUT2 | J45: GEO3 | K45: CNAEL13 | L45: NACE14050203
B46: 00411 | C46: 00000 | D46: BI00411 | E46: CONT1;HFS2;B01;MC02;ACPF6;SC0303;STAG1;DEFA2;COLL1;TYVA01;FVAD3;PERF1;EXC2;MESG1 | F46: 107275 | G46: EU1 | H46: CHRO2 | I46: ACUT1 | J46: GEO3 | K46: CNAEL7 | L46: NACE07010201 | M46: 1
B47: 00411 | C47: 00000 | D47: BI00411 | E47: CONT1;HFS2;B01;MC02;ACPF6;SC0303;STAG1;DEFA2;COLL1;TYVA01;FVAD3;PERF1;EXC2;MESG1 | F47: 9071036 | G47: EU1 | H47: CHRO2 | I47: ACUT2 | J47: GEO3 | K47: CNAEL7 | L47: NACE07020409 | M47: 2
...

Sheet Index
B6: 1. Variables and values for each table
C10: Variables | D10: Value | E10: Comments
C12: Main Sector | D12: SC0303 | E12: "Non financial corporations"
D13: SC0301 | E13: "General Government"
D14: SC0302 | E14: "Other financial Corporation"
D15: SC0304 | E15: "HouseHolds"
C16: Exposures | D16: TYVA01 | E16: "Gross carrying amount"
D17: TYVA02 | E17: "Imparment"
C18: Main Category | D18: MC08 | E18: "Investment sector"
D19: MC10 | E19: "Tangible assets"
C20: Sector | D20: INVS5 | E20: "Non Financial Corporations"
D21: INVS4 | E21: "Other Financial Corporations"
D22: INVS3 | E22: "General Governments"
C23: Stage | D23: STAG2 | E23: "Stage 2"
D24: STAG3 | E24: "Stage 3"
C25: Excluded | D25: EXC1 | E25: "Excluded for Paris Agreement"
C26: Maturity | D26: MESG1 | E26: <5y
D27: MESG2 | E27: >5y & <10y
D28: MESG3 | E28: >10y & <20y
D29: MESG4 | E29: >20y
D30: MESG5 | E30: "Counterparty having the choice of the repayment date"
D31: MESG6 | E31: "Other contracts with no stated maturity"
D32: MESG | E32: No maturity (Provisions)
C33: Chronic Changes | D33: CHRO1 | E33: "Yes"
D34: CHRO2 | E34: "No"
C35: Acute Changes | D35: ACUT1 | E35: "Yes"
D36: ACUT2 | E36: "No"
B38: 2. Formulas for each table
C41: 1.Credit Quality by sector
C43: Total Gross Carrying Amount = ( NACE | SC030(1-4) | TYVA01) + ( NACE | INVS(3-5) | TYVA01 | MC05)
C44: Of which STAGE2 = ( NACE | SC030(1-4) | TYVA01 | STAG2) + ( NACE | INVS(3-5) | TYVA01 | MC05 | STAG2)
C45: Of which STAGE32 = ( NACE | SC030(1-4) | TYVA01 | STAG3) + ( NACE | INVS(3-5) | TYVA01 | MC05 | STAG3)
C46: Acumulated Impairment = ( NACE | SC030(1-4) | TYVA02) + ( NACE | INVS(3-5) | TYVA02 | MC05)
C47: Net Carrying Amount = ( NACE | SC030(1-4)) + ( NACE | INVS(3-5) | MC05)
C50: 2.Exposures of Corp excl_P
C52: Total GCA = ( NACE | SC030(1-4)) + ( NACE | INVS(3-5) | MC05)
C53: Of which excluded from Paris agreement = ( NACE | SC030(1-4) | EXC1) + ( NACE | INVS(3-5) | MC05 | EXC1)
C56: 3.Net Carrying Amt by Maturity
C58: Total net carrying amount = MESG(1-6)
C59: Prone to the impact of chronic climate change events = (MESG(1-6) | CHRO1)
...

Sheet 1. Credit Quality by sector
B8: Credit quality of exposures by sector
B9: Gross Carrying Amount and Accumulated impairment by NACE
B11: Sector | C11: ID | D11: Activity Sector Description | E11: Total Gross Carrying Amount | I11: Of which STAGE1 | M11: Of which STAGE2 | Q11: Of which STAGE3 | U11: Accumulated impairment | Y11: Net Carrying Amount
A12: at | B12: NFC | E12: Satélite Dez24 pós ajustes corp. | F12: Satélite Jun24 pós ajustes corp. | G12: ∆ | H12: ∆ (%) | I12: Satélite Dez24 pós ajustes corp. | J12: Satélite Jun24 pós ajustes corp. | K12: ∆ | L12: ∆ (%) | M12: Satélite Dez24 pós ajustes corp. | N12: Satélite Jun24 pós ajustes corp. | O12: ∆ | P12: ∆ (%) | Q12: Satélite Dez24 pós ajustes corp. | R12: Satélite Jun24 pós ajustes corp. | S12: ∆ | T12: ∆ (%) | U12: Satélite Dez24 pós ajustes corp. | V12: Satélite Jun24 pós ajustes corp. | W12: ∆ | X12: ∆ (%) | Y12: Satélite Dez24 pós ajustes corp. | Z12: Satélite Jun24 pós ajustes corp. | AA12: ∆ | AB12: ∆ (%)
A13: =+LEN(C13) -> 6 | B13: Non Financial Corporations | C13: NACE01 | D13: Agriculture, forestry and fishing | E13: =SUMIFS(#REF!,#REF!,"*" & C13 & "*",#REF!,"*" & Index!$D$12 & "*",#REF!,"*" & Index!$D$16 & "*")+SUMIFS(#REF!,#REF!,"*" & C13 & "*",#REF!,"*" & Index!$D$18 & "*",#REF!,"*" & Index!$D$20 & "*",#REF!,"*" & Index!$D$16 & "*") -> #REF! | F13: 337406183 | G13: =+E13-F13 -> #REF! | H13: =IFERROR(IF(((E13/F13)-1)=0,"-",((E13/F13)-1)),"-") -> - | I13: =+E13-M13-Q13 -> #REF! | J13: 288117379 | K13: =+I13-J13 -> #REF! | L13: =IFERROR(IF(((I13/J13)-1)=0,"-",((I13/J13)-1)),"-") -> - | M13: =SUMIFS(#REF!,#REF!,"*" & $C13 & "*",#REF!,"*" & Index!$D$12 & "*",#REF!,"*" & Index!$D$23 & "*",#REF!,"*" & Index!$D$16 & "*") + SUMIFS(#REF!,#REF!,"*" & $C13 & "*",#REF!,"*" & Index!$D$18 & "*",#REF!,"*" & Index!$D$23 & "*",#REF!,"*" & Index!$D$16 & "*",#REF!,"*" & Index!$D$20 & "*") -> #REF! | N13: 43312234 | O13: =+M13-N13 -> #REF! | P13: =IFERROR(IF(((M13/N13)-1)=0,"-",((M13/N13)-1)),"-") -> - | Q13: =SUMIFS(#REF!,#REF!,"*" & $C13 & "*",#REF!,"*" & Index!$D$12 & "*",#REF!,"*" & Index!$D$24 & "*",#REF!,"*" & Index!$D$16 & "*") + SUMIFS(#REF!,#REF!,"*" & $C13 & "*",#REF!,"*" & Index!$D$18 & "*",#REF!,"*" & Index!$D$24 & "*",#REF!,"*" & Index!$D$16 & "*",#REF!,"*" & Index!$D$20 & "*") -> #REF! | R13: 5976570 | S13: =+Q13-R13 -> #REF! | T13: =IFERROR(IF(((Q13/R13)-1)=0,"-",((Q13/R13)-1)),"-") -> - | U13: =SUMIFS(#REF!,#REF!,"*" & C13 &"*",#REF!,"*" & Index!$D$12 & "*",#REF!,"*" & Index!$D$17 & "*")+SUMIFS(#REF!,#REF!,"*" & C13 &"*",#REF!,"*" & Index!$D$18 & "*",#REF!,"*" & Index!$D$17 & "*",#REF!,"*" & Index!$D$20 & "*") -> #REF! | V13: -7176720 | W13: =+U13-V13 -> #REF! | X13: =IFERROR(IF(((U13/V13)-1)=0,"-",((U13/V13)-1)),"-") -> - | Y13: =SUMIFS(#REF!,#REF!,"*" & C13 & "*",#REF!,"*" & Index!$D$12 & "*")+ SUMIFS(#REF!,#REF!,"*" & C13 & "*",#REF!,"*" & Index!$D$18 & "*",#REF!,"*" & Index!$D$20 & "*") -> #REF! | Z13: 330229463 | AA13: =+Y13-Z13 -> #REF! | AB13: =IFERROR(IF(((Y13/Z13)-1)=0,"-",((Y13/Z13)-1)),"-") -> -
A14: =+LEN(C14) -> 8 | C14: NACE0101 | E14: =SUMIFS(#REF!,#REF!,"*" & C14 & "*",#REF!,"*" & Index!$D$12 & "*",#REF!,"*" & Index!$D$16 & "*")+SUMIFS(#REF!,#REF!,"*" & C14 & "*",#REF!,"*" & Index!$D$18 & "*",#REF!,"*" & Index!$D$20 & "*") -> #REF! | F14: 293599318 | G14: =+E14-F14 -> #REF! | H14: =IFERROR(IF(((E14/F14)-1)=0,"-",((E14/F14)-1)),"-") -> - | I14: =+E14-M14-Q14 -> #REF! | J14: 255451113 | K14: =+I14-J14 -> #REF! | L14: =IFERROR(IF(((I14/J14)-1)=0,"-",((I14/J14)-1)),"-") -> - | M14: =SUMIFS(#REF!,#REF!,"*" & $C14 & "*",#REF!,"*" & Index!$D$12 & "*",#REF!,"*" & Index!$D$23 & "*",#REF!,"*" & Index!$D$16 & "*") + SUMIFS(#REF!,#REF!,"*" & $C14 & "*",#REF!,"*" & Index!$D$18 & "*",#REF!,"*" & Index!$D$23 & "*",#REF!,"*" & Index!$D$16 & "*",#REF!,"*" & Index!$D$20 & "*") -> #REF! | N14: 33492977 | O14: =+M14-N14 -> #REF! | P14: =IFERROR(IF(((M14/N14)-1)=0,"-",((M14/N14)-1)),"-") -> - | Q14: =SUMIFS(#REF!,#REF!,"*" & $C14 & "*",#REF!,"*" & Index!$D$12 & "*",#REF!,"*" & Index!$D$24 & "*",#REF!,"*" & Index!$D$16 & "*") + SUMIFS(#REF!,#REF!,"*" & $C14 & "*",#REF!,"*" & Index!$D$18 & "*",#REF!,"*" & Index!$D$24 & "*",#REF!,"*" & Index!$D$16 & "*",#REF!,"*" & Index!$D$20 & "*") -> #REF! | R14: 4655228 | S14: =+Q14-R14 -> #REF! | T14: =IFERROR(IF(((Q14/R14)-1)=0,"-",((Q14/R14)-1)),"-") -> - | U14: =SUMIFS(#REF!,#REF!,"*" & C14 &"*",#REF!,"*" & Index!$D$12 & "*",#REF!,"*" & Index!$D$17 & "*")+SUMIFS(#REF!,#REF!,"*" & C14 &"*",#REF!,"*" & Index!$D$18 & "*",#REF!,"*" & Index!$D$17 & "*",#REF!,"*" & Index!$D$20 & "*") -> #REF! | V14: -5515592 | W14: =+U14-V14 -> #REF! | X14: =IFERROR(IF(((U14/V14)-1)=0,"-",((U14/V14)-1)),"-") -> - | Y14: =SUMIFS(#REF!,#REF!,"*" & C14 & "*",#REF!,"*" & Index!$D$12 & "*")+ SUMIFS(#REF!,#REF!,"*" & C14 & "*",#REF!,"*" & Index!$D$18 & "*",#REF!,"*" & Index!$D$20 & "*") -> #REF! | Z14: 288083726 | AA14: =+Y14-Z14 -> #REF! | AB14: =IFERROR(IF(((Y14/Z14)-1)=0,"-",((Y14/Z14)-1)),"-") -> -
A15: =+LEN(C15) -> 8 | C15: NACE0102 | E15: =SUMIFS(#REF!,#REF!,"*" & C15 & "*",#REF!,"*" & Index!$D$12 & "*",#REF!,"*" & Index!$D$16 & "*")+SUMIFS(#REF!,#REF!,"*" & C15 & "*",#REF!,"*" & Index!$D$18 & "*",#REF!,"*" & Index!$D$20 & "*") -> #REF! | F15: 39060709 | G15: =+E15-F15 -> #REF! | H15: =IFERROR(IF(((E15/F15)-1)=0,"-",((E15/F15)-1)),"-") -> - | I15: =+E15-M15-Q15 -> #REF! | J15: 28922963 | K15: =+I15-J15 -> #REF! | L15: =IFERROR(IF(((I15/J15)-1)=0,"-",((I15/J15)-1)),"-") -> - | M15: =SUMIFS(#REF!,#REF!,"*" & $C15 & "*",#REF!,"*" & Index!$D$12 & "*",#REF!,"*" & Index!$D$23 & "*",#REF!,"*" & Index!$D$16 & "*") + SUMIFS(#REF!,#REF!,"*" & $C15 & "*",#REF!,"*" & Index!$D$18 & "*",#REF!,"*" & Index!$D$23 & "*",#REF!,"*" & Index!$D$16 & "*",#REF!,"*" & Index!$D$20 & "*") -> #REF! | N15: 8881956 | O15: =+M15-N15 -> #REF! | P15: =IFERROR(IF(((M15/N15)-1)=0,"-",((M15/N15)-1)),"-") -> - | Q15: =SUMIFS(#REF!,#REF!,"*" & $C15 & "*",#REF!,"*" & Index!$D$12 & "*",#REF!,"*" & Index!$D$24 & "*",#REF!,"*" & Index!$D$16 & "*") + SUMIFS(#REF!,#REF!,"*" & $C15 & "*",#REF!,"*" & Index!$D$18 & "*",#REF!,"*" & Index!$D$24 & "*",#REF!,"*" & Index!$D$16 & "*",#REF!,"*" & Index!$D$20 & "*") -> #REF! | R15: 1255790 | S15: =+Q15-R15 -> #REF! | T15: =IFERROR(IF(((Q15/R15)-1)=0,"-",((Q15/R15)-1)),"-") -> - | U15: =SUMIFS(#REF!,#REF!,"*" & C15 &"*",#REF!,"*" & Index!$D$12 & "*",#REF!,"*" & Index!$D$17 & "*")+SUMIFS(#REF!,#REF!,"*" & C15 &"*",#REF!,"*" & Index!$D$18 & "*",#REF!,"*" & Index!$D$17 & "*",#REF!,"*" & Index!$D$20 & "*") -> #REF! | V15: -1572407 | W15: =+U15-V15 -> #REF! | X15: =IFERROR(IF(((U15/V15)-1)=0,"-",((U15/V15)-1)),"-") -> - | Y15: =SUMIFS(#REF!,#REF!,"*" & C15 & "*",#REF!,"*" & Index!$D$12 & "*")+ SUMIFS(#REF!,#REF!,"*" & C15 & "*",#REF!,"*" & Index!$D$18 & "*",#REF!,"*" & Index!$D$20 & "*") -> #REF! | Z15: 37488302 | AA15: =+Y15-Z15 -> #REF! | AB15: =IFERROR(IF(((Y15/Z15)-1)=0,"-",((Y15/Z15)-1)),"-") -> -
A16: =+LEN(C16) -> 8 | C16: NACE0103 | E16: =SUMIFS(#REF!,#REF!,"*" & C16 & "*",#REF!,"*" & Index!$D$12 & "*",#REF!,"*" & Index!$D$16 & "*")+SUMIFS(#REF!,#REF!,"*" & C16 & "*",#REF!,"*" & Index!$D$18 & "*",#REF!,"*" & Index!$D$20 & "*") -> #REF! | F16: 4746156 | G16: =+E16-F16 -> #REF! | H16: =IFERROR(IF(((E16/F16)-1)=0,"-",((E16/F16)-1)),"-") -> - | I16: =+E16-M16-Q16 -> #REF! | J16: 3743303 | K16: =+I16-J16 -> #REF! | L16: =IFERROR(IF(((I16/J16)-1)=0,"-",((I16/J16)-1)),"-") -> - | M16: =SUMIFS(#REF!,#REF!,"*" & $C16 & "*",#REF!,"*" & Index!$D$12 & "*",#REF!,"*" & Index!$D$23 & "*",#REF!,"*" & Index!$D$16 & "*") + SUMIFS(#REF!,#REF!,"*" & $C16 & "*",#REF!,"*" & Index!$D$18 & "*",#REF!,"*" & Index!$D$23 & "*",#REF!,"*" & Index!$D$16 & "*",#REF!,"*" & Index!$D$20 & "*") -> #REF! | N16: 937301 | O16: =+M16-N16 -> #REF! | P16: =IFERROR(IF(((M16/N16)-1)=0,"-",((M16/N16)-1)),"-") -> - | Q16: =SUMIFS(#REF!,#REF!,"*" & $C16 & "*",#REF!,"*" & Index!$D$12 & "*",#REF!,"*" & Index!$D$24 & "*",#REF!,"*" & Index!$D$16 & "*") + SUMIFS(#REF!,#REF!,"*" & $C16 & "*",#REF!,"*" & Index!$D$18 & "*",#REF!,"*" & Index!$D$24 & "*",#REF!,"*" & Index!$D$16 & "*",#REF!,"*" & Index!$D$20 & "*") -> #REF! | R16: 65552 | S16: =+Q16-R16 -> #REF! | T16: =IFERROR(IF(((Q16/R16)-1)=0,"-",((Q16/R16)-1)),"-") -> - | U16: =SUMIFS(#REF!,#REF!,"*" & C16 &"*",#REF!,"*" & Index!$D$12 & "*",#REF!,"*" & Index!$D$17 & "*")+SUMIFS(#REF!,#REF!,"*" & C16 &"*",#REF!,"*" & Index!$D$18 & "*",#REF!,"*" & Index!$D$17 & "*",#REF!,"*" & Index!$D$20 & "*") -> #REF! | V16: -88721 | W16: =+U16-V16 -> #REF! | X16: =IFERROR(IF(((U16/V16)-1)=0,"-",((U16/V16)-1)),"-") -> - | Y16: =SUMIFS(#REF!,#REF!,"*" & C16 & "*",#REF!,"*" & Index!$D$12 & "*")+ SUMIFS(#REF!,#REF!,"*" & C16 & "*",#REF!,"*" & Index!$D$18 & "*",#REF!,"*" & Index!$D$20 & "*") -> #REF! | Z16: 4657435 | AA16: =+Y16-Z16 -> #REF! | AB16: =IFERROR(IF(((Y16/Z16)-1)=0,"-",((Y16/Z16)-1)),"-") -> -
A17: =+LEN(C17) -> 6 | C17: NACE02 | D17: Mining and quarrying | E17: =SUMIFS(#REF!,#REF!,"*" & C17 & "*",#REF!,"*" & Index!$D$12 & "*",#REF!,"*" & Index!$D$16 & "*")+SUMIFS(#REF!,#REF!,"*" & C17 & "*",#REF!,"*" & Index!$D$18 & "*",#REF!,"*" & Index!$D$20 & "*",#REF!,"*" & Index!$D$16 & "*") -> #REF! | F17: 13442698 | G17: =+E17-F17 -> #REF! | H17: =IFERROR(IF(((E17/F17)-1)=0,"-",((E17/F17)-1)),"-") -> - | I17: =+E17-M17-Q17 -> #REF! | J17: 9513074 | K17: =+I17-J17 -> #REF! | L17: =IFERROR(IF(((I17/J17)-1)=0,"-",((I17/J17)-1)),"-") -> - | M17: =SUMIFS(#REF!,#REF!,"*" & $C17 & "*",#REF!,"*" & Index!$D$12 & "*",#REF!,"*" & Index!$D$23 & "*",#REF!,"*" & Index!$D$16 & "*") + SUMIFS(#REF!,#REF!,"*" & $C17 & "*",#REF!,"*" & Index!$D$18 & "*",#REF!,"*" & Index!$D$23 & "*",#REF!,"*" & Index!$D$16 & "*",#REF!,"*" & Index!$D$20 & "*") -> #REF! | N17: 2376255 | O17: =+M17-N17 -> #REF! | P17: =IFERROR(IF(((M17/N17)-1)=0,"-",((M17/N17)-1)),"-") -> - | Q17: =SUMIFS(#REF!,#REF!,"*" & $C17 & "*",#REF!,"*" & Index!$D$12 & "*",#REF!,"*" & Index!$D$24 & "*",#REF!,"*" & Index!$D$16 & "*") + SUMIFS(#REF!,#REF!,"*" & $C17 & "*",#REF!,"*" & Index!$D$18 & "*",#REF!,"*" & Index!$D$24 & "*",#REF!,"*" & Index!$D$16 & "*",#REF!,"*" & Index!$D$20 & "*") -> #REF! | R17: 1553369 | S17: =+Q17-R17 -> #REF! | T17: =IFERROR(IF(((Q17/R17)-1)=0,"-",((Q17/R17)-1)),"-") -> - | U17: =SUMIFS(#REF!,#REF!,"*" & C17 &"*",#REF!,"*" & Index!$D$12 & "*",#REF!,"*" & Index!$D$17 & "*")+SUMIFS(#REF!,#REF!,"*" & C17 &"*",#REF!,"*" & Index!$D$18 & "*",#REF!,"*" & Index!$D$17 & "*",#REF!,"*" & Index!$D$20 & "*") -> #REF! | V17: -1152150 | W17: =+U17-V17 -> #REF! | X17: =IFERROR(IF(((U17/V17)-1)=0,"-",((U17/V17)-1)),"-") -> - | Y17: =SUMIFS(#REF!,#REF!,"*" & C17 & "*",#REF!,"*" & Index!$D$12 & "*")+ SUMIFS(#REF!,#REF!,"*" & C17 & "*",#REF!,"*" & Index!$D$18 & "*",#REF!,"*" & Index!$D$20 & "*") -> #REF! | Z17: 12290548 | AA17: =+Y17-Z17 -> #REF! | AB17: =IFERROR(IF(((Y17/Z17)-1)=0,"-",((Y17/Z17)-1)),"-") -> -
A18: =+LEN(C18) -> 8 | C18: NACE0203 | E18: =SUMIFS(#REF!,#REF!,"*" & C18 & "*",#REF!,"*" & Index!$D$12 & "*",#REF!,"*" & Index!$D$16 & "*")+SUMIFS(#REF!,#REF!,"*" & C18 & "*",#REF!,"*" & Index!$D$18 & "*",#REF!,"*" & Index!$D$20 & "*") -> #REF! | F18: 91384 | G18: =+E18-F18 -> #REF! | H18: =IFERROR(IF(((E18/F18)-1)=0,"-",((E18/F18)-1)),"-") -> - | I18: =+E18-M18-Q18 -> #REF! | J18: 91384 | K18: =+I18-J18 -> #REF! | L18: =IFERROR(IF(((I18/J18)-1)=0,"-",((I18/J18)-1)),"-") -> - | M18: =SUMIFS(#REF!,#REF!,"*" & $C18 & "*",#REF!,"*" & Index!$D$12 & "*",#REF!,"*" & Index!$D$23 & "*",#REF!,"*" & Index!$D$16 & "*") + SUMIFS(#REF!,#REF!,"*" & $C18 & "*",#REF!,"*" & Index!$D$18 & "*",#REF!,"*" & Index!$D$23 & "*",#REF!,"*" & Index!$D$16 & "*",#REF!,"*" & Index!$D$20 & "*") -> #REF! | N18: 0 | O18: =+M18-N18 -> #REF! | P18: =IFERROR(IF(((M18/N18)-1)=0,"-",((M18/N18)-1)),"-") -> - | Q18: =SUMIFS(#REF!,#REF!,"*" & $C18 & "*",#REF!,"*" & Index!$D$12 & "*",#REF!,"*" & Index!$D$24 & "*",#REF!,"*" & Index!$D$16 & "*") + SUMIFS(#REF!,#REF!,"*" & $C18 & "*",#REF!,"*" & Index!$D$18 & "*",#REF!,"*" & Index!$D$24 & "*",#REF!,"*" & Index!$D$16 & "*",#REF!,"*" & Index!$D$20 & "*") -> #REF! | R18: 0 | S18: =+Q18-R18 -> #REF! | T18: =IFERROR(IF(((Q18/R18)-1)=0,"-",((Q18/R18)-1)),"-") -> - | U18: =SUMIFS(#REF!,#REF!,"*" & C18 &"*",#REF!,"*" & Index!$D$12 & "*",#REF!,"*" & Index!$D$17 & "*")+SUMIFS(#REF!,#REF!,"*" & C18 &"*",#REF!,"*" & Index!$D$18 & "*",#REF!,"*" & Index!$D$17 & "*",#REF!,"*" & Index!$D$20 & "*") -> #REF! | V18: -167 | W18: =+U18-V18 -> #REF! | X18: =IFERROR(IF(((U18/V18)-1)=0,"-",((U18/V18)-1)),"-") -> - | Y18: =SUMIFS(#REF!,#REF!,"*" & C18 & "*",#REF!,"*" & Index!$D$12 & "*")+ SUMIFS(#REF!,#REF!,"*" & C18 & "*",#REF!,"*" & Index!$D$18 & "*",#REF!,"*" & Index!$D$20 & "*") -> #REF! | Z18: 91217 | AA18: =+Y18-Z18 -> #REF! | AB18: =IFERROR(IF(((Y18/Z18)-1)=0,"-",((Y18/Z18)-1)),"-") -> -
A19: =+LEN(C19) -> 8 | C19: NACE0204 | E19: =SUMIFS(#REF!,#REF!,"*" & C19 & "*",#REF!,"*" & Index!$D$12 & "*",#REF!,"*" & Index!$D$16 & "*")+SUMIFS(#REF!,#REF!,"*" & C19 & "*",#REF!,"*" & Index!$D$18 & "*",#REF!,"*" & Index!$D$20 & "*") -> #REF! | F19: 13254285 | G19: =+E19-F19 -> #REF! | H19: =IFERROR(IF(((E19/F19)-1)=0,"-",((E19/F19)-1)),"-") -> - | I19: =+E19-M19-Q19 -> #REF! | J19: 9421682 | K19: =+I19-J19 -> #REF! | L19: =IFERROR(IF(((I19/J19)-1)=0,"-",((I19/J19)-1)),"-") -> - | M19: =SUMIFS(#REF!,#REF!,"*" & $C19 & "*",#REF!,"*" & Index!$D$12 & "*",#REF!,"*" & Index!$D$23 & "*",#REF!,"*" & Index!$D$16 & "*") + SUMIFS(#REF!,#REF!,"*" & $C19 & "*",#REF!,"*" & Index!$D$18 & "*",#REF!,"*" & Index!$D$23 & "*",#REF!,"*" & Index!$D$16 & "*",#REF!,"*" & Index!$D$20 & "*") -> #REF! | N19: 2279614 | O19: =+M19-N19 -> #REF! | P19: =IFERROR(IF(((M19/N19)-1)=0,"-",((M19/N19)-1)),"-") -> - | Q19: =SUMIFS(#REF!,#REF!,"*" & $C19 & "*",#REF!,"*" & Index!$D$12 & "*",#REF!,"*" & Index!$D$24 & "*",#REF!,"*" & Index!$D$16 & "*") + SUMIFS(#REF!,#REF!,"*" & $C19 & "*",#REF!,"*" & Index!$D$18 & "*",#REF!,"*" & Index!$D$24 & "*",#REF!,"*" & Index!$D$16 & "*",#REF!,"*" & Index!$D$20 & "*") -> #REF! | R19: 1552989 | S19: =+Q19-R19 -> #REF! | T19: =IFERROR(IF(((Q19/R19)-1)=0,"-",((Q19/R19)-1)),"-") -> - | U19: =SUMIFS(#REF!,#REF!,"*" & C19 &"*",#REF!,"*" & Index!$D$12 & "*",#REF!,"*" & Index!$D$17 & "*")+SUMIFS(#REF!,#REF!,"*" & C19 &"*",#REF!,"*" & Index!$D$18 & "*",#REF!,"*" & Index!$D$17 & "*",#REF!,"*" & Index!$D$20 & "*") -> #REF! | V19: -1150072 | W19: =+U19-V19 -> #REF! | X19: =IFERROR(IF(((U19/V19)-1)=0,"-",((U19/V19)-1)),"-") -> - | Y19: =SUMIFS(#REF!,#REF!,"*" & C19 & "*",#REF!,"*" & Index!$D$12 & "*")+ SUMIFS(#REF!,#REF!,"*" & C19 & "*",#REF!,"*" & Index!$D$18 & "*",#REF!,"*" & Index!$D$20 & "*") -> #REF! | Z19: 12104213 | AA19: =+Y19-Z19 -> #REF! | AB19: =IFERROR(IF(((Y19/Z19)-1)=0,"-",((Y19/Z19)-1)),"-") -> -
A20: =+LEN(C20) -> 8 | C20: NACE0205 | E20: =SUMIFS(#REF!,#REF!,"*" & C20 & "*",#REF!,"*" & Index!$D$12 & "*",#REF!,"*" & Index!$D$16 & "*")+SUMIFS(#REF!,#REF!,"*" & C20 & "*",#REF!,"*" & Index!$D$18 & "*",#REF!,"*" & Index!$D$20 & "*") -> #REF! | F20: 97029 | G20: =+E20-F20 -> #REF! | H20: =IFERROR(IF(((E20/F20)-1)=0,"-",((E20/F20)-1)),"-") -> - | I20: =+E20-M20-Q20 -> #REF! | J20: 8 | K20: =+I20-J20 -> #REF! | L20: =IFERROR(IF(((I20/J20)-1)=0,"-",((I20/J20)-1)),"-") -> - | M20: =SUMIFS(#REF!,#REF!,"*" & $C20 & "*",#REF!,"*" & Index!$D$12 & "*",#REF!,"*" & Index!$D$23 & "*",#REF!,"*" & Index!$D$16 & "*") + SUMIFS(#REF!,#REF!,"*" & $C20 & "*",#REF!,"*" & Index!$D$18 & "*",#REF!,"*" & Index!$D$23 & "*",#REF!,"*" & Index!$D$16 & "*",#REF!,"*" & Index!$D$20 & "*") -> #REF! | N20: 96641 | O20: =+M20-N20 -> #REF! | P20: =IFERROR(IF(((M20/N20)-1)=0,"-",((M20/N20)-1)),"-") -> - | Q20: =SUMIFS(#REF!,#REF!,"*" & $C20 & "*",#REF!,"*" & Index!$D$12 & "*",#REF!,"*" & Index!$D$24 & "*",#REF!,"*" & Index!$D$16 & "*") + SUMIFS(#REF!,#REF!,"*" & $C20 & "*",#REF!,"*" & Index!$D$18 & "*",#REF!,"*" & Index!$D$24 & "*",#REF!,"*" & Index!$D$16 & "*",#REF!,"*" & Index!$D$20 & "*") -> #REF! | R20: 380 | S20: =+Q20-R20 -> #REF! | T20: =IFERROR(IF(((Q20/R20)-1)=0,"-",((Q20/R20)-1)),"-") -> - | U20: =SUMIFS(#REF!,#REF!,"*" & C20 &"*",#REF!,"*" & Index!$D$12 & "*",#REF!,"*" & Index!$D$17 & "*")+SUMIFS(#REF!,#REF!,"*" & C20 &"*",#REF!,"*" & Index!$D$18 & "*",#REF!,"*" & Index!$D$17 & "*",#REF!,"*" & Index!$D$20 & "*") -> #REF! | V20: -1911 | W20: =+U20-V20 -> #REF! | X20: =IFERROR(IF(((U20/V20)-1)=0,"-",((U20/V20)-1)),"-") -> - | Y20: =SUMIFS(#REF!,#REF!,"*" & C20 & "*",#REF!,"*" & Index!$D$12 & "*")+ SUMIFS(#REF!,#REF!,"*" & C20 & "*",#REF!,"*" & Index!$D$18 & "*",#REF!,"*" & Index!$D$20 & "*") -> #REF! | Z20: 95118 | AA20: =+Y20-Z20 -> #REF! | AB20: =IFERROR(IF(((Y20/Z20)-1)=0,"-",((Y20/Z20)-1)),"-") -> -
A21: =+LEN(C21) -> 6 | C21: NACE03 | D21: Manufacturing | E21: =SUMIFS(#REF!,#REF!,"*" & C21 & "*",#REF!,"*" & Index!$D$12 & "*",#REF!,"*" & Index!$D$16 & "*")+SUMIFS(#REF!,#REF!,"*" & C21 & "*",#REF!,"*" & Index!$D$18 & "*",#REF!,"*" & Index!$D$20 & "*",#REF!,"*" & Index!$D$16 & "*") -> #REF! | F21: 2524539509 | G21: =+E21-F21 -> #REF! | H21: =IFERROR(IF(((E21/F21)-1)=0,"-",((E21/F21)-1)),"-") -> - | I21: =+E21-M21-Q21 -> #REF! | J21: 2226715100 | K21: =+I21-J21 -> #REF! | L21: =IFERROR(IF(((I21/J21)-1)=0,"-",((I21/J21)-1)),"-") -> - | M21: =SUMIFS(#REF!,#REF!,"*" & $C21 & "*",#REF!,"*" & Index!$D$12 & "*",#REF!,"*" & Index!$D$23 & "*",#REF!,"*" & Index!$D$16 & "*") + SUMIFS(#REF!,#REF!,"*" & $C21 & "*",#REF!,"*" & Index!$D$18 & "*",#REF!,"*" & Index!$D$23 & "*",#REF!,"*" & Index!$D$16 & "*",#REF!,"*" & Index!$D$20 & "*") -> #REF! | N21: 223870280 | O21: =+M21-N21 -> #REF! | P21: =IFERROR(IF(((M21/N21)-1)=0,"-",((M21/N21)-1)),"-") -> - | Q21: =SUMIFS(#REF!,#REF!,"*" & $C21 & "*",#REF!,"*" & Index!$D$12 & "*",#REF!,"*" & Index!$D$24 & "*",#REF!,"*" & Index!$D$16 & "*") + SUMIFS(#REF!,#REF!,"*" & $C21 & "*",#REF!,"*" & Index!$D$18 & "*",#REF!,"*" & Index!$D$24 & "*",#REF!,"*" & Index!$D$16 & "*",#REF!,"*" & Index!$D$20 & "*") -> #REF! | R21: 73954129 | S21: =+Q21-R21 -> #REF! | T21: =IFERROR(IF(((Q21/R21)-1)=0,"-",((Q21/R21)-1)),"-") -> - | U21: =SUMIFS(#REF!,#REF!,"*" & C21 &"*",#REF!,"*" & Index!$D$12 & "*",#REF!,"*" & Index!$D$17 & "*")+SUMIFS(#REF!,#REF!,"*" & C21 &"*",#REF!,"*" & Index!$D$18 & "*",#REF!,"*" & Index!$D$17 & "*",#REF!,"*" & Index!$D$20 & "*") -> #REF! | V21: -90151536 | W21: =+U21-V21 -> #REF! | X21: =IFERROR(IF(((U21/V21)-1)=0,"-",((U21/V21)-1)),"-") -> - | Y21: =SUMIFS(#REF!,#REF!,"*" & C21 & "*",#REF!,"*" & Index!$D$12 & "*")+ SUMIFS(#REF!,#REF!,"*" & C21 & "*",#REF!,"*" & Index!$D$18 & "*",#REF!,"*" & Index!$D$20 & "*") -> #REF! | Z21: 2434387973 | AA21: =+Y21-Z21 -> #REF! | AB21: =IFERROR(IF(((Y21/Z21)-1)=0,"-",((Y21/Z21)-1)),"-") -> -
A22: =+LEN(C22) -> 8 | C22: NACE0301 | E22: =SUMIFS(#REF!,#REF!,"*" & C22 & "*",#REF!,"*" & Index!$D$12 & "*",#REF!,"*" & Index!$D$16 & "*")+SUMIFS(#REF!,#REF!,"*" & C22 & "*",#REF!,"*" & Index!$D$18 & "*",#REF!,"*" & Index!$D$20 & "*") -> #REF! | F22: 333416925 | G22: =+E22-F22 -> #REF! | H22: =IFERROR(IF(((E22/F22)-1)=0,"-",((E22/F22)-1)),"-") -> - | I22: =+E22-M22-Q22 -> #REF! | J22: 294837778 | K22: =+I22-J22 -> #REF! | L22: =IFERROR(IF(((I22/J22)-1)=0,"-",((I22/J22)-1)),"-") -> - | M22: =SUMIFS(#REF!,#REF!,"*" & $C22 & "*",#REF!,"*" & Index!$D$12 & "*",#REF!,"*" & Index!$D$23 & "*",#REF!,"*" & Index!$D$16 & "*") + SUMIFS(#REF!,#REF!,"*" & $C22 & "*",#REF!,"*" & Index!$D$18 & "*",#REF!,"*" & Index!$D$23 & "*",#REF!,"*" & Index!$D$16 & "*",#REF!,"*" & Index!$D$20 & "*") -> #REF! | N22: 31571750 | O22: =+M22-N22 -> #REF! | P22: =IFERROR(IF(((M22/N22)-1)=0,"-",((M22/N22)-1)),"-") -> - | Q22: =SUMIFS(#REF!,#REF!,"*" & $C22 & "*",#REF!,"*" & Index!$D$12 & "*",#REF!,"*" & Index!$D$24 & "*",#REF!,"*" & Index!$D$16 & "*") + SUMIFS(#REF!,#REF!,"*" & $C22 & "*",#REF!,"*" & Index!$D$18 & "*",#REF!,"*" & Index!$D$24 & "*",#REF!,"*" & Index!$D$16 & "*",#REF!,"*" & Index!$D$20 & "*") -> #REF! | R22: 7007397 | S22: =+Q22-R22 -> #REF! | T22: =IFERROR(IF(((Q22/R22)-1)=0,"-",((Q22/R22)-1)),"-") -> - | U22: =SUMIFS(#REF!,#REF!,"*" & C22 &"*",#REF!,"*" & Index!$D$12 & "*",#REF!,"*" & Index!$D$17 & "*")+SUMIFS(#REF!,#REF!,"*" & C22 &"*",#REF!,"*" & Index!$D$18 & "*",#REF!,"*" & Index!$D$17 & "*",#REF!,"*" & Index!$D$20 & "*") -> #REF! | V22: -9646514 | W22: =+U22-V22 -> #REF! | X22: =IFERROR(IF(((U22/V22)-1)=0,"-",((U22/V22)-1)),"-") -> - | Y22: =SUMIFS(#REF!,#REF!,"*" & C22 & "*",#REF!,"*" & Index!$D$12 & "*")+ SUMIFS(#REF!,#REF!,"*" & C22 & "*",#REF!,"*" & Index!$D$18 & "*",#REF!,"*" & Index!$D$20 & "*") -> #REF! | Z22: 323770411 | AA22: =+Y22-Z22 -> #REF! | AB22: =IFERROR(IF(((Y22/Z22)-1)=0,"-",((Y22/Z22)-1)),"-") -> -
A23: =+LEN(C23) -> 8 | C23: NACE0302 | E23: =SUMIFS(#REF!,#REF!,"*" & C23 & "*",#REF!,"*" & Index!$D$12 & "*",#REF!,"*" & Index!$D$16 & "*")+SUMIFS(#REF!,#REF!,"*" & C23 & "*",#REF!,"*" & Index!$D$18 & "*",#REF!,"*" & Index!$D$20 & "*") -> #REF! | F23: 272073401 | G23: =+E23-F23 -> #REF! | H23: =IFERROR(IF(((E23/F23)-1)=0,"-",((E23/F23)-1)),"-") -> - | I23: =+E23-M23-Q23 -> #REF! | J23: 265934632 | K23: =+I23-J23 -> #REF! | L23: =IFERROR(IF(((I23/J23)-1)=0,"-",((I23/J23)-1)),"-") -> - | M23: =SUMIFS(#REF!,#REF!,"*" & $C23 & "*",#REF!,"*" & Index!$D$12 & "*",#REF!,"*" & Index!$D$23 & "*",#REF!,"*" & Index!$D$16 & "*") + SUMIFS(#REF!,#REF!,"*" & $C23 & "*",#REF!,"*" & Index!$D$18 & "*",#REF!,"*" & Index!$D$23 & "*",#REF!,"*" & Index!$D$16 & "*",#REF!,"*" & Index!$D$20 & "*") -> #REF! | N23: 5265650 | O23: =+M23-N23 -> #REF! | P23: =IFERROR(IF(((M23/N23)-1)=0,"-",((M23/N23)-1)),"-") -> - | Q23: =SUMIFS(#REF!,#REF!,"*" & $C23 & "*",#REF!,"*" & Index!$D$12 & "*",#REF!,"*" & Index!$D$24 & "*",#REF!,"*" & Index!$D$16 & "*") + SUMIFS(#REF!,#REF!,"*" & $C23 & "*",#REF!,"*" & Index!$D$18 & "*",#REF!,"*" & Index!$D$24 & "*",#REF!,"*" & Index!$D$16 & "*",#REF!,"*" & Index!$D$20 & "*") -> #REF! | R23: 873119 | S23: =+Q23-R23 -> #REF! | T23: =IFERROR(IF(((Q23/R23)-1)=0,"-",((Q23/R23)-1)),"-") -> - | U23: =SUMIFS(#REF!,#REF!,"*" & C23 &"*",#REF!,"*" & Index!$D$12 & "*",#REF!,"*" & Index!$D$17 & "*")+SUMIFS(#REF!,#REF!,"*" & C23 &"*",#REF!,"*" & Index!$D$18 & "*",#REF!,"*" & Index!$D$17 & "*",#REF!,"*" & Index!$D$20 & "*") -> #REF! | V23: -1600099 | W23: =+U23-V23 -> #REF! | X23: =IFERROR(IF(((U23/V23)-1)=0,"-",((U23/V23)-1)),"-") -> - | Y23: =SUMIFS(#REF!,#REF!,"*" & C23 & "*",#REF!,"*" & Index!$D$12 & "*")+ SUMIFS(#REF!,#REF!,"*" & C23 & "*",#REF!,"*" & Index!$D$18 & "*",#REF!,"*" & Index!$D$20 & "*") -> #REF! | Z23: 270473302 | AA23: =+Y23-Z23 -> #REF! | AB23: =IFERROR(IF(((Y23/Z23)-1)=0,"-",((Y23/Z23)-1)),"-") -> -
A24: =+LEN(C24) -> 8 | C24: NACE0303 | E24: =SUMIFS(#REF!,#REF!,"*" & C24 & "*",#REF!,"*" & Index!$D$12 & "*",#REF!,"*" & Index!$D$16 & "*")+SUMIFS(#REF!,#REF!,"*" & C24 & "*",#REF!,"*" & Index!$D$18 & "*",#REF!,"*" & Index!$D$20 & "*") -> #REF! | F24: 2589178 | G24: =+E24-F24 -> #REF! | H24: =IFERROR(IF(((E24/F24)-1)=0,"-",((E24/F24)-1)),"-") -> - | I24: =+E24-M24-Q24 -> #REF! | J24: 2589178 | K24: =+I24-J24 -> #REF! | L24: =IFERROR(IF(((I24/J24)-1)=0,"-",((I24/J24)-1)),"-") -> - | M24: =SUMIFS(#REF!,#REF!,"*" & $C24 & "*",#REF!,"*" & Index!$D$12 & "*",#REF!,"*" & Index!$D$23 & "*",#REF!,"*" & Index!$D$16 & "*") + SUMIFS(#REF!,#REF!,"*" & $C24 & "*",#REF!,"*" & Index!$D$18 & "*",#REF!,"*" & Index!$D$23 & "*",#REF!,"*" & Index!$D$16 & "*",#REF!,"*" & Index!$D$20 & "*") -> #REF! | N24: 0 | O24: =+M24-N24 -> #REF! | P24: =IFERROR(IF(((M24/N24)-1)=0,"-",((M24/N24)-1)),"-") -> - | Q24: =SUMIFS(#REF!,#REF!,"*" & $C24 & "*",#REF!,"*" & Index!$D$12 & "*",#REF!,"*" & Index!$D$24 & "*",#REF!,"*" & Index!$D$16 & "*") + SUMIFS(#REF!,#REF!,"*" & $C24 & "*",#REF!,"*" & Index!$D$18 & "*",#REF!,"*" & Index!$D$24 & "*",#REF!,"*" & Index!$D$16 & "*",#REF!,"*" & Index!$D$20 & "*") -> #REF! | R24: 0 | S24: =+Q24-R24 -> #REF! | T24: =IFERROR(IF(((Q24/R24)-1)=0,"-",((Q24/R24)-1)),"-") -> - | U24: =SUMIFS(#REF!,#REF!,"*" & C24 &"*",#REF!,"*" & Index!$D$12 & "*",#REF!,"*" & Index!$D$17 & "*")+SUMIFS(#REF!,#REF!,"*" & C24 &"*",#REF!,"*" & Index!$D$18 & "*",#REF!,"*" & Index!$D$17 & "*",#REF!,"*" & Index!$D$20 & "*") -> #REF! | V24: -6172 | W24: =+U24-V24 -> #REF! | X24: =IFERROR(IF(((U24/V24)-1)=0,"-",((U24/V24)-1)),"-") -> - | Y24: =SUMIFS(#REF!,#REF!,"*" & C24 & "*",#REF!,"*" & Index!$D$12 & "*")+ SUMIFS(#REF!,#REF!,"*" & C24 & "*",#REF!,"*" & Index!$D$18 & "*",#REF!,"*" & Index!$D$20 & "*") -> #REF! | Z24: 2583006 | AA24: =+Y24-Z24 -> #REF! | AB24: =IFERROR(IF(((Y24/Z24)-1)=0,"-",((Y24/Z24)-1)),"-") -> -
A25: =+LEN(C25) -> 8 | C25: NACE0304 | E25: =SUMIFS(#REF!,#REF!,"*" & C25 & "*",#REF!,"*" & Index!$D$12 & "*",#REF!,"*" & Index!$D$16 & "*")+SUMIFS(#REF!,#REF!,"*" & C25 & "*",#REF!,"*" & Index!$D$18 & "*",#REF!,"*" & Index!$D$20 & "*") -> #REF! | F25: 104395029 | G25: =+E25-F25 -> #REF! | H25: =IFERROR(IF(((E25/F25)-1)=0,"-",((E25/F25)-1)),"-") -> - | I25: =+E25-M25-Q25 -> #REF! | J25: 83116123 | K25: =+I25-J25 -> #REF! | L25: =IFERROR(IF(((I25/J25)-1)=0,"-",((I25/J25)-1)),"-") -> - | M25: =SUMIFS(#REF!,#REF!,"*" & $C25 & "*",#REF!,"*" & Index!$D$12 & "*",#REF!,"*" & Index!$D$23 & "*",#REF!,"*" & Index!$D$16 & "*") + SUMIFS(#REF!,#REF!,"*" & $C25 & "*",#REF!,"*" & Index!$D$18 & "*",#REF!,"*" & Index!$D$23 & "*",#REF!,"*" & Index!$D$16 & "*",#REF!,"*" & Index!$D$20 & "*") -> #REF! | N25: 18072849 | O25: =+M25-N25 -> #REF! | P25: =IFERROR(IF(((M25/N25)-1)=0,"-",((M25/N25)-1)),"-") -> - | Q25: =SUMIFS(#REF!,#REF!,"*" & $C25 & "*",#REF!,"*" & Index!$D$12 & "*",#REF!,"*" & Index!$D$24 & "*",#REF!,"*" & Index!$D$16 & "*") + SUMIFS(#REF!,#REF!,"*" & $C25 & "*",#REF!,"*" & Index!$D$18 & "*",#REF!,"*" & Index!$D$24 & "*",#REF!,"*" & Index!$D$16 & "*",#REF!,"*" & Index!$D$20 & "*") -> #REF! | R25: 3206057 | S25: =+Q25-R25 -> #REF! | T25: =IFERROR(IF(((Q25/R25)-1)=0,"-",((Q25/R25)-1)),"-") -> - | U25: =SUMIFS(#REF!,#REF!,"*" & C25 &"*",#REF!,"*" & Index!$D$12 & "*",#REF!,"*" & Index!$D$17 & "*")+SUMIFS(#REF!,#REF!,"*" & C25 &"*",#REF!,"*" & Index!$D$18 & "*",#REF!,"*" & Index!$D$17 & "*",#REF!,"*" & Index!$D$20 & "*") -> #REF! | V25: -4399029 | W25: =+U25-V25 -> #REF! | X25: =IFERROR(IF(((U25/V25)-1)=0,"-",((U25/V25)-1)),"-") -> - | Y25: =SUMIFS(#REF!,#REF!,"*" & C25 & "*",#REF!,"*" & Index!$D$12 & "*")+ SUMIFS(#REF!,#REF!,"*" & C25 & "*",#REF!,"*" & Index!$D$18 & "*",#REF!,"*" & Index!$D$20 & "*") -> #REF! | Z25: 99996000 | AA25: =+Y25-Z25 -> #REF! | AB25: =IFERROR(IF(((Y25/Z25)-1)=0,"-",((Y25/Z25)-1)),"-") -> -
A26: =+LEN(C26) -> 8 | C26: NACE0305 | E26: =SUMIFS(#REF!,#REF!,"*" & C26 & "*",#REF!,"*" & Index!$D$12 & "*",#REF!,"*" & Index!$D$16 & "*")+SUMIFS(#REF!,#REF!,"*" & C26 & "*",#REF!,"*" & Index!$D$18 & "*",#REF!,"*" & Index!$D$20 & "*") -> #REF! | F26: 94181379 | G26: =+E26-F26 -> #REF! | H26: =IFERROR(IF(((E26/F26)-1)=0,"-",((E26/F26)-1)),"-") -> - | I26: =+E26-M26-Q26 -> #REF! | J26: 67761186 | K26: =+I26-J26 -> #REF! | L26: =IFERROR(IF(((I26/J26)-1)=0,"-",((I26/J26)-1)),"-") -> - | M26: =SUMIFS(#REF!,#REF!,"*" & $C26 & "*",#REF!,"*" & Index!$D$12 & "*",#REF!,"*" & Index!$D$23 & "*",#REF!,"*" & Index!$D$16 & "*") + SUMIFS(#REF!,#REF!,"*" & $C26 & "*",#REF!,"*" & Index!$D$18 & "*",#REF!,"*" & Index!$D$23 & "*",#REF!,"*" & Index!$D$16 & "*",#REF!,"*" & Index!$D$20 & "*") -> #REF! | N26: 19296273 | O26: =+M26-N26 -> #REF! | P26: =IFERROR(IF(((M26/N26)-1)=0,"-",((M26/N26)-1)),"-") -> - | Q26: =SUMIFS(#REF!,#REF!,"*" & $C26 & "*",#REF!,"*" & Index!$D$12 & "*",#REF!,"*" & Index!$D$24 & "*",#REF!,"*" & Index!$D$16 & "*") + SUMIFS(#REF!,#REF!,"*" & $C26 & "*",#REF!,"*" & Index!$D$18 & "*",#REF!,"*" & Index!$D$24 & "*",#REF!,"*" & Index!$D$16 & "*",#REF!,"*" & Index!$D$20 & "*") -> #REF! | R26: 7123920 | S26: =+Q26-R26 -> #REF! | T26: =IFERROR(IF(((Q26/R26)-1)=0,"-",((Q26/R26)-1)),"-") -> - | U26: =SUMIFS(#REF!,#REF!,"*" & C26 &"*",#REF!,"*" & Index!$D$12 & "*",#REF!,"*" & Index!$D$17 & "*")+SUMIFS(#REF!,#REF!,"*" & C26 &"*",#REF!,"*" & Index!$D$18 & "*",#REF!,"*" & Index!$D$17 & "*",#REF!,"*" & Index!$D$20 & "*") -> #REF! | V26: -10890183 | W26: =+U26-V26 -> #REF! | X26: =IFERROR(IF(((U26/V26)-1)=0,"-",((U26/V26)-1)),"-") -> - | Y26: =SUMIFS(#REF!,#REF!,"*" & C26 & "*",#REF!,"*" & Index!$D$12 & "*")+ SUMIFS(#REF!,#REF!,"*" & C26 & "*",#REF!,"*" & Index!$D$18 & "*",#REF!,"*" & Index!$D$20 & "*") -> #REF! | Z26: 83291196 | AA26: =+Y26-Z26 -> #REF! | AB26: =IFERROR(IF(((Y26/Z26)-1)=0,"-",((Y26/Z26)-1)),"-") -> -
A27: =+LEN(C27) -> 8 | C27: NACE0306 | E27: =SUMIFS(#REF!,#REF!,"*" & C27 & "*",#REF!,"*" & Index!$D$12 & "*",#REF!,"*" & Index!$D$16 & "*")+SUMIFS(#REF!,#REF!,"*" & C27 & "*",#REF!,"*" & Index!$D$18 & "*",#REF!,"*" & Index!$D$20 & "*") -> #REF! | F27: 54384318 | G27: =+E27-F27 -> #REF! | H27: =IFERROR(IF(((E27/F27)-1)=0,"-",((E27/F27)-1)),"-") -> - | I27: =+E27-M27-Q27 -> #REF! | J27: 36970853 | K27: =+I27-J27 -> #REF! | L27: =IFERROR(IF(((I27/J27)-1)=0,"-",((I27/J27)-1)),"-") -> - | M27: =SUMIFS(#REF!,#REF!,"*" & $C27 & "*",#REF!,"*" & Index!$D$12 & "*",#REF!,"*" & Index!$D$23 & "*",#REF!,"*" & Index!$D$16 & "*") + SUMIFS(#REF!,#REF!,"*" & $C27 & "*",#REF!,"*" & Index!$D$18 & "*",#REF!,"*" & Index!$D$23 & "*",#REF!,"*" & Index!$D$16 & "*",#REF!,"*" & Index!$D$20 & "*") -> #REF! | N27: 10416012 | O27: =+M27-N27 -> #REF! | P27: =IFERROR(IF(((M27/N27)-1)=0,"-",((M27/N27)-1)),"-") -> - | Q27: =SUMIFS(#REF!,#REF!,"*" & $C27 & "*",#REF!,"*" & Index!$D$12 & "*",#REF!,"*" & Index!$D$24 & "*",#REF!,"*" & Index!$D$16 & "*") + SUMIFS(#REF!,#REF!,"*" & $C27 & "*",#REF!,"*" & Index!$D$18 & "*",#REF!,"*" & Index!$D$24 & "*",#REF!,"*" & Index!$D$16 & "*",#REF!,"*" & Index!$D$20 & "*") -> #REF! | R27: 6997453 | S27: =+Q27-R27 -> #REF! | T27: =IFERROR(IF(((Q27/R27)-1)=0,"-",((Q27/R27)-1)),"-") -> - | U27: =SUMIFS(#REF!,#REF!,"*" & C27 &"*",#REF!,"*" & Index!$D$12 & "*",#REF!,"*" & Index!$D$17 & "*")+SUMIFS(#REF!,#REF!,"*" & C27 &"*",#REF!,"*" & Index!$D$18 & "*",#REF!,"*" & Index!$D$17 & "*",#REF!,"*" & Index!$D$20 & "*") -> #REF! | V27: -7653435 | W27: =+U27-V27 -> #REF! | X27: =IFERROR(IF(((U27/V27)-1)=0,"-",((U27/V27)-1)),"-") -> - | Y27: =SUMIFS(#REF!,#REF!,"*" & C27 & "*",#REF!,"*" & Index!$D$12 & "*")+ SUMIFS(#REF!,#REF!,"*" & C27 & "*",#REF!,"*" & Index!$D$18 & "*",#REF!,"*" & Index!$D$20 & "*") -> #REF! | Z27: 46730883 | AA27: =+Y27-Z27 -> #REF! | AB27: =IFERROR(IF(((Y27/Z27)-1)=0,"-",((Y27/Z27)-1)),"-") -> -
