Workbook

Sheet Sheet
A1: chave | B1: scp1 | C1: scp2 | D1: =+SUM(D2:D949) -> 28110777 | E1: =+SUM(E2:E949) -> 28838525
A2: 89000000000247796000420000664413 | B2: 326326.48 | D2: =+B2+C2 -> 326326.48 | E2: =+VLOOKUP(A2,Sheet3!A:B,2,FALSE) -> 652653.36 | F2: =+ABS(E2-D2) -> 326326.88 | H2: Coluna A,B e C da tabela de emissões financiadas
A3: 89000000000251214000420000678581 | B3: 105641.3 | D3: =+B3+C3 -> 105641.3 | E3: =+VLOOKUP(A3,Sheet3!A:B,2,FALSE) -> 211282.82 | F3: =+ABS(E3-D3) -> 105641.52
A4: 89000000000244444000420000322385 | B4: 77053.132 | D4: =+B4+C4 -> 77053.132 | E4: =+VLOOKUP(A4,Sheet3!A:B,2,FALSE) -> 154107.1 | F4: =+ABS(E4-D4) -> 77053.968
A5: 89000000000249606000420000775937 | B5: 73304.762 | D5: =+B5+C5 -> 73304.762 | E5: =+VLOOKUP(A5,Sheet3!A:B,2,FALSE) -> 146609.54 | F5: =+ABS(E5-D5) -> 73304.778
A6: 89000000000242900000420000660098 | B6: 38735.955 | D6: =+B6+C6 -> 38735.955 | E6: =+VLOOKUP(A6,Sheet3!A:B,2,FALSE) -> 77472.12 | F6: =+ABS(E6-D6) -> 38736.165
A7: 89000000000229669000420000658958 | B7: 38282.142 | D7: =+B7+C7 -> 38282.142 | E7: =+VLOOKUP(A7,Sheet3!A:B,2,FALSE) -> 76564.6 | F7: =+ABS(E7-D7) -> 38282.458
A8: 89000000000241739000420000427267 | B8: 14591.333 | D8: =+B8+C8 -> 14591.333 | E8: =+VLOOKUP(A8,Sheet3!A:B,2,FALSE) -> 29182.76 | F8: =+ABS(E8-D8) -> 14591.427
A9: 89000000000226300000420000659907 | B9: 14244.319 | D9: =+B9+C9 -> 14244.319 | E9: =+VLOOKUP(A9,Sheet3!A:B,2,FALSE) -> 28488.74 | F9: =+ABS(E9-D9) -> 14244.421
A10: 89000000000237393000420000709714 | B10: 10734.942 | D10: =+B10+C10 -> 10734.942 | E10: =+VLOOKUP(A10,Sheet3!A:B,2,FALSE) -> 21470 | F10: =+ABS(E10-D10) -> 10735.058
A11: 89000000000247433000450000323361 | B11: 8673.065 | D11: =+B11+C11 -> 8673.065 | E11: =+VLOOKUP(A11,Sheet3!A:B,2,FALSE) -> 16094.7 | F11: =+ABS(E11-D11) -> 7421.635
A12: 89000000000220615000420000688408 | B12: 47946.713 | D12: =+B12+C12 -> 47946.713 | E12: =+VLOOKUP(A12,Sheet3!A:B,2,FALSE) -> 53274.4 | F12: =+ABS(E12-D12) -> 5327.687
A13: 89000000000236893000420000739549 | B13: 4103.1906 | D13: =+B13+C13 -> 4103.1906 | E13: =+VLOOKUP(A13,Sheet3!A:B,2,FALSE) -> 8206.52 | F13: =+ABS(E13-D13) -> 4103.3294
A14: 89000000000247318000450000408182 | B14: 3122.3659 | D14: =+B14+C14 -> 3122.3659 | E14: =+VLOOKUP(A14,Sheet3!A:B,2,FALSE) -> 6244.74 | F14: =+ABS(E14-D14) -> 3122.3741
... A624: 89000000000223389000420000695941 | B624: 6924.0408 | D624: =+B624+C624 -> 6924.0408 | E624: =+VLOOKUP(A624,Sheet3!A:B,2,FALSE) -> 6924.05 | F624: =+ABS(E624-D624) -> 0.009213
A625: 89000000000250728000450000474788 | C625: 920.48901 | D625: =+B625+C625 -> 920.48901 | E625: =+VLOOKUP(A625,Sheet3!A:B,2,FALSE) -> 920.48 | F625: =+ABS(E625-D625) -> 0.00901
A626: 89000000000241711000420000577193 | B626: 16215.051 | D626: =+B626+C626 -> 16215.051 | E626: =+VLOOKUP(A626,Sheet3!A:B,2,FALSE) -> 16215.06 | F626: =+ABS(E626-D626) -> 0.008991
A627: 89000000000248313000420000674810 | B627: 38416.711 | D627: =+B627+C627 -> 38416.711 | E627: =+VLOOKUP(A627,Sheet3!A:B,2,FALSE) -> 38416.72 | F627: =+ABS(E627-D627) -> 0.008982
A628: 89000000000242929000420000742118 | B628: 17062.521 | D628: =+B628+C628 -> 17062.521 | E628: =+VLOOKUP(A628,Sheet3!A:B,2,FALSE) -> 17062.53 | F628: =+ABS(E628-D628) -> 0.008608
A629: 89000000000248042000420000658159 | B629: 40296.191 | D629: =+B629+C629 -> 40296.191 | E629: =+VLOOKUP(A629,Sheet3!A:B,2,FALSE) -> 40296.2 | F629: =+ABS(E629-D629) -> 0.008519
A630: 89000000000248043000420000658159 | B630: 40296.191 | D630: =+B630+C630 -> 40296.191 | E630: =+VLOOKUP(A630,Sheet3!A:B,2,FALSE) -> 40296.2 | F630: =+ABS(E630-D630) -> 0.008519
A631: 89000000000248044000420000658159 | B631: 40296.191 | D631: =+B631+C631 -> 40296.191 | E631: =+VLOOKUP(A631,Sheet3!A:B,2,FALSE) -> 40296.2 | F631: =+ABS(E631-D631) -> 0.008519
A632: 89000000000248045000420000658159 | B632: 40296.191 | D632: =+B632+C632 -> 40296.191 | E632: =+VLOOKUP(A632,Sheet3!A:B,2,FALSE) -> 40296.2 | F632: =+ABS(E632-D632) -> 0.008519
A633: 89000000000248046000420000658159 | B633: 40296.191 | D633: =+B633+C633 -> 40296.191 | E633: =+VLOOKUP(A633,Sheet3!A:B,2,FALSE) -> 40296.2 | F633: =+ABS(E633-D633) -> 0.008519
A634: 89000000000239290000420000702302 | B634: 7916.6715 | D634: =+B634+C634 -> 7916.6715 | E634: =+VLOOKUP(A634,Sheet3!A:B,2,FALSE) -> 7916.68 | F634: =+ABS(E634-D634) -> 0.008465
A635: 89000000000247239000420000478253 | B635: 39170.622 | D635: =+B635+C635 -> 39170.622 | E635: =+VLOOKUP(A635,Sheet3!A:B,2,FALSE) -> 39170.63 | F635: =+ABS(E635-D635) -> 0.00846
A636: 89000000000244712000450000579367 | B636: 3432.1917 | D636: =+B636+C636 -> 3432.1917 | E636: =+VLOOKUP(A636,Sheet3!A:B,2,FALSE) -> 3432.2 | F636: =+ABS(E636-D636) -> 0.008276
A637: 89000000000232021000420000482273 | B637: 9083.5219 | D637: =+B637+C637 -> 9083.5219 | E637: =+VLOOKUP(A637,Sheet3!A:B,2,FALSE) -> 9083.53 | F637: =+ABS(E637-D637) -> 0.008121
... A679: 89000000000246263000450000656961 | B679: 1360.974 | D679: =+B679+C679 -> 1360.974 | E679: =+VLOOKUP(A679,Sheet3!A:B,2,FALSE) -> 1360.98 | F679: =+ABS(E679-D679) -> 0.005997
A680: 89000000000246095000450000587303 | B680: 483.9246 | C680: 411.06139 | D680: =+B680+C680 -> 894.98599 | E680: =+VLOOKUP(A680,Sheet3!A:B,2,FALSE) -> 894.98 | F680: =+ABS(E680-D680) -> 0.005991
A681: 89000000008046280000530000730704 | B681: 929.93607 | C681: 789.91814 | D681: =+B681+C681 -> 1719.8542 | E681: =+VLOOKUP(A681,Sheet3!A:B,2,FALSE) -> 1719.86 | F681: =+ABS(E681-D681) -> 0.005795
A682: 89000000000238587000450000694683 | B682: 1111.3642 | D682: =+B682+C682 -> 1111.3642 | E682: =+VLOOKUP(A682,Sheet3!A:B,2,FALSE) -> 1111.37 | F682: =+ABS(E682-D682) -> 0.005789
A683: 89000000000250980000450000769101 | B683: 1820.1343 | D683: =+B683+C683 -> 1820.1343 | E683: =+VLOOKUP(A683,Sheet3!A:B,2,FALSE) -> 1820.14 | F683: =+ABS(E683-D683) -> 0.005746
A684: 89000000000234069000450000517280 | B684: 840.77427 | D684: =+B684+C684 -> 840.77427 | E684: =+VLOOKUP(A684,Sheet3!A:B,2,FALSE) -> 840.78 | F684: =+ABS(E684-D684) -> 0.005733
A685: 89000000000248104000420000321896 | B685: 230944.51 | D685: =+B685+C685 -> 230944.51 | E685: =+VLOOKUP(A685,Sheet3!A:B,2,FALSE) -> 230944.5 | F685: =+ABS(E685-D685) -> 0.005715
A686: 89000000000248115000420000321896 | B686: 230944.51 | D686: =+B686+C686 -> 230944.51 | E686: =+VLOOKUP(A686,Sheet3!A:B,2,FALSE) -> 230944.5 | F686: =+ABS(E686-D686) -> 0.005715
A687: 89000000000241521000450000585395 | C687: 31.154298 | D687: =+B687+C687 -> 31.154298 | E687: =+VLOOKUP(A687,Sheet3!A:B,2,FALSE) -> 31.16 | F687: =+ABS(E687-D687) -> 0.005702
A688: 89000000000250666000420000666000 | B688: 47866.664 | D688: =+B688+C688 -> 47866.664 | E688: =+VLOOKUP(A688,Sheet3!A:B,2,FALSE) -> 47866.67 | F688: =+ABS(E688-D688) -> 0.005628
A689: 89000000000244899000450000754223 | B689: 400.51437 | C689: 340.21002 | D689: =+B689+C689 -> 740.72439 | E689: =+VLOOKUP(A689,Sheet3!A:B,2,FALSE) -> 740.73 | F689: =+ABS(E689-D689) -> 0.00561
A690: 89000000000247423000450000476117 | B690: 1028.1444 | D690: =+B690+C690 -> 1028.1444 | E690: =+VLOOKUP(A690,Sheet3!A:B,2,FALSE) -> 1028.15 | F690: =+ABS(E690-D690) -> 0.005581
...

Sheet Sheet3
A3: Row Labels | B3: Sum of GHG_FINANCED_EMISSIONS
A4: 89000000000213179000420000532622 | B4: 5511.8
A5: 89000000000216667000420000532622 | B5: 1862.75
A6: 89000000000220119000420000514177 | B6: 18908.75
A7: 89000000000220134000420000688408 | B7: 3757.91
A8: 89000000000220136000420000688408 | B8: 15639.8
A9: 89000000000220438000420000690115 | B9: 25621.69
A10: 89000000000220557000420000688408 | B10: 3880.34
A11: 89000000000220615000420000688408 | B11: 53274.4
A12: 89000000000220959000420000688408 | B12: 14672.6
A13: 89000000000221101000420000515640 | B13: 2207.98
A14: 89000000000221647000420000637589 | B14: 11023.05
A15: 89000000000221760000420000656779 | B15: 4024.33
... A952: Grand Total | B952: 28838525

Sheet Sheet1
A1: INSTRMNT_ID | B1: PRTCTN_ID | C1: TYP_VHCL | D1: DT_INCPTN | E1: IDCMB | F1: TYP_PRTCTN | G1: TYP_RLTN | H1: SCOPE_USED | I1: CALCULATION_APPROACH_LOC | J1: SOURCE_EMISSION_LOC | K1: DATA_QUALITY_SCORE_LOC | L1: GHG_FINANCED_EMISSIONS
A2: 89000000000213179000420000532622 | B2: M_0000_00000213179_000000000000001 | C2: VEH05 | D2: 2016-04-01 | E2: CONT1;HFS2;B01;MC02;PR0302;ACPF6;SC0303;STAG2;POCI2;SUBO2;DEFA2;FORB2;SSC4;PURP6;COLL4;TYVA01;FVAD3 | F2: 51 | G2: REL01 | H2: SCOPE_1 | I2: CAAP4 | J2: SOUR2 | K2: DQS4 | L2: 5511.8 | M2: =+SUMIF(A:A,A2,L:L) -> 5511.8
A3: 89000000000216667000420000532622 | B3: M_0000_00000216667_000000000000001 | C3: VEH16 | D3: 2016-12-15 | E3: CONT1;HFS2;B01;MC02;PR0302;ACPF6;SC0303;STAG2;POCI2;SUBO2;DEFA2;FORB2;SSC4;PURP6;COLL4;TYVA01;FVAD3 | F3: 51 | G3: REL01 | H3: SCOPE_1 | I3: CAAP4 | J3: SOUR2 | K3: DQS4 | L3: 1862.75 | M3: =+SUMIF(A:A,A3,L:L) -> 1862.75
A4: 89000000000220119000420000514177 | B4: M_0000_00000220119_000000000000003 | C4: VEH16 | D4: 2017-09-01 | E4: CONT1;HFS2;B01;MC02;PR0302;ACPF6;SC0303;STAG1;SUBO2;DEFA2;FORB2;SSC3;PURP6;COLL4;TYVA01;FVAD3 | F4: 51 | G4: REL01 | H4: SCOPE_1 | I4: CAAP4 | J4: SOUR2 | K4: DQS4 | L4: 3781.75 | M4: =+SUMIF(A:A,A4,L:L) -> 38306.46
A5: 89000000000220119000420000514177 | B5: M_0000_00000220119_000000000000007 | C5: VEH16 | D5: 2017-09-01 | E5: CONT1;HFS2;B01;MC02;PR0302;ACPF6;SC0303;STAG1;SUBO2;DEFA2;FORB2;SSC3;PURP6;COLL4;TYVA01;FVAD3 | F5: 51 | G5: REL01 | H5: SCOPE_1 | I5: CAAP4 | J5: SOUR2 | K5: DQS4 | L5: 3781.75 | M5: =+SUMIF(A:A,A5,L:L) -> 38306.46
A6: 89000000000220119000420000514177 | B6: M_0000_00000220119_000000000000001 | C6: VEH16 | D6: 2017-09-01 | E6: CONT1;HFS2;B01;MC02;PR0302;ACPF6;SC0303;STAG1;SUBO2;DEFA2;FORB2;SSC3;PURP6;COLL4;TYVA01;FVAD3 | F6: 51 | G6: REL01 | H6: SCOPE_1 | I6: CAAP4 | J6: SOUR2 | K6: DQS4 | L6: 3781.75 | M6: =+SUMIF(A:A,A6,L:L) -> 38306.46
A7: 89000000000220119000420000514177 | B7: M_0000_00000220119_000000000000009 | C7: VEH16 | D7: 2017-09-01 | E7: CONT1;HFS2;B01;MC02;PR0302;ACPF6;SC0303;STAG1;SUBO2;DEFA2;FORB2;SSC3;PURP6;COLL4;TYVA01;FVAD3 | F7: 51 | G7: REL01 | H7: SCOPE_1 | I7: CAAP4 | J7: SOUR2 | K7: DQS4 | L7: 3781.75 | M7: =+SUMIF(A:A,A7,L:L) -> 38306.46
A8: 89000000000220119000420000514177 | B8: M_0000_00000220119_000000000000005 | C8: VEH16 | D8: 2017-09-01 | E8: CONT1;HFS2;B01;MC02;PR0302;ACPF6;SC0303;STAG1;SUBO2;DEFA2;FORB2;SSC3;PURP6;COLL4;TYVA01;FVAD3 | F8: 51 | G8: REL01 | H8: SCOPE_1 | I8: CAAP4 | J8: SOUR2 | K8: DQS4 | L8: 3781.75 | M8: =+SUMIF(A:A,A8,L:L) -> 38306.46
A9: 89000000000220134000420000688408 | B9: M_0000_00000220134_000000000000001 | C9: VEH05 | D9: 2017-09-01 | E9: CONT1;HFS2;B01;MC02;PR0302;ACPF6;SC0303;STAG1;SUBO2;DEFA2;FORB2;SSC3;PURP6;COLL4;TYVA01;FVAD3 | F9: 51 | G9: REL01 | H9: SCOPE_1 | I9: CAAP4 | J9: SOUR2 | K9: DQS4 | L9: 3757.91 | M9: =+SUMIF(A:A,A9,L:L) -> 38306.46
A10: 89000000000220136000420000688408 | B10: M_0000_00000220136_000000000000013 | C10: VEH05 | D10: 2017-09-01 | E10: CONT1;HFS2;B01;MC02;PR0302;ACPF6;SC0303;STAG1;SUBO2;DEFA2;FORB2;SSC3;PURP6;COLL4;TYVA01;FVAD3 | F10: 51 | G10: REL01 | H10: SCOPE_1 | I10: CAAP4 | J10: SOUR2 | K10: DQS4 | L10: 3909.95 | M10: =+SUMIF(A:A,A10,L:L) -> 38306.46
A11: 89000000000220136000420000688408 | B11: M_0000_00000220136_000000000000005 | C11: VEH05 | D11: 2017-09-01 | E11: CONT1;HFS2;B01;MC02;PR0302;ACPF6;SC0303;STAG1;SUBO2;DEFA2;FORB2;SSC3;PURP6;COLL4;TYVA01;FVAD3 | F11: 51 | G11: REL01 | H11: SCOPE_1 | I11: CAAP4 | J11: SOUR2 | K11: DQS4 | L11: 3909.95 | M11: =+SUMIF(A:A,A11,L:L) -> 38306.46
A12: 89000000000220136000420000688408 | B12: M_0000_00000220136_000000000000001 | C12: VEH05 | D12: 2017-09-01 | E12: CONT1;HFS2;B01;MC02;PR0302;ACPF6;SC0303;STAG1;SUBO2;DEFA2;FORB2;SSC3;PURP6;COLL4;TYVA01;FVAD3 | F12: 51 | G12: REL01 | H12: SCOPE_1 | I12: CAAP4 | J12: SOUR2 | K12: DQS4 | L12: 3909.95 | M12: =+SUMIF(A:A,A12,L:L) -> 38306.46
A13: 89000000000220136000420000688408 | B13: M_0000_00000220136_000000000000009 | C13: VEH05 | D13: 2017-09-01 | E13: CONT1;HFS2;B01;MC02;PR0302;ACPF6;SC0303;STAG1;SUBO2;DEFA2;FORB2;SSC3;PURP6;COLL4;TYVA01;FVAD3 | F13: 51 | G13: REL01 | H13: SCOPE_1 | I13: CAAP4 | J13: SOUR2 | K13: DQS4 | L13: 3909.95 | M13: =+SUMIF(A:A,A13,L:L) -> 38306.46
... A1415: 89000000008047123000530000737662 | B1415: M_0000_00008047123_000000000000001 | C1415: VEH04 | D1415: 2025-06-27 | E1415: CONT1;HFS2;B01;MC02;PR0302;ACPF6;SC0303;STAG1;SUBO2;DEFA2;FORB2;SSC4;PURP6;COLL4;TYVA01;FVAD3 | F1415: 51 | G1415: REL01 | H1415: SCOPE_1 | I1415: CAAP4 | J1415: SOUR2 | K1415: DQS4 | L1415: 2590.92 | M1415: =+SUMIF(A:A,A1415,L:L) -> 2590.92

Sheet Sheet2
