Workbook

Sheet 0. Instruções
B6: 0. Instruções
B8: Projeto | D8: Testes MBDT
B9: Âmbito | D9: Análise dos campos da Loan Tape para o âmbito PM entre cd_loan_tapes_bce e bu_loantape_work.
B11: Para a validação dos campos da Loan Tape é necessário percorrer os seguintes steps:
B14: 1. Atualizar o script de simulação com o campo em análise.
B15: 1.1. Verificar a especificação do campo em análise. Se aplicável, verificar se é necessário reportar valor para ajustes.
B16: 1.2. Montar a simulação do campo tendo atenção aos seguintes pormenores:
B17: a) Não vamos fazer JOIN com a tabela de parametrização (LT803). Em alternativa, montamos um CASE WHEN ou importamos a parametrização.
B18: b) Para operações de ajustes verificar se o campo deve reportar valor.
B19: c) Se for necessário aplicar algum filtro (ou tratamento) que não está na especificação deixar um comentário no código.
B20: d) Garantir que não existem duplicados e deixar no código o número de registos de cada LEFT JOIN.
B21: 2. Executar no HUE (em HIVE) o CREATE TABLE do script de simulação.
B22: 3. Executar no HUE o script de controlo de universo.
B23: a) O número de registos em comum tem de ser igual ao número de registos do teste de coerência. Caso tenhamos registos que não são comuns é necessário ver exemplos para ver o que está a acontecer.
B24: 4. Verificar com IT o nome da tabela a testar e filtros. Caso seja necessário, atualizar as tabelas infra:
C26: Nome da Tabela | D26: Tabela Loan Tape PM | E26: Tabela Simulada | F26: Chave 1 | G26: Chave 2
C27: Univ_Oper | D27: lt001_univ_oper | E27: lt001_univ_oper | F27: concat(cempresa, cbalcao, cnumecta, zdeposit, ccontab_final_ifrs, ccontab_final_pcsb, ccontab_final_cargabal, ccontab_final) | G27: zcliente
C28: Entity | D28: lt003_entity | E28: lt003_entity | F28: entty_id
C29: Instrument | D29: lt002_instrument | E29: lt002_instrument | F29: instrmnt_id
C30: Protection | D30: lt004_protection | E30: lt004_protection | F30: prtctn_id
C31: INSTR_ENT | D31: lt005_instr_ent | E31: lt005_instr_ent | F31: instrmnt_id | G31: entty_id
C32: INSTR_PROT | D32: lt006_instr_prot | E32: lt006_instr_prot | F32: instrmnt_id | G32: prtctn_id
C34: Filtros
C35: Schema Loan Tape PM | D35: cd_loan_tapes_bce
C36: Schema Simulada | D36: bu_loantape_work
C37: nome_perimetro | D37: Individual Local
C38: segmento | D38: ESTR
C39: ambito Loan Tape | D39: PM
C40: ambito Simulação | D40: PM
C41: entidade | D41: 00100
C42: Filtro Loan Tape | D42: =+"ref_date='${ref_date}'"&" AND "&C37&"='"&D37&"' AND "&C38&"='"&D38&"' AND ambito='"&D40&"'"&" AND "&C41&"='"&D41&"'" -> ref_date='${ref_date}' AND nome_perimetro='Individual Local' AND segmento='ESTR' AND ambito='PM' AND entidade='00100'
C43: Filtro Simulação | D43: =+"ref_date='${ref_date}'"&" AND "&C37&"='"&D37&"' AND "&C38&"='"&D38&"' AND ambito='"&D39&"'"&" AND "&C41&"='"&D41&"'" -> ref_date='${ref_date}' AND nome_perimetro='Individual Local' AND segmento='ESTR' AND ambito='PM' AND entidade='00100'

Sheet 1. Status
H6: 1. Status dos Testes
H8: REF_DATE | I8: 45991
B9: Auxiliar
B10: Coerência | C10: Validade | D10: Caracteres Especiais | E10: Missings | F10: Not applicable | H10: Tabela | I10: Campo | J10: Testes Corridos (#) | K10: Número de Registos ID1. (#) | L10: ID Exec. 1. | M10: 1. Erros de Coerência (#) | N10: Comentário | O10: Status
A11: =+H11&I11&$I$8 -> UNIV_OPERmsaldo_final45991 | B11: {=+MAX(IF('3. Resultados'!A:A='1. Status'!A11&'1. Status'!$B$10,'3. Resultados'!K:K))} -> 0 | C11: {=+MAX(IF('3. Resultados'!A:A='1. Status'!A11&'1. Status'!$C$10,'3. Resultados'!K:K))} -> 0 | D11: {=+MAX(IF('3. Resultados'!A:A='1. Status'!A11&'1. Status'!$D$10,'3. Resultados'!K:K))} -> 0 | E11: {=+MAX(IF('3. Resultados'!A:A='1. Status'!A11&'1. Status'!$E$10,'3. Resultados'!K:K))} -> 0 | F11: {=+MAX(IF('3. Resultados'!A:A='1. Status'!A11&'1. Status'!$F$10,'3. Resultados'!K:K))} -> 0 | H11: UNIV_OPER | I11: msaldo_final | J11: =+COUNTIFS('3. Resultados'!C:C,'1. Status'!H11,'3. Resultados'!G:G,'1. Status'!I11) -> 1 | K11: =+IFERROR(VLOOKUP(CONCATENATE(A11,$B$10,B11),'3. Resultados'!B:J,8,FALSE),"-") -> - | L11: =+IFERROR(VLOOKUP(B11,'3. Resultados'!K:L,2,FALSE),"-") -> - | M11: =+IFERROR(VLOOKUP(CONCATENATE(A11,$B$10,B11),'3. Resultados'!B:J,9,FALSE),"-") -> - | O11: =+IF(J11=0,"Por iniciar",IF(OR(K11="-",M11="-"),"Em testes",IF(M11=0,"OK","NOK"))) -> Em testes
A12: =+H12&I12&$I$8 -> UNIV_OPERcarteira_contabilistica45991 | B12: {=+MAX(IF('3. Resultados'!A:A='1. Status'!A12&'1. Status'!$B$10,'3. Resultados'!K:K))} -> 0 | C12: {=+MAX(IF('3. Resultados'!A:A='1. Status'!A12&'1. Status'!$C$10,'3. Resultados'!K:K))} -> 0 | D12: {=+MAX(IF('3. Resultados'!A:A='1. Status'!A12&'1. Status'!$D$10,'3. Resultados'!K:K))} -> 0 | E12: {=+MAX(IF('3. Resultados'!A:A='1. Status'!A12&'1. Status'!$E$10,'3. Resultados'!K:K))} -> 0 | F12: {=+MAX(IF('3. Resultados'!A:A='1. Status'!A12&'1. Status'!$F$10,'3. Resultados'!K:K))} -> 0 | H12: UNIV_OPER | I12: carteira_contabilistica | J12: =+COUNTIFS('3. Resultados'!C:C,'1. Status'!H12,'3. Resultados'!G:G,'1. Status'!I12) -> 1 | K12: =+IFERROR(VLOOKUP(CONCATENATE(A12,$B$10,B12),'3. Resultados'!B:J,8,FALSE),"-") -> - | L12: =+IFERROR(VLOOKUP(B12,'3. Resultados'!K:L,2,FALSE),"-") -> - | M12: =+IFERROR(VLOOKUP(CONCATENATE(A12,$B$10,B12),'3. Resultados'!B:J,9,FALSE),"-") -> - | O12: =+IF(J12=0,"Por iniciar",IF(OR(K12="-",M12="-"),"Em testes",IF(M12=0,"OK","NOK"))) -> Em testes
A13: =+H13&I13&$I$8 -> UNIV_OPERinstrumento_financeiro45991 | B13: {=+MAX(IF('3. Resultados'!A:A='1. Status'!A13&'1. Status'!$B$10,'3. Resultados'!K:K))} -> 0 | C13: {=+MAX(IF('3. Resultados'!A:A='1. Status'!A13&'1. Status'!$C$10,'3. Resultados'!K:K))} -> 0 | D13: {=+MAX(IF('3. Resultados'!A:A='1. Status'!A13&'1. Status'!$D$10,'3. Resultados'!K:K))} -> 0 | E13: {=+MAX(IF('3. Resultados'!A:A='1. Status'!A13&'1. Status'!$E$10,'3. Resultados'!K:K))} -> 0 | F13: {=+MAX(IF('3. Resultados'!A:A='1. Status'!A13&'1. Status'!$F$10,'3. Resultados'!K:K))} -> 0 | H13: UNIV_OPER | I13: instrumento_financeiro | J13: =+COUNTIFS('3. Resultados'!C:C,'1. Status'!H13,'3. Resultados'!G:G,'1. Status'!I13) -> 1 | K13: =+IFERROR(VLOOKUP(CONCATENATE(A13,$B$10,B13),'3. Resultados'!B:J,8,FALSE),"-") -> - | L13: =+IFERROR(VLOOKUP(B13,'3. Resultados'!K:L,2,FALSE),"-") -> - | M13: =+IFERROR(VLOOKUP(CONCATENATE(A13,$B$10,B13),'3. Resultados'!B:J,9,FALSE),"-") -> - | O13: =+IF(J13=0,"Por iniciar",IF(OR(K13="-",M13="-"),"Em testes",IF(M13=0,"OK","NOK"))) -> Em testes
A14: =+H14&I14&$I$8 -> UNIV_OPERcontraparte45991 | B14: {=+MAX(IF('3. Resultados'!A:A='1. Status'!A14&'1. Status'!$B$10,'3. Resultados'!K:K))} -> 0 | C14: {=+MAX(IF('3. Resultados'!A:A='1. Status'!A14&'1. Status'!$C$10,'3. Resultados'!K:K))} -> 0 | D14: {=+MAX(IF('3. Resultados'!A:A='1. Status'!A14&'1. Status'!$D$10,'3. Resultados'!K:K))} -> 0 | E14: {=+MAX(IF('3. Resultados'!A:A='1. Status'!A14&'1. Status'!$E$10,'3. Resultados'!K:K))} -> 0 | F14: {=+MAX(IF('3. Resultados'!A:A='1. Status'!A14&'1. Status'!$F$10,'3. Resultados'!K:K))} -> 0 | H14: UNIV_OPER | I14: contraparte | J14: =+COUNTIFS('3. Resultados'!C:C,'1. Status'!H14,'3. Resultados'!G:G,'1. Status'!I14) -> 1 | K14: =+IFERROR(VLOOKUP(CONCATENATE(A14,$B$10,B14),'3. Resultados'!B:J,8,FALSE),"-") -> - | L14: =+IFERROR(VLOOKUP(B14,'3. Resultados'!K:L,2,FALSE),"-") -> - | M14: =+IFERROR(VLOOKUP(CONCATENATE(A14,$B$10,B14),'3. Resultados'!B:J,9,FALSE),"-") -> - | O14: =+IF(J14=0,"Por iniciar",IF(OR(K14="-",M14="-"),"Em testes",IF(M14=0,"OK","NOK"))) -> Em testes
A15: =+H15&I15&$I$8 -> UNIV_OPERcontraparte_i45991 | B15: {=+MAX(IF('3. Resultados'!A:A='1. Status'!A15&'1. Status'!$B$10,'3. Resultados'!K:K))} -> 0 | C15: {=+MAX(IF('3. Resultados'!A:A='1. Status'!A15&'1. Status'!$C$10,'3. Resultados'!K:K))} -> 0 | D15: {=+MAX(IF('3. Resultados'!A:A='1. Status'!A15&'1. Status'!$D$10,'3. Resultados'!K:K))} -> 0 | E15: {=+MAX(IF('3. Resultados'!A:A='1. Status'!A15&'1. Status'!$E$10,'3. Resultados'!K:K))} -> 0 | F15: {=+MAX(IF('3. Resultados'!A:A='1. Status'!A15&'1. Status'!$F$10,'3. Resultados'!K:K))} -> 0 | H15: UNIV_OPER | I15: contraparte_i | J15: =+COUNTIFS('3. Resultados'!C:C,'1. Status'!H15,'3. Resultados'!G:G,'1. Status'!I15) -> 1 | K15: =+IFERROR(VLOOKUP(CONCATENATE(A15,$B$10,B15),'3. Resultados'!B:J,8,FALSE),"-") -> - | L15: =+IFERROR(VLOOKUP(B15,'3. Resultados'!K:L,2,FALSE),"-") -> - | M15: =+IFERROR(VLOOKUP(CONCATENATE(A15,$B$10,B15),'3. Resultados'!B:J,9,FALSE),"-") -> - | O15: =+IF(J15=0,"Por iniciar",IF(OR(K15="-",M15="-"),"Em testes",IF(M15=0,"OK","NOK"))) -> Em testes
A16: =+H16&I16&$I$8 -> UNIV_OPERproduto45991 | B16: {=+MAX(IF('3. Resultados'!A:A='1. Status'!A16&'1. Status'!$B$10,'3. Resultados'!K:K))} -> 0 | C16: {=+MAX(IF('3. Resultados'!A:A='1. Status'!A16&'1. Status'!$C$10,'3. Resultados'!K:K))} -> 0 | D16: {=+MAX(IF('3. Resultados'!A:A='1. Status'!A16&'1. Status'!$D$10,'3. Resultados'!K:K))} -> 0 | E16: {=+MAX(IF('3. Resultados'!A:A='1. Status'!A16&'1. Status'!$E$10,'3. Resultados'!K:K))} -> 0 | F16: {=+MAX(IF('3. Resultados'!A:A='1. Status'!A16&'1. Status'!$F$10,'3. Resultados'!K:K))} -> 0 | H16: UNIV_OPER | I16: produto | J16: =+COUNTIFS('3. Resultados'!C:C,'1. Status'!H16,'3. Resultados'!G:G,'1. Status'!I16) -> 1 | K16: =+IFERROR(VLOOKUP(CONCATENATE(A16,$B$10,B16),'3. Resultados'!B:J,8,FALSE),"-") -> - | L16: =+IFERROR(VLOOKUP(B16,'3. Resultados'!K:L,2,FALSE),"-") -> - | M16: =+IFERROR(VLOOKUP(CONCATENATE(A16,$B$10,B16),'3. Resultados'!B:J,9,FALSE),"-") -> - | O16: =+IF(J16=0,"Por iniciar",IF(OR(K16="-",M16="-"),"Em testes",IF(M16=0,"OK","NOK"))) -> Em testes
A17: =+H17&I17&$I$8 -> UNIV_OPERtipo_conta45991 | B17: {=+MAX(IF('3. Resultados'!A:A='1. Status'!A17&'1. Status'!$B$10,'3. Resultados'!K:K))} -> 0 | C17: {=+MAX(IF('3. Resultados'!A:A='1. Status'!A17&'1. Status'!$C$10,'3. Resultados'!K:K))} -> 0 | D17: {=+MAX(IF('3. Resultados'!A:A='1. Status'!A17&'1. Status'!$D$10,'3. Resultados'!K:K))} -> 0 | E17: {=+MAX(IF('3. Resultados'!A:A='1. Status'!A17&'1. Status'!$E$10,'3. Resultados'!K:K))} -> 0 | F17: {=+MAX(IF('3. Resultados'!A:A='1. Status'!A17&'1. Status'!$F$10,'3. Resultados'!K:K))} -> 0 | H17: UNIV_OPER | I17: tipo_conta | J17: =+COUNTIFS('3. Resultados'!C:C,'1. Status'!H17,'3. Resultados'!G:G,'1. Status'!I17) -> 1 | K17: =+IFERROR(VLOOKUP(CONCATENATE(A17,$B$10,B17),'3. Resultados'!B:J,8,FALSE),"-") -> - | L17: =+IFERROR(VLOOKUP(B17,'3. Resultados'!K:L,2,FALSE),"-") -> - | M17: =+IFERROR(VLOOKUP(CONCATENATE(A17,$B$10,B17),'3. Resultados'!B:J,9,FALSE),"-") -> - | O17: =+IF(J17=0,"Por iniciar",IF(OR(K17="-",M17="-"),"Em testes",IF(M17=0,"OK","NOK"))) -> Em testes
A18: =+H18&I18&$I$8 -> UNIV_OPERbruto_imparidade45991 | B18: {=+MAX(IF('3. Resultados'!A:A='1. Status'!A18&'1. Status'!$B$10,'3. Resultados'!K:K))} -> 0 | C18: {=+MAX(IF('3. Resultados'!A:A='1. Status'!A18&'1. Status'!$C$10,'3. Resultados'!K:K))} -> 0 | D18: {=+MAX(IF('3. Resultados'!A:A='1. Status'!A18&'1. Status'!$D$10,'3. Resultados'!K:K))} -> 0 | E18: {=+MAX(IF('3. Resultados'!A:A='1. Status'!A18&'1. Status'!$E$10,'3. Resultados'!K:K))} -> 0 | F18: {=+MAX(IF('3. Resultados'!A:A='1. Status'!A18&'1. Status'!$F$10,'3. Resultados'!K:K))} -> 0 | H18: UNIV_OPER | I18: bruto_imparidade | J18: =+COUNTIFS('3. Resultados'!C:C,'1. Status'!H18,'3. Resultados'!G:G,'1. Status'!I18) -> 1 | K18: =+IFERROR(VLOOKUP(CONCATENATE(A18,$B$10,B18),'3. Resultados'!B:J,8,FALSE),"-") -> - | L18: =+IFERROR(VLOOKUP(B18,'3. Resultados'!K:L,2,FALSE),"-") -> - | M18: =+IFERROR(VLOOKUP(CONCATENATE(A18,$B$10,B18),'3. Resultados'!B:J,9,FALSE),"-") -> - | O18: =+IF(J18=0,"Por iniciar",IF(OR(K18="-",M18="-"),"Em testes",IF(M18=0,"OK","NOK"))) -> Em testes
A19: =+H19&I19&$I$8 -> UNIV_OPERcomposicao_valor45991 | B19: {=+MAX(IF('3. Resultados'!A:A='1. Status'!A19&'1. Status'!$B$10,'3. Resultados'!K:K))} -> 0 | C19: {=+MAX(IF('3. Resultados'!A:A='1. Status'!A19&'1. Status'!$C$10,'3. Resultados'!K:K))} -> 0 | D19: {=+MAX(IF('3. Resultados'!A:A='1. Status'!A19&'1. Status'!$D$10,'3. Resultados'!K:K))} -> 0 | E19: {=+MAX(IF('3. Resultados'!A:A='1. Status'!A19&'1. Status'!$E$10,'3. Resultados'!K:K))} -> 0 | F19: {=+MAX(IF('3. Resultados'!A:A='1. Status'!A19&'1. Status'!$F$10,'3. Resultados'!K:K))} -> 0 | H19: UNIV_OPER | I19: composicao_valor | J19: =+COUNTIFS('3. Resultados'!C:C,'1. Status'!H19,'3. Resultados'!G:G,'1. Status'!I19) -> 1 | K19: =+IFERROR(VLOOKUP(CONCATENATE(A19,$B$10,B19),'3. Resultados'!B:J,8,FALSE),"-") -> - | L19: =+IFERROR(VLOOKUP(B19,'3. Resultados'!K:L,2,FALSE),"-") -> - | M19: =+IFERROR(VLOOKUP(CONCATENATE(A19,$B$10,B19),'3. Resultados'!B:J,9,FALSE),"-") -> - | O19: =+IF(J19=0,"Por iniciar",IF(OR(K19="-",M19="-"),"Em testes",IF(M19=0,"OK","NOK"))) -> Em testes
A20: =+H20&I20&$I$8 -> UNIV_OPERcolateral45991 | B20: {=+MAX(IF('3. Resultados'!A:A='1. Status'!A20&'1. Status'!$B$10,'3. Resultados'!K:K))} -> 0 | C20: {=+MAX(IF('3. Resultados'!A:A='1. Status'!A20&'1. Status'!$C$10,'3. Resultados'!K:K))} -> 0 | D20: {=+MAX(IF('3. Resultados'!A:A='1. Status'!A20&'1. Status'!$D$10,'3. Resultados'!K:K))} -> 0 | E20: {=+MAX(IF('3. Resultados'!A:A='1. Status'!A20&'1. Status'!$E$10,'3. Resultados'!K:K))} -> 0 | F20: {=+MAX(IF('3. Resultados'!A:A='1. Status'!A20&'1. Status'!$F$10,'3. Resultados'!K:K))} -> 0 | H20: UNIV_OPER | I20: colateral | J20: =+COUNTIFS('3. Resultados'!C:C,'1. Status'!H20,'3. Resultados'!G:G,'1. Status'!I20) -> 1 | K20: =+IFERROR(VLOOKUP(CONCATENATE(A20,$B$10,B20),'3. Resultados'!B:J,8,FALSE),"-") -> - | L20: =+IFERROR(VLOOKUP(B20,'3. Resultados'!K:L,2,FALSE),"-") -> - | M20: =+IFERROR(VLOOKUP(CONCATENATE(A20,$B$10,B20),'3. Resultados'!B:J,9,FALSE),"-") -> - | O20: =+IF(J20=0,"Por iniciar",IF(OR(K20="-",M20="-"),"Em testes",IF(M20=0,"OK","NOK"))) -> Em testes
A21: =+H21&I21&$I$8 -> UNIV_OPERflag_poci45991 | B21: {=+MAX(IF('3. Resultados'!A:A='1. Status'!A21&'1. Status'!$B$10,'3. Resultados'!K:K))} -> 0 | C21: {=+MAX(IF('3. Resultados'!A:A='1. Status'!A21&'1. Status'!$C$10,'3. Resultados'!K:K))} -> 0 | D21: {=+MAX(IF('3. Resultados'!A:A='1. Status'!A21&'1. Status'!$D$10,'3. Resultados'!K:K))} -> 0 | E21: {=+MAX(IF('3. Resultados'!A:A='1. Status'!A21&'1. Status'!$E$10,'3. Resultados'!K:K))} -> 0 | F21: {=+MAX(IF('3. Resultados'!A:A='1. Status'!A21&'1. Status'!$F$10,'3. Resultados'!K:K))} -> 0 | H21: UNIV_OPER | I21: flag_poci | J21: =+COUNTIFS('3. Resultados'!C:C,'1. Status'!H21,'3. Resultados'!G:G,'1. Status'!I21) -> 1 | K21: =+IFERROR(VLOOKUP(CONCATENATE(A21,$B$10,B21),'3. Resultados'!B:J,8,FALSE),"-") -> - | L21: =+IFERROR(VLOOKUP(B21,'3. Resultados'!K:L,2,FALSE),"-") -> - | M21: =+IFERROR(VLOOKUP(CONCATENATE(A21,$B$10,B21),'3. Resultados'!B:J,9,FALSE),"-") -> - | O21: =+IF(J21=0,"Por iniciar",IF(OR(K21="-",M21="-"),"Em testes",IF(M21=0,"OK","NOK"))) -> Em testes
A22: =+H22&I22&$I$8 -> UNIV_OPERpurpose_code45991 | B22: {=+MAX(IF('3. Resultados'!A:A='1. Status'!A22&'1. Status'!$B$10,'3. Resultados'!K:K))} -> 0 | C22: {=+MAX(IF('3. Resultados'!A:A='1. Status'!A22&'1. Status'!$C$10,'3. Resultados'!K:K))} -> 0 | D22: {=+MAX(IF('3. Resultados'!A:A='1. Status'!A22&'1. Status'!$D$10,'3. Resultados'!K:K))} -> 0 | E22: {=+MAX(IF('3. Resultados'!A:A='1. Status'!A22&'1. Status'!$E$10,'3. Resultados'!K:K))} -> 0 | F22: {=+MAX(IF('3. Resultados'!A:A='1. Status'!A22&'1. Status'!$F$10,'3. Resultados'!K:K))} -> 0 | H22: UNIV_OPER | I22: purpose_code | J22: =+COUNTIFS('3. Resultados'!C:C,'1. Status'!H22,'3. Resultados'!G:G,'1. Status'!I22) -> 1 | K22: =+IFERROR(VLOOKUP(CONCATENATE(A22,$B$10,B22),'3. Resultados'!B:J,8,FALSE),"-") -> - | L22: =+IFERROR(VLOOKUP(B22,'3. Resultados'!K:L,2,FALSE),"-") -> - | M22: =+IFERROR(VLOOKUP(CONCATENATE(A22,$B$10,B22),'3. Resultados'!B:J,9,FALSE),"-") -> - | O22: =+IF(J22=0,"Por iniciar",IF(OR(K22="-",M22="-"),"Em testes",IF(M22=0,"OK","NOK"))) -> Em testes
... A63: =+H63&I63&$I$8 -> Instrumentchnnl_orgntn45991 | B63: {=+MAX(IF('3. Resultados'!A:A='1. Status'!A63&'1. Status'!$B$10,'3. Resultados'!K:K))} -> 0 | C63: {=+MAX(IF('3. Resultados'!A:A='1. Status'!A63&'1. Status'!$C$10,'3. Resultados'!K:K))} -> 0 | D63: {=+MAX(IF('3. Resultados'!A:A='1. Status'!A63&'1. Status'!$D$10,'3. Resultados'!K:K))} -> 0 | E63: {=+MAX(IF('3. Resultados'!A:A='1. Status'!A63&'1. Status'!$E$10,'3. Resultados'!K:K))} -> 0 | F63: {=+MAX(IF('3. Resultados'!A:A='1. Status'!A63&'1. Status'!$F$10,'3. Resultados'!K:K))} -> 0 | H63: Instrument | I63: chnnl_orgntn | J63: =+COUNTIFS('3. Resultados'!C:C,'1. Status'!H63,'3. Resultados'!G:G,'1. Status'!I63) -> 0 | K63: =+IFERROR(VLOOKUP(CONCATENATE(A63,$B$10,B63),'3. Resultados'!B:J,8,FALSE),"-") -> - | L63: =+IFERROR(VLOOKUP(B63,'3. Resultados'!K:L,2,FALSE),"-") -> - | M63: =+IFERROR(VLOOKUP(CONCATENATE(A63,$B$10,B63),'3. Resultados'!B:J,9,FALSE),"-") -> - | O63: =+IF(J63=0,"Por iniciar",IF(OR(K63="-",M63="-"),"Em testes",IF(M63=0,"OK","NOK"))) -> Por iniciar
H64: Instrument | I64: csh_swp_trp | J64: =+COUNTIFS('3. Resultados'!C:C,'1. Status'!H64,'3. Resultados'!G:G,'1. Status'!I64) -> 0 | K64: =+IFERROR(VLOOKUP(CONCATENATE(A64,$B$10,B64),'3. Resultados'!B:J,8,FALSE),"-") -> - | L64: =+IFERROR(VLOOKUP(B64,'3. Resultados'!K:L,2,FALSE),"-") -> - | M64: =+IFERROR(VLOOKUP(CONCATENATE(A64,$B$10,B64),'3. Resultados'!B:J,9,FALSE),"-") -> - | O64: =+IF(J64=0,"Por iniciar",IF(OR(K64="-",M64="-"),"Em testes",IF(M64=0,"OK","NOK"))) -> Por iniciar
H65: Instrument | I65: cvnnt_stts | J65: =+COUNTIFS('3. Resultados'!C:C,'1. Status'!H65,'3. Resultados'!G:G,'1. Status'!I65) -> 0 | K65: =+IFERROR(VLOOKUP(CONCATENATE(A65,$B$10,B65),'3. Resultados'!B:J,8,FALSE),"-") -> - | L65: =+IFERROR(VLOOKUP(B65,'3. Resultados'!K:L,2,FALSE),"-") -> - | M65: =+IFERROR(VLOOKUP(CONCATENATE(A65,$B$10,B65),'3. Resultados'!B:J,9,FALSE),"-") -> - | O65: =+IF(J65=0,"Por iniciar",IF(OR(K65="-",M65="-"),"Em testes",IF(M65=0,"OK","NOK"))) -> Por iniciar
H66: Instrument | I66: cvnnt_typ | J66: =+COUNTIFS('3. Resultados'!C:C,'1. Status'!H66,'3. Resultados'!G:G,'1. Status'!I66) -> 0 | K66: =+IFERROR(VLOOKUP(CONCATENATE(A66,$B$10,B66),'3. Resultados'!B:J,8,FALSE),"-") -> - | L66: =+IFERROR(VLOOKUP(B66,'3. Resultados'!K:L,2,FALSE),"-") -> - | M66: =+IFERROR(VLOOKUP(CONCATENATE(A66,$B$10,B66),'3. Resultados'!B:J,9,FALSE),"-") -> - | O66: =+IF(J66=0,"Por iniciar",IF(OR(K66="-",M66="-"),"Em testes",IF(M66=0,"OK","NOK"))) -> Por iniciar
H67: Instrument | I67: dflt_stts_instrmnt | J67: =+COUNTIFS('3. Resultados'!C:C,'1. Status'!H67,'3. Resultados'!G:G,'1. Status'!I67) -> 0 | K67: =+IFERROR(VLOOKUP(CONCATENATE(A67,$B$10,B67),'3. Resultados'!B:J,8,FALSE),"-") -> - | L67: =+IFERROR(VLOOKUP(B67,'3. Resultados'!K:L,2,FALSE),"-") -> - | M67: =+IFERROR(VLOOKUP(CONCATENATE(A67,$B$10,B67),'3. Resultados'!B:J,9,FALSE),"-") -> - | O67: =+IF(J67=0,"Por iniciar",IF(OR(K67="-",M67="-"),"Em testes",IF(M67=0,"OK","NOK"))) -> Por iniciar
H68: Instrument | I68: dt_dflt_stts_instrmnt | J68: =+COUNTIFS('3. Resultados'!C:C,'1. Status'!H68,'3. Resultados'!G:G,'1. Status'!I68) -> 0 | K68: =+IFERROR(VLOOKUP(CONCATENATE(A68,$B$10,B68),'3. Resultados'!B:J,8,FALSE),"-") -> - | L68: =+IFERROR(VLOOKUP(B68,'3. Resultados'!K:L,2,FALSE),"-") -> - | M68: =+IFERROR(VLOOKUP(CONCATENATE(A68,$B$10,B68),'3. Resultados'!B:J,9,FALSE),"-") -> - | O68: =+IF(J68=0,"Por iniciar",IF(OR(K68="-",M68="-"),"Em testes",IF(M68=0,"OK","NOK"))) -> Por iniciar
H69: Instrument | I69: dt_end_gp_ppal | J69: =+COUNTIFS('3. Resultados'!C:C,'1. Status'!H69,'3. Resultados'!G:G,'1. Status'!I69) -> 0 | K69: =+IFERROR(VLOOKUP(CONCATENATE(A69,$B$10,B69),'3. Resultados'!B:J,8,FALSE),"-") -> - | L69: =+IFERROR(VLOOKUP(B69,'3. Resultados'!K:L,2,FALSE),"-") -> - | M69: =+IFERROR(VLOOKUP(CONCATENATE(A69,$B$10,B69),'3. Resultados'!B:J,9,FALSE),"-") -> - | O69: =+IF(J69=0,"Por iniciar",IF(OR(K69="-",M69="-"),"Em testes",IF(M69=0,"OK","NOK"))) -> Por iniciar
H70: Instrument | I70: dt_end_intrst_only | J70: =+COUNTIFS('3. Resultados'!C:C,'1. Status'!H70,'3. Resultados'!G:G,'1. Status'!I70) -> 0 | K70: =+IFERROR(VLOOKUP(CONCATENATE(A70,$B$10,B70),'3. Resultados'!B:J,8,FALSE),"-") -> - | L70: =+IFERROR(VLOOKUP(B70,'3. Resultados'!K:L,2,FALSE),"-") -> - | M70: =+IFERROR(VLOOKUP(CONCATENATE(A70,$B$10,B70),'3. Resultados'!B:J,9,FALSE),"-") -> - | O70: =+IF(J70=0,"Por iniciar",IF(OR(K70="-",M70="-"),"Em testes",IF(M70=0,"OK","NOK"))) -> Por iniciar
H71: Instrument | I71: dt_frbrnc_stts | J71: =+COUNTIFS('3. Resultados'!C:C,'1. Status'!H71,'3. Resultados'!G:G,'1. Status'!I71) -> 0 | K71: =+IFERROR(VLOOKUP(CONCATENATE(A71,$B$10,B71),'3. Resultados'!B:J,8,FALSE),"-") -> - | L71: =+IFERROR(VLOOKUP(B71,'3. Resultados'!K:L,2,FALSE),"-") -> - | M71: =+IFERROR(VLOOKUP(CONCATENATE(A71,$B$10,B71),'3. Resultados'!B:J,9,FALSE),"-") -> - | O71: =+IF(J71=0,"Por iniciar",IF(OR(K71="-",M71="-"),"Em testes",IF(M71=0,"OK","NOK"))) -> Por iniciar
H72: Instrument | I72: dt_frbrnc_stts_prvs | J72: =+COUNTIFS('3. Resultados'!C:C,'1. Status'!H72,'3. Resultados'!G:G,'1. Status'!I72) -> 0 | K72: =+IFERROR(VLOOKUP(CONCATENATE(A72,$B$10,B72),'3. Resultados'!B:J,8,FALSE),"-") -> - | L72: =+IFERROR(VLOOKUP(B72,'3. Resultados'!K:L,2,FALSE),"-") -> - | M72: =+IFERROR(VLOOKUP(CONCATENATE(A72,$B$10,B72),'3. Resultados'!B:J,9,FALSE),"-") -> - | O72: =+IF(J72=0,"Por iniciar",IF(OR(K72="-",M72="-"),"Em testes",IF(M72=0,"OK","NOK"))) -> Por iniciar
H73: Instrument | I73: dt_intrnl_rtng | J73: =+COUNTIFS('3. Resultados'!C:C,'1. Status'!H73,'3. Resultados'!G:G,'1. Status'!I73) -> 0 | K73: =+IFERROR(VLOOKUP(CONCATENATE(A73,$B$10,B73),'3. Resultados'!B:J,8,FALSE),"-") -> - | L73: =+IFERROR(VLOOKUP(B73,'3. Resultados'!K:L,2,FALSE),"-") -> - | M73: =+IFERROR(VLOOKUP(CONCATENATE(A73,$B$10,B73),'3. Resultados'!B:J,9,FALSE),"-") -> - | O73: =+IF(J73=0,"Por iniciar",IF(OR(K73="-",M73="-"),"Em testes",IF(M73=0,"OK","NOK"))) -> Por iniciar
H74: Instrument | I74: dt_prfrmng_stts | J74: =+COUNTIFS('3. Resultados'!C:C,'1. Status'!H74,'3. Resultados'!G:G,'1. Status'!I74) -> 0 | K74: =+IFERROR(VLOOKUP(CONCATENATE(A74,$B$10,B74),'3. Resultados'!B:J,8,FALSE),"-") -> - | L74: =+IFERROR(VLOOKUP(B74,'3. Resultados'!K:L,2,FALSE),"-") -> - | M74: =+IFERROR(VLOOKUP(CONCATENATE(A74,$B$10,B74),'3. Resultados'!B:J,9,FALSE),"-") -> - | O74: =+IF(J74=0,"Por iniciar",IF(OR(K74="-",M74="-"),"Em testes",IF(M74=0,"OK","NOK"))) -> Por iniciar
H75: Instrument | I75: dt_prfrmng_stts_prvs | J75: =+COUNTIFS('3. Resultados'!C:C,'1. Status'!H75,'3. Resultados'!G:G,'1. Status'!I75) -> 0 | K75: =+IFERROR(VLOOKUP(CONCATENATE(A75,$B$10,B75),'3. Resultados'!B:J,8,FALSE),"-") -> - | L75: =+IFERROR(VLOOKUP(B75,'3. Resultados'!K:L,2,FALSE),"-") -> - | M75: =+IFERROR(VLOOKUP(CONCATENATE(A75,$B$10,B75),'3. Resultados'!B:J,9,FALSE),"-") -> - | O75: =+IF(J75=0,"Por iniciar",IF(OR(K75="-",M75="-"),"Em testes",IF(M75=0,"OK","NOK"))) -> Por iniciar
... H667: INSTR_PROT | I667: cod_soc | J667: =+COUNTIFS('3. Resultados'!C:C,'1. Status'!H667,'3. Resultados'!G:G,'1. Status'!I667) -> 0 | K667: =+IFERROR(VLOOKUP(CONCATENATE(A667,$B$10,B667),'3. Resultados'!B:J,8,FALSE),"-") -> - | L667: =+IFERROR(VLOOKUP(B667,'3. Resultados'!K:L,2,FALSE),"-") -> - | M667: =+IFERROR(VLOOKUP(CONCATENATE(A667,$B$10,B667),'3. Resultados'!B:J,9,FALSE),"-") -> - | O667: =+IF(J667=0,"Por iniciar",IF(OR(K667="-",M667="-"),"Em testes",IF(M667=0,"OK","NOK"))) -> Por iniciar

Sheet 2. Script 
B6: 2. Script de Controlos
B8: TABELA | C8: CAMPO | D8: TIPOLOGIA_TESTE | E8: TABELA_LT | F8: TABELA_SIMUL | H8: FORMATO CAMPO | I8: VALORES CODE LIST | J8: UNIVERSO_PM | K8: UNIVERSO_SIMUL | L8: CRUZAMENTO | M8: QUERY 1 | N8: UNION ALL
A9: =+B9&C9 -> UNIV_OPERmsaldo_final | B9: UNIV_OPER | C9: msaldo_final | D9: Coerência | E9: =+UPPER('0. Instruções'!$D$35&"."&VLOOKUP(B9,'0. Instruções'!$C$27:$D$32,2,FALSE)) -> CD_LOAN_TAPES_BCE.LT001_UNIV_OPER | F9: =+UPPER('0. Instruções'!$D$36&"."&VLOOKUP(B9,'0. Instruções'!$C$27:$E$32,3,FALSE)) -> BU_LOANTAPE_WORK.LT001_UNIV_OPER | J9: =IF(VLOOKUP(B9,'0. Instruções'!$C$27:$G$32,5,FALSE)=0, "(SELECT "&VLOOKUP(B9,'0. Instruções'!$C$27:$G$32,4,FALSE)&" AS CHAVE_IT, "&C9&" AS CAMPO_IT FROM "&E9&" WHERE "&'0. Instruções'!$D$43&")X", "(SELECT "&VLOOKUP(B9,'0. Instruções'!$C$27:$G$32,4,FALSE)&" AS CHAVE_IT1, "&VLOOKUP(B9,'0. Instruções'!$C$27:$G$32,5,FALSE)&" AS CHAVE_IT2, "&C9&" AS CAMPO_IT FROM "&E9&" WHERE "&'0. Instruções'!$D$43&")X") -> (SELECT concat(cempresa, cbalcao, cnumecta, zdeposit, ccontab_final_ifrs, ccontab_final_pcsb, ccontab_final_cargabal, ccontab_final) AS CHAVE_IT1, zcliente AS CHAVE_IT2, msaldo_final AS CAMPO_IT FROM CD_LOAN_TAPES_BCE.LT001_UNIV_OPER WHERE ref_date='${ref_date}' AND nome_perimetro='Individual Local' AND segmento='ESTR' AND ambito='PM' AND entidade='00100')X | K9: =IF(VLOOKUP(B9,'0. Instruções'!$C$27:$G$32,5,FALSE)=0, "(SELECT "&VLOOKUP(B9,'0. Instruções'!$C$27:$G$32,4,FALSE)&" AS CHAVE_SIMUL, "&C9&" AS CAMPO_SIMUL FROM "&F9&" WHERE "&'0. Instruções'!$D$42&")Y", "(SELECT "&VLOOKUP(B9,'0. Instruções'!$C$27:$G$32,4,FALSE)&" AS CHAVE_SIMUL1, "&VLOOKUP(B9,'0. Instruções'!$C$27:$G$32,5,FALSE)&" AS CHAVE_SIMUL2, "&C9&" AS CAMPO_SIMUL FROM "&F9&" WHERE "&'0. Instruções'!$D$42&")Y") -> (SELECT concat(cempresa, cbalcao, cnumecta, zdeposit, ccontab_final_ifrs, ccontab_final_pcsb, ccontab_final_cargabal, ccontab_final) AS CHAVE_SIMUL1, zcliente AS CHAVE_SIMUL2, msaldo_final AS CAMPO_SIMUL FROM BU_LOANTAPE_WORK.LT001_UNIV_OPER WHERE ref_date='${ref_date}' AND nome_perimetro='Individual Local' AND segmento='ESTR' AND ambito='PM' AND entidade='00100')Y | L9: =IF(VLOOKUP(B9,'0. Instruções'!$C$27:$G$32,5,FALSE)=0, "ON X.CHAVE_IT=Y.CHAVE_SIMUL", "ON X.CHAVE_IT1=Y.CHAVE_SIMUL1 AND X.CHAVE_IT2=Y.CHAVE_SIMUL2") -> ON X.CHAVE_IT1=Y.CHAVE_SIMUL1 AND X.CHAVE_IT2=Y.CHAVE_SIMUL2 | M9: =+IF(D9="Coerência",+IF(LEFT(H9,5)="FLOAT","SELECT '"&UPPER(B9)&"' AS TABELA, '"&UPPER(D9)&"' AS TIPOLOGIA_TESTE,'"&E9&"' AS TABELA_LT,'"&F9&"' AS TABELA_SIMUL,'"&C9&"' AS CAMPO, "&_xlfn._LONGTEXT("'${ref_date}' AS REF_DATE, COUNT(*) AS NUM_REG, SUM(IF((ABS(COALESCE(CAST(X.CAMPO_IT AS DECIMAL(18,6)),0)-COALESCE(CAST(Y.CAMPO_SIMUL AS DECIMAL(18,6)),0))>0.000001) OR (X.CAMPO_IT IS NULL AND Y.CAMPO_SIMUL IS NOT NULL ) OR (X.CAMPO_IT IS NOT NULL AND Y.C","AMPO_SIMUL IS NULL),1,0)) AS NUM_REG_DIF,'")&MAX('3. Resultados'!K:K)+1&"' AS ID_EXEC, CURRENT_TIMESTAMP() AS TIME_EXEC FROM "&J9&" INNER JOIN "&K9&" "&L9,"SELECT '"&UPPER(B9)&"' AS TABELA, '"&UPPER(D9)&"' AS TIPOLOGIA_TESTE,'"&E9&"' AS TABELA_LT,'"&F9&"' AS TABELA_SIMUL,'"&C9&"' AS CAMPO, "&_xlfn._LONGTEXT("'${ref_date}' AS REF_DATE, COUNT(*) AS NUM_REG, SUM(IF(COALESCE(CAST(X.CAMPO_IT AS STRING),'')<>COALESCE(CAST(Y.CAMPO_SIMUL AS STRING),'') OR (X.CAMPO_IT IS NULL AND Y.CAMPO_SIMUL IS NOT NULL ) OR (X.CAMPO_IT IS NOT NULL AND Y.CAMPO_SIMUL IS NULL),1,0)) A","S NUM_REG_DIF,'")&MAX('3. Resultados'!L:L)+1&"' AS ID_EXEC, CURRENT_TIMESTAMP() AS TIME_EXEC FROM "&J9&" INNER JOIN "&K9&" "&L9)) -> SELECT 'UNIV_OPER' AS TABELA, 'COERÊNCIA' AS TIPOLOGIA_TESTE,'CD_LOAN_TAPES_BCE.LT001_UNIV_OPER' AS TABELA_LT,'BU_LOANTAPE_WORK.LT001_UNIV_OPER' AS TABELA_SIMUL,'msaldo_final' AS CAMPO, '${ref_date}' AS REF_DATE, COUNT(*) AS NUM_REG, SUM(IF(COALESCE(CAST(X.CAMPO_IT AS STRING),'')<>COALESCE(CAST(Y.CAMPO_SIMUL AS STRING),'') OR (X.CAMPO_IT IS NULL AND Y.CAMPO_SIMUL IS NOT NULL ) OR (X.CAMPO_IT IS NOT NULL AND Y.CAMPO_SIMUL IS NULL),1,0)) AS NUM_REG_DIF,'1' AS ID_EXEC, CURRENT_TIMESTAMP() AS TIME_EXEC FROM (SELECT concat(cempresa, cbalcao, cnumecta, zdeposit, ccontab_final_ifrs, ccontab_final_pcsb, ccontab_final_cargabal, ccontab_final) AS CHAVE_IT1, zcliente AS CHAVE_IT2, msaldo_final AS CAMPO_IT FROM CD_LOAN_TAPES_BCE.LT001_UNIV_OPER WHERE ref_date='${ref_date}' AND nome_perimetro='Individual Local' AND segmento='ESTR' AND ambito='PM' AND entidade='00100')X INNER JOIN (SELECT concat(cempresa, cbalcao, cnumecta, zdeposit, ccontab_final_ifrs, ccontab_final_pcsb, ccontab_final_cargabal, ccontab_final) AS CHAVE_SIMUL1, zcliente AS CHAVE_SIMUL2, msaldo_final AS CAMPO_SIMUL FROM BU_LOANTAPE_WORK.LT001_UNIV_OPER WHERE ref_date='${ref_date}' AND nome_perimetro='Individual Local' AND segmento='ESTR' AND ambito='PM' AND entidade='00100')Y ON X.CHAVE_IT1=Y.CHAVE_SIMUL1 AND X.CHAVE_IT2=Y.CHAVE_SIMUL2 | N9: =+"UNION ALL "&M9 -> UNION ALL SELECT 'UNIV_OPER' AS TABELA, 'COERÊNCIA' AS TIPOLOGIA_TESTE,'CD_LOAN_TAPES_BCE.LT001_UNIV_OPER' AS TABELA_LT,'BU_LOANTAPE_WORK.LT001_UNIV_OPER' AS TABELA_SIMUL,'msaldo_final' AS CAMPO, '${ref_date}' AS REF_DATE, COUNT(*) AS NUM_REG, SUM(IF(COALESCE(CAST(X.CAMPO_IT AS STRING),'')<>COALESCE(CAST(Y.CAMPO_SIMUL AS STRING),'') OR (X.CAMPO_IT IS NULL AND Y.CAMPO_SIMUL IS NOT NULL ) OR (X.CAMPO_IT IS NOT NULL AND Y.CAMPO_SIMUL IS NULL),1,0)) AS NUM_REG_DIF,'1' AS ID_EXEC, CURRENT_TIMESTAMP() AS TIME_EXEC FROM (SELECT concat(cempresa, cbalcao, cnumecta, zdeposit, ccontab_final_ifrs, ccontab_final_pcsb, ccontab_final_cargabal, ccontab_final) AS CHAVE_IT1, zcliente AS CHAVE_IT2, msaldo_final AS CAMPO_IT FROM CD_LOAN_TAPES_BCE.LT001_UNIV_OPER WHERE ref_date='${ref_date}' AND nome_perimetro='Individual Local' AND segmento='ESTR' AND ambito='PM' AND entidade='00100')X INNER JOIN (SELECT concat(cempresa, cbalcao, cnumecta, zdeposit, ccontab_final_ifrs, ccontab_final_pcsb, ccontab_final_cargabal, ccontab_final) AS CHAVE_SIMUL1, zcliente AS CHAVE_SIMUL2, msaldo_final AS CAMPO_SIMUL FROM BU_LOANTAPE_WORK.LT001_UNIV_OPER WHERE ref_date='${ref_date}' AND nome_perimetro='Individual Local' AND segmento='ESTR' AND ambito='PM' AND entidade='00100')Y ON X.CHAVE_IT1=Y.CHAVE_SIMUL1 AND X.CHAVE_IT2=Y.CHAVE_SIMUL2
A10: =+B10&C10 -> UNIV_OPERcarteira_contabilistica | B10: UNIV_OPER | C10: carteira_contabilistica | D10: Coerência | E10: =+UPPER('0. Instruções'!$D$35&"."&VLOOKUP(B10,'0. Instruções'!$C$27:$D$32,2,FALSE)) -> CD_LOAN_TAPES_BCE.LT001_UNIV_OPER | F10: =+UPPER('0. Instruções'!$D$36&"."&VLOOKUP(B10,'0. Instruções'!$C$27:$E$32,3,FALSE)) -> BU_LOANTAPE_WORK.LT001_UNIV_OPER | J10: =IF(VLOOKUP(B10,'0. Instruções'!$C$27:$G$32,5,FALSE)=0, "(SELECT "&VLOOKUP(B10,'0. Instruções'!$C$27:$G$32,4,FALSE)&" AS CHAVE_IT, "&C10&" AS CAMPO_IT FROM "&E10&" WHERE "&'0. Instruções'!$D$43&")X", "(SELECT "&VLOOKUP(B10,'0. Instruções'!$C$27:$G$32,4,FALSE)&" AS CHAVE_IT1, "&VLOOKUP(B10,'0. Instruções'!$C$27:$G$32,5,FALSE)&" AS CHAVE_IT2, "&C10&" AS CAMPO_IT FROM "&E10&" WHERE "&'0. Instruções'!$D$43&")X") -> (SELECT concat(cempresa, cbalcao, cnumecta, zdeposit, ccontab_final_ifrs, ccontab_final_pcsb, ccontab_final_cargabal, ccontab_final) AS CHAVE_IT1, zcliente AS CHAVE_IT2, carteira_contabilistica AS CAMPO_IT FROM CD_LOAN_TAPES_BCE.LT001_UNIV_OPER WHERE ref_date='${ref_date}' AND nome_perimetro='Individual Local' AND segmento='ESTR' AND ambito='PM' AND entidade='00100')X | K10: =IF(VLOOKUP(B10,'0. Instruções'!$C$27:$G$32,5,FALSE)=0, "(SELECT "&VLOOKUP(B10,'0. Instruções'!$C$27:$G$32,4,FALSE)&" AS CHAVE_SIMUL, "&C10&" AS CAMPO_SIMUL FROM "&F10&" WHERE "&'0. Instruções'!$D$42&")Y", "(SELECT "&VLOOKUP(B10,'0. Instruções'!$C$27:$G$32,4,FALSE)&" AS CHAVE_SIMUL1, "&VLOOKUP(B10,'0. Instruções'!$C$27:$G$32,5,FALSE)&" AS CHAVE_SIMUL2, "&C10&" AS CAMPO_SIMUL FROM "&F10&" WHERE "&'0. Instruções'!$D$42&")Y") -> (SELECT concat(cempresa, cbalcao, cnumecta, zdeposit, ccontab_final_ifrs, ccontab_final_pcsb, ccontab_final_cargabal, ccontab_final) AS CHAVE_SIMUL1, zcliente AS CHAVE_SIMUL2, carteira_contabilistica AS CAMPO_SIMUL FROM BU_LOANTAPE_WORK.LT001_UNIV_OPER WHERE ref_date='${ref_date}' AND nome_perimetro='Individual Local' AND segmento='ESTR' AND ambito='PM' AND entidade='00100')Y | L10: =IF(VLOOKUP(B10,'0. Instruções'!$C$27:$G$32,5,FALSE)=0, "ON X.CHAVE_IT=Y.CHAVE_SIMUL", "ON X.CHAVE_IT1=Y.CHAVE_SIMUL1 AND X.CHAVE_IT2=Y.CHAVE_SIMUL2") -> ON X.CHAVE_IT1=Y.CHAVE_SIMUL1 AND X.CHAVE_IT2=Y.CHAVE_SIMUL2 | M10: =+IF(D10="Coerência",+IF(LEFT(H10,5)="FLOAT","SELECT '"&UPPER(B10)&"' AS TABELA, '"&UPPER(D10)&"' AS TIPOLOGIA_TESTE,'"&E10&"' AS TABELA_LT,'"&F10&"' AS TABELA_SIMUL,'"&C10&"' AS CAMPO, "&_xlfn._LONGTEXT("'${ref_date}' AS REF_DATE, COUNT(*) AS NUM_REG, SUM(IF((ABS(COALESCE(CAST(X.CAMPO_IT AS DECIMAL(18,6)),0)-COALESCE(CAST(Y.CAMPO_SIMUL AS DECIMAL(18,6)),0))>0.000001) OR (X.CAMPO_IT IS NULL AND Y.CAMPO_SIMUL IS NOT NULL ) OR (X.CAMPO_IT IS NOT NULL AND Y.C","AMPO_SIMUL IS NULL),1,0)) AS NUM_REG_DIF,'")&MAX('3. Resultados'!K:K)+1&"' AS ID_EXEC, CURRENT_TIMESTAMP() AS TIME_EXEC FROM "&J10&" INNER JOIN "&K10&" "&L10,"SELECT '"&UPPER(B10)&"' AS TABELA, '"&UPPER(D10)&"' AS TIPOLOGIA_TESTE,'"&E10&"' AS TABELA_LT,'"&F10&"' AS TABELA_SIMUL,'"&C10&"' AS CAMPO, "&_xlfn._LONGTEXT("'${ref_date}' AS REF_DATE, COUNT(*) AS NUM_REG, SUM(IF(COALESCE(CAST(X.CAMPO_IT AS STRING),'')<>COALESCE(CAST(Y.CAMPO_SIMUL AS STRING),'') OR (X.CAMPO_IT IS NULL AND Y.CAMPO_SIMUL IS NOT NULL ) OR (X.CAMPO_IT IS NOT NULL AND Y.CAMPO_SIMUL IS NULL),1,0)) A","S NUM_REG_DIF,'")&MAX('3. Resultados'!L:L)+1&"' AS ID_EXEC, CURRENT_TIMESTAMP() AS TIME_EXEC FROM "&J10&" INNER JOIN "&K10&" "&L10)) -> SELECT 'UNIV_OPER' AS TABELA, 'COERÊNCIA' AS TIPOLOGIA_TESTE,'CD_LOAN_TAPES_BCE.LT001_UNIV_OPER' AS TABELA_LT,'BU_LOANTAPE_WORK.LT001_UNIV_OPER' AS TABELA_SIMUL,'carteira_contabilistica' AS CAMPO, '${ref_date}' AS REF_DATE, COUNT(*) AS NUM_REG, SUM(IF(COALESCE(CAST(X.CAMPO_IT AS STRING),'')<>COALESCE(CAST(Y.CAMPO_SIMUL AS STRING),'') OR (X.CAMPO_IT IS NULL AND Y.CAMPO_SIMUL IS NOT NULL ) OR (X.CAMPO_IT IS NOT NULL AND Y.CAMPO_SIMUL IS NULL),1,0)) AS NUM_REG_DIF,'1' AS ID_EXEC, CURRENT_TIMESTAMP() AS TIME_EXEC FROM (SELECT concat(cempresa, cbalcao, cnumecta, zdeposit, ccontab_final_ifrs, ccontab_final_pcsb, ccontab_final_cargabal, ccontab_final) AS CHAVE_IT1, zcliente AS CHAVE_IT2, carteira_contabilistica AS CAMPO_IT FROM CD_LOAN_TAPES_BCE.LT001_UNIV_OPER WHERE ref_date='${ref_date}' AND nome_perimetro='Individual Local' AND segmento='ESTR' AND ambito='PM' AND entidade='00100')X INNER JOIN (SELECT concat(cempresa, cbalcao, cnumecta, zdeposit, ccontab_final_ifrs, ccontab_final_pcsb, ccontab_final_cargabal, ccontab_final) AS CHAVE_SIMUL1, zcliente AS CHAVE_SIMUL2, carteira_contabilistica AS CAMPO_SIMUL FROM BU_LOANTAPE_WORK.LT001_UNIV_OPER WHERE ref_date='${ref_date}' AND nome_perimetro='Individual Local' AND segmento='ESTR' AND ambito='PM' AND entidade='00100')Y ON X.CHAVE_IT1=Y.CHAVE_SIMUL1 AND X.CHAVE_IT2=Y.CHAVE_SIMUL2 | N10: =+"UNION ALL "&M10 -> UNION ALL SELECT 'UNIV_OPER' AS TABELA, 'COERÊNCIA' AS TIPOLOGIA_TESTE,'CD_LOAN_TAPES_BCE.LT001_UNIV_OPER' AS TABELA_LT,'BU_LOANTAPE_WORK.LT001_UNIV_OPER' AS TABELA_SIMUL,'carteira_contabilistica' AS CAMPO, '${ref_date}' AS REF_DATE, COUNT(*) AS NUM_REG, SUM(IF(COALESCE(CAST(X.CAMPO_IT AS STRING),'')<>COALESCE(CAST(Y.CAMPO_SIMUL AS STRING),'') OR (X.CAMPO_IT IS NULL AND Y.CAMPO_SIMUL IS NOT NULL ) OR (X.CAMPO_IT IS NOT NULL AND Y.CAMPO_SIMUL IS NULL),1,0)) AS NUM_REG_DIF,'1' AS ID_EXEC, CURRENT_TIMESTAMP() AS TIME_EXEC FROM (SELECT concat(cempresa, cbalcao, cnumecta, zdeposit, ccontab_final_ifrs, ccontab_final_pcsb, ccontab_final_cargabal, ccontab_final) AS CHAVE_IT1, zcliente AS CHAVE_IT2, carteira_contabilistica AS CAMPO_IT FROM CD_LOAN_TAPES_BCE.LT001_UNIV_OPER WHERE ref_date='${ref_date}' AND nome_perimetro='Individual Local' AND segmento='ESTR' AND ambito='PM' AND entidade='00100')X INNER JOIN (SELECT concat(cempresa, cbalcao, cnumecta, zdeposit, ccontab_final_ifrs, ccontab_final_pcsb, ccontab_final_cargabal, ccontab_final) AS CHAVE_SIMUL1, zcliente AS CHAVE_SIMUL2, carteira_contabilistica AS CAMPO_SIMUL FROM BU_LOANTAPE_WORK.LT001_UNIV_OPER WHERE ref_date='${ref_date}' AND nome_perimetro='Individual Local' AND segmento='ESTR' AND ambito='PM' AND entidade='00100')Y ON X.CHAVE_IT1=Y.CHAVE_SIMUL1 AND X.CHAVE_IT2=Y.CHAVE_SIMUL2
A11: =+B11&C11 -> UNIV_OPERinstrumento_financeiro | B11: UNIV_OPER | C11: instrumento_financeiro | D11: Coerência | E11: =+UPPER('0. Instruções'!$D$35&"."&VLOOKUP(B11,'0. Instruções'!$C$27:$D$32,2,FALSE)) -> CD_LOAN_TAPES_BCE.LT001_UNIV_OPER | F11: =+UPPER('0. Instruções'!$D$36&"."&VLOOKUP(B11,'0. Instruções'!$C$27:$E$32,3,FALSE)) -> BU_LOANTAPE_WORK.LT001_UNIV_OPER | J11: =IF(VLOOKUP(B11,'0. Instruções'!$C$27:$G$32,5,FALSE)=0, "(SELECT "&VLOOKUP(B11,'0. Instruções'!$C$27:$G$32,4,FALSE)&" AS CHAVE_IT, "&C11&" AS CAMPO_IT FROM "&E11&" WHERE "&'0. Instruções'!$D$43&")X", "(SELECT "&VLOOKUP(B11,'0. Instruções'!$C$27:$G$32,4,FALSE)&" AS CHAVE_IT1, "&VLOOKUP(B11,'0. Instruções'!$C$27:$G$32,5,FALSE)&" AS CHAVE_IT2, "&C11&" AS CAMPO_IT FROM "&E11&" WHERE "&'0. Instruções'!$D$43&")X") -> (SELECT concat(cempresa, cbalcao, cnumecta, zdeposit, ccontab_final_ifrs, ccontab_final_pcsb, ccontab_final_cargabal, ccontab_final) AS CHAVE_IT1, zcliente AS CHAVE_IT2, instrumento_financeiro AS CAMPO_IT FROM CD_LOAN_TAPES_BCE.LT001_UNIV_OPER WHERE ref_date='${ref_date}' AND nome_perimetro='Individual Local' AND segmento='ESTR' AND ambito='PM' AND entidade='00100')X | K11: =IF(VLOOKUP(B11,'0. Instruções'!$C$27:$G$32,5,FALSE)=0, "(SELECT "&VLOOKUP(B11,'0. Instruções'!$C$27:$G$32,4,FALSE)&" AS CHAVE_SIMUL, "&C11&" AS CAMPO_SIMUL FROM "&F11&" WHERE "&'0. Instruções'!$D$42&")Y", "(SELECT "&VLOOKUP(B11,'0. Instruções'!$C$27:$G$32,4,FALSE)&" AS CHAVE_SIMUL1, "&VLOOKUP(B11,'0. Instruções'!$C$27:$G$32,5,FALSE)&" AS CHAVE_SIMUL2, "&C11&" AS CAMPO_SIMUL FROM "&F11&" WHERE "&'0. Instruções'!$D$42&")Y") -> (SELECT concat(cempresa, cbalcao, cnumecta, zdeposit, ccontab_final_ifrs, ccontab_final_pcsb, ccontab_final_cargabal, ccontab_final) AS CHAVE_SIMUL1, zcliente AS CHAVE_SIMUL2, instrumento_financeiro AS CAMPO_SIMUL FROM BU_LOANTAPE_WORK.LT001_UNIV_OPER WHERE ref_date='${ref_date}' AND nome_perimetro='Individual Local' AND segmento='ESTR' AND ambito='PM' AND entidade='00100')Y | L11: =IF(VLOOKUP(B11,'0. Instruções'!$C$27:$G$32,5,FALSE)=0, "ON X.CHAVE_IT=Y.CHAVE_SIMUL", "ON X.CHAVE_IT1=Y.CHAVE_SIMUL1 AND X.CHAVE_IT2=Y.CHAVE_SIMUL2") -> ON X.CHAVE_IT1=Y.CHAVE_SIMUL1 AND X.CHAVE_IT2=Y.CHAVE_SIMUL2 | M11: =+IF(D11="Coerência",+IF(LEFT(H11,5)="FLOAT","SELECT '"&UPPER(B11)&"' AS TABELA, '"&UPPER(D11)&"' AS TIPOLOGIA_TESTE,'"&E11&"' AS TABELA_LT,'"&F11&"' AS TABELA_SIMUL,'"&C11&"' AS CAMPO, "&_xlfn._LONGTEXT("'${ref_date}' AS REF_DATE, COUNT(*) AS NUM_REG, SUM(IF((ABS(COALESCE(CAST(X.CAMPO_IT AS DECIMAL(18,6)),0)-COALESCE(CAST(Y.CAMPO_SIMUL AS DECIMAL(18,6)),0))>0.000001) OR (X.CAMPO_IT IS NULL AND Y.CAMPO_SIMUL IS NOT NULL ) OR (X.CAMPO_IT IS NOT NULL AND Y.C","AMPO_SIMUL IS NULL),1,0)) AS NUM_REG_DIF,'")&MAX('3. Resultados'!K:K)+1&"' AS ID_EXEC, CURRENT_TIMESTAMP() AS TIME_EXEC FROM "&J11&" INNER JOIN "&K11&" "&L11,"SELECT '"&UPPER(B11)&"' AS TABELA, '"&UPPER(D11)&"' AS TIPOLOGIA_TESTE,'"&E11&"' AS TABELA_LT,'"&F11&"' AS TABELA_SIMUL,'"&C11&"' AS CAMPO, "&_xlfn._LONGTEXT("'${ref_date}' AS REF_DATE, COUNT(*) AS NUM_REG, SUM(IF(COALESCE(CAST(X.CAMPO_IT AS STRING),'')<>COALESCE(CAST(Y.CAMPO_SIMUL AS STRING),'') OR (X.CAMPO_IT IS NULL AND Y.CAMPO_SIMUL IS NOT NULL ) OR (X.CAMPO_IT IS NOT NULL AND Y.CAMPO_SIMUL IS NULL),1,0)) A","S NUM_REG_DIF,'")&MAX('3. Resultados'!L:L)+1&"' AS ID_EXEC, CURRENT_TIMESTAMP() AS TIME_EXEC FROM "&J11&" INNER JOIN "&K11&" "&L11)) -> SELECT 'UNIV_OPER' AS TABELA, 'COERÊNCIA' AS TIPOLOGIA_TESTE,'CD_LOAN_TAPES_BCE.LT001_UNIV_OPER' AS TABELA_LT,'BU_LOANTAPE_WORK.LT001_UNIV_OPER' AS TABELA_SIMUL,'instrumento_financeiro' AS CAMPO, '${ref_date}' AS REF_DATE, COUNT(*) AS NUM_REG, SUM(IF(COALESCE(CAST(X.CAMPO_IT AS STRING),'')<>COALESCE(CAST(Y.CAMPO_SIMUL AS STRING),'') OR (X.CAMPO_IT IS NULL AND Y.CAMPO_SIMUL IS NOT NULL ) OR (X.CAMPO_IT IS NOT NULL AND Y.CAMPO_SIMUL IS NULL),1,0)) AS NUM_REG_DIF,'1' AS ID_EXEC, CURRENT_TIMESTAMP() AS TIME_EXEC FROM (SELECT concat(cempresa, cbalcao, cnumecta, zdeposit, ccontab_final_ifrs, ccontab_final_pcsb, ccontab_final_cargabal, ccontab_final) AS CHAVE_IT1, zcliente AS CHAVE_IT2, instrumento_financeiro AS CAMPO_IT FROM CD_LOAN_TAPES_BCE.LT001_UNIV_OPER WHERE ref_date='${ref_date}' AND nome_perimetro='Individual Local' AND segmento='ESTR' AND ambito='PM' AND entidade='00100')X INNER JOIN (SELECT concat(cempresa, cbalcao, cnumecta, zdeposit, ccontab_final_ifrs, ccontab_final_pcsb, ccontab_final_cargabal, ccontab_final) AS CHAVE_SIMUL1, zcliente AS CHAVE_SIMUL2, instrumento_financeiro AS CAMPO_SIMUL FROM BU_LOANTAPE_WORK.LT001_UNIV_OPER WHERE ref_date='${ref_date}' AND nome_perimetro='Individual Local' AND segmento='ESTR' AND ambito='PM' AND entidade='00100')Y ON X.CHAVE_IT1=Y.CHAVE_SIMUL1 AND X.CHAVE_IT2=Y.CHAVE_SIMUL2 | N11: =+"UNION ALL "&M11 -> UNION ALL SELECT 'UNIV_OPER' AS TABELA, 'COERÊNCIA' AS TIPOLOGIA_TESTE,'CD_LOAN_TAPES_BCE.LT001_UNIV_OPER' AS TABELA_LT,'BU_LOANTAPE_WORK.LT001_UNIV_OPER' AS TABELA_SIMUL,'instrumento_financeiro' AS CAMPO, '${ref_date}' AS REF_DATE, COUNT(*) AS NUM_REG, SUM(IF(COALESCE(CAST(X.CAMPO_IT AS STRING),'')<>COALESCE(CAST(Y.CAMPO_SIMUL AS STRING),'') OR (X.CAMPO_IT IS NULL AND Y.CAMPO_SIMUL IS NOT NULL ) OR (X.CAMPO_IT IS NOT NULL AND Y.CAMPO_SIMUL IS NULL),1,0)) AS NUM_REG_DIF,'1' AS ID_EXEC, CURRENT_TIMESTAMP() AS TIME_EXEC FROM (SELECT concat(cempresa, cbalcao, cnumecta, zdeposit, ccontab_final_ifrs, ccontab_final_pcsb, ccontab_final_cargabal, ccontab_final) AS CHAVE_IT1, zcliente AS CHAVE_IT2, instrumento_financeiro AS CAMPO_IT FROM CD_LOAN_TAPES_BCE.LT001_UNIV_OPER WHERE ref_date='${ref_date}' AND nome_perimetro='Individual Local' AND segmento='ESTR' AND ambito='PM' AND entidade='00100')X INNER JOIN (SELECT concat(cempresa, cbalcao, cnumecta, zdeposit, ccontab_final_ifrs, ccontab_final_pcsb, ccontab_final_cargabal, ccontab_final) AS CHAVE_SIMUL1, zcliente AS CHAVE_SIMUL2, instrumento_financeiro AS CAMPO_SIMUL FROM BU_LOANTAPE_WORK.LT001_UNIV_OPER WHERE ref_date='${ref_date}' AND nome_perimetro='Individual Local' AND segmento='ESTR' AND ambito='PM' AND entidade='00100')Y ON X.CHAVE_IT1=Y.CHAVE_SIMUL1 AND X.CHAVE_IT2=Y.CHAVE_SIMUL2
A12: =+B12&C12 -> UNIV_OPERcontraparte | B12: UNIV_OPER | C12: contraparte | D12: Coerência | E12: =+UPPER('0. Instruções'!$D$35&"."&VLOOKUP(B12,'0. Instruções'!$C$27:$D$32,2,FALSE)) -> CD_LOAN_TAPES_BCE.LT001_UNIV_OPER | F12: =+UPPER('0. Instruções'!$D$36&"."&VLOOKUP(B12,'0. Instruções'!$C$27:$E$32,3,FALSE)) -> BU_LOANTAPE_WORK.LT001_UNIV_OPER | J12: =IF(VLOOKUP(B12,'0. Instruções'!$C$27:$G$32,5,FALSE)=0, "(SELECT "&VLOOKUP(B12,'0. Instruções'!$C$27:$G$32,4,FALSE)&" AS CHAVE_IT, "&C12&" AS CAMPO_IT FROM "&E12&" WHERE "&'0. Instruções'!$D$43&")X", "(SELECT "&VLOOKUP(B12,'0. Instruções'!$C$27:$G$32,4,FALSE)&" AS CHAVE_IT1, "&VLOOKUP(B12,'0. Instruções'!$C$27:$G$32,5,FALSE)&" AS CHAVE_IT2, "&C12&" AS CAMPO_IT FROM "&E12&" WHERE "&'0. Instruções'!$D$43&")X") -> (SELECT concat(cempresa, cbalcao, cnumecta, zdeposit, ccontab_final_ifrs, ccontab_final_pcsb, ccontab_final_cargabal, ccontab_final) AS CHAVE_IT1, zcliente AS CHAVE_IT2, contraparte AS CAMPO_IT FROM CD_LOAN_TAPES_BCE.LT001_UNIV_OPER WHERE ref_date='${ref_date}' AND nome_perimetro='Individual Local' AND segmento='ESTR' AND ambito='PM' AND entidade='00100')X | K12: =IF(VLOOKUP(B12,'0. Instruções'!$C$27:$G$32,5,FALSE)=0, "(SELECT "&VLOOKUP(B12,'0. Instruções'!$C$27:$G$32,4,FALSE)&" AS CHAVE_SIMUL, "&C12&" AS CAMPO_SIMUL FROM "&F12&" WHERE "&'0. Instruções'!$D$42&")Y", "(SELECT "&VLOOKUP(B12,'0. Instruções'!$C$27:$G$32,4,FALSE)&" AS CHAVE_SIMUL1, "&VLOOKUP(B12,'0. Instruções'!$C$27:$G$32,5,FALSE)&" AS CHAVE_SIMUL2, "&C12&" AS CAMPO_SIMUL FROM "&F12&" WHERE "&'0. Instruções'!$D$42&")Y") -> (SELECT concat(cempresa, cbalcao, cnumecta, zdeposit, ccontab_final_ifrs, ccontab_final_pcsb, ccontab_final_cargabal, ccontab_final) AS CHAVE_SIMUL1, zcliente AS CHAVE_SIMUL2, contraparte AS CAMPO_SIMUL FROM BU_LOANTAPE_WORK.LT001_UNIV_OPER WHERE ref_date='${ref_date}' AND nome_perimetro='Individual Local' AND segmento='ESTR' AND ambito='PM' AND entidade='00100')Y | L12: =IF(VLOOKUP(B12,'0. Instruções'!$C$27:$G$32,5,FALSE)=0, "ON X.CHAVE_IT=Y.CHAVE_SIMUL", "ON X.CHAVE_IT1=Y.CHAVE_SIMUL1 AND X.CHAVE_IT2=Y.CHAVE_SIMUL2") -> ON X.CHAVE_IT1=Y.CHAVE_SIMUL1 AND X.CHAVE_IT2=Y.CHAVE_SIMUL2 | M12: =+IF(D12="Coerência",+IF(LEFT(H12,5)="FLOAT","SELECT '"&UPPER(B12)&"' AS TABELA, '"&UPPER(D12)&"' AS TIPOLOGIA_TESTE,'"&E12&"' AS TABELA_LT,'"&F12&"' AS TABELA_SIMUL,'"&C12&"' AS CAMPO, "&_xlfn._LONGTEXT("'${ref_date}' AS REF_DATE, COUNT(*) AS NUM_REG, SUM(IF((ABS(COALESCE(CAST(X.CAMPO_IT AS DECIMAL(18,6)),0)-COALESCE(CAST(Y.CAMPO_SIMUL AS DECIMAL(18,6)),0))>0.000001) OR (X.CAMPO_IT IS NULL AND Y.CAMPO_SIMUL IS NOT NULL ) OR (X.CAMPO_IT IS NOT NULL AND Y.C","AMPO_SIMUL IS NULL),1,0)) AS NUM_REG_DIF,'")&MAX('3. Resultados'!K:K)+1&"' AS ID_EXEC, CURRENT_TIMESTAMP() AS TIME_EXEC FROM "&J12&" INNER JOIN "&K12&" "&L12,"SELECT '"&UPPER(B12)&"' AS TABELA, '"&UPPER(D12)&"' AS TIPOLOGIA_TESTE,'"&E12&"' AS TABELA_LT,'"&F12&"' AS TABELA_SIMUL,'"&C12&"' AS CAMPO, "&_xlfn._LONGTEXT("'${ref_date}' AS REF_DATE, COUNT(*) AS NUM_REG, SUM(IF(COALESCE(CAST(X.CAMPO_IT AS STRING),'')<>COALESCE(CAST(Y.CAMPO_SIMUL AS STRING),'') OR (X.CAMPO_IT IS NULL AND Y.CAMPO_SIMUL IS NOT NULL ) OR (X.CAMPO_IT IS NOT NULL AND Y.CAMPO_SIMUL IS NULL),1,0)) A","S NUM_REG_DIF,'")&MAX('3. Resultados'!L:L)+1&"' AS ID_EXEC, CURRENT_TIMESTAMP() AS TIME_EXEC FROM "&J12&" INNER JOIN "&K12&" "&L12)) -> SELECT 'UNIV_OPER' AS TABELA, 'COERÊNCIA' AS TIPOLOGIA_TESTE,'CD_LOAN_TAPES_BCE.LT001_UNIV_OPER' AS TABELA_LT,'BU_LOANTAPE_WORK.LT001_UNIV_OPER' AS TABELA_SIMUL,'contraparte' AS CAMPO, '${ref_date}' AS REF_DATE, COUNT(*) AS NUM_REG, SUM(IF(COALESCE(CAST(X.CAMPO_IT AS STRING),'')<>COALESCE(CAST(Y.CAMPO_SIMUL AS STRING),'') OR (X.CAMPO_IT IS NULL AND Y.CAMPO_SIMUL IS NOT NULL ) OR (X.CAMPO_IT IS NOT NULL AND Y.CAMPO_SIMUL IS NULL),1,0)) AS NUM_REG_DIF,'1' AS ID_EXEC, CURRENT_TIMESTAMP() AS TIME_EXEC FROM (SELECT concat(cempresa, cbalcao, cnumecta, zdeposit, ccontab_final_ifrs, ccontab_final_pcsb, ccontab_final_cargabal, ccontab_final) AS CHAVE_IT1, zcliente AS CHAVE_IT2, contraparte AS CAMPO_IT FROM CD_LOAN_TAPES_BCE.LT001_UNIV_OPER WHERE ref_date='${ref_date}' AND nome_perimetro='Individual Local' AND segmento='ESTR' AND ambito='PM' AND entidade='00100')X INNER JOIN (SELECT concat(cempresa, cbalcao, cnumecta, zdeposit, ccontab_final_ifrs, ccontab_final_pcsb, ccontab_final_cargabal, ccontab_final) AS CHAVE_SIMUL1, zcliente AS CHAVE_SIMUL2, contraparte AS CAMPO_SIMUL FROM BU_LOANTAPE_WORK.LT001_UNIV_OPER WHERE ref_date='${ref_date}' AND nome_perimetro='Individual Local' AND segmento='ESTR' AND ambito='PM' AND entidade='00100')Y ON X.CHAVE_IT1=Y.CHAVE_SIMUL1 AND X.CHAVE_IT2=Y.CHAVE_SIMUL2 | N12: =+"UNION ALL "&M12 -> UNION ALL SELECT 'UNIV_OPER' AS TABELA, 'COERÊNCIA' AS TIPOLOGIA_TESTE,'CD_LOAN_TAPES_BCE.LT001_UNIV_OPER' AS TABELA_LT,'BU_LOANTAPE_WORK.LT001_UNIV_OPER' AS TABELA_SIMUL,'contraparte' AS CAMPO, '${ref_date}' AS REF_DATE, COUNT(*) AS NUM_REG, SUM(IF(COALESCE(CAST(X.CAMPO_IT AS STRING),'')<>COALESCE(CAST(Y.CAMPO_SIMUL AS STRING),'') OR (X.CAMPO_IT IS NULL AND Y.CAMPO_SIMUL IS NOT NULL ) OR (X.CAMPO_IT IS NOT NULL AND Y.CAMPO_SIMUL IS NULL),1,0)) AS NUM_REG_DIF,'1' AS ID_EXEC, CURRENT_TIMESTAMP() AS TIME_EXEC FROM (SELECT concat(cempresa, cbalcao, cnumecta, zdeposit, ccontab_final_ifrs, ccontab_final_pcsb, ccontab_final_cargabal, ccontab_final) AS CHAVE_IT1, zcliente AS CHAVE_IT2, contraparte AS CAMPO_IT FROM CD_LOAN_TAPES_BCE.LT001_UNIV_OPER WHERE ref_date='${ref_date}' AND nome_perimetro='Individual Local' AND segmento='ESTR' AND ambito='PM' AND entidade='00100')X INNER JOIN (SELECT concat(cempresa, cbalcao, cnumecta, zdeposit, ccontab_final_ifrs, ccontab_final_pcsb, ccontab_final_cargabal, ccontab_final) AS CHAVE_SIMUL1, zcliente AS CHAVE_SIMUL2, contraparte AS CAMPO_SIMUL FROM BU_LOANTAPE_WORK.LT001_UNIV_OPER WHERE ref_date='${ref_date}' AND nome_perimetro='Individual Local' AND segmento='ESTR' AND ambito='PM' AND entidade='00100')Y ON X.CHAVE_IT1=Y.CHAVE_SIMUL1 AND X.CHAVE_IT2=Y.CHAVE_SIMUL2
A13: =+B13&C13 -> UNIV_OPERcontraparte_i | B13: UNIV_OPER | C13: contraparte_i | D13: Coerência | E13: =+UPPER('0. Instruções'!$D$35&"."&VLOOKUP(B13,'0. Instruções'!$C$27:$D$32,2,FALSE)) -> CD_LOAN_TAPES_BCE.LT001_UNIV_OPER | F13: =+UPPER('0. Instruções'!$D$36&"."&VLOOKUP(B13,'0. Instruções'!$C$27:$E$32,3,FALSE)) -> BU_LOANTAPE_WORK.LT001_UNIV_OPER | J13: =IF(VLOOKUP(B13,'0. Instruções'!$C$27:$G$32,5,FALSE)=0, "(SELECT "&VLOOKUP(B13,'0. Instruções'!$C$27:$G$32,4,FALSE)&" AS CHAVE_IT, "&C13&" AS CAMPO_IT FROM "&E13&" WHERE "&'0. Instruções'!$D$43&")X", "(SELECT "&VLOOKUP(B13,'0. Instruções'!$C$27:$G$32,4,FALSE)&" AS CHAVE_IT1, "&VLOOKUP(B13,'0. Instruções'!$C$27:$G$32,5,FALSE)&" AS CHAVE_IT2, "&C13&" AS CAMPO_IT FROM "&E13&" WHERE "&'0. Instruções'!$D$43&")X") -> (SELECT concat(cempresa, cbalcao, cnumecta, zdeposit, ccontab_final_ifrs, ccontab_final_pcsb, ccontab_final_cargabal, ccontab_final) AS CHAVE_IT1, zcliente AS CHAVE_IT2, contraparte_i AS CAMPO_IT FROM CD_LOAN_TAPES_BCE.LT001_UNIV_OPER WHERE ref_date='${ref_date}' AND nome_perimetro='Individual Local' AND segmento='ESTR' AND ambito='PM' AND entidade='00100')X | K13: =IF(VLOOKUP(B13,'0. Instruções'!$C$27:$G$32,5,FALSE)=0, "(SELECT "&VLOOKUP(B13,'0. Instruções'!$C$27:$G$32,4,FALSE)&" AS CHAVE_SIMUL, "&C13&" AS CAMPO_SIMUL FROM "&F13&" WHERE "&'0. Instruções'!$D$42&")Y", "(SELECT "&VLOOKUP(B13,'0. Instruções'!$C$27:$G$32,4,FALSE)&" AS CHAVE_SIMUL1, "&VLOOKUP(B13,'0. Instruções'!$C$27:$G$32,5,FALSE)&" AS CHAVE_SIMUL2, "&C13&" AS CAMPO_SIMUL FROM "&F13&" WHERE "&'0. Instruções'!$D$42&")Y") -> (SELECT concat(cempresa, cbalcao, cnumecta, zdeposit, ccontab_final_ifrs, ccontab_final_pcsb, ccontab_final_cargabal, ccontab_final) AS CHAVE_SIMUL1, zcliente AS CHAVE_SIMUL2, contraparte_i AS CAMPO_SIMUL FROM BU_LOANTAPE_WORK.LT001_UNIV_OPER WHERE ref_date='${ref_date}' AND nome_perimetro='Individual Local' AND segmento='ESTR' AND ambito='PM' AND entidade='00100')Y | L13: =IF(VLOOKUP(B13,'0. Instruções'!$C$27:$G$32,5,FALSE)=0, "ON X.CHAVE_IT=Y.CHAVE_SIMUL", "ON X.CHAVE_IT1=Y.CHAVE_SIMUL1 AND X.CHAVE_IT2=Y.CHAVE_SIMUL2") -> ON X.CHAVE_IT1=Y.CHAVE_SIMUL1 AND X.CHAVE_IT2=Y.CHAVE_SIMUL2 | M13: =+IF(D13="Coerência",+IF(LEFT(H13,5)="FLOAT","SELECT '"&UPPER(B13)&"' AS TABELA, '"&UPPER(D13)&"' AS TIPOLOGIA_TESTE,'"&E13&"' AS TABELA_LT,'"&F13&"' AS TABELA_SIMUL,'"&C13&"' AS CAMPO, "&_xlfn._LONGTEXT("'${ref_date}' AS REF_DATE, COUNT(*) AS NUM_REG, SUM(IF((ABS(COALESCE(CAST(X.CAMPO_IT AS DECIMAL(18,6)),0)-COALESCE(CAST(Y.CAMPO_SIMUL AS DECIMAL(18,6)),0))>0.000001) OR (X.CAMPO_IT IS NULL AND Y.CAMPO_SIMUL IS NOT NULL ) OR (X.CAMPO_IT IS NOT NULL AND Y.C","AMPO_SIMUL IS NULL),1,0)) AS NUM_REG_DIF,'")&MAX('3. Resultados'!K:K)+1&"' AS ID_EXEC, CURRENT_TIMESTAMP() AS TIME_EXEC FROM "&J13&" INNER JOIN "&K13&" "&L13,"SELECT '"&UPPER(B13)&"' AS TABELA, '"&UPPER(D13)&"' AS TIPOLOGIA_TESTE,'"&E13&"' AS TABELA_LT,'"&F13&"' AS TABELA_SIMUL,'"&C13&"' AS CAMPO, "&_xlfn._LONGTEXT("'${ref_date}' AS REF_DATE, COUNT(*) AS NUM_REG, SUM(IF(COALESCE(CAST(X.CAMPO_IT AS STRING),'')<>COALESCE(CAST(Y.CAMPO_SIMUL AS STRING),'') OR (X.CAMPO_IT IS NULL AND Y.CAMPO_SIMUL IS NOT NULL ) OR (X.CAMPO_IT IS NOT NULL AND Y.CAMPO_SIMUL IS NULL),1,0)) A","S NUM_REG_DIF,'")&MAX('3. Resultados'!L:L)+1&"' AS ID_EXEC, CURRENT_TIMESTAMP() AS TIME_EXEC FROM "&J13&" INNER JOIN "&K13&" "&L13)) -> SELECT 'UNIV_OPER' AS TABELA, 'COERÊNCIA' AS TIPOLOGIA_TESTE,'CD_LOAN_TAPES_BCE.LT001_UNIV_OPER' AS TABELA_LT,'BU_LOANTAPE_WORK.LT001_UNIV_OPER' AS TABELA_SIMUL,'contraparte_i' AS CAMPO, '${ref_date}' AS REF_DATE, COUNT(*) AS NUM_REG, SUM(IF(COALESCE(CAST(X.CAMPO_IT AS STRING),'')<>COALESCE(CAST(Y.CAMPO_SIMUL AS STRING),'') OR (X.CAMPO_IT IS NULL AND Y.CAMPO_SIMUL IS NOT NULL ) OR (X.CAMPO_IT IS NOT NULL AND Y.CAMPO_SIMUL IS NULL),1,0)) AS NUM_REG_DIF,'1' AS ID_EXEC, CURRENT_TIMESTAMP() AS TIME_EXEC FROM (SELECT concat(cempresa, cbalcao, cnumecta, zdeposit, ccontab_final_ifrs, ccontab_final_pcsb, ccontab_final_cargabal, ccontab_final) AS CHAVE_IT1, zcliente AS CHAVE_IT2, contraparte_i AS CAMPO_IT FROM CD_LOAN_TAPES_BCE.LT001_UNIV_OPER WHERE ref_date='${ref_date}' AND nome_perimetro='Individual Local' AND segmento='ESTR' AND ambito='PM' AND entidade='00100')X INNER JOIN (SELECT concat(cempresa, cbalcao, cnumecta, zdeposit, ccontab_final_ifrs, ccontab_final_pcsb, ccontab_final_cargabal, ccontab_final) AS CHAVE_SIMUL1, zcliente AS CHAVE_SIMUL2, contraparte_i AS CAMPO_SIMUL FROM BU_LOANTAPE_WORK.LT001_UNIV_OPER WHERE ref_date='${ref_date}' AND nome_perimetro='Individual Local' AND segmento='ESTR' AND ambito='PM' AND entidade='00100')Y ON X.CHAVE_IT1=Y.CHAVE_SIMUL1 AND X.CHAVE_IT2=Y.CHAVE_SIMUL2 | N13: =+"UNION ALL "&M13 -> UNION ALL SELECT 'UNIV_OPER' AS TABELA, 'COERÊNCIA' AS TIPOLOGIA_TESTE,'CD_LOAN_TAPES_BCE.LT001_UNIV_OPER' AS TABELA_LT,'BU_LOANTAPE_WORK.LT001_UNIV_OPER' AS TABELA_SIMUL,'contraparte_i' AS CAMPO, '${ref_date}' AS REF_DATE, COUNT(*) AS NUM_REG, SUM(IF(COALESCE(CAST(X.CAMPO_IT AS STRING),'')<>COALESCE(CAST(Y.CAMPO_SIMUL AS STRING),'') OR (X.CAMPO_IT IS NULL AND Y.CAMPO_SIMUL IS NOT NULL ) OR (X.CAMPO_IT IS NOT NULL AND Y.CAMPO_SIMUL IS NULL),1,0)) AS NUM_REG_DIF,'1' AS ID_EXEC, CURRENT_TIMESTAMP() AS TIME_EXEC FROM (SELECT concat(cempresa, cbalcao, cnumecta, zdeposit, ccontab_final_ifrs, ccontab_final_pcsb, ccontab_final_cargabal, ccontab_final) AS CHAVE_IT1, zcliente AS CHAVE_IT2, contraparte_i AS CAMPO_IT FROM CD_LOAN_TAPES_BCE.LT001_UNIV_OPER WHERE ref_date='${ref_date}' AND nome_perimetro='Individual Local' AND segmento='ESTR' AND ambito='PM' AND entidade='00100')X INNER JOIN (SELECT concat(cempresa, cbalcao, cnumecta, zdeposit, ccontab_final_ifrs, ccontab_final_pcsb, ccontab_final_cargabal, ccontab_final) AS CHAVE_SIMUL1, zcliente AS CHAVE_SIMUL2, contraparte_i AS CAMPO_SIMUL FROM BU_LOANTAPE_WORK.LT001_UNIV_OPER WHERE ref_date='${ref_date}' AND nome_perimetro='Individual Local' AND segmento='ESTR' AND ambito='PM' AND entidade='00100')Y ON X.CHAVE_IT1=Y.CHAVE_SIMUL1 AND X.CHAVE_IT2=Y.CHAVE_SIMUL2
A14: =+B14&C14 -> UNIV_OPERproduto | B14: UNIV_OPER | C14: produto | D14: Coerência | E14: =+UPPER('0. Instruções'!$D$35&"."&VLOOKUP(B14,'0. Instruções'!$C$27:$D$32,2,FALSE)) -> CD_LOAN_TAPES_BCE.LT001_UNIV_OPER | F14: =+UPPER('0. Instruções'!$D$36&"."&VLOOKUP(B14,'0. Instruções'!$C$27:$E$32,3,FALSE)) -> BU_LOANTAPE_WORK.LT001_UNIV_OPER | J14: =IF(VLOOKUP(B14,'0. Instruções'!$C$27:$G$32,5,FALSE)=0, "(SELECT "&VLOOKUP(B14,'0. Instruções'!$C$27:$G$32,4,FALSE)&" AS CHAVE_IT, "&C14&" AS CAMPO_IT FROM "&E14&" WHERE "&'0. Instruções'!$D$43&")X", "(SELECT "&VLOOKUP(B14,'0. Instruções'!$C$27:$G$32,4,FALSE)&" AS CHAVE_IT1, "&VLOOKUP(B14,'0. Instruções'!$C$27:$G$32,5,FALSE)&" AS CHAVE_IT2, "&C14&" AS CAMPO_IT FROM "&E14&" WHERE "&'0. Instruções'!$D$43&")X") -> (SELECT concat(cempresa, cbalcao, cnumecta, zdeposit, ccontab_final_ifrs, ccontab_final_pcsb, ccontab_final_cargabal, ccontab_final) AS CHAVE_IT1, zcliente AS CHAVE_IT2, produto AS CAMPO_IT FROM CD_LOAN_TAPES_BCE.LT001_UNIV_OPER WHERE ref_date='${ref_date}' AND nome_perimetro='Individual Local' AND segmento='ESTR' AND ambito='PM' AND entidade='00100')X | K14: =IF(VLOOKUP(B14,'0. Instruções'!$C$27:$G$32,5,FALSE)=0, "(SELECT "&VLOOKUP(B14,'0. Instruções'!$C$27:$G$32,4,FALSE)&" AS CHAVE_SIMUL, "&C14&" AS CAMPO_SIMUL FROM "&F14&" WHERE "&'0. Instruções'!$D$42&")Y", "(SELECT "&VLOOKUP(B14,'0. Instruções'!$C$27:$G$32,4,FALSE)&" AS CHAVE_SIMUL1, "&VLOOKUP(B14,'0. Instruções'!$C$27:$G$32,5,FALSE)&" AS CHAVE_SIMUL2, "&C14&" AS CAMPO_SIMUL FROM "&F14&" WHERE "&'0. Instruções'!$D$42&")Y") -> (SELECT concat(cempresa, cbalcao, cnumecta, zdeposit, ccontab_final_ifrs, ccontab_final_pcsb, ccontab_final_cargabal, ccontab_final) AS CHAVE_SIMUL1, zcliente AS CHAVE_SIMUL2, produto AS CAMPO_SIMUL FROM BU_LOANTAPE_WORK.LT001_UNIV_OPER WHERE ref_date='${ref_date}' AND nome_perimetro='Individual Local' AND segmento='ESTR' AND ambito='PM' AND entidade='00100')Y | L14: =IF(VLOOKUP(B14,'0. Instruções'!$C$27:$G$32,5,FALSE)=0, "ON X.CHAVE_IT=Y.CHAVE_SIMUL", "ON X.CHAVE_IT1=Y.CHAVE_SIMUL1 AND X.CHAVE_IT2=Y.CHAVE_SIMUL2") -> ON X.CHAVE_IT1=Y.CHAVE_SIMUL1 AND X.CHAVE_IT2=Y.CHAVE_SIMUL2 | M14: =+IF(D14="Coerência",+IF(LEFT(H14,5)="FLOAT","SELECT '"&UPPER(B14)&"' AS TABELA, '"&UPPER(D14)&"' AS TIPOLOGIA_TESTE,'"&E14&"' AS TABELA_LT,'"&F14&"' AS TABELA_SIMUL,'"&C14&"' AS CAMPO, "&_xlfn._LONGTEXT("'${ref_date}' AS REF_DATE, COUNT(*) AS NUM_REG, SUM(IF((ABS(COALESCE(CAST(X.CAMPO_IT AS DECIMAL(18,6)),0)-COALESCE(CAST(Y.CAMPO_SIMUL AS DECIMAL(18,6)),0))>0.000001) OR (X.CAMPO_IT IS NULL AND Y.CAMPO_SIMUL IS NOT NULL ) OR (X.CAMPO_IT IS NOT NULL AND Y.C","AMPO_SIMUL IS NULL),1,0)) AS NUM_REG_DIF,'")&MAX('3. Resultados'!K:K)+1&"' AS ID_EXEC, CURRENT_TIMESTAMP() AS TIME_EXEC FROM "&J14&" INNER JOIN "&K14&" "&L14,"SELECT '"&UPPER(B14)&"' AS TABELA, '"&UPPER(D14)&"' AS TIPOLOGIA_TESTE,'"&E14&"' AS TABELA_LT,'"&F14&"' AS TABELA_SIMUL,'"&C14&"' AS CAMPO, "&_xlfn._LONGTEXT("'${ref_date}' AS REF_DATE, COUNT(*) AS NUM_REG, SUM(IF(COALESCE(CAST(X.CAMPO_IT AS STRING),'')<>COALESCE(CAST(Y.CAMPO_SIMUL AS STRING),'') OR (X.CAMPO_IT IS NULL AND Y.CAMPO_SIMUL IS NOT NULL ) OR (X.CAMPO_IT IS NOT NULL AND Y.CAMPO_SIMUL IS NULL),1,0)) A","S NUM_REG_DIF,'")&MAX('3. Resultados'!L:L)+1&"' AS ID_EXEC, CURRENT_TIMESTAMP() AS TIME_EXEC FROM "&J14&" INNER JOIN "&K14&" "&L14)) -> SELECT 'UNIV_OPER' AS TABELA, 'COERÊNCIA' AS TIPOLOGIA_TESTE,'CD_LOAN_TAPES_BCE.LT001_UNIV_OPER' AS TABELA_LT,'BU_LOANTAPE_WORK.LT001_UNIV_OPER' AS TABELA_SIMUL,'produto' AS CAMPO, '${ref_date}' AS REF_DATE, COUNT(*) AS NUM_REG, SUM(IF(COALESCE(CAST(X.CAMPO_IT AS STRING),'')<>COALESCE(CAST(Y.CAMPO_SIMUL AS STRING),'') OR (X.CAMPO_IT IS NULL AND Y.CAMPO_SIMUL IS NOT NULL ) OR (X.CAMPO_IT IS NOT NULL AND Y.CAMPO_SIMUL IS NULL),1,0)) AS NUM_REG_DIF,'1' AS ID_EXEC, CURRENT_TIMESTAMP() AS TIME_EXEC FROM (SELECT concat(cempresa, cbalcao, cnumecta, zdeposit, ccontab_final_ifrs, ccontab_final_pcsb, ccontab_final_cargabal, ccontab_final) AS CHAVE_IT1, zcliente AS CHAVE_IT2, produto AS CAMPO_IT FROM CD_LOAN_TAPES_BCE.LT001_UNIV_OPER WHERE ref_date='${ref_date}' AND nome_perimetro='Individual Local' AND segmento='ESTR' AND ambito='PM' AND entidade='00100')X INNER JOIN (SELECT concat(cempresa, cbalcao, cnumecta, zdeposit, ccontab_final_ifrs, ccontab_final_pcsb, ccontab_final_cargabal, ccontab_final) AS CHAVE_SIMUL1, zcliente AS CHAVE_SIMUL2, produto AS CAMPO_SIMUL FROM BU_LOANTAPE_WORK.LT001_UNIV_OPER WHERE ref_date='${ref_date}' AND nome_perimetro='Individual Local' AND segmento='ESTR' AND ambito='PM' AND entidade='00100')Y ON X.CHAVE_IT1=Y.CHAVE_SIMUL1 AND X.CHAVE_IT2=Y.CHAVE_SIMUL2 | N14: =+"UNION ALL "&M14 -> UNION ALL SELECT 'UNIV_OPER' AS TABELA, 'COERÊNCIA' AS TIPOLOGIA_TESTE,'CD_LOAN_TAPES_BCE.LT001_UNIV_OPER' AS TABELA_LT,'BU_LOANTAPE_WORK.LT001_UNIV_OPER' AS TABELA_SIMUL,'produto' AS CAMPO, '${ref_date}' AS REF_DATE, COUNT(*) AS NUM_REG, SUM(IF(COALESCE(CAST(X.CAMPO_IT AS STRING),'')<>COALESCE(CAST(Y.CAMPO_SIMUL AS STRING),'') OR (X.CAMPO_IT IS NULL AND Y.CAMPO_SIMUL IS NOT NULL ) OR (X.CAMPO_IT IS NOT NULL AND Y.CAMPO_SIMUL IS NULL),1,0)) AS NUM_REG_DIF,'1' AS ID_EXEC, CURRENT_TIMESTAMP() AS TIME_EXEC FROM (SELECT concat(cempresa, cbalcao, cnumecta, zdeposit, ccontab_final_ifrs, ccontab_final_pcsb, ccontab_final_cargabal, ccontab_final) AS CHAVE_IT1, zcliente AS CHAVE_IT2, produto AS CAMPO_IT FROM CD_LOAN_TAPES_BCE.LT001_UNIV_OPER WHERE ref_date='${ref_date}' AND nome_perimetro='Individual Local' AND segmento='ESTR' AND ambito='PM' AND entidade='00100')X INNER JOIN (SELECT concat(cempresa, cbalcao, cnumecta, zdeposit, ccontab_final_ifrs, ccontab_final_pcsb, ccontab_final_cargabal, ccontab_final) AS CHAVE_SIMUL1, zcliente AS CHAVE_SIMUL2, produto AS CAMPO_SIMUL FROM BU_LOANTAPE_WORK.LT001_UNIV_OPER WHERE ref_date='${ref_date}' AND nome_perimetro='Individual Local' AND segmento='ESTR' AND ambito='PM' AND entidade='00100')Y ON X.CHAVE_IT1=Y.CHAVE_SIMUL1 AND X.CHAVE_IT2=Y.CHAVE_SIMUL2
