Workbook

Sheet GD- LT atual
B2: Categoria GD | C2: Code | D2: Descritivo
B3: AGFGR001 | C3: SCA01010101 | D3: Renewable energy production
B4: AGFGR001 | C4: SCA01010102 | D4: Hydrogen and Bioenergy production
B5: AGFGR001 | C5: SCA01010103 | D5: Transmission and distribution of electricity
B6: AGFGR001 | C6: SCA01010104 | D6: Energy Storage
B7: AGFGR002 | C7: SCA0101020101 | D7: Land Transport - Purchase
B8: AGFGR002 | C8: SCA0101020102 | D8: Land Transport - Renovation
B9: AGFGR002 | C9: SCA0101020103 | D9: Land Transport - Purchase and renovation
B10: AGFGR002 | C10: SCA0101020201 | D10: Water Transport - Purchase
B11: AGFGR002 | C11: SCA0101020202 | D11: Water Transport - Renovation
B12: AGFGR002 | C12: SCA0101020203 | D12: Water Transport - Purchase and renovation
B13: AGFGR003 | C13: SCA01010203 | D13: Transport Infrastructure
... B47: AGFSO001 | C47: SCA010210 | D47: Social - Default
C48: SCA010301 | D48: Mortgages
C49: SCA010302 | D49: Building renovation loan
C50: SCA010303 | D50: Motor vehicle loans
C51: SCA010304 | D51: Others
B52: AGFSL001 | C52: SCA020101 | D52: ESG Rating Linked
B53: AGFSL001 | C53: SCA02010201 | D53: KPI Linked - Green
B54: AGFSL001 | C54: SCA02010202 | D54: KPI Linked - Green & Social
B55: AGFSL001 | C55: SCA02010203 | D55: KPI Linked - Social
B56: AGFSL001 | C56: SCA02010301 | D56: KPI & ESG Rating Linked - Green
B57: AGFSL001 | C57: SCA02010302 | D57: KPI & ESG Rating Linked - Green & Social
B58: AGFSL001 | C58: SCA02010303 | D58: KPI & ESG Rating Linked - Social
B59: AGFSL001 | C59: SCA020104 | D59: Sustainability Linked Finance - Default
C60: SCA020201 | D60: Pure Green counterparty - Default
B61: AGFSR001 | C61: SCA020301 | D61: Sustainable Responsible - Default
B62: AGFSD001 | C62: SCA0204 | D62: General Purpose - Default

Sheet SFICS e LT
B2: Categorias SFICS | D2: Ficheiro Corporativo Loan Tape Dezembro | F2: Ficheiro Corporativo Loan Tape Atual
B3: Code | C3: Descritivo | D3: Code | E3: Descritivo | F3: Code | G3: Descritivo | H3: Categoria GD
B4: A.1. | C4: Energy | E4: Energy
B5: A.1.1. | C5: Electricity generation using solar photovoltaic technology | D5: 210101 | E5: Electricity generation using solar photovoltaic technology | F5: SCA01010101 | G5: Renewable energy production | H5: =INDEX('GD- LT atual'!$B$2:$D$62,MATCH('SFICS e LT'!F5,'GD- LT atual'!$C$2:$C$62,0),1) -> AGFGR001
B6: A.1.2. | C6: Electricity generation using concentrated solar power (CSP) technology | D6: 210102 | E6: Electricity generation using concentrated solar power (CSP) technology | F6: SCA01010101 | G6: Renewable energy production | H6: =INDEX('GD- LT atual'!$B$2:$D$62,MATCH('SFICS e LT'!F6,'GD- LT atual'!$C$2:$C$62,0),1) -> AGFGR001
B7: A.1.3. | C7: Electricity generation from wind power | D7: 210103 | E7: Electricity generation from wind power | F7: SCA01010101 | G7: Renewable energy production | H7: =INDEX('GD- LT atual'!$B$2:$D$62,MATCH('SFICS e LT'!F7,'GD- LT atual'!$C$2:$C$62,0),1) -> AGFGR001
B8: A.1.4. | C8: Electricity generation from ocean energy technologies | D8: 210104 | E8: Electricity generation from ocean energy technologies | F8: SCA01010101 | G8: Renewable energy production | H8: =INDEX('GD- LT atual'!$B$2:$D$62,MATCH('SFICS e LT'!F8,'GD- LT atual'!$C$2:$C$62,0),1) -> AGFGR001
B9: A.1.5. | C9: Electricity generation from hydropower | D9: 210105 | E9: Electricity generation from hydropower | F9: SCA01010101 | G9: Renewable energy production | H9: =INDEX('GD- LT atual'!$B$2:$D$62,MATCH('SFICS e LT'!F9,'GD- LT atual'!$C$2:$C$62,0),1) -> AGFGR001
B10: A.1.6. | C10: Electricity generation from geothermal energy | D10: 210106 | E10: Electricity generation from geothermal energy | F10: SCA01010101 | G10: Renewable energy production | H10: =INDEX('GD- LT atual'!$B$2:$D$62,MATCH('SFICS e LT'!F10,'GD- LT atual'!$C$2:$C$62,0),1) -> AGFGR001
B11: A.1.7. | C11: Electricity generation from renewable non-fossil gaseous and liquid fuels | D11: 210201 | E11: Electricity generation from renewable non-fossil gaseous and liquid fuels | F11: SCA01010101 | G11: Renewable energy production | H11: =INDEX('GD- LT atual'!$B$2:$D$62,MATCH('SFICS e LT'!F11,'GD- LT atual'!$C$2:$C$62,0),1) -> AGFGR001
B12: A.1.8. | C12: Electricity generation from bioenergy | D12: 210202 | E12: Electricity generation from bioenergy | F12: SCA01010101 | G12: Renewable energy production | H12: =INDEX('GD- LT atual'!$B$2:$D$62,MATCH('SFICS e LT'!F12,'GD- LT atual'!$C$2:$C$62,0),1) -> AGFGR001
B13: A.1.9. | C13: Transmission and distribution of electricity | D13: 210419 | E13: Transmission and distribution of electricity | F13: SCA01010103 | G13: Transmission and distribution of electricity | H13: =INDEX('GD- LT atual'!$B$2:$D$62,MATCH('SFICS e LT'!F13,'GD- LT atual'!$C$2:$C$62,0),1) -> AGFGR001
B14: A.1.10. | C14: Storage of electricity | D14: 210601 | E14: Storage of electricity | F14: SCA01010104 | G14: Energy Storage | H14: =INDEX('GD- LT atual'!$B$2:$D$62,MATCH('SFICS e LT'!F14,'GD- LT atual'!$C$2:$C$62,0),1) -> AGFGR001
B15: A.1.11. | C15: Storage of thermal energy | D15: 210602 | E15: Storage of thermal energy | F15: SCA01010104 | G15: Energy Storage | H15: =INDEX('GD- LT atual'!$B$2:$D$62,MATCH('SFICS e LT'!F15,'GD- LT atual'!$C$2:$C$62,0),1) -> AGFGR001
B16: A.1.12. | C16: Storage of hydrogen | D16: 210603 | E16: Storage of hydrogen | F16: SCA01010104 | G16: Energy Storage | H16: =INDEX('GD- LT atual'!$B$2:$D$62,MATCH('SFICS e LT'!F16,'GD- LT atual'!$C$2:$C$62,0),1) -> AGFGR001
B17: A.1.13. | C17: Manufacture of biogas and biofuels for use in transport and of bioliquids | D17: 210203 | E17: Manufacture of biogas and biofuels for use in transport and of bioliquids | F17: SCA01010102 | G17: Hydrogen and Bioenergy production | H17: =INDEX('GD- LT atual'!$B$2:$D$62,MATCH('SFICS e LT'!F17,'GD- LT atual'!$C$2:$C$62,0),1) -> AGFGR001
... B29: A.1.25. | C29: Production of heat/cool using waste heat | D29: 210208 | E29: Production of heat/cool using waste heat | F29: SCA01010101 | G29: Renewable energy production | H29: =INDEX('GD- LT atual'!$B$2:$D$62,MATCH('SFICS e LT'!F29,'GD- LT atual'!$C$2:$C$62,0),1) -> AGFGR001
B30: A.1.26. | C30: Pre-commercial stages of advanced technologies to produce energy from nuclear processes with minimal waste from the fuel cycle | D30: 210301 | E30: Pre-commercial stages of advanced technologies to produce energy from nuclear processes with minimal waste from the fuel cycle | F30: - | H30: =INDEX('GD- LT atual'!$B$2:$D$62,MATCH('SFICS e LT'!F30,'GD- LT atual'!$C$2:$C$62,0),1) -> #N/A
B31: A.1.27. | C31: Construction and safe operation of new nuclear power plants, for the generation of electricity and/or heat, including for hydrogen production, using best-available technologies | D31: 210302 | E31: Construction and safe operation of new nuclear power plants, for the generation of electricity and/or heat, including for hydrogen production, using best-available technologies | F31: SCA01010102 | G31: Hydrogen and Bioenergy production | H31: =INDEX('GD- LT atual'!$B$2:$D$62,MATCH('SFICS e LT'!F31,'GD- LT atual'!$C$2:$C$62,0),1) -> AGFGR001
B32: A.1.28. | C32: Electricity generation from nuclear energy in existing installations | D32: 210303 | E32: Electricity generation from nuclear energy in existing installations | F32: - | H32: =INDEX('GD- LT atual'!$B$2:$D$62,MATCH('SFICS e LT'!F32,'GD- LT atual'!$C$2:$C$62,0),1) -> #N/A
B33: A.1.29. | C33: Electricity generation from fossil gaseous fuels | D33: 210304 | E33: Electricity generation from fossil gaseous fuels | F33: - | H33: =INDEX('GD- LT atual'!$B$2:$D$62,MATCH('SFICS e LT'!F33,'GD- LT atual'!$C$2:$C$62,0),1) -> #N/A
B34: A.1.30. | C34: Production of heat/cool from fossil gaseous fuels in an efficient district heating and cooling system | D34: 210305 | E34: Production of heat/cool from fossil gaseous fuels in an efficient district heating and cooling system | F34: - | H34: =INDEX('GD- LT atual'!$B$2:$D$62,MATCH('SFICS e LT'!F34,'GD- LT atual'!$C$2:$C$62,0),1) -> #N/A
B35: A.1.31. | C35: High-efficiency co-generation of heat/cool and power from fossil gaseous fuels | D35: 210306 | E35: High-efficiency co-generation of heat/cool and power from fossil gaseous fuels | F35: - | H35: =INDEX('GD- LT atual'!$B$2:$D$62,MATCH('SFICS e LT'!F35,'GD- LT atual'!$C$2:$C$62,0),1) -> #N/A
B36: A.1.32. | C36: Renewable Energy Procurement | D36: 210701 | E36: Renewable Energy Procurement | F36: SCA010204 | G36: Social - Energy | H36: =INDEX('GD- LT atual'!$B$2:$D$62,MATCH('SFICS e LT'!F36,'GD- LT atual'!$C$2:$C$62,0),1) -> AGFSO001
B37: A.1.33. | C37: Terminology definitions | D37: - | F37: - | H37: =INDEX('GD- LT atual'!$B$2:$D$62,MATCH('SFICS e LT'!F37,'GD- LT atual'!$C$2:$C$62,0),1) -> #N/A
B38: A.2. | C38: Transport | E38: Transport | H38: =INDEX('GD- LT atual'!$B$2:$D$62,MATCH('SFICS e LT'!F38,'GD- LT atual'!$C$2:$C$62,0),1) -> #N/A
B39: A.2.1. | C39: Passenger interurban rail transport | D39: 220101 | E39: Passenger interurban rail transport | F39: SCA0101020101 | G39: Land Transport - Purchase | H39: =INDEX('GD- LT atual'!$B$2:$D$62,MATCH('SFICS e LT'!F39,'GD- LT atual'!$C$2:$C$62,0),1) -> AGFGR002
B40: A.2.2. | C40: Freight rail transport | D40: 220102 | E40: Freight rail transport | F40: SCA0101020101 | G40: Land Transport - Purchase | H40: =INDEX('GD- LT atual'!$B$2:$D$62,MATCH('SFICS e LT'!F40,'GD- LT atual'!$C$2:$C$62,0),1) -> AGFGR002
B41: A.2.3. | C41: Urban and suburban transport, road passenger transport | D41: 220103 | E41: Urban and suburban transport, road passenger transport | F41: SCA0101020101 | G41: Land Transport - Purchase | H41: =INDEX('GD- LT atual'!$B$2:$D$62,MATCH('SFICS e LT'!F41,'GD- LT atual'!$C$2:$C$62,0),1) -> AGFGR002
B42: A.2.4. | C42: Operation of personal mobility devices, cycle logistics | D42: 220104 | E42: Operation of personal mobility devices, cycle logistics | F42: SCA01010203 | G42: Transport Infrastructure | H42: =INDEX('GD- LT atual'!$B$2:$D$62,MATCH('SFICS e LT'!F42,'GD- LT atual'!$C$2:$C$62,0),1) -> AGFGR003
B43: A.2.5. | C43: Transport by motorbikes, passenger cars and light commercial vehicles | D43: 220105 | E43: Transport by motorbikes, passenger cars and light commercial vehicles | F43: SCA01010203 | G43: Transport Infrastructure | H43: =INDEX('GD- LT atual'!$B$2:$D$62,MATCH('SFICS e LT'!F43,'GD- LT atual'!$C$2:$C$62,0),1) -> AGFGR003
B44: A.2.6. | C44: Freight transport services by road | D44: 220106 | E44: Freight transport services by road | F44: SCA0101020101 | G44: Land Transport - Purchase | H44: =INDEX('GD- LT atual'!$B$2:$D$62,MATCH('SFICS e LT'!F44,'GD- LT atual'!$C$2:$C$62,0),1) -> AGFGR002
B45: A.2.7. | C45: Inland passenger water transport | D45: 220201 | E45: Inland passenger water transport | F45: SCA0101020201 | G45: Water Transport - Purchase | H45: =INDEX('GD- LT atual'!$B$2:$D$62,MATCH('SFICS e LT'!F45,'GD- LT atual'!$C$2:$C$62,0),1) -> AGFGR002
B46: A.2.8. | C46: Inland freight water transport | D46: 220202 | E46: Inland freight water transport | F46: SCA0101020201 | G46: Water Transport - Purchase | H46: =INDEX('GD- LT atual'!$B$2:$D$62,MATCH('SFICS e LT'!F46,'GD- LT atual'!$C$2:$C$62,0),1) -> AGFGR002
B47: A.2.9. | C47: Retrofitting of inland water passenger and freight transport | D47: 220203 | E47: Retrofitting of inland water passenger and freight transport | F47: SCA0101020202 | G47: Water Transport - Renovation | H47: =INDEX('GD- LT atual'!$B$2:$D$62,MATCH('SFICS e LT'!F47,'GD- LT atual'!$C$2:$C$62,0),1) -> AGFGR002
B48: A.2.10. | C48: Sea and coastal freight water transport, vessels for port operations and auxiliary activities | D48: 220204 | E48: Sea and coastal freight water transport, vessels for port operations and auxiliary activities | F48: SCA0101020201 | G48: Water Transport - Purchase | H48: =INDEX('GD- LT atual'!$B$2:$D$62,MATCH('SFICS e LT'!F48,'GD- LT atual'!$C$2:$C$62,0),1) -> AGFGR002
B49: A.2.11. | C49: Sea and coastal passenger water transport | D49: 220205 | E49: Sea and coastal passenger water transport | F49: SCA0101020201 | G49: Water Transport - Purchase | H49: =INDEX('GD- LT atual'!$B$2:$D$62,MATCH('SFICS e LT'!F49,'GD- LT atual'!$C$2:$C$62,0),1) -> AGFGR002
B50: A.2.12. | C50: Retrofitting of sea and coastal freight and passenger water transport | D50: 220206 | E50: Retrofitting of sea and coastal freight and passenger water transport | F50: SCA0101020202 | G50: Water Transport - Renovation | H50: =INDEX('GD- LT atual'!$B$2:$D$62,MATCH('SFICS e LT'!F50,'GD- LT atual'!$C$2:$C$62,0),1) -> AGFGR002
... B54: A.2.16. | C54: Infrastructure enabling low carbon water transport | D54: 220403 | E54: Infrastructure enabling low carbon water transport | F54: SCA01010203 | G54: Transport Infrastructure | H54: =INDEX('GD- LT atual'!$B$2:$D$62,MATCH('SFICS e LT'!F54,'GD- LT atual'!$C$2:$C$62,0),1) -> AGFGR003
B55: A.2.17. | C55: Low carbon airport infrastructure | D55: 220404 | E55: Low carbon airport infrastructure | F55: SCA01010203 | G55: Transport Infrastructure | H55: =INDEX('GD- LT atual'!$B$2:$D$62,MATCH('SFICS e LT'!F55,'GD- LT atual'!$C$2:$C$62,0),1) -> AGFGR003
...

Sheet Mapeamento FC
E1: Categoria GD | F1: AGFSO001
B2: Code | C2: Categoria GD | H2: GD | I2: Descritivo | J2: SSTNBL_CTGRY
B3: 210101 | C3: AGFGR001 | E3: Row Labels | H3: 'AGFGR001' | I3: Energy | J3: ('210101','210102','210103','210104','210105','210106','210107','210108','210109','210110','210201','210202','210203','210204','210205','210206','210207','210208','210302','210419','210420','210421','210501','210601','210602','210603','280201','280202','280203') | K3: =_xlfn.CONCAT("WHEN ",$J$2," IN ",$J3," THEN ",$H3) -> WHEN SSTNBL_CTGRY IN ('210101','210102','210103','210104','210105','210106','210107','210108','210109','210110','210201','210202','210203','210204','210205','210206','210207','210208','210302','210419','210420','210421','210501','210601','210602','210603','280201','280202','280203') THEN 'AGFGR001'
B4: 210102 | C4: AGFGR001 | E4: 2401 | F4: =_xlfn.CONCAT("'",E4,"'",",") -> '2401', | H4: 'AGFGR002' | I4: Transport | J4: ('220501','220101','220102','220103','220106','220201','220202','220203','220204','220205','220206','220303') | K4: =_xlfn.CONCAT("WHEN ",$J$2," IN ",$J4," THEN ",$H4) -> WHEN SSTNBL_CTGRY IN ('220501','220101','220102','220103','220106','220201','220202','220203','220204','220205','220206','220303') THEN 'AGFGR002'
B5: 210103 | C5: AGFGR001 | E5: 2502 | F5: =_xlfn.CONCAT("'",E5,"'",",") -> '2502', | H5: 'AGFGR003' | I5: Transport | J5: ('220404','220104','220105','220301','220302','220401','220402','220403','220405') | K5: =_xlfn.CONCAT("WHEN ",$J$2," IN ",$J5," THEN ",$H5) -> WHEN SSTNBL_CTGRY IN ('220404','220104','220105','220301','220302','220401','220402','220403','220405') THEN 'AGFGR003'
B6: 210104 | C6: AGFGR001 | E6: 2503 | F6: =_xlfn.CONCAT("'",E6,"'",",") -> '2503', | H6: 'AGFGR005' | I6: Agriculture | J6: ('2704','2705','270201','270203','270204','270301','270302','270303','270304','270305','270306','270307','270308','270309','270310','270311','270101','270102','270202') | K6: =_xlfn.CONCAT("WHEN ",$J$2," IN ",$J6," THEN ",$H6) -> WHEN SSTNBL_CTGRY IN ('2704','2705','270201','270203','270204','270301','270302','270303','270304','270305','270306','270307','270308','270309','270310','270311','270101','270102','270202') THEN 'AGFGR005'
B7: 210105 | C7: AGFGR001 | E7: 3001 | F7: =_xlfn.CONCAT("'",E7,"'",",") -> '3001', | H7: 'AGFGR006' | I7: Construction and Real Estate | J7: ('2301') | K7: =_xlfn.CONCAT("WHEN ",$J$2," IN ",$J7," THEN ",$H7) -> WHEN SSTNBL_CTGRY IN ('2301') THEN 'AGFGR006'
B8: 210106 | C8: AGFGR001 | E8: 3102 | F8: =_xlfn.CONCAT("'",E8,"'",",") -> '3102', | H8: 'AGFGR007' | I8: Construction and Real Estate | J8: ('2302','230301') | K8: =_xlfn.CONCAT("WHEN ",$J$2," IN ",$J8," THEN ",$H8) -> WHEN SSTNBL_CTGRY IN ('2302','230301') THEN 'AGFGR007'
B9: 210201 | C9: AGFGR001 | E9: 210701 | F9: =_xlfn.CONCAT("'",E9,"'",",") -> '210701', | H9: 'AGFGR008' | I9: Construction and Real Estate | J9: ('230302','230303','230304') | K9: =_xlfn.CONCAT("WHEN ",$J$2," IN ",$J9," THEN ",$H9) -> WHEN SSTNBL_CTGRY IN ('230302','230303','230304') THEN 'AGFGR008'
B10: 210202 | C10: AGFGR001 | E10: 260104 | F10: =_xlfn.CONCAT("'",E10,"'",",") -> '260104', | H10: 'AGFGR009' | I10: Water and Waste | J10: ('2305','230601','280101') | K10: =_xlfn.CONCAT("WHEN ",$J$2," IN ",$J10," THEN ",$H10) -> WHEN SSTNBL_CTGRY IN ('2305','230601','280101') THEN 'AGFGR009'
B11: 210419 | C11: AGFGR001 | E11: 260403 | F11: =_xlfn.CONCAT("'",E11,"'",",") -> '260403', | H11: 'AGFGR010' | I11: Manufacturing | J11: ('280302','280303','280304','280504','280706','280107','2804','280501','280503','280505','280601','280602','280603','280701','280702','280703','280704','280705','280801','280802','280901','280902') | K11: =_xlfn.CONCAT("WHEN ",$J$2," IN ",$J11," THEN ",$H11) -> WHEN SSTNBL_CTGRY IN ('280302','280303','280304','280504','280706','280107','2804','280501','280503','280505','280601','280602','280603','280701','280702','280703','280704','280705','280801','280802','280901','280902') THEN 'AGFGR010'
B12: 210601 | C12: AGFGR001 | E12: 300201 | F12: =_xlfn.CONCAT("'",E12,"'",",") -> '300201', | H12: 'AGFGR011' | I12: Other Sectors | J12: ('2706','3101','280301','281001','260304','260601','260602','280502','280604','3104') | K12: =_xlfn.CONCAT("WHEN ",$J$2," IN ",$J12," THEN ",$H12) -> WHEN SSTNBL_CTGRY IN ('2706','3101','280301','281001','260304','260601','260602','280502','280604','3104') THEN 'AGFGR011'
B13: 210602 | C13: AGFGR001 | E13: 2304 | F13: =_xlfn.CONCAT("'",E13,"'",",") -> '2304', | H13: 'AGFSO001' | I13: Social | J13: ('2401','2502','2503','3001','3102','210701','260104','260403','300201','2304','230602','2501','260101','260102','260103','260201','260202','260203','260204','260205','260301','260302','260303','260305','260401','260402','260404','260405','260406','260407','260501','260502','300202','3103') | K13: =_xlfn.CONCAT("WHEN ",$J$2," IN ",$J13," THEN ",$H13) -> WHEN SSTNBL_CTGRY IN ('2401','2502','2503','3001','3102','210701','260104','260403','300201','2304','230602','2501','260101','260102','260103','260201','260202','260203','260204','260205','260301','260302','260303','260305','260401','260402','260404','260405','260406','260407','260501','260502','300202','3103') THEN 'AGFSO001'
B14: 210603 | C14: AGFGR001 | E14: 230602 | F14: =_xlfn.CONCAT("'",E14,"'",",") -> '230602',
B15: 210203 | C15: AGFGR001 | E15: 2501 | F15: =_xlfn.CONCAT("'",E15,"'",",") -> '2501 ',
B16: 210420 | C16: AGFGR001 | E16: 260101 | F16: =_xlfn.CONCAT("'",E16,"'",",") -> '260101',
B17: 210421 | C17: AGFGR001 | E17: 260102 | F17: =_xlfn.CONCAT("'",E17,"'",",") -> '260102',
B18: 210501 | C18: AGFGR001 | E18: 260103 | F18: =_xlfn.CONCAT("'",E18,"'",",") -> '260103',
B19: 210107 | C19: AGFGR001 | E19: 260201 | F19: =_xlfn.CONCAT("'",E19,"'",",") -> '260201',
B20: 210108 | C20: AGFGR001 | E20: 260202 | F20: =_xlfn.CONCAT("'",E20,"'",",") -> '260202',
B21: 210204 | C21: AGFGR001 | E21: 260203 | F21: =_xlfn.CONCAT("'",E21,"'",",") -> '260203',
B22: 210205 | C22: AGFGR001 | E22: 260204 | F22: =_xlfn.CONCAT("'",E22,"'",",") -> '260204',
B23: 210109 | C23: AGFGR001 | E23: 260205 | F23: =_xlfn.CONCAT("'",E23,"'",",") -> '260205',
B24: 210110 | C24: AGFGR001 | E24: 260301 | F24: =_xlfn.CONCAT("'",E24,"'",",") -> '260301',
B25: 210206 | C25: AGFGR001 | E25: 260302 | F25: =_xlfn.CONCAT("'",E25,"'",",") -> '260302',
... B28: 210302 | C28: AGFGR001 | E28: 260401 | F28: =_xlfn.CONCAT("'",E28,"'",",") -> '260401',
B29: 210701 | C29: AGFSO001 | E29: 260402 | F29: =_xlfn.CONCAT("'",E29,"'",",") -> '260402',
B30: 220101 | C30: AGFGR002 | E30: 260404 | F30: =_xlfn.CONCAT("'",E30,"'",",") -> '260404',
B31: 220102 | C31: AGFGR002 | E31: 260405 | F31: =_xlfn.CONCAT("'",E31,"'",",") -> '260405',
B32: 220103 | C32: AGFGR002 | E32: 260406 | F32: =_xlfn.CONCAT("'",E32,"'",",") -> '260406',
B33: 220104 | C33: AGFGR003 | E33: 260407 | F33: =_xlfn.CONCAT("'",E33,"'",",") -> '260407',
B34: 220105 | C34: AGFGR003 | E34: 260501 | F34: =_xlfn.CONCAT("'",E34,"'",",") -> '260501',
B35: 220106 | C35: AGFGR002 | E35: 260502 | F35: =_xlfn.CONCAT("'",E35,"'",",") -> '260502',
B36: 220201 | C36: AGFGR002 | E36: 300202 | F36: =_xlfn.CONCAT("'",E36,"'",",") -> '300202',
B37: 220202 | C37: AGFGR002 | E37: 3103 | F37: =_xlfn.CONCAT("'",E37,"'",",") -> '3103 ',
B38: 220203 | C38: AGFGR002 | E38: Grand Total
B39: 220204 | C39: AGFGR002
B40: 220205 | C40: AGFGR002
B41: 220206 | C41: AGFGR002
B42: 220401 | C42: AGFGR003
...

Sheet Resultados LT
