Workbook

Sheet 0. Instructions
B2: Instructions
B3: In order facilitate reaching an understanding of the data requirements a description of the functionality of each column is provided below:
B5: Data Compilation
B6: Metric Name: Name given to the data
B7: Metric Description: Functional description of the data
B9: Operational Information
B10: Scope Business: Customer segment for which it is required to provision the data
B11: Level: level of granularity of the information required (Counterparty, Contract,etc)
B12: Frequency: frequency with which data is required
B13: Deadline for data availability: when data need to be available to be consumed for be used in pilot or reporting
B14: Related Standard: if data is used in other standard or regulation (e.g. FINREP). In affirmative case, data should be aligned with the data used in other standard
B16: Pillar III
... B44: If the balance sheet of the last 24 months is not available, previous balance sheet will be used, following the same priority as explained before.

Sheet 1. Data dictionary
A1: Cardinality | C1: Data Compilation | G1: Sourcing | M1: Pillar III: Uses and Guidelines | Q1: Data Quality Indicators (DQIs)
Q2: Completeness | R2: Accuracy | V2: Consistency | X2: Comments
A3: Metric | B3: Applicability to units | C3: Metric Name | D3: Metric Description | E3: Scope Business | F3: Level (op, client,…) | G3: Estrategical Source | H3: Loan tapes inclusion | I3: External Data Providers referenced by HQ | J3: Needed to report a tactical to HQ? | K3: Needed to be reported to HQ by the Unit | M3: Template | N3: Satelite | O3: HQ functional guidelines | P3: Use of variable | R3: Format checking | S3: Ranges and dimensions validation | T3: Integrity checks between correlated data | U3: Duplicates detection | V3: Key data elements conciliation against other reporting | W3: Consistency checks with external data
K4: Origin Source | L4: Local Data Owner
A5: 1 | B5: All | C5: GHG Financed Emissions: Scope 1 | D5: Scope 1 emissions are direct greenhouse (GHG) emissions that occur from sources that are controlled or owned by an organization (e.g., emissions associated with fuel combustion in boilers, furnaces, vehicles). | E5: Banking Book: Non-Financial Corporation | F5: Client | G5: This metric has been requested to be included in BDR. Comments on whether or not they will be included are pending. All units will be notified as soon as we receive it. | H5: Yes | I5: CDP & PCAF | J5: No | K5: TBD | L5: TBD | M5: T1 | N5: GHGE_GHG Financed emissions | O5: Functional guidelines will be provided by HQ for sourcing this variable. | Q5: x | R5: Numeric (CO2 tonnes (TCO2)) | S5: >=0. In case value = 0 or <0, review if it is correct. | T5: - If scope 2 informed, scope 1 should be informed - If scope 3 informed, scope 1&2 should be informed. | X5: Real data preferred (published by counterparty) to estimations (sector/country average, PCAF), thus required effort to identify based on counterparty's publications.
A6: 2 | B6: All | C6: GHG Financed Emissions: Scope 2 | D6: Scope 2 emissions are indirect emissions from the generation of purchased energy, from a utility provider. In other words, all GHG emissions released in the atmosphere, from the consumption of purchased electricity, steam, heat and cooling. For most organizations, electricity will be the unique source of scope 2 emissions. | E6: Banking Book: Non-Financial Corporation | F6: Client | G6: This metric has been requested to be included in BDR. Comments on whether or not they will be included are pending. All units will be notified as soon as we receive it. | H6: Yes | I6: CDP & PCAF | J6: No | K6: TBD | L6: TBD | M6: T1 | N6: GHGE_GHG Financed emissions | O6: Functional guidelines will be provided by HQ for sourcing this variable.
A7: 3 | B7: All | C7: GHG Financed Emissions: Scope 3 | D7: Counterparties’ scope 3 emissions associated with lending and investment activities. Scope 3 emissions shall be disclosed on a best effort basis covering the most relevant sectors for example in line with PCAF approach and the phased-in approach for scope 3. Financial institutions shall start disclosing information scope 3 emissions, when available, for the oil, gas, and mining sectors from 2021 onward and additional sectors will be added subsequently. Information on scope 3 emissions of the counterparty for all sectors included in the template shall be disclosed as of 30 June 2024 first disclosure reference date. For sectors where data and methodological challenges exist, banks shall follow the GHG protocol and its 15 stages, both upstream and downstream, as presented in the Commission Guidelines on non-financial reporting: supplement on reporting climate related information. | E7: Banking Book: Non-Financial Corporation | F7: Client | G7: This metric has been requested to be included in BDR. Comments on whether or not they will be included are pending. All units will be notified as soon as we receive it. | H7: Yes | I7: CDP & PCAF | J7: No | K7: TBD | L7: TBD | M7: T1 | N7: GHGE_GHG Financed emissions | O7: Functional guidelines will be provided by HQ for sourcing this variable.
A8: 4 | B8: For units in Europe | C8: Geography of the collateral: NUTS | D8: Location of the collateral's country, geographical or administrative region (maximum level of available breakdown) where activities of the counterparty are located. For EU countries + UK the level of divisions indicated in Nomenclature of Territorial Units for Statistics (NUTS) shall be used. The NUTS classification is a hierarchical system for dividing up the economic territory of the EU and the UK: - NUTS 1: major socio-economic regions - NUTS 2: basic regions for the application of regional policies - NUTS 3: small regions for specific diagnoses In the following link NUTs codes are available: https://ec.europa.eu/eurostat/documents/3859598/10967554/KS-GQ-20-092-EN-N.pdf/9d57ae79-3ee7-3c14-da3e-34726da385cf?t=1591285035000 For non EU countries equivalent classification shall be used. | E8: Banking Book: Non-Financial Corporation, Households (Commercial and Residential) and Repossessed Collaterals | F8: Collateral | G8: This metric has been requested to be included in BDR. Comments on whether or not they will be included are pending. All units will be notified as soon as we receive it. | H8: Yes | J8: Yes | K8: Table: cd_estruturais.tat91_tabelas where tayd91c0_ctabela = 'J48' Var: tayd91c0_nelemc05 (NUT3) NOTA: When there is no information for NUTS3, it is used NUTS1. For countries outside the EU, it is used the 3 digits ISO code. | L8: CDO | M8: T2 T5 | N8: CESG_CNAE_ESG ENPC_Energy_Performance_Certificate | Q8: x | R8: Numeric | S8: All codes are part of the reference pre-defined list of values (NUT3, Postal Code or equivalent)
A9: 5 | B9: All | C9: Geography of the collateral: ZIP Code | D9: Postal Code associated to the location of the collateral | E9: Banking Book: Non-Financial Corporation, Households (Commercial and Residential) and Repossessed Collaterals | F9: Collateral | G9: BDR: Table: JM_GARA_REAL Var: codposgr | H9: Yes | J9: Yes | K9: Table: cd_garantias.gt009_bens_imov Var: cpost | L9: CDO | M9: T2 T5 | N9: CESG_CNAE_ESG ENPC_Energy_Performance_Certificate | Q9: x | R9: Numeric | S9: All codes are part of the reference pre-defined list of values (NUT3, Postal Code or equivalent)
A10: 6 | B10: Not necessary at the moment. Having the zip code or the NUTS is enough | C10: Geography of the collateral: Full Address | D10: Full address associated to the location of the collateral | E10: Banking Book: Non-Financial Corporation, Households (Commercial and Residential) and Repossessed Collaterals | F10: Collateral | G10: This metric has been requested to be included in BDR. Comments on whether or not they will be included are pending. All units will be notified as soon as we receive it. | H10: Yes | J10: No | K10: N/A | L10: N/A | M10: T2 T5 | N10: CESG_CNAE_ESG ENPC_Energy_Performance_Certificate | Q10: x | R10: Numeric | S10: All codes are part of the reference pre-defined list of values (NUT3, Postal Code or equivalent)
A11: 7 | B11: Only for ESP, PT and UK | C11: EPC label | D11: Letter code representing the energy performance of the collateral (from A to G) regarding the energy consumption. For EU countries, the label of the energy performance certificate (EPC) recognised by a Member State or by a legal person designated by it, which indicates the energy performance of a building or building unit, calculated according to the methodology set out in Annex I of 2010/31/EU Directive. For exposures outside the EU, the label of the EPC of the collateral as defined in the relevant regulation, where a mapping to the EU EPC label exists. | E11: Banking Book: Households (Commercial and Residential) and Repossessed Collaterals | F11: Collateral | G11: This metric has been requested to be included in BDR. Comments on whether or not they will be included are pending. All units will be notified as soon as we receive it. | H11: Yes | I11: Landmark & Gloval | J11: Yes | K11: External Provider | L11: N/A | M11: T2 | N11: ENPC_Energy_Performance_Certificate | O11: Functional guidelines will be provided by HQ for sourcing this variable. | Q11: x | R11: Text | S11: All possible labels are part of the reference Group list of EPCs. Possible values: A-G | U11: Only an EPC label can be declared by property | X11: Changes > +/- 10% to be justified (i.e. changes in the composition of the portfolio due to the acquisition of material CRE, periodic updates of overduew EPC labels). Se va a pedir One-Off, no se si es viable ver tendencias o evoluciones
A12: 8 | B12: Only for ESP, PT, UK and POL | C12: EP Score | D12: Specific energy consumption of a collateral in kWh/m² per year, as indicated in the EPC label of the collateral. | E12: Banking Book: Households (Commercial and Residential) and Repossessed Collaterals | F12: Collateral | G12: This metric has been requested to be included in BDR. Comments on whether or not they will be included are pending. All units will be notified as soon as we receive it. | H12: Yes | I12: Landmark & Gloval | J12: Yes | K12: External Provider | L12: N/A | M12: T2 | N12: ENPC_Energy_Performance_Certificate | O12: Functional guidelines will be provided by HQ for sourcing this variable. | Q12: x | R12: Numeric (kWh/m² ) | S12: >=0 | X12: -To be informed at least when EPC is required by local applicable law / internal bank's procedures. - Ideally for all potential existing cases. Same criteria as for EPC label.
A13: 9 | B13: Only for ESP, PT and UK | C13: EPC Label: Flag original / calculated | D13: This flag allows to identify if the EPC Label data is original or calculated. Original data means that the EPC data asigned to the collateral is a real value of the EPC label vs "calculated", meaning that the institution has applied some kind of methodology to estimate the EPC related data. | E13: Banking Book: Households (Commercial and Residential) and Repossessed Collaterals | F13: Collateral | G13: This metric has been requested to be included in BDR. Comments on whether or not they will be included are pending. All units will be notified as soon as we receive it. | H13: Yes | I13: Landmark & Gloval | J13: Yes | K13: External Provider | L13: N/A | M13: T2 | N13: ENPC_Energy_Performance_Certificate | O13: Functional guidelines will be provided by HQ for sourcing this variable. | Q13: x
A14: 10 | B14: Only for ESP, PT, UK and POL | C14: EP Score: Flag original / calculated | D14: This flag allows to identify if the EPC score data is original or calculated. Original data means that the EPC data asigned to the collateral is a real value of the EPC score vs "calculated", meaning that the institution has applied some kind of methodology to estimate the EPC related data. | E14: Banking Book: Households (Commercial and Residential) and Repossessed Collaterals | F14: Collateral | G14: This metric has been requested to be included in BDR. Comments on whether or not they will be included are pending. All units will be notified as soon as we receive it. | H14: Yes | I14: Landmark & Gloval | K14: External Provider | L14: N/A | M14: T2 | N14: ENPC_Energy_Performance_Certificate | O14: Functional guidelines will be provided by HQ for sourcing this variable. | Q14: x
A15: 11 | B15: Only for ESP, PT and UK | C15: EPC CO2 emissions | D15: Specific emissions of a collateral in kgCO2/m² per year, as indicated in the EPC label of the collateral. | E15: Banking Book: Households (Commercial and Residential) and Repossessed Collaterals | F15: Collateral | G15: This metric has been requested to be included in BDR. Comments on whether or not they will be included are pending. All units will be notified as soon as we receive it. | H15: No | J15: No | K15: External Provider | L15: N/A | M15: T1 T3 | N15: N/A - Variable not reported in the satelite, used as an input | O15: Functional guidelines will be provided by HQ for sourcing this variable. | P15: For financed emissions: Commercial Real Estate | Q15: x | R15: Numeric (kgCO2/m²) | S15: >=0
A16: 12 | B16: All | C16: Non-performing | D16: Credit risk classification of the exposure that meets at least one of the following criteria: a) An exposure in respect of which a default is considered to have occurred in accordance with CRR, Article 178 (Default of an Obligor). Where the institution has on-balance-sheet exposures to an obligor that are past due by more than 90 days and that represent more than 20 % of all on-balance-sheet exposures to that obligor, all on- and off-balance-sheet exposures to that obligor shall be considered to be non-performing. (b) An exposure which is considered to be impaired in accordance with the applicable accounting framework; (c) An exposure under probation, where additional forbearance measures are granted or where the exposure becomes more than 30 days past due; (d) An exposure in the form of a commitment that, were it drawn down or otherwise used, would likely not be paid back in full without realisation of collateral; (e) An exposure in form of a financial guarantee that is likely to be called by the guaranteed party, including where the underlying guaranteed exposure meets the criteria to be considered as non-performing. | E16: Banking Book: Financial Corporations, Non-Financial Corporations, Credit Institutions, Households (Commercial and Residential), General Governments | F16: Contract | G16: BDR Table: JM_CTO_AJ_REG Var: O9209_INDMORA1 | H16: No (esperaría que ya esté incluida) | J16: No | K16: Table: cd_captools.fr004_cto Var: stage_atual | L16: Risk | M16: T1 T5 | N16: CESG_CNAE_ESG | Q16: x
A17: 13 | B17: All | C17: Gross carrying amount | D17: Exposures must be reported on a gross carrying amount basis | E17: Banking Book: Financial Corporations, Non-Financial Corporations, Credit Institutions, Households (Commercial and Residential), General Governments | F17: Contract | G17: This metric has been requested to be included in BDR. Comments on whether or not they will be included are pending. All units will be notified as soon as we receive it. | H17: No (esperaría que ya esté incluida) | J17: No | K17: Table: cd_captools.fr004_cto Var: valor_bruto_on_a | L17: Accounting | M17: T1, T2, T3, T4, T5, T6, T7, T8, T9, T10 | N17: CESG_CNAE_ESG ENPC_Energy_Performance_Certificate MITI_Mitigation actions GARB_GAR & BTAR GHGE_GHG Financed emissions | Q17: x
A18: 14 | B18: All | C18: Main NACE code | D18: National Classification of Economic Activities, prepared according to the conditions contained in the EC regulation 1893/2006 for the approval of the Statistical Nomenclature of Economic Activities of the European Community (NACE). The counterparty NACE sector allocation shall be based on the nature of the immediate counterparty. Each counterparty has to be mapped to one single sector based on its principle activity NACE code has to be completed with NACE level 4 detail | E18: Banking Book: Non-Financial Corporations | F18: Client | G18: BDR Table: JM_CLIENT_BII Var: G4093_COD_SECT | H18: Yes at a NACE4 level | J18: Yes | K18: Table: cd_captools.ct003_univ_cli Var: nace_code | L18: Accounting | M18: T1 T3 T5 T7 | N18: CESG_CNAE_ESG ENPC_Energy_Performance_Certificate GARB_GAR & BTAR GHGE_GHG Financed emissions | O18: Functional guidelines will be provided by HQ for sourcing this variable. | Q18: x | R18: Numeric | S18: -All codes are part of the reference Group list of NACE codes -Level 3 NACEs are required as a minimum. Level 4 is highly recommended (mandatory in future). | V18: Same as reported in FINREP | W18: Review with evidence of the total portfolio segmented by client relevance in which we see that the NACE is correct (external data, public information, risk analysts). Ensure that the NACE described is aligned with the main activity of the company
A19: 15 | B19: All | C19: NACE Code ESG | D19: The counterparty NACE sector allocation shall be based on the nature of the immediate counterparty. When the counterparty is a holding company, institutions shall consider the NACE sector of the specific obligor under the holding company (if different than the holding company itself) which receives the funding (i.e., the specific subsidiary of the holding company in question) rather than that of the holding company; particularly in those cases where the obligor that is benefiting from the financing is a non-financial corporate. Similarly, when the direct counterparty (the obligor) is a special purpose vehicle (SPV), institution shall disclose the relevant information under the NACE sector associated with the economic activity of the parent company of the SPV. The classification of the exposures incurred jointly by more than one obligor shall be done based on the characteristics of the obligor that was the more relevant, or determinant, for the institution to grant the exposure. The distribution of jointly incurred exposures by NACE codes shall be driven by the characteristics of the more relevant or determinant obligor. NACE code ESG has to be completed with NACE level 4 detail | E19: Banking Book: Non-Financial Corporations | F19: Client | G19: This metric has been requested to be included in BDR. Comments on whether or not they will be included are pending. All units will be notified as soon as we receive it. | H19: Yes | J19: Yes | K19: Table: cd_captools.ct003_univ_cli Var: nace_code | L19: Accounting | M19: T1 T3 T5 T7 | N19: CESG_CNAE_ESG ENPC_Energy_Performance_Certificate GARB_GAR & BTAR GHGE_GHG Financed emissions | O19: Functional guidelines will be provided by HQ for sourcing this variable. | Q19: x | R19: Numeric | S19: -All codes are part of the reference Group list of NACE codes -Level 4 NACEs are required as a minimum. | V19: Same as reported in FINREP unless Counterparty under SPV or Holding Company with different NACE | W19: Review with evidence of the total portfolio segmented by client relevance in which we see that the NACE is correct (external data, public information, risk analysts). Ensure that the NACE described is aligned with the main activity of the company
A20: 16 | B20: All | C20: % Collateralised | D20: Percentage of the gross carrying amount of the collateral that can be considered arising from loans collateralised by residential or commercial immovable property. Residential property is defined as a residence which is occupied by the owner or the lessee of the residence, including the right to inhabit an apartment in housing cooperatives located in Sweden. Loans collateralised by comercial immovable property shall include loans secured by pledges of immovable property other than residential, including offices and commercial premises and other types of commercial immovable property. | E20: Banking Book: Households (Commercial and Residential) and Repossessed Collaterals | F20: Contract | G20: BDR: Table:(JM_GARANT_CTO) Var:(G4124_PORCOBER) | H20: No (esperaría que ya esté incluida) | J20: No | K20: Table: cd_garantias.gt018_rateio_aval Var: per_cobert | L20: CDO | M20: T2 T5 T6 T7 T8 T9.1 T9.2 | N20: CESG_CNAE_ESG ENPC_Energy_Performance_Certificate MITI_Mitigation actions GARB_GAR & BTAR | Q20: x
A21: 17 | B21: All | C21: Accumulated impairment | D21: Accumulated changes in fair value due to credit risk where the accumulated net change is negative. The accumulated net change in fair value due to credit risk shall be calculated by adding all negative and positive changes in fair value due to credit risk that have occurred since recognition of the debt instrument. That amount shall only be reported where the addition of positive and negative changes in fair value due to credit risk results in a negative amount. The valuation of the debt instruments shall be performed on the level of single financial instruments. | E21: Banking Book: Financial Corporations, Non-Financial Corporations, Credit Institutions, Households (Commercial and Residential), General Governments | F21: Contract | G21: BDR: Table: JM_CTO_AJ_REG Var: O9209_IPROVISI | H21: No (esperaría que ya esté incluida) | J21: No | K21: Table: cd_captools.fr004_cto Var: provisao | L21: Risk | M21: T1 T5 | N21: CESG_CNAE_ESG | Q21: x
A22: 18 | B22: All | C22: Type of activity | D22: Transitional activity: must not have a technologically and economically feasible low-carbon alternative but supports the transition to a climate-neutral economy consistent with a pathway to limit the temperature increase to 1,5 ºC above pre- industrial levels, including by phasing out greenhouse gas emissions, in particular emissions from solid fossil fuels, and where that activity: (a) has greenhouse gas emission levels that correspond to the best performance in the sector or industry; (b) does not hamper the development and deployment of low-carbon alternatives; and (c) does not lead to a lock-in of carbon-intensive assets, considering the economic lifetime of those assets. This kind of activity shall also qualify as contributing substantially to the objective of climate change mitigation Adaptation activity: (a) include adaptation solutions that either substantially reduce the risk of the adverse impact of the current climate and the expected future climate on that economic activity or substantially reduce that adverse impact, without increasing the risk of an adverse impact on people, nature or assets; or (b) provides adaptation solutions that, in addition to satisfying the conditions set out in Article 16, contribute substantially to preventing or reducing the risk of the adverse impact of the current climate and the expected future climate on people, nature or assets, without increasing the risk of an adverse impact on other people, nature or assets. This kind of activity shall also qualify as contributing substantially to the objective of climate change adaptation Enabling activity: must be contributing substantially to one or more of the environmental objectives set out in the Taxonomy Regulation by directly enabling other activities to make a substantial contribution to one or more of those objectives, provided that such economic activity: (a) does not lead to a lock-in of assets that undermine long-term environmental goals, considering the economic lifetime of those assets; and (b) has a substantial positive environmental impact, on the basis of life-cycle considerations. This kind of activity shall also qualify as contributing substantially to the objective of climate change mitigation or adaptation None of these activities: If none of this characteristics apply | E22: Banking Book: Financial Corporations, Non-Financial Corporations, Credit Institutions, Households (Commercial and Residential), General Governments | F22: Contract | G22: This metric has been requested to be included in BDR. Comments on whether or not they will be included are pending. All units will be notified as soon as we receive it. | H22: Yes | J22: No | K22: TBD | L22: TBD | M22: T7 T8 T9.1 T9.2 T9.3 | N22: GARB_GAR & BTAR | O22: Functional guidelines will be provided by HQ for sourcing this variable. | Q22: x
A23: 19 | B23: All | C23: Type of asset | D23: Breakdown of immovable properties obtained by taking posession, distinguising: - Residential property. Residential property is defined as a residence which is occupied by the owner or the lessee of the residence, including the right to inhabit an apartment in housing cooperatives located in Sweden. - Commercial property. Immovable property other than residential, including offices and commercial premises and other types of commercial immovable property - Other. When a collateral is neither classified as residential nor commercial property. | E23: Banking Book: Repossessed Collaterals | F23: Contract | G23: BDR Table: JM_INM_POSADJ Var: O9220_TIP_ACT | H23: No (esperaría que ya esté incluida) | J23: No | K23: Table: cd_garantias.gt009_bens_imov Var: cfinbem, ctipbem | L23: CDO | M23: T2 T5 T6 T7 T8 T9.1 T9.2 T9.3 | N23: CESG_CNAE_ESG ENPC_Energy_Performance_Certificate GARB_GAR & BTAR | Q23: x
A24: 20 | B24: All | C24: Flag: Companies excluded from EU Paris-aligned benchmarks | D24: This flag allows to identify which counterparties that are excluded from the EU Paris-aligned Benchmarks as specified in Article 12.1, points (d) to (g) and Article 12.2 of Commission Delegated Regulation (EU) 2020/1818: d) companies that derive 1 % or more of their revenues from exploration, mining, extraction, distribution or refining of hard coal and lignite; (e) companies that derive 10 % or more of their revenues from the exploration, extraction, distribution or refining of oil fuels; (f) companies that derive 50 % or more of their revenues from the exploration, extraction, manufacturing or distribution of gaseous fuels; (g) companies that derive 50 % or more of their revenues from electricity generation with a GHG intensity of more than 100 g CO2 e/kWh. Companies to significantly harm one or more of the environmental objectives referred to in Article 9 of Regulation (EU) 2020/852 of the European Parliament and of the Council (8), in accordance with the rules on estimations laid down in Article 13(2) of this Regulation | E24: Banking Book: Non-Financial Corporations | F24: Client | G24: This metric has been requested to be included in BDR. Comments on whether or not they will be included are pending. All units will be notified as soon as we receive it. | H24: Yes | I24: S&P | J24: No | K24: File provided by HQ | L24: N/A | M24: T1 | N24: CESG_CNAE_ESG | O24: Functional guidelines will be provided by HQ for sourcing this variable. | Q24: x
A25: 21 | B25: All | C25: Flag of NFRD applicability | D25: This flag allows to identify if the NFRD is applicable: '- NFCs subject to NFRD disclosure obligations. Large corporations and quasi-corporations not engaged in financial intermediation but principally in the production of market goods and non-financial services, considered public interest entities exceeding on their balance sheet dates the criterion of the average number of 500 employees during the financial year. '- SMEs and NFC (other than SMEs) not subject to NFRD disclosure obligations. For disclosures involving corporates not subject to NFRD disclosure obligations, including SMEs, when assessing general purpose lending/financing with unknown use of proceeds, institutions shall follow a simplified approach and focus their assessment on the main economic activity of the corporate, that is, on their main source of turnover, in order to determine the overall alignment of the exposures with the Taxonomy Regulation. In the case of specialised lending the assessment shall be based on the extent and proportion to which the specific project funded qualify as contributing substantially to climate change mitigation or adaptation (project specific information). | E25: Banking Book: Non-Financial Corporations | F25: Client | G25: This metric has been requested to be included in BDR. Comments on whether or not they will be included are pending. All units will be notified as soon as we receive it. | H25: Yes | J25: No | K25: TBD | L25: TBD | M25: T6 T7 T8 T9.1 T9.2 T9.3 | N25: GARB_GAR & BTAR | O25: Functional guidelines will be provided by HQ for sourcing this variable. | Q25: x
A26: 22 | B26: For units in Europe | C26: Geography of the counterparty: NUTS | D26: Location of the counterparty's country, geographical or administrative region (maximum level of available breakdown) where activities of the counterparty are located. For EU countries + UK the level of divisions indicated in Nomenclature of Territorial Units for Statistics (NUTS) shall be used. The NUTS classification is a hierarchical system for dividing up the economic territory of the EU and the UK: - NUTS 1: major socio-economic regions - NUTS 2: basic regions for the application of regional policies - NUTS 3: small regions for specific diagnoses In the following link NUTs codes are available: https://ec.europa.eu/eurostat/documents/3859598/10967554/KS-GQ-20-092-EN-N.pdf/9d57ae79-3ee7-3c14-da3e-34726da385cf?t=1591285035000 For non EU countries equivalent classification shall be used. | E26: Banking Book: Non-Financial Corporation, Households (Commercial and Residential) and Repossessed Collaterals | F26: Client | G26: This metric has been requested to be included in BDR. Comments on whether or not they will be included are pending. All units will be notified as soon as we receive it. | H26: Yes | J26: Yes | K26: Table: cd_estruturais.tat91_tables where tayd91c0_ctable = 'J48' Var: tayd91c0_nelemc05 | L26: CDO | M26: T5 | N26: CESG_CNAE_ESG | Q26: x | R26: Numeric | S26: All codes are part of the reference pre-defined list of values (NUT3, Postal Code or equivalent)
A27: 23 | B27: All | C27: Geography of the counterparty: ZIP Code | D27: Postal Code associated to the location of the counterparty's country, geographical or administrative region where activities of the counterparty are located. | E27: Banking Book: Non-Financial Corporation, Households (Commercial and Residential) and Repossessed Collaterals | F27: Client | G27: BDR Table: JM_CLIENT_BII Var: G4093_CDPOSTAL | H27: Yes | J27: Yes | K27: Table cd_estruturais.interface_moradas Var: clyr7003_cpostal + clyr7003_cp3 | L27: CDO | M27: T2, T5 | N27: CESG_CNAE_ESG ENPC_Energy_Performance_Certificate | Q27: x | R27: Numeric | S27: All codes are part of the reference pre-defined list of values (NUT3, Postal Code or equivalent)
A28: 24 | B28: Not necessary at the moment. Having the zip code or the NUTS is enough | C28: Geography of the counterparty: Full Address | D28: Full address associated to the location of the counterparty's country, geographical or administrative region where activities of the counterparty are located. | E28: Banking Book: Non-Financial Corporation, Households (Commercial and Residential) and Repossessed Collaterals | F28: Client | G28: This metric has been requested to be included in BDR. Comments on whether or not they will be included are pending. All units will be notified as soon as we receive it. | H28: Yes | J28: No | K28: TBD | L28: TBD | M28: T2, T5 | N28: CESG_CNAE_ESG ENPC_Energy_Performance_Certificate | Q28: x | R28: Numeric | S28: All codes are part of the reference pre-defined list of values (NUT3, Postal Code or equivalent)
A29: 25 | B29: All | C29: GHG Reported Emissions - scope 1: flag original / calculated | D29: This flag allows to identify if the data is original data refered to counterparties’ scope 1 emissions associated with lending and investment activities based on information disclosed by the Group's counterparties or reported to the Group on bilateral basis. | E29: Banking Book: Non-Financial Corporations | F29: Client | G29: This metric has been requested to be included in BDR. Comments on whether or not they will be included are pending. All units will be notified as soon as we receive it. | H29: Yes | I29: CDP & PCAF | J29: No | K29: TBD | L29: TBD | M29: T1 | N29: GHGE_GHG Financed emissions | O29: Functional guidelines will be provided by HQ for sourcing this variable. | Q29: x
A30: 26 | B30: All | C30: GHG Reported Emissions - scope 2: flag original / calculated | D30: This flag allows to identify if the data is original data refered to counterparties’ scope 2 emissions associated with lending and investment activities based on information disclosed by the Group's counterparties or reported to the Group on bilateral basis. | E30: Banking Book: Non-Financial Corporations | F30: Client | G30: This metric has been requested to be included in BDR. Comments on whether or not they will be included are pending. All units will be notified as soon as we receive it. | H30: Yes | I30: CDP & PCAF | J30: No | K30: TBD | L30: TBD | M30: T1 | N30: GHGE_GHG Financed emissions | O30: Functional guidelines will be provided by HQ for sourcing this variable. | Q30: x
A31: 27 | B31: All | C31: GHG Reported Emissions - scope 3: flag original / calculated | D31: This flag allows to identify if the data is original data refered to counterparties’ scope 3 emissions associated with lending and investment activities based on information disclosed by the Group's counterparties or reported to the Group on bilateral basis. | E31: Banking Book: Non-Financial Corporations | F31: Client | G31: This metric has been requested to be included in BDR. Comments on whether or not they will be included are pending. All units will be notified as soon as we receive it. | H31: Yes | I31: CDP & PCAF | J31: No | K31: TBD | L31: TBD | M31: T1 | N31: GHGE_GHG Financed emissions | O31: Functional guidelines will be provided by HQ for sourcing this variable. | Q31: x
A32: 28 | B32: All | C32: Maturity | D32: End date of the financial instrument, taking into account the following: i) Where the amount is repaid in instalments, date corresponding to the last instalment; ii) Where an exposure has no stated maturity for reasons other than the counterparty having the choice of the repayment date, or in the case of equity holdings, do not report (leave blank); | E32: Banking Book: Non-Financial Corporation, Households (Commercial and Residential) and Repossessed Collaterals | F32: Contract | G32: BDR Table: JM_CTO_AJ_REG Var: O9209_MATUPOSM | H32: No (esperaría que ya esté incluida) | J32: No | K32: Table: cd_captools.fr004_cto Var: data_vencimento | L32: N/A | M32: T1 T4 T5 | N32: CESG_CNAE_ESG | O32: Functional guidelines will be provided by HQ for sourcing this variable. | Q32: x
A33: 29 | B33: All | C33: Flag of specialised lending | D33: This flag allows to identify specialised lending transactions. Specialised lending or project finance transactions refer to those exposures which possess the following characteristics: (a) the exposure is to an entity which was created specifically to finance or operate physical assets or is an economically comparable exposure; (b) the contractual arrangements give the lender a substantial degree of control over the assets and the income that they generate; (c) the primary source of repayment of the obligation is the income generated by the assets being financed, rather than the independent capacity of a broader commercial enterprise. | E33: Banking Book: Financial Corporations, Non-Financial Corporations, Credit Institutions, Households (Commercial and Residential), General Governments | F33: Contract | G33: BDR Table: JM_CTO_AJ_REG Var: O9209_CAT_MSTA | H33: No (esperaría que ya esté incluida) | J33: No | K33: Table: cd_captools.fr004_cto Var: flag_project_finance | L33: Accounting | M33: T7 T8 T9.1 T9.2 T9.3 | N33: GARB_GAR & BTAR | Q33: x | S33: Possible values: 0,1 | V33: Same as reported in FINREP
A34: 30 | B34: All | C34: Stage 2 IFRS 9 | D34: Credit risk classification of exposure, as defined in IFRS 9. | E34: Banking Book: Financial Corporations, Non-Financial Corporations, Credit Institutions, Households (Commercial and Residential), General Governments | F34: Contract | G34: BDR Table: JM_CTO_STAGE Var: T2420_STAGEFIN | H34: No (esperaría que ya esté incluida) | J34: No | K34: Table: cd_captools.fr004_cto Var: stage_atual | L34: Risk | M34: T1 T5 | N34: CESG_CNAE_ESG | Q34: x
A35: 31 | B35: All | C35: Taken possession | D35: Identifier of residential and commercial immovable properties obtained by taking possession | E35: Banking Book: Repossessed Collaterals | F35: Collateral | G35: This metric has been requested to be included in BDR. Comments on whether or not they will be included are pending. All units will be notified as soon as we receive it. | H35: No (esperaría que ya esté incluida) | J35: No | K35: DL Capital Tools Table: cd_captools.fr802_pl_contas All operations with : tipo_conta = 'A' and carteira_contabilistica = 'ativos nao correntes detidos para venda' and conta in ('191000', '1991000', '19910024') | L35: Recuperações/Desinvestimento | M35: T2 T5 T6 T7 T8 T9.1 T9.2 T9.3 | N35: ENPC_Energy_Performance_Certificate CESG_CNAE_ESG GARB_GAR & BTAR | Q35: x
A36: 32 | B36: All | C36: Type of collateral | D36: Breakdown of pledges backing loans, distinguising: - Residential property. Residential property is defined as a residence which is occupied by the owner or the lessee of the residence, including the right to inhabit an apartment in housing cooperatives located in Sweden. - Commercial property. Immovable property other than residential, including offices and commercial premises and other types of commercial immovable property - Other. When a collateral is neither classified as residential nor commercial property. | E36: Banking Book: Households (Commercial and Residential) | F36: Contract | G36: BDR Table: JM_INMUEBLES Var: O9270_TIP_PPDA | H36: No (esperaría que ya esté incluida) | J36: No | K36: Table: cd_captools.fr801_tip_garan Var: subtipo_garantia | L36: Accounting | M36: T2 T5 T6 T7 T8 T9.1 T9.2 T9.3 | N36: CESG_CNAE_ESG ENPC_Energy_Performance_Certificate GARB_GAR & BTAR | Q36: x
A37: 33 | B37: All | C37: Type of counterparty | D37: Breakdown of information by type of counterparty, including: - Financial corporations (FC) -- Credit institutions -- Other financial corporations --- Of which investment firms --- Of which management companies --- Of which insurance undertakings - Non Financial corporations (NFC) - Households - Local governments | E37: Banking Book: Financial Corporations, Non-Financial Corporations, Credit Institutions, Households (Commercial and Residential), General Governments | F37: Client | G37: BDR Table: JM_CLIGLO_CUA Var: T2888_TIPENTID | H37: No (esperaría que ya esté incluida) | J37: No | K37: Table: cd_captools.fr004_cto Var: contraparte | L37: Accounting | M37: T1 T2 T3 T5 T6 T7 T8 T9.1 T9.2 T9.3 T10 | N37: CESG_CNAE_ESG ENPC_Energy_Performance_Certificate GARB_GAR & BTAR MITI_Mitigation actions | Q37: x
A38: 34 | B38: All | C38: Type of product | D38: - Loans and advances: debt instruments held by the institutions that are not securities. That item includes loans as well as advances that cannot be classified as “loans”. - Debt securities: debt instruments held by the institution issued as securities that are not loans - Equity instruments: any contract that evidences an interest in the asset of an entity. | E38: Banking Book: Financial Corporations, Non-Financial Corporations, Credit Institutions, Households (Commercial and Residential), General Governments | F38: Contract | G38: This metric has not been requested to be included in BDR for this evolution of the model. It will be requested next year for the following evolution. Until then, this information should be stored in local systems. All units will be notified as soon as we receive it. | H38: No (esperaría que ya esté incluida) | J38: No | K38: DL Capital Tools Table: cd_captools.fr802_pl_contas All operations with : tipo_conta = 'A' and 1) Intrumento financeiro = 'credito concedido e outros ativos financeiros' => Loans and advances (F18) 2) Intrumento financeiro = 'instrumentos de capital' => Debt securities (F18) 3) Intrumento financeiro = 'instrumentos de divida' => Equity instruments (F04) | L38: Accounting | M38: T2 T6 T7 T8 T9.1 T9.2 T9.3 T10 | N38: ENPC_Energy_Performance_Certificate GARB_GAR & BTAR MITI_Mitigation actions | Q38: x
A39: 35 | B39: All | C39: Climate change physical risk | D39: Type of climate risk that is being mitigated with a specific loan or debt: climate change physical risk. ‘Physical risk’, is defined as the risk of losses arising from any negative financial impact on the institution stemming from the current or prospective impacts of the physical effects of environmental factors on the institution’s counterparties or invested assets. | E39: Banking Book: Non-Financial Corporation, Households (Commercial and Residential) and Repossessed Collaterals | F39: Contract | G39: This metric has not been requested to be included in BDR for this evolution of the model. It will be requested next year for the following evolution. Until then, this information should be stored in local systems. All units will be notified as soon as we receive it. | H39: Yes | I39: Munich RE | J39: No | K39: File provided by HQ | L39: N/A | M39: T10 | N39: MITI_Mitigation actions | O39: Functional guidelines will be provided by HQ for sourcing this variable. | Q39: x
A40: 36 | B40: All | C40: Climate change transition risk | D40: Type of climate risk that is being mitigated with a specific loan or debt: climate change transition risk. 'Transition risk’ is defined as the risk of losses arising from any negative financial impact on the institution stemming from the current or prospective impacts of the transition to an environmentally sustainable economy on its counterparties or invested assets. | E40: Banking Book: Non-Financial Corporation, Households (Commercial and Residential) and Repossessed Collaterals | F40: Contract | G40: This metric has not been requested to be included in BDR for this evolution of the model. It will be requested next year for the following evolution. Until then, this information should be stored in local systems. All units will be notified as soon as we receive it. | H40: Yes | I40: Munich RE | J40: No | K40: File provided by HQ | L40: N/A | M40: T10 | N40: MITI_Mitigation actions | O40: Functional guidelines will be provided by HQ for sourcing this variable. | Q40: x
...

Sheet Sheet1
B2: Banking Book: Non-Financial Corporation
B3: Banking Book: Non-Financial Corporation, Households (Commercial and Residential) and Repossessed Collaterals
B4: Banking Book: Households (Commercial and Residential) and Repossessed Collaterals
B5: Banking Book: Financial Corporations, Non-Financial Corporations, Credit Institutions, Households (Commercial and Residential), General Governments
B6: Banking Book: Non-Financial Corporations
B7: Banking Book: Repossessed Collaterals
B8: Banking Book: Households (Commercial and Residential)

Sheet 2. Track Changes V4
B2: Track changes v4
B3: Campo | C3: Cambios (ES)
B4: Cadastral ID | C4: Quitamos la métrica porque es para estimación de EPCs
B5: Year of construction | C5: Quitamos la métrica porque es para estimación de EPCs
B6: Floor | C6: Quitamos la métrica porque es para estimación de EPCs
B7: Type of reform | C7: Quitamos la métrica porque es para estimación de EPCs
B8: Year of renovation | C8: Quitamos la métrica porque es para estimación de EPCs
B9: Climate zone | C9: Quitamos la métrica porque es para estimación de EPCs
B10: Altitude | C10: Quitamos la métrica porque es para estimación de EPCs
B11: Inhabitants | C11: Quitamos la métrica porque es para estimación de EPCs
B12: Income | C12: Quitamos la métrica porque es para estimación de EPCs
B13: Taxpayers | C13: Quitamos la métrica porque es para estimación de EPCs
B14: Gross carrying amount | C14: Añadimos su uso en las templates 5 y 10
... B42: Risk Mitigated CCP | C42: Quitamos debido a estar duplicada con Climate change physical risk

Sheet 2) Check dicc. y satelites 
B2: ID Metric | C2: Metric | D2: CAMBIOS | E2: Metric Name
B3: =+VLOOKUP(E3,'3) Todos satelites '!$C$6:$F$58,4,0) -> #N/A | C3: 1 | E3: GHG Financed Emissions: Scope 1
B4: =+VLOOKUP(E4,'3) Todos satelites '!$C$6:$F$58,4,0) -> #N/A | C4: 2 | E4: GHG Financed Emissions: Scope 2
B5: =+VLOOKUP(E5,'3) Todos satelites '!$C$6:$F$58,4,0) -> #N/A | C5: 3 | E5: GHG Financed Emissions: Scope 3
B6: =+VLOOKUP(E6,'3) Todos satelites '!$C$6:$F$58,4,0) -> #N/A | C6: 4 | E6: Geography of the collateral: NUTS
B7: =+VLOOKUP(E7,'3) Todos satelites '!$C$6:$F$58,4,0) -> #N/A | C7: 5 | E7: Geography of the collateral: ZIP Code
B8: =+VLOOKUP(E8,'3) Todos satelites '!$C$6:$F$58,4,0) -> #N/A | C8: 6 | D8: Si ya tenemos el NUTS y el Zip, queremos el address? | E8: Geography of the collateral: Full Address
B9: =+VLOOKUP(E9,'3) Todos satelites '!$C$6:$F$58,4,0) -> EPCL | C9: 7 | E9: EPC label
B10: =+VLOOKUP(E10,'3) Todos satelites '!$C$6:$F$58,4,0) -> EPSC | C10: 8 | E10: EP Score
B11: =+VLOOKUP(E11,'3) Todos satelites '!$C$6:$F$58,4,0) -> #N/A | C11: 9 | E11: EPC Label: Flag original / calculated
B12: =+VLOOKUP(E12,'3) Todos satelites '!$C$6:$F$58,4,0) -> #N/A | C12: 10 | E12: EP Score: Flag original / calculated
B13: =+VLOOKUP(E13,'3) Todos satelites '!$C$6:$F$58,4,0) -> #N/A | C13: 11 | D13: Se pueden usar para calcular las emisiones financiadas para CRE. Si no calculamos emisiones para esta cartera, no es una métrica necesaria | E13: EPC CO2 emissions
B14: =+VLOOKUP(E14,'3) Todos satelites '!$C$6:$F$58,4,0) -> #N/A | C14: 12 | E14: Non-performing
B15: =+VLOOKUP(E15,'3) Todos satelites '!$C$6:$F$58,4,0) -> #N/A | C15: 13 | E15: Gross carrying amount
B16: =+VLOOKUP(E16,'3) Todos satelites '!$C$6:$F$58,4,0) -> #N/A | C16: 14 | E16: Main NACE code
B17: =+VLOOKUP(E17,'3) Todos satelites '!$C$6:$F$58,4,0) -> NACE | C17: 15 | E17: NACE Code ESG
B18: =+VLOOKUP(E18,'3) Todos satelites '!$C$6:$F$58,4,0) -> #N/A | C18: 16 | E18: % Collateralised
B19: =+VLOOKUP(E19,'3) Todos satelites '!$C$6:$F$58,4,0) -> #N/A | C19: 17 | E19: Accumulated impairment
B20: =+VLOOKUP(E20,'3) Todos satelites '!$C$6:$F$58,4,0) -> #N/A | C20: 18 | E20: Type of activity
B21: =+VLOOKUP(E21,'3) Todos satelites '!$C$6:$F$58,4,0) -> #N/A | C21: 19 | E21: Type of asset
B22: =+VLOOKUP(E22,'3) Todos satelites '!$C$6:$F$58,4,0) -> #N/A | C22: 20 | E22: Flag: Companies excluded from EU Paris-aligned benchmarks
B23: =+VLOOKUP(E23,'3) Todos satelites '!$C$6:$F$58,4,0) -> #N/A | C23: 21 | E23: Flag of NFRD applicability
B24: =+VLOOKUP(E24,'3) Todos satelites '!$C$6:$F$58,4,0) -> #N/A | C24: 22 | E24: Geography of the counterparty: NUTS
B25: =+VLOOKUP(E25,'3) Todos satelites '!$C$6:$F$58,4,0) -> #N/A | C25: 23 | E25: Geography of the counterparty: ZIP Code
B26: =+VLOOKUP(E26,'3) Todos satelites '!$C$6:$F$58,4,0) -> #N/A | C26: 24 | D26: Si ya tenemos el NUTS y el Zip, queremos el address? | E26: Geography of the counterparty: Full Address
B27: =+VLOOKUP(E27,'3) Todos satelites '!$C$6:$F$58,4,0) -> #N/A | C27: 25 | E27: GHG Reported Emissions - scope 1: flag original / calculated
B28: =+VLOOKUP(E28,'3) Todos satelites '!$C$6:$F$58,4,0) -> #N/A | C28: 26 | E28: GHG Reported Emissions - scope 2: flag original / calculated
B29: =+VLOOKUP(E29,'3) Todos satelites '!$C$6:$F$58,4,0) -> #N/A | C29: 27 | E29: GHG Reported Emissions - scope 3: flag original / calculated
B30: =+VLOOKUP(E30,'3) Todos satelites '!$C$6:$F$58,4,0) -> #N/A | C30: 28 | E30: Maturity
B31: =+VLOOKUP(E31,'3) Todos satelites '!$C$6:$F$58,4,0) -> #N/A | C31: 29 | E31: Flag of specialised lending
B32: =+VLOOKUP(E32,'3) Todos satelites '!$C$6:$F$58,4,0) -> #N/A | C32: 30 | E32: Stage 2 IFRS 9
B33: =+VLOOKUP(E33,'3) Todos satelites '!$C$6:$F$58,4,0) -> #N/A | C33: 31 | E33: Taken possession
B34: =+VLOOKUP(E34,'3) Todos satelites '!$C$6:$F$58,4,0) -> #N/A | C34: 32 | E34: Type of collateral
B35: =+VLOOKUP(E35,'3) Todos satelites '!$C$6:$F$58,4,0) -> #N/A | C35: 33 | E35: Type of counterparty
B36: =+VLOOKUP(E36,'3) Todos satelites '!$C$6:$F$58,4,0) -> #N/A | C36: 34 | E36: Type of product
B37: =+VLOOKUP(E37,'3) Todos satelites '!$C$6:$F$58,4,0) -> #N/A | C37: 35 | E37: Climate change physical risk
B38: =+VLOOKUP(E38,'3) Todos satelites '!$C$6:$F$58,4,0) -> #N/A | C38: 36 | E38: Climate change transition risk
... B92: =+VLOOKUP(E92,'3) Todos satelites '!$C$6:$F$58,4,0) -> RMCP | C92: 90 | E92: Risk Mitigated CCP
B93: =+VLOOKUP(E93,'3) Todos satelites '!$C$6:$F$58,4,0) -> INC | E93: Interest commisions
B94: =+VLOOKUP(E94,'3) Todos satelites '!$C$6:$F$58,4,0) -> GEO | E94: Physical risk_Geographical Area
...

Sheet 3) Todos satelites 
C2: Metricas encontradas con nombre similares
C3: Metricas con nombre diferentes o no encontradas
B5: ID | C5: Metric | D5: ID | E5: ENCONTRADO EN DICCIONARIO | F5: ID
B6: INC | C6: Interest commisions | D6: INC | E6: =+VLOOKUP(C6,'2) Check dicc. y satelites '!$E$3:$E$95,1,0) -> Interest commisions | F6: INC
B7: EU | C7: European Union | D7: EU | E7: No need | F7: EU
B8: GEO | C8: Physical risk_Geographical Area | D8: GEO | E8: =+VLOOKUP(C8,'2) Check dicc. y satelites '!$E$3:$E$95,1,0) -> Physical risk_Geographical Area | F8: GEO
B9: CNAEL | C9: NACE_Level1 | D9: CNAEL | E9: =+VLOOKUP(C9,'2) Check dicc. y satelites '!$E$3:$E$95,1,0) -> NACE_Level1 | F9: CNAEL
B10: NACE | C10: NACE Code ESG | D10: NACE | E10: =+VLOOKUP(C10,'2) Check dicc. y satelites '!$E$3:$E$95,1,0) -> NACE Code ESG | F10: NACE
B11: EXC | C11: Excluded from EU Paris-aligned benchmark | D11: EXC | E11: =+'2) Check dicc. y satelites '!E22 -> Flag: Companies excluded from EU Paris-aligned benchmarks | F11: EXC
B12: ENSM | C12: Environmentally sustainable CCM | D12: ENSM | E12: =+'2) Check dicc. y satelites '!E62 -> Environmentally sustainable activity | F12: ENSM
B13: GEO | C13: Physical risk_Geographical Area | D13: GEO | E13: =+VLOOKUP(C13,'2) Check dicc. y satelites '!$E$3:$E$95,1,0) -> Physical risk_Geographical Area | F13: GEO
B14: CHRO | C14: Chronic changes | D14: CHRO | E14: =+'2) Check dicc. y satelites '!E83 -> Sensitive to impact from chronic climate change events | F14: CHRO
B15: ACUT | C15: Acute changes | D15: ACUT | E15: =+'2) Check dicc. y satelites '!E82 -> Sensitive to impact from acute climate change events | F15: ACUT
B16: MESG | C16: Maturity ESG | D16: MESG | E16: =+'2) Check dicc. y satelites '!E30 -> Maturity | F16: MESG
B17: CNAEL | C17: NACE_Level1 | D17: CNAEL | E17: =+VLOOKUP(C17,'2) Check dicc. y satelites '!$E$3:$E$95,1,0) -> NACE_Level1 | F17: CNAEL
B18: NACE | C18: NACE Code ESG | D18: NACE | E18: =+VLOOKUP(C18,'2) Check dicc. y satelites '!$E$3:$E$95,1,0) -> NACE Code ESG | F18: NACE
B19: AVEG | C19: Average weighted maturity | D19: AVEG | E19: Se calcula con MESG | F19: AVEG
B20: EPSD | C20: EP Score Data | D20: EPSD | E20: =+'2) Check dicc. y satelites '!E10 -> EP Score | F20: EPSD
B21: EPSC | C21: EP Score | D21: EPSC | E21: =+VLOOKUP(C21,'2) Check dicc. y satelites '!$E$3:$E$95,1,0) -> EP Score | F21: EPSC
B22: EPCD | C22: EPC Label Data | D22: EPCD | E22: =+'2) Check dicc. y satelites '!E9 -> EPC label | F22: EPCD
B23: EPCL | C23: EPC Label | D23: EPCL | E23: =+VLOOKUP(C23,'2) Check dicc. y satelites '!$E$3:$E$95,1,0) -> EPC label | F23: EPCL
B24: EU | C24: European Union | D24: EU | E24: No need | F24: EU
B25: GFI | C25: Green Financial Instrument | D25: GFI | E25: =+VLOOKUP(C25,'2) Check dicc. y satelites '!$E$3:$E$95,1,0) -> #N/A | F25: GFI
B26: PESG | C26: Purpose ESG | D26: PESG | E26: =+VLOOKUP(C26,'2) Check dicc. y satelites '!$E$3:$E$95,1,0) -> Purpose ESG | F26: PESG
B27: FUTY | C27: Funding type | D27: FUTY | E27: =+VLOOKUP(C27,'2) Check dicc. y satelites '!$E$3:$E$95,1,0) -> Funding Type | F27: FUTY
B28: RMCT | C28: Risk Mitigated CCT | D28: RMCT | E28: =+VLOOKUP(C28,'2) Check dicc. y satelites '!$E$3:$E$95,1,0) -> Risk Mitigated CCT | F28: RMCT
B29: RMCP | C29: Risk Mitigated CCP | D29: RMCP | E29: =+VLOOKUP(C29,'2) Check dicc. y satelites '!$E$3:$E$95,1,0) -> Risk Mitigated CCP | F29: RMCP
B30: DCON | C30: Comment | D30: DCON | E30: No need | F30: DCON
B31: ESGS | C31: ESG Subsector | D31: ESGS | E31: =+VLOOKUP(C31,'2) Check dicc. y satelites '!$E$3:$E$95,1,0) -> #N/A | F31: ESGS
B32: PESG | C32: Purpose ESG | D32: PESG | E32: =+VLOOKUP(C32,'2) Check dicc. y satelites '!$E$3:$E$95,1,0) -> Purpose ESG | F32: PESG
B33: NFRD | C33: NFRD disclosures | D33: NFRD | E33: =+'2) Check dicc. y satelites '!E23 -> Flag of NFRD applicability | F33: NFRD
B34: EU | C34: European Union | D34: EU | E34: No need | F34: EU
B35: CCM | C35: Climate Change Mitigation | D35: CCM | E35: =+'2) Check dicc. y satelites '!E59 -> Environmental objective | F35: CCM
B36: CCA | C36: Climate Change Adaptation | D36: CCA | E36: =+'2) Check dicc. y satelites '!E59 -> Environmental objective | F36: CCA
B37: GSPUR | C37: General_Specific purpose | D37: GSPUR | E37: =+VLOOKUP(C37,'2) Check dicc. y satelites '!$E$3:$E$95,1,0) -> #N/A | F37: GSPUR
B38: ENSM | C38: Environmentally sustainable CCM | D38: ENSM | E38: =+'2) Check dicc. y satelites '!E59 -> Environmental objective | F38: ENSM
B39: ENSA | C39: Environmentally sustainable CCA | D39: ENSA | E39: =+'2) Check dicc. y satelites '!E59 -> Environmental objective | F39: ENSA
B40: SPLE | C40: Specialised lending | D40: SPLE | E40: =+'2) Check dicc. y satelites '!E31 -> Flag of specialised lending | F40: SPLE
B41: TRNS | C41: Transitional | D41: TRNS | E41: =+VLOOKUP(C41,'2) Check dicc. y satelites '!$E$3:$E$95,1,0) -> #N/A | F41: TRNS
B42: ENAB | C42: Enabling CCM | D42: ENAB | E42: =+VLOOKUP(C42,'2) Check dicc. y satelites '!$E$3:$E$95,1,0) -> #N/A | F42: ENAB
...
