Workbook

Sheet 1. Status Resumo
D11: Resumo de Testes
D13: Streams | F13: Semana Atual | L13: Highlights
F14: Por iniciar | G14: Em curso | H14: Concluído | I14: Com Incidências | J14: Pendente de desenvolv.
C15: A. Novos Campos | D15: B02.00
C16: B1. Re-especificação de campos de Sindicados | D16: Loan Tape | F16: =COUNTIFS('2. Status Detalhe Campos'!B:B,"B02.00",'2. Status Detalhe Campos'!C:C,"Loan Tape",'2. Status Detalhe Campos'!J:J,'1. Status Resumo'!$F$14) -> 0 | G16: =COUNTIFS('2. Status Detalhe Campos'!B:B,"B02.00",'2. Status Detalhe Campos'!C:C,"Loan Tape",'2. Status Detalhe Campos'!J:J,'1. Status Resumo'!$G$14) -> 12 | H16: =COUNTIFS('2. Status Detalhe Campos'!B:B,"B02.00",'2. Status Detalhe Campos'!C:C,"Loan Tape",'2. Status Detalhe Campos'!J:J,'1. Status Resumo'!$H$14) -> 6 | I16: =COUNTIFS('2. Status Detalhe Campos'!B:B,"B02.00",'2. Status Detalhe Campos'!C:C,"Loan Tape",'2. Status Detalhe Campos'!J:J,'1. Status Resumo'!$I$14) -> 7 | J16: =COUNTIFS('2. Status Detalhe Campos'!B:B,"B02.00",'2. Status Detalhe Campos'!C:C,"Loan Tape",'2. Status Detalhe Campos'!J:J,'1. Status Resumo'!$J$14) -> 3 | K16: =SUM(F16:J16) -> 28
C17: B2. Re-especificação de outros campos | D17: Tabela Output | F17: =COUNTIFS('2. Status Detalhe Campos'!B:B,"B02.00",'2. Status Detalhe Campos'!C:C,"Tabela Output",'2. Status Detalhe Campos'!J:J,'1. Status Resumo'!F14) -> 0 | G17: =COUNTIFS('2. Status Detalhe Campos'!B:B,"B02.00",'2. Status Detalhe Campos'!C:C,"Tabela Output",'2. Status Detalhe Campos'!J:J,'1. Status Resumo'!G14) -> 5 | H17: =COUNTIFS('2. Status Detalhe Campos'!B:B,"B02.00",'2. Status Detalhe Campos'!C:C,"Tabela Output",'2. Status Detalhe Campos'!J:J,'1. Status Resumo'!H14) -> 61 | I17: =COUNTIFS('2. Status Detalhe Campos'!B:B,"B02.00",'2. Status Detalhe Campos'!C:C,"Tabela Output",'2. Status Detalhe Campos'!J:J,'1. Status Resumo'!I14) -> 7 | J17: =COUNTIFS('2. Status Detalhe Campos'!B:B,"B02.00",'2. Status Detalhe Campos'!C:C,"Tabela Output",'2. Status Detalhe Campos'!J:J,'1. Status Resumo'!J14) -> 8 | K17: =SUM(F17:J17) -> 81
C18: F4. Fora âmbito | Re-especificação de campos complexos - Dem. Fin. CIB | D18: Total | F18: =SUM(F16:F17) -> 0 | G18: =SUM(G16:G17) -> 17 | H18: =SUM(H16:H17) -> 67 | I18: =SUM(I16:I17) -> 14 | J18: =SUM(J16:J17) -> 11 | K18: =SUM(F18:J18) -> 109
C19: C. Campos em testes ou c/ incidências | D19: B05.00
C20: D. Campos com NOK controlos Corporativos | D20: Loan Tape | F20: =COUNTIFS('2. Status Detalhe Campos'!B:B,"B05.00",'2. Status Detalhe Campos'!C:C,"Loan Tape",'2. Status Detalhe Campos'!J:J,'1. Status Resumo'!F14) -> 2 | G20: =COUNTIFS('2. Status Detalhe Campos'!B:B,"B05.00",'2. Status Detalhe Campos'!C:C,"Loan Tape",'2. Status Detalhe Campos'!J:J,'1. Status Resumo'!G14) -> 0 | H20: =COUNTIFS('2. Status Detalhe Campos'!B:B,"B05.00",'2. Status Detalhe Campos'!C:C,"Loan Tape",'2. Status Detalhe Campos'!J:J,'1. Status Resumo'!H14) -> 0 | I20: =COUNTIFS('2. Status Detalhe Campos'!B:B,"B05.00",'2. Status Detalhe Campos'!C:C,"Loan Tape",'2. Status Detalhe Campos'!J:J,'1. Status Resumo'!I14) -> 0 | J20: =COUNTIFS('2. Status Detalhe Campos'!B:B,"B05.00",'2. Status Detalhe Campos'!C:C,"Loan Tape",'2. Status Detalhe Campos'!J:J,'1. Status Resumo'!J14) -> 2 | K20: =SUM(F20:J20) -> 4
C21: E. Campos com outras possíveis alterações - Dependente de decisões OSI | D21: Tabela Output | F21: =COUNTIFS('2. Status Detalhe Campos'!B:B,"B05.00",'2. Status Detalhe Campos'!C:C,"Tabela Output",'2. Status Detalhe Campos'!J:J,'1. Status Resumo'!F14) -> 13 | G21: =COUNTIFS('2. Status Detalhe Campos'!B:B,"B05.00",'2. Status Detalhe Campos'!C:C,"Tabela Output",'2. Status Detalhe Campos'!J:J,'1. Status Resumo'!G14) -> 0 | H21: =COUNTIFS('2. Status Detalhe Campos'!B:B,"B05.00",'2. Status Detalhe Campos'!C:C,"Tabela Output",'2. Status Detalhe Campos'!J:J,'1. Status Resumo'!H14) -> 0 | I21: =COUNTIFS('2. Status Detalhe Campos'!B:B,"B05.00",'2. Status Detalhe Campos'!C:C,"Tabela Output",'2. Status Detalhe Campos'!J:J,'1. Status Resumo'!I14) -> 0 | J21: =COUNTIFS('2. Status Detalhe Campos'!B:B,"B05.00",'2. Status Detalhe Campos'!C:C,"Tabela Output",'2. Status Detalhe Campos'!J:J,'1. Status Resumo'!J14) -> 2 | K21: =SUM(F21:J21) -> 15
C22: F4. Fora âmbito | Re-especificação de campos complexos - Dem. Fin. CIB | D22: Total | F22: =SUM(F20:F21) -> 15 | G22: =SUM(G20:G21) -> 0 | H22: =SUM(H20:H21) -> 0 | I22: =SUM(I20:I21) -> 0 | J22: =SUM(J20:J21) -> 4 | K22: =SUM(F22:J22) -> 19
C23: F1. Fora âmbito | Campos concluídos - Sem necessidade de espec. | D23: B90.00
C24: F2. Fora âmbito | Campos em testes ou c/ incidências (LT - PM) | D24: Loan Tape | F24: =COUNTIFS('2. Status Detalhe Campos'!B:B,"B90.00",'2. Status Detalhe Campos'!C:C,"Loan Tape",'2. Status Detalhe Campos'!J:J,'1. Status Resumo'!$F$14) -> 1 | G24: =COUNTIFS('2. Status Detalhe Campos'!B:B,"B90.00",'2. Status Detalhe Campos'!C:C,"Loan Tape",'2. Status Detalhe Campos'!J:J,'1. Status Resumo'!$G$14) -> 8 | H24: =COUNTIFS('2. Status Detalhe Campos'!B:B,"B90.00",'2. Status Detalhe Campos'!C:C,"Loan Tape",'2. Status Detalhe Campos'!J:J,'1. Status Resumo'!$H$14) -> 0 | I24: =COUNTIFS('2. Status Detalhe Campos'!B:B,"B90.00",'2. Status Detalhe Campos'!C:C,"Loan Tape",'2. Status Detalhe Campos'!J:J,'1. Status Resumo'!$I$14) -> 0 | J24: =COUNTIFS('2. Status Detalhe Campos'!B:B,"B90.00",'2. Status Detalhe Campos'!C:C,"Loan Tape",'2. Status Detalhe Campos'!J:J,'1. Status Resumo'!$J$14) -> 2 | K24: =SUM(F24:J24) -> 11
C25: F3. Fora âmbito | Fonte manual LF | D25: Tabela Output | F25: =COUNTIFS('2. Status Detalhe Campos'!B:B,"B90.00",'2. Status Detalhe Campos'!C:C,"Tabela Output",'2. Status Detalhe Campos'!J:J,'1. Status Resumo'!$F$14) -> 0 | G25: =COUNTIFS('2. Status Detalhe Campos'!B:B,"B90.00",'2. Status Detalhe Campos'!C:C,"Tabela Output",'2. Status Detalhe Campos'!J:J,'1. Status Resumo'!$G$14) -> 3 | H25: =COUNTIFS('2. Status Detalhe Campos'!B:B,"B90.00",'2. Status Detalhe Campos'!C:C,"Tabela Output",'2. Status Detalhe Campos'!J:J,'1. Status Resumo'!$H$14) -> 0 | I25: =COUNTIFS('2. Status Detalhe Campos'!B:B,"B90.00",'2. Status Detalhe Campos'!C:C,"Tabela Output",'2. Status Detalhe Campos'!J:J,'1. Status Resumo'!$I$14) -> 0 | J25: =COUNTIFS('2. Status Detalhe Campos'!B:B,"B90.00",'2. Status Detalhe Campos'!C:C,"Tabela Output",'2. Status Detalhe Campos'!J:J,'1. Status Resumo'!$J$14) -> 8 | K25: =SUM(F25:J25) -> 11
C26: F4. Fora âmbito | Re-especificação de campos complexos - Dem. Fin. CIB | D26: Total | F26: =SUM(F24:F25) -> 1 | G26: =SUM(G24:G25) -> 11 | H26: =SUM(H24:H25) -> 0 | I26: =SUM(I24:I25) -> 0 | J26: =SUM(J24:J25) -> 10 | K26: =SUM(F26:J26) -> 22
D28: Resumo de Controlos
D30: Streams | F30: Semana Atual
F31: Por iniciar | G31: Em curso | H31: Concluído | I31: Com Incidências | J31: Pendente de desenvolv.
D32: B02.00 | F32: =COUNTIFS('2. Status Detalhe Campos'!$B:$B,$D$32,'2. Status Detalhe Campos'!$C:$C,"Controlos",'2. Status Detalhe Campos'!$J:$J,F$31) -> 29 | G32: =COUNTIFS('2. Status Detalhe Campos'!$B:$B,$D$32,'2. Status Detalhe Campos'!$C:$C,"Controlos",'2. Status Detalhe Campos'!$J:$J,G$31) -> 0 | H32: =COUNTIFS('2. Status Detalhe Campos'!$B:$B,$D$32,'2. Status Detalhe Campos'!$C:$C,"Controlos",'2. Status Detalhe Campos'!$J:$J,H$31) -> 92 | I32: =COUNTIFS('2. Status Detalhe Campos'!$B:$B,$D$32,'2. Status Detalhe Campos'!$C:$C,"Controlos",'2. Status Detalhe Campos'!$J:$J,I$31) -> 6 | J32: =COUNTIFS('2. Status Detalhe Campos'!$B:$B,$D$32,'2. Status Detalhe Campos'!$C:$C,"Controlos",'2. Status Detalhe Campos'!$J:$J,J$31) -> 27 | K32: =SUM(F32:J32) -> 154
D33: B05.00 | F33: 18 | G33: =COUNTIFS('2. Status Detalhe Campos'!$B:$B,$D$33,'2. Status Detalhe Campos'!$C:$C,"Controlos",'2. Status Detalhe Campos'!$J:$J,G$31) -> 0 | H33: =COUNTIFS('2. Status Detalhe Campos'!$B:$B,$D$33,'2. Status Detalhe Campos'!$C:$C,"Controlos",'2. Status Detalhe Campos'!$J:$J,H$31) -> 0 | I33: =COUNTIFS('2. Status Detalhe Campos'!$B:$B,$D$33,'2. Status Detalhe Campos'!$C:$C,"Controlos",'2. Status Detalhe Campos'!$J:$J,I$31) -> 0 | J33: 3 | K33: =SUM(F33:J33) -> 21
D34: B90.00 | F34: 13 | G34: =COUNTIFS('2. Status Detalhe Campos'!$B:$B,$D$34,'2. Status Detalhe Campos'!$C:$C,"Controlos",'2. Status Detalhe Campos'!$J:$J,G$31) -> 0 | H34: =COUNTIFS('2. Status Detalhe Campos'!$B:$B,$D$34,'2. Status Detalhe Campos'!$C:$C,"Controlos",'2. Status Detalhe Campos'!$J:$J,H$31) -> 0 | I34: =COUNTIFS('2. Status Detalhe Campos'!$B:$B,$D$34,'2. Status Detalhe Campos'!$C:$C,"Controlos",'2. Status Detalhe Campos'!$J:$J,I$31) -> 0 | J34: 3 | K34: =SUM(F34:J34) -> 16
D35: Total | F35: =SUM(F32:F34) -> 60 | G35: =SUM(G32:G34) -> 0 | H35: =SUM(H32:H34) -> 92 | I35: =SUM(I32:I34) -> 6 | J35: =SUM(J32:J34) -> 33 | K35: =SUM(F35:J35) -> 191
D37: Resumo do Dry-run
D39: Streams | F39: Semana Atual
F40: Concluído com ajuste | G40: Concluído sem ajuste | H40: Em curso | I40: Pendente de ajuste
D41: B02.00 | F41: =COUNTIFS('2. Status Detalhe Campos'!$B:$B,'1. Status Resumo'!$D$41,'2. Status Detalhe Campos'!$I:$I,'1. Status Resumo'!F40) -> 13 | G41: =COUNTIFS('2. Status Detalhe Campos'!$B:$B,'1. Status Resumo'!$D$41,'2. Status Detalhe Campos'!$I:$I,'1. Status Resumo'!G40) -> 61 | H41: =COUNTIFS('2. Status Detalhe Campos'!$B:$B,'1. Status Resumo'!$D$41,'2. Status Detalhe Campos'!$I:$I,'1. Status Resumo'!H40) -> 0 | I41: =COUNTIFS('2. Status Detalhe Campos'!$B:$B,'1. Status Resumo'!$D$41,'2. Status Detalhe Campos'!$I:$I,'1. Status Resumo'!I40) -> 7 | J41: =SUM(E41:I41) -> 81
D42: B90.00 | F42: =COUNTIFS('2. Status Detalhe Campos'!$B:$B,'1. Status Resumo'!$D$42,'2. Status Detalhe Campos'!$I:$I,'1. Status Resumo'!F40) -> 6 | G42: =COUNTIFS('2. Status Detalhe Campos'!$B:$B,'1. Status Resumo'!$D$42,'2. Status Detalhe Campos'!$I:$I,'1. Status Resumo'!G40) -> 4 | H42: =COUNTIFS('2. Status Detalhe Campos'!$B:$B,'1. Status Resumo'!$D$42,'2. Status Detalhe Campos'!$I:$I,'1. Status Resumo'!H40) -> 0 | I42: =COUNTIFS('2. Status Detalhe Campos'!$B:$B,'1. Status Resumo'!$D$42,'2. Status Detalhe Campos'!$I:$I,'1. Status Resumo'!I40) -> 1 | J42: =SUM(E42:I42) -> 11
D43: Total | F43: =SUM(F41:F42) -> 19 | G43: =SUM(G41:G42) -> 65 | H43: =SUM(H41:H42) -> 0 | I43: =SUM(I41:I42) -> 8
D45: Controlos | F45: # Controlos Totais | G45: Controlos NOK
D46: Level 1 | F46: =+SUM(F47:F48) -> 40 | G46: =+SUM(G47:G48) -> 0 | H46: =+G46/F46 -> 0
D47: B02.00 | F47: 39 | G47: 0 | H47: =+G47/F47 -> 0 | I47: 0180_dt_nxt_intrst_pymnt
D48: B90.00 | F48: 1 | G48: 0 | H48: =+G48/F48 -> 0
D49: Level 2 | F49: =+SUM(F50:F51) -> 40 | G49: =+SUM(G50:G51) -> 0 | H49: =+G49/F49 -> 0
D50: B02.00 | F50: 36 | G50: 0 | H50: =+G50/F50 -> 0 | I50: 0530_typ_own_fnds_ind_lvl, 0550_typ_own_fnds_cnsldtd_lvl
D51: B90.00 | F51: 4 | G51: 0 | H51: =+G51/F51 -> 0 | I51: 0090_CNTRY_CNTRPRTY STRING, 0100_RLVNT_AMNT_WDC
D57: B02.00
P60: Highlights
C61: A. Novos Campos | P61: Resumo semana atual: Tabela de Operações (lt002_instrument): Foram testados 3 campos onde foram verificadas as seguintes incidências: - Campo typ_own_fnds_indvdl_lvl - Registos com valor null. Necessidade de ajustar a parametrização lt804_conf_dflt. - Campo orgnl_amnt_fx - Todos os registos com valor default (99999999999.00). Necessidade de ajustar a parametrização lt804_conf_dflt. - Campo accntng_clssfctn - Todos os registos com valor default (99999999999). Necessidade de ajustar as parametrizações lt829_regras_conversao e lt830_conversoes. - Campo isin - O campo não está de acordo com a especificação de PM (valores de N/A para quando flag_inst_div = 0) - Campo typ_instrmnt - Todos os registos não respeitam a code list.Necessidade de ajustar as parametrizações lt829_regras_conversao e lt830_conversoes. Tabela Output (out_b0200_main_liabilities): Foram testados 48 campos onde foram verificadas 5 campos com incidências: - Campo 0020_uniq_id - 1 operação duplicada; - Campo 0030_uniq_id_knwn_cntrprty - Campo com incidências - Campo 0140_ntr_lblty - Todos os registos mapeados com valores que não respeitam code list. - Campo 0060_orgnl_amnt_fx - Todos os registos mapeados com um valor default. - Campo 0530_typ_own_fnds_ind_lvl - 2 registos com valores não válidos (null). - Campo 0550_typ_own_fnds_cnsldtd_lvl - 2 registos com valores não válidos (null). - Campo 0620_blnc_sht_ifrs - Todos os registos mapeados com um valor default. Após o ajuste das parametrizações no LT é expectável a resolução das incidência reportadas (exceto a operação duplicada). Todos os temas supramencionados já foram endereçados com a equipa de IT.
C62: B1. Re-especificação de campos de Sindicados
C63: B2. Re-especificação de outros campos
...

Sheet 2. Status Detalhe Campos
B7: Stream | C7: Sub-stream | D7: Loan Tape/Output Table | E7: Data field | F7: Field Status | G7: Status Especificação | H7: Status Desenvolvimento | I7: Status Dry-run | J7: Status Atual | K7: Status Anterior | L7: Data entrega IT (real) | M7: Data conclusão | N7: Observações
B8: B02.00 | C8: Loan Tape | D8: lt002_instrument | E8: instrmnt_id | F8: Campo já existente no LT | G8: Concluído | H8: Concluído | J8: Com Incidências | K8: Com Incidências
B9: B02.00 | C9: Loan Tape | D9: lt002_instrument | E9: isin | F9: Campo já existente no LT | G9: Concluído | H9: Concluído | J9: Com Incidências | K9: Com Incidências
B10: B02.00 | C10: Loan Tape | D10: lt002_instrument | E10: orgnl_amnt_eur | F10: Campo novo no LT | G10: Concluído | H10: Concluído | J10: Concluído | K10: Concluído
B11: B02.00 | C11: Loan Tape | D11: lt002_instrument | E11: orgnl_amnt_fx | F11: Campo novo no LT | G11: Concluído | H11: Concluído | J11: Com Incidências | K11: Com Incidências
B12: B02.00 | C12: Loan Tape | D12: lt002_instrument | E12: crrncy_dnmntn | F12: Campo já existente no LT | G12: Concluído | H12: Concluído | J12: Concluído | K12: Concluído
B13: B02.00 | C13: Loan Tape | D13: lt005_instr_ent. | E13: otstndng_prncpl_amnt | F13: Campo novo no LT | G13: Concluído | H13: Não Concluído | J13: Pendente de desenvolv. | K13: Pendente de desenvolv.
B14: B02.00 | C14: Loan Tape | D14: lt005_instr_ent. | E14: prtn_amnt_rprtng_entty | F14: Campo novo no LT | G14: Concluído | H14: Não Concluído | J14: Pendente de desenvolv. | K14: Pendente de desenvolv.
B15: B02.00 | C15: Loan Tape | D15: lt002_instrument | E15: accrd_intrst_instrmnt | F15: Campo já existente no LT - Nova Especificação | G15: Concluído | H15: Não Concluído | J15: Em curso | K15: Em curso
B16: B02.00 | C16: Loan Tape | D16: lt005_instr_ent | E16: accrd_intrst_instrmnt | F16: Campo já existente no LT - Nova Especificação | G16: Concluído | H16: Não Concluído | J16: Em curso | K16: Em curso
B17: B02.00 | C17: Loan Tape | D17: lt002_instrument | E17: typ_instrmnt | F17: Campo já existente no LT | G17: Concluído | H17: Concluído | J17: Com Incidências | K17: Com Incidências
B18: B02.00 | C18: Loan Tape | D18: lt002_instrument | E18: rank_insolv | F18: Campo novo no LT | G18: Concluído | H18: Concluído | J18: Em curso | K18: Em curso
B19: B02.00 | C19: Loan Tape | D19: lt002_instrument | E19: dt_incptn | F19: Campo já existente no LT | G19: Concluído | H19: Concluído | J19: Concluído | K19: Concluído
... B35: B02.00 | C35: Loan Tape | D35: lt801_param_segm | E35: flag_inst_titulos | F35: Campo já existente no LT | G35: Concluído | H35: Concluído | J35: Em curso | K35: Em curso
B36: B02.00 | C36: Tabela Output | D36: out_b0200_main_liabilities | E36: 0010_row_nmbr | F36: Campo não LT (apenas tabela Output) | G36: Concluído | H36: =+VLOOKUP(B36&"_"&E36,'B02.00'!A:X,24,FALSE) -> Concluído | I36: Concluído sem ajuste | J36: Concluído | K36: Concluído
B37: B02.00 | C37: Tabela Output | D37: out_b0200_main_liabilities | E37: 0020_uniq_id | F37: Campo já existente no LT | G37: Concluído | H37: =+VLOOKUP(B37&"_"&E37,'B02.00'!A:X,24,FALSE) -> Concluído | I37: Concluído sem ajuste | J37: Com Incidências | K37: Com Incidências
B38: B02.00 | C38: Tabela Output | D38: out_b0200_main_liabilities | E38: 0030_uniq_id_knwn_cntrprty | F38: Campo já existente no LT | G38: Concluído | H38: =+VLOOKUP(B38&"_"&E38,'B02.00'!A:X,24,FALSE) -> Concluído | I38: Concluído sem ajuste | J38: Com Incidências | K38: Com Incidências
B39: B02.00 | C39: Tabela Output | D39: out_b0200_main_liabilities | E39: 0040_typ_uniq_id_knwn_cntrprty | F39: Campo não LT (apenas tabela Output) | G39: Concluído | H39: =+VLOOKUP(B39&"_"&E39,'B02.00'!A:X,24,FALSE) -> Concluído | I39: Concluído sem ajuste | J39: Concluído | K39: Concluído
B40: B02.00 | C40: Tabela Output | D40: out_b0200_main_liabilities | E40: 0050_orgnl_amnt_eur | F40: Campo novo no LT | G40: Concluído | H40: =+VLOOKUP(B40&"_"&E40,'B02.00'!A:X,24,FALSE) -> Concluído | I40: Concluído sem ajuste | J40: Concluído | K40: Concluído
B41: B02.00 | C41: Tabela Output | D41: out_b0200_main_liabilities | E41: 0060_orgnl_amnt_fx | F41: Campo novo no LT | G41: Concluído | H41: =+VLOOKUP(B41&"_"&E41,'B02.00'!A:X,24,FALSE) -> Concluído | I41: Concluído sem ajuste | J41: Com Incidências | K41: Com Incidências
B42: B02.00 | C42: Tabela Output | D42: out_b0200_main_liabilities | E42: 0070_cntrct_crrncy | F42: Campo já existente no LT | G42: Concluído | H42: =+VLOOKUP(B42&"_"&E42,'B02.00'!A:X,24,FALSE) -> Concluído | I42: Concluído sem ajuste | J42: Concluído | K42: Concluído
B43: B02.00 | C43: Tabela Output | D43: out_b0200_main_liabilities | E43: 0080_otstndng_prncpl_amnt | F43: Campo novo no LT | G43: Concluído | H43: =+VLOOKUP(B43&"_"&E43,'B02.00'!A:X,24,FALSE) -> Não Concluído | I43: Concluído com ajuste | J43: Pendente de desenvolv. | K43: Pendente de desenvolv.
B44: B02.00 | C44: Tabela Output | D44: out_b0200_main_liabilities | E44: 0090_prtn_amnt_rprtng_entty | F44: Campo novo no LT | G44: Concluído | H44: =+VLOOKUP(B44&"_"&E44,'B02.00'!A:X,24,FALSE) -> Não Concluído | I44: Concluído sem ajuste | J44: Pendente de desenvolv. | K44: Pendente de desenvolv.
B45: B02.00 | C45: Tabela Output | D45: out_b0200_main_liabilities | E45: 0100_accrd_intrst_instrmnt | F45: Campo já existente no LT - Nova Especificação | G45: Concluído | H45: =+VLOOKUP(B45&"_"&E45,'B02.00'!A:X,24,FALSE) -> Concluído | I45: Pendente de ajuste | J45: Em curso | K45: Em curso
B46: B02.00 | C46: Tabela Output | D46: out_b0200_main_liabilities | E46: 0110_applcbl_fees_charges | F46: Campo não LT (apenas tabela Output) | G46: Concluído | H46: =+VLOOKUP(B46&"_"&E46,'B02.00'!A:X,24,FALSE) -> Concluído | I46: Concluído sem ajuste | J46: Concluído | K46: Concluído
B47: B02.00 | C47: Tabela Output | D47: out_b0200_main_liabilities | E47: 0120_otstndng_amnt | F47: Campo não LT (apenas tabela Output) | G47: Concluído | H47: =+VLOOKUP(B47&"_"&E47,'B02.00'!A:X,24,FALSE) -> Não Concluído | I47: Pendente de ajuste | J47: Pendente de desenvolv. | K47: Pendente de desenvolv.
... B63: B02.00 | C63: Tabela Output | D63: out_b0200_main_liabilities | E63: 0250_strctrd_prdct | F63: Campo não LT (apenas tabela Output) | G63: Concluído | H63: =+VLOOKUP(B63&"_"&E63,'B02.00'!A:X,24,FALSE) -> Concluído | I63: Concluído sem ajuste | J63: Concluído | K63: Concluído
B64: B02.00 | C64: Tabela Output | D64: out_b0200_main_liabilities | E64: 0260_grntd_min_amnt_strctrd_prdc | F64: Campo não LT (apenas tabela Output) | G64: Concluído | H64: Concluído | I64: Concluído sem ajuste | J64: Concluído | K64: Concluído
B65: B02.00 | C65: Tabela Output | D65: out_b0200_main_liabilities | E65: 0270_fv_amnt_strctrd_prdct | F65: Campo não LT (apenas tabela Output) | G65: Concluído | H65: =+VLOOKUP(B65&"_"&E65,'B02.00'!A:X,24,FALSE) -> Concluído | I65: Concluído sem ajuste | J65: Concluído | K65: Concluído
B66: B02.00 | C66: Tabela Output | D66: out_b0200_main_liabilities | E66: 0280_flg_ncnp_dpsts | F66: Campo não LT (apenas tabela Output) | G66: Concluído | H66: =+VLOOKUP(B66&"_"&E66,'B02.00'!A:X,24,FALSE) -> Concluído | I66: Concluído sem ajuste | J66: Concluído | K66: Concluído
B67: B02.00 | C67: Tabela Output | D67: out_b0200_main_liabilities | E67: 0290_flg_ncbp_dpsts | F67: Campo não LT (apenas tabela Output) | G67: Concluído | H67: =+VLOOKUP(B67&"_"&E67,'B02.00'!A:X,24,FALSE) -> Concluído | I67: Concluído sem ajuste | J67: Concluído | K67: Concluído
B68: B02.00 | C68: Tabela Output | D68: out_b0200_main_liabilities | E68: 0300_amnt_cvrd_elgbl_dpsts | F68: Campo não LT (apenas tabela Output) | G68: Concluído | H68: =+VLOOKUP(B68&"_"&E68,'B02.00'!A:X,24,FALSE) -> Concluído | I68: Concluído sem ajuste | J68: Concluído | K68: Concluído
B69: B02.00 | C69: Tabela Output | D69: out_b0200_main_liabilities | E69: 0310_flg_clltrl_agrmnts | F69: Campo não LT (apenas tabela Output) | G69: Concluído | H69: =+VLOOKUP(B69&"_"&E69,'B02.00'!A:X,24,FALSE) -> Concluído | I69: Concluído sem ajuste | J69: Concluído | K69: Concluído
B70: B02.00 | C70: Tabela Output | D70: out_b0200_main_liabilities | E70: 0320_amnt_clltrl | F70: Campo não LT (apenas tabela Output) | G70: Concluído | H70: =+VLOOKUP(B70&"_"&E70,'B02.00'!A:X,24,FALSE) -> Concluído | I70: Concluído sem ajuste | J70: Concluído | K70: Concluído
B71: B02.00 | C71: Tabela Output | D71: out_b0200_main_liabilities | E71: 0330_amnt_unclltrlzd | F71: Campo não LT (apenas tabela Output) | G71: Concluído | H71: =+VLOOKUP(B71&"_"&E71,'B02.00'!A:X,24,FALSE) -> Concluído | I71: Concluído sem ajuste | J71: Concluído | K71: Concluído
B72: B02.00 | C72: Tabela Output | D72: out_b0200_main_liabilities | E72: 0340_id_clltrl | F72: Campo não LT (apenas tabela Output) | G72: Concluído | H72: =+VLOOKUP(B72&"_"&E72,'B02.00'!A:X,24,FALSE) -> Concluído | I72: Concluído sem ajuste | J72: Concluído | K72: Concluído
B73: B02.00 | C73: Tabela Output | D73: out_b0200_main_liabilities | E73: 0350_typ_clltrl | F73: Campo não LT (apenas tabela Output) | G73: Concluído | H73: =+VLOOKUP(B73&"_"&E73,'B02.00'!A:X,24,FALSE) -> Concluído | I73: Concluído sem ajuste | J73: Concluído | K73: Concluído
B74: B02.00 | C74: Tabela Output | D74: out_b0200_main_liabilities | E74: 0351_typ_clltrl_othr | F74: Campo não LT (apenas tabela Output) | G74: Concluído | H74: =+VLOOKUP(B74&"_"&E74,'B02.00'!A:X,24,FALSE) -> Concluído | I74: Concluído sem ajuste | J74: Concluído | K74: Concluído
B75: B02.00 | C75: Tabela Output | D75: out_b0200_main_liabilities | E75: 0360_trdng_mthd | F75: Em curso | G75: Não Concluído | H75: =+VLOOKUP(B75&"_"&E75,'B02.00'!A:X,24,FALSE) -> Não Concluído | I75: Concluído com ajuste | J75: Pendente de desenvolv. | K75: Pendente de desenvolv.
B76: B02.00 | C76: Tabela Output | D76: out_b0200_main_liabilities | E76: 0370_amnt_scrty_eur | F76: Campo novo no LT | G76: Concluído | H76: =+VLOOKUP(B76&"_"&E76,'B02.00'!A:X,24,FALSE) -> Concluído | I76: Concluído sem ajuste | J76: Concluído | K76: Concluído
...

Sheet Aux
B7: Field Status
B9: Campo já existente no LT
B10: Campo já existente no LT - Nova Especificação
B11: Campo novo no LT
B12: Campo via Holístico
B13: Campo não LT (apenas tabela Output)
B14: Não aplicável
B15: Em curso
B17: Status Especificação/Desenvolvimento
B18: Em curso
B19: Concluído
B20: Não aplicável
... B36: Não aplicável

Sheet 3. Status Testes
A1: wvg
I6: 1. Status dos Testes
I8: Âmbito | J8: Bail-In
B9: Auxiliar
B10: Coerência | C10: Validade | D10: Caracteres Especiais | E10: Missings | F10: Not applicable | G10: Min/Max | I10: Tabela | J10: Campo | K10: Status especificação | L10: Status desenvolvimento | M10: Testes Corridos (#) | N10: Data de Referência | O10: Número de Registos ID1. (#) | P10: ID Exec. 1. | Q10: 1. Erros de Coerência (#) | R10: Número de Registos ID2&9 (#) | S10: ID Exec. 2 | T10: 2. Erros de Valores Admitidos (#) | U10: ID Exec. 3. | V10: 3. Erros de Caract. Especiais (#) | W10: ID Exec. 4. | X10: 4. Registos com Missing (#) | Y10: % de Missings | Z10: ID Exec. 5. | AA10: 5. Registos com N/A (#) | AB10: % de N/A | AC10: 6. Valor Mínimo | AD10: 7. Valor Máximo | AE10: 8. Controlos Regulamentares (#) | AF10: 9. Controlos de Formatos (#) | AG10: Comentário | AH10: Status
A11: =+I11&J11 -> B02.000010_ROW_NMBR | B11: =+VLOOKUP(I11&J11,[1]Auxiliar!B:C,2,FALSE) -> 2 | C11: =+VLOOKUP(I11&J11,[1]Auxiliar!E:F,2,FALSE) -> 2 | D11: =+VLOOKUP(I11&J11,[1]Auxiliar!H:I,2,FALSE) -> 2 | E11: =+VLOOKUP(I11&J11,[1]Auxiliar!K:L,2,FALSE) -> 2 | F11: =+VLOOKUP(I11&J11,[1]Auxiliar!N:O,2,FALSE) -> 2 | G11: =+VLOOKUP(I11&J11,[1]Auxiliar!Q:R,2,FALSE) -> 2 | H11: =+"c"&LEFT(J11,4) -> c0010 | I11: B02.00 | J11: 0010_ROW_NMBR | L11: =+VLOOKUP(J11,#REF!,3,FALSE) -> #REF! | N11: 2025-10-31 | O11: 8 | P11: =+IFERROR(VLOOKUP(B11,'[1]ID1&5'!K:L,2,FALSE),"-") -> - | Q11: 0 | R11: =+IFERROR(VLOOKUP(CONCATENATE(A11,$C$10,C11),'[1]ID1&5'!B:J,8,FALSE),"-") -> - | S11: =+IFERROR(VLOOKUP(C11,'[1]ID1&5'!K:L,2,FALSE),"-") -> - | T11: 0 | U11: =+IFERROR(VLOOKUP(D11,'[1]ID1&5'!K:L,2,FALSE),"-") -> - | V11: 0 | W11: =+IFERROR(VLOOKUP(E11,'[1]ID1&5'!K:L,2,FALSE),"-") -> - | X11: 0 | Y11: =+X11/O11 -> 0 | Z11: =+IFERROR(VLOOKUP(F11,'[1]ID1&5'!K:L,2,FALSE),"-") -> - | AA11: 0 | AB11: =+AA11/O11 -> 0 | AC11: 1 | AD11: 8 | AE11: 0 | AF11: 0 | AH11: OK | AI11: Concluído
A12: =+I12&J12 -> B02.000020_UNIQ_ID | B12: =+VLOOKUP(I12&J12,[1]Auxiliar!B:C,2,FALSE) -> 2 | C12: =+VLOOKUP(I12&J12,[1]Auxiliar!E:F,2,FALSE) -> 2 | D12: =+VLOOKUP(I12&J12,[1]Auxiliar!H:I,2,FALSE) -> 2 | E12: =+VLOOKUP(I12&J12,[1]Auxiliar!K:L,2,FALSE) -> 2 | F12: =+VLOOKUP(I12&J12,[1]Auxiliar!N:O,2,FALSE) -> 2 | G12: =+VLOOKUP(I12&J12,[1]Auxiliar!Q:R,2,FALSE) -> 2 | H12: =+"c"&LEFT(J12,4) -> c0020 | I12: B02.00 | J12: 0020_UNIQ_ID | L12: =+VLOOKUP(J12,#REF!,3,FALSE) -> #REF! | N12: 2025-10-31 | O12: 8 | P12: =+IFERROR(VLOOKUP(B12,'[1]ID1&5'!K:L,2,FALSE),"-") -> - | Q12: 0 | R12: =+IFERROR(VLOOKUP(CONCATENATE(A12,$C$10,C12),'[1]ID1&5'!B:J,8,FALSE),"-") -> - | S12: =+IFERROR(VLOOKUP(C12,'[1]ID1&5'!K:L,2,FALSE),"-") -> - | T12: 0 | U12: =+IFERROR(VLOOKUP(D12,'[1]ID1&5'!K:L,2,FALSE),"-") -> - | V12: 0 | W12: =+IFERROR(VLOOKUP(E12,'[1]ID1&5'!K:L,2,FALSE),"-") -> - | X12: 0 | Y12: =+X12/O12 -> 0 | Z12: =+IFERROR(VLOOKUP(F12,'[1]ID1&5'!K:L,2,FALSE),"-") -> - | AA12: 0 | AB12: =+AA12/O12 -> 0 | AC12: 31641600000000000PTBSREOM0028000 | AD12: 31641600005800007PTSTOCOM0007000 | AE12: 0 | AF12: 0 | AH12: OK | AI12: Com Incidências
A13: =+I13&J13 -> B02.000030_UNIQ_ID_KNWN_CNTRPRTY | B13: =+VLOOKUP(I13&J13,[1]Auxiliar!B:C,2,FALSE) -> 2 | C13: =+VLOOKUP(I13&J13,[1]Auxiliar!E:F,2,FALSE) -> 2 | D13: =+VLOOKUP(I13&J13,[1]Auxiliar!H:I,2,FALSE) -> 2 | E13: =+VLOOKUP(I13&J13,[1]Auxiliar!K:L,2,FALSE) -> 2 | F13: =+VLOOKUP(I13&J13,[1]Auxiliar!N:O,2,FALSE) -> 2 | G13: =+VLOOKUP(I13&J13,[1]Auxiliar!Q:R,2,FALSE) -> 2 | H13: =+"c"&LEFT(J13,4) -> c0030 | I13: B02.00 | J13: 0030_UNIQ_ID_KNWN_CNTRPRTY | L13: =+VLOOKUP(J13,#REF!,3,FALSE) -> #REF! | N13: 2025-10-31 | O13: 8 | P13: =+IFERROR(VLOOKUP(B13,'[1]ID1&5'!K:L,2,FALSE),"-") -> - | Q13: 0 | R13: =+IFERROR(VLOOKUP(CONCATENATE(A13,$C$10,C13),'[1]ID1&5'!B:J,8,FALSE),"-") -> - | S13: =+IFERROR(VLOOKUP(C13,'[1]ID1&5'!K:L,2,FALSE),"-") -> - | T13: 0 | U13: =+IFERROR(VLOOKUP(D13,'[1]ID1&5'!K:L,2,FALSE),"-") -> - | V13: 0 | W13: =+IFERROR(VLOOKUP(E13,'[1]ID1&5'!K:L,2,FALSE),"-") -> - | X13: 0 | Y13: =+X13/O13 -> 0 | Z13: =+IFERROR(VLOOKUP(F13,'[1]ID1&5'!K:L,2,FALSE),"-") -> - | AA13: 0 | AB13: =+AA13/O13 -> 0 | AC13: PTBSRDOM0037 | AD13: PTSTOHOM0002 | AE13: 0 | AF13: 0 | AH13: OK | AI13: Com Incidências
A14: =+I14&J14 -> B02.000040_TYP_UNIQ_ID_KNWN_CNTRPRTY | B14: =+VLOOKUP(I14&J14,[1]Auxiliar!B:C,2,FALSE) -> 2 | C14: =+VLOOKUP(I14&J14,[1]Auxiliar!E:F,2,FALSE) -> 2 | D14: =+VLOOKUP(I14&J14,[1]Auxiliar!H:I,2,FALSE) -> 2 | E14: =+VLOOKUP(I14&J14,[1]Auxiliar!K:L,2,FALSE) -> 2 | F14: =+VLOOKUP(I14&J14,[1]Auxiliar!N:O,2,FALSE) -> 2 | G14: =+VLOOKUP(I14&J14,[1]Auxiliar!Q:R,2,FALSE) -> 2 | H14: =+"c"&LEFT(J14,4) -> c0040 | I14: B02.00 | J14: 0040_TYP_UNIQ_ID_KNWN_CNTRPRTY | L14: =+VLOOKUP(J14,#REF!,3,FALSE) -> #REF! | N14: 2025-10-31 | O14: 8 | P14: =+IFERROR(VLOOKUP(B14,'[1]ID1&5'!K:L,2,FALSE),"-") -> - | Q14: 0 | R14: =+IFERROR(VLOOKUP(CONCATENATE(A14,$C$10,C14),'[1]ID1&5'!B:J,8,FALSE),"-") -> - | S14: =+IFERROR(VLOOKUP(C14,'[1]ID1&5'!K:L,2,FALSE),"-") -> - | T14: 0 | U14: =+IFERROR(VLOOKUP(D14,'[1]ID1&5'!K:L,2,FALSE),"-") -> - | V14: 0 | W14: =+IFERROR(VLOOKUP(E14,'[1]ID1&5'!K:L,2,FALSE),"-") -> - | X14: 0 | Y14: =+X14/O14 -> 0 | Z14: =+IFERROR(VLOOKUP(F14,'[1]ID1&5'!K:L,2,FALSE),"-") -> - | AA14: 0 | AB14: =+AA14/O14 -> 0 | AC14: ISIN | AD14: ISIN | AE14: 0 | AF14: 0 | AH14: OK | AI14: Concluído
A15: =+I15&J15 -> B02.000050_ORGNL_AMNT_EUR | B15: =+VLOOKUP(I15&J15,[1]Auxiliar!B:C,2,FALSE) -> 2 | C15: =+VLOOKUP(I15&J15,[1]Auxiliar!E:F,2,FALSE) -> 2 | D15: =+VLOOKUP(I15&J15,[1]Auxiliar!H:I,2,FALSE) -> 2 | E15: =+VLOOKUP(I15&J15,[1]Auxiliar!K:L,2,FALSE) -> 2 | F15: =+VLOOKUP(I15&J15,[1]Auxiliar!N:O,2,FALSE) -> 2 | G15: =+VLOOKUP(I15&J15,[1]Auxiliar!Q:R,2,FALSE) -> 2 | H15: =+"c"&LEFT(J15,4) -> c0050 | I15: B02.00 | J15: 0050_ORGNL_AMNT_EUR | L15: =+VLOOKUP(J15,#REF!,3,FALSE) -> #REF! | N15: 2025-10-31 | O15: 8 | P15: =+IFERROR(VLOOKUP(B15,'[1]ID1&5'!K:L,2,FALSE),"-") -> - | Q15: 0 | R15: =+IFERROR(VLOOKUP(CONCATENATE(A15,$C$10,C15),'[1]ID1&5'!B:J,8,FALSE),"-") -> - | S15: =+IFERROR(VLOOKUP(C15,'[1]ID1&5'!K:L,2,FALSE),"-") -> - | T15: 0 | U15: =+IFERROR(VLOOKUP(D15,'[1]ID1&5'!K:L,2,FALSE),"-") -> - | V15: 0 | W15: =+IFERROR(VLOOKUP(E15,'[1]ID1&5'!K:L,2,FALSE),"-") -> - | X15: 0 | Y15: =+X15/O15 -> 0 | Z15: =+IFERROR(VLOOKUP(F15,'[1]ID1&5'!K:L,2,FALSE),"-") -> - | AA15: 0 | AB15: =+AA15/O15 -> 0 | AC15: 7599000.00 | AD15: 1391779674.00 | AE15: 0 | AF15: 0 | AH15: OK | AI15: Concluído
A16: =+I16&J16 -> B02.000060_ORGNL_AMNT_FX | B16: =+VLOOKUP(I16&J16,[1]Auxiliar!B:C,2,FALSE) -> 2 | C16: =+VLOOKUP(I16&J16,[1]Auxiliar!E:F,2,FALSE) -> 2 | D16: =+VLOOKUP(I16&J16,[1]Auxiliar!H:I,2,FALSE) -> 2 | E16: =+VLOOKUP(I16&J16,[1]Auxiliar!K:L,2,FALSE) -> 2 | F16: =+VLOOKUP(I16&J16,[1]Auxiliar!N:O,2,FALSE) -> 2 | G16: =+VLOOKUP(I16&J16,[1]Auxiliar!Q:R,2,FALSE) -> 2 | H16: =+"c"&LEFT(J16,4) -> c0060 | I16: B02.00 | J16: 0060_ORGNL_AMNT_FX | L16: =+VLOOKUP(J16,#REF!,3,FALSE) -> #REF! | N16: 2025-10-31 | O16: 8 | P16: =+IFERROR(VLOOKUP(B16,'[1]ID1&5'!K:L,2,FALSE),"-") -> - | Q16: 0 | R16: =+IFERROR(VLOOKUP(CONCATENATE(A16,$C$10,C16),'[1]ID1&5'!B:J,8,FALSE),"-") -> - | S16: =+IFERROR(VLOOKUP(C16,'[1]ID1&5'!K:L,2,FALSE),"-") -> - | T16: 0 | U16: =+IFERROR(VLOOKUP(D16,'[1]ID1&5'!K:L,2,FALSE),"-") -> - | V16: 0 | W16: =+IFERROR(VLOOKUP(E16,'[1]ID1&5'!K:L,2,FALSE),"-") -> - | X16: 0 | Y16: =+X16/O16 -> 0 | Z16: =+IFERROR(VLOOKUP(F16,'[1]ID1&5'!K:L,2,FALSE),"-") -> - | AA16: 8 | AB16: =+AA16/O16 -> 1 | AC16: 999999999999999.00 | AD16: 999999999999999.00 | AE16: 0 | AF16: 0 | AG16: Comentário 14/11 - Todos os registos estão classificador como não aplicável pois o campo refere-se ao montante em moeda estrangeira. | AH16: OK | AI16: Com Incidências
A17: =+I17&J17 -> B02.000070_CNTRCT_CRRNCY | B17: =+VLOOKUP(I17&J17,[1]Auxiliar!B:C,2,FALSE) -> 2 | C17: =+VLOOKUP(I17&J17,[1]Auxiliar!E:F,2,FALSE) -> 2 | D17: =+VLOOKUP(I17&J17,[1]Auxiliar!H:I,2,FALSE) -> 2 | E17: =+VLOOKUP(I17&J17,[1]Auxiliar!K:L,2,FALSE) -> 2 | F17: =+VLOOKUP(I17&J17,[1]Auxiliar!N:O,2,FALSE) -> 2 | G17: =+VLOOKUP(I17&J17,[1]Auxiliar!Q:R,2,FALSE) -> 2 | H17: =+"c"&LEFT(J17,4) -> c0070 | I17: B02.00 | J17: 0070_CNTRCT_CRRNCY | L17: =+VLOOKUP(J17,#REF!,3,FALSE) -> #REF! | N17: 2025-10-31 | O17: 8 | P17: =+IFERROR(VLOOKUP(B17,'[1]ID1&5'!K:L,2,FALSE),"-") -> - | Q17: 0 | R17: =+IFERROR(VLOOKUP(CONCATENATE(A17,$C$10,C17),'[1]ID1&5'!B:J,8,FALSE),"-") -> - | S17: =+IFERROR(VLOOKUP(C17,'[1]ID1&5'!K:L,2,FALSE),"-") -> - | T17: 0 | U17: =+IFERROR(VLOOKUP(D17,'[1]ID1&5'!K:L,2,FALSE),"-") -> - | V17: 0 | W17: =+IFERROR(VLOOKUP(E17,'[1]ID1&5'!K:L,2,FALSE),"-") -> - | X17: 0 | Y17: =+X17/O17 -> 0 | Z17: =+IFERROR(VLOOKUP(F17,'[1]ID1&5'!K:L,2,FALSE),"-") -> - | AA17: 0 | AB17: =+AA17/O17 -> 0 | AC17: EUR | AD17: EUR | AE17: 0 | AF17: 0 | AH17: OK | AI17: Concluído
A18: =+I18&J18 -> B02.000080_OTSTNDNG_PRNCPL_AMNT | B18: =+VLOOKUP(I18&J18,[1]Auxiliar!B:C,2,FALSE) -> 2 | C18: =+VLOOKUP(I18&J18,[1]Auxiliar!E:F,2,FALSE) -> 2 | D18: =+VLOOKUP(I18&J18,[1]Auxiliar!H:I,2,FALSE) -> 2 | E18: =+VLOOKUP(I18&J18,[1]Auxiliar!K:L,2,FALSE) -> 2 | F18: =+VLOOKUP(I18&J18,[1]Auxiliar!N:O,2,FALSE) -> 2 | G18: =+VLOOKUP(I18&J18,[1]Auxiliar!Q:R,2,FALSE) -> 2 | H18: =+"c"&LEFT(J18,4) -> c0080 | I18: B02.00 | J18: 0080_OTSTNDNG_PRNCPL_AMNT | L18: =+VLOOKUP(J18,#REF!,3,FALSE) -> #REF! | N18: 2025-10-31 | O18: 8 | P18: =+IFERROR(VLOOKUP(B18,'[1]ID1&5'!K:L,2,FALSE),"-") -> - | Q18: 8 | R18: =+IFERROR(VLOOKUP(CONCATENATE(A18,$C$10,C18),'[1]ID1&5'!B:J,8,FALSE),"-") -> - | S18: =+IFERROR(VLOOKUP(C18,'[1]ID1&5'!K:L,2,FALSE),"-") -> - | T18: 0 | U18: =+IFERROR(VLOOKUP(D18,'[1]ID1&5'!K:L,2,FALSE),"-") -> - | V18: 0 | W18: =+IFERROR(VLOOKUP(E18,'[1]ID1&5'!K:L,2,FALSE),"-") -> - | X18: 0 | Y18: =+X18/O18 -> 0 | Z18: =+IFERROR(VLOOKUP(F18,'[1]ID1&5'!K:L,2,FALSE),"-") -> - | AA18: 0 | AB18: =+AA18/O18 -> 0 | AC18: 7599000.00 | AD18: 1385452938.00 | AE18: 0 | AF18: 0 | AH18: OK | AI18: Pendente de desenvolv.
A19: =+I19&J19 -> B02.000090_PRTN_AMNT_RPRTNG_ENTTY | B19: =+VLOOKUP(I19&J19,[1]Auxiliar!B:C,2,FALSE) -> 2 | C19: =+VLOOKUP(I19&J19,[1]Auxiliar!E:F,2,FALSE) -> 2 | D19: =+VLOOKUP(I19&J19,[1]Auxiliar!H:I,2,FALSE) -> 2 | E19: =+VLOOKUP(I19&J19,[1]Auxiliar!K:L,2,FALSE) -> 2 | F19: =+VLOOKUP(I19&J19,[1]Auxiliar!N:O,2,FALSE) -> 2 | G19: =+VLOOKUP(I19&J19,[1]Auxiliar!Q:R,2,FALSE) -> 2 | H19: =+"c"&LEFT(J19,4) -> c0090 | I19: B02.00 | J19: 0090_PRTN_AMNT_RPRTNG_ENTTY | L19: =+VLOOKUP(J19,#REF!,3,FALSE) -> #REF! | N19: 2025-10-31 | O19: 8 | P19: =+IFERROR(VLOOKUP(B19,'[1]ID1&5'!K:L,2,FALSE),"-") -> - | Q19: 8 | R19: =+IFERROR(VLOOKUP(CONCATENATE(A19,$C$10,C19),'[1]ID1&5'!B:J,8,FALSE),"-") -> - | S19: =+IFERROR(VLOOKUP(C19,'[1]ID1&5'!K:L,2,FALSE),"-") -> - | T19: 0 | U19: =+IFERROR(VLOOKUP(D19,'[1]ID1&5'!K:L,2,FALSE),"-") -> - | V19: 0 | W19: =+IFERROR(VLOOKUP(E19,'[1]ID1&5'!K:L,2,FALSE),"-") -> - | X19: 0 | Y19: =+X19/O19 -> 0 | Z19: =+IFERROR(VLOOKUP(F19,'[1]ID1&5'!K:L,2,FALSE),"-") -> - | AA19: 0 | AB19: =+AA19/O19 -> 0 | AC19: 0.00 | AD19: 6326736.00 | AE19: 0 | AF19: 0 | AH19: OK | AI19: Pendente de desenvolv.
A20: =+I20&J20 -> B02.000100_ACCRD_INTRST_INSTRMNT | B20: =+VLOOKUP(I20&J20,[1]Auxiliar!B:C,2,FALSE) -> 2 | C20: =+VLOOKUP(I20&J20,[1]Auxiliar!E:F,2,FALSE) -> 2 | D20: =+VLOOKUP(I20&J20,[1]Auxiliar!H:I,2,FALSE) -> 2 | E20: =+VLOOKUP(I20&J20,[1]Auxiliar!K:L,2,FALSE) -> 2 | F20: =+VLOOKUP(I20&J20,[1]Auxiliar!N:O,2,FALSE) -> 2 | G20: =+VLOOKUP(I20&J20,[1]Auxiliar!Q:R,2,FALSE) -> 2 | H20: =+"c"&LEFT(J20,4) -> c0100 | I20: B02.00 | J20: 0100_ACCRD_INTRST_INSTRMNT | L20: =+VLOOKUP(J20,#REF!,3,FALSE) -> #REF! | N20: 2025-10-31 | O20: 8 | P20: =+IFERROR(VLOOKUP(B20,'[1]ID1&5'!K:L,2,FALSE),"-") -> - | Q20: 4 | R20: =+IFERROR(VLOOKUP(CONCATENATE(A20,$C$10,C20),'[1]ID1&5'!B:J,8,FALSE),"-") -> - | S20: =+IFERROR(VLOOKUP(C20,'[1]ID1&5'!K:L,2,FALSE),"-") -> - | T20: 0 | U20: =+IFERROR(VLOOKUP(D20,'[1]ID1&5'!K:L,2,FALSE),"-") -> - | V20: 0 | W20: =+IFERROR(VLOOKUP(E20,'[1]ID1&5'!K:L,2,FALSE),"-") -> - | X20: 0 | Y20: =+X20/O20 -> 0 | Z20: =+IFERROR(VLOOKUP(F20,'[1]ID1&5'!K:L,2,FALSE),"-") -> - | AA20: 0 | AB20: =+AA20/O20 -> 0 | AC20: 0.00 | AD20: 7640186.30 | AE20: 0 | AF20: 0 | AH20: OK | AI20: Em curso
A21: =+I21&J21 -> B02.000110_APPLCBL_FEES_CHARGES | B21: =+VLOOKUP(I21&J21,[1]Auxiliar!B:C,2,FALSE) -> 2 | C21: =+VLOOKUP(I21&J21,[1]Auxiliar!E:F,2,FALSE) -> 2 | D21: =+VLOOKUP(I21&J21,[1]Auxiliar!H:I,2,FALSE) -> 2 | E21: =+VLOOKUP(I21&J21,[1]Auxiliar!K:L,2,FALSE) -> 2 | F21: =+VLOOKUP(I21&J21,[1]Auxiliar!N:O,2,FALSE) -> 2 | G21: =+VLOOKUP(I21&J21,[1]Auxiliar!Q:R,2,FALSE) -> 2 | H21: =+"c"&LEFT(J21,4) -> c0110 | I21: B02.00 | J21: 0110_APPLCBL_FEES_CHARGES | L21: =+VLOOKUP(J21,#REF!,3,FALSE) -> #REF! | N21: 2025-10-31 | O21: 8 | P21: =+IFERROR(VLOOKUP(B21,'[1]ID1&5'!K:L,2,FALSE),"-") -> - | Q21: 0 | R21: =+IFERROR(VLOOKUP(CONCATENATE(A21,$C$10,C21),'[1]ID1&5'!B:J,8,FALSE),"-") -> - | S21: =+IFERROR(VLOOKUP(C21,'[1]ID1&5'!K:L,2,FALSE),"-") -> - | T21: 0 | U21: =+IFERROR(VLOOKUP(D21,'[1]ID1&5'!K:L,2,FALSE),"-") -> - | V21: 0 | W21: =+IFERROR(VLOOKUP(E21,'[1]ID1&5'!K:L,2,FALSE),"-") -> - | X21: 0 | Y21: =+X21/O21 -> 0 | Z21: =+IFERROR(VLOOKUP(F21,'[1]ID1&5'!K:L,2,FALSE),"-") -> - | AA21: 0 | AB21: =+AA21/O21 -> 0 | AC21: 0.00 | AD21: 0.00 | AE21: 0 | AF21: 0 | AH21: OK | AI21: Concluído
A22: =+I22&J22 -> B02.000120_OTSTNDNG_AMNT | B22: =+VLOOKUP(I22&J22,[1]Auxiliar!B:C,2,FALSE) -> 2 | C22: =+VLOOKUP(I22&J22,[1]Auxiliar!E:F,2,FALSE) -> 2 | D22: =+VLOOKUP(I22&J22,[1]Auxiliar!H:I,2,FALSE) -> 2 | E22: =+VLOOKUP(I22&J22,[1]Auxiliar!K:L,2,FALSE) -> 2 | F22: =+VLOOKUP(I22&J22,[1]Auxiliar!N:O,2,FALSE) -> 2 | G22: =+VLOOKUP(I22&J22,[1]Auxiliar!Q:R,2,FALSE) -> 2 | H22: =+"c"&LEFT(J22,4) -> c0120 | I22: B02.00 | J22: 0120_OTSTNDNG_AMNT | L22: =+VLOOKUP(J22,#REF!,3,FALSE) -> #REF! | N22: 2025-10-31 | O22: 8 | P22: =+IFERROR(VLOOKUP(B22,'[1]ID1&5'!K:L,2,FALSE),"-") -> - | Q22: 8 | R22: =+IFERROR(VLOOKUP(CONCATENATE(A22,$C$10,C22),'[1]ID1&5'!B:J,8,FALSE),"-") -> - | S22: =+IFERROR(VLOOKUP(C22,'[1]ID1&5'!K:L,2,FALSE),"-") -> - | T22: 0 | U22: =+IFERROR(VLOOKUP(D22,'[1]ID1&5'!K:L,2,FALSE),"-") -> - | V22: 0 | W22: =+IFERROR(VLOOKUP(E22,'[1]ID1&5'!K:L,2,FALSE),"-") -> - | X22: 0 | Y22: =+X22/O22 -> 0 | Z22: =+IFERROR(VLOOKUP(F22,'[1]ID1&5'!K:L,2,FALSE),"-") -> - | AA22: 0 | AB22: =+AA22/O22 -> 0 | AC22: 7639597.40 | AD22: 1385452938.00 | AE22: 0 | AF22: 0 | AH22: OK | AI22: Pendente de desenvolv.
A23: =+I23&J23 -> B02.000130_RLVNT_AMNT_WDC | B23: =+VLOOKUP(I23&J23,[1]Auxiliar!B:C,2,FALSE) -> 2 | C23: =+VLOOKUP(I23&J23,[1]Auxiliar!E:F,2,FALSE) -> 2 | D23: =+VLOOKUP(I23&J23,[1]Auxiliar!H:I,2,FALSE) -> 2 | E23: =+VLOOKUP(I23&J23,[1]Auxiliar!K:L,2,FALSE) -> 2 | F23: =+VLOOKUP(I23&J23,[1]Auxiliar!N:O,2,FALSE) -> 2 | G23: =+VLOOKUP(I23&J23,[1]Auxiliar!Q:R,2,FALSE) -> 2 | H23: =+"c"&LEFT(J23,4) -> c0130 | I23: B02.00 | J23: 0130_RLVNT_AMNT_WDC | L23: =+VLOOKUP(J23,#REF!,3,FALSE) -> #REF! | N23: 2025-10-31 | O23: 8 | P23: =+IFERROR(VLOOKUP(B23,'[1]ID1&5'!K:L,2,FALSE),"-") -> - | Q23: 8 | R23: =+IFERROR(VLOOKUP(CONCATENATE(A23,$C$10,C23),'[1]ID1&5'!B:J,8,FALSE),"-") -> - | S23: =+IFERROR(VLOOKUP(C23,'[1]ID1&5'!K:L,2,FALSE),"-") -> - | T23: 0 | U23: =+IFERROR(VLOOKUP(D23,'[1]ID1&5'!K:L,2,FALSE),"-") -> - | V23: 0 | W23: =+IFERROR(VLOOKUP(E23,'[1]ID1&5'!K:L,2,FALSE),"-") -> - | X23: 0 | Y23: =+X23/O23 -> 0 | Z23: =+IFERROR(VLOOKUP(F23,'[1]ID1&5'!K:L,2,FALSE),"-") -> - | AA23: 0 | AB23: =+AA23/O23 -> 0 | AC23: 7639597.40 | AD23: 1385452938.00 | AE23: 0 | AF23: 0 | AH23: OK | AI23: Pendente de desenvolv.
A24: =+I24&J24 -> B02.000140_NTR_LBLTY | B24: =+VLOOKUP(I24&J24,[1]Auxiliar!B:C,2,FALSE) -> 2 | C24: =+VLOOKUP(I24&J24,[1]Auxiliar!E:F,2,FALSE) -> 2 | D24: =+VLOOKUP(I24&J24,[1]Auxiliar!H:I,2,FALSE) -> 2 | E24: =+VLOOKUP(I24&J24,[1]Auxiliar!K:L,2,FALSE) -> 2 | F24: =+VLOOKUP(I24&J24,[1]Auxiliar!N:O,2,FALSE) -> 2 | G24: =+VLOOKUP(I24&J24,[1]Auxiliar!Q:R,2,FALSE) -> 2 | H24: =+"c"&LEFT(J24,4) -> c0140 | I24: B02.00 | J24: 0140_NTR_LBLTY | L24: =+VLOOKUP(J24,#REF!,3,FALSE) -> #REF! | N24: 2025-10-31 | O24: 8 | P24: =+IFERROR(VLOOKUP(B24,'[1]ID1&5'!K:L,2,FALSE),"-") -> - | Q24: 4 | R24: =+IFERROR(VLOOKUP(CONCATENATE(A24,$C$10,C24),'[1]ID1&5'!B:J,8,FALSE),"-") -> - | S24: =+IFERROR(VLOOKUP(C24,'[1]ID1&5'!K:L,2,FALSE),"-") -> - | T24: 0 | U24: =+IFERROR(VLOOKUP(D24,'[1]ID1&5'!K:L,2,FALSE),"-") -> - | V24: 0 | W24: =+IFERROR(VLOOKUP(E24,'[1]ID1&5'!K:L,2,FALSE),"-") -> - | X24: 0 | Y24: =+X24/O24 -> 0 | Z24: =+IFERROR(VLOOKUP(F24,'[1]ID1&5'!K:L,2,FALSE),"-") -> - | AA24: 0 | AB24: =+AA24/O24 -> 0 | AC24: Registered Bond | AD24: Title of ownership | AE24: 0 | AF24: 0 | AH24: OK | AI24: Com Incidências
A25: =+I25&J25 -> B02.000141_NTR_LBLTY_OTHR | B25: =+VLOOKUP(I25&J25,[1]Auxiliar!B:C,2,FALSE) -> 2 | C25: =+VLOOKUP(I25&J25,[1]Auxiliar!E:F,2,FALSE) -> 2 | D25: =+VLOOKUP(I25&J25,[1]Auxiliar!H:I,2,FALSE) -> 2 | E25: =+VLOOKUP(I25&J25,[1]Auxiliar!K:L,2,FALSE) -> 2 | F25: =+VLOOKUP(I25&J25,[1]Auxiliar!N:O,2,FALSE) -> 2 | G25: =+VLOOKUP(I25&J25,[1]Auxiliar!Q:R,2,FALSE) -> 2 | H25: =+"c"&LEFT(J25,4) -> c0141 | I25: B02.00 | J25: 0141_NTR_LBLTY_OTHR | L25: =+VLOOKUP(J25,#REF!,3,FALSE) -> #REF! | N25: 2025-10-31 | O25: 8 | P25: =+IFERROR(VLOOKUP(B25,'[1]ID1&5'!K:L,2,FALSE),"-") -> - | Q25: 0 | R25: =+IFERROR(VLOOKUP(CONCATENATE(A25,$C$10,C25),'[1]ID1&5'!B:J,8,FALSE),"-") -> - | S25: =+IFERROR(VLOOKUP(C25,'[1]ID1&5'!K:L,2,FALSE),"-") -> - | T25: 0 | U25: =+IFERROR(VLOOKUP(D25,'[1]ID1&5'!K:L,2,FALSE),"-") -> - | V25: 0 | W25: =+IFERROR(VLOOKUP(E25,'[1]ID1&5'!K:L,2,FALSE),"-") -> - | X25: 0 | Y25: =+X25/O25 -> 0 | Z25: =+IFERROR(VLOOKUP(F25,'[1]ID1&5'!K:L,2,FALSE),"-") -> - | AA25: 8 | AB25: =+AA25/O25 -> 1 | AC25: Not applicable | AD25: Not applicable | AE25: 0 | AF25: 1 | AG25: Comentário 14/11 - Campo com valor fixo de not applicable conforme a especificação funcional. | AH25: OK | AI25: Concluído
A26: =+I26&J26 -> B02.000150_FLG_STRCTRLLY_SBRDNTD | B26: =+VLOOKUP(I26&J26,[1]Auxiliar!B:C,2,FALSE) -> 2 | C26: =+VLOOKUP(I26&J26,[1]Auxiliar!E:F,2,FALSE) -> 2 | D26: =+VLOOKUP(I26&J26,[1]Auxiliar!H:I,2,FALSE) -> 2 | E26: =+VLOOKUP(I26&J26,[1]Auxiliar!K:L,2,FALSE) -> 2 | F26: =+VLOOKUP(I26&J26,[1]Auxiliar!N:O,2,FALSE) -> 2 | G26: =+VLOOKUP(I26&J26,[1]Auxiliar!Q:R,2,FALSE) -> 2 | H26: =+"c"&LEFT(J26,4) -> c0150 | I26: B02.00 | J26: 0150_FLG_STRCTRLLY_SBRDNTD | L26: =+VLOOKUP(J26,#REF!,3,FALSE) -> #REF! | N26: 2025-10-31 | O26: 8 | P26: =+IFERROR(VLOOKUP(B26,'[1]ID1&5'!K:L,2,FALSE),"-") -> - | Q26: 0 | R26: =+IFERROR(VLOOKUP(CONCATENATE(A26,$C$10,C26),'[1]ID1&5'!B:J,8,FALSE),"-") -> - | S26: =+IFERROR(VLOOKUP(C26,'[1]ID1&5'!K:L,2,FALSE),"-") -> - | T26: 0 | U26: =+IFERROR(VLOOKUP(D26,'[1]ID1&5'!K:L,2,FALSE),"-") -> - | V26: 0 | W26: =+IFERROR(VLOOKUP(E26,'[1]ID1&5'!K:L,2,FALSE),"-") -> - | X26: 0 | Y26: =+X26/O26 -> 0 | Z26: =+IFERROR(VLOOKUP(F26,'[1]ID1&5'!K:L,2,FALSE),"-") -> - | AA26: 8 | AB26: =+AA26/O26 -> 1 | AC26: Not applicable | AD26: Not applicable | AE26: 0 | AF26: 1 | AG26: Comentário 14/11 - Campo com valor fixo de not applicable conforme a especificação funcional. | AH26: OK | AI26: Concluído
A27: =+I27&J27 -> B02.000160_RANK_INSOLV | B27: =+VLOOKUP(I27&J27,[1]Auxiliar!B:C,2,FALSE) -> 2 | C27: =+VLOOKUP(I27&J27,[1]Auxiliar!E:F,2,FALSE) -> 2 | D27: =+VLOOKUP(I27&J27,[1]Auxiliar!H:I,2,FALSE) -> 2 | E27: =+VLOOKUP(I27&J27,[1]Auxiliar!K:L,2,FALSE) -> 2 | F27: =+VLOOKUP(I27&J27,[1]Auxiliar!N:O,2,FALSE) -> 2 | G27: =+VLOOKUP(I27&J27,[1]Auxiliar!Q:R,2,FALSE) -> 2 | H27: =+"c"&LEFT(J27,4) -> c0160 | I27: B02.00 | J27: 0160_RANK_INSOLV | L27: =+VLOOKUP(J27,#REF!,3,FALSE) -> #REF! | N27: 2025-10-31 | O27: 8 | P27: =+IFERROR(VLOOKUP(B27,'[1]ID1&5'!K:L,2,FALSE),"-") -> - | Q27: 0 | R27: =+IFERROR(VLOOKUP(CONCATENATE(A27,$C$10,C27),'[1]ID1&5'!B:J,8,FALSE),"-") -> - | S27: =+IFERROR(VLOOKUP(C27,'[1]ID1&5'!K:L,2,FALSE),"-") -> - | T27: 0 | U27: =+IFERROR(VLOOKUP(D27,'[1]ID1&5'!K:L,2,FALSE),"-") -> - | V27: 0 | W27: =+IFERROR(VLOOKUP(E27,'[1]ID1&5'!K:L,2,FALSE),"-") -> - | X27: 0 | Y27: =+X27/O27 -> 0 | Z27: =+IFERROR(VLOOKUP(F27,'[1]ID1&5'!K:L,2,FALSE),"-") -> - | AA27: 0 | AB27: =+AA27/O27 -> 0 | AC27: 1 | AD27: 8 | AE27: 0 | AF27: 0 | AH27: OK | AI27: Concluído
A28: =+I28&J28 -> B02.000161_CNTRCTL_SBRDNTN | B28: =+VLOOKUP(I28&J28,[1]Auxiliar!B:C,2,FALSE) -> 2 | C28: =+VLOOKUP(I28&J28,[1]Auxiliar!E:F,2,FALSE) -> 2 | D28: =+VLOOKUP(I28&J28,[1]Auxiliar!H:I,2,FALSE) -> 2 | E28: =+VLOOKUP(I28&J28,[1]Auxiliar!K:L,2,FALSE) -> 2 | F28: =+VLOOKUP(I28&J28,[1]Auxiliar!N:O,2,FALSE) -> 2 | G28: =+VLOOKUP(I28&J28,[1]Auxiliar!Q:R,2,FALSE) -> 2 | H28: =+"c"&LEFT(J28,4) -> c0161 | I28: B02.00 | J28: 0161_CNTRCTL_SBRDNTN | L28: =+VLOOKUP(J28,#REF!,3,FALSE) -> #REF! | N28: 2025-10-31 | O28: 8 | P28: =+IFERROR(VLOOKUP(B28,'[1]ID1&5'!K:L,2,FALSE),"-") -> - | Q28: 0 | R28: =+IFERROR(VLOOKUP(CONCATENATE(A28,$C$10,C28),'[1]ID1&5'!B:J,8,FALSE),"-") -> - | S28: =+IFERROR(VLOOKUP(C28,'[1]ID1&5'!K:L,2,FALSE),"-") -> - | T28: 0 | U28: =+IFERROR(VLOOKUP(D28,'[1]ID1&5'!K:L,2,FALSE),"-") -> - | V28: 0 | W28: =+IFERROR(VLOOKUP(E28,'[1]ID1&5'!K:L,2,FALSE),"-") -> - | X28: 0 | Y28: =+X28/O28 -> 0 | Z28: =+IFERROR(VLOOKUP(F28,'[1]ID1&5'!K:L,2,FALSE),"-") -> - | AA28: 8 | AB28: =+AA28/O28 -> 1 | AC28: 999999999999999.00 | AD28: 999999999999999.00 | AE28: 0 | AF28: 0 | AG28: Comentário 14/11 - Campo com valor fixo de not applicable conforme a especificação funcional. | AH28: OK | AI28: Concluído
A29: =+I29&J29 -> B02.000162_BAIL_IN_CASCADE | B29: =+VLOOKUP(I29&J29,[1]Auxiliar!B:C,2,FALSE) -> 2 | C29: =+VLOOKUP(I29&J29,[1]Auxiliar!E:F,2,FALSE) -> 2 | D29: =+VLOOKUP(I29&J29,[1]Auxiliar!H:I,2,FALSE) -> 2 | E29: =+VLOOKUP(I29&J29,[1]Auxiliar!K:L,2,FALSE) -> 2 | F29: =+VLOOKUP(I29&J29,[1]Auxiliar!N:O,2,FALSE) -> 2 | G29: =+VLOOKUP(I29&J29,[1]Auxiliar!Q:R,2,FALSE) -> 2 | H29: =+"c"&LEFT(J29,4) -> c0162 | I29: B02.00 | J29: 0162_BAIL_IN_CASCADE | L29: =+VLOOKUP(J29,#REF!,3,FALSE) -> #REF! | N29: 2025-10-31 | O29: 8 | P29: =+IFERROR(VLOOKUP(B29,'[1]ID1&5'!K:L,2,FALSE),"-") -> - | Q29: 0 | R29: =+IFERROR(VLOOKUP(CONCATENATE(A29,$C$10,C29),'[1]ID1&5'!B:J,8,FALSE),"-") -> - | S29: =+IFERROR(VLOOKUP(C29,'[1]ID1&5'!K:L,2,FALSE),"-") -> - | T29: 0 | U29: =+IFERROR(VLOOKUP(D29,'[1]ID1&5'!K:L,2,FALSE),"-") -> - | V29: 0 | W29: =+IFERROR(VLOOKUP(E29,'[1]ID1&5'!K:L,2,FALSE),"-") -> - | X29: 0 | Y29: =+X29/O29 -> 0 | Z29: =+IFERROR(VLOOKUP(F29,'[1]ID1&5'!K:L,2,FALSE),"-") -> - | AA29: 0 | AB29: =+AA29/O29 -> 0 | AC29: 1 | AD29: 8 | AE29: 0 | AF29: 0 | AH29: OK | AI29: Concluído
A30: =+I30&J30 -> B02.000170_DT_INCPTN | B30: =+VLOOKUP(I30&J30,[1]Auxiliar!B:C,2,FALSE) -> 2 | C30: =+VLOOKUP(I30&J30,[1]Auxiliar!E:F,2,FALSE) -> 2 | D30: =+VLOOKUP(I30&J30,[1]Auxiliar!H:I,2,FALSE) -> 2 | E30: =+VLOOKUP(I30&J30,[1]Auxiliar!K:L,2,FALSE) -> 2 | F30: =+VLOOKUP(I30&J30,[1]Auxiliar!N:O,2,FALSE) -> 2 | G30: =+VLOOKUP(I30&J30,[1]Auxiliar!Q:R,2,FALSE) -> 2 | H30: =+"c"&LEFT(J30,4) -> c0170 | I30: B02.00 | J30: 0170_DT_INCPTN | L30: =+VLOOKUP(J30,#REF!,3,FALSE) -> #REF! | N30: 2025-10-31 | O30: 8 | P30: =+IFERROR(VLOOKUP(B30,'[1]ID1&5'!K:L,2,FALSE),"-") -> - | Q30: 0 | R30: =+IFERROR(VLOOKUP(CONCATENATE(A30,$C$10,C30),'[1]ID1&5'!B:J,8,FALSE),"-") -> - | S30: =+IFERROR(VLOOKUP(C30,'[1]ID1&5'!K:L,2,FALSE),"-") -> - | T30: 0 | U30: =+IFERROR(VLOOKUP(D30,'[1]ID1&5'!K:L,2,FALSE),"-") -> - | V30: 0 | W30: =+IFERROR(VLOOKUP(E30,'[1]ID1&5'!K:L,2,FALSE),"-") -> - | X30: 0 | Y30: =+X30/O30 -> 0 | Z30: =+IFERROR(VLOOKUP(F30,'[1]ID1&5'!K:L,2,FALSE),"-") -> - | AA30: 0 | AB30: =+AA30/O30 -> 0 | AC30: 33608 | AD30: 45806 | AE30: 1 | AF30: 0 | AH30: OK | AI30: Concluído
A31: =+I31&J31 -> B02.000180_DT_NXT_INTRST_PYMNT | B31: =+VLOOKUP(I31&J31,[1]Auxiliar!B:C,2,FALSE) -> 2 | C31: =+VLOOKUP(I31&J31,[1]Auxiliar!E:F,2,FALSE) -> 2 | D31: =+VLOOKUP(I31&J31,[1]Auxiliar!H:I,2,FALSE) -> 2 | E31: =+VLOOKUP(I31&J31,[1]Auxiliar!K:L,2,FALSE) -> 2 | F31: =+VLOOKUP(I31&J31,[1]Auxiliar!N:O,2,FALSE) -> 2 | G31: =+VLOOKUP(I31&J31,[1]Auxiliar!Q:R,2,FALSE) -> 2 | H31: =+"c"&LEFT(J31,4) -> c0180 | I31: B02.00 | J31: 0180_DT_NXT_INTRST_PYMNT | L31: =+VLOOKUP(J31,#REF!,3,FALSE) -> #REF! | N31: 2025-10-31 | O31: 8 | P31: =+IFERROR(VLOOKUP(B31,'[1]ID1&5'!K:L,2,FALSE),"-") -> - | Q31: 8 | R31: =+IFERROR(VLOOKUP(CONCATENATE(A31,$C$10,C31),'[1]ID1&5'!B:J,8,FALSE),"-") -> - | S31: =+IFERROR(VLOOKUP(C31,'[1]ID1&5'!K:L,2,FALSE),"-") -> - | T31: 0 | U31: =+IFERROR(VLOOKUP(D31,'[1]ID1&5'!K:L,2,FALSE),"-") -> - | V31: 0 | W31: =+IFERROR(VLOOKUP(E31,'[1]ID1&5'!K:L,2,FALSE),"-") -> - | X31: 0 | Y31: =+X31/O31 -> 0 | Z31: =+IFERROR(VLOOKUP(F31,'[1]ID1&5'!K:L,2,FALSE),"-") -> - | AA31: 4 | AB31: =+AA31/O31 -> 0.5 | AC31: 0001-01-01 | AD31: 2026-06-10 | AE31: 0 | AF31: 0 | AG31: Comentário 14/11 - Os registos referem-se a instrumentos de capital e não é expectável que exista uma data | AH31: OK | AI31: Em curso
A32: =+I32&J32 -> B02.000190_DT_NXT_RDMPTN_PYMNT | B32: =+VLOOKUP(I32&J32,[1]Auxiliar!B:C,2,FALSE) -> 2 | C32: =+VLOOKUP(I32&J32,[1]Auxiliar!E:F,2,FALSE) -> 2 | D32: =+VLOOKUP(I32&J32,[1]Auxiliar!H:I,2,FALSE) -> 2 | E32: =+VLOOKUP(I32&J32,[1]Auxiliar!K:L,2,FALSE) -> 2 | F32: =+VLOOKUP(I32&J32,[1]Auxiliar!N:O,2,FALSE) -> 2 | G32: =+VLOOKUP(I32&J32,[1]Auxiliar!Q:R,2,FALSE) -> 2 | H32: =+"c"&LEFT(J32,4) -> c0190 | I32: B02.00 | J32: 0190_DT_NXT_RDMPTN_PYMNT | L32: =+VLOOKUP(J32,#REF!,3,FALSE) -> #REF! | N32: 2025-10-31 | O32: 8 | P32: =+IFERROR(VLOOKUP(B32,'[1]ID1&5'!K:L,2,FALSE),"-") -> - | Q32: 1 | R32: =+IFERROR(VLOOKUP(CONCATENATE(A32,$C$10,C32),'[1]ID1&5'!B:J,8,FALSE),"-") -> - | S32: =+IFERROR(VLOOKUP(C32,'[1]ID1&5'!K:L,2,FALSE),"-") -> - | T32: 0 | U32: =+IFERROR(VLOOKUP(D32,'[1]ID1&5'!K:L,2,FALSE),"-") -> - | V32: 0 | W32: =+IFERROR(VLOOKUP(E32,'[1]ID1&5'!K:L,2,FALSE),"-") -> - | X32: 0 | Y32: =+X32/O32 -> 0 | Z32: =+IFERROR(VLOOKUP(F32,'[1]ID1&5'!K:L,2,FALSE),"-") -> - | AA32: 4 | AB32: =+AA32/O32 -> 0.5 | AC32: 0001-01-01 | AD32: 2030-07-30 | AE32: 0 | AF32: 0 | AG32: Comentário 14/11 - 3 registos referem-se a instrumentos sem maturidade contratualizada (cd_captools.fr004_cto, data_vencimento='9999-12-%'). 1 registo com o valor '2069-01-14', que se refere à data de perpetuidade, no entanto por indicação de Pedro Mendes, em sede de reunião, foi alterado para '0001-01-01'. | AH32: OK | AI32: Concluído
A33: =+I33&J33 -> B02.000200_DT_ERLST_RDMPTN | B33: =+VLOOKUP(I33&J33,[1]Auxiliar!B:C,2,FALSE) -> 2 | C33: =+VLOOKUP(I33&J33,[1]Auxiliar!E:F,2,FALSE) -> 2 | D33: =+VLOOKUP(I33&J33,[1]Auxiliar!H:I,2,FALSE) -> 2 | E33: =+VLOOKUP(I33&J33,[1]Auxiliar!K:L,2,FALSE) -> 2 | F33: =+VLOOKUP(I33&J33,[1]Auxiliar!N:O,2,FALSE) -> 2 | G33: =+VLOOKUP(I33&J33,[1]Auxiliar!Q:R,2,FALSE) -> 2 | H33: =+"c"&LEFT(J33,4) -> c0200 | I33: B02.00 | J33: 0200_DT_ERLST_RDMPTN | L33: =+VLOOKUP(J33,#REF!,3,FALSE) -> #REF! | N33: 2025-10-31 | O33: 8 | P33: =+IFERROR(VLOOKUP(B33,'[1]ID1&5'!K:L,2,FALSE),"-") -> - | Q33: 0 | R33: =+IFERROR(VLOOKUP(CONCATENATE(A33,$C$10,C33),'[1]ID1&5'!B:J,8,FALSE),"-") -> - | S33: =+IFERROR(VLOOKUP(C33,'[1]ID1&5'!K:L,2,FALSE),"-") -> - | T33: 0 | U33: =+IFERROR(VLOOKUP(D33,'[1]ID1&5'!K:L,2,FALSE),"-") -> - | V33: 0 | W33: =+IFERROR(VLOOKUP(E33,'[1]ID1&5'!K:L,2,FALSE),"-") -> - | X33: 0 | Y33: =+X33/O33 -> 0 | Z33: =+IFERROR(VLOOKUP(F33,'[1]ID1&5'!K:L,2,FALSE),"-") -> - | AA33: 8 | AB33: =+AA33/O33 -> 1 | AC33: 0001-01-01 | AD33: 0001-01-01 | AE33: 0 | AF33: 0 | AG33: Comentário 14/11 - Campo com valor fixo de not applicable conforme a especificação funcional. | AH33: OK | AI33: Concluído
A34: =+I34&J34 -> B02.000210_DT_LGL_FNL_MTRTY | B34: =+VLOOKUP(I34&J34,[1]Auxiliar!B:C,2,FALSE) -> 2 | C34: =+VLOOKUP(I34&J34,[1]Auxiliar!E:F,2,FALSE) -> 2 | D34: =+VLOOKUP(I34&J34,[1]Auxiliar!H:I,2,FALSE) -> 2 | E34: =+VLOOKUP(I34&J34,[1]Auxiliar!K:L,2,FALSE) -> 2 | F34: =+VLOOKUP(I34&J34,[1]Auxiliar!N:O,2,FALSE) -> 2 | G34: =+VLOOKUP(I34&J34,[1]Auxiliar!Q:R,2,FALSE) -> 2 | H34: =+"c"&LEFT(J34,4) -> c0210 | I34: B02.00 | J34: 0210_DT_LGL_FNL_MTRTY | L34: =+VLOOKUP(J34,#REF!,3,FALSE) -> #REF! | N34: 2025-10-31 | O34: 8 | P34: =+IFERROR(VLOOKUP(B34,'[1]ID1&5'!K:L,2,FALSE),"-") -> - | Q34: 1 | R34: =+IFERROR(VLOOKUP(CONCATENATE(A34,$C$10,C34),'[1]ID1&5'!B:J,8,FALSE),"-") -> - | S34: =+IFERROR(VLOOKUP(C34,'[1]ID1&5'!K:L,2,FALSE),"-") -> - | T34: 0 | U34: =+IFERROR(VLOOKUP(D34,'[1]ID1&5'!K:L,2,FALSE),"-") -> - | V34: 0 | W34: =+IFERROR(VLOOKUP(E34,'[1]ID1&5'!K:L,2,FALSE),"-") -> - | X34: 0 | Y34: =+X34/O34 -> 0 | Z34: =+IFERROR(VLOOKUP(F34,'[1]ID1&5'!K:L,2,FALSE),"-") -> - | AA34: 4 | AB34: =+AA34/O34 -> 0.5 | AC34: 0001-01-01 | AD34: 2030-07-30 | AE34: 0 | AF34: 0 | AG34: Comentário 14/11 - 3 registos referem-se a instrumentos sem maturidade contratualizada (cd_captools.fr004_cto, data_vencimento='9999-12-%'). 1 registo com o valor '2069-01-14', que se refere à data de perpetuidade, no entanto por indicação de Pedro Mendes, em sede de reunião, foi alterado para '0001-01-01'. | AH34: OK | AI34: Concluído
A35: =+I35&J35 -> B02.000220_GOVERNING_LAW | B35: =+VLOOKUP(I35&J35,[1]Auxiliar!B:C,2,FALSE) -> 2 | C35: =+VLOOKUP(I35&J35,[1]Auxiliar!E:F,2,FALSE) -> 2 | D35: =+VLOOKUP(I35&J35,[1]Auxiliar!H:I,2,FALSE) -> 2 | E35: =+VLOOKUP(I35&J35,[1]Auxiliar!K:L,2,FALSE) -> 2 | F35: =+VLOOKUP(I35&J35,[1]Auxiliar!N:O,2,FALSE) -> 2 | G35: =+VLOOKUP(I35&J35,[1]Auxiliar!Q:R,2,FALSE) -> 2 | H35: =+"c"&LEFT(J35,4) -> c0220 | I35: B02.00 | J35: 0220_GOVERNING_LAW | L35: =+VLOOKUP(J35,#REF!,3,FALSE) -> #REF! | N35: 2025-10-31 | O35: 8 | P35: =+IFERROR(VLOOKUP(B35,'[1]ID1&5'!K:L,2,FALSE),"-") -> - | Q35: 0 | R35: =+IFERROR(VLOOKUP(CONCATENATE(A35,$C$10,C35),'[1]ID1&5'!B:J,8,FALSE),"-") -> - | S35: =+IFERROR(VLOOKUP(C35,'[1]ID1&5'!K:L,2,FALSE),"-") -> - | T35: 0 | U35: =+IFERROR(VLOOKUP(D35,'[1]ID1&5'!K:L,2,FALSE),"-") -> - | V35: 0 | W35: =+IFERROR(VLOOKUP(E35,'[1]ID1&5'!K:L,2,FALSE),"-") -> - | X35: 0 | Y35: =+X35/O35 -> 0 | Z35: =+IFERROR(VLOOKUP(F35,'[1]ID1&5'!K:L,2,FALSE),"-") -> - | AA35: 0 | AB35: =+AA35/O35 -> 0 | AC35: PT | AD35: PT | AE35: 0 | AF35: 0 | AH35: OK | AI35: Concluído
A36: =+I36&J36 -> B02.000230_BAIL_IN_RCGNTN_CLS | B36: =+VLOOKUP(I36&J36,[1]Auxiliar!B:C,2,FALSE) -> 2 | C36: =+VLOOKUP(I36&J36,[1]Auxiliar!E:F,2,FALSE) -> 2 | D36: =+VLOOKUP(I36&J36,[1]Auxiliar!H:I,2,FALSE) -> 2 | E36: =+VLOOKUP(I36&J36,[1]Auxiliar!K:L,2,FALSE) -> 2 | F36: =+VLOOKUP(I36&J36,[1]Auxiliar!N:O,2,FALSE) -> 2 | G36: =+VLOOKUP(I36&J36,[1]Auxiliar!Q:R,2,FALSE) -> 2 | H36: =+"c"&LEFT(J36,4) -> c0230 | I36: B02.00 | J36: 0230_BAIL_IN_RCGNTN_CLS | L36: =+VLOOKUP(J36,#REF!,3,FALSE) -> #REF! | N36: 2025-10-31 | O36: 8 | P36: =+IFERROR(VLOOKUP(B36,'[1]ID1&5'!K:L,2,FALSE),"-") -> - | Q36: 0 | R36: =+IFERROR(VLOOKUP(CONCATENATE(A36,$C$10,C36),'[1]ID1&5'!B:J,8,FALSE),"-") -> - | S36: =+IFERROR(VLOOKUP(C36,'[1]ID1&5'!K:L,2,FALSE),"-") -> - | T36: 0 | U36: =+IFERROR(VLOOKUP(D36,'[1]ID1&5'!K:L,2,FALSE),"-") -> - | V36: 0 | W36: =+IFERROR(VLOOKUP(E36,'[1]ID1&5'!K:L,2,FALSE),"-") -> - | X36: 0 | Y36: =+X36/O36 -> 0 | Z36: =+IFERROR(VLOOKUP(F36,'[1]ID1&5'!K:L,2,FALSE),"-") -> - | AA36: 0 | AB36: =+AA36/O36 -> 0 | AC36: Yes, supported by Legal Opinion | AD36: Yes, supported by Legal Opinion | AE36: 0 | AF36: 0 | AH36: OK | AI36: Concluído
A37: =+I37&J37 -> B02.000240_ZERO_COUPON | B37: =+VLOOKUP(I37&J37,[1]Auxiliar!B:C,2,FALSE) -> 2 | C37: =+VLOOKUP(I37&J37,[1]Auxiliar!E:F,2,FALSE) -> 2 | D37: =+VLOOKUP(I37&J37,[1]Auxiliar!H:I,2,FALSE) -> 2 | E37: =+VLOOKUP(I37&J37,[1]Auxiliar!K:L,2,FALSE) -> 2 | F37: =+VLOOKUP(I37&J37,[1]Auxiliar!N:O,2,FALSE) -> 2 | G37: =+VLOOKUP(I37&J37,[1]Auxiliar!Q:R,2,FALSE) -> 2 | H37: =+"c"&LEFT(J37,4) -> c0240 | I37: B02.00 | J37: 0240_ZERO_COUPON | L37: =+VLOOKUP(J37,#REF!,3,FALSE) -> #REF! | N37: 2025-10-31 | O37: 8 | P37: =+IFERROR(VLOOKUP(B37,'[1]ID1&5'!K:L,2,FALSE),"-") -> - | Q37: 0 | R37: =+IFERROR(VLOOKUP(CONCATENATE(A37,$C$10,C37),'[1]ID1&5'!B:J,8,FALSE),"-") -> - | S37: =+IFERROR(VLOOKUP(C37,'[1]ID1&5'!K:L,2,FALSE),"-") -> - | T37: 0 | U37: =+IFERROR(VLOOKUP(D37,'[1]ID1&5'!K:L,2,FALSE),"-") -> - | V37: 0 | W37: =+IFERROR(VLOOKUP(E37,'[1]ID1&5'!K:L,2,FALSE),"-") -> - | X37: 0 | Y37: =+X37/O37 -> 0 | Z37: =+IFERROR(VLOOKUP(F37,'[1]ID1&5'!K:L,2,FALSE),"-") -> - | AA37: 0 | AB37: =+AA37/O37 -> 0 | AC37: No ZCB | AD37: No ZCB | AE37: 0 | AF37: 0 | AH37: OK | AI37: Concluído
A38: =+I38&J38 -> B02.000250_STRCTRD_PRDCT | B38: =+VLOOKUP(I38&J38,[1]Auxiliar!B:C,2,FALSE) -> 2 | C38: =+VLOOKUP(I38&J38,[1]Auxiliar!E:F,2,FALSE) -> 2 | D38: =+VLOOKUP(I38&J38,[1]Auxiliar!H:I,2,FALSE) -> 2 | E38: =+VLOOKUP(I38&J38,[1]Auxiliar!K:L,2,FALSE) -> 2 | F38: =+VLOOKUP(I38&J38,[1]Auxiliar!N:O,2,FALSE) -> 2 | G38: =+VLOOKUP(I38&J38,[1]Auxiliar!Q:R,2,FALSE) -> 2 | H38: =+"c"&LEFT(J38,4) -> c0250 | I38: B02.00 | J38: 0250_STRCTRD_PRDCT | L38: =+VLOOKUP(J38,#REF!,3,FALSE) -> #REF! | N38: 2025-10-31 | O38: 8 | P38: =+IFERROR(VLOOKUP(B38,'[1]ID1&5'!K:L,2,FALSE),"-") -> - | Q38: 0 | R38: =+IFERROR(VLOOKUP(CONCATENATE(A38,$C$10,C38),'[1]ID1&5'!B:J,8,FALSE),"-") -> - | S38: =+IFERROR(VLOOKUP(C38,'[1]ID1&5'!K:L,2,FALSE),"-") -> - | T38: 0 | U38: =+IFERROR(VLOOKUP(D38,'[1]ID1&5'!K:L,2,FALSE),"-") -> - | V38: 0 | W38: =+IFERROR(VLOOKUP(E38,'[1]ID1&5'!K:L,2,FALSE),"-") -> - | X38: 0 | Y38: =+X38/O38 -> 0 | Z38: =+IFERROR(VLOOKUP(F38,'[1]ID1&5'!K:L,2,FALSE),"-") -> - | AA38: 0 | AB38: =+AA38/O38 -> 0 | AC38: Non-structured/Vanilla | AD38: Non-structured/Vanilla | AE38: 0 | AF38: 0 | AH38: OK | AI38: Concluído
A39: =+I39&J39 -> B02.000260_GRNTD_MIN_AMNT_STRCTRD_PRDCT | B39: =+VLOOKUP(I39&J39,[1]Auxiliar!B:C,2,FALSE) -> 2 | C39: =+VLOOKUP(I39&J39,[1]Auxiliar!E:F,2,FALSE) -> 2 | D39: =+VLOOKUP(I39&J39,[1]Auxiliar!H:I,2,FALSE) -> 2 | E39: =+VLOOKUP(I39&J39,[1]Auxiliar!K:L,2,FALSE) -> 2 | F39: =+VLOOKUP(I39&J39,[1]Auxiliar!N:O,2,FALSE) -> 2 | G39: =+VLOOKUP(I39&J39,[1]Auxiliar!Q:R,2,FALSE) -> 2 | H39: =+"c"&LEFT(J39,4) -> c0260 | I39: B02.00 | J39: 0260_GRNTD_MIN_AMNT_STRCTRD_PRDCT | L39: =+VLOOKUP(J39,#REF!,3,FALSE) -> #REF! | N39: 2025-10-31 | O39: 8 | P39: =+IFERROR(VLOOKUP(B39,'[1]ID1&5'!K:L,2,FALSE),"-") -> - | Q39: 0 | R39: =+IFERROR(VLOOKUP(CONCATENATE(A39,$C$10,C39),'[1]ID1&5'!B:J,8,FALSE),"-") -> - | S39: =+IFERROR(VLOOKUP(C39,'[1]ID1&5'!K:L,2,FALSE),"-") -> - | T39: 0 | U39: =+IFERROR(VLOOKUP(D39,'[1]ID1&5'!K:L,2,FALSE),"-") -> - | V39: 0 | W39: =+IFERROR(VLOOKUP(E39,'[1]ID1&5'!K:L,2,FALSE),"-") -> - | X39: 0 | Y39: =+X39/O39 -> 0 | Z39: =+IFERROR(VLOOKUP(F39,'[1]ID1&5'!K:L,2,FALSE),"-") -> - | AA39: 8 | AB39: =+AA39/O39 -> 1 | AC39: 999999999999999.00 | AD39: 999999999999999.00 | AE39: 0 | AF39: 0 | AG39: Comentário 14/11 - Campo com valor fixo de not applicable conforme a especificação funcional. | AH39: OK | AI39: Concluído
A40: =+I40&J40 -> B02.000270_FV_AMNT_STRCTRD_PRDCT | B40: =+VLOOKUP(I40&J40,[1]Auxiliar!B:C,2,FALSE) -> 2 | C40: =+VLOOKUP(I40&J40,[1]Auxiliar!E:F,2,FALSE) -> 2 | D40: =+VLOOKUP(I40&J40,[1]Auxiliar!H:I,2,FALSE) -> 2 | E40: =+VLOOKUP(I40&J40,[1]Auxiliar!K:L,2,FALSE) -> 2 | F40: =+VLOOKUP(I40&J40,[1]Auxiliar!N:O,2,FALSE) -> 2 | G40: =+VLOOKUP(I40&J40,[1]Auxiliar!Q:R,2,FALSE) -> 2 | H40: =+"c"&LEFT(J40,4) -> c0270 | I40: B02.00 | J40: 0270_FV_AMNT_STRCTRD_PRDCT | L40: =+VLOOKUP(J40,#REF!,3,FALSE) -> #REF! | N40: 2025-10-31 | O40: 8 | P40: =+IFERROR(VLOOKUP(B40,'[1]ID1&5'!K:L,2,FALSE),"-") -> - | Q40: 0 | R40: =+IFERROR(VLOOKUP(CONCATENATE(A40,$C$10,C40),'[1]ID1&5'!B:J,8,FALSE),"-") -> - | S40: =+IFERROR(VLOOKUP(C40,'[1]ID1&5'!K:L,2,FALSE),"-") -> - | T40: 0 | U40: =+IFERROR(VLOOKUP(D40,'[1]ID1&5'!K:L,2,FALSE),"-") -> - | V40: 0 | W40: =+IFERROR(VLOOKUP(E40,'[1]ID1&5'!K:L,2,FALSE),"-") -> - | X40: 0 | Y40: =+X40/O40 -> 0 | Z40: =+IFERROR(VLOOKUP(F40,'[1]ID1&5'!K:L,2,FALSE),"-") -> - | AA40: 8 | AB40: =+AA40/O40 -> 1 | AC40: 999999999999999.00 | AD40: 999999999999999.00 | AE40: 0 | AF40: 0 | AG40: Comentário 14/11 - Campo com valor fixo de not applicable conforme a especificação funcional. | AH40: OK | AI40: Concluído
A41: =+I41&J41 -> B02.000280_FLG_NCNP_DPSTS | B41: =+VLOOKUP(I41&J41,[1]Auxiliar!B:C,2,FALSE) -> 2 | C41: =+VLOOKUP(I41&J41,[1]Auxiliar!E:F,2,FALSE) -> 2 | D41: =+VLOOKUP(I41&J41,[1]Auxiliar!H:I,2,FALSE) -> 2 | E41: =+VLOOKUP(I41&J41,[1]Auxiliar!K:L,2,FALSE) -> 2 | F41: =+VLOOKUP(I41&J41,[1]Auxiliar!N:O,2,FALSE) -> 2 | G41: =+VLOOKUP(I41&J41,[1]Auxiliar!Q:R,2,FALSE) -> 2 | H41: =+"c"&LEFT(J41,4) -> c0280 | I41: B02.00 | J41: 0280_FLG_NCNP_DPSTS | L41: =+VLOOKUP(J41,#REF!,3,FALSE) -> #REF! | N41: 2025-10-31 | O41: 8 | P41: =+IFERROR(VLOOKUP(B41,'[1]ID1&5'!K:L,2,FALSE),"-") -> - | Q41: 0 | R41: =+IFERROR(VLOOKUP(CONCATENATE(A41,$C$10,C41),'[1]ID1&5'!B:J,8,FALSE),"-") -> - | S41: =+IFERROR(VLOOKUP(C41,'[1]ID1&5'!K:L,2,FALSE),"-") -> - | T41: 0 | U41: =+IFERROR(VLOOKUP(D41,'[1]ID1&5'!K:L,2,FALSE),"-") -> - | V41: 0 | W41: =+IFERROR(VLOOKUP(E41,'[1]ID1&5'!K:L,2,FALSE),"-") -> - | X41: 0 | Y41: =+X41/O41 -> 0 | Z41: =+IFERROR(VLOOKUP(F41,'[1]ID1&5'!K:L,2,FALSE),"-") -> - | AA41: 0 | AB41: =+AA41/O41 -> 0 | AC41: FALSE | AD41: FALSE | AE41: 0 | AF41: 0 | AH41: OK | AI41: Concluído
