Workbook
Name _Toc51154475: Mapeamentos!$B$3
Name _Toc51154476: Mapeamentos!#REF!
Name _Toc51154477: Mapeamentos!#REF!
Name _Toc51154478: Mapeamentos!#REF!
Name _Toc51154479: Mapeamentos!#REF!
Name _Toc51154480: Mapeamentos!#REF!
Name _Toc51154482: Mapeamentos!#REF!
Name _Toc51154483: Mapeamentos!#REF!
Name _Toc51154484: Mapeamentos!#REF!
Name _Toc51154485: Mapeamentos!#REF!

Sheet PDS
E1: Estado Especificação | V1: Estado Desenvolvimento
C2: Total | E2: Concluido | G2: Mapeamento com LT fechado, mas parametrização pendente | I2: Novo campo, mapeamento datalake fechado, com necessidade de criar parametrização | K2: Novo campo, mapeamento datalake fechado, sem necessidade de criar parametrização | M2: Novo campo, mapeamento datalake pendente, com necessidade de criar parametrização | O2: Novo campo, mapeamento datalake pendente, sem necessidade de criar parametrização | Q2: Em curso | S2: Por iniciar | U2: Total | V2: Concluido | X2: Em curso | Z2: Por iniciar
B3: Submódulo | C3: abs | D3: Total (%) | E3: abs | F3: % | G3: abs | H3: % | I3: abs | J3: % | K3: abs | L3: % | M3: abs | N3: % | O3: abs | P3: % | Q3: abs | R3: % | S3: abs | T3: % | V3: abs | W3: % | X3: abs | Y3: % | Z3: abs | AA3: %
B4: DATA POINTS FOR IDENTIFICATION | C4: 13 | D4: =SUM(F4,H4,J4,L4,N4,O4,P4,R4,T4) -> 1 | E4: =COUNTIF(Mapeamentos!J4:J16,"Concluido") -> 13 | F4: =E4/C4 -> 1 | G4: =COUNTIF(Mapeamentos!AF4:AF16,"Mapeamento com LT fechado, mas parametrização pendente") -> 0 | H4: =G4/C4 -> 0 | I4: =COUNTIF(Mapeamentos!AF4:AH16,"Novo campo, mapeamento datalake fechado, com necessidade de criar parametrização") -> 0 | J4: =COUNTIF(Mapeamentos!AO10:AT12,"Mapeamento com LT fechado, mas parametrização pendente") -> 0 | K4: =COUNTIF(Mapeamentos!AF4:AF16,"Novo campo, mapeamento datalake fechado, sem necessidade de criar parametrização") -> 0 | L4: =COUNTIF(Mapeamentos!AW10:BD10,"Mapeamento com LT fechado, mas parametrização pendente") -> 0 | M4: =COUNTIF(Mapeamentos!AF4:AF16,"Novo campo, mapeamento datalake pendente, com necessidade de criar parametrização") -> 0 | N4: =COUNTIF(Mapeamentos!BK10:CB10,"Mapeamento com LT fechado, mas parametrização pendente") -> 0 | O4: =COUNTIF(Mapeamentos!AF4:AF16,"Novo campo, mapeamento datalake pendente, sem necessidade de criar parametrização") -> 0 | P4: =O4/C4 -> 0 | Q4: =COUNTIF(Mapeamentos!J4:J16,"Em curso") -> 0 | R4: =Q4/C4 -> 0 | S4: =COUNTIF(Mapeamentos!J4:J16,"Por iniciar") -> 0 | T4: =S4/C4 -> 0 | U4: =SUM(G4,E4,I4,K4,M4,O4,S4) -> 13 | V4: =COUNTIF(Mapeamentos!K4:K16,"Concluido") -> 13 | W4: =V4/C4 -> 1 | X4: =COUNTIF(Mapeamentos!K4:K16,"Em curso") -> 0 | Y4: =X4/C4 -> 0 | Z4: =COUNTIF(Mapeamentos!K4:K16,"Por iniciar") -> 0 | AA4: =Z4/C4 -> 0
B5: DATA POINTS FOR LINK WITH OWN FUNDS | C5: 6 | D5: =SUM(F5,H5,J5,L5,N5,O5,P5,R5,T5) -> 1 | E5: =COUNTIF(Mapeamentos!J17:J22,"Concluido") -> 6 | F5: =E5/C5 -> 1 | G5: =COUNTIF(Mapeamentos!AF17:AF22,"Mapeamento com LT fechado, mas parametrização pendente") -> 0 | H5: =G5/C5 -> 0 | I5: =COUNTIF(Mapeamentos!AF17:AF22,"Novo campo, mapeamento datalake fechado, com necessidade de criar parametrização") -> 0 | J5: =COUNTIF(Mapeamentos!AO12:AT14,"Mapeamento com LT fechado, mas parametrização pendente") -> 0 | K5: =COUNTIF(Mapeamentos!AF17:AF22,"Novo campo, mapeamento datalake fechado, sem necessidade de criar parametrização") -> 0 | L5: =COUNTIF(Mapeamentos!AW11:BD11,"Mapeamento com LT fechado, mas parametrização pendente") -> 0 | M5: =COUNTIF(Mapeamentos!AF17:AF22,"Novo campo, mapeamento datalake pendente, com necessidade de criar parametrização") -> 0 | N5: =COUNTIF(Mapeamentos!BK11:CB11,"Mapeamento com LT fechado, mas parametrização pendente") -> 0 | O5: =COUNTIF(Mapeamentos!AF17:AF22,"Novo campo, mapeamento datalake pendente, sem necessidade de criar parametrização") -> 0 | P5: =O5/C5 -> 0 | Q5: =COUNTIF(Mapeamentos!J17:J22,"Em curso") -> 0 | R5: =Q5/C5 -> 0 | S5: =COUNTIF(Mapeamentos!J17:J22,"Por iniciar") -> 0 | T5: =S5/C5 -> 0 | U5: =SUM(G5,E5,I5,K5,M5,O5,S5) -> 6 | V5: =COUNTIF(Mapeamentos!K17:K22,"Concluido") -> 6 | W5: =V5/C5 -> 1 | X5: =COUNTIF(Mapeamentos!K17:K22,"Em curso") -> 0 | Y5: =X5/C5 -> 0 | Z5: =COUNTIF(Mapeamentos!K17:K22,"Por iniciar") -> 0 | AA5: =Z5/C5 -> 0
B6: DATA POINTS FOR LINK WITH ACCOUNTING | C6: 2 | D6: =SUM(F6,H6,J6,L6,N6,O6,P6,R6,T6) -> 1 | E6: =COUNTIF(Mapeamentos!J23:J24,"Concluido") -> 2 | F6: =E6/C6 -> 1 | G6: =COUNTIF(Mapeamentos!AF23:AF24,"Mapeamento com LT fechado, mas parametrização pendente") -> 0 | H6: =G6/C6 -> 0 | I6: =COUNTIF(Mapeamentos!AF23:AF24,"Novo campo, mapeamento datalake fechado, com necessidade de criar parametrização") -> 0 | J6: =COUNTIF(Mapeamentos!AO12:AT14,"Mapeamento com LT fechado, mas parametrização pendente") -> 0 | K6: =COUNTIF(Mapeamentos!AF23:AF24,"Novo campo, mapeamento datalake fechado, sem necessidade de criar parametrização") -> 0 | L6: =COUNTIF(Mapeamentos!AW12:BD12,"Mapeamento com LT fechado, mas parametrização pendente") -> 0 | M6: =COUNTIF(Mapeamentos!AF23:AF24,"Novo campo, mapeamento datalake pendente, com necessidade de criar parametrização") -> 0 | N6: =COUNTIF(Mapeamentos!BK12:CB12,"Mapeamento com LT fechado, mas parametrização pendente") -> 0 | O6: =COUNTIF(Mapeamentos!AF23:AF24,"Novo campo, mapeamento datalake pendente, sem necessidade de criar parametrização") -> 0 | P6: =O6/C6 -> 0 | Q6: =COUNTIF(Mapeamentos!J23:J24,"Em curso") -> 0 | R6: =Q6/C6 -> 0 | S6: =COUNTIF(Mapeamentos!J23:J24,"Por iniciar") -> 0 | T6: =S6/C6 -> 0 | U6: =SUM(G6,E6,I6,K6,M6,O6,S6) -> 2 | V6: =COUNTIF(Mapeamentos!K23:K24,"Concluido") -> 2 | W6: =V6/C6 -> 1 | X6: =COUNTIF(Mapeamentos!K23:K24,"Em curso") -> 0 | Y6: =X6/C6 -> 0 | Z6: =COUNTIF(Mapeamentos!K23:K24,"Por iniciar") -> 0 | AA6: =Z6/C6 -> 0
B7: DATA POINTS FOR AMOUNTS REQUIRED FOR CALCULATION | C7: 8 | D7: =SUM(F7,H7,J7,L7,N7,O7,P7,R7,T7) -> 1 | E7: =COUNTIF(Mapeamentos!J25:J32,"Concluido") -> 8 | F7: =E7/C7 -> 1 | G7: =COUNTIF(Mapeamentos!AF25:AF32,"Mapeamento com LT fechado, mas parametrização pendente") -> 0 | H7: =G7/C7 -> 0 | I7: =COUNTIF(Mapeamentos!AF25:AF32,"Novo campo, mapeamento datalake fechado, com necessidade de criar parametrização") -> 0 | J7: =COUNTIF(Mapeamentos!AO13:AT15,"Mapeamento com LT fechado, mas parametrização pendente") -> 0 | K7: =COUNTIF(Mapeamentos!AF25:AF32,"Novo campo, mapeamento datalake fechado, sem necessidade de criar parametrização") -> 0 | L7: =COUNTIF(Mapeamentos!AW13:BD13,"Mapeamento com LT fechado, mas parametrização pendente") -> 0 | M7: =COUNTIF(Mapeamentos!AF25:AF32,"Novo campo, mapeamento datalake pendente, com necessidade de criar parametrização") -> 0 | N7: =COUNTIF(Mapeamentos!BK13:CB13,"Mapeamento com LT fechado, mas parametrização pendente") -> 0 | O7: =COUNTIF(Mapeamentos!AF25:AF32,"Novo campo, mapeamento datalake pendente, sem necessidade de criar parametrização") -> 0 | P7: =O7/C7 -> 0 | Q7: =COUNTIF(Mapeamentos!J25:J32,"Em curso") -> 0 | R7: =Q7/C7 -> 0 | S7: =COUNTIF(Mapeamentos!J25:J32,"Por iniciar") -> 0 | T7: =S7/C7 -> 0 | U7: =SUM(G7,E7,I7,K7,M7,O7,S7) -> 8 | V7: =COUNTIF(Mapeamentos!K25:K32,"Concluido") -> 8 | W7: =V7/C7 -> 1 | X7: =COUNTIF(Mapeamentos!K25:K32,"Em curso") -> 0 | Y7: =X7/C7 -> 0 | Z7: =COUNTIF(Mapeamentos!K25:K32,"Por iniciar") -> 0 | AA7: =Z7/C7 -> 0
B8: DATA POINTS FOR INFORMATION ON THE INVESTOR/CREDITOR | C8: 6 | D8: =SUM(F8,H8,J8,L8,N8,O8,P8,R8,T8) -> 1 | E8: =COUNTIF(Mapeamentos!J33:J38,"Concluido") -> 6 | F8: =E8/C8 -> 1 | G8: =COUNTIF(Mapeamentos!AF33:AF38,"Mapeamento com LT fechado, mas parametrização pendente") -> 0 | H8: =G8/C8 -> 0 | I8: =COUNTIF(Mapeamentos!AF33:AF38,"Novo campo, mapeamento datalake fechado, com necessidade de criar parametrização") -> 0 | J8: =COUNTIF(Mapeamentos!AO14:AT16,"Mapeamento com LT fechado, mas parametrização pendente") -> 0 | K8: =COUNTIF(Mapeamentos!AF33:AF38,"Novo campo, mapeamento datalake fechado, sem necessidade de criar parametrização") -> 0 | L8: =COUNTIF(Mapeamentos!AW14:BD14,"Mapeamento com LT fechado, mas parametrização pendente") -> 0 | M8: =COUNTIF(Mapeamentos!AF33:AF38,"Novo campo, mapeamento datalake pendente, com necessidade de criar parametrização") -> 0 | N8: =COUNTIF(Mapeamentos!BK14:CB14,"Mapeamento com LT fechado, mas parametrização pendente") -> 0 | O8: =COUNTIF(Mapeamentos!AF33:AF38,"Novo campo, mapeamento datalake pendente, sem necessidade de criar parametrização") -> 0 | P8: =O8/C8 -> 0 | Q8: =COUNTIF(Mapeamentos!J33:J38,"Em curso") -> 0 | R8: =Q8/C8 -> 0 | S8: =COUNTIF(Mapeamentos!J33:J38,"Por iniciar") -> 0 | T8: =S8/C8 -> 0 | U8: =SUM(G8,E8,I8,K8,M8,O8,S8) -> 6 | V8: =COUNTIF(Mapeamentos!K33:K38,"Concluido") -> 6 | W8: =V8/C8 -> 1 | X8: =COUNTIF(Mapeamentos!K33:K38,"Em curso") -> 0 | Y8: =X8/C8 -> 0 | Z8: =COUNTIF(Mapeamentos!K33:K38,"Por iniciar") -> 0 | AA8: =Z8/C8 -> 0
B9: DATA POINTS FOR GUARANTEES | C9: 18 | D9: =SUM(F9,H9,J9,L9,N9,O9,P9,R9,T9) -> 1 | E9: =COUNTIF(Mapeamentos!J39:J56,"Concluido") -> 18 | F9: =E9/C9 -> 1 | G9: =COUNTIF(Mapeamentos!AF39:AF56,"Mapeamento com LT fechado, mas parametrização pendente") -> 0 | H9: =G9/C9 -> 0 | I9: =COUNTIF(Mapeamentos!AF39:AF56,"Novo campo, mapeamento datalake fechado, com necessidade de criar parametrização") -> 0 | J9: =COUNTIF(Mapeamentos!AO15:AT17,"Mapeamento com LT fechado, mas parametrização pendente") -> 0 | K9: =COUNTIF(Mapeamentos!AF39:AF56,"Novo campo, mapeamento datalake fechado, sem necessidade de criar parametrização") -> 0 | L9: =COUNTIF(Mapeamentos!AW15:BD15,"Mapeamento com LT fechado, mas parametrização pendente") -> 0 | M9: =COUNTIF(Mapeamentos!AF39:AF56,"Novo campo, mapeamento datalake pendente, com necessidade de criar parametrização") -> 0 | N9: =COUNTIF(Mapeamentos!BK15:CB15,"Mapeamento com LT fechado, mas parametrização pendente") -> 0 | O9: =COUNTIF(Mapeamentos!AF39:AF56,"Novo campo, mapeamento datalake pendente, sem necessidade de criar parametrização") -> 0 | P9: =O9/C9 -> 0 | Q9: =COUNTIF(Mapeamentos!J39:J56,"Em curso") -> 0 | R9: =Q9/C9 -> 0 | S9: =COUNTIF(Mapeamentos!J39:J56,"Por iniciar") -> 0 | T9: =S9/C9 -> 0 | U9: =SUM(G9,E9,I9,K9,M9,O9,S9) -> 18 | V9: =COUNTIF(Mapeamentos!K39:K56,"Concluido") -> 18 | W9: =V9/C9 -> 1 | X9: =COUNTIF(Mapeamentos!K39:K56,"Em curso") -> 0 | Y9: =X9/C9 -> 0 | Z9: =COUNTIF(Mapeamentos!K39:K56,"Por iniciar") -> 0 | AA9: =Z9/C9 -> 0
B10: Total | C10: =SUM(C4:C9) -> 53 | D10: =SUM(F10,H10,J10,L10,N10,O10,P10,R10,T10) -> 1 | E10: =SUM(E4:E9) -> 53 | F10: =E10/C10 -> 1 | G10: =SUM(G4:G9) -> 0 | H10: =G10/C10 -> 0 | I10: =SUM(I4:I9) -> 0 | J10: =I10/C10 -> 0 | K10: =SUM(K4:K9) -> 0 | L10: =K10/C10 -> 0 | M10: =SUM(M4:M9) -> 0 | N10: =M10/C10 -> 0 | O10: =SUM(O4:O9) -> 0 | P10: =O10/C10 -> 0 | Q10: =SUM(Q4:Q9) -> 0 | R10: =Q10/C10 -> 0 | S10: =SUM(S4:S9) -> 0 | T10: =S10/C10 -> 0 | V10: =SUM(V4:V9) -> 53 | W10: =V10/C10 -> 1 | X10: =SUM(X4:X9) -> 0 | Y10: =X10/C10 -> 0 | Z10: =SUM(Z4:Z9) -> 0 | AA10: =Z10/C10 -> 0

Sheet Mapeamentos
B2: Instruções SRB - Bail-in data set | G2: Análise IT | N2: Instruções SRB - Novo Bail-in (MBDT) | Q2: Análise IT (Comparativo com o novo MBDT) | Z2: Análise IT + CDO (Old) | AH2: Mapeamento Financeira
B3: Tipo | C3: SRB_ID | D3: Data Point | E3: Attribute | F3: Definition | G3: Nome do campo na tabela bu_captools_work.bail_in_srb | H3: Mapeamento | I3: Comentários | J3: Estado Especificação | K3: Estado Desenvolvimento | L3: Estado Validação | N3: Ficheiro | O3: Data Point | P3: Definition | Q3: Definição igual? | R3: Estado especificação Anterior | S3: Mapeamento Anterior | T3: Requer reanálise no Novo Bail-in? | U3: Comentário | X3: Pertence/ Não Pertence ao novo Bail-in? | Z3: Nome do campo na tabela | AA3: Nome do campo no ficheiro | AB3: Desdodrável? | AC3: Mapeamento LT / Comentários | AD3: Description LT | AE3: Field Definition LT | AF3: Estado especificação | AH3: Tabela Data Lake | AI3: Campo Data Lake | AJ3: Comentário
B4: 4.2.1. DATA POINTS FOR IDENTIFICATION | C4: 1 | D4: Legal entity | E4: [Entity name] | F4: Name of the subsidiary. Free-form text identification of incorporation name of the entity for which the table is reported. Please state the official name as it is listed in corporate acts, including the indication of the incorporation form. | G4: legal_entity | H4: Campo Fixo: "BANCO SANTANDER TOTTA, S.A" | I4: Reunião Pedro Mendes 2025-01-21 | J4: Concluido | K4: Concluido | L4: OK | N4: B99.00 | O4: Name of Legal Entity | P4: Free-form text identification of the incorporation name of the entity for which the table is reported. Please state the official name as listed in corporate registry, including the indication of the company form. | Q4: Sim | R4: Concluido | S4: Novo campo lt002_instrument.entidade_desc | T4: Não | U4: No novo Bail-in este campo constará no ficheiro B99.00 que será produzido manualmente pelo Pedro Mendes | X4: 1 - Pertence ao novo Bail-in | AB4: Não | AC4: Reunião 02/10/2024 Luís Capitão-Mor, Pedro Mendes: Novo campo lt002_instrument.entidade_desc Este novo campo converterá o campo lt002_instrument.entidade que contém os códigos de Entidade Locais ('00100', '00110', ...) para o respetivo descritivo ('BANCO SANTANDER TOTTA' , 'SANTANDER-PENSOES-SOC.GEST.FUNDOS' , ...). Para tal, será necessário recorrer à tabela cd_captools.perimetro ligando o campo lt002_instrument.entidade com o campo "cod_soc_cpus", e obter o campo "descricao". Nota: Bruno Matos procedeu à alteração na tabela cd_captools.perimetro da descrição "BANCO SANTANDER TOTTA" para "BANCO SANTANDER TOTTA, S.A." no caso de cod_soc_cpus 00100 (email de Bruno Matos 31/10/2024 12:11) | AF4: Concluido | AJ4: Campo Fixo - "Banco Santander Totta S.A."
B5: 4.2.1. DATA POINTS FOR IDENTIFICATION | C5: =+C4+1 -> 2 | D5: Legal entity identifier | E5: [LEI code] | F5: LEI code (unique code) identifying the reporting entity. | G5: lei_code | H5: Campo Fixo: "549300URJH9VSI58CS32" | I5: Reunião Pedro Mendes 2025-01-21 | J5: Concluido | K5: Concluido | L5: OK | N5: B99.00 | O5: LEI of Legal Entity | P5: The unique LEI code for the entity, in line with the requirements of EMIR or the Dodd-Frank Act, for which the report is submitted. In the absence of an LEI, the ECB Monetary Financial Institutions unique Identifier (MFI ID) of the entity for use in RIAD (Register of Institutions and Affiliates Database) should be used. In the absence of both such identifiers, a local identifier must be used. | Q5: Não Contudo, aparenta ser o mesmo | R5: Concluido | S5: Novo campo lt002_instrument.lei_rprtng_entty. | T5: Não | U5: No novo Bail-in este campo constará no ficheiro B99.00 que será produzido manualmente pelo Pedro Mendes | X5: 1 - Pertence ao novo Bail-in | AB5: Não | AC5: Reunião 02/10/2024 Luís Capitão-Mor, Pedro Mendes: Novo campo lt002_instrument.lei_rprtng_entty. Partindo do campo entidade (codigo da entidade local) da lt002_instrument : 1) Identificam-se os zcliente's associados a cada consolpt (codigo da entidade local) através da tabela cd_captools.clientes_intragrupo; 2) Identificam-se os ccli_grupo's associados a esses zcliente's através da tabela cd_captools.ct003_univ_cli; 3) Identificam-se os zcliente's associados a esses ccli_grupo's através da tabela cd_captools.ct003_univ_cli; 4) Retiram-se os zcliente's com clei = '#'; 5) Para o caso de uma entidade apresentar mais do que um clei, utilizar a mesma regra que atualmente se aplica no campo lei da tabela lt003_entity (com o objetivo de se selecionar apenas um único clei). | AF5: Concluido | AJ5: Campo Fixo - "549300URJH9VSI58CS32"
B6: 4.2.1. DATA POINTS FOR IDENTIFICATION | C6: =+C5+1 -> 3 | D6: Unique identification number for the liability | E6: [ISIN/Specific ID] | F6: ID provided by the resolution entity for a liability (e.g. ISIN, contract number, account number). | G6: id_liability | H6: concat(cempresa, cbalcao, cnumecta, zdeposit) da cd_captools.fr004_cto | I6: Reunião Pedro Mendes 2025-01-21 | J6: Concluido | K6: Concluido | L6: OK | N6: B02.00 | O6: Unique internal identification number ou Unique identification number (known to the counterparty) | P6: The unique internal identifier of the instrument/liability. For deposits reported on an aggregate level, please indicate: ‘NCNP’ for the aggregated not covered not preferential deposits (field c0280 = TRUE); and ▪ ‘NCBP’ for the aggregated not covered but preferential deposits (field c0290 = TRUE). ou The unique identifier of the instrument/liability that would allow the counterparty to conclude that it will be affected by the potential resolution action, without external third parties being able to identify the creditor. For securities, the ISIN code must be indicated where available (other identifiers need only be provided in the absence of an ISIN). For deposits and other liabilities, the account/contract number should be reported. In the event of multiple tranches (multiple counterparties) of one promissory-note loan (e.g. Schuldscheindarlehen) or a syndicated loan, a unique ID must be allocated to each tranche. For deposits reported on an aggregate level, please indicate: ▪ ‘NCNP’ for the aggregated not covered not preferential deposits (field c0280 = TRUE); and ▪ ‘NCBP’ for the aggregated not covered but preferential deposits (field c0290 = TRUE). | Q6: Não | R6: Concluido | S6: lt002_instrument.instrmnt_id | T6: Sim | U6: Novo campo lt002_instrument.instrmnt_id_knwn_cntrprty em que -Se títulos: isin -Se não títulos: instrmnt_id | X6: 1 - Pertence ao novo Bail-in | AB6: Não | AC6: Reunião 02/10/2024 Luís Capitão-Mor, Pedro Mendes: lt002_instrument.instrmnt_id | AD6: Instrument ID | AE6: LT002_INSTRUMENT.INSTRMNT_ID: An identifier applied by the reporting agent to uniquely identify each instrument under a single contract. Each instrument must have one instrument identifier. This value will not change over time and cannot be used as the instrument identifier for any other instrument under the same contract. Supervised Insitutions are asked to furnish the INSTRMNT_ID with the exact same value as it is reported to AnaCredit (or any similar central credit register). If this is not available, the value shall be reported as it is internally used. If an instrument is not reported to AnaCredit but requested for the purposes of the on-site inspection please provide the bank-internally used value. | AF6: Concluido | AH6: AL029_CNT_CORE / AL030_SLD_CORE_M CT610_titulos | AI6: Chave cempresa_cbalcao_cnumecta_zdeposit para ALM isin para emissões (títulos) | AJ6: Para todos os produtos menos emissões (títulos) Para emissões (títulos)
B7: 4.2.1. DATA POINTS FOR IDENTIFICATION | C7: =+C6+1 -> 4 | D7: Nature of the instrument | E7: [e.g. bond, shares, reserves, contingent liability] | F7: Information on the nature of the liability | G7: nature_instrument | H7: 1) Para os registos que estão na cd_captools.ct610_titulos obter o campo tipo_titulo; 2) Para os registos que não estão na cd_captools.ct610_titulos aplicar a seguinte lógica: Partindo do cproduto da cd_captools.fr004_cto, obter o respetivo descritivo na cd_estruturais.tat91_tabelas (TAYD91C0_CTABELA = '023') no campo tayd91c0_gelemtab (ligando por tayd91c0_celemtab) 3) Por último, fazer o seguinte mapeamento: CARTOES MISTOS -> Other CONFIRMING -> Other CONTA CHEQUE FORNECEDORES -> Other CONTABILIZACAO CARTEIRA PROPRIA-TITULOS -> Other CONTAS CORRENTES - M.N. -> Other CONTAS CORRENTES - M/E -> Other CONTAS INTERNAS - M.N. -> Other CONTAS INTERNAS - MOEDA ESTRANGEIRA (NOSTROS) -> Other D.O. ESPECIAL -> Cash account/saving account DEP.ORDEM ME (OFFSHORE MADEIRA) -> Cash account/saving account DEP.ORDEM MN(OFFSHORE MADEIRA) -> Cash account/saving account DEPOSITO A ORDEM - M.N. (OFFSHORE CAYMAN) -> Cash account/saving account DEPOSITO A ORDEM - M.N. -> Cash account/saving account DEPOSITO A ORDEM - MOEDA ESTRANGEIRA OFFSHORE -> Cash account/saving account DEPOSITO A ORDEM - MOEDA ESTRANGEIRA -> Cash account/saving account DEPOSITO A PRAZO EM MOEDA NACIONAL -> Term deposit DEPOSITOS A PRAZO - M.E. -> Term deposit DEPOSITOS A PRAZO - M.N. (OFFSHORE) -> Term deposit DEPOSITOS A PRAZO - POUPANCA REFORMA -> Term deposit DEPOSITOS A PRAZO - PRODUTOS ESTRUTURADOS -> Term deposit DEPOSITOS A PRAZO EM MOEDA ESTRANGEIRA -> Term deposit DEPOSITOS A PRAZO EM MOEDA NACIONAL -> Term deposit DEPOSITOS DE POUPANCA -> Term deposit DEVEDORES / CREDORES DIVERSOS -> Other EMPRESTIMOS -> Other ESTRANGEIRO-AVALES E GARANTIAS -> Other FACTORING -> Other Obrigacao Hipotecaria -> Registered Bond Obrigacao Senior -> Registered Bond Obrigacao Subordinada -> Registered Bond PRODUTO GESTAO BALCAO -> Other PRODUTOS ESTRANGEIRO - CREDITOS DOCUMENTARIOS IMPORTACAO -> Other RESERVADO PARA NOVA APLICACAO DE TESOURARIA -> Borrower Note Loan SANTANDER - PRODUTOS TESOURARIA -> Other SUPER SATISFACAO RECARREGAVEL -> Other Titularizacao Sintetica -> Registered Bond Titularizacao -> Registered Bond Acao Ordinaria -> Title of ownership Acao Preferencial -> Title of ownership Emprestimo Subordinado -> Registered Bond Instrumento Fundos Proprios Adicionais Nivel 1 (AT1) -> Registered Bond Prestacao Suplementar -> Title of ownership Suprimento -> Title of ownership NULL ->MISS | I7: Reunião Pedro Mendes 2025-02-17 1) Estes cprodutos não têm tradução na TAT023, contudo, sabe-se que o cproduto 0V0 é Factoring portanto, nesse caso, o descritivo será "Factoring". Ou seja sobram apenas 33315+5 registos sem cproduto e que não vão ter nature instrument (0,77% do Universo). cproduto count(*) 33315 0V0 34797 96 5 | J7: Concluido | K7: Concluido | L7: OK | N7: B02.00 | O7: Nature of the liability | P7: The corresponding category of the instrument/liability. Value to be chosen from the following drop-down list: • Registered Bond • Bearer Bond • Borrower Note Loan • Certificate of Deposit / Commercial paper • Title of ownership44 • Cash account/saving account 45 • Term deposit 46 • Loan • Bill of exchange • Other For deposits reported on an aggregated level (Submission A), please indicate ‘Other’. | Q7: Não | R7: Em curso | S7: lt002_instrument .typ_instrmnt | T7: Sim | U7: Anteriormente a Contabilidade iria preencher o instrumento_financeiro e depois terìamos de ter um mapeamento desses valores na lt809_typ_instrmnt. Contudo, no novo Bail-in existe uma drop-down a respeitar, pelo que este campo terá de ser reanalisado. | X7: 1 - Pertence ao novo Bail-in | AB7: Não | AC7: Campo comum ao Valuation Reunião 21/11/2024 Luís Capitão-Mor, Pedro Mendes, Nuno Pinheiro, Rafael Pessoa: A solução passará por adicionar novas linhas à lt809_typ_instrmnt, concretamente, no campo "instrmnt_fncr" em que se colocarão os instrumentos financeiros de tipo_conta='P' e 'C'. Garantir que a nova parametrização não vai modificar nenhum valor atual dos Contratos do Loan Tape Estrutural. Nota: Existem mais códigos que a Corporação/BCE definiu para além dos que estão na lt809_typ_instrmnt PR: 1) distinct instrumento_finaceiro da fr802 quando tipo_conta=P, C (No caso do tipo_conta=C enviou-se email a 02/12/2024 12:19 a Rafael Pessoa/Nuno Pinheiro a solicitar o preenchimento do campo instrumento_financeiro) 2) mapear instrumento_financeiro com o código typ_instrmnt da lt809 3) fazer novo mapeamento da LT809 (ou a nova multivariável ) e o mapeamento LT829 (para Inglês) Reunião 25/10/2024 Luís Capitão-Mor, Luísa Quendera, Flávia Pinho: Identificar a tabela mais completa da 925, 926, 927; a granularidade que permite responder a todos CRC, Contabilidade, Loan Tape. Cria-se uma TAT nova Este produto/subproduto (nelem1 CRC, nelem2 Contabilidade, ...) Solução1 (não será esta a seguir devido a interferência com CRC): - Perceber a agrupação/classificação que é feita na CRC atualmente (falar com Sandra Lopes). A CRC não tem o Ativo todo (por ex: papel comercial, outros devedores, ...); - Proposta de códigos para o que falta do Ativo (Sandra Lopes); - Perceber a granularidade que o SRB quer no Bail-in (Flávia/Pedro) e fazerem uma proposta de códigos; - Ver se existe um nelem que não esteja a ser utilizado Solução 4 (será esta a seguir): Ações pedidas por Luís Capitão-Mor: 1- Papel Comercial: Ver como está a sair no LT no campo typ_instrmnt (Ver com o gonçalo marques e no limite gerar: derivados, títulos, ...) : -> Verificou-se que existe o campo instrumento_financeiro na tabela na lt809_typ_instrmnt. No caso do campo instrumento_financeiro da LT001 ='instrumentos de divida' (que é o caso dos contratos de Papel Comercial), o campo typ_instrmnt será 1005 (Debt securities) 2- Tipologias que o FINREP faz de Ativo e Passivo -> O produto que é apresentado no FINREP corresponde ao campo produto da fr802_pl_contas. Exemplo: : "Deposits" na sheet F 08.01.a do FINREP -> instrumento_financeiro="depositos" "Current accounts / overnight deposits" na sheet F 08.01.a do FINREP -> produto='depositos a ordem, overnights' Nuno Pinheiro, 24/10/2024 via teams: "a 926 tem a lista dos nossos produtos/subprodutos e no campo NELEM6 colocamos um codigo auxiliar ao mapemaneto para os produtos FINREP Através desse mapeamento, as subcontas contabilisticas de cada produto FINREP são populadas através da GLT12" Este tema foi discutido na reunião de dia 02/10/2024 e na de 24/10/2024 Reunião 02/10/2024 Luís Capitão-Mor, Pedro Mendes: O campo a utilizar será lt002_instrument.typ_instrmnt. Este campo atualmente é construído partindo da concatenação dos campos cproduto, subproduto da tabela lt001_univ_oper, cruzando com o campo tayd91c0_celemtab, obtendo depois o substr(tat91.tayd91c0_nelemc19,2,4) , ligando posteriormente com o campo c_typ_instmnt da tabela cd_loan_tapes_bce.lt809_typ_instrmnt, obtendo assim o campo typ_instrmnt Temas identificados: 1) O campo tayd91c0_nelemc19 (agregador de produtos) terá de ser preenchido para passivo. 2) Teriam de ser adicionadas novas parametrizações à tabela cd_loan_tapes_bce.lt809_typ_instrmnt, contudo, o campo typ_instrmnt contém apenas códigos numéricos, mas o bail-in pede descritivos [e.g. bond, shares, reserves, contingent liability] Query draft: select distinct concat(lt001.cempresa, lt001.cbalcao, lt001.cnumecta, lt001.zdeposit), lt809.typ_instrmnt from (select * from cd_loan_tapes_bce.lt001_univ_oper where ref_date='2024-06-30' and concat(cempresa,cbalcao,cnumecta,zdeposit)='31000601388398096000000000000000') lt001 left join (select * from cd_estruturais.tat91_tabelas where data_date_part='2024-06-28' and TAYD91C0_CTABELA = '927') tat91 on concat(lt001.cproduto, lt001.subproduto) = tat91.TAYD91C0_CELEMTAB left join (select * from cd_loan_tapes_bce.lt809_typ_instrmnt where ref_date='2024-06-30') lt809 on SUBSTR(tat91.TAYD91C0_NELEMC19,2,4) = lt809.c_typ_instmnt ; select distinct instrmnt_id,typ_instrmnt from cd_loan_tapes_bce.lt002_instrument where ref_date='2024-06-30' and instrmnt_id='31000601388398096000000000000000' ; | AF7: Em curso | AH7: AL029_CNT_CORE / AL030_SLD_CORE_M CT610_titulos | AI7: cproduto / csubproduto / origem Origem | AJ7: Code list dependendo do produto
B8: 4.2.1. DATA POINTS FOR IDENTIFICATION | C8: =+C7+1 -> 5 | D8: Jurisdiction governing the contract of the claim | E8: [e.g. FR, IT] | F8: ISO 3166-1 alpha 2-country c ode. The name of the country whose law governs the instrument. If the contract is governed by the law of more than one country, the jurisdiction, which has the highest relevance for the recognition of write down and conversion powers shall be reported. If required, IRT might also request the ISO 3166-2 to ensure more granular information (e.g. state level). | G8: governing_law | H8: 1) Para os registos que estão na cd_captools.ct610_titulos obter o campo lei_aplicavel; 2) Para os registos que não estão na cd_captools.ct610_titulos colocar valor fixo 'PT'. | I8: Reunião Pedro Mendes 2025-01-21 Query: select distinct bail_in.contract_id,ct610.lei_aplicavel, coalesce(tat91.tayd91c0_nelemc09, 'PT') from (select * from bu_captools_work.universo_temp ) bail_in left join (select CONCAT(cempresa,cbalcao,cnumecta,zdeposit) as contract_id,* from cd_captools.ct610_titulos where ref_date='2024-11-30') ct610 on bail_in.contract_id = ct610.contract_id left join (select * from cd_estruturais.tat91_tabelas where data_date_part='2024-09-30' and TAYD91C0_CTABELA ='015') tat91 on ct610.lei_aplicavel = tat91.tayd91c0_celemtab; --------------------------------------------------------------------------------------------------------------------------- query para traduzir o campo lei_aplicavel (ex: 620) para ISO 3166-1 alpha 2-country code (ex: PT): select distinct ct610.lei_aplicavel, tat91.tayd91c0_nelemc09 from (select * from cd_captools.ct610_titulos where ref_date='2024-11-30') ct610 left join (select * from cd_estruturais.tat91_tabelas where data_date_part='2024-09-30' and TAYD91C0_CTABELA ='015') tat91 on ct610.lei_aplicavel = tat91.tayd91c0_celemtab | J8: Concluido | K8: Concluido | L8: OK | N8: B02.00 | O8: Governing law | P8: The ISO 3166-1 alpha-2 code of the country whose law governs the instrument (please use the ISO 3166-2 code when the law of an administrative subdivision is relevant, e.g. ‘US-NY’). If the contract is governed by the law of more than one country, the country whose law has the highest relevance for the recognition of writedown and conversion powers must be reported. For deposits reported on an aggregate level, please indicate ‘XX’. | Q8: Não Contudo, aparenta ser o mesmo | R8: Em curso | S8: Novo campo lt002_instrument (nome por definir) | T8: Sim | U8: Na nova definição é indicado: "For deposits reported on an aggregate level, please indicate ‘XX’." | X8: 1 - Pertence ao novo Bail-in | AB8: Não | AC8: Reunião 27/11/2024 com Luís Capitão-Mor, Pedro Mendes e Reunião 15/11/2024 com Luís Capitão-Mor, Pedro Mendes, Pedro Henriques, Luís Henriques, Rogério Sacadura, Sandra Santos: Títulos: campo "lei_aplicavel" da cd_captools.ct610_titulos Papel Comercial (SIGOM): Novo campo na al007_prog_ppc. Este novo campo (de preenchimento obrigatório) será acrescentado no(s) ecrã(s) respetivo do SIGOM e depois será enviado nos ficheiros sigom_ppc e sigom_irl_ppc que o ALM consome (Reunião 21/11/2024 com Luís Gatinho, Luís Capitão-Mor, Luís Henriques, Rogério Sacadura, Luís Baptista). Derivados e REPOs (SIGOM): Novo campo na al012_cq_alm. Este novo campo (de preenchimento obrigatório) será acrescentado no(s) ecrã(s) respetivo do SIGOM e depois será enviado no ficheiro cq_isda que o ALM consome (Reunião 21/11/2024 com Luís Gatinho, Luís Capitão-Mor, Luís Henriques, Rogério Sacadura, Luís Baptista) Email 26/11/2024 10:11 de Luís Capitão-Mor com a indicação das tabelas de ALM onde deverá constar este campo (al007_prog_ppc e al012_cq_alm) - Luís Capitão-Mor solicitou a Luís Henriques que envie um email com (para o Papel Comercial e Derivados/REPOs): 1) Requisitos 2) Estimativa 3) Calendário de entrega Depósitos: Segundo Pedro Mendes, deverá ser reportado 'PT' para todos os depósitos (DPs, CRPs, DOs, Estruturados, Poupança). Email recebido de Pedro Mendes a 02/12/2024 14:32. Money Market e Loan and Depo: Pedro Mendes referiu " Deverá ficar a lei do país da contraparte. Ou seja, se for com um Banco cujo país é França deve ficar “FR”, Alemanha “DE”, etc," Questões LCM: 1) Questão genérica: Qual a melhor forma de filtrar os sub universos ( derivados, titulos, depósitos, money market, papel comercial, etc ) -> pela fr802 ? Para Money Market e Loan and Depos: , Pedro Mendes referiu " Deverá ficar a lei do país da contraparte. Ou seja, se for com um Banco cujo país é França deve ficar “FR”, Alemanha “DE”, etc," . 2) Para Money Market, pode-se utilizar o campo "gpais_contraparte" da tabela al004_det_mm ? 3) Para Loan and Depos, pode-se utilizar o campo "zcliente" da tabela al010_loandepos, e em seguida ir à tabela ct003_univ_cli, e trazer o campo "cpais_residencia" ? 4) lei_aplicavel da ct610 está atualmente no formato ISO 3166-1 de 3 dígitos (ex: 620), contudo, no pedido que se fez ao SIGOM não se definiu o formato, mas deveria ser o mesmo em todo o lado: os 3 dígitos (ex: 620) ou 2 dígitos (ex: PT). Caso fossem os 3 dígitos, na tabela de parametrização multivariada transformaríamos para os 2 digitos solicitados pelo SRB. 5) ISO 3166-2 não se aplica no nosso caso, certo? -> nivel informação distritos ( PT-11 -> Lisboa, PT-13 -> Porto, etc ... ) | AF8: Em curso | AH8: CT610_titulos | AI8: lei_aplicavel | AJ8: Para todos os produtos menos emissões (títulos) - "PT" Para emissões (títulos)
B9: 4.2.1. DATA POINTS FOR IDENTIFICATION | C9: =+C8+1 -> 6 | D9: Contract currency | E9: [e.g. EUR, USD] | F9: ISO 4217 currency code. The currency in which the instrument is issued. | G9: contract_currency | H9: 1) Para os registos que estão na cd_captools.ct610_titulos obter o campo cmoeda; 2) Para os registos que não estão na cd_captools.ct610_titulos obter o campo cmoeda1 da cd_captools.fr004_cto. Adicionalmente, converter os campos cmoeda/cmoeda1 nos respetivos descritivos, que constam na cd_estruturais.tat91_tabelas (TAYD91C0_CTABELA = '206') no campo tayd91c0_gelemtab (ligando por tayd91c0_celemtab). Nota: Se o campo cmoeda1 = 'NULL' ou ' ' , forçar 'EUR'. | I9: Reunião Pedro Mendes 2025-01-21 Query para traduzir o caso do campo cmoeda1 (ex: 978) para o ISO4217 (ex: EUR): select distinct fr004_cto.cmoeda1, coalesce(tat91.TAYD91C0_NELEMC01, 'EUR') from (select * from cd_captools.fr004_cto where ref_date='2024-09-30') fr004_cto left join (select * from cd_estruturais.tat91_tabelas where data_date_part='2024-09-30' and TAYD91C0_CTABELA = '206') tat91 on fr004_cto.cmoeda1 = tat91.tayd91c0_celemtab | J9: Concluido | K9: Concluido | L9: OK | N9: B02.00 | O9: Contract currency | P9: The currency in which the instrument/liability is issued. The currency must be reported with its 3-letter ISO 4217 code. For deposits reported on an aggregate level, please indicate ‘XXX’._x000D_ | Q9: Não Contudo, aparenta ser o mesmo | R9: Concluido | S9: LT002_INSTRUMENT.CRRNCY_DNMNTN | T9: Sim | U9: Na nova definição é indicado: "For deposits reported on an aggregate level, please indicate ‘XX’." | X9: 1 - Pertence ao novo Bail-in | AB9: Não | AC9: Reunião 02/10/2024 Luís Capitão-Mor, Pedro Mendes: LT002_INSTRUMENT.CRRNCY_DNMNTN | AD9: Currency denomination | AE9: Currency denomination of instruments, in accordance with the ISO 4217 standard. | AF9: Concluido | AH9: AL029_CNT_CORE / AL030_SLD_CORE_M CT610_titulos | AI9: cmoeda_pass cmoeda | AJ9: Para todos os produtos menos emissões (títulos) Para emissões (títulos)
B10: 4.2.1. DATA POINTS FOR IDENTIFICATION | C10: =+C9+1 -> 7 | D10: Issuance Date | E10: [date] | F10: Date of the original issuance of the instrument | G10: issuance_date | H10: 1) Para os registos que estão na cd_captools.ct610_titulos obter o campo campo dt_emissao. Adicionalmente, deverá converter-se o formato do campo dt_emissao para aaaa-mm-dd (atualmente encontra-se no formato dd-mm-aaaa). 2) Para os registos que não estão na cd_captools.ct610_titulos obter o campo campo data_abertura da cd_captools.fr004_cto. | I10: Reunião Pedro Mendes 2025-01-21 Query: SELECT ct610.contract_id,concat(substr(ct610.dt_emissao,7,4),substr(ct610.dt_emissao,3,4),substr(ct610.dt_emissao,1,2)) AS dt_emissao, coalesce(concat(substr(ct610.dt_emissao,7,4),substr(ct610.dt_emissao,3,4),substr(ct610.dt_emissao,1,2)),fr004.data_abertura) AS data_emissao_final FROM (SELECT CONCAT(cempresa,cbalcao,cnumecta,zdeposit) AS contract_id,* FROM cd_captools.fr004_cto WHERE ref_date = '2024-09-30') fr004 INNER JOIN (SELECT CONCAT(cempresa,cbalcao,cnumecta,zdeposit) AS contract_id,* FROM cd_captools.ct610_titulos WHERE ref_date = '2024-09-30') ct610 ON fr004.contract_id = ct610.contract_id; Notas: verificámos que: --ref_date='2024-09-30' --#384 contratos na ct610 --#205 contratos estao na fr004 --#179 contratos não estao na fr004 Não deveriam estar todos os titulos na fr004? Aplicando os filtros definidos pela Contablidade temos apenas 64 títulos: select count( distinct ct610.contract_id) from (select * from bu_captools_work.bail_in_univ_cto) univ inner join (select CONCAT(cempresa,cbalcao,cnumecta,zdeposit) as contract_id, * from cd_captools.ct610_titulos where ref_date = '2024-09-30') ct610 on univ.contract_id = ct610.contract_id ; | J10: Concluido | K10: Concluido | L10: OK | N10: B02.00 | O10: Date of issuance | P10: Date of the original issuance of the liability. Format required: yyyy-mm-dd. This field is not applicable for liabilities of the type ‘Cash account/saving account’ (c0140) and deposits reported in aggregated form (Submission A). For securities issued as part of a tap issue, i.e. an issuance of additional securities under an ISIN that already exists, there should only be one row including all securities under that ISIN. The date of issuance should be the issuance date of the first issue under that ISIN. | Q10: Não Contudo, aparenta ser o mesmo | R10: Concluido | S10: LT002_INSTRUMENT.DT_INCPTN | T10: Sim | U10: Na nova definição é indicado: "This field is not applicable for liabilities of the type ‘Cash account/saving account’ (c0140) and deposits reported in aggregated form (Submission A)" | X10: 1 - Pertence ao novo Bail-in | AB10: Não | AC10: Reunião 02/10/2024 Luís Capitão-Mor, Pedro Mendes: LT002_INSTRUMENT.DT_INCPTN | AD10: Date of inception | AE10: The date on which the contractual relationship originated, i.e. the date on which the contract agreement becomes binding for all parties | AF10: Concluido | AH10: AL029_CNT_CORE / AL030_SLD_CORE_M CT610_titulos | AI10: dinicio dt_emissão | AJ10: Para todos os produtos menos emissões (títulos) Para emissões (títulos)
B11: 4.2.1. DATA POINTS FOR IDENTIFICATION | C11: =+C10+1 -> 8 | D11: Legal Maturity Date | E11: [date] | F11: Date of the legal, final maturity of the instrument. For perpetual instruments, this should be ‘2099-01-31’. | G11: legal_maturity_date | H11: 1) Para os registos que estão na cd_captools.ct610_titulos obter o campo campo dt_vencim. Adicionalmente, deverá converter-se o formato do campo dt_vencim para aaaa-mm-dd (atualmente encontra-se no formato dd-mm-aaaa). 2) Para os registos que não estão na cd_captools.ct610_titulos obter o campo campo data_vencimento da cd_captools.fr004_cto. | I11: Reunião Pedro Mendes 2025-02-10 Query: Aplicar mesma lógica do campo acima. | J11: Concluido | K11: Concluido | L11: OK | N11: B02.00 | O11: Legal maturity | P11: Date of the legal, final maturity of the instrument or liability (including term deposits). Format required: yyyy-mm-dd. For perpetual instruments, the bank should report ‘2099-01-31’. If not applicable, the bank should report ‘0001-01-01’. This field is not applicable for liabilities of the type ‘Cash account/saving account’ (c0140) and for deposits reported in aggregated form (Submission A). | Q11: Não Contudo, aparenta ser o mesmo | R11: Concluido | S11: LT002_INSTRUMENT.DT_LGL_FNL_MTRTY | T11: Sim | U11: Na nova definição é indicado: "This field is not applicable for liabilities of the type ‘Cash account/saving account’ (c0140) and for deposits reported in aggregated form (Submission A)." | X11: 1 - Pertence ao novo Bail-in | AB11: Não | AC11: Reunião 02/10/2024 Luís Capitão-Mor, Pedro Mendes: LT002_INSTRUMENT.DT_LGL_FNL_MTRTY | AD11: Legal final maturity date (latest repayment date) | AE11: The contractual maturity date of the instrument, taking into account any agreements amending initial contracts. As for retail revolving credit facilities this attribute is to be reported "not applicable". | AF11: Concluido | AH11: AL029_CNT_CORE / AL030_SLD_CORE_M CT610_titulos | AI11: dfim dt_vencim | AJ11: Para todos os produtos menos emissões (títulos) Para emissões (títulos)
B12: 4.2.1. DATA POINTS FOR IDENTIFICATION | C12: =+C11+1 -> 9 | D12: Earliest redemption date | E12: [date] | F12: If an option exists for the holders of the instrument to request early reimbursement, or conditions for early reimbursement are contractually foreseen, the earliest occurrence date should be completed. If the early reimbursement relates to only a portion of the liability (e.g. early reimbursement of 50% of the nominal amount), the liability should be split to take into account this partial early redemption clause. | G12: earliest_redemption_date | H12: 1) Para os registos que estão na cd_captools.ct610_titulos obter o campo dt_prim_amrt_ant_inv. 2) Para os registos que não estão na cd_captools.ct610_titulos colocar valor fixo 'N/A' (Varchar Default value for not applicable fields). Nota: Caso campo dt_prim_amrt_ant_inv da cd_captools.ct610_titulos = NULL colocar 'N/A' | J12: Concluido | K12: Concluido | L12: OK | N12: B02.00 | O12: Earliest redemption date | P12: If an option exists for holders of the instrument to request early reimbursement, or conditions for early reimbursement are contractually provided, the earliest occurrence date should be reported. Format required: yyyy-mm-dd. If that date corresponds to the legal maturity (c0210), please report the latter. If not applicable, the bank should report ‘0001-01-01’. This field is not applicable for liabilities of the type ‘Cash account/saving account’ (c0140) and for deposits reported in aggregated form (Submission A). | Q12: Não Contudo, aparenta ser o mesmo | R12: Em curso | S12: Em curso | T12: Sim | U12: Na nova definição é indicado: "If that date corresponds to the legal maturity (c0210), please report the latter. If not applicable, the bank should report ‘0001-01-01’. This field is not applicable for liabilities of the type ‘Cash account/saving account’ (c0140) and for deposits reported in aggregated form (Submission A)." | X12: 1 - Pertence ao novo Bail-in | AB12: Não | AC12: Reunião 29/11/2024, 27/11/2024 e 02/10/2024 Luís Capitão-Mor, Pedro Mendes: Terão de ser adicionados 2 campos na ct004_univ_cto/ fr004_cto, no entanto, o Loan Tape apenas consumirá o campo 2 (nesta fase estará preenchido apenas para o Ativo): Campo 1: 1ª data de quando será possível a mobilização antecipada (data de abertura + 1 ) Campo 2: Próxima data de quando será possível a mobilização antecipada (data de referência +1) - Para títulos: 1) Luis Capitão-Mor, solicitou que se verifique se a codificação dos campos de frequência da tabela al029_cnt_core_m são todos traduzidos pelas TAT's ( 248,785) Campo 1: campo dt_prim_amrt_ant_inv da ct610_titulos (primeira data possível de amortização antecipada por opção do investidores) Campo 2: campo dt_prim_amrt_ant_inv e de forma iterativa, somar campo frq_amrt_ant_inv até ultrapassar data de referência e menor que a data de vencimento. Ex: data de referência dos dados: 2024-11-30 dt_prim_amrt_ant_inv= 2024-11-15 frq_amrt_ant_inv= 201 (MENSAL) ( este campo pode assumir mais valores, Men, Diario,Trimens campo 1= 2024-11-15 campo 2= 2024-12-05 -> 2024-11-15 + ( Códigos:212,202,206,101,201,203,301) Contudo, estes dois campos estão sempre a N/A ou NULL (Pedro Mendes terá de falar com Miguel para que estes campos passem a vir preenchidos); - Para Depósitos: a) Para DPs ( alguns DPs estruturados só permitem mobilização antecipada em certos momentos) e CRPs (no fundo são DPs com pagamentos intercalares que permite reforços): Ver com a Andreia Pontífice. Ver se os interfaces DCT001, DCT02, ...(PR vai analisar tabelas do datalake). Se não encontrarmos, falar com a Andreia Pontífice (Sandra Lopes podes ajudar na conversa). Luís Capitão-Mor sabe que ela consegue acrescentar o campo sem grande dificuldade (claro que depois tem de se alterar a ingesta). Se não existir, seriam 2 campos novos no interface: Campo 1: 1ª data de quando será possível a mobilização antecipada (data de abertura + 1 ) Campo 2: Próxima data de quando será possível a mobilização antecipada (data de referência +1) Para os DPs que não permitam mobilização antecipada ficariam a N/A? (Mas para isso precisávamos de um Campo 3 que seria uma flag que indicaria se o depósito permite ou não mobilização antecipada) b) Para DOs (não terá de se adicionar nenhum campo novo pois estes 2 campos ficarão hard coded na ct004) Campo 1: data de abertura + 1 Campo 2: data de referência+1 -Falar com o João Godinho, no modelo comum de dados, quais foram as tabelas input ( indentificar as chaves,características) que foram definidas. Para DO's, DP's,CRP's Pedro Mendes: - Deverá verificar se há mais produtos em que se aplique este campo Questões LCM: Campo 1 na ct004/fr004: data de abertura + 1 Campo 2 na ct004/fr004: data de referência+1 (será este que o LT consome) | AF12: Em curso | AH12: AL029_CNT_CORE / AL030_SLD_CORE_M | AJ12: Para todos produtos é o dia seguinte à data de referência com exceção de títulos emitidos e derivados que é igual
B13: 4.2.1. DATA POINTS FOR IDENTIFICATION | C13: =+C12+1 -> 10 | D13: Date of the next interest payment | E13: [date] | F13: The payment date from which the income distribution is made available for payment by the bank. | G13: payment_interest_date | H13: Tabela cd_alm.al029_cnt_core_m: - se tipo balanço = P, buscar campo dt_prox_liq_juros_pas Nota: Usar Tradutores FINREP, ALM. | I13: Reunião Pedro Mendes 2025-01-21 | J13: Concluido | K13: Concluido | L13: OK | N13: B02.00 | O13: Date of the next interest payment | P13: The payment date from which the income distribution is made available for payment by the reporting entity. Format required: yyyy-mm-dd. If not applicable (e.g. shares), the bank should report ‘0001-01-01’. This field is not applicable for deposits reported in aggregated form (Submission A). | Q13: Não Contudo, aparenta ser o mesmo | R13: Concluido | S13: Novo campo lt002_instrument (nome por definir) | T13: Sim | U13: Na nova definição é indicado: "If not applicable (e.g. shares), the bank should report ‘0001-01-01’. This field is not applicable for deposits reported in aggregated form (Submission A)." | X13: 1 - Pertence ao novo Bail-in | AB13: Não | AC13: Reunião 15/10/2024: Luís Capitão-Mor, Pedro Mendes: Tabela cd_alm.al029_cnt_core_m: - se tipo balanço = P, buscar campo dt_prox_liq_juros_pas - se tipo balanço = A, buscar campo dt_prox_liq_juros_act | AF13: Concluido | AH13: AL029_CNT_CORE / AL030_SLD_CORE_M CT610_titulos | AI13: dt_prox_liq_jur_pass dt_proc_liq_jur | AJ13: Para todos os produtos menos emissões (títulos) Para emissões (títulos)
B14: 4.2.1. DATA POINTS FOR IDENTIFICATION | C14: =+C13+1 -> 11 | D14: Outstanding amount | E14: [Euro amount] | F14: The amount is the aggregate of the outstanding principal amount as at the request date plus, if applicable, interest accrued up to the request date and fees and charges, irrespective of whether and to what extent the relevant principal, interest or fees and charges liability was already due as at the request date and whether it is required to be recognised as an item of liabilities in the balance sheet of the subsidiary of the resolution entity prepared in accordance with the applicable accounting principles. | G14: outstanding_amount | H14: Campo msaldo_final da cd_captools.fr001_univ_saldo | I14: Mapeamento novo Reunião Pedro Mendes 2025-03-31: Campo msaldo_final da cd_captools.fr001_univ_saldo (para reconciliar com o FINREP) Mapeamento antigo Reunião Pedro Mendes 2025-02-04: Campo valor_bruto_on_p da cd_captools.fr004_cto No Loan Tape, GRSS_CRRYNG_AMNT_INSTRMNT= NVL ( SUM(-1*VALOR_BRUTO_ON) ; 0) | J14: Concluido | K14: Concluido | L14: OK | N14: B02.00 | O14: Outstanding amount | P14: Total EUR value of the outstanding amount of the instrument/deposit held by the counterparty, calculated as the sum of the amounts reported in data points c0080, c0100 and c0110 (where applicable). The amount is in fact the aggregate of the outstanding principal amount plus, if applicable, interest accrued up to the reference date, and fees and charges, irrespective of whether and to what extent the relevant principal, interest or fee-and-charge liability was already due as at the reference date and whether it is required to be recognised as a liability item in the relevant entity’s balance sheet drawn up in accordance with the applicable accounting principles. In jurisdictions where accrued interest may not rank pari passu to the liability amount, the relevant NRA may request the reporting of interest accruals on separate line items. | Q14: Não Contudo, aparenta ser o mesmo | R14: Concluido | S14: Reunião 13/12/2024: Luís Capitão-Mor, Pedro Mendes: Novo campo LT002_INSTRUMENT.GRSS_CRRYNG_AMNT_INSTRMNT_VECTOR Reunião 15/10/2024: Luís Capitão-Mor, Pedro Mendes: 'LT002_INSTRUMENT.GRSS_CRRYNG_AMNT_INSTRMNT | T14: Sim | X14: 1 - Pertence ao novo Bail-in | AB14: Sim, Montante | AC14: Reunião 13/12/2024: Luís Capitão-Mor, Pedro Mendes: Novo campo LT002_INSTRUMENT.GRSS_CRRYNG_AMNT_INSTRMNT_VECTOR Reunião 15/10/2024: Luís Capitão-Mor, Pedro Mendes: 'LT002_INSTRUMENT.GRSS_CRRYNG_AMNT_INSTRMNT | AD14: Gross carrying amount | AE14: Reported gross carrying amount for the instrument according to definition in Annex V to Implementing Regulation (EU) No 680/2014. | AF14: Concluido | AH14: AL029_CNT_CORE / AL030_SLD_CORE_M | AI14: mon_cap_st1_vivo
B15: 4.2.1. DATA POINTS FOR IDENTIFICATION | C15: =+C14+1 -> 12 | D15: Rank of liability (on- and -off balance sheet) within the national insolvency ranking | E15: [number] | F15: Rank of liability according to the national insolvency ranking. | G15: insolvency_ranking | H15: 1) Para os registos que estão na cd_captools.ct610_titulos obter o campo rank_insolv. Nota: Caso campo rank_insolv = NULL, preencher 'MISS'. 2) Para os registos que não estão na cd_captools.ct610_titulos, mapear: CARTOES MISTOS -> Ranking 14 CONFIRMING -> Ranking 9 CONTA CHEQUE FORNECEDORES -> Ranking 14 CONTABILIZACAO CARTEIRA PROPRIA-TITULOS -> Ranking 9 CONTAS CORRENTES - M.N. -> Ranking 9 CONTAS CORRENTES - M/E -> Ranking 9 CONTAS INTERNAS - M.N. -> Ranking 9 CONTAS INTERNAS - MOEDA ESTRANGEIRA (NOSTROS) -> Ranking 9 DEVEDORES / CREDORES DIVERSOS -> Ranking 14 EMPRESTIMOS -> Ranking 9 ESTRANGEIRO-AVALES E GARANTIAS -> Ranking 9 FACTORING -> Ranking 9 NULL -> Ranking 14 PRODUTO GESTAO BALCAO -> Ranking 14 PRODUTOS ESTRANGEIRO - CREDITOS DOCUMENTARIOS IMPORTACAO -> Ranking 9 RESERVADO PARA NOVA APLICACAO DE TESOURARIA -> Ranking 20 SUPER SATISFACAO RECARREGAVEL -> Ranking 12 SANTANDER - PRODUTOS TESOURARIA -> Ranking 9 Registos que estejam na fg001 e que não tenham ( calinea = '#' e flag_ativo = '1') -> Ranking 12 Nota: Os produtos apresentados acima, resultam do campo nature_instrument (SRB_ID='4') antes da conversão para Inglês. 3) Para os registos que se encontrem na tabela cd_alm.fg001_fgd com calinea = ‘#’ e flag_ativo = ‘1’: 3.1) Mapear ranking 14 (depósitos elegiveis para FGD). 3.2) Se sum(campo mtot_nao_coberto_por_depositante) por contrato da cd_alm.fg001_fgd > 0 e se SME(campo cod_empr_pme da business_sme2003361.out_sme_2003_361 in ('1','2','3')) ou Households(campo SRB_ID_34 = 'Households (1)'), criar um vector com a seguinte estrutura (14;13), ou seja, nestes casos, teremos um contrato com dois ranking's, 14 e 13. 3.3) Para os restantes, criar um vector com a seguinte estrutura (14;12), ou seja, nestes casos, teremos um contrato com dois ranking's, 14 e 12. 4) Para os restantes registos, preencher 'MISS'. 5) Para os Registos com cproduto = '020' (nature_instrument = 'Cash account/saving account') com ranking = 'MISS', mapear com ranking 9. | I15: Reunião Pedro Mendes 2025-02-17 Nota: Existem 299 registos com cproduto = '020' ( nature_instrument = 'Cash account/saving account') com ranking = 'MISS' (para ref_date='2024-12-31'). Questionou-se a Sandra Brito, no sentido de perceber qual o motivo de não estarem na tabela fg001 (email enviado 2025-03-07). Sandra Brito respondeu, dando a justificação pela qual não constam na tabela fg001 tais registos. Segundo mail enviado por Pedro Mendes ( 2025-03-14) os registos que tenham cproduto = '020' e nature_instrument = 'Cash account/saving account', deverão ter ranking 9. | J15: Concluido | K15: Concluido | N15: B02.00 | O15: Insolvency ranking_x000D_ | P15: The corresponding insolvency ranking of the instrument. Numeric value (e.g. integer of 1 or more) | Q15: Não Contudo, aparenta ser o mesmo | R15: Em curso | S15: Em curso | T15: Sim | U15: No novo Bail-in este campo poderá ir apenas até ao ranking 8 (a confirmar) | X15: 1 - Pertence ao novo Bail-in | AB15: Sim | AC15: Reunião 06/12/2024: Luís Capitão-Mor, Pedro Mendes: (O) Reunião 15/10/2024: Luís Capitão-Mor, Pedro Mendes: - Tabela de parametrização em que os campos desta tabela representam critérios: Esta tabela constará no bloco de resolução do Front-end na mesma localização da tabela de parametrização do campo abaixo (SRB_ID 13) Owner da cd_alm.fg001_fgd é a Sandra Brito Depósitos: -> 14 Covered deposits (deposits guaranteed by the FGD, up to the coverage level): if ‘calinea’ = ‘#’ and flag_ativo =‘1’ and mtot_coberto_por_depositante <= 100.000 (cd_alm.fg001_fgd) ->13 Deposits that would be eligible deposits from natural persons,micro, small and medium-sized enterprises were they not made through branches located outside the EU of institutions established within the EU Questão: O BST tem balcões foram da União Europeia? O Totta Ireland está na Irelanda portanto pertence à União Europeia. Se não houver mais balcões fora de PT para alé do Totta Ireland, então este valor de ranking não se aplica. -> 13 Eligible deposits above EUR 100,000 held by natural persons and micro, small and medium sized enterprises. if ‘calinea’ = ‘#’ and flag_ativo =‘1’ and mtot_coberto_por_depositante > 100.000 (da tabela cd_alm.fg001_fgd) if itip_cli='F' (da tabela cd_captools.ct003_univ_cli) and cod_empr_pme in ('1','2','3') (da tabela out_sme_2003_361) -> Deposits above EUR 100,000 that are not held by natural persons and micro, small and medium sized enterprises (i.e., deposits held by larger companies and some excluded deposits, such as deposits made on behalf and for the account of credit institutions), except if such deposits result from: • Operations pertaining to which a criminal court decision has been issued on account of money laundering; • The depositor has not been identified pursuant to the antimoney laundering legislation in force; and • Deposits held by persons or entities that have, in the two years before the date on which deposits became unavailable or on which a resolution measure was adopted, a direct or indirect holding which represents at least 2% of the share capital of the credit institution or have been members of the management body of the credit institution, except if proven that they did cause through their action or failure to act the financial difficulties experienced by the credit institution or helped to aggravate that situation. if ‘calinea’ = ‘#’ and flag_ativo =‘1’ and mtot_coberto_por_depositante > 100.000 (da tabela cd_alm.fg001_fgd) if itip_cli='J' (da tabela cd_captools.ct003_univ_cli) and cod_empr_pme in ('0') (da tabela out_sme_2003_361) Segundo o documento funcional do FGD (LCM partilhou e consta na pasta do Teams da documentação): "Os registos de depósito que beneficiam da cobertura pelo FGD podem identificar-se na tabela de output cd_alm.fg001_fgd considerando as condições ‘calinea’ = ‘#’ e flag_ativo = ‘1’, pelo que desconsiderando os registos que (i) tenham, automaticamente, a alínea (campo ‘calinea’) igual ao artigo 165º - “Depósitos excluídos da garantia” do Decreto-Lei 298/92 - Regime Geral das Instituições de Crédito e Sociedades Financeiras, ou em que (ii) o utilizador tenha excluído manualmente o respetivo titular na tabela de parametrização cd_alm.fg801_filtro_cli. - No PDF em anexo extraído do site de SRB, temos o Insolvency Ranking mais recente. Necessário perceber a fonte dos rankings mencionados. - existe o campo rank_insolv na tabela CT610_TITULOS, contudo verifica-se que nos útlimos dois meses, existiam mais rankings NULL's do que 3 e 17 (Pedro Mendes terá de solicitar a Miguel Silva para atualizar): ref_date rank_insolv count(*) 2024-09-30 NULL 263 2024-09-30 17 113 2024-09-30 3 8 2024-08-31 NULL 247 2024-08-31 3 8 2024-08-31 17 113 | AF15: Em curso | AH15: AL029_CNT_CORE / AL030_SLD_CORE_M CT610_titulos | AI15: cproduto / csubproduto / origem Origem | AJ15: Code list dependendo do produto
