Workbook
Name Excel_BuiltIn_Sheet_Title_1: "Cabeçalho"
Name Excel_BuiltIn_Sheet_Title_10: "Descrição contratos fechados"
Name Excel_BuiltIn_Sheet_Title_11: "Operações Reporte"
Name Excel_BuiltIn_Sheet_Title_12: "Empréstimo de valores"
Name Excel_BuiltIn_Sheet_Title_13: "Validações"
Name Excel_BuiltIn_Sheet_Title_14: "Instruções"
Name Excel_BuiltIn_Sheet_Title_15: "versao"
Name Excel_BuiltIn_Sheet_Title_2: "Provisões Técnicas"
Name Excel_BuiltIn_Sheet_Title_3: "Representação"
Name Excel_BuiltIn_Sheet_Title_4: "Grupo económico"
Name Excel_BuiltIn_Sheet_Title_5: "Carteira"
Name Excel_BuiltIn_Sheet_Title_6: "Mapa Carteira 2"
Name Excel_BuiltIn_Sheet_Title_7: "Mapa Carteira 3"
Name Excel_BuiltIn_Sheet_Title_8: "Carteira Derivados"
Name Excel_BuiltIn_Sheet_Title_9: "Descrição contratos abertos"

Sheet Cabeçalho
A1: Resposta ao Relatório de Prevenção do Branqueamento de Capitais e Financiamento do Terrorismo
A3: Data: | B3: 45657
A4: CE: | B4: 419501250
A5: NE: | B5: BST
A6: ID: | B6: José Mota Veiga - Financial Crime Compliance
A7: Atividade em: | B7: GGG
A8: Tipo de período de reporte: | B8: Anual
A9: LEI: | B9: 549300URJH9VSI58CS32
A10: Ano a que respeita o reporte: | B10: =IF(B3=0,"",YEAR(B3)) -> 2024
A14: INFORMAÇÃO RELATIVA AO TRATAMENTO DE DADOS PESSOAIS
A15: (Titular de dados pessoais)
A17: a) Responsável, fundamento e finalidades
A18: Os dados pessoais recolhidos através da presente norma regulamentar são tratados pela Autoridade de Supervisão de Seguros e Fundos de Pensões (ASF), pessoa coletiva de direito público com o n.º 501 328 599 e com sede na Avenida da República, n.º 76, 1600-205, Lisboa, no respeito pelo Regulamento (UE) n.º 2016/679, do Parlamento Europeu e do Conselho, de 27 de abril de 2016 (“RGPD”) e demais legislação de proteção de dados aplicável, com base no cumprimento de obrigação jurídica e no exercício de funções de interesse público de que a ASF está investida, conforme estabelecido nas alíneas c) e e) do n.º 1 do artigo 6.º do RGPD.
A19: O referido tratamento de dados pessoais tem como finalidade o exercício das competências de supervisão que estão legalmente cometidas à ASF, conforme previsto na alínea a) do n.º 1 do artigo 84.º e no artigo 85.º da Lei n.º 83/2017, de 18 de agosto, que estabelece as medidas de combate ao branqueamento de capitais e ao financiamento do terrorismo.
A20: Os dados pessoais recolhidos através da presente norma regulamentar podem ainda ser tratados pela ASF para as seguintes finalidades posteriores: - Gestão de reclamações apresentadas junto da ASF, ao abrigo do disposto na alínea d) do n.º 7 do artigo 16.º dos Estatutos da ASF, aprovados pelo Decreto-Lei n.º 1/2015, de 6 de janeiro; - Aplicação de sanções, ao abrigo do disposto no n.º 5 do artigo 16.º dos Estatutos da ASF, aprovados pelo Decreto-Lei n.º 1/2015, de 6 de janeiro, de acordo com a primeira parte do artigo 10.º do RGPD.
A21: b) Obrigatoriedade
A22: O fornecimento de dados pessoais à ASF pelas entidades obrigadas para estas finalidades é obrigatório, nos termos das alíneas j) e k) do n.º 1 e nas alíneas a) e d) do n.º 2 do artigo 3.º da Lei n.º 83/2017, de 18 de agosto.
A23: c) Conservação
A24: Os dados pessoais recolhidos serão conservados enquanto forem necessários ao cumprimento das finalidades inerentes à supervisão das entidades supervisionadas e, após a sua cessação, pelo tempo correspondente ao prazo prescricional do procedimento criminal ou contraordenacional aplicável por ilícitos relacionados com a atividade seguradora e de gestão de fundos de pensões.
A25: d) Destinatários
A26: Os dados pessoais recolhidos podem ser partilhados nos termos do regime legal de troca de informações aplicável à ASF, previsto no Capítulo IX da Lei n.º 83/2017, de 18 de agosto, nos artigos 32.º a 38.º do RJASR, 72.º a 75.º do RJDS e 202.º a 207.º do RJFP.
... A43: O titular dos dados tem ainda direito a apresentar reclamação à autoridade de controlo (CNPD - Comissão Nacional de Proteção de Dados, www.cnpd.pt)

Sheet Info Institucional
B1: Resposta ao Relatório de Prevenção do Branqueamento de Capitais e Financiamento do Terrorismo
B2: Informação Institucional
A4: Questões
B5: Informação geral
B6: Período de Referência
A7: 1. a) | B7: Início | C7: =+IF(Cabeçalho!B3=0,"","01/01/"&YEAR((Cabeçalho!B3))) -> 01/01/2024
A8: 1. b) | B8: Termo | C8: =IF(Cabeçalho!B3=0,"",Cabeçalho!B3) -> 45657
A9: 2.1. a) | B9: Denominação social | C9: Banco Santander Totta, S.A
A10: 2.1. b) | B10: Número de Identificação de Pessoa Coletiva (NIPC) | C10: 500844321
A11: 2.1. c) | B11: Código LEI (Legal Entity Identifier) | C11: =IF(Cabeçalho!B9=0,"",Cabeçalho!B9) -> 549300URJH9VSI58CS32
A12: 2.1. d) | B12: Número de registo junto da ASF | C12: =IF(Cabeçalho!B4=0,"",Cabeçalho!B4) -> 419501250
A13: 2.1. e) | B13: Morada
A14: 2.1. e) - i) | B14: Da sede, para as entidades obrigadas com sede em Portugal | C14: Rua do Ouro, 88 - 1100-063 Lisboa
A15: 2.1. e) - ii) | B15: Do estabelecimento, para as sucursais situadas em território português das entidades obrigadas, ou outras de natureza equivalente, que tenham sede no estrangeiro
A16: 2.1. f) | B16: Identificação dos beneficiários efetivos
B17: Nome | C17: 1. José Carlos Brito Sítima; 2. Pedro Aires Coruche Castro e Almeida; 3. Amílcar da Silva Lourenço; 4. Ana Isabel Abranches Pereira de Carvalho Morais; 5. Cristina Alvarez Alvarez; 6. Daniel Abel Monteiro Palhares Traça; 7. Isabel Cristina da Silva Guerreiro; 8. João Pedro Cabral Tavares; 9. Manuel António Amaral Franco Preto; 10. Manuel Maria de Olazábal Albuquerque; 11. Maria Manuela Machado Costa Farelo Ataíde Marques; 12. Miguel Belo de Carvalho; 13. Remedios Ruiz Macia; e 14. Ricardo Lopes da Costa Jorge
B18: Nome
B19: Nome
B20: Nome
B21: Código do comprovativo da última submissão no RCBE | C21: 20c49af1-2acb-4f94-bcf6-000353545ecf
B24: Órgão de administração e recursos humanos
A25: 2.2. a) | B25: Membros do órgão de administração e respetivos pelouros, sempre que aplicável
B26: Nome | C26: Pelouro
B27: Pedro Aires Coruche Castro e Almeida | CEO | C27: Pessoas e Cultura; Secretaria Geral; Cumprimento e Conduta; Gestão de Riscos; Suporte da Presidência; Comunicação.
B28: Manuel António Amaral Franco Preto | CFO | C28: Acompanhamento de Créditos; Compras e Custos; Contabilidade e Controlo de Gestão; Estratégia, Planeamento Financeiro e Estudos Económicos; Fiscalidade; Gestão Financeira e de Capital; Imóveis; Organização e Normas; Recuperações e Desinvestimento.
B29: Miguel Belo de Carvalho | C29: Private Banking; Corporate & Investment Banking; Crédito a Particulares; Wealth Management & Insurance; Sustentabilidade; Customer Care; Universidades. Relacionamento com o Grupo Santander Totta Seguros e Santander Asset Management.
B30: Isabel Cristina da Silva Guerreiro | C30: Área Comercial Particulares e Negócios; Banca Remota e Customer Experience; Gestão e Eficácia Comercial; Gestão e Estratégia de Segmento de Negócios; Gestão de Cliente e Performance Digital; Analítica e Modelos; Process; Tecnologia e Operações.
B31: Amílcar Silva Lourenço | C31: Área Comercial Empresas; Empresas Multinacionais; Grandes Empresas Norte; Grandes Empresas Sul; Gestão de Rorwa e Preço; Lending Office; Crédito Especializado e Protocolado; Fomento à Construção e IFRRU; Negócio Internacional; Projetos Especiais; Estratégia de Empresas. Responsável indicado por temas de Prevenção de Branqueamento de Capitais.
B32: Ricardo Lopes da Costa Jorge | C32: Everyday Banking; Comercialização de Soluções de Pagamento; Marca e Comunicação Corporativa.
A43: 2.2. b) | B43: No caso das sucursais, identificação do mantário geral ou seu representante e respetivo(s) substituto(s) | G43: Mandatário geral
B44: Nome | C44: Função | G44: Representante do mandatário geral
B45: N/A | G45: Substituto
A51: 2.2. c) | B51: Número total de trabalhadores | C51: 4610
B53: Atividade e áreas de negócio
A54: 2.3. a) | B54: Ativo total (líquido, em base individual) | C54: 57068000000
A55: 2.3. b) | B55: Volume de negócios, por referência ao ramo Vida e Fundos de Pensões | C55: 86670000
A56: 2.3. c) | B56: Áreas de negócio exploradas
B57: a) Seguro de vida; | C57: Sim
B58: b) Seguro de nupcialidade e seguro de natalidade; | C58: Não
B59: c) Seguros ligados a fundos de investimento; | C59: Sim
...

Sheet DC - Controlo
B1: Resposta ao Relatório de Prevenção do Branqueamento de Capitais e Financiamento do Terrorismo
B2: Dever de Controlo
A4: Questões | B4: Membro do órgão de administração ou do mandatário geral responsável
A5: 3.1. a) | B5: Nome | C5: Amílcar Silva Lourenço
A6: 3.1. b) | B6: Endereço de correio eletrónico | C6: amilcar.lourenco@santander.pt
B8: Função de responsável pelo cumprimento normativo
B9: Função de responsável pelo cumprimento normativo
A10: 3.2.1. a) | B10: Cargo | C10: Responsável área Financial Crime Compliance (FCC)
A11: 3.2.1. a) | B11: Inserção na estrutura organizativa | C11: Diretor
A12: 3.2.1. b) | B12: Data de início de funções | C12: 44972
A13: 3.2.1. c) | B13: Contacto telefónico | C13: 938886047
A14: 3.2.1. c) | B14: Endereço de correio eletrónico | C14: jose.veiga@santander.pt
A15: 3.2.1. d) | B15: Função autónoma ou cumulada com outra função | C15: Autónoma
A16: 3.2.1. d) | B16: Função com que cumula a função de responsável pelo cumprimento normativo
A17: 3.2.1. e) | B17: Número de trabalhadores afetos à função | C17: 90
A18: 3.2.1. e) | B18: Dos quais em exclusividade | C18: 81
A19: 3.2.2. | B19: Caso não se verifique a segregação entre a função de responsável pelo cumprimento normativo e outras funções, descrição de quais os mecanismos de controlo adicionais existentes que permitam mitigar os potenciais conflitos e riscos acrescidos daí emergentes | C19: N/A
B22: Serviço comum a um mesmo grupo
B23: Pertence a um grupo? | C23: Sim
A24: 3.3. | B24: Existe um serviço comum para o exercício partilhado das responsabilidades inerentes à função de responsável pelo cumprimento normativo dentro do grupo? | C24: Não
B25: NIPC das entidades obrigadas que partilham o serviço | C25: Entidade | D25: Serviços comuns
A26: 3.3. a) e c) | B26: Entidade 1
A27: 3.3. a) e c) | B27: Entidade 2
A28: 3.3. a) e c) | B28: Entidade 3
A29: 3.3. a) e c) | B29: Entidade 4
A30: 3.3. a) e c) | B30: Entidade 5
A31: 3.3. a) e c) | B31: Entidade 6
A32: 3.3. a) e c) | B32: Entidade 7
A33: 3.3. a) e c) | B33: Entidade 8
A34: 3.3. a) e c) | B34: Entidade 9
A35: 3.3. a) e c) | B35: Entidade 10
A36: 3.3. b) | B36: NIPC da entidade obrigada responsável pelo serviço comum
B38: Modelo de gestão de risco
A39: 3.4. | B39: Descrição do modelo de gestão de risco, com indicação das suas características e princípios aplicáveis, nos termos do artigo 14.º da Lei n.º 83/2017, de 18 de agosto | C39: O Banco identifica, avalia e mitiga os riscos concretos de BC/FT existentes, no contexto da sua realidade operativa específica. Neste contexto, o Banco dispõe de um modelo eficaz para a avaliação, gestão e mitigação de tais riscos, recorrendo a práticas adequadas e procedendo, através de sistemas de informação, à análise de informação e da documentação pertinente de acordo com os requisitos legais e regulamentares aplicáveis. Recorre às ferramentas mais avançadas de screening e monitorização de transações para robustecer o ambiente de controlo, com vista a assegurar uma gestão eficaz das medidas restritivas, a identificação de clientes sujeitos a procedimentos de diligência reforçada (e.g. PEPs e ARIs), e também uma monitorização eficiente das transações, baseada no risco. Tem ainda definido e implementado um modelo de cálculo de risco do cliente - Customer Risk Assessment (CRA) - o qual permite gerir de forma eficiente o perfil de risco de BC/FT do cliente. Este processo permite aferir de forma contínua, o perfil de risco de toda a base de clientes, representantes e beneficiários efetivos, aquando do estabelecimento e manutenção das relações de negócio. O grau de risco aplicado decorre, nomeadamente, dos fatores de risco legal e regulamentarmente previstos, com o tipo de cliente, a natureza, dimensão e complexidade da atividade prosseguida, a origem e o destino dos fundos, os produtos e serviços utilizados, entre outros. Tal modelo considera 4 tipologias de atributos na ponderação do cálculo do risco BC/FT do cliente e que agrupam os diferentes fatores de risco, nomeadamente (i) atributos de risco demográfico, (ii) atributos de risco comportamental; (iii) atributos de risco automático e (iv) contágio de risco. Para os clientes em que existe um risco acrescido de branqueamento de capitais e financiamento do terrorismo são adotados procedimentos de verificação e diligência reforçados. O Banco consegue, desta forma, inferir de forma automática e contínua, o nível de risco do cliente, o que, por sua vez, permite definir a forma como o Banco se deve com ele relacionar durante o seu ciclo de vida.
A41: Questões 3.5. (avaliação da eficácia) e 3.6. (documentos aprovados e/ou atualizados) autonomizadas em folhas próprias
B43: Procedimentos e sistemas de informação
B44: A entidade recorre, para efeitos dos artigos 18.º e 19.º da Lei n.º 83/2017, de 18 de agosto, a:
A45: 3.7.1. a) | B45: Ferramentas gerais | C45: Sim
A46: 3.7.1. a) | B46: Ferramentas específicas | C46: Sim
A47: 3.7.1. b) | B47: Sistemas de informação gerais | C47: Sim
...

Sheet DC - Avaliação da eficácia
B1: Resposta ao Relatório de Prevenção do Branqueamento de Capitais e Financiamento do Terrorismo
B2: Dever de Controlo - Avaliação da eficácia
A4: Questões | B4: Avaliação da eficácia
A5: 3.5 | B5: Efetuaram avaliações à qualidade, adequação e eficácia das políticas e dos procedimentos e controlos em matéria de prevenção do branqueamento de capitais e financiamento do terrorismo? | G5: Sim
B7: Lista de avaliações da eficácia (se aplicável)
B8: Data [Questão 3.5. a)] | C8: Responsável [Questão 3.5. b)] | D8: Resumo dos resultados [Questão 3.5. c)]
B9: 45674 | C9: Auditoria interna | D9: Em setembro de 2024, foi iniciada uma Auditoria Interna focalizada na revisão sobre os procedimentos estabelecidos para a gestão dos riscos e cumprimento das respetivas exigências locais e corporativas (Grupo Santander), tendo sido efetuado um seguimento de todas as recomendações em matéria de FCC e seguimento da matéria pela Alta Direção. No seguimento desta auditoria, que concluiu com um rating global de “Necessita Melhorar” (relatório emitido em janeiro de 2025), foram emitidas 4 recomendações de ação prioritária. As deficiências identificadas foram classificadas como F2 – moderada (três recomendações de ação prioritária) e F1 – reduzida (uma recomendação de ação prioritária). As temáticas da PBCFT envolvem matérias de relevância fundamental para o Banco e para as quais existe uma necessidade de permanente atenção, de modo a assegurar a adequada gestão e mitigação dos riscos num contexto normativo e regulatório particularmente exigente e dinâmico, com riscos emergentes crescentes face ao crescimento exponencial dos casos e tipologias de fraude, nomeadamente online. Neste contexto, está na fase final de implementação no Banco um plano de ação detalhado para a melhoria permanente do seu sistema de controlo interno e da gestão dos riscos e do ambiente de controlo em PBCFT, no âmbito do programa de transformação do Grupo Santander (One FCC), mantendo o acompanhamento contínuo no que se refere à remediação das debilidades identificadas. Este plano de ação conta com uma equipa dedicada e inclui, nomeadamente, a implementação das recomendações de Auditoria Interna, em várias frentes de trabalho, das quais destacamos: avaliação de risco do branqueamento de capitais e do financiamento do terrorismo do negócio do Banco; revisão do modelo operativo da área de prevenção do branqueamento de capitais e do financiamento do terrorismo; programa específico de formação para os Órgãos Sociais e a Alta Direção do Banco; Upgrade das ferramentas de filtragem e de monitorização de transações; atualização de políticas e procedimentos em matéria de prevenção do branqueamento de capitais e do financiamento do terrorismo; desenvolvimento de informação de gestão; formação especializada para a equipa da área de prevenção do branqueamento de capitais e do financiamento do terrorismo; reforço da capacitação da área de prevenção do branqueamento de capitais e do financiamento do terrorismo para incrementar a sua efetividade e eficiência. A Comissão de Auditoria considera que todas estas ações evidenciam o foco do Banco na melhoria permanente do seu sistema de controlo interno em matéria de PBCFT e têm permitido ao Banco, no decurso do ano de 2024, atingir um reforço significativo e progressivo do ambiente de controlo, dos procedimentos e das práticas de gestão e mitigação de risco em tal matéria.
C25: Auditoria interna
C26: Auditor externo
C27: Entidade terceira devidamente qualificada

Sheet DC - Documentos
B1: Resposta ao Relatório de Prevenção do Branqueamento de Capitais e Financiamento do Terrorismo
B2: Dever de Controlo - Documentos aprovados e/ou atualizados
A4: Questões | B4: Lista de documentos aprovados e/ou atualizados
C5: Nome do documento aprovado | D5: Data da aprovação | E5: Data da última atualização
A6: 3.6. a) | B6: Documentos que definam as políticas e procedimentos e controlos relacionados com o artigo 12.º da Lei n.º 83/2017, de 18 de agosto | C6: Política de Prevenção de Capitais e Financiamento do Terrorismo | D6: 45503 | E6: 45503
A7: 3.6. a) | B7: Documentos que implementem as políticas e procedimentos e controlos relacionados com o artigo 12.º da Lei n.º 83/2017, de 18 de agosto | C7: Manual de Procedimentos do Norkom Watchlist Management (“Manual WLM”) | D7: 45474 | E7: 45474
A8: 3.6. a) | B8: Documentos que definam e implementem as políticas e procedimentos e controlos relacionados com o artigo 12.º da Lei n.º 83/2017, de 18 de agosto | C8: Manual de Procedimentos de Revisão Crítica e Controlo de Qualidade de Casos e Alertas (“Manual de Revisão Crítica e Controlo de Qualidade”) | D8: 45474 | E8: 45474
A9: 3.6. b) - i) | B9: Documentos que identifiquem os riscos de branqueamento de capitais e financiamento do terrorismo, no âmbito do modelo de gestão de risco | C9: BST_Relatório de avaliação de risco PBC/FT (RCSA) | D9: 45803 | E9: 45672
A10: 3.6. b) - ii) | B10: Documentos que identifiquem os processos utilizados para identificar, avaliar, acompanhar e controlar os riscos de branqueamento de capitais e financiamento do terrorismo, no âmbito do modelo de gestão de risco | C10: BST_Relatório de avaliação de risco PBC/FT (RCSA) | D10: 45803 | E10: 45672
A11: 3.6. c) | B11: Documentos que demonstrem que a estrutura organizacional da entidade é adequada a prevenir conflitos de interesses e, sempre que necessário, promove a separação de funções no seio da organização | C11: Código Geral de Conduta | D11: 45713 | E11: 45742
A12: 3.6. d) | B12: Documentos que definam códigos de conduta relevantes para a promoção da cultura de prevenção do branqueamento de capitais e financiamento do terrorismo | C12: Código Geral de Conduta | D12: 45713 | E12: 45742
A13: 3.6. e) | B13: Documentos que contenham a avaliação periódica da qualidade, adequação e eficácia das políticas e procedimentos e controlos | C13: BST_Relatório de avaliação de risco PBC/FT (RCSA) | D13: 45803 | E13: 45672
A14: 3.6. e) | B14: Documentos que assegurem a execução de medidas adequadas à correção das deficiências detetadas nas políticas e procedimentos e controlos | C14: BST_Relatório de avaliação de risco PBC/FT (RCSA) | D14: 45803 | E14: 45672

Sheet DC - Perfis de risco
B1: Resposta ao Relatório de Prevenção do Branqueamento de Capitais e Financiamento do Terrorismo | P1: Periodicidade
B2: Dever de Controlo - Perfis de risco de branqueamento de capitais e financiamento do terrorismo
P3: Inferior a um ano
A4: Questões | B4: Informação sobre perfis de risco | P4: Anual
A5: 3.7.4. e) | B5: Existe um sistema automatizado para a classificação do perfil de risco de cada um dos clientes? | E5: Sim | P5: Bienal
A6: 3.7.4. g) | B6: O perfil de risco é recalculado automaticamente durante a relação de negócio sempre que a informação do cliente seja alterada? | E6: Sim | P6: Trienal
A7: 3.7.4. h) | B7: O perfil de risco é recalculado automaticamente durante a relação de negócio em função de alterações ao padrão operativo do cliente? | E7: Sim | P7: Quadrienal
A8: 3.7.4. h) | B8: O perfil de risco possibilita a alteração manual? | E8: Sim | P8: Quinquenal
A9: 3.7.4. i) | B9: Existe registo histórico das alterações do perfil de risco? | E9: Sim
B11: Perfis de risco | G11: Método de cálculo do perfil de risco de branqueamento de capitais e financiamento do terrorismo [Questão 3.7.4. f)]
G12: Descrição sumária | H12: Principais variáveis consideradas no cálculo do perfil de risco
B13: Código | C13: Designação | D13: Caracterização | E13: Periodicidade de atualização | F13: Percentagem de clientes | H13: Variável 1 | J13: Variável 2 | L13: Variável 3 | N13: Variável 4
C14: [Questão 3.7.4. a)] | D14: [Questão 3.7.4. b)] | E14: [Questão 3.7.4. d)] | F14: [Questão 3.7.4. c)] | H14: Designação | I14: Peso | J14: Designação | K14: Peso | L14: Designação | M14: Peso | N14: Designação | O14: Peso
C15: Risco Alto | D15: [30,50] - pontuação superior a 30 pontos e igual ou inferior a 50 pontos | E15: Anual | F15: 0.0185
C16: Risco Médio | D16: [20,30] - pontuação superior a 20 pontos e igual ou inferior a 30 pontos | E16: Trienal | F16: 0.071
C17: Risco Baixo | D17: [10,20] - pontuação igual ou inferior a 20 pontos | E17: Quinquenal | F17: 0.9105

Sheet DC - Qualificação de pessoas
B1: Resposta ao Relatório de Prevenção do Branqueamento de Capitais e Financiamento do Terrorismo
B2: Dever de Controlo - Qualificação de pessoas
C4: Percentagem de clientes, representantes de clientes e beneficiários efetivos de clientes face ao respetivo total | G4: Número total
A5: Questões | C5: Clientes | D5: Representantes de clientes | E5: Beneficiários efetivos de clientes | F5: Clientes, representantes de clientes e beneficiários efetivos de clientes | G5: Clientes | H5: Representantes de clientes | I5: Beneficiários efetivos de clientes | J5: Clientes, representantes de clientes e beneficiários efetivos de clientes
B6: Total | G6: 2868287 | H6: 850134 | I6: 287360 | J6: =SUM(G6:I6) -> 4005781
A7: 3.7.6. a) | B7: Pessoa politicamente exposta | C7: 0.0009 | D7: 0.00125 | E7: 0.0016 | F7: 0.00102
A8: 3.7.6. b) | B8: Membro próximo da família | C8: 0.0004 | D8: 0.00015 | E8: 0.0006 | F8: 0.00037
A9: 3.7.6. c) | B9: Pessoa reconhecida como estreitamente associada | C9: 2e-05 | D9: 8e-05 | E9: 0.0001 | F9: 4e-05
A10: 3.7.6. d) | B10: Titular de outro cargo político ou público | C10: 6e-05 | D10: 6e-05 | E10: 0.0001 | F10: 6e-05
A12: 3.7.7. | C12: Identificação das fontes/listas utilizadas para a qualificação | E12: Identificação da entidade fornecedora
B13: Pessoa politicamente exposta | C13: Lista PEP (Political Exposed Person) | E13: PEP Data; Dow Jones-Factiva
B14: Membro próximo da família | C14: Lista PEP (Political Exposed Person) | E14: PEP Data; Dow Jones-Factiva
B15: Pessoa reconhecida como estreitamente associada | C15: Lista PEP (Political Exposed Person) | E15: PEP Data; Dow Jones-Factiva
B16: Titular de outro cargo político ou público | C16: Lista PEP (Political Exposed Person) | E16: PEP Data; Dow Jones-Factiva

Sheet Identificação e Diligência
B1: Resposta ao Relatório de Prevenção do Branqueamento de Capitais e Financiamento do Terrorismo
B2: Dever de Identificação e Diligência
A4: Questões
B5: Comprovação diferida dos elementos identificativos | C5: Número | D5: Percentagem face ao total
A6: 4.1 | B6: Novas relações de negócio em que a verificação da identidade foi completada após o início da relação de negócio | C6: 0 | D6: 0
B8: Informação sobre a origem e destino dos fundos | C8: Número | D8: Percentagem face ao total
A9: 4.2. a) | B9: Novas relações de negócio nas quais tenha tido lugar a obtenção de informação sobre a origem e o destino dos fundos justificada pelo perfil de risco do cliente | C9: 15318 | D9: 0.104
A10: 4.2. b) | B10: Transações ocasionais efetuadas nas quais tenha tido lugar a obtenção de informação sobre a origem e o destino dos fundos justificada pelo perfil de risco do cliente | C10: 17571 | D10: 1
B12: Comprovação dos elementos identificativos dos beneficiários efetivos com base em declaração | C12: Número | D12: Percentagem face ao total
A13: 4.3. a) | B13: Novas relações de negócio nas quais a comprovação dos elementos identificativos dos beneficiários efetivos tenha sido realizada com base em declaração emitida pelo cliente ou por quem legalmente o represente | C13: 0 | D13: 0
A14: 4.3. b) | B14: Transações ocasionais efetuadas nas quais a comprovação dos elementos identificativos dos beneficiários efetivos tenha sido realizada com base em declaração emitida pelo cliente ou por quem legalmente o represente | C14: 0 | D14: 0

Sheet Medidas
B1: Resposta ao Relatório de Prevenção do Branqueamento de Capitais e Financiamento do Terrorismo
B2: Medidas simplificadas e medidas reforçadas
A4: Questões | B4: Medidas simplificadas | C4: Número | D4: Percentagem face ao total
A5: 5.1.1. | B5: Novas relações de negócio relativamente às quais tenha sido decidida a aplicação de medidas de diligência simplificadas | C5: 0 | D5: 0
B7: Medidas reforçadas | C7: Número | D7: Percentagem face ao total
A8: 5.2.1. | B8: Novas relações de negócio relativamente às quais tenha tido lugar a intervenção do responsável pelo cumprimento normativo ou de outro membro da direção de topo, com a subsequente decisão de aplicação de medidas de diligência reforçada | C8: 1128 | D8: 0.0186
A9: 5.2.2. | B9: Relações de negócio, transações ocasionais ou operações que de algum modo se relacionem com países terceiros de risco elevado para efeito do disposto no n.º 1 do artigo 37.º da Lei n.º 83/2017, de 18 de agosto | C9: 26683 | D9: 0.4423
A10: 5.2.3. a) | B10: Novas relações de negócio estabelecidas com clientes detendo a qualidade de "pessoa politicamente exposta" | C10: 21 | D10: 0.0009
A11: 5.2.3. b) | B11: Transações ocasionais efetuadas com clientes detendo a qualidade de "pessoa politicamente exposta" | C11: 8 | D11: 0.0001

Sheet Terceiros
B1: Resposta ao Relatório de Prevenção do Branqueamento de Capitais e Financiamento do Terrorismo
B2: Execução dos procedimentos de identificação e de diligência por entidades terceiras e Externalização / Outsourcing
A4: Questões | B4: Recurso a entidades terceiras para a execução dos procedimentos de identificação e de diligência (artigo 41.º da Lei n.º 83/2017, de 18 de agosto) - Lista
A7: 6 | B7: Denominação [Questão 6. a)] | C7: Tipo institucional [Questão 6. b)] | D7: Jurisdição [Questão 6. c)] | E7: Número de clientes objeto de procedimentos de identificação e diligência [Questão 6. d)]
B8: LOQR, S.A. | C8: Outro | D8: PRT | E8: 1737 | J8: Empresa de seguros
J9: Sociedade gestora de fundos de pensões
J10: Mediador de seguros
J11: Outro
B25: Externalização / Outsourcing
A26: 7 | B26: Recorre a terceiros prestadores de serviços para executar processos, serviços ou atividades instrumentais ou auxiliares ao cumprimento dos deveres preventivos do branqueamento de capitais e financiamento do terrorismo? | E26: Sim

Sheet Comunicação
B1: Resposta ao Relatório de Prevenção do Branqueamento de Capitais e Financiamento do Terrorismo
B2: Dever de Comunicação
A4: Questões | B4: Procedimentos implementados
A5: 8.1. | B5: Descrição dos procedimentos implementados, incluindo o circuito de informação, intervenientes formais e funcionalidades informáticas associadas, para cumprimento do dever de comunicação previsto no artigo 43.º da Lei n.º 83/2017, de 18 de agosto | C5: Procedimentos implementados e circuito de informação: Toda a operação que seja eventualmente suspeita ou relativamente à qual haja razões suficientes para suspeitar que certos fundos ou outros bens, qualquer que seja o seu valor, provenham de atividades criminosas ou estão relacionados com o financiamento de terrorismo, é: (i) é identificada por intermédio de monitorização por aplicação informática (Norkom) e (ii) identificadas pela 1.ª LoD à área de FCC, por e-mail, mediante comunicação imediata. Na situação referida em (ii), FCC pondera a abertura de um caso em Norkom sempre que se justifique pela análise efetuada. Os alertas gerados em Norkom são analisados por um 1.º nível de decisão, que define se os mesmos reúnem os requisitos que sustentem a abertura de um caso. Sendo a análise em sentido negativo, é fechado o alerta. Se a análise for em sentido positivo, o alerta é encaminhado para um 2.º nível de decisão, que pondera a abertura de um caso. Se a análise for em sentido negativo, o alerta é encerrado. Se o 2.º nível de decisão considerar que se justifica a abertura de caso, procede em conformidade. A análise do caso é registada em Norkom. Quanto aos casos abertos em que o entendimento seja no sentido de ser efetuada comunicação, por se encontrarem reunidos os requisitos previstos no art.º 43, é remetida a proposta de comunicação ao RCN ou RCN substituto, que valida se o caso reúne os requisitos atrás indicados. Se reunir tais requisitos, autoriza que a comunicação seja realizada. Relativamente aos casos em que foi entendido não ser efetuada comunicação, estes são objeto de uma revisão crítica por uma equipa independente de revisão e controlo de qualidade, a qual, caso entenda necessário, propõe igualmente a comunicação da operativa suspeita. Todos os casos, bem como o resultado da revisão crítica realizada, são apresentados no Comité de Análise e Resolução (“CAR”), comité com competências em matéria de PBC/FT, presidido pelo membro da administração, designado nos termos no n.º 4, do art. 13.º da Lei 83/2017.Intervenientes formais no processo: o colaborador comunicante, analistas especialistas da área de FCC, analistas especialistas da Área de Revisão Crítica, RCN, membros permanentes do CAR, presidido pelo membro da administração, designado nos termos no n.º 4, do art. 13.º da Lei 83/2017.Funcionalidades informáticas associadas: Norkom.
B7: Comunicação de operações suspeitas e comunicação sistemática de operações
C8: Número | D8: Montante
A9: 8.2. c) | B9: Total de operações suspeitas comunicadas ao DCIAP e à UIF | C9: 955 | D9: 844501763
A10: 8.2. a) e c) | B10: Comunicações com informação de que certos fundos ou outros bens podem provir de atividades criminosas (que não estejam relacionadas com o financiamento do terrorismo) | C10: 955 | D10: 844501763
A11: 8.2. b) e c) | B11: Comunicações com informação de que certos fundos ou outros bens podem estar relacionados com o financiamento do terrorismo | C11: 0 | D11: 0
A12: 8.2. d) | B12: Operações comunicadas que se enquadrem no âmbito do dever de abstenção | C12: 250
A13: 8.2. e) | B13: Operações comunicadas que se enquadrem no âmbito do exercício do dever de recusa | C13: 0
A14: 8.3. | B14: Total de operações comunicadas ao DCIAP e à UIF, nos termos do artigo 45.º da Lei n.º 83/2017, de 18 de agosto (comunicação sistemática de operações) | C14: 7681

Sheet Abstenção
B1: Resposta ao Relatório de Prevenção do Branqueamento de Capitais e Financiamento do Terrorismo
B2: Dever de Abstenção
A4: Questões | B4: Procedimentos implementados
A5: 9.1. | B5: Descrição dos procedimentos implementados para cumprimento do dever de abstenção previsto no artigo 47.º da Lei n.º 83/2017, de 18 de agosto | C5: Na prevenção do branqueamento de capitais e do financiamento do terrorismo é essencial haver um conhecimento adequado do cliente, o que constitui um aspeto essencial para identificação do perfil desse cliente e para a avaliação da coerência da operativa realizada pelo cliente nas suas contas. Aplicam-se os procedimentos descritos no ponto 8.1. anterior, com vista a identificar cada situação em concreto. Atenta a natureza de cada uma destas situações, e ponderado o risco pela equipa comercial, e/ou mediante indicação da área de FCC é solicitada ao cliente justificação fiável da operação, a qual é avaliada quanto à sua suficiência e credibilidade. Verificados que sejam os requisitos previstos no n.º 1 do art.º 47, a área de FCC, com autorização prévia do RCN ou do RCN substituto, reporta ao DCIAP e Ação Penal e à Unidade de Informação Financeira, de que se absteve de executar a operação ou conjunto de operações, consoante aplicável.
B7: Comunicações de operações suspeitas | C7: Número
A8: 9.2. a) | B8: Comunicações resultantes de situações em que tenha executado uma operação suspeita por considerar que a abstenção da respetiva realização não era possível | C8: 0
A9: 9.2. b) | B9: Comunicações resultantes de situações em que, após consulta ao DCIAP e à UIF, o exercício do dever de abstenção foi considerado suscetível de prejudicar a prevenção ou a futura investigação das atividades criminosas de que provenham fundos ou outros bens relacionados com branqueamento de capitais e financiamento do terrorismo | C9: 0
A10: 9.2. c) | B10: Comunicações resultantes de situações em que tenha executado as operações relativamente às quais exerceu o dever de abstenção, nos termos no n.º 5 do artigo 47.º da Lei n.º 83/2017, de 18 de agosto | C10: 0

Sheet Recusa
B1: Resposta ao Relatório de Prevenção do Branqueamento de Capitais e Financiamento do Terrorismo
B2: Dever de Recusa
A4: Questões | B4: Procedimentos implementados
A5: 10.1. | B5: Descrição dos procedimentos implementados para cumprimento do dever de recusa previsto no artigo 50.º da Lei n.º 83/2017, de 18 de agosto | C5: No âmbito do início ou manutenção de uma relação de negócio, na realização de transações ocasionais ou de operações, é necessário um conjunto de documentos e informações (eg. elementos identificativos e respetivos comprovativos, informação sobre a natureza, objeto e finalidade da relação de negócios, entre outros) que, quando não obtidos pelo Banco, constituem fundamento para o exercício do dever de recusa, impedindo que a relação de negócio se inicie ou que seja colocado termo à mesma, consoante aplicável, desencadeando-se os tramites previstos na legislação aplicável.
B7: Relações de negócio, transações ocasionais ou outras operações não iniciadas, recusadas ou terminadas
C8: Número de relações de negócio | D8: Número de transações ocasionais | E8: Número de outras operações
B9: Não iniciadas
A10: 10.2. a) | B10: Por não obtenção de elementos constantes da alínea a) do n.º 1 do artigo 50.º da Lei n.º 83/2017, de 18 de agosto | C10: 0 | D10: 0 | E10: 0
A11: 10.2. b) | B11: Por não obtenção de elementos constantes da alínea b) do n.º 1 do artigo 50.º da Lei n.º 83/2017, de 18 de agosto | C11: 0 | D11: 0 | E11: 0
A12: 10.2. c) | B12: Por não obtenção de outros elementos, nos termos do n.º 3 do artigo 50.º da Lei n.º 83/2017, de 18 de agosto | C12: 0 | D12: 0 | E12: 0
B13: Recusadas
A14: 10.2. a) | B14: Por não obtenção de elementos constantes da alínea a) do n.º 1 do artigo 50.º da Lei n.º 83/2017, de 18 de agosto | C14: 0 | D14: 0 | E14: 0
A15: 10.2. b) | B15: Por não obtenção de elementos constantes da alínea b) do n.º 1 do artigo 50.º da Lei n.º 83/2017, de 18 de agosto | C15: 0 | D15: 0 | E15: 0
A16: 10.2. c) | B16: Por não obtenção de outros elementos, nos termos do n.º 3 do artigo 50.º da Lei n.º 83/2017, de 18 de agosto | C16: 0 | D16: 0 | E16: 0
B17: Terminadas
A18: 10.2. a) | B18: Por não obtenção de elementos constantes da alínea a) do n.º 1 do artigo 50.º da Lei n.º 83/2017, de 18 de agosto | C18: 0 | D18: 0 | E18: 0
A19: 10.2. b) | B19: Por não obtenção de elementos constantes da alínea b) do n.º 1 do artigo 50.º da Lei n.º 83/2017, de 18 de agosto | C19: 0 | D19: 0 | E19: 0
A20: 10.2. c) | B20: Por não obtenção de outros elementos, nos termos do n.º 3 do artigo 50.º da Lei n.º 83/2017, de 18 de agosto | C20: 0 | D20: 0 | E20: 0

Sheet Conservação
B1: Resposta ao Relatório de Prevenção do Branqueamento de Capitais e Financiamento do Terrorismo
B2: Dever de Conservação
A4: Questões | B4: Procedimentos implementados
A5: 11.1. | B5: Descrição dos procedimentos implementados para cumprimento do dever de conservação previsto no artigo 51.º da Lei n.º 83/2017, de 18 de agosto | C5: O Banco através das suas aplicações (vulgo Workflow´s) assegura a digitalização e o arquivo em suporte eletrónico e duradouro, de toda a documentação obrigatória prevista nos artigos 24.º e 25.º da Lei n.º 83/2027, de 18.08. O arquivo mantém-se acessível para consulta ou para outros fins, enquanto a relação comercial com o cliente se mantiver. Finda a relação, a documentação é conservada pelo prazo e nos termos previstos no art.º 51 Lei n.º 83/2027, de 18.08, ou por prazo superior, para efeitos de cumprimento (i) de outras obrigações legais não decorrentes desta lei e/ou (ii) de políticas do Grupo, no qual o Banco se insere.
C7: Tipos de suporte duradouro utilizados
A8: 11.2. a) e b) | B8: Suporte e local de arquivo | C8: Eletrónicos (Sim/Não) | D8: Físicos
B9: Tipo de documento | D9: (Sim/Não) | E9: Local de arquivo
B10: Cópias, registos ou dados eletrónicos extraídos de todos os documentos no âmbito dos procedimentos de identificação e diligência [alínea a) do n.º 1 do artigo 51.º da Lei n.º 83/2017, de 18 de agosto] | C10: Sim | D10: Não | E10: N/A
B11: Documentação integrante dos processos ou ficheiros relativos aos clientes e às suas contas, incluindo a correspondência comercial enviada [alínea b) do n.º 1 do artigo 51.º da Lei n.º 83/2017, de 18 de agosto] | C11: Sim | D11: Não | E11: N/A
B12: Outros documentos, registos e análises, de foro interno ou externo, que formalizem o cumprimento da Lei n.º 83/2017, de 18 de agosto [alínea c) do n.º 1 do artigo 51.º da Lei n.º 83/2017, de 18 de agosto] | C12: Sim | D12: Não | E12: N/A

Sheet Exame
B1: Resposta ao Relatório de Prevenção do Branqueamento de Capitais e Financiamento do Terrorismo
B2: Dever de Exame
A4: Questões | B4: Procedimentos implementados
A5: 12.1. | B5: Descrição dos procedimentos implementados para cumprimento do dever de exame previsto no artigo 52.º da Lei n.º 83/2017, de 18 de agosto, incluindo a descrição da participação do responsável pelo cumprimento normativo da entidade obrigada no processo de exame, com indicação do momento em que o mesmo intervém | C5: O Banco assegura a monitorização da operativa dos clientes através de distintas linhas de atuação, suportadas, por sua vez, também em diferentes ferramentas e atende para o efeito a determinados elementos caracterizadores, tais como, a natureza, a finalidade, a frequência e a complexidade das operações, os montantes, a origem e o destino dos fundos movimentados, o local de origem e de destino das operações, bem como os meios de pagamento utilizados, sem prejuízo de considerar outros que se verifiquem adequados a cada caso concreto.A 1.ª linha de atuação é constituída pelas unidades de negócio, às quais incumbe assegurar a identificação dos clientes, a due diligence associada a essa identificação e a monitorização contínua da relação comercial. A operativa efetuada nas contas dos clientes ou em transações ocasionais, são analisadas através de uma aplicação informática corporativa designada por Norkom, no âmbito da qual são utilizados algoritmos comportamentais e de outra natureza, que geram alertas, que são analisados por equipa dedicada nos termos referidos no ponto 8.1. deste ficheiro e que, quando entende que há suspeita fundada efetua uma análise mais profunda e detalhada, que recebe a denominação interna de caso. Existindo operativa suspeita, é efetuada a proposta de COS (comunicação de operação suspeita) que, após aprovação pelo RCN ou RCN substituto, é remetida às autoridades competentes.
B7: Intervenientes e funcionalidades informáticas
A8: 12.2. | B8: Descrição, relativamente a uma decisão de comunicação, dos procedimentos implementados para cumprimento do dever de exame, com informação sobre os intervenientes, o respetivo circuito hierárquico (com indicação do cargo/função) e as funcionalidades informáticas associadas | C8: Uma comunicação é precedida dos procedimentos descritos no ponto 12.1 anterior, sendo que a mesma apenas ocorre se o RCN determinar a sua comunicação às autoridades competentes. As investigações relativamente às quais o RCN decide não ser efetuada a comunicação, são sujeitas a revisão crítica pelo membro da administração, designado nos termos no n.º 4, do art. 13.º da Lei 83/2017. Os intervenientes no processo são: as unidades de negócio; analistas da área de FCC; RCN/RCN substituto e administrador (designado nos termos no n.º 4, do art. 13.º da Lei 83/2017). Circuito hierárquico: unidade de negócio - gestor de cliente/diretor de balcão; área de FCC - especialista de FCC; RCN substituto e administrador (designado nos termos no n.º 4, do art. 13.º da Lei 83/2017). Funcionalidades informáticas associadas: Norkom.
B10: Operações examinadas | C10: Número | D10: Montante
A11: 12.3.1 | B11: Total de operações examinadas | C11: 144545 | D11: 3636771742
A12: 12.3.2. a) | B12: Operações examinadas em relação às quais não tenha havido comunicação às autoridades competentes | C12: 7
A13: 12.3.2. b) | B13: Operações examinadas em relação às quais a revisão crítica, constante da alínea b) do n.º 3 do artigo 13.º da Lei n.º 83/2017, de 18 de agosto, tenha determinado a sua comunicação | C13: 1

Sheet Colaboração
B1: Resposta ao Relatório de Prevenção do Branqueamento de Capitais e Financiamento do Terrorismo
B2: Dever de Colaboração
A4: Questões | B4: Procedimentos implementados
A5: 13.1 | B5: Descrição dos procedimentos implementados para cumprimento do dever de colaboração previsto no artigo 53.º da Lei n.º 83/2017, de 18 de agosto | C5: A área de FCC presta, de forma cabal e pronta, a colaboração que lhe é requerida pelo DCIAP, pela Unidade de Informação Financeira, bem como pelas demais entidades judiciárias e policiais, pelas autoridades setoriais e pela Autoridade Tributária e Aduaneira. Adicionalmente, o Banco dispõe de um área de Reportes a Entidades Oficiais que tem como funções, entre outras: a) assegurar o envio aos Tribunais Criminais e Entidades de investigação criminal, de todas as informações e documentos solicitados, no âmbito dos processos de Branqueamento de Capitais, com reporte dos ofícios e cartas de resposta para o Departamento de Prevenção e Branqueamento de Capitais; e b) efetivar as determinações dos Tribunais Criminais para apreensão de valores depositados em contas bancárias, suspensão de movimentos a débito e/ou crédito e contumácias, assegurando os respetivos cativos e inibições, bem como, as respostas a estas entidades e aos titulares das contas afetadas, quando aplicável.
B7: Entidade Requerente | C7: Número de pedidos de colaboração recebidos
A8: 13.2. a) | B8: DCIAP | C8: 681
A9: 13.2. b) | B9: UIF | C9: 20
A10: 13.2. c) | B10: Autoridades judiciárias e policiais | C10: 1597
A11: 13.2. d) | B11: ASF | C11: 0
A12: 13.2. d) | B12: Outras autoridades setoriais | C12: 3
A13: 13.2. e) | B13: Autoridade Tributária e Aduaneira | C13: 45

Sheet Não Divulgação
B1: Resposta ao Relatório de Prevenção do Branqueamento de Capitais e Financiamento do Terrorismo
B2: Dever de Não Divulgação
A4: Questões
A5: 14 | B5: Descrição dos procedimentos implementados para cumprimento do dever de não divulgação previsto no artigo 54.º da Lei n.º 83/2017, de 18 de agosto | C5: O normativo interno do Banco proíbe a revelação ao cliente, ou a terceiros, da divulgação de quaisquer informações relativas a comunicações, independentemente de as mesmas decorrerem de análises internas ou de pedidos efetuados pelas autoridades judiciárias, policiais ou sectoriais, que se encontram ou possam vir a encontrar-se em curso, bem como, de quaisquer outras investigações, inquéritos, averiguações, análises ou procedimentos legais a conduzidos pelas autoridades, quaisquer outras informações ou análises de foro interno ou externo. De forma a assegurar o cumprimento do dever de confidencialidade, o Banco tem, para além de normativo interno, um plano de formação que abrange conteúdos sobre os deveres preventivos, nos quais o tema é abordado e reforçado.

Sheet Formação
B1: Resposta ao Relatório de Prevenção do Branqueamento de Capitais e Financiamento do Terrorismo | O1: Natureza | P1: Ambiente
B2: Dever de Formação | O2: Interna | P2: Presencial
O3: Externa | P3: À distância
A4: Questões | B4: Procedimentos implementados
A5: 15.1. | B5: Descrição dos procedimentos implementados para cumprimento do dever de formação previsto no artigo 55.º da Lei n.º 83/2017, de 18 de agosto | C5: O Banco garante a formação permanente e adequada aos seus colaboradores, incluindo a Alta Direção e membros dos Órgãos Sociais, visando o (i) cumprimento das obrigações impostas pela legislação e regulamentação aplicável; o (ii) desenvolvimento das competências dos seus colaboradores e (iii) o reforço do cumprimento dos procedimentos implementados para efeitos de controlo. Para o efeito, é aprovado anualmente um Plano de Formação em matéria de PBC/FT. O Plano visa ainda definir os conteúdos programáticos necessários à promoção da cultura de Prevenção do Crime Financeiro, com especial enfoque na PBC/FT e compliance com as Sanções Internacionais no Banco, Prevenção da Fraude, Suborno e Corrupção e ao cumprimento da legislação aplicável por todos os colaboradores, em especial por aqueles cujas funções se relacionem com estas temáticas. O Plano é precedido de parecer prévio do RCN e é aprovado no Comité competente.
B7: Informação sobre ações de formação
A8: 15.2.1. | B8: Foram ministradas ações de formação em matéria de prevenção do branqueamento de capitais e financiamento do terrorismo? | F8: Sim
A9: 15.2.1. | B9: Número de ações de formação em matéria de prevenção do branqueamento de capitais e financiamento do terrorismo dirigidas aos colaboradores relevantes | F9: 11
A10: 15.2.3. | B10: O plano de formação em matéria de prevenção do branqueamento de capitais e financiamento do terrorismo aprovado foi cumprido? | F10: Sim
A11: 15.2.3. | B11: Nível de cumprimento do plano de formação em matéria de prevenção do branqueamento de capitais e financiamento do terrorismo aprovado (entre 0% e 100%) | F11: 1
A13: 15.2.3. | B13: Informação fundamentada, qualitativa e quantitativa, sobre o cumprimento do plano de formação aprovado | C13: O Plano de formação é cumprido através da realização de formações presenciais e na modalidade de sala virtual via teams. Complementarmente, e por via de e-learning, cada colaborador do Banco tem à sua disposição os conteúdos formações adicionais em matéria de PBC/FT, tendo em conta a sua função específica. As ações formativas são asseguradas por pessoas ou entidades com reconhecida competência e experiência no domínio da PBC/FT, Sanções e Prevenção da Fraude, Suborno e Corrupção. A cada colaborador com o curso concluído será atribuído um certificado de formação, ficando o mesmo disponível e consultável na ferramenta disponível para o efeito. O seguimento do Plano de Formação é reportado no Comité competente, pelo menos, duas vezes por ano. Abaixo estão elencados os cursos ministrados no âmbito do Plano de Formação para 2024.
B15: Lista de formações
B16: Denominação da formação [Questão 15.2.2. a)] | C16: Matéria sobre a qual versou a ação [Questão 15.2.2. b)] | D16: Data da formação [Questão 15.2.2. c)] | E16: Entidade formadora [Questão 15.2.2. d)] | F16: Duração (em horas) [Questão 15.2.2. e)] | G16: Natureza [Questão 15.2.2. f)] | H16: Ambiente [Questão 15.2.2. g)] | I16: Funções dos formandos [Questão 15.2.2. h)] | J16: Número de participantes [Questão 15.2.2. i)] | K16: Teve avaliação final dos formandos? [Questão 15.2.2. j)] | L16: Avaliação final média ou mediana dos formandos [Questão 15.2.2. j)]
B17: PBC/CFT e Sanções Corporativo (Novos Colaboradores) | C17: Dotar os novos Colaboradores de conhecimentos sobre o cumprimento das políticas, processos e procedimentos relativos a PBC/CFT e Sanções e proteger o Banco de riscos de natureza reputacional e contraordenacional; • Capacitar os novos colaboradores para reconhecer práticas, deveres e indicadores de risco de BC/FT: o Princípios e Critérios do Banco Santander; o Conceitos e Fases de BC; o Crimes subjacentes ao BC; o Consequências do BC; o Conceitos e Fases de FT; o Indícios do FT; o Ideias iniciais sobre Sanções; o Legislação em Vigor – Sujeitos Obrigados; o Medidas de Prevenção (Políticas, Avaliação de Clientes, Fatores de Risco); o Deveres de Prevenção de BC/F (Identificação e Diligências, BEFs, Deveres, SCI); o Sanções e Contramedidas Financeiras (Listas de entidades, Transações, Deveres, Lei n.º 97/2017, Medidas Restritivas); e, o Sanções – Coimas. riscos de natureza reputacional e contraordenacional; | D17: Decorre ao longo do ano | E17: Academia Santander | F17: 6h | G17: Interna | H17: Presencial | I17: Colaboradores de diversas Áreas | J17: 144 | K17: Sim | L17: A conclusão da formação está sujeita a um teste final de avaliação, o qual requer, no minímo, 8 respostas corretas em 10.
B18: PBC/CFT e Sanções Corporativo | C18: • Permitir recordar ou aprofundar os conhecimentos, por parte de todos os colaboradores do Grupo, em sede de PBC/CFT e Sanções: o Crime Financeiro – Conceito; o Prevenção do Crime Financeiro; o KYC; o Políticas e o Procedimentos; o Avaliação de Riscos; o Área de Operações; o Novo Desenvolvimento de Produto; o Comunicação de Sanções; o UIF, Intercâmbio de Informações e o Relações de Correspondência; e, o Teste de Avaliação e Certificado. | D18: Decorre ao longo do ano | E18: Academia Santander | F18: 1,5h | G18: Interna | H18: À distância | I18: Todos os colaboradores | J18: 4201 | K18: Sim | L18: A conclusão da formação está sujeita a um teste final de avaliação, o qual requer, no minímo, 8 respostas corretas em 10.
B19: PBC/CFT e Sanções Complementar | C19: • Contexto Regulamentar Nacional e Políticas e Procedimentos do Banco; • Obrigações relacionadas com Imóveis. | D19: Decorre ao longo do ano | E19: Academia Santander | F19: 1h | G19: Interna | H19: À distância | I19: Todos os colaboradores | J19: 4201 | K19: Sim | L19: A conclusão da formação está sujeita a um teste final de avaliação, o qual requer, no minímo, 8 respostas corretas em 10.
B20: Prevenção de Suborno, Corrupção e Fraude (PSCF) | C20: • Definições e enquadramento: o o que é a Ética e o comportamento Ético; o o triangulo da Fraude e a importância da prevenção deste crime. o o suborno e a corrupção, bem como o enquadramento de facilitation payments. o Conflitos de interesses; o Gestão de presentes e outras gratificações atribuídas e recebidas. o Elementos fundamentais para construir uma cultura de compliance. o Vantagens da existência de uma cultura de compliance (para o management e colaboradores em geral); o Gestão de presentes e outras gratificações atribuídas e recebidas. • Exemplos de casos sobre maus comportamentos éticos, fraudes, suborno e corrupção; • Riscos reputacionais e consequências do incumprimento | D20: 45413 | E20: Academia Santander | F20: 1,5h | G20: Interna | H20: À distância | I20: Todos os colaboradores | J20: 4464 | K20: Sim | L20: A conclusão da formação está sujeita a um teste final de avaliação, o qual requer, no minímo, 8 respostas corretas em 10.
B21: Prevenção da Fraude, Suborno e Corrupção (PFSC) | C21: • A legislação em vigor e os princípios base estabelecidos a nível nacional e internacional; • Enquadramento legal e regulamentar do RGPC, incluindo as obrigações legais das entidades a quem se aplica o RGPC (com foco nas entidades privadas); • Definições e enquadramento: o o que é a Ética e o comportamento Ético; o o triangulo da Fraude e a importância da prevenção deste crime. o o suborno e a corrupção, bem como o enquadramento de facilitation payments. o Conflitos de interesses; o Elementos fundamentais para construir uma cultura de compliance. o Vantagens da existência de uma cultura de compliance (para o management e colaboradores em geral); o Gestão de presentes e outras gratificações atribuídas e recebidas. • Tipologias, tendências e técnicas de prevenção, deteção e resposta; • Quadro normativo interno, nomeadamente políticas, meios e procedimentos preventivos do BSP; • Riscos reputacionais e consequências do incumprimento; • Whistleblowing, com foco no canal de denúncias interno; • Casos práticos. • Penalizações / consequências de incumprimento. o Gestão de presentes e outras gratificações atribuídas e recebidas. | D21: 45474 | E21: Instituto de Formação Bancária- IFB | F21: 3,5h | G21: Externa | H21: À distância | I21: Colaboradores (especialistas) da Área de FCC | J21: 13 | K21: Não | L21: N/A
B22: PBC/CFT e Sanções | C22: Reforçar o pensamento crítico, abordar os riscos de crimes financeiros e potenciar a eficiência e eficácia das investigações e outros processos e procedimentos da equipa; • Aprofundar o enquadramento regulamentar, políticas, procedimentos e melhores práticas; • e, • Apresentação de casos de estudo e promoção do mindset adequado | D22: 45474 | E22: Instituto de Formação Bancária- IFB | F22: 6h | G22: Externa | H22: À distância | I22: Colaboradores (especialistas) da Área de FCC | J22: 34 | K22: Não | L22: N/A
B23: PBC/CFT e Sanções – Órgãos Sociais | C23: • Reforço de conhecimentos para o exercício das funções: o Principais Conceitos (relevância do combate a BC/FT e do Compliance face a Sanções e Embargos Internacionais, uso do Banco para BC/FT, violação de Sanções e Embargos Internacionais); o Enquadramento Regulamentar (evolução e princípios base a nível nacional e internacional, obrigações e responsabilidades, evolução da situação Portuguesa e Europeia, más práticas e impacto); o PBC/CFT e Sanções na prática (ciclo e programa de PBC/CFT e Sanções, boas práticas, papel da Alta Direção, cultura e governance, falhas geralmente identificadas e importância da avaliação e gestão de risco de BC/FT e Sanções); o Casos de Estudo (situações que levaram a penalização por falhas de PBC/CFT e Sanções); e o Futuro do Compliance em termos de PBC/CFT e Sanções (discussão de tendências futuras e desafios). | D23: 45627 | E23: Instituto de Formação Bancária- IFB | F23: 5h | G23: Externa | H23: Presencial | I23: Órgãos Sociais (Comissão Auditoria e Comissão Executiva) e Alta Direção (chefias com reporte à Admisntração ou à Europa) | J23: 15 | K23: Não | L23: N/A
B24: PBC/CFT e Sanções – Órgãos Sociais | C24: • Reforço de conhecimentos para o exercício das funções: o Principais Conceitos (relevância do combate a BC/FT e do Compliance face a Sanções e Embargos Internacionais, uso do Banco para BC/FT, violação de Sanções e Embargos Internacionais); o Enquadramento Regulamentar (evolução e princípios base a nível nacional e internacional, obrigações e responsabilidades, evolução da situação Portuguesa e Europeia, más práticas e impacto); o PBC/CFT e Sanções na prática (ciclo e programa de PBC/CFT e Sanções, boas práticas, papel da Alta Direção, cultura e governance, falhas geralmente identificadas e importância da avaliação e gestão de risco de BC/FT e Sanções); o Casos de Estudo (situações que levaram a penalização por falhas de PBC/CFT e Sanções); e o Futuro do Compliance em termos de PBC/CFT e Sanções (discussão de tendências futuras e desafios). | D24: 45627 | E24: Instituto de Formação Bancária- IFB | F24: 5h | G24: Externa | H24: À distância | I24: Órgãos Sociais (Comissão Auditoria e Comissão Executiva) e Alta Direção (chefias com reporte à Admisntração ou à Europa) | J24: 23 | K24: Não | L24: N/A
B25: PBC/CFT Específica Private Banking | C25: Apresentação dos riscos associados a private banking, da regulamentação em vigor e dos procedimentos a seguir para mitigar o risco de BC/FT neste contexto; • Apresentação de exemplos práticos, incluindo operações suspeitas de BC/FT. | D25: 45566 | E25: Área Corporativa e Responsável pela Área de Private Banking | F25: 1h | G25: Interna | H25: À distância | I25: Colaboradores da Área de Private Banking | J25: 77 | K25: Não | L25: N/A
B26: PBC/CFT Específica Banca Correspondente | C26: • Apresentação dos riscos associados a relações de correspondência e chaves RMA, da regulamentação em vigor e dos procedimentos a seguir para mitigar o risco de BC/FT neste contexto; • Apresentação de exemplos práticos, incluindo operações suspeitas de BC/FT. | D26: 45566 | E26: KPMG Advisory – Consultores de Gestão, S.A. - Entidade externa com credenciais em matérias de PBC/CFT | F26: 1h | G26: Interna | H26: À distância | I26: Colaboradores alocados à Área responsável por relações de Banca Correspondente | J26: 10 | K26: Não | L26: N/A
B27: PBC/CFT Específica GCB / CIB | C27: • Apresentação dos riscos associados a corporate banking, da regulamentação em vigor e dos procedimentos a seguir para mitigar o risco de BC/FT neste contexto; • Apresentação de exemplos práticos, incluindo operações suspeitas de BC/FT. | D27: 45597 | E27: Instituto de Formação Bancária- IFB | F27: 1h | G27: Externa | H27: À distância | I27: Colaboradores alocados à área responsável por GCB/CIB | J27: 38 | K27: Não | L27: N/A
B28: PBC/CFT Específica Trade Finance | C28: Apresentação dos riscos associados a operações de Trade Finance, da regulamentação em vigor e dos procedimentos a seguir para mitigar o risco de BC/FT neste contexto; • Dotar os colaboradores de conhecimentos que permitam exercer o dever de exame, e verificar a consistência da operação proposta com a atividade e o perfil do Cliente; • Apresentação de exemplos práticos, incluindo operações suspeitas de BC/FT. | D28: 45597 | E28: Instituto de Formação Bancária- IFB | F28: 1h | G28: Externa | H28: À distância | I28: Colaboradores alocados à área responsável por Trade Finance | J28: 19 | K28: Não | L28: N/A

Sheet Oportunidades de melhoria
B1: Resposta ao Relatório de Prevenção do Branqueamento de Capitais e Financiamento do Terrorismo
B2: Oportunidades de melhoria identificadas em matéria de prevenção do branqueamento de capitais e financiamento do terrorismo
A4: Questões
A5: 16 | B5: Identificação das oportunidades de melhoria constatadas referentes ao cumprimento dos deveres preventivos em matéria de branqueamento de capitais e financiamento do terrorismo | C5: Remete-se para a resposta constante no separador "DC - Avaliação da Eficácia", na questão 3.5. c).

Sheet Outras informações
B1: Resposta ao Relatório de Prevenção do Branqueamento de Capitais e Financiamento do Terrorismo
B2: Outras informações
A4: Questões | B4: Informação adicional considerada relevante pela entidade obrigada
A5: 17.1 | B5: Outra informação julgada relevante pela entidade obrigada e associada ao período de referência, incluindo, se aplicável, alterações ocorridas na entidade obrigada, com impacto nas políticas e nos procedimentos e controlos preventivos do branqueamento de capitais e financiamento do terrorismo | C5: N/A
B7: Outras informações a reportar por determinação da ASF
A8: 17.2. | B8: Descrição de eventuais informações a reportar, de acordo com determinação da ASF, sem que para as mesmas exista um campo específico | C8: N/A

Sheet Validações
A1: CodMapa | B1: DtReporte | C1: CodEntidade | D1: ID Validação | E1: Descrição da Validação | F1: Resultado | G1: Erro / Aviso
E2: Na folha "Info Institucional" apenas deve preencher uma dos campos "Morada - Da sede, para as entidades obrigadas com sede em Portugal" ou "Morada - Do estabelecimento, para as sucursais situadas em território português das entidades obrigadas, ou outras de natureza equivalente, que tenham sede no estrangeiro". | F2: =+IF(AND('Info Institucional'!C14<>0,'Info Institucional'!C15<>0),1,0) -> 0 | G2: =+IF(F2=1,"Erro","")
E3: Na folha "DC - Controlo", se a variável "Função autónoma ou cumulada com outra função" está preenchida com "Autónoma", então a variável "Função com que cumula a função de responsável pelo cumprimento normativo" não pode estar preenchida. | F3: =+IF(AND('DC - Controlo'!C15="Autónoma",'DC - Controlo'!C16<>0),1,0) -> 0
