Workbook
Name asefadf: #REF!
Name bn: #REF!

Sheet Status Resumo
B7: Sumário Executivo | 16/mai a 22/mai
C10: Resumo das entregas da equipa de IT | N10: Highlights
D12: Entregas Semana Anterior 1 | G12: Entregas Semana Atual | J12: Entregas Semana Seguinte | N12: 1. As entregas da equipa de IT cumpriram os prazos estipulados em plano. 2. O foco da equipa de testes durante a semana atual foi: • Validação do universo da lt002_instrument • Validação dos campos provenientes da rentabilidade, referentes à tabela lt002_instrument
C13: Tabela | D13: Planeado | E13: Real | F13: ∆ | G13: Planeado | H13: Real | I13: ∆ | J13: Planeado | K13: Real | L13: ∆
C14: lt002_instrument | D14: 18 | E14: 18 | F14: =E14-D14 -> 0 | G14: 12 | H14: 12 | I14: =H14-G14 -> 0 | J14: 13 | K14: TBD | L14: TBD
C15: lt004_protection | D15: 1 | E15: 1 | F15: =E15-D15 -> 0 | G15: 0 | H15: 0 | I15: =H15-G15 -> 0 | J15: 6 | K15: TBD | L15: TBD
C16: lt006_instr_protection | D16: 0 | E16: 0 | F16: =E16-D16 -> 0 | G16: 0 | H16: 0 | I16: =H16-G16 -> 0 | J16: 5 | K16: TBD | L16: TBD
C17: lt007_instr_activity | D17: 5 | E17: 5 | F17: =E17-D17 -> 0 | G17: 0 | H17: 0 | I17: =H17-G17 -> 0 | J17: 1 | K17: TBD | L17: TBD
C18: Total | D18: =SUM(D14:D17) -> 24 | E18: =SUM(E14:E17) -> 24 | F18: =SUM(F14:F17) -> 0 | G18: =SUM(G14:G17) -> 12 | H18: =SUM(H14:H17) -> 12 | I18: =SUM(I14:I17) -> 0 | J18: =SUM(J14:J17) -> 25 | K18: =SUM(K14:K17) -> 0 | L18: =SUM(L14:L17) -> 0
C20: 1 Nas entregas da semana anterior foram incluidas as entregas estimadas nas semanas de 5/mai e 12/mai.
C22: Tracking das correções efetuadas pela equipa de IT
C24: Tema | D24: Descritivo | M24: Status
C25: lt002 - instrmnt_id | D25: Existiam instrmnt_id em falta devido à forma como estavam a ser efetuados os cruzamentos. | M25: Done
C26: lt002 - campos provenientes de rentabilidade | D26: Erro na forma como estava a ser aplicada a ponderação aos kpm para obtenção do valor em termos de chave FINREP. | M26: Done
C27: lt002 - campos "_CCRR" | D27: Preenchimento com os valores default para os campos com o sufixo "_CCRR". | M27: Done
B30: 1. LT002_INSTRUMENT
C33: Resumo | G33: Status (Campos) | I33: 45799 | J33: 45792 | K33: ∆ | M33: Highlights
G34: 1. Concluído | I34: =COUNTIFS('Detalhe Entregas e Status'!$I:$I,'Status Resumo'!G34,'Detalhe Entregas e Status'!$B:$B,"lt002_instrument",'Detalhe Entregas e Status'!$C:$C,"<>"&"UNIVERSO") -> 9 | J34: =COUNTIFS('Detalhe Entregas e Status'!$J:$J,'Status Resumo'!G34,'Detalhe Entregas e Status'!$B:$B,"lt002_instrument",'Detalhe Entregas e Status'!$C:$C,"<>"&"UNIVERSO") -> 0 | K34: =IF(I34-J34=0,"-",IF(I34-J34>0,_xlfn.CONCAT("+ ",I34-J34),_xlfn.CONCAT("- ",J34-I34))) -> + 9 | M34: Face à semana anterior, foram entreges para testes mais 13 campos referentes à tabela lt002_instrument. Desta amostra encontra-se em análise por parte da equipa de testes: • Universo e construção do instrmnt_id • Campos provenientes das tabelas de rentabilidade No decorrer das nossas análises, houve a necessidade de se re-especificar os seguintes campos (que serão formalizados até 23/mai): • nt_ln_lss_prvsn • cnclld_instrmnt_stts
G35: 2. Em Teste | I35: =COUNTIFS('Detalhe Entregas e Status'!$I:$I,'Status Resumo'!G35,'Detalhe Entregas e Status'!$B:$B,"lt002_instrument",'Detalhe Entregas e Status'!$C:$C,"<>"&"UNIVERSO") -> 9 | J35: =COUNTIFS('Detalhe Entregas e Status'!$J:$J,'Status Resumo'!G35,'Detalhe Entregas e Status'!$B:$B,"lt002_instrument",'Detalhe Entregas e Status'!$C:$C,"<>"&"UNIVERSO") -> 1 | K35: =IF(I35-J35=0,"-",IF(I35-J35>0,_xlfn.CONCAT("+ ",I35-J35),_xlfn.CONCAT("- ",J35-I35))) -> + 8
G36: 3. Em Re-especificação | I36: =COUNTIFS('Detalhe Entregas e Status'!$I:$I,'Status Resumo'!G36,'Detalhe Entregas e Status'!$B:$B,"lt002_instrument",'Detalhe Entregas e Status'!$C:$C,"<>"&"UNIVERSO") -> 2 | J36: =COUNTIFS('Detalhe Entregas e Status'!$J:$J,'Status Resumo'!G36,'Detalhe Entregas e Status'!$B:$B,"lt002_instrument",'Detalhe Entregas e Status'!$C:$C,"<>"&"UNIVERSO") -> 0 | K36: =IF(I36-J36=0,"-",IF(I36-J36>0,_xlfn.CONCAT("+ ",I36-J36),_xlfn.CONCAT("- ",J36-I36))) -> + 2
G37: 4. Em Correção | I37: =COUNTIFS('Detalhe Entregas e Status'!$I:$I,'Status Resumo'!G37,'Detalhe Entregas e Status'!$B:$B,"lt002_instrument",'Detalhe Entregas e Status'!$C:$C,"<>"&"UNIVERSO") -> 0 | J37: =COUNTIFS('Detalhe Entregas e Status'!$J:$J,'Status Resumo'!G37,'Detalhe Entregas e Status'!$B:$B,"lt002_instrument",'Detalhe Entregas e Status'!$C:$C,"<>"&"UNIVERSO") -> 0 | K37: =IF(I37-J37=0,"-",IF(I37-J37>0,_xlfn.CONCAT("+ ",I37-J37),_xlfn.CONCAT("- ",J37-I37))) -> -
G38: 5. Em Re-teste | I38: =COUNTIFS('Detalhe Entregas e Status'!$I:$I,'Status Resumo'!G38,'Detalhe Entregas e Status'!$B:$B,"lt002_instrument",'Detalhe Entregas e Status'!$C:$C,"<>"&"UNIVERSO") -> 0 | J38: =COUNTIFS('Detalhe Entregas e Status'!$J:$J,'Status Resumo'!G38,'Detalhe Entregas e Status'!$B:$B,"lt002_instrument",'Detalhe Entregas e Status'!$C:$C,"<>"&"UNIVERSO") -> 0 | K38: =IF(I38-J38=0,"-",IF(I38-J38>0,_xlfn.CONCAT("+ ",I38-J38),_xlfn.CONCAT("- ",J38-I38))) -> -
G39: 6. Por Iniciar | I39: =COUNTIFS('Detalhe Entregas e Status'!$I:$I,'Status Resumo'!G39,'Detalhe Entregas e Status'!$B:$B,"lt002_instrument",'Detalhe Entregas e Status'!$C:$C,"<>"&"UNIVERSO") -> 10 | J39: =COUNTIFS('Detalhe Entregas e Status'!$J:$J,'Status Resumo'!G39,'Detalhe Entregas e Status'!$B:$B,"lt002_instrument",'Detalhe Entregas e Status'!$C:$C,"<>"&"UNIVERSO") -> 17 | K39: =IF(I39-J39=0,"-",IF(I39-J39>0,_xlfn.CONCAT("+ ",I39-J39),_xlfn.CONCAT("- ",J39-I39))) -> - 7
G40: 7. Por Entregar | I40: =COUNTIFS('Detalhe Entregas e Status'!$I:$I,'Status Resumo'!G40,'Detalhe Entregas e Status'!$B:$B,"lt002_instrument",'Detalhe Entregas e Status'!$C:$C,"<>"&"UNIVERSO") -> 21 | J40: =COUNTIFS('Detalhe Entregas e Status'!$J:$J,'Status Resumo'!G40,'Detalhe Entregas e Status'!$B:$B,"lt002_instrument",'Detalhe Entregas e Status'!$C:$C,"<>"&"UNIVERSO") -> 33 | K40: =IF(I40-J40=0,"-",IF(I40-J40>0,_xlfn.CONCAT("+ ",I40-J40),_xlfn.CONCAT("- ",J40-I40))) -> - 12
G41: Total | I41: =SUM(I34:I40) -> 51 | J41: =SUM(J34:J40) -> 51
G43: Status (Universo) | I43: 45799
G44: lt002_instrument | I44: wip
B47: 2. LT004_PROTECTION
C50: Resumo | G50: Status (Campos) | I50: 45799 | J50: 45792 | K50: ∆ | M50: Highlights
G51: 1. Concluído | I51: =COUNTIFS('Detalhe Entregas e Status'!$I:$I,'Status Resumo'!G51,'Detalhe Entregas e Status'!$B:$B,"lt004_protection",'Detalhe Entregas e Status'!$C:$C,"<>"&"UNIVERSO") -> 0 | J51: =COUNTIFS('Detalhe Entregas e Status'!$J:$J,'Status Resumo'!G51,'Detalhe Entregas e Status'!$B:$B,"lt004_protection",'Detalhe Entregas e Status'!$C:$C,"<>"&"UNIVERSO") -> 0 | K51: =IF(I51-J51=0,"-",IF(I51-J51>0,_xlfn.CONCAT("+ ",I51-J51),_xlfn.CONCAT("- ",J51-I51))) -> - | M51: Relativamente ao campo typ_vhcl da tabela lt004_protection falta testar os valores entre o âmbito GD e o âmbito Pilar 3.
G52: 2. Em Teste | I52: =COUNTIFS('Detalhe Entregas e Status'!$I:$I,'Status Resumo'!G52,'Detalhe Entregas e Status'!$B:$B,"lt004_protection",'Detalhe Entregas e Status'!$C:$C,"<>"&"UNIVERSO") -> 1 | J52: =COUNTIFS('Detalhe Entregas e Status'!$J:$J,'Status Resumo'!G52,'Detalhe Entregas e Status'!$B:$B,"lt004_protection",'Detalhe Entregas e Status'!$C:$C,"<>"&"UNIVERSO") -> 1 | K52: =IF(I52-J52=0,"-",IF(I52-J52>0,_xlfn.CONCAT("+ ",I52-J52),_xlfn.CONCAT("- ",J52-I52))) -> -
G53: 3. Em Re-especificação | I53: =COUNTIFS('Detalhe Entregas e Status'!$I:$I,'Status Resumo'!G53,'Detalhe Entregas e Status'!$B:$B,"lt004_protection",'Detalhe Entregas e Status'!$C:$C,"<>"&"UNIVERSO") -> 0 | J53: =COUNTIFS('Detalhe Entregas e Status'!$J:$J,'Status Resumo'!G53,'Detalhe Entregas e Status'!$B:$B,"lt004_protection",'Detalhe Entregas e Status'!$C:$C,"<>"&"UNIVERSO") -> 0 | K53: =IF(I53-J53=0,"-",IF(I53-J53>0,_xlfn.CONCAT("+ ",I53-J53),_xlfn.CONCAT("- ",J53-I53))) -> -
G54: 4. Em Correção | I54: =COUNTIFS('Detalhe Entregas e Status'!$I:$I,'Status Resumo'!G54,'Detalhe Entregas e Status'!$B:$B,"lt004_protection",'Detalhe Entregas e Status'!$C:$C,"<>"&"UNIVERSO") -> 0 | J54: =COUNTIFS('Detalhe Entregas e Status'!$J:$J,'Status Resumo'!G54,'Detalhe Entregas e Status'!$B:$B,"lt004_protection",'Detalhe Entregas e Status'!$C:$C,"<>"&"UNIVERSO") -> 0 | K54: =IF(I54-J54=0,"-",IF(I54-J54>0,_xlfn.CONCAT("+ ",I54-J54),_xlfn.CONCAT("- ",J54-I54))) -> -
G55: 5. Em Re-teste | I55: =COUNTIFS('Detalhe Entregas e Status'!$I:$I,'Status Resumo'!G55,'Detalhe Entregas e Status'!$B:$B,"lt004_protection",'Detalhe Entregas e Status'!$C:$C,"<>"&"UNIVERSO") -> 0 | J55: =COUNTIFS('Detalhe Entregas e Status'!$J:$J,'Status Resumo'!G55,'Detalhe Entregas e Status'!$B:$B,"lt004_protection",'Detalhe Entregas e Status'!$C:$C,"<>"&"UNIVERSO") -> 0 | K55: =IF(I55-J55=0,"-",IF(I55-J55>0,_xlfn.CONCAT("+ ",I55-J55),_xlfn.CONCAT("- ",J55-I55))) -> -
G56: 6. Por Iniciar | I56: =COUNTIFS('Detalhe Entregas e Status'!$I:$I,'Status Resumo'!G56,'Detalhe Entregas e Status'!$B:$B,"lt004_protection",'Detalhe Entregas e Status'!$C:$C,"<>"&"UNIVERSO") -> 0 | J56: =COUNTIFS('Detalhe Entregas e Status'!$J:$J,'Status Resumo'!G56,'Detalhe Entregas e Status'!$B:$B,"lt004_protection",'Detalhe Entregas e Status'!$C:$C,"<>"&"UNIVERSO") -> 0 | K56: =IF(I56-J56=0,"-",IF(I56-J56>0,_xlfn.CONCAT("+ ",I56-J56),_xlfn.CONCAT("- ",J56-I56))) -> -
G57: 7. Por Entregar | I57: =COUNTIFS('Detalhe Entregas e Status'!$I:$I,'Status Resumo'!G57,'Detalhe Entregas e Status'!$B:$B,"lt004_protection",'Detalhe Entregas e Status'!$C:$C,"<>"&"UNIVERSO") -> 6 | J57: =COUNTIFS('Detalhe Entregas e Status'!$J:$J,'Status Resumo'!G57,'Detalhe Entregas e Status'!$B:$B,"lt004_protection",'Detalhe Entregas e Status'!$C:$C,"<>"&"UNIVERSO") -> 6 | K57: =IF(I57-J57=0,"-",IF(I57-J57>0,_xlfn.CONCAT("+ ",I57-J57),_xlfn.CONCAT("- ",J57-I57))) -> -
G58: Total | I58: =SUM(I51:I57) -> 7 | J58: =SUM(J51:J57) -> 7
G60: Status (Universo) | I60: 45799
G61: lt004_protection | I61: ok
B64: 3. LT007_INSTR_ACTIVITY
...

Sheet Aux Gráficos
F1: Tabela | G1: lt002_instrument
B2: Tabela | C2: Campo | D2: Status Atual | F2: Campo | G2: (Multiple Items)
B3: lt002_instrument | C3: UNIVERSO | D3: 2. Em Teste
B4: lt002_instrument | C4: AVRG_BLNC | D4: 2. Em Teste | F4: Row Labels | G4: Count of Status Atual
B5: lt002_instrument | C5: NW_BSNSS | D5: 6. Por Iniciar | F5: 1. Concluído | G5: 9
B6: lt002_instrument | C6: GRSS_INTRST_INCM | D6: 2. Em Teste | F6: 2. Em Teste | G6: 9
B7: lt002_instrument | C7: GRSS_CMMSSN_INCM | D7: 2. Em Teste | F7: 6. Por Iniciar | G7: 10
B8: lt002_instrument | C8: INTRNL_TRNSFR_RT | D8: 6. Por Iniciar | F8: 7. Por Entregar | G8: 21
B9: lt002_instrument | C9: NT_LN_LSS_PRVSN | D9: 3. Em Re-especificação | F9: 3. Em Re-especificação | G9: 2
B10: lt002_instrument | C10: BSNSS_AREA | D10: 7. Por Entregar
B11: lt002_instrument | C11: MNGMNT_PRDCT | D11: 6. Por Iniciar
B12: lt002_instrument | C12: GRSS_CMMSSN_EXPNS | D12: 2. Em Teste
B13: lt002_instrument | C13: GNS_FNNCL_TRNSCTN_EXCHNG_DFFRNCS | D13: 6. Por Iniciar
B14: lt002_instrument | C14: FLG_INTRBSNSS | D14: 6. Por Iniciar
B15: lt002_instrument | C15: INTRBSNSS_ADJ_COD | D15: 6. Por Iniciar | F15: Tabela | G15: lt004_protection
B16: lt002_instrument | C16: COD_SOC_DSTNTN | D16: 6. Por Iniciar | F16: Campo | G16: (Multiple Items)
B17: lt002_instrument | C17: BSNSS_AREA_DSTNTN | D17: 6. Por Iniciar
B18: lt002_instrument | C18: AVRG_BLNC_OFF_BLNC | D18: 2. Em Teste | F18: Row Labels | G18: Count of Status Atual
B19: lt002_instrument | C19: INTRNL_TRNSFR_RT_OFF_BLNC | D19: 6. Por Iniciar | F19: 2. Em Teste | G19: 1
B20: lt002_instrument | C20: GRSS_CMMSSN_INCM_OFF_BLNC | D20: 2. Em Teste | F20: 7. Por Entregar | G20: 6
B21: lt002_instrument | C21: GRSS_CMMSSN_EXPNS_OFF_BLNC | D21: 2. Em Teste
B22: lt002_instrument | C22: RWA_OFF_BLNC | D22: 7. Por Entregar
B23: lt002_instrument | C23: GRSS_INTRST_EXPNS | D23: 2. Em Teste | F23: Tabela | G23: lt007_instr_activity
B24: lt002_instrument | C24: NT_LN_LSS_PRVSN_OFF_BLNC | D24: 7. Por Entregar | F24: Campo | G24: (Multiple Items)
B25: lt002_instrument | C25: GRSS_INTRST_INCM_CCRR | D25: 1. Concluído
B26: lt002_instrument | C26: GRSS_INTRST_EXPNS_CCRR | D26: 1. Concluído | F26: Row Labels | G26: Count of Status Atual
B27: lt002_instrument | C27: GRSS_CMMSSN_INCM_CCRR | D27: 1. Concluído | F27: 6. Por Iniciar | G27: 5
B28: lt002_instrument | C28: GRSS_CMMSSN_EXPNS_CCRR | D28: 1. Concluído | F28: 7. Por Entregar | G28: 1
B29: lt002_instrument | C29: GNS_FNNCL_TRNSCTN_EXCHNG_CCRR | D29: 1. Concluído
B30: lt002_instrument | C30: BSNSS_AREA_CCRR | D30: 1. Concluído
B31: lt002_instrument | C31: GRSS_CMMSSN_INCM_OFF_BLNC_CCRR | D31: 1. Concluído
B32: lt002_instrument | C32: GRSS_CMMSSN_EXPNS_OFF_BLNC_CCRR | D32: 1. Concluído
B33: lt002_instrument | C33: CCF | D33: 7. Por Entregar
B34: lt002_instrument | C34: EAD | D34: 7. Por Entregar
B35: lt002_instrument | C35: TYP_OFF_BLNC_PRDCT | D35: 7. Por Entregar
B36: lt002_instrument | C36: COD_SOC | D36: 7. Por Entregar
B37: lt002_instrument | C37: SUBPORTFOLIO_ID | D37: 7. Por Entregar
B38: lt002_instrument | C38: DT_RFRNC | D38: 1. Concluído
B39: lt002_instrument | C39: DFLT_STTS_INSTRMNT | D39: 7. Por Entregar
B40: lt002_instrument | C40: IMPRMNT_STTS | D40: 7. Por Entregar
...

Sheet MacroPlano
B7: Legenda:
B9: « | C9: Entregas da equipa de IT
B10: ♦ | C10: Reuniões de PdS com cliente
B11: 3 | C11: Tempo estimado para a realização da atividade
C12: Feriados
G14: Semana 1 | K14: Semana 2 | P14: Semana 3 | U14: Semana 4 | Z14: Semana 5 | AF14: Semana 6 | AK14: Semana 7 | AO14: Semana 8 | AT14: Semana 9
B15: ID | C15: Atividade | E15: Owner | G15: 12/mai a 15/mai | K15: 16/mai a 22/mai | P15: 23/mai a 29/mai | U15: 30/mai a 05/jun | Z15: 06/jun a 13/jun | AF15: 16/jun a 20/jun | AK15: 23/jun a 26/jun | AO15: 27/jun a 03/jul | AT15: 04/jul a 11/jul
B16: 0. | C16: Gestão
B17: 0.1 | C17: SetUp | E17: Neyond
B18: 0.2 | C18: Reuniões de PdS | E18: Neyond/CdG/IT | J18: ♦ | O18: ♦ | T18: ♦ | Y18: ♦ | AD18: ♦ | AJ18: ♦ | AN18: ♦ | AS18: ♦ | AX18: ♦
B19: 1. | C19: Testes - Entrega 1 | G19: «
B20: 1.1 | C20: lt002_instrument | D20: UNIVERSO | E20: Neyond
B21: 1.2 | C21: lt002_instrument | D21: NW_BSNSS | E21: Neyond
B22: 1.3 | C22: lt002_instrument | D22: GRSS_INTRST_INCM_CCRR | E22: Neyond
B23: =_xlfn.CONCAT(B19,RIGHT(B22,1)+1) -> 1.4 | C23: lt002_instrument | D23: GRSS_INTRST_EXPNS_CCRR | E23: Neyond
B24: 1.5 | C24: lt002_instrument | D24: GRSS_CMMSSN_INCM_CCRR | E24: Neyond
B25: 1.6 | C25: lt002_instrument | D25: GRSS_CMMSSN_EXPNS_CCRR | E25: Neyond
B26: 1.7 | C26: lt002_instrument | D26: GNS_FNNCL_TRNSCTN_EXCHNG_CCRR | E26: Neyond
B27: 1.8 | C27: lt002_instrument | D27: BSNSS_AREA_CCRR | E27: Neyond
B28: 1.9 | C28: lt002_instrument | D28: GRSS_CMMSSN_INCM_OFF_BLNC_CCRR | E28: Neyond
B29: 1.10 | C29: lt002_instrument | D29: GRSS_CMMSSN_EXPNS_OFF_BLNC_CCRR | E29: Neyond
B30: 1.11 | C30: lt002_instrument | D30: DT_RFRNC | E30: Neyond
B31: 1.12 | C31: lt002_instrument | D31: CNCLLD_INSTRMNT_STTS | E31: Neyond
B32: 1.13 | C32: lt002_instrument | D32: INSTRMNT_ID | E32: Neyond
B33: 2. | C33: Testes - Entrega 2 | G33: «
B34: 2.1 | C34: lt002_instrument | D34: GRSS_INTRST_INCM | E34: Neyond
B35: 2.2 | C35: lt002_instrument | D35: GRSS_CMMSSN_INCM | E35: Neyond
B36: 2.3 | C36: lt002_instrument | D36: GRSS_CMMSSN_EXPNS | E36: Neyond
B37: 2.4 | C37: lt002_instrument | D37: AVRG_BLNC_OFF_BLNC | E37: Neyond
B38: 2.5 | C38: lt002_instrument | D38: GRSS_CMMSSN_INCM_OFF_BLNC | E38: Neyond
B39: 2.6 | C39: lt002_instrument | D39: GRSS_CMMSSN_EXPNS_OFF_BLNC | E39: Neyond
B40: 2.7 | C40: lt004_protection | D40: UNIVERSO | E40: Neyond
B41: 2.8 | C41: lt004_protection | D41: TYP_VHCL | E41: Neyond
B42: 2.9 | C42: lt007_instr_activity | D42: UNIVERSO | E42: Neyond
B43: 2.10 | C43: lt007_instr_activity | D43: PRCNTG_ACTVTY | E43: Neyond
B44: 2.11 | C44: lt007_instr_activity | D44: SSTNBL_CTGRY | E44: Neyond
B45: 2.12 | C45: lt007_instr_activity | D45: COD_SOC | E45: Neyond
... B47: 2.14 | C47: lt007_instr_activity | D47: INSTRMNT_ID | E47: Neyond
B48: 3. | C48: Testes - Entrega 3 | L48: «
B49: 3.1 | C49: lt002_instrument | D49: AVRG_BLNC | E49: Neyond
...

Sheet Detalhe Entregas e Status
E7: Entrega IT
B8: Tabela | C8: Campo | D8: Entrega Neyond | E8: Data Prevista | F8: Data Real | G8: Atraso (em dias) | I8: Status Atual | J8: Status Anterior
B9: lt002_instrument | C9: UNIVERSO | D9: Package 1 | E9: 45782 | F9: 45782 | G9: =+IF(F9="","N/A",F9-E9) -> 0 | I9: 2. Em Teste | J9: 2. Em Teste
B10: lt002_instrument | C10: AVRG_BLNC | D10: Package 4 | E10: 45796 | F10: 45796 | G10: =+IF(F10="","N/A",F10-E10) -> 0 | I10: 2. Em Teste | J10: 7. Por Entregar
B11: lt002_instrument | C11: NW_BSNSS | D11: Package 5 | E11: 45782 | F11: 45782 | G11: =+IF(F11="","N/A",F11-E11) -> 0 | I11: 6. Por Iniciar | J11: 6. Por Iniciar
B12: lt002_instrument | C12: GRSS_INTRST_INCM | D12: Package 4 | E12: 45789 | F12: 45789 | G12: =+IF(F12="","N/A",F12-E12) -> 0 | I12: 2. Em Teste | J12: 6. Por Iniciar
B13: lt002_instrument | C13: GRSS_CMMSSN_INCM | D13: Package 4 | E13: 45789 | F13: 45789 | G13: =+IF(F13="","N/A",F13-E13) -> 0 | I13: 2. Em Teste | J13: 6. Por Iniciar
B14: lt002_instrument | C14: INTRNL_TRNSFR_RT | D14: Package 1 | E14: 45796 | F14: 45796 | G14: =+IF(F14="","N/A",F14-E14) -> 0 | I14: 6. Por Iniciar | J14: 7. Por Entregar
B15: lt002_instrument | C15: NT_LN_LSS_PRVSN | D15: Package 4 | E15: 45796 | F15: 45796 | G15: =+IF(F15="","N/A",F15-E15) -> 0 | I15: 3. Em Re-especificação | J15: 7. Por Entregar
B16: lt002_instrument | C16: BSNSS_AREA | D16: Package 5 | E16: 45803 | G16: =+IF(F16="","N/A",F16-E16) -> N/A | I16: 7. Por Entregar | J16: 7. Por Entregar
B17: lt002_instrument | C17: MNGMNT_PRDCT | D17: Package 1 | E17: 45796 | F17: 45796 | G17: =+IF(F17="","N/A",F17-E17) -> 0 | I17: 6. Por Iniciar | J17: 7. Por Entregar
B18: lt002_instrument | C18: GRSS_CMMSSN_EXPNS | D18: Package 4 | E18: 45789 | F18: 45789 | G18: =+IF(F18="","N/A",F18-E18) -> 0 | I18: 2. Em Teste | J18: 6. Por Iniciar
B19: lt002_instrument | C19: GNS_FNNCL_TRNSCTN_EXCHNG_DFFRNCS | D19: Package 4 | E19: 45796 | F19: 45796 | G19: =+IF(F19="","N/A",F19-E19) -> 0 | I19: 6. Por Iniciar | J19: 7. Por Entregar
B20: lt002_instrument | C20: FLG_INTRBSNSS | D20: Package 1 | E20: 45796 | F20: 45796 | G20: =+IF(F20="","N/A",F20-E20) -> 0 | I20: 6. Por Iniciar | J20: 7. Por Entregar
B21: lt002_instrument | C21: INTRBSNSS_ADJ_COD | D21: Package 1 | E21: 45796 | F21: 45796 | G21: =+IF(F21="","N/A",F21-E21) -> 0 | I21: 6. Por Iniciar | J21: 7. Por Entregar
B22: lt002_instrument | C22: COD_SOC_DSTNTN | D22: Package 1 | E22: 45796 | F22: 45796 | G22: =+IF(F22="","N/A",F22-E22) -> 0 | I22: 6. Por Iniciar | J22: 7. Por Entregar
B23: lt002_instrument | C23: BSNSS_AREA_DSTNTN | D23: Package 1 | E23: 45796 | F23: 45796 | G23: =+IF(F23="","N/A",F23-E23) -> 0 | I23: 6. Por Iniciar | J23: 7. Por Entregar
B24: lt002_instrument | C24: AVRG_BLNC_OFF_BLNC | D24: Package 4 | E24: 45789 | F24: 45789 | G24: =+IF(F24="","N/A",F24-E24) -> 0 | I24: 2. Em Teste | J24: 6. Por Iniciar
B25: lt002_instrument | C25: INTRNL_TRNSFR_RT_OFF_BLNC | D25: Package 1 | E25: 45796 | F25: 45796 | G25: =+IF(F25="","N/A",F25-E25) -> 0 | I25: 6. Por Iniciar | J25: 7. Por Entregar
B26: lt002_instrument | C26: GRSS_CMMSSN_INCM_OFF_BLNC | D26: Package 4 | E26: 45789 | F26: 45789 | G26: =+IF(F26="","N/A",F26-E26) -> 0 | I26: 2. Em Teste | J26: 6. Por Iniciar
B27: lt002_instrument | C27: GRSS_CMMSSN_EXPNS_OFF_BLNC | D27: Package 4 | E27: 45789 | F27: 45789 | G27: =+IF(F27="","N/A",F27-E27) -> 0 | I27: 2. Em Teste | J27: 6. Por Iniciar
B28: lt002_instrument | C28: RWA_OFF_BLNC | D28: Package 1 | E28: 45803 | G28: =+IF(F28="","N/A",F28-E28) -> N/A | I28: 7. Por Entregar | J28: 7. Por Entregar
B29: lt002_instrument | C29: GRSS_INTRST_EXPNS | D29: Package 4 | E29: 45796 | F29: 45796 | G29: =+IF(F29="","N/A",F29-E29) -> 0 | I29: 2. Em Teste | J29: 7. Por Entregar
B30: lt002_instrument | C30: NT_LN_LSS_PRVSN_OFF_BLNC | D30: Package 4 | E30: 45803 | G30: =+IF(F30="","N/A",F30-E30) -> N/A | I30: 7. Por Entregar | J30: 7. Por Entregar
B31: lt002_instrument | C31: GRSS_INTRST_INCM_CCRR | D31: Package 4 | E31: 45782 | F31: 45782 | G31: =+IF(F31="","N/A",F31-E31) -> 0 | I31: 1. Concluído | J31: 6. Por Iniciar
B32: lt002_instrument | C32: GRSS_INTRST_EXPNS_CCRR | D32: Package 4 | E32: 45782 | F32: 45782 | G32: =+IF(F32="","N/A",F32-E32) -> 0 | I32: 1. Concluído | J32: 6. Por Iniciar
B33: lt002_instrument | C33: GRSS_CMMSSN_INCM_CCRR | D33: Package 4 | E33: 45782 | F33: 45782 | G33: =+IF(F33="","N/A",F33-E33) -> 0 | I33: 1. Concluído | J33: 6. Por Iniciar
B34: lt002_instrument | C34: GRSS_CMMSSN_EXPNS_CCRR | D34: Package 4 | E34: 45782 | F34: 45782 | G34: =+IF(F34="","N/A",F34-E34) -> 0 | I34: 1. Concluído | J34: 6. Por Iniciar
B35: lt002_instrument | C35: GNS_FNNCL_TRNSCTN_EXCHNG_CCRR | D35: Package 4 | E35: 45782 | F35: 45782 | G35: =+IF(F35="","N/A",F35-E35) -> 0 | I35: 1. Concluído | J35: 6. Por Iniciar
B36: lt002_instrument | C36: BSNSS_AREA_CCRR | D36: Package 4 | E36: 45782 | F36: 45782 | G36: =+IF(F36="","N/A",F36-E36) -> 0 | I36: 1. Concluído | J36: 6. Por Iniciar
B37: lt002_instrument | C37: GRSS_CMMSSN_INCM_OFF_BLNC_CCRR | D37: Package 4 | E37: 45782 | F37: 45782 | G37: =+IF(F37="","N/A",F37-E37) -> 0 | I37: 1. Concluído | J37: 6. Por Iniciar
B38: lt002_instrument | C38: GRSS_CMMSSN_EXPNS_OFF_BLNC_CCRR | D38: Package 4 | E38: 45782 | F38: 45782 | G38: =+IF(F38="","N/A",F38-E38) -> 0 | I38: 1. Concluído | J38: 6. Por Iniciar
B39: lt002_instrument | C39: CCF | D39: Package 2 | E39: 45803 | G39: =+IF(F39="","N/A",F39-E39) -> N/A | I39: 7. Por Entregar | J39: 7. Por Entregar
B40: lt002_instrument | C40: EAD | D40: Package 2 | E40: 45810 | G40: =+IF(F40="","N/A",F40-E40) -> N/A | I40: 7. Por Entregar | J40: 7. Por Entregar
B41: lt002_instrument | C41: TYP_OFF_BLNC_PRDCT | D41: Package 2 | E41: 45810 | G41: =+IF(F41="","N/A",F41-E41) -> N/A | I41: 7. Por Entregar | J41: 7. Por Entregar
B42: lt002_instrument | C42: COD_SOC | D42: Package 2 | E42: 45803 | G42: =+IF(F42="","N/A",F42-E42) -> N/A | I42: 7. Por Entregar | J42: 7. Por Entregar
B43: lt002_instrument | C43: SUBPORTFOLIO_ID | D43: Package 2 | E43: 45803 | G43: =+IF(F43="","N/A",F43-E43) -> N/A | I43: 7. Por Entregar | J43: 7. Por Entregar
B44: lt002_instrument | C44: DT_RFRNC | D44: Package 2 | E44: 45782 | F44: 45782 | G44: =+IF(F44="","N/A",F44-E44) -> 0 | I44: 1. Concluído | J44: 6. Por Iniciar
B45: lt002_instrument | C45: DFLT_STTS_INSTRMNT | D45: Package 2 | E45: 45803 | G45: =+IF(F45="","N/A",F45-E45) -> N/A | I45: 7. Por Entregar | J45: 7. Por Entregar
B46: lt002_instrument | C46: IMPRMNT_STTS | D46: Package 2 | E46: 45803 | G46: =+IF(F46="","N/A",F46-E46) -> N/A | I46: 7. Por Entregar | J46: 7. Por Entregar
...

Sheet Aux Testes_Status
B7: Status para Testes/Re-Testes
B9: Status | C9: Descrição
B10: 1. Concluído | C10: Campo concluído com sucesso.
B11: 2. Em Teste | C11: Campo em teste pela equipa Neyond.
B12: 3. Em Re-especificação | C12: Campo em re-especificação pela equipa Neyond.
B13: 4. Em Correção | C13: Campo em correção pela equipa IT.
B14: 5. Em Re-teste | C14: Campo em re-teste pela equipa Neyond.
B15: 6. Por Iniciar | C15: Campo não iniciado pela equipa Neyond.
B16: 7. Por Entregar | C16: Campo ainda não entregue para testes por parte da equipa de IT.
