Workbook
Name Ambiente: #REF!
Name Estado: #REF!
Name Metas: #REF!

Sheet Capa
B18: =TODAY() -> 46028

Sheet Pressupostos
B7: A tabela infra apresenta os pressupostos considerados para o cálculo das emissões financiadas em âmbito de Portfolio Alignment:
B9: Tópico | C9: Pressupostos
B10: Granularidade de reporte | C10: Considerar granularidade ao nível do Bem Imóvel.
B11: Universo | C11: Considerar universo corporativo, cuja a exposição se encontre associada a um contrato com classificação específica CRE (considerando apenas operçaões cuja contraparte seja uma empresa que possua NACE 41.10, 55.11 e 58) ou Habitação e que possua, pelo menos, uma garantia imobiliário associada.
C12: Considerar todas as exposições CRE (via classificação da classificação do empréstimo combinado com a classificação do propósito do bem imóvel), exceto operações de financiamento à construção.
C13: Considerar todas as exposições mortgage (via classificação do propósito do empréstimo combinado com a classificação do propósito do bem imóvel), incluíndo operações de financiamento à construção.
C14: Considerar país como Portugal ou Espanha, para todo o universo, dependendo do cenário de análise, mesmo para os casos em que a informação relativa ao país do imóvel se encontra indisponível.
B15: Cálculo das emissões financiadas | C15: Considerar, em caso de ausência de informação relativa às características dos bens necessárias para aplicação de determinada metologia de cálculo, uma metodologia de data quality score mais conservadora.
C16: Desconsiderar valores de EPC fora dos definidos pelo input corporativo, será adotada uma metodologia de data quality score mais conservadora, sempre que possível o cruzamento com finalidade do bem.
C17: Desconsiderar cálculo das emissões sempre que não é possível efetuar cruzamento com as características definidas pelo input corporativo.
C18: Considerar, em caso aplicável, o fator de emissão associado ao ano mais recente presente no input corporativo.
C19: Desconsiderar o cálculo de emissões de Scope 3.
C20: Garantir que o quociente entre o montante em dívida do contrato e o valor do imóvel na originação assume, no máximo, o valor 1.
B21: Outstanding amount | C21: Considerar o valor bruto atual do empréstimo (gross carrying amount).
B22: Property value at origination | C22: Considerar o valor total do imóvel ('preço_aquisição') no momento da transação e, quando não for possível, considerar uma das seguintes alternativas: - Montante de avaliação do bem ('mavalia'); - Montante de avaliação do bem rateado ('mavaliaa').
C23: Desconsiderar o valor total do imóvel quando este é igual a 0, passando supletivamente para o montante de avaliação do bem.
B24: Classificação da finalidade do bem | C24: Considerar, para a classificação de CRE/Mortgage, o campos de finalidade do bem ('property_purpose_code') e descritivo da garantia ('property_code').
C25: Considerar, para a classificação de CRE/Mortgage, nos casos em que a finalidade do bem corresponde a outras ('property_purpose_code' = 08 e 'property_code' = 'outras'), o código da garantia associado ao bem ('cgarant_bem').
C26: Considerar todas as exposições CRE/Mortgage, sem ter em conta o fator de geração de rendimento.
C27: Revisitar, em cada data de reporte, o mapeamento da finalidade dado que os inputs corporativos poderão alterar os valores admissíveis e/ou poderá ser adicionada ou alterado algum código de finalidade das tabelas do banco (este mapeamento será do ownership da área responsável pela tabela de modesg_out_bens_imoveis).

Sheet Overview - Emissões Dez24 
B7: O quadro infra apresenta o valor da exposição (€) e emissões (tCO2e) por setor para a data de referência de dezembro de 2024:
C8: CRE
B10: Setor | C10: Portugal | F10: Espanha | I10: Variação Emissões Financiadas (tCO2e)
A11: CTO_IMO | C11: Valor bruto (€) | D11: Valor bruto (%) | E11: Emissões Financiadas (tCO2e) | F11: Valor bruto (€) | G11: Valor bruto (%) | H11: Emissões Financiadas (tCO2e)
A12: CRE_OUTRO | B12: Commercial Real Estate (CRE) | C12: =SUM(C13:C16) -> 1.2684332e+09 | D12: =+C12/$C$23 -> 0.049827306 | E12: =SUM(E13:E16) -> 101493.7 | F12: =SUM(F13:F16) -> 1.2448052e+09 | G12: =+F12/$F$23 -> 0.048899138 | H12: =SUM(H13:H16) -> 63065.377 | I12: =+H12-E12 -> -38428.327
A13: outras empresas nao financeiras | B13: Outras Empresas Não Financeiras | C13: 1.2405572e+09 | D13: =+C13/$C$12 -> 0.97802327 | E13: 100330.09 | F13: 1.2179246e+09 | G13: =+F13/$F$12 -> 0.97840581 | H13: 62381.278 | I13: =+H13-E13 -> -37948.807
A14: outras instituicoes financeiras | B14: Outras Instituições Financeiras | C14: 27876011 | D14: =+C14/$C$12 -> 0.021976727 | E14: 1163.6182 | F14: 26880558 | G14: =+F14/$F$12 -> 0.021594189 | H14: 684.09854 | I14: =+H14-E14 -> -479.51964
A15: instituicoes de credito | B15: Instituições de Crédito | C15: 0 | D15: =+C15/$C$12 -> 0 | E15: 0 | F15: 0 | G15: =+F15/$F$12 -> 0 | H15: 0 | I15: =+H15-E15 -> 0
A16: setor publico | B16: Setor Público | C16: 0 | D16: =+C16/$C$12 -> 0 | E16: 0 | F16: 0 | G16: =+F16/$F$12 -> 0 | H16: 0 | I16: =+H16-E16 -> 0
A17: Habitacao | B17: Mortgages Loans | C17: =C18 -> 2.330418e+10 | D17: =+C17/$C$23 -> 0.91544788 | E17: 422389.15 | F17: =F18 -> 2.3304158e+10 | G17: =+F17/$F$23 -> 0.91544702 | H17: =+H18 -> 606396.29 | I17: =+H17-E17 -> 184007.14
A18: particulares | B18: Particulares | C18: 2.330418e+10 | D18: =+C18/C17 -> 1 | E18: 422389.15 | F18: 2.3304158e+10 | G18: =+F18/F17 -> 1 | H18: 606396.29 | I18: =+H18-E18 -> 184007.14
A19: CRE_FC | B19: Financiamentos para Construção (FC) | C19: 8.7640673e+08 | D19: =+C19/$C$23 -> 0.034427502 | E19: 12148.851 | F19: 8.7640673e+08 | G19: =+F19/$F$23 -> 0.034427502 | H19: =+SUM(H20:H21) -> 9625.9538 | I19: =+H19-E19 -> -2522.8969
A20: outras empresas nao financeiras | B20: Outras Empresas Não Financeiras | C20: 7.5813307e+08 | D20: =+C20/$C$19 -> 0.86504707 | E20: 11442.488 | F20: 7.5813307e+08 | G20: =+F20/$F$19 -> 0.86504707 | H20: 8886.6655 | I20: =+H20-E20 -> -2555.8222
A21: outras instituicoes financeiras | B21: Outras Instituições Financeiras | C21: 1.1827366e+08 | D21: =+C21/$C$19 -> 0.13495293 | E21: 706.3629 | F21: 1.1827366e+08 | G21: =+F21/$F$19 -> 0.13495293 | H21: 739.28826 | I21: =+H21-E21 -> 32.92536
B22: Fora de âmbito | C22: 7568682.2 | D22: =+C22/$C$23 -> 0.00029731723 | E22: 0 | F22: 31218459 | G22: =+F22/$F$23 -> 0.001226341 | H22: 0 | I22: =+H22-E22 -> 0
B23: Total | C23: =+C19+C17+C12+C22 -> 2.5456588e+10 | D23: =+D12+D17+D19 -> 0.99970268 | E23: =+E19+E17+E12 -> 536031.71 | F23: =+F19+F17+F12+F22 -> 2.5456588e+10 | G23: =+G12+G17+G19 -> 0.99877366 | H23: =+H19+H17+H12 -> 679087.62 | I23: =+I19+I17+I12 -> 143055.92
B26: Resumo Global - Portugal
B28: Setor | C28: Valor bruto (€) | D28: Scope de Emissões | E28: Emissões Financiadas (tCO2e) | F28: Physical Emission Intensity (kgCO2e/m2) | G28: Economic Emission Intensity (tCO2e/€M) | H28: PCAF Score
B30: Commercial Real Estate (CRE) | C30: =+C12 -> 1.2684332e+09 | D30: 1+2 | E30: =+E12 -> 101493.7 | F30: =+('3. Área'!C12+'3. Área'!C13)*1000/'3. Área'!E11 -> 48.865532 | G30: =+E30/(C30/1000000) -> 80.015017 | H30: =+(('3. Área'!C12*3)+('3. Área'!C13*4)+('3. Área'!C14*5))/SUM('3. Área'!C12:C14) -> 4.0513659
B31: Mortgages Loans | C31: =+C17 -> 2.330418e+10 | D31: 1+2 | E31: =+E17 -> 422389.15 | F31: =+('3. Área'!C16+'3. Área'!C17)*1000/'3. Área'!E15 -> 13.700139 | G31: =+E31/(C31/1000000) -> 18.125039 | H31: =+(('3. Área'!C16*3)+('3. Área'!C17*4)+('3. Área'!C18*5))/SUM('3. Área'!C16:C18) -> 3.8351396
B32: Total | C32: =SUM(C30:C31) -> 2.4572613e+10 | E32: =SUM(E30:E31) -> 523882.86
C33: =+C38-C30 -> -23627992
B34: Resumo Global - Espanha | C34: =+C39-C31 -> -21784.55
B36: Setor | C36: Valor bruto (€) | D36: Scope de Emissões | E36: Emissões Financiadas (tCO2e) | F36: Physical Emission Intensity (kgCO2e/m2) | G36: Economic Emission Intensity (tCO2e/€M) | H36: PCAF Score
B38: Commercial Real Estate (CRE) | C38: =+F12 -> 1.2448052e+09 | D38: 1+2 | E38: =+H12 -> 63065.377 | F38: =+('3. Área'!F12+'3. Área'!F13)*1000/'3. Área'!H11 -> 30.794097 | G38: =+E38/(C38/1000000) -> 50.662848 | H38: =+(('3. Área'!F12*3)+('3. Área'!F13*4)+('3. Área'!F14*5))/'3. Área'!F11 -> 4.0453826
B39: Mortgages Loans | C39: =+F17 -> 2.3304158e+10 | D39: 1+2 | E39: =+H17 -> 606396.29 | F39: =+('3. Área'!F16+'3. Área'!F17)*1000/'3. Área'!H15 -> 19.736516 | G39: =+E39/(C39/1000000) -> 26.020949 | H39: =+(('3. Área'!F16*3)+('3. Área'!F17*4)+('3. Área'!F18*5))/'3. Área'!F15 -> 3.8137798
B40: Total | C40: =SUM(C38:C39) -> 2.4548963e+10 | E40: =SUM(E38:E39) -> 669461.67

Sheet Analises >>

Sheet 1. EPC - Commercial Real Estate
B7: O quadro infra apresenta a distribuição dos EPC's reais do Banco para a carteira de Commercial Real Estate (CRE).
B9: EPC | C9: Portugal | F9: Espanha
C10: Valor bruto (€) | D10: Valor bruto (%) | E10: Emissões Financiadas (tCO2e) | F10: Valor bruto (€) | G10: Valor bruto (%) | H10: Emissões Financiadas (tCO2e)
B11: A | C11: 7114027.9 | D11: =C11/$C$20 -> 0.040722165 | E11: 7.5457864 | F11: 7114027.9 | G11: =F11/$F$20 -> 0.048065928 | H11: 5.6653876
B12: A+ | C12: 1281288.6 | D12: =C12/$C$20 -> 0.0073343607 | E12: 5.4415455 | F12: 0 | G12: =F12/$F$20 -> 0 | H12: 0
B13: B | C13: 20095139 | D13: =C13/$C$20 -> 0.11502873 | E13: 47.633175 | F13: 20095139 | G13: =F13/$F$20 -> 0.1357728 | H13: 45.161546
B14: B- | C14: 25966869 | D14: =C14/$C$20 -> 0.14863972 | E14: 291.26534 | F14: 0 | G14: =F14/$F$20 -> 0 | H14: 0
B15: C | C15: 63408913 | D15: =C15/$C$20 -> 0.36296571 | E15: 667.29719 | F15: 63408913 | G15: =F15/$F$20 -> 0.4284223 | H15: 445.75928
B16: D | C16: 45135182 | D16: =C16/$C$20 -> 0.2583631 | E16: 170.90433 | F16: 45135182 | G16: =F16/$F$20 -> 0.30495584 | H16: 220.53735
B17: E | C17: 5593508.9 | D17: =C17/$C$20 -> 0.0320184 | E17: 92.075798 | F17: 5593508.9 | G17: =F17/$F$20 -> 0.037792541 | H17: 77.461684
B18: F | C18: 6101773.2 | D18: =C18/$C$20 -> 0.03492781 | E18: 91.311164 | F18: 6101773.2 | G18: =F18/$F$20 -> 0.041226629 | H18: 95.218255
B19: G | C19: Não Aplicável | F19: 557086.54 | G19: =F19/$F$20 -> 0.0037639551 | H19: 31.587348
B20: Total | C20: =+SUM(C11:C19) -> 1.746967e+08 | D20: =+SUM(D11:D19) -> 1 | E20: =+SUM(E11:E19) -> 1373.4743 | F20: =+SUM(F11:F19) -> 1.4800563e+08 | G20: =+SUM(G11:G19) -> 1 | H20: =+SUM(H11:H19) -> 921.39086
B23: O quadro infra apresenta a distribuição dos EPC's estimados do Banco para a carteira de Commercial Real Estate (CRE).
B24: ▪ Denote-se que estes EPC's não são utilizados para apurar o fator de emissão do imóvel.
B26: EPC | C26: Portugal | F26: Espanha
C27: Valor bruto (€) | D27: Valor bruto (%) | E27: Emissões Financiadas (tCO2e) | F27: Valor bruto (€) | G27: Valor bruto (%) | H27: Emissões Financiadas (tCO2e)
B28: A | C28: 84193989 | D28: =C28/$C$40 -> 0.076653772 | E28: 1723.21 | F28: 84193989 | G28: =F28/$F$40 -> 0.074835225 | H28: 1150.3666
B29: A+ | C29: 3211392.1 | D29: =C29/$C$40 -> 0.0029237873 | E29: 4323.7996 | F29: 3211392.1 | G29: =F29/$F$40 -> 0.0028544229 | H29: 2567.5783
B30: B | C30: 20295957 | D30: =C30/$C$40 -> 0.018478298 | E30: 1060.3859 | F30: 20295957 | G30: =F30/$F$40 -> 0.018039916 | H30: 646.49102
B31: B- | C31: 1.0929775e+08 | D31: =C31/$C$40 -> 0.099509298 | E31: 2839.4895 | F31: 1.1236083e+08 | G31: =F31/$F$40 -> 0.099871118 | H31: 1841.5142
B32: C | C32: 5.5684636e+08 | D32: =C32/$C$40 -> 0.5069765 | E32: 49058.217 | F32: 5.5684636e+08 | G32: =F32/$F$40 -> 0.4949489 | H32: 29625.445
B33: D | C33: 1.9914865e+08 | D33: =C33/$C$40 -> 0.18131336 | E33: 34378.165 | F33: 1.9914865e+08 | G33: =F33/$F$40 -> 0.17701185 | H33: 21997.097
B34: E | C34: 65339946 | D34: =C34/$C$40 -> 0.059488253 | E34: 4952.6114 | F34: 65339946 | G34: =F34/$F$40 -> 0.058076944 | H34: 3238.0225
B35: F | C35: 13169159 | D35: =C35/$C$40 -> 0.01198976 | E35: 1473.6052 | F35: 13169159 | G35: =F35/$F$40 -> 0.011705313 | H35: 898.05433
B36: G | C36: 5432270.5 | D36: =C36/$C$40 -> 0.0049457691 | E36: 135.02915 | F36: 5432270.5 | G36: =F36/$F$40 -> 0.0048284348 | H36: 84.31296
B37: Sem EPC | C37: 8689672.6 | D37: =C37/$C$40 -> 0.0079114458 | E37: 175.71628 | F37: 8689672.6 | G37: =F37/$F$40 -> 0.0077237534 | H37: 95.103865
B38: Exposição não colaterizada | C38: 28111362 | D38: =C38/$C$40 -> 0.025593774 | E38: 0 | F38: 28111362 | G38: =F38/$F$40 -> 0.024986583 | H38: 0
B39: Fora de âmbito | C39: 4630704.4 | D39: =C39/$C$40 -> 0.0042159893 | E39: 0 | F39: 28258696 | G39: =F39/$F$40 -> 0.02511754 | H39: 0
B40: Total | C40: =+SUM(C28:C39) -> 1.0983672e+09 | D40: =+SUM(D28:D39) -> 1 | E40: =+SUM(E28:E39) -> 100120.23 | F40: =+SUM(F28:F39) -> 1.1250583e+09 | G40: =+SUM(G28:G39) -> 1 | H40: =+SUM(H28:H39) -> 62143.986
B43: Resumo Global - Portugal
C45: Valor bruto (€) | D45: Valor bruto (%) | E45: Emissões Financiadas (tCO2e)
B47: Com EPC Real | C47: =+C20 -> 1.746967e+08 | D47: =C47/$C$50 -> 0.1372254 | E47: =+E20 -> 1373.4743
B48: Sem EPC Real | C48: =+SUM(C28:C38) -> 1.0937365e+09 | D48: =C48/$C$50 -> 0.85913715 | E48: =+SUM(E28:E38) -> 100120.23
B49: Fora de âmbito | C49: =+C39 -> 4630704.4 | D49: =C49/$C$50 -> 0.0036374485 | E49: =+E39 -> 0
B50: Total | C50: =SUM(C47:C49) -> 1.2730639e+09 | D50: =SUM(D47:D49) -> 1 | E50: =SUM(E47:E49) -> 101493.7
B52: Resumo Global - Espanha
C54: Valor bruto (€) | D54: Valor bruto (%) | E54: Emissões Financiadas (tCO2e)
B56: Com EPC Real | C56: =+F20 -> 1.4800563e+08 | D56: =C56/$C$59 -> 0.11625939 | E56: =+H20 -> 921.39086
B57: Sem EPC Real | C57: =+SUM(F28:F38) -> 1.0967996e+09 | D57: =C57/$C$59 -> 0.86154322 | E57: =+SUM(H28:H38) -> 62143.986
...

Sheet 2. EPC - Mortgages Loans
B7: O quadro infra apresenta a distribuição dos EPC's reais do Banco para a carteira de Mortgages Loans.
B9: EPC | C9: Portugal | F9: Espanha
C10: Valor bruto (€) | D10: Valor bruto (%) | E10: Emissões Financiadas (tCO2e) | F10: Valor bruto (€) | G10: Valor bruto (%) | H10: Emissões Financiadas (tCO2e)
B11: A | C11: 1.1667907e+09 | D11: =C11/$C$20 -> 0.094750958 | E11: 1815.7049 | F11: 1.1667907e+09 | G11: =F11/$F$20 -> 0.10649358 | H11: 2343.1254
B12: A+ | C12: 4.9868473e+08 | D12: =C12/$C$20 -> 0.040496428 | E12: 297.01848 | F12: 0 | G12: =F12/$F$20 -> 0 | H12: 0
B13: B | C13: 7.8907877e+08 | D13: =C13/$C$20 -> 0.064078304 | E13: 2288.3154 | F13: 7.8907877e+08 | G13: =F13/$F$20 -> 0.072019622 | H13: 4686.671
B14: B- | C14: 8.6147392e+08 | D14: =C14/$C$20 -> 0.069957258 | E14: 3410.5565 | F14: 0 | G14: =F14/$F$20 -> 0 | H14: 0
B15: C | C15: 3.2050248e+09 | D15: =C15/$C$20 -> 0.26026876 | E15: 17425.619 | F15: 3.2050248e+09 | G15: =F15/$F$20 -> 0.29252425 | H15: 28098.798
B16: D | C16: 3.2107711e+09 | D16: =C16/$C$20 -> 0.2607354 | E16: 26741.843 | F16: 3.2107711e+09 | G16: =F16/$F$20 -> 0.29304872 | H16: 42962.367
B17: E | C17: 1.7950085e+09 | D17: =C17/$C$20 -> 0.14576631 | E17: 21588.72 | F17: 1.7950085e+09 | G17: =F17/$F$20 -> 0.16383134 | H17: 34030.699
B18: F | C18: 7.874568e+08 | D18: =C18/$C$20 -> 0.063946589 | E18: 13783.053 | F18: 7.874568e+08 | G18: =F18/$F$20 -> 0.071871584 | H18: 24136.337
B19: G | C19: Não Aplicável | F19: 2310673.6 | G19: =F19/$F$20 -> 0.00021089636 | H19: 86.466532
B20: Total | C20: =+SUM(C11:C19) -> 1.2314289e+10 | D20: =+SUM(D11:D19) -> 1 | E20: =+SUM(E11:E19) -> 87350.829 | F20: =+SUM(F11:F19) -> 1.0956441e+10 | G20: =SUM(G11:G19) -> 1 | H20: =+SUM(H11:H19) -> 136344.46
B23: O quadro infra apresenta a distribuição dos EPC's estimados do Banco para a carteira de Mortgages Loans.
B24: ▪ Denote-se que estes EPC's não são utilizados para apurar o fator de emissão do imóvel.
B26: EPC | C26: Portugal | F26: Espanha
C27: Valor bruto (€) | D27: Valor bruto (%) | E27: Emissões Financiadas (tCO2e) | F27: Valor bruto (€) | G27: Valor bruto (%) | H27: Emissões Financiadas (tCO2e)
B28: A | C28: 5.0862311e+08 | D28: =C28/$C$40 -> 0.046268631 | E28: 9062.3233 | F28: 5.0862311e+08 | G28: =F28/$F$40 -> 0.041181803 | H28: 12389.141
B29: A+ | C29: 1.8730299e+08 | D29: =C29/$C$40 -> 0.017038653 | E29: 4157.4002 | F29: 6.8598772e+08 | G29: =F29/$F$40 -> 0.055542523 | H29: 13485.758
B30: B | C30: 5.7572126e+08 | D30: =C30/$C$40 -> 0.052372442 | E30: 32999.506 | F30: 5.7572126e+08 | G30: =F30/$F$40 -> 0.046614553 | H30: 45355.37
B31: B- | C31: 6.0221689e+08 | D31: =C31/$C$40 -> 0.054782708 | E31: 11723.41 | F31: 1.4636247e+09 | G31: =F31/$F$40 -> 0.11850563 | H31: 28397.738
B32: C | C32: 3.4380386e+09 | D32: =C32/$C$40 -> 0.31275287 | E32: 71525.375 | F32: 3.4380386e+09 | G32: =F32/$F$40 -> 0.27836845 | H32: 91620.557
B33: D | C33: 3.2493798e+09 | D33: =C33/$C$40 -> 0.29559088 | E33: 130825.53 | F33: 3.2493798e+09 | G33: =F33/$F$40 -> 0.26309327 | H33: 175125.07
B34: E | C34: 1.4331546e+09 | D34: =C34/$C$40 -> 0.13037178 | E34: 29542.331 | F34: 1.4331546e+09 | G34: =F34/$F$40 -> 0.11603855 | H34: 41178.659
B35: F | C35: 9.0814229e+08 | D35: =C35/$C$40 -> 0.082612251 | E35: 43896.892 | F35: 9.0814229e+08 | G35: =F35/$F$40 -> 0.073529762 | H35: 60982.018
B36: G | C36: 49814981 | D36: =C36/$C$40 -> 0.0045315892 | E36: 1066.0231 | F36: 47548622 | G36: =F36/$F$40 -> 0.00384988 | H36: 1367.5738
B37: Sem EPC | C37: 819783.32 | D37: =C37/$C$40 -> 7.4574378e-05 | E37: 239.53171 | F37: 819783.32 | G37: =F37/$F$40 -> 6.6375582e-05 | H37: 149.9477
B38: Exposição não colaterizada | C38: 36675990 | D38: =C38/$C$40 -> 0.0033363562 | E38: 0 | F38: 36675990 | G38: =F38/$F$40 -> 0.0029695532 | H38: 0
B39: Fora de âmbito | C39: 2937977.9 | D39: =C39/$C$40 -> 0.00026726315 | E39: 0 | F39: 2959762.4 | G39: =F39/$F$40 -> 0.00023964375 | H39: 0
B40: Total | C40: =+SUM(C28:C39) -> 1.0992828e+10 | D40: =+SUM(D28:D39) -> 1 | E40: =+SUM(E28:E39) -> 335038.32 | F40: =+SUM(F28:F39) -> 1.2350676e+10 | G40: =+SUM(G28:G39) -> 1 | H40: =+SUM(H28:H39) -> 470051.83
B43: Resumo - Portugal
C45: Valor bruto (€) | D45: Valor bruto (%) | E45: Emissões Financiadas (tCO2e)
B47: Com EPC Real | C47: =+C20 -> 1.2314289e+10 | D47: =C47/$C$50 -> 0.52834888 | E47: =+E20 -> 87350.829
B48: Sem EPC Real | C48: =+SUM(C28:C38) -> 1.098989e+10 | D48: =C48/$C$50 -> 0.47152507 | E48: =+SUM(E28:E38) -> 335038.32
B49: Fora de âmbito | C49: =+C39 -> 2937977.9 | D49: =C49/$C$50 -> 0.00012605496 | E49: =E39 -> 0
B50: Total | C50: =SUM(C47:C49) -> 2.3307118e+10 | D50: =SUM(D47:D49) -> 1 | E50: =SUM(E47:E49) -> 422389.15
B52: Resumo Global - Espanha
C54: Valor bruto (€) | D54: Valor bruto (%) | E54: Emissões Financiadas (tCO2e)
B56: Com EPC Real | C56: =+F20 -> 1.0956441e+10 | D56: =C56/$C$59 -> 0.47008993 | E56: =+H20 -> 136344.46
B57: Sem EPC Real | C57: =+SUM(F28:F38) -> 1.2347716e+10 | D57: =C57/$C$59 -> 0.52978308 | E57: =+SUM(H28:H38) -> 470051.83
...

Sheet 3. Área
B7: O quadro infra apresenta a distribuição da área do imóvel para a carteira de Commercial Real Estate (CRE) e Mortgages Loans.
B9: Setor | C9: Portugal | F9: Espanha
C10: Emissões Financiadas (tCO2e) | D10: Emissões Financiadas (%) | E10: Área Ponderada (m2) | F10: Emissões Financiadas (tCO2e) | G10: Emissões Financiadas (%) | H10: Área Ponderada (m2)
B11: Commercial Real Estate (CRE) | C11: =+SUM(C12:C14) -> 101493.7 | D11: =+C11/$C$19 -> 0.19373358 | E11: =+SUM(E12:E14) -> 1942205.7 | F11: =+SUM(F12:F14) -> 63065.377 | G11: =+F11/$F$19 -> 0.094203118 | H11: =+SUM(H12:H14) -> 1925106.4
B12: Metodologia floor area (Data Quality Score 3) | C12: 1373.4743 | D12: =+C12/$C$11 -> 0.013532606 | E12: 70446.82 | F12: 921.39086 | G12: =+F12/$F$11 -> 0.01461009 | H12: 52501.018
B13: Metodologia floor area (Data Quality Score 4) | C13: 93533.439 | D13: =+C13/$C$11 -> 0.92156888 | E13: 1871758.8 | F13: 58360.524 | G13: =+F13/$F$11 -> 0.92539721 | H13: 1872605.4
B14: Metodologia number of buildings (Data Quality Score 5) | C14: 6586.7903 | D14: =+C14/$C$11 -> 0.064898511 | E14: 0 | F14: 3783.4623 | G14: =+F14/$F$11 -> 0.059992701 | H14: 0
B15: Mortgages Loans | C15: =+SUM(C16:C18) -> 422389.15 | D15: =+C15/$C$19 -> 0.80626642 | E15: =+SUM(E16:E18) -> 29537918 | F15: =+SUM(F16:F18) -> 606396.29 | G15: =+F15/$F$19 -> 0.90579688 | H15: =+SUM(H16:H18) -> 29537890
B16: Metodologia floor area (Data Quality Score 3) | C16: 87350.829 | D16: =+C16/$C$15 -> 0.20680178 | E16: 9226649.8 | F16: 136344.46 | G16: =+F16/$F$15 -> 0.22484383 | H16: 8249588.2
B17: Metodologia floor area (Data Quality Score 4) | C17: 317322.75 | D17: =+C17/$C$15 -> 0.75125686 | E17: 20311268 | F17: 446630.59 | G17: =+F17/$F$15 -> 0.73653251 | H17: 21288302
B18: Metodologia number of buildings (Data Quality Score 5) | C18: 17715.575 | D18: =+C18/$C$15 -> 0.041941359 | E18: 0 | F18: 23421.245 | G18: =+F18/$F$15 -> 0.038623662 | H18: 0
B19: Total | C19: =+C15+C11 -> 523882.86 | D19: =+D11+D15 -> 1 | E19: =+E11+E15 -> 31480124 | F19: =+F15+F11 -> 669461.67 | G19: =+G11+G15 -> 1 | H19: =+H11+H15 -> 31462997

Sheet 4. Finalidade
B7: O quadro infra apresenta o mapeamento das finalidades do bem, para a carteira Commercial Real Estate (CRE)
B9: property_purpose_code | C9: Descritivo cgarant bem | D9: Portugal | F9: Espanha | I9: purpose_code | J9: finalidade_mod | K9: valor_bruto | L9: sum(emiss_op2b)
D10: Exposição (€) | E10: Emissões Financiadas (tCO2e) | F10: Exposição (€) | G10: Emissões Financiadas (tCO2e)
B11: CRE_OUTRO | D11: =+SUM(D12:D23) -> 1.2684332e+09 | E11: =+SUM(E12:E23) -> 101493.7 | F11: =+SUM(F12:F23) -> 1.2448052e+09 | G11: =+SUM(G12:G23) -> 63065.377
B12: 01 | C12: Habitacao | D12: 2.7051978e+08 | E12: 1973.467 | F12: 2.7051978e+08 | G12: 2880.1699
B13: 02 | C13: Comercio | D13: 7.6841966e+08 | E13: 74086.172 | F13: 7.4578712e+08 | G13: 43714.922
B14: 03 | C14: Escritorio | D14: 51259021 | E14: 1872.3189 | F14: 51259021 | G14: 1099.7226
B15: 04 | C15: Armazem | D15: 72170592 | E15: 5046.542 | F15: 71175140 | G15: 3054.5495
B16: 05 | C16: Industria | D16: 11356426 | E16: 2000.4611 | F16: 11356426 | G16: 1323.1735
B17: 08 | C17: Outras | D17: 4653702.9 | E17: 15713.768 | F17: 4653702.9 | G17: 10463.188
B18: 09 | C18: Hotel | D18: 33574396 | E18: 391.23662 | F18: 33574396 | G18: 251.53899
B19: 10 | C19: Educacao | D19: 194.52 | E19: 0.012009535 | F19: 194.52 | G19: 0.0064869034
B20: 11 | C20: Saude | D20: 9810905.6 | E20: 260.5746 | F20: 9810905.6 | G20: 197.54041
B21: 13 | C21: Agricultura | D21: 408890.19 | E21: 0.010087207 | F21: 408890.19 | G21: 0.0067441422
B22: Sem finalidade | D22: 18148278 | E22: 149.14122 | F22: 18148278 | G22: 80.558045
B23: Exposição não colaterizada | D23: 28111362 | E23: 0 | F23: 28111362 | G23: 0
B24: Fora de âmbito | D24: 4630704.4 | E24: 0 | F24: 28258696 | G24: 0
B25: Total | D25: =+D24+D11 -> 1.2730639e+09 | E25: =+E24+E11 -> 101493.7 | F25: =+F24+F11 -> 1.2730639e+09 | G25: =+G24+G11 -> 63065.377
B28: O quadro infra apresenta o mapeamento das finalidades do bem, para a carteira de Mortgages Loans
B30: property_purpose_code | C30: Descritivo cgarant bem | D30: Portugal | F30: Espanha
D31: Exposição (€) | E31: Emissões Financiadas (tCO2e) | F31: Exposição (€) | G31: Emissões Financiadas (tCO2e)
B32: Habitacao | D32: =+SUM(D33:D42) -> 2.330418e+10 | E32: =+SUM(E33:E42) -> 422389.15 | F32: =+SUM(F33:F42) -> 2.3304158e+10 | G32: =+SUM(G33:G42) -> 606396.29
B33: 01 | C33: Habitacao | D33: 2.3225312e+10 | E33: 396766 | F33: 2.3225312e+10 | G33: 591303.22
B34: 02 | C34: Comercio | D34: 30591558 | E34: 19066.796 | F34: 30569773 | G34: 11017.154
B35: 03 | C35: Escritorio | D35: 4097961 | E35: 986.00507 | F35: 4097961 | G35: 553.65604
B36: 04 | C36: Armazem | D36: 6162600.3 | E36: 1284.1378 | F36: 6162600.3 | G36: 717.97908
B37: 05 | C37: Industria | D37: 168410.06 | E37: 43.465183 | F37: 168410.06 | G37: 26.653839
B38: 08 | C38: Outras | D38: 1038375.3 | E38: 4001.159 | F38: 1038375.3 | G38: 2647.1342
B39: 10 | C39: Educacao | D39: 93777.47 | E39: 9.931413 | F39: 93777.47 | G39: 5.3644138
B40: 11 | C40: Saude | D40: 3640.1 | E40: 2.8573798 | F40: 3640.1 | G40: 1.5434025
B41: Sem finalidade | D41: 35637.465 | E41: 228.80369 | F41: 35637.465 | G41: 123.58742
B42: Exposição não colaterizada | D42: 36675990 | E42: 0 | F42: 36675990 | G42: 0
B43: Fora de âmbito | D43: 2937977.9 | E43: 0 | F43: 2959762.4 | G43: 0
B44: Total | D44: =+D32+D43 -> 2.3307118e+10 | E44: =+E32+E43 -> 422389.15 | F44: =+F32+F43 -> 2.3307118e+10 | G44: =+G32+G43 -> 606396.29

Sheet 5. CCAE
B7: ccae | C7: Descritivo CAE | D7: Amount
B8: 23312 | C8: FABRICACAO DE LADRILHOS, MOSAICOS E PLACAS DE CERAMICA | D8: -1649773.4
B9: 56302 | C9: BARES | D9: -1440295.7
B10: 72200 | C10: INVESTIGACAO E DESENV. CIENCIAS SOCIAIS E HUMANAS | D10: -202954.72
B11: 55121 | C11: HOTEIS SEM RESTAURANTE | D11: -13777001
B12: 79900 | C12: OUTROS SERVICOS DE RESERVAS E ACTIVIDADES RELACIONADAS | D12: -2514163.9
B13: 94910 | C13: ACTIVIDADES DE ORGANIZACOES RELIGIOSAS | D13: -450305.47
B14: 46320 | C14: COMERCIO POR GROSSO DE CARNE E PRODUTOS A BASE DE CARNE | D14: -3663019.7
B15: 85201 | C15: ENSINO BASICO (1. CICLO) | D15: -994787.22
B16: 49410 | C16: TRANSPORTES RODOVIARIOS DE MERCADORIAS | D16: -7685103
B17: 47191 | C17: COM.RET.NAO ESPECIAL.,SEM PREDOMIN.PROD.ALIMENT.,BEBIDAS,TABACO,GR.ARM. E SIMIL. | D17: -2363423.9
B18: 46422 | C18: COMERCIO POR GROSSO DE CALCADO | D18: -52254.81
B19: 46331 | C19: COMERCIO POR GROSSO DE LEITE, SEUS DERIVADOS E OVOS | D19: -113942.92
... B477: 46771 | C477: COMERCIO POR GROSSO DE SUCATAS E DE DESPERDICIOS METALICOS | D477: -2817497.8
