Workbook
Name Ambito: #REF!
Name ÁREA: #REF!
Name ÁREA: #REF!
Name ÁREA: #REF!
Name ÁREA: #REF!
Name ÁREA: #REF!
Name ÁREA: #REF!
Name ÁREA: #REF!
Name asefadf: #REF!
Name bn: '[3]Code List'!#REF!
Name Default_values: #REF!
Name Estados: [5]!Table7[Estados]
Name Estados_testes: #REF!
Name Estados_testes: #REF!
Name Estados_testes: #REF!
Name Estados_testes: #REF!
Name Estados_testes: #REF!
Name Estados_testes: #REF!
Name Estados_testes: #REF!
Name Pendências: [5]!Table6[Pendências]
Name TABELA: #REF!
Name TABELA: #REF!
Name TABELA: #REF!
Name TABELA: #REF!
Name TABELA: #REF!
Name TABELA: #REF!
Name TABELA: #REF!
Name Validações_Especificas: #REF!
Name Validaçoes_Genericas: #REF!

Sheet Capa
B4: BCE Loan Tape
B5: Modelo Consolidado de Garantias | Testes
B8: Lisboa, | C8: 45068
B10: Análise e testes de Modelo em produção a 30 Abril 2023, com respeito a 30 Abril 2023 real

Sheet 1. Resumo Universo
B5: 1. Análises Universos
C7: Data de referência | D7: 45046
C8: Data de atualização | D8: 45032
B11: Universo BIYR 2500 | J11: Universo BIYR9500
C13: tipo | D13: biyr2500_caplic | E13: biyr2500_tipgargblbg | F13: num_resp_proc | H13: biyr2500_mavaliaa
C14: F | D14: DC | E14: 2 | F14: 2080 | H14: 97220800 | J14: =(H14-'Dados Fevereiro | 16-04-23'!H14)/'Dados Fevereiro | 16-04-23'!H14 -> -0.076691745
C15: F | D15: DP | E15: 2 | F15: 1959 | H15: 1.9725246e+08 | J15: =(H15-'Dados Fevereiro | 16-04-23'!H15)/'Dados Fevereiro | 16-04-23'!H15 -> -0.026380262
C16: F | D16: FU | E16: 2 | F16: 1910 | H16: 2.3319971e+08 | J16: =(H16-'Dados Fevereiro | 16-04-23'!H16)/'Dados Fevereiro | 16-04-23'!H16 -> 0.034782
C17: F | D17: SG | E17: 2 | F17: 1111 | H17: 88514777 | J17: =(H17-'Dados Fevereiro | 16-04-23'!H17)/'Dados Fevereiro | 16-04-23'!H17 -> -0.034271906
C18: F | D18: TT | E18: 2 | F18: 59 | H18: 60749720 | J18: =(H18-'Dados Fevereiro | 16-04-23'!H18)/'Dados Fevereiro | 16-04-23'!H18 -> 0.025215979
C19: FAC | D19: FAC | E19: 1 | F19: 931 | H19: 1.0599748e+08 | J19: =(H19-'Dados Fevereiro | 16-04-23'!H19)/'Dados Fevereiro | 16-04-23'!H19 -> 0.18094528
C20: I | D20: CS | E20: 2 | F20: 1519 | H20: 5.013535e+09 | J20: =(H20-'Dados Fevereiro | 16-04-23'!H20)/'Dados Fevereiro | 16-04-23'!H20 -> 0.1983807
C21: I | D21: GP | E21: 2 | F21: 364116 | H21: 5.3228846e+10 | J21: =(H21-'Dados Fevereiro | 16-04-23'!H21)/'Dados Fevereiro | 16-04-23'!H21 -> -0.0095344758
C22: LEA | D22: LEA | E22: 1 | F22: 21454 | H22: 1.6449139e+09 | J22: =(H22-'Dados Fevereiro | 16-04-23'!H22)/'Dados Fevereiro | 16-04-23'!H22 -> -0.01556773
C23: LEA | D23: LEA | E23: 2 | F23: 5155 | H23: 1.516394e+09 | J23: =(H23-'Dados Fevereiro | 16-04-23'!H23)/'Dados Fevereiro | 16-04-23'!H23 -> -0.0075587664
C24: P | D24: CLI | E24: 1 | F24: 90394 | H24: 8.6205061e+09 | J24: =(H24-'Dados Fevereiro | 16-04-23'!H24)/'Dados Fevereiro | 16-04-23'!H24 -> -0.026368522
C25: P | D25: CS | E25: 1 | F25: 35116 | H25: 4.7796841e+09 | J25: =(H25-'Dados Fevereiro | 16-04-23'!H25)/'Dados Fevereiro | 16-04-23'!H25 -> 0.097850144
... C27: TBD | D27: CS | E27: 2 | F27: 396 | H27: 5.4768751e+08 | J27: =(H27-'Dados Fevereiro | 16-04-23'!H27)/'Dados Fevereiro | 16-04-23'!H27 -> 0.014774663
B29: Universo Modelo
C31: tipo | D31: origem | E31: num_resp_proc | F31: mavaliaa | H31: Variação face à execução anterior
C32: F | D32: CS | E32: 7419 | F32: 6.7978282e+08 | H32: =E32-'Dados Fevereiro | 16-04-23'!E32 -> -378 | I32: =F32-'Dados Fevereiro | 16-04-23'!F32 -> -9217284.6 | J32: =I32/'Dados Fevereiro | 16-04-23'!F32 -> -0.01337777
C33: I | D33: CS | E33: 966 | F33: 4.3973813e+09 | H33: =E33-'Dados Fevereiro | 16-04-23'!E33 -> -31 | I33: =F33-'Dados Fevereiro | 16-04-23'!F33 -> 7.3954507e+08 | J33: =I33/'Dados Fevereiro | 16-04-23'!F33 -> 0.20218102
C34: I | D34: GP | E34: 399722 | F34: 5.3143386e+10 | H34: =E34-'Dados Fevereiro | 16-04-23'!E34 -> -4115 | I34: =F34-'Dados Fevereiro | 16-04-23'!F34 -> -4.8950923e+08 | J34: =I34/'Dados Fevereiro | 16-04-23'!F34 -> -0.0091270334
C35: I | D35: LEA | E35: 4941 | F35: 1.4928783e+09 | H35: =E35-'Dados Fevereiro | 16-04-23'!E35 -> -64 | I35: =F35-'Dados Fevereiro | 16-04-23'!F35 -> -10946367 | J35: =I35/'Dados Fevereiro | 16-04-23'!F35 -> -0.0072790178
C36: P | D36: CS | E36: 107594 | F36: 1.3872364e+10 | H36: =E36-'Dados Fevereiro | 16-04-23'!E36 -> -1561 | I36: =F36-'Dados Fevereiro | 16-04-23'!F36 -> -1.9971591e+08 | J36: =I36/'Dados Fevereiro | 16-04-23'!F36 -> -0.014192352
C37: P | D37: FAC | E37: 11174 | F37: 1.0599739e+08 | H37: =E37-'Dados Fevereiro | 16-04-23'!E37 -> 2133 | I37: =F37-'Dados Fevereiro | 16-04-23'!F37 -> 16239423 | J37: =I37/'Dados Fevereiro | 16-04-23'!F37 -> 0.18092458
C38: P | D38: GP | E38: 98371 | F38: 8.4670604e+09 | H38: =E38-'Dados Fevereiro | 16-04-23'!E38 -> -2186 | I38: =F38-'Dados Fevereiro | 16-04-23'!F38 -> -2.1656789e+08 | J38: =I38/'Dados Fevereiro | 16-04-23'!F38 -> -0.024939793
C39: P | D39: LEA | E39: 17437 | F39: 1.5863997e+09 | H39: =E39-'Dados Fevereiro | 16-04-23'!E39 -> -26 | I39: =F39-'Dados Fevereiro | 16-04-23'!F39 -> -2609044.2 | J39: =I39/'Dados Fevereiro | 16-04-23'!F39 -> -0.0016419319
E40: =SUM(E32:E39) -> 647624
C43: Valores originais
D45: BIYR9500 | F45: Novo Modelo de Garantias
C46: Tipo | D46: # Responsabilidade/ Processo | E46: MAVALIAA | F46: # Responsabilidade/ Processo | H46: MAVALIAA | I46: ∆ Responsabilidade/ Processo | J46: ∆ MAVALIAA
C47: Factoring | D47: =F19 -> 931 | E47: =H19 -> 1.0599748e+08 | F47: =E37 -> 11174 | H47: =F37 -> 1.0599739e+08 | I47: =F47-D47 -> 10243 | J47: =H47-E47 -> -86.1
C48: Pessoais | D48: =SUM(F24:F26) -> 248175 | E48: =SUM(H24:H26) -> 3.3810922e+10 | F48: =E36+E38 -> 205965 | H48: =F36+F38 -> 2.2339424e+10 | I48: =F48-D48 -> -42210 | J48: =H48-E48 -> -1.1471497e+10
C49: Financeiras | D49: =SUM(F14:F18)+F27 -> 7515 | E49: =SUM(H14:H18)+H27 -> 1.224625e+09 | F49: =SUM(E32) -> 7419 | H49: =SUM(F32) -> 6.7978282e+08 | I49: =F49-D49 -> -96 | J49: =H49-E49 -> -5.4484215e+08
C50: Imóveis | D50: =SUM(F20:F21) -> 365635 | E50: =SUM(H20:H21) -> 5.8242381e+10 | F50: =SUM(E33:E34) -> 400688 | H50: =SUM(F33:F34) -> 5.7540768e+10 | I50: =F50-D50 -> 35053 | J50: =H50-E50 -> -7.016135e+08
C51: Leasing - Imóveis | D51: =F23 -> 5155 | E51: =H23 -> 1.516394e+09 | F51: =E35 -> 4941 | H51: =F35 -> 1.4928783e+09 | I51: =F51-D51 -> -214 | J51: =H51-E51 -> -23515645
C52: Leasing - Pessoais | D52: =F22 -> 21454 | E52: =H22 -> 1.6449139e+09 | F52: =E39 -> 17437 | H52: =F39 -> 1.5863997e+09 | I52: =F52-D52 -> -4017 | J52: =H52-E52 -> -58514159
C53: Total | D53: =SUM(D47:D52) -> 648865 | E53: =SUM(E47:E52) -> 9.6545233e+10 | F53: =SUM(F47:F52) -> 647624 | H53: =SUM(H47:H52) -> 8.374525e+10 | I53: =SUM(I47:I52) -> -1241 | J53: =SUM(J47:J52) -> -1.2799983e+10
B55: Comparação entre o BIYR2500 e o Novo Modelo de Garantias
...

Sheet 1.1.Pessoais
B5: 1.1 Garantias Pessoais
E7: EXECUÇÃO abril | 16-04-2023
B8: Validação Universos | C8: Casuística | E8: Número de registos | Modelo | F8: Mavalia Modelo | G8: Número de registos | biyr (2500) | H8: Mavalia Biyr (2500) | I8: Diferenças | J8: BIYR 9500 | K8: DIFERENÇA (2500-9500)
B10: 1) Universo Comum | C10: Sem diferenças de mavaliaa | E10: 27026 | F10: 1.90134e+09 | G10: 27026 | H10: 1.90134e+09 | I10: 0
C11: Garantias Manuais | E11: 6 | F11: 3.9336433e+08 | G11: 6 | H11: 472000000 | I11: -78635670
C12: Diferenças na metdologia de cálculo das CSs | E12: 144517 | F12: 1.1378349e+10 | G12: 135918 | H12: 1.7428231e+10 | I12: =F12-H12 -> -6.0498812e+09
C13: Diferenças na metdologia de cálculo das GPs | E13: 183894 | F13: 8.3190518e+09 | G13: 165607 | H13: 8.2932246e+09 | I13: 25827205
C14: Duplicados - CSs | E14: 18 | F14: 1037142.2 | G14: 9 | H14: 877638.1 | I14: 159504.09
C15: Saldo da responsabilidade duplicado no Modelo - CSs | E15: 1660 | F15: 1.2970522e+08 | G15: 1660 | H15: 64852610 | I15: 64852610
C16: Em analise | E16: 1 | F16: 26429.25 | G16: 1 | H16: 18472.25 | I16: 7957
B18: 3) Exclusivo BIYR2500 | C18: Titulares excluidos do novo modelo de garantias | G18: 59257 | H18: 5.0825446e+09 | I18: -5.0825446e+09
C19: Não existe bem pessoal CS | G19: 962 | H19: 1.2189169e+08 | I19: -1.2189169e+08
C20: Garantias Manuais - Titulares excluidos do novo modelo de garantias | G20: 7 | H20: 1456901 | I20: -1456901
C21: Garantias Manuais - Não existe caução carregada. Documentação em revisão pela respetiva área | G21: 61 | H21: 193133818 | I21: -193133818
C22: Garantias Manuais - Garantes diferentes nas cauções | G22: 7 | H22: 40000000 | I22: -40000000
C23: Garantias Manuais - atualizar parametrização de garantias manuais
C24: Ex-cliente | G24: 42 | H24: 8182539.8 | I24: -8182539.8
C25: Caução de PPC aplicada a DOs incorretamente | G25: 1 | H25: 12500000 | I25: -12500000
C26: Sem saldo nas carteiras | G26: 9 | H26: 3109256 | I26: -3109256
C27: Empréstimo Partenon | G27: 1134 | H27: 52759041 | I27: -52759041
C28: Empréstimo sem processo formalizado (GP) | G28: 1314 | H28: 1.2458378e+08 | I28: -1.2458378e+08
C29: Duplicados CS eliminados incorretamente do Modelo
C30: Garantes eliminados da clt18
C31: Produtos diferentes de empréstimos com garantes (sem caução) | G31: 108 | H31: 2276054.5 | I31: -2276054.5
C32: Em analise | G32: 29 | H32: 7939808.3 | I32: -7939808.3
B34: 2) Exclusivo Modelo | C34: Garantias Manuais - Garantes diferentes nas cauções | E34: 6 | F34: 20108600 | I34: 20108600
C35: Garantias Manuais - Zdeposit da parametrização BIYR desatualizado | E35: 6 | F35: 62710951 | I35: 62710951
C36: Garantias Manuais - Caução PPC parametrizada por BIYR com relação cancelada | E36: 39 | F36: 54208756 | I36: 54208756
C37: Titulares ainda não excluidos do novo modelo de garantias | E37: 5 | F37: 49840.86 | I37: 49840.86
C38: Biyr exclui cauções com o mesmo produto | E38: 262 | F38: 48516318 | I38: 48516318
C39: Garantias Manuais - Modelo aplica caução diferente da parameterização | E39: 1 | F39: 4526250 | I39: 4526250
C40: Em analise | E40: 1436 | F40: 26429373 | I40: 26429373
C42: Total | E42: 358877 | F42: =SUM(F10:F40) -> 2.2339424e+10 | G42: 393158 | H42: 3.3810922e+10 | I42: -1.1471492e+10
B45: Validação Universos | C45: Casuística | E45: Número de registos | Modelo | F45: Mavalia Modelo | G45: Número de registos | biyr (2500) | H45: Mavalia Biyr (2500) | I45: Diferenças | J45: BIYR 9500 | K45: DIFERENÇA (2500-9500)
B46: 1) Universo Comum | C46: Sem diferenças de mavaliaa | E46: 27026 | F46: 1.90134e+09 | G46: 27026 | H46: 1.90134e+09 | I46: =F46-H46 -> 0 | J46: 1.7721834e+09 | K46: 1.905074e+09 | M46: N/A | N46: N/A
C47: CS - Caução duplicada no Modelo | E47: 18 | F47: 1037142.2 | G47: 9 | H47: 877638.1 | I47: =F47-H47 -> 159504.09 | J47: 877638.1 | K47: 931075.07 | M47: N/A | N47: N/A
C48: CS - Valor da responsabilidade incorreto no Modelo | E48: 1660 | F48: 1.2970522e+08 | G48: 1660 | H48: 64852610 | I48: =F48-H48 -> 64852610 | J48: 64852610 | K48: 1.3295522e+08 | M48: N/A | N48: N/A
C49: Garantias Manuais - Valor da responsabilidade <> valor da cuação / percentagem cobertura 100% | E49: 6 | F49: 3.9336433e+08 | G49: 6 | H49: 472000000 | I49: =F49-H49 -> -78635670 | J49: 472000000 | K49: 3.9336433e+08 | M49: =I49-N49 -> -78635670 | N49: =F49-K49 -> 0
C50: CS - Valor da responsabilidade <> valor da cuação / percentagem cobertura 100% | E50: 108860 | F50: 9.4844154e+09 | G50: 101715 | H50: 1.4999949e+10 | I50: =F50-H50 -> -5.5155339e+09 | J50: 1.5196769e+10 | K50: 9.4844154e+09 | M50: =I50-N50 -> -5.5155339e+09 | N50: =F50-K50 -> 0
C51: CS - Valor da responsabilidade <> valor da cuação / percentagem cobertura diferente de 100% (campo da % coerente no Biyr e no modelo) | E51: 10465 | F51: 8.0455314e+08 | G51: 9969 | H51: 1.2346095e+09 | I51: =F51-H51 -> -4.3005635e+08 | J51: 1.2346095e+09 | K51: 1.2154199e+09 | M51: =I51-N51 -> -19189556 | N51: =F51-K51 -> -4.1086679e+08
...

Sheet 1.2.Imóveis
B5: 1.2 Garantias Imóveis
B7: val_universos | C7: origem | D7: num_reg_total | F7: num_reg_biyr | G7: total_biyr2500_mavaliaa | H7: total_modelo_mavaliaa | I7: dif_mavaliaa
B8: COMUM | C8: CS | D8: 855 | F8: 761 | G8: 4.7578658e+09 | H8: 4.3967462e+09 | I8: -3.6111962e+08
B9: COMUM | C9: GP | D9: 399722 | F9: 363631 | G9: 5.3175168e+10 | H9: 5.3143386e+10 | I9: -31781337
B10: EXCL_BIYR | C10: CS | D10: 758 | F10: 758 | G10: 2.5566917e+08
B11: EXCL_BIYR | C11: GP | D11: 485 | F11: 485 | G11: 53678519
B12: EXCL_MODELO | C12: CS | D12: 111 | F12: 1 | H12: 635144.6
B13: EXCL_MODELO | C13: GP | D13: 0 | F13: 0 | H13: 0
F15: EXECUÇÃO abril | 16-04-2023
B16: Validação Universos | C16: Origem/Casuística | F16: Número de registos | Modelo | G16: Número de registos | biyr | H16: Mavalia Modelo | I16: Mavalia Biyr | J16: Diferenças
C18: CS | F18: =D8 -> 855 | G18: =F8 -> 761 | H18: =H8 -> 4.3967462e+09 | I18: =G8 -> 4.7578658e+09 | J18: =I8 -> -3.6111962e+08
C19: Sem diferenças de mavaliaa | F19: 557 | G19: 490 | H19: 3.1732958e+09 | I19: 3.1732958e+09 | J19: =H19-I19 -> 0
C20: Diferenças de rateio | F20: 82 | G20: 75 | H20: 688478056 | I20: 688478056 | J20: =H20-I20 -> 0
C21: Outros Fomentos à Construção | F21: 11 | G21: 10 | H21: 29360905 | I21: 1.8991125e+08 | J21: =H21-I21 -> -1.6055035e+08
C22: Processo de rateio incorreto no BIYR | F22: 54 | G22: 48 | H22: 67921882 | I22: 263590047 | J22: =H22-I22 -> -1.9566817e+08
C23: Percentagem da CST05 ao invés do rateio por responsabilidade | F23: 130 | G23: 118 | H23: 58585567 | I23: 50515870 | J23: =H23-I23 -> 8069697.1
C24: Valor de avaliação mais recente a zero no modelo | F24: 7 | G24: 7 | H24: 0 | I24: 13020419 | J24: =H24-I24 -> -13020419
C25: Erro no cálculo do mavaliaa do lado do modelo | F25: 9 | G25: 9 | H25: 3.7882e+08 | I25: 378820000 | J25: =H25-I25 -> 0.0099999905
B26: 1) Universo Comum | C26: Em análise | F26: =F18-SUM(F19:F25) -> 5 | G26: =G18-SUM(G19:G25) -> 4 | H26: =H18-SUM(H19:H25) -> 283924.15 | I26: =I18-SUM(I19:I25) -> 234311.04 | J26: =J18-SUM(J19:J25) -> 49613.11
C27: GP | F27: =D9 -> 399722 | G27: =F9 -> 363631 | H27: =H9 -> 5.3143386e+10 | I27: =G9 -> 5.3175168e+10 | J27: =I9 -> -31781337
B28: 1) Universo Comum | C28: Sem diferenças de mavaliaa | F28: 246910 | G28: 228862 | H28: 4.0515735e+10 | I28: 4.0515735e+10 | J28: =H28-I28 -> 0
C29: Diferenças de rateio | F29: =SUM(F77:F78) -> 129582 | G29: =SUM(G77:G78) -> 120178 | H29: =SUM(H77:H78) -> 10487467287 | I29: =SUM(I77:I78) -> 1.0487512e+10 | J29: =H29-I29 -> -44873.47
C30: Diferenças de rateio + Erro no cálculo do mavaliaa do lado do modelo | F30: 22743 | G30: 14209 | H30: 1.122253e+09 | I30: 1.122253e+09 | J30: =H30-I30 -> 0.11000013
C31: Erro no cálculo do mavaliaa do lado do modelo | F31: 0 | G31: 0 | H31: 0 | I31: 0 | J31: =H31-I31 -> 0
C32: IFRRU | F32: 242 | G32: 183 | H32: 4.0288241e+08 | I32: 3.4565146e+08 | J32: =H32-I32 -> 57230945
C33: Mapeamento de avaliações por processo e não bem do lado do biyr | F33: =SUM(F80:F81) -> 87 | G33: =SUM(G80:G81) -> 70 | H33: =SUM(H80:H81) -> 11376030 | I33: =SUM(I80:I81) -> 10055039 | J33: =H33-I33 -> 1320991.4
C34: Processo de rateio incorreto no BIYR | F34: 83 | G34: 71 | H34: 4.3399278e+08 | I34: 5.2134009e+08 | J34: =H34-I34 -> -87347311
C35: Valor de avaliação mais recente a zero no modelo | F35: 45 | G35: 38 | H35: 1.5019964e+08 | I35: 1.5333468e+08 | J35: =H35-I35 -> -3135042
C36: Bem IFRRU associado a um segundo empréstimo | F36: 8 | G36: 7 | H36: 11568788 | I36: 11576446 | J36: =H36-I36 -> -7658.28
C37: Rateio realizado por contratos exclusivos do BIYR | F37: 12 | G37: 5 | H37: 5877228.5 | I37: 5253843.9 | J37: =H37-I37 -> 623384.59
B38: 1) Universo Comum | C38: Em análise | F38: =F27-SUM(F28:F37) -> 10 | G38: =G27-SUM(G28:G37) -> 8 | H38: =H27-SUM(H28:H37) -> 2034051.1 | I38: =I27-SUM(I28:I37) -> 2455824.4 | J38: =H38-I38 -> -421773.24
B40: 2) Exclusivo Modelo | C40: CS | F40: =D12 -> 111 | G40: =F12 -> 1 | H40: =H12 -> 635144.6 | J40: =H40-I40 -> 635144.6
B41: 2) Exclusivo Modelo | C41: Em análise | F41: 111 | G41: 1 | H41: 635144.6 | J41: =H41-I41 -> 635144.6
B43: 3) Exclusivo BIYR2500 | C43: CS | F43: =D10 -> 758 | G43: =F10 -> 758 | I43: =G10 -> 2.5566917e+08 | J43: =H43-I43 -> -2.5566917e+08
B44: 3) Exclusivo BIYR2500 | C44: Processos sem bens associados | F44: 562 | G44: 562 | I44: 1.4882485e+08 | J44: =H44-I44 -> -1.4882485e+08
C45: Bens CS com datas de avaliação inválidas | F45: =SUM(F68:F71) -> 194 | G45: =SUM(G68:G71) -> 194 | I45: =SUM(I68:I71) -> 62277314 | J45: =H45-I45 -> -62277314
C46: Inclusão de avaliações sobre processos não formalizados | F46: 2 | G46: 2 | I46: 44567000 | J46: =H46-I46 -> -44567000
C47: Em análise | F47: =F43-SUM(F44:F46) -> 0 | G47: =G43-SUM(G44:G46) -> 0 | I47: =I43-SUM(I44:I46) -> 0 | J47: =H47-I47 -> 0
B48: 3) Exclusivo BIYR2500 | C48: GP | F48: =D11 -> 485 | G48: =F11 -> 485 | I48: =G11 -> 53678519 | J48: =H48-I48 -> -53678519
C49: Processos sem bens associados | F49: =SUM(F73:F75) -> 353 | G49: =SUM(G73:G75) -> 353 | I49: =SUM(I73:I75) -> 31156631 | J49: =H49-I49 -> -31156631
...

Sheet 1.3.Financeiras
B5: 1.3 Garantias Financeiras
E7: EXECUÇÃO abril | 16-04-2023
B8: Validação Universos | C8: Casuística | E8: Número de registos | Modelo | F8: Mavalia Modelo | G8: Número de registos | biyr (2500) | H8: Mavalia Biyr (2500) | I8: Diferenças
B10: 1) Universo Comum | C10: Sem diferenças de mavaliaa | E10: 4235 | F10: 3.5247266e+08 | G10: 4115 | H10: 3.5247266e+08 | I10: 0
C11: Diferenças de repartição | E11: 58 | F11: 3428802.3 | G11: 51 | H11: 3428802.3 | I11: 0
C12: Garantias de outras tipologias
C13: Diferença de saldo - cativo de D+1 | E13: 2894 | F13: 3.0034966e+08 | G13: 2768 | H13: 3.0085939e+08 | I13: -509730.38
C14: Diferença de saldo - cativo de D+1/ Fx Rate
C15: Diferença de saldo - cativo de D+1/ Fx Rate/ Percentagem repartição
C16: Em análise | E16: 205 | F16: 22601119 | G16: 183 | H16: 20173285 | I16: 2427834.4
B18: 3) Exclusivo BIYR2500 | C18: Não existe bem associado | G18: 370 | H18: 5.4650689e+08 | I18: -5.4650689e+08
C19: Data de Cativo vencida | G19: 26 | H19: 1180615.1 | I19: -1180615.1
C20: Em analise | G20: 2 | H20: 3333.3 | I20: -3333.3
B22: 2) Exclusivo Modelo | C22: Em analise | E22: 27 | F22: 930585.01 | I22: 1232874.8
C24: Total | E24: 7419 | F24: 6.7978282e+08 | G24: 7515 | H24: 1.224625e+09 | I24: -5.4484215e+08

Sheet 1.4.Imóveis - LEA
B5: 1.4 Garantias Imóveis - LEA
B7: val_universos | C7: origem | D7: num_reg_total | F7: total_biyr2500_mavaliaa | G7: total_modelo_mavaliaa | H7: dif_mavaliaa
B8: COMUM | C8: LEA | D8: 4941 | F8: 1.4915268e+09 | G8: 1.4928783e+09 | H8: 1351495.8
B9: EXCL_BIYR | C9: LEA | D9: 214 | F9: 24867141 | G9: NULL | H9: NULL
B10: EXCL_MODELO | C10: LEA | D10: 0 | G10: 0
F12: EXECUÇÃO abril | 16-04-2023
B13: Validação Universos | C13: Origem/Casuística | F13: Número de registos (chave_cruzamento) | G13: Mavalia Modelo | H13: Mavalia Biyr | I13: Diferenças
B15: 1) Universo Comum | C15: Total | F15: =D8 -> 4941 | G15: =G8 -> 1.4928783e+09 | H15: =F8 -> 1.4915268e+09 | I15: =H8 -> 1351495.8
B16: 1) Universo Comum | C16: Sem diferenças de mavaliaa | F16: 4926 | G16: 1.4907692e+09 | H16: 1.4907692e+09 | I16: 0
C17: Em análise | F17: =F15-SUM(F16:F16) -> 15 | G17: =G15-SUM(G16:G16) -> 2109095.8 | H17: =H15-SUM(H16:H16) -> 757600 | I17: =G17-H17 -> 1351495.8
B19: 2) Exclusivo Modelo | C19: Total | F19: =D10 -> 0 | G19: =G10 -> 0
C20: Em análise | F20: =F19 -> 0 | G20: =G19 -> 0
B22: 3) Exclusivo BIYR2500 | C22: Total | F22: =D9 -> 214 | H22: =F9 -> 24867141 | I22: =G22-H22 -> -24867141
C23: Datas de vencimento inferiores à data de rácio | F23: 0 | H23: 0 | I23: =G23-H23 -> 0
C24: Universo não existente na CL001 | F24: 0 | H24: 0 | I24: =G24-H24 -> 0
C25: Bens LEA sem chave GP associada na LGT03 | F25: 190 | H25: 22705006 | I25: =G25-H25 -> -22705006
C26: CGARANT = 502 - Garantias financeiras excluidas do modelo | F26: 24 | H26: 2162135.1 | I26: =G26-H26 -> -2162135.1
C27: Em análise | F27: =F22-SUM(F23:F26) -> 0 | H27: =H22-SUM(H23:H26) -> 0 | I27: =G27-H27 -> 0
D29: Total | F29: =F15+F19+F22 -> 5155 | G29: =G15+G19+G22 -> 1.4928783e+09 | H29: =H15+H19+H22 -> 1.516394e+09 | I29: =I15+I19+I22 -> -23515645
B31: Legenda
B32: Diferenças de metodologia
B33: Correções concluídas
B34: Em resolução - requisitos definidos e planificados
B35: Em resolução - definição de requisitos em curso
B36: Em análise

Sheet 1.5.Pessoais - LEA
B5: 1.5 Garantias Pessoais- LEA
E7: EXECUÇÃO abril | 16-04-2023
B8: Validação Universos | C8: Casuística | E8: Número de registos | Modelo | F8: Mavalia Modelo | G8: Número de registos | biyr (2500) | H8: Mavalia Biyr (2500) | I8: Diferenças
B10: 1) Universo Comum | C10: Sem diferenças de mavaliaa | E10: 2352 | F10: 17384623 | G10: 2352 | H10: 17384623 | I10: 0
C11: Contas de juros,comissoes | E11: 29796 | F11: 1.4135821e+09 | G11: 29796 | H11: 1.4099095e+09 | I11: 3672643.3
C12: Contas de juros,comissoes e capital(28) | E12: 62 | F12: 10480063 | G12: 62 | H12: 5404960.4 | I12: 5075102.4
C13: Contas em analise | E13: 1282 | F13: 1.4495291e+08 | G13: 1282 | H13: 1.2006287e+08 | I13: 24890040
B15: 3) Exclusivo BIYR2500 | C15: Titulares excluidos do novo modelo de garantias | G15: 4165 | H15: 83862122 | I15: -83862122
C16: Ex - cliente | G16: 184 | H16: 8262922.5 | I16: -8262922.5
C17: A operação não existe no Biyr1500 (Leasing) | G17: 32 | H17: 900.12 | I17: -900.12
C18: Em analise | G18: 1 | H18: 26000 | I18: -26000
B20: 2) Exclusivo Modelo | C20: Em analise
C22: Total | E22: =SUM(E10:E20) -> 33492 | F22: =SUM(F10:F20) -> 1.5863997e+09 | G22: =SUM(G10:G20) -> 37874 | H22: =SUM(H10:H20) -> 1.6449139e+09 | I22: =SUM(I10:I20) -> -58514159
B25: Legenda
B26: Diferenças de metodologia
B27: Correções concluídas
B28: Em resolução - requisitos definidos e planificados
B29: Em resolução - definição de requisitos em curso
B30: Em análise

Sheet 1.6.Factoring
B5: 1.6 Factoring
E7: EXECUÇÃO abril | 16-04-2023
B8: Validação Universos | C8: Casuística | E8: Número de registos | Modelo | F8: Mavalia Modelo | G8: Número de registos | biyr (2500) | H8: Mavalia Biyr (2500) | I8: Diferenças | K8: BIYR 9500 | L8: DIFERENÇA BIYRs
B10: 1) Universo Comum | C10: Sem diferenças de mavaliaa | E10: 11158 | F10: 1.0598608e+08 | G10: 603 | H10: 1.0598608e+08 | I10: 0
C11: Em analise | E11: 16 | F11: 11311.21 | G11: 1 | H11: 11397.31 | I11: -86.1
B13: 3) Exclusivo BIYR2500 | C13: Faturas sem saldo | G13: 327 | H13: 0 | I13: 0
B15: 2) Exclusivo Modelo | C15: Em analise
C17: Total | E17: 11174 | F17: 1.0599739e+08 | G17: 931 | H17: 1.0599748e+08 | I17: -86.1
B21: Legenda
B22: Diferenças de metodologia
B23: Correções concluídas
B24: Em resolução - requisitos definidos e planificados
B25: Em resolução - definição de requisitos em curso
B26: Em análise

Sheet Dados Fevereiro | 16-04-23
B5: 1. Análises Universos
C7: Data de referência | D7: 44985
C8: Data de atualização | D8: 45032
B11: Universo BIYR 2500 | J11: Universo BIYR9500
C13: tipo | D13: biyr2500_caplic | E13: biyr2500_tipgargblbg | F13: num_resp_proc | H13: biyr2500_mavaliaa
C14: F | D14: DC | E14: 2 | F14: 2224 | H14: 1.0529615e+08 | J14: 2224 | K14: 1.0529615e+08 | M14: 0 | N14: 0
C15: F | D15: DP | E15: 2 | F15: 2023 | H15: 2.0259703e+08 | J15: 2023 | K15: 2.0259703e+08 | M15: 0 | N15: 0
C16: F | D16: FU | E16: 2 | F16: 1970 | H16: 2.2536119e+08 | J16: 1970 | K16: 2.2536119e+08 | M16: 0 | N16: 0
C17: F | D17: SG | E17: 2 | F17: 1158 | H17: 91656003 | J17: 1158 | K17: 91656003 | M17: 0 | N17: 0
C18: F | D18: TT | E18: 2 | F18: 59 | H18: 59255534 | J18: 59 | K18: 59255534 | M18: 0 | N18: 0
C19: FAC | D19: FAC | E19: 1 | F19: 908 | H19: 89756471 | J19: 908 | K19: 89756471 | M19: 0 | N19: 0
C20: I | D20: CS | E20: 2 | F20: 1544 | H20: 4.1835912e+09 | J20: 1544 | K20: 4.1835912e+09 | M20: 0 | N20: 0
C21: I | D21: GP | E21: 2 | F21: 367686 | H21: 5.3741241e+10 | J21: 367686 | K21: 5.3741241e+10 | M21: 0 | N21: 0
C22: LEA | D22: LEA | E22: 1 | F22: 21585 | H22: 1.6709264e+09 | J22: 21585 | K22: 1.6709264e+09 | M22: 0 | N22: 0
C23: LEA | D23: LEA | E23: 2 | F23: 5224 | H23: 1.5279433e+09 | J23: 5224 | K23: 1.5279433e+09 | M23: 0 | N23: 0
C24: P | D24: CLI | E24: 1 | F24: 92235 | H24: 8.8539723e+09 | J24: 92235 | K24: 8.8539723e+09 | M24: 0 | N24: 0
C25: P | D25: CS | E25: 1 | F25: 36189 | H25: 4.3536762e+09 | J25: 36189 | K25: 4.3237217e+09 | M25: 0 | N25: -29954520
... C27: TBD | D27: CS | E27: 2 | F27: 394 | H27: 5.3971342e+08 | J27: 394 | K27: 5.3971342e+08 | M27: 0 | N27: 0
B29: Universo Modelo
C31: tipo | D31: origem | E31: num_resp_proc | F31: mavaliaa | H31: Variação face à execução anterior
C32: F | D32: CS | E32: 7797 | F32: 6.8900011e+08 | H32: -128 | I32: -23263880
C33: I | D33: CS | E33: 997 | F33: 3.6578362e+09 | H33: -6 | I33: 32819882
C34: I | D34: GP | E34: 403837 | F34: 5.3632896e+10 | H34: -572 | I34: -1.9325523e+08
C35: I | D35: LEA | E35: 5005 | F35: 1.5038247e+09 | H35: -36 | I35: -25110208
C36: P | D36: CS | E36: 109155 | F36: 1.407208e+10 | H36: -57 | I36: -98348613
C37: P | D37: FAC | E37: 9041 | F37: 89757971 | H37: 567 | I37: 10499982
C38: P | D38: GP | E38: 100557 | F38: 8.6836283e+09 | H38: -378 | I38: -1.0063296e+08
C39: P | D39: LEA | E39: 17463 | F39: 1.5890088e+09 | H39: -38 | I39: 1.4284615e+09
E40: 653852
C43: Valores originais
D45: BIYR9500 | F45: Novo Modelo de Garantias
C46: Tipo | D46: # Responsabilidade/ Processo | E46: MAVALIAA | F46: # Responsabilidade/ Processo | H46: MAVALIAA | I46: ∆ Responsabilidade/ Processo | J46: ∆ MAVALIAA
C47: Factoring | D47: 908 | E47: 89756471 | F47: 9041 | H47: 89757971 | I47: 8133 | J47: 1500
C48: Pessoais | D48: 253562 | E48: 3.5128683e+10 | F48: 209712 | H48: 2.2755708e+10 | I48: -43850 | J48: -1.2372974e+10
C49: Financeiras | D49: 7828 | E49: 1.2238793e+09 | F49: 7797 | H49: 6.8900011e+08 | I49: -31 | J49: -5.3487922e+08
C50: Imóveis | D50: 369230 | E50: 5.7924832e+10 | F50: 404834 | H50: 5.7290732e+10 | I50: 35604 | J50: -6.3410014e+08
C51: Leasing - Imóveis | D51: 5224 | E51: 1.5279433e+09 | F51: 5005 | H51: 1.5038247e+09 | I51: -219 | J51: -24118645
C52: Leasing - Pessoais | D52: 21585 | E52: 1.6709264e+09 | F52: 17463 | H52: 1.5890088e+09 | I52: -4122 | J52: -81917646
C53: Total | D53: 658337 | E53: 9.756602e+10 | F53: 653852 | H53: 8.3918032e+10 | I53: -4485 | J53: -1.3647988e+10
C55: Para Steering
...
