Workbook

Sheet 0. Instruções
B6: 0. Instruções
B8: Projeto | D8: Testes GD & Pilar 3
B9: Âmbito | D9: Análise dos campo da Loan Tape Pilar III
B11: Para a validação dos campos da Loan Tape Pilar III é necessário percorrer os seguintes steps:
B14: 1. Atualizar o script de simulação com o campo em análise.
B15: 1.1. Verificar a especificação do campo em análise. Se aplicável, verificar se é necessário reportar valor para ajustes.
B16: 1.2. Montar a simulação do campo tendo atenção aos seguintes pormenores:
B17: a) Não vamos fazer JOIN com a tabela de parametrização (LT803). Em alternativa, montamos um CASE WHEN ou importamos a parametrização.
B18: b) Para operações de ajustes verificar se o campo deve reportar valor.
B19: c) Se for necessário aplicar algum filtro (ou tratamento) que não está na especificação deixar um comentário no código.
B20: d) Garantir que não existem duplicados e deixar no código o número de registos de cada LEFT JOIN.
B21: 2. Executar no HUE (em HIVE) o CREATE TABLE do script de simulação.
B22: 3. Executar no HUE o script de controlo de universo.
B23: a) O número de registos em comum tem de ser igual ao número de registos do teste de coerência. Caso tenhamos registos que não são comuns é necessário ver exemplos para ver o que está a acontecer.
B24: 4. Verificar com IT o nome da tabela a testar e filtros. Caso seja necessário, atualizar as tabelas infra:
C26: Nome da Tabela | D26: Tabela Loan Tape Pilar 3 | E26: Tabela Simulada | F26: Chave 1 | G26: Chave 2
C27: Entity | D27: lt003_entity | E27: lt003_entity | F27: entty_id
C28: Instrument | D28: lt002_instrument | E28: lt002_instrument | F28: instrmnt_id
C29: Protection | D29: lt004_protection | E29: lt004_protection | F29: prtctn_id
C30: INSTR_ENTITY | D30: lt005_instr_ent | E30: lt005_instr_ent | F30: instrmnt_id | G30: entty_id
C31: INSTR_PROTECTION | D31: lt006_instr_prot | E31: lt006_instr_prot | F31: instrmnt_id | G31: prtctn_id
C32: Instr_activity | D32: lt007_instr_activity | E32: lt007_instr_activity | F32: instrmnt_id
C34: Filtros
C35: Schema Loan Tape Pilar 3 | D35: cd_loan_tapes_bce
C36: Schema Simulada | D36: bu_loantape_work
C37: nome_perimetro | D37: Individual Corporativo
C38: segmento | D38: ESTR
C39: ambito (Pilar 3) | D39: PM
C40: ambito (PM) | D40: PM
C41: entidade | D41: 00100
C42: Filtro Loan Tape Pilar 3 | D42: =+"ref_date='${ref_date}'"&" AND "&C37&"='"&D37&"' AND "&C38&"='"&D38&"' AND ambito='"&D39&"'"&" AND "&C41&"='"&D41&"'" -> ref_date='${ref_date}' AND nome_perimetro='Individual Corporativo' AND segmento='ESTR' AND ambito='PM' AND entidade='00100'
C43: Filtro Simulada | D43: =+"ref_date='${ref_date}'"&" AND "&C37&"='"&D37&"' AND "&C38&"='"&D38&"' AND ambito='"&D39&"'"&" AND "&C41&"='"&D41&"'" -> ref_date='${ref_date}' AND nome_perimetro='Individual Corporativo' AND segmento='ESTR' AND ambito='PM' AND entidade='00100'
B45: 5. Executar no HUE a bateria de testes da sheet 2. Script para o campo em análise
B46: a) Analisar resultados. Caso no teste de coerência conste diferenças é necessário ver exemplos. Deixo abaixo uma query de exemplo:
C48: SELECT *
C49: FROM
C50: (SELECT instrmnt_id,
C51: LNS_CLLTRLZD_CLSSFCTN
C52: FROM BU_LOANTAPE_WORK.LT002_INSTRUMENT
C53: WHERE ref_date='${ref_date}'
...

Sheet 1. Status
L2: Instr_activity
H6: 1. Status dos Testes
H8: REF_DATE | I8: 45596
B9: Auxiliar
B10: Coerência | C10: Validade | D10: Caracteres Especiais | E10: Missings | F10: Not applicable | H10: Tabela | I10: Campo | J10: Testes Corridos (#) | K10: Número de Registos ID1. (#) | L10: ID Exec. 1. | M10: 1. Erros de Coerência (#) | N10: Número de Registos ID2&9 (#) | O10: ID Exec. 2 | P10: 2. Erros de Valores Admitidos (#) | Q10: ID Exec. 3. | R10: 3. Erros de Caract. Especiais (#) | S10: ID Exec. 4. | T10: 4. Registos com Missing (#) | U10: ID Exec. 5. | V10: 5. Registos com N/A (#) | W10: 6. Valor Mínimo | X10: 7. Valor Máximo | Y10: Comentário | Z10: Status
A11: =+H11&I11&$I$8 -> ENTITYCOD_SOC45596 | H11: ENTITY | I11: COD_SOC | J11: =+COUNTIF('ID1&5'!G:G,'1. Status'!I11) -> 0 | K11: =+IFERROR(VLOOKUP(CONCATENATE(A11,$B$10,B11),'ID1&5'!B:J,8,FALSE),"-") -> - | L11: =+IFERROR(VLOOKUP(B11,'ID1&5'!K:L,2,FALSE),"-") -> - | M11: =+IFERROR(VLOOKUP(CONCATENATE(A11,$B$10,B11),'ID1&5'!B:J,9,FALSE),"-") -> - | N11: =+IFERROR(VLOOKUP(CONCATENATE(A11,$C$10,C11),'ID1&5'!B:J,8,FALSE),"-") -> - | O11: =+IFERROR(VLOOKUP(C11,'ID1&5'!K:L,2,FALSE),"-") -> - | P11: =+IFERROR(VLOOKUP(CONCATENATE(A11,$C$10,C11),'ID1&5'!B:J,9,FALSE),"-") -> - | Q11: =+IFERROR(VLOOKUP(D11,'ID1&5'!K:L,2,FALSE),"-") -> - | R11: =+IFERROR(VLOOKUP(CONCATENATE(A11,$D$10,D11),'ID1&5'!B:J,9,FALSE),"-") -> - | S11: =+IFERROR(VLOOKUP(E11,'ID1&5'!K:L,2,FALSE),"-") -> - | T11: =+IFERROR(VLOOKUP(CONCATENATE(A11,$E$10,E11),'ID1&5'!B:J,9,FALSE),"-") -> - | U11: =+IFERROR(VLOOKUP(F11,'ID1&5'!K:L,2,FALSE),"-") -> - | V11: =+IFERROR(VLOOKUP(CONCATENATE(A11,$F$10,F11),'ID1&5'!B:J,9,FALSE),"-") -> - | W11: =+IFERROR(VLOOKUP(A11,'ID6&7'!A:I,9,FALSE),"-") -> - | X11: =+IFERROR(VLOOKUP(A11,'ID6&7'!A:J,10,FALSE),"-") -> - | Z11: =+IF(J11=0,"Por iniciar",IF(OR(K11="-",M11="-",P11="-",R11="-",T11="-",V11="-"),"Em testes",IF(AND(M11=0,P11=0,R11=0,T11<>K11,V11<>K11),"OK","NOK"))) -> Por iniciar
A12: =+H12&I12&$I$8 -> ENTITYCNTRY45596 | H12: ENTITY | I12: CNTRY | J12: =+COUNTIF('ID1&5'!G:G,'1. Status'!I12) -> 0 | K12: =+IFERROR(VLOOKUP(CONCATENATE(A12,$B$10,B12),'ID1&5'!B:J,8,FALSE),"-") -> - | L12: =+IFERROR(VLOOKUP(B12,'ID1&5'!K:L,2,FALSE),"-") -> - | M12: =+IFERROR(VLOOKUP(CONCATENATE(A12,$B$10,B12),'ID1&5'!B:J,9,FALSE),"-") -> - | N12: =+IFERROR(VLOOKUP(CONCATENATE(A12,$C$10,C12),'ID1&5'!B:J,8,FALSE),"-") -> - | O12: =+IFERROR(VLOOKUP(C12,'ID1&5'!K:L,2,FALSE),"-") -> - | P12: =+IFERROR(VLOOKUP(CONCATENATE(A12,$C$10,C12),'ID1&5'!B:J,9,FALSE),"-") -> - | Q12: =+IFERROR(VLOOKUP(D12,'ID1&5'!K:L,2,FALSE),"-") -> - | R12: =+IFERROR(VLOOKUP(CONCATENATE(A12,$D$10,D12),'ID1&5'!B:J,9,FALSE),"-") -> - | S12: =+IFERROR(VLOOKUP(E12,'ID1&5'!K:L,2,FALSE),"-") -> - | T12: =+IFERROR(VLOOKUP(CONCATENATE(A12,$E$10,E12),'ID1&5'!B:J,9,FALSE),"-") -> - | U12: =+IFERROR(VLOOKUP(F12,'ID1&5'!K:L,2,FALSE),"-") -> - | V12: =+IFERROR(VLOOKUP(CONCATENATE(A12,$F$10,F12),'ID1&5'!B:J,9,FALSE),"-") -> - | W12: =+IFERROR(VLOOKUP(A12,'ID6&7'!A:I,9,FALSE),"-") -> - | X12: =+IFERROR(VLOOKUP(A12,'ID6&7'!A:J,10,FALSE),"-") -> - | Z12: =+IF(J12=0,"Por iniciar",IF(OR(K12="-",M12="-",P12="-",R12="-",T12="-",V12="-"),"Em testes",IF(AND(M12=0,P12=0,R12=0,T12<>K12,V12<>K12),"OK","NOK"))) -> Por iniciar
A13: =+H13&I13&$I$8 -> ENTITYDT_BRTH45596 | H13: ENTITY | I13: DT_BRTH | J13: =+COUNTIF('ID1&5'!G:G,'1. Status'!I13) -> 0 | K13: =+IFERROR(VLOOKUP(CONCATENATE(A13,$B$10,B13),'ID1&5'!B:J,8,FALSE),"-") -> - | L13: =+IFERROR(VLOOKUP(B13,'ID1&5'!K:L,2,FALSE),"-") -> - | M13: =+IFERROR(VLOOKUP(CONCATENATE(A13,$B$10,B13),'ID1&5'!B:J,9,FALSE),"-") -> - | N13: =+IFERROR(VLOOKUP(CONCATENATE(A13,$C$10,C13),'ID1&5'!B:J,8,FALSE),"-") -> - | O13: =+IFERROR(VLOOKUP(C13,'ID1&5'!K:L,2,FALSE),"-") -> - | P13: =+IFERROR(VLOOKUP(CONCATENATE(A13,$C$10,C13),'ID1&5'!B:J,9,FALSE),"-") -> - | Q13: =+IFERROR(VLOOKUP(D13,'ID1&5'!K:L,2,FALSE),"-") -> - | R13: =+IFERROR(VLOOKUP(CONCATENATE(A13,$D$10,D13),'ID1&5'!B:J,9,FALSE),"-") -> - | S13: =+IFERROR(VLOOKUP(E13,'ID1&5'!K:L,2,FALSE),"-") -> - | T13: =+IFERROR(VLOOKUP(CONCATENATE(A13,$E$10,E13),'ID1&5'!B:J,9,FALSE),"-") -> - | U13: =+IFERROR(VLOOKUP(F13,'ID1&5'!K:L,2,FALSE),"-") -> - | V13: =+IFERROR(VLOOKUP(CONCATENATE(A13,$F$10,F13),'ID1&5'!B:J,9,FALSE),"-") -> - | W13: =+IFERROR(VLOOKUP(A13,'ID6&7'!A:I,9,FALSE),"-") -> - | X13: =+IFERROR(VLOOKUP(A13,'ID6&7'!A:J,10,FALSE),"-") -> - | Z13: =+IF(J13=0,"Por iniciar",IF(OR(K13="-",M13="-",P13="-",R13="-",T13="-",V13="-"),"Em testes",IF(AND(M13=0,P13=0,R13=0,T13<>K13,V13<>K13),"OK","NOK"))) -> Por iniciar
A14: =+H14&I14&$I$8 -> ENTITYDT_DFLT_STTS45596 | H14: ENTITY | I14: DT_DFLT_STTS | J14: =+COUNTIF('ID1&5'!G:G,'1. Status'!I14) -> 0 | K14: =+IFERROR(VLOOKUP(CONCATENATE(A14,$B$10,B14),'ID1&5'!B:J,8,FALSE),"-") -> - | L14: =+IFERROR(VLOOKUP(B14,'ID1&5'!K:L,2,FALSE),"-") -> - | M14: =+IFERROR(VLOOKUP(CONCATENATE(A14,$B$10,B14),'ID1&5'!B:J,9,FALSE),"-") -> - | N14: =+IFERROR(VLOOKUP(CONCATENATE(A14,$C$10,C14),'ID1&5'!B:J,8,FALSE),"-") -> - | O14: =+IFERROR(VLOOKUP(C14,'ID1&5'!K:L,2,FALSE),"-") -> - | P14: =+IFERROR(VLOOKUP(CONCATENATE(A14,$C$10,C14),'ID1&5'!B:J,9,FALSE),"-") -> - | Q14: =+IFERROR(VLOOKUP(D14,'ID1&5'!K:L,2,FALSE),"-") -> - | R14: =+IFERROR(VLOOKUP(CONCATENATE(A14,$D$10,D14),'ID1&5'!B:J,9,FALSE),"-") -> - | S14: =+IFERROR(VLOOKUP(E14,'ID1&5'!K:L,2,FALSE),"-") -> - | T14: =+IFERROR(VLOOKUP(CONCATENATE(A14,$E$10,E14),'ID1&5'!B:J,9,FALSE),"-") -> - | U14: =+IFERROR(VLOOKUP(F14,'ID1&5'!K:L,2,FALSE),"-") -> - | V14: =+IFERROR(VLOOKUP(CONCATENATE(A14,$F$10,F14),'ID1&5'!B:J,9,FALSE),"-") -> - | W14: =+IFERROR(VLOOKUP(A14,'ID6&7'!A:I,9,FALSE),"-") -> - | X14: =+IFERROR(VLOOKUP(A14,'ID6&7'!A:J,10,FALSE),"-") -> - | Z14: =+IF(J14=0,"Por iniciar",IF(OR(K14="-",M14="-",P14="-",R14="-",T14="-",V14="-"),"Em testes",IF(AND(M14=0,P14=0,R14=0,T14<>K14,V14<>K14),"OK","NOK"))) -> Por iniciar
A15: =+H15&I15&$I$8 -> ENTITYDT_FNNCL_STTMTS45596 | H15: ENTITY | I15: DT_FNNCL_STTMTS | J15: =+COUNTIF('ID1&5'!G:G,'1. Status'!I15) -> 0 | K15: =+IFERROR(VLOOKUP(CONCATENATE(A15,$B$10,B15),'ID1&5'!B:J,8,FALSE),"-") -> - | L15: =+IFERROR(VLOOKUP(B15,'ID1&5'!K:L,2,FALSE),"-") -> - | M15: =+IFERROR(VLOOKUP(CONCATENATE(A15,$B$10,B15),'ID1&5'!B:J,9,FALSE),"-") -> - | N15: =+IFERROR(VLOOKUP(CONCATENATE(A15,$C$10,C15),'ID1&5'!B:J,8,FALSE),"-") -> - | O15: =+IFERROR(VLOOKUP(C15,'ID1&5'!K:L,2,FALSE),"-") -> - | P15: =+IFERROR(VLOOKUP(CONCATENATE(A15,$C$10,C15),'ID1&5'!B:J,9,FALSE),"-") -> - | Q15: =+IFERROR(VLOOKUP(D15,'ID1&5'!K:L,2,FALSE),"-") -> - | R15: =+IFERROR(VLOOKUP(CONCATENATE(A15,$D$10,D15),'ID1&5'!B:J,9,FALSE),"-") -> - | S15: =+IFERROR(VLOOKUP(E15,'ID1&5'!K:L,2,FALSE),"-") -> - | T15: =+IFERROR(VLOOKUP(CONCATENATE(A15,$E$10,E15),'ID1&5'!B:J,9,FALSE),"-") -> - | U15: =+IFERROR(VLOOKUP(F15,'ID1&5'!K:L,2,FALSE),"-") -> - | V15: =+IFERROR(VLOOKUP(CONCATENATE(A15,$F$10,F15),'ID1&5'!B:J,9,FALSE),"-") -> - | W15: =+IFERROR(VLOOKUP(A15,'ID6&7'!A:I,9,FALSE),"-") -> - | X15: =+IFERROR(VLOOKUP(A15,'ID6&7'!A:J,10,FALSE),"-") -> - | Z15: =+IF(J15=0,"Por iniciar",IF(OR(K15="-",M15="-",P15="-",R15="-",T15="-",V15="-"),"Em testes",IF(AND(M15=0,P15=0,R15=0,T15<>K15,V15<>K15),"OK","NOK"))) -> Por iniciar
A16: =+H16&I16&$I$8 -> ENTITYDT_FNNCL_STTMTS_PRVS45596 | H16: ENTITY | I16: DT_FNNCL_STTMTS_PRVS | J16: =+COUNTIF('ID1&5'!G:G,'1. Status'!I16) -> 0 | K16: =+IFERROR(VLOOKUP(CONCATENATE(A16,$B$10,B16),'ID1&5'!B:J,8,FALSE),"-") -> - | L16: =+IFERROR(VLOOKUP(B16,'ID1&5'!K:L,2,FALSE),"-") -> - | M16: =+IFERROR(VLOOKUP(CONCATENATE(A16,$B$10,B16),'ID1&5'!B:J,9,FALSE),"-") -> - | N16: =+IFERROR(VLOOKUP(CONCATENATE(A16,$C$10,C16),'ID1&5'!B:J,8,FALSE),"-") -> - | O16: =+IFERROR(VLOOKUP(C16,'ID1&5'!K:L,2,FALSE),"-") -> - | P16: =+IFERROR(VLOOKUP(CONCATENATE(A16,$C$10,C16),'ID1&5'!B:J,9,FALSE),"-") -> - | Q16: =+IFERROR(VLOOKUP(D16,'ID1&5'!K:L,2,FALSE),"-") -> - | R16: =+IFERROR(VLOOKUP(CONCATENATE(A16,$D$10,D16),'ID1&5'!B:J,9,FALSE),"-") -> - | S16: =+IFERROR(VLOOKUP(E16,'ID1&5'!K:L,2,FALSE),"-") -> - | T16: =+IFERROR(VLOOKUP(CONCATENATE(A16,$E$10,E16),'ID1&5'!B:J,9,FALSE),"-") -> - | U16: =+IFERROR(VLOOKUP(F16,'ID1&5'!K:L,2,FALSE),"-") -> - | V16: =+IFERROR(VLOOKUP(CONCATENATE(A16,$F$10,F16),'ID1&5'!B:J,9,FALSE),"-") -> - | W16: =+IFERROR(VLOOKUP(A16,'ID6&7'!A:I,9,FALSE),"-") -> - | X16: =+IFERROR(VLOOKUP(A16,'ID6&7'!A:J,10,FALSE),"-") -> - | Z16: =+IF(J16=0,"Por iniciar",IF(OR(K16="-",M16="-",P16="-",R16="-",T16="-",V16="-"),"Em testes",IF(AND(M16=0,P16=0,R16=0,T16<>K16,V16<>K16),"OK","NOK"))) -> Por iniciar
A17: =+H17&I17&$I$8 -> ENTITYDT_INTTN_LGL_PRCDNGS_LE45596 | H17: ENTITY | I17: DT_INTTN_LGL_PRCDNGS_LE | J17: =+COUNTIF('ID1&5'!G:G,'1. Status'!I17) -> 0 | K17: =+IFERROR(VLOOKUP(CONCATENATE(A17,$B$10,B17),'ID1&5'!B:J,8,FALSE),"-") -> - | L17: =+IFERROR(VLOOKUP(B17,'ID1&5'!K:L,2,FALSE),"-") -> - | M17: =+IFERROR(VLOOKUP(CONCATENATE(A17,$B$10,B17),'ID1&5'!B:J,9,FALSE),"-") -> - | N17: =+IFERROR(VLOOKUP(CONCATENATE(A17,$C$10,C17),'ID1&5'!B:J,8,FALSE),"-") -> - | O17: =+IFERROR(VLOOKUP(C17,'ID1&5'!K:L,2,FALSE),"-") -> - | P17: =+IFERROR(VLOOKUP(CONCATENATE(A17,$C$10,C17),'ID1&5'!B:J,9,FALSE),"-") -> - | Q17: =+IFERROR(VLOOKUP(D17,'ID1&5'!K:L,2,FALSE),"-") -> - | R17: =+IFERROR(VLOOKUP(CONCATENATE(A17,$D$10,D17),'ID1&5'!B:J,9,FALSE),"-") -> - | S17: =+IFERROR(VLOOKUP(E17,'ID1&5'!K:L,2,FALSE),"-") -> - | T17: =+IFERROR(VLOOKUP(CONCATENATE(A17,$E$10,E17),'ID1&5'!B:J,9,FALSE),"-") -> - | U17: =+IFERROR(VLOOKUP(F17,'ID1&5'!K:L,2,FALSE),"-") -> - | V17: =+IFERROR(VLOOKUP(CONCATENATE(A17,$F$10,F17),'ID1&5'!B:J,9,FALSE),"-") -> - | W17: =+IFERROR(VLOOKUP(A17,'ID6&7'!A:I,9,FALSE),"-") -> - | X17: =+IFERROR(VLOOKUP(A17,'ID6&7'!A:J,10,FALSE),"-") -> - | Z17: =+IF(J17=0,"Por iniciar",IF(OR(K17="-",M17="-",P17="-",R17="-",T17="-",V17="-"),"Em testes",IF(AND(M17=0,P17=0,R17=0,T17<>K17,V17<>K17),"OK","NOK"))) -> Por iniciar
A18: =+H18&I18&$I$8 -> ENTITYDT_PRFRMNG_STTS_LE45596 | H18: ENTITY | I18: DT_PRFRMNG_STTS_LE | J18: =+COUNTIF('ID1&5'!G:G,'1. Status'!I18) -> 0 | K18: =+IFERROR(VLOOKUP(CONCATENATE(A18,$B$10,B18),'ID1&5'!B:J,8,FALSE),"-") -> - | L18: =+IFERROR(VLOOKUP(B18,'ID1&5'!K:L,2,FALSE),"-") -> - | M18: =+IFERROR(VLOOKUP(CONCATENATE(A18,$B$10,B18),'ID1&5'!B:J,9,FALSE),"-") -> - | N18: =+IFERROR(VLOOKUP(CONCATENATE(A18,$C$10,C18),'ID1&5'!B:J,8,FALSE),"-") -> - | O18: =+IFERROR(VLOOKUP(C18,'ID1&5'!K:L,2,FALSE),"-") -> - | P18: =+IFERROR(VLOOKUP(CONCATENATE(A18,$C$10,C18),'ID1&5'!B:J,9,FALSE),"-") -> - | Q18: =+IFERROR(VLOOKUP(D18,'ID1&5'!K:L,2,FALSE),"-") -> - | R18: =+IFERROR(VLOOKUP(CONCATENATE(A18,$D$10,D18),'ID1&5'!B:J,9,FALSE),"-") -> - | S18: =+IFERROR(VLOOKUP(E18,'ID1&5'!K:L,2,FALSE),"-") -> - | T18: =+IFERROR(VLOOKUP(CONCATENATE(A18,$E$10,E18),'ID1&5'!B:J,9,FALSE),"-") -> - | U18: =+IFERROR(VLOOKUP(F18,'ID1&5'!K:L,2,FALSE),"-") -> - | V18: =+IFERROR(VLOOKUP(CONCATENATE(A18,$F$10,F18),'ID1&5'!B:J,9,FALSE),"-") -> - | W18: =+IFERROR(VLOOKUP(A18,'ID6&7'!A:I,9,FALSE),"-") -> - | X18: =+IFERROR(VLOOKUP(A18,'ID6&7'!A:J,10,FALSE),"-") -> - | Z18: =+IF(J18=0,"Por iniciar",IF(OR(K18="-",M18="-",P18="-",R18="-",T18="-",V18="-"),"Em testes",IF(AND(M18=0,P18=0,R18=0,T18<>K18,V18<>K18),"OK","NOK"))) -> Por iniciar
A19: =+H19&I19&$I$8 -> ENTITYGCC_PRNT_ID45596 | H19: ENTITY | I19: GCC_PRNT_ID | J19: =+COUNTIF('ID1&5'!G:G,'1. Status'!I19) -> 0 | K19: =+IFERROR(VLOOKUP(CONCATENATE(A19,$B$10,B19),'ID1&5'!B:J,8,FALSE),"-") -> - | L19: =+IFERROR(VLOOKUP(B19,'ID1&5'!K:L,2,FALSE),"-") -> - | M19: =+IFERROR(VLOOKUP(CONCATENATE(A19,$B$10,B19),'ID1&5'!B:J,9,FALSE),"-") -> - | N19: =+IFERROR(VLOOKUP(CONCATENATE(A19,$C$10,C19),'ID1&5'!B:J,8,FALSE),"-") -> - | O19: =+IFERROR(VLOOKUP(C19,'ID1&5'!K:L,2,FALSE),"-") -> - | P19: =+IFERROR(VLOOKUP(CONCATENATE(A19,$C$10,C19),'ID1&5'!B:J,9,FALSE),"-") -> - | Q19: =+IFERROR(VLOOKUP(D19,'ID1&5'!K:L,2,FALSE),"-") -> - | R19: =+IFERROR(VLOOKUP(CONCATENATE(A19,$D$10,D19),'ID1&5'!B:J,9,FALSE),"-") -> - | S19: =+IFERROR(VLOOKUP(E19,'ID1&5'!K:L,2,FALSE),"-") -> - | T19: =+IFERROR(VLOOKUP(CONCATENATE(A19,$E$10,E19),'ID1&5'!B:J,9,FALSE),"-") -> - | U19: =+IFERROR(VLOOKUP(F19,'ID1&5'!K:L,2,FALSE),"-") -> - | V19: =+IFERROR(VLOOKUP(CONCATENATE(A19,$F$10,F19),'ID1&5'!B:J,9,FALSE),"-") -> - | W19: =+IFERROR(VLOOKUP(A19,'ID6&7'!A:I,9,FALSE),"-") -> - | X19: =+IFERROR(VLOOKUP(A19,'ID6&7'!A:J,10,FALSE),"-") -> - | Z19: =+IF(J19=0,"Por iniciar",IF(OR(K19="-",M19="-",P19="-",R19="-",T19="-",V19="-"),"Em testes",IF(AND(M19=0,P19=0,R19=0,T19<>K19,V19<>K19),"OK","NOK"))) -> Por iniciar
A20: =+H20&I20&$I$8 -> ENTITYGCC_PRNT_NM45596 | H20: ENTITY | I20: GCC_PRNT_NM | J20: =+COUNTIF('ID1&5'!G:G,'1. Status'!I20) -> 0 | K20: =+IFERROR(VLOOKUP(CONCATENATE(A20,$B$10,B20),'ID1&5'!B:J,8,FALSE),"-") -> - | L20: =+IFERROR(VLOOKUP(B20,'ID1&5'!K:L,2,FALSE),"-") -> - | M20: =+IFERROR(VLOOKUP(CONCATENATE(A20,$B$10,B20),'ID1&5'!B:J,9,FALSE),"-") -> - | N20: =+IFERROR(VLOOKUP(CONCATENATE(A20,$C$10,C20),'ID1&5'!B:J,8,FALSE),"-") -> - | O20: =+IFERROR(VLOOKUP(C20,'ID1&5'!K:L,2,FALSE),"-") -> - | P20: =+IFERROR(VLOOKUP(CONCATENATE(A20,$C$10,C20),'ID1&5'!B:J,9,FALSE),"-") -> - | Q20: =+IFERROR(VLOOKUP(D20,'ID1&5'!K:L,2,FALSE),"-") -> - | R20: =+IFERROR(VLOOKUP(CONCATENATE(A20,$D$10,D20),'ID1&5'!B:J,9,FALSE),"-") -> - | S20: =+IFERROR(VLOOKUP(E20,'ID1&5'!K:L,2,FALSE),"-") -> - | T20: =+IFERROR(VLOOKUP(CONCATENATE(A20,$E$10,E20),'ID1&5'!B:J,9,FALSE),"-") -> - | U20: =+IFERROR(VLOOKUP(F20,'ID1&5'!K:L,2,FALSE),"-") -> - | V20: =+IFERROR(VLOOKUP(CONCATENATE(A20,$F$10,F20),'ID1&5'!B:J,9,FALSE),"-") -> - | W20: =+IFERROR(VLOOKUP(A20,'ID6&7'!A:I,9,FALSE),"-") -> - | X20: =+IFERROR(VLOOKUP(A20,'ID6&7'!A:J,10,FALSE),"-") -> - | Z20: =+IF(J20=0,"Por iniciar",IF(OR(K20="-",M20="-",P20="-",R20="-",T20="-",V20="-"),"Em testes",IF(AND(M20=0,P20=0,R20=0,T20<>K20,V20<>K20),"OK","NOK"))) -> Por iniciar
A21: =+H21&I21&$I$8 -> ENTITYINTRNL_SGMNT45596 | H21: ENTITY | I21: INTRNL_SGMNT | J21: =+COUNTIF('ID1&5'!G:G,'1. Status'!I21) -> 0 | K21: =+IFERROR(VLOOKUP(CONCATENATE(A21,$B$10,B21),'ID1&5'!B:J,8,FALSE),"-") -> - | L21: =+IFERROR(VLOOKUP(B21,'ID1&5'!K:L,2,FALSE),"-") -> - | M21: =+IFERROR(VLOOKUP(CONCATENATE(A21,$B$10,B21),'ID1&5'!B:J,9,FALSE),"-") -> - | N21: =+IFERROR(VLOOKUP(CONCATENATE(A21,$C$10,C21),'ID1&5'!B:J,8,FALSE),"-") -> - | O21: =+IFERROR(VLOOKUP(C21,'ID1&5'!K:L,2,FALSE),"-") -> - | P21: =+IFERROR(VLOOKUP(CONCATENATE(A21,$C$10,C21),'ID1&5'!B:J,9,FALSE),"-") -> - | Q21: =+IFERROR(VLOOKUP(D21,'ID1&5'!K:L,2,FALSE),"-") -> - | R21: =+IFERROR(VLOOKUP(CONCATENATE(A21,$D$10,D21),'ID1&5'!B:J,9,FALSE),"-") -> - | S21: =+IFERROR(VLOOKUP(E21,'ID1&5'!K:L,2,FALSE),"-") -> - | T21: =+IFERROR(VLOOKUP(CONCATENATE(A21,$E$10,E21),'ID1&5'!B:J,9,FALSE),"-") -> - | U21: =+IFERROR(VLOOKUP(F21,'ID1&5'!K:L,2,FALSE),"-") -> - | V21: =+IFERROR(VLOOKUP(CONCATENATE(A21,$F$10,F21),'ID1&5'!B:J,9,FALSE),"-") -> - | W21: =+IFERROR(VLOOKUP(A21,'ID6&7'!A:I,9,FALSE),"-") -> - | X21: =+IFERROR(VLOOKUP(A21,'ID6&7'!A:J,10,FALSE),"-") -> - | Z21: =+IF(J21=0,"Por iniciar",IF(OR(K21="-",M21="-",P21="-",R21="-",T21="-",V21="-"),"Em testes",IF(AND(M21=0,P21=0,R21=0,T21<>K21,V21<>K21),"OK","NOK"))) -> Por iniciar
A22: =+H22&I22&$I$8 -> ENTITYINTRNL_UNT45596 | H22: ENTITY | I22: INTRNL_UNT | J22: =+COUNTIF('ID1&5'!G:G,'1. Status'!I22) -> 0 | K22: =+IFERROR(VLOOKUP(CONCATENATE(A22,$B$10,B22),'ID1&5'!B:J,8,FALSE),"-") -> - | L22: =+IFERROR(VLOOKUP(B22,'ID1&5'!K:L,2,FALSE),"-") -> - | M22: =+IFERROR(VLOOKUP(CONCATENATE(A22,$B$10,B22),'ID1&5'!B:J,9,FALSE),"-") -> - | N22: =+IFERROR(VLOOKUP(CONCATENATE(A22,$C$10,C22),'ID1&5'!B:J,8,FALSE),"-") -> - | O22: =+IFERROR(VLOOKUP(C22,'ID1&5'!K:L,2,FALSE),"-") -> - | P22: =+IFERROR(VLOOKUP(CONCATENATE(A22,$C$10,C22),'ID1&5'!B:J,9,FALSE),"-") -> - | Q22: =+IFERROR(VLOOKUP(D22,'ID1&5'!K:L,2,FALSE),"-") -> - | R22: =+IFERROR(VLOOKUP(CONCATENATE(A22,$D$10,D22),'ID1&5'!B:J,9,FALSE),"-") -> - | S22: =+IFERROR(VLOOKUP(E22,'ID1&5'!K:L,2,FALSE),"-") -> - | T22: =+IFERROR(VLOOKUP(CONCATENATE(A22,$E$10,E22),'ID1&5'!B:J,9,FALSE),"-") -> - | U22: =+IFERROR(VLOOKUP(F22,'ID1&5'!K:L,2,FALSE),"-") -> - | V22: =+IFERROR(VLOOKUP(CONCATENATE(A22,$F$10,F22),'ID1&5'!B:J,9,FALSE),"-") -> - | W22: =+IFERROR(VLOOKUP(A22,'ID6&7'!A:I,9,FALSE),"-") -> - | X22: =+IFERROR(VLOOKUP(A22,'ID6&7'!A:J,10,FALSE),"-") -> - | Z22: =+IF(J22=0,"Por iniciar",IF(OR(K22="-",M22="-",P22="-",R22="-",T22="-",V22="-"),"Em testes",IF(AND(M22=0,P22=0,R22=0,T22<>K22,V22<>K22),"OK","NOK"))) -> Por iniciar
... A88: =+H88&I88&$I$8 -> ENTITYDBT_SRVC_RT45596 | H88: ENTITY | I88: DBT_SRVC_RT | J88: =+COUNTIF('ID1&5'!G:G,'1. Status'!I88) -> 0 | K88: =+IFERROR(VLOOKUP(CONCATENATE(A88,$B$10,B88),'ID1&5'!B:J,8,FALSE),"-") -> - | L88: =+IFERROR(VLOOKUP(B88,'ID1&5'!K:L,2,FALSE),"-") -> - | M88: =+IFERROR(VLOOKUP(CONCATENATE(A88,$B$10,B88),'ID1&5'!B:J,9,FALSE),"-") -> - | N88: =+IFERROR(VLOOKUP(CONCATENATE(A88,$C$10,C88),'ID1&5'!B:J,8,FALSE),"-") -> - | O88: =+IFERROR(VLOOKUP(C88,'ID1&5'!K:L,2,FALSE),"-") -> - | P88: =+IFERROR(VLOOKUP(CONCATENATE(A88,$C$10,C88),'ID1&5'!B:J,9,FALSE),"-") -> - | Q88: =+IFERROR(VLOOKUP(D88,'ID1&5'!K:L,2,FALSE),"-") -> - | R88: =+IFERROR(VLOOKUP(CONCATENATE(A88,$D$10,D88),'ID1&5'!B:J,9,FALSE),"-") -> - | S88: =+IFERROR(VLOOKUP(E88,'ID1&5'!K:L,2,FALSE),"-") -> - | T88: =+IFERROR(VLOOKUP(CONCATENATE(A88,$E$10,E88),'ID1&5'!B:J,9,FALSE),"-") -> - | U88: =+IFERROR(VLOOKUP(F88,'ID1&5'!K:L,2,FALSE),"-") -> - | V88: =+IFERROR(VLOOKUP(CONCATENATE(A88,$F$10,F88),'ID1&5'!B:J,9,FALSE),"-") -> - | W88: =+IFERROR(VLOOKUP(A88,'ID6&7'!A:I,9,FALSE),"-") -> - | X88: =+IFERROR(VLOOKUP(A88,'ID6&7'!A:J,10,FALSE),"-") -> - | Z88: =+IF(J88=0,"Por iniciar",IF(OR(K88="-",M88="-",P88="-",R88="-",T88="-",V88="-"),"Em testes",IF(AND(M88=0,P88=0,R88=0,T88<>K88,V88<>K88),"OK","NOK"))) -> Por iniciar
A89: =+H89&I89&$I$8 -> ENTITYDBT_SRVC_RT_12M45596 | B89: {=+MAX(IF('ID1&5'!A:A='1. Status'!A89&'1. Status'!$B$10,'ID1&5'!K:K))} -> 0 | C89: {=+MAX(IF('ID1&5'!A:A='1. Status'!A89&'1. Status'!$C$10,'ID1&5'!K:K))} -> 0 | D89: {=+MAX(IF('ID1&5'!A:A='1. Status'!A89&'1. Status'!$D$10,'ID1&5'!K:K))} -> 0 | E89: {=+MAX(IF('ID1&5'!A:A='1. Status'!A89&'1. Status'!$E$10,'ID1&5'!K:K))} -> 0 | F89: {=+MAX(IF('ID1&5'!A:A='1. Status'!A89&'1. Status'!$F$10,'ID1&5'!K:K))} -> 0 | H89: ENTITY | I89: DBT_SRVC_RT_12M | J89: =+COUNTIF('ID1&5'!G:G,'1. Status'!I89) -> 0 | K89: =+IFERROR(VLOOKUP(CONCATENATE(A89,$B$10,B89),'ID1&5'!B:J,8,FALSE),"-") -> - | L89: =+IFERROR(VLOOKUP(B89,'ID1&5'!K:L,2,FALSE),"-") -> - | M89: =+IFERROR(VLOOKUP(CONCATENATE(A89,$B$10,B89),'ID1&5'!B:J,9,FALSE),"-") -> - | N89: =+IFERROR(VLOOKUP(CONCATENATE(A89,$C$10,C89),'ID1&5'!B:J,8,FALSE),"-") -> - | O89: =+IFERROR(VLOOKUP(C89,'ID1&5'!K:L,2,FALSE),"-") -> - | P89: =+IFERROR(VLOOKUP(CONCATENATE(A89,$C$10,C89),'ID1&5'!B:J,9,FALSE),"-") -> - | Q89: =+IFERROR(VLOOKUP(D89,'ID1&5'!K:L,2,FALSE),"-") -> - | R89: =+IFERROR(VLOOKUP(CONCATENATE(A89,$D$10,D89),'ID1&5'!B:J,9,FALSE),"-") -> - | S89: =+IFERROR(VLOOKUP(E89,'ID1&5'!K:L,2,FALSE),"-") -> - | T89: =+IFERROR(VLOOKUP(CONCATENATE(A89,$E$10,E89),'ID1&5'!B:J,9,FALSE),"-") -> - | U89: =+IFERROR(VLOOKUP(F89,'ID1&5'!K:L,2,FALSE),"-") -> - | V89: =+IFERROR(VLOOKUP(CONCATENATE(A89,$F$10,F89),'ID1&5'!B:J,9,FALSE),"-") -> - | W89: =+IFERROR(VLOOKUP(A89,'ID6&7'!A:I,9,FALSE),"-") -> - | X89: =+IFERROR(VLOOKUP(A89,'ID6&7'!A:J,10,FALSE),"-") -> - | Z89: =+IF(J89=0,"Por iniciar",IF(OR(K89="-",M89="-",P89="-",R89="-",T89="-",V89="-"),"Em testes",IF(AND(M89=0,P89=0,R89=0,T89<>K89,V89<>K89),"OK","NOK"))) -> Por iniciar
A90: =+H90&I90&$I$8 -> ENTITYPD_CRR_RD45596 | B90: {=+MAX(IF('ID1&5'!A:A='1. Status'!A90&'1. Status'!$B$10,'ID1&5'!K:K))} -> 0 | C90: {=+MAX(IF('ID1&5'!A:A='1. Status'!A90&'1. Status'!$C$10,'ID1&5'!K:K))} -> 0 | D90: {=+MAX(IF('ID1&5'!A:A='1. Status'!A90&'1. Status'!$D$10,'ID1&5'!K:K))} -> 0 | E90: {=+MAX(IF('ID1&5'!A:A='1. Status'!A90&'1. Status'!$E$10,'ID1&5'!K:K))} -> 0 | F90: {=+MAX(IF('ID1&5'!A:A='1. Status'!A90&'1. Status'!$F$10,'ID1&5'!K:K))} -> 0 | H90: ENTITY | I90: PD_CRR_RD | J90: =+COUNTIF('ID1&5'!G:G,'1. Status'!I90) -> 0 | K90: =+IFERROR(VLOOKUP(CONCATENATE(A90,$B$10,B90),'ID1&5'!B:J,8,FALSE),"-") -> - | L90: =+IFERROR(VLOOKUP(B90,'ID1&5'!K:L,2,FALSE),"-") -> - | M90: =+IFERROR(VLOOKUP(CONCATENATE(A90,$B$10,B90),'ID1&5'!B:J,9,FALSE),"-") -> - | N90: =+IFERROR(VLOOKUP(CONCATENATE(A90,$C$10,C90),'ID1&5'!B:J,8,FALSE),"-") -> - | O90: =+IFERROR(VLOOKUP(C90,'ID1&5'!K:L,2,FALSE),"-") -> - | P90: =+IFERROR(VLOOKUP(CONCATENATE(A90,$C$10,C90),'ID1&5'!B:J,9,FALSE),"-") -> - | Q90: =+IFERROR(VLOOKUP(D90,'ID1&5'!K:L,2,FALSE),"-") -> - | R90: =+IFERROR(VLOOKUP(CONCATENATE(A90,$D$10,D90),'ID1&5'!B:J,9,FALSE),"-") -> - | S90: =+IFERROR(VLOOKUP(E90,'ID1&5'!K:L,2,FALSE),"-") -> - | T90: =+IFERROR(VLOOKUP(CONCATENATE(A90,$E$10,E90),'ID1&5'!B:J,9,FALSE),"-") -> - | U90: =+IFERROR(VLOOKUP(F90,'ID1&5'!K:L,2,FALSE),"-") -> - | V90: =+IFERROR(VLOOKUP(CONCATENATE(A90,$F$10,F90),'ID1&5'!B:J,9,FALSE),"-") -> - | W90: =+IFERROR(VLOOKUP(A90,'ID6&7'!A:I,9,FALSE),"-") -> - | X90: =+IFERROR(VLOOKUP(A90,'ID6&7'!A:J,10,FALSE),"-") -> - | Z90: =+IF(J90=0,"Por iniciar",IF(OR(K90="-",M90="-",P90="-",R90="-",T90="-",V90="-"),"Em testes",IF(AND(M90=0,P90=0,R90=0,T90<>K90,V90<>K90),"OK","NOK"))) -> Por iniciar
A91: =+H91&I91&$I$8 -> ENTITYPD_IFRS9_12M_RD45596 | B91: {=+MAX(IF('ID1&5'!A:A='1. Status'!A91&'1. Status'!$B$10,'ID1&5'!K:K))} -> 0 | C91: {=+MAX(IF('ID1&5'!A:A='1. Status'!A91&'1. Status'!$C$10,'ID1&5'!K:K))} -> 0 | D91: {=+MAX(IF('ID1&5'!A:A='1. Status'!A91&'1. Status'!$D$10,'ID1&5'!K:K))} -> 0 | E91: {=+MAX(IF('ID1&5'!A:A='1. Status'!A91&'1. Status'!$E$10,'ID1&5'!K:K))} -> 0 | F91: {=+MAX(IF('ID1&5'!A:A='1. Status'!A91&'1. Status'!$F$10,'ID1&5'!K:K))} -> 0 | H91: ENTITY | I91: PD_IFRS9_12M_RD | J91: =+COUNTIF('ID1&5'!G:G,'1. Status'!I91) -> 0 | K91: =+IFERROR(VLOOKUP(CONCATENATE(A91,$B$10,B91),'ID1&5'!B:J,8,FALSE),"-") -> - | L91: =+IFERROR(VLOOKUP(B91,'ID1&5'!K:L,2,FALSE),"-") -> - | M91: =+IFERROR(VLOOKUP(CONCATENATE(A91,$B$10,B91),'ID1&5'!B:J,9,FALSE),"-") -> - | N91: =+IFERROR(VLOOKUP(CONCATENATE(A91,$C$10,C91),'ID1&5'!B:J,8,FALSE),"-") -> - | O91: =+IFERROR(VLOOKUP(C91,'ID1&5'!K:L,2,FALSE),"-") -> - | P91: =+IFERROR(VLOOKUP(CONCATENATE(A91,$C$10,C91),'ID1&5'!B:J,9,FALSE),"-") -> - | Q91: =+IFERROR(VLOOKUP(D91,'ID1&5'!K:L,2,FALSE),"-") -> - | R91: =+IFERROR(VLOOKUP(CONCATENATE(A91,$D$10,D91),'ID1&5'!B:J,9,FALSE),"-") -> - | S91: =+IFERROR(VLOOKUP(E91,'ID1&5'!K:L,2,FALSE),"-") -> - | T91: =+IFERROR(VLOOKUP(CONCATENATE(A91,$E$10,E91),'ID1&5'!B:J,9,FALSE),"-") -> - | U91: =+IFERROR(VLOOKUP(F91,'ID1&5'!K:L,2,FALSE),"-") -> - | V91: =+IFERROR(VLOOKUP(CONCATENATE(A91,$F$10,F91),'ID1&5'!B:J,9,FALSE),"-") -> - | W91: =+IFERROR(VLOOKUP(A91,'ID6&7'!A:I,9,FALSE),"-") -> - | X91: =+IFERROR(VLOOKUP(A91,'ID6&7'!A:J,10,FALSE),"-") -> - | Z91: =+IF(J91=0,"Por iniciar",IF(OR(K91="-",M91="-",P91="-",R91="-",T91="-",V91="-"),"Em testes",IF(AND(M91=0,P91=0,R91=0,T91<>K91,V91<>K91),"OK","NOK"))) -> Por iniciar
A92: =+H92&I92&$I$8 -> ENTITYPD_IFRS9_12M_RD_T145596 | B92: {=+MAX(IF('ID1&5'!A:A='1. Status'!A92&'1. Status'!$B$10,'ID1&5'!K:K))} -> 0 | C92: {=+MAX(IF('ID1&5'!A:A='1. Status'!A92&'1. Status'!$C$10,'ID1&5'!K:K))} -> 0 | D92: {=+MAX(IF('ID1&5'!A:A='1. Status'!A92&'1. Status'!$D$10,'ID1&5'!K:K))} -> 0 | E92: {=+MAX(IF('ID1&5'!A:A='1. Status'!A92&'1. Status'!$E$10,'ID1&5'!K:K))} -> 0 | F92: {=+MAX(IF('ID1&5'!A:A='1. Status'!A92&'1. Status'!$F$10,'ID1&5'!K:K))} -> 0 | H92: ENTITY | I92: PD_IFRS9_12M_RD_T1 | J92: =+COUNTIF('ID1&5'!G:G,'1. Status'!I92) -> 0 | K92: =+IFERROR(VLOOKUP(CONCATENATE(A92,$B$10,B92),'ID1&5'!B:J,8,FALSE),"-") -> - | L92: =+IFERROR(VLOOKUP(B92,'ID1&5'!K:L,2,FALSE),"-") -> - | M92: =+IFERROR(VLOOKUP(CONCATENATE(A92,$B$10,B92),'ID1&5'!B:J,9,FALSE),"-") -> - | N92: =+IFERROR(VLOOKUP(CONCATENATE(A92,$C$10,C92),'ID1&5'!B:J,8,FALSE),"-") -> - | O92: =+IFERROR(VLOOKUP(C92,'ID1&5'!K:L,2,FALSE),"-") -> - | P92: =+IFERROR(VLOOKUP(CONCATENATE(A92,$C$10,C92),'ID1&5'!B:J,9,FALSE),"-") -> - | Q92: =+IFERROR(VLOOKUP(D92,'ID1&5'!K:L,2,FALSE),"-") -> - | R92: =+IFERROR(VLOOKUP(CONCATENATE(A92,$D$10,D92),'ID1&5'!B:J,9,FALSE),"-") -> - | S92: =+IFERROR(VLOOKUP(E92,'ID1&5'!K:L,2,FALSE),"-") -> - | T92: =+IFERROR(VLOOKUP(CONCATENATE(A92,$E$10,E92),'ID1&5'!B:J,9,FALSE),"-") -> - | U92: =+IFERROR(VLOOKUP(F92,'ID1&5'!K:L,2,FALSE),"-") -> - | V92: =+IFERROR(VLOOKUP(CONCATENATE(A92,$F$10,F92),'ID1&5'!B:J,9,FALSE),"-") -> - | W92: =+IFERROR(VLOOKUP(A92,'ID6&7'!A:I,9,FALSE),"-") -> - | X92: =+IFERROR(VLOOKUP(A92,'ID6&7'!A:J,10,FALSE),"-") -> - | Z92: =+IF(J92=0,"Por iniciar",IF(OR(K92="-",M92="-",P92="-",R92="-",T92="-",V92="-"),"Em testes",IF(AND(M92=0,P92=0,R92=0,T92<>K92,V92<>K92),"OK","NOK"))) -> Por iniciar
A93: =+H93&I93&$I$8 -> ENTITYTAX_ID45596 | B93: {=+MAX(IF('ID1&5'!A:A='1. Status'!A93&'1. Status'!$B$10,'ID1&5'!K:K))} -> 0 | C93: {=+MAX(IF('ID1&5'!A:A='1. Status'!A93&'1. Status'!$C$10,'ID1&5'!K:K))} -> 0 | D93: {=+MAX(IF('ID1&5'!A:A='1. Status'!A93&'1. Status'!$D$10,'ID1&5'!K:K))} -> 0 | E93: {=+MAX(IF('ID1&5'!A:A='1. Status'!A93&'1. Status'!$E$10,'ID1&5'!K:K))} -> 0 | F93: {=+MAX(IF('ID1&5'!A:A='1. Status'!A93&'1. Status'!$F$10,'ID1&5'!K:K))} -> 0 | H93: ENTITY | I93: TAX_ID | J93: =+COUNTIF('ID1&5'!G:G,'1. Status'!I93) -> 0 | K93: =+IFERROR(VLOOKUP(CONCATENATE(A93,$B$10,B93),'ID1&5'!B:J,8,FALSE),"-") -> - | L93: =+IFERROR(VLOOKUP(B93,'ID1&5'!K:L,2,FALSE),"-") -> - | M93: =+IFERROR(VLOOKUP(CONCATENATE(A93,$B$10,B93),'ID1&5'!B:J,9,FALSE),"-") -> - | N93: =+IFERROR(VLOOKUP(CONCATENATE(A93,$C$10,C93),'ID1&5'!B:J,8,FALSE),"-") -> - | O93: =+IFERROR(VLOOKUP(C93,'ID1&5'!K:L,2,FALSE),"-") -> - | P93: =+IFERROR(VLOOKUP(CONCATENATE(A93,$C$10,C93),'ID1&5'!B:J,9,FALSE),"-") -> - | Q93: =+IFERROR(VLOOKUP(D93,'ID1&5'!K:L,2,FALSE),"-") -> - | R93: =+IFERROR(VLOOKUP(CONCATENATE(A93,$D$10,D93),'ID1&5'!B:J,9,FALSE),"-") -> - | S93: =+IFERROR(VLOOKUP(E93,'ID1&5'!K:L,2,FALSE),"-") -> - | T93: =+IFERROR(VLOOKUP(CONCATENATE(A93,$E$10,E93),'ID1&5'!B:J,9,FALSE),"-") -> - | U93: =+IFERROR(VLOOKUP(F93,'ID1&5'!K:L,2,FALSE),"-") -> - | V93: =+IFERROR(VLOOKUP(CONCATENATE(A93,$F$10,F93),'ID1&5'!B:J,9,FALSE),"-") -> - | W93: =+IFERROR(VLOOKUP(A93,'ID6&7'!A:I,9,FALSE),"-") -> - | X93: =+IFERROR(VLOOKUP(A93,'ID6&7'!A:J,10,FALSE),"-") -> - | Z93: =+IF(J93=0,"Por iniciar",IF(OR(K93="-",M93="-",P93="-",R93="-",T93="-",V93="-"),"Em testes",IF(AND(M93=0,P93=0,R93=0,T93<>K93,V93<>K93),"OK","NOK"))) -> Por iniciar
A94: =+H94&I94&$I$8 -> ENTITYANNL_TRNVR_LE_BDR45596 | B94: {=+MAX(IF('ID1&5'!A:A='1. Status'!A94&'1. Status'!$B$10,'ID1&5'!K:K))} -> 0 | C94: {=+MAX(IF('ID1&5'!A:A='1. Status'!A94&'1. Status'!$C$10,'ID1&5'!K:K))} -> 0 | D94: {=+MAX(IF('ID1&5'!A:A='1. Status'!A94&'1. Status'!$D$10,'ID1&5'!K:K))} -> 0 | E94: {=+MAX(IF('ID1&5'!A:A='1. Status'!A94&'1. Status'!$E$10,'ID1&5'!K:K))} -> 0 | F94: {=+MAX(IF('ID1&5'!A:A='1. Status'!A94&'1. Status'!$F$10,'ID1&5'!K:K))} -> 0 | H94: ENTITY | I94: ANNL_TRNVR_LE_BDR | J94: =+COUNTIF('ID1&5'!G:G,'1. Status'!I94) -> 0 | K94: =+IFERROR(VLOOKUP(CONCATENATE(A94,$B$10,B94),'ID1&5'!B:J,8,FALSE),"-") -> - | L94: =+IFERROR(VLOOKUP(B94,'ID1&5'!K:L,2,FALSE),"-") -> - | M94: =+IFERROR(VLOOKUP(CONCATENATE(A94,$B$10,B94),'ID1&5'!B:J,9,FALSE),"-") -> - | N94: =+IFERROR(VLOOKUP(CONCATENATE(A94,$C$10,C94),'ID1&5'!B:J,8,FALSE),"-") -> - | O94: =+IFERROR(VLOOKUP(C94,'ID1&5'!K:L,2,FALSE),"-") -> - | P94: =+IFERROR(VLOOKUP(CONCATENATE(A94,$C$10,C94),'ID1&5'!B:J,9,FALSE),"-") -> - | Q94: =+IFERROR(VLOOKUP(D94,'ID1&5'!K:L,2,FALSE),"-") -> - | R94: =+IFERROR(VLOOKUP(CONCATENATE(A94,$D$10,D94),'ID1&5'!B:J,9,FALSE),"-") -> - | S94: =+IFERROR(VLOOKUP(E94,'ID1&5'!K:L,2,FALSE),"-") -> - | T94: =+IFERROR(VLOOKUP(CONCATENATE(A94,$E$10,E94),'ID1&5'!B:J,9,FALSE),"-") -> - | U94: =+IFERROR(VLOOKUP(F94,'ID1&5'!K:L,2,FALSE),"-") -> - | V94: =+IFERROR(VLOOKUP(CONCATENATE(A94,$F$10,F94),'ID1&5'!B:J,9,FALSE),"-") -> - | W94: =+IFERROR(VLOOKUP(A94,'ID6&7'!A:I,9,FALSE),"-") -> - | X94: =+IFERROR(VLOOKUP(A94,'ID6&7'!A:J,10,FALSE),"-") -> - | Z94: =+IF(J94=0,"Por iniciar",IF(OR(K94="-",M94="-",P94="-",R94="-",T94="-",V94="-"),"Em testes",IF(AND(M94=0,P94=0,R94=0,T94<>K94,V94<>K94),"OK","NOK"))) -> Por iniciar
A95: =+H95&I95&$I$8 -> ENTITYANNL_TRNVR_PRVS_BDR45596 | B95: {=+MAX(IF('ID1&5'!A:A='1. Status'!A95&'1. Status'!$B$10,'ID1&5'!K:K))} -> 0 | C95: {=+MAX(IF('ID1&5'!A:A='1. Status'!A95&'1. Status'!$C$10,'ID1&5'!K:K))} -> 0 | D95: {=+MAX(IF('ID1&5'!A:A='1. Status'!A95&'1. Status'!$D$10,'ID1&5'!K:K))} -> 0 | E95: {=+MAX(IF('ID1&5'!A:A='1. Status'!A95&'1. Status'!$E$10,'ID1&5'!K:K))} -> 0 | F95: {=+MAX(IF('ID1&5'!A:A='1. Status'!A95&'1. Status'!$F$10,'ID1&5'!K:K))} -> 0 | H95: ENTITY | I95: ANNL_TRNVR_PRVS_BDR | J95: =+COUNTIF('ID1&5'!G:G,'1. Status'!I95) -> 0 | K95: =+IFERROR(VLOOKUP(CONCATENATE(A95,$B$10,B95),'ID1&5'!B:J,8,FALSE),"-") -> - | L95: =+IFERROR(VLOOKUP(B95,'ID1&5'!K:L,2,FALSE),"-") -> - | M95: =+IFERROR(VLOOKUP(CONCATENATE(A95,$B$10,B95),'ID1&5'!B:J,9,FALSE),"-") -> - | N95: =+IFERROR(VLOOKUP(CONCATENATE(A95,$C$10,C95),'ID1&5'!B:J,8,FALSE),"-") -> - | O95: =+IFERROR(VLOOKUP(C95,'ID1&5'!K:L,2,FALSE),"-") -> - | P95: =+IFERROR(VLOOKUP(CONCATENATE(A95,$C$10,C95),'ID1&5'!B:J,9,FALSE),"-") -> - | Q95: =+IFERROR(VLOOKUP(D95,'ID1&5'!K:L,2,FALSE),"-") -> - | R95: =+IFERROR(VLOOKUP(CONCATENATE(A95,$D$10,D95),'ID1&5'!B:J,9,FALSE),"-") -> - | S95: =+IFERROR(VLOOKUP(E95,'ID1&5'!K:L,2,FALSE),"-") -> - | T95: =+IFERROR(VLOOKUP(CONCATENATE(A95,$E$10,E95),'ID1&5'!B:J,9,FALSE),"-") -> - | U95: =+IFERROR(VLOOKUP(F95,'ID1&5'!K:L,2,FALSE),"-") -> - | V95: =+IFERROR(VLOOKUP(CONCATENATE(A95,$F$10,F95),'ID1&5'!B:J,9,FALSE),"-") -> - | W95: =+IFERROR(VLOOKUP(A95,'ID6&7'!A:I,9,FALSE),"-") -> - | X95: =+IFERROR(VLOOKUP(A95,'ID6&7'!A:J,10,FALSE),"-") -> - | Z95: =+IF(J95=0,"Por iniciar",IF(OR(K95="-",M95="-",P95="-",R95="-",T95="-",V95="-"),"Em testes",IF(AND(M95=0,P95=0,R95=0,T95<>K95,V95<>K95),"OK","NOK"))) -> Por iniciar
A96: =+H96&I96&$I$8 -> ENTITYOSI_ID45596 | B96: {=+MAX(IF('ID1&5'!A:A='1. Status'!A96&'1. Status'!$B$10,'ID1&5'!K:K))} -> 0 | C96: {=+MAX(IF('ID1&5'!A:A='1. Status'!A96&'1. Status'!$C$10,'ID1&5'!K:K))} -> 0 | D96: {=+MAX(IF('ID1&5'!A:A='1. Status'!A96&'1. Status'!$D$10,'ID1&5'!K:K))} -> 0 | E96: {=+MAX(IF('ID1&5'!A:A='1. Status'!A96&'1. Status'!$E$10,'ID1&5'!K:K))} -> 0 | F96: {=+MAX(IF('ID1&5'!A:A='1. Status'!A96&'1. Status'!$F$10,'ID1&5'!K:K))} -> 0 | H96: ENTITY | I96: OSI_ID | J96: =+COUNTIF('ID1&5'!G:G,'1. Status'!I96) -> 0 | K96: =+IFERROR(VLOOKUP(CONCATENATE(A96,$B$10,B96),'ID1&5'!B:J,8,FALSE),"-") -> - | L96: =+IFERROR(VLOOKUP(B96,'ID1&5'!K:L,2,FALSE),"-") -> - | M96: =+IFERROR(VLOOKUP(CONCATENATE(A96,$B$10,B96),'ID1&5'!B:J,9,FALSE),"-") -> - | N96: =+IFERROR(VLOOKUP(CONCATENATE(A96,$C$10,C96),'ID1&5'!B:J,8,FALSE),"-") -> - | O96: =+IFERROR(VLOOKUP(C96,'ID1&5'!K:L,2,FALSE),"-") -> - | P96: =+IFERROR(VLOOKUP(CONCATENATE(A96,$C$10,C96),'ID1&5'!B:J,9,FALSE),"-") -> - | Q96: =+IFERROR(VLOOKUP(D96,'ID1&5'!K:L,2,FALSE),"-") -> - | R96: =+IFERROR(VLOOKUP(CONCATENATE(A96,$D$10,D96),'ID1&5'!B:J,9,FALSE),"-") -> - | S96: =+IFERROR(VLOOKUP(E96,'ID1&5'!K:L,2,FALSE),"-") -> - | T96: =+IFERROR(VLOOKUP(CONCATENATE(A96,$E$10,E96),'ID1&5'!B:J,9,FALSE),"-") -> - | U96: =+IFERROR(VLOOKUP(F96,'ID1&5'!K:L,2,FALSE),"-") -> - | V96: =+IFERROR(VLOOKUP(CONCATENATE(A96,$F$10,F96),'ID1&5'!B:J,9,FALSE),"-") -> - | W96: =+IFERROR(VLOOKUP(A96,'ID6&7'!A:I,9,FALSE),"-") -> - | X96: =+IFERROR(VLOOKUP(A96,'ID6&7'!A:J,10,FALSE),"-") -> - | Z96: =+IF(J96=0,"Por iniciar",IF(OR(K96="-",M96="-",P96="-",R96="-",T96="-",V96="-"),"Em testes",IF(AND(M96=0,P96=0,R96=0,T96<>K96,V96<>K96),"OK","NOK"))) -> Por iniciar
A97: =+H97&I97&$I$8 -> ENTITYPD_CRR_RD_T145596 | B97: {=+MAX(IF('ID1&5'!A:A='1. Status'!A97&'1. Status'!$B$10,'ID1&5'!K:K))} -> 0 | C97: {=+MAX(IF('ID1&5'!A:A='1. Status'!A97&'1. Status'!$C$10,'ID1&5'!K:K))} -> 0 | D97: {=+MAX(IF('ID1&5'!A:A='1. Status'!A97&'1. Status'!$D$10,'ID1&5'!K:K))} -> 0 | E97: {=+MAX(IF('ID1&5'!A:A='1. Status'!A97&'1. Status'!$E$10,'ID1&5'!K:K))} -> 0 | F97: {=+MAX(IF('ID1&5'!A:A='1. Status'!A97&'1. Status'!$F$10,'ID1&5'!K:K))} -> 0 | H97: ENTITY | I97: PD_CRR_RD_T1 | J97: =+COUNTIF('ID1&5'!G:G,'1. Status'!I97) -> 0 | K97: =+IFERROR(VLOOKUP(CONCATENATE(A97,$B$10,B97),'ID1&5'!B:J,8,FALSE),"-") -> - | L97: =+IFERROR(VLOOKUP(B97,'ID1&5'!K:L,2,FALSE),"-") -> - | M97: =+IFERROR(VLOOKUP(CONCATENATE(A97,$B$10,B97),'ID1&5'!B:J,9,FALSE),"-") -> - | N97: =+IFERROR(VLOOKUP(CONCATENATE(A97,$C$10,C97),'ID1&5'!B:J,8,FALSE),"-") -> - | O97: =+IFERROR(VLOOKUP(C97,'ID1&5'!K:L,2,FALSE),"-") -> - | P97: =+IFERROR(VLOOKUP(CONCATENATE(A97,$C$10,C97),'ID1&5'!B:J,9,FALSE),"-") -> - | Q97: =+IFERROR(VLOOKUP(D97,'ID1&5'!K:L,2,FALSE),"-") -> - | R97: =+IFERROR(VLOOKUP(CONCATENATE(A97,$D$10,D97),'ID1&5'!B:J,9,FALSE),"-") -> - | S97: =+IFERROR(VLOOKUP(E97,'ID1&5'!K:L,2,FALSE),"-") -> - | T97: =+IFERROR(VLOOKUP(CONCATENATE(A97,$E$10,E97),'ID1&5'!B:J,9,FALSE),"-") -> - | U97: =+IFERROR(VLOOKUP(F97,'ID1&5'!K:L,2,FALSE),"-") -> - | V97: =+IFERROR(VLOOKUP(CONCATENATE(A97,$F$10,F97),'ID1&5'!B:J,9,FALSE),"-") -> - | W97: =+IFERROR(VLOOKUP(A97,'ID6&7'!A:I,9,FALSE),"-") -> - | X97: =+IFERROR(VLOOKUP(A97,'ID6&7'!A:J,10,FALSE),"-") -> - | Z97: =+IF(J97=0,"Por iniciar",IF(OR(K97="-",M97="-",P97="-",R97="-",T97="-",V97="-"),"Em testes",IF(AND(M97=0,P97=0,R97=0,T97<>K97,V97<>K97),"OK","NOK"))) -> Por iniciar
A98: =+H98&I98&$I$8 -> ENTITYEC_GRP_ID45596 | B98: {=+MAX(IF('ID1&5'!A:A='1. Status'!A98&'1. Status'!$B$10,'ID1&5'!K:K))} -> 0 | C98: {=+MAX(IF('ID1&5'!A:A='1. Status'!A98&'1. Status'!$C$10,'ID1&5'!K:K))} -> 0 | D98: {=+MAX(IF('ID1&5'!A:A='1. Status'!A98&'1. Status'!$D$10,'ID1&5'!K:K))} -> 0 | E98: {=+MAX(IF('ID1&5'!A:A='1. Status'!A98&'1. Status'!$E$10,'ID1&5'!K:K))} -> 0 | F98: {=+MAX(IF('ID1&5'!A:A='1. Status'!A98&'1. Status'!$F$10,'ID1&5'!K:K))} -> 0 | H98: ENTITY | I98: EC_GRP_ID | J98: =+COUNTIF('ID1&5'!G:G,'1. Status'!I98) -> 0 | K98: =+IFERROR(VLOOKUP(CONCATENATE(A98,$B$10,B98),'ID1&5'!B:J,8,FALSE),"-") -> - | L98: =+IFERROR(VLOOKUP(B98,'ID1&5'!K:L,2,FALSE),"-") -> - | M98: =+IFERROR(VLOOKUP(CONCATENATE(A98,$B$10,B98),'ID1&5'!B:J,9,FALSE),"-") -> - | N98: =+IFERROR(VLOOKUP(CONCATENATE(A98,$C$10,C98),'ID1&5'!B:J,8,FALSE),"-") -> - | O98: =+IFERROR(VLOOKUP(C98,'ID1&5'!K:L,2,FALSE),"-") -> - | P98: =+IFERROR(VLOOKUP(CONCATENATE(A98,$C$10,C98),'ID1&5'!B:J,9,FALSE),"-") -> - | Q98: =+IFERROR(VLOOKUP(D98,'ID1&5'!K:L,2,FALSE),"-") -> - | R98: =+IFERROR(VLOOKUP(CONCATENATE(A98,$D$10,D98),'ID1&5'!B:J,9,FALSE),"-") -> - | S98: =+IFERROR(VLOOKUP(E98,'ID1&5'!K:L,2,FALSE),"-") -> - | T98: =+IFERROR(VLOOKUP(CONCATENATE(A98,$E$10,E98),'ID1&5'!B:J,9,FALSE),"-") -> - | U98: =+IFERROR(VLOOKUP(F98,'ID1&5'!K:L,2,FALSE),"-") -> - | V98: =+IFERROR(VLOOKUP(CONCATENATE(A98,$F$10,F98),'ID1&5'!B:J,9,FALSE),"-") -> - | W98: =+IFERROR(VLOOKUP(A98,'ID6&7'!A:I,9,FALSE),"-") -> - | X98: =+IFERROR(VLOOKUP(A98,'ID6&7'!A:J,10,FALSE),"-") -> - | Z98: =+IF(J98=0,"Por iniciar",IF(OR(K98="-",M98="-",P98="-",R98="-",T98="-",V98="-"),"Em testes",IF(AND(M98=0,P98=0,R98=0,T98<>K98,V98<>K98),"OK","NOK"))) -> Por iniciar
A99: =+H99&I99&$I$8 -> ENTITYEC_GRP_NM45596 | B99: {=+MAX(IF('ID1&5'!A:A='1. Status'!A99&'1. Status'!$B$10,'ID1&5'!K:K))} -> 0 | C99: {=+MAX(IF('ID1&5'!A:A='1. Status'!A99&'1. Status'!$C$10,'ID1&5'!K:K))} -> 0 | D99: {=+MAX(IF('ID1&5'!A:A='1. Status'!A99&'1. Status'!$D$10,'ID1&5'!K:K))} -> 0 | E99: {=+MAX(IF('ID1&5'!A:A='1. Status'!A99&'1. Status'!$E$10,'ID1&5'!K:K))} -> 0 | F99: {=+MAX(IF('ID1&5'!A:A='1. Status'!A99&'1. Status'!$F$10,'ID1&5'!K:K))} -> 0 | H99: ENTITY | I99: EC_GRP_NM | J99: =+COUNTIF('ID1&5'!G:G,'1. Status'!I99) -> 0 | K99: =+IFERROR(VLOOKUP(CONCATENATE(A99,$B$10,B99),'ID1&5'!B:J,8,FALSE),"-") -> - | L99: =+IFERROR(VLOOKUP(B99,'ID1&5'!K:L,2,FALSE),"-") -> - | M99: =+IFERROR(VLOOKUP(CONCATENATE(A99,$B$10,B99),'ID1&5'!B:J,9,FALSE),"-") -> - | N99: =+IFERROR(VLOOKUP(CONCATENATE(A99,$C$10,C99),'ID1&5'!B:J,8,FALSE),"-") -> - | O99: =+IFERROR(VLOOKUP(C99,'ID1&5'!K:L,2,FALSE),"-") -> - | P99: =+IFERROR(VLOOKUP(CONCATENATE(A99,$C$10,C99),'ID1&5'!B:J,9,FALSE),"-") -> - | Q99: =+IFERROR(VLOOKUP(D99,'ID1&5'!K:L,2,FALSE),"-") -> - | R99: =+IFERROR(VLOOKUP(CONCATENATE(A99,$D$10,D99),'ID1&5'!B:J,9,FALSE),"-") -> - | S99: =+IFERROR(VLOOKUP(E99,'ID1&5'!K:L,2,FALSE),"-") -> - | T99: =+IFERROR(VLOOKUP(CONCATENATE(A99,$E$10,E99),'ID1&5'!B:J,9,FALSE),"-") -> - | U99: =+IFERROR(VLOOKUP(F99,'ID1&5'!K:L,2,FALSE),"-") -> - | V99: =+IFERROR(VLOOKUP(CONCATENATE(A99,$F$10,F99),'ID1&5'!B:J,9,FALSE),"-") -> - | W99: =+IFERROR(VLOOKUP(A99,'ID6&7'!A:I,9,FALSE),"-") -> - | X99: =+IFERROR(VLOOKUP(A99,'ID6&7'!A:J,10,FALSE),"-") -> - | Z99: =+IF(J99=0,"Por iniciar",IF(OR(K99="-",M99="-",P99="-",R99="-",T99="-",V99="-"),"Em testes",IF(AND(M99=0,P99=0,R99=0,T99<>K99,V99<>K99),"OK","NOK"))) -> Por iniciar
A100: =+H100&I100&$I$8 -> ENTITYPRSN_TYP45596 | B100: {=+MAX(IF('ID1&5'!A:A='1. Status'!A100&'1. Status'!$B$10,'ID1&5'!K:K))} -> 0 | C100: {=+MAX(IF('ID1&5'!A:A='1. Status'!A100&'1. Status'!$C$10,'ID1&5'!K:K))} -> 0 | D100: {=+MAX(IF('ID1&5'!A:A='1. Status'!A100&'1. Status'!$D$10,'ID1&5'!K:K))} -> 0 | E100: {=+MAX(IF('ID1&5'!A:A='1. Status'!A100&'1. Status'!$E$10,'ID1&5'!K:K))} -> 0 | F100: {=+MAX(IF('ID1&5'!A:A='1. Status'!A100&'1. Status'!$F$10,'ID1&5'!K:K))} -> 0 | H100: ENTITY | I100: PRSN_TYP | J100: =+COUNTIF('ID1&5'!G:G,'1. Status'!I100) -> 0 | K100: =+IFERROR(VLOOKUP(CONCATENATE(A100,$B$10,B100),'ID1&5'!B:J,8,FALSE),"-") -> - | L100: =+IFERROR(VLOOKUP(B100,'ID1&5'!K:L,2,FALSE),"-") -> - | M100: =+IFERROR(VLOOKUP(CONCATENATE(A100,$B$10,B100),'ID1&5'!B:J,9,FALSE),"-") -> - | N100: =+IFERROR(VLOOKUP(CONCATENATE(A100,$C$10,C100),'ID1&5'!B:J,8,FALSE),"-") -> - | O100: =+IFERROR(VLOOKUP(C100,'ID1&5'!K:L,2,FALSE),"-") -> - | P100: =+IFERROR(VLOOKUP(CONCATENATE(A100,$C$10,C100),'ID1&5'!B:J,9,FALSE),"-") -> - | Q100: =+IFERROR(VLOOKUP(D100,'ID1&5'!K:L,2,FALSE),"-") -> - | R100: =+IFERROR(VLOOKUP(CONCATENATE(A100,$D$10,D100),'ID1&5'!B:J,9,FALSE),"-") -> - | S100: =+IFERROR(VLOOKUP(E100,'ID1&5'!K:L,2,FALSE),"-") -> - | T100: =+IFERROR(VLOOKUP(CONCATENATE(A100,$E$10,E100),'ID1&5'!B:J,9,FALSE),"-") -> - | U100: =+IFERROR(VLOOKUP(F100,'ID1&5'!K:L,2,FALSE),"-") -> - | V100: =+IFERROR(VLOOKUP(CONCATENATE(A100,$F$10,F100),'ID1&5'!B:J,9,FALSE),"-") -> - | W100: =+IFERROR(VLOOKUP(A100,'ID6&7'!A:I,9,FALSE),"-") -> - | X100: =+IFERROR(VLOOKUP(A100,'ID6&7'!A:J,10,FALSE),"-") -> - | Z100: =+IF(J100=0,"Por iniciar",IF(OR(K100="-",M100="-",P100="-",R100="-",T100="-",V100="-"),"Em testes",IF(AND(M100=0,P100=0,R100=0,T100<>K100,V100<>K100),"OK","NOK"))) -> Por iniciar
... A110: =+H110&I110&$I$8 -> ENTITYHD_OFFC_UNDRTKNG_ID45596 | B110: {=+MAX(IF('ID1&5'!A:A='1. Status'!A110&'1. Status'!$B$10,'ID1&5'!K:K))} -> 0 | C110: {=+MAX(IF('ID1&5'!A:A='1. Status'!A110&'1. Status'!$C$10,'ID1&5'!K:K))} -> 0 | D110: {=+MAX(IF('ID1&5'!A:A='1. Status'!A110&'1. Status'!$D$10,'ID1&5'!K:K))} -> 0 | E110: {=+MAX(IF('ID1&5'!A:A='1. Status'!A110&'1. Status'!$E$10,'ID1&5'!K:K))} -> 0 | F110: {=+MAX(IF('ID1&5'!A:A='1. Status'!A110&'1. Status'!$F$10,'ID1&5'!K:K))} -> 0 | H110: ENTITY | I110: HD_OFFC_UNDRTKNG_ID | J110: =+COUNTIF('ID1&5'!G:G,'1. Status'!I110) -> 0 | K110: =+IFERROR(VLOOKUP(CONCATENATE(A110,$B$10,B110),'ID1&5'!B:J,8,FALSE),"-") -> - | L110: =+IFERROR(VLOOKUP(B110,'ID1&5'!K:L,2,FALSE),"-") -> - | M110: =+IFERROR(VLOOKUP(CONCATENATE(A110,$B$10,B110),'ID1&5'!B:J,9,FALSE),"-") -> - | N110: =+IFERROR(VLOOKUP(CONCATENATE(A110,$C$10,C110),'ID1&5'!B:J,8,FALSE),"-") -> - | O110: =+IFERROR(VLOOKUP(C110,'ID1&5'!K:L,2,FALSE),"-") -> - | P110: =+IFERROR(VLOOKUP(CONCATENATE(A110,$C$10,C110),'ID1&5'!B:J,9,FALSE),"-") -> - | Q110: =+IFERROR(VLOOKUP(D110,'ID1&5'!K:L,2,FALSE),"-") -> - | R110: =+IFERROR(VLOOKUP(CONCATENATE(A110,$D$10,D110),'ID1&5'!B:J,9,FALSE),"-") -> - | S110: =+IFERROR(VLOOKUP(E110,'ID1&5'!K:L,2,FALSE),"-") -> - | T110: =+IFERROR(VLOOKUP(CONCATENATE(A110,$E$10,E110),'ID1&5'!B:J,9,FALSE),"-") -> - | U110: =+IFERROR(VLOOKUP(F110,'ID1&5'!K:L,2,FALSE),"-") -> - | V110: =+IFERROR(VLOOKUP(CONCATENATE(A110,$F$10,F110),'ID1&5'!B:J,9,FALSE),"-") -> - | W110: =+IFERROR(VLOOKUP(A110,'ID6&7'!A:I,9,FALSE),"-") -> - | X110: =+IFERROR(VLOOKUP(A110,'ID6&7'!A:J,10,FALSE),"-") -> - | Z110: =+IF(J110=0,"Por iniciar",IF(OR(K110="-",M110="-",P110="-",R110="-",T110="-",V110="-"),"Em testes",IF(AND(M110=0,P110=0,R110=0,T110<>K110,V110<>K110),"OK","NOK"))) -> Por iniciar
A111: =+H111&I111&$I$8 -> ENTITYIMMDT_PRNT_UNDRTKNG_ID45596 | H111: ENTITY | I111: IMMDT_PRNT_UNDRTKNG_ID | J111: =+COUNTIF('ID1&5'!G:G,'1. Status'!I111) -> 0 | K111: =+IFERROR(VLOOKUP(CONCATENATE(A111,$B$10,B111),'ID1&5'!B:J,8,FALSE),"-") -> - | L111: =+IFERROR(VLOOKUP(B111,'ID1&5'!K:L,2,FALSE),"-") -> - | M111: =+IFERROR(VLOOKUP(CONCATENATE(A111,$B$10,B111),'ID1&5'!B:J,9,FALSE),"-") -> - | N111: =+IFERROR(VLOOKUP(CONCATENATE(A111,$C$10,C111),'ID1&5'!B:J,8,FALSE),"-") -> - | O111: =+IFERROR(VLOOKUP(C111,'ID1&5'!K:L,2,FALSE),"-") -> - | P111: =+IFERROR(VLOOKUP(CONCATENATE(A111,$C$10,C111),'ID1&5'!B:J,9,FALSE),"-") -> - | Q111: =+IFERROR(VLOOKUP(D111,'ID1&5'!K:L,2,FALSE),"-") -> - | R111: =+IFERROR(VLOOKUP(CONCATENATE(A111,$D$10,D111),'ID1&5'!B:J,9,FALSE),"-") -> - | S111: =+IFERROR(VLOOKUP(E111,'ID1&5'!K:L,2,FALSE),"-") -> - | T111: =+IFERROR(VLOOKUP(CONCATENATE(A111,$E$10,E111),'ID1&5'!B:J,9,FALSE),"-") -> - | U111: =+IFERROR(VLOOKUP(F111,'ID1&5'!K:L,2,FALSE),"-") -> - | V111: =+IFERROR(VLOOKUP(CONCATENATE(A111,$F$10,F111),'ID1&5'!B:J,9,FALSE),"-") -> - | W111: =+IFERROR(VLOOKUP(A111,'ID6&7'!A:I,9,FALSE),"-") -> - | X111: =+IFERROR(VLOOKUP(A111,'ID6&7'!A:J,10,FALSE),"-") -> - | Z111: =+IF(J111=0,"Por iniciar",IF(OR(K111="-",M111="-",P111="-",R111="-",T111="-",V111="-"),"Em testes",IF(AND(M111=0,P111=0,R111=0,T111<>K111,V111<>K111),"OK","NOK"))) -> Por iniciar
A112: =+H112&I112&$I$8 -> ENTITYULTMT_PRNT_UNDRTKNG_ID45596 | B112: {=+MAX(IF('ID1&5'!A:A='1. Status'!A112&'1. Status'!$B$10,'ID1&5'!K:K))} -> 0 | C112: {=+MAX(IF('ID1&5'!A:A='1. Status'!A112&'1. Status'!$C$10,'ID1&5'!K:K))} -> 0 | D112: {=+MAX(IF('ID1&5'!A:A='1. Status'!A112&'1. Status'!$D$10,'ID1&5'!K:K))} -> 0 | E112: {=+MAX(IF('ID1&5'!A:A='1. Status'!A112&'1. Status'!$E$10,'ID1&5'!K:K))} -> 0 | F112: {=+MAX(IF('ID1&5'!A:A='1. Status'!A112&'1. Status'!$F$10,'ID1&5'!K:K))} -> 0 | H112: ENTITY | I112: ULTMT_PRNT_UNDRTKNG_ID | J112: =+COUNTIF('ID1&5'!G:G,'1. Status'!I112) -> 0 | K112: =+IFERROR(VLOOKUP(CONCATENATE(A112,$B$10,B112),'ID1&5'!B:J,8,FALSE),"-") -> - | L112: =+IFERROR(VLOOKUP(B112,'ID1&5'!K:L,2,FALSE),"-") -> - | M112: =+IFERROR(VLOOKUP(CONCATENATE(A112,$B$10,B112),'ID1&5'!B:J,9,FALSE),"-") -> - | N112: =+IFERROR(VLOOKUP(CONCATENATE(A112,$C$10,C112),'ID1&5'!B:J,8,FALSE),"-") -> - | O112: =+IFERROR(VLOOKUP(C112,'ID1&5'!K:L,2,FALSE),"-") -> - | P112: =+IFERROR(VLOOKUP(CONCATENATE(A112,$C$10,C112),'ID1&5'!B:J,9,FALSE),"-") -> - | Q112: =+IFERROR(VLOOKUP(D112,'ID1&5'!K:L,2,FALSE),"-") -> - | R112: =+IFERROR(VLOOKUP(CONCATENATE(A112,$D$10,D112),'ID1&5'!B:J,9,FALSE),"-") -> - | S112: =+IFERROR(VLOOKUP(E112,'ID1&5'!K:L,2,FALSE),"-") -> - | T112: =+IFERROR(VLOOKUP(CONCATENATE(A112,$E$10,E112),'ID1&5'!B:J,9,FALSE),"-") -> - | U112: =+IFERROR(VLOOKUP(F112,'ID1&5'!K:L,2,FALSE),"-") -> - | V112: =+IFERROR(VLOOKUP(CONCATENATE(A112,$F$10,F112),'ID1&5'!B:J,9,FALSE),"-") -> - | W112: =+IFERROR(VLOOKUP(A112,'ID6&7'!A:I,9,FALSE),"-") -> - | X112: =+IFERROR(VLOOKUP(A112,'ID6&7'!A:J,10,FALSE),"-") -> - | Z112: =+IF(J112=0,"Por iniciar",IF(OR(K112="-",M112="-",P112="-",R112="-",T112="-",V112="-"),"Em testes",IF(AND(M112=0,P112=0,R112=0,T112<>K112,V112<>K112),"OK","NOK"))) -> Por iniciar
A113: =+H113&I113&$I$8 -> ENTITYTTL_ASSTS45596 | B113: {=+MAX(IF('ID1&5'!A:A='1. Status'!A113&'1. Status'!$B$10,'ID1&5'!K:K))} -> 0 | C113: {=+MAX(IF('ID1&5'!A:A='1. Status'!A113&'1. Status'!$C$10,'ID1&5'!K:K))} -> 0 | D113: {=+MAX(IF('ID1&5'!A:A='1. Status'!A113&'1. Status'!$D$10,'ID1&5'!K:K))} -> 0 | E113: {=+MAX(IF('ID1&5'!A:A='1. Status'!A113&'1. Status'!$E$10,'ID1&5'!K:K))} -> 0 | F113: {=+MAX(IF('ID1&5'!A:A='1. Status'!A113&'1. Status'!$F$10,'ID1&5'!K:K))} -> 0 | H113: ENTITY | I113: TTL_ASSTS | J113: =+COUNTIF('ID1&5'!G:G,'1. Status'!I113) -> 0 | K113: =+IFERROR(VLOOKUP(CONCATENATE(A113,$B$10,B113),'ID1&5'!B:J,8,FALSE),"-") -> - | L113: =+IFERROR(VLOOKUP(B113,'ID1&5'!K:L,2,FALSE),"-") -> - | M113: =+IFERROR(VLOOKUP(CONCATENATE(A113,$B$10,B113),'ID1&5'!B:J,9,FALSE),"-") -> - | N113: =+IFERROR(VLOOKUP(CONCATENATE(A113,$C$10,C113),'ID1&5'!B:J,8,FALSE),"-") -> - | O113: =+IFERROR(VLOOKUP(C113,'ID1&5'!K:L,2,FALSE),"-") -> - | P113: =+IFERROR(VLOOKUP(CONCATENATE(A113,$C$10,C113),'ID1&5'!B:J,9,FALSE),"-") -> - | Q113: =+IFERROR(VLOOKUP(D113,'ID1&5'!K:L,2,FALSE),"-") -> - | R113: =+IFERROR(VLOOKUP(CONCATENATE(A113,$D$10,D113),'ID1&5'!B:J,9,FALSE),"-") -> - | S113: =+IFERROR(VLOOKUP(E113,'ID1&5'!K:L,2,FALSE),"-") -> - | T113: =+IFERROR(VLOOKUP(CONCATENATE(A113,$E$10,E113),'ID1&5'!B:J,9,FALSE),"-") -> - | U113: =+IFERROR(VLOOKUP(F113,'ID1&5'!K:L,2,FALSE),"-") -> - | V113: =+IFERROR(VLOOKUP(CONCATENATE(A113,$F$10,F113),'ID1&5'!B:J,9,FALSE),"-") -> - | W113: =+IFERROR(VLOOKUP(A113,'ID6&7'!A:I,9,FALSE),"-") -> - | X113: =+IFERROR(VLOOKUP(A113,'ID6&7'!A:J,10,FALSE),"-") -> - | Z113: =+IF(J113=0,"Por iniciar",IF(OR(K113="-",M113="-",P113="-",R113="-",T113="-",V113="-"),"Em testes",IF(AND(M113=0,P113=0,R113=0,T113<>K113,V113<>K113),"OK","NOK"))) -> Por iniciar
A114: =+H114&I114&$I$8 -> ENTITYENTTY_ID_BDR45596 | B114: {=+MAX(IF('ID1&5'!A:A='1. Status'!A114&'1. Status'!$B$10,'ID1&5'!K:K))} -> 0 | C114: {=+MAX(IF('ID1&5'!A:A='1. Status'!A114&'1. Status'!$C$10,'ID1&5'!K:K))} -> 0 | D114: {=+MAX(IF('ID1&5'!A:A='1. Status'!A114&'1. Status'!$D$10,'ID1&5'!K:K))} -> 0 | E114: {=+MAX(IF('ID1&5'!A:A='1. Status'!A114&'1. Status'!$E$10,'ID1&5'!K:K))} -> 0 | F114: {=+MAX(IF('ID1&5'!A:A='1. Status'!A114&'1. Status'!$F$10,'ID1&5'!K:K))} -> 0 | H114: ENTITY | I114: ENTTY_ID_BDR | J114: =+COUNTIF('ID1&5'!G:G,'1. Status'!I114) -> 0 | K114: =+IFERROR(VLOOKUP(CONCATENATE(A114,$B$10,B114),'ID1&5'!B:J,8,FALSE),"-") -> - | L114: =+IFERROR(VLOOKUP(B114,'ID1&5'!K:L,2,FALSE),"-") -> - | M114: =+IFERROR(VLOOKUP(CONCATENATE(A114,$B$10,B114),'ID1&5'!B:J,9,FALSE),"-") -> - | N114: =+IFERROR(VLOOKUP(CONCATENATE(A114,$C$10,C114),'ID1&5'!B:J,8,FALSE),"-") -> - | O114: =+IFERROR(VLOOKUP(C114,'ID1&5'!K:L,2,FALSE),"-") -> - | P114: =+IFERROR(VLOOKUP(CONCATENATE(A114,$C$10,C114),'ID1&5'!B:J,9,FALSE),"-") -> - | Q114: =+IFERROR(VLOOKUP(D114,'ID1&5'!K:L,2,FALSE),"-") -> - | R114: =+IFERROR(VLOOKUP(CONCATENATE(A114,$D$10,D114),'ID1&5'!B:J,9,FALSE),"-") -> - | S114: =+IFERROR(VLOOKUP(E114,'ID1&5'!K:L,2,FALSE),"-") -> - | T114: =+IFERROR(VLOOKUP(CONCATENATE(A114,$E$10,E114),'ID1&5'!B:J,9,FALSE),"-") -> - | U114: =+IFERROR(VLOOKUP(F114,'ID1&5'!K:L,2,FALSE),"-") -> - | V114: =+IFERROR(VLOOKUP(CONCATENATE(A114,$F$10,F114),'ID1&5'!B:J,9,FALSE),"-") -> - | W114: =+IFERROR(VLOOKUP(A114,'ID6&7'!A:I,9,FALSE),"-") -> - | X114: =+IFERROR(VLOOKUP(A114,'ID6&7'!A:J,10,FALSE),"-") -> - | Z114: =+IF(J114=0,"Por iniciar",IF(OR(K114="-",M114="-",P114="-",R114="-",T114="-",V114="-"),"Em testes",IF(AND(M114=0,P114=0,R114=0,T114<>K114,V114<>K114),"OK","NOK"))) -> Por iniciar
A115: =+H115&I115&$I$8 -> INSTR_ENTITYCOD_SOC45596 | B115: {=+MAX(IF('ID1&5'!A:A='1. Status'!A115&'1. Status'!$B$10,'ID1&5'!K:K))} -> 0 | C115: {=+MAX(IF('ID1&5'!A:A='1. Status'!A115&'1. Status'!$C$10,'ID1&5'!K:K))} -> 0 | D115: {=+MAX(IF('ID1&5'!A:A='1. Status'!A115&'1. Status'!$D$10,'ID1&5'!K:K))} -> 0 | E115: {=+MAX(IF('ID1&5'!A:A='1. Status'!A115&'1. Status'!$E$10,'ID1&5'!K:K))} -> 0 | F115: {=+MAX(IF('ID1&5'!A:A='1. Status'!A115&'1. Status'!$F$10,'ID1&5'!K:K))} -> 0 | H115: INSTR_ENTITY | I115: COD_SOC | J115: =+COUNTIF('ID1&5'!G:G,'1. Status'!I115) -> 0 | K115: =+IFERROR(VLOOKUP(CONCATENATE(A115,$B$10,B115),'ID1&5'!B:J,8,FALSE),"-") -> - | L115: =+IFERROR(VLOOKUP(B115,'ID1&5'!K:L,2,FALSE),"-") -> - | M115: =+IFERROR(VLOOKUP(CONCATENATE(A115,$B$10,B115),'ID1&5'!B:J,9,FALSE),"-") -> - | N115: =+IFERROR(VLOOKUP(CONCATENATE(A115,$C$10,C115),'ID1&5'!B:J,8,FALSE),"-") -> - | O115: =+IFERROR(VLOOKUP(C115,'ID1&5'!K:L,2,FALSE),"-") -> - | P115: =+IFERROR(VLOOKUP(CONCATENATE(A115,$C$10,C115),'ID1&5'!B:J,9,FALSE),"-") -> - | Q115: =+IFERROR(VLOOKUP(D115,'ID1&5'!K:L,2,FALSE),"-") -> - | R115: =+IFERROR(VLOOKUP(CONCATENATE(A115,$D$10,D115),'ID1&5'!B:J,9,FALSE),"-") -> - | S115: =+IFERROR(VLOOKUP(E115,'ID1&5'!K:L,2,FALSE),"-") -> - | T115: =+IFERROR(VLOOKUP(CONCATENATE(A115,$E$10,E115),'ID1&5'!B:J,9,FALSE),"-") -> - | U115: =+IFERROR(VLOOKUP(F115,'ID1&5'!K:L,2,FALSE),"-") -> - | V115: =+IFERROR(VLOOKUP(CONCATENATE(A115,$F$10,F115),'ID1&5'!B:J,9,FALSE),"-") -> - | W115: =+IFERROR(VLOOKUP(A115,'ID6&7'!A:I,9,FALSE),"-") -> - | X115: =+IFERROR(VLOOKUP(A115,'ID6&7'!A:J,10,FALSE),"-") -> - | Z115: =+IF(J115=0,"Por iniciar",IF(OR(K115="-",M115="-",P115="-",R115="-",T115="-",V115="-"),"Em testes",IF(AND(M115=0,P115=0,R115=0,T115<>K115,V115<>K115),"OK","NOK"))) -> Por iniciar
A116: =+H116&I116&$I$8 -> INSTR_ENTITYJNT_LBLTY_AMNT45596 | B116: {=+MAX(IF('ID1&5'!A:A='1. Status'!A116&'1. Status'!$B$10,'ID1&5'!K:K))} -> 0 | C116: {=+MAX(IF('ID1&5'!A:A='1. Status'!A116&'1. Status'!$C$10,'ID1&5'!K:K))} -> 0 | D116: {=+MAX(IF('ID1&5'!A:A='1. Status'!A116&'1. Status'!$D$10,'ID1&5'!K:K))} -> 0 | E116: {=+MAX(IF('ID1&5'!A:A='1. Status'!A116&'1. Status'!$E$10,'ID1&5'!K:K))} -> 0 | F116: {=+MAX(IF('ID1&5'!A:A='1. Status'!A116&'1. Status'!$F$10,'ID1&5'!K:K))} -> 0 | H116: INSTR_ENTITY | I116: JNT_LBLTY_AMNT | J116: =+COUNTIF('ID1&5'!G:G,'1. Status'!I116) -> 0 | K116: =+IFERROR(VLOOKUP(CONCATENATE(A116,$B$10,B116),'ID1&5'!B:J,8,FALSE),"-") -> - | L116: =+IFERROR(VLOOKUP(B116,'ID1&5'!K:L,2,FALSE),"-") -> - | M116: =+IFERROR(VLOOKUP(CONCATENATE(A116,$B$10,B116),'ID1&5'!B:J,9,FALSE),"-") -> - | N116: =+IFERROR(VLOOKUP(CONCATENATE(A116,$C$10,C116),'ID1&5'!B:J,8,FALSE),"-") -> - | O116: =+IFERROR(VLOOKUP(C116,'ID1&5'!K:L,2,FALSE),"-") -> - | P116: =+IFERROR(VLOOKUP(CONCATENATE(A116,$C$10,C116),'ID1&5'!B:J,9,FALSE),"-") -> - | Q116: =+IFERROR(VLOOKUP(D116,'ID1&5'!K:L,2,FALSE),"-") -> - | R116: =+IFERROR(VLOOKUP(CONCATENATE(A116,$D$10,D116),'ID1&5'!B:J,9,FALSE),"-") -> - | S116: =+IFERROR(VLOOKUP(E116,'ID1&5'!K:L,2,FALSE),"-") -> - | T116: =+IFERROR(VLOOKUP(CONCATENATE(A116,$E$10,E116),'ID1&5'!B:J,9,FALSE),"-") -> - | U116: =+IFERROR(VLOOKUP(F116,'ID1&5'!K:L,2,FALSE),"-") -> - | V116: =+IFERROR(VLOOKUP(CONCATENATE(A116,$F$10,F116),'ID1&5'!B:J,9,FALSE),"-") -> - | W116: =+IFERROR(VLOOKUP(A116,'ID6&7'!A:I,9,FALSE),"-") -> - | X116: =+IFERROR(VLOOKUP(A116,'ID6&7'!A:J,10,FALSE),"-") -> - | Z116: =+IF(J116=0,"Por iniciar",IF(OR(K116="-",M116="-",P116="-",R116="-",T116="-",V116="-"),"Em testes",IF(AND(M116=0,P116=0,R116=0,T116<>K116,V116<>K116),"OK","NOK"))) -> Por iniciar
A117: =+H117&I117&$I$8 -> INSTR_ENTITYMN_ENTTY_ID45596 | B117: {=+MAX(IF('ID1&5'!A:A='1. Status'!A117&'1. Status'!$B$10,'ID1&5'!K:K))} -> 0 | C117: {=+MAX(IF('ID1&5'!A:A='1. Status'!A117&'1. Status'!$C$10,'ID1&5'!K:K))} -> 0 | D117: {=+MAX(IF('ID1&5'!A:A='1. Status'!A117&'1. Status'!$D$10,'ID1&5'!K:K))} -> 0 | E117: {=+MAX(IF('ID1&5'!A:A='1. Status'!A117&'1. Status'!$E$10,'ID1&5'!K:K))} -> 0 | F117: {=+MAX(IF('ID1&5'!A:A='1. Status'!A117&'1. Status'!$F$10,'ID1&5'!K:K))} -> 0 | H117: INSTR_ENTITY | I117: MN_ENTTY_ID | J117: =+COUNTIF('ID1&5'!G:G,'1. Status'!I117) -> 0 | K117: =+IFERROR(VLOOKUP(CONCATENATE(A117,$B$10,B117),'ID1&5'!B:J,8,FALSE),"-") -> - | L117: =+IFERROR(VLOOKUP(B117,'ID1&5'!K:L,2,FALSE),"-") -> - | M117: =+IFERROR(VLOOKUP(CONCATENATE(A117,$B$10,B117),'ID1&5'!B:J,9,FALSE),"-") -> - | N117: =+IFERROR(VLOOKUP(CONCATENATE(A117,$C$10,C117),'ID1&5'!B:J,8,FALSE),"-") -> - | O117: =+IFERROR(VLOOKUP(C117,'ID1&5'!K:L,2,FALSE),"-") -> - | P117: =+IFERROR(VLOOKUP(CONCATENATE(A117,$C$10,C117),'ID1&5'!B:J,9,FALSE),"-") -> - | Q117: =+IFERROR(VLOOKUP(D117,'ID1&5'!K:L,2,FALSE),"-") -> - | R117: =+IFERROR(VLOOKUP(CONCATENATE(A117,$D$10,D117),'ID1&5'!B:J,9,FALSE),"-") -> - | S117: =+IFERROR(VLOOKUP(E117,'ID1&5'!K:L,2,FALSE),"-") -> - | T117: =+IFERROR(VLOOKUP(CONCATENATE(A117,$E$10,E117),'ID1&5'!B:J,9,FALSE),"-") -> - | U117: =+IFERROR(VLOOKUP(F117,'ID1&5'!K:L,2,FALSE),"-") -> - | V117: =+IFERROR(VLOOKUP(CONCATENATE(A117,$F$10,F117),'ID1&5'!B:J,9,FALSE),"-") -> - | W117: =+IFERROR(VLOOKUP(A117,'ID6&7'!A:I,9,FALSE),"-") -> - | X117: =+IFERROR(VLOOKUP(A117,'ID6&7'!A:J,10,FALSE),"-") -> - | Z117: =+IF(J117=0,"Por iniciar",IF(OR(K117="-",M117="-",P117="-",R117="-",T117="-",V117="-"),"Em testes",IF(AND(M117=0,P117=0,R117=0,T117<>K117,V117<>K117),"OK","NOK"))) -> Por iniciar
A118: =+H118&I118&$I$8 -> INSTRUMENTCOD_SOC45596 | B118: {=+MAX(IF('ID1&5'!A:A='1. Status'!A118&'1. Status'!$B$10,'ID1&5'!K:K))} -> 0 | C118: {=+MAX(IF('ID1&5'!A:A='1. Status'!A118&'1. Status'!$C$10,'ID1&5'!K:K))} -> 0 | D118: {=+MAX(IF('ID1&5'!A:A='1. Status'!A118&'1. Status'!$D$10,'ID1&5'!K:K))} -> 0 | E118: {=+MAX(IF('ID1&5'!A:A='1. Status'!A118&'1. Status'!$E$10,'ID1&5'!K:K))} -> 0 | F118: {=+MAX(IF('ID1&5'!A:A='1. Status'!A118&'1. Status'!$F$10,'ID1&5'!K:K))} -> 0 | H118: INSTRUMENT | I118: COD_SOC | J118: =+COUNTIF('ID1&5'!G:G,'1. Status'!I118) -> 0 | K118: =+IFERROR(VLOOKUP(CONCATENATE(A118,$B$10,B118),'ID1&5'!B:J,8,FALSE),"-") -> - | L118: =+IFERROR(VLOOKUP(B118,'ID1&5'!K:L,2,FALSE),"-") -> - | M118: =+IFERROR(VLOOKUP(CONCATENATE(A118,$B$10,B118),'ID1&5'!B:J,9,FALSE),"-") -> - | N118: =+IFERROR(VLOOKUP(CONCATENATE(A118,$C$10,C118),'ID1&5'!B:J,8,FALSE),"-") -> - | O118: =+IFERROR(VLOOKUP(C118,'ID1&5'!K:L,2,FALSE),"-") -> - | P118: =+IFERROR(VLOOKUP(CONCATENATE(A118,$C$10,C118),'ID1&5'!B:J,9,FALSE),"-") -> - | Q118: =+IFERROR(VLOOKUP(D118,'ID1&5'!K:L,2,FALSE),"-") -> - | R118: =+IFERROR(VLOOKUP(CONCATENATE(A118,$D$10,D118),'ID1&5'!B:J,9,FALSE),"-") -> - | S118: =+IFERROR(VLOOKUP(E118,'ID1&5'!K:L,2,FALSE),"-") -> - | T118: =+IFERROR(VLOOKUP(CONCATENATE(A118,$E$10,E118),'ID1&5'!B:J,9,FALSE),"-") -> - | U118: =+IFERROR(VLOOKUP(F118,'ID1&5'!K:L,2,FALSE),"-") -> - | V118: =+IFERROR(VLOOKUP(CONCATENATE(A118,$F$10,F118),'ID1&5'!B:J,9,FALSE),"-") -> - | W118: =+IFERROR(VLOOKUP(A118,'ID6&7'!A:I,9,FALSE),"-") -> - | X118: =+IFERROR(VLOOKUP(A118,'ID6&7'!A:J,10,FALSE),"-") -> - | Z118: =+IF(J118=0,"Por iniciar",IF(OR(K118="-",M118="-",P118="-",R118="-",T118="-",V118="-"),"Em testes",IF(AND(M118=0,P118=0,R118=0,T118<>K118,V118<>K118),"OK","NOK"))) -> Por iniciar
A119: =+H119&I119&$I$8 -> INSTRUMENTSUBPORTFOLIO_ID45596 | B119: {=+MAX(IF('ID1&5'!A:A='1. Status'!A119&'1. Status'!$B$10,'ID1&5'!K:K))} -> 0 | C119: {=+MAX(IF('ID1&5'!A:A='1. Status'!A119&'1. Status'!$C$10,'ID1&5'!K:K))} -> 0 | D119: {=+MAX(IF('ID1&5'!A:A='1. Status'!A119&'1. Status'!$D$10,'ID1&5'!K:K))} -> 0 | E119: {=+MAX(IF('ID1&5'!A:A='1. Status'!A119&'1. Status'!$E$10,'ID1&5'!K:K))} -> 0 | F119: {=+MAX(IF('ID1&5'!A:A='1. Status'!A119&'1. Status'!$F$10,'ID1&5'!K:K))} -> 0 | H119: INSTRUMENT | I119: SUBPORTFOLIO_ID | J119: =+COUNTIF('ID1&5'!G:G,'1. Status'!I119) -> 0 | K119: =+IFERROR(VLOOKUP(CONCATENATE(A119,$B$10,B119),'ID1&5'!B:J,8,FALSE),"-") -> - | L119: =+IFERROR(VLOOKUP(B119,'ID1&5'!K:L,2,FALSE),"-") -> - | M119: =+IFERROR(VLOOKUP(CONCATENATE(A119,$B$10,B119),'ID1&5'!B:J,9,FALSE),"-") -> - | N119: =+IFERROR(VLOOKUP(CONCATENATE(A119,$C$10,C119),'ID1&5'!B:J,8,FALSE),"-") -> - | O119: =+IFERROR(VLOOKUP(C119,'ID1&5'!K:L,2,FALSE),"-") -> - | P119: =+IFERROR(VLOOKUP(CONCATENATE(A119,$C$10,C119),'ID1&5'!B:J,9,FALSE),"-") -> - | Q119: =+IFERROR(VLOOKUP(D119,'ID1&5'!K:L,2,FALSE),"-") -> - | R119: =+IFERROR(VLOOKUP(CONCATENATE(A119,$D$10,D119),'ID1&5'!B:J,9,FALSE),"-") -> - | S119: =+IFERROR(VLOOKUP(E119,'ID1&5'!K:L,2,FALSE),"-") -> - | T119: =+IFERROR(VLOOKUP(CONCATENATE(A119,$E$10,E119),'ID1&5'!B:J,9,FALSE),"-") -> - | U119: =+IFERROR(VLOOKUP(F119,'ID1&5'!K:L,2,FALSE),"-") -> - | V119: =+IFERROR(VLOOKUP(CONCATENATE(A119,$F$10,F119),'ID1&5'!B:J,9,FALSE),"-") -> - | W119: =+IFERROR(VLOOKUP(A119,'ID6&7'!A:I,9,FALSE),"-") -> - | X119: =+IFERROR(VLOOKUP(A119,'ID6&7'!A:J,10,FALSE),"-") -> - | Z119: =+IF(J119=0,"Por iniciar",IF(OR(K119="-",M119="-",P119="-",R119="-",T119="-",V119="-"),"Em testes",IF(AND(M119=0,P119=0,R119=0,T119<>K119,V119<>K119),"OK","NOK"))) -> Por iniciar
...

Sheet 2. Script 
B6: 2. Script de Controlos
B8: TABELA | C8: TIPOLOGIA_TESTE | D8: TABELA_LT_PILAR3 | E8: TABELA_SIMUL | F8: CAMPO | G8: FORMATO CAMPO | H8: VALORES CODE LIST | I8: UNIVERSO_PILAR3 | J8: UNIVERSO_SIMUL | K8: CRUZAMENTO | L8: QUERY 1 | M8: UNION ALL
