Workbook
Name BM: #REF!
Name BM: #REF!
Name BM: #REF!
Name BM: #REF!
Name BM: #REF!
Name IQ_CH: 110000
Name IQ_CQ: 5000
Name IQ_CY: 10000
Name IQ_DAILY: 500000
Name IQ_FH: 100000
Name IQ_FQ: 500
Name IQ_FY: 1000
Name IQ_LTM: 2000
Name IQ_MONTH: 15000
Name IQ_NTM: 6000
Name IQ_WEEK: 50000
Name IQ_YTD: 3000

Sheet Comparativos granulares_R01
B8: Métrica | C8: Casuística | D8: Δ Montante vs Tático Dez24
B9: Cod_nace_esg | C9: Alteração da reclassificação do código NACE | D9: 14634847
B10: D | C10: Antes era M agora é D | D10: 7919081.7
C11: Antes era F agora é D | D11: 195750.68
B12: F | C12: Antes era I agora é F | D12: -100477.12
B13: H | C13: Antes era C agora é H | D13: 3138023.4
C14: Antes era M agora é H | D14: 604591.52
B15: K | C15: Antes era Q agora é K | D15: 20657.3
C16: Antes era G agora é K | D16: 183.45
C17: Antes era S agora é K | D17: 7106.64
C18: Antes era F agora é K | D18: 104970
B19: L | C19: Antes era I agora é L | D19: 2744959.2

Sheet Comparativos granulares_R04
B8: Métrica | C8: Casuística | D8: Δ Montante vs Tático Dez24
B9: Cod_nace_esg | C9: Alteração da reclassificação do código NACE | D9: 1673043.2
B10: A | C10: Antes era L agora é A | D10: 397.09
B11: C | C11: Antes era L agora é C | D11: 189.6
C12: Antes era A agora é C | D12: 142.9
C13: Antes era G agora é C | D13: 1885.77
B14: D | C14: Antes era M agora é D | D14: 17560.9
C15: Antes era F agora é D | D15: 785.37
C16: Antes era I agora é D | D16: 14568.24
B17: F | C17: Antes era M agora é F | D17: 496.75
C18: Antes era I agora é F | D18: 0
C19: Antes era E agora é F | D19: 204
C20: Antes era G agora é F | D20: 137.66
C21: Antes era L agora é F | D21: 485.1
B22: G | C22: Antes era A agora é G | D22: 207.38
C23: Antes era I agora é G | D23: 110.6
C24: Antes era C agora é G | D24: 1271.53
B25: H | C25: Antes era S agora é H | D25: 2007.77
C26: Antes era C agora é H | D26: 205033.53
B27: J | C27: Antes era F agora é J | D27: 668.6
B28: K | C28: Antes era Q agora é K | D28: 1204.01
C29: Antes era N agora é K | D29: 26640.97
C30: Antes era C agora é K | D30: 18712.54
C31: Antes era I agora é K | D31: 282.4
C32: Antes era G agora é K | D32: 348.88
C33: Antes era H agora é K | D33: 351.5
C34: Antes era A agora é K | D34: 575.11
C35: Antes era J agora é K | D35: 692.26
C36: Antes era S agora é K | D36: 34145.29
C37: Antes era F agora é K | D37: 5325.19
C38: Antes era D agora é K | D38: 0
C39: Antes era M agora é K | D39: 2090.84
C40: Antes era L agora é K | D40: 6031.39
B41: L | C41: Antes era H agora é L | D41: 189.6
C42: Antes era I agora é L | D42: 1015630.1
C43: Antes era F agora é L | D43: 123803.54
B44: M | C44: Antes era H agora é M | D44: 187978.83
C45: Antes era G agora é M | D45: 160.08
C46: Antes era C agora é M | D46: 189.6
C47: Antes era N agora é M | D47: 688.3
...

Sheet Variação Absoluta
C8: EU1 | L8: EU2
C9: Exposição | F9: Exposição R01 | I9: Exposição R04 | L9: Exposição | O9: Exposição R01 | R9: Exposição R04
B10: NACEs | C10: Dez24 Estrutural | D10: Dez24 Tático | E10: ∆ | F10: Dez24 Estrutural | G10: Dez24 Tático | H10: ∆ | I10: Dez24 Estrutural | J10: Dez24 Tático | K10: ∆ | L10: Dez24 Estrutural | M10: Dez24 Tático | N10: ∆ | O10: Dez24 Estrutural | P10: Dez24 Tático | Q10: ∆ | R10: Dez24 Estrutural | S10: Dez24 Tático | T10: ∆
B11: A - Agriculture, forestry and fishing | C11: =Paralelo!D8 -> 331599460 | D11: ='Dez24'!D8 -> 331599441 | E11: =C11-D11 -> 19 | F11: =Paralelo!E8 -> 15687251 | G11: ='Dez24'!E8 -> 15710968 | H11: =F11-G11 -> -23717 | I11: =Paralelo!F8 -> 2437101 | J11: ='Dez24'!F8 -> 2437629 | K11: =I11-J11 -> -528 | L11: =Paralelo!J8 -> 0 | M11: ='Dez24'!J8 -> 0 | N11: =L11-M11 -> 0 | O11: =Paralelo!K8 -> 0 | P11: ='Dez24'!K8 -> 0 | Q11: =O11-P11 -> 0 | R11: =Paralelo!L8 -> 297 | S11: ='Dez24'!L8 -> 297 | T11: =R11-S11 -> 0
B12: B - Mining and quarrying | C12: =Paralelo!D9 -> 14172404 | D12: ='Dez24'!D9 -> 14172372 | E12: =C12-D12 -> 32 | F12: =Paralelo!E9 -> 752507 | G12: ='Dez24'!E9 -> 754361 | H12: =F12-G12 -> -1854 | I12: =Paralelo!F9 -> 446416 | J12: ='Dez24'!F9 -> 446416 | K12: =I12-J12 -> 0 | L12: =Paralelo!J9 -> 0 | M12: ='Dez24'!J9 -> 0 | N12: =L12-M12 -> 0 | O12: =Paralelo!K9 -> 0 | P12: ='Dez24'!K9 -> 0 | Q12: =O12-P12 -> 0 | R12: =Paralelo!L9 -> 6028 | S12: ='Dez24'!L9 -> 6028 | T12: =R12-S12 -> 0
B13: B.05 - Mining of coal and lignite | C13: =Paralelo!D10 -> 0 | D13: ='Dez24'!D10 -> 0 | E13: =C13-D13 -> 0 | F13: =Paralelo!E10 -> 0 | G13: ='Dez24'!E10 -> 0 | H13: =F13-G13 -> 0 | I13: =Paralelo!F10 -> 0 | J13: ='Dez24'!F10 -> 0 | K13: =I13-J13 -> 0 | L13: =Paralelo!J10 -> 0 | M13: ='Dez24'!J10 -> 0 | N13: =L13-M13 -> 0 | O13: =Paralelo!K10 -> 0 | P13: ='Dez24'!K10 -> 0 | Q13: =O13-P13 -> 0 | R13: =Paralelo!L10 -> 0 | S13: ='Dez24'!L10 -> 0 | T13: =R13-S13 -> 0
B14: B.06 - Extraction of crude petroleum and natural gas | C14: =Paralelo!D11 -> 0 | D14: ='Dez24'!D11 -> 0 | E14: =C14-D14 -> 0 | F14: =Paralelo!E11 -> 0 | G14: ='Dez24'!E11 -> 0 | H14: =F14-G14 -> 0 | I14: =Paralelo!F11 -> 190 | J14: ='Dez24'!F11 -> 190 | K14: =I14-J14 -> 0 | L14: =Paralelo!J11 -> 0 | M14: ='Dez24'!J11 -> 0 | N14: =L14-M14 -> 0 | O14: =Paralelo!K11 -> 0 | P14: ='Dez24'!K11 -> 0 | Q14: =O14-P14 -> 0 | R14: =Paralelo!L11 -> 6028 | S14: ='Dez24'!L11 -> 6028 | T14: =R14-S14 -> 0
B15: B.07 - Mining of metal ores | C15: =Paralelo!D12 -> 141472 | D15: ='Dez24'!D12 -> 141471 | E15: =C15-D15 -> 1 | F15: =Paralelo!E12 -> 34428 | G15: ='Dez24'!E12 -> 34264 | H15: =F15-G15 -> 164 | I15: =Paralelo!F12 -> 41958 | J15: ='Dez24'!F12 -> 41958 | K15: =I15-J15 -> 0 | L15: =Paralelo!J12 -> 0 | M15: ='Dez24'!J12 -> 0 | N15: =L15-M15 -> 0 | O15: =Paralelo!K12 -> 0 | P15: ='Dez24'!K12 -> 0 | Q15: =O15-P15 -> 0 | R15: =Paralelo!L12 -> 0 | S15: ='Dez24'!L12 -> 0 | T15: =R15-S15 -> 0
B16: B.08 - Other mining and quarrying | C16: =Paralelo!D13 -> 13954368 | D16: ='Dez24'!D13 -> 13954338 | E16: =C16-D16 -> 30 | F16: =Paralelo!E13 -> 707631 | G16: ='Dez24'!E13 -> 709641 | H16: =F16-G16 -> -2010 | I16: =Paralelo!F13 -> 400421 | J16: ='Dez24'!F13 -> 400421 | K16: =I16-J16 -> 0 | L16: =Paralelo!J13 -> 0 | M16: ='Dez24'!J13 -> 0 | N16: =L16-M16 -> 0 | O16: =Paralelo!K13 -> 0 | P16: ='Dez24'!K13 -> 0 | Q16: =O16-P16 -> 0 | R16: =Paralelo!L13 -> 0 | S16: ='Dez24'!L13 -> 0 | T16: =R16-S16 -> 0
B17: B.09 - Mining support service activities | C17: =Paralelo!D14 -> 76564 | D17: ='Dez24'!D14 -> 76563 | E17: =C17-D17 -> 1 | F17: =Paralelo!E14 -> 10448 | G17: ='Dez24'!E14 -> 10456 | H17: =F17-G17 -> -8 | I17: =Paralelo!F14 -> 3847 | J17: ='Dez24'!F14 -> 3847 | K17: =I17-J17 -> 0 | L17: =Paralelo!J14 -> 0 | M17: ='Dez24'!J14 -> 0 | N17: =L17-M17 -> 0 | O17: =Paralelo!K14 -> 0 | P17: ='Dez24'!K14 -> 0 | Q17: =O17-P17 -> 0 | R17: =Paralelo!L14 -> 0 | S17: ='Dez24'!L14 -> 0 | T17: =R17-S17 -> 0
B18: C - Manufacturing | C18: =Paralelo!D15 -> 2162719946 | D18: ='Dez24'!D15 -> 2220273775 | E18: =C18-D18 -> -57553829 | F18: =Paralelo!E15 -> 111890711 | G18: ='Dez24'!E15 -> 115470868 | H18: =F18-G18 -> -3580157 | I18: =Paralelo!F15 -> 17581811 | J18: ='Dez24'!F15 -> 17804799 | K18: =I18-J18 -> -222988 | L18: =Paralelo!J15 -> 0 | M18: ='Dez24'!J15 -> 0 | N18: =L18-M18 -> 0 | O18: =Paralelo!K15 -> 261587 | P18: ='Dez24'!K15 -> 261587 | Q18: =O18-P18 -> 0 | R18: =Paralelo!L15 -> 39804 | S18: ='Dez24'!L15 -> 39804 | T18: =R18-S18 -> 0
B19: C.10 - Manufacture of food products | C19: =Paralelo!D16 -> 336423701 | D19: ='Dez24'!D16 -> 336423698 | E19: =C19-D19 -> 3 | F19: =Paralelo!E16 -> 15965449 | G19: ='Dez24'!E16 -> 16021606 | H19: =F19-G19 -> -56157 | I19: =Paralelo!F16 -> 2211995 | J19: ='Dez24'!F16 -> 2209965 | K19: =I19-J19 -> 2030 | L19: =Paralelo!J16 -> 0 | M19: ='Dez24'!J16 -> 0 | N19: =L19-M19 -> 0 | O19: =Paralelo!K16 -> 194616 | P19: ='Dez24'!K16 -> 194616 | Q19: =O19-P19 -> 0 | R19: =Paralelo!L16 -> 1899 | S19: ='Dez24'!L16 -> 1899 | T19: =R19-S19 -> 0
B20: C.11 - Manufacture of beverages | C20: =Paralelo!D17 -> 217522093 | D20: ='Dez24'!D17 -> 217522088 | E20: =C20-D20 -> 5 | F20: =Paralelo!E17 -> 10741445 | G20: ='Dez24'!E17 -> 10764705 | H20: =F20-G20 -> -23260 | I20: =Paralelo!F17 -> 1264338 | J20: ='Dez24'!F17 -> 1264338 | K20: =I20-J20 -> 0 | L20: =Paralelo!J17 -> 0 | M20: ='Dez24'!J17 -> 0 | N20: =L20-M20 -> 0 | O20: =Paralelo!K17 -> 0 | P20: ='Dez24'!K17 -> 0 | Q20: =O20-P20 -> 0 | R20: =Paralelo!L17 -> 0 | S20: ='Dez24'!L17 -> 0 | T20: =R20-S20 -> 0
B21: C.12 - Manufacture of tobacco products | C21: =Paralelo!D18 -> 2924771 | D21: ='Dez24'!D18 -> 2924771 | E21: =C21-D21 -> 0 | F21: =Paralelo!E18 -> 128825 | G21: ='Dez24'!E18 -> 128825 | H21: =F21-G21 -> 0 | I21: =Paralelo!F18 -> 15487 | J21: ='Dez24'!F18 -> 15487 | K21: =I21-J21 -> 0 | L21: =Paralelo!J18 -> 0 | M21: ='Dez24'!J18 -> 0 | N21: =L21-M21 -> 0 | O21: =Paralelo!K18 -> 0 | P21: ='Dez24'!K18 -> 0 | Q21: =O21-P21 -> 0 | R21: =Paralelo!L18 -> 0 | S21: ='Dez24'!L18 -> 0 | T21: =R21-S21 -> 0
B22: C.13 - Manufacture of textiles | C22: =Paralelo!D19 -> 112288974 | D22: ='Dez24'!D19 -> 112288971 | E22: =C22-D22 -> 3 | F22: =Paralelo!E19 -> 5711850 | G22: ='Dez24'!E19 -> 5728198 | H22: =F22-G22 -> -16348 | I22: =Paralelo!F19 -> 854236 | J22: ='Dez24'!F19 -> 854047 | K22: =I22-J22 -> 189 | L22: =Paralelo!J19 -> 0 | M22: ='Dez24'!J19 -> 0 | N22: =L22-M22 -> 0 | O22: =Paralelo!K19 -> 0 | P22: ='Dez24'!K19 -> 0 | Q22: =O22-P22 -> 0 | R22: =Paralelo!L19 -> 0 | S22: ='Dez24'!L19 -> 0 | T22: =R22-S22 -> 0
... B61: L - Real estate activities | C61: =Paralelo!D58 -> 1166127334 | D61: ='Dez24'!D58 -> 1116120857 | E61: =C61-D61 -> 50006477 | F61: =Paralelo!E58 -> 59513748 | G61: ='Dez24'!E58 -> 56882565 | H61: =F61-G61 -> 2631183 | I61: =Paralelo!F58 -> 11305686 | J61: ='Dez24'!F58 -> 10173166 | K61: =I61-J61 -> 1132520 | L61: =Paralelo!J58 -> 0 | M61: ='Dez24'!J58 -> 0 | N61: =L61-M61 -> 0 | O61: =Paralelo!K58 -> 3054 | P61: ='Dez24'!K58 -> 3054 | Q61: =O61-P61 -> 0 | R61: =Paralelo!L58 -> 3410 | S61: ='Dez24'!L58 -> 3410 | T61: =R61-S61 -> 0
B62: K - Financial and insurance activities | C62: =Paralelo!D60 -> 8716736 | D62: ='Dez24'!D60 -> 4114667 | E62: =C62-D62 -> 4602069 | F62: =Paralelo!E60 -> 205346 | G62: ='Dez24'!E60 -> 72508 | H62: =F62-G62 -> 132838 | I62: =Paralelo!F60 -> 798598 | J62: ='Dez24'!F60 -> 704794 | K62: =I62-J62 -> 93804 | L62: =Paralelo!J60 -> 0 | M62: ='Dez24'!J60 -> 0 | N62: =L62-M62 -> 0 | O62: =Paralelo!K60 -> 331 | P62: ='Dez24'!K60 -> 324 | Q62: =O62-P62 -> 7 | R62: =Paralelo!L60 -> 84610 | S62: ='Dez24'!L60 -> 82015 | T62: =R62-S62 -> 2595
B63: Exposures to other sectors (NACE codes J, M - U) | C63: =Paralelo!D61 -> 2818570812 | D63: ='Dez24'!D61 -> 2967217545 | E63: =C63-D63 -> -148646733 | F63: =Paralelo!E61 -> 118059432 | G63: ='Dez24'!E61 -> 126885534 | H63: =F63-G63 -> -8826102 | I63: =Paralelo!F61 -> 37490429 | J63: ='Dez24'!F61 -> 37385637 | K63: =I63-J63 -> 104792 | L63: =Paralelo!J61 -> 0 | M63: ='Dez24'!J61 -> 0 | N63: =L63-M63 -> 0 | O63: =Paralelo!K61 -> 1208567 | P63: ='Dez24'!K61 -> 1208772 | Q63: =O63-P63 -> -205 | R63: =Paralelo!L61 -> 44423 | S63: ='Dez24'!L61 -> 46907 | T63: =R63-S63 -> -2484
B64: TOTAL | C64: =Paralelo!D62 -> 12241903690 | D64: ='Dez24'!D62 -> 12241935469 | E64: =C64-D64 -> -31779 | F64: =Paralelo!E62 -> 572060212 | G64: ='Dez24'!E62 -> 573541486 | H64: =F64-G64 -> -1481274 | I64: =Paralelo!F62 -> 145733170 | J64: ='Dez24'!F62 -> 145734929 | K64: =I64-J64 -> -1759 | L64: =Paralelo!J62 -> 0 | M64: ='Dez24'!J62 -> 0 | N64: =L64-M64 -> 0 | O64: =Paralelo!K62 -> 1563975 | P64: ='Dez24'!K62 -> 1564836 | Q64: =O64-P64 -> -861 | R64: =Paralelo!L62 -> 304348 | S64: ='Dez24'!L62 -> 304441 | T64: =R64-S64 -> -93

Sheet Input >>

Sheet Paralelo
C2: Template 1: Banking book - Climate Change transition risk: Interest income of exposures by sector and emissions
C3: Sector/subsector | D3: EU area | J3: Non-EU area
D4: Gross carrying amount (thousand euro) | E4: Gross interest income (thousand euro) | F4: Gross fee and commission income (thousand euro) | G4: GHG financed emissions (scope 1, scope 2 and scope 3 emissions of the counterparty) (in tons of CO2 equivalent) | J4: Gross carrying amount (thousand euro) | K4: Gross interest income (thousand euro) | L4: Gross fee and commission income (thousand euro) | M4: GHG financed emissions (scope 1, scope 2 and scope 3 emissions of the counterparty) (in tons of CO2 equivalent)
H5: Of which Scope 1 financed emissions | I5: Of which Scope 2 financed emissions | N5: Of which Scope 1 financed emissions | O5: Of which Scope 2 financed emissions
D6: 010 | E6: 020 | F6: 030 | G6: 040 | H6: 050 | I6: 060 | J6: 070 | K6: 080 | L6: 090 | M6: 100 | N6: 110 | O6: 120
B7: 1 | C7: Exposures towards sectors that highly contribute to climate change* | D7: 9414616142 | E7: 453795434 | F7: 107444143 | G7: 84082430 | H7: 60855478 | I7: 3210961 | K7: 355077 | L7: 175315 | M7: 496768 | N7: 21276 | O7: 78667
B8: 2 | C8: A - Agriculture, forestry and fishing | D8: 331599460 | E8: 15687251 | F8: 2437101 | G8: 2659813 | H8: 2289670 | I8: 70365 | K8: 0 | L8: 297 | M8: 0 | N8: 0 | O8: 0
B9: 3 | C9: B - Mining and quarrying | D9: 14172404 | E9: 752507 | F9: 446416 | G9: 441276 | H9: 412784 | I9: 22041 | K9: 0 | L9: 6028 | M9: 0 | N9: 0 | O9: 0
B10: 4 | C10: B.05 - Mining of coal and lignite | D10: 0 | E10: 0 | F10: 0 | G10: 0 | H10: 0 | I10: 0 | K10: 0 | L10: 0 | M10: 0 | N10: 0 | O10: 0
B11: 5 | C11: B.06 - Extraction of crude petroleum and natural gas | D11: 0 | E11: 0 | F11: 190 | G11: 0 | H11: 0 | I11: 0 | K11: 0 | L11: 6028 | M11: 0 | N11: 0 | O11: 0
B12: 6 | C12: B.07 - Mining of metal ores | D12: 141472 | E12: 34428 | F12: 41958 | G12: 87 | H12: 49 | I12: 6 | K12: 0 | L12: 0 | M12: 0 | N12: 0 | O12: 0
B13: 7 | C13: B.08 - Other mining and quarrying | D13: 13954368 | E13: 707631 | F13: 400421 | G13: 441139 | H13: 412706 | I13: 22032 | K13: 0 | L13: 0 | M13: 0 | N13: 0 | O13: 0
B14: 8 | C14: B.09 - Mining support service activities | D14: 76564 | E14: 10448 | F14: 3847 | G14: 50 | H14: 28 | I14: 3 | K14: 0 | L14: 0 | M14: 0 | N14: 0 | O14: 0
B15: 9 | C15: C - Manufacturing | D15: 2162719946 | E15: 111890711 | F15: 17581811 | G15: 6930193 | H15: 3700751 | I15: 435977 | K15: 261587 | L15: 39804 | M15: 496738 | N15: 21271 | O15: 78661
B16: 10 | C16: C.10 - Manufacture of food products | D16: 336423701 | E16: 15965449 | F16: 2211995 | G16: 2102666 | H16: 574252 | I16: 96073 | K16: 194616 | L16: 1899 | M16: 493383 | N16: 21252 | O16: 78645
B17: 11 | C17: C.11 - Manufacture of beverages | D17: 217522093 | E17: 10741445 | F17: 1264338 | G17: 99889 | H17: 39064 | I17: 4861 | K17: 0 | L17: 0 | M17: 0 | N17: 0 | O17: 0
B18: 12 | C18: C.12 - Manufacture of tobacco products | D18: 2924771 | E18: 128825 | F18: 15487 | G18: 82692 | H18: 5963 | I18: 4055 | K18: 0 | L18: 0 | M18: 0 | N18: 0 | O18: 0
... B58: 52 | C58: L - Real estate activities | D58: 1166127334 | E58: 59513748 | F58: 11305686 | G58: 451799 | H58: 252458 | I58: 153501 | K58: 3054 | L58: 3410 | M58: 1 | N58: 0 | O58: 0
B59: 53 | C59: Exposures towards sectors other than those that highly contribute to climate change* | D59: 2827287548 | E59: 118264778 | F59: 38289027 | K59: 1208898 | L59: 129033
B60: 54 | C60: K - Financial and insurance activities | D60: 8716736 | E60: 205346 | F60: 798598 | K60: 331 | L60: 84610
B61: 55 | C61: Exposures to other sectors (NACE codes J, M - S) | D61: 2818570812 | E61: 118059432 | F61: 37490429 | K61: 1208567 | L61: 44423
B62: 56 | C62: TOTAL | D62: 12241903690 | E62: 572060212 | F62: 145733170 | K62: 1563975 | L62: 304348
B63: 57 | C63: Coverage of portfolio with use of proxies (according to PCAF) (in %) | G63: 0.92599181 | H63: 0.99254056 | I63: 0.99746673 | M63: 1 | N63: 1 | O63: 1
C64: * In accordance with the Commission delegated regulation EU) 2020/1818 supplementing regulation (EU) 2016/1011 as regards minimum standards for EU Climate Transition Benchmarks and EU Paris-aligned Benchmarks -Climate Benchmark Standards Regulation - Recital 6: Sectors listed in Sections A to H and Section L of Annex I to Regulation (EC) No 1893/2006

Sheet Dez24
C2: Template 1: Banking book - Climate Change transition risk: Interest income of exposures by sector and emissions
C3: Sector/subsector | D3: EU area | J3: Non-EU area
D4: Gross carrying amount (thousand euro) | E4: Gross interest income (thousand euro) | F4: Gross fee and commission income (thousand euro) | G4: GHG financed emissions (scope 1, scope 2 and scope 3 emissions of the counterparty) (in tons of CO2 equivalent) | J4: Gross carrying amount (thousand euro) | K4: Gross interest income (thousand euro) | L4: Gross fee and commission income (thousand euro) | M4: GHG financed emissions (scope 1, scope 2 and scope 3 emissions of the counterparty) (in tons of CO2 equivalent)
H5: Of which Scope 1 financed emissions | I5: Of which Scope 2 financed emissions | N5: Of which Scope 1 financed emissions | O5: Of which Scope 2 financed emissions
D6: 010 | E6: 020 | F6: 030 | G6: 040 | H6: 050 | I6: 060 | J6: 070 | K6: 080 | L6: 090 | M6: 100 | N6: 110 | O6: 120
B7: 1 | C7: Exposures towards sectors that highly contribute to climate change* | D7: 9270603257 | E7: 446583444 | F7: 107644498 | G7: 6501276.7 | H7: 1874072.2 | I7: 847793.4 | K7: 355740 | L7: 175519 | M7: 9966.13 | N7: 1284.27 | O7: 598.04
B8: 2 | C8: A - Agriculture, forestry and fishing | D8: 331599441 | E8: 15710968 | F8: 2437629 | G8: 378876.39 | H8: 256251.37 | I8: 23088.04 | K8: 0 | L8: 297 | M8: 0.22 | N8: 0.14 | O8: 0.01
B9: 3 | C9: B - Mining and quarrying | D9: 14172372 | E9: 754361 | F9: 446416 | G9: 273035.17 | H9: 49245.27 | I9: 218132.31 | K9: 0 | L9: 6028 | M9: 0 | N9: 0 | O9: 0
B10: 4 | C10: B.05 - Mining of coal and lignite | D10: 0 | E10: 0 | F10: 0 | G10: 0 | H10: 0 | I10: 0 | K10: 0 | L10: 0 | M10: 0 | N10: 0 | O10: 0
B11: 5 | C11: B.06 - Extraction of crude petroleum and natural gas | D11: 0 | E11: 0 | F11: 190 | G11: 0 | H11: 0 | I11: 0 | K11: 0 | L11: 6028 | M11: 0 | N11: 0 | O11: 0
B12: 6 | C12: B.07 - Mining of metal ores | D12: 141471 | E12: 34264 | F12: 41958 | G12: 87.08 | H12: 49.35 | I12: 5.97 | K12: 0 | L12: 0 | M12: 0 | N12: 0 | O12: 0
B13: 7 | C13: B.08 - Other mining and quarrying | D13: 13954338 | E13: 709641 | F13: 400421 | G13: 272898.29 | H13: 49167.7 | I13: 218122.92 | K13: 0 | L13: 0 | M13: 0 | N13: 0 | O13: 0
B14: 8 | C14: B.09 - Mining support service activities | D14: 76563 | E14: 10456 | F14: 3847 | G14: 49.8 | H14: 28.22 | I14: 3.42 | K14: 0 | L14: 0 | M14: 0 | N14: 0 | O14: 0
B15: 9 | C15: C - Manufacturing | D15: 2220273775 | E15: 115470868 | F15: 17804799 | G15: 1911948.7 | H15: 406983.12 | I15: 179222.33 | K15: 261587 | L15: 39804 | M15: 7203.04 | N15: 897.63 | O15: 428.06
B16: 10 | C16: C.10 - Manufacture of food products | D16: 336423698 | E16: 16021606 | F16: 2209965 | G16: 423462.04 | H16: 34225.18 | I16: 23959.52 | K16: 194616 | L16: 1899 | M16: 1906.47 | N16: 82.12 | O16: 303.89
B17: 11 | C17: C.11 - Manufacture of beverages | D17: 217522088 | E17: 10764705 | F17: 1264338 | G17: 105276.42 | H17: 7653.93 | I17: 5772.42 | K17: 0 | L17: 0 | M17: 0 | N17: 0 | O17: 0
B18: 12 | C18: C.12 - Manufacture of tobacco products | D18: 2924771 | E18: 128825 | F18: 15487 | G18: 7897.48 | H18: 569.53 | I18: 387.24 | K18: 0 | L18: 0 | M18: 0 | N18: 0 | O18: 0
... B58: 52 | C58: L - Real estate activities | D58: 1116120857 | E58: 56882565 | F58: 10173166 | G58: 168968.01 | H58: 46297.86 | I58: 111180.88 | K58: 3054 | L58: 3410 | M58: 0.18 | N58: 0.06 | O58: 0.12
B59: 53 | C59: Exposures towards sectors other than those that highly contribute to climate change* | D59: 2971332212 | E59: 126958042 | F59: 38090431 | K59: 1209096 | L59: 128922
B60: 54 | C60: K - Financial and insurance activities | D60: 4114667 | E60: 72508 | F60: 704794 | K60: 324 | L60: 82015
B61: 55 | C61: Exposures to other sectors (NACE codes J, M - S) | D61: 2967217545 | E61: 126885534 | F61: 37385637 | K61: 1208772 | L61: 46907
B62: 56 | C62: TOTAL | D62: 12241935469 | E62: 573541486 | F62: 145734929 | K62: 1564836 | L62: 304441
B63: 57 | C63: Coverage of portfolio with use of proxies (according to PCAF) (in %) | G63: 0.97993198 | H63: 0.99254056 | I63: 0.99746673 | M63: 1 | N63: 1 | O63: 1
C64: * In accordance with the Commission delegated regulation EU) 2020/1818 supplementing regulation (EU) 2016/1011 as regards minimum standards for EU Climate Transition Benchmarks and EU Paris-aligned Benchmarks -Climate Benchmark Standards Regulation - Recital 6: Sectors listed in Sections A to H and Section L of Annex I to Regulation (EC) No 1893/2006
