Workbook
Name \a: #REF!
Name \a: #REF!
Name \a: #REF!
Name \b: #REF!
Name \b: #REF!
Name \b: #REF!
Name \c: #REF!
Name \c: #REF!
Name \c: #REF!
Name \d: #REF!
Name \d: #REF!
Name \d: #REF!
Name \e: #REF!
Name \e: #REF!
Name \e: #REF!
Name \m: #REF!
Name \m: #REF!
Name \m: #REF!
Name \p: #REF!
Name \p: #REF!
Name \p: #REF!
Name \q: #REF!
Name \q: #REF!
Name \q: #REF!
Name \s: #REF!
Name \s: #REF!
Name \s: #REF!
Name \v: #REF!
Name \v: #REF!
Name \v: #REF!
Name ___GRUPO_ENVIO: [1]GENMASIVA!$AC$4
Name ___INDEX_SHEET___ASAP_Utilities: #REF!
Name ___INDEX_SHEET___ASAP_Utilities: #REF!
Name ___INDEX_SHEET___ASAP_Utilities: #REF!
Name ___PERIODO: [1]GENMASIVA!$AC$2
Name ___td2: #REF!
Name ___td2: #REF!
Name ___td2: #REF!
Name ___td3: #REF!
Name ___td3: #REF!
Name ___td3: #REF!
Name ___td4: #REF!
Name ___td4: #REF!
Name ___td4: #REF!
Name ___ti1: #REF!
Name ___ti1: #REF!
Name ___ti1: #REF!
Name ___ti2: #REF!
Name ___ti2: #REF!
Name ___ti2: #REF!
Name ___ti3: #REF!
Name ___ti3: #REF!
Name ___ti3: #REF!
Name ___ti4: #REF!
Name ___ti4: #REF!
Name ___ti4: #REF!
Name ___tp1: #REF!
Name ___tp1: #REF!
Name ___tp1: #REF!
Name ___tp2: #REF!

Sheet Comparativo s adjudicados
B8: Tatico
B9: informing_soc | C9: counterparty_soc | D9: adjustment_code | E9: comb_code | F9: amount | G9: eu | H9: chro | I9: acut | J9: geo | K9: cnael | L9: nace
A10: =CONCATENATE(B10,C10,D10,E10) -> 411421BI00411CONT1;HFS2;B01;MC08;TYVA01;INVS4;MESG4 | B10: 411 | C10: 421 | D10: BI00411 | E10: CONT1;HFS2;B01;MC08;TYVA01;INVS4;MESG4 | F10: 450662960 | G10: EU1 | H10: CHRO2 | I10: ACUT2 | J10: GEO18 | O10: =VLOOKUP(A10,$A$27:$A$44,1,FALSE) -> 411421BI00411CONT1;HFS2;B01;MC08;TYVA01;INVS4;MESG4
A11: =CONCATENATE(B11,C11,D11,E11) -> 4113162BI00411CONT1;HFS2;B01;MC08;TYVA01;INVS4;MESG4 | B11: 411 | C11: 3162 | D11: BI00411 | E11: CONT1;HFS2;B01;MC08;TYVA01;INVS4;MESG4 | F11: 7932813 | G11: EU1 | H11: CHRO2 | I11: ACUT2 | J11: GEO3 | O11: =VLOOKUP(A11,$A$27:$A$44,1,FALSE) -> 4113162BI00411CONT1;HFS2;B01;MC08;TYVA01;INVS4;MESG4
A12: =CONCATENATE(B12,C12,D12,E12) -> 4111333BI00411CONT1;HFS2;B01;MC08;TYVA01;INVS4;MESG4 | B12: 411 | C12: 1333 | D12: BI00411 | E12: CONT1;HFS2;B01;MC08;TYVA01;INVS4;MESG4 | F12: 88691496 | G12: EU1 | H12: CHRO2 | I12: ACUT2 | J12: GEO3 | O12: =VLOOKUP(A12,$A$27:$A$44,1,FALSE) -> 4111333BI00411CONT1;HFS2;B01;MC08;TYVA01;INVS4;MESG4
A13: =CONCATENATE(B13,C13,D13,E13) -> 411421BI00411CONT1;HFS2;B01;MC08;TYVA01;MESG4 | B13: 411 | C13: 421 | D13: BI00411 | E13: CONT1;HFS2;B01;MC08;TYVA01;MESG4 | F13: -1 | G13: EU1 | H13: CHRO2 | I13: ACUT2 | J13: GEO18 | O13: =VLOOKUP(A13,$A$27:$A$44,1,FALSE) -> #N/A
A14: =CONCATENATE(B14,C14,D14,E14) -> 411442BI00411CONT1;HFS2;B01;MC08;TYVA01;INVS5;EXC2;MESG4 | B14: 411 | C14: 442 | D14: BI00411 | E14: CONT1;HFS2;B01;MC08;TYVA01;INVS5;EXC2;MESG4 | F14: 99962303 | G14: EU1 | H14: CHRO2 | I14: ACUT2 | J14: GEO3 | K14: CNAEL6 | L14: NACE06010101 | O14: =VLOOKUP(A14,$A$27:$A$44,1,FALSE) -> 411442BI00411CONT1;HFS2;B01;MC08;TYVA01;INVS5;EXC2;MESG4
A15: =CONCATENATE(B15,C15,D15,E15) -> 4110BI00411CONT1;HFS2;B01;MC06;ACPF5;SC0303;TYVA01;EXC2;MESG4 | B15: 411 | C15: 0 | D15: BI00411 | E15: CONT1;HFS2;B01;MC06;ACPF5;SC0303;TYVA01;EXC2;MESG4 | F15: 22684 | G15: EU1 | H15: CHRO2 | I15: ACUT2 | J15: GEO3 | K15: CNAEL18 | L15: NACE19010303 | O15: =VLOOKUP(A15,$A$27:$A$44,1,FALSE) -> 4110BI00411CONT1;HFS2;B01;MC06;ACPF5;SC0303;TYVA01;EXC2;MESG4
A16: =CONCATENATE(B16,C16,D16,E16) -> 4110BI00411CONT1;HFS2;B01;MC06;ACPF3;SC0302;TYVA01;MESG4 | B16: 411 | C16: 0 | D16: BI00411 | E16: CONT1;HFS2;B01;MC06;ACPF3;SC0302;TYVA01;MESG4 | F16: 17085832 | G16: EU1 | H16: CHRO2 | I16: ACUT2 | J16: GEO3 | O16: =VLOOKUP(A16,$A$27:$A$44,1,FALSE) -> 4110BI00411CONT1;HFS2;B01;MC06;ACPF3;SC0302;TYVA01;MESG4
A17: =CONCATENATE(B17,C17,D17,E17) -> 411445BI00411CONT1;HFS2;B01;MC08;TYVA01;INVS4;MESG4 | B17: 411 | C17: 445 | D17: BI00411 | E17: CONT1;HFS2;B01;MC08;TYVA01;INVS4;MESG4 | F17: 49500 | G17: EU1 | H17: CHRO2 | I17: ACUT2 | J17: GEO3 | O17: =VLOOKUP(A17,$A$27:$A$44,1,FALSE) -> 411445BI00411CONT1;HFS2;B01;MC08;TYVA01;INVS4;MESG4
A18: =CONCATENATE(B18,C18,D18,E18) -> 4110BI00411CONT1;HFS2;B01;MC06;ACPF5;SC0303;TYVA01;EXC2;MESG4 | B18: 411 | C18: 0 | D18: BI00411 | E18: CONT1;HFS2;B01;MC06;ACPF5;SC0303;TYVA01;EXC2;MESG4 | F18: 131176 | G18: EU1 | H18: CHRO2 | I18: ACUT2 | J18: GEO18 | K18: CNAEL11 | L18: NACE12010101 | O18: =VLOOKUP(A18,$A$27:$A$44,1,FALSE) -> 4110BI00411CONT1;HFS2;B01;MC06;ACPF5;SC0303;TYVA01;EXC2;MESG4
A19: =CONCATENATE(B19,C19,D19,E19) -> 411442BI00411CONT1;HFS2;B01;MC08;TYVA02;INVS5;EXC2 | B19: 411 | C19: 442 | D19: BI00411 | E19: CONT1;HFS2;B01;MC08;TYVA02;INVS5;EXC2 | F19: -11000000 | G19: EU1 | H19: CHRO2 | I19: ACUT2 | J19: GEO3 | K19: CNAEL6 | L19: NACE06010101 | O19: =VLOOKUP(A19,$A$27:$A$44,1,FALSE) -> 411442BI00411CONT1;HFS2;B01;MC08;TYVA02;INVS5;EXC2
A20: =CONCATENATE(B20,C20,D20,E20) -> 4110BI00411CONT1;HFS2;B01;MC06;ACPF5;SC0302;TYVA01;MESG4 | B20: 411 | C20: 0 | D20: BI00411 | E20: CONT1;HFS2;B01;MC06;ACPF5;SC0302;TYVA01;MESG4 | F20: 2493971 | G20: EU2 | H20: CHRO2 | I20: ACUT2 | J20: GEO2 | O20: =VLOOKUP(A20,$A$27:$A$44,1,FALSE) -> 4110BI00411CONT1;HFS2;B01;MC06;ACPF5;SC0302;TYVA01;MESG4
A21: =CONCATENATE(B21,C21,D21,E21) -> 4110BI00411CONT1;HFS2;B01;MC06;ACPF5;SC0303;TYVA01;EXC2;MESG4 | B21: 411 | C21: 0 | D21: BI00411 | E21: CONT1;HFS2;B01;MC06;ACPF5;SC0303;TYVA01;EXC2;MESG4 | F21: 35578 | G21: EU1 | H21: CHRO2 | I21: ACUT2 | J21: GEO3 | K21: CNAEL3 | L21: NACE03200302 | O21: =VLOOKUP(A21,$A$27:$A$44,1,FALSE) -> 4110BI00411CONT1;HFS2;B01;MC06;ACPF5;SC0303;TYVA01;EXC2;MESG4
A22: =CONCATENATE(B22,C22,D22,E22) -> 4110BI00411CONT1;HFS2;B01;MC06;ACPF5;SC0302;TYVA01;MESG4 | B22: 411 | C22: 0 | D22: BI00411 | E22: CONT1;HFS2;B01;MC06;ACPF5;SC0302;TYVA01;MESG4 | F22: 171653011 | G22: EU1 | H22: CHRO2 | I22: ACUT2 | J22: GEO3 | O22: =VLOOKUP(A22,$A$27:$A$44,1,FALSE) -> 4110BI00411CONT1;HFS2;B01;MC06;ACPF5;SC0302;TYVA01;MESG4
B25: Estrutural
B26: reporting_soc | C26: counterparty_soc | D26: adjustment_code | E26: comb_code | F26: amount | G26: eu | H26: chro | I26: acut | J26: geo | K26: cnael | L26: nace | M26: IDCOMBS vs dez24 | N26: Saldos vs Dez 24 | O26: Casuística Saldo
A27: =CONCATENATE(B27,C27,D27,E27) -> 4110BI00411CONT1;HFS1;B01;MC1005;ORIG4;TYVA01;MESG1 | B27: 411 | C27: 0 | D27: BI00411 | E27: CONT1;HFS1;B01;MC1005;ORIG4;TYVA01;MESG1 | F27: 40660146 | H27: CHRO2 | I27: ACUT2 | J27: GEO19 | M27: =VLOOKUP(E27,$E$10:$F$22,1,FALSE) -> #N/A | N27: =VLOOKUP(F27,$F$10:$G$22,1,FALSE) -> #N/A | Q27: =VLOOKUP(A27,$A$10:$A$22,1,FALSE) -> #N/A
A28: =CONCATENATE(B28,C28,D28,E28) -> 4110BI00411CONT1;HFS1;B01;MC1005;ORIG4;TYVA02;MESG1 | B28: 411 | C28: 0 | D28: BI00411 | E28: CONT1;HFS1;B01;MC1005;ORIG4;TYVA02;MESG1 | F28: -21154251 | H28: CHRO2 | I28: ACUT2 | J28: GEO19 | M28: =VLOOKUP(E28,$E$10:$F$22,1,FALSE) -> #N/A | N28: =VLOOKUP(F28,$F$10:$G$22,1,FALSE) -> #N/A | Q28: =VLOOKUP(A28,$A$10:$A$22,1,FALSE) -> #N/A
A29: =CONCATENATE(B29,C29,D29,E29) -> 4110BI00411CONT1;HFS2;B01;MC06;ACPF3;SC0302;TYVA01;MESG4 | B29: 411 | C29: 0 | D29: BI00411 | E29: CONT1;HFS2;B01;MC06;ACPF3;SC0302;TYVA01;MESG4 | F29: 11163168 | G29: EU1 | H29: CHRO2 | I29: ACUT2 | J29: GEO3 | L29: NACE11030301 | M29: =VLOOKUP(E29,$E$10:$F$22,1,FALSE) -> CONT1;HFS2;B01;MC06;ACPF3;SC0302;TYVA01;MESG4 | N29: =VLOOKUP(F29,$F$10:$G$22,1,FALSE) -> #N/A | Q29: =VLOOKUP(A29,$A$10:$A$22,1,FALSE) -> 4110BI00411CONT1;HFS2;B01;MC06;ACPF3;SC0302;TYVA01;MESG4
A30: =CONCATENATE(B30,C30,D30,E30) -> 4110BI00411CONT1;HFS2;B01;MC06;ACPF3;SC0302;TYVA01;MESG4 | B30: 411 | C30: 0 | D30: BI00411 | E30: CONT1;HFS2;B01;MC06;ACPF3;SC0302;TYVA01;MESG4 | F30: 799901 | G30: EU1 | H30: CHRO2 | I30: ACUT2 | J30: GEO3 | L30: NACE11010403 | M30: =VLOOKUP(E30,$E$10:$F$22,1,FALSE) -> CONT1;HFS2;B01;MC06;ACPF3;SC0302;TYVA01;MESG4 | Q30: =VLOOKUP(A30,$A$10:$A$22,1,FALSE) -> 4110BI00411CONT1;HFS2;B01;MC06;ACPF3;SC0302;TYVA01;MESG4
A31: =CONCATENATE(B31,C31,D31,E31) -> 4110BI00411CONT1;HFS2;B01;MC06;ACPF3;SC0302;TYVA01;MESG4 | B31: 411 | C31: 0 | D31: BI00411 | E31: CONT1;HFS2;B01;MC06;ACPF3;SC0302;TYVA01;MESG4 | F31: 5122764 | G31: EU1 | H31: CHRO2 | I31: ACUT2 | J31: GEO3 | M31: =VLOOKUP(E31,$E$10:$F$22,1,FALSE) -> CONT1;HFS2;B01;MC06;ACPF3;SC0302;TYVA01;MESG4 | N31: =VLOOKUP(F31,$F$10:$G$22,1,FALSE) -> #N/A | Q31: =VLOOKUP(A31,$A$10:$A$22,1,FALSE) -> 4110BI00411CONT1;HFS2;B01;MC06;ACPF3;SC0302;TYVA01;MESG4
A32: =CONCATENATE(B32,C32,D32,E32) -> 4110BI00411CONT1;HFS2;B01;MC06;ACPF5;SC0302;TYVA01;MESG4 | B32: 411 | C32: 0 | D32: BI00411 | E32: CONT1;HFS2;B01;MC06;ACPF5;SC0302;TYVA01;MESG4 | F32: 1 | H32: CHRO2 | I32: ACUT2 | J32: GEO19 | M32: =VLOOKUP(E32,$E$10:$F$22,1,FALSE) -> CONT1;HFS2;B01;MC06;ACPF5;SC0302;TYVA01;MESG4 | N32: =VLOOKUP(F32,$F$10:$G$22,1,FALSE) -> #N/A | Q32: =VLOOKUP(A32,$A$10:$A$22,1,FALSE) -> 4110BI00411CONT1;HFS2;B01;MC06;ACPF5;SC0302;TYVA01;MESG4
A33: =CONCATENATE(B33,C33,D33,E33) -> 4110BI00411CONT1;HFS2;B01;MC06;ACPF5;SC0302;TYVA01;MESG4 | B33: 411 | C33: 0 | D33: BI00411 | E33: CONT1;HFS2;B01;MC06;ACPF5;SC0302;TYVA01;MESG4 | F33: 2493971 | G33: EU2 | H33: CHRO2 | I33: ACUT2 | J33: GEO2 | M33: =VLOOKUP(E33,$E$10:$F$22,1,FALSE) -> CONT1;HFS2;B01;MC06;ACPF5;SC0302;TYVA01;MESG4 | N33: =VLOOKUP(F33,$F$10:$G$22,1,FALSE) -> 2493971 | Q33: =VLOOKUP(A33,$A$10:$A$22,1,FALSE) -> 4110BI00411CONT1;HFS2;B01;MC06;ACPF5;SC0302;TYVA01;MESG4
A34: =CONCATENATE(B34,C34,D34,E34) -> 4110BI00411CONT1;HFS2;B01;MC06;ACPF5;SC0302;TYVA01;MESG4 | B34: 411 | C34: 0 | D34: BI00411 | E34: CONT1;HFS2;B01;MC06;ACPF5;SC0302;TYVA01;MESG4 | F34: 171653012 | G34: EU1 | H34: CHRO2 | I34: ACUT2 | J34: GEO3 | M34: =VLOOKUP(E34,$E$10:$F$22,1,FALSE) -> CONT1;HFS2;B01;MC06;ACPF5;SC0302;TYVA01;MESG4 | N34: =VLOOKUP(F34,$F$10:$G$22,1,FALSE) -> #N/A | Q34: =VLOOKUP(A34,$A$10:$A$22,1,FALSE) -> 4110BI00411CONT1;HFS2;B01;MC06;ACPF5;SC0302;TYVA01;MESG4
A35: =CONCATENATE(B35,C35,D35,E35) -> 4110BI00411CONT1;HFS2;B01;MC06;ACPF5;SC0303;TYVA01;EXC2;MESG4 | B35: 411 | C35: 0 | D35: BI00411 | E35: CONT1;HFS2;B01;MC06;ACPF5;SC0303;TYVA01;EXC2;MESG4 | F35: 35578 | G35: EU1 | H35: CHRO2 | I35: ACUT2 | J35: GEO3 | K35: CNAEL3 | L35: NACE03200302 | M35: =VLOOKUP(E35,$E$10:$F$22,1,FALSE) -> CONT1;HFS2;B01;MC06;ACPF5;SC0303;TYVA01;EXC2;MESG4 | N35: =VLOOKUP(F35,$F$10:$G$22,1,FALSE) -> 35578 | Q35: =VLOOKUP(A35,$A$10:$A$22,1,FALSE) -> 4110BI00411CONT1;HFS2;B01;MC06;ACPF5;SC0303;TYVA01;EXC2;MESG4
A36: =CONCATENATE(B36,C36,D36,E36) -> 4110BI00411CONT1;HFS2;B01;MC06;ACPF5;SC0303;TYVA01;EXC2;MESG4 | B36: 411 | C36: 0 | D36: BI00411 | E36: CONT1;HFS2;B01;MC06;ACPF5;SC0303;TYVA01;EXC2;MESG4 | F36: 131176 | G36: EU1 | H36: CHRO2 | I36: ACUT2 | J36: GEO18 | K36: CNAEL11 | L36: NACE12010101 | M36: =VLOOKUP(E36,$E$10:$F$22,1,FALSE) -> CONT1;HFS2;B01;MC06;ACPF5;SC0303;TYVA01;EXC2;MESG4 | N36: =VLOOKUP(F36,$F$10:$G$22,1,FALSE) -> 131176 | Q36: =VLOOKUP(A36,$A$10:$A$22,1,FALSE) -> 4110BI00411CONT1;HFS2;B01;MC06;ACPF5;SC0303;TYVA01;EXC2;MESG4
A37: =CONCATENATE(B37,C37,D37,E37) -> 4110BI00411CONT1;HFS2;B01;MC06;ACPF5;SC0303;TYVA01;EXC2;MESG4 | B37: 411 | C37: 0 | D37: BI00411 | E37: CONT1;HFS2;B01;MC06;ACPF5;SC0303;TYVA01;EXC2;MESG4 | F37: 22684 | G37: EU1 | H37: CHRO2 | I37: ACUT2 | J37: GEO3 | K37: CNAEL18 | L37: NACE19010303 | M37: =VLOOKUP(E37,$E$10:$F$22,1,FALSE) -> CONT1;HFS2;B01;MC06;ACPF5;SC0303;TYVA01;EXC2;MESG4 | N37: =VLOOKUP(F37,$F$10:$G$22,1,FALSE) -> 22684 | Q37: =VLOOKUP(A37,$A$10:$A$22,1,FALSE) -> 4110BI00411CONT1;HFS2;B01;MC06;ACPF5;SC0303;TYVA01;EXC2;MESG4
A38: =CONCATENATE(B38,C38,D38,E38) -> 4111333BI00411CONT1;HFS2;B01;MC08;TYVA01;INVS4;MESG4 | B38: 411 | C38: 1333 | D38: BI00411 | E38: CONT1;HFS2;B01;MC08;TYVA01;INVS4;MESG4 | F38: 88691496 | G38: EU1 | H38: CHRO2 | I38: ACUT2 | J38: GEO3 | M38: =VLOOKUP(E38,$E$10:$F$22,1,FALSE) -> CONT1;HFS2;B01;MC08;TYVA01;INVS4;MESG4 | N38: =VLOOKUP(F38,$F$10:$G$22,1,FALSE) -> 88691496 | Q38: =VLOOKUP(A38,$A$10:$A$22,1,FALSE) -> 4111333BI00411CONT1;HFS2;B01;MC08;TYVA01;INVS4;MESG4
A39: =CONCATENATE(B39,C39,D39,E39) -> 4113162BI00411CONT1;HFS2;B01;MC08;TYVA01;INVS4;MESG4 | B39: 411 | C39: 3162 | D39: BI00411 | E39: CONT1;HFS2;B01;MC08;TYVA01;INVS4;MESG4 | F39: 7932813 | G39: EU1 | H39: CHRO2 | I39: ACUT2 | J39: GEO3 | M39: =VLOOKUP(E39,$E$10:$F$22,1,FALSE) -> CONT1;HFS2;B01;MC08;TYVA01;INVS4;MESG4 | N39: =VLOOKUP(F39,$F$10:$G$22,1,FALSE) -> 7932813 | Q39: =VLOOKUP(A39,$A$10:$A$22,1,FALSE) -> 4113162BI00411CONT1;HFS2;B01;MC08;TYVA01;INVS4;MESG4
A40: =CONCATENATE(B40,C40,D40,E40) -> 411421BI00411CONT1;HFS2;B01;MC08;TYVA01;;MESG4 | B40: 411 | C40: 421 | D40: BI00411 | E40: CONT1;HFS2;B01;MC08;TYVA01;;MESG4 | F40: -1 | G40: EU1 | H40: CHRO2 | I40: ACUT2 | J40: GEO18 | M40: =VLOOKUP(E40,$E$10:$F$22,1,FALSE) -> #N/A | N40: =VLOOKUP(F40,$F$10:$G$22,1,FALSE) -> -1 | Q40: =VLOOKUP(A40,$A$10:$A$22,1,FALSE) -> #N/A
A41: =CONCATENATE(B41,C41,D41,E41) -> 411421BI00411CONT1;HFS2;B01;MC08;TYVA01;INVS4;MESG4 | B41: 411 | C41: 421 | D41: BI00411 | E41: CONT1;HFS2;B01;MC08;TYVA01;INVS4;MESG4 | F41: 450662960 | G41: EU1 | H41: CHRO2 | I41: ACUT2 | J41: GEO18 | M41: =VLOOKUP(E41,$E$10:$F$22,1,FALSE) -> CONT1;HFS2;B01;MC08;TYVA01;INVS4;MESG4 | N41: =VLOOKUP(F41,$F$10:$G$22,1,FALSE) -> 450662960 | Q41: =VLOOKUP(A41,$A$10:$A$22,1,FALSE) -> 411421BI00411CONT1;HFS2;B01;MC08;TYVA01;INVS4;MESG4
A42: =CONCATENATE(B42,C42,D42,E42) -> 411442BI00411CONT1;HFS2;B01;MC08;TYVA01;INVS5;EXC2;MESG4 | B42: 411 | C42: 442 | D42: BI00411 | E42: CONT1;HFS2;B01;MC08;TYVA01;INVS5;EXC2;MESG4 | F42: 99962303 | G42: EU1 | H42: CHRO2 | I42: ACUT2 | J42: GEO3 | K42: CNAEL6 | L42: NACE06010101 | M42: =VLOOKUP(E42,$E$10:$F$22,1,FALSE) -> CONT1;HFS2;B01;MC08;TYVA01;INVS5;EXC2;MESG4 | N42: =VLOOKUP(F42,$F$10:$G$22,1,FALSE) -> 99962303 | Q42: =VLOOKUP(A42,$A$10:$A$22,1,FALSE) -> 411442BI00411CONT1;HFS2;B01;MC08;TYVA01;INVS5;EXC2;MESG4
A43: =CONCATENATE(B43,C43,D43,E43) -> 411442BI00411CONT1;HFS2;B01;MC08;TYVA02;INVS5;EXC2 | B43: 411 | C43: 442 | D43: BI00411 | E43: CONT1;HFS2;B01;MC08;TYVA02;INVS5;EXC2 | F43: -11000000 | G43: EU1 | H43: CHRO2 | I43: ACUT2 | J43: GEO3 | K43: CNAEL6 | L43: NACE06010101 | M43: =VLOOKUP(E43,$E$10:$F$22,1,FALSE) -> CONT1;HFS2;B01;MC08;TYVA02;INVS5;EXC2 | N43: =VLOOKUP(F43,$F$10:$G$22,1,FALSE) -> -11000000 | Q43: =VLOOKUP(A43,$A$10:$A$22,1,FALSE) -> 411442BI00411CONT1;HFS2;B01;MC08;TYVA02;INVS5;EXC2
A44: =CONCATENATE(B44,C44,D44,E44) -> 411445BI00411CONT1;HFS2;B01;MC08;TYVA01;INVS4;MESG4 | B44: 411 | C44: 445 | D44: BI00411 | E44: CONT1;HFS2;B01;MC08;TYVA01;INVS4;MESG4 | F44: 49500 | G44: EU1 | H44: CHRO2 | I44: ACUT2 | J44: GEO3 | M44: =VLOOKUP(E44,$E$10:$F$22,1,FALSE) -> CONT1;HFS2;B01;MC08;TYVA01;INVS4;MESG4 | N44: =VLOOKUP(F44,$F$10:$G$22,1,FALSE) -> 49500 | Q44: =VLOOKUP(A44,$A$10:$A$22,1,FALSE) -> 411445BI00411CONT1;HFS2;B01;MC08;TYVA01;INVS4;MESG4
B49: evidencia tabela granular exercicio de dez24 a marcar GEO3 em 'outras instituições financeiras'
B50: csatelite | C50: idcomb_satelite | D50: idcomb_fr012 | E50: cempresa_fr012 | F50: cbalcao_fr012 | G50: cnumecta_fr012 | H50: zdeposit_fr012 | I50: cod_ajust | J50: sociedade_contraparte | K50: saldo_fr012 | L50: cempresa_ct | M50: cbalcao_ct | N50: cnumecta_ct | O50: zdeposit_ct | P50: sociedade_contraparte_ct | Q50: idcomb_ct | R50: pcsb_ct | S50: cargabal_ct | T50: ifrs_ct | U50: cod_ajust_ct | V50: saldo_ct | W50: ps_date | X50: dt_rfrnc | Y50: id_corrida | Z50: zcliente | AA50: 28_dt_maturity | AB50: maturity_esg | AC50: flag_maturity | AD50: years_to_maturity | AE50: european_union | AF50: performing_esg | AG50: 22_counterparty_nuts | AH50: 23_counterparty_zipcode | AI50: 14_nace | AJ50: nace_esg_orig | AK50: 12_non_performing | AL50: 17_accumulated_impairment | AM50: 30_stage_ifrs9 | AN50: 51_client_own_funds | AO50: 75_isin | AP50: cpais_residencia | AQ50: 5_collateral_zip_code | AR50: 4_collateral_nuts | AS50: 16_percent_collateral | AT50: 33_counterparty_type | AU50: excluded_paris | AV50: cnael | AW50: nace_esg | AX50: investment_sector | AY50: peso | AZ50: flag_hipotec | BA50: ckbalbem | BB50: ckctabem | BC50: ckrefbem | BD50: amount | BE50: id | BF50: nace_level4 | BG50: zipcode_collateral | BH50: zipcode_counterparty | BI50: nace_esg_aux | BJ50: acute_changes | BK50: chronic_changes | BL50: geo | BM50: saldo_satelite_agrup | BN50: chave
B51: 79 | C51: CONT1;HFS2;B01;MC06;ACPF5;SC0302;TYVA01 | D51: CONT1;HFS2;B01;MC06;PR18;ACPF5;SC0302;ORIG1;ULINK2;TYVA01 | E51: 31 | F51: 6416 | G51: 0 | H51: PTSIB0AM0008000 | I51: BI00411 | J51: 0 | K51: -140000000.000000 | L51: 31 | M51: 6416 | N51: 0 | O51: PTSIB0AM0008000 | Q51: CONT1;HFS2;B01;MC06;PR18;ACPF5;SC0302;ORIG1;ULINK2;TYVA01 | R51: 25701103 | S51: 15313 | T51: 14137 | U51: BI00411 | V51: -71687210.000000 | W51: 45675 | X51: 45657 | Y51: 1 | Z51: 8006098485 | AA51: 2958465 | AB51: MESG4 | AC51: 0 | AD51: NULL | AE51: EU1 | AG51: PT170 | AH51: 1600 | AI51: M70.1.0 | AJ51: K66.2.9 | AK51: no_stage | AL51: 0.000000 | AN51: 141095835.010000 | AO51: PTSIB0AM0008 | AP51: 620 | AQ51: NULL | AR51: NULL | AS51: NULL | AT51: outras instituicoes financeiras | AY51: 1.000000 | AZ51: 0 | BA51: NULL | BB51: NULL | BC51: NULL | BD51: -71687210.000000000000 | BE51: NACE11030203 | BF51: K6629 - Other activities auxiliary to insurance and pension funding | BG51: NULL | BH51: 1600 | BI51: K.66 | BJ51: ACUT2 | BK51: CHRO2 | BL51: GEO3 | BM51: -171653011.480000000000 | BN51: 31641600000000000PTSIB0AM0008000
B52: 79 | C52: CONT1;HFS2;B01;MC06;ACPF5;SC0302;TYVA01 | D52: CONT1;HFS2;B01;MC06;PR18;ACPF5;SC0302;ORIG1;ULINK2;TYVA01 | E52: 31 | F52: 6416 | G52: 0 | H52: PTSIB0AM0008000 | I52: BI00411 | J52: 0 | K52: -140000000.000000 | L52: 31 | M52: 6416 | N52: 0 | O52: PTSIB0AM0008000 | Q52: CONT1;HFS2;B01;MC06;PR18;ACPF5;SC0302;ORIG1;ULINK2;TYVA01 | R52: 4002010 | S52: 15313 | T52: 14130 | U52: BI00411 | V52: -68312790.000000 | W52: 45675 | X52: 45657 | Y52: 1 | Z52: 8006098485 | AA52: 2958465 | AB52: MESG4 | AC52: 0 | AD52: NULL | AE52: EU1 | AG52: PT170 | AH52: 1600 | AI52: M70.1.0 | AJ52: K66.2.9 | AK52: no_stage | AL52: 0.000000 | AN52: 141095835.010000 | AO52: PTSIB0AM0008 | AP52: 620 | AQ52: NULL | AR52: NULL | AS52: NULL | AT52: outras instituicoes financeiras | AY52: 1.000000 | AZ52: 0 | BA52: NULL | BB52: NULL | BC52: NULL | BD52: -68312790.000000000000 | BE52: NACE11030203 | BF52: K6629 - Other activities auxiliary to insurance and pension funding | BG52: NULL | BH52: 1600 | BI52: K.66 | BJ52: ACUT2 | BK52: CHRO2 | BL52: GEO3 | BM52: -171653011.480000000000 | BN52: 31641600000000000PTSIB0AM0008000

Sheet Comparativo - Deltas Granul
B8: Deltas comparativos entre o exercício tático reportado (Dez24) e o Satélite gerado via solução estrutural To Be (Dez24)
B10: informing_soc | C10: counterparty_soc | D10: adjustment_code | E10: comb_code | F10: amount | I10: eu | L10: chro | O10: acut | R10: geo | U10: cnael | X10: nace
F11: Dez24 Tático | G11: Dez24 Estrutural | H11: ∆ | I11: Dez24 Tático | J11: Dez24 Estrutural | K11: ∆ | L11: Dez24 Tático | M11: Dez24 Estrutural | N11: ∆ | O11: Dez24 Tático | P11: Dez24 Estrutural | Q11: ∆ | R11: Dez24 Tático | S11: Dez24 Estrutural | T11: ∆ | U11: Dez24 Tático | V11: Dez24 Estrutural | W11: ∆ | X11: Dez24 Tático | Y11: Dez24 Estrutural | Z11: ∆
A12: =CONCATENATE(B12,C12,D12,E12) -> 4110BI00411CONT1;HFS2;B01;MC06;ACPF3;SC0302;TYVA01;MESG4 | B12: 411 | C12: 0 | D12: BI00411 | E12: CONT1;HFS2;B01;MC06;ACPF3;SC0302;TYVA01;MESG4 | F12: =_xlfn.IFNA(INDEX('Comparativo s adjudicados'!$A$9:$L$22, MATCH('Comparativo - Deltas Granul'!$A12,'Comparativo s adjudicados'!$A$9:$A$22,0), MATCH('Comparativo - Deltas Granul'!F$10,'Comparativo s adjudicados'!$A$9:$L$9,0)),"") -> 17085832 | G12: ='Comparativo s adjudicados'!F29 -> 11163168 | H12: =SUM(G12:G14)-F12 -> 1 | I12: =_xlfn.IFNA(INDEX('Comparativo s adjudicados'!$A$9:$L$22, MATCH('Comparativo - Deltas Granul'!$A12,'Comparativo s adjudicados'!$A$9:$A$22,0), MATCH('Comparativo - Deltas Granul'!I$10,'Comparativo s adjudicados'!$A$9:$L$9,0)),"") -> EU1 | J12: ='Comparativo s adjudicados'!G29 -> EU1 | K12: =I12=J12 -> TRUE | L12: =INDEX('Comparativo s adjudicados'!$A$9:$L$22,MATCH('Comparativo - Deltas Granul'!$A12,'Comparativo s adjudicados'!$A$9:$A$22,0),MATCH('Comparativo - Deltas Granul'!L$10,'Comparativo s adjudicados'!$A$9:$L$9,0)) -> CHRO2 | M12: =INDEX('Comparativo s adjudicados'!$A$26:$O$44, MATCH('Comparativo - Deltas Granul'!$A12,'Comparativo s adjudicados'!$A$26:$A$44,0), MATCH('Comparativo - Deltas Granul'!L$10,'Comparativo s adjudicados'!$A$26:$O$26,0)) -> CHRO2 | N12: =L12=M12 -> TRUE | O12: =INDEX('Comparativo s adjudicados'!$A$9:$L$22,MATCH('Comparativo - Deltas Granul'!$A12,'Comparativo s adjudicados'!$A$9:$A$22,0),MATCH('Comparativo - Deltas Granul'!O$10,'Comparativo s adjudicados'!$A$9:$L$9,0)) -> ACUT2 | P12: =INDEX('Comparativo s adjudicados'!$A$26:$O$44, MATCH('Comparativo - Deltas Granul'!$A12,'Comparativo s adjudicados'!$A$26:$A$44,0), MATCH('Comparativo - Deltas Granul'!O$10,'Comparativo s adjudicados'!$A$26:$O$26,0)) -> ACUT2 | Q12: =O12=P12 -> TRUE | R12: =INDEX('Comparativo s adjudicados'!$A$9:$L$22,MATCH('Comparativo - Deltas Granul'!$A12,'Comparativo s adjudicados'!$A$9:$A$22,0),MATCH('Comparativo - Deltas Granul'!R$10,'Comparativo s adjudicados'!$A$9:$L$9,0)) -> GEO3 | S12: =INDEX('Comparativo s adjudicados'!$A$26:$O$44, MATCH('Comparativo - Deltas Granul'!$A12,'Comparativo s adjudicados'!$A$26:$A$44,0), MATCH('Comparativo - Deltas Granul'!R$10,'Comparativo s adjudicados'!$A$26:$O$26,0)) -> GEO3 | T12: =R12=S12 -> TRUE | W12: =U12=V12 -> TRUE | Y12: ='Comparativo s adjudicados'!L29 -> NACE11030301 | Z12: =Y12=X12 -> FALSE
D13: BI00411 | E13: CONT1;HFS2;B01;MC06;ACPF3;SC0302;TYVA01;MESG4 | G13: ='Comparativo s adjudicados'!F30 -> 799901 | M13: =INDEX('Comparativo s adjudicados'!$A$26:$O$42,MATCH('Comparativo - Deltas Granul'!$A13,'Comparativo s adjudicados'!$A$26:$A$42,0),MATCH('Comparativo - Deltas Granul'!L$10,'Comparativo s adjudicados'!$A$26:$O$26,0)) -> #N/A | N13: =L13=M13 -> #N/A | P13: =INDEX('Comparativo s adjudicados'!$A$26:$O$42,MATCH('Comparativo - Deltas Granul'!$A13,'Comparativo s adjudicados'!$A$26:$A$42,0),MATCH('Comparativo - Deltas Granul'!O$10,'Comparativo s adjudicados'!$A$26:$O$26,0)) -> #N/A | Q13: =O13=P13 -> #N/A | S13: =INDEX('Comparativo s adjudicados'!$A$26:$O$42,MATCH('Comparativo - Deltas Granul'!$A13,'Comparativo s adjudicados'!$A$26:$A$42,0),MATCH('Comparativo - Deltas Granul'!R$10,'Comparativo s adjudicados'!$A$26:$O$26,0)) -> #N/A | T13: =R13=S13 -> #N/A | Y13: ='Comparativo s adjudicados'!L30 -> NACE11010403 | Z13: =Y13=X13 -> FALSE
C14: 0 | D14: BI00411 | E14: CONT1;HFS2;B01;MC06;ACPF3;SC0302;TYVA01;MESG4 | G14: ='Comparativo s adjudicados'!F31 -> 5122764 | Z14: =Y14=X14 -> TRUE
A15: =CONCATENATE(B15,C15,D15,E15) -> 4110BI00411CONT1;HFS2;B01;MC06;ACPF5;SC0302;TYVA01;MESG4 | B15: 411 | C15: 0 | D15: BI00411 | E15: CONT1;HFS2;B01;MC06;ACPF5;SC0302;TYVA01;MESG4 | F15: ='Comparativo s adjudicados'!F20 -> 2493971 | G15: ='Comparativo s adjudicados'!F33 -> 2493971 | H15: =G15-F15 -> 0 | I15: ='Comparativo s adjudicados'!G20 -> EU2 | J15: ='Comparativo s adjudicados'!G33 -> EU2 | K15: =I15=J15 -> TRUE | L15: ='Comparativo s adjudicados'!H20 -> CHRO2 | M15: ='Comparativo s adjudicados'!H33 -> CHRO2 | N15: =L15=M15 -> TRUE | O15: ='Comparativo s adjudicados'!I20 -> ACUT2 | P15: ='Comparativo s adjudicados'!I33 -> ACUT2 | Q15: =O15=P15 -> TRUE | R15: ='Comparativo s adjudicados'!J20 -> GEO2 | S15: ='Comparativo s adjudicados'!J33 -> GEO2 | T15: =R15=S15 -> TRUE | W15: =U15=V15 -> TRUE | Z15: =Y15=X15 -> TRUE
A16: =CONCATENATE(B16,C16,D16,E16) | F16: ='Comparativo s adjudicados'!F22 -> 171653011 | G16: ='Comparativo s adjudicados'!F34 -> 171653012 | H16: =G16-F16 -> 1 | I16: ='Comparativo s adjudicados'!G22 -> EU1 | J16: ='Comparativo s adjudicados'!G34 -> EU1 | K16: =I16=J16 -> TRUE | L16: ='Comparativo s adjudicados'!H22 -> CHRO2 | M16: ='Comparativo s adjudicados'!H34 -> CHRO2 | N16: =L16=M16 -> TRUE | O16: ='Comparativo s adjudicados'!I22 -> ACUT2 | P16: ='Comparativo s adjudicados'!I34 -> ACUT2 | Q16: =O16=P16 -> TRUE | R16: ='Comparativo s adjudicados'!J22 -> GEO3 | S16: ='Comparativo s adjudicados'!J34 -> GEO3 | T16: =R16=S16 -> TRUE | W16: =U16=V16 -> TRUE | Z16: =Y16=X16 -> TRUE
A17: =CONCATENATE(B17,C17,D17,E17) -> 4110BI00411CONT1;HFS2;B01;MC06;ACPF5;SC0303;TYVA01;EXC2;MESG4 | B17: 411 | C17: 0 | D17: BI00411 | E17: CONT1;HFS2;B01;MC06;ACPF5;SC0303;TYVA01;EXC2;MESG4 | F17: ='Comparativo s adjudicados'!F15 -> 22684 | G17: ='Comparativo s adjudicados'!F37 -> 22684 | H17: =G17-F17 -> 0 | I17: ='Comparativo s adjudicados'!G15 -> EU1 | J17: ='Comparativo s adjudicados'!G37 -> EU1 | K17: =I17=J17 -> TRUE | L17: ='Comparativo s adjudicados'!H15 -> CHRO2 | M17: ='Comparativo s adjudicados'!H37 -> CHRO2 | N17: =L17=M17 -> TRUE | O17: ='Comparativo s adjudicados'!I15 -> ACUT2 | P17: ='Comparativo s adjudicados'!I37 -> ACUT2 | Q17: =O17=P17 -> TRUE | R17: ='Comparativo s adjudicados'!J15 -> GEO3 | S17: ='Comparativo s adjudicados'!J37 -> GEO3 | T17: =R17=S17 -> TRUE | U17: ='Comparativo s adjudicados'!K15 -> CNAEL18 | V17: ='Comparativo s adjudicados'!K37 -> CNAEL18 | W17: =U17=V17 -> TRUE | X17: ='Comparativo s adjudicados'!L15 -> NACE19010303 | Y17: ='Comparativo s adjudicados'!L37 -> NACE19010303 | Z17: =Y17=X17 -> TRUE
A18: =CONCATENATE(B18,C18,D18,E18) -> 4110BI00411 | B18: 411 | C18: 0 | D18: BI00411 | F18: ='Comparativo s adjudicados'!F18 -> 131176 | G18: ='Comparativo s adjudicados'!F36 -> 131176 | H18: =G18-F18 -> 0 | J18: =INDEX('Comparativo s adjudicados'!$A$26:$O$42,MATCH('Comparativo - Deltas Granul'!$A18,'Comparativo s adjudicados'!$A$26:$A$42,0),MATCH('Comparativo - Deltas Granul'!I$10,'Comparativo s adjudicados'!$A$26:$O$26,0)) -> #N/A | L18: =INDEX('Comparativo s adjudicados'!$A$9:$L$22,MATCH('Comparativo - Deltas Granul'!$A18,'Comparativo s adjudicados'!$A$9:$A$22,0),MATCH('Comparativo - Deltas Granul'!L$10,'Comparativo s adjudicados'!$A$9:$L$9,0)) -> #N/A | M18: =INDEX('Comparativo s adjudicados'!$A$26:$O$42,MATCH('Comparativo - Deltas Granul'!$A18,'Comparativo s adjudicados'!$A$26:$A$42,0),MATCH('Comparativo - Deltas Granul'!L$10,'Comparativo s adjudicados'!$A$26:$O$26,0)) -> #N/A | N18: =L18=M18 -> #N/A | O18: =INDEX('Comparativo s adjudicados'!$A$9:$L$22,MATCH('Comparativo - Deltas Granul'!$A18,'Comparativo s adjudicados'!$A$9:$A$22,0),MATCH('Comparativo - Deltas Granul'!O$10,'Comparativo s adjudicados'!$A$9:$L$9,0)) -> #N/A | P18: =INDEX('Comparativo s adjudicados'!$A$26:$O$42,MATCH('Comparativo - Deltas Granul'!$A18,'Comparativo s adjudicados'!$A$26:$A$42,0),MATCH('Comparativo - Deltas Granul'!O$10,'Comparativo s adjudicados'!$A$26:$O$26,0)) -> #N/A | Q18: =O18=P18 -> #N/A | R18: ='Comparativo s adjudicados'!J18 -> GEO18 | S18: ='Comparativo s adjudicados'!J36 -> GEO18 | T18: =R18=S18 -> TRUE | U18: ='Comparativo s adjudicados'!K18 -> CNAEL11 | V18: ='Comparativo s adjudicados'!K36 -> CNAEL11 | W18: =U18=V18 -> TRUE | X18: ='Comparativo s adjudicados'!L18 -> NACE12010101 | Y18: ='Comparativo s adjudicados'!L36 -> NACE12010101 | Z18: =Y18=X18 -> TRUE
A19: =CONCATENATE(B19,C19,D19,E19) -> 4110BI00411 | B19: 411 | C19: 0 | D19: BI00411 | F19: ='Comparativo s adjudicados'!F21 -> 35578 | G19: ='Comparativo s adjudicados'!F35 -> 35578 | H19: =G19-F19 -> 0 | J19: ='Comparativo s adjudicados'!G37 -> EU1 | L19: ='Comparativo s adjudicados'!H15 -> CHRO2 | M19: ='Comparativo s adjudicados'!H37 -> CHRO2 | N19: =L19=M19 -> TRUE | O19: ='Comparativo s adjudicados'!I15 -> ACUT2 | P19: ='Comparativo s adjudicados'!I37 -> ACUT2 | Q19: =O19=P19 -> TRUE | R19: ='Comparativo s adjudicados'!J21 -> GEO3 | S19: ='Comparativo s adjudicados'!J35 -> GEO3 | T19: =R19=S19 -> TRUE | U19: ='Comparativo s adjudicados'!K21 -> CNAEL3 | V19: ='Comparativo s adjudicados'!K35 -> CNAEL3 | W19: =U19=V19 -> TRUE | X19: ='Comparativo s adjudicados'!L21 -> NACE03200302 | Y19: ='Comparativo s adjudicados'!L35 -> NACE03200302 | Z19: =Y19=X19 -> TRUE
A20: =CONCATENATE(B20,C20,D20,E20) -> 4111333BI00411CONT1;HFS2;B01;MC08;TYVA01;INVS4;MESG4 | B20: 411 | C20: 1333 | D20: BI00411 | E20: CONT1;HFS2;B01;MC08;TYVA01;INVS4;MESG4 | F20: =_xlfn.IFNA(INDEX('Comparativo s adjudicados'!$A$9:$L$22, MATCH('Comparativo - Deltas Granul'!$A20,'Comparativo s adjudicados'!$A$9:$A$22,0), MATCH('Comparativo - Deltas Granul'!F$10,'Comparativo s adjudicados'!$A$9:$L$9,0)),"") -> 88691496 | G20: =INDEX('Comparativo s adjudicados'!$A$26:$O$44, MATCH('Comparativo - Deltas Granul'!$A20,'Comparativo s adjudicados'!$A$26:$A$44,0), MATCH('Comparativo - Deltas Granul'!F$10,'Comparativo s adjudicados'!$A$26:$O$26,0)) -> 88691496 | H20: =G20-F20 -> 0 | I20: =_xlfn.IFNA(INDEX('Comparativo s adjudicados'!$A$9:$L$22, MATCH('Comparativo - Deltas Granul'!$A20,'Comparativo s adjudicados'!$A$9:$A$22,0), MATCH('Comparativo - Deltas Granul'!I$10,'Comparativo s adjudicados'!$A$9:$L$9,0)),"") -> EU1 | J20: =_xlfn.IFNA(INDEX('Comparativo s adjudicados'!$A$26:$O$44, MATCH('Comparativo - Deltas Granul'!$A20,'Comparativo s adjudicados'!$A$26:$A$44,0), MATCH('Comparativo - Deltas Granul'!I$10,'Comparativo s adjudicados'!$A$26:$O$26,0)),"") -> EU1 | K20: =I20=J20 -> TRUE | L20: =_xlfn.IFNA(INDEX('Comparativo s adjudicados'!$A$9:$L$22,MATCH('Comparativo - Deltas Granul'!$A20,'Comparativo s adjudicados'!$A$9:$A$22,0),MATCH('Comparativo - Deltas Granul'!L$10,'Comparativo s adjudicados'!$A$9:$L$9,0)),"") -> CHRO2 | M20: =_xlfn.IFNA(INDEX('Comparativo s adjudicados'!$A$26:$O$44, MATCH('Comparativo - Deltas Granul'!$A20,'Comparativo s adjudicados'!$A$26:$A$44,0), MATCH('Comparativo - Deltas Granul'!L$10,'Comparativo s adjudicados'!$A$26:$O$26,0)),"") -> CHRO2 | N20: =L20=M20 -> TRUE | O20: =_xlfn.IFNA(INDEX('Comparativo s adjudicados'!$A$9:$L$22,MATCH('Comparativo - Deltas Granul'!$A20,'Comparativo s adjudicados'!$A$9:$A$22,0),MATCH('Comparativo - Deltas Granul'!O$10,'Comparativo s adjudicados'!$A$9:$L$9,0)),"") -> ACUT2 | P20: =_xlfn.IFNA(INDEX('Comparativo s adjudicados'!$A$26:$O$44, MATCH('Comparativo - Deltas Granul'!$A20,'Comparativo s adjudicados'!$A$26:$A$44,0), MATCH('Comparativo - Deltas Granul'!O$10,'Comparativo s adjudicados'!$A$26:$O$26,0)),"") -> ACUT2 | Q20: =O20=P20 -> TRUE | R20: =_xlfn.IFNA(INDEX('Comparativo s adjudicados'!$A$9:$L$22,MATCH('Comparativo - Deltas Granul'!$A20,'Comparativo s adjudicados'!$A$9:$A$22,0),MATCH('Comparativo - Deltas Granul'!R$10,'Comparativo s adjudicados'!$A$9:$L$9,0)),"") -> GEO3 | S20: =_xlfn.IFNA(INDEX('Comparativo s adjudicados'!$A$26:$O$44, MATCH('Comparativo - Deltas Granul'!$A20,'Comparativo s adjudicados'!$A$26:$A$44,0), MATCH('Comparativo - Deltas Granul'!R$10,'Comparativo s adjudicados'!$A$26:$O$26,0)),"") -> GEO3 | T20: =R20=S20 -> TRUE | W20: =U20=V20 -> TRUE | Z20: =Y20=X20 -> TRUE
A21: =CONCATENATE(B21,C21,D21,E21) -> 4113162BI00411CONT1;HFS2;B01;MC08;TYVA01;INVS4;MESG4 | B21: 411 | C21: 3162 | D21: BI00411 | E21: CONT1;HFS2;B01;MC08;TYVA01;INVS4;MESG4 | F21: =_xlfn.IFNA(INDEX('Comparativo s adjudicados'!$A$9:$L$22, MATCH('Comparativo - Deltas Granul'!$A21,'Comparativo s adjudicados'!$A$9:$A$22,0), MATCH('Comparativo - Deltas Granul'!F$10,'Comparativo s adjudicados'!$A$9:$L$9,0)),"") -> 7932813 | G21: =INDEX('Comparativo s adjudicados'!$A$26:$O$44, MATCH('Comparativo - Deltas Granul'!$A21,'Comparativo s adjudicados'!$A$26:$A$44,0), MATCH('Comparativo - Deltas Granul'!F$10,'Comparativo s adjudicados'!$A$26:$O$26,0)) -> 7932813 | H21: =G21-F21 -> 0 | I21: =_xlfn.IFNA(INDEX('Comparativo s adjudicados'!$A$9:$L$22, MATCH('Comparativo - Deltas Granul'!$A21,'Comparativo s adjudicados'!$A$9:$A$22,0), MATCH('Comparativo - Deltas Granul'!I$10,'Comparativo s adjudicados'!$A$9:$L$9,0)),"") -> EU1 | J21: =_xlfn.IFNA(INDEX('Comparativo s adjudicados'!$A$26:$O$44, MATCH('Comparativo - Deltas Granul'!$A21,'Comparativo s adjudicados'!$A$26:$A$44,0), MATCH('Comparativo - Deltas Granul'!I$10,'Comparativo s adjudicados'!$A$26:$O$26,0)),"") -> EU1 | K21: =I21=J21 -> TRUE | L21: =_xlfn.IFNA(INDEX('Comparativo s adjudicados'!$A$9:$L$22,MATCH('Comparativo - Deltas Granul'!$A21,'Comparativo s adjudicados'!$A$9:$A$22,0),MATCH('Comparativo - Deltas Granul'!L$10,'Comparativo s adjudicados'!$A$9:$L$9,0)),"") -> CHRO2 | M21: =_xlfn.IFNA(INDEX('Comparativo s adjudicados'!$A$26:$O$44, MATCH('Comparativo - Deltas Granul'!$A21,'Comparativo s adjudicados'!$A$26:$A$44,0), MATCH('Comparativo - Deltas Granul'!L$10,'Comparativo s adjudicados'!$A$26:$O$26,0)),"") -> CHRO2 | N21: =L21=M21 -> TRUE | O21: =_xlfn.IFNA(INDEX('Comparativo s adjudicados'!$A$9:$L$22,MATCH('Comparativo - Deltas Granul'!$A21,'Comparativo s adjudicados'!$A$9:$A$22,0),MATCH('Comparativo - Deltas Granul'!O$10,'Comparativo s adjudicados'!$A$9:$L$9,0)),"") -> ACUT2 | P21: =_xlfn.IFNA(INDEX('Comparativo s adjudicados'!$A$26:$O$44, MATCH('Comparativo - Deltas Granul'!$A21,'Comparativo s adjudicados'!$A$26:$A$44,0), MATCH('Comparativo - Deltas Granul'!O$10,'Comparativo s adjudicados'!$A$26:$O$26,0)),"") -> ACUT2 | Q21: =O21=P21 -> TRUE | R21: =_xlfn.IFNA(INDEX('Comparativo s adjudicados'!$A$9:$L$22,MATCH('Comparativo - Deltas Granul'!$A21,'Comparativo s adjudicados'!$A$9:$A$22,0),MATCH('Comparativo - Deltas Granul'!R$10,'Comparativo s adjudicados'!$A$9:$L$9,0)),"") -> GEO3 | S21: =_xlfn.IFNA(INDEX('Comparativo s adjudicados'!$A$26:$O$44, MATCH('Comparativo - Deltas Granul'!$A21,'Comparativo s adjudicados'!$A$26:$A$44,0), MATCH('Comparativo - Deltas Granul'!R$10,'Comparativo s adjudicados'!$A$26:$O$26,0)),"") -> GEO3 | T21: =R21=S21 -> TRUE | W21: =U21=V21 -> TRUE | Z21: =Y21=X21 -> TRUE
A22: =CONCATENATE(B22,C22,D22,E22) -> 411421BI00411CONT1;HFS2;B01;MC08;TYVA01;INVS4;MESG4 | B22: 411 | C22: 421 | D22: BI00411 | E22: CONT1;HFS2;B01;MC08;TYVA01;INVS4;MESG4 | F22: =_xlfn.IFNA(INDEX('Comparativo s adjudicados'!$A$9:$L$22, MATCH('Comparativo - Deltas Granul'!$A22,'Comparativo s adjudicados'!$A$9:$A$22,0), MATCH('Comparativo - Deltas Granul'!F$10,'Comparativo s adjudicados'!$A$9:$L$9,0)),"") -> 450662960 | G22: =INDEX('Comparativo s adjudicados'!$A$26:$O$44, MATCH('Comparativo - Deltas Granul'!$A22,'Comparativo s adjudicados'!$A$26:$A$44,0), MATCH('Comparativo - Deltas Granul'!F$10,'Comparativo s adjudicados'!$A$26:$O$26,0)) -> 450662960 | H22: =G22-F22 -> 0 | I22: =_xlfn.IFNA(INDEX('Comparativo s adjudicados'!$A$9:$L$22, MATCH('Comparativo - Deltas Granul'!$A22,'Comparativo s adjudicados'!$A$9:$A$22,0), MATCH('Comparativo - Deltas Granul'!I$10,'Comparativo s adjudicados'!$A$9:$L$9,0)),"") -> EU1 | J22: =_xlfn.IFNA(INDEX('Comparativo s adjudicados'!$A$26:$O$44, MATCH('Comparativo - Deltas Granul'!$A22,'Comparativo s adjudicados'!$A$26:$A$44,0), MATCH('Comparativo - Deltas Granul'!I$10,'Comparativo s adjudicados'!$A$26:$O$26,0)),"") -> EU1 | K22: =I22=J22 -> TRUE | L22: =_xlfn.IFNA(INDEX('Comparativo s adjudicados'!$A$9:$L$22,MATCH('Comparativo - Deltas Granul'!$A22,'Comparativo s adjudicados'!$A$9:$A$22,0),MATCH('Comparativo - Deltas Granul'!L$10,'Comparativo s adjudicados'!$A$9:$L$9,0)),"") -> CHRO2 | M22: =_xlfn.IFNA(INDEX('Comparativo s adjudicados'!$A$26:$O$44, MATCH('Comparativo - Deltas Granul'!$A22,'Comparativo s adjudicados'!$A$26:$A$44,0), MATCH('Comparativo - Deltas Granul'!L$10,'Comparativo s adjudicados'!$A$26:$O$26,0)),"") -> CHRO2 | N22: =L22=M22 -> TRUE | O22: =_xlfn.IFNA(INDEX('Comparativo s adjudicados'!$A$9:$L$22,MATCH('Comparativo - Deltas Granul'!$A22,'Comparativo s adjudicados'!$A$9:$A$22,0),MATCH('Comparativo - Deltas Granul'!O$10,'Comparativo s adjudicados'!$A$9:$L$9,0)),"") -> ACUT2 | P22: =_xlfn.IFNA(INDEX('Comparativo s adjudicados'!$A$26:$O$44, MATCH('Comparativo - Deltas Granul'!$A22,'Comparativo s adjudicados'!$A$26:$A$44,0), MATCH('Comparativo - Deltas Granul'!O$10,'Comparativo s adjudicados'!$A$26:$O$26,0)),"") -> ACUT2 | Q22: =O22=P22 -> TRUE | R22: =_xlfn.IFNA(INDEX('Comparativo s adjudicados'!$A$9:$L$22,MATCH('Comparativo - Deltas Granul'!$A22,'Comparativo s adjudicados'!$A$9:$A$22,0),MATCH('Comparativo - Deltas Granul'!R$10,'Comparativo s adjudicados'!$A$9:$L$9,0)),"") -> GEO18 | S22: =_xlfn.IFNA(INDEX('Comparativo s adjudicados'!$A$26:$O$44, MATCH('Comparativo - Deltas Granul'!$A22,'Comparativo s adjudicados'!$A$26:$A$44,0), MATCH('Comparativo - Deltas Granul'!R$10,'Comparativo s adjudicados'!$A$26:$O$26,0)),"") -> GEO18 | T22: =R22=S22 -> TRUE | W22: =U22=V22 -> TRUE | Z22: =Y22=X22 -> TRUE
A23: =CONCATENATE(B23,C23,D23,E23) -> 411442BI00411CONT1;HFS2;B01;MC08;TYVA01;INVS5;EXC2;MESG4 | B23: 411 | C23: 442 | D23: BI00411 | E23: CONT1;HFS2;B01;MC08;TYVA01;INVS5;EXC2;MESG4 | F23: =_xlfn.IFNA(INDEX('Comparativo s adjudicados'!$A$9:$L$22, MATCH('Comparativo - Deltas Granul'!$A23,'Comparativo s adjudicados'!$A$9:$A$22,0), MATCH('Comparativo - Deltas Granul'!F$10,'Comparativo s adjudicados'!$A$9:$L$9,0)),"") -> 99962303 | G23: =INDEX('Comparativo s adjudicados'!$A$26:$O$44, MATCH('Comparativo - Deltas Granul'!$A23,'Comparativo s adjudicados'!$A$26:$A$44,0), MATCH('Comparativo - Deltas Granul'!F$10,'Comparativo s adjudicados'!$A$26:$O$26,0)) -> 99962303 | H23: =G23-F23 -> 0 | I23: =_xlfn.IFNA(INDEX('Comparativo s adjudicados'!$A$9:$L$22, MATCH('Comparativo - Deltas Granul'!$A23,'Comparativo s adjudicados'!$A$9:$A$22,0), MATCH('Comparativo - Deltas Granul'!I$10,'Comparativo s adjudicados'!$A$9:$L$9,0)),"") -> EU1 | J23: =_xlfn.IFNA(INDEX('Comparativo s adjudicados'!$A$26:$O$44, MATCH('Comparativo - Deltas Granul'!$A23,'Comparativo s adjudicados'!$A$26:$A$44,0), MATCH('Comparativo - Deltas Granul'!I$10,'Comparativo s adjudicados'!$A$26:$O$26,0)),"") -> EU1 | K23: =I23=J23 -> TRUE | L23: =_xlfn.IFNA(INDEX('Comparativo s adjudicados'!$A$9:$L$22,MATCH('Comparativo - Deltas Granul'!$A23,'Comparativo s adjudicados'!$A$9:$A$22,0),MATCH('Comparativo - Deltas Granul'!L$10,'Comparativo s adjudicados'!$A$9:$L$9,0)),"") -> CHRO2 | M23: =_xlfn.IFNA(INDEX('Comparativo s adjudicados'!$A$26:$O$44, MATCH('Comparativo - Deltas Granul'!$A23,'Comparativo s adjudicados'!$A$26:$A$44,0), MATCH('Comparativo - Deltas Granul'!L$10,'Comparativo s adjudicados'!$A$26:$O$26,0)),"") -> CHRO2 | N23: =L23=M23 -> TRUE | O23: =_xlfn.IFNA(INDEX('Comparativo s adjudicados'!$A$9:$L$22,MATCH('Comparativo - Deltas Granul'!$A23,'Comparativo s adjudicados'!$A$9:$A$22,0),MATCH('Comparativo - Deltas Granul'!O$10,'Comparativo s adjudicados'!$A$9:$L$9,0)),"") -> ACUT2 | P23: =_xlfn.IFNA(INDEX('Comparativo s adjudicados'!$A$26:$O$44, MATCH('Comparativo - Deltas Granul'!$A23,'Comparativo s adjudicados'!$A$26:$A$44,0), MATCH('Comparativo - Deltas Granul'!O$10,'Comparativo s adjudicados'!$A$26:$O$26,0)),"") -> ACUT2 | Q23: =O23=P23 -> TRUE | R23: =_xlfn.IFNA(INDEX('Comparativo s adjudicados'!$A$9:$L$22,MATCH('Comparativo - Deltas Granul'!$A23,'Comparativo s adjudicados'!$A$9:$A$22,0),MATCH('Comparativo - Deltas Granul'!R$10,'Comparativo s adjudicados'!$A$9:$L$9,0)),"") -> GEO3 | S23: =_xlfn.IFNA(INDEX('Comparativo s adjudicados'!$A$26:$O$44, MATCH('Comparativo - Deltas Granul'!$A23,'Comparativo s adjudicados'!$A$26:$A$44,0), MATCH('Comparativo - Deltas Granul'!R$10,'Comparativo s adjudicados'!$A$26:$O$26,0)),"") -> GEO3 | T23: =R23=S23 -> TRUE | U23: =_xlfn.IFNA(INDEX('Comparativo s adjudicados'!$A$9:$L$22,MATCH('Comparativo - Deltas Granul'!$A23,'Comparativo s adjudicados'!$A$9:$A$22,0),MATCH('Comparativo - Deltas Granul'!U$10,'Comparativo s adjudicados'!$A$9:$L$9,0)),"") -> CNAEL6 | V23: =_xlfn.IFNA(INDEX('Comparativo s adjudicados'!$A$26:$O$44, MATCH('Comparativo - Deltas Granul'!$A23,'Comparativo s adjudicados'!$A$26:$A$44,0), MATCH('Comparativo - Deltas Granul'!U$10,'Comparativo s adjudicados'!$A$26:$O$26,0)),"") -> CNAEL6 | W23: =U23=V23 -> TRUE | X23: =_xlfn.IFNA(INDEX('Comparativo s adjudicados'!$A$9:$L$22,MATCH('Comparativo - Deltas Granul'!$A23,'Comparativo s adjudicados'!$A$9:$A$22,0),MATCH('Comparativo - Deltas Granul'!X$10,'Comparativo s adjudicados'!$A$9:$L$9,0)),"") -> NACE06010101 | Y23: =_xlfn.IFNA(INDEX('Comparativo s adjudicados'!$A$26:$O$44, MATCH('Comparativo - Deltas Granul'!$A23,'Comparativo s adjudicados'!$A$26:$A$44,0), MATCH('Comparativo - Deltas Granul'!X$10,'Comparativo s adjudicados'!$A$26:$O$26,0)),"") -> NACE06010101 | Z23: =Y23=X23 -> TRUE
A24: =CONCATENATE(B24,C24,D24,E24) -> 411442BI00411CONT1;HFS2;B01;MC08;TYVA02;INVS5;EXC2 | B24: 411 | C24: 442 | D24: BI00411 | E24: CONT1;HFS2;B01;MC08;TYVA02;INVS5;EXC2 | F24: =_xlfn.IFNA(INDEX('Comparativo s adjudicados'!$A$9:$L$22, MATCH('Comparativo - Deltas Granul'!$A24,'Comparativo s adjudicados'!$A$9:$A$22,0), MATCH('Comparativo - Deltas Granul'!F$10,'Comparativo s adjudicados'!$A$9:$L$9,0)),"") -> -11000000 | G24: =INDEX('Comparativo s adjudicados'!$A$26:$O$44, MATCH('Comparativo - Deltas Granul'!$A24,'Comparativo s adjudicados'!$A$26:$A$44,0), MATCH('Comparativo - Deltas Granul'!F$10,'Comparativo s adjudicados'!$A$26:$O$26,0)) -> -11000000 | H24: =G24-F24 -> 0 | I24: =_xlfn.IFNA(INDEX('Comparativo s adjudicados'!$A$9:$L$22, MATCH('Comparativo - Deltas Granul'!$A24,'Comparativo s adjudicados'!$A$9:$A$22,0), MATCH('Comparativo - Deltas Granul'!I$10,'Comparativo s adjudicados'!$A$9:$L$9,0)),"") -> EU1 | J24: =_xlfn.IFNA(INDEX('Comparativo s adjudicados'!$A$26:$O$44, MATCH('Comparativo - Deltas Granul'!$A24,'Comparativo s adjudicados'!$A$26:$A$44,0), MATCH('Comparativo - Deltas Granul'!I$10,'Comparativo s adjudicados'!$A$26:$O$26,0)),"") -> EU1 | K24: =I24=J24 -> TRUE | L24: =_xlfn.IFNA(INDEX('Comparativo s adjudicados'!$A$9:$L$22,MATCH('Comparativo - Deltas Granul'!$A24,'Comparativo s adjudicados'!$A$9:$A$22,0),MATCH('Comparativo - Deltas Granul'!L$10,'Comparativo s adjudicados'!$A$9:$L$9,0)),"") -> CHRO2 | M24: =_xlfn.IFNA(INDEX('Comparativo s adjudicados'!$A$26:$O$44, MATCH('Comparativo - Deltas Granul'!$A24,'Comparativo s adjudicados'!$A$26:$A$44,0), MATCH('Comparativo - Deltas Granul'!L$10,'Comparativo s adjudicados'!$A$26:$O$26,0)),"") -> CHRO2 | N24: =L24=M24 -> TRUE | O24: =_xlfn.IFNA(INDEX('Comparativo s adjudicados'!$A$9:$L$22,MATCH('Comparativo - Deltas Granul'!$A24,'Comparativo s adjudicados'!$A$9:$A$22,0),MATCH('Comparativo - Deltas Granul'!O$10,'Comparativo s adjudicados'!$A$9:$L$9,0)),"") -> ACUT2 | P24: =_xlfn.IFNA(INDEX('Comparativo s adjudicados'!$A$26:$O$44, MATCH('Comparativo - Deltas Granul'!$A24,'Comparativo s adjudicados'!$A$26:$A$44,0), MATCH('Comparativo - Deltas Granul'!O$10,'Comparativo s adjudicados'!$A$26:$O$26,0)),"") -> ACUT2 | Q24: =O24=P24 -> TRUE | R24: =_xlfn.IFNA(INDEX('Comparativo s adjudicados'!$A$9:$L$22,MATCH('Comparativo - Deltas Granul'!$A24,'Comparativo s adjudicados'!$A$9:$A$22,0),MATCH('Comparativo - Deltas Granul'!R$10,'Comparativo s adjudicados'!$A$9:$L$9,0)),"") -> GEO3 | S24: =_xlfn.IFNA(INDEX('Comparativo s adjudicados'!$A$26:$O$44, MATCH('Comparativo - Deltas Granul'!$A24,'Comparativo s adjudicados'!$A$26:$A$44,0), MATCH('Comparativo - Deltas Granul'!R$10,'Comparativo s adjudicados'!$A$26:$O$26,0)),"") -> GEO3 | T24: =R24=S24 -> TRUE | U24: =_xlfn.IFNA(INDEX('Comparativo s adjudicados'!$A$9:$L$22,MATCH('Comparativo - Deltas Granul'!$A24,'Comparativo s adjudicados'!$A$9:$A$22,0),MATCH('Comparativo - Deltas Granul'!U$10,'Comparativo s adjudicados'!$A$9:$L$9,0)),"") -> CNAEL6 | V24: =_xlfn.IFNA(INDEX('Comparativo s adjudicados'!$A$26:$O$44, MATCH('Comparativo - Deltas Granul'!$A24,'Comparativo s adjudicados'!$A$26:$A$44,0), MATCH('Comparativo - Deltas Granul'!U$10,'Comparativo s adjudicados'!$A$26:$O$26,0)),"") -> CNAEL6 | W24: =U24=V24 -> TRUE | X24: =_xlfn.IFNA(INDEX('Comparativo s adjudicados'!$A$9:$L$22,MATCH('Comparativo - Deltas Granul'!$A24,'Comparativo s adjudicados'!$A$9:$A$22,0),MATCH('Comparativo - Deltas Granul'!X$10,'Comparativo s adjudicados'!$A$9:$L$9,0)),"") -> NACE06010101 | Y24: =_xlfn.IFNA(INDEX('Comparativo s adjudicados'!$A$26:$O$44, MATCH('Comparativo - Deltas Granul'!$A24,'Comparativo s adjudicados'!$A$26:$A$44,0), MATCH('Comparativo - Deltas Granul'!X$10,'Comparativo s adjudicados'!$A$26:$O$26,0)),"") -> NACE06010101 | Z24: =Y24=X24 -> TRUE
A25: =CONCATENATE(B25,C25,D25,E25) -> 411445BI00411CONT1;HFS2;B01;MC08;TYVA01;INVS4;MESG4 | B25: 411 | C25: 445 | D25: BI00411 | E25: CONT1;HFS2;B01;MC08;TYVA01;INVS4;MESG4 | F25: =_xlfn.IFNA(INDEX('Comparativo s adjudicados'!$A$9:$L$22, MATCH('Comparativo - Deltas Granul'!$A25,'Comparativo s adjudicados'!$A$9:$A$22,0), MATCH('Comparativo - Deltas Granul'!F$10,'Comparativo s adjudicados'!$A$9:$L$9,0)),"") -> 49500 | G25: =INDEX('Comparativo s adjudicados'!$A$26:$O$44, MATCH('Comparativo - Deltas Granul'!$A25,'Comparativo s adjudicados'!$A$26:$A$44,0), MATCH('Comparativo - Deltas Granul'!F$10,'Comparativo s adjudicados'!$A$26:$O$26,0)) -> 49500 | H25: =G25-F25 -> 0 | I25: =_xlfn.IFNA(INDEX('Comparativo s adjudicados'!$A$9:$L$22, MATCH('Comparativo - Deltas Granul'!$A25,'Comparativo s adjudicados'!$A$9:$A$22,0), MATCH('Comparativo - Deltas Granul'!I$10,'Comparativo s adjudicados'!$A$9:$L$9,0)),"") -> EU1 | J25: =_xlfn.IFNA(INDEX('Comparativo s adjudicados'!$A$26:$O$44, MATCH('Comparativo - Deltas Granul'!$A25,'Comparativo s adjudicados'!$A$26:$A$44,0), MATCH('Comparativo - Deltas Granul'!I$10,'Comparativo s adjudicados'!$A$26:$O$26,0)),"") -> EU1 | K25: =I25=J25 -> TRUE | L25: =_xlfn.IFNA(INDEX('Comparativo s adjudicados'!$A$9:$L$22,MATCH('Comparativo - Deltas Granul'!$A25,'Comparativo s adjudicados'!$A$9:$A$22,0),MATCH('Comparativo - Deltas Granul'!L$10,'Comparativo s adjudicados'!$A$9:$L$9,0)),"") -> CHRO2 | M25: =_xlfn.IFNA(INDEX('Comparativo s adjudicados'!$A$26:$O$44, MATCH('Comparativo - Deltas Granul'!$A25,'Comparativo s adjudicados'!$A$26:$A$44,0), MATCH('Comparativo - Deltas Granul'!L$10,'Comparativo s adjudicados'!$A$26:$O$26,0)),"") -> CHRO2 | N25: =L25=M25 -> TRUE | O25: =_xlfn.IFNA(INDEX('Comparativo s adjudicados'!$A$9:$L$22,MATCH('Comparativo - Deltas Granul'!$A25,'Comparativo s adjudicados'!$A$9:$A$22,0),MATCH('Comparativo - Deltas Granul'!O$10,'Comparativo s adjudicados'!$A$9:$L$9,0)),"") -> ACUT2 | P25: =_xlfn.IFNA(INDEX('Comparativo s adjudicados'!$A$26:$O$44, MATCH('Comparativo - Deltas Granul'!$A25,'Comparativo s adjudicados'!$A$26:$A$44,0), MATCH('Comparativo - Deltas Granul'!O$10,'Comparativo s adjudicados'!$A$26:$O$26,0)),"") -> ACUT2 | Q25: =O25=P25 -> TRUE | R25: =_xlfn.IFNA(INDEX('Comparativo s adjudicados'!$A$9:$L$22,MATCH('Comparativo - Deltas Granul'!$A25,'Comparativo s adjudicados'!$A$9:$A$22,0),MATCH('Comparativo - Deltas Granul'!R$10,'Comparativo s adjudicados'!$A$9:$L$9,0)),"") -> GEO3 | S25: =_xlfn.IFNA(INDEX('Comparativo s adjudicados'!$A$26:$O$44, MATCH('Comparativo - Deltas Granul'!$A25,'Comparativo s adjudicados'!$A$26:$A$44,0), MATCH('Comparativo - Deltas Granul'!R$10,'Comparativo s adjudicados'!$A$26:$O$26,0)),"") -> GEO3 | T25: =R25=S25 -> TRUE | W25: =U25=V25 -> TRUE | Z25: =Y25=X25 -> TRUE
B26: Total | F26: =SUM(F12:F25) -> 827721324 | G26: =SUM(G12:G25) -> 827721326 | H26: =G26-F26 -> 2

Sheet Sat79 - Tático Dez 24
B8: Satélite 79 reportado no exercício tático do Pilar III em ESG - Dezembro 2024
B10: informing_soc | C10: counterparty_soc | D10: adjustment_code | E10: comb_code | F10: amount | G10: eu | H10: chro | I10: acut | J10: geo | K10: cnael | L10: nace
B11: 411 | C11: 421 | D11: BI00411 | E11: CONT1;HFS2;B01;MC08;TYVA01;INVS4;MESG4 | F11: 450662960 | G11: EU1 | H11: CHRO2 | I11: ACUT2 | J11: GEO18
B12: 411 | C12: 3162 | D12: BI00411 | E12: CONT1;HFS2;B01;MC08;TYVA01;INVS4;MESG4 | F12: 7932813 | G12: EU1 | H12: CHRO2 | I12: ACUT2 | J12: GEO3
B13: 411 | C13: 1333 | D13: BI00411 | E13: CONT1;HFS2;B01;MC08;TYVA01;INVS4;MESG4 | F13: 88691496 | G13: EU1 | H13: CHRO2 | I13: ACUT2 | J13: GEO3
B14: 411 | C14: 421 | D14: BI00411 | E14: CONT1;HFS2;B01;MC08;TYVA01;;MESG4 | F14: -1 | G14: EU1 | H14: CHRO2 | I14: ACUT2 | J14: GEO18
B15: 411 | C15: 442 | D15: BI00411 | E15: CONT1;HFS2;B01;MC08;TYVA01;INVS5;EXC2;MESG4 | F15: 99962303 | G15: EU1 | H15: CHRO2 | I15: ACUT2 | J15: GEO3 | K15: CNAEL6 | L15: NACE06010101
B16: 411 | C16: 0 | D16: BI00411 | E16: CONT1;HFS2;B01;MC06;ACPF5;SC0303;TYVA01;EXC2;MESG4 | F16: 22684 | G16: EU1 | H16: CHRO2 | I16: ACUT2 | J16: GEO3 | K16: CNAEL18 | L16: NACE19010303
B17: 411 | C17: 0 | D17: BI00411 | E17: CONT1;HFS2;B01;MC06;ACPF3;SC0302;TYVA01;MESG4 | F17: 17085832 | G17: EU1 | H17: CHRO2 | I17: ACUT2 | J17: GEO3
B18: 411 | C18: 445 | D18: BI00411 | E18: CONT1;HFS2;B01;MC08;TYVA01;INVS4;MESG4 | F18: 49500 | G18: EU1 | H18: CHRO2 | I18: ACUT2 | J18: GEO3
B19: 411 | C19: 0 | D19: BI00411 | E19: CONT1;HFS2;B01;MC06;ACPF5;SC0303;TYVA01;EXC2;MESG4 | F19: 131176 | G19: EU1 | H19: CHRO2 | I19: ACUT2 | J19: GEO18 | K19: CNAEL11 | L19: NACE12010101
B20: 411 | C20: 442 | D20: BI00411 | E20: CONT1;HFS2;B01;MC08;TYVA02;INVS5;EXC2 | F20: -11000000 | G20: EU1 | H20: CHRO2 | I20: ACUT2 | J20: GEO3 | K20: CNAEL6 | L20: NACE06010101
B21: 411 | C21: 0 | D21: BI00411 | E21: CONT1;HFS2;B01;MC06;ACPF5;SC0302;TYVA01;MESG4 | F21: 2493971 | G21: EU2 | H21: CHRO2 | I21: ACUT2 | J21: GEO2
B22: 411 | C22: 0 | D22: BI00411 | E22: CONT1;HFS2;B01;MC06;ACPF5;SC0303;TYVA01;EXC2;MESG4 | F22: 35578 | G22: EU1 | H22: CHRO2 | I22: ACUT2 | J22: GEO3 | K22: CNAEL3 | L22: NACE03200302
B23: 411 | C23: 0 | D23: BI00411 | E23: CONT1;HFS2;B01;MC06;ACPF5;SC0302;TYVA01;MESG4 | F23: 171653011 | G23: EU1 | H23: CHRO2 | I23: ACUT2 | J23: GEO3

Sheet Sat 79 - Sol. Estrutural
B8: Satélite 79 - Satélite gerado pela solução estrutural To Be - Dezembro 2024
B10: reporting_soc | C10: counterparty_soc | D10: adjustment_code | E10: comb_code | F10: amount | G10: eu | H10: chro | I10: acut | J10: geo | K10: cnael | L10: nace
B11: 411 | C11: 0 | D11: BI00411 | E11: CONT1;HFS2;B01;MC06;ACPF3;SC0302;TYVA01;MESG4 | F11: 11163168 | G11: EU1 | H11: CHRO2 | I11: ACUT2 | J11: GEO3 | L11: NACE11030301
B12: 411 | C12: 0 | D12: BI00411 | E12: CONT1;HFS2;B01;MC06;ACPF3;SC0302;TYVA01;MESG4 | F12: 799901 | G12: EU1 | H12: CHRO2 | I12: ACUT2 | J12: GEO3 | L12: NACE11010403
B13: 411 | C13: 0 | D13: BI00411 | E13: CONT1;HFS2;B01;MC06;ACPF3;SC0302;TYVA01;MESG4 | F13: 5122764 | G13: EU1 | H13: CHRO2 | I13: ACUT2 | J13: GEO3
B14: 411 | C14: 0 | D14: BI00411 | E14: CONT1;HFS2;B01;MC06;ACPF5;SC0302;TYVA01;MESG4 | F14: 2493971 | G14: EU2 | H14: CHRO2 | I14: ACUT2 | J14: GEO2
B15: 411 | C15: 0 | D15: BI00411 | E15: CONT1;HFS2;B01;MC06;ACPF5;SC0302;TYVA01;MESG4 | F15: 171653012 | G15: EU1 | H15: CHRO2 | I15: ACUT2 | J15: GEO3
B16: 411 | C16: 0 | D16: BI00411 | E16: CONT1;HFS2;B01;MC06;ACPF5;SC0303;TYVA01;EXC2;MESG4 | F16: 35578 | G16: EU1 | H16: CHRO2 | I16: ACUT2 | J16: GEO3 | K16: CNAEL3 | L16: NACE03200302
B17: 411 | C17: 0 | D17: BI00411 | E17: CONT1;HFS2;B01;MC06;ACPF5;SC0303;TYVA01;EXC2;MESG4 | F17: 131176 | G17: EU1 | H17: CHRO2 | I17: ACUT2 | J17: GEO18 | K17: CNAEL11 | L17: NACE12010101
B18: 411 | C18: 0 | D18: BI00411 | E18: CONT1;HFS2;B01;MC06;ACPF5;SC0303;TYVA01;EXC2;MESG4 | F18: 22684 | G18: EU1 | H18: CHRO2 | I18: ACUT2 | J18: GEO3 | K18: CNAEL18 | L18: NACE19010303
B19: 411 | C19: 1333 | D19: BI00411 | E19: CONT1;HFS2;B01;MC08;TYVA01;INVS4;MESG4 | F19: 88691496 | G19: EU1 | H19: CHRO2 | I19: ACUT2 | J19: GEO3
B20: 411 | C20: 3162 | D20: BI00411 | E20: CONT1;HFS2;B01;MC08;TYVA01;INVS4;MESG4 | F20: 7932813 | G20: EU1 | H20: CHRO2 | I20: ACUT2 | J20: GEO3
B21: 411 | C21: 421 | D21: BI00411 | E21: CONT1;HFS2;B01;MC08;TYVA01;INVS4;MESG4 | F21: 450662960 | G21: EU1 | H21: CHRO2 | I21: ACUT2 | J21: GEO18
B22: 411 | C22: 442 | D22: BI00411 | E22: CONT1;HFS2;B01;MC08;TYVA01;INVS5;EXC2;MESG4 | F22: 99962303 | G22: EU1 | H22: CHRO2 | I22: ACUT2 | J22: GEO3 | K22: CNAEL6 | L22: NACE06010101
B23: 411 | C23: 442 | D23: BI00411 | E23: CONT1;HFS2;B01;MC08;TYVA02;INVS5;EXC2 | F23: -11000000 | G23: EU1 | H23: CHRO2 | I23: ACUT2 | J23: GEO3 | K23: CNAEL6 | L23: NACE06010101
B24: 411 | C24: 445 | D24: BI00411 | E24: CONT1;HFS2;B01;MC08;TYVA01;INVS4;MESG4 | F24: 49500 | G24: EU1 | H24: CHRO2 | I24: ACUT2 | J24: GEO3

Sheet Sat79_dez24
B8: reporting_soc | C8: counterparty_soc | D8: adjustment_code | E8: id_comb | F8: amount | G8: eu | H8: chro | I8: acut | J8: geo | K8: cnael | L8: nace | M8: aveg
B9: 00411 | C9: 00000 | D9: BI00411 | E9: CONT1;HFS2;B01;MC02;ACPF6;SC0303;STAG2;DEFA2;COLL1;TYVA02;FVAD3;PERF1;EXC2 | F9: -22 | G9: EU2 | H9: CHRO2 | I9: ACUT2 | J9: GEO17 | K9: CNAEL7 | L9: NACE07020703
B10: 00411 | C10: 00000 | D10: BI00411 | E10: CONT1;HFS2;B01;MC04;ACPF6;SC0303;STAG1;DEFA2;COLL1;TYVA01;FVAD3;PERF1;EXC2;MESG1 | F10: 4644341 | G10: EU1 | H10: CHRO2 | I10: ACUT2 | J10: GEO3 | K10: CNAEL18 | L10: NACE10040401 | M10: 1
B11: 00411 | C11: 00000 | D11: BI00411 | E11: CONT1;HFS2;B01;MC02;ACPF6;SC0303;STAG1;DEFA2;COLL1;TYVA02;FVAD3;PERF1;EXC2 | F11: -9188 | G11: EU1 | H11: CHRO2 | I11: ACUT2 | J11: GEO3 | K11: CNAEL3 | L11: NACE03140401
B12: 00411 | C12: 00000 | D12: BI00411 | E12: CONT1;HFS2;B01;MC02;ACPF6;SC0303;STAG2;DEFA2;COLL4;TYVA02;FVAD3;PERF1;EXC2 | F12: -121 | G12: EU1 | H12: CHRO1 | I12: ACUT2 | J12: GEO3 | K12: CNAEL3 | L12: NACE03240201
B13: 00411 | C13: 00000 | D13: BI00411 | E13: CONT1;HFS2;B01;MC02;ACPF6;SC0303;STAG1;DEFA2;COLL3;TYVA01;FVAD3;PERF1;EXC2;MESG2 | F13: 118825 | G13: EU1 | H13: CHRO1 | I13: ACUT2 | J13: GEO3 | K13: CNAEL7 | L13: NACE07030505 | M13: 6
B14: 00411 | C14: 00000 | D14: BI00411 | E14: CONT1;HFS2;B01;MC02;ACPF6;SC0303;STAG1;DEFA2;COLL4;TYVA01;FVAD3;PERF1;EXC2;MESG1 | F14: 342170 | G14: EU1 | H14: CHRO2 | I14: ACUT2 | J14: GEO3 | K14: CNAEL12 | L14: NACE13030101 | M14: 3
B15: 00411 | C15: 00000 | D15: BI00411 | E15: CONT1;HFS2;B01;MC02;ACPF6;SC0303;STAG3;DEFA1;COLL4;TYVA02;FVAD3;PERF2;EXC2 | F15: -19996 | G15: EU1 | H15: CHRO2 | I15: ACUT2 | J15: GEO3 | K15: CNAEL16 | L15: NACE17010301
B16: 00411 | C16: 00000 | D16: BI00411 | E16: CONT1;HFS2;B01;MC02;ACPF6;SC0303;STAG1;DEFA2;COLL4;TYVA01;FVAD3;PERF1;EXC2;MESG1 | F16: 55070 | G16: EU1 | H16: CHRO1 | I16: ACUT2 | J16: GEO3 | K16: CNAEL3 | L16: NACE03140802 | M16: 1
B17: 00411 | C17: 00000 | D17: BI00411 | E17: CONT1;HFS2;B01;MC02;ACPF6;SC0303;STAG1;DEFA2;COLL1;TYVA02;FVAD3;PERF1;EXC2 | F17: -2081 | G17: EU1 | H17: CHRO2 | I17: ACUT2 | J17: GEO3 | K17: CNAEL15 | L17: NACE16010601
B18: 00411 | C18: 00000 | D18: BI00411 | E18: CONT1;HFS2;B01;MC02;ACPF6;SC0303;STAG3;DEFA1;COLL3;TYVA01;FVAD3;PERF2;EXC2;MESG1 | F18: 37 | G18: EU1 | H18: CHRO2 | I18: ACUT2 | J18: GEO3 | K18: CNAEL7 | L18: NACE07020701 | M18: 0
B19: 00411 | C19: 00000 | D19: BI00411 | E19: CONT1;HFS2;B01;MC02;ACPF6;SC0303;STAG1;DEFA2;COLL4;TYVA02;FVAD3;PERF1;EXC1 | F19: -9 | G19: EU1 | H19: CHRO2 | I19: ACUT2 | J19: GEO3 | K19: CNAEL12 | L19: NACE13030102
B20: 00411 | C20: 00000 | D20: BI00411 | E20: CONT1;HFS2;B01;MC02;ACPF6;SC0303;STAG3;DEFA1;COLL3;TYVA02;FVAD3;PERF2;EXC2 | F20: -30449 | G20: EU1 | H20: CHRO1 | I20: ACUT2 | J20: GEO3 | K20: CNAEL3 | L20: NACE03040201
B21: 00411 | C21: 00000 | D21: BI00411 | E21: CONT1;HFS2;B01;MC02;ACPF6;SC0303;STAG2;DEFA2;COLL1;TYVA01;FVAD3;PERF1;EXC2;MESG5 | F21: 255474 | G21: EU1 | H21: CHRO2 | I21: ACUT2 | J21: GEO3 | K21: CNAEL6 | L21: NACE06030303
B22: 00411 | C22: 00000 | D22: BI00411 | E22: CONT1;HFS2;B01;MC02;ACPF6;SC0303;STAG2;DEFA2;COLL4;TYVA02;FVAD3;PERF1;EXC2 | F22: -217 | G22: EU1 | H22: CHRO1 | I22: ACUT2 | J22: GEO3 | K22: CNAEL3 | L22: NACE03010103
B23: 00411 | C23: 00000 | D23: BI00411 | E23: CONT1;HFS2;B01;MC02;ACPF6;SC0303;STAG3;DEFA1;COLL3;TYVA02;FVAD3;PERF2;EXC2 | F23: -681 | G23: EU1 | H23: CHRO2 | I23: ACUT2 | J23: GEO3 | K23: CNAEL12 | L23: NACE13060101
B24: 00411 | C24: 00000 | D24: BI00411 | E24: CONT1;HFS2;B01;MC02;ACPF6;SC0303;STAG1;DEFA2;COLL4;TYVA02;FVAD3;PERF1;EXC2 | F24: -4585 | G24: EU1 | H24: CHRO2 | I24: ACUT2 | J24: GEO3 | K24: CNAEL7 | L24: NACE07030708
B25: 00411 | C25: 00000 | D25: BI00411 | E25: CONT1;HFS2;B01;MC02;ACPF6;SC0303;STAG2;DEFA2;COLL4;TYVA01;FVAD3;PERF1;EXC2;MESG1 | F25: 30748 | G25: EU1 | H25: CHRO2 | I25: ACUT2 | J25: GEO3 | K25: CNAEL8 | L25: NACE08040204 | M25: 5
B26: 00411 | C26: 00000 | D26: BI00411 | E26: CONT1;HFS2;B01;MC02;ACPF6;SC0303;STAG2;DEFA2;COLL4;TYVA02;FVAD3;PERF1;EXC2 | F26: -4681 | G26: EU1 | H26: CHRO2 | I26: ACUT2 | J26: GEO3 | K26: CNAEL3 | L26: NACE03110401
B27: 00411 | C27: 00000 | D27: BI00411 | E27: CONT1;HFS2;B01;MC02;ACPF6;SC0303;STAG1;DEFA2;COLL1;TYVA01;FVAD3;PERF1;EXC2;MESG1 | F27: 246120 | G27: EU1 | H27: CHRO2 | I27: ACUT2 | J27: GEO3 | K27: CNAEL10 | L27: NACE10050103 | M27: 2
B28: 00411 | C28: 00000 | D28: BI00411 | E28: CONT1;HFS2;B01;MC02;ACPF6;SC0303;STAG1;DEFA2;COLL1;TYVA01;FVAD3;PERF1;EXC2;MESG1 | F28: 12914804 | G28: EU1 | H28: CHRO2 | I28: ACUT2 | J28: GEO3 | K28: CNAEL10 | L28: NACE10040101 | M28: 1
B29: 00411 | C29: 00000 | D29: BI00411 | E29: CONT1;HFS2;B01;MC02;ACPF6;SC0303;STAG1;DEFA2;COLL1;TYVA01;FVAD3;PERF1;EXC2;MESG1 | F29: 542115 | G29: EU1 | H29: CHRO1 | I29: ACUT2 | J29: GEO3 | K29: CNAEL3 | L29: NACE03160701 | M29: 2
B30: 00411 | C30: 00000 | D30: BI00411 | E30: CONT1;HFS2;B01;MC02;ACPF6;SC0303;STAG2;DEFA2;COLL1;TYVA01;FVAD3;PERF1;EXC2;MESG5 | F30: 66 | G30: EU1 | H30: CHRO2 | I30: ACUT2 | J30: GEO3 | K30: CNAEL3 | L30: NACE03190103
B31: 00411 | C31: 00000 | D31: BI00411 | E31: CONT1;HFS2;B01;MC02;ACPF6;SC0303;STAG1;DEFA2;COLL1;TYVA02;FVAD3;PERF1;EXC2 | F31: -1803 | G31: EU1 | H31: CHRO1 | I31: ACUT2 | J31: GEO3 | K31: CNAEL3 | L31: NACE03170301
B32: 00411 | C32: 00000 | D32: BI00411 | E32: CONT1;HFS2;B01;MC02;ACPF6;SC0303;STAG2;DEFA2;COLL4;TYVA02;FVAD3;PERF1;EXC2 | F32: -2598 | G32: EU1 | H32: CHRO2 | I32: ACUT2 | J32: GEO3 | K32: CNAEL7 | L32: NACE07020204
B33: 00411 | C33: 00000 | D33: BI00411 | E33: CONT1;HFS2;B01;MC02;ACPF6;SC0303;STAG2;DEFA2;COLL1;TYVA01;FVAD3;PERF1;EXC2;MESG1 | F33: 3304605 | G33: EU1 | H33: CHRO1 | I33: ACUT2 | J33: GEO3 | K33: CNAEL3 | L33: NACE03040201 | M33: 2
B34: 00411 | C34: 00000 | D34: BI00411 | E34: CONT1;HFS2;B01;MC02;ACPF6;SC0303;STAG1;DEFA2;COLL1;TYVA02;FVAD3;PERF1;EXC2 | F34: -2351 | G34: EU1 | H34: CHRO1 | I34: ACUT2 | J34: GEO3 | K34: CNAEL6 | L34: NACE06030302
B35: 00411 | C35: 00000 | D35: BI00411 | E35: CONT1;HFS2;B01;MC02;ACPF6;SC0303;STAG3;DEFA1;COLL1;TYVA01;FVAD3;PERF2;EXC2;MESG5 | F35: 1556 | G35: EU1 | H35: CHRO1 | I35: ACUT2 | J35: GEO3 | K35: CNAEL3 | L35: NACE03010703
B36: 00411 | C36: 00000 | D36: BI00411 | E36: CONT1;HFS2;B01;MC02;ACPF6;SC0303;STAG2;DEFA2;COLL1;TYVA01;FVAD3;PERF1;EXC2;MESG2 | F36: 225187 | G36: EU1 | H36: CHRO2 | I36: ACUT2 | J36: GEO3 | K36: CNAEL10 | L36: NACE10020201 | M36: 7
B37: 00411 | C37: 00000 | D37: BI00411 | E37: CONT1;HFS2;B01;MC02;ACPF6;SC0303;STAG1;DEFA2;COLL1;TYVA01;FVAD3;PERF1;EXC2;MESG1 | F37: 5876887 | G37: EU1 | H37: CHRO2 | I37: ACUT2 | J37: GEO3 | K37: CNAEL8 | L37: NACE08040202 | M37: 2
B38: 00411 | C38: 00000 | D38: BI00411 | E38: CONT1;HFS2;B01;MC02;ACPF6;SC0303;STAG2;DEFA2;COLL4;TYVA02;FVAD3;PERF1;EXC2 | F38: -19629 | G38: EU1 | H38: CHRO2 | I38: ACUT2 | J38: GEO3 | K38: CNAEL9 | L38: NACE09010201
B39: 00411 | C39: 00000 | D39: BI00411 | E39: CONT1;HFS2;B01;MC02;ACPF6;SC0303;STAG1;DEFA2;COLL1;TYVA02;FVAD3;PERF1;EXC2 | F39: -16763 | G39: EU1 | H39: CHRO1 | I39: ACUT2 | J39: GEO3 | K39: CNAEL3 | L39: NACE03160803
B40: 00411 | C40: 00000 | D40: BI00411 | E40: CONT1;HFS2;B01;MC02;ACPF6;SC0303;STAG3;DEFA1;COLL1;TYVA01;FVAD3;PERF2;EXC2;MESG5 | F40: 3235 | G40: EU1 | H40: CHRO1 | I40: ACUT2 | J40: GEO3 | K40: CNAEL7 | L40: NACE07030203
B41: 00411 | C41: 00000 | D41: BI00411 | E41: CONT1;HFS2;B01;MC02;ACPF6;SC0303;STAG1;DEFA2;COLL1;TYVA01;FVAD3;PERF1;EXC2;MESG2 | F41: 834339 | G41: EU1 | H41: CHRO2 | I41: ACUT2 | J41: GEO3 | K41: CNAEL9 | L41: NACE09020301 | M41: 7
B42: 00411 | C42: 00000 | D42: BI00411 | E42: CONT1;HFS2;B01;MC02;ACPF6;SC0303;STAG2;DEFA2;COLL4;TYVA02;FVAD3;PERF1;EXC2 | F42: -8 | G42: EU1 | H42: CHRO2 | I42: ACUT2 | J42: GEO3 | K42: CNAEL12 | L42: NACE13040102
B43: 00411 | C43: 00000 | D43: BI00411 | E43: CONT1;HFS2;B01;MC02;ACPF6;SC0303;STAG1;DEFA2;COLL4;TYVA02;FVAD3;PERF1;EXC2 | F43: -1068 | G43: EU1 | H43: CHRO2 | I43: ACUT2 | J43: GEO3 | K43: CNAEL3 | L43: NACE03070101
B44: 00411 | C44: 00000 | D44: BI00411 | E44: CONT1;HFS2;B01;MC02;ACPF6;SC0303;STAG3;DEFA1;COLL4;TYVA01;FVAD3;PERF2;EXC2;MESG1 | F44: 56857 | G44: EU1 | H44: CHRO2 | I44: ACUT2 | J44: GEO3 | K44: CNAEL7 | L44: NACE07020703 | M44: 2
