Workbook

Sheet Reconciliação
B2: BALANCETE (Nov25) | G2: B0200 (Nov25) | L2: FINREP (Set25) | R2: B0200 (Set25)
B3: Conta IFRS | C3: Descritivo Conta IFRS | D3: Valor Original | E3: Filtros adicionais | F3: Valor Final | G3: Rank Insolvência | H3: Valor (c0080, c0100) | I3: diff | J3: Status | L3: Mapa | M3: Rubrica | N3: Descritivo Conta IFRS | O3: Valor Original | P3: Filtros adicionais | Q3: Valor final | R3: Rank Insolvência | S3: Valor (c0080, c0100) | T3: diff | U3: Status
B4: 251019900 | C4: =+VLOOKUP(B4,Balancete!A:F,2,FALSE) -> Capital/ Nocional/ Custo de aquisição | D4: =-VLOOKUP(B4,Balancete!A:F,5,FALSE)+VLOOKUP(B4,Balancete!A:F,6,FALSE) -> 207599000 | F4: =+D4 -> 207599000 | G4: 3 | H4: =+SUMIFS('B0200 (Nov25)'!H:H,'B0200 (Nov25)'!Q:Q,Reconciliação!G4) -> 207599000 | I4: =+H4-F4 -> 0 | J4: =+IF(ABS(I4)<1,"OK","NOK") -> OK | L4: f01.02 | M4: 0130 | N4: Debt securities issued | O4: =+VLOOKUP(M4,'F 01.02'!C:D,2,FALSE) -> 6788545206 | P4: CT610.RANK_INSOLV IN ('3','8') AND FR001.CCONTAB_FINAL_IFRS IN ('25101110','25101111','25101112','25101113','251019210','251019211','251019900','251019901','251019910','251019911','25111110') | Q4: =+$M$16 -> 1.3206838e+09 | R4: 3 e 8 | S4: =+SUMIFS('B0200 (Set25)'!H:H,'B0200 (Set25)'!Q:Q,3)+SUMIFS('B0200 (Set25)'!J:J,'B0200 (Set25)'!Q:Q,3) +SUMIFS('B0200 (Set25)'!H:H,'B0200 (Set25)'!Q:Q,8)+SUMIFS('B0200 (Set25)'!J:J,'B0200 (Set25)'!Q:Q,8) -> 1.3206838e+09 | T4: =+S4-Q4 -> 0 | U4: =+IF(ABS(T4)<1,"OK","NOK") -> OK
B5: 251019901 | C5: =+VLOOKUP(B5,Balancete!A:F,2,FALSE) -> Juros/encargos a pagar | D5: =-VLOOKUP(B5,Balancete!A:F,5,FALSE)+VLOOKUP(B5,Balancete!A:F,6,FALSE) -> 4607714.5 | F5: =+D5 -> 4607714.5 | G5: 3 | H5: =+SUMIFS('B0200 (Nov25)'!J:J,'B0200 (Nov25)'!Q:Q,Reconciliação!G5) -> 4607714.5 | I5: =+H5-F5 -> 0 | J5: =+IF(ABS(I5)<1,"OK","NOK") -> OK | L5: f01.03 | M5: 0020 | N5: Paid up capital | O5: =+VLOOKUP(M5,'F 01.03'!C:D,2,FALSE) -> 1391779674 | P5: Retirar o montante detido pela reporting entity (5100011001), uma vez que o montante será reportado no campo c0090. | Q5: =+$N$16 -> 1385452938 | R5: 1 | S5: =+SUMIFS('B0200 (Set25)'!H:H,'B0200 (Set25)'!Q:Q,R5) -> 1385452938 | T5: =+S5-SUM(Q5,Q6,Q7) -> -174242988 | U5: =+IF(ABS(T5)<1,"OK","NOK") -> NOK
B6: 251019910 | C6: =+VLOOKUP(B6,Balancete!A:F,2,FALSE) -> Capital/ Nocional/ Custo de aquisição | D6: =-VLOOKUP(B6,Balancete!A:F,5,FALSE)+VLOOKUP(B6,Balancete!A:F,6,FALSE) -> 1600000000 | E6: CT610.RANK_INSOLV = 8 | F6: =+SUMIFS($G$16:$G$31,$B$16:$B$31,B6) -> 1100000000 | G6: 8 | H6: =+SUMIFS('B0200 (Nov25)'!H:H,'B0200 (Nov25)'!Q:Q,Reconciliação!G6) -> 1100000000 | I6: =+H6-F6 -> 0 | J6: =+IF(ABS(I6)<1,"OK","NOK") -> OK | M6: 0040 | N6: Share premium | O6: =+VLOOKUP(M6,'F 01.03'!C:D,2,FALSE) -> 193389954 | Q6: =+O6 -> 193389954 | U6: =+IF(ABS(T6)<1,"OK","NOK") -> OK
B7: 251019911 | C7: =+VLOOKUP(B7,Balancete!A:F,2,FALSE) -> Juros/encargos a pagar | D7: =-VLOOKUP(B7,Balancete!A:F,5,FALSE)+VLOOKUP(B7,Balancete!A:F,6,FALSE) -> 17603816 | E7: CT610.RANK_INSOLV = 8 | F7: =+SUMIFS($G$16:$G$31,$B$16:$B$31,B7) -> 16059638 | G7: 8 | H7: =+SUMIFS('B0200 (Nov25)'!J:J,'B0200 (Nov25)'!Q:Q,Reconciliação!G7) -> 16059638 | I7: =+H7-F7 -> 0 | J7: =+IF(ABS(I7)<1,"OK","NOK") -> OK | M7: 0240 | N7: (-) Treasury shares | O7: =+VLOOKUP(M7,'F 01.03'!C:D,2,FALSE) -> -19146966 | Q7: =+O7 -> -19146966 | U7: =+IF(ABS(T7)<1,"OK","NOK") -> OK
B8: 6000 | C8: =+VLOOKUP(B8,Balancete!A:F,2,FALSE) -> Acções ordinárias | D8: =-VLOOKUP(B8,Balancete!A:F,5,FALSE)+VLOOKUP(B8,Balancete!A:F,6,FALSE) -> 1391779674 | E8: Retirar o montante detido pela reporting entity (5100011001), uma vez que o montante será reportado no campo c0090. | F8: =+SUMIFS($G$16:$G$31,$B$16:$B$31,B8) -> 1385452938 | G8: 1 | H8: =+SUMIFS('B0200 (Nov25)'!H:H,'B0200 (Nov25)'!Q:Q,Reconciliação!G8) -> 1385452938 | I8: =+H8-SUM($F$8:$F$10) -> -1.7424299e+08 | J8: =+IF(ABS(I8)<1,"OK","NOK") -> NOK | M8: 0070 | N8: Other equity instruments issued | O8: =+VLOOKUP(M8,'F 01.03'!C:D,2,FALSE) -> 1200000000 | Q8: =+O8 -> 1200000000 | R8: 2 | S8: =+SUMIFS('B0200 (Set25)'!H:H,'B0200 (Set25)'!Q:Q,R8) -> 1200000000 | T8: =+S8-Q8 -> 0 | U8: =+IF(ABS(T8)<1,"OK","NOK") -> OK
B9: 610 | C9: =+VLOOKUP(B9,Balancete!A:F,2,FALSE) -> De instrumentos de capital | D9: =-VLOOKUP(B9,Balancete!A:F,5,FALSE)+VLOOKUP(B9,Balancete!A:F,6,FALSE) -> 1.9338995e+08 | F9: =+D9 -> 1.9338995e+08 | J9: =+IF(ABS(I9)<1,"OK","NOK") -> OK | L9: f08.01.A | M9: 0430 | N9: Other debt securities issued (non convertible) | O9: =+VLOOKUP(M9,'F 08.01.a'!C:F,4,FALSE) -> 1821663986 | P9: CT610.RANK_INSOLV IN ('3','8') AND FR001.CCONTAB_FINAL_IFRS IN ('25101110','25101111','25101112','25101113','251019210','251019211','251019900','251019901','251019910','251019911','25111110') | Q9: =+$O$16 -> 1.3206838e+09 | R9: 3 e 8 | S9: =+SUMIFS('B0200 (Set25)'!H:H,'B0200 (Set25)'!Q:Q,3)+SUMIFS('B0200 (Set25)'!J:J,'B0200 (Set25)'!Q:Q,3) +SUMIFS('B0200 (Set25)'!H:H,'B0200 (Set25)'!Q:Q,8)+SUMIFS('B0200 (Set25)'!J:J,'B0200 (Set25)'!Q:Q,8) -> 1.3206838e+09 | T9: =+S9-Q9 -> 0 | U9: =+IF(ABS(T9)<1,"OK","NOK") -> OK
B10: 660 | C10: =+VLOOKUP(B10,Balancete!A:F,2,FALSE) -> Acções ordinárias | D10: =-VLOOKUP(B10,Balancete!A:F,5,FALSE)+VLOOKUP(B10,Balancete!A:F,6,FALSE) -> -19146966 | F10: =+D10 -> -19146966 | J10: =+IF(ABS(I10)<1,"OK","NOK") -> OK | L10: f08.02 | M10: 0030 | N10: Subordinated financial liabilities | O10: =+VLOOKUP(M10,'F 08.02'!C:E,3,FALSE) -> 211105753 | Q10: =+O10 -> 211105753 | R10: 3 | S10: =+SUMIFS('B0200 (Set25)'!H:H,'B0200 (Set25)'!Q:Q,3)+SUMIFS('B0200 (Set25)'!J:J,'B0200 (Set25)'!Q:Q,3) -> 2.1110575e+08 | T10: =+S10-Q10 -> 0.43000001 | U10: =+IF(ABS(T10)<1,"OK","NOK") -> OK
B11: 6205 | C11: =+VLOOKUP(B11,Balancete!A:F,2,FALSE) -> Instrumentos AT1 | D11: =-VLOOKUP(B11,Balancete!A:F,5,FALSE)+VLOOKUP(B11,Balancete!A:F,6,FALSE) -> 1200000000 | F11: =+D11 -> 1200000000 | G11: 2 | H11: =+SUMIFS('B0200 (Nov25)'!H:H,'B0200 (Nov25)'!Q:Q,Reconciliação!G11) -> 1200000000 | I11: =+H11-F11 -> 0 | J11: =+IF(ABS(I11)<1,"OK","NOK") -> OK
B13: query de extração: | L13: query de extração:
B15: conta | C15: rank_insolv | D15: msaldo_final | E15: zcliente | F15: prtn_amnt_rprtng_entty | G15: valor_final | M15: f0102_valor_final | N15: f0103_valor_final | O15: f0801a_valor_final
B16: 251019910 | C16: 8 | D16: 600000000.000000 | E16: 3686 | F16: 0.000000 | G16: 600000000 | M16: 1.3206838e+09 | N16: 1385452938 | O16: 1.3206838e+09
B17: 251019910 | C17: 8 | D17: 500000000.000000 | E17: 3686 | F17: 0.000000 | G17: 500000000
B18: 251019911 | C18: 8 | D18: 6901534.250000 | E18: 3686 | F18: 0.000000 | G18: 6901534.2
B19: 251019911 | C19: 8 | D19: 9158104.110000 | E19: 3686 | F19: 0.000000 | G19: 9158104.1
B20: 6000 | C20: 1 | D20: 1762761.000000 | E20: 0 | F20: 0.000000 | G20: 1762761 | M20: zcliente | N20: chave_fr001 | O20: ccontab_final_ifrs | P20: saldo | Q20: chave_master | R20: chave_finrep | S20: chave | T20: rank_insolv | U20: chave | V20: zcliente_emitente | W20: zcliente_investidor | X20: nom_tot_ini_investe | Y20: racio | Z20: otstndng_prncpl_amnt | AA20: prtn_amnt_rprtng_entty
B21: 6000 | C21: 1 | D21: 6326736.000000 | E21: 5100011001 | F21: 6326736.000000 | G21: 0 | M21: 5100011001 | N21: 31641600005800007PTCPP0AM0007000 | O21: 6000 | P21: 6326736 | Q21: 31641600005800007PTCPP0AM0007000 | R21: 31641600005800007PTCPP0AM0007000 | S21: 31641600005800007PTCPP0AM0007000 | T21: 1 | U21: 31641600005800007PTCPP0AM0007000 | V21: 5100011001 | W21: 5100011001 | X21: 6326736.000000 | Y21: 1.000000 | Z21: 6326736.000000000000 | AA21: 6326736.000000
B22: 6000 | C22: 1 | D22: 1383690177.000000 | E22: 3686 | F22: 0.000000 | G22: 1383690177 | M22: 3686 | N22: 31641600005800007PTCPP0AM0007000 | O22: 6000 | P22: 1383690177 | Q22: 31641600005800007PTCPP0AM0007000 | R22: 31641600005800007PTCPP0AM0007000 | S22: 31641600005800007PTCPP0AM0007000 | T22: 1 | U22: 31641600005800007PTCPP0AM0007000 | V22: 5100011001 | W22: 3686 | X22: 1383690177.000000 | Y22: 1.000000 | Z22: 1383690177.000000000000 | AA22: 0.000000
M23: 0 | N23: 31641600005800007PTCPP0AM0007000 | O23: 6000 | P23: 1762761 | Q23: 31641600005800007PTCPP0AM0007000 | R23: 31641600005800007PTCPP0AM0007000 | S23: 31641600005800007PTCPP0AM0007000 | T23: 1 | U23: 31641600005800007PTCPP0AM0007000 | V23: 5100011001 | W23: 0 | X23: 1762761.000000 | Y23: 1.000000 | Z23: 1762761.000000000000 | AA23: 0.000000
M24: 3686 | N24: 31641600000000000PTSTOFOM0004000 | O24: 251019900 | P24: 200000000 | Q24: 31641600000000000PTSTOFOM0004000 | R24: 31641600000000000PTSTOFOM0004000 | S24: 31641600000000000PTSTOFOM0004000 | T24: 3 | U24: 31641600000000000PTSTOFOM0004000 | V24: 5100011001 | W24: 3686 | X24: 200000000.000000 | Y24: 1.000000 | Z24: 200000000.000000000000 | AA24: 0.000000
M25: 3686 | N25: 31641600000000000PTSTOFOM0004000 | O25: 251019901 | P25: 4520274 | Q25: 31641600000000000PTSTOFOM0004000 | R25: 31641600000000000PTSTOFOM0004000 | S25: 31641600000000000PTSTOFOM0004000 | T25: 3 | U25: 31641600000000000PTSTOFOM0004000 | V25: 5100011001 | W25: 3686 | X25: 200000000.000000 | Y25: 1.000000 | Z25: 200000000.000000000000 | AA25: 0.000000
M26: 0 | N26: 31641600000000000PTBSREOM0028000 | O26: 251019900 | P26: 7599000 | Q26: 31641600000000000PTBSREOM0028000 | R26: 31641600000000000PTBSREOM0028000 | S26: 31641600000000000PTBSREOM0028000 | T26: 3 | U26: 31641600000000000PTBSREOM0028000 | V26: 5100011001 | W26: 0 | X26: 7599000.000000 | Y26: 1.000000 | Z26: 7599000.000000000000 | AA26: 0.000000
M27: 0 | N27: 31641600000000000PTBSREOM0028000 | O27: 251019901 | P27: 87440.55 | Q27: 31641600000000000PTBSREOM0028000 | R27: 31641600000000000PTBSREOM0028000 | S27: 31641600000000000PTBSREOM0028000 | T27: 3 | U27: 31641600000000000PTBSREOM0028000 | V27: 5100011001 | W27: 0 | X27: 7599000.000000 | Y27: 1.000000 | Z27: 7599000.000000000000 | AA27: 0.000000
M28: 3686 | N28: 31641600000000000PTSTOHOM0002000 | O28: 251019910 | P28: 500000000 | Q28: 31641600000000000PTSTOHOM0002000 | R28: 31641600000000000PTSTOHOM0002000 | S28: 31641600000000000PTSTOHOM0002000 | T28: 8 | U28: 31641600000000000PTSTOHOM0002000 | V28: 5100011001 | W28: 3686 | X28: 500000000.000000 | Y28: 1.000000 | Z28: 500000000.000000000000 | AA28: 0.000000
M29: 3686 | N29: 31641600000000000PTSTOHOM0002000 | O29: 251019911 | P29: 6901534.2 | Q29: 31641600000000000PTSTOHOM0002000 | R29: 31641600000000000PTSTOHOM0002000 | S29: 31641600000000000PTSTOHOM0002000 | T29: 8 | U29: 31641600000000000PTSTOHOM0002000 | V29: 5100011001 | W29: 3686 | X29: 500000000.000000 | Y29: 1.000000 | Z29: 500000000.000000000000 | AA29: 0.000000
M30: 3686 | N30: 31641600000000000PTSTOEOM0021000 | O30: 251019911 | P30: 9158104.1 | Q30: 31641600000000000PTSTOEOM0021000 | R30: 31641600000000000PTSTOEOM0021000 | S30: 31641600000000000PTSTOEOM0021000 | T30: 8 | U30: 31641600000000000PTSTOEOM0021000 | V30: 5100011001 | W30: 3686 | X30: 600000000.000000 | Y30: 1.000000 | Z30: 600000000.000000000000 | AA30: 0.000000
M31: 3686 | N31: 31641600000000000PTSTOEOM0021000 | O31: 251019910 | P31: 600000000 | Q31: 31641600000000000PTSTOEOM0021000 | R31: 31641600000000000PTSTOEOM0021000 | S31: 31641600000000000PTSTOEOM0021000 | T31: 8 | U31: 31641600000000000PTSTOEOM0021000 | V31: 5100011001 | W31: 3686 | X31: 600000000.000000 | Y31: 1.000000 | Z31: 600000000.000000000000 | AA31: 0.000000

Sheet B0200 (Nov25)
A2: 0010_row_nmbr | B2: 0020_uniq_id | C2: 0030_uniq_id_knwn_cntrprty | D2: 0040_typ_uniq_id_knwn_cntrprty | E2: 0050_orgnl_amnt_eur | F2: 0060_orgnl_amnt_fx | G2: 0070_cntrct_crrncy | H2: 0080_otstndng_prncpl_amnt | I2: 0090_prtn_amnt_rprtng_entty | J2: 0100_accrd_intrst_instrmnt | K2: 0110_applcbl_fees_charges | L2: 0120_otstndng_amnt | M2: 0130_rlvnt_amnt_wdc | N2: 0140_ntr_lblty | O2: 0141_ntr_lblty_othr | P2: 0150_flg_strctrlly_sbrdntd | Q2: 0160_rank_insolv | R2: 0161_cntrctl_sbrdntn | S2: 0162_bail_in_cascade | T2: 0170_dt_incptn | U2: 0180_dt_nxt_intrst_pymnt | V2: 0190_dt_nxt_rdmptn_pymnt | W2: 0200_dt_erlst_rdmptn | X2: 0210_dt_lgl_fnl_mtrty | Y2: 0220_governing_law | Z2: 0230_bail_in_rcgntn_cls | AA2: 0240_zero_coupon | AB2: 0250_strctrd_prdct | AC2: 0260_grntd_min_amnt_strctrd_prdct | AD2: 0270_fv_amnt_strctrd_prdct | AE2: 0280_flg_ncnp_dpsts | AF2: 0290_flg_ncbp_dpsts | AG2: 0300_amnt_cvrd_elgbl_dpsts | AH2: 0310_flg_clltrl_agrmnts | AI2: 0320_amnt_clltrl | AJ2: 0330_amnt_unclltrlzd | AK2: 0340_id_clltrl | AL2: 0350_typ_clltrl | AM2: 0351_typ_clltrl_othr | AN2: 0360_trdng_mthd | AO2: 0370_amnt_scrty_eur | AP2: 0380_amnt_scrty_fx | AQ2: 0390_nmbr_scrts_not_rprtng_entty | AR2: 0391_nmbr_scrts_rprtng_entty | AS2: 0400_accrd_intrst_scrty | AT2: 0410_fees_charges_scrty | AU2: 0420_fv_amnt_scrty | AV2: 0430_prncpl_amnt_glbl_nt_eur | AW2: 0431_prncpl_amnt_glbl_nt_fx | AX2: 0440_ntr_glbl_nt | AY2: 0450_crrnt_pool_fctr | AZ2: 0460_csd | BA2: 0461_csd_lei | BB2: 0462_csd_othr | BC2: 0470_pyng_agnt | BD2: 0471_pyng_agnt_lei | BE2: 0480_trdng_vn | BF2: 0481_trdng_vn_lei | BG2: 0490_rgstrr | BH2: 0491_rgstrr_lei | BI2: 0500_nna | BJ2: 0501_nna_lei | BK2: 0510_cmmn_dpstry | BL2: 0511_cmmn_dpstry_lei | BM2: 0520_cmmn_srvc_prvdr | BN2: 0521_cmmn_srvc_prvdr_lei | BO2: 0530_typ_own_fnds_ind_lvl | BP2: 0540_elgbl_amnt_own_fnds_ind_lvl | BQ2: 0550_typ_own_fnds_cnsldtd_lvl | BR2: 0560_elgbl_amnt_own_fnds_cnsldtd_lvl | BS2: 0570_amnt_scrty_intrst_prvdd | BT2: 0580_scrty_intrst_prvdr | BU2: 0581_scrty_intrst_prvdr_lei | BV2: 0590_typ_scrty_intrst_prvdd | BW2: 0600_flg_clltrl_asst_pstn | BX2: 0610_crryng_amnt_ifrs | BY2: 0620_blnc_sht_ifrs | BZ2: 0630_crrying_amnt_ngaap | CA2: 0640_blnc_sht_ngaap | CB2: 5000_flg_shrhldr_not_rsltn_grp | CC2: 5010_flg_art21_7a_srmr | CD2: ckutulmo | CE2: htimest | CF2: ref_date | CG2: cod_visao
A3: 1 | B3: 31641600000000000PTBSREOM0028000 | C3: PTBSREOM0028 | D3: ISIN | E3: 7599000 | F3: 999999999999999 | G3: EUR | H3: 7599000 | I3: 0 | J3: 87440.55 | K3: 0 | L3: 7686440.5 | M3: 7686440.5 | N3: Registered Bond | O3: Not applicable | P3: Not applicable | Q3: 3 | R3: 999999999999999 | S3: 3 | T3: 2016-09-28 | U3: 2026-10-06 | V3: 2026-10-06 | W3: 0001-01-01 | X3: 2026-10-06 | Y3: PT | Z3: Yes, supported by Legal Opinion | AA3: No ZCB | AB3: Non-structured/Vanilla | AC3: 999999999999999 | AD3: 999999999999999 | AE3: FALSE | AF3: FALSE | AG3: 999999999999999 | AH3: Unsecured | AI3: 999999999999999 | AJ3: 999999999999999 | AK3: Not applicable | AL3: Not applicable | AM3: Not applicable | AN3: Nominal | AO3: 1000 | AP3: 1000 | AQ3: 7599 | AR3: 0 | AS3: 11.5069 | AT3: 0 | AU3: 999999999999999 | AV3: 999999999999999 | AW3: 999999999999999 | AX3: Not applicable | AY3: -10000 | AZ3: INTERBOLSA_PT | BA3: 529900LG70TCAGWCXT47 | BB3: Not applicable | BC3: BANCO SANTANDER TOTTA S,A, | BD3: 549300URJH9VSI58CS32 | BE3: Not applicable | BF3: Not applicable | BG3: INTERBOLSA_PT | BH3: 529900LG70TCAGWCXT47 | BI3: INTERBOLSA_PT | BJ3: 529900LG70TCAGWCXT47 | BK3: Not applicable | BL3: Not applicable | BM3: Not applicable | BN3: Not applicable | BO3: Fully Compliant T2 | BP3: 7599000 | BQ3: Fully Compliant T2 | BR3: 7599000 | BS3: 0 | BT3: Not applicable | BU3: Not applicable | BV3: Not applicable | BW3: FALSE | BX3: 7686440.5 | BY3: 110 Financial liabilities at amortized cost | BZ3: 999999999999999 | CA3: Not applicable | CB3: FALSE | CC3: TRUE | CD3: servdlakep | CE3: 46027.477 | CF3: 2025-11-30 | CG3: 1
A4: 2 | B4: 31641600000000000PTSTOEOM0021000 | C4: PTSTOEOM0021 | D4: ISIN | E4: 600000000 | F4: 999999999999999 | G4: EUR | H4: 600000000 | I4: 0 | J4: 9158104.1 | K4: 0 | L4: 6.091581e+08 | M4: 6.091581e+08 | N4: Registered Bond | O4: Not applicable | P4: Not applicable | Q4: 8 | R4: 999999999999999 | S4: 8 | T4: 2022-06-01 | U4: 2026-06-03 | V4: 2027-06-03 | W4: 0001-01-01 | X4: 2027-06-03 | Y4: PT | Z4: Yes, supported by Legal Opinion | AA4: No ZCB | AB4: Non-structured/Vanilla | AC4: 999999999999999 | AD4: 999999999999999 | AE4: FALSE | AF4: FALSE | AG4: 999999999999999 | AH4: Unsecured | AI4: 999999999999999 | AJ4: 999999999999999 | AK4: Not applicable | AL4: Not applicable | AM4: Not applicable | AN4: Nominal | AO4: 100000 | AP4: 100000 | AQ4: 6000 | AR4: 0 | AS4: 1526.3507 | AT4: 0 | AU4: 999999999999999 | AV4: 999999999999999 | AW4: 999999999999999 | AX4: Not applicable | AY4: -10000 | AZ4: INTERBOLSA_PT | BA4: 529900LG70TCAGWCXT47 | BB4: Not applicable | BC4: BANCO SANTANDER TOTTA S,A, | BD4: 549300URJH9VSI58CS32 | BE4: Not applicable | BF4: Not applicable | BG4: INTERBOLSA_PT | BH4: 529900LG70TCAGWCXT47 | BI4: INTERBOLSA_PT | BJ4: 529900LG70TCAGWCXT47 | BK4: Not applicable | BL4: Not applicable | BM4: Not applicable | BN4: Not applicable | BO4: No | BP4: 0 | BQ4: No | BR4: 0 | BS4: 0 | BT4: Not applicable | BU4: Not applicable | BV4: Not applicable | BW4: FALSE | BX4: 6.091581e+08 | BY4: 110 Financial liabilities at amortized cost | BZ4: 999999999999999 | CA4: Not applicable | CB4: FALSE | CC4: TRUE | CD4: servdlakep | CE4: 46027.477 | CF4: 2025-11-30 | CG4: 1
A5: 3 | B5: 31641600000000000PTSTOFOM0004000 | C5: PTSTOFOM0004 | D5: ISIN | E5: 200000000 | F5: 999999999999999 | G5: EUR | H5: 200000000 | I5: 0 | J5: 4520274 | K5: 0 | L5: 2.0452027e+08 | M5: 2.0452027e+08 | N5: Registered Bond | O5: Not applicable | P5: Not applicable | Q5: 3 | R5: 999999999999999 | S5: 3 | T5: 2022-06-07 | U5: 2026-06-09 | V5: 2027-06-09 | W5: 0001-01-01 | X5: 2027-06-09 | Y5: PT | Z5: Yes, supported by Legal Opinion | AA5: No ZCB | AB5: Non-structured/Vanilla | AC5: 999999999999999 | AD5: 999999999999999 | AE5: FALSE | AF5: FALSE | AG5: 999999999999999 | AH5: Unsecured | AI5: 999999999999999 | AJ5: 999999999999999 | AK5: Not applicable | AL5: Not applicable | AM5: Not applicable | AN5: Nominal | AO5: 100000 | AP5: 100000 | AQ5: 2000 | AR5: 0 | AS5: 2260.137 | AT5: 0 | AU5: 999999999999999 | AV5: 999999999999999 | AW5: 999999999999999 | AX5: Not applicable | AY5: -10000 | AZ5: INTERBOLSA_PT | BA5: 529900LG70TCAGWCXT47 | BB5: Not applicable | BC5: BANCO SANTANDER TOTTA S,A, | BD5: 549300URJH9VSI58CS32 | BE5: Not applicable | BF5: Not applicable | BG5: INTERBOLSA_PT | BH5: 529900LG70TCAGWCXT47 | BI5: INTERBOLSA_PT | BJ5: 529900LG70TCAGWCXT47 | BK5: Not applicable | BL5: Not applicable | BM5: Not applicable | BN5: Not applicable | BO5: Fully Compliant T2 | BP5: 200000000 | BQ5: Fully Compliant T2 | BR5: 200000000 | BS5: 0 | BT5: Not applicable | BU5: Not applicable | BV5: Not applicable | BW5: FALSE | BX5: 2.0452027e+08 | BY5: 110 Financial liabilities at amortized cost | BZ5: 999999999999999 | CA5: Not applicable | CB5: FALSE | CC5: TRUE | CD5: servdlakep | CE5: 46027.477 | CF5: 2025-11-30 | CG5: 1
A6: 4 | B6: 31641600000000000PTSTOGOM0003000 | C6: PTSTOGOM0003 | D6: ISIN | E6: 300000000 | F6: 999999999999999 | G6: EUR | H6: 300000000 | I6: 0 | J6: 0 | K6: 0 | L6: 300000000 | M6: 300000000 | N6: Title of ownership | O6: Not applicable | P6: Not applicable | Q6: 2 | R6: 999999999999999 | S6: 2 | T6: 2024-02-22 | U6: 0001-01-01 | V6: 2099-01-31 | W6: 0001-01-01 | X6: 2099-01-31 | Y6: PT | Z6: Yes, supported by Legal Opinion | AA6: No ZCB | AB6: Non-structured/Vanilla | AC6: 999999999999999 | AD6: 999999999999999 | AE6: FALSE | AF6: FALSE | AG6: 999999999999999 | AH6: Unsecured | AI6: 999999999999999 | AJ6: 999999999999999 | AK6: Not applicable | AL6: Not applicable | AM6: Not applicable | AN6: Nominal | AO6: 100000 | AP6: 100000 | AQ6: 3000 | AR6: 0 | AS6: 0 | AT6: 0 | AU6: 999999999999999 | AV6: 999999999999999 | AW6: 999999999999999 | AX6: Not applicable | AY6: -10000 | AZ6: INTERBOLSA_PT | BA6: 529900LG70TCAGWCXT47 | BB6: Not applicable | BC6: BANCO SANTANDER TOTTA S,A, | BD6: 549300URJH9VSI58CS32 | BE6: Not applicable | BF6: Not applicable | BG6: INTERBOLSA_PT | BH6: 529900LG70TCAGWCXT47 | BI6: INTERBOLSA_PT | BJ6: 529900LG70TCAGWCXT47 | BK6: Not applicable | BL6: Not applicable | BM6: Not applicable | BN6: Not applicable | BO6: Fully Compliant AT1 | BP6: 300000000 | BQ6: Fully Compliant AT1 | BR6: 300000000 | BS6: 0 | BT6: Not applicable | BU6: Not applicable | BV6: Not applicable | BW6: FALSE | BX6: 300000000 | BY6: 300 Total equity | BZ6: 999999999999999 | CA6: Not applicable | CB6: FALSE | CC6: TRUE | CD6: servdlakep | CE6: 46027.477 | CF6: 2025-11-30 | CG6: 1
A7: 5 | B7: 31641600000000000PTSTOHOM0002000 | C7: PTSTOHOM0002 | D7: ISIN | E7: 500000000 | F7: 999999999999999 | G7: EUR | H7: 500000000 | I7: 0 | J7: 6901534.2 | K7: 0 | L7: 5.0690153e+08 | M7: 5.0690153e+08 | N7: Registered Bond | O7: Not applicable | P7: Not applicable | Q7: 8 | R7: 999999999999999 | S7: 8 | T7: 2024-07-30 | U7: 2026-07-30 | V7: 2030-07-30 | W7: 0001-01-01 | X7: 2030-07-30 | Y7: PT | Z7: Yes, supported by Legal Opinion | AA7: No ZCB | AB7: Non-structured/Vanilla | AC7: 999999999999999 | AD7: 999999999999999 | AE7: FALSE | AF7: FALSE | AG7: 999999999999999 | AH7: Unsecured | AI7: 999999999999999 | AJ7: 999999999999999 | AK7: Not applicable | AL7: Not applicable | AM7: Not applicable | AN7: Nominal | AO7: 100000 | AP7: 100000 | AQ7: 5000 | AR7: 0 | AS7: 1380.3069 | AT7: 0 | AU7: 999999999999999 | AV7: 999999999999999 | AW7: 999999999999999 | AX7: Not applicable | AY7: -10000 | AZ7: INTERBOLSA_PT | BA7: 529900LG70TCAGWCXT47 | BB7: Not applicable | BC7: BANCO SANTANDER TOTTA S,A, | BD7: 549300URJH9VSI58CS32 | BE7: Not applicable | BF7: Not applicable | BG7: INTERBOLSA_PT | BH7: 529900LG70TCAGWCXT47 | BI7: INTERBOLSA_PT | BJ7: 529900LG70TCAGWCXT47 | BK7: Not applicable | BL7: Not applicable | BM7: Not applicable | BN7: Not applicable | BO7: No | BP7: 0 | BQ7: No | BR7: 0 | BS7: 0 | BT7: Not applicable | BU7: Not applicable | BV7: Not applicable | BW7: FALSE | BX7: 5.0690153e+08 | BY7: 110 Financial liabilities at amortized cost | BZ7: 999999999999999 | CA7: Not applicable | CB7: FALSE | CC7: TRUE | CD7: servdlakep | CE7: 46027.477 | CF7: 2025-11-30 | CG7: 1
A8: 6 | B8: 31641600005800007PTBSRDOM0037000 | C8: PTBSRDOM0037 | D8: ISIN | E8: 500000000 | F8: 999999999999999 | G8: EUR | H8: 500000000 | I8: 0 | J8: 0 | K8: 0 | L8: 500000000 | M8: 500000000 | N8: Title of ownership | O8: Not applicable | P8: Not applicable | Q8: 2 | R8: 999999999999999 | S8: 2 | T8: 2025-05-29 | U8: 0001-01-01 | V8: 2099-01-31 | W8: 0001-01-01 | X8: 2099-01-31 | Y8: PT | Z8: Yes, supported by Legal Opinion | AA8: No ZCB | AB8: Non-structured/Vanilla | AC8: 999999999999999 | AD8: 999999999999999 | AE8: FALSE | AF8: FALSE | AG8: 999999999999999 | AH8: Unsecured | AI8: 999999999999999 | AJ8: 999999999999999 | AK8: Not applicable | AL8: Not applicable | AM8: Not applicable | AN8: Nominal | AO8: 100000 | AP8: 100000 | AQ8: 5000 | AR8: 0 | AS8: 0 | AT8: 0 | AU8: 999999999999999 | AV8: 999999999999999 | AW8: 999999999999999 | AX8: Not applicable | AY8: -10000 | AZ8: INTERBOLSA_PT | BA8: 529900LG70TCAGWCXT47 | BB8: Not applicable | BC8: BANCO SANTANDER TOTTA S,A, | BD8: 549300URJH9VSI58CS32 | BE8: Not applicable | BF8: Not applicable | BG8: INTERBOLSA_PT | BH8: 529900LG70TCAGWCXT47 | BI8: INTERBOLSA_PT | BJ8: 529900LG70TCAGWCXT47 | BK8: Not applicable | BL8: Not applicable | BM8: Not applicable | BN8: Not applicable | BO8: Fully Compliant AT1 | BP8: 500000000 | BQ8: Fully Compliant AT1 | BR8: 500000000 | BS8: 0 | BT8: Not applicable | BU8: Not applicable | BV8: Not applicable | BW8: FALSE | BX8: 500000000 | BY8: 300 Total equity | BZ8: 999999999999999 | CA8: Not applicable | CB8: FALSE | CC8: TRUE | CD8: servdlakep | CE8: 46027.477 | CF8: 2025-11-30 | CG8: 1
A9: 7 | B9: 31641600005800007PTCPP0AM0007000 | C9: PTCPP0AM0007 | D9: ISIN | E9: 1391779674 | F9: 999999999999999 | G9: EUR | H9: 1385452938 | I9: 6326736 | J9: 0 | K9: 0 | L9: 1385452938 | M9: 1385452938 | N9: Title of ownership | O9: Not applicable | P9: Not applicable | Q9: 1 | R9: 999999999999999 | S9: 1 | T9: 1992-01-05 | U9: 0001-01-01 | V9: 2099-01-31 | W9: 0001-01-01 | X9: 2099-01-31 | Y9: PT | Z9: Yes, supported by Legal Opinion | AA9: No ZCB | AB9: Non-structured/Vanilla | AC9: 999999999999999 | AD9: 999999999999999 | AE9: FALSE | AF9: FALSE | AG9: 999999999999999 | AH9: Unsecured | AI9: 999999999999999 | AJ9: 999999999999999 | AK9: Not applicable | AL9: Not applicable | AM9: Not applicable | AN9: Unit | AO9: 1 | AP9: 1 | AQ9: 1385452938 | AR9: 6326736 | AS9: 0 | AT9: 0 | AU9: 999999999999999 | AV9: 999999999999999 | AW9: 999999999999999 | AX9: Not applicable | AY9: -10000 | AZ9: INTERBOLSA_PT | BA9: 529900LG70TCAGWCXT47 | BB9: Not applicable | BC9: BANCO SANTANDER TOTTA S,A, | BD9: 549300URJH9VSI58CS32 | BE9: Not applicable | BF9: Not applicable | BG9: INTERBOLSA_PT | BH9: 529900LG70TCAGWCXT47 | BI9: INTERBOLSA_PT | BJ9: 529900LG70TCAGWCXT47 | BK9: Not applicable | BL9: Not applicable | BM9: Not applicable | BN9: Not applicable | BO9: CET1 | BP9: 1256723284 | BQ9: CET1 | BR9: 1256723284 | BS9: 0 | BT9: Not applicable | BU9: Not applicable | BV9: Not applicable | BW9: FALSE | BX9: 1.3726327e+09 | BY9: 300 Total equity | BZ9: 999999999999999 | CA9: Not applicable | CB9: FALSE | CC9: TRUE | CD9: servdlakep | CE9: 46027.477 | CF9: 2025-11-30 | CG9: 1
A10: 9 | B10: 31641600005800007PTSTOCOM0007000 | C10: PTSTOCOM0007 | D10: ISIN | E10: 400000000 | F10: 999999999999999 | G10: EUR | H10: 400000000 | I10: 0 | J10: 0 | K10: 0 | L10: 400000000 | M10: 400000000 | N10: Title of ownership | O10: Not applicable | P10: Not applicable | Q10: 2 | R10: 999999999999999 | S10: 2 | T10: 2021-01-14 | U10: 0001-01-01 | V10: 2099-01-31 | W10: 0001-01-01 | X10: 2099-01-31 | Y10: PT | Z10: Yes, supported by Legal Opinion | AA10: No ZCB | AB10: Non-structured/Vanilla | AC10: 999999999999999 | AD10: 999999999999999 | AE10: FALSE | AF10: FALSE | AG10: 999999999999999 | AH10: Unsecured | AI10: 999999999999999 | AJ10: 999999999999999 | AK10: Not applicable | AL10: Not applicable | AM10: Not applicable | AN10: Nominal | AO10: 100000 | AP10: 100000 | AQ10: 4000 | AR10: 0 | AS10: 0 | AT10: 0 | AU10: 999999999999999 | AV10: 999999999999999 | AW10: 999999999999999 | AX10: Not applicable | AY10: -10000 | AZ10: INTERBOLSA_PT | BA10: 529900LG70TCAGWCXT47 | BB10: Not applicable | BC10: BANCO SANTANDER TOTTA S,A, | BD10: 549300URJH9VSI58CS32 | BE10: Not applicable | BF10: Not applicable | BG10: INTERBOLSA_PT | BH10: 529900LG70TCAGWCXT47 | BI10: INTERBOLSA_PT | BJ10: 529900LG70TCAGWCXT47 | BK10: Not applicable | BL10: Not applicable | BM10: Not applicable | BN10: Not applicable | BO10: Fully Compliant AT1 | BP10: 400000000 | BQ10: Fully Compliant AT1 | BR10: 400000000 | BS10: 0 | BT10: Not applicable | BU10: Not applicable | BV10: Not applicable | BW10: FALSE | BX10: 400000000 | BY10: 300 Total equity | BZ10: 999999999999999 | CA10: Not applicable | CB10: FALSE | CC10: TRUE | CD10: servdlakep | CE10: 46027.477 | CF10: 2025-11-30 | CG10: 1
A13: 0010_row_nmbr | B13: CAST( | C13: =+"`"&A13&"`" -> `0010_row_nmbr` | D13: AS STRING) | E13: =+B13&C13&D13&" AS "&C13&", " -> CAST(`0010_row_nmbr`AS STRING) AS `0010_row_nmbr`, | F13: =+E13 -> CAST(`0010_row_nmbr`AS STRING) AS `0010_row_nmbr`,
A14: 0020_uniq_id | B14: CAST( | C14: =+"`"&A14&"`" -> `0020_uniq_id` | D14: AS STRING) | E14: =+B14&C14&D14&" AS "&C14&", " -> CAST(`0020_uniq_id`AS STRING) AS `0020_uniq_id`, | F14: =+F13&E14 -> CAST(`0010_row_nmbr`AS STRING) AS `0010_row_nmbr`, CAST(`0020_uniq_id`AS STRING) AS `0020_uniq_id`,
A15: 0030_uniq_id_knwn_cntrprty | B15: CAST( | C15: =+"`"&A15&"`" -> `0030_uniq_id_knwn_cntrprty` | D15: AS STRING) | E15: =+B15&C15&D15&" AS "&C15&", " -> CAST(`0030_uniq_id_knwn_cntrprty`AS STRING) AS `0030_uniq_id_knwn_cntrprty`, | F15: =+F14&E15 -> CAST(`0010_row_nmbr`AS STRING) AS `0010_row_nmbr`, CAST(`0020_uniq_id`AS STRING) AS `0020_uniq_id`, CAST(`0030_uniq_id_knwn_cntrprty`AS STRING) AS `0030_uniq_id_knwn_cntrprty`,
A16: 0040_typ_uniq_id_knwn_cntrprty | B16: CAST( | C16: =+"`"&A16&"`" -> `0040_typ_uniq_id_knwn_cntrprty` | D16: AS STRING) | E16: =+B16&C16&D16&" AS "&C16&", " -> CAST(`0040_typ_uniq_id_knwn_cntrprty`AS STRING) AS `0040_typ_uniq_id_knwn_cntrprty`, | F16: =+F15&E16 -> CAST(`0010_row_nmbr`AS STRING) AS `0010_row_nmbr`, CAST(`0020_uniq_id`AS STRING) AS `0020_uniq_id`, CAST(`0030_uniq_id_knwn_cntrprty`AS STRING) AS `0030_uniq_id_knwn_cntrprty`, CAST(`0040_typ_uniq_id_knwn_cntrprty`AS STRING) AS `0040_typ_uniq_id_knwn_cntrprty`,
A17: 0050_orgnl_amnt_eur | B17: CAST( | C17: =+"`"&A17&"`" -> `0050_orgnl_amnt_eur` | D17: AS STRING) | E17: =+B17&C17&D17&" AS "&C17&", " -> CAST(`0050_orgnl_amnt_eur`AS STRING) AS `0050_orgnl_amnt_eur`, | F17: =+F16&E17 -> CAST(`0010_row_nmbr`AS STRING) AS `0010_row_nmbr`, CAST(`0020_uniq_id`AS STRING) AS `0020_uniq_id`, CAST(`0030_uniq_id_knwn_cntrprty`AS STRING) AS `0030_uniq_id_knwn_cntrprty`, CAST(`0040_typ_uniq_id_knwn_cntrprty`AS STRING) AS `0040_typ_uniq_id_knwn_cntrprty`, CAST(`0050_orgnl_amnt_eur`AS STRING) AS `0050_orgnl_amnt_eur`,
A18: 0060_orgnl_amnt_fx | B18: CAST( | C18: =+"`"&A18&"`" -> `0060_orgnl_amnt_fx` | D18: AS STRING) | E18: =+B18&C18&D18&" AS "&C18&", " -> CAST(`0060_orgnl_amnt_fx`AS STRING) AS `0060_orgnl_amnt_fx`, | F18: =+F17&E18 -> CAST(`0010_row_nmbr`AS STRING) AS `0010_row_nmbr`, CAST(`0020_uniq_id`AS STRING) AS `0020_uniq_id`, CAST(`0030_uniq_id_knwn_cntrprty`AS STRING) AS `0030_uniq_id_knwn_cntrprty`, CAST(`0040_typ_uniq_id_knwn_cntrprty`AS STRING) AS `0040_typ_uniq_id_knwn_cntrprty`, CAST(`0050_orgnl_amnt_eur`AS STRING) AS `0050_orgnl_amnt_eur`, CAST(`0060_orgnl_amnt_fx`AS STRING) AS `0060_orgnl_amnt_fx`,
A19: 0070_cntrct_crrncy | B19: CAST( | C19: =+"`"&A19&"`" -> `0070_cntrct_crrncy` | D19: AS STRING) | E19: =+B19&C19&D19&" AS "&C19&", " -> CAST(`0070_cntrct_crrncy`AS STRING) AS `0070_cntrct_crrncy`, | F19: =+F18&E19 -> CAST(`0010_row_nmbr`AS STRING) AS `0010_row_nmbr`, CAST(`0020_uniq_id`AS STRING) AS `0020_uniq_id`, CAST(`0030_uniq_id_knwn_cntrprty`AS STRING) AS `0030_uniq_id_knwn_cntrprty`, CAST(`0040_typ_uniq_id_knwn_cntrprty`AS STRING) AS `0040_typ_uniq_id_knwn_cntrprty`, CAST(`0050_orgnl_amnt_eur`AS STRING) AS `0050_orgnl_amnt_eur`, CAST(`0060_orgnl_amnt_fx`AS STRING) AS `0060_orgnl_amnt_fx`, CAST(`0070_cntrct_crrncy`AS STRING) AS `0070_cntrct_crrncy`,
A20: 0080_otstndng_prncpl_amnt | B20: CAST( | C20: =+"`"&A20&"`" -> `0080_otstndng_prncpl_amnt` | D20: AS STRING) | E20: =+B20&C20&D20&" AS "&C20&", " -> CAST(`0080_otstndng_prncpl_amnt`AS STRING) AS `0080_otstndng_prncpl_amnt`, | F20: =+F19&E20 -> CAST(`0010_row_nmbr`AS STRING) AS `0010_row_nmbr`, CAST(`0020_uniq_id`AS STRING) AS `0020_uniq_id`, CAST(`0030_uniq_id_knwn_cntrprty`AS STRING) AS `0030_uniq_id_knwn_cntrprty`, CAST(`0040_typ_uniq_id_knwn_cntrprty`AS STRING) AS `0040_typ_uniq_id_knwn_cntrprty`, CAST(`0050_orgnl_amnt_eur`AS STRING) AS `0050_orgnl_amnt_eur`, CAST(`0060_orgnl_amnt_fx`AS STRING) AS `0060_orgnl_amnt_fx`, CAST(`0070_cntrct_crrncy`AS STRING) AS `0070_cntrct_crrncy`, CAST(`0080_otstndng_prncpl_amnt`AS STRING) AS `0080_otstndng_prncpl_amnt`,
A21: 0090_prtn_amnt_rprtng_entty | B21: CAST( | C21: =+"`"&A21&"`" -> `0090_prtn_amnt_rprtng_entty` | D21: AS STRING) | E21: =+B21&C21&D21&" AS "&C21&", " -> CAST(`0090_prtn_amnt_rprtng_entty`AS STRING) AS `0090_prtn_amnt_rprtng_entty`, | F21: =+F20&E21 -> CAST(`0010_row_nmbr`AS STRING) AS `0010_row_nmbr`, CAST(`0020_uniq_id`AS STRING) AS `0020_uniq_id`, CAST(`0030_uniq_id_knwn_cntrprty`AS STRING) AS `0030_uniq_id_knwn_cntrprty`, CAST(`0040_typ_uniq_id_knwn_cntrprty`AS STRING) AS `0040_typ_uniq_id_knwn_cntrprty`, CAST(`0050_orgnl_amnt_eur`AS STRING) AS `0050_orgnl_amnt_eur`, CAST(`0060_orgnl_amnt_fx`AS STRING) AS `0060_orgnl_amnt_fx`, CAST(`0070_cntrct_crrncy`AS STRING) AS `0070_cntrct_crrncy`, CAST(`0080_otstndng_prncpl_amnt`AS STRING) AS `0080_otstndng_prncpl_amnt`, CAST(`0090_prtn_amnt_rprtng_entty`AS STRING) AS `0090_prtn_amnt_rprtng_entty`,
A22: 0100_accrd_intrst_instrmnt | B22: CAST( | C22: =+"`"&A22&"`" -> `0100_accrd_intrst_instrmnt` | D22: AS STRING) | E22: =+B22&C22&D22&" AS "&C22&", " -> CAST(`0100_accrd_intrst_instrmnt`AS STRING) AS `0100_accrd_intrst_instrmnt`, | F22: =+F21&E22 -> CAST(`0010_row_nmbr`AS STRING) AS `0010_row_nmbr`, CAST(`0020_uniq_id`AS STRING) AS `0020_uniq_id`, CAST(`0030_uniq_id_knwn_cntrprty`AS STRING) AS `0030_uniq_id_knwn_cntrprty`, CAST(`0040_typ_uniq_id_knwn_cntrprty`AS STRING) AS `0040_typ_uniq_id_knwn_cntrprty`, CAST(`0050_orgnl_amnt_eur`AS STRING) AS `0050_orgnl_amnt_eur`, CAST(`0060_orgnl_amnt_fx`AS STRING) AS `0060_orgnl_amnt_fx`, CAST(`0070_cntrct_crrncy`AS STRING) AS `0070_cntrct_crrncy`, CAST(`0080_otstndng_prncpl_amnt`AS STRING) AS `0080_otstndng_prncpl_amnt`, CAST(`0090_prtn_amnt_rprtng_entty`AS STRING) AS `0090_prtn_amnt_rprtng_entty`, CAST(`0100_accrd_intrst_instrmnt`AS STRING) AS `0100_accrd_intrst_instrmnt`,
A23: 0110_applcbl_fees_charges | B23: CAST( | C23: =+"`"&A23&"`" -> `0110_applcbl_fees_charges` | D23: AS STRING) | E23: =+B23&C23&D23&" AS "&C23&", " -> CAST(`0110_applcbl_fees_charges`AS STRING) AS `0110_applcbl_fees_charges`, | F23: =+F22&E23 -> CAST(`0010_row_nmbr`AS STRING) AS `0010_row_nmbr`, CAST(`0020_uniq_id`AS STRING) AS `0020_uniq_id`, CAST(`0030_uniq_id_knwn_cntrprty`AS STRING) AS `0030_uniq_id_knwn_cntrprty`, CAST(`0040_typ_uniq_id_knwn_cntrprty`AS STRING) AS `0040_typ_uniq_id_knwn_cntrprty`, CAST(`0050_orgnl_amnt_eur`AS STRING) AS `0050_orgnl_amnt_eur`, CAST(`0060_orgnl_amnt_fx`AS STRING) AS `0060_orgnl_amnt_fx`, CAST(`0070_cntrct_crrncy`AS STRING) AS `0070_cntrct_crrncy`, CAST(`0080_otstndng_prncpl_amnt`AS STRING) AS `0080_otstndng_prncpl_amnt`, CAST(`0090_prtn_amnt_rprtng_entty`AS STRING) AS `0090_prtn_amnt_rprtng_entty`, CAST(`0100_accrd_intrst_instrmnt`AS STRING) AS `0100_accrd_intrst_instrmnt`, CAST(`0110_applcbl_fees_charges`AS STRING) AS `0110_applcbl_fees_charges`,
A24: 0120_otstndng_amnt | B24: CAST( | C24: =+"`"&A24&"`" -> `0120_otstndng_amnt` | D24: AS STRING) | E24: =+B24&C24&D24&" AS "&C24&", " -> CAST(`0120_otstndng_amnt`AS STRING) AS `0120_otstndng_amnt`, | F24: =+F23&E24 -> CAST(`0010_row_nmbr`AS STRING) AS `0010_row_nmbr`, CAST(`0020_uniq_id`AS STRING) AS `0020_uniq_id`, CAST(`0030_uniq_id_knwn_cntrprty`AS STRING) AS `0030_uniq_id_knwn_cntrprty`, CAST(`0040_typ_uniq_id_knwn_cntrprty`AS STRING) AS `0040_typ_uniq_id_knwn_cntrprty`, CAST(`0050_orgnl_amnt_eur`AS STRING) AS `0050_orgnl_amnt_eur`, CAST(`0060_orgnl_amnt_fx`AS STRING) AS `0060_orgnl_amnt_fx`, CAST(`0070_cntrct_crrncy`AS STRING) AS `0070_cntrct_crrncy`, CAST(`0080_otstndng_prncpl_amnt`AS STRING) AS `0080_otstndng_prncpl_amnt`, CAST(`0090_prtn_amnt_rprtng_entty`AS STRING) AS `0090_prtn_amnt_rprtng_entty`, CAST(`0100_accrd_intrst_instrmnt`AS STRING) AS `0100_accrd_intrst_instrmnt`, CAST(`0110_applcbl_fees_charges`AS STRING) AS `0110_applcbl_fees_charges`, CAST(`0120_otstndng_amnt`AS STRING) AS `0120_otstndng_amnt`,
A25: 0130_rlvnt_amnt_wdc | B25: CAST( | C25: =+"`"&A25&"`" -> `0130_rlvnt_amnt_wdc` | D25: AS STRING) | E25: =+B25&C25&D25&" AS "&C25&", " -> CAST(`0130_rlvnt_amnt_wdc`AS STRING) AS `0130_rlvnt_amnt_wdc`, | F25: =+F24&E25 -> CAST(`0010_row_nmbr`AS STRING) AS `0010_row_nmbr`, CAST(`0020_uniq_id`AS STRING) AS `0020_uniq_id`, CAST(`0030_uniq_id_knwn_cntrprty`AS STRING) AS `0030_uniq_id_knwn_cntrprty`, CAST(`0040_typ_uniq_id_knwn_cntrprty`AS STRING) AS `0040_typ_uniq_id_knwn_cntrprty`, CAST(`0050_orgnl_amnt_eur`AS STRING) AS `0050_orgnl_amnt_eur`, CAST(`0060_orgnl_amnt_fx`AS STRING) AS `0060_orgnl_amnt_fx`, CAST(`0070_cntrct_crrncy`AS STRING) AS `0070_cntrct_crrncy`, CAST(`0080_otstndng_prncpl_amnt`AS STRING) AS `0080_otstndng_prncpl_amnt`, CAST(`0090_prtn_amnt_rprtng_entty`AS STRING) AS `0090_prtn_amnt_rprtng_entty`, CAST(`0100_accrd_intrst_instrmnt`AS STRING) AS `0100_accrd_intrst_instrmnt`, CAST(`0110_applcbl_fees_charges`AS STRING) AS `0110_applcbl_fees_charges`, CAST(`0120_otstndng_amnt`AS STRING) AS `0120_otstndng_amnt`, CAST(`0130_rlvnt_amnt_wdc`AS STRING) AS `0130_rlvnt_amnt_wdc`,
... A97: cod_visao | B97: CAST( | C97: =+"`"&A97&"`" -> `cod_visao` | D97: AS STRING) | E97: =+B97&C97&D97&" AS "&C97&", " -> CAST(`cod_visao`AS STRING) AS `cod_visao`, | F97: =+F96&E97 -> CAST(`0010_row_nmbr`AS STRING) AS `0010_row_nmbr`, CAST(`0020_uniq_id`AS STRING) AS `0020_uniq_id`, CAST(`0030_uniq_id_knwn_cntrprty`AS STRING) AS `0030_uniq_id_knwn_cntrprty`, CAST(`0040_typ_uniq_id_knwn_cntrprty`AS STRING) AS `0040_typ_uniq_id_knwn_cntrprty`, CAST(`0050_orgnl_amnt_eur`AS STRING) AS `0050_orgnl_amnt_eur`, CAST(`0060_orgnl_amnt_fx`AS STRING) AS `0060_orgnl_amnt_fx`, CAST(`0070_cntrct_crrncy`AS STRING) AS `0070_cntrct_crrncy`, CAST(`0080_otstndng_prncpl_amnt`AS STRING) AS `0080_otstndng_prncpl_amnt`, CAST(`0090_prtn_amnt_rprtng_entty`AS STRING) AS `0090_prtn_amnt_rprtng_entty`, CAST(`0100_accrd_intrst_instrmnt`AS STRING) AS `0100_accrd_intrst_instrmnt`, CAST(`0110_applcbl_fees_charges`AS STRING) AS `0110_applcbl_fees_charges`, CAST(`0120_otstndng_amnt`AS STRING) AS `0120_otstndng_amnt`, CAST(`0130_rlvnt_amnt_wdc`AS STRING) AS `0130_rlvnt_amnt_wdc`, CAST(`0140_ntr_lblty`AS STRING) AS `0140_ntr_lblty`, CAST(`0141_ntr_lblty_othr`AS STRING) AS `0141_ntr_lblty_othr`, CAST(`0150_flg_strctrlly_sbrdntd`AS STRING) AS `0150_flg_strctrlly_sbrdntd`, CAST(`0160_rank_insolv`AS STRING) AS `0160_rank_insolv`, CAST(`0161_cntrctl_sbrdntn`AS STRING) AS `0161_cntrctl_sbrdntn`, CAST(`0162_bail_in_cascade`AS STRING) AS `0162_bail_in_cascade`, CAST(`0170_dt_incptn`AS STRING) AS `0170_dt_incptn`, CAST(`0180_dt_nxt_intrst_pymnt`AS STRING) AS `0180_dt_nxt_intrst_pymnt`, CAST(`0190_dt_nxt_rdmptn_pymnt`AS STRING) AS `0190_dt_nxt_rdmptn_pymnt`, CAST(`0200_dt_erlst_rdmptn`AS STRING) AS `0200_dt_erlst_rdmptn`, CAST(`0210_dt_lgl_fnl_mtrty`AS STRING) AS `0210_dt_lgl_fnl_mtrty`, CAST(`0220_governing_law`AS STRING) AS `0220_governing_law`, CAST(`0230_bail_in_rcgntn_cls`AS STRING) AS `0230_bail_in_rcgntn_cls`, CAST(`0240_zero_coupon`AS STRING) AS `0240_zero_coupon`, CAST(`0250_strctrd_prdct`AS STRING) AS `0250_strctrd_prdct`, CAST(`0260_grntd_min_amnt_strctrd_prdct`AS STRING) AS `0260_grntd_min_amnt_strctrd_prdct`, CAST(`0270_fv_amnt_strctrd_prdct`AS STRING) AS `0270_fv_amnt_strctrd_prdct`, CAST(`0280_flg_ncnp_dpsts`AS STRING) AS `0280_flg_ncnp_dpsts`, CAST(`0290_flg_ncbp_dpsts`AS STRING) AS `0290_flg_ncbp_dpsts`, CAST(`0300_amnt_cvrd_elgbl_dpsts`AS STRING) AS `0300_amnt_cvrd_elgbl_dpsts`, CAST(`0310_flg_clltrl_agrmnts`AS STRING) AS `0310_flg_clltrl_agrmnts`, CAST(`0320_amnt_clltrl`AS STRING) AS `0320_amnt_clltrl`, CAST(`0330_amnt_unclltrlzd`AS STRING) AS `0330_amnt_unclltrlzd`, CAST(`0340_id_clltrl`AS STRING) AS `0340_id_clltrl`, CAST(`0350_typ_clltrl`AS STRING) AS `0350_typ_clltrl`, CAST(`0351_typ_clltrl_othr`AS STRING) AS `0351_typ_clltrl_othr`, CAST(`0360_trdng_mthd`AS STRING) AS `0360_trdng_mthd`, CAST(`0370_amnt_scrty_eur`AS STRING) AS `0370_amnt_scrty_eur`, CAST(`0380_amnt_scrty_fx`AS STRING) AS `0380_amnt_scrty_fx`, CAST(`0390_nmbr_scrts_not_rprtng_entty`AS STRING) AS `0390_nmbr_scrts_not_rprtng_entty`, CAST(`0391_nmbr_scrts_rprtng_entty`AS STRING) AS `0391_nmbr_scrts_rprtng_entty`, CAST(`0400_accrd_intrst_scrty`AS STRING) AS `0400_accrd_intrst_scrty`, CAST(`0410_fees_charges_scrty`AS STRING) AS `0410_fees_charges_scrty`, CAST(`0420_fv_amnt_scrty`AS STRING) AS `0420_fv_amnt_scrty`, CAST(`0430_prncpl_amnt_glbl_nt_eur`AS STRING) AS `0430_prncpl_amnt_glbl_nt_eur`, CAST(`0431_prncpl_amnt_glbl_nt_fx`AS STRING) AS `0431_prncpl_amnt_glbl_nt_fx`, CAST(`0440_ntr_glbl_nt`AS STRING) AS `0440_ntr_glbl_nt`, CAST(`0450_crrnt_pool_fctr`AS STRING) AS `0450_crrnt_pool_fctr`, CAST(`0460_csd`AS STRING) AS `0460_csd`, CAST(`0461_csd_lei`AS STRING) AS `0461_csd_lei`, CAST(`0462_csd_othr`AS STRING) AS `0462_csd_othr`, CAST(`0470_pyng_agnt`AS STRING) AS `0470_pyng_agnt`, CAST(`0471_pyng_agnt_lei`AS STRING) AS `0471_pyng_agnt_lei`, CAST(`0480_trdng_vn`AS STRING) AS `0480_trdng_vn`, CAST(`0481_trdng_vn_lei`AS STRING) AS `0481_trdng_vn_lei`, CAST(`0490_rgstrr`AS STRING) AS `0490_rgstrr`, CAST(`0491_rgstrr_lei`AS STRING) AS `0491_rgstrr_lei`, CAST(`0500_nna`AS STRING) AS `0500_nna`, CAST(`0501_nna_lei`AS STRING) AS `0501_nna_lei`, CAST(`0510_cmmn_dpstry`AS STRING) AS `0510_cmmn_dpstry`, CAST(`0511_cmmn_dpstry_lei`AS STRING) AS `0511_cmmn_dpstry_lei`, CAST(`0520_cmmn_srvc_prvdr`AS STRING) AS `0520_cmmn_srvc_prvdr`, CAST(`0521_cmmn_srvc_prvdr_lei`AS STRING) AS `0521_cmmn_srvc_prvdr_lei`, CAST(`0530_typ_own_fnds_ind_lvl`AS STRING) AS `0530_typ_own_fnds_ind_lvl`, CAST(`0540_elgbl_amnt_own_fnds_ind_lvl`AS STRING) AS `0540_elgbl_amnt_own_fnds_ind_lvl`, CAST(`0550_typ_own_fnds_cnsldtd_lvl`AS STRING) AS `0550_typ_own_fnds_cnsldtd_lvl`, CAST(`0560_elgbl_amnt_own_fnds_cnsldtd_lvl`AS STRING) AS `0560_elgbl_amnt_own_fnds_cnsldtd_lvl`, CAST(`0570_amnt_scrty_intrst_prvdd`AS STRING) AS `0570_amnt_scrty_intrst_prvdd`, CAST(`0580_scrty_intrst_prvdr`AS STRING) AS `0580_scrty_intrst_prvdr`, CAST(`0581_scrty_intrst_prvdr_lei`AS STRING) AS `0581_scrty_intrst_prvdr_lei`, CAST(`0590_typ_scrty_intrst_prvdd`AS STRING) AS `0590_typ_scrty_intrst_prvdd`, CAST(`0600_flg_clltrl_asst_pstn`AS STRING) AS `0600_flg_clltrl_asst_pstn`, CAST(`0610_crryng_amnt_ifrs`AS STRING) AS `0610_crryng_amnt_ifrs`, CAST(`0620_blnc_sht_ifrs`AS STRING) AS `0620_blnc_sht_ifrs`, CAST(`0630_crrying_amnt_ngaap`AS STRING) AS `0630_crrying_amnt_ngaap`, CAST(`0640_blnc_sht_ngaap`AS STRING) AS `0640_blnc_sht_ngaap`, CAST(`5000_flg_shrhldr_not_rsltn_grp`AS STRING) AS `5000_flg_shrhldr_not_rsltn_grp`, CAST(`5010_flg_art21_7a_srmr`AS STRING) AS `5010_flg_art21_7a_srmr`, CAST(`ckutulmo`AS STRING) AS `ckutulmo`, CAST(`htimest`AS STRING) AS `htimest`, CAST(`ref_date`AS STRING) AS `ref_date`, CAST(`cod_visao`AS STRING) AS `cod_visao`,
C99: CAST(`0010_row_nmbr`AS STRING) AS `0010_row_nmbr`, CAST(`0020_uniq_id`AS STRING) AS `0020_uniq_id`, CAST(`0030_uniq_id_knwn_cntrprty`AS STRING) AS `0030_uniq_id_knwn_cntrprty`, CAST(`0040_typ_uniq_id_knwn_cntrprty`AS STRING) AS `0040_typ_uniq_id_knwn_cntrprty`, CAST(`0050_orgnl_amnt_eur`AS STRING) AS `0050_orgnl_amnt_eur`, CAST(`0060_orgnl_amnt_fx`AS STRING) AS `0060_orgnl_amnt_fx`, CAST(`0070_cntrct_crrncy`AS STRING) AS `0070_cntrct_crrncy`, CAST(`0080_otstndng_prncpl_amnt`AS STRING) AS `0080_otstndng_prncpl_amnt`, CAST(`0090_prtn_amnt_rprtng_entty`AS STRING) AS `0090_prtn_amnt_rprtng_entty`, CAST(`0100_accrd_intrst_instrmnt`AS STRING) AS `0100_accrd_intrst_instrmnt`, CAST(`0110_applcbl_fees_charges`AS STRING) AS `0110_applcbl_fees_charges`, CAST(`0120_otstndng_amnt`AS STRING) AS `0120_otstndng_amnt`, CAST(`0130_rlvnt_amnt_wdc`AS STRING) AS `0130_rlvnt_amnt_wdc`, CAST(`0140_ntr_lblty`AS STRING) AS `0140_ntr_lblty`, CAST(`0141_ntr_lblty_othr`AS STRING) AS `0141_ntr_lblty_othr`, CAST(`0150_flg_strctrlly_sbrdntd`AS STRING) AS `0150_flg_strctrlly_sbrdntd`, CAST(`0160_rank_insolv`AS STRING) AS `0160_rank_insolv`, CAST(`0161_cntrctl_sbrdntn`AS STRING) AS `0161_cntrctl_sbrdntn`, CAST(`0162_bail_in_cascade`AS STRING) AS `0162_bail_in_cascade`, CAST(`0170_dt_incptn`AS STRING) AS `0170_dt_incptn`, CAST(`0180_dt_nxt_intrst_pymnt`AS STRING) AS `0180_dt_nxt_intrst_pymnt`, CAST(`0190_dt_nxt_rdmptn_pymnt`AS STRING) AS `0190_dt_nxt_rdmptn_pymnt`, CAST(`0200_dt_erlst_rdmptn`AS STRING) AS `0200_dt_erlst_rdmptn`, CAST(`0210_dt_lgl_fnl_mtrty`AS STRING) AS `0210_dt_lgl_fnl_mtrty`, CAST(`0220_governing_law`AS STRING) AS `0220_governing_law`, CAST(`0230_bail_in_rcgntn_cls`AS STRING) AS `0230_bail_in_rcgntn_cls`, CAST(`0240_zero_coupon`AS STRING) AS `0240_zero_coupon`, CAST(`0250_strctrd_prdct`AS STRING) AS `0250_strctrd_prdct`, CAST(`0260_grntd_min_amnt_strctrd_prdct`AS STRING) AS `0260_grntd_min_amnt_strctrd_prdct`, CAST(`0270_fv_amnt_strctrd_prdct`AS STRING) AS `0270_fv_amnt_strctrd_prdct`, CAST(`0280_flg_ncnp_dpsts`AS STRING) AS `0280_flg_ncnp_dpsts`, CAST(`0290_flg_ncbp_dpsts`AS STRING) AS `0290_flg_ncbp_dpsts`, CAST(`0300_amnt_cvrd_elgbl_dpsts`AS STRING) AS `0300_amnt_cvrd_elgbl_dpsts`, CAST(`0310_flg_clltrl_agrmnts`AS STRING) AS `0310_flg_clltrl_agrmnts`, CAST(`0320_amnt_clltrl`AS STRING) AS `0320_amnt_clltrl`, CAST(`0330_amnt_unclltrlzd`AS STRING) AS `0330_amnt_unclltrlzd`, CAST(`0340_id_clltrl`AS STRING) AS `0340_id_clltrl`, CAST(`0350_typ_clltrl`AS STRING) AS `0350_typ_clltrl`, CAST(`0351_typ_clltrl_othr`AS STRING) AS `0351_typ_clltrl_othr`, CAST(`0360_trdng_mthd`AS STRING) AS `0360_trdng_mthd`, CAST(`0370_amnt_scrty_eur`AS STRING) AS `0370_amnt_scrty_eur`, CAST(`0380_amnt_scrty_fx`AS STRING) AS `0380_amnt_scrty_fx`, CAST(`0390_nmbr_scrts_not_rprtng_entty`AS STRING) AS `0390_nmbr_scrts_not_rprtng_entty`, CAST(`0391_nmbr_scrts_rprtng_entty`AS STRING) AS `0391_nmbr_scrts_rprtng_entty`, CAST(`0400_accrd_intrst_scrty`AS STRING) AS `0400_accrd_intrst_scrty`, CAST(`0410_fees_charges_scrty`AS STRING) AS `0410_fees_charges_scrty`, CAST(`0420_fv_amnt_scrty`AS STRING) AS `0420_fv_amnt_scrty`, CAST(`0430_prncpl_amnt_glbl_nt_eur`AS STRING) AS `0430_prncpl_amnt_glbl_nt_eur`, CAST(`0431_prncpl_amnt_glbl_nt_fx`AS STRING) AS `0431_prncpl_amnt_glbl_nt_fx`, CAST(`0440_ntr_glbl_nt`AS STRING) AS `0440_ntr_glbl_nt`, CAST(`0450_crrnt_pool_fctr`AS STRING) AS `0450_crrnt_pool_fctr`, CAST(`0460_csd`AS STRING) AS `0460_csd`, CAST(`0461_csd_lei`AS STRING) AS `0461_csd_lei`, CAST(`0462_csd_othr`AS STRING) AS `0462_csd_othr`, CAST(`0470_pyng_agnt`AS STRING) AS `0470_pyng_agnt`, CAST(`0471_pyng_agnt_lei`AS STRING) AS `0471_pyng_agnt_lei`, CAST(`0480_trdng_vn`AS STRING) AS `0480_trdng_vn`, CAST(`0481_trdng_vn_lei`AS STRING) AS `0481_trdng_vn_lei`, CAST(`0490_rgstrr`AS STRING) AS `0490_rgstrr`, CAST(`0491_rgstrr_lei`AS STRING) AS `0491_rgstrr_lei`, CAST(`0500_nna`AS STRING) AS `0500_nna`, CAST(`0501_nna_lei`AS STRING) AS `0501_nna_lei`, CAST(`0510_cmmn_dpstry`AS STRING) AS `0510_cmmn_dpstry`, CAST(`0511_cmmn_dpstry_lei`AS STRING) AS `0511_cmmn_dpstry_lei`, CAST(`0520_cmmn_srvc_prvdr`AS STRING) AS `0520_cmmn_srvc_prvdr`, CAST(`0521_cmmn_srvc_prvdr_lei`AS STRING) AS `0521_cmmn_srvc_prvdr_lei`, CAST(`0530_typ_own_fnds_ind_lvl`AS STRING) AS `0530_typ_own_fnds_ind_lvl`, CAST(`0540_elgbl_amnt_own_fnds_ind_lvl`AS STRING) AS `0540_elgbl_amnt_own_fnds_ind_lvl`, CAST(`0550_typ_own_fnds_cnsldtd_lvl`AS STRING) AS `0550_typ_own_fnds_cnsldtd_lvl`, CAST(`0560_elgbl_amnt_own_fnds_cnsldtd_lvl`AS STRING) AS `0560_elgbl_amnt_own_fnds_cnsldtd_lvl`, CAST(`0570_amnt_scrty_intrst_prvdd`AS STRING) AS `0570_amnt_scrty_intrst_prvdd`, CAST(`0580_scrty_intrst_prvdr`AS STRING) AS `0580_scrty_intrst_prvdr`, CAST(`0581_scrty_intrst_prvdr_lei`AS STRING) AS `0581_scrty_intrst_prvdr_lei`, CAST(`0590_typ_scrty_intrst_prvdd`AS STRING) AS `0590_typ_scrty_intrst_prvdd`, CAST(`0600_flg_clltrl_asst_pstn`AS STRING) AS `0600_flg_clltrl_asst_pstn`, CAST(`0610_crryng_amnt_ifrs`AS STRING) AS `0610_crryng_amnt_ifrs`, CAST(`0620_blnc_sht_ifrs`AS STRING) AS `0620_blnc_sht_ifrs`, CAST(`0630_crrying_amnt_ngaap`AS STRING) AS `0630_crrying_amnt_ngaap`, CAST(`0640_blnc_sht_ngaap`AS STRING) AS `0640_blnc_sht_ngaap`, CAST(`5000_flg_shrhldr_not_rsltn_grp`AS STRING) AS `5000_flg_shrhldr_not_rsltn_grp`, CAST(`5010_flg_art21_7a_srmr`AS STRING) AS `5010_flg_art21_7a_srmr`

Sheet b0500
A1: 0010_row_nmbr | B1: CAST( | C1: =+"`"&A1&"`" -> `0010_row_nmbr` | D1: AS STRING) | E1: =+B1&C1&D1&" AS "&C1&", " -> CAST(`0010_row_nmbr`AS STRING) AS `0010_row_nmbr`, | F1: =+E1 -> CAST(`0010_row_nmbr`AS STRING) AS `0010_row_nmbr`,
A2: 0011_tab_origin | B2: CAST( | C2: =+"`"&A2&"`" -> `0011_tab_origin` | D2: AS STRING) | E2: =+B2&C2&D2&" AS "&C2&", " -> CAST(`0011_tab_origin`AS STRING) AS `0011_tab_origin`, | F2: =+F1&E2 -> CAST(`0010_row_nmbr`AS STRING) AS `0010_row_nmbr`, CAST(`0011_tab_origin`AS STRING) AS `0011_tab_origin`,
A3: 0020_uniq_id_knwn_cntrprty | B3: CAST( | C3: =+"`"&A3&"`" -> `0020_uniq_id_knwn_cntrprty` | D3: AS STRING) | E3: =+B3&C3&D3&" AS "&C3&", " -> CAST(`0020_uniq_id_knwn_cntrprty`AS STRING) AS `0020_uniq_id_knwn_cntrprty`, | F3: =+F2&E3 -> CAST(`0010_row_nmbr`AS STRING) AS `0010_row_nmbr`, CAST(`0011_tab_origin`AS STRING) AS `0011_tab_origin`, CAST(`0020_uniq_id_knwn_cntrprty`AS STRING) AS `0020_uniq_id_knwn_cntrprty`,
A4: 0030_cntrprty_rsltn_grp | B4: CAST( | C4: =+"`"&A4&"`" -> `0030_cntrprty_rsltn_grp` | D4: AS STRING) | E4: =+B4&C4&D4&" AS "&C4&", " -> CAST(`0030_cntrprty_rsltn_grp`AS STRING) AS `0030_cntrprty_rsltn_grp`, | F4: =+F3&E4 -> CAST(`0010_row_nmbr`AS STRING) AS `0010_row_nmbr`, CAST(`0011_tab_origin`AS STRING) AS `0011_tab_origin`, CAST(`0020_uniq_id_knwn_cntrprty`AS STRING) AS `0020_uniq_id_knwn_cntrprty`, CAST(`0030_cntrprty_rsltn_grp`AS STRING) AS `0030_cntrprty_rsltn_grp`,
A5: 0040_cntrprty_nm | B5: CAST( | C5: =+"`"&A5&"`" -> `0040_cntrprty_nm` | D5: AS STRING) | E5: =+B5&C5&D5&" AS "&C5&", " -> CAST(`0040_cntrprty_nm`AS STRING) AS `0040_cntrprty_nm`, | F5: =+F4&E5 -> CAST(`0010_row_nmbr`AS STRING) AS `0010_row_nmbr`, CAST(`0011_tab_origin`AS STRING) AS `0011_tab_origin`, CAST(`0020_uniq_id_knwn_cntrprty`AS STRING) AS `0020_uniq_id_knwn_cntrprty`, CAST(`0030_cntrprty_rsltn_grp`AS STRING) AS `0030_cntrprty_rsltn_grp`, CAST(`0040_cntrprty_nm`AS STRING) AS `0040_cntrprty_nm`,
A6: 0050_cntrprty_lei | B6: CAST( | C6: =+"`"&A6&"`" -> `0050_cntrprty_lei` | D6: AS STRING) | E6: =+B6&C6&D6&" AS "&C6&", " -> CAST(`0050_cntrprty_lei`AS STRING) AS `0050_cntrprty_lei`, | F6: =+F5&E6 -> CAST(`0010_row_nmbr`AS STRING) AS `0010_row_nmbr`, CAST(`0011_tab_origin`AS STRING) AS `0011_tab_origin`, CAST(`0020_uniq_id_knwn_cntrprty`AS STRING) AS `0020_uniq_id_knwn_cntrprty`, CAST(`0030_cntrprty_rsltn_grp`AS STRING) AS `0030_cntrprty_rsltn_grp`, CAST(`0040_cntrprty_nm`AS STRING) AS `0040_cntrprty_nm`, CAST(`0050_cntrprty_lei`AS STRING) AS `0050_cntrprty_lei`,
A7: 0060_typ_cntrprty_id | B7: CAST( | C7: =+"`"&A7&"`" -> `0060_typ_cntrprty_id` | D7: AS STRING) | E7: =+B7&C7&D7&" AS "&C7&", " -> CAST(`0060_typ_cntrprty_id`AS STRING) AS `0060_typ_cntrprty_id`, | F7: =+F6&E7 -> CAST(`0010_row_nmbr`AS STRING) AS `0010_row_nmbr`, CAST(`0011_tab_origin`AS STRING) AS `0011_tab_origin`, CAST(`0020_uniq_id_knwn_cntrprty`AS STRING) AS `0020_uniq_id_knwn_cntrprty`, CAST(`0030_cntrprty_rsltn_grp`AS STRING) AS `0030_cntrprty_rsltn_grp`, CAST(`0040_cntrprty_nm`AS STRING) AS `0040_cntrprty_nm`, CAST(`0050_cntrprty_lei`AS STRING) AS `0050_cntrprty_lei`, CAST(`0060_typ_cntrprty_id`AS STRING) AS `0060_typ_cntrprty_id`,
A8: 0070_cntrprty_id | B8: CAST( | C8: =+"`"&A8&"`" -> `0070_cntrprty_id` | D8: AS STRING) | E8: =+B8&C8&D8&" AS "&C8&", " -> CAST(`0070_cntrprty_id`AS STRING) AS `0070_cntrprty_id`, | F8: =+F7&E8 -> CAST(`0010_row_nmbr`AS STRING) AS `0010_row_nmbr`, CAST(`0011_tab_origin`AS STRING) AS `0011_tab_origin`, CAST(`0020_uniq_id_knwn_cntrprty`AS STRING) AS `0020_uniq_id_knwn_cntrprty`, CAST(`0030_cntrprty_rsltn_grp`AS STRING) AS `0030_cntrprty_rsltn_grp`, CAST(`0040_cntrprty_nm`AS STRING) AS `0040_cntrprty_nm`, CAST(`0050_cntrprty_lei`AS STRING) AS `0050_cntrprty_lei`, CAST(`0060_typ_cntrprty_id`AS STRING) AS `0060_typ_cntrprty_id`, CAST(`0070_cntrprty_id`AS STRING) AS `0070_cntrprty_id`,
A9: 0080_cntrprty_typ | B9: CAST( | C9: =+"`"&A9&"`" -> `0080_cntrprty_typ` | D9: AS STRING) | E9: =+B9&C9&D9&" AS "&C9&", " -> CAST(`0080_cntrprty_typ`AS STRING) AS `0080_cntrprty_typ`, | F9: =+F8&E9 -> CAST(`0010_row_nmbr`AS STRING) AS `0010_row_nmbr`, CAST(`0011_tab_origin`AS STRING) AS `0011_tab_origin`, CAST(`0020_uniq_id_knwn_cntrprty`AS STRING) AS `0020_uniq_id_knwn_cntrprty`, CAST(`0030_cntrprty_rsltn_grp`AS STRING) AS `0030_cntrprty_rsltn_grp`, CAST(`0040_cntrprty_nm`AS STRING) AS `0040_cntrprty_nm`, CAST(`0050_cntrprty_lei`AS STRING) AS `0050_cntrprty_lei`, CAST(`0060_typ_cntrprty_id`AS STRING) AS `0060_typ_cntrprty_id`, CAST(`0070_cntrprty_id`AS STRING) AS `0070_cntrprty_id`, CAST(`0080_cntrprty_typ`AS STRING) AS `0080_cntrprty_typ`,
A10: 0090_cntry_cntrprty | B10: CAST( | C10: =+"`"&A10&"`" -> `0090_cntry_cntrprty` | D10: AS STRING) | E10: =+B10&C10&D10&" AS "&C10&", " -> CAST(`0090_cntry_cntrprty`AS STRING) AS `0090_cntry_cntrprty`, | F10: =+F9&E10 -> CAST(`0010_row_nmbr`AS STRING) AS `0010_row_nmbr`, CAST(`0011_tab_origin`AS STRING) AS `0011_tab_origin`, CAST(`0020_uniq_id_knwn_cntrprty`AS STRING) AS `0020_uniq_id_knwn_cntrprty`, CAST(`0030_cntrprty_rsltn_grp`AS STRING) AS `0030_cntrprty_rsltn_grp`, CAST(`0040_cntrprty_nm`AS STRING) AS `0040_cntrprty_nm`, CAST(`0050_cntrprty_lei`AS STRING) AS `0050_cntrprty_lei`, CAST(`0060_typ_cntrprty_id`AS STRING) AS `0060_typ_cntrprty_id`, CAST(`0070_cntrprty_id`AS STRING) AS `0070_cntrprty_id`, CAST(`0080_cntrprty_typ`AS STRING) AS `0080_cntrprty_typ`, CAST(`0090_cntry_cntrprty`AS STRING) AS `0090_cntry_cntrprty`,
A11: 0100_rlvnt_amnt_wdc | B11: CAST( | C11: =+"`"&A11&"`" -> `0100_rlvnt_amnt_wdc` | D11: AS STRING) | E11: =+B11&C11&D11&" AS "&C11&", " -> CAST(`0100_rlvnt_amnt_wdc`AS STRING) AS `0100_rlvnt_amnt_wdc`, | F11: =+F10&E11 -> CAST(`0010_row_nmbr`AS STRING) AS `0010_row_nmbr`, CAST(`0011_tab_origin`AS STRING) AS `0011_tab_origin`, CAST(`0020_uniq_id_knwn_cntrprty`AS STRING) AS `0020_uniq_id_knwn_cntrprty`, CAST(`0030_cntrprty_rsltn_grp`AS STRING) AS `0030_cntrprty_rsltn_grp`, CAST(`0040_cntrprty_nm`AS STRING) AS `0040_cntrprty_nm`, CAST(`0050_cntrprty_lei`AS STRING) AS `0050_cntrprty_lei`, CAST(`0060_typ_cntrprty_id`AS STRING) AS `0060_typ_cntrprty_id`, CAST(`0070_cntrprty_id`AS STRING) AS `0070_cntrprty_id`, CAST(`0080_cntrprty_typ`AS STRING) AS `0080_cntrprty_typ`, CAST(`0090_cntry_cntrprty`AS STRING) AS `0090_cntry_cntrprty`, CAST(`0100_rlvnt_amnt_wdc`AS STRING) AS `0100_rlvnt_amnt_wdc`,
F15: CAST(`0010_row_nmbr`AS STRING) AS `0010_row_nmbr`, CAST(`0011_tab_origin`AS STRING) AS `0011_tab_origin`, CAST(`0020_uniq_id_knwn_cntrprty`AS STRING) AS `0020_uniq_id_knwn_cntrprty`, CAST(`0030_cntrprty_rsltn_grp`AS STRING) AS `0030_cntrprty_rsltn_grp`, CAST(`0040_cntrprty_nm`AS STRING) AS `0040_cntrprty_nm`, CAST(`0050_cntrprty_lei`AS STRING) AS `0050_cntrprty_lei`, CAST(`0060_typ_cntrprty_id`AS STRING) AS `0060_typ_cntrprty_id`, CAST(`0070_cntrprty_id`AS STRING) AS `0070_cntrprty_id`, CAST(`0080_cntrprty_typ`AS STRING) AS `0080_cntrprty_typ`, CAST(`0090_cntry_cntrprty`AS STRING) AS `0090_cntry_cntrprty`, CAST(`0100_rlvnt_amnt_wdc`AS STRING) AS `0100_rlvnt_amnt_wdc`,

Sheet B0200 (Set25)
A1: 0010_row_nmbr | B1: 0020_uniq_id | C1: 0030_uniq_id_knwn_cntrprty | D1: 0040_typ_uniq_id_knwn_cntrprty | E1: 0050_orgnl_amnt_eur | F1: 0060_orgnl_amnt_fx | G1: 0070_cntrct_crrncy | H1: 0080_otstndng_prncpl_amnt | I1: 0090_prtn_amnt_rprtng_entty | J1: 0100_accrd_intrst_instrmnt | K1: 0110_applcbl_fees_charges | L1: 0120_otstndng_amnt | M1: 0130_rlvnt_amnt_wdc | N1: 0140_ntr_lblty | O1: 0141_ntr_lblty_othr | P1: 0150_flg_strctrlly_sbrdntd | Q1: 0160_rank_insolv | R1: 0161_cntrctl_sbrdntn | S1: 0162_bail_in_cascade | T1: 0170_dt_incptn | U1: 0180_dt_nxt_intrst_pymnt | V1: 0190_dt_nxt_rdmptn_pymnt | W1: 0200_dt_erlst_rdmptn | X1: 0210_dt_lgl_fnl_mtrty | Y1: 0220_governing_law | Z1: 0230_bail_in_rcgntn_cls | AA1: 0240_zero_coupon | AB1: 0250_strctrd_prdct | AC1: 0260_grntd_min_amnt_strctrd_prdct | AD1: 0270_fv_amnt_strctrd_prdct | AE1: 0280_flg_ncnp_dpsts | AF1: 0290_flg_ncbp_dpsts | AG1: 0300_amnt_cvrd_elgbl_dpsts | AH1: 0310_flg_clltrl_agrmnts | AI1: 0320_amnt_clltrl | AJ1: 0330_amnt_unclltrlzd | AK1: 0340_id_clltrl | AL1: 0350_typ_clltrl | AM1: 0351_typ_clltrl_othr | AN1: 0360_trdng_mthd | AO1: 0370_amnt_scrty_eur | AP1: 0380_amnt_scrty_fx | AQ1: 0390_nmbr_scrts_not_rprtng_entty | AR1: 0391_nmbr_scrts_rprtng_entty | AS1: 0400_accrd_intrst_scrty | AT1: 0410_fees_charges_scrty | AU1: 0420_fv_amnt_scrty | AV1: 0430_prncpl_amnt_glbl_nt_eur | AW1: 0431_prncpl_amnt_glbl_nt_fx | AX1: 0440_ntr_glbl_nt | AY1: 0450_crrnt_pool_fctr | AZ1: 0460_csd | BA1: 0461_csd_lei | BB1: 0462_csd_othr | BC1: 0470_pyng_agnt | BD1: 0471_pyng_agnt_lei | BE1: 0480_trdng_vn | BF1: 0481_trdng_vn_lei | BG1: 0490_rgstrr | BH1: 0491_rgstrr_lei | BI1: 0500_nna | BJ1: 0501_nna_lei | BK1: 0510_cmmn_dpstry | BL1: 0511_cmmn_dpstry_lei | BM1: 0520_cmmn_srvc_prvdr | BN1: 0521_cmmn_srvc_prvdr_lei | BO1: 0530_typ_own_fnds_ind_lvl | BP1: 0540_elgbl_amnt_own_fnds_ind_lvl | BQ1: 0550_typ_own_fnds_cnsldtd_lvl | BR1: 0560_elgbl_amnt_own_fnds_cnsldtd_lvl | BS1: 0570_amnt_scrty_intrst_prvdd | BT1: 0580_scrty_intrst_prvdr | BU1: 0581_scrty_intrst_prvdr_lei | BV1: 0590_typ_scrty_intrst_prvdd | BW1: 0600_flg_clltrl_asst_pstn | BX1: 0610_crryng_amnt_ifrs | BY1: 0620_blnc_sht_ifrs | BZ1: 0630_crrying_amnt_ngaap | CA1: 0640_blnc_sht_ngaap | CB1: 5000_flg_shrhldr_not_rsltn_grp | CC1: 5010_flg_art21_7a_srmr | CD1: crryng_amnt_instrmnt | CE1: prtn_amnt_rprtng_entty | CF1: otstndng_prncpl_amnt | CG1: accrd_intrst_instrmnt | CH1: id_corrida | CI1: ref_date
A2: 1 | B2: 31641600000000000PTBSREOM0028000 | C2: PTBSREOM0028 | D2: ISIN | E2: 7599000 | F2: 999999999999999 | G2: EUR | H2: 7599000 | I2: 0 | J2: 562117.81 | K2: 0 | L2: 8161117.8 | M2: 8161117.8 | N2: Registered Bond | O2: Not applicable | P2: Not applicable | Q2: 3 | R2: 999999999999999 | S2: 3 | T2: 2016-09-28 | U2: 2025-10-06 | V2: 2026-10-06 | W2: 0001-01-01 | X2: 2026-10-06 | Y2: PT | Z2: Yes, supported by Legal Opinion | AA2: No ZCB | AB2: Non-structured/Vanilla | AC2: 999999999999999 | AD2: 999999999999999 | AE2: FALSE | AF2: FALSE | AG2: 999999999999999 | AH2: Unsecured | AI2: 999999999999999 | AJ2: 999999999999999 | AK2: Not applicable | AL2: Not applicable | AM2: Not applicable | AN2: Nominal | AO2: 1000 | AP2: 1000 | AQ2: 7599 | AR2: 0 | AS2: 73.9726 | AT2: 0 | AU2: 999999999999999 | AV2: 999999999999999 | AW2: 999999999999999 | AX2: Not applicable | AY2: -10000 | AZ2: INTERBOLSA_PT | BA2: 529900LG70TCAGWCXT47 | BB2: Not applicable | BC2: BANCO SANTANDER TOTTA S,A, | BD2: 549300URJH9VSI58CS32 | BE2: Not applicable | BF2: Not applicable | BG2: INTERBOLSA_PT | BH2: 529900LG70TCAGWCXT47 | BI2: INTERBOLSA_PT | BJ2: 529900LG70TCAGWCXT47 | BK2: Not applicable | BL2: Not applicable | BM2: Not applicable | BN2: Not applicable | BO2: Fully Compliant T2 | BP2: 7599000 | BQ2: Fully Compliant T2 | BR2: 7599000 | BS2: 0 | BT2: Not applicable | BU2: Not applicable | BV2: Not applicable | BW2: FALSE | BX2: 8161117.8 | BY2: 110 Financial liabilities at amortized cost | BZ2: 999999999999999 | CA2: Not applicable | CB2: FALSE | CC2: TRUE | CD2: -8161117.8 | CE2: 0 | CF2: 7599000 | CG2: -562117.81 | CH2: 1 | CI2: 2025-09-30
A3: 2 | B3: 31641600000000000PTSTOEOM0021000 | C3: PTSTOEOM0021 | D3: ISIN | E3: 600000000 | F3: 999999999999999 | G3: EUR | H3: 600000000 | I3: 0 | J3: 6071671.2 | K3: 0 | L3: 6.0607167e+08 | M3: 6.0607167e+08 | N3: Registered Bond | O3: Not applicable | P3: Not applicable | Q3: 8 | R3: 999999999999999 | S3: 8 | T3: 2022-06-01 | U3: 2026-06-03 | V3: 2027-06-03 | W3: 0001-01-01 | X3: 2027-06-03 | Y3: PT | Z3: Yes, supported by Legal Opinion | AA3: No ZCB | AB3: Non-structured/Vanilla | AC3: 999999999999999 | AD3: 999999999999999 | AE3: FALSE | AF3: FALSE | AG3: 999999999999999 | AH3: Unsecured | AI3: 999999999999999 | AJ3: 999999999999999 | AK3: Not applicable | AL3: Not applicable | AM3: Not applicable | AN3: Nominal | AO3: 100000 | AP3: 100000 | AQ3: 6000 | AR3: 0 | AS3: 1011.9452 | AT3: 0 | AU3: 999999999999999 | AV3: 999999999999999 | AW3: 999999999999999 | AX3: Not applicable | AY3: -10000 | AZ3: INTERBOLSA_PT | BA3: 529900LG70TCAGWCXT47 | BB3: Not applicable | BC3: BANCO SANTANDER TOTTA S,A, | BD3: 549300URJH9VSI58CS32 | BE3: Not applicable | BF3: Not applicable | BG3: INTERBOLSA_PT | BH3: 529900LG70TCAGWCXT47 | BI3: INTERBOLSA_PT | BJ3: 529900LG70TCAGWCXT47 | BK3: Not applicable | BL3: Not applicable | BM3: Not applicable | BN3: Not applicable | BP3: 0 | BR3: 0 | BS3: 0 | BT3: Not applicable | BU3: Not applicable | BV3: Not applicable | BW3: FALSE | BX3: 6.0607167e+08 | BY3: 110 Financial liabilities at amortized cost | BZ3: 999999999999999 | CA3: Not applicable | CB3: FALSE | CC3: TRUE | CD3: -6.0607167e+08 | CE3: 0 | CF3: 600000000 | CG3: -6071671.2 | CH3: 1 | CI3: 2025-09-30
