Workbook
Name _Hlk71900621: 'Campos IMP vs CNT'!$C$61
Name _Toc164082157: 'Campos IMP vs CNT'!#REF!
Name _Toc164082158: 'Campos IMP vs CNT'!$C$52
Name _Toc164082286: 'Campos IMP vs CNT'!$C$62
Name _Toc164082298: 'Campos IMP vs CNT'!$C$64
Name _Toc164082299: 'Campos IMP vs CNT'!$C$65
Name _Toc164082302: 'Campos IMP vs CNT'!$C$12
Name _Toc164082303: 'Campos IMP vs CNT'!$C$13
Name _Toc164082304: 'Campos IMP vs CNT'!$C$49
Name _Toc164082314: 'Campos IMP vs CNT'!$C$5
Name _Toc164082315: 'Campos IMP vs CNT'!$C$3
Name _Toc164082316: 'Campos IMP vs CNT'!$C$4
Name _Toc164082319: 'Campos IMP vs CNT'!$C$60
Name _Toc164082330: 'Campos IMP vs CNT'!$C$48
Name _Toc164082331: 'Campos IMP vs CNT'!$C$68
Name _Toc164082332: 'Campos IMP vs CNT'!$C$22
Name _Toc164082333: 'Campos IMP vs CNT'!$C$36
Name _Toc164082334: 'Campos IMP vs CNT'!$C$37
Name _Toc164082339: 'Campos IMP vs CNT'!$C$42
Name _Toc164082348: 'Campos IMP vs CNT'!$C$51
Name _Toc164082349: 'Campos IMP vs CNT'!$C$69
Name _Toc164082351: 'Campos IMP vs CNT'!$C$57
Name _Toc164082352: 'Campos IMP vs CNT'!$C$58
Name _Toc164082353: 'Campos IMP vs CNT'!$C$59
Name _Toc164082359: 'Campos IMP vs CNT'!$C$33
Name _Toc164082360: 'Campos IMP vs CNT'!$C$34
Name _Toc164082361: 'Campos IMP vs CNT'!$C$35
Name _Toc164082362: 'Campos IMP vs CNT'!$C$38
Name _Toc164082363: 'Campos IMP vs CNT'!$C$39
Name _Toc164082366: 'Campos IMP vs CNT'!$C$43
Name _Toc164082367: 'Campos IMP vs CNT'!$C$44
Name _Toc164082368: 'Campos IMP vs CNT'!$C$7
Name _Toc164082369: 'Campos IMP vs CNT'!$C$45
Name _Toc164082370: 'Campos IMP vs CNT'!$C$8
Name _Toc164082371: 'Campos IMP vs CNT'!$C$46
Name _Toc164082372: 'Campos IMP vs CNT'!$C$9
Name _Toc164082373: 'Campos IMP vs CNT'!$C$10
Name _Toc164082374: 'Campos IMP vs CNT'!$C$11
Name _Toc164082375: 'Campos IMP vs CNT'!$C$66
Name _Toc164082381: 'Campos IMP vs CNT'!#REF!
Name _Toc164082382: 'Campos IMP vs CNT'!$C$53
Name _Toc164082383: 'Campos IMP vs CNT'!$C$54
Name _Toc164082394: 'Campos IMP vs CNT'!#REF!
Name _Toc164082395: 'Campos IMP vs CNT'!#REF!
Name _Toc164082396: 'Campos IMP vs CNT'!#REF!
Name _Toc164082397: 'Campos IMP vs CNT'!#REF!

Sheet Status
U7: Status Atual | V7: (All)
U9: Row Labels | V9: Count of Categorização
C10: Âmbito (Projeto) | D10: PM | I10: Âmbito (Projeto) | J10: PM | U10: Fora OSI | V10: 119
R11: Potencial de proposta - Campos concluídos, sem melhorias identidicadas, mas com necessidade de documentação | U11: Analisar controlos NOK | V11: 16
C12: Count of Status Atual | J12: OSI VS FORA OSI | R12: Potencial de proposta - Campos com melhorias mais complexas identificadas na OSI ou fora da mesma. | U12: Melhorias estruturais (garantir coerência entre campos) | V12: 14
C13: Status Atual | D13: Fora OSI | E13: OSI | F13: Grand Total | J13: Fora OSI | L13: OSI | N13: Total # | O13: Total % | R13: Quick-win âmbito do projeto em curso | U13: Novo campo | V13: 9
C14: 1. Especificar | D14: 9 | E14: 1 | F14: 10 | I14: Quick Win | J14: # | K14: % | L14: # | M14: % | U14: Necessidade de correção de erros | V14: 5
C15: 2. Alterar especificação | D15: 3 | E15: 14 | F15: 17 | I15: Campo Fechado | J15: 69 | K15: 0.26436782 | L15: 96 | M15: 0.36781609 | N15: 165 | O15: 0.63218391 | U15: Campo concluído, mas sem ou pouca informação na fonte | V15: 10
C16: 3. Pendente de decisão | E16: 2 | F16: 2 | I16: Não | J16: 30 | K16: 0.11494253 | L16: 40 | M16: 0.1532567 | N16: 70 | O16: 0.26819923 | U16: Campo concluido | V16: 65
C17: 4.1 Em implementação - Re-especificação | D17: 1 | F17: 1 | I17: Sim | J17: 3 | K17: 0.011494253 | L17: 23 | M17: 0.088122605 | N17: 26 | O17: 0.099616858 | U17: OSI | V17: 227
C18: 5.1 Em testes - Re-especificação | D18: 4 | E18: 18 | F18: 22 | I18: Grand Total | J18: 102 | K18: 0.3908046 | L18: 159 | M18: 0.6091954 | N18: 261 | O18: 1 | U18: Alteração de especificação por parte do BCE | V18: 8
C19: 5.2 Em testes - Incidência | E19: 3 | F19: 3 | U19: Analisar controlos NOK | V19: 41
C20: 7. Analisar controlos e completude | D20: 16 | E20: 26 | F20: 42 | U20: Melhorias estruturais (garantir coerência entre campos) | V20: 37
C21: 8. Concluído - sem dados | D21: 6 | E21: 1 | F21: 7 | U21: Novo campo | V21: 6
C22: 9. Concluído | D22: 63 | E22: 94 | F22: 157 | U22: Necessidade de correção de erros | V22: 21
C23: Grand Total | D23: 102 | E23: 159 | F23: 261 | U23: Pendente de decisão | V23: 24
U24: Campo concluído, mas sem ou pouca informação na fonte | V24: 2
U25: Campo concluido | V25: 88
U26: Grand Total | V26: 346

Sheet PDS (old)
B8: 2 | C8: Especificação | D8: 11 | E8: Especificação
C9: ORGNL_PRTCTN_VL | E9: Campos Contabilidade
C10: DT_ORGNL_PRTCTN_VL | E10: IMPRMNT_STTS
E11: PRFRMNG_STTS
E12: IMPRMNT_STTS_PRVS
E13: PRFRMNG_STTS_PRVS
E14: DPD_12M_PRFRMNG_STTS
E15: DPD_24M_PRFRMNG_STTS
E16: DPD_PRFRMNG_STTS
E17: DT_IMPRMNT_STTS
E18: DT_IMPRMNT_STTS_PRVS
E19: DT_PRFRMNG_STTS
E20: DT_PRFRMNG_STTS_PRVS
J27: 1. Especificar | K27: 2. Alterar especificação | L27: 3. Pendente de decisão | M27: 4.1 Em implementação - Re-especificação | N27: 4.2 Em implementação - Incidência | O27: 5.1 Em testes - Re-especificação | P27: 5.2 Em testes - Incidência | Q27: 6. Outros Desenvolvimentos | R27: 7. Analisar controlos e completude | S27: 8. Concluído - sem dados | T27: 9. Concluído
I28: Status Atual | J28: =COUNTIF(Detalhe!$K:$K,J27) -> 50 | K28: =COUNTIF(Detalhe!$K:$K,K27) -> 41 | L28: =COUNTIF(Detalhe!$K:$K,L27) -> 8 | M28: =COUNTIF(Detalhe!$K:$K,M27) -> 1 | N28: =COUNTIF(Detalhe!$K:$K,N27) -> 0 | O28: =COUNTIF(Detalhe!$K:$K,O27) -> 32 | P28: =COUNTIF(Detalhe!$K:$K,P27) -> 9 | Q28: =COUNTIF(Detalhe!$K:$K,Q27) -> 10 | ... T28: =COUNTIF(Detalhe!$K:$K,T27) -> 161
I29: Status Inicial (pós OSI) | J29: =COUNTIF(Detalhe!$E:$E,J27) -> 50 | K29: =COUNTIF(Detalhe!$E:$E,K27) -> 42 | L29: =COUNTIF(Detalhe!$E:$E,L27) -> 17 | M29: =COUNTIF(Detalhe!$E:$E,M27) -> 4 | N29: =COUNTIF(Detalhe!$E:$E,N27) -> 0 | O29: =COUNTIF(Detalhe!$E:$E,O27) -> 21 | P29: =COUNTIF(Detalhe!$E:$E,P27) -> 17 | Q29: =COUNTIF(Detalhe!$E:$E,Q27) -> 10 | ... T29: =COUNTIF(Detalhe!$E:$E,T27) -> 151
I30: Variação | J30: {=_xlfn.IFS(J28>J29, "↑",J28<J29, "↓",J28=J29, "=")} -> = | K30: {=_xlfn.IFS(K28>K29, "↑",K28<K29, "↓",K28=K29, "=")} -> ↓ | L30: {=_xlfn.IFS(L28>L29, "↑",L28<L29, "↓",L28=L29, "=")} -> ↓ | M30: {=_xlfn.IFS(M28>M29, "↑",M28<M29, "↓",M28=M29, "=")} -> ↓ | N30: {=_xlfn.IFS(N28>N29, "↑",N28<N29, "↓",N28=N29, "=")} -> = | O30: {=_xlfn.IFS(O28>O29, "↑",O28<O29, "↓",O28=O29, "=")} -> ↑ | P30: {=_xlfn.IFS(P28>P29, "↑",P28<P29, "↓",P28=P29, "=")} -> ↓ | Q30: {=_xlfn.IFS(Q28>Q29, "↑",Q28<Q29, "↓",Q28=Q29, "=")} -> = | ... T30: {=_xlfn.IFS(T28>T29, "↑",T28<T29, "↓",T28=T29, "=")} -> ↑
I31: Progressão | J31: =J28-J29 -> 0 | K31: =K28-K29 -> -1 | L31: =L28-L29 -> -9 | M31: =M28-M29 -> -3 | N31: =N28-N29 -> 0 | O31: =O28-O29 -> 11 | P31: =P28-P29 -> -8 | Q31: =Q28-Q29 -> 0 | ... T31: =T28-T29 -> 10
J34: 3. Pendente de decisão - Identificados temas em OSI nos campos e é necessário identificar cauisticas (pode ficar como está ou ser alterado). Quem toma as decisões são as areas de negócio, porém o Luis poderá dar a decisão final
C35: 45555
B36: Tema | D36: Questão | I36: Decisão
B37: DT_ORGNL_PRTCTN_VL | D37: O campo 'dtvalia_resp_bem' só possuI informação para datas de referências posteriores a 2024-07-31. Como devemos proceder caso seja necessário reportar dados anteriores a Jul.2024? | I37: Manter a especificação com mapeamento após jul.24
B38: ORGNL_PRTCTN_VL | D38: O campo 'mavaliai_resp_bem' só possuI informação para datas de referências posteriores a 2024-07-31. Como devemos proceder caso seja necessário reportar dados anteriores a Jul.2024? | I38: Manter a especificação com mapeamento após jul.24
B39: DT_CNSTRCTN_STTS | D39: Teremos de criar uma tabela auxiliar com o histórico dos estados de construção e mapear para a data mais antiga do estado de construção atual. Uma vez que o MUG tem uma ótica de atualização diária, para o mapeamento e criação desta tabela auxiliar devemos olhar para uma ótica ou mensal? | I39: Criar tabela auxiliar e ir buscar a ref_date. Devemos utilizar uma ótica diária. Analisar controlos por amostragem.
B40: DT_CNSTRCTN_STTS | D40: Caso o bem só tenha um estado desde sempre/ desde que foi recebido como garantia devemos reportar a DT_INCPTN? E caso tenha mais do que um instrumento associado, qual a dt_incptn que devemos utilizar? A mais antiga? | I40: Questionar Corporação: 1) Caso o bem só tenha um estado desde sempre/ desde que foi recebido como garantia qual a data que devemos reportar? 2) A DR_CNSTRCTN_STTS pode ser anterior à DT_INCPTN? Estes casos poderão acontecer caso uma garantia esteja associada a mais do que um contrato.
B41: Campos Contabilidade vs Imparidade | D41: 12 campos com informação de Imparidade, em que a Contabilidade assumiu a ownership uma vez que reporta este dado. Avançamos na re-especificação dos campos utilizando o mapeamento das tabelas de Contabilidade para datas de referência após Dez.22 e a tabela 7_8 de Imparidade para datas anteriores a Dez.22? IMPRMNT_STTS PRFRMNG_STTS IMPRMNT_STTS_PRVS POCI PRFRMNG_STTS_PRVS DPD_12M_PRFRMNG_STTS DPD_24M_PRFRMNG_STTS DPD_PRFRMNG_STTS DT_IMPRMNT_STTS DT_IMPRMNT_STTS_PRVS DT_PRFRMNG_STTS DT_PRFRMNG_STTS_PRVS | I41: Atualmente o campo de stage está a ser populado com informação de Imparidade até Dez.19 e a partir de Jan.20 com informação da FR004. Deste modo, a alteração de especificação prende-se apenas com a alteração da data para Dez.22. Solicitar a Alexandre Gonçalvez que validem os campos após implementação de IT, sem prejuizo dos testes por parte da equipa LT.
B42: Campos Imparidade - Fonte da Verdade | D42: 12 campos de Imparidade. Devemos sugerir mapeamento dos campos tendo em conta a tabela de o David Texugo indicou e enviar para validação? Enviamos um e-mail a solicitar esse mapeamento, mas sem resposta até ao momento. EIR EIR_INCPTN IFRS9_CCF IFRS9_EAD IFRS9_LGD INTRNL_SGMNT_IFRS9 PD_IFRS9_12M_INCPTN PD_IFRS9_12M_RD PD_IFRS9_12M_RD_T1 PD_IFRS9_LFTM_INCPTN PD_IFRS9_RMNNG_LFTM_INCPTN PD_IFRS9_RMNNG_LFTM_RD | I42: Fazer proposta. Segmentar por campos OK e NOK.
B43: PRTCTN_VL | D43: 40 garantias imóveis com valor de proteção a zero, cuja origem são a G39 ou G26. Analisados por Henrique e Susana: 35 casos encontram-se no nosso ficheiro de Erros dos Métodos Indiciários com falta de informação: 33 – Apenas com informação na GP26 1 – Valor de avaliação a zero 1 - % de CI não encontrado para o critério 2 casos são do cliente Vilamoura World – imóvel não identificado 3 casos são do cliente IAD da Madeira e já foram distratados
B44: PRTCTN_VL | D44: 11 Garantias Imóveis cuja origem provêm das CSs, com valor da proteção igual a zero (não são clones). Para quem devemos enviar estes casos para análise?
B45: PRTCTN_VL | D45: 121 Garantias Imóveis com contratos de Leasing associados, cujo valor da proteção é zero (não são clones). Para quem devemos enviar estes casos para análise?
B46: PRTCTN_VL | D46: 1 garantia Financeira, cujo valor da proteção é zero – Caso não está na GT018 para datas posteriores a 2024-05-31. Devíamos retirar da LT os casos com o msldreal a zero (temos 25 casos)?
B47: PRTCTN_VL | D47: 46 casos com data inválidas 0001-01-01 para análise da equipa de leasing.
J49: 4.1 respecificado
J50: 4.2 IT não implementou corretamente
J51: 6. Outros desenvolvimentos - Não podemos avançar no campo por haver necessidade de alguma alteração no campo fonte
J52: 7. Controlos corporativos NOK que necessitam de ser analizados
J53: 8. Campos que não são para mexer
J54: 9. A partir do momento que sobe a CD

Sheet Aux.
B2: Estado | C2: Status Inicial | E2: Status Atual | F2: Status Atual (%) | G2: Progressão
B3: 1. Especificar | C3: =COUNTIFS(Detalhe!E:E,B3,Detalhe!W:W,"PM") -> 10 | D3: =C3/$C$14 -> 0.038314176 | E3: =COUNTIFS(Detalhe!K:K,B3,Detalhe!W:W,"PM") -> 10 | F3: =E3/$E$14 -> 0.038314176 | G3: =E3-C3 -> 0
B4: 2. Alterar especificação | C4: =COUNTIFS(Detalhe!E:E,B4,Detalhe!W:W,"PM") -> 18 | D4: =C4/$C$14 -> 0.068965517 | E4: =COUNTIFS(Detalhe!K:K,B4,Detalhe!W:W,"PM") -> 17 | F4: =E4/$E$14 -> 0.0651341 | G4: =E4-C4 -> -1
B5: 3. Pendente de decisão | C5: =COUNTIFS(Detalhe!E:E,B5,Detalhe!W:W,"PM") -> 11 | D5: =C5/$C$14 -> 0.042145594 | E5: =COUNTIFS(Detalhe!K:K,B5,Detalhe!W:W,"PM") -> 2 | F5: =E5/$E$14 -> 0.0076628352 | G5: =E5-C5 -> -9
B6: 4.1 Em implementação - Re-especificação | C6: =COUNTIFS(Detalhe!E:E,B6,Detalhe!W:W,"PM") -> 4 | D6: =C6/$C$14 -> 0.01532567 | E6: =COUNTIFS(Detalhe!K:K,B6,Detalhe!W:W,"PM") -> 1 | F6: =E6/$E$14 -> 0.0038314176 | G6: =E6-C6 -> -3
B7: 4.2 Em implementação - Incidência | C7: =COUNTIFS(Detalhe!E:E,B7,Detalhe!W:W,"PM") -> 0 | D7: =C7/$C$14 -> 0 | E7: =COUNTIFS(Detalhe!K:K,B7,Detalhe!W:W,"PM") -> 0 | F7: =E7/$E$14 -> 0 | G7: =E7-C7 -> 0
B8: 5.1 Em testes - Re-especificação | C8: =COUNTIFS(Detalhe!E:E,B8,Detalhe!W:W,"PM") -> 11 | D8: =C8/$C$14 -> 0.042145594 | E8: =COUNTIFS(Detalhe!K:K,B8,Detalhe!W:W,"PM") -> 22 | F8: =E8/$E$14 -> 0.084291188 | G8: =E8-C8 -> 11
B9: 5.2 Em testes - Incidência | C9: =COUNTIFS(Detalhe!E:E,B9,Detalhe!W:W,"PM") -> 11 | D9: =C9/$C$14 -> 0.042145594 | E9: =COUNTIFS(Detalhe!K:K,B9,Detalhe!W:W,"PM") -> 3 | F9: =E9/$E$14 -> 0.011494253 | G9: =E9-C9 -> -8
B10: 6. Outros Desenvolvimentos | C10: =COUNTIFS(Detalhe!E:E,B10,Detalhe!W:W,"PM") -> 0 | D10: =C10/$C$14 -> 0 | E10: =COUNTIFS(Detalhe!K:K,B10,Detalhe!W:W,"PM") -> 0 | F10: =E10/$E$14 -> 0 | G10: =E10-C10 -> 0
B11: 7. Analisar controlos e completude | C11: =COUNTIFS(Detalhe!E:E,B11,Detalhe!W:W,"PM") -> 42 | D11: =C11/$C$14 -> 0.16091954 | E11: =COUNTIFS(Detalhe!K:K,B11,Detalhe!W:W,"PM") -> 42 | F11: =E11/$E$14 -> 0.16091954 | G11: =E11-C11 -> 0
B12: 8. Concluído - sem dados | C12: =COUNTIFS(Detalhe!E:E,B12,Detalhe!W:W,"PM") -> 7 | D12: =C12/$C$14 -> 0.026819923 | E12: =COUNTIFS(Detalhe!K:K,B12,Detalhe!W:W,"PM") -> 7 | F12: =E12/$E$14 -> 0.026819923 | G12: =E12-C12 -> 0
B13: 9. Concluído | C13: =COUNTIFS(Detalhe!E:E,B13,Detalhe!W:W,"PM") -> 147 | D13: =C13/$C$14 -> 0.56321839 | E13: =COUNTIFS(Detalhe!K:K,B13,Detalhe!W:W,"PM") -> 157 | F13: =E13/$E$14 -> 0.60153257 | G13: =E13-C13 -> 10
C14: =SUM(C3:C13) -> 261 | E14: =SUM(E3:E13) -> 261

Sheet PDS
B8: 2 | C8: Especificação | D8: 11 | E8: Especificação
C9: ORGNL_PRTCTN_VL | E9: Campos Contabilidade
C10: DT_ORGNL_PRTCTN_VL | E10: IMPRMNT_STTS
E11: PRFRMNG_STTS
E12: IMPRMNT_STTS_PRVS
E13: PRFRMNG_STTS_PRVS
E14: DPD_12M_PRFRMNG_STTS
E15: DPD_24M_PRFRMNG_STTS
E16: DPD_PRFRMNG_STTS
E17: DT_IMPRMNT_STTS
E18: DT_IMPRMNT_STTS_PRVS
E19: DT_PRFRMNG_STTS
E20: DT_PRFRMNG_STTS_PRVS
J27: 1. Especificar | K27: 2. Alterar especificação | L27: 3. Pendente de decisão | M27: 4.1 Em implementação - Re-especificação | N27: 4.2 Em implementação - Incidência | O27: 5.1 Em testes - Re-especificação | P27: 5.2 Em testes - Incidência | Q27: 6. Outros Desenvolvimentos | R27: 7. Analisar controlos e completude | S27: 8. Concluído - sem dados | T27: 9. Concluído
I28: Status Atual | J28: =COUNTIFS(Detalhe!$K:$K,J27,Detalhe!$W:$W,"PM") -> 10 | K28: =COUNTIFS(Detalhe!$K:$K,K27,Detalhe!$W:$W,"PM") -> 17 | L28: =COUNTIFS(Detalhe!$K:$K,L27,Detalhe!$W:$W,"PM") -> 2 | M28: =COUNTIFS(Detalhe!$K:$K,M27,Detalhe!$W:$W,"PM") -> 1 | N28: =COUNTIFS(Detalhe!$K:$K,N27,Detalhe!$W:$W,"PM") -> 0 | O28: =COUNTIFS(Detalhe!$K:$K,O27,Detalhe!$W:$W,"PM") -> 22 | P28: =COUNTIFS(Detalhe!$K:$K,P27,Detalhe!$W:$W,"PM") -> 3 | Q28: =COUNTIFS(Detalhe!$K:$K,Q27,Detalhe!$W:$W,"PM") -> 0 | ... T28: =COUNTIFS(Detalhe!$K:$K,T27,Detalhe!$W:$W,"PM") -> 157
I29: Status Inicial (pós OSI) | J29: =COUNTIFS(Detalhe!$E:$E,J27,Detalhe!$W:$W,"PM") -> 10 | K29: =COUNTIFS(Detalhe!$E:$E,K27,Detalhe!$W:$W,"PM") -> 18 | L29: =COUNTIFS(Detalhe!$E:$E,L27,Detalhe!$W:$W,"PM") -> 11 | M29: =COUNTIFS(Detalhe!$E:$E,M27,Detalhe!$W:$W,"PM") -> 4 | N29: =COUNTIFS(Detalhe!$E:$E,N27,Detalhe!$W:$W,"PM") -> 0 | O29: =COUNTIFS(Detalhe!$E:$E,O27,Detalhe!$W:$W,"PM") -> 11 | P29: =COUNTIFS(Detalhe!$E:$E,P27,Detalhe!$W:$W,"PM") -> 11 | Q29: =COUNTIFS(Detalhe!$E:$E,Q27,Detalhe!$W:$W,"PM") -> 0 | ... T29: =COUNTIFS(Detalhe!$E:$E,T27,Detalhe!$W:$W,"PM") -> 147
I30: Variação | J30: {=_xlfn.IFS(J28>J29, "↑",J28<J29, "↓",J28=J29, "=")} -> = | K30: {=_xlfn.IFS(K28>K29, "↑",K28<K29, "↓",K28=K29, "=")} -> ↓ | L30: {=_xlfn.IFS(L28>L29, "↑",L28<L29, "↓",L28=L29, "=")} -> ↓ | M30: {=_xlfn.IFS(M28>M29, "↑",M28<M29, "↓",M28=M29, "=")} -> ↓ | N30: {=_xlfn.IFS(N28>N29, "↑",N28<N29, "↓",N28=N29, "=")} -> = | O30: {=_xlfn.IFS(O28>O29, "↑",O28<O29, "↓",O28=O29, "=")} -> ↑ | P30: {=_xlfn.IFS(P28>P29, "↑",P28<P29, "↓",P28=P29, "=")} -> ↓ | Q30: {=_xlfn.IFS(Q28>Q29, "↑",Q28<Q29, "↓",Q28=Q29, "=")} -> = | ... T30: {=_xlfn.IFS(T28>T29, "↑",T28<T29, "↓",T28=T29, "=")} -> ↑
I31: Progressão | J31: =J28-J29 -> 0 | K31: =K28-K29 -> -1 | L31: =L28-L29 -> -9 | M31: =M28-M29 -> -3 | N31: =N28-N29 -> 0 | O31: =O28-O29 -> 11 | P31: =P28-P29 -> -8 | Q31: =Q28-Q29 -> 0 | ... T31: =T28-T29 -> 10
I35: Legenda
I37: 1. Especificar | J37: O campo será especificado pela primeira vez
I38: 2. Alterar especificação | J38: O campo já foi especificado, no entanto foi necessário alterar
I39: 3. Pendente de decisão | J39: Houve algum tema identificado em OSI nos campos e é necessário identificar casuísticas (podendo ficar como está ou ser alterado). Quem toma as decisões são as áreas de negócio, porém o Luis poderá dar a decisão final
I40: 4.1 Em implementação - Re-especificação | J40: O campo já foi re-especificado e está do lado de IT
I41: 4.2 Em implementação - Incidência | J41: O campo já foi re-especificado e entregue, no entanto veio com erros de implementação por parte de IT
I42: 5.1 Em testes - Re-especificação | J42: O campo foi re-especificado e implementado por IT e está em fase de testes
I43: 5.2 Em testes - Incidência | J43: O campo foi re-especificado e implementado por IT, porém foram encontradas incidências que levaram a uma nova fase de testes
I44: 6. Outros Desenvolvimentos | J44: Não podemos avançar no campo por haver necessidade de alguma alteração no campo fonte pendente da área responsável
I45: 7. Analisar controlos e completude | J45: Controlos corporativos NOK que necessitam de ser analizados
I46: 8. Concluído - sem dados | J46: Campos que não são para alterar
I47: 9. Concluído | J47: O campo já subiu a CD

Sheet Detalhe
C2: Quick-win de alta prioridade
C3: Quick-win de média prioridade
B5: TABLE_NAME | C5: COLUMN_NAME | D5: ÂMBITO | E5: Status | F5: Controlos e Completude | G5: Descrição | H5: Detalhe | I5: Quick-win | J5: Data alteração status | K5: Status Atual | L5: Controlos e Completuade atual | M5: Comentários | N5: Data envio para IT | O5: Data Implementação | P5: Categorização | Q5: Structural ECB Loan Tape | R5: Green Dashboard | S5: Pillar III ESG | T5: Green Finance | U5: ESG Risks | V5: Leveraged Finance | W5: Âmbito (Projeto) | X5: STREAM | Y5: ac
A6: =B6&"_"&C6 -> INSTRUMENT_ACCMLTD_CHNGS_FV_CR_INSTRMNT | B6: INSTRUMENT | C6: ACCMLTD_CHNGS_FV_CR_INSTRMNT | D6: OSI | E6: 9. Concluído | F6: OK | G6: Concluido, controlos OK | I6: Campo Fechado | J6: 45450 | K6: 9. Concluído | L6: =F6 -> OK | P6: Campo concluido | Q6: Y | R6: Y | S6: Y | T6: N | U6: N | V6: N | W6: PM | X6: 0
A7: =B7&"_"&C7 -> INSTRUMENT_ACCMLTD_IMPRMNT_INSTRMNT | B7: INSTRUMENT | C7: ACCMLTD_IMPRMNT_INSTRMNT | D7: OSI | E7: 9. Concluído | F7: OK | G7: Concluido, controlos OK | I7: Campo Fechado | J7: 45450 | K7: 9. Concluído | L7: =F7 -> OK | P7: Campo concluido | Q7: Y | R7: Y | S7: Y | T7: N | U7: N | V7: Y | W7: PM | X7: 6.1. Fora âmbito | Campos concluídos - Sem necessidade de espec.
A8: =B8&"_"&C8 -> INSTRUMENT_ACCMLTD_IMPRMNT_INSTRMNT_PRVS | B8: INSTRUMENT | C8: ACCMLTD_IMPRMNT_INSTRMNT_PRVS | D8: OSI | E8: 5.2 Em testes - Incidência | F8: OK | G8: Campo com incidência. Verificar fonte LT | I8: Sim | J8: 45450 | K8: 5.2 Em testes - Incidência | L8: =F8 -> OK | P8: Necessidade de correção de erros | Q8: Y | R8: N | S8: N | T8: N | U8: N | V8: Y | W8: LF | X8: 3. Campos em testes ou c/ incidências
A9: =B9&"_"&C9 -> INSTRUMENT_ACCMLTD_WRTFFS_INSTRMNT | B9: INSTRUMENT | C9: ACCMLTD_WRTFFS_INSTRMNT | D9: OSI | E9: 9. Concluído | F9: OK | G9: Concluido, controlos OK | I9: Campo Fechado | J9: 45450 | K9: 9. Concluído | L9: =F9 -> OK | P9: Campo concluido | Q9: Y | R9: N | S9: N | T9: N | U9: N | V9: Y | W9: PM | X9: 6.1. Fora âmbito | Campos concluídos - Sem necessidade de espec.
A10: =B10&"_"&C10 -> INSTRUMENT_ACCNTNG_CLSSFCTN | B10: INSTRUMENT | C10: ACCNTNG_CLSSFCTN | D10: OSI | E10: 9. Concluído | F10: OK | G10: Concluido, controlos OK | I10: Campo Fechado | J10: 45450 | K10: 9. Concluído | L10: =F10 -> OK | P10: Campo concluido | Q10: Y | R10: Y | S10: Y | T10: N | U10: N | V10: Y | W10: PM | X10: 6.1. Fora âmbito | Campos concluídos - Sem necessidade de espec.
A11: =B11&"_"&C11 -> ENTITY_ACCNTNG_FRMWRK_SL | B11: ENTITY | C11: ACCNTNG_FRMWRK_SL | D11: OSI | E11: 2. Alterar especificação | F11: OK | G11: Em especificação (Financial Statments CIB) | H11: Campo implementação, mas com falta de informação para o segmento de clientes CIB | I11: Não | J11: 45450 | K11: 2. Alterar especificação | L11: =F11 -> OK | P11: Melhorias estruturais (garantir coerência entre campos) | Q11: Y | R11: N | S11: N | T11: N | U11: N | V11: Y | W11: PM & LF | X11: 6.4. Fora âmbito | Re-especificação de campos complexos - Dem. Fin. CIB
A12: =B12&"_"&C12 -> INSTRUMENT_TYP_MRTGG | B12: INSTRUMENT | C12: TYP_MRTGG | D12: OSI | E12: 3. Pendente de decisão | F12: NOK | G12: Alteração da Code list por parte do BCE | I12: Sim | J12: 45568 | K12: 2. Alterar especificação | L12: =F12 -> NOK | M12: Alterar especificação de acordo com codelist atual. No MUG existem apenas garantias elegiveis para cálculo de capital? Se sim, TYP_MRTGG irá assumir os valores 1, 5 e N/A. Caso contrário assumirá os valores 1, 5, 6 e N/A. | P12: Alteração de especificação por parte do BCE | Q12: Y | R12: N | S12: N | T12: N | U12: N | V12: N | W12: PM | X12: 0
A13: =B13&"_"&C13 -> INSTRUMENT_AMNT_D_AT_MTRTY | B13: INSTRUMENT | C13: AMNT_D_AT_MTRTY | D13: OSI | E13: 1. Especificar | F13: NOK | G13: Em especificação | I13: Não | J13: 45450 | K13: 1. Especificar | L13: =F13 -> NOK | P13: Novo campo | Q13: Y | R13: N | S13: N | T13: N | U13: N | V13: Y | W13: LF | X13: 2.2 Re-especificação de campos complexos - Resto
A14: =B14&"_"&C14 -> ENTITY_ANNL_TRNVR_LE | B14: ENTITY | C14: ANNL_TRNVR_LE | D14: OSI | E14: 2. Alterar especificação | F14: OK | G14: Em especificação (Financial Statments CIB) | H14: Campo implementação, mas com falta de informação para o segmento de clientes CIB | I14: Não | J14: 45450 | K14: 2. Alterar especificação | L14: =F14 -> OK | P14: Melhorias estruturais (garantir coerência entre campos) | Q14: Y | R14: N | S14: Y | T14: N | U14: N | V14: Y | W14: PM & LF | X14: 6.4. Fora âmbito | Re-especificação de campos complexos - Dem. Fin. CIB
A15: =B15&"_"&C15 -> ENTITY_ANNL_TRNVR_LE_BDR | B15: ENTITY | C15: ANNL_TRNVR_LE_BDR | D15: Fora OSI | E15: 9. Concluído | F15: OK | G15: Concluido, controlos OK | I15: Campo Fechado | J15: 45450 | K15: 9. Concluído | L15: =F15 -> OK | P15: Campo concluido | Q15: Y | R15: N | S15: N | T15: N | U15: N | V15: N | W15: PM | X15: 0
A16: =B16&"_"&C16 -> ENTITY_ANNL_TRNVR_PRVS | B16: ENTITY | C16: ANNL_TRNVR_PRVS | D16: OSI | E16: 2. Alterar especificação | F16: OK | G16: Em especificação (Financial Statments CIB) | H16: Campo implementação, mas com falta de informação para o segmento de clientes CIB | I16: Não | J16: 45450 | K16: 2. Alterar especificação | L16: =F16 -> OK | P16: Melhorias estruturais (garantir coerência entre campos) | Q16: Y | R16: N | S16: N | T16: N | U16: N | V16: Y | W16: PM & LF | X16: 6.4. Fora âmbito | Re-especificação de campos complexos - Dem. Fin. CIB
A17: =B17&"_"&C17 -> ENTITY_ANNL_TRNVR_PRVS_BDR | B17: ENTITY | C17: ANNL_TRNVR_PRVS_BDR | D17: Fora OSI | E17: 9. Concluído | F17: OK | G17: Concluido, controlos OK | I17: Campo Fechado | J17: 45450 | K17: 9. Concluído | L17: =F17 -> OK | P17: Campo concluido | Q17: Y | R17: N | S17: N | T17: N | U17: N | V17: N | W17: PM | X17: 0
A18: =B18&"_"&C18 -> INSTRUMENT_ANNLSD_AGRD_RT | B18: INSTRUMENT | C18: ANNLSD_AGRD_RT | D18: OSI | E18: 3. Pendente de decisão | F18: OK | G18: Verificar necessidade de alteração da fonte para fins de reconciliação. Rever Fonte | H18: Rever se devemos utilizar a informação de IFRS9 ou manter a de alm | I18: Sim | J18: 45450 | K18: 3. Pendente de decisão | L18: =F18 -> OK | P18: Pendente de decisão | Q18: Y | R18: N | S18: Y | T18: N | U18: N | V18: N | W18: PM | X18: 0
A19: =B19&"_"&C19 -> PROTECTION_APPRSL_CRRNCY | B19: PROTECTION | C19: APPRSL_CRRNCY | D19: OSI | E19: 7. Analisar controlos e completude | F19: NOK | G19: Controlos NOK | I19: Não | J19: 45450 | K19: 7. Analisar controlos e completude | L19: =F19 -> NOK | P19: Analisar controlos NOK | Q19: Y | R19: N | S19: N | T19: N | U19: N | V19: N | W19: PM | X19: 0
A20: =B20&"_"&C20 -> PROTECTION_APPRSR | B20: PROTECTION | C20: APPRSR | D20: OSI | E20: 7. Analisar controlos e completude | F20: NOK | G20: Controlos NOK | I20: Não | J20: 45450 | K20: 7. Analisar controlos e completude | L20: =F20 -> NOK | P20: Analisar controlos NOK | Q20: Y | R20: N | S20: N | T20: N | U20: N | V20: N | W20: PM | X20: 0
A21: =B21&"_"&C21 -> INSTRUMENT_ARRRS_INSTRMNT | B21: INSTRUMENT | C21: ARRRS_INSTRMNT | D21: OSI | E21: 7. Analisar controlos e completude | F21: NOK | G21: Controlos NOK | I21: Não | J21: 45450 | K21: 7. Analisar controlos e completude | L21: =F21 -> NOK | P21: Analisar controlos NOK | Q21: Y | R21: N | S21: N | T21: N | U21: N | V21: Y | W21: LF | X21: 4. Campos com NOK controlos Corporativos
A22: =B22&"_"&C22 -> INSTRUMENT_ARRRS_INSTRMNT_12M | B22: INSTRUMENT | C22: ARRRS_INSTRMNT_12M | D22: OSI | E22: 7. Analisar controlos e completude | F22: NOK | G22: Controlos NOK | I22: Não | J22: 45450 | K22: 7. Analisar controlos e completude | L22: =F22 -> NOK | P22: Analisar controlos NOK | Q22: Y | R22: N | S22: N | T22: N | U22: N | V22: N | W22: PM | X22: 0
A23: =B23&"_"&C23 -> INSTRUMENT_ASST_SCRT_CLSS | B23: INSTRUMENT | C23: ASST_SCRT_CLSS | D23: Fora OSI | E23: 9. Concluído | F23: OK | G23: Concluido, controlos OK | I23: Campo Fechado | J23: 45450 | K23: 9. Concluído | L23: =F23 -> OK | P23: Campo concluido | Q23: Y | R23: N | S23: N | T23: N | U23: N | V23: N | W23: PM | X23: 0
A24: =B24&"_"&C24 -> INSTRUMENT_BRCHD_CVNNTS | B24: INSTRUMENT | C24: BRCHD_CVNNTS | D24: OSI | E24: 8. Concluído - sem dados | F24: OK | G24: Campo especificado, mas sem dados. Campo marcado com MISS ou NA | I24: Campo Fechado | J24: 45450 | K24: 8. Concluído - sem dados | L24: =F24 -> OK | P24: Campo concluído, mas sem ou pouca informação na fonte | Q24: Y | R24: N | S24: N | T24: N | U24: N | V24: Y | W24: PM | X24: 6.1. Fora âmbito | Campos concluídos - Sem necessidade de espec.
A25: =B25&"_"&C25 -> ENTITY_CAPEX | B25: ENTITY | C25: CAPEX | D25: OSI | E25: 2. Alterar especificação | F25: OK | G25: Em especificação (Financial Statments CIB) | H25: Campo implementação, mas com falta de informação para o segmento de clientes CIB | I25: Não | J25: 45450 | K25: 2. Alterar especificação | L25: =F25 -> OK | P25: Melhorias estruturais (garantir coerência entre campos) | Q25: Y | R25: N | S25: N | T25: N | U25: N | V25: N | W25: PM | X25: 0
A26: =B26&"_"&C26 -> ENTITY_CAPEX_PRVS | B26: ENTITY | C26: CAPEX_PRVS | D26: OSI | E26: 2. Alterar especificação | F26: OK | G26: Em especificação (Financial Statments CIB) | H26: Campo implementação, mas com falta de informação para o segmento de clientes CIB | I26: Não | J26: 45450 | K26: 2. Alterar especificação | L26: =F26 -> OK | P26: Melhorias estruturais (garantir coerência entre campos) | Q26: Y | R26: N | S26: N | T26: N | U26: N | V26: N | W26: PM | X26: 0
A27: =B27&"_"&C27 -> INSTRUMENT_CCF | B27: INSTRUMENT | C27: CCF | D27: OSI | E27: 9. Concluído | F27: OK | G27: Concluido, controlos OK | I27: Campo Fechado | J27: 45450 | K27: 9. Concluído | L27: =F27 -> OK | P27: Campo concluido | Q27: Y | R27: Y | S27: N | T27: N | U27: N | V27: Y | W27: PM | X27: 6.1. Fora âmbito | Campos concluídos - Sem necessidade de espec.
A28: =B28&"_"&C28 -> INSTRUMENT_CHNNL_ORGNTN | B28: INSTRUMENT | C28: CHNNL_ORGNTN | D28: Fora OSI | E28: 4.1 Em implementação - Re-especificação | F28: NOK | G28: Aguarda implementação de IT | I28: Não | J28: 45450 | K28: 4.1 Em implementação - Re-especificação | L28: =F28 -> NOK | N28: 45296 | P28: Melhorias estruturais (garantir coerência entre campos) | Q28: Y | R28: N | S28: N | T28: N | U28: N | V28: N | W28: PM | X28: 0
A29: =B29&"_"&C29 -> ENTITY_CLLCTN_MD | B29: ENTITY | C29: CLLCTN_MD | D29: Fora OSI | E29: 9. Concluído | F29: OK | G29: Concluido, controlos OK | I29: Campo Fechado | J29: 45450 | K29: 9. Concluído | L29: =F29 -> OK | P29: Campo concluido | Q29: Y | R29: N | S29: N | T29: N | U29: N | V29: N | W29: PM | X29: 0
A30: =B30&"_"&C30 -> ENTITY_TTL_INTRST_PD | B30: ENTITY | C30: TTL_INTRST_PD | D30: Fora OSI | E30: 2. Alterar especificação | F30: NOK | G30: Em especificação (Amortizações Capital/ Juros) | I30: Não | J30: 45450 | K30: 2. Alterar especificação | L30: =F30 -> NOK | P30: Melhorias estruturais (garantir coerência entre campos) | Q30: Y | R30: N | S30: N | T30: N | U30: N | V30: Y | W30: LF | X30: 2.2 Re-especificação de campos complexos - Resto
A31: =B31&"_"&C31 -> INSTRUMENT_CMMTMNT_INCPTN_INSTRMNT | B31: INSTRUMENT | C31: CMMTMNT_INCPTN_INSTRMNT | D31: OSI | E31: 7. Analisar controlos e completude | F31: NOK | G31: Analisar controlos e completude | I31: Não | J31: 45450 | K31: 7. Analisar controlos e completude | L31: =F31 -> NOK | P31: Analisar controlos NOK | Q31: Y | R31: N | S31: N | T31: N | U31: N | V31: N | W31: PM | X31: 0
A32: =B32&"_"&C32 -> PROTECTION_RL_ESTT_CLLTRL_LCTN | B32: PROTECTION | C32: RL_ESTT_CLLTRL_LCTN | D32: OSI | E32: 2. Alterar especificação | F32: NOK | G32: Alterados 3 casos. Campo está a devolver PT para todas as proteções, no entanto estas não estão localizadas em PT e alterou-se a localização para os respetivos paises. | I32: Não | J32: 45450 | K32: 2. Alterar especificação | L32: =F32 -> NOK | P32: Melhorias estruturais (garantir coerência entre campos) | Q32: Y | R32: N | S32: Y | T32: N | U32: Y | V32: N | W32: PM | X32: 0
A33: =B33&"_"&C33 -> INSTRUMENT_CMPLNT_MRTR_C19_NM | B33: INSTRUMENT | C33: CMPLNT_MRTR_C19_NM | D33: Fora OSI | E33: 9. Concluído | F33: OK | G33: Concluido, controlos OK | I33: Campo Fechado | J33: 45450 | K33: 9. Concluído | L33: =F33 -> OK | P33: Campo concluido | Q33: Y | R33: N | S33: N | T33: N | U33: N | V33: N | W33: PM | X33: 0
A34: =B34&"_"&C34 -> INSTRUMENT_CNSMPTN_FNRP18 | B34: INSTRUMENT | C34: CNSMPTN_FNRP18 | D34: Fora OSI | E34: 9. Concluído | F34: OK | G34: Concluido, controlos OK | I34: Campo Fechado | J34: 45450 | K34: 9. Concluído | L34: =F34 -> OK | P34: Campo concluido | Q34: Y | R34: N | S34: N | T34: N | U34: N | V34: N | W34: PM | X34: 0
A35: =B35&"_"&C35 -> PROTECTION_DT_APPRSL_PRVS | B35: PROTECTION | C35: DT_APPRSL_PRVS | D35: OSI | E35: 5.2 Em testes - Incidência | F35: NOK | G35: Campo com incidência e controlos NOK | H35: 1) Campo com incidência, data igual à data da protection_vl 2) Alteração de formatos MISS | I35: Campo Fechado | J35: 45670 | K35: 9. Concluído | L35: OK | M35: Alteraração da definição do campo no Guia da Corporação. Campo passou a reportar a data da avaliação completa anterior à data da última avaliação completa. | N35: 45485 | O35: 45646 | P35: Alteração de especificação por parte do BCE | Q35: Y | R35: N | S35: N | T35: N | U35: N | V35: N | W35: PM | X35: 0
A36: =B36&"_"&C36 -> INSTRUMENT_CNTRCT_ID | B36: INSTRUMENT | C36: CNTRCT_ID | D36: OSI | E36: 9. Concluído | F36: OK | G36: Concluido, controlos OK | I36: Campo Fechado | J36: 45450 | K36: 9. Concluído | L36: =F36 -> OK | P36: Campo concluido | Q36: Y | R36: N | S36: N | T36: N | U36: N | V36: N | W36: PM | X36: 0
A37: =B37&"_"&C37 -> INSTRUMENT_CNTRCT_ID_BDR | B37: INSTRUMENT | C37: CNTRCT_ID_BDR | D37: Fora OSI | E37: 9. Concluído | F37: OK | G37: Concluido, controlos OK | I37: Campo Fechado | J37: 45450 | K37: 9. Concluído | L37: =F37 -> OK | P37: Campo concluido | Q37: Y | R37: N | S37: N | T37: N | U37: N | V37: N | W37: PM | X37: 0
A38: =B38&"_"&C38 -> ENTITY_CNTRY | B38: ENTITY | C38: CNTRY | D38: OSI | E38: 9. Concluído | F38: OK | G38: Concluido, controlos OK | I38: Campo Fechado | J38: 45450 | K38: 9. Concluído | L38: =F38 -> OK | P38: Campo concluido | Q38: Y | R38: N | S38: Y | T38: N | U38: Y | V38: Y | W38: PM | X38: 6.1. Fora âmbito | Campos concluídos - Sem necessidade de espec.
A39: =B39&"_"&C39 -> ENTITY_COD_SOC | B39: ENTITY | C39: COD_SOC | D39: OSI | E39: 9. Concluído | F39: OK | G39: Concluido, controlos OK | I39: Campo Fechado | J39: 45450 | K39: 9. Concluído | L39: =F39 -> OK | P39: Campo concluido | Q39: Y | R39: N | S39: Y | T39: N | U39: Y | V39: Y | W39: PM | X39: 6.1. Fora âmbito | Campos concluídos - Sem necessidade de espec.
A40: =B40&"_"&C40 -> INSTR_ENTITY_COD_SOC | B40: INSTR_ENTITY | C40: COD_SOC | D40: OSI | E40: 9. Concluído | F40: OK | G40: Concluido, controlos OK | I40: Campo Fechado | J40: 45450 | K40: 9. Concluído | L40: =F40 -> OK | P40: Campo concluido | Q40: Y | R40: N | S40: Y | T40: N | U40: N | V40: Y | W40: PM | X40: 6.1. Fora âmbito | Campos concluídos - Sem necessidade de espec.
A41: =B41&"_"&C41 -> INSTR_PROTECTION_COD_SOC | B41: INSTR_PROTECTION | C41: COD_SOC | D41: OSI | E41: 9. Concluído | F41: OK | G41: Concluido, controlos OK | I41: Campo Fechado | J41: 45450 | K41: 9. Concluído | L41: =F41 -> OK | P41: Campo concluido | Q41: Y | R41: Y | S41: Y | T41: N | U41: N | V41: N | W41: PM | X41: 0
A42: =B42&"_"&C42 -> INSTRUMENT_COD_SOC | B42: INSTRUMENT | C42: COD_SOC | D42: OSI | E42: 9. Concluído | F42: OK | G42: Concluido, controlos OK | I42: Campo Fechado | J42: 45450 | K42: 9. Concluído | L42: =F42 -> OK | P42: Campo concluido | Q42: Y | R42: Y | S42: Y | T42: N | U42: Y | V42: Y | W42: PM | X42: 6.1. Fora âmbito | Campos concluídos - Sem necessidade de espec.
...

Sheet Caderno Testes
A1: Tabela | B1: Campo | C1: Tipo de teste | D1: Descritivo | E1: Data atualização | F1: Data de referência | G1: Status | H1: Duvidas/comentários | I1: Query
A2: INSTRMNT | B2: RWA_MTHD | C2: Completude | D2: Validar se o número de MISS e N/A | E2: 45460 | F2: 45443 | G2: OK | I2: SELECT rwa_mthd, a.NUM_REGISTOS, a.NUM_REGISTOS/b.NUM_REGISTOS*100 as Perc from (SELECT rwa_mthd , COUNT(*) AS NUM_REGISTOS FROM cd_loan_tapes_bce.LT002_INSTRUMENT WHERE REF_DATE='${date}' AND NOME_PERIMETRO='Individual Corporativo' AND AMBITO = 'PM' AND SEGMENTO = 'ESTR' GROUP BY 1 ) a join ( SELECT COUNT(*) AS NUM_REGISTOS FROM cd_loan_tapes_bce.LT002_INSTRUMENT WHERE REF_DATE='${date}' AND NOME_PERIMETRO='Individual Corporativo' AND AMBITO = 'PM' AND SEGMENTO = 'ESTR' ) b where rwa_mthd in ('99999999999', '11111111111')
A3: INSTRMNT | B3: RWA_MTHD | C3: Desenvolvimento | D3: Validar alteração de formato de 11111111.00 para 11111111 | E3: 45460 | F3: 45443 | G3: OK | I3: SELECT count(*), rwa_mthd FROM cd_loan_tapes_bce.lt002_instrument WHERE 1=1 AND REF_DATE='${date}' AND NOME_PERIMETRO='Individual Corporativo' AND AMBITO = 'PM' AND SEGMENTO = 'ESTR' GROUP BY 2 ORDER BY 1
A4: INSTRMNT | B4: RWA_MTHD | C4: Desenvolvimento | D4: Validar condição de N/A sempre que não existe de consumo de capital | E4: 45460 | F4: 45443 | G4: OK | I4: SELECT DISTINCT EAD, RWA, rwa_mthd, VAL FROM (SELECT DISTINCT INSTRMNT_ID, EAD, RWA, rwa_mthd FROM cd_loan_tapes_bce.LT002_INSTRUMENT WHERE REF_DATE='${date}' AND NOME_PERIMETRO='Individual Corporativo' AND AMBITO = 'PM') LT002 LEFT JOIN (SELECT CHAVE_FR, SUM(flag_cons_cap) AS VAL FROM (SELECT CHAVE_FR, S1EMP, CONTRA1 FROM (SELECT DISTINCT CONCAT(CEMPRESA, CBALCAO,CNUMECTA, ZDEPOSIT) AS CHAVE_MASTER, CONCAT(CEMPRESA_FR, CBALCAO_FR,CNUMECTA_FR, ZDEPOSIT_FR) AS CHAVE_FR FROM cd_captools.KT_CHAVES_FINREP WHERE REF_DATE='${date}') KT_FR INNER JOIN (SELECT DISTINCT CONCAT(CEMPRESA, CBALCAO,CNUMECTA, ZDEPOSIT) AS CHAVE_MASTER, S1EMP, CONTRA1 FROM cd_captools.KT_CHAVES_BDR WHERE REF_DATE='${date}') KT_BDR ON KT_FR.CHAVE_MASTER=KT_BDR.CHAVE_MASTER ) KT LEFT JOIN (SELECT CT013.* FROM (SELECT DISTINCT REF_DATE, id_capital_perimetros, s1emp, contra1, flag_cons_cap FROM cd_captools.ct013_rwa_princ WHERE REF_DATE = '${date}' -- AND flag_cons_cap = 1 AND flag_conc_contab = 1 AND exercicio = "REAL" -- 30-03-2021: Adição de filtro AND subtipo_risco in ('1.1', '1.2', '1.3', '1.4', '1.5', '1.6', '1.7', '1.8', '1.9', '1.13')) CT013 INNER JOIN (SELECT DISTINCT ID_CAPITAL_PERIMETROS, REF_DATE FROM cd_captools.ct020_rwa_per WHERE REF_DATE = '${date}' AND NOME_PERIMETRO='Individual Corporativo') CT020 on CT013.ID_CAPITAL_PERIMETROS=CT020.ID_CAPITAL_PERIMETROS) CAP ON CAP.S1EMP=KT.S1EMP AND CAP.CONTRA1=KT.CONTRA1 GROUP BY 1 ) BASE ON INSTRMNT_ID=CHAVE_FR WHERE VAL=0
A5: INSTRMNT | B5: RWA_MTHD | C5: Controlos | D5: If "RWA" is populated other than default values, then "RWA calculation method" cannot be 'Not applicable' | E5: 45460 | F5: 45443 | G5: OK | I5: SELECT instrmnt_id, ead, rwa, rwa_mthd FROM cd_loan_tapes_bce.lt002_instrument WHERE 1=1 AND REF_DATE='${date}' AND NOME_PERIMETRO='Individual Corporativo' AND AMBITO = 'PM' AND SEGMENTO = 'ESTR' AND rwa NOT IN (99999999999.00, 11111111111.00) and rwa_mthd = 11111111111
A6: INSTRMNT | B6: RWA_MTHD | C6: Controlos | D6: If "RWA" is populated with 'Not applicable', then "RWA calculation method" must be a default value | E6: 45460 | F6: 45443 | G6: OK | I6: SELECT instrmnt_id, ead, rwa, rwa_mthd FROM cd_loan_tapes_bce.lt002_instrument WHERE 1=1 AND REF_DATE='${date}' AND NOME_PERIMETRO='Individual Corporativo' AND AMBITO = 'PM' AND SEGMENTO = 'ESTR' AND rwa = 11111111111.00 and rwa_mthd <> 11111111111
A7: INSTRMNT | B7: RWA_MTHD | C7: Controlos | D7: Validar se o campo está de acordo com a Codelist | E7: 45460 | F7: 45443 | G7: OK | I7: SELECT count(*), rwa_mthd FROM cd_loan_tapes_bce.lt002_instrument WHERE 1=1 AND REF_DATE='${date}' AND NOME_PERIMETRO='Individual Corporativo' AND AMBITO = 'PM' AND SEGMENTO = 'ESTR' GROUP BY 2 ORDER BY 1
A8: INSTRMNT | B8: RWA | C8: Completude | D8: Validar se o número de MISS e N/A | E8: 45460 | F8: 45443 | G8: OK | I8: SELECT rwa, a.NUM_REGISTOS, a.NUM_REGISTOS/b.NUM_REGISTOS*100 as Perc from (SELECT rwa , COUNT(*) AS NUM_REGISTOS FROM cd_loan_tapes_bce.LT002_INSTRUMENT WHERE REF_DATE='${date}' AND NOME_PERIMETRO='Individual Corporativo' AND AMBITO = 'PM' AND SEGMENTO = 'ESTR' GROUP BY 1 ) a join ( SELECT COUNT(*) AS NUM_REGISTOS FROM cd_loan_tapes_bce.LT002_INSTRUMENT WHERE REF_DATE='${date}' AND NOME_PERIMETRO='Individual Corporativo' AND AMBITO = 'PM' AND SEGMENTO = 'ESTR' ) b where rwa in (99999999999, 11111111111)
A9: INSTRMNT | B9: RWA | C9: Desenvolvimento | D9: Validar condição de N/A sempre que não existe de consumo de capital | E9: 45460 | F9: 45443 | G9: OK | I9: SELECT DISTINCT EAD, RWA, rwa_mthd, VAL FROM (SELECT DISTINCT INSTRMNT_ID, EAD, RWA, rwa_mthd FROM cd_loan_tapes_bce.LT002_INSTRUMENT WHERE REF_DATE='${date}' AND NOME_PERIMETRO='Individual Corporativo' AND AMBITO = 'PM') LT002 LEFT JOIN (SELECT CHAVE_FR, SUM(flag_cons_cap) AS VAL FROM (SELECT CHAVE_FR, S1EMP, CONTRA1 FROM (SELECT DISTINCT CONCAT(CEMPRESA, CBALCAO,CNUMECTA, ZDEPOSIT) AS CHAVE_MASTER, CONCAT(CEMPRESA_FR, CBALCAO_FR,CNUMECTA_FR, ZDEPOSIT_FR) AS CHAVE_FR FROM cd_captools.KT_CHAVES_FINREP WHERE REF_DATE='${date}') KT_FR INNER JOIN (SELECT DISTINCT CONCAT(CEMPRESA, CBALCAO,CNUMECTA, ZDEPOSIT) AS CHAVE_MASTER, S1EMP, CONTRA1 FROM cd_captools.KT_CHAVES_BDR WHERE REF_DATE='${date}') KT_BDR ON KT_FR.CHAVE_MASTER=KT_BDR.CHAVE_MASTER ) KT LEFT JOIN (SELECT CT013.* FROM (SELECT DISTINCT REF_DATE, id_capital_perimetros, s1emp, contra1, flag_cons_cap FROM cd_captools.ct013_rwa_princ WHERE REF_DATE = '${date}' -- AND flag_cons_cap = 1 AND flag_conc_contab = 1 AND exercicio = "REAL" -- 30-03-2021: Adição de filtro AND subtipo_risco in ('1.1', '1.2', '1.3', '1.4', '1.5', '1.6', '1.7', '1.8', '1.9', '1.13')) CT013 INNER JOIN (SELECT DISTINCT ID_CAPITAL_PERIMETROS, REF_DATE FROM cd_captools.ct020_rwa_per WHERE REF_DATE = '${date}' AND NOME_PERIMETRO='Individual Corporativo') CT020 on CT013.ID_CAPITAL_PERIMETROS=CT020.ID_CAPITAL_PERIMETROS) CAP ON CAP.S1EMP=KT.S1EMP AND CAP.CONTRA1=KT.CONTRA1 GROUP BY 1 ) BASE ON INSTRMNT_ID=CHAVE_FR WHERE VAL=0
A10: INSTRMNT | B10: RWA | C10: Controlos | D10: Validar formatos | E10: 45460 | F10: 45443 | G10: OK | I10: SELECT count(*), rwa FROM cd_loan_tapes_bce.lt002_instrument WHERE 1=1 AND REF_DATE='${date}' AND NOME_PERIMETRO='Individual Corporativo' AND AMBITO = 'PM' AND SEGMENTO = 'ESTR' GROUP BY 2 ORDER BY 1
A11: INSTRMNT | B11: RWA | C11: Controlos | D11: Validar se não existem valores negativos | E11: 45460 | F11: 45443 | G11: NOK | H11: 1 Contrato com valores negativos | I11: SELECT DISTINCT INSTRMNT_ID, EAD, RWA, rwa_mthd, VAL FROM (SELECT DISTINCT INSTRMNT_ID, EAD, RWA, rwa_mthd FROM cd_loan_tapes_bce.LT002_INSTRUMENT WHERE REF_DATE='${date}' AND NOME_PERIMETRO='Individual Corporativo' AND AMBITO = 'PM' -- AND instrmnt_id = '31000314294093096000000000000000' ) LT002 LEFT JOIN (SELECT CHAVE_FR, SUM(flag_cons_cap) AS VAL FROM (SELECT CHAVE_FR, S1EMP, CONTRA1 FROM (SELECT DISTINCT CONCAT(CEMPRESA, CBALCAO,CNUMECTA, ZDEPOSIT) AS CHAVE_MASTER, CONCAT(CEMPRESA_FR, CBALCAO_FR,CNUMECTA_FR, ZDEPOSIT_FR) AS CHAVE_FR FROM cd_captools.KT_CHAVES_FINREP WHERE REF_DATE='${date}') KT_FR INNER JOIN (SELECT DISTINCT CONCAT(CEMPRESA, CBALCAO,CNUMECTA, ZDEPOSIT) AS CHAVE_MASTER, S1EMP, CONTRA1 FROM cd_captools.KT_CHAVES_BDR WHERE REF_DATE='${date}') KT_BDR ON KT_FR.CHAVE_MASTER=KT_BDR.CHAVE_MASTER ) KT LEFT JOIN (SELECT CT013.* FROM (SELECT DISTINCT REF_DATE, id_capital_perimetros, s1emp, contra1, flag_cons_cap FROM cd_captools.ct013_rwa_princ WHERE REF_DATE = '${date}' -- AND flag_cons_cap = 1 AND flag_conc_contab = 1 AND exercicio = "REAL" -- 30-03-2021: Adição de filtro AND subtipo_risco in ('1.1', '1.2', '1.3', '1.4', '1.5', '1.6', '1.7', '1.8', '1.9', '1.13')) CT013 INNER JOIN (SELECT DISTINCT ID_CAPITAL_PERIMETROS, REF_DATE FROM cd_captools.ct020_rwa_per WHERE REF_DATE = '${date}' AND NOME_PERIMETRO='Individual Corporativo') CT020 on CT013.ID_CAPITAL_PERIMETROS=CT020.ID_CAPITAL_PERIMETROS) CAP ON CAP.S1EMP=KT.S1EMP AND CAP.CONTRA1=KT.CONTRA1 GROUP BY 1 ) BASE ON INSTRMNT_ID=CHAVE_FR WHERE RWA < 0
A12: INSTRMNT | B12: RWA | C12: Controlos | D12: Teste contra a fonte | E12: 45462 | F12: 45443 | G12: OK | H12: A fonte (CT013) tem um valor muito superior, porque existem várias chaves FR para uma chave BDR | I12: SELECT DISTINCT INSTRMNT_ID, S1EMP, CONTRA1, EAD, RWA, rwa_final, ead_final_bruta FROM (SELECT DISTINCT INSTRMNT_ID, CCF, dflt_stts_instrmnt, DPD, EAD, LGD, pd_crr_incptn, pd_crr_rd, pd_crr_rd_t1, RWA, rwa_mthd, spcltv_lndng, crrltn_cffcnt FROM cd_loan_tapes_bce.LT002_INSTRUMENT WHERE REF_DATE='${date}' AND NOME_PERIMETRO='Individual Corporativo' AND AMBITO = 'PM' -- AND instrmnt_id = '31000347000690020000000000000000' ) LT002 INNER JOIN (SELECT CHAVE_FR, KT.S1EMP, KT.CONTRA1, SUM(flag_cons_cap) AS VAL, SUM(RWA_FINAL) AS RWA_FINAL, SUM(ead_final_bruta) AS ead_final_bruta FROM (SELECT CHAVE_FR, S1EMP, CONTRA1 FROM (SELECT DISTINCT CONCAT(CEMPRESA, CBALCAO,CNUMECTA, ZDEPOSIT) AS CHAVE_MASTER, CONCAT(CEMPRESA_FR, CBALCAO_FR,CNUMECTA_FR, ZDEPOSIT_FR) AS CHAVE_FR FROM cd_captools.KT_CHAVES_FINREP WHERE REF_DATE='${date}') KT_FR INNER JOIN (SELECT DISTINCT CONCAT(CEMPRESA, CBALCAO,CNUMECTA, ZDEPOSIT) AS CHAVE_MASTER, S1EMP, CONTRA1 FROM cd_captools.KT_CHAVES_BDR WHERE REF_DATE='${date}') KT_BDR ON KT_FR.CHAVE_MASTER=KT_BDR.CHAVE_MASTER WHERE CHAVE_FR = '31005122428280011667450200000001' OR concat(S1EMP,CONTRA1) = '1814008684' ) KT INNER JOIN (SELECT CT013.* FROM (SELECT REF_DATE, id_capital_perimetros, s1emp, contra1, flag_cons_cap, rwa_final, ead_final_bruta FROM cd_captools.ct013_rwa_princ WHERE REF_DATE = '${date}' -- AND flag_cons_cap = 1 AND flag_conc_contab = 1 AND exercicio = "REAL" -- 30-03-2021: Adição de filtro AND subtipo_risco in ('1.1', '1.2', '1.3', '1.4', '1.5', '1.6', '1.7', '1.8', '1.9', '1.13')) CT013 INNER JOIN (SELECT DISTINCT ID_CAPITAL_PERIMETROS, REF_DATE FROM cd_captools.ct020_rwa_per WHERE REF_DATE = '${date}' AND NOME_PERIMETRO='Individual Corporativo') CT020 on CT013.ID_CAPITAL_PERIMETROS=CT020.ID_CAPITAL_PERIMETROS) CAP ON CAP.S1EMP=KT.S1EMP AND CAP.CONTRA1=KT.CONTRA1 GROUP BY 1,2,3 ) X on CHAVE_FR = INSTRMNT_ID
A13: INSTRMNT | B13: RWA | C13: Controlos | D13: Verificar saldo de capital | E13: 45462 | F13: 45443 | G13: OK | I13: SELECT LT002.instrmnt_id, RWA, EAD, CONCAT(LT001.cempresa,LT001.cbalcao,LT001.cnumecta,LT001.zdeposit) AS CHAVE_FR, NVL(SUM(LT001.msaldo_final),0) AS Saldo_Capital FROM (SELECT cempresa, cbalcao, cnumecta, zdeposit, ccontab_final_cargabal, msaldo_final FROM cd_loan_tapes_bce.lt001_univ_oper WHERE REF_DATE = '${date}' AND NOME_PERIMETRO='Individual Corporativo' AND AMBITO = 'PM' ) LT001 INNER JOIN (SELECT * FROM cd_loan_tapes_bce.kt_chaves_lt WHERE REF_DATE = '${date}' AND NOME_PERIMETRO='Individual Corporativo' AND AMBITO = 'PM' AND segmento = 'ESTR') KT_LT ON CONCAT(LT001.cempresa,LT001.cbalcao,LT001.cnumecta,LT001.zdeposit) = CONCAT(KT_LT.cempresa,KT_LT.cbalcao,KT_LT.cnumecta,KT_LT.zdeposit) INNER JOIN (SELECT instrmnt_id, rwa, ead FROM cd_loan_tapes_bce.lt002_instrument WHERE REF_DATE = '${date}' AND NOME_PERIMETRO='Individual Corporativo' AND AMBITO = 'PM' AND segmento ='ESTR' AND instrmnt_id in ( '310051224282800116674502P0080001', '310051224282800116674502P0070001', '310051224282800116674502P0060001', '31005122428280011667450200000001', '310051224282800116674502P0100001', '310051224282800116674502P0110001', '310051224282800116674502P0020001', '310051224282800116674502P0010001', '310051224282800116674502P0030001', '310051224282800116674502P0090001' ) ) LT002 ON KT_LT.INSTRMNT_ID = LT002.INSTRMNT_ID LEFT JOIN (SELECT * FROM cd_captools.fr802_pl_contas WHERE 1=1 AND REF_DATE = '${date}' AND cod_plano = 'CARGABAL' AND ((tipo_conta IN ('A','P') AND carteira_contabilistica not in('provisoes para compromissos e garantias concedidas', 'outras provisoes') AND composicao_valor <> 'imparidade acumulada' AND bruto_imparidade <> 'imparidade') OR (tipo_conta IN ('EA','EP','M'))) ) FR802 ON FR802.CONTA = LT001.ccontab_final_cargabal LEFT JOIN (SELECT * FROM cd_captools.ct805_matriz_cnt WHERE 1=1 AND REF_DATE = '${date}' AND DOMINIO = 'Capital' AND NOME_PERIMETRO = 'Individual Corporativo' ) CT805 ON FR802.CONTA = CT805.CONTA GROUP BY 1,2,3,4
A14: INSTRMNT | B14: EAD | C14: Completude | D14: Validar se o número de MISS e N/A | E14: 45460 | F14: 45443 | G14: OK | I14: SELECT ead, a.NUM_REGISTOS, a.NUM_REGISTOS/b.NUM_REGISTOS*100 as Perc from (SELECT ead , COUNT(*) AS NUM_REGISTOS FROM cd_loan_tapes_bce.LT002_INSTRUMENT WHERE REF_DATE='${date}' AND NOME_PERIMETRO='Individual Corporativo' AND AMBITO = 'PM' AND SEGMENTO = 'ESTR' GROUP BY 1 ) a join ( SELECT COUNT(*) AS NUM_REGISTOS FROM cd_loan_tapes_bce.LT002_INSTRUMENT WHERE REF_DATE='${date}' AND NOME_PERIMETRO='Individual Corporativo' AND AMBITO = 'PM' AND SEGMENTO = 'ESTR' ) b where ead in (99999999999, 11111111111)
A15: INSTRMNT | B15: EAD | C15: Desenvolvimento | D15: Validar condição de N/A sempre que não existe de consumo de capital | E15: 45460 | F15: 45443 | G15: OK | I15: SELECT DISTINCT EAD, RWA, rwa_mthd, VAL FROM (SELECT DISTINCT INSTRMNT_ID, EAD, RWA, rwa_mthd FROM cd_loan_tapes_bce.LT002_INSTRUMENT WHERE REF_DATE='${date}' AND NOME_PERIMETRO='Individual Corporativo' AND AMBITO = 'PM') LT002 LEFT JOIN (SELECT CHAVE_FR, SUM(flag_cons_cap) AS VAL FROM (SELECT CHAVE_FR, S1EMP, CONTRA1 FROM (SELECT DISTINCT CONCAT(CEMPRESA, CBALCAO,CNUMECTA, ZDEPOSIT) AS CHAVE_MASTER, CONCAT(CEMPRESA_FR, CBALCAO_FR,CNUMECTA_FR, ZDEPOSIT_FR) AS CHAVE_FR FROM cd_captools.KT_CHAVES_FINREP WHERE REF_DATE='${date}') KT_FR INNER JOIN (SELECT DISTINCT CONCAT(CEMPRESA, CBALCAO,CNUMECTA, ZDEPOSIT) AS CHAVE_MASTER, S1EMP, CONTRA1 FROM cd_captools.KT_CHAVES_BDR WHERE REF_DATE='${date}') KT_BDR ON KT_FR.CHAVE_MASTER=KT_BDR.CHAVE_MASTER ) KT LEFT JOIN (SELECT CT013.* FROM (SELECT DISTINCT REF_DATE, id_capital_perimetros, s1emp, contra1, flag_cons_cap FROM cd_captools.ct013_rwa_princ WHERE REF_DATE = '${date}' -- AND flag_cons_cap = 1 AND flag_conc_contab = 1 AND exercicio = "REAL" -- 30-03-2021: Adição de filtro AND subtipo_risco in ('1.1', '1.2', '1.3', '1.4', '1.5', '1.6', '1.7', '1.8', '1.9', '1.13')) CT013 INNER JOIN (SELECT DISTINCT ID_CAPITAL_PERIMETROS, REF_DATE FROM cd_captools.ct020_rwa_per WHERE REF_DATE = '${date}' AND NOME_PERIMETRO='Individual Corporativo') CT020 on CT013.ID_CAPITAL_PERIMETROS=CT020.ID_CAPITAL_PERIMETROS) CAP ON CAP.S1EMP=KT.S1EMP AND CAP.CONTRA1=KT.CONTRA1 GROUP BY 1 ) BASE ON INSTRMNT_ID=CHAVE_FR WHERE VAL=0
A16: INSTRMNT | B16: EAD | C16: Controlos | D16: Validar formatos | E16: 45460 | F16: 45443 | G16: OK | I16: SELECT count(*), rwa FROM cd_loan_tapes_bce.lt002_instrument WHERE 1=1 AND REF_DATE='${date}' AND NOME_PERIMETRO='Individual Corporativo' AND AMBITO = 'PM' AND SEGMENTO = 'ESTR' GROUP BY 2 ORDER BY 1
A17: INSTRMNT | B17: EAD | C17: Controlos | D17: Validar se não existem valores negativos | E17: 45460 | F17: 45443 | G17: NOK | H17: 1 Contrato com valores negativos | I17: SELECT DISTINCT INSTRMNT_ID, EAD, RWA, rwa_mthd, VAL FROM (SELECT DISTINCT INSTRMNT_ID, EAD, RWA, rwa_mthd FROM cd_loan_tapes_bce.LT002_INSTRUMENT WHERE REF_DATE='${date}' AND NOME_PERIMETRO='Individual Corporativo' AND AMBITO = 'PM' -- AND instrmnt_id = '31000314294093096000000000000000' ) LT002 LEFT JOIN (SELECT CHAVE_FR, SUM(flag_cons_cap) AS VAL FROM (SELECT CHAVE_FR, S1EMP, CONTRA1 FROM (SELECT DISTINCT CONCAT(CEMPRESA, CBALCAO,CNUMECTA, ZDEPOSIT) AS CHAVE_MASTER, CONCAT(CEMPRESA_FR, CBALCAO_FR,CNUMECTA_FR, ZDEPOSIT_FR) AS CHAVE_FR FROM cd_captools.KT_CHAVES_FINREP WHERE REF_DATE='${date}') KT_FR INNER JOIN (SELECT DISTINCT CONCAT(CEMPRESA, CBALCAO,CNUMECTA, ZDEPOSIT) AS CHAVE_MASTER, S1EMP, CONTRA1 FROM cd_captools.KT_CHAVES_BDR WHERE REF_DATE='${date}') KT_BDR ON KT_FR.CHAVE_MASTER=KT_BDR.CHAVE_MASTER ) KT LEFT JOIN (SELECT CT013.* FROM (SELECT DISTINCT REF_DATE, id_capital_perimetros, s1emp, contra1, flag_cons_cap FROM cd_captools.ct013_rwa_princ WHERE REF_DATE = '${date}' -- AND flag_cons_cap = 1 AND flag_conc_contab = 1 AND exercicio = "REAL" -- 30-03-2021: Adição de filtro AND subtipo_risco in ('1.1', '1.2', '1.3', '1.4', '1.5', '1.6', '1.7', '1.8', '1.9', '1.13')) CT013 INNER JOIN (SELECT DISTINCT ID_CAPITAL_PERIMETROS, REF_DATE FROM cd_captools.ct020_rwa_per WHERE REF_DATE = '${date}' AND NOME_PERIMETRO='Individual Corporativo') CT020 on CT013.ID_CAPITAL_PERIMETROS=CT020.ID_CAPITAL_PERIMETROS) CAP ON CAP.S1EMP=KT.S1EMP AND CAP.CONTRA1=KT.CONTRA1 GROUP BY 1 ) BASE ON INSTRMNT_ID=CHAVE_FR WHERE EAD < 0
A18: INSTRMNT | B18: EAD | C18: Controlos | D18: Teste contra a fonte | E18: 45462 | F18: 45443 | G18: OK | H18: A fonte (CT013) tem um valor muito superior, porque existem várias chaves FR para uma chave BDR | I18: SELECT DISTINCT INSTRMNT_ID, S1EMP, CONTRA1, EAD, RWA, rwa_final, ead_final_bruta FROM (SELECT DISTINCT INSTRMNT_ID, CCF, dflt_stts_instrmnt, DPD, EAD, LGD, pd_crr_incptn, pd_crr_rd, pd_crr_rd_t1, RWA, rwa_mthd, spcltv_lndng, crrltn_cffcnt FROM cd_loan_tapes_bce.LT002_INSTRUMENT WHERE REF_DATE='${date}' AND NOME_PERIMETRO='Individual Corporativo' AND AMBITO = 'PM' -- AND instrmnt_id = '31000347000690020000000000000000' ) LT002 INNER JOIN (SELECT CHAVE_FR, KT.S1EMP, KT.CONTRA1, SUM(flag_cons_cap) AS VAL, SUM(RWA_FINAL) AS RWA_FINAL, SUM(ead_final_bruta) AS ead_final_bruta FROM (SELECT CHAVE_FR, S1EMP, CONTRA1 FROM (SELECT DISTINCT CONCAT(CEMPRESA, CBALCAO,CNUMECTA, ZDEPOSIT) AS CHAVE_MASTER, CONCAT(CEMPRESA_FR, CBALCAO_FR,CNUMECTA_FR, ZDEPOSIT_FR) AS CHAVE_FR FROM cd_captools.KT_CHAVES_FINREP WHERE REF_DATE='${date}') KT_FR INNER JOIN (SELECT DISTINCT CONCAT(CEMPRESA, CBALCAO,CNUMECTA, ZDEPOSIT) AS CHAVE_MASTER, S1EMP, CONTRA1 FROM cd_captools.KT_CHAVES_BDR WHERE REF_DATE='${date}') KT_BDR ON KT_FR.CHAVE_MASTER=KT_BDR.CHAVE_MASTER WHERE CHAVE_FR = '31005122428280011667450200000001' OR concat(S1EMP,CONTRA1) = '1814008684' ) KT INNER JOIN (SELECT CT013.* FROM (SELECT REF_DATE, id_capital_perimetros, s1emp, contra1, flag_cons_cap, rwa_final, ead_final_bruta FROM cd_captools.ct013_rwa_princ WHERE REF_DATE = '${date}' -- AND flag_cons_cap = 1 AND flag_conc_contab = 1 AND exercicio = "REAL" -- 30-03-2021: Adição de filtro AND subtipo_risco in ('1.1', '1.2', '1.3', '1.4', '1.5', '1.6', '1.7', '1.8', '1.9', '1.13')) CT013 INNER JOIN (SELECT DISTINCT ID_CAPITAL_PERIMETROS, REF_DATE FROM cd_captools.ct020_rwa_per WHERE REF_DATE = '${date}' AND NOME_PERIMETRO='Individual Corporativo') CT020 on CT013.ID_CAPITAL_PERIMETROS=CT020.ID_CAPITAL_PERIMETROS) CAP ON CAP.S1EMP=KT.S1EMP AND CAP.CONTRA1=KT.CONTRA1 GROUP BY 1,2,3 ) X on CHAVE_FR = INSTRMNT_ID
A19: INSTRMNT | B19: EAD | C19: Controlos | D19: Verificar saldo de capital | E19: 45462 | F19: 45443 | G19: OK | I19: SELECT LT002.instrmnt_id, RWA, EAD, CONCAT(LT001.cempresa,LT001.cbalcao,LT001.cnumecta,LT001.zdeposit) AS CHAVE_FR, NVL(SUM(LT001.msaldo_final),0) AS Saldo_Capital FROM (SELECT cempresa, cbalcao, cnumecta, zdeposit, ccontab_final_cargabal, msaldo_final FROM cd_loan_tapes_bce.lt001_univ_oper WHERE REF_DATE = '${date}' AND NOME_PERIMETRO='Individual Corporativo' AND AMBITO = 'PM' ) LT001 INNER JOIN (SELECT * FROM cd_loan_tapes_bce.kt_chaves_lt WHERE REF_DATE = '${date}' AND NOME_PERIMETRO='Individual Corporativo' AND AMBITO = 'PM' AND segmento = 'ESTR') KT_LT ON CONCAT(LT001.cempresa,LT001.cbalcao,LT001.cnumecta,LT001.zdeposit) = CONCAT(KT_LT.cempresa,KT_LT.cbalcao,KT_LT.cnumecta,KT_LT.zdeposit) INNER JOIN (SELECT instrmnt_id, rwa, ead FROM cd_loan_tapes_bce.lt002_instrument WHERE REF_DATE = '${date}' AND NOME_PERIMETRO='Individual Corporativo' AND AMBITO = 'PM' AND segmento ='ESTR' AND instrmnt_id in ( '310051224282800116674502P0080001', '310051224282800116674502P0070001', '310051224282800116674502P0060001', '31005122428280011667450200000001', '310051224282800116674502P0100001', '310051224282800116674502P0110001', '310051224282800116674502P0020001', '310051224282800116674502P0010001', '310051224282800116674502P0030001', '310051224282800116674502P0090001' ) ) LT002 ON KT_LT.INSTRMNT_ID = LT002.INSTRMNT_ID LEFT JOIN (SELECT * FROM cd_captools.fr802_pl_contas WHERE 1=1 AND REF_DATE = '${date}' AND cod_plano = 'CARGABAL' AND ((tipo_conta IN ('A','P') AND carteira_contabilistica not in('provisoes para compromissos e garantias concedidas', 'outras provisoes') AND composicao_valor <> 'imparidade acumulada' AND bruto_imparidade <> 'imparidade') OR (tipo_conta IN ('EA','EP','M'))) ) FR802 ON FR802.CONTA = LT001.ccontab_final_cargabal LEFT JOIN (SELECT * FROM cd_captools.ct805_matriz_cnt WHERE 1=1 AND REF_DATE = '${date}' AND DOMINIO = 'Capital' AND NOME_PERIMETRO = 'Individual Corporativo' ) CT805 ON FR802.CONTA = CT805.CONTA GROUP BY 1,2,3,4
A20: PRTCTN | B20: PRM_LCTN | C20: Default values | D20: Validar que os MISS e NA estão de acordo com a especificação | E20: 45464 | F20: 45443 | G20: NOK | H20: 100220 Casos que deviam ser N e estão a ser reportados MISS | I20: SELECT substr(prtctn_id,1,1), valor_it, count(*) FROM (SELECT prtctn_id, valor_it, CASE WHEN substr(prtctn_id,1,1)<>'I' THEN 'N/A' WHEN cfinbem IN ('01','06','07','08') AND CL_HAB>='3.40' THEN 'Y' WHEN cfinbem IN ('01','06','07','08') AND CL_HAB<'3.40' THEN 'N' WHEN cfinbem='02' AND CL_COM>='3.40' THEN 'Y' WHEN cfinbem='02' AND CL_COM<'3.40' THEN 'N' WHEN cfinbem='03' AND CL_SERV>='3.40' THEN 'Y' WHEN cfinbem='03' AND CL_SERV<'3.40' THEN 'N' WHEN cfinbem IN ('04','05') AND CL_IND>='3.40' THEN 'Y' WHEN cfinbem IN ('04','05') AND CL_IND<'3.40' THEN 'N' else 'MISS' END AS valor_simulado, cdisconf, cfinbem, CD_REPARTICAO_FIN, CL_COM, CL_HAB, CL_IND, CL_SERV FROM (SELECT prtctn_id, prm_lctn as valor_it FROM cd_loan_tapes_bce.lt004_protection WHERE ref_date='${date}' AND nome_perimetro='Individual Corporativo' AND segmento='ESTR' AND ambito='PM') AS LT004 LEFT JOIN (SELECT ckbalbem, ckctabem, ckrefbem, trim (cfinbem) as cfinbem, cdisconf FROM cd_garantias.gt009_bens_imov WHERE ref_date='${date}') AS gt009 on prtctn_id=concat('I_', CKBALBEM, '_', CKCTABEM, '_', CKREFBEM) LEFT JOIN (SELECT tayd91c0_celemtab, tayd91c0_nelemc10 AS CD_REPARTICAO_FIN FROM cd_estruturais.tat91_tabelas WHERE tayd91c0_ctabela='J48' AND data_date_part IN (SELECT MAX(data_date_part) from cd_estruturais.tat91_tabelas where data_date_part <= '${date}' and tayd91c0_ctabela= 'J48' )) AS TAT_J48 ON gt009.cdisconf=TAT_J48.tayd91c0_celemtab LEFT JOIN (SELECT tayd91c0_celemtab, trim(SUBSTR(TAYD91C0_NELEMC11,5,4)) as CL_HAB, trim(SUBSTR(TAYD91C0_NELEMC12,5,4)) AS CL_COM, trim(SUBSTR(TAYD91C0_NELEMC13,5,4)) AS CL_IND, trim(SUBSTR(TAYD91C0_NELEMC14,5,4)) AS CL_SERV FROM cd_estruturais.tat91_tabelas WHERE tayd91c0_ctabela='162' AND data_date_part IN (SELECT MAX(data_date_part) from cd_estruturais.tat91_tabelas where data_date_part <= '${date}' and tayd91c0_ctabela= '162' )) AS TAT_162 ON TAT_J48.CD_REPARTICAO_FIN=TAT_162.tayd91c0_celemtab ) as base GROUP BY 1,2
A21: PRTCTN | B21: PRM_LCTN | C21: Desenvolvimento | D21: Validar se campo está de acordo com o especificado | E21: 45464 | F21: 45443 | G21: NOK | H21: 100220 Casos que deviam ser N e estão a ser reportados MISS | I21: SELECT count(*) FROM (SELECT prtctn_id, valor_it, CASE WHEN substr(prtctn_id,1,1)<>'I' THEN 'N/A' WHEN cfinbem IN ('','01','06','07','08') AND CL_HAB>='3.40' THEN 'Y' WHEN cfinbem IN ('','01','06','07','08') AND CL_HAB<'3.40' THEN 'N' WHEN cfinbem is NULL AND CL_HAB>='3.40' THEN 'Y' WHEN cfinbem is NULL AND CL_HAB < '3.40' THEN 'N' WHEN cfinbem='02' AND CL_COM>='3.40' THEN 'Y' WHEN cfinbem='02' AND CL_COM<'3.40' THEN 'N' WHEN cfinbem='03' AND CL_SERV>='3.40' THEN 'Y' WHEN cfinbem='03' AND CL_SERV<'3.40' THEN 'N' WHEN cfinbem IN ('04','05') THEN 'N' else 'N' END AS valor_simulado, cdisconf, cfinbem, CD_REPARTICAO_FIN, CL_COM, CL_HAB, CL_IND, CL_SERV FROM (SELECT prtctn_id, prm_lctn as valor_it FROM cd_loan_tapes_bce.lt004_protection WHERE ref_date='${date}' AND nome_perimetro='Individual Corporativo' AND segmento='ESTR' AND ambito='PM') AS LT004 LEFT JOIN (SELECT ckbalbem, ckctabem, ckrefbem, trim (cfinbem) as cfinbem, cdisconf FROM cd_garantias.gt009_bens_imov WHERE ref_date='${date}') AS gt009 on prtctn_id=concat('I_', CKBALBEM, '_', CKCTABEM, '_', CKREFBEM) LEFT JOIN (SELECT tayd91c0_celemtab, tayd91c0_nelemc10 AS CD_REPARTICAO_FIN FROM cd_estruturais.tat91_tabelas WHERE tayd91c0_ctabela='J48' AND data_date_part='2024-05-31') AS TAT_J48 ON gt009.cdisconf=TAT_J48.tayd91c0_celemtab LEFT JOIN (SELECT tayd91c0_celemtab, trim(SUBSTR(TAYD91C0_NELEMC11,5,4)) as CL_HAB, trim(SUBSTR(TAYD91C0_NELEMC12,5,4)) AS CL_COM, trim(SUBSTR(TAYD91C0_NELEMC13,5,4)) AS CL_IND, trim(SUBSTR(TAYD91C0_NELEMC14,5,4)) AS CL_SERV FROM cd_estruturais.tat91_tabelas WHERE tayd91c0_ctabela='162' AND data_date_part='2024-05-31') AS TAT_162 ON TAT_J48.CD_REPARTICAO_FIN=TAT_162.tayd91c0_celemtab ) as base WHERE 1=1 AND valor_it <> valor_simulado
A22: PRTCTN | B22: PRM_LCTN | C22: Controlos | D22: Verificar se o campo está de acordo com a Codelist | E22: 45464 | F22: 45443 | G22: OK | I22: SELECT prm_lctn, COUNT(*) FROM cd_loan_tapes_bce.lt004_protection WHERE ref_date='${date}' AND nome_perimetro='Individual Corporativo' AND segmento='ESTR' AND ambito='PM' GROUP BY prm_lctn
