Workbook
Name asefadf: #REF!
Name asefadf: #REF!
Name asefadf: #REF!
Name asefadf: #REF!
Name asefadf: #REF!
Name asefadf: #REF!
Name bn: #REF!
Name bn: #REF!
Name bn: #REF!

Sheet PlanoV1.0
H1: =I1/8/5 -> 68.2 | I1: =SUM(J1:AF1) -> 2728 | K1: =K4*8*5 -> 124 | L1: =L4*8*5 -> 124 | M1: =M4*8*5 -> 124 | N1: =N4*8*5 -> 124 | O1: =O4*8*5 -> 124 | P1: =P4*8*5 -> 124 | Q1: =Q4*8*5 -> 124 | R1: =R4*8*5 -> 124 | ... BU1: =BU4*8*5 -> 84
I2: VAL | K2: =K3-K4 -> 0 | L2: =L3-L4 -> 0 | M2: =M3-M4 -> 0 | N2: =N3-N4 -> 0 | O2: =O3-O4 -> 0 | P2: =P3-P4 -> 0 | Q2: =Q3-Q4 -> 0 | R2: =R3-R4 -> 0 | ... BA2: =BA3-BA4 -> 0 | BC2: =BC3-BC4 -> 0 | BD2: =BD3-BD4 -> 0 | BE2: =BE3-BE4 -> 0 | BF2: =BF3-BF4 -> 0 | BG2: =BG3-BG4 -> 0 | BH2: =BH3-BH4 -> 0 | BI2: =BI3-BI4 -> 0 | BJ2: =BJ3-BJ4 -> 0 | ... BU2: =BU3-BU4 -> 0
I3: FTE REAIS | K3: =SUM(K9:K226) -> 3.1 | L3: =SUM(L9:L226) -> 3.1 | M3: =SUM(M9:M226) -> 3.1 | N3: =SUM(N9:N226) -> 3.1 | O3: =SUM(O9:O226) -> 3.1 | P3: =SUM(P9:P226) -> 3.1 | Q3: =SUM(Q9:Q226) -> 3.1 | R3: =SUM(R9:R226) -> 3.1 | ... BA3: =SUM(BA9:BA226) -> 2.1 | BC3: =SUM(BC9:BC226) -> 2.1 | BD3: =SUM(BD9:BD226) -> 2.1 | BE3: =SUM(BE9:BE226) -> 2.1 | BF3: =SUM(BF9:BF226) -> 2.1 | BG3: =SUM(BG9:BG226) -> 2.1 | BH3: =SUM(BH9:BH226) -> 2.1 | BI3: =SUM(BI9:BI226) -> 2.1 | BJ3: =SUM(BJ9:BJ226) -> 2.1 | ... BU3: =SUM(BU9:BU226) -> 2.1
I4: FTE ESP. | K4: 3.1 | L4: 3.1 | M4: 3.1 | N4: 3.1 | O4: 3.1 | P4: 3.1 | Q4: 3.1 | R4: 3.1 | S4: 3.1 | T4: 3.1 | U4: 3.1 | V4: 3.1 | W4: 3.1 | X4: 3.1 | Y4: 3.1 | Z4: 3.1 | AA4: 3.1 | AB4: 3.1 | AC4: 3.1 | AD4: 3.1 | AE4: 3.1 | AF4: 3.1 | AG4: 2.1 | AH4: 2.1 | AI4: 2.1 | AJ4: 2.1 | AK4: 2.1 | AL4: 2.1 | AM4: 2.1 | AN4: 2.1 | AO4: 2.1 | AP4: 2.1 | AQ4: 2.1 | AR4: 2.1 | AS4: 2.1 | AT4: 2.1 | AU4: 2.1 | AV4: 2.1 | AW4: 2.1 | AX4: 2.1 | AY4: 2.1 | AZ4: 2.1 | BA4: 2.1 | BC4: 2.1 | BD4: 2.1 | BE4: 2.1 | BF4: 2.1 | BG4: 2.1 | BH4: 2.1 | BI4: 2.1 | BJ4: 2.1 | BK4: 2.1 | BL4: 2.1 | BM4: 2.1 | BN4: 2.1 | BO4: 2.1 | BP4: 2.1 | BQ4: 2.1 | BR4: 2.1 | BS4: 2.1 | BT4: 2.1 | BU4: 2.1
J5: Janeiro | AG5: Fevereiro | BA5: Março | BV5: Abril
J6: 45649 | K6: 45650 | L6: 45651 | M6: 45652 | N6: 45653 | O6: 45649 | P6: 45650 | Q6: 45651 | R6: 45652 | S6: 45653 | T6: 45649 | U6: 45650 | V6: 45651 | W6: 45652 | X6: 45653 | Y6: 45649 | Z6: 45650 | AA6: 45651 | AB6: 45652 | AC6: 45653 | AD6: 45649 | AE6: 45650 | AF6: 45651 | AG6: 45652 | AH6: 45653 | AI6: 45649 | AJ6: 45650 | AK6: 45651 | AL6: 45652 | AM6: 45653 | AN6: 45649 | AO6: 45650 | AP6: 45651 | AQ6: 45652 | AR6: 45653 | AS6: 45649 | AT6: 45650 | AU6: 45651 | AV6: 45652 | AW6: 45653 | AX6: 45649 | AY6: 45650 | AZ6: 45651 | BA6: 45652 | BB6: 45653 | BC6: 45649 | BD6: 45650 | BE6: 45651 | BF6: 45652 | BG6: 45653 | BH6: 45649 | BI6: 45650 | BJ6: 45651 | BK6: 45652 | BL6: 45653 | BM6: 45649 | BN6: 45650 | BO6: 45651 | BP6: 45652 | BQ6: 45653 | BR6: 45649 | BS6: 45650 | BT6: 45651 | BU6: 45652 | BV6: 45653 | BW6: 45649 | BX6: 45650 | BY6: 45651 | BZ6: 45652 | CA6: 45653 | CB6: 45649 | CC6: 45650 | CD6: 45651 | CE6: 45652 | CF6: 45653 | CG6: 45649 | CH6: 45650 | CI6: 45651 | CJ6: 45652 | CK6: 45653 | CL6: 45649 | CM6: 45650 | CN6: 45651 | CO6: 45652 | CP6: 45653 | CQ6: 45649
I7: 45657 | J7: =WORKDAY(I7,1) -> 45658 | K7: =WORKDAY(J7,1) -> 45659 | L7: =WORKDAY(K7,1) -> 45660 | M7: =WORKDAY(L7,1) -> 45663 | N7: =WORKDAY(M7,1) -> 45664 | O7: =WORKDAY(N7,1) -> 45665 | P7: =WORKDAY(O7,1) -> 45666 | Q7: =WORKDAY(P7,1) -> 45667 | ... X7: =WORKDAY(W7,1) -> 45678
F8: # Campos | G8: Duração (horas) | H8: Duração (Dias) | I8: VAL | J8: =WORKDAY(I7,1) -> 45658 | K8: =WORKDAY(J8,1) -> 45659 | L8: =WORKDAY(K8,1) -> 45660 | M8: =WORKDAY(L8,1) -> 45663 | N8: =WORKDAY(M8,1) -> 45664 | O8: =WORKDAY(N8,1) -> 45665 | P8: =WORKDAY(O8,1) -> 45666 | Q8: =WORKDAY(P8,1) -> 45667 | R8: =WORKDAY(Q8,1) -> 45670 | ... CQ8: =WORKDAY(CP8,1) -> 45777
C10: Gestão Projeto | F10: n.a. | G10: =H10*8*5 -> 0 | H10: =SUM(J10:M10) -> 0
C11: Gestão Projeto | F11: n.a. | G11: =H11*8*5 -> 12 | H11: =SUM(J11:M11) -> 0.3 | I11: =SUM(J11:M11)-H11 -> 0 | K11: 0.1 | L11: 0.1 | M11: 0.1 | N11: 0.1 | O11: 0.1 | P11: 0.1 | Q11: 0.1 | R11: 0.1 | S11: 0.1 | T11: 0.1 | U11: 0.1 | V11: 0.1 | W11: 0.1 | X11: 0.1 | Y11: 0.1 | Z11: 0.1 | AA11: 0.1 | AB11: 0.1 | AC11: 0.1 | AD11: 0.1 | AE11: 0.1 | AF11: 0.1 | AG11: 0.1 | AH11: 0.1 | AI11: 0.1 | AJ11: 0.1 | AK11: 0.1 | AL11: 0.1 | AM11: 0.1 | AN11: 0.1 | AO11: 0.1 | AP11: 0.1 | AQ11: 0.1 | AR11: 0.1 | AS11: 0.1 | AT11: 0.1 | AU11: 0.1 | AV11: 0.1 | AW11: 0.1 | AX11: 0.1 | AY11: 0.1 | AZ11: 0.1 | BA11: 0.1 | BC11: 0.1 | BD11: 0.1 | BE11: 0.1 | BF11: 0.1 | BG11: 0.1 | BH11: 0.1 | BI11: 0.1 | BJ11: 0.1 | BK11: 0.1 | BL11: 0.1 | BM11: 0.1 | BN11: 0.1 | BO11: 0.1 | BP11: 0.1 | BQ11: 0.1 | BR11: 0.1 | BS11: 0.1 | BT11: 0.1 | BU11: 0.1 | BV11: 0.1 | BW11: 0.1 | BX11: 0.1 | BY11: 0.1 | BZ11: 0.1 | CA11: 0.1 | CB11: 0.1 | CC11: 0.1 | CD11: 0.1 | CE11: 0.1 | CF11: 0.1 | CG11: 0.1 | CH11: 0.1 | CJ11: 0.1 | CK11: 0.1 | CL11: 0.1 | CM11: 0.1 | CO11: 0.1 | CP11: 0.1 | CQ11: 0.1
C12: 1. Re-especificações + Simulação + Testes + Re-testes requisitos atuais) | G12: =SUM(G13:G15) -> 128 | H12: =ROUND(SUM(H13:H15),0) -> 16
C13: MunichRe | G13: 16 | H13: =ROUNDUP(G13/8,1) -> 2 | I13: 0 | K13: 3
C14: Gloval - Tabela intermédia | G14: 16 | H14: =ROUNDUP(G14/8,1) -> 2 | I14: 0 | L14: 3
C15: Re-testes | G15: =12*8 -> 96 | H15: =ROUNDUP(G15/8,1) -> 12 | I15: 0 | M15: 3 | N15: 3 | O15: 3 | P15: 3 | Q15: 3 | R15: 3 | S15: 3 | T15: 3 | U15: 3 | V15: 3 | W15: 3 | X15: 3
C16: 2. Novos Campos (Especificação + Simulação + Testes+ Re-testes) | F16: =F17+F66 -> 68 | G16: =G17+G66+G87+G156+G225 -> 311.5 | H16: =H17+H66+H87+H156+H225 -> 46
C17: Especificação de Requisitos - P3 | F17: =COUNTA(E18:E65) -> 48 | G17: =SUM(G18:G55) -> 86 | H17: =ROUND(SUM(H18:H55),0) -> 13
B18: =Table1[[#Headers],[Especificação]] -> Especificação | C18: =D18&"_"&E18 -> ENTITY_TXNMY_ELGBL_CAPEX_W | D18: ENTITY | E18: TXNMY_ELGBL_CAPEX_W | G18: =INDEX(Table1[[Especificação]:[Total Testes]],MATCH(PlanoV1.0!C18,Table1[CONCAT],0),MATCH(PlanoV1.0!B18,Table1[[#Headers],[Especificação]:[Total Testes]],0)) -> 8 | H18: =ROUNDUP(G18/8,1) -> 1 | I18: =SUM(J18:CQ18)-H18 -> 0 | Y18: 1
B19: =Table1[[#Headers],[Especificação]] -> Especificação | C19: =D19&"_"&E19 -> ENTITY_TXNMY_ELGBL_TRNVR_W | D19: ENTITY | E19: TXNMY_ELGBL_TRNVR_W | G19: =INDEX(Table1[[Especificação]:[Total Testes]],MATCH(PlanoV1.0!C19,Table1[CONCAT],0),MATCH(PlanoV1.0!B19,Table1[[#Headers],[Especificação]:[Total Testes]],0)) -> 8 | H19: =ROUNDUP(G19/8,1) -> 1 | I19: =SUM(J19:CQ19)-H19 -> -0.5 | Z19: 0.5
B20: =Table1[[#Headers],[Especificação]] -> Especificação | C20: =D20&"_"&E20 -> ENTITY_TXNMY_ELGBL_CAPEX_P | D20: ENTITY | E20: TXNMY_ELGBL_CAPEX_P | G20: =INDEX(Table1[[Especificação]:[Total Testes]],MATCH(PlanoV1.0!C20,Table1[CONCAT],0),MATCH(PlanoV1.0!B20,Table1[[#Headers],[Especificação]:[Total Testes]],0)) -> 1 | H20: =ROUNDUP(G20/8,1) -> 0.2 | I20: =SUM(J20:CQ20)-H20 -> 0.1 | Z20: 0.3
B21: =Table1[[#Headers],[Especificação]] -> Especificação | C21: =D21&"_"&E21 -> ENTITY_TXNMY_ELGBL_TRNVR_P | D21: ENTITY | E21: TXNMY_ELGBL_TRNVR_P | G21: =INDEX(Table1[[Especificação]:[Total Testes]],MATCH(PlanoV1.0!C21,Table1[CONCAT],0),MATCH(PlanoV1.0!B21,Table1[[#Headers],[Especificação]:[Total Testes]],0)) -> 1 | H21: =ROUNDUP(G21/8,1) -> 0.2 | I21: =SUM(J21:CQ21)-H21 -> 0.1 | Z21: 0.2 | AA21: 0.1
B22: =Table1[[#Headers],[Especificação]] -> Especificação | C22: =D22&"_"&E22 -> ENTITY_TXNMY_ELGBL_CAPEX_B | D22: ENTITY | E22: TXNMY_ELGBL_CAPEX_B | G22: =INDEX(Table1[[Especificação]:[Total Testes]],MATCH(PlanoV1.0!C22,Table1[CONCAT],0),MATCH(PlanoV1.0!B22,Table1[[#Headers],[Especificação]:[Total Testes]],0)) -> 1 | H22: =ROUNDUP(G22/8,1) -> 0.2 | I22: =SUM(J22:CQ22)-H22 -> 0.1 | AA22: 0.3
B23: =Table1[[#Headers],[Especificação]] -> Especificação | C23: =D23&"_"&E23 -> ENTITY_TXNMY_ELGBL_TRNVR_B | D23: ENTITY | E23: TXNMY_ELGBL_TRNVR_B | G23: =INDEX(Table1[[Especificação]:[Total Testes]],MATCH(PlanoV1.0!C23,Table1[CONCAT],0),MATCH(PlanoV1.0!B23,Table1[[#Headers],[Especificação]:[Total Testes]],0)) -> 1 | H23: =ROUNDUP(G23/8,1) -> 0.2 | I23: =SUM(J23:CQ23)-H23 -> 0.1 | AA23: 0.3
B24: =Table1[[#Headers],[Especificação]] -> Especificação | C24: =D24&"_"&E24 -> ENTITY_TXNMY_ELGBL_CAPEX_CE | D24: ENTITY | E24: TXNMY_ELGBL_CAPEX_CE | G24: =INDEX(Table1[[Especificação]:[Total Testes]],MATCH(PlanoV1.0!C24,Table1[CONCAT],0),MATCH(PlanoV1.0!B24,Table1[[#Headers],[Especificação]:[Total Testes]],0)) -> 1 | H24: =ROUNDUP(G24/8,1) -> 0.2 | I24: =SUM(J24:CQ24)-H24 -> 0 | AA24: 0.2
B25: =Table1[[#Headers],[Especificação]] -> Especificação | C25: =D25&"_"&E25 -> ENTITY_TXNMY_ELGBL_TRNVR_CE | D25: ENTITY | E25: TXNMY_ELGBL_TRNVR_CE | G25: =INDEX(Table1[[Especificação]:[Total Testes]],MATCH(PlanoV1.0!C25,Table1[CONCAT],0),MATCH(PlanoV1.0!B25,Table1[[#Headers],[Especificação]:[Total Testes]],0)) -> 1 | H25: =ROUNDUP(G25/8,1) -> 0.2 | I25: =SUM(J25:CQ25)-H25 -> 0 | AA25: 0.1 | AB25: 0.1
B26: =Table1[[#Headers],[Especificação]] -> Especificação | C26: =D26&"_"&E26 -> ENTITY_PURE_CAPEX_P | D26: ENTITY | E26: PURE_CAPEX_P | G26: =INDEX(Table1[[Especificação]:[Total Testes]],MATCH(PlanoV1.0!C26,Table1[CONCAT],0),MATCH(PlanoV1.0!B26,Table1[[#Headers],[Especificação]:[Total Testes]],0)) -> 1 | H26: =ROUNDUP(G26/8,1) -> 0.2 | I26: =SUM(J26:CQ26)-H26 -> 0 | AB26: 0.2
B27: =Table1[[#Headers],[Especificação]] -> Especificação | C27: =D27&"_"&E27 -> ENTITY_PURE_TRNVR_P | D27: ENTITY | E27: PURE_TRNVR_P | G27: =INDEX(Table1[[Especificação]:[Total Testes]],MATCH(PlanoV1.0!C27,Table1[CONCAT],0),MATCH(PlanoV1.0!B27,Table1[[#Headers],[Especificação]:[Total Testes]],0)) -> 1 | H27: =ROUNDUP(G27/8,1) -> 0.2 | I27: =SUM(J27:CQ27)-H27 -> 0 | AB27: 0.2
B28: =Table1[[#Headers],[Especificação]] -> Especificação | C28: =D28&"_"&E28 -> ENTITY_PURE_CAPEX_B | D28: ENTITY | E28: PURE_CAPEX_B | G28: =INDEX(Table1[[Especificação]:[Total Testes]],MATCH(PlanoV1.0!C28,Table1[CONCAT],0),MATCH(PlanoV1.0!B28,Table1[[#Headers],[Especificação]:[Total Testes]],0)) -> 1 | H28: =ROUNDUP(G28/8,1) -> 0.2 | I28: =SUM(J28:CQ28)-H28 -> 0 | AB28: 0.2
B29: =Table1[[#Headers],[Especificação]] -> Especificação | C29: =D29&"_"&E29 -> ENTITY_PURE_TRNVR_B | D29: ENTITY | E29: PURE_TRNVR_B | G29: =INDEX(Table1[[Especificação]:[Total Testes]],MATCH(PlanoV1.0!C29,Table1[CONCAT],0),MATCH(PlanoV1.0!B29,Table1[[#Headers],[Especificação]:[Total Testes]],0)) -> 1 | H29: =ROUNDUP(G29/8,1) -> 0.2 | I29: =SUM(J29:CQ29)-H29 -> 0 | AB29: 0.2
B30: =Table1[[#Headers],[Especificação]] -> Especificação | C30: =D30&"_"&E30 -> ENTITY_PURE_CAPEX_W | D30: ENTITY | E30: PURE_CAPEX_W | G30: =INDEX(Table1[[Especificação]:[Total Testes]],MATCH(PlanoV1.0!C30,Table1[CONCAT],0),MATCH(PlanoV1.0!B30,Table1[[#Headers],[Especificação]:[Total Testes]],0)) -> 1 | H30: =ROUNDUP(G30/8,1) -> 0.2 | I30: =SUM(J30:CQ30)-H30 -> 0 | AB30: 0.1 | AC30: 0.1
B31: =Table1[[#Headers],[Especificação]] -> Especificação | C31: =D31&"_"&E31 -> ENTITY_PURE_TRNVR_W | D31: ENTITY | E31: PURE_TRNVR_W | G31: =INDEX(Table1[[Especificação]:[Total Testes]],MATCH(PlanoV1.0!C31,Table1[CONCAT],0),MATCH(PlanoV1.0!B31,Table1[[#Headers],[Especificação]:[Total Testes]],0)) -> 1 | H31: =ROUNDUP(G31/8,1) -> 0.2 | I31: =SUM(J31:CQ31)-H31 -> 0 | AC31: 0.2
B32: =Table1[[#Headers],[Especificação]] -> Especificação | C32: =D32&"_"&E32 -> ENTITY_PURE_CAPEX_CE | D32: ENTITY | E32: PURE_CAPEX_CE | G32: =INDEX(Table1[[Especificação]:[Total Testes]],MATCH(PlanoV1.0!C32,Table1[CONCAT],0),MATCH(PlanoV1.0!B32,Table1[[#Headers],[Especificação]:[Total Testes]],0)) -> 1 | H32: =ROUNDUP(G32/8,1) -> 0.2 | I32: =SUM(J32:CQ32)-H32 -> 0 | AC32: 0.2
B33: =Table1[[#Headers],[Especificação]] -> Especificação | C33: =D33&"_"&E33 -> ENTITY_PURE_TRNVR_CE | D33: ENTITY | E33: PURE_TRNVR_CE | G33: =INDEX(Table1[[Especificação]:[Total Testes]],MATCH(PlanoV1.0!C33,Table1[CONCAT],0),MATCH(PlanoV1.0!B33,Table1[[#Headers],[Especificação]:[Total Testes]],0)) -> 1 | H33: =ROUNDUP(G33/8,1) -> 0.2 | I33: =SUM(J33:CQ33)-H33 -> 0 | AC33: 0.2
B34: =Table1[[#Headers],[Especificação]] -> Especificação | C34: =D34&"_"&E34 -> ENTITY_ENBLNG_CAPEX_W | D34: ENTITY | E34: ENBLNG_CAPEX_W | G34: =INDEX(Table1[[Especificação]:[Total Testes]],MATCH(PlanoV1.0!C34,Table1[CONCAT],0),MATCH(PlanoV1.0!B34,Table1[[#Headers],[Especificação]:[Total Testes]],0)) -> 1 | H34: =ROUNDUP(G34/8,1) -> 0.2 | I34: =SUM(J34:CQ34)-H34 -> 0 | AC34: 0.2
B35: =Table1[[#Headers],[Especificação]] -> Especificação | C35: =D35&"_"&E35 -> ENTITY_ENBLNG_TRNVR_W | D35: ENTITY | E35: ENBLNG_TRNVR_W | G35: =INDEX(Table1[[Especificação]:[Total Testes]],MATCH(PlanoV1.0!C35,Table1[CONCAT],0),MATCH(PlanoV1.0!B35,Table1[[#Headers],[Especificação]:[Total Testes]],0)) -> 1 | H35: =ROUNDUP(G35/8,1) -> 0.2 | I35: =SUM(J35:CQ35)-H35 -> 0 | AC35: 0.1 | AD35: 0.1
B36: =Table1[[#Headers],[Especificação]] -> Especificação | C36: =D36&"_"&E36 -> ENTITY_ENBLNG_CAPEX_CE | D36: ENTITY | E36: ENBLNG_CAPEX_CE | G36: =INDEX(Table1[[Especificação]:[Total Testes]],MATCH(PlanoV1.0!C36,Table1[CONCAT],0),MATCH(PlanoV1.0!B36,Table1[[#Headers],[Especificação]:[Total Testes]],0)) -> 1 | H36: =ROUNDUP(G36/8,1) -> 0.2 | I36: =SUM(J36:CQ36)-H36 -> 0 | AD36: 0.2
B37: =Table1[[#Headers],[Especificação]] -> Especificação | C37: =D37&"_"&E37 -> ENTITY_ENBLNG_TRNVR_CE | D37: ENTITY | E37: ENBLNG_TRNVR_CE | G37: =INDEX(Table1[[Especificação]:[Total Testes]],MATCH(PlanoV1.0!C37,Table1[CONCAT],0),MATCH(PlanoV1.0!B37,Table1[[#Headers],[Especificação]:[Total Testes]],0)) -> 1 | H37: =ROUNDUP(G37/8,1) -> 0.2 | I37: =SUM(J37:CQ37)-H37 -> 0 | AD37: 0.2
B38: =Table1[[#Headers],[Especificação]] -> Especificação | C38: =D38&"_"&E38 -> INSTRUMENT_TYP_OFF_BLNC_PRDCT | D38: INSTRUMENT | E38: TYP_OFF_BLNC_PRDCT | G38: =INDEX(Table1[[Especificação]:[Total Testes]],MATCH(PlanoV1.0!C38,Table1[CONCAT],0),MATCH(PlanoV1.0!B38,Table1[[#Headers],[Especificação]:[Total Testes]],0)) -> 1 | H38: =ROUNDUP(G38/8,1) -> 0.2 | I38: =SUM(J38:CQ38)-H38 -> 0 | AD38: 0.2
B39: =Table1[[#Headers],[Especificação]] -> Especificação | C39: =D39&"_"&E39 -> INSTRUMENT_FLG_MNMM_SFGRDS | D39: INSTRUMENT | E39: FLG_MNMM_SFGRDS | G39: =INDEX(Table1[[Especificação]:[Total Testes]],MATCH(PlanoV1.0!C39,Table1[CONCAT],0),MATCH(PlanoV1.0!B39,Table1[[#Headers],[Especificação]:[Total Testes]],0)) -> 0 | H39: =ROUNDUP(G39/8,1) -> 0 | I39: =SUM(J39:CQ39)-H39 -> 1.3 | Y39: 1.3
B40: =Table1[[#Headers],[Especificação]] -> Especificação | C40: =D40&"_"&E40 -> INSTR_PROTECTION_TYP_RLTN | D40: INSTR_PROTECTION | E40: TYP_RLTN | G40: =INDEX(Table1[[Especificação]:[Total Testes]],MATCH(PlanoV1.0!C40,Table1[CONCAT],0),MATCH(PlanoV1.0!B40,Table1[[#Headers],[Especificação]:[Total Testes]],0)) -> 4 | H40: =ROUNDUP(G40/8,1) -> 0.5 | I40: =SUM(J40:CQ40)-H40 -> 0 | Y40: 0.5
B41: =Table1[[#Headers],[Especificação]] -> Especificação | C41: =D41&"_"&E41 -> PROTECTION_BLDNG_AR | D41: PROTECTION | E41: BLDNG_AR | G41: =INDEX(Table1[[Especificação]:[Total Testes]],MATCH(PlanoV1.0!C41,Table1[CONCAT],0),MATCH(PlanoV1.0!B41,Table1[[#Headers],[Especificação]:[Total Testes]],0)) -> 2 | H41: =ROUNDUP(G41/8,1) -> 0.3 | I41: =SUM(J41:CQ41)-H41 -> 0 | AD41: 0.3
...

Sheet Sheet1
H1: =I1/8 -> 150.3 | I1: =SUM(J1:BU1) -> 1202.4 | K1: =K4*8 -> 24.8 | L1: =L4*8 -> 24.8 | M1: =M4*8 -> 24.8 | N1: =N4*8 -> 24.8 | O1: =O4*8 -> 24.8 | P1: =P4*8 -> 24.8 | Q1: =Q4*8 -> 24.8 | R1: =R4*8 -> 24.8 | ... BU1: =BU4*8 -> 1.6
I2: VAL | K2: =K3-K4 -> 0 | L2: =L3-L4 -> 0 | M2: =M3-M4 -> 0 | N2: =N3-N4 -> 0 | O2: =O3-O4 -> 0 | P2: =P3-P4 -> 0 | Q2: =Q3-Q4 -> 0 | R2: =R3-R4 -> 0 | ... BA2: =BA3-BA4 -> 0 | BC2: =BC3-BC4 -> 0 | BD2: =BD3-BD4 -> 0 | BE2: =BE3-BE4 -> 0 | BF2: =BF3-BF4 -> 0 | BG2: =BG3-BG4 -> 0 | BH2: =BH3-BH4 -> 0 | BI2: =BI3-BI4 -> 0 | BJ2: =BJ3-BJ4 -> 0 | ... BU2: =BU3-BU4 -> 0
I3: FTE REAIS | K3: =SUM(K9:K226) -> 3.1 | L3: =SUM(L9:L226) -> 3.1 | M3: =SUM(M9:M226) -> 3.1 | N3: =SUM(N9:N226) -> 3.1 | O3: =SUM(O9:O226) -> 3.1 | P3: =SUM(P9:P226) -> 3.1 | Q3: =SUM(Q9:Q226) -> 3.1 | R3: =SUM(R9:R226) -> 3.1 | ... BA3: =SUM(BA9:BA226) -> 2.1 | BC3: =SUM(BC9:BC226) -> 2.1 | BD3: =SUM(BD9:BD226) -> 2.1 | BE3: =SUM(BE9:BE226) -> 2.1 | BF3: =SUM(BF9:BF226) -> 2.1 | BG3: =SUM(BG9:BG226) -> 2.1 | BH3: =SUM(BH9:BH226) -> 2.1 | BI3: =SUM(BI9:BI226) -> 2.1 | BJ3: =SUM(BJ9:BJ226) -> 2.1 | ... BU3: =SUM(BU9:BU226) -> 0.2
I4: FTE ESP. | K4: 3.1 | L4: 3.1 | M4: 3.1 | N4: 3.1 | O4: 3.1 | P4: 3.1 | Q4: 3.1 | R4: 3.1 | S4: 3.1 | T4: 3.1 | U4: 3.1 | V4: 3.1 | W4: 3.1 | X4: 3.1 | Y4: 3.1 | Z4: 3.1 | AA4: 3.1 | AB4: 3.1 | AC4: 3.1 | AD4: 3.1 | AE4: 3.1 | AF4: 3.1 | AG4: 2.1 | AH4: 2.1 | AI4: 2.1 | AJ4: 2.1 | AK4: 2.1 | AL4: 2.1 | AM4: 2.1 | AN4: 2.1 | AO4: 2.1 | AP4: 2.1 | AQ4: 2.1 | AR4: 2.1 | AS4: 2.1 | AT4: 2.1 | AU4: 2.1 | AV4: 2.1 | AW4: 2.1 | AX4: 2.1 | AY4: 2.1 | AZ4: 2.1 | BA4: 2.1 | BC4: 2.1 | BD4: 2.1 | BE4: 2.1 | BF4: 2.1 | BG4: 2.1 | BH4: 2.1 | BI4: 2.1 | BJ4: 2.1 | BK4: 2.1 | BL4: 2.1 | BM4: 2.1 | BN4: 2.1 | BO4: 2.1 | BP4: 2.1 | BQ4: 2.1 | BR4: 2.1 | BS4: 2.1 | BT4: 2.1 | BU4: 0.2
G5: =G11+G12+G16 -> 545.1 | H5: =H11+H12+H16 -> 68.4 | J5: Janeiro | AG5: Fevereiro | BA5: Março | BV5: Abril
G6: =G5/8 -> 68.1375 | H6: =H5-G6 -> 0.2625 | J6: 45649 | K6: 45650 | L6: 45651 | M6: 45652 | N6: 45653 | O6: 45649 | P6: 45650 | Q6: 45651 | R6: 45652 | S6: 45653 | T6: 45649 | U6: 45650 | V6: 45651 | W6: 45652 | X6: 45653 | Y6: 45649 | Z6: 45650 | AA6: 45651 | AB6: 45652 | AC6: 45653 | AD6: 45649 | AE6: 45650 | AF6: 45651 | AG6: 45652 | AH6: 45653 | AI6: 45649 | AJ6: 45650 | AK6: 45651 | AL6: 45652 | AM6: 45653 | AN6: 45649 | AO6: 45650 | AP6: 45651 | AQ6: 45652 | AR6: 45653 | AS6: 45649 | AT6: 45650 | AU6: 45651 | AV6: 45652 | AW6: 45653 | AX6: 45649 | AY6: 45650 | AZ6: 45651 | BA6: 45652 | BB6: 45653 | BC6: 45649 | BD6: 45650 | BE6: 45651 | BF6: 45652 | BG6: 45653 | BH6: 45649 | BI6: 45650 | BJ6: 45651 | BK6: 45652 | BL6: 45653 | BM6: 45649 | BN6: 45650 | BO6: 45651 | BP6: 45652 | BQ6: 45653 | BR6: 45649 | BS6: 45650 | BT6: 45651 | BU6: 45652 | BV6: 45653 | BW6: 45649 | BX6: 45650 | BY6: 45651 | BZ6: 45652 | CA6: 45653 | CB6: 45649 | CC6: 45650 | CD6: 45651 | CE6: 45652 | CF6: 45653 | CG6: 45649 | CH6: 45650 | CI6: 45651 | CJ6: 45652 | CK6: 45653 | CL6: 45649 | CM6: 45650 | CN6: 45651 | CO6: 45652 | CP6: 45653 | CQ6: 45649
I7: 45657 | J7: =WORKDAY(I7,1) -> 45658 | K7: =WORKDAY(J7,1) -> 45659 | L7: =WORKDAY(K7,1) -> 45660 | M7: =WORKDAY(L7,1) -> 45663 | N7: =WORKDAY(M7,1) -> 45664 | O7: =WORKDAY(N7,1) -> 45665 | P7: =WORKDAY(O7,1) -> 45666 | Q7: =WORKDAY(P7,1) -> 45667 | ... X7: =WORKDAY(W7,1) -> 45678
F8: # Campos | G8: Duração (horas) | H8: Duração (Dias) | I8: VAL | J8: =WORKDAY(I7,1) -> 45658 | K8: =WORKDAY(J8,1) -> 45659 | L8: =WORKDAY(K8,1) -> 45660 | M8: =WORKDAY(L8,1) -> 45663 | N8: =WORKDAY(M8,1) -> 45664 | O8: =WORKDAY(N8,1) -> 45665 | P8: =WORKDAY(O8,1) -> 45666 | Q8: =WORKDAY(P8,1) -> 45667 | R8: =WORKDAY(Q8,1) -> 45670 | ... CQ8: =WORKDAY(CP8,1) -> 45777
C10: Gestão Projeto | F10: n.a. | G10: =H10*8*5 -> 0 | H10: =SUM(J10:M10) -> 0
C11: Gestão Projeto | F11: n.a. | G11: =H11*8 -> 49.6 | H11: =SUM(J11:BU11) -> 6.2 | I11: =SUM(J11:BU11)-H11 -> 0 | K11: 0.1 | L11: 0.1 | M11: 0.1 | N11: 0.1 | O11: 0.1 | P11: 0.1 | Q11: 0.1 | R11: 0.1 | S11: 0.1 | T11: 0.1 | U11: 0.1 | V11: 0.1 | W11: 0.1 | X11: 0.1 | Y11: 0.1 | Z11: 0.1 | AA11: 0.1 | AB11: 0.1 | AC11: 0.1 | AD11: 0.1 | AE11: 0.1 | AF11: 0.1 | AG11: 0.1 | AH11: 0.1 | AI11: 0.1 | AJ11: 0.1 | AK11: 0.1 | AL11: 0.1 | AM11: 0.1 | AN11: 0.1 | AO11: 0.1 | AP11: 0.1 | AQ11: 0.1 | AR11: 0.1 | AS11: 0.1 | AT11: 0.1 | AU11: 0.1 | AV11: 0.1 | AW11: 0.1 | AX11: 0.1 | AY11: 0.1 | AZ11: 0.1 | BA11: 0.1 | BC11: 0.1 | BD11: 0.1 | BE11: 0.1 | BF11: 0.1 | BG11: 0.1 | BH11: 0.1 | BI11: 0.1 | BJ11: 0.1 | BK11: 0.1 | BL11: 0.1 | BM11: 0.1 | BN11: 0.1 | BO11: 0.1 | BP11: 0.1 | BQ11: 0.1 | BR11: 0.1 | BS11: 0.1 | BT11: 0.1 | BU11: 0.1
C12: 1. Re-especificações + Simulação + Testes + Re-testes requisitos atuais) | G12: =SUM(G13:G15) -> 128 | H12: =ROUND(SUM(H13:H15),1) -> 16
C13: MunichRe | G13: 16 | H13: =ROUNDUP(G13/8,1) -> 2 | I13: 0 | K13: 3
C14: Gloval - Tabela intermédia | G14: 16 | H14: =ROUNDUP(G14/8,1) -> 2 | I14: 0 | L14: 3
C15: Re-testes | G15: =12*8 -> 96 | H15: =ROUNDUP(G15/8,1) -> 12 | I15: 0 | M15: 3 | N15: 3 | O15: 3 | P15: 3 | Q15: 3 | R15: 3 | S15: 3 | T15: 3 | U15: 3 | V15: 3 | W15: 3 | X15: 3
C16: 2. Novos Campos (Especificação + Simulação + Testes+ Re-testes) | F16: =F17+F66 -> 68 | G16: =G17+G66+G87+G156+G225 -> 367.5 | H16: =H17+H66+H87+H156+H225 -> 46.2
C17: Especificação de Requisitos - P3 | F17: =COUNTA(E18:E65) -> 48 | G17: =SUM(G18:G65) -> 112 | H17: =ROUND(SUM(H18:H65),1) -> 14.2 | I17: =SUM(J17:CQ17)-H17 -> 6.9 | Y17: 3 | Z17: 3 | AA17: 3 | AB17: 3 | AC17: 3 | AD17: 3 | AE17: 3 | AF17: 0.1
B18: =Table1[[#Headers],[Especificação]] -> Especificação | C18: =D18&"_"&E18 -> ENTITY_TXNMY_ELGBL_CAPEX_W | D18: ENTITY | E18: TXNMY_ELGBL_CAPEX_W | G18: =INDEX(Table1[[Especificação]:[Total Testes]],MATCH(Sheet1!C18,Table1[CONCAT],0),MATCH(Sheet1!B18,Table1[[#Headers],[Especificação]:[Total Testes]],0)) -> 8 | H18: =ROUND(G18/8,2) -> 1
B19: =Table1[[#Headers],[Especificação]] -> Especificação | C19: =D19&"_"&E19 -> ENTITY_TXNMY_ELGBL_TRNVR_W | D19: ENTITY | E19: TXNMY_ELGBL_TRNVR_W | G19: =INDEX(Table1[[Especificação]:[Total Testes]],MATCH(Sheet1!C19,Table1[CONCAT],0),MATCH(Sheet1!B19,Table1[[#Headers],[Especificação]:[Total Testes]],0)) -> 8 | H19: =ROUND(G19/8,2) -> 1
B20: =Table1[[#Headers],[Especificação]] -> Especificação | C20: =D20&"_"&E20 -> ENTITY_TXNMY_ELGBL_CAPEX_P | D20: ENTITY | E20: TXNMY_ELGBL_CAPEX_P | G20: =INDEX(Table1[[Especificação]:[Total Testes]],MATCH(Sheet1!C20,Table1[CONCAT],0),MATCH(Sheet1!B20,Table1[[#Headers],[Especificação]:[Total Testes]],0)) -> 1 | H20: =ROUND(G20/8,2) -> 0.13
B21: =Table1[[#Headers],[Especificação]] -> Especificação | C21: =D21&"_"&E21 -> ENTITY_TXNMY_ELGBL_TRNVR_P | D21: ENTITY | E21: TXNMY_ELGBL_TRNVR_P | G21: =INDEX(Table1[[Especificação]:[Total Testes]],MATCH(Sheet1!C21,Table1[CONCAT],0),MATCH(Sheet1!B21,Table1[[#Headers],[Especificação]:[Total Testes]],0)) -> 1 | H21: =ROUND(G21/8,2) -> 0.13
B22: =Table1[[#Headers],[Especificação]] -> Especificação | C22: =D22&"_"&E22 -> ENTITY_TXNMY_ELGBL_CAPEX_B | D22: ENTITY | E22: TXNMY_ELGBL_CAPEX_B | G22: =INDEX(Table1[[Especificação]:[Total Testes]],MATCH(Sheet1!C22,Table1[CONCAT],0),MATCH(Sheet1!B22,Table1[[#Headers],[Especificação]:[Total Testes]],0)) -> 1 | H22: =ROUND(G22/8,2) -> 0.13
B23: =Table1[[#Headers],[Especificação]] -> Especificação | C23: =D23&"_"&E23 -> ENTITY_TXNMY_ELGBL_TRNVR_B | D23: ENTITY | E23: TXNMY_ELGBL_TRNVR_B | G23: =INDEX(Table1[[Especificação]:[Total Testes]],MATCH(Sheet1!C23,Table1[CONCAT],0),MATCH(Sheet1!B23,Table1[[#Headers],[Especificação]:[Total Testes]],0)) -> 1 | H23: =ROUND(G23/8,2) -> 0.13
B24: =Table1[[#Headers],[Especificação]] -> Especificação | C24: =D24&"_"&E24 -> ENTITY_TXNMY_ELGBL_CAPEX_CE | D24: ENTITY | E24: TXNMY_ELGBL_CAPEX_CE | G24: =INDEX(Table1[[Especificação]:[Total Testes]],MATCH(Sheet1!C24,Table1[CONCAT],0),MATCH(Sheet1!B24,Table1[[#Headers],[Especificação]:[Total Testes]],0)) -> 1 | H24: =ROUND(G24/8,2) -> 0.13
B25: =Table1[[#Headers],[Especificação]] -> Especificação | C25: =D25&"_"&E25 -> ENTITY_TXNMY_ELGBL_TRNVR_CE | D25: ENTITY | E25: TXNMY_ELGBL_TRNVR_CE | G25: =INDEX(Table1[[Especificação]:[Total Testes]],MATCH(Sheet1!C25,Table1[CONCAT],0),MATCH(Sheet1!B25,Table1[[#Headers],[Especificação]:[Total Testes]],0)) -> 1 | H25: =ROUND(G25/8,2) -> 0.13
B26: =Table1[[#Headers],[Especificação]] -> Especificação | C26: =D26&"_"&E26 -> ENTITY_PURE_CAPEX_P | D26: ENTITY | E26: PURE_CAPEX_P | G26: =INDEX(Table1[[Especificação]:[Total Testes]],MATCH(Sheet1!C26,Table1[CONCAT],0),MATCH(Sheet1!B26,Table1[[#Headers],[Especificação]:[Total Testes]],0)) -> 1 | H26: =ROUND(G26/8,2) -> 0.13
B27: =Table1[[#Headers],[Especificação]] -> Especificação | C27: =D27&"_"&E27 -> ENTITY_PURE_TRNVR_P | D27: ENTITY | E27: PURE_TRNVR_P | G27: =INDEX(Table1[[Especificação]:[Total Testes]],MATCH(Sheet1!C27,Table1[CONCAT],0),MATCH(Sheet1!B27,Table1[[#Headers],[Especificação]:[Total Testes]],0)) -> 1 | H27: =ROUND(G27/8,2) -> 0.13
B28: =Table1[[#Headers],[Especificação]] -> Especificação | C28: =D28&"_"&E28 -> ENTITY_PURE_CAPEX_B | D28: ENTITY | E28: PURE_CAPEX_B | G28: =INDEX(Table1[[Especificação]:[Total Testes]],MATCH(Sheet1!C28,Table1[CONCAT],0),MATCH(Sheet1!B28,Table1[[#Headers],[Especificação]:[Total Testes]],0)) -> 1 | H28: =ROUND(G28/8,2) -> 0.13
B29: =Table1[[#Headers],[Especificação]] -> Especificação | C29: =D29&"_"&E29 -> ENTITY_PURE_TRNVR_B | D29: ENTITY | E29: PURE_TRNVR_B | G29: =INDEX(Table1[[Especificação]:[Total Testes]],MATCH(Sheet1!C29,Table1[CONCAT],0),MATCH(Sheet1!B29,Table1[[#Headers],[Especificação]:[Total Testes]],0)) -> 1 | H29: =ROUND(G29/8,2) -> 0.13
... B65: =Table1[[#Headers],[Especificação]] -> Especificação | C65: =D65&"_"&E65 -> PROTECTION_YR_CNSTRCTN | D65: PROTECTION | E65: YR_CNSTRCTN | G65: =INDEX(Table1[[Especificação]:[Total Testes]],MATCH(Sheet1!C65,Table1[CONCAT],0),MATCH(Sheet1!B65,Table1[[#Headers],[Especificação]:[Total Testes]],0)) -> 8 | H65: =ROUND(G65/8,2) -> 1
C66: Especificação de Requisitos - ESG Risks | F66: =+COUNTA(E67:E86) -> 20 | G66: =SUM(G67:G86) -> 25 | H66: =ROUND(SUM(H67:H86),1) -> 3.1 | I66: =SUM(J66:CQ66)-H66 -> 8.3 | AF66: 2.9 | AG66: 2 | AH66: 2 | AI66: 2 | AJ66: 2 | AK66: 0.5
B67: =Table1[[#Headers],[Especificação]] -> Especificação | C67: =D67&"_"&E67 -> ENTITY_GRP_ECNMC_ACTVTY | D67: ENTITY | E67: GRP_ECNMC_ACTVTY | G67: =INDEX(Table1[[Especificação]:[Total Testes]],MATCH(Sheet1!C67,Table1[CONCAT],0),MATCH(Sheet1!B67,Table1[[#Headers],[Especificação]:[Total Testes]],0)) -> 2 | H67: =ROUND(G67/8,2) -> 0.25
B68: =Table1[[#Headers],[Especificação]] -> Especificação | C68: =D68&"_"&E68 -> PROTECTION_TYP_EMSSNS_LBL | D68: PROTECTION | E68: TYP_EMSSNS_LBL | G68: =INDEX(Table1[[Especificação]:[Total Testes]],MATCH(Sheet1!C68,Table1[CONCAT],0),MATCH(Sheet1!B68,Table1[[#Headers],[Especificação]:[Total Testes]],0)) -> 0 | H68: =ROUND(G68/8,2) -> 0
B69: =Table1[[#Headers],[Especificação]] -> Especificação | C69: =D69&"_"&E69 -> PROTECTION_EPC_EMSSNS_LBL | D69: PROTECTION | E69: EPC_EMSSNS_LBL | G69: =INDEX(Table1[[Especificação]:[Total Testes]],MATCH(Sheet1!C69,Table1[CONCAT],0),MATCH(Sheet1!B69,Table1[[#Headers],[Especificação]:[Total Testes]],0)) -> 2 | H69: =ROUND(G69/8,2) -> 0.25
B70: =Table1[[#Headers],[Especificação]] -> Especificação | C70: =D70&"_"&E70 -> PROTECTION_VHCL_EMSSNS_LBL | D70: PROTECTION | E70: VHCL_EMSSNS_LBL | G70: =INDEX(Table1[[Especificação]:[Total Testes]],MATCH(Sheet1!C70,Table1[CONCAT],0),MATCH(Sheet1!B70,Table1[[#Headers],[Especificação]:[Total Testes]],0)) -> 0 | H70: =ROUND(G70/8,2) -> 0
B71: =Table1[[#Headers],[Especificação]] -> Especificação | C71: =D71&"_"&E71 -> PROTECTION_TYP_EMSSNS_SCR | D71: PROTECTION | E71: TYP_EMSSNS_SCR | G71: =INDEX(Table1[[Especificação]:[Total Testes]],MATCH(Sheet1!C71,Table1[CONCAT],0),MATCH(Sheet1!B71,Table1[[#Headers],[Especificação]:[Total Testes]],0)) -> 2 | H71: =ROUND(G71/8,2) -> 0.25
B72: =Table1[[#Headers],[Especificação]] -> Especificação | C72: =D72&"_"&E72 -> PROTECTION_EPC_EMSSNS_SCR | D72: PROTECTION | E72: EPC_EMSSNS_SCR | G72: =INDEX(Table1[[Especificação]:[Total Testes]],MATCH(Sheet1!C72,Table1[CONCAT],0),MATCH(Sheet1!B72,Table1[[#Headers],[Especificação]:[Total Testes]],0)) -> 4 | H72: =ROUND(G72/8,2) -> 0.5
B73: =Table1[[#Headers],[Especificação]] -> Especificação | C73: =D73&"_"&E73 -> PROTECTION_VHCL_EMSSNS_SCR | D73: PROTECTION | E73: VHCL_EMSSNS_SCR | G73: =INDEX(Table1[[Especificação]:[Total Testes]],MATCH(Sheet1!C73,Table1[CONCAT],0),MATCH(Sheet1!B73,Table1[[#Headers],[Especificação]:[Total Testes]],0)) -> 0 | H73: =ROUND(G73/8,2) -> 0
B74: =Table1[[#Headers],[Especificação]] -> Especificação | C74: =D74&"_"&E74 -> PROTECTION_INSRNC_ID | D74: PROTECTION | E74: INSRNC_ID | G74: =INDEX(Table1[[Especificação]:[Total Testes]],MATCH(Sheet1!C74,Table1[CONCAT],0),MATCH(Sheet1!B74,Table1[[#Headers],[Especificação]:[Total Testes]],0)) -> 0 | H74: =ROUND(G74/8,2) -> 0
B75: =Table1[[#Headers],[Especificação]] -> Especificação | C75: =D75&"_"&E75 -> PROTECTION_TYP_HZRDS_INSRD | D75: PROTECTION | E75: TYP_HZRDS_INSRD | G75: =INDEX(Table1[[Especificação]:[Total Testes]],MATCH(Sheet1!C75,Table1[CONCAT],0),MATCH(Sheet1!B75,Table1[[#Headers],[Especificação]:[Total Testes]],0)) -> 0 | H75: =ROUND(G75/8,2) -> 0
B76: =Table1[[#Headers],[Especificação]] -> Especificação | C76: =D76&"_"&E76 -> PROTECTION_AMNT_CVRD_INSRNC | D76: PROTECTION | E76: AMNT_CVRD_INSRNC | G76: =INDEX(Table1[[Especificação]:[Total Testes]],MATCH(Sheet1!C76,Table1[CONCAT],0),MATCH(Sheet1!B76,Table1[[#Headers],[Especificação]:[Total Testes]],0)) -> 0 | H76: =ROUND(G76/8,2) -> 0
...

Sheet RESUMO
B2: Leverage Finance = "Y" | C2: =COUNTIFS('LISTA - Setembro2024'!$K$3:$K$539,"Y") -> 174
B4: Alteração | C4: Âmbito | D4: # Campos | E4: Observações | H4: Leveraged Finance | I4: STATUS | J4: AMBITO | K4: Status Data Lake | L4: # Campos
B5: Novo Campo | C5: ESTR (& outros) | D5: =GETPIVOTDATA("[Measures].[Count of ID Data field / Field order]",$H$4,"[Range].[STATUS]","[Range].[STATUS].&[Novo Campo]","[Range].[AMBITO]","[Range].[AMBITO].&[ESTR & GD & PILAR3]","[Range].[Status Data Lake]","[Range].[Status Data Lake].&[n/a]","[Range].[Leveraged Finance]","[Range].[Leveraged Finance].&[Y]") -> 1 | E5: n.a. | H5: N | I5: Campo eliminado | J5: PILAR3 | K5: n/a | L5: 1
C6: LF | D6: =GETPIVOTDATA("[Measures].[Count of ID Data field / Field order]",$H$4,"[Range].[STATUS]","[Range].[STATUS].&[Novo Campo]","[Range].[AMBITO]","[Range].[AMBITO].&[LF]","[Range].[Status Data Lake]","[Range].[Status Data Lake].&[n/a]","[Range].[Leveraged Finance]","[Range].[Leveraged Finance].&[Y]") -> 19 | E6: n.a. | I6: Campo eliminado - troca tabela | J6: GD & PILAR3 | K6: n/a | L6: 2
B7: Sem alterações | C7: ESTR (& outros) | D7: =SUM(L50:L72) -> 154 | E7: De notar que destes campos: - 9 provém da fonte manual de LF (lt601_lev_fin) - 39 estão sem dados/pouca qualidade com necessidades de (re)-especificações (Sindicados, Demonstrações Financeiras CIB, Re-estruturados) - 24 em testes/implementação - 15 com incidências nos controlos corporativos | J7: PILAR3 | K7: n/a | L7: 2
C8: Total | D8: =SUM(D5:D7) -> 174 | I8: Nome campo alterado | J8: PILAR3 | K8: n/a | L8: 2
I9: Nova Tabela | J9: ESTR & GD & PILAR3 | K9: n/a | L9: 1
J10: GD & PILAR3 | K10: n/a | L10: 3
B11: Leverage Finance = "N" | C11: =COUNTIFS('LISTA - Setembro2024'!$K$3:$K$539,"N") -> 362 | J11: PILAR3 | K11: n/a | L11: 3
I12: Nova Tabela - Campo existente | J12: GD & PILAR3 | K12: n/a | L12: 2
J13: PILAR3 | K13: n/a | L13: 2
B14: Alteração | C14: Âmbito | D14: # Campos | E14: Observações | I14: Novo Campo | J14: ESG_RISKS | K14: n/a | L14: 12
B15: Nova tabela | C15: ESTR (& outros) | D15: =GETPIVOTDATA("[Measures].[Count of ID Data field / Field order]",$H$4,"[Range].[STATUS]","[Range].[STATUS].&[Nova Tabela]","[Range].[AMBITO]","[Range].[AMBITO].&[ESTR & GD & PILAR3]","[Range].[Status Data Lake]","[Range].[Status Data Lake].&[n/a]","[Range].[Leveraged Finance]","[Range].[Leveraged Finance].&[N]") -> 1 | E15: Apenas 1 campo reportado na LT estrutural (questionar corporação) >>> é para ESG | J15: ESTR | K15: n/a | L15: 25
C16: GD & PILAR3 | D16: =GETPIVOTDATA("[Measures].[Count of ID Data field / Field order]",$H$4,"[Range].[STATUS]","[Range].[STATUS].&[Nova Tabela]","[Range].[AMBITO]","[Range].[AMBITO].&[GD & PILAR3]","[Range].[Status Data Lake]","[Range].[Status Data Lake].&[n/a]","[Range].[Leveraged Finance]","[Range].[Leveraged Finance].&[N]")+GETPIVOTDATA("[Measures].[Count of ID Data field / Field order]",$H$4,"[Range].[STATUS]","[Range].[STATUS].&[Nova Tabela - Campo existente]","[Range].[AMBITO]","[Range].[AMBITO].&[GD & PILAR3]","[Range].[Status Data Lake]","[Range].[Status Data Lake].&[n/a]","[Range].[Leveraged Finance]","[Range].[Leveraged Finance].&[N]") -> 5 | E16: De notar que 2 campos trocaram de tabela | J16: ESTR & GFINANCE | K16: n/a | L16: 7
C17: PILAR3 | D17: =GETPIVOTDATA("[Measures].[Count of ID Data field / Field order]",$H$4,"[Range].[STATUS]","[Range].[STATUS].&[Nova Tabela]","[Range].[AMBITO]","[Range].[AMBITO].&[PILAR3]","[Range].[Status Data Lake]","[Range].[Status Data Lake].&[n/a]","[Range].[Leveraged Finance]","[Range].[Leveraged Finance].&[N]")+GETPIVOTDATA("[Measures].[Count of ID Data field / Field order]",$H$4,"[Range].[STATUS]","[Range].[STATUS].&[Nova Tabela - Campo existente]","[Range].[AMBITO]","[Range].[AMBITO].&[PILAR3]","[Range].[Status Data Lake]","[Range].[Status Data Lake].&[n/a]","[Range].[Leveraged Finance]","[Range].[Leveraged Finance].&[N]") -> 5 | E17: De notar que 2 campos trocaram de tabela | J17: GD | K17: n/a | L17: 1
B18: Novo Campo | C18: ESTR | D18: =GETPIVOTDATA("[Measures].[Count of ID Data field / Field order]",$H$4,"[Range].[STATUS]","[Range].[STATUS].&[Novo Campo]","[Range].[AMBITO]","[Range].[AMBITO].&[ESTR]","[Range].[Status Data Lake]","[Range].[Status Data Lake].&[n/a]","[Range].[Leveraged Finance]","[Range].[Leveraged Finance].&[N]") -> 25 | E18: n.a. | J18: GD & PILAR3 | K18: n/a | L18: 1
C19: ESTR (& Green Finance) | D19: =GETPIVOTDATA("[Measures].[Count of ID Data field / Field order]",$H$4,"[Range].[STATUS]","[Range].[STATUS].&[Novo Campo]","[Range].[AMBITO]","[Range].[AMBITO].&[ESTR & GFINANCE]","[Range].[Status Data Lake]","[Range].[Status Data Lake].&[n/a]","[Range].[Leveraged Finance]","[Range].[Leveraged Finance].&[N]") -> 7 | E19: n.a. | J19: PILAR3 | K19: n/a | L19: 29
C20: GD & PILAR3 | D20: =GETPIVOTDATA("[Measures].[Count of ID Data field / Field order]",$H$4,"[Range].[STATUS]","[Range].[STATUS].&[Novo Campo]","[Range].[AMBITO]","[Range].[AMBITO].&[GD & PILAR3]","[Range].[Status Data Lake]","[Range].[Status Data Lake].&[n/a]","[Range].[Leveraged Finance]","[Range].[Leveraged Finance].&[N]") -> 1 | E20: n.a. | I20: Sem alteração | J20: ESTR | K20: 1. Especificar | L20: 9
C21: PILAR3 | D21: =GETPIVOTDATA("[Measures].[Count of ID Data field / Field order]",$H$4,"[Range].[STATUS]","[Range].[STATUS].&[Novo Campo]","[Range].[AMBITO]","[Range].[AMBITO].&[PILAR3]","[Range].[Status Data Lake]","[Range].[Status Data Lake].&[n/a]","[Range].[Leveraged Finance]","[Range].[Leveraged Finance].&[N]") -> 29 | E21: n.a. | K21: 2. Alterar especificação | L21: 15
C22: GD | D22: =GETPIVOTDATA("[Measures].[Count of ID Data field / Field order]",$H$4,"[Range].[STATUS]","[Range].[STATUS].&[Novo Campo]","[Range].[AMBITO]","[Range].[AMBITO].&[GD]","[Range].[Status Data Lake]","[Range].[Status Data Lake].&[n/a]","[Range].[Leveraged Finance]","[Range].[Leveraged Finance].&[N]") -> 1 | E22: n.a. | K22: 3. Pendente de decisão | L22: 1
C23: ESG Risks | D23: =GETPIVOTDATA("[Measures].[Count of ID Data field / Field order]",$H$4,"[Range].[STATUS]","[Range].[STATUS].&[Novo Campo]","[Range].[AMBITO]","[Range].[AMBITO].&[ESG_RISKS]","[Range].[Status Data Lake]","[Range].[Status Data Lake].&[n/a]","[Range].[Leveraged Finance]","[Range].[Leveraged Finance].&[N]") -> 12 | E23: Campos adicionados pela Corporação antes de abril e não contemplados no Data Lake. | K23: 4.1 Em implementação - Re-especificação | L23: 13
B24: Nome de campo alterado | C24: PILAR3 | D24: =GETPIVOTDATA("[Measures].[Count of ID Data field / Field order]",$H$4,"[Range].[STATUS]","[Range].[STATUS].&[Nome campo alterado]","[Range].[AMBITO]","[Range].[AMBITO].&[PILAR3]","[Range].[Status Data Lake]","[Range].[Status Data Lake].&[n/a]","[Range].[Leveraged Finance]","[Range].[Leveraged Finance].&[N]") -> 2 | E24: Sem impacto previsto a nível de re-especificação. | K24: 4.2 Em implementação - Incidência | L24: 1
B25: Sem alterações | C25: - | D25: =SUM(L20:L47) -> 269 | E25: De notar que destes campos (âmbito ESTR): - 29 estão sem dados/pouca qualidade com necessidades de (re)-especificações (Salários, Demonstrações Financeiras CIB) - 27 em testes/implementação - 42 com incidências nos controlos corporativos | K25: 5.1 Em testes - Re-especificação | L25: 7
C26: Total (excl. campos elim.) | D26: =SUM(D15:D25) -> 357 | K26: 5.2 Em testes - Incidência | L26: 2
B27: Campo eliminado | C27: GD & PILAR3 | D27: =GETPIVOTDATA("[Measures].[Count of ID Data field / Field order]",$H$4,"[Range].[STATUS]","[Range].[STATUS].&[Campo eliminado - troca tabela]","[Range].[AMBITO]","[Range].[AMBITO].&[GD & PILAR3]","[Range].[Status Data Lake]","[Range].[Status Data Lake].&[n/a]","[Range].[Leveraged Finance]","[Range].[Leveraged Finance].&[N]") -> 2 | E27: De notar que 2 campos trocaram de tabela | K27: 7. Analisar controlos e completude | L27: 36
C28: PILAR3 | D28: =GETPIVOTDATA("[Measures].[Count of ID Data field / Field order]",$H$4,"[Range].[STATUS]","[Range].[STATUS].&[Campo eliminado]","[Range].[AMBITO]","[Range].[AMBITO].&[PILAR3]","[Range].[Status Data Lake]","[Range].[Status Data Lake].&[n/a]","[Range].[Leveraged Finance]","[Range].[Leveraged Finance].&[N]")+GETPIVOTDATA("[Measures].[Count of ID Data field / Field order]",$H$4,"[Range].[STATUS]","[Range].[STATUS].&[Campo eliminado - troca tabela]","[Range].[AMBITO]","[Range].[AMBITO].&[PILAR3]","[Range].[Status Data Lake]","[Range].[Status Data Lake].&[n/a]","[Range].[Leveraged Finance]","[Range].[Leveraged Finance].&[N]") -> 3 | E28: De notar que 2 campos trocaram de tabela | K28: 8. Concluído - sem dados | L28: 6
D29: =D26+SUM(D27:D28) -> 362 | K29: 9. Concluído | L29: 73
J30: ESTR & GD | K30: 5.1 Em testes - Re-especificação | L30: 1
K31: 9. Concluído | L31: 1
J32: ESTR & GD & PILAR3 | K32: 4.1 Em implementação - Re-especificação | L32: 1
K33: 5.2 Em testes - Incidência | L33: 1
K34: 7. Analisar controlos e completude | L34: 3
K35: 9. Concluído | L35: 6
J36: ESTR & GFINANCE | K36: 9. Concluído | L36: 1
J37: ESTR & PILAR3 | K37: 1. Especificar | L37: 1
K38: 2. Alterar especificação | L38: 2
C39: Green finance + ESG Risks o que são e para que são utilizados >> 7+12 | K39: 3. Pendente de decisão | L39: 1
C40: Quem está a solicitar esta informação? >> 25 campos ESTR >> custo à unidade | K40: 4.1 Em implementação - Re-especificação | L40: 1
K41: 7. Analisar controlos e completude | L41: 3
B42: Confirmar com ficheiro enviado pela Raquel > LF | K42: 9. Concluído | L42: 6
...

Sheet Sheet1 (2)
H1: =I1/8 -> 81.4 | I1: =SUM(J1:CA1) -> 651.2 | K1: =K4*8 -> 0 | L1: =L4*8 -> 0 | M1: =M4*8 -> 0 | N1: =N4*8 -> 0 | O1: =O4*8 -> 0 | P1: =P4*8 -> 0 | Q1: =Q4*8 -> 0 | R1: =R4*8 -> 0 | ... CA1: =CA4*8 -> 0
I2: VAL | K2: =K3-K4 -> 3.2 | L2: =L3-L4 -> 3.2 | M2: =M3-M4 -> 3.2 | N2: =N3-N4 -> 3.2 | O2: =O3-O4 -> 3.2 | P2: =P3-P4 -> 3.2 | Q2: =Q3-Q4 -> 3.2 | R2: =R3-R4 -> 3.2 | ... BA2: =BA3-BA4 -> 0 | BC2: =BC3-BC4 -> 0 | BD2: =BD3-BD4 -> 0 | BE2: =BE3-BE4 -> 0 | BF2: =BF3-BF4 -> 0 | BG2: =BG3-BG4 -> 0 | BH2: =BH3-BH4 -> -0.9 | BI2: =BI3-BI4 -> -0.9 | BJ2: =BJ3-BJ4 -> -0.9 | ... CA2: =CA3-CA4 -> 0
I3: FTE REAIS | K3: =SUM(K9:K231) -> 3.2 | L3: =SUM(L9:L231) -> 3.2 | M3: =SUM(M9:M231) -> 3.2 | N3: =SUM(N9:N231) -> 3.2 | O3: =SUM(O9:O231) -> 3.2 | P3: =SUM(P9:P231) -> 3.2 | Q3: =SUM(Q9:Q231) -> 3.2 | R3: =SUM(R9:R231) -> 3.2 | ... BA3: =SUM(BA9:BA231) -> 2.2 | BC3: =SUM(BC9:BC231) -> 2.2 | BD3: =SUM(BD9:BD231) -> 2.2 | BE3: =SUM(BE9:BE231) -> 2.2 | BF3: =SUM(BF9:BF231) -> 2.2 | BG3: =SUM(BG9:BG231) -> 2.2 | BH3: =SUM(BH9:BH231) -> 1.3 | BI3: =SUM(BI9:BI231) -> 1.3 | BJ3: =SUM(BJ9:BJ231) -> 1.3 | ... CA3: =SUM(CA9:CA231) -> 0
I4: FTE ESP. | Y4: 2.2 | Z4: 2.2 | AA4: 2.2 | AB4: 2.2 | AC4: 2.2 | AD4: 2.2 | AE4: 2.2 | AF4: 2.2 | AG4: 2.2 | AH4: 2.2 | AI4: 2.2 | AJ4: 2.2 | AK4: 2.2 | AL4: 2.2 | AM4: 2.2 | AN4: 2.2 | AO4: 2.2 | AP4: 2.2 | AQ4: 2.2 | AR4: 2.2 | AS4: 2.2 | AT4: 2.2 | AU4: 2.2 | AV4: 2.2 | AW4: 2.2 | AX4: 2.2 | AY4: 2.2 | AZ4: 2.2 | BA4: 2.2 | BC4: 2.2 | BD4: 2.2 | BE4: 2.2 | BF4: 2.2 | BG4: 2.2 | BH4: 2.2 | BI4: 2.2 | BJ4: 2.2 | BK4: 0 | BL4: 0 | BM4: 0 | BN4: 0 | BO4: 0 | BP4: 0 | BQ4: 0 | BR4: 0 | BS4: 0 | BT4: 0 | BU4: 0 | BV4: 0 | BW4: 0 | BX4: 0 | BY4: 0 | BZ4: 0 | CA4: 0
J5: Janeiro | AG5: Fevereiro | BA5: Março | BV5: Abril
J6: =J8 -> 45658 | K6: =K8 -> 45659 | L6: =L8 -> 45660 | M6: =M8 -> 45663 | N6: =N8 -> 45664 | O6: =O8 -> 45665 | P6: =P8 -> 45666 | Q6: =Q8 -> 45667 | ... CQ6: =CQ8 -> 45777
I7: 45657 | J7: =WORKDAY(I7,1) -> 45658 | K7: =WORKDAY(J7,1) -> 45659 | L7: =WORKDAY(K7,1) -> 45660 | M7: 4 | N7: =WORKDAY(M7,1) -> 5 | O7: =WORKDAY(N7,1) -> 6 | P7: =WORKDAY(O7,1) -> 9 | Q7: =WORKDAY(P7,1) -> 10 | R7: =WORKDAY(Q7,1) -> 11 | S7: =WORKDAY(R7,1) -> 12 | T7: =WORKDAY(S7,1) -> 13 | U7: =WORKDAY(T7,1) -> 16 | ... X7: =WORKDAY(W7,1) -> 19
F8: # Campos | G8: Duração (horas) | H8: Duração (Dias) | I8: VAL | J8: =WORKDAY(I7,1) -> 45658 | K8: =WORKDAY(J8,1) -> 45659 | L8: =WORKDAY(K8,1) -> 45660 | M8: =WORKDAY(L8,1) -> 45663 | N8: =WORKDAY(M8,1) -> 45664 | O8: =WORKDAY(N8,1) -> 45665 | P8: =WORKDAY(O8,1) -> 45666 | Q8: =WORKDAY(P8,1) -> 45667 | R8: =WORKDAY(Q8,1) -> 45670 | ... CQ8: =WORKDAY(CP8,1) -> 45777
C10: Gestão Projeto | F10: n.a. | G10: =H10*8*5 -> 0 | H10: =SUM(J10:M10) -> 0
C11: Gestão Projeto | F11: n.a. | G11: =H11*8 -> 70.4 | H11: =SUM(J11:BU11) -> 8.8 | I11: =SUM(J11:BU11)-H11 -> 0 | K11: 0.2 | L11: 0.2 | M11: 0.2 | N11: 0.2 | O11: 0.2 | P11: 0.2 | Q11: 0.2 | R11: 0.2 | S11: 0.2 | T11: 0.2 | U11: 0.2 | V11: 0.2 | W11: 0.2 | X11: 0.2 | Y11: 0.2 | Z11: 0.2 | AA11: 0.2 | AB11: 0.2 | AC11: 0.2 | AD11: 0.2 | AE11: 0.2 | AF11: 0.2 | AG11: 0.2 | AH11: 0.2 | AI11: 0.2 | AJ11: 0.2 | AK11: 0.2 | AL11: 0.2 | AM11: 0.2 | AU11: 0.2 | AV11: 0.2 | AW11: 0.2 | AX11: 0.2 | AY11: 0.2 | AZ11: 0.2 | BA11: 0.2 | BC11: 0.2 | BD11: 0.2 | BE11: 0.2 | BF11: 0.2 | BG11: 0.2 | BH11: 0.2 | BI11: 0.2 | BJ11: 0.2
C12: 0. Re-especificações + Simulação + Testes + Re-testes requisitos atuais) | G12: =SUM(G13:G14) -> 336 | H12: =ROUND(SUM(H13:H14),1) -> 42 | I12: =SUM(J12:CQ12)-H12 -> 0 | K12: 3 | L12: 3 | M12: 3 | N12: 3 | O12: 3 | P12: 3 | Q12: 3 | R12: 3 | S12: 3 | T12: 3 | U12: 3 | V12: 3 | W12: 3 | X12: 3
C13: Gloval - Tabela intermédia | G13: 16 | H13: =ROUNDUP(G13/8,1) -> 2
C14: Re-testes | G14: =(13*8*3)+8 -> 320 | H14: =ROUNDUP(G14/8,1) -> 40
C15: 1. Re-especificação de MunichRe | G15: =SUM(G16:G20) -> 60 | H15: =ROUND(SUM(H16:H20),1) -> 7.5 | I15: =SUM(I16:I20) -> 0
C16: Especificação novo input | G16: 4 | H16: =ROUND(G16/8,2) -> 0.5 | I16: =SUM(J16:CQ16)-H16 -> 0 | Y16: 0.5
C17: Re-especificação de campos riscos fisicos - Modelo Verde (4) | G17: 8 | H17: =ROUND(G17/8,2) -> 1 | I17: =SUM(J17:CQ17)-H17 -> 0 | Y17: 1
A18: esperar IT | C18: Testar input | G18: 8 | H18: =ROUND(G18/8,2) -> 1 | I18: =SUM(J18:CQ18)-H18 -> 0 | AU18: 1
A19: esperar IT | C19: Testar campos risco MV (4) | G19: =5*8 -> 40 | H19: =ROUND(G19/8,2) -> 5 | I19: =SUM(J19:CQ19)-H19 -> 0 | AU19: 1 | AV19: 1 | AW19: 1 | AX19: 1 | AY19: 1
A20: esperar IT | C20: Testar 4 campos de LT P3 | G20: 0 | H20: =ROUND(G20/8,2) -> 0 | I20: =SUM(J20:CQ20)-H20 -> 0
C21: 2. Novos Campos (Especificação + Simulação + Testes+ Re-testes) | F21: =F22+F71 -> 54 | G21: =G22+G71+G92+G161+G230 -> 367.5 | H21: =H22+H71+H92+H161+H230 -> 46.2
C22: Especificação de Requisitos - P3 | F22: =COUNTA(E23:E64) -> 42 | G22: =SUM(G23:G64) -> 112 | H22: =ROUND(SUM(H23:H64),1) -> 14.2 | I22: =SUM(J22:CQ22)-H22 -> 0 | Y22: 0.5 | Z22: 0.5 | AA22: 0.5 | AB22: 0.5 | AC22: 0.5 | AD22: 0.5 | AE22: 0.5 | AF22: 0.9 | AG22: 1.5 | AH22: 1.5 | AI22: 1.5 | AJ22: 1.5 | AK22: 1.5 | AL22: 1.7 | AM22: 0.6
B23: =Table1[[#Headers],[Especificação]] -> Especificação | C23: =D23&"_"&E23 -> ENTITY_TXNMY_ELGBL_CAPEX_W | D23: ENTITY | E23: TXNMY_ELGBL_CAPEX_W | G23: =INDEX(Table1[[Especificação]:[Total Testes]],MATCH('Sheet1 (2)'!C23,Table1[CONCAT],0),MATCH('Sheet1 (2)'!B23,Table1[[#Headers],[Especificação]:[Total Testes]],0)) -> 8 | H23: =ROUND(G23/8,2) -> 1
B24: =Table1[[#Headers],[Especificação]] -> Especificação | C24: =D24&"_"&E24 -> ENTITY_TXNMY_ELGBL_TRNVR_W | D24: ENTITY | E24: TXNMY_ELGBL_TRNVR_W | G24: =INDEX(Table1[[Especificação]:[Total Testes]],MATCH('Sheet1 (2)'!C24,Table1[CONCAT],0),MATCH('Sheet1 (2)'!B24,Table1[[#Headers],[Especificação]:[Total Testes]],0)) -> 8 | H24: =ROUND(G24/8,2) -> 1
B25: =Table1[[#Headers],[Especificação]] -> Especificação | C25: =D25&"_"&E25 -> ENTITY_TXNMY_ELGBL_CAPEX_P | D25: ENTITY | E25: TXNMY_ELGBL_CAPEX_P | G25: =INDEX(Table1[[Especificação]:[Total Testes]],MATCH('Sheet1 (2)'!C25,Table1[CONCAT],0),MATCH('Sheet1 (2)'!B25,Table1[[#Headers],[Especificação]:[Total Testes]],0)) -> 1 | H25: =ROUND(G25/8,2) -> 0.13
B26: =Table1[[#Headers],[Especificação]] -> Especificação | C26: =D26&"_"&E26 -> ENTITY_TXNMY_ELGBL_TRNVR_P | D26: ENTITY | E26: TXNMY_ELGBL_TRNVR_P | G26: =INDEX(Table1[[Especificação]:[Total Testes]],MATCH('Sheet1 (2)'!C26,Table1[CONCAT],0),MATCH('Sheet1 (2)'!B26,Table1[[#Headers],[Especificação]:[Total Testes]],0)) -> 1 | H26: =ROUND(G26/8,2) -> 0.13
B27: =Table1[[#Headers],[Especificação]] -> Especificação | C27: =D27&"_"&E27 -> ENTITY_TXNMY_ELGBL_CAPEX_B | D27: ENTITY | E27: TXNMY_ELGBL_CAPEX_B | G27: =INDEX(Table1[[Especificação]:[Total Testes]],MATCH('Sheet1 (2)'!C27,Table1[CONCAT],0),MATCH('Sheet1 (2)'!B27,Table1[[#Headers],[Especificação]:[Total Testes]],0)) -> 1 | H27: =ROUND(G27/8,2) -> 0.13
B28: =Table1[[#Headers],[Especificação]] -> Especificação | C28: =D28&"_"&E28 -> ENTITY_TXNMY_ELGBL_TRNVR_B | D28: ENTITY | E28: TXNMY_ELGBL_TRNVR_B | G28: =INDEX(Table1[[Especificação]:[Total Testes]],MATCH('Sheet1 (2)'!C28,Table1[CONCAT],0),MATCH('Sheet1 (2)'!B28,Table1[[#Headers],[Especificação]:[Total Testes]],0)) -> 1 | H28: =ROUND(G28/8,2) -> 0.13
B29: =Table1[[#Headers],[Especificação]] -> Especificação | C29: =D29&"_"&E29 -> ENTITY_TXNMY_ELGBL_CAPEX_CE | D29: ENTITY | E29: TXNMY_ELGBL_CAPEX_CE | G29: =INDEX(Table1[[Especificação]:[Total Testes]],MATCH('Sheet1 (2)'!C29,Table1[CONCAT],0),MATCH('Sheet1 (2)'!B29,Table1[[#Headers],[Especificação]:[Total Testes]],0)) -> 1 | H29: =ROUND(G29/8,2) -> 0.13
B30: =Table1[[#Headers],[Especificação]] -> Especificação | C30: =D30&"_"&E30 -> ENTITY_TXNMY_ELGBL_TRNVR_CE | D30: ENTITY | E30: TXNMY_ELGBL_TRNVR_CE | G30: =INDEX(Table1[[Especificação]:[Total Testes]],MATCH('Sheet1 (2)'!C30,Table1[CONCAT],0),MATCH('Sheet1 (2)'!B30,Table1[[#Headers],[Especificação]:[Total Testes]],0)) -> 1 | H30: =ROUND(G30/8,2) -> 0.13
B31: =Table1[[#Headers],[Especificação]] -> Especificação | C31: =D31&"_"&E31 -> ENTITY_PURE_CAPEX_P | D31: ENTITY | E31: PURE_CAPEX_P | G31: =INDEX(Table1[[Especificação]:[Total Testes]],MATCH('Sheet1 (2)'!C31,Table1[CONCAT],0),MATCH('Sheet1 (2)'!B31,Table1[[#Headers],[Especificação]:[Total Testes]],0)) -> 1 | H31: =ROUND(G31/8,2) -> 0.13
B32: =Table1[[#Headers],[Especificação]] -> Especificação | C32: =D32&"_"&E32 -> ENTITY_PURE_TRNVR_P | D32: ENTITY | E32: PURE_TRNVR_P | G32: =INDEX(Table1[[Especificação]:[Total Testes]],MATCH('Sheet1 (2)'!C32,Table1[CONCAT],0),MATCH('Sheet1 (2)'!B32,Table1[[#Headers],[Especificação]:[Total Testes]],0)) -> 1 | H32: =ROUND(G32/8,2) -> 0.13
B33: =Table1[[#Headers],[Especificação]] -> Especificação | C33: =D33&"_"&E33 -> ENTITY_PURE_CAPEX_B | D33: ENTITY | E33: PURE_CAPEX_B | G33: =INDEX(Table1[[Especificação]:[Total Testes]],MATCH('Sheet1 (2)'!C33,Table1[CONCAT],0),MATCH('Sheet1 (2)'!B33,Table1[[#Headers],[Especificação]:[Total Testes]],0)) -> 1 | H33: =ROUND(G33/8,2) -> 0.13
B34: =Table1[[#Headers],[Especificação]] -> Especificação | C34: =D34&"_"&E34 -> ENTITY_PURE_TRNVR_B | D34: ENTITY | E34: PURE_TRNVR_B | G34: =INDEX(Table1[[Especificação]:[Total Testes]],MATCH('Sheet1 (2)'!C34,Table1[CONCAT],0),MATCH('Sheet1 (2)'!B34,Table1[[#Headers],[Especificação]:[Total Testes]],0)) -> 1 | H34: =ROUND(G34/8,2) -> 0.13
... B70: =Table1[[#Headers],[Especificação]] -> Especificação | C70: =D70&"_"&E70 -> INSTR_ACTIVITY_DNSH_DTL | D70: INSTR_ACTIVITY | E70: DNSH_DTL | G70: =INDEX(Table1[[Especificação]:[Total Testes]],MATCH('Sheet1 (2)'!C70,Table1[CONCAT],0),MATCH('Sheet1 (2)'!B70,Table1[[#Headers],[Especificação]:[Total Testes]],0)) -> 0 | H70: =ROUND(G70/8,2) -> 0
C71: Especificação de Requisitos - ESG Risks | F71: =+COUNTA(E72:E83) -> 12 | G71: =SUM(G72:G83) -> 25 | H71: =ROUND(SUM(H72:H83),1) -> 3.1 | I71: =SUM(J71:CQ71)-H71 -> 0 | Z71: 0.5 | AA71: 0.5 | AB71: 0.5 | AC71: 0.5 | AD71: 0.5 | AE71: 0.5 | AF71: 0.1
B72: =Table1[[#Headers],[Especificação]] -> Especificação | C72: =D72&"_"&E72 -> ENTITY_GRP_ECNMC_ACTVTY | D72: ENTITY | E72: GRP_ECNMC_ACTVTY | G72: =INDEX(Table1[[Especificação]:[Total Testes]],MATCH('Sheet1 (2)'!C72,Table1[CONCAT],0),MATCH('Sheet1 (2)'!B72,Table1[[#Headers],[Especificação]:[Total Testes]],0)) -> 2 | H72: =ROUND(G72/8,2) -> 0.25
B73: =Table1[[#Headers],[Especificação]] -> Especificação | C73: =D73&"_"&E73 -> PROTECTION_EPC_EMSSNS_LBL | D73: PROTECTION | E73: EPC_EMSSNS_LBL | G73: =INDEX(Table1[[Especificação]:[Total Testes]],MATCH('Sheet1 (2)'!C73,Table1[CONCAT],0),MATCH('Sheet1 (2)'!B73,Table1[[#Headers],[Especificação]:[Total Testes]],0)) -> 2 | H73: =ROUND(G73/8,2) -> 0.25
B74: =Table1[[#Headers],[Especificação]] -> Especificação | C74: =D74&"_"&E74 -> PROTECTION_TYP_EMSSNS_SCR | D74: PROTECTION | E74: TYP_EMSSNS_SCR | G74: =INDEX(Table1[[Especificação]:[Total Testes]],MATCH('Sheet1 (2)'!C74,Table1[CONCAT],0),MATCH('Sheet1 (2)'!B74,Table1[[#Headers],[Especificação]:[Total Testes]],0)) -> 2 | H74: =ROUND(G74/8,2) -> 0.25
B75: =Table1[[#Headers],[Especificação]] -> Especificação | C75: =D75&"_"&E75 -> PROTECTION_EPC_EMSSNS_SCR | D75: PROTECTION | E75: EPC_EMSSNS_SCR | G75: =INDEX(Table1[[Especificação]:[Total Testes]],MATCH('Sheet1 (2)'!C75,Table1[CONCAT],0),MATCH('Sheet1 (2)'!B75,Table1[[#Headers],[Especificação]:[Total Testes]],0)) -> 4 | H75: =ROUND(G75/8,2) -> 0.5
B76: =Table1[[#Headers],[Especificação]] -> Especificação | C76: =D76&"_"&E76 -> INSTRUMENT_INTRNL_SGMNT | D76: INSTRUMENT | E76: INTRNL_SGMNT | G76: =INDEX(Table1[[Especificação]:[Total Testes]],MATCH('Sheet1 (2)'!C76,Table1[CONCAT],0),MATCH('Sheet1 (2)'!B76,Table1[[#Headers],[Especificação]:[Total Testes]],0)) -> 2 | H76: =ROUND(G76/8,2) -> 0.25
...

Sheet LISTA - Setembro2024
Y1: &
A2: SETEMBRO | F2: ESTR | G2: GD | H2: PILAR3 | I2: GFINANCE | J2: ESG_RISKS | K2: LF | L2: Comparação com lista ATUAL | V2: Comparação com lista ATUAL | AC2: Estimativas
A3: ID Data field / Field order | B3: CONCAT | C3: Table | D3: Data field | E3: Field name | F3: Structural ECB Loan Tape | G3: Green Dashboard | H3: Pillar III ESG | I3: Green Finance | J3: ESG Risks | K3: Leveraged Finance | L3: ATUAL_Structural ECB Loan Tape | M3: val_ESTR | N3: ATUAL_Green Dashboard | O3: val_GD | P3: ATUAL_Pillar III ESG | Q3: val_PILAR3 | R3: ATUAL_Green Finance | S3: ATUAL_ESG Risks | T3: val_ESG_RISKS | U3: ATUAL_Leveraged Finance | V3: Fonte manual LF | W3: Status Data Lake | X3: Status Data Lake (Detalhe) | Y3: AMBITO | Z3: STATUS | AA3: xx | AB3: format | AC3: Complexidade (todos) | AD3: Especificação | AE3: Simulação | AF3: 2. Testes comparativos | AG3: Complexidade (code list) | AH3: 3. Val. Code List | AI3: 4. Val. Formatos | AJ3: 5. Val.Controlos Corp. | AK3: Total Testes | AL3: Observações
A4: EN.001 | B4: =C4&"_"&D4 -> ENTITY_COD_SOC | C4: ENTITY | D4: COD_SOC | E4: Entity code of the informing society. | F4: Y | G4: N | H4: Y | I4: N | J4: Y | K4: Y | L4: =IFERROR(VLOOKUP($B4,'LISTA - Atual'!$B$1:$I$444,5,0),"Novo") -> Y | M4: =IF(L4="Novo","Novo Campo",IF(L4=F4,"Igual","Diferente")) -> Igual | N4: =IFERROR(VLOOKUP($B4,'LISTA - Atual'!$B$1:$I$444,6,0),"Novo") -> N | O4: =IF(N4="Novo","Novo Campo",IF(N4=G4,"Igual","Diferente")) -> Igual | P4: =IFERROR(VLOOKUP($B4,'LISTA - Atual'!$B$1:$I$444,7,0),"Novo") -> Y | Q4: =IF(P4="Novo","Novo Campo",IF(P4=H4,"Igual","Diferente")) -> Igual | R4: n/a | S4: =IFERROR(VLOOKUP($B4,'LISTA - Atual'!$B$1:$I$444,8,0),"Novo") -> Y | T4: =IF(S4="Novo","Novo Campo",IF(S4=J4,"Igual","Diferente")) -> Igual | U4: n/a | V4: N | W4: =IFERROR(VLOOKUP(B4,#REF!,11,0),"n/a") -> n/a | X4: =IFERROR(VLOOKUP(B4,#REF!,8,0),"n/a") -> n/a | Y4: =$F$2&$Y$1&$H$2 -> ESTR & PILAR3 | Z4: Sem alteração | AA4: =VLOOKUP(Table1[[#This Row],[CONCAT]],'Campos Resumo Prop2.0'!A:H,8,0) -> #N/A | AB4: VARCHAR2(5) | AC4: n.a. | AD4: =INDEX(Auxiliar!$D$5:$I$10,MATCH('LISTA - Setembro2024'!AD$3,Auxiliar!$B$5:$B$10,0),MATCH('LISTA - Setembro2024'!$AC4,Auxiliar!$D$4:$I$4,0)) -> 0 | AE4: =INDEX(Auxiliar!$D$5:$I$10,MATCH('LISTA - Setembro2024'!AE$3,Auxiliar!$B$5:$B$10,0),MATCH('LISTA - Setembro2024'!$AC4,Auxiliar!$D$4:$I$4,0)) -> 0 | AF4: =INDEX(Auxiliar!$D$5:$I$10,MATCH('LISTA - Setembro2024'!AF$3,Auxiliar!$B$5:$B$10,0),MATCH('LISTA - Setembro2024'!$AC4,Auxiliar!$D$4:$I$4,0)) -> 0 | AG4: =IF(OR(AB4="Code List",AB4="Y, N"),AC4,"n.a.") -> n.a. | AH4: =INDEX(Auxiliar!$D$5:$I$10,MATCH('LISTA - Setembro2024'!AH$3,Auxiliar!$B$5:$B$10,0),MATCH('LISTA - Setembro2024'!$AG4,Auxiliar!$D$4:$I$4,0)) -> 0 | AI4: =INDEX(Auxiliar!$D$5:$I$10,MATCH('LISTA - Setembro2024'!AI$3,Auxiliar!$B$5:$B$10,0),MATCH('LISTA - Setembro2024'!$AC4,Auxiliar!$D$4:$I$4,0)) -> 0 | AJ4: =INDEX(Auxiliar!$D$5:$I$10,MATCH('LISTA - Setembro2024'!AJ$3,Auxiliar!$B$5:$B$10,0),MATCH('LISTA - Setembro2024'!$AC4,Auxiliar!$D$4:$I$4,0)) -> 0 | AK4: =SUM(AF4,AH4:AJ4) -> 0
A5: EN.002 | B5: =C5&"_"&D5 -> ENTITY_CNTRY | C5: ENTITY | D5: CNTRY | E5: Country of counterparty residence | F5: Y | G5: N | H5: Y | I5: N | J5: Y | K5: Y | L5: =IFERROR(VLOOKUP($B5,'LISTA - Atual'!$B$1:$I$444,5,0),"Novo") -> Y | M5: =IF(L5="Novo","Novo Campo",IF(L5=F5,"Igual","Diferente")) -> Igual | N5: =IFERROR(VLOOKUP($B5,'LISTA - Atual'!$B$1:$I$444,6,0),"Novo") -> N | O5: =IF(N5="Novo","Novo Campo",IF(N5=G5,"Igual","Diferente")) -> Igual | P5: =IFERROR(VLOOKUP($B5,'LISTA - Atual'!$B$1:$I$444,7,0),"Novo") -> Y | Q5: =IF(P5="Novo","Novo Campo",IF(P5=H5,"Igual","Diferente")) -> Igual | R5: n/a | S5: =IFERROR(VLOOKUP($B5,'LISTA - Atual'!$B$1:$I$444,8,0),"Novo") -> Y | T5: =IF(S5="Novo","Novo Campo",IF(S5=J5,"Igual","Diferente")) -> Igual | U5: n/a | V5: N | W5: =IFERROR(VLOOKUP(B5,#REF!,11,0),"n/a") -> n/a | X5: =IFERROR(VLOOKUP(B5,#REF!,8,0),"n/a") -> n/a | Y5: =$F$2&$Y$1&$H$2 -> ESTR & PILAR3 | Z5: Sem alteração | AA5: =VLOOKUP(Table1[[#This Row],[CONCAT]],'Campos Resumo Prop2.0'!A:H,8,0) -> #N/A | AB5: Code List | AC5: n.a. | AD5: =INDEX(Auxiliar!$D$5:$I$10,MATCH('LISTA - Setembro2024'!AD$3,Auxiliar!$B$5:$B$10,0),MATCH('LISTA - Setembro2024'!$AC5,Auxiliar!$D$4:$I$4,0)) -> 0 | AE5: =INDEX(Auxiliar!$D$5:$I$10,MATCH('LISTA - Setembro2024'!AE$3,Auxiliar!$B$5:$B$10,0),MATCH('LISTA - Setembro2024'!$AC5,Auxiliar!$D$4:$I$4,0)) -> 0 | AF5: =INDEX(Auxiliar!$D$5:$I$10,MATCH('LISTA - Setembro2024'!AF$3,Auxiliar!$B$5:$B$10,0),MATCH('LISTA - Setembro2024'!$AC5,Auxiliar!$D$4:$I$4,0)) -> 0 | AG5: =IF(OR(AB5="Code List",AB5="Y, N"),AC5,"n.a.") -> n.a. | AH5: =INDEX(Auxiliar!$D$5:$I$10,MATCH('LISTA - Setembro2024'!AH$3,Auxiliar!$B$5:$B$10,0),MATCH('LISTA - Setembro2024'!$AG5,Auxiliar!$D$4:$I$4,0)) -> 0 | AI5: =INDEX(Auxiliar!$D$5:$I$10,MATCH('LISTA - Setembro2024'!AI$3,Auxiliar!$B$5:$B$10,0),MATCH('LISTA - Setembro2024'!$AC5,Auxiliar!$D$4:$I$4,0)) -> 0 | AJ5: =INDEX(Auxiliar!$D$5:$I$10,MATCH('LISTA - Setembro2024'!AJ$3,Auxiliar!$B$5:$B$10,0),MATCH('LISTA - Setembro2024'!$AC5,Auxiliar!$D$4:$I$4,0)) -> 0 | AK5: =SUM(AF5,AH5:AJ5) -> 0
A6: EN.003 | B6: =C6&"_"&D6 -> ENTITY_DT_BRTH | C6: ENTITY | D6: DT_BRTH | E6: Birth date counterparty | F6: Y | G6: N | H6: N | I6: N | J6: N | K6: N | L6: =IFERROR(VLOOKUP($B6,'LISTA - Atual'!$B$1:$I$444,5,0),"Novo") -> Y | M6: =IF(L6="Novo","Novo Campo",IF(L6=F6,"Igual","Diferente")) -> Igual | N6: =IFERROR(VLOOKUP($B6,'LISTA - Atual'!$B$1:$I$444,6,0),"Novo") -> N | O6: =IF(N6="Novo","Novo Campo",IF(N6=G6,"Igual","Diferente")) -> Igual | P6: =IFERROR(VLOOKUP($B6,'LISTA - Atual'!$B$1:$I$444,7,0),"Novo") -> N | Q6: =IF(P6="Novo","Novo Campo",IF(P6=H6,"Igual","Diferente")) -> Igual | R6: n/a | S6: =IFERROR(VLOOKUP($B6,'LISTA - Atual'!$B$1:$I$444,8,0),"Novo") -> N | T6: =IF(S6="Novo","Novo Campo",IF(S6=J6,"Igual","Diferente")) -> Igual | U6: n/a | V6: N | W6: =IFERROR(VLOOKUP(B6,#REF!,11,0),"n/a") -> n/a | X6: =IFERROR(VLOOKUP(B6,#REF!,8,0),"n/a") -> n/a | Y6: =$F$2 -> ESTR | Z6: Sem alteração | AA6: =VLOOKUP(Table1[[#This Row],[CONCAT]],'Campos Resumo Prop2.0'!A:H,8,0) -> #N/A | AB6: DATE | AC6: n.a. | AD6: =INDEX(Auxiliar!$D$5:$I$10,MATCH('LISTA - Setembro2024'!AD$3,Auxiliar!$B$5:$B$10,0),MATCH('LISTA - Setembro2024'!$AC6,Auxiliar!$D$4:$I$4,0)) -> 0 | AE6: =INDEX(Auxiliar!$D$5:$I$10,MATCH('LISTA - Setembro2024'!AE$3,Auxiliar!$B$5:$B$10,0),MATCH('LISTA - Setembro2024'!$AC6,Auxiliar!$D$4:$I$4,0)) -> 0 | AF6: =INDEX(Auxiliar!$D$5:$I$10,MATCH('LISTA - Setembro2024'!AF$3,Auxiliar!$B$5:$B$10,0),MATCH('LISTA - Setembro2024'!$AC6,Auxiliar!$D$4:$I$4,0)) -> 0 | AG6: =IF(OR(AB6="Code List",AB6="Y, N"),AC6,"n.a.") -> n.a. | AH6: =INDEX(Auxiliar!$D$5:$I$10,MATCH('LISTA - Setembro2024'!AH$3,Auxiliar!$B$5:$B$10,0),MATCH('LISTA - Setembro2024'!$AG6,Auxiliar!$D$4:$I$4,0)) -> 0 | AI6: =INDEX(Auxiliar!$D$5:$I$10,MATCH('LISTA - Setembro2024'!AI$3,Auxiliar!$B$5:$B$10,0),MATCH('LISTA - Setembro2024'!$AC6,Auxiliar!$D$4:$I$4,0)) -> 0 | AJ6: =INDEX(Auxiliar!$D$5:$I$10,MATCH('LISTA - Setembro2024'!AJ$3,Auxiliar!$B$5:$B$10,0),MATCH('LISTA - Setembro2024'!$AC6,Auxiliar!$D$4:$I$4,0)) -> 0 | AK6: =SUM(AF6,AH6:AJ6) -> 0
A7: EN.004 | B7: =C7&"_"&D7 -> ENTITY_DT_DFLT_STTS | C7: ENTITY | D7: DT_DFLT_STTS | E7: Date of default status | F7: Y | G7: N | H7: N | I7: N | J7: N | K7: Y | L7: =IFERROR(VLOOKUP($B7,'LISTA - Atual'!$B$1:$I$444,5,0),"Novo") -> Y | M7: =IF(L7="Novo","Novo Campo",IF(L7=F7,"Igual","Diferente")) -> Igual | N7: =IFERROR(VLOOKUP($B7,'LISTA - Atual'!$B$1:$I$444,6,0),"Novo") -> N | O7: =IF(N7="Novo","Novo Campo",IF(N7=G7,"Igual","Diferente")) -> Igual | P7: =IFERROR(VLOOKUP($B7,'LISTA - Atual'!$B$1:$I$444,7,0),"Novo") -> N | Q7: =IF(P7="Novo","Novo Campo",IF(P7=H7,"Igual","Diferente")) -> Igual | R7: n/a | S7: =IFERROR(VLOOKUP($B7,'LISTA - Atual'!$B$1:$I$444,8,0),"Novo") -> N | T7: =IF(S7="Novo","Novo Campo",IF(S7=J7,"Igual","Diferente")) -> Igual | U7: n/a | V7: N | W7: =IFERROR(VLOOKUP(B7,#REF!,11,0),"n/a") -> n/a | X7: =IFERROR(VLOOKUP(B7,#REF!,8,0),"n/a") -> n/a | Y7: =$F$2 -> ESTR | Z7: Sem alteração | AA7: =VLOOKUP(Table1[[#This Row],[CONCAT]],'Campos Resumo Prop2.0'!A:H,8,0) -> #N/A | AB7: DATE | AC7: n.a. | AD7: =INDEX(Auxiliar!$D$5:$I$10,MATCH('LISTA - Setembro2024'!AD$3,Auxiliar!$B$5:$B$10,0),MATCH('LISTA - Setembro2024'!$AC7,Auxiliar!$D$4:$I$4,0)) -> 0 | AE7: =INDEX(Auxiliar!$D$5:$I$10,MATCH('LISTA - Setembro2024'!AE$3,Auxiliar!$B$5:$B$10,0),MATCH('LISTA - Setembro2024'!$AC7,Auxiliar!$D$4:$I$4,0)) -> 0 | AF7: =INDEX(Auxiliar!$D$5:$I$10,MATCH('LISTA - Setembro2024'!AF$3,Auxiliar!$B$5:$B$10,0),MATCH('LISTA - Setembro2024'!$AC7,Auxiliar!$D$4:$I$4,0)) -> 0 | AG7: =IF(OR(AB7="Code List",AB7="Y, N"),AC7,"n.a.") -> n.a. | AH7: =INDEX(Auxiliar!$D$5:$I$10,MATCH('LISTA - Setembro2024'!AH$3,Auxiliar!$B$5:$B$10,0),MATCH('LISTA - Setembro2024'!$AG7,Auxiliar!$D$4:$I$4,0)) -> 0 | AI7: =INDEX(Auxiliar!$D$5:$I$10,MATCH('LISTA - Setembro2024'!AI$3,Auxiliar!$B$5:$B$10,0),MATCH('LISTA - Setembro2024'!$AC7,Auxiliar!$D$4:$I$4,0)) -> 0 | AJ7: =INDEX(Auxiliar!$D$5:$I$10,MATCH('LISTA - Setembro2024'!AJ$3,Auxiliar!$B$5:$B$10,0),MATCH('LISTA - Setembro2024'!$AC7,Auxiliar!$D$4:$I$4,0)) -> 0 | AK7: =SUM(AF7,AH7:AJ7) -> 0 | AL7: Dependente de decisão
