Workbook
Name asefadf: #REF!
Name bn: #REF!

Sheet Sheet1
A1: LOANS Efectivo y otros depósitos a la vista / Cash balances and other deposits | B1: (All)
A2: LOANS Administraciones públicas / General governments | B2: (All)
A3: LOANS Entidades de crédito / Credit institutions | B3: (All)
A4: LOANS Otras sociedades financieras / Other financial corporations | B4: (All)
A5: LOANS Sociedad no financieras / Non financial corporations | B5: (All)
A6: LOANS Hogares / Households | B6: (All)
A7: DEBT SECURITIES | B7: (All)
A9: Row Labels | B9: Count of Data field
A10: ENTITY | B10: 85
A11: INSTR_ENTITY | B11: 5
A12: INSTR_PROTECTION | B12: 6
A13: INSTRUMENT | B13: 184
A14: PROTECTION | B14: 39
A15: Grand Total | B15: 319

Sheet READ ME - APPLICABILITY
B5: GUIDANCE ON THE APPLICABILITY OF LOAN TAPE' DATA FIELDS
B7: Corporation has performed an assessment of the applicability of data fields considering two axis:
B8: - counterparty sector (central banks, general governments, credit institutions, other financial corporations, non-financial corporations and households) and
B9: - type of product (cash and other demand deposits, debt securities and loans)
B11: As a consequence, within 'Overview' tab, columns F to M (highlighted in red) determine the applicability of data fields, considering the following rules:
B13: Possible values:
B14: - If remarked as 'Y' = Yes, it does apply, those fields might be applicable, depending on the characteristics of each instrument,entity or protection.
B16: - If remarked as 'N' = No, not applicable, it means that given the counterparty sector or the type of product we conclude that this field is not applicable and therefore,
B17: Unit shall informe these fields as 'Not applicable', with the proper format set up for each field (Date: 1111-11-11 ; Text: N/A ; Numeric: 11111111111).
B19: - If remarked as 'Corporation' = Field to be populated by Corporation, it means that the Unit will inform this field as not applicable, with the proper format
B20: set up for each field (Date: 1111-11-11 ; Text: N/A ; Numeric: 11111111111).
B22: Special case for debt securities:
... B24: given that 'Entity' table might be populated with loan information (in almost all cases, we estimate that the issuer of debt securities acquired will have direct exposures - loans as well).

Sheet Overview
A1: ID Data field / Field order | B1: Table | C1: Category | D1: Anacredit | E1: Data field | F1: Efectivo y otros depósitos a la vista / Cash balances and other deposits | G1: Bancos Centrales / Central Banks | H1: Administraciones públicas / General governments | I1: Entidades de crédito / Credit institutions | J1: Otras sociedades financieras / Other financial corporations | K1: Sociedades no financieras / Non financial corporations | L1: Hogares / Households | M1: DEBT SECURITIES (this column only applies to report the instrument table) | N1: Non-contractual balances and Accounting adjustments (this column only applies to report the instrument table) | O1: Instrument cancelled (this column only applies to report the instrument and instrument activity tables) | P1: Data Types | Q1: Guidance on data types | R1: Default value for missing data | S1: Default value for not applicable fields to be used WHEN the field is applicable for the corresponding segment (F to L columns ) | T1: Default value for not applicable fields to be used WHEN: (1) Non-contractual balances and accounting adjustments (2) If the field is not applicable for the corresponding segment (F to L columns) | U1: Field name | V1: Field Definition / Additional Guidance | W1: BDR Status (*) Not applicable = not identified as available in BDR | X1: BDR Definition | Y1: BDR Comments | Z1: Structural ECB Loan Tape | AA1: Green Dashboard | AB1: Pillar III ESG & CSRD | AC1: Green Finance | AD1: ESG Risks | AE1: Leveraged Finance | AF1: D + 15 [Green Dashboard] | AG1: D + 18 [+ Pillar III ESG] | AH1: > D + 18 [+ ECB Loan Tape]
A2: EN.001 | B2: ENTITY | C2: Cargabal entity | D2: N | E2: COD_SOC | F2: Y | G2: Y | H2: Y | I2: Y | J2: Y | K2: Y | L2: Y | P2: VARCHAR2(5) | Q2: Free (latin) text without special characters (semicolon, quotes, …) | R2: Default value not allowed | S2: Default value not allowed | T2: Default value not allowed | U2: Entity code of the informing society. | V2: Cargabal code or internal identifier of the informing society. | W2: Not applicable | X2: N/A | Y2: - | Z2: Y | AA2: N | AB2: Y | AC2: Y | AD2: Y | AE2: Y | AF2: N | AG2: Y | AH2: Y | AI2: =IF(AND(Z2="Y",AA2="Y",AB2="Y",AC2="Y",AD2="Y",AE2="Y"),"Y","")
A3: EN.002 | B3: ENTITY | C3: General | D3: Y | E3: CNTRY | F3: Y | G3: Y | H3: Y | I3: Y | J3: Y | K3: Y | L3: Y | P3: Code list | Q3: Use codes from the code list sheet | R3: MISS | S3: Default value not allowed | T3: N/A | U3: Country of counterparty residence | V3: Country of counterparty residence. | W3: Yes - Mapping | X3: BDR - Code List | Y3: - | Z3: Y | AA3: N | AB3: Y | AC3: Y | AD3: Y | AE3: Y | AF3: N | AG3: Y | AH3: Y | AI3: =IF(AND(Z3="Y",AA3="Y",AB3="Y",AC3="Y",AD3="Y",AE3="Y"),"Y","")
A4: EN.003 | B4: ENTITY | C4: General | D4: Y | E4: DT_BRTH | F4: N | G4: N | H4: N | I4: N | J4: N | K4: Y | L4: Y | P4: DATE | Q4: YYYY-MM-DD | R4: 0000-00-00 | S4: Default value not allowed | T4: 1111-11-11 | U4: Birth date counterparty | V4: Date when the entity was born / registered. | W4: Yes - Equivalent | X4: JM_CLIENT_BII - G4093_FECNACIM | Y4: - | Z4: Y | AA4: N | AB4: N | AC4: N | AD4: N | AE4: N | AF4: N | AG4: N | AH4: Y | AI4: =IF(AND(Z4="Y",AA4="Y",AB4="Y",AC4="Y",AD4="Y",AE4="Y"),"Y","")
A5: EN.004 | B5: ENTITY | C5: General | D5: Y | E5: DT_DFLT_STTS | F5: Y | G5: Y | H5: Y | I5: Y | J5: Y | K5: Y | L5: Y | P5: DATE | Q5: YYYY-MM-DD | R5: 0000-00-00 | S5: 1111-11-11 | T5: 1111-11-11 | U5: Date of default status | V5: The date on which the default status, as reported in the data attribute “Default status”, is considered to have arisen. If "Not in default" since inception then this attribute is to be reported equally to the inception date. If default classification performed on instrument level then Entity is classified as defaulted when at least one instrument is classified as defaulted. If more than one Instrument is classified as defaulted then the earliest date has to be provided. The definition of default is aligned with Art 178 of Regulation (EU) No 575/2013. | W5: Not applicable | X5: N/A | Y5: - | Z5: Y | AA5: N | AB5: N | AC5: N | AD5: N | AE5: Y | AF5: N | AG5: N | AH5: Y | AI5: =IF(AND(Z5="Y",AA5="Y",AB5="Y",AC5="Y",AD5="Y",AE5="Y"),"Y","")
A6: EN.005 | B6: ENTITY | C6: General | D6: N | E6: DT_FNNCL_STTMTS | F6: Y | G6: Y | H6: Y | I6: Y | J6: Y | K6: Y | L6: N | P6: DATE | Q6: YYYY-MM-DD | R6: 0000-00-00 | S6: 1111-11-11 | T6: 1111-11-11 | U6: Date of financial statements | V6: Date of financial statements. Please report on solo entity level unless advised otherwise. | W6: Not applicable | X6: N/A | Y6: - | Z6: Y | AA6: N | AB6: N | AC6: N | AD6: N | AE6: Y | AF6: N | AG6: N | AH6: Y | AI6: =IF(AND(Z6="Y",AA6="Y",AB6="Y",AC6="Y",AD6="Y",AE6="Y"),"Y","")
A7: EN.006 | B7: ENTITY | C7: General | D7: N | E7: DT_FNNCL_STTMTS_PRVS | F7: Y | G7: Y | H7: Y | I7: Y | J7: Y | K7: Y | L7: N | P7: DATE | Q7: YYYY-MM-DD | R7: 0000-00-00 | S7: 1111-11-11 | T7: 1111-11-11 | U7: Date of previous fiscal year financial statements | V7: Date of previous fiscal year financial statements. Please report on solo entity level unless advised otherwise. | W7: Not applicable | X7: N/A | Y7: - | Z7: Y | AA7: N | AB7: N | AC7: N | AD7: N | AE7: Y | AF7: N | AG7: N | AH7: Y | AI7: =IF(AND(Z7="Y",AA7="Y",AB7="Y",AC7="Y",AD7="Y",AE7="Y"),"Y","")
A8: EN.007 | B8: ENTITY | C8: General | D8: Y | E8: DT_INTTN_LGL_PRCDNGS_LE | F8: Y | G8: Y | H8: Y | I8: Y | J8: Y | K8: Y | L8: Y | P8: DATE | Q8: YYYY-MM-DD | R8: 0000-00-00 | S8: 1111-11-11 | T8: 1111-11-11 | U8: Date of initiation of legal proceedings counterparty (LE) | V8: Date of initiation of legal proceedings counterparty (LE). Only for Retail portfolios: The date when the hard collection process was initiated for given entity. If the hard collection process is defined on the level of instrument or protection and more instruments or protections with status "Other legal measures" are linked to the same entity the oldest date is reported. | W8: Yes - Computed | X8: IF E0623_GEST_SIT in (8;9) THEN E0623_FECULTMO | Y8: - | Z8: Y | AA8: N | AB8: N | AC8: N | AD8: N | AE8: Y | AF8: N | AG8: N | AH8: Y | AI8: =IF(AND(Z8="Y",AA8="Y",AB8="Y",AC8="Y",AD8="Y",AE8="Y"),"Y","")
A9: EN.008 | B9: ENTITY | C9: General | D9: N | E9: DT_PRFRMNG_STTS_LE | F9: Y | G9: Y | H9: Y | I9: Y | J9: Y | K9: Y | L9: Y | P9: DATE | Q9: YYYY-MM-DD | R9: 0000-00-00 | S9: 1111-11-11 | T9: 1111-11-11 | U9: Date of performing status | V9: The date at which the latest change of the performing status according to Part 17 of Annex V to Implementing Regulation (EU) No 680/2014 occurred. For entities performing from inception this date should be equal to inception date. | W9: Not applicable | X9: N/A | Y9: - | Z9: Y | AA9: N | AB9: N | AC9: N | AD9: N | AE9: Y | AF9: N | AG9: N | AH9: Y | AI9: =IF(AND(Z9="Y",AA9="Y",AB9="Y",AC9="Y",AD9="Y",AE9="Y"),"Y","")
A10: EN.009 | B10: ENTITY | C10: General | D10: Y | E10: DT_RFRNC | F10: Y | G10: Y | H10: Y | I10: Y | J10: Y | K10: Y | L10: Y | P10: DATE | Q10: YYYY-MM-DD | R10: Default value not allowed | S10: Default value not allowed | T10: Default value not allowed | U10: Reference date. | V10: Reference date. The reference date can refer to end-of-month, end-of-quarter or end-of-year. The value is fixed for the entire loan tape and will be defined and communicated by the Head of Mission. | W10: Not applicable | X10: N/A | Y10: - | Z10: Y | AA10: N | AB10: Y | AC10: Y | AD10: N | AE10: Y | AF10: N | AG10: Y | AH10: Y | AI10: =IF(AND(Z10="Y",AA10="Y",AB10="Y",AC10="Y",AD10="Y",AE10="Y"),"Y","")
A11: EN.010 | B11: ENTITY | C11: General | D11: Y | E11: ENTTY_ID | F11: Y | G11: Y | H11: Y | I11: Y | J11: Y | K11: Y | L11: Y | P11: VARCHAR2(255) | Q11: Free (latin) text without special characters (semicolon, quotes, …) | R11: Default value not allowed | S11: Default value not allowed | T11: Default value not allowed | U11: Entity ID | V11: An identifier applied by the reporting agent to uniquely identify each counterparty. Each counterparty has a unique and exclusive counterparty identifier. This means that this value will not change over time and can never be used as the counterparty identifier for any other counterparty. | W11: Not applicable | X11: N/A | Y11: - | Z11: Y | AA11: N | AB11: Y | AC11: Y | AD11: Y | AE11: Y | AF11: N | AG11: Y | AH11: Y | AI11: =IF(AND(Z11="Y",AA11="Y",AB11="Y",AC11="Y",AD11="Y",AE11="Y"),"Y","")
A12: EN.011 | B12: ENTITY | C12: General | D12: N | E12: GCC_PRNT_ID | F12: Y | G12: Y | H12: Y | I12: Y | J12: Y | K12: Y | L12: N | P12: VARCHAR2(255) | Q12: Free (latin) text without special characters (semicolon, quotes, …) | R12: MISS | S12: N/A | T12: N/A | U12: Identifier for the parent entity of a group of connected clients | V12: The unique identifier of the group of connected clients according to Art 4 para. 39 of Regulation (EU) No 575/2013. If an entity is part of more than one group of connected clients please report the identifier for the most relevant. | W12: Yes - Equivalent | X12: JM_GRUP_ECONO - G5512_GRUP_ECO | Y12: - | Z12: Y | AA12: N | AB12: N | AC12: N | AD12: N | AE12: Y | AF12: N | AG12: N | AH12: Y | AI12: =IF(AND(Z12="Y",AA12="Y",AB12="Y",AC12="Y",AD12="Y",AE12="Y"),"Y","")
A13: EN.012 | B13: ENTITY | C13: General | D13: N | E13: GCC_PRNT_NM | F13: Y | G13: Y | H13: Y | I13: Y | J13: Y | K13: Y | L13: N | P13: VARCHAR2(255) | Q13: Free (latin) text without special characters (semicolon, quotes, …) | R13: MISS | S13: N/A | T13: N/A | U13: Name of the parent entity of a group of connected clients | V13: The name of the group of connected clients according to Art 4 para. 39 of Regulation (EU) No 575/2013. If an entity is part of more than one group of connected clients please report the name for the most relevant. | W13: Yes - Equivalent | X13: JM_GRUP_ECONO - G5512_DGRUPO | Y13: Report Name of the entity reported in EN.011 | Z13: Y | AA13: N | AB13: N | AC13: N | AD13: N | AE13: Y | AF13: N | AG13: N | AH13: Y | AI13: =IF(AND(Z13="Y",AA13="Y",AB13="Y",AC13="Y",AD13="Y",AE13="Y"),"Y","")
... A18: EN.017 | B18: ENTITY | C18: General | D18: N | E18: EXTRNL_RTNG_NM | F18: Y | G18: Y | H18: Y | I18: Y | J18: Y | K18: Y | L18: N | P18: VARCHAR2(255) | Q18: Free (latin) text without special characters (semicolon, quotes, …) | R18: MISS | S18: N/A | T18: N/A | U18: Name of external rating agency | V18: Name of external rating agency for the external rating at the reference date. | W18: Yes - Equivalent | X18: JM_CAL_EXT_CL - R9415_COD_AGEN | Y18: - | Z18: Y | AA18: N | AB18: N | AC18: N | AD18: N | AE18: Y | AF18: N | AG18: N | AH18: Y | AI18: =IF(AND(Z18="Y",AA18="Y",AB18="Y",AC18="Y",AD18="Y",AE18="Y"),"Y","")
A19: EN.018 | B19: ENTITY | C19: Classification | D19: Y | E19: ACCNTNG_FRMWRK_SL | F19: Y | G19: Y | H19: Y | I19: Y | J19: Y | K19: Y | L19: N | P19: =HYPERLINK("#"&"CodeList!"&ADDRESS(2,MATCH($E19,CodeList!$2:$2,0)+1,),"Code List") -> Code List | Q19: Use codes from the code list sheet | R19: 99999999999 | S19: 11111111111 | T19: 11111111111 | U19: Accounting standard counterparty | V19: Accounting standard counterparty. | W19: Not applicable | X19: N/A | Y19: - | Z19: Y | AA19: N | AB19: N | AC19: N | AD19: N | AE19: Y | AF19: N | AG19: N | AH19: Y | AI19: =IF(AND(Z19="Y",AA19="Y",AB19="Y",AC19="Y",AD19="Y",AE19="Y"),"Y","")
A20: EN.019 | B20: ENTITY | C20: Classification | D20: N | E20: CR_FLG | F20: Y | G20: Y | H20: Y | I20: Y | J20: Y | K20: Y | L20: Y | P20: Y, N | Q20: Boolean: Y/N | R20: MISS | S20: N/A | T20: N/A | U20: Cure flag for entity which was classified as non-performing in the last 1.5 years and is classified as performing at the reference date | V20: The entity is to be classified on the reference date under one of the following categories: performing or non-performing, in accordance with Annex V to Implementing Regulation (EU) No 680/2014. | W20: Yes - Computed | X20: IF H0883_IND_CURA = 1 THEN T; ELSE IF H0883_IND_CURA = 0 THEN F; THEN N/A | Y20: - | Z20: Y | AA20: N | AB20: N | AC20: N | AD20: N | AE20: N | AF20: N | AG20: N | AH20: Y | AI20: =IF(AND(Z20="Y",AA20="Y",AB20="Y",AC20="Y",AD20="Y",AE20="Y"),"Y","")
A21: EN.020 | B21: ENTITY | C21: Classification | D21: N | E21: DCSD | F21: N | G21: N | H21: N | I21: N | J21: N | K21: N | L21: Y | P21: Y, N | Q21: Boolean: Y/N | R21: MISS | S21: N/A | T21: N/A | U21: Entity deceased | V21: Indicator as to whether the Entity has passed away. The data attribute is applicable to natural persons only. | W21: Not applicable | X21: N/A | Y21: - | Z21: Y | AA21: N | AB21: N | AC21: N | AD21: N | AE21: N | AF21: N | AG21: N | AH21: Y | AI21: =IF(AND(Z21="Y",AA21="Y",AB21="Y",AC21="Y",AD21="Y",AE21="Y"),"Y","")
A22: EN.021 | B22: ENTITY | C22: Classification | D22: Y | E22: DFLT_STTS | F22: Y | G22: Y | H22: Y | I22: Y | J22: Y | K22: Y | L22: Y | P22: =HYPERLINK("#"&"CodeList!"&ADDRESS(2,MATCH($E22,CodeList!$2:$2,0)+1,),"Code List") -> Code List | Q22: Use codes from the code list sheet | R22: 99999999999 | S22: 11111111111 | T22: 11111111111 | U22: Default status of the entity | V22: Identification of the default status of the counterparty. Categories describing the motives for which the counterparty can be in default in accordance with Article 178 of Regulation (EU) No 575/2013. For retail only: If default classification performed on instrument level then Entity is classified as defaulted when at least one instrument is classified as defaulted. For corporate, SME, CRE and LF: if default classification performed on instrument level then entity level is "not applicable". | W22: Not applicable | X22: N/A | Y22: - | Z22: Y | AA22: N | AB22: N | AC22: N | AD22: N | AE22: Y | AF22: N | AG22: N | AH22: Y | AI22: =IF(AND(Z22="Y",AA22="Y",AB22="Y",AC22="Y",AD22="Y",AE22="Y"),"Y","")
A23: EN.022 | B23: ENTITY | C23: Classification | D23: N | E23: DT_EXTRNL_RTNG | F23: Y | G23: Y | H23: Y | I23: Y | J23: Y | K23: Y | L23: N | P23: DATE | Q23: YYYY-MM-DD | R23: 0000-00-00 | S23: 1111-11-11 | T23: 1111-11-11 | U23: Date of external rating | V23: Date of the most recent external rating, i.e. applicable at the reference date. | W23: Yes - Equivalent | X23: JM_CAL_EXT_CL - R9415_FECCALIF | Y23: - | Z23: Y | AA23: N | AB23: N | AC23: N | AD23: N | AE23: Y | AF23: N | AG23: N | AH23: Y | AI23: =IF(AND(Z23="Y",AA23="Y",AB23="Y",AC23="Y",AD23="Y",AE23="Y"),"Y","")
A24: EN.023 | B24: ENTITY | C24: Classification | D24: N | E24: DT_INTRNL_RTNG | F24: Y | G24: Y | H24: Y | I24: Y | J24: Y | K24: Y | L24: Y | P24: DATE | Q24: YYYY-MM-DD | R24: 0000-00-00 | S24: 1111-11-11 | T24: 1111-11-11 | U24: Date of internal rating | V24: Date of the most recent internal rating according to Regulation (EU) No 575/2013, i.e. applicable rating as at the reference date. If the rating is assigned on instrument level then provide the rating for the instrument with the highest EAD. | W24: Yes - Equivalent | X24: JM_CAL_IN_CL - E9954_FECCALI | Y24: - | Z24: Y | AA24: N | AB24: N | AC24: N | AD24: N | AE24: Y | AF24: N | AG24: N | AH24: Y | AI24: =IF(AND(Z24="Y",AA24="Y",AB24="Y",AC24="Y",AD24="Y",AE24="Y"),"Y","")
A25: EN.024 | B25: ENTITY | C25: Classification | D25: Y | E25: ECNMC_ACTVTY | F25: N | G25: Y | H25: Y | I25: Y | J25: Y | K25: Y | L25: N | P25: Code list | Q25: Use codes from the code list sheet | R25: MISS | S25: N/A | T25: N/A | U25: Economic activity counterparty | V25: The level four NACE code in accordance with Regulation (EC) No 1893/2006 is generally reported. If the level four NACE code is not available it may be allowed to report a level three or level two NACE code. | W25: Not applicable | X25: N/A | Y25: - | Z25: Y | AA25: N | AB25: Y | AC25: Y | AD25: Y | AE25: Y | AF25: N | AG25: Y | AH25: Y | AI25: =IF(AND(Z25="Y",AA25="Y",AB25="Y",AC25="Y",AD25="Y",AE25="Y"),"Y","")
A26: EN.025 | B26: ENTITY | C26: Classification | D26: N | E26: EMPLYMNT_STTS_INTRNL | F26: N | G26: N | H26: N | I26: N | J26: N | K26: N | L26: Y | P26: VARCHAR2(255) | Q26: Free (latin) text without special characters (semicolon, quotes, …) | R26: MISS | S26: N/A | T26: N/A | U26: Employment status according to bank-internal classification | V26: Employment status according to bank-internal classification. | W26: Not applicable | X26: N/A | Y26: - | Z26: Y | AA26: N | AB26: N | AC26: N | AD26: N | AE26: N | AF26: N | AG26: N | AH26: Y | AI26: =IF(AND(Z26="Y",AA26="Y",AB26="Y",AC26="Y",AD26="Y",AE26="Y"),"Y","")
A27: EN.026 | B27: ENTITY | C27: Classification | D27: N | E27: EMPLYMNT_STTS | F27: N | G27: N | H27: N | I27: N | J27: N | K27: N | L27: Y | P27: =HYPERLINK("#"&"CodeList!"&ADDRESS(2,MATCH($E27,CodeList!$2:$2,0)+1,),"Code List") -> Code List | Q27: Use codes from the code list sheet | R27: 99999999999 | S27: 11111111111 | T27: 11111111111 | U27: Employment status (Code List) | V27: Employment status. | W27: Not applicable | X27: N/A | Y27: - | Z27: Y | AA27: N | AB27: N | AC27: N | AD27: N | AE27: N | AF27: N | AG27: N | AH27: Y | AI27: =IF(AND(Z27="Y",AA27="Y",AB27="Y",AC27="Y",AD27="Y",AE27="Y"),"Y","")
A28: EN.027 | B28: ENTITY | C28: Classification | D28: Y | E28: ENTRPRS_SZ_LE | F28: N | G28: N | H28: N | I28: N | J28: N | K28: Y | L28: N | P28: =HYPERLINK("#"&"CodeList!"&ADDRESS(2,MATCH($E28,CodeList!$2:$2,0)+1,),"Code List") -> Code List | Q28: Use codes from the code list sheet | R28: 99999999999 | S28: 11111111111 | T28: 11111111111 | U28: Enterprise size Counterparty (LE) | V28: Enterprise size counterparty (LE). Classification of enterprises by size, in accordance with the Annex to Commission Recommendation 2003/361/EC. However, if the local NCB decides not to request this attribute as part of the AnaC reporting data set then please report "Not applicable". | W28: Yes - Computed | X28: IF ((G5508_NUM_EMPL IS <250 AND >=50) AND ((G5508_IMPFACTM <=50MM) OR (G5508_TOT_ACTI<=43MM))) THEN 2; ELSE IF ((G5508_NUM_EMPL IS <50 AND >=10) AND ((G5508_IMPFACTM <=10MM) OR (G5508_TOT_ACTI<=10MM))) THEN 3; ELSE IF ((G5508_NUM_EMPL IS <10) AND ((G5508_IMPFACTM <=2MM) OR (G5508_TOT_ACTI<=2MM))) THEN 4; ELSE 1 | Y28: - | Z28: Y | AA28: N | AB28: N | AC28: N | AD28: N | AE28: N | AF28: N | AG28: N | AH28: Y | AI28: =IF(AND(Z28="Y",AA28="Y",AB28="Y",AC28="Y",AD28="Y",AE28="Y"),"Y","")
A29: EN.028 | B29: ENTITY | C29: Classification | D29: N | E29: EXTRNL_RTNG | F29: Y | G29: Y | H29: Y | I29: Y | J29: Y | K29: Y | L29: N | P29: Code List | Q29: Use codes from the code list sheet | R29: 99999999999 | S29: 11111111111 | T29: 11111111111 | U29: External rating | V29: External rating at the reference date. | W29: Yes - Computed | X29: R9415_CALIFMAE following the conditions: 1) In those cases in which more than one ECAI provides an external rating: - Where two credit assessments are available from nominated ECAIs and the two correspond to different risk weights for a rated item, the higher risk weight shall be assigned - Where more than two credit assessments are available from nominated ECAIs for a rated item, the two assessments generating the two lowest risk weights shall be referred to. If the two lowest risk weights are different, the higher risk weight shall be assigned. If the two lowest risk weights are the same, that risk weight shall be assigned 2) If the rating is not available, the unit should report “99999999999” in the Loan Tape. In case, for example, of exposures calculated under the IRB approach, where the external rating does not apply, the expected value is “11111111111” 3) If the client was not part of any applicable portfolio in the prior year, the value informed should be “11111111111”, as not applicable | Y29: - | Z29: Y | AA29: N | AB29: N | AC29: N | AD29: N | AE29: Y | AF29: N | AG29: N | AH29: Y | AI29: =IF(AND(Z29="Y",AA29="Y",AB29="Y",AC29="Y",AD29="Y",AE29="Y"),"Y","")
A30: EN.029 | B30: ENTITY | C30: Classification | D30: N | E30: EXTRNL_RTNG_PRVS | F30: Y | G30: Y | H30: Y | I30: Y | J30: Y | K30: Y | L30: N | P30: Code List | Q30: Use codes from the code list sheet | R30: 99999999999 | S30: 11111111111 | T30: 11111111111 | U30: External rating T-1 | V30: External rating one year prior to the reference date. | W30: Yes - Computed | X30: R9415_CALIFMAE having R9415_CALIFMAE one year prior to the reference date and following the conditions: 1) In those cases in which more than one ECAI provides an external rating: - Where two credit assessments are available from nominated ECAIs and the two correspond to different risk weights for a rated item, the higher risk weight shall be assigned - Where more than two credit assessments are available from nominated ECAIs for a rated item, the two assessments generating the two lowest risk weights shall be referred to. If the two lowest risk weights are different, the higher risk weight shall be assigned. If the two lowest risk weights are the same, that risk weight shall be assigned 2) If the rating is not available, the unit should report “99999999999” in the Loan Tape. In case, for example, of exposures calculated under the IRB approach, where the external rating does not apply, the expected value is “11111111111” 3) If the client was not part of any applicable portfolio in the prior year, the value informed should be “11111111111”, as not applicable | Y30: - | Z30: Y | AA30: N | AB30: N | AC30: N | AD30: N | AE30: Y | AF30: N | AG30: N | AH30: Y | AI30: =IF(AND(Z30="Y",AA30="Y",AB30="Y",AC30="Y",AD30="Y",AE30="Y"),"Y","")
A31: EN.030 | B31: ENTITY | C31: Classification | D31: N | E31: FLG_BNKRPTCY_IN_GRP | F31: N | G31: Y | H31: Y | I31: Y | J31: Y | K31: Y | L31: N | P31: Y, N | Q31: Boolean: Y/N | R31: MISS | S31: N/A | T31: N/A | U31: Any legal entity within the group of connected clients of the debtor (incl. subsidiaries of the debtor) has filed bankruptcy application | V31: Report "Y' if any legal entity within the group of connected clients of the debtor (incl. subsidiaries of the debtor) has filed bankruptcy application according to local insolvency law. | W31: Yes - Computed | X31: IF G4093_UTP_CLI = 00001 for any of the related clientes (necessary to identify the Group of the cliente (E1963_GRUP_ECO) and then all the connected clients (E1963_IDNUMCLI) for this Group) THEN Y; ELSE N | Y31: - | Z31: Y | AA31: N | AB31: N | AC31: N | AD31: N | AE31: N | AF31: N | AG31: N | AH31: Y | AI31: =IF(AND(Z31="Y",AA31="Y",AB31="Y",AC31="Y",AD31="Y",AE31="Y"),"Y","")
A32: EN.031 | B32: ENTITY | C32: Classification | D32: N | E32: FLG_HGH_CDS | F32: Y | G32: Y | H32: Y | I32: Y | J32: Y | K32: Y | L32: N | P32: Y, N | Q32: Boolean: Y/N | R32: MISS | S32: N/A | T32: N/A | U32: 5Y CDS > 1,000bps over the last 12 months | V32: Report "Y" if 5Y CDS > 1,000bps over the last 12 months. The flag would be required to be reported "Y" if the 5y CDS spread of a debtor is at least once greater or equal 1000bps within the last 12 months. | W32: Not applicable | X32: N/A | Y32: - | Z32: Y | AA32: N | AB32: N | AC32: N | AD32: N | AE32: N | AF32: N | AG32: N | AH32: Y | AI32: =IF(AND(Z32="Y",AA32="Y",AB32="Y",AC32="Y",AD32="Y",AE32="Y"),"Y","")
A33: EN.032 | B33: ENTITY | C33: Classification | D33: N | E33: FLG_ISDA_CRDT_EVNT | F33: Y | G33: Y | H33: Y | I33: Y | J33: Y | K33: Y | L33: N | P33: Y, N | Q33: Boolean: Y/N | R33: MISS | S33: N/A | T33: N/A | U33: ISDA credit event declared | V33: The flag would be required to be reported "Y" if a credit event occurred under any ISDA master agreement associated with this debtor. | W33: Not applicable | X33: N/A | Y33: - | Z33: Y | AA33: N | AB33: N | AC33: N | AD33: N | AE33: N | AF33: N | AG33: N | AH33: Y | AI33: =IF(AND(Z33="Y",AA33="Y",AB33="Y",AC33="Y",AD33="Y",AE33="Y"),"Y","")
A34: EN.033 | B34: ENTITY | C34: Classification | D34: N | E34: FLG_NN_ACCRL | F34: N | G34: N | H34: N | I34: N | J34: N | K34: Y | L34: Y | P34: Y, N | Q34: Boolean: Y/N | R34: MISS | S34: N/A | T34: N/A | U34: Credit obligation on non-accrual status | V34: Report "Y" if any credit obligation associated to this debtor is set on non-accrual status. | W34: Not applicable | X34: N/A | Y34: - | Z34: Y | AA34: N | AB34: N | AC34: N | AD34: N | AE34: N | AF34: N | AG34: N | AH34: Y | AI34: =IF(AND(Z34="Y",AA34="Y",AB34="Y",AC34="Y",AD34="Y",AE34="Y"),"Y","")
A35: EN.034 | B35: ENTITY | C35: Classification | D35: N | E35: FLG_RQST_BNKRPTCY | F35: N | G35: Y | H35: Y | I35: Y | J35: Y | K35: Y | L35: N | P35: Y, N | Q35: Boolean: Y/N | R35: MISS | S35: N/A | T35: N/A | U35: Request by the institution for the obligor's bankruptcy | V35: Flag "Y" if bankruptcy proceedings have been initiated by the bank according to local insolvency law, e.g. due to illiquidity, over-indebtedness. | W35: Not applicable | X35: N/A | Y35: - | Z35: Y | AA35: N | AB35: N | AC35: N | AD35: N | AE35: N | AF35: N | AG35: N | AH35: Y | AI35: =IF(AND(Z35="Y",AA35="Y",AB35="Y",AC35="Y",AD35="Y",AE35="Y"),"Y","")
A36: EN.035 | B36: ENTITY | C36: Classification | D36: N | E36: FLG_RQST_DSTRSSD_RSTRCTRNG | F36: N | G36: N | H36: N | I36: N | J36: N | K36: Y | L36: Y | P36: Y, N | Q36: Boolean: Y/N | R36: MISS | S36: N/A | T36: N/A | U36: Request for current concession of forbearance measures as defined in EBA/ITS/2013/03 resulting in distressed restructuring of the credit obligation | V36: Report "Y" if there is a request for current concession of forbearance measures as defined in EBA/ITS/2013/03 resulting in distressed restructuring of the credit obligation. | W36: Not applicable | X36: N/A | Y36: - | Z36: Y | AA36: N | AB36: N | AC36: N | AD36: N | AE36: N | AF36: N | AG36: N | AH36: Y | AI36: =IF(AND(Z36="Y",AA36="Y",AB36="Y",AC36="Y",AD36="Y",AE36="Y"),"Y","")
A37: EN.036 | B37: ENTITY | C37: Classification | D37: N | E37: FLG_RQST_EMRGNCY_FNDNG | F37: N | G37: N | H37: N | I37: N | J37: Y | K37: Y | L37: Y | P37: Y, N | Q37: Boolean: Y/N | R37: MISS | S37: Default value not allowed | T37: N/A | U37: Request by the debtor for emergency funding from the bank | V37: Report "Y" if there is a request by the debtor for emergency funding from the bank. | W37: Not applicable | X37: N/A | Y37: - | Z37: Y | AA37: N | AB37: N | AC37: N | AD37: N | AE37: Y | AF37: N | AG37: N | AH37: Y | AI37: =IF(AND(Z37="Y",AA37="Y",AB37="Y",AC37="Y",AD37="Y",AE37="Y"),"Y","")
A38: EN.037 | B38: ENTITY | C38: Classification | D38: N | E38: FLG_SLL_WTH_LSS | F38: N | G38: Y | H38: Y | I38: Y | J38: Y | K38: Y | L38: N | P38: Y, N | Q38: Boolean: Y/N | R38: MISS | S38: N/A | T38: N/A | U38: Sell of a credit obligation with material credit related economic loss (>= 5%) | V38: Report "Y" if there is a sell of a credit obligation with material credit related economic loss (>= 5%) according to EBA/GL/2016/07 para 44. | W38: Yes - Computed | X38: IF T2437_SITGESND = 23 THEN Y; ELSE N | Y38: - | Z38: Y | AA38: N | AB38: N | AC38: N | AD38: N | AE38: N | AF38: N | AG38: N | AH38: Y | AI38: =IF(AND(Z38="Y",AA38="Y",AB38="Y",AC38="Y",AD38="Y",AE38="Y"),"Y","")
A39: EN.038 | B39: ENTITY | C39: Classification | D39: N | E39: INCM_SC | F39: N | G39: N | H39: N | I39: N | J39: N | K39: N | L39: Y | P39: Y, N | Q39: Boolean: Y/N | R39: MISS | S39: N/A | T39: N/A | U39: Income self-certified | V39: The data field applicable to natural persons only should be flagged "Y" if the counterpart has no other source of income certification than its own personal declaration, e.g. absence of payroll or tax declaration forms. | W39: Yes - Computed | X39: IF H0780_INGCLIEN is informed and H0780_FLGACSLD = 1 THEN Y; ELSE N | Y39: - | Z39: Y | AA39: N | AB39: N | AC39: N | AD39: N | AE39: N | AF39: N | AG39: N | AH39: Y | AI39: =IF(AND(Z39="Y",AA39="Y",AB39="Y",AC39="Y",AD39="Y",AE39="Y"),"Y","")
A40: EN.039 | B40: ENTITY | C40: Classification | D40: N | E40: INTRNL_RTNG | F40: Y | G40: Y | H40: Y | I40: Y | J40: Y | K40: Y | L40: Y | P40: =HYPERLINK("#"&"CodeList!"&ADDRESS(2,MATCH($E40,CodeList!$2:$2,0)+1,),"Code List") -> Code List | Q40: Use codes from the code list sheet | R40: MISS | S40: N/A | T40: N/A | U40: Internal rating at reference date | V40: Internal rating at the reference date according to Regulation (EU) No 575/2013. Please also add in sheet "Code List" the list of values used, i.e. bank-internal masterscale. | W40: Not applicable | X40: N/A | Y40: - | Z40: Y | AA40: N | AB40: N | AC40: N | AD40: N | AE40: Y | AF40: N | AG40: N | AH40: Y | AI40: =IF(AND(Z40="Y",AA40="Y",AB40="Y",AC40="Y",AD40="Y",AE40="Y"),"Y","")
A41: EN.040 | B41: ENTITY | C41: Classification | D41: N | E41: INTRNL_RTNG_PRVS | F41: Y | G41: Y | H41: Y | I41: Y | J41: Y | K41: Y | L41: Y | P41: =HYPERLINK("#"&"CodeList!"&ADDRESS(2,MATCH($E41,CodeList!$2:$2,0)+1,),"Code List") -> Code List | Q41: Use codes from the code list sheet | R41: MISS | S41: N/A | T41: N/A | U41: Previous internal rating | V41: Internal rating according to Regulation (EU) No 575/2013 one year prior to the reference date. | W41: Not applicable | X41: N/A | Y41: - | Z41: Y | AA41: N | AB41: N | AC41: N | AD41: N | AE41: Y | AF41: N | AG41: N | AH41: Y | AI41: =IF(AND(Z41="Y",AA41="Y",AB41="Y",AC41="Y",AD41="Y",AE41="Y"),"Y","")
A42: EN.041 | B42: ENTITY | C42: Classification | D42: Y | E42: LGL_PRCDNG_STTS_LE | F42: Y | G42: Y | H42: Y | I42: Y | J42: Y | K42: Y | L42: Y | P42: =HYPERLINK("#"&"CodeList!"&ADDRESS(2,MATCH($E42,CodeList!$2:$2,0)+1,),"Code List") -> Code List | Q42: Use codes from the code list sheet | R42: 99999999999 | S42: Default value not allowed | T42: Default value not allowed | U42: Legal proceedings status Counterparty (LE) | V42: Legal proceedings status Counterparty (LE). Only for Retail portfolios: Status "No legal action taken" or "Other legal measures" are possible. Status "Other legal measures" is reported when the hard collection process was initiated at the level of a given entity or at the level of any associated instrument or protection of this entity. | W42: Yes - Computed | X42: IF T1824_GEST_SIT in (8) THEN LGL_PRCDNG_STTS = 2; ELSE IF G4093_UTP_CLI = 00001 THEN 3; ELSE 1 | Y42: - | Z42: Y | AA42: N | AB42: N | AC42: N | AD42: N | AE42: Y | AF42: N | AG42: N | AH42: Y | AI42: =IF(AND(Z42="Y",AA42="Y",AB42="Y",AC42="Y",AD42="Y",AE42="Y"),"Y","")
A43: EN.042 | B43: ENTITY | C43: Classification | D43: N | E43: OWND_BY_SPNSR | F43: N | G43: N | H43: N | I43: N | J43: Y | K43: Y | L43: N | P43: Y, N | Q43: Boolean: Y/N | R43: MISS | S43: N/A | T43: N/A | U43: >50% owned by a sponsor as per ECB Guidance on leveraged transactions | V43: In accordance the ECB Guidance on Leveraged Transactions. As per point (37) of Article 4(1) of Regulation (EU) No 575/2013, a financial sponsor is deemed to be the owner if it controls or owns more than 50% of the borrower’s equity. The term “financial sponsor” refers to an investment firm that undertakes private equity investments in and/or leveraged buyouts of companies with the intention of exiting those investments on a mediumterm basis | W43: Not applicable | X43: N/A | Y43: - | Z43: Y | AA43: N | AB43: N | AC43: N | AD43: N | AE43: Y | AF43: N | AG43: N | AH43: Y | AI43: =IF(AND(Z43="Y",AA43="Y",AB43="Y",AC43="Y",AD43="Y",AE43="Y"),"Y","")
A44: EN.043 | B44: ENTITY | C44: Classification | D44: N | E44: PRFRMNG_STTS_LE | F44: Y | G44: Y | H44: Y | I44: Y | J44: Y | K44: Y | L44: Y | P44: =HYPERLINK("#"&"CodeList!"&ADDRESS(2,MATCH($E44,CodeList!$2:$2,0)+1,),"Code List") -> Code List | Q44: Use codes from the code list sheet | R44: 99999999999 | S44: 11111111111 | T44: 11111111111 | U44: Performing status | V44: Performing status. Identification of the performing status of the counterparty. Categories describing the motives for which the counterparty can be non-performing in accordance with Implementing Technical Standard (ITS) on Supervisory Reporting (Forbearance and non-performing exposures). For retail only: If performing classification performed on instrument level then Entity is classified as non-performing when at least one instrument is classified as non-performing For corporate, SME, CRE and LF: if default classification performed on instrument level then entity level is "not applicable". | W44: Not applicable | X44: N/A | Y44: - | Z44: Y | AA44: N | AB44: N | AC44: N | AD44: N | AE44: Y | AF44: N | AG44: N | AH44: Y | AI44: =IF(AND(Z44="Y",AA44="Y",AB44="Y",AC44="Y",AD44="Y",AE44="Y"),"Y","")
...

Sheet CodeList
A1: Table | B1: INSTRUMENT | D1: INSTRUMENT / ENTITY | F1: INSTRUMENT / PROTECTION | H1: INSTRUMENT | J1: INSTRUMENT | L1: PROTECTION | N1: PROTECTION | P1: INSTRUMENT | R1: INSTRUMENT | T1: INSTRUMENT | V1: INSTRUMENT | X1: INSTRUMENT | Z1: INSTRUMENT | AB1: INSTRUMENT | AD1: INSTRUMENT | AF1: INSTRUMENT | AH1: INSTRUMENT | AJ1: INSTRUMENT | AL1: INSTRUMENT / ENTITY | AN1: INSTRUMENT / ENTITY | AP1: INSTRUMENT | AR1: INSTRUMENT | AT1: INSTRUMENT | AV1: INSTRUMENT | AX1: INSTRUMENT | AZ1: INSTRUMENT | BB1: INSTRUMENT | BD1: INSTRUMENT | BF1: INSTRUMENT | BH1: INSTRUMENT | BJ1: INSTRUMENT | BL1: INSTRUMENT | BN1: INSTRUMENT | BP1: INSTRUMENT | BR1: INSTRUMENT | BT1: ENTITY | BV1: PROTECTION | BX1: PROTECTION | BZ1: PROTECTION | CB1: PROTECTION | CD1: PROTECTION | CF1: PROTECTION | CH1: ENTITY | CJ1: ENTITY | CL1: ENTITY/PROTECTION | CN1: ENTITY | CP1: ENTITY | CR1: ENTITY | CT1: ENTITY | CV1: ENTITY | CX1: ENTITY | CZ1: INSTRUMENT / ENTITY | DB1: INSTRUMENT | DD1: ENTITY | DF1: INSTRUMENT / ENTITY | DH1: ENTITY | DJ1: INSTRUMENT_C19 | DL1: INSTRUMENT_C19 | DN1: INSTRUMENT_C19 | DP1: INSTRUMENT_C19 | DR1: INSTRUMENT | DT1: INSTRUMENT | DV1: INSTRUMENT | DX1: INSTRUMENT | DZ1: INSTRUMENT | EB1: INSTRUMENT | ED1: INSTRUMENT | EF1: INSTRUMENT | EH1: INSTRUMENT | EJ1: INSTRUMENT | EL1: INSTRUMENT | EN1: INSTRUMENT | EP1: INSTRUMENT | ER1: INSTRUMENT | ET1: INSTRUMENT | EV1: INSTRUMENT | EX1: INSTRUMENT | EZ1: INSTRUMENT | FB1: INSTRUMENT | FD1: PROTECTION | FF1: PROTECTION | FH1: PROTECTION | FJ1: PROTECTION | FL1: ENTITY | FN1: INSTRUMENT | FP1: INSTRUMENT | FR1: INSTRUMENT | FY1: INSTRUMENT | GA1: INSTRUMENT | GC1: INSTRUMENT | GE1: INSTRUMENT | GG1: INSTRUMENT | GI1: INSTRUMENT | GK1: PROTECTION | GM1: PROTECTION | GS1: PROTECTION | GU1: PROTECTION | GW1: INSTRUMENT | GY1: ENTITY | HA1: INSTRUMENT | HC1: INSTRUMENT | HE1: INSTRUMENT | HG1: INSTRUMENT | HI1: INSTRUMENT | HK1: INSTRUMENT | HM1: INSTRUMENT | HO1: INSTRUMENT | HQ1: INSTRUMENT - PROTECTION
A2: Data field | B2: ACCNTNG_CLSSFCTN | D2: CHNNL_ORGNTN | F2: CRRNCY_DNMNTN | H2: CPN_CRRNCY | J2: VLTN_CRRNCY | L2: APPRSL_CRRNCY | N2: CRE_INCM_CRRNCY | P2: CVNNT_STTS | R2: CVNNT_TYP | T2: DFLT_STTS_INSTRMNT | V2: PRFRMNG_STTS | X2: PRFRMNG_STTS_PRVS | Z2: FRBRNC_STTS_INSTRMNT | AB2: IMPRMNT_STTS | AD2: IMPRMNT_STTS_PRVS | AF2: IMPRMNT_ASSSSMNT_MTHD | AH2: IMPRMNT_CLCLTN_MTHD | AJ2: INTRST_RT_RST_FRQNCY | AL2: LGL_PRCDNG_STTS | AN2: LGL_PRCDNG_STTS_LE | AP2: PRJCT_FNNC_LN | AR2: PRPS | AT2: PYMNT_FRQNCY | AV2: RCRS | AX2: RWA_MTHD | AZ2: SICR_ASSSSMNT_MTHD | BB2: STTS_UNDRWRTTN_TRNSCTN | BD2: SYNDCT_RL | BF2: SYNDCTN_TYP | BH2: TRNCH | BJ2: TYP_AMRTSTN | BL2: TYP_CRE_OPRTN | BN2: TYP_INSTRMNT | BP2: TYP_INTRST_RT | BR2: TYP_MRTGG | BT2: EXTRNL_RTNG / EXTRNL_RTNG_PRVS / ISSR_RTNG | BV2: CNSTRCTN_STTS | BX2: DVLPMNT_STTS | BZ2: MN_PRPS | CB2: PRTCTN_VLTN_APPRCH | CD2: TYP_PRTCTN | CF2: TYP_PRTCTN_VL | CH2: ACCNTNG_FRMWRK_SL | CJ2: CLLCTN_MD | CL2: CNTRY/RL_ESTT_CLLTRL_LCTN | CN2: DFLT_STTS | CP2: ECNMC_ACTVTY/GRP_ECNMC_ACTVTY/ISSR_NACE_SCTR/NACE_ESG | CR2: EMPLYMNT_STTS | CT2: ENTRPRS_SZ_LE | CV2: PRFRMNG_STTS_LE | CX2: RTNG_MTHD | CZ2: INTRNL_RTNG | DB2: INTRNL_RTNG_INCPTN | DD2: INTRNL_RTNG_PRVS | DF2: RTNG_SCL | DH2: SNGL_PRPS_VHCL | DJ2: EBA_CMPLNT_MRTR_ST_C19 | DL2: TYP_CMPLNT_MRTR_C19 | DN2: FRBRNC_STTS_C19 | DP2: SBJCT_PBLC_GRNT_SCHM_C19 | DR2: ISSR_ID_TYP | DT2: GRNTR_ID_TYP | DV2: ISSR_CNTRY | DX2: ISSR_ESA_2010 | DZ2: LVRG_FNNC_FLG | EB2: ISSR_TYP | ED2: VLTN_TYP | EF2: INSTRMNT_CLSS | EH2: PRMRY_ASST_CLSSF | EJ2: ASST_SCRT_CLSS | EL2: TYPE_OF_PLCMNT | EN2: INSTR_SNRTY_CLSS | EP2: SRCS_ENCMBRNC | ER2: LCR_BFFR_CTGRY | ET2: PRDNTL_PRTFL | EV2: INTRNL_SGMNT_CAT_MSTA | EX2: INTRNL_SGMNT_CATGSUB | EZ2: RSK_MTGTD_CCT | FB2: RSK_MTGTD_CCP | FD2: TYP_EP_SCR/TYP_EMSSNS_SCR | FF2: EP_SCR | FH2: TYP_EMSSNS_LBL/TYP_EPC_LBL | FJ2: EPC_LBL/EPC_EMSSNS_LBL | FL2: ESG_SBSCTR | FN2: BSNSS_AREA/BSNSS_AREA_DSTNTN/BSNN_AREA_CIB/BSNSS_AREA_CCRR | FP2: SSTNBL_CTGRY_TXNMY | FR2: SSTNBL_CTGRY | FY2: MNGMNT_PRDCT | GA2: ENVRNMNTL_OBJCTV | GC2: TYP_ACTVTY | GE2: LNS_CLLTRLZD_CLSSFCTN | GG2: INTRBSNSS_ADJ_COD | GI2: MTHD_USD_INSTRMNT_SCP_1 / MTHD_USD_INSTRMNT_SCP_2 / MTHD_USD_INSTRMNT_SCP_3 | GK2: MTHD_USD_PRTCTN_SCP_1 / MTHD_USD_PRTCTN_SCP_2 / MTHD_USD_PRTCTN_SCP_3 | GM2: RL_ESTT_CRTFCTN | GO2: DNSH_DTL | GQ2: SSTNBL_INDCTR | GS2: TYP_HZRDS_INSRD | GU2: VHCL_EMSSNS_LBL | GW2: CNCLLD_INSTRMNT_STTS | GY2: PRSN_TYP | HA2: RFRNC_RT | HC2: TYP_SCRTZTN | HE2: TYP_OFF_BLNC_PRDCT | HG2: BLNC_SHT_RCGNTN | HI2: EXCLDD_LF | HK2: US_PRCDS | HM2: TYP_FCLTY | HO2: TYP_CL | HQ2: TYP_RLTN | HS2: RL_ESTT_CLMT_ZN | HU2: SCAN | HW2: TYP_DL | HY2: DSTNTN_FNDS | IA2: TYP_VHCL
CZ3: The rating collected in local databases should be reported. | DB3: The rating collected in local databases should be reported. | DD3: The rating collected in local databases should be reported. | DF3: to be populated by Corporation
A4: Code / Name | B4: ACCNTNG_CLSSFCTN_CD | C4: ACCNTNG_CLSSFCTN_NM | D4: CHNNL_ORGNTN_CD | E4: CHNNL_ORGNTN_NM | F4: CRRNCY_DNMNTN_CD | G4: CRRNCY_DNMNTN_NM | H4: CPN_CRRNCY_CD | I4: CPN_CRRNCY_NM | J4: VLTN_CRRNCY_CD | K4: VLTN_CRRNCY_NM | L4: APPRSL_CRRNCY_CD | M4: APPRSL_CRRNCY_NM | N4: CRE_INCM_CRRNCY_CD | O4: CRE_INCM_CRRNCY_NM | P4: CVNNT_STTS_CD | Q4: CVNNT_STTS_NM | R4: CVNNT_TYP_CD | S4: CVNNT_TYP_NM | T4: DFLT_STTS_INSTRMNT_CD | U4: DFLT_STTS_INSTRMNT_NM | V4: PRFRMNG_STTS_CD | W4: PRFRMNG_STTS_NM | X4: PRFRMNG_STTS_PRVS_CD | Y4: PRFRMNG_STTS_PRVS_NM | Z4: FRBRNC_STTS_CD | AA4: FRBRNC_STTS_NM | AB4: IMPRMNT_STTS_CD | AC4: IMPRMNT_STTS_NM | AD4: IMPRMNT_STTS_PRVS_CD | AE4: IMPRMNT_STTS_PRVS_NM | AF4: IMPRMNT_ASSSSMNT_MTHD_CD | AG4: IMPRMNT_ASSSSMNT_MTHD_NM | AH4: IMPRMNT_CLCLTN_MTHD_CD | AI4: IMPRMNT_CLCLTN_MTHD_NM | AJ4: INTRST_RT_RST_FRQNCY_CD | AK4: INTRST_RT_RST_FRQNCY_NM | AL4: LGL_PRCDNG_STTS_CD | AM4: LGL_PRCDNG_STTS_NM | AN4: LGL_PRCDNG_STTS_LE_CD | AO4: LGL_PRCDNG_STTS_LE_NM | AP4: PRJCT_FNNC_LN_CD | AQ4: PRJCT_FNNC_LN_NM | AR4: PRPS_CD | AS4: PRPS_NM | AT4: PYMNT_FRQNCY_CD | AU4: PYMNT_FRQNCY_NM | AV4: RCRS_CD | AW4: RCRS_NM | AX4: RWA_MTHD_CD | AY4: RWA_MTHD_ID | AZ4: SICR_ASSSSMNT_MTHD_CD | BA4: SICR_ASSSSMNT_MTHD_NM | BB4: STTS_UNDRWRTTN_TRNSCTN_CD | BC4: STTS_UNDRWRTTN_TRNSCTN_ID | BD4: SYNDCT_RL_CD | BE4: SYNDCT_RL_ID | BF4: SYNDCTN_TYP_CD | BG4: SYNDCTN_TYP_ID | BH4: TRNCH_CD | BI4: TRNCH_ID | BJ4: TYP_AMRTSTN_CD | BK4: TYP_AMRTSTN_NM | BL4: TYP_CRE_OPRTN_CD | BM4: TYP_CRE_OPRTN_NM | BN4: TYP_INSTRMNT_CD | BO4: TYP_INSTRMNT_NM | BP4: TYP_INTRST_RT_CD | BQ4: TYP_INTRST_RT_NM | BR4: TYP_MRTGG_CD | BS4: TYP_MRTGG_ID | BT4: EXTRNL_RTNG_CD | BU4: EXTRNL_RTNG_ID | BV4: CNSTRCTN_STTS_CD | BW4: CNSTRCTN_STTS_NM | BX4: DVLPMNT_STTS_CD | BY4: DVLPMNT_STTS_ID | BZ4: MN_PRPS_CD | CA4: MN_PRPS_ID | CB4: PRTCTN_VLTN_APPRCH_CD | CC4: PRTCTN_VLTN_APPRCH_NM | CD4: TYP_PRTCTN_CD | CE4: TYP_PRTCTN_NM | CF4: TYP_PRTCTN_VL_CD | CG4: TYP_PRTCTN_VL_NM | CH4: ACCNTNG_FRMWRK_CD | CI4: ACCNTNG_FRMWRK_NM | CJ4: CLLCTN_MD_CD | CK4: CLLCTN_MD_NM | CL4: CNTRY_CD | CM4: CNTRY_ID | CN4: DFLT_STTS_CD | CO4: DFLT_STTS_ID | CP4: ECNMC_ACTVTY_CD | CQ4: ECNMC_ACTVTY_NM | CR4: EMPLYMNT_STTS_CD | CS4: EMPLYMNT_STTS_ID | CT4: ENTRPRS_SZ_LE_CD | CU4: ENTRPRS_SZ_LE_ID | CV4: PRFRMNG_STTS_LE_CD | CW4: PRFRMNG_STTS_LE_ID | CX4: RTNG_MTHD_CD | CY4: RTNG_MTHD_NM | CZ4: INTRNL_RTNG | DA4: PD | DB4: INTRNL_RTNG_INCPTN | DC4: PD | DD4: INTRNL_RTNG_PRVS | DE4: PD | DF4: RTNG_SCL_CD | DG4: RTNG_SCL_NM | DH4: SNGL_PRPS_VHCL_CD | DI4: SNGL_PRPS_VHCL_NM | DJ4: EBA_CMPLNT_MRTR_ST_C19_CD | DK4: EBA_CMPLNT_MRTR_ST_C19_NM | DL4: TP_CMPLNT_MRTR_C19_CD | DM4: TP_CMPLNT_MRTR_C19_NM | DN4: FRBRNC_STTS_C19_CD | DO4: FRBRNC_STTS_C19_NM | DP4: SBJCT_PBLC_GRNT_SCHM_C19_CD | DQ4: SBJCT_PBLC_GRNT_SCHM_C19_NM | DR4: ISSR_ID_TYP_CD | DS4: ISSR_ID_TYP_NM | DT4: IGRNTR_ID_TYP_CD | DU4: IGRNTR_ID_TYP_NM | DV4: ISSR_CNTRY_CD | DW4: ISSR_CNTRY_NM | DX4: ISSR_ESA_2010_CD | DY4: ISSR_ESA_2010_NM | DZ4: LVRG_FNNC_FLG_CD | EA4: LVRG_FNNC_FLG_NM | EB4: ISSR_TYP_CD | EC4: ISSR_TYP_ID | ED4: VLTN_TYP_CD | EE4: VLTN_TYP_ID | EF4: INSTRMNT_CLSS_CD | EG4: INSTRMNT_CLSS_ID | EH4: PRMRY_ASST_CLSSF_CD | EI4: PRMRY_ASST_CLSSF_ID | EJ4: ASST_SCRT_CLSS_CD | EK4: ASST_SCRT_CLSS_ID | EL4: TYPE_OF_PLCMNT_CD | EM4: TYPE_OF_PLCMNT_ID | EN4: INSTR_SNRTY_CLSS_CD | EO4: INSTR_SNRTY_CLSS_ID | EP4: SRCS_ENCMBRNC_CD | EQ4: SRCS_ENCMBRNC_NM | ER4: LCR_BFFR_CTGRY_CD | ES4: LCR_BFFR_CTGRY_NM | ET4: PRDNTL_PRTFL_CD | EU4: PRDNTL_PRTFL_NM | EV4: INTRNL_SGMNT_CAT_MSTA_CD | EW4: INTRNL_SGMNT_CAT_MSTA_NM | EX4: INTRNL_SGMNT_CATGSUB_CD | EY4: INTRNL_SGMNT_CATGSUB_NM | EZ4: RSK_MTGTD_CCT_CD | FA4: RSK_MTGTD_CCT_NM | FB4: RSK_MTGTD_CCP_CD | FC4: RSK_MTGTD_CCP_NM | FD4: TYP_EP_SCR_CD | FE4: TYP_EP_SCR_NM | FF4: EP_SCR_CD | FG4: EP_SCR_NM | FH4: TYP_EMSSNS_LBL_CD/TYP_EPC_LBL_CD/TYP_EPC_LBL_PRVS_YR_CD/TYP_EP_SCR_PRVS_YR_CD | FI4: TYP_EMSSNS_LBL_NM/TYP_EPC_LBL_NM/TYP_EPC_LBL_PRVS_YR_NM/TYP_EP_SCR_PRVS_YR_NM | FJ4: EPC_LBL_CD/EPC_EMSSNS_LBL_CD/EPC_LBL_PRVS_YR_CD | FK4: EPC_LBL_NM/EPC_EMSSNS_LBL_NM/EPC_LBL_PRVS_YR_NM | FL4: ESG_SBSCTR_CD | FM4: ESG_SBSCTR_NM | FN4: BSNSS_AREA_CD | FO4: BSNSS_AREA_NM | FP4: SSTNBL_CTGRY_TXNMY_CD | FQ4: SSTNBL_CTGRY_TXNMY_NM | FR4: SSTNBL_CTGRY_CD | FT4: SSTNBL_CTGRY_NM | FY4: MNGMNT_PRDCT_CD | FZ4: MNGMNT_PRDCT_NM | GA4: ENVRNMNTL_OBJCTV_CD | GB4: ENVRNMNTL_OBJCTV_NM | GC4: TYP_ACTVTY_CD | GD4: TYP_ACTVTY_NM | GE4: LNS_CLLTRLZD_CLSSFCTN_CD | GF4: LNS_CLLTRLZD_CLSSFCTN_NM | GG4: INTRBSNSS_ADJ_COD_CD | GH4: INTRBSNSS_ADJ_COD_NM | GI4: MTHD_USD_INSTRMNT_SCP_1_CD | GJ4: MTHD_USD_INSTRMNT_SCP_1_NM | GK4: MTHD_USD_PRTCTN_SCP_1 _CD | GL4: MTHD_USD_PRTCTN_SCP_1 _NM | GM4: RL_STT_CRTFCTN_CD | GN4: RL_STT_CRTFCTN _NM | GO4: DNSH_DTL_CD | GP4: DNSH_DTL_NM | GQ4: SSTNBL_INDCTR_CD | GR4: SSTNBL_INDCTR_NM | GS4: TYP_HZRDS_INSRD_CD | GT4: TYP_HZRDS_INSRD_NM | GU4: VHCL_EMSSNS_LBL_CD | GV4: VHCL_EMSSNS_LBL_NM | GW4: CNCLLD_INSTRMNT_STTS_CD | GX4: CNCLLD_INSTRMNT_STTS_NM | GY4: PRSN_TYP_CD | GZ4: PRSN_TYP_NM | HA4: RFRNC_RT_CD | HB4: RFRNC_RT_NM | HC4: TYP_SCRTZTN_CD | HD4: TYP_SCRTZTN_NM | HE4: TYP_OFF_BLNC_PRDCT_CD | HF4: TYP_OFF_BLNC_PRDCT_NM | HG4: BLNC_SHT_RCGNTN_CD | HH4: BLNC_SHT_RCGNTN_NM | HI4: EXCLDD_LF_CD | HJ4: EXCLDD_LF_NM | HK4: US_PRCDS_CD | HL4: US_PRCDS_NM | HM4: FCLTY_TYP_CD | HN4: FCLTY_TYP_NM | HO4: CL_TYP_CD | HP4: FCLTY_TYP_NM | HQ4: TYP_RLTN_CD | HR4: TYP_RLTN_NM | HS4: CLMTC_ZN_CD | HT4: CLMTC_ZN_NM | HU4: SCAN_CD | HV4: SCAN_NM | HW4: TYP_DL_CD | HX4: TYP_DL_NM | HY4: DSTNTN_FNDS_CD | HZ4: DSTNTN_FNDS_NM | IA4: TYP_VHCL_CD | IB4: TYP_VHCL_NM
B5: Code | C5: Description | D5: Code | E5: Description | F5: Code | G5: Description | H5: Code | I5: Description | J5: Code | K5: Description | L5: Code | M5: Description | N5: Code | O5: Description | P5: Code | Q5: Description | R5: Code | S5: Description | T5: Code | U5: Description | V5: Code | W5: Description | X5: Code | Y5: Description | Z5: Code | AA5: Description | AB5: Code | AC5: Description | AD5: Code | AE5: Description | AF5: Code | AG5: Description | AH5: Code | AI5: Description | AJ5: Code | AK5: Description | AL5: Code | AM5: Description | AN5: Code | AO5: Description | AP5: Code | AQ5: Description | AR5: Code | AS5: Description | AT5: Code | AU5: Description | AV5: Code | AW5: Description | AX5: Code | AY5: Description | AZ5: Code | BA5: Description | BB5: Code | BC5: Description | BD5: Code | BE5: Description | BF5: Code | BG5: Description | BH5: Code | BI5: Description | BJ5: Code | BK5: Description | BL5: Code | BM5: Description | BN5: Code | BO5: Description | BP5: Code | BQ5: Description | BR5: Code | BS5: Description | BT5: Code | BU5: Description | BV5: Code | BW5: Description | BX5: Code | BY5: Description | BZ5: Code | CA5: Description | CB5: Code | CC5: Description | CD5: Code | CE5: Description | CF5: Code | CG5: Description | CH5: Code | CI5: Description | CJ5: Code | CK5: Description | CL5: Code | CM5: Description | CN5: Code | CO5: Description | CP5: Code | CQ5: Description | CR5: Code | CS5: Description | CT5: Code | CU5: Description | CV5: Code | CW5: Description | CX5: Code | CY5: Description | CZ5: Code | DA5: Description | DB5: Code | DC5: Description | DD5: Code | DE5: Description | DF5: Code | DG5: Description | DH5: Code | DI5: Description | DJ5: Code | DK5: Description | DL5: Code | DM5: Description | DN5: Code | DO5: Description | DP5: Code | DQ5: Description | DR5: Code | DS5: Description | DT5: Code | DU5: Description | DV5: Code | DW5: Description | DX5: Code | DY5: Description | DZ5: Code | EA5: Description | EB5: Code | EC5: Description | ED5: Code | EE5: Description | EF5: Code | EG5: Description | EH5: Code | EI5: Description | EJ5: Code | EK5: Description | EL5: Code | EM5: Description | EN5: Code | EO5: Description | EP5: Code | EQ5: Description | ER5: Code | ES5: Description | ET5: Code | EU5: Description | EV5: Code | EW5: Description | EX5: Code | EY5: Description | EZ5: Code | FA5: Description | FB5: Code | FC5: Description | FD5: Code | FE5: Description | FF5: Code | FG5: Description | FH5: Code | FI5: Description | FJ5: Code | FK5: Description | FL5: Code | FM5: Description | FN5: Code | FO5: Description | FP5: Code | FQ5: Description | FR5: Code | FS5: Description | FY5: Code | FZ5: Description | GA5: Code | GB5: Description | GC5: Code | GD5: Description | GE5: Code | GF5: Description | GG5: Code | GH5: Description | GI5: Code | GJ5: Description | GK5: Code | GL5: Description | GM5: Code | GN5: Description | GO5: Code | GP5: Description | GQ5: Code | GR5: Description | GS5: Code | GT5: Description | GU5: Code | GV5: Description | GW5: Code | GX5: Description | GY5: Code | GZ5: Description | HA5: Code | HB5: Description | HC5: Code | HD5: Description | HE5: Code | HF5: Description | HG5: Code | HH5: Description | HI5: Code | HJ5: Description | HK5: Code | HL5: Description | HM5: Code | HN5: Description | HO5: Code | HP5: Description | HQ5: Code | HR5: Description | HS5: Code | HT5: Description | HU5: Code | HV5: Description | HW5: Code | HX5: Description | HY5: Code | HZ5: Description | IA5: Code | IB5: Description
B6: 2 | C6: IFRS: Financial assets held for trading | D6: 1 | E6: Branch | F6: AED | G6: UAE Dirham | H6: AED | I6: UAE Dirham | J6: AED | K6: UAE Dirham | L6: AED | M6: UAE Dirham | N6: AED | O6: UAE Dirham | P6: 1 | Q6: No financial covenant to check | R6: 1 | S6: Full Covenant | T6: 14 | U6: Not in default | V6: 1 | W6: Non-performing | X6: 1 | Y6: Non-performing | Z6: 3 | AA6: Forborne: Refinanced debt | AB6: 21 | AC6: General allowances (GAAP) | AD6: 21 | AE6: General allowances (GAAP) | AF6: 1 | AG6: Collectively assessed | AH6: 1 | AI6: Specific. Going concern | AJ6: 1 | AK6: Annual | AL6: 1 | AM6: No legal actions taken | AN6: 1 | AO6: No legal actions taken | AP6: 1 | AQ6: Project finance loan | AR6: 4 | AS6: Margin lending | AT6: 1 | AU6: Annual | AV6: 1 | AW6: Recourse | AX6: 1 | AY6: IRB | AZ6: 1 | BA6: Collective approach | BB6: 1 | BC6: Underwritten or warehoused but not yet syndicated | BD6: 1 | BE6: Lead_arranger | BF6: 1 | BG6: Club_deal | BH6: 1 | BI6: Super-Senior | BJ6: 1 | BK6: French | BL6: 1 | BM6: Property development financing | BN6: 20 | BO6: Overdrafts | BP6: 1 | BQ6: Fixed | BR6: 1 | BS6: First rank fully registered mortgage | BT6: 1 | BU6: Aaa, AAA | BV6: 1 | BW6: Built | BX6: 1 | BY6: Not in construction | BZ6: 1 | CA6: Office | CB6: 1 | CC6: Counterparty estimation | CD6: 2 | CE6: Life insurance policies pledged | CF6: 1 | CG6: Fair value | CH6: 1 | CI6: National GAAP not consistent with IFRS | CJ6: 1 | CK6: Hard collection (judicial procedures engaged) | CL6: __ | CM6: Not assigned yet | CN6: 14 | CO6: Not in default | CP6: A | CQ6: Agriculture, forestry and fishing | CR6: 1 | CS6: Employed | CT6: 1 | CU6: Large enterprise | CV6: 1 | CW6: Non-performing | CX6: 10 | CY6: Rating - Grandes empresas | DH6: 1 | DI6: SPV with recourse | DJ6: 1 | DK6: Requested | DL6: 1 | DM6: Legislative | DN6: 1 | DO6: Requested | DP6: 1 | DQ6: Requested | DR6: BIC | DS6: BIC code | DT6: BIC | DU6: BIC code | DV6: 1C | DW6: IMF (International Monetary Fund) | DX6: S_11 | DY6: Non-financial corporations | DZ6: HLT | EA6: High Leveraged transaction | EB6: 1 | EC6: Other group entity | ED6: 1 | EE6: Mark-to-market | EF6: F_31 | EG6: Short-term debt securities | EH6: D | EI6: Debt - Debt securities are negotiable financial instruments serving as evidence of a debt. They are covered by the financial assets and liabilities (financial instrument) category “debt securities” (F.3) in ESA 2010. | EJ6: 1000 | EK6: Securitisation - Securitisation is the issuance of debt securities for which coupon or principal payments are backed by specified assets or by future income streams. | EL6: 1 | EM6: Public | EO6: Guarantee level | EP6: 1 | EQ6: SRCS_ENCMBRNC_NM | ER6: 1 | ES6: L1 | ET6: 1 | EU6: Trading book | EV6: 1 | EW6: STD - Regional governments or local authorities | EX6: 1 | EY6: Covered Bonds | EZ6: RMCT1 | FA6: Policy and legal risk | FB6: RMCP1 | FC6: Chronic | FD6: EPSD1 | FE6: Real | FF6: EPSC1 | FG6: 0; <= 100 | FH6: EPCD1 | FI6: Real | FJ6: EPCL1 | FK6: A | FL6: ESGS1 | FM6: Local Governments | FN6: BA1 | FO6: Private Banking | FQ6: Non financial corporations | FS6: DEDICATED PURPOSE | FT6: Green | FZ6: On Balance (excluding HfT) | GA6: 22 | GB6: Climate change mitigation | GC6: 02 | GD6: Transitional activity | GE6: FMC1 | GF6: Real estate. Commercial | GG6: 99569 | GH6: Vendor Activity Chile | GJ6: Corporate Funding | GL6: Motor vehicle loans | GM6: ESTT01 | GN6: HQE SB v4. Certification | GO6: DNSH01 | GP6: DNSH1 - Do not significant harm to climate change mitigation objective | GQ6: SSTNBL1 | GR6: Santander Specific | GS6: HZRDS01 | GT6: Cyclone | GU6: VHCL1 | GV6: *codelist to be completed by the Unit based on the local vehicle emissions label codification | GW6: C | GX6: Cancelled | GY6: N | GZ6: Natural person | HA6: ESTR-OVERNIGHT | HB6: ESTR-OVERNIGHT | HC6: SEC01 | HD6: Traditional securitization | HE6: MC41 | HF6: Financial guarantees given | HG6: REC01 | HH6: Entirely recognised | HI6: EXC01 | HJ6: Collective investment undertaking | HK6: USP01 | HL6: LBO/M&A (exclusive purchase financing) | HM6: FCL01 | HN6: Revolving credit Facilities (RCF) | HO6: CLO01 | HP6: Direct holding of CLO | HQ6: REL01 | HR6: The guarantee is the financed asset | HS6: CLM01 | HT6: Climatic Zone α | HU6: SCN01 | HV6: Do not serve | HW6: DEL01 | HX6: Syndicated loan (includes underwritten, best effort, club deals and other syndicated loans) | HY6: DST01 | HZ6: New money new customer | IA6: VEH01 | IB6: M1 - Vehicles used for the carriage of passengers and comprising not more than eight seats in addition to the driver's seat
B7: 3 | C7: nGAAP: Trading Financial assets | D7: 2 | E7: Internet | F7: AFN | G7: Afghani | H7: AFN | I7: Afghani | J7: AFN | K7: Afghani | L7: AFN | M7: Afghani | N7: AFN | O7: Afghani | P7: 2 | Q7: In line with all financial covenants | R7: 2 | S7: Covenant loose | T7: 18 | U7: Default because both unlikely to pay and more than 90/180 days past due | V7: 11 | W7: Performing | X7: 11 | Y7: Performing | Z7: 4 | AA7: Forborne: instruments with modified interest rate below market conditions | AB7: 23 | AC7: Stage 1 (IFRS) | AD7: 23 | AE7: Stage 1 (IFRS) | AF7: 2 | AG7: Individually assessed | AH7: 2 | AI7: Specific. Gone concern | AJ7: 3 | AK7: At creditor discretion | AL7: 2 | AM7: Under judicial administration, receivership or similar measures | AN7: 2 | AO7: Under judicial administration, receivership or similar measures | AP7: 2 | AQ7: Non-project finance loan | AR7: 5 | AS7: Debt financing | AT7: 4 | AU7: Bullet | AV7: 2 | AW7: No recourse | AX7: 2 | AY7: STANDARD | AZ7: 2 | BA7: Individial approach | BB7: 2 | BC7: Syndicated or sold but not yet settled and transferred to investors | BD7: 2 | BE7: Participant | BF7: 2 | BG7: Underwriting | BH7: 2 | BI7: Senior/First Lien | BJ7: 2 | BK7: German | BL7: 2 | BM7: Property investment financing | BN7: 51 | BO7: Credit card debt | BP7: 2 | BQ7: Variable | BR7: 2 | BS7: Subordinated rank fully registered mortgage | BT7: 2 | BU7: Aa1, AA+ | BV7: 2 | BW7: In construction | BX7: 2 | BY7: In construction and not operational | BZ7: 2 | CA7: Hotel | CB7: 2 | CC7: Creditor valuation | CD7: 3 | CE7: Other physical collaterals | CF7: 2 | CG7: Long-term sustainable value | CH7: 2 | CI7: IFRS | CJ7: 2 | CK7: Soft collection (all other) | CL7: AD | CM7: Andorra | CN7: 18 | CO7: Default because both unlikely to pay and more than 90/180 days past due | CP7: 1 | CQ7: Crop and animal production, hunting and related service activities | CR7: 2 | CS7: Employed with partial support (company subsidy) | CT7: 2 | CU7: Medium enterprise | CV7: 11 | CW7: Performing | CX7: 11 | CY7: Rating - Corporativa | DH7: 2 | DI7: SPV without recourse | DJ7: 2 | DK7: Granted | DL7: 2 | DM7: Non-Legislative | DN7: 2 | DO7: Granted | DP7: 2 | DQ7: Covered | DR7: IPF | DS7: Investment/Pension fund identifier | DT7: IPF | DU7: Investment/Pension fund identifier | DV7: 1D | DW7: WTO (World Trade Organisation) | DX7: S_11001 | DY7: Non-financial corporations - public | DZ7: LFT | EA7: Leveraged finance transaction | EB7: 2 | EC7: Third party | ED7: 2 | EE7: Mark-to-model | EF7: F_32 | EG7: Long-term debt securities | EH7: D.1 | EI7: Bond - Bonds and debentures are long-term debt securities that give the holders the unconditional right to fixed payments or contractually determined variable payments on a specified date or dates, that is, the earning of interest is not dependent on earnings of the debtors. Bonds and debentures also give holders the unconditional right to fixed sums as payments to the creditor on a specified date or dates. | EJ7: 1100 | EK7: Asset-backed security (ABS) - A bond, created through securitisation, whose coupon payments and principal repayments are dependent on a pool of assets, either purchased in the secondary market or from the balance sheet of an original asset owner; excluding mortgages. | EL7: 2 | EM7: Private | EN7: 1XX | EO7: Unguaranteed - In case of unguaranteed securities, there are no obligations to guarantors to make payments to the holder of the security if the issuer fails to meet the obligation to make repayments arising under the instrument secured by the guarantor. | EP7: 5 | EQ7: Central bank funding - Central bank funding (of all types, including repos), in accordance with the European Banking Authority’s (EBA) implementing technical standards on asset encumbrance reporting as referred to in Article 99(5) and Article 100 of Regulation (EU) No 575/2013. | ER7: 2 | ES7: L2A | ET7: 2 | EU7: Non-trading book | EV7: 2 | EW7: STD - Public sector entities | EX7: 4 | EY7: Exposures secured by mortgages on immovable property | EZ7: RMCT2 | FA7: Technology risk | FB7: RMCP2 | FC7: Acute | FD7: EPSD2 | FE7: Estimated | FF7: EPSC2 | FG7: > 100; <= 200 | FH7: EPCD2 | FI7: Estimated | FJ7: EPCL2 | FK7: B | FL7: ESGS2 | FM7: Sovereigns | FN7: BA2 | FO7: Individuals | FP7: SCATX01 | FQ7: Non financial corporations - General purpose | FU7: Energy | FZ7: Loans & advances (customers and credit institutions) | GA7: 23 | GB7: Climate change adaptation | GC7: 05 | GD7: Pure Activity | GE7: FMC2 | GF7: Real estate. Residential | GG7: 99505 | GH7: Distribution BdI to Commercial (Eng) | GJ7: Reported emissions | GL7: Actual vehicle - specific emissions | GM7: ESTT02 | GN7: Buildings that have a PED that is 10% below the Net Zero Energy Building CertificationTM (NZEB) | GO7: DNSH02 | GP7: DNSH2 - Do not significant harm to climate change adaptation | GQ7: SSTNBL2 | GR7: Taxonomy Specific | GS7: HZRDS02 | GT7: Winter storm | GU7: VHCL1 | GW7: M | GX7: Interannual cancelled instrument | GY7: L | GZ7: Legal person | HA7: TERM ESTR-1W | HB7: TERM ESTR-1W | HC7: SEC02 | HD7: Synthetic securitization | HE7: MC42 | HF7: Loan commitments given | HG7: REC02 | HH7: Recognised to the extent of the institution’s continuing involvement | HI7: EXC02 | HJ7: Securitisations | HK7: USP02 | HL7: Refinancing | HM7: FCL02 | HN7: Bullet term loans | HO7: CLO02 | HP7: CLO warehousing first lien | HQ7: REL02 | HR7: The guarantee is not the financed asset | HS7: CLM02 | HT7: Climatic Zone A | HU7: SCN02 | HV7: Specialised | HW7: DEL02 | HX7: Bilateral loan | HY7: DST02 | HZ7: New money existing customer | IA7: VEH02 | IB7: M2 - Vehicles used for the carriage of passengers, comprising more than eight seats in addition to the driver's seat, and having a maximum mass not exceeding 5 tonnes
