Workbook

Sheet Macroplano
C2: BS - ESG Pilar 3
C3: Plano de Atividades
I6: =SUM(I13:I96)=4 -> FALSE | J6: =SUM(J13:J96)=4 -> FALSE | K6: =SUM(K13:K96)=4 -> FALSE | L6: =SUM(L13:L96)=4 -> FALSE | M6: =SUM(M13:M96)=4 -> FALSE | N6: =SUM(N13:N96)=4 -> FALSE | O6: =SUM(O13:O96)=4 -> FALSE | P6: =SUM(P13:P96)=4 -> FALSE | ... CN6: =SUM(CN13:CN96)=4 -> FALSE | CP6: =SUM(CP13:CP96)=4 -> FALSE | CQ6: =SUM(CQ13:CQ96)=4 -> FALSE | CR6: =SUM(CR13:CR96)=4 -> FALSE | CS6: =SUM(CS13:CS96)=4 -> FALSE | CT6: =SUM(CT13:CT96)=4 -> FALSE | CU6: =SUM(CU13:CU96)=4 -> FALSE | CV6: =SUM(CV13:CV96)=4 -> FALSE | CW6: =SUM(CW13:CW96)=4 -> FALSE | ... FD6: =SUM(FD13:FD96)=4 -> FALSE
I7: Novembro | AA7: Dezembro | AF7: Dezembro | AW7: Janeiro | BT7: Fevereiro | CP7: Março | DM7: Abril | EH7: Maio
B11: ID | C11: Atividade | D11: Nº dias | E11: Data Início | F11: Status PPT | G11: FTEs (#) | I11: 45238 | J11: =I11+1 -> 45239 | K11: =J11+1 -> 45240 | L11: 45243 | M11: =L11+1 -> 45244 | N11: =M11+1 -> 45245 | O11: =N11+1 -> 45246 | P11: =O11+1 -> 45247 | Q11: 45250 | R11: =Q11+1 -> 45251 | S11: =R11+1 -> 45252 | T11: =S11+1 -> 45253 | U11: =T11+1 -> 45254 | V11: 45257 | W11: =V11+1 -> 45258 | X11: =W11+1 -> 45259 | Y11: =X11+1 -> 45260 | AA11: =Y11+1 -> 45261 | AB11: 45234 | AC11: =AB11+1 -> 45235 | AD11: =AC11+1 -> 45236 | AE11: =AD11+1 -> 45237 | AF11: =AE11+1 -> 45238 | AG11: 45241 | AH11: =AG11+1 -> 45242 | AI11: =AH11+1 -> 45243 | AJ11: =AI11+1 -> 45244 | AK11: =AJ11+1 -> 45245 | AL11: 45248 | AM11: 45249 | AN11: 45250 | AO11: 45251 | AP11: 45252 | AQ11: =AP11+3 -> 45255 | AR11: =AQ11+1 -> 45256 | AS11: =AR11+1 -> 45257 | AT11: =AS11+1 -> 45258 | AU11: =AT11+1 -> 45259 | AW11: =AU11+2 -> 45261 | AX11: =AW11+1 -> 45262 | AY11: =AX11+1 -> 45263 | AZ11: =AY11+1 -> 45264 | BA11: =AZ11+1 -> 45265 | BB11: =BA11+3 -> 45268 | BC11: =BB11+1 -> 45269 | BD11: =BC11+1 -> 45270 | BE11: =BD11+1 -> 45271 | BF11: =BE11+1 -> 45272 | BG11: =BF11+3 -> 45275 | BH11: =BG11+1 -> 45276 | BI11: =BH11+1 -> 45277 | BJ11: =BI11+1 -> 45278 | BK11: =BJ11+1 -> 45279 | BL11: =BK11+3 -> 45282 | BM11: =BL11+1 -> 45283 | BN11: =BM11+1 -> 45284 | BO11: =BN11+1 -> 45285 | BP11: =BO11+1 -> 45286 | BQ11: =BP11+3 -> 45289 | BR11: =BQ11+1 -> 45290 | BT11: =BR11+1 -> 45291 | BU11: =BT11+1 -> 45292 | BV11: =BU11+1 -> 45293 | BW11: =BV11+3 -> 45296 | BX11: =BW11+1 -> 45297 | BY11: =BX11+1 -> 45298 | BZ11: =BY11+1 -> 45299 | CA11: =BZ11+1 -> 45300 | CB11: =CA11+3 -> 45303 | CC11: =CB11+1 -> 45304 | CD11: =CC11+1 -> 45305 | CE11: =CD11+1 -> 45306 | CF11: =CE11+1 -> 45307 | CG11: =CF11+3 -> 45310 | CH11: =CG11+1 -> 45311 | CI11: =CH11+1 -> 45312 | CJ11: =CI11+1 -> 45313 | CK11: =CJ11+1 -> 45314 | CL11: =CK11+3 -> 45317 | CM11: =CL11+1 -> 45318 | CN11: =CM11+1 -> 45319 | CP11: 1 | CQ11: =CP11+1 -> 2 | CR11: =CQ11+2 -> 4 | CS11: =CR11+1 -> 5 | CT11: =CS11+1 -> 6 | CU11: =CT11+1 -> 7 | CV11: =CU11+1 -> 8 | CW11: =CV11+3 -> 11 | CX11: =CW11+1 -> 12 | CY11: =CX11+1 -> 13 | CZ11: =CY11+1 -> 14 | DA11: =CZ11+1 -> 15 | DB11: =DA11+3 -> 18 | DC11: =DB11+1 -> 19 | DD11: =DC11+1 -> 20 | DE11: =DD11+1 -> 21 | DF11: =DE11+1 -> 22 | DG11: =DF11+3 -> 25 | DH11: =DG11+1 -> 26 | DI11: =DH11+1 -> 27 | DJ11: =DI11+1 -> 28 | DK11: =DJ11+1 -> 29 | DM11: =DK11+3 -> 32 | DN11: =DM11+1 -> 33 | DO11: =DN11+1 -> 34 | DP11: =DO11+1 -> 35 | DQ11: =DP11+1 -> 36 | DR11: =DQ11+3 -> 39 | DS11: =DR11+1 -> 40 | DT11: =DS11+1 -> 41 | DU11: =DT11+1 -> 42 | DV11: =DU11+1 -> 43 | DW11: =DV11+3 -> 46 | DX11: =DW11+1 -> 47 | DY11: =DX11+1 -> 48 | DZ11: =DY11+1 -> 49 | EA11: =DZ11+1 -> 50 | EB11: =EA11+3 -> 53 | EC11: =EB11+1 -> 54 | ED11: =EC11+1 -> 55 | EE11: =ED11+1 -> 56 | EF11: =EE11+1 -> 57 | EH11: =EF11+3 -> 60 | EI11: =EH11+1 -> 61 | EJ11: =EI11+1 -> 62 | EK11: =EJ11+1 -> 63 | EL11: =EK11+1 -> 64 | EM11: =EL11+2 -> 66 | EN11: =EM11+1 -> 67 | EO11: =EN11+1 -> 68 | EP11: =EO11+1 -> 69 | EQ11: =EP11+1 -> 70 | ER11: =EQ11+3 -> 73 | ES11: =ER11+1 -> 74 | ET11: =ES11+1 -> 75 | EU11: =ET11+1 -> 76 | EV11: =EU11+1 -> 77 | EW11: =EV11+3 -> 80 | EX11: =EW11+1 -> 81 | EY11: =EX11+1 -> 82 | EZ11: =EY11+1 -> 83 | FA11: =EZ11+1 -> 84 | FB11: =FA11+3 -> 87 | FC11: =FB11+1 -> 88 | FD11: =FC11+1 -> 89
A12: x | B12: 0 | C12: Gestão
A13: xxx | B13: =_xlfn.CONCAT( IF(A12="",1,""), IF(AND(A12<>"",LEN(A12)>LEN(A13)),_xlfn.CONCAT(LEFT(B12,(LEN(#REF!)-1)*2),MID(B12,(LEN(#REF!)-1)*2 + 1,1)+1),""), IF(AND(A12<>"",LEN(A12)<LEN(A13)),_xlfn.CONCAT(B12,".",1),""), IF(AND(A12<>"",LEN(A12)=LEN(A13)),_xlfn.CONCAT(LEFT(B12,LEN(B12)-1),RIGHT(B12,1)+1),"")) -> #NAME? | C13: Gestão e acompanhamento de equipa | I13: 0.25 | J13: 0.25 | K13: 0.25 | L13: 0.25 | M13: 0.25 | N13: 0.25 | O13: 0.25 | P13: 0.25 | Q13: 0.25 | R13: 0.25 | S13: 0.25 | T13: 0.25 | U13: 0.25 | V13: 0.25 | W13: 0.25 | X13: 0.25 | Y13: 0.25 | AA13: 0.25 | AB13: 0.25 | AC13: 0.25 | AD13: 0.25 | AE13: 0.25 | AF13: 0.25 | AG13: 0.25 | AH13: 0.25 | AI13: 0.25 | AJ13: 0.25 | AK13: 0.25 | AL13: 0.25 | AM13: 0.25 | AN13: 0.25 | AO13: 0.25 | AP13: 0.25 | AX13: 0.25 | AY13: 0.25 | AZ13: 0.25 | BA13: 0.25 | BB13: 0.25 | BC13: 0.25 | BD13: 0.25 | BE13: 0.25 | BF13: 0.25 | BG13: 0.25 | BH13: 0.25 | BI13: 0.25 | BJ13: 0.25 | BK13: 0.25 | BL13: 0.25 | BM13: 0.25 | BN13: 0.25 | BO13: 0.25 | BP13: 0.25 | BQ13: 0.25 | BR13: 0.25 | BS13: 0.25 | BT13: 0.25 | BU13: 0.25 | BV13: 0.25 | BW13: 0.25 | BX13: 0.25 | BY13: 0.25 | BZ13: 0.25 | CA13: 0.25 | CB13: 0.25 | CC13: 0.25 | CD13: 0.25 | CE13: 0.25 | CF13: 0.25 | CG13: 0.25 | CH13: 0.25 | CI13: 0.25 | CJ13: 0.25 | CK13: 0.25 | CL13: 0.25 | CM13: 0.25 | CN13: 0.25 | CP13: 0.25 | CQ13: 0.25 | CR13: 0.25 | CS13: 0.25 | CT13: 0.25 | CU13: 0.25 | CV13: 0.25
A14: x | B14: 1 | C14: Importação e prepração de ficheiros
A15: xxx | B15: =_xlfn.CONCAT( IF(A14="",1,""), IF(AND(A14<>"",LEN(A14)>LEN(A15)),_xlfn.CONCAT(LEFT(B14,(LEN(#REF!)-1)*2),MID(B14,(LEN(#REF!)-1)*2 + 1,1)+1),""), IF(AND(A14<>"",LEN(A14)<LEN(A15)),_xlfn.CONCAT(B14,".",1),""), IF(AND(A14<>"",LEN(A14)=LEN(A15)),_xlfn.CONCAT(LEFT(B14,LEN(B14)-1),RIGHT(B14,1)+1),"")) -> #NAME? | C15: Importação de tabelas input | D15: 2 | F15: =2/2 -> 1 | AF15: 2
A16: x | B16: 2 | C16: Revisão do processo de obtenção de informação + Implementação de alterações | F16: =(9/(9+14)*F17)+(14/(9+14)*F24) -> 1
A17: xx | B17: =_xlfn.CONCAT( IF(A16="",1,""), IF(AND(A16<>"",LEN(A16)>LEN(A17)),_xlfn.CONCAT(LEFT(B16,(LEN(#REF!)-1)*2),MID(B16,(LEN(#REF!)-1)*2 + 1,1)+1),""), IF(AND(A16<>"",LEN(A16)<LEN(A17)),_xlfn.CONCAT(B16,".",1),""), IF(AND(A16<>"",LEN(A16)=LEN(A17)),_xlfn.CONCAT(LEFT(B16,LEN(B16)-1),RIGHT(B16,1)+1),"")) -> #NAME? | C17: Universo Corporativo (Satélites) | F17: =9/9 -> 1
A18: xxx | B18: =_xlfn.CONCAT( IF(A17="",1,""), IF(AND(A17<>"",LEN(A17)>LEN(A18)),_xlfn.CONCAT(LEFT(B17,(LEN(#REF!)-1)*2),MID(B17,(LEN(#REF!)-1)*2 + 1,1)+1),""), IF(AND(A17<>"",LEN(A17)<LEN(A18)),_xlfn.CONCAT(B17,".",1),""), IF(AND(A17<>"",LEN(A17)=LEN(A18)),_xlfn.CONCAT(LEFT(B17,LEN(B17)-1),RIGHT(B17,1)+1),"")) -> #NAME? | C18: Informação Gloval | D18: 2 | H18: =SUM(I18:EQ18)=D18 -> TRUE | AX18: 1 | BA18: 1
A19: xxx | B19: =_xlfn.CONCAT( IF(A18="",1,""), IF(AND(A18<>"",LEN(A18)>LEN(A19)),_xlfn.CONCAT(LEFT(B18,(LEN(#REF!)-1)*2),MID(B18,(LEN(#REF!)-1)*2 + 1,1)+1),""), IF(AND(A18<>"",LEN(A18)<LEN(A19)),_xlfn.CONCAT(B18,".",1),""), IF(AND(A18<>"",LEN(A18)=LEN(A19)),_xlfn.CONCAT(LEFT(B18,LEN(B18)-1),RIGHT(B18,1)+1),"")) -> #NAME? | C19: Universo Corporativo (Idcombs) | D19: 1 | H19: =SUM(I19:EQ19)=D19 -> TRUE | AX19: 1
A20: xxx | B20: =_xlfn.CONCAT( IF(A19="",1,""), IF(AND(A19<>"",LEN(A19)>LEN(A20)),_xlfn.CONCAT(LEFT(B19,(LEN(#REF!)-1)*2),MID(B19,(LEN(#REF!)-1)*2 + 1,1)+1),""), IF(AND(A19<>"",LEN(A19)<LEN(A20)),_xlfn.CONCAT(B19,".",1),""), IF(AND(A19<>"",LEN(A19)=LEN(A20)),_xlfn.CONCAT(LEFT(B19,LEN(B19)-1),RIGHT(B19,1)+1),"")) -> #NAME? | C20: Métricas (Contrato + Cliente) | D20: 1 | H20: =SUM(I20:EQ20)=D20 -> TRUE | BB20: 1
A21: xxx | B21: =_xlfn.CONCAT( IF(A20="",1,""), IF(AND(A20<>"",LEN(A20)>LEN(A21)),_xlfn.CONCAT(LEFT(B20,(LEN(#REF!)-1)*2),MID(B20,(LEN(#REF!)-1)*2 + 1,1)+1),""), IF(AND(A20<>"",LEN(A20)<LEN(A21)),_xlfn.CONCAT(B20,".",1),""), IF(AND(A20<>"",LEN(A20)=LEN(A21)),_xlfn.CONCAT(LEFT(B20,LEN(B20)-1),RIGHT(B20,1)+1),"")) -> #NAME? | C21: Métricas (Colaterais) | D21: 1 | H21: =SUM(I21:EQ21)=D21 -> TRUE | AX21: 0.75 | BC21: 0.25
A22: xxx | B22: =_xlfn.CONCAT( IF(A21="",1,""), IF(AND(A21<>"",LEN(A21)>LEN(A22)),_xlfn.CONCAT(LEFT(B21,(LEN(#REF!)-1)*2),MID(B21,(LEN(#REF!)-1)*2 + 1,1)+1),""), IF(AND(A21<>"",LEN(A21)<LEN(A22)),_xlfn.CONCAT(B21,".",1),""), IF(AND(A21<>"",LEN(A21)=LEN(A22)),_xlfn.CONCAT(LEFT(B21,LEN(B21)-1),RIGHT(B21,1)+1),"")) -> #NAME? | C22: Tratamento de adjudicados | D22: 2 | H22: =SUM(I22:EQ22)=D22 -> TRUE | AG22: 1 | BA22: 1
A23: xxx | B23: =_xlfn.CONCAT( IF(A22="",1,""), IF(AND(A22<>"",LEN(A22)>LEN(A23)),_xlfn.CONCAT(LEFT(B22,(LEN(#REF!)-1)*2),MID(B22,(LEN(#REF!)-1)*2 + 1,1)+1),""), IF(AND(A22<>"",LEN(A22)<LEN(A23)),_xlfn.CONCAT(B22,".",1),""), IF(AND(A22<>"",LEN(A22)=LEN(A23)),_xlfn.CONCAT(LEFT(B22,LEN(B22)-1),RIGHT(B22,1)+1),"")) -> #NAME? | C23: Repartição de Garantias | D23: 2 | H23: =SUM(I23:EQ23)=D23 -> TRUE | AG23: 1 | BD23: 0.75 | BE23: 0.25
A24: xx | B24: =_xlfn.CONCAT( IF(A17="",1,""), IF(AND(A17<>"",LEN(A17)>LEN(A24)),_xlfn.CONCAT(LEFT(B17,(LEN(#REF!)-1)*2),MID(B17,(LEN(#REF!)-1)*2 + 1,1)+1),""), IF(AND(A17<>"",LEN(A17)<LEN(A24)),_xlfn.CONCAT(B17,".",1),""), IF(AND(A17<>"",LEN(A17)=LEN(A24)),_xlfn.CONCAT(LEFT(B17,LEN(B17)-1),RIGHT(B17,1)+1),"")) -> #NAME? | C24: Universo Local | F24: =5/5 -> 1
A25: xxx | B25: =_xlfn.CONCAT( IF(A24="",1,""), IF(AND(A24<>"",LEN(A24)>LEN(A25)),_xlfn.CONCAT(LEFT(B24,(LEN(#REF!)-1)*2),MID(B24,(LEN(#REF!)-1)*2 + 1,1)+1),""), IF(AND(A24<>"",LEN(A24)<LEN(A25)),_xlfn.CONCAT(B24,".",1),""), IF(AND(A24<>"",LEN(A24)=LEN(A25)),_xlfn.CONCAT(LEFT(B24,LEN(B24)-1),RIGHT(B24,1)+1),"")) -> #NAME? | C25: Template 1 | D25: 1 | E25: Em sumultâneo | H25: =SUM(I25:EQ25)=D25 -> TRUE | BJ25: 1
A26: xxx | B26: =_xlfn.CONCAT( IF(A25="",1,""), IF(AND(A25<>"",LEN(A25)>LEN(A26)),_xlfn.CONCAT(LEFT(B25,(LEN(#REF!)-1)*2),MID(B25,(LEN(#REF!)-1)*2 + 1,1)+1),""), IF(AND(A25<>"",LEN(A25)<LEN(A26)),_xlfn.CONCAT(B25,".",1),""), IF(AND(A25<>"",LEN(A25)=LEN(A26)),_xlfn.CONCAT(LEFT(B25,LEN(B25)-1),RIGHT(B25,1)+1),"")) -> #NAME? | C26: Template 2 | D26: 1 | E26: Em sumultâneo | H26: =SUM(I26:EQ26)=D26 -> TRUE | BK26: 1
A27: xxx | B27: =_xlfn.CONCAT( IF(A26="",1,""), IF(AND(A26<>"",LEN(A26)>LEN(A27)),_xlfn.CONCAT(LEFT(B26,(LEN(#REF!)-1)*2),MID(B26,(LEN(#REF!)-1)*2 + 1,1)+1),""), IF(AND(A26<>"",LEN(A26)<LEN(A27)),_xlfn.CONCAT(B26,".",1),""), IF(AND(A26<>"",LEN(A26)=LEN(A27)),_xlfn.CONCAT(LEFT(B26,LEN(B26)-1),RIGHT(B26,1)+1),"")) -> #NAME? | C27: Template 4 | D27: 0 | E27: Em sumultâneo | H27: =SUM(I27:EQ27)=D27 -> TRUE
A28: xxx | B28: =_xlfn.CONCAT( IF(A27="",1,""), IF(AND(A27<>"",LEN(A27)>LEN(A28)),_xlfn.CONCAT(LEFT(B27,(LEN(#REF!)-1)*2),MID(B27,(LEN(#REF!)-1)*2 + 1,1)+1),""), IF(AND(A27<>"",LEN(A27)<LEN(A28)),_xlfn.CONCAT(B27,".",1),""), IF(AND(A27<>"",LEN(A27)=LEN(A28)),_xlfn.CONCAT(LEFT(B27,LEN(B27)-1),RIGHT(B27,1)+1),"")) -> #NAME? | C28: Template 5 | D28: 1 | E28: Em sumultâneo | H28: =SUM(I28:EQ28)=D28 -> TRUE | BK28: 1
A29: xxx | B29: =_xlfn.CONCAT( IF(A28="",1,""), IF(AND(A28<>"",LEN(A28)>LEN(A29)),_xlfn.CONCAT(LEFT(B28,(LEN(#REF!)-1)*2),MID(B28,(LEN(#REF!)-1)*2 + 1,1)+1),""), IF(AND(A28<>"",LEN(A28)<LEN(A29)),_xlfn.CONCAT(B28,".",1),""), IF(AND(A28<>"",LEN(A28)=LEN(A29)),_xlfn.CONCAT(LEFT(B28,LEN(B28)-1),RIGHT(B28,1)+1),"")) -> #NAME? | C29: Template 6 | D29: 2 | H29: =SUM(I29:EQ29)=D29 -> TRUE | BK29: 1 | BM29: 1
A30: xxx | B30: =_xlfn.CONCAT( IF(A29="",1,""), IF(AND(A29<>"",LEN(A29)>LEN(A30)),_xlfn.CONCAT(LEFT(B29,(LEN(#REF!)-1)*2),MID(B29,(LEN(#REF!)-1)*2 + 1,1)+1),""), IF(AND(A29<>"",LEN(A29)<LEN(A30)),_xlfn.CONCAT(B29,".",1),""), IF(AND(A29<>"",LEN(A29)=LEN(A30)),_xlfn.CONCAT(LEFT(B29,LEN(B29)-1),RIGHT(B29,1)+1),"")) -> #NAME? | C30: Template 7 | D30: 2 | H30: =SUM(I30:EQ30)=D30 -> TRUE | BM30: 1 | BN30: 1
A31: xxx | B31: =_xlfn.CONCAT( IF(A30="",1,""), IF(AND(A30<>"",LEN(A30)>LEN(A31)),_xlfn.CONCAT(LEFT(B30,(LEN(#REF!)-1)*2),MID(B30,(LEN(#REF!)-1)*2 + 1,1)+1),""), IF(AND(A30<>"",LEN(A30)<LEN(A31)),_xlfn.CONCAT(B30,".",1),""), IF(AND(A30<>"",LEN(A30)=LEN(A31)),_xlfn.CONCAT(LEFT(B30,LEN(B30)-1),RIGHT(B30,1)+1),"")) -> #NAME? | C31: Template 8 | D31: 2 | H31: =SUM(I31:EQ31)=D31 -> TRUE | BL31: 1 | BM31: 1
A32: xxx | B32: =_xlfn.CONCAT( IF(A31="",1,""), IF(AND(A31<>"",LEN(A31)>LEN(A32)),_xlfn.CONCAT(LEFT(B31,(LEN(#REF!)-1)*2),MID(B31,(LEN(#REF!)-1)*2 + 1,1)+1),""), IF(AND(A31<>"",LEN(A31)<LEN(A32)),_xlfn.CONCAT(B31,".",1),""), IF(AND(A31<>"",LEN(A31)=LEN(A32)),_xlfn.CONCAT(LEFT(B31,LEN(B31)-1),RIGHT(B31,1)+1),"")) -> #NAME? | C32: Template 9 | D32: 2 | H32: =SUM(I32:EQ32)=D32 -> TRUE | BL32: 0.75 | BM32: 0.75 | BN32: 0.5
A33: xxx | B33: =_xlfn.CONCAT( IF(A32="",1,""), IF(AND(A32<>"",LEN(A32)>LEN(A33)),_xlfn.CONCAT(LEFT(B32,(LEN(#REF!)-1)*2),MID(B32,(LEN(#REF!)-1)*2 + 1,1)+1),""), IF(AND(A32<>"",LEN(A32)<LEN(A33)),_xlfn.CONCAT(B32,".",1),""), IF(AND(A32<>"",LEN(A32)=LEN(A33)),_xlfn.CONCAT(LEFT(B32,LEN(B32)-1),RIGHT(B32,1)+1),"")) -> #NAME? | C33: Template 10 | D33: 1 | E33: Em sumultâneo | H33: =SUM(I33:EQ33)=D33 -> TRUE | BL33: 1
A34: xxx | B34: =_xlfn.CONCAT( IF(A33="",1,""), IF(AND(A33<>"",LEN(A33)>LEN(A34)),_xlfn.CONCAT(LEFT(B33,(LEN(#REF!)-1)*2),MID(B33,(LEN(#REF!)-1)*2 + 1,1)+1),""), IF(AND(A33<>"",LEN(A33)<LEN(A34)),_xlfn.CONCAT(B33,".",1),""), IF(AND(A33<>"",LEN(A33)=LEN(A34)),_xlfn.CONCAT(LEFT(B33,LEN(B33)-1),RIGHT(B33,1)+1),"")) -> #NAME? | C34: Template 1 - STE | D34: 1 | E34: Em sumultâneo | H34: =SUM(I34:EQ34)=D34 -> TRUE | BJ34: 0.25 | BK34: 0.75
A35: xxx | B35: =_xlfn.CONCAT( IF(A34="",1,""), IF(AND(A34<>"",LEN(A34)>LEN(A35)),_xlfn.CONCAT(LEFT(B34,(LEN(#REF!)-1)*2),MID(B34,(LEN(#REF!)-1)*2 + 1,1)+1),""), IF(AND(A34<>"",LEN(A34)<LEN(A35)),_xlfn.CONCAT(B34,".",1),""), IF(AND(A34<>"",LEN(A34)=LEN(A35)),_xlfn.CONCAT(LEFT(B34,LEN(B34)-1),RIGHT(B34,1)+1),"")) -> #NAME? | C35: Template 2 - STE | D35: 1 | E35: Em sumultâneo | H35: =SUM(I35:EQ35)=D35 -> TRUE | BL35: 1
A36: x | B36: 3 | C36: Revisão do mapeamento de Satélites + Implementação de alterações | F36: =(SUM(D38:D43)/SUM(D38:D43,D45:D55)*F44)+(SUM(D45:D55)/SUM(D38:D43,D45:D55)*F37) -> 0.8065677
A37: xx | B37: =_xlfn.CONCAT( IF(A36="",1,""), IF(AND(A36<>"",LEN(A36)>LEN(A37)),_xlfn.CONCAT(LEFT(B36,(LEN(#REF!)-1)*2),MID(B36,(LEN(#REF!)-1)*2 + 1,1)+1),""), IF(AND(A36<>"",LEN(A36)<LEN(A37)),_xlfn.CONCAT(B36,".",1),""), IF(AND(A36<>"",LEN(A36)=LEN(A37)),_xlfn.CONCAT(LEFT(B36,LEN(B36)-1),RIGHT(B36,1)+1),"")) -> #NAME? | C37: Universo Corporativo (Satélites) | F37: =20/20 -> 1 | AG37: 1 | AH37: 1 | AI37: 1 | AJ37: 1 | AK37: 1 | AL37: 1 | AM37: 1 | AN37: 1 | AO37: 1 | AP37: 1 | AX37: 1 | AY37: 1 | AZ37: 1 | BA37: 1 | BB37: 1 | BC37: 1 | BD37: 1 | BE37: 1 | BF37: 1
A38: xxx | B38: =_xlfn.CONCAT( IF(A37="",1,""), IF(AND(A37<>"",LEN(A37)>LEN(A38)),_xlfn.CONCAT(LEFT(B37,(LEN(#REF!)-1)*2),MID(B37,(LEN(#REF!)-1)*2 + 1,1)+1),""), IF(AND(A37<>"",LEN(A37)<LEN(A38)),_xlfn.CONCAT(B37,".",1),""), IF(AND(A37<>"",LEN(A37)=LEN(A38)),_xlfn.CONCAT(LEFT(B37,LEN(B37)-1),RIGHT(B37,1)+1),"")) -> #NAME? | C38: Satélite 79 | D38: 6 | H38: =SUM(I38:EQ38)=D38 -> TRUE | AG38: 1 | AH38: 1 | AI38: 1 | AJ38: 1 | AK38: 1 | AL38: 1
A39: xxx | B39: =_xlfn.CONCAT( IF(A38="",1,""), IF(AND(A38<>"",LEN(A38)>LEN(A39)),_xlfn.CONCAT(LEFT(B38,(LEN(#REF!)-1)*2),MID(B38,(LEN(#REF!)-1)*2 + 1,1)+1),""), IF(AND(A38<>"",LEN(A38)<LEN(A39)),_xlfn.CONCAT(B38,".",1),""), IF(AND(A38<>"",LEN(A38)=LEN(A39)),_xlfn.CONCAT(LEFT(B38,LEN(B38)-1),RIGHT(B38,1)+1),"")) -> #NAME? | C39: Satélite 80 | D39: 3 | H39: =SUM(I39:EQ39)=D39 -> TRUE | AG39: 0.75 | AH39: 0.25 | BE39: 1 | BF39: 1
A40: xxx | B40: =_xlfn.CONCAT( IF(A39="",1,""), IF(AND(A39<>"",LEN(A39)>LEN(A40)),_xlfn.CONCAT(LEFT(B39,(LEN(#REF!)-1)*2),MID(B39,(LEN(#REF!)-1)*2 + 1,1)+1),""), IF(AND(A39<>"",LEN(A39)<LEN(A40)),_xlfn.CONCAT(B39,".",1),""), IF(AND(A39<>"",LEN(A39)=LEN(A40)),_xlfn.CONCAT(LEFT(B39,LEN(B39)-1),RIGHT(B39,1)+1),"")) -> #NAME? | C40: Satélite 83 | D40: 7 | H40: =SUM(I40:EQ40)=D40 -> TRUE | AH40: 1 | AI40: 1 | AJ40: 1 | AK40: 1 | AL40: 1 | BD40: 1 | BE40: 1
A41: xxx | B41: =_xlfn.CONCAT( IF(A40="",1,""), IF(AND(A40<>"",LEN(A40)>LEN(A41)),_xlfn.CONCAT(LEFT(B40,(LEN(#REF!)-1)*2),MID(B40,(LEN(#REF!)-1)*2 + 1,1)+1),""), IF(AND(A40<>"",LEN(A40)<LEN(A41)),_xlfn.CONCAT(B40,".",1),""), IF(AND(A40<>"",LEN(A40)=LEN(A41)),_xlfn.CONCAT(LEFT(B40,LEN(B40)-1),RIGHT(B40,1)+1),"")) -> #NAME? | C41: Satélite 84 | D41: 12 | H41: =SUM(I41:EQ41)=D41 -> TRUE | AH41: 1 | AI41: 1 | AJ41: 1 | AK41: 1 | AL41: 1 | AM41: 1 | AN41: 1 | AO41: 1 | AP41: 1 | AY41: 1 | AZ41: 1 | BF41: 1
A42: xxx | B42: =_xlfn.CONCAT( IF(A41="",1,""), IF(AND(A41<>"",LEN(A41)>LEN(A42)),_xlfn.CONCAT(LEFT(B41,(LEN(#REF!)-1)*2),MID(B41,(LEN(#REF!)-1)*2 + 1,1)+1),""), IF(AND(A41<>"",LEN(A41)<LEN(A42)),_xlfn.CONCAT(B41,".",1),""), IF(AND(A41<>"",LEN(A41)=LEN(A42)),_xlfn.CONCAT(LEFT(B41,LEN(B41)-1),RIGHT(B41,1)+1),"")) -> #NAME? | C42: Satélite 93 | D42: 5 | H42: =SUM(I42:EQ42)=D42 -> TRUE | AM42: 1 | AN42: 1 | AO42: 1 | BF42: 1 | BG42: 1
A43: xxx | B43: =_xlfn.CONCAT( IF(A42="",1,""), IF(AND(A42<>"",LEN(A42)>LEN(A43)),_xlfn.CONCAT(LEFT(B42,(LEN(#REF!)-1)*2),MID(B42,(LEN(#REF!)-1)*2 + 1,1)+1),""), IF(AND(A42<>"",LEN(A42)<LEN(A43)),_xlfn.CONCAT(B42,".",1),""), IF(AND(A42<>"",LEN(A42)=LEN(A43)),_xlfn.CONCAT(LEFT(B42,LEN(B42)-1),RIGHT(B42,1)+1),"")) -> #NAME? | C43: Satélite 109 | D43: 10 | H43: =SUM(I43:EQ43)=D43 -> TRUE | AH43: 0.5 | AI43: 0.75 | AJ43: 0.75 | AK43: 0.75 | AL43: 0.75 | AM43: 0.75 | AN43: 0.75 | AO43: 0.75 | AP43: 0.75 | AY43: 0.75 | AZ43: 0.75 | BA43: 0.75 | BB43: 0.75 | BC43: 0.5
A44: xx | B44: =_xlfn.CONCAT( IF(A37="",1,""), IF(AND(A37<>"",LEN(A37)>LEN(A44)),_xlfn.CONCAT(LEFT(B37,(LEN(#REF!)-1)*2),MID(B37,(LEN(#REF!)-1)*2 + 1,1)+1),""), IF(AND(A37<>"",LEN(A37)<LEN(A44)),_xlfn.CONCAT(B37,".",1),""), IF(AND(A37<>"",LEN(A37)=LEN(A44)),_xlfn.CONCAT(LEFT(B37,LEN(B37)-1),RIGHT(B37,1)+1),"")) -> #NAME? | C44: Universo Local | F44: =9/19 -> 0.47368421
A45: xxx | B45: =_xlfn.CONCAT( IF(A44="",1,""), IF(AND(A44<>"",LEN(A44)>LEN(A45)),_xlfn.CONCAT(LEFT(B44,(LEN(#REF!)-1)*2),MID(B44,(LEN(#REF!)-1)*2 + 1,1)+1),""), IF(AND(A44<>"",LEN(A44)<LEN(A45)),_xlfn.CONCAT(B44,".",1),""), IF(AND(A44<>"",LEN(A44)=LEN(A45)),_xlfn.CONCAT(LEFT(B44,LEN(B44)-1),RIGHT(B44,1)+1),"")) -> #NAME? | C45: Template 1 | D45: 4 | H45: =SUM(I45:EQ45)=D45 -> TRUE | BN45: 1 | BO45: 1 | BP45: 1 | BQ45: 1
A46: xxx | B46: =_xlfn.CONCAT( IF(A45="",1,""), IF(AND(A45<>"",LEN(A45)>LEN(A46)),_xlfn.CONCAT(LEFT(B45,(LEN(#REF!)-1)*2),MID(B45,(LEN(#REF!)-1)*2 + 1,1)+1),""), IF(AND(A45<>"",LEN(A45)<LEN(A46)),_xlfn.CONCAT(B45,".",1),""), IF(AND(A45<>"",LEN(A45)=LEN(A46)),_xlfn.CONCAT(LEFT(B45,LEN(B45)-1),RIGHT(B45,1)+1),"")) -> #NAME? | C46: Template 2 | D46: 2 | H46: =SUM(I46:EQ46)=D46 -> TRUE | BO46: 1 | BP46: 1
...

Sheet Macroplano_v2
C2: BS - ESG Pilar 3
C3: Plano de Atividades
I6: =SUM(I13:I96)=4 -> FALSE | J6: =SUM(J13:J96)=4 -> FALSE | K6: =SUM(K13:K96)=4 -> FALSE | L6: =SUM(L13:L96)=4 -> FALSE | M6: =SUM(M13:M96)=4 -> FALSE | N6: =SUM(N13:N96)=4 -> FALSE | O6: =SUM(O13:O96)=4 -> FALSE | P6: =SUM(P13:P96)=4 -> FALSE | ... CN6: =SUM(CN13:CN96)=4 -> FALSE | CP6: =SUM(CP13:CP96)=4 -> FALSE | CQ6: =SUM(CQ13:CQ96)=4 -> FALSE | CR6: =SUM(CR13:CR96)=4 -> FALSE | CS6: =SUM(CS13:CS96)=4 -> FALSE | CT6: =SUM(CT13:CT96)=4 -> FALSE | CU6: =SUM(CU13:CU96)=4 -> FALSE | CV6: =SUM(CV13:CV96)=4 -> FALSE | CW6: =SUM(CW13:CW96)=4 -> FALSE | ... FD6: =SUM(FD13:FD96)=4 -> FALSE
I7: Novembro | AA7: Dezembro | AF7: Dezembro | AW7: Janeiro | BT7: Fevereiro | CP7: Março | DM7: Abril | EH7: Maio
B11: ID | C11: Atividade | D11: Nº dias | E11: Data Início | F11: Status PPT | G11: FTEs (#) | I11: 45238 | J11: =I11+1 -> 45239 | K11: =J11+1 -> 45240 | L11: 45243 | M11: =L11+1 -> 45244 | N11: =M11+1 -> 45245 | O11: =N11+1 -> 45246 | P11: =O11+1 -> 45247 | Q11: 45250 | R11: =Q11+1 -> 45251 | S11: =R11+1 -> 45252 | T11: =S11+1 -> 45253 | U11: =T11+1 -> 45254 | V11: 45257 | W11: =V11+1 -> 45258 | X11: =W11+1 -> 45259 | Y11: =X11+1 -> 45260 | AA11: =Y11+1 -> 45261 | AB11: 45234 | AC11: =AB11+1 -> 45235 | AD11: =AC11+1 -> 45236 | AE11: =AD11+1 -> 45237 | AF11: =AE11+1 -> 45238 | AG11: 45241 | AH11: =AG11+1 -> 45242 | AI11: =AH11+1 -> 45243 | AJ11: =AI11+1 -> 45244 | AK11: =AJ11+1 -> 45245 | AL11: 45248 | AM11: 45249 | AN11: 45250 | AO11: 45251 | AP11: 45252 | AQ11: =AP11+3 -> 45255 | AR11: =AQ11+1 -> 45256 | AS11: =AR11+1 -> 45257 | AT11: =AS11+1 -> 45258 | AU11: =AT11+1 -> 45259 | AW11: =AU11+2 -> 45261 | AX11: =AW11+1 -> 45262 | AY11: =AX11+1 -> 45263 | AZ11: =AY11+1 -> 45264 | BA11: =AZ11+1 -> 45265 | BB11: =BA11+3 -> 45268 | BC11: =BB11+1 -> 45269 | BD11: =BC11+1 -> 45270 | BE11: =BD11+1 -> 45271 | BF11: =BE11+1 -> 45272 | BG11: =BF11+3 -> 45275 | BH11: =BG11+1 -> 45276 | BI11: =BH11+1 -> 45277 | BJ11: =BI11+1 -> 45278 | BK11: =BJ11+1 -> 45279 | BL11: =BK11+3 -> 45282 | BM11: =BL11+1 -> 45283 | BN11: =BM11+1 -> 45284 | BO11: =BN11+1 -> 45285 | BP11: =BO11+1 -> 45286 | BQ11: =BP11+3 -> 45289 | BR11: =BQ11+1 -> 45290 | BT11: =BR11+1 -> 45291 | BU11: =BT11+1 -> 45292 | BV11: =BU11+1 -> 45293 | BW11: =BV11+3 -> 45296 | BX11: =BW11+1 -> 45297 | BY11: =BX11+1 -> 45298 | BZ11: =BY11+1 -> 45299 | CA11: =BZ11+1 -> 45300 | CB11: =CA11+3 -> 45303 | CC11: =CB11+1 -> 45304 | CD11: =CC11+1 -> 45305 | CE11: =CD11+1 -> 45306 | CF11: =CE11+1 -> 45307 | CG11: =CF11+3 -> 45310 | CH11: =CG11+1 -> 45311 | CI11: =CH11+1 -> 45312 | CJ11: =CI11+1 -> 45313 | CK11: =CJ11+1 -> 45314 | CL11: =CK11+3 -> 45317 | CM11: =CL11+1 -> 45318 | CN11: =CM11+1 -> 45319 | CP11: 1 | CQ11: =CP11+1 -> 2 | CR11: =CQ11+2 -> 4 | CS11: =CR11+1 -> 5 | CT11: =CS11+1 -> 6 | CU11: =CT11+1 -> 7 | CV11: =CU11+1 -> 8 | CW11: =CV11+3 -> 11 | CX11: =CW11+1 -> 12 | CY11: =CX11+1 -> 13 | CZ11: =CY11+1 -> 14 | DA11: =CZ11+1 -> 15 | DB11: =DA11+3 -> 18 | DC11: =DB11+1 -> 19 | DD11: =DC11+1 -> 20 | DE11: =DD11+1 -> 21 | DF11: =DE11+1 -> 22 | DG11: =DF11+3 -> 25 | DH11: =DG11+1 -> 26 | DI11: =DH11+1 -> 27 | DJ11: =DI11+1 -> 28 | DK11: =DJ11+1 -> 29 | DM11: =DK11+3 -> 32 | DN11: =DM11+1 -> 33 | DO11: =DN11+1 -> 34 | DP11: =DO11+1 -> 35 | DQ11: =DP11+1 -> 36 | DR11: =DQ11+3 -> 39 | DS11: =DR11+1 -> 40 | DT11: =DS11+1 -> 41 | DU11: =DT11+1 -> 42 | DV11: =DU11+1 -> 43 | DW11: =DV11+3 -> 46 | DX11: =DW11+1 -> 47 | DY11: =DX11+1 -> 48 | DZ11: =DY11+1 -> 49 | EA11: =DZ11+1 -> 50 | EB11: =EA11+3 -> 53 | EC11: =EB11+1 -> 54 | ED11: =EC11+1 -> 55 | EE11: =ED11+1 -> 56 | EF11: =EE11+1 -> 57 | EH11: =EF11+3 -> 60 | EI11: =EH11+1 -> 61 | EJ11: =EI11+1 -> 62 | EK11: =EJ11+1 -> 63 | EL11: =EK11+1 -> 64 | EM11: =EL11+2 -> 66 | EN11: =EM11+1 -> 67 | EO11: =EN11+1 -> 68 | EP11: =EO11+1 -> 69 | EQ11: =EP11+1 -> 70 | ER11: =EQ11+3 -> 73 | ES11: =ER11+1 -> 74 | ET11: =ES11+1 -> 75 | EU11: =ET11+1 -> 76 | EV11: =EU11+1 -> 77 | EW11: =EV11+3 -> 80 | EX11: =EW11+1 -> 81 | EY11: =EX11+1 -> 82 | EZ11: =EY11+1 -> 83 | FA11: =EZ11+1 -> 84 | FB11: =FA11+3 -> 87 | FC11: =FB11+1 -> 88 | FD11: =FC11+1 -> 89
A12: x | B12: 0 | C12: Gestão
A13: xxx | B13: =_xlfn.CONCAT( IF(A12="",1,""), IF(AND(A12<>"",LEN(A12)>LEN(A13)),_xlfn.CONCAT(LEFT(B12,(LEN(#REF!)-1)*2),MID(B12,(LEN(#REF!)-1)*2 + 1,1)+1),""), IF(AND(A12<>"",LEN(A12)<LEN(A13)),_xlfn.CONCAT(B12,".",1),""), IF(AND(A12<>"",LEN(A12)=LEN(A13)),_xlfn.CONCAT(LEFT(B12,LEN(B12)-1),RIGHT(B12,1)+1),"")) -> #NAME? | C13: Gestão e acompanhamento de equipa | I13: 0.25 | J13: 0.25 | K13: 0.25 | L13: 0.25 | M13: 0.25 | N13: 0.25 | O13: 0.25 | P13: 0.25 | Q13: 0.25 | R13: 0.25 | S13: 0.25 | T13: 0.25 | U13: 0.25 | V13: 0.25 | W13: 0.25 | X13: 0.25 | Y13: 0.25 | AA13: 0.25 | AB13: 0.25 | AC13: 0.25 | AD13: 0.25 | AE13: 0.25 | AF13: 0.25 | AG13: 0.25 | AH13: 0.25 | AI13: 0.25 | AJ13: 0.25 | AK13: 0.25 | AL13: 0.25 | AM13: 0.25 | AN13: 0.25 | AO13: 0.25 | AP13: 0.25 | AX13: 0.25 | AY13: 0.25 | AZ13: 0.25 | BA13: 0.25 | BB13: 0.25 | BC13: 0.25 | BD13: 0.25 | BE13: 0.25 | BF13: 0.25 | BG13: 0.25 | BH13: 0.25 | BI13: 0.25 | BJ13: 0.25 | BK13: 0.25 | BL13: 0.25 | BM13: 0.25 | BN13: 0.25 | BO13: 0.25 | BP13: 0.25 | BQ13: 0.25 | BR13: 0.25 | BS13: 0.25 | BT13: 0.25 | BU13: 0.25 | BV13: 0.25 | BW13: 0.25 | BX13: 0.25 | BY13: 0.25 | BZ13: 0.25 | CA13: 0.25 | CB13: 0.25 | CC13: 0.25 | CD13: 0.25 | CE13: 0.25 | CF13: 0.25 | CG13: 0.25 | CH13: 0.25 | CI13: 0.25 | CJ13: 0.25 | CK13: 0.25 | CL13: 0.25 | CM13: 0.25 | CN13: 0.25 | CP13: 0.25 | CQ13: 0.25 | CR13: 0.25 | CS13: 0.25 | CT13: 0.25 | CU13: 0.25 | CV13: 0.25
A14: x | B14: 1 | C14: Importação e prepração de ficheiros
A15: xxx | B15: =_xlfn.CONCAT( IF(A14="",1,""), IF(AND(A14<>"",LEN(A14)>LEN(A15)),_xlfn.CONCAT(LEFT(B14,(LEN(#REF!)-1)*2),MID(B14,(LEN(#REF!)-1)*2 + 1,1)+1),""), IF(AND(A14<>"",LEN(A14)<LEN(A15)),_xlfn.CONCAT(B14,".",1),""), IF(AND(A14<>"",LEN(A14)=LEN(A15)),_xlfn.CONCAT(LEFT(B14,LEN(B14)-1),RIGHT(B14,1)+1),"")) -> #NAME? | C15: Importação de tabelas input | D15: 2 | F15: =2/2 -> 1 | AF15: 2
A16: x | B16: 2 | C16: Revisão do processo de obtenção de informação + Implementação de alterações | F16: =(SUM(D18:D23)/SUM(D18:D23,D25:D35)*F17)+(SUM(D25:D35)/SUM(D18:D23,D25:D35)*F24) -> 1
A17: xx | B17: =_xlfn.CONCAT( IF(A16="",1,""), IF(AND(A16<>"",LEN(A16)>LEN(A17)),_xlfn.CONCAT(LEFT(B16,(LEN(#REF!)-1)*2),MID(B16,(LEN(#REF!)-1)*2 + 1,1)+1),""), IF(AND(A16<>"",LEN(A16)<LEN(A17)),_xlfn.CONCAT(B16,".",1),""), IF(AND(A16<>"",LEN(A16)=LEN(A17)),_xlfn.CONCAT(LEFT(B16,LEN(B16)-1),RIGHT(B16,1)+1),"")) -> #NAME? | C17: Universo Corporativo (Satélites) | F17: =9/9 -> 1
A18: xxx | B18: =_xlfn.CONCAT( IF(A17="",1,""), IF(AND(A17<>"",LEN(A17)>LEN(A18)),_xlfn.CONCAT(LEFT(B17,(LEN(#REF!)-1)*2),MID(B17,(LEN(#REF!)-1)*2 + 1,1)+1),""), IF(AND(A17<>"",LEN(A17)<LEN(A18)),_xlfn.CONCAT(B17,".",1),""), IF(AND(A17<>"",LEN(A17)=LEN(A18)),_xlfn.CONCAT(LEFT(B17,LEN(B17)-1),RIGHT(B17,1)+1),"")) -> #NAME? | C18: Informação Gloval | D18: 2 | H18: =SUM(I18:EQ18)=D18 -> TRUE | AX18: 1 | BA18: 1
A19: xxx | B19: =_xlfn.CONCAT( IF(A18="",1,""), IF(AND(A18<>"",LEN(A18)>LEN(A19)),_xlfn.CONCAT(LEFT(B18,(LEN(#REF!)-1)*2),MID(B18,(LEN(#REF!)-1)*2 + 1,1)+1),""), IF(AND(A18<>"",LEN(A18)<LEN(A19)),_xlfn.CONCAT(B18,".",1),""), IF(AND(A18<>"",LEN(A18)=LEN(A19)),_xlfn.CONCAT(LEFT(B18,LEN(B18)-1),RIGHT(B18,1)+1),"")) -> #NAME? | C19: Universo Corporativo (Idcombs) | D19: 1 | H19: =SUM(I19:EQ19)=D19 -> TRUE | AX19: 1
A20: xxx | B20: =_xlfn.CONCAT( IF(A19="",1,""), IF(AND(A19<>"",LEN(A19)>LEN(A20)),_xlfn.CONCAT(LEFT(B19,(LEN(#REF!)-1)*2),MID(B19,(LEN(#REF!)-1)*2 + 1,1)+1),""), IF(AND(A19<>"",LEN(A19)<LEN(A20)),_xlfn.CONCAT(B19,".",1),""), IF(AND(A19<>"",LEN(A19)=LEN(A20)),_xlfn.CONCAT(LEFT(B19,LEN(B19)-1),RIGHT(B19,1)+1),"")) -> #NAME? | C20: Métricas (Contrato + Cliente) | D20: 1 | H20: =SUM(I20:EQ20)=D20 -> TRUE | BB20: 1
A21: xxx | B21: =_xlfn.CONCAT( IF(A20="",1,""), IF(AND(A20<>"",LEN(A20)>LEN(A21)),_xlfn.CONCAT(LEFT(B20,(LEN(#REF!)-1)*2),MID(B20,(LEN(#REF!)-1)*2 + 1,1)+1),""), IF(AND(A20<>"",LEN(A20)<LEN(A21)),_xlfn.CONCAT(B20,".",1),""), IF(AND(A20<>"",LEN(A20)=LEN(A21)),_xlfn.CONCAT(LEFT(B20,LEN(B20)-1),RIGHT(B20,1)+1),"")) -> #NAME? | C21: Métricas (Colaterais) | D21: 1 | H21: =SUM(I21:EQ21)=D21 -> TRUE | AX21: 0.75 | BC21: 0.25
A22: xxx | B22: =_xlfn.CONCAT( IF(A21="",1,""), IF(AND(A21<>"",LEN(A21)>LEN(A22)),_xlfn.CONCAT(LEFT(B21,(LEN(#REF!)-1)*2),MID(B21,(LEN(#REF!)-1)*2 + 1,1)+1),""), IF(AND(A21<>"",LEN(A21)<LEN(A22)),_xlfn.CONCAT(B21,".",1),""), IF(AND(A21<>"",LEN(A21)=LEN(A22)),_xlfn.CONCAT(LEFT(B21,LEN(B21)-1),RIGHT(B21,1)+1),"")) -> #NAME? | C22: Tratamento de adjudicados | D22: 2 | H22: =SUM(I22:EQ22)=D22 -> TRUE | AG22: 1 | BA22: 1
A23: xxx | B23: =_xlfn.CONCAT( IF(A22="",1,""), IF(AND(A22<>"",LEN(A22)>LEN(A23)),_xlfn.CONCAT(LEFT(B22,(LEN(#REF!)-1)*2),MID(B22,(LEN(#REF!)-1)*2 + 1,1)+1),""), IF(AND(A22<>"",LEN(A22)<LEN(A23)),_xlfn.CONCAT(B22,".",1),""), IF(AND(A22<>"",LEN(A22)=LEN(A23)),_xlfn.CONCAT(LEFT(B22,LEN(B22)-1),RIGHT(B22,1)+1),"")) -> #NAME? | C23: Repartição de Garantias | D23: 2 | H23: =SUM(I23:EQ23)=D23 -> TRUE | AG23: 1 | BD23: 0.75 | BE23: 0.25
A24: xx | B24: =_xlfn.CONCAT( IF(A17="",1,""), IF(AND(A17<>"",LEN(A17)>LEN(A24)),_xlfn.CONCAT(LEFT(B17,(LEN(#REF!)-1)*2),MID(B17,(LEN(#REF!)-1)*2 + 1,1)+1),""), IF(AND(A17<>"",LEN(A17)<LEN(A24)),_xlfn.CONCAT(B17,".",1),""), IF(AND(A17<>"",LEN(A17)=LEN(A24)),_xlfn.CONCAT(LEFT(B17,LEN(B17)-1),RIGHT(B17,1)+1),"")) -> #NAME? | C24: Universo Local | F24: =5/5 -> 1 | BV24: 1 | BW24: 1 | BX24: 1 | BY24: 1 | BZ24: 1
A25: xxx | B25: =_xlfn.CONCAT( IF(A24="",1,""), IF(AND(A24<>"",LEN(A24)>LEN(A25)),_xlfn.CONCAT(LEFT(B24,(LEN(#REF!)-1)*2),MID(B24,(LEN(#REF!)-1)*2 + 1,1)+1),""), IF(AND(A24<>"",LEN(A24)<LEN(A25)),_xlfn.CONCAT(B24,".",1),""), IF(AND(A24<>"",LEN(A24)=LEN(A25)),_xlfn.CONCAT(LEFT(B24,LEN(B24)-1),RIGHT(B24,1)+1),"")) -> #NAME? | C25: Template 1 | D25: 1 | E25: Em sumultâneo | H25: =SUM(I25:EQ25)=D25 -> TRUE | BV25: 1
A26: xxx | B26: =_xlfn.CONCAT( IF(A25="",1,""), IF(AND(A25<>"",LEN(A25)>LEN(A26)),_xlfn.CONCAT(LEFT(B25,(LEN(#REF!)-1)*2),MID(B25,(LEN(#REF!)-1)*2 + 1,1)+1),""), IF(AND(A25<>"",LEN(A25)<LEN(A26)),_xlfn.CONCAT(B25,".",1),""), IF(AND(A25<>"",LEN(A25)=LEN(A26)),_xlfn.CONCAT(LEFT(B25,LEN(B25)-1),RIGHT(B25,1)+1),"")) -> #NAME? | C26: Template 2 | D26: 1 | E26: Em sumultâneo | H26: =SUM(I26:EQ26)=D26 -> TRUE | BW26: 1
A27: xxx | B27: =_xlfn.CONCAT( IF(A26="",1,""), IF(AND(A26<>"",LEN(A26)>LEN(A27)),_xlfn.CONCAT(LEFT(B26,(LEN(#REF!)-1)*2),MID(B26,(LEN(#REF!)-1)*2 + 1,1)+1),""), IF(AND(A26<>"",LEN(A26)<LEN(A27)),_xlfn.CONCAT(B26,".",1),""), IF(AND(A26<>"",LEN(A26)=LEN(A27)),_xlfn.CONCAT(LEFT(B26,LEN(B26)-1),RIGHT(B26,1)+1),"")) -> #NAME? | C27: Template 4 | D27: 0 | E27: Em sumultâneo | H27: =SUM(I27:EQ27)=D27 -> TRUE
A28: xxx | B28: =_xlfn.CONCAT( IF(A27="",1,""), IF(AND(A27<>"",LEN(A27)>LEN(A28)),_xlfn.CONCAT(LEFT(B27,(LEN(#REF!)-1)*2),MID(B27,(LEN(#REF!)-1)*2 + 1,1)+1),""), IF(AND(A27<>"",LEN(A27)<LEN(A28)),_xlfn.CONCAT(B27,".",1),""), IF(AND(A27<>"",LEN(A27)=LEN(A28)),_xlfn.CONCAT(LEFT(B27,LEN(B27)-1),RIGHT(B27,1)+1),"")) -> #NAME? | C28: Template 5 | D28: 1 | E28: Em sumultâneo | H28: =SUM(I28:EQ28)=D28 -> TRUE | BW28: 1
A29: xxx | B29: =_xlfn.CONCAT( IF(A28="",1,""), IF(AND(A28<>"",LEN(A28)>LEN(A29)),_xlfn.CONCAT(LEFT(B28,(LEN(#REF!)-1)*2),MID(B28,(LEN(#REF!)-1)*2 + 1,1)+1),""), IF(AND(A28<>"",LEN(A28)<LEN(A29)),_xlfn.CONCAT(B28,".",1),""), IF(AND(A28<>"",LEN(A28)=LEN(A29)),_xlfn.CONCAT(LEFT(B28,LEN(B28)-1),RIGHT(B28,1)+1),"")) -> #NAME? | C29: Template 6 | D29: 2 | H29: =SUM(I29:EQ29)=D29 -> TRUE | BW29: 1 | BY29: 1
A30: xxx | B30: =_xlfn.CONCAT( IF(A29="",1,""), IF(AND(A29<>"",LEN(A29)>LEN(A30)),_xlfn.CONCAT(LEFT(B29,(LEN(#REF!)-1)*2),MID(B29,(LEN(#REF!)-1)*2 + 1,1)+1),""), IF(AND(A29<>"",LEN(A29)<LEN(A30)),_xlfn.CONCAT(B29,".",1),""), IF(AND(A29<>"",LEN(A29)=LEN(A30)),_xlfn.CONCAT(LEFT(B29,LEN(B29)-1),RIGHT(B29,1)+1),"")) -> #NAME? | C30: Template 7 | D30: 2 | H30: =SUM(I30:EQ30)=D30 -> TRUE | BY30: 1 | BZ30: 1
A31: xxx | B31: =_xlfn.CONCAT( IF(A30="",1,""), IF(AND(A30<>"",LEN(A30)>LEN(A31)),_xlfn.CONCAT(LEFT(B30,(LEN(#REF!)-1)*2),MID(B30,(LEN(#REF!)-1)*2 + 1,1)+1),""), IF(AND(A30<>"",LEN(A30)<LEN(A31)),_xlfn.CONCAT(B30,".",1),""), IF(AND(A30<>"",LEN(A30)=LEN(A31)),_xlfn.CONCAT(LEFT(B30,LEN(B30)-1),RIGHT(B30,1)+1),"")) -> #NAME? | C31: Template 8 | D31: 2 | H31: =SUM(I31:EQ31)=D31 -> TRUE | BX31: 1 | BY31: 1
A32: xxx | B32: =_xlfn.CONCAT( IF(A31="",1,""), IF(AND(A31<>"",LEN(A31)>LEN(A32)),_xlfn.CONCAT(LEFT(B31,(LEN(#REF!)-1)*2),MID(B31,(LEN(#REF!)-1)*2 + 1,1)+1),""), IF(AND(A31<>"",LEN(A31)<LEN(A32)),_xlfn.CONCAT(B31,".",1),""), IF(AND(A31<>"",LEN(A31)=LEN(A32)),_xlfn.CONCAT(LEFT(B31,LEN(B31)-1),RIGHT(B31,1)+1),"")) -> #NAME? | C32: Template 9 | D32: 2 | H32: =SUM(I32:EQ32)=D32 -> TRUE | BX32: 0.75 | BY32: 0.75 | BZ32: 0.5
A33: xxx | B33: =_xlfn.CONCAT( IF(A32="",1,""), IF(AND(A32<>"",LEN(A32)>LEN(A33)),_xlfn.CONCAT(LEFT(B32,(LEN(#REF!)-1)*2),MID(B32,(LEN(#REF!)-1)*2 + 1,1)+1),""), IF(AND(A32<>"",LEN(A32)<LEN(A33)),_xlfn.CONCAT(B32,".",1),""), IF(AND(A32<>"",LEN(A32)=LEN(A33)),_xlfn.CONCAT(LEFT(B32,LEN(B32)-1),RIGHT(B32,1)+1),"")) -> #NAME? | C33: Template 10 | D33: 1 | E33: Em sumultâneo | H33: =SUM(I33:EQ33)=D33 -> TRUE | BX33: 1
A34: xxx | B34: =_xlfn.CONCAT( IF(A33="",1,""), IF(AND(A33<>"",LEN(A33)>LEN(A34)),_xlfn.CONCAT(LEFT(B33,(LEN(#REF!)-1)*2),MID(B33,(LEN(#REF!)-1)*2 + 1,1)+1),""), IF(AND(A33<>"",LEN(A33)<LEN(A34)),_xlfn.CONCAT(B33,".",1),""), IF(AND(A33<>"",LEN(A33)=LEN(A34)),_xlfn.CONCAT(LEFT(B33,LEN(B33)-1),RIGHT(B33,1)+1),"")) -> #NAME? | C34: Template 1 - STE | D34: 1 | E34: Em sumultâneo | H34: =SUM(I34:EQ34)=D34 -> TRUE | BV34: 0.25 | BW34: 0.75
A35: xxx | B35: =_xlfn.CONCAT( IF(A34="",1,""), IF(AND(A34<>"",LEN(A34)>LEN(A35)),_xlfn.CONCAT(LEFT(B34,(LEN(#REF!)-1)*2),MID(B34,(LEN(#REF!)-1)*2 + 1,1)+1),""), IF(AND(A34<>"",LEN(A34)<LEN(A35)),_xlfn.CONCAT(B34,".",1),""), IF(AND(A34<>"",LEN(A34)=LEN(A35)),_xlfn.CONCAT(LEFT(B34,LEN(B34)-1),RIGHT(B34,1)+1),"")) -> #NAME? | C35: Template 2 - STE | D35: 1 | E35: Em sumultâneo | H35: =SUM(I35:EQ35)=D35 -> TRUE | BX35: 1
A36: x | B36: 3 | C36: Revisão do mapeamento de Satélites + Implementação de alterações | F36: =(SUM(D38:D43)/SUM(D38:D43,D45:D55)*F37)+(SUM(D45:D55)/SUM(D38:D43,D45:D55)*F44) -> 0.54822955
A37: xx | B37: =_xlfn.CONCAT( IF(A36="",1,""), IF(AND(A36<>"",LEN(A36)>LEN(A37)),_xlfn.CONCAT(LEFT(B36,(LEN(#REF!)-1)*2),MID(B36,(LEN(#REF!)-1)*2 + 1,1)+1),""), IF(AND(A36<>"",LEN(A36)<LEN(A37)),_xlfn.CONCAT(B36,".",1),""), IF(AND(A36<>"",LEN(A36)=LEN(A37)),_xlfn.CONCAT(LEFT(B36,LEN(B36)-1),RIGHT(B36,1)+1),"")) -> #NAME? | C37: Universo Corporativo (Satélites) | F37: =20/20 -> 1 | AG37: 1 | AH37: 1 | AI37: 1 | AJ37: 1 | AK37: 1 | AL37: 1 | AM37: 1 | AN37: 1 | AO37: 1 | AP37: 1 | AX37: 1 | AY37: 1 | AZ37: 1 | BA37: 1 | BB37: 1 | BC37: 1 | BD37: 1 | BE37: 1 | BF37: 1
A38: xxx | B38: =_xlfn.CONCAT( IF(A37="",1,""), IF(AND(A37<>"",LEN(A37)>LEN(A38)),_xlfn.CONCAT(LEFT(B37,(LEN(#REF!)-1)*2),MID(B37,(LEN(#REF!)-1)*2 + 1,1)+1),""), IF(AND(A37<>"",LEN(A37)<LEN(A38)),_xlfn.CONCAT(B37,".",1),""), IF(AND(A37<>"",LEN(A37)=LEN(A38)),_xlfn.CONCAT(LEFT(B37,LEN(B37)-1),RIGHT(B37,1)+1),"")) -> #NAME? | C38: Satélite 79 | D38: 6 | H38: =SUM(I38:EQ38)=D38 -> TRUE | AG38: 1 | AH38: 1 | AI38: 1 | AJ38: 1 | AK38: 1 | AL38: 1
A39: xxx | B39: =_xlfn.CONCAT( IF(A38="",1,""), IF(AND(A38<>"",LEN(A38)>LEN(A39)),_xlfn.CONCAT(LEFT(B38,(LEN(#REF!)-1)*2),MID(B38,(LEN(#REF!)-1)*2 + 1,1)+1),""), IF(AND(A38<>"",LEN(A38)<LEN(A39)),_xlfn.CONCAT(B38,".",1),""), IF(AND(A38<>"",LEN(A38)=LEN(A39)),_xlfn.CONCAT(LEFT(B38,LEN(B38)-1),RIGHT(B38,1)+1),"")) -> #NAME? | C39: Satélite 80 | D39: 3 | H39: =SUM(I39:EQ39)=D39 -> TRUE | AG39: 0.75 | AH39: 0.25 | BE39: 1 | BF39: 1
A40: xxx | B40: =_xlfn.CONCAT( IF(A39="",1,""), IF(AND(A39<>"",LEN(A39)>LEN(A40)),_xlfn.CONCAT(LEFT(B39,(LEN(#REF!)-1)*2),MID(B39,(LEN(#REF!)-1)*2 + 1,1)+1),""), IF(AND(A39<>"",LEN(A39)<LEN(A40)),_xlfn.CONCAT(B39,".",1),""), IF(AND(A39<>"",LEN(A39)=LEN(A40)),_xlfn.CONCAT(LEFT(B39,LEN(B39)-1),RIGHT(B39,1)+1),"")) -> #NAME? | C40: Satélite 83 | D40: 7 | H40: =SUM(I40:EQ40)=D40 -> TRUE | AH40: 1 | AI40: 1 | AJ40: 1 | AK40: 1 | AL40: 1 | BD40: 1 | BE40: 1
A41: xxx | B41: =_xlfn.CONCAT( IF(A40="",1,""), IF(AND(A40<>"",LEN(A40)>LEN(A41)),_xlfn.CONCAT(LEFT(B40,(LEN(#REF!)-1)*2),MID(B40,(LEN(#REF!)-1)*2 + 1,1)+1),""), IF(AND(A40<>"",LEN(A40)<LEN(A41)),_xlfn.CONCAT(B40,".",1),""), IF(AND(A40<>"",LEN(A40)=LEN(A41)),_xlfn.CONCAT(LEFT(B40,LEN(B40)-1),RIGHT(B40,1)+1),"")) -> #NAME? | C41: Satélite 84 | D41: 12 | H41: =SUM(I41:EQ41)=D41 -> TRUE | AH41: 1 | AI41: 1 | AJ41: 1 | AK41: 1 | AL41: 1 | AM41: 1 | AN41: 1 | AO41: 1 | AP41: 1 | AY41: 1 | AZ41: 1 | BF41: 1
A42: xxx | B42: =_xlfn.CONCAT( IF(A41="",1,""), IF(AND(A41<>"",LEN(A41)>LEN(A42)),_xlfn.CONCAT(LEFT(B41,(LEN(#REF!)-1)*2),MID(B41,(LEN(#REF!)-1)*2 + 1,1)+1),""), IF(AND(A41<>"",LEN(A41)<LEN(A42)),_xlfn.CONCAT(B41,".",1),""), IF(AND(A41<>"",LEN(A41)=LEN(A42)),_xlfn.CONCAT(LEFT(B41,LEN(B41)-1),RIGHT(B41,1)+1),"")) -> #NAME? | C42: Satélite 93 | D42: 5 | H42: =SUM(I42:EQ42)=D42 -> TRUE | AM42: 1 | AN42: 1 | AO42: 1 | BF42: 1 | BG42: 1
A43: xxx | B43: =_xlfn.CONCAT( IF(A42="",1,""), IF(AND(A42<>"",LEN(A42)>LEN(A43)),_xlfn.CONCAT(LEFT(B42,(LEN(#REF!)-1)*2),MID(B42,(LEN(#REF!)-1)*2 + 1,1)+1),""), IF(AND(A42<>"",LEN(A42)<LEN(A43)),_xlfn.CONCAT(B42,".",1),""), IF(AND(A42<>"",LEN(A42)=LEN(A43)),_xlfn.CONCAT(LEFT(B42,LEN(B42)-1),RIGHT(B42,1)+1),"")) -> #NAME? | C43: Satélite 109 | D43: 10 | H43: =SUM(I43:EQ43)=D43 -> TRUE | AH43: 0.5 | AI43: 0.75 | AJ43: 0.75 | AK43: 0.75 | AL43: 0.75 | AM43: 0.75 | AN43: 0.75 | AO43: 0.75 | AP43: 0.75 | AY43: 0.75 | AZ43: 0.75 | BA43: 0.75 | BB43: 0.75 | BC43: 0.5
A44: xx | B44: =_xlfn.CONCAT( IF(A37="",1,""), IF(AND(A37<>"",LEN(A37)>LEN(A44)),_xlfn.CONCAT(LEFT(B37,(LEN(#REF!)-1)*2),MID(B37,(LEN(#REF!)-1)*2 + 1,1)+1),""), IF(AND(A37<>"",LEN(A37)<LEN(A44)),_xlfn.CONCAT(B37,".",1),""), IF(AND(A37<>"",LEN(A37)=LEN(A44)),_xlfn.CONCAT(LEFT(B37,LEN(B37)-1),RIGHT(B37,1)+1),"")) -> #NAME? | C44: Universo Local | F44: =6/21 -> 0.28571429 | BZ44: 1 | CA44: 1 | CB44: 1 | CC44: 1 | CD44: 1 | CE44: 1 | CF44: 1 | CG44: 1 | CH44: 1 | CI44: 1 | CJ44: 1 | CK44: 1 | CL44: 1 | CM44: 1 | CN44: 1 | CP44: 1 | CQ44: 1 | CR44: 1 | CS44: 1 | CT44: 1 | CU44: 1
A45: xxx | B45: =_xlfn.CONCAT( IF(A44="",1,""), IF(AND(A44<>"",LEN(A44)>LEN(A45)),_xlfn.CONCAT(LEFT(B44,(LEN(#REF!)-1)*2),MID(B44,(LEN(#REF!)-1)*2 + 1,1)+1),""), IF(AND(A44<>"",LEN(A44)<LEN(A45)),_xlfn.CONCAT(B44,".",1),""), IF(AND(A44<>"",LEN(A44)=LEN(A45)),_xlfn.CONCAT(LEFT(B44,LEN(B44)-1),RIGHT(B44,1)+1),"")) -> #NAME? | C45: Template 1 | D45: 4 | H45: =SUM(I45:EQ45)=D45 -> TRUE | BZ45: 1 | CA45: 1 | CB45: 1 | CC45: 1
A46: xxx | B46: =_xlfn.CONCAT( IF(A45="",1,""), IF(AND(A45<>"",LEN(A45)>LEN(A46)),_xlfn.CONCAT(LEFT(B45,(LEN(#REF!)-1)*2),MID(B45,(LEN(#REF!)-1)*2 + 1,1)+1),""), IF(AND(A45<>"",LEN(A45)<LEN(A46)),_xlfn.CONCAT(B45,".",1),""), IF(AND(A45<>"",LEN(A45)=LEN(A46)),_xlfn.CONCAT(LEFT(B45,LEN(B45)-1),RIGHT(B45,1)+1),"")) -> #NAME? | C46: Template 2 | D46: 2 | H46: =SUM(I46:EQ46)=D46 -> TRUE | CA46: 1 | CB46: 1
...

Sheet Notas HR
A1: Pressupostos
A3: Consideramos 25% de gestão do SC
A4: Satelites corporativos são entregues a 15 de Março
A5: Templetes locais são entregues a 5 de março (ainda não temos esta data fechada) [Extender até dia 8 prevendo questões]
A6: STE é entregue a 15 de março
A7: A equipa proposta considera 4 fte
A8: Não consideramos esforço para piloto
A9: Não foi considerado esforço para a implementação do satelite 127 ( 140h)
A10: Incluimos esforço para atualização de inputs e templates/ satelites (120 h) > Novos requisitos
A11: Não temos esforço para a geração 6,7,8 e 9 com dados de junho e as novas guidelines
A12: Para a estimativa usamos as guidelines de dia 11 de out mas entretanto no dia 20 de out sairam novas guidelines
A13: Não temos esforço para otimizações
... A28: Satelites com dependencia da gloval: 83, 84 e 93

Sheet Estimativa - Sat. 79
B2: Satélite 79
B4: Campos | C4: 9 | H4: Hora | I4: Dia | J4: Proporção
H5: 24 | I5: 24 | J5: =H5/I5 -> 1
B7: Atividades | G7: Complexidade: | H7: Estudar | I7: Assessment | J7: Implementação | K7: Teste | L7: Conciliação | M7: Corporação
B8: Estudar guia | G8: Baixa | H8: =$J$5 -> 1 | I8: =$J$5 -> 1 | J8: =$J$5 -> 1 | K8: =$J$5 -> 1 | L8: =$J$5*3 -> 3 | M8: =$J$5*4 -> 4
B9: Assessment a fontes de informação | G9: Média | H9: =$J$5*2 -> 2 | I9: =$J$5*2 -> 2 | J9: =$J$5*1.5 -> 1.5 | K9: =$J$5*1.5 -> 1.5 | L9: =$J$5*6 -> 6 | M9: =$J$5*6 -> 6
B10: Implementação | G10: Alta | H10: =$J$5*4 -> 4 | I10: =$J$5*4 -> 4 | J10: =$J$5*2 -> 2 | K10: =$J$5*2 -> 2 | L10: =$J$5*8 -> 8 | M10: =$J$5*8 -> 8
B11: Teste
B12: Conciliação
B13: Validações Corporação
G15: Campo: | H15: Estudar | I15: Assessment | J15: Implementação | K15: Teste | L15: Conciliação* | M15: Corporação** | N15: Comentário
B16: =SUM(H16:M24)+M28 -> 70 | C16: Horas Totais | G16: Performing ESG | K16: =K8 -> 1 | L16: =L8 -> 3
B17: =B16/8 -> 8.75 | C17: Dias Totais** | G17: Exc Paris | I17: =I9 -> 2 | J17: =J9 -> 1.5 | K17: =K8 -> 1 | N17: Tempo estimado para inclusão dos clientes não CIB (a Jun23 apenas foi feita ligação para clientes CIB)
G18: Env. Sustainable CCM | H18: =H10 -> 4 | I18: =I8 -> 1 | J18: =J10 -> 2 | K18: =K10 -> 2 | L18: =L9 -> 6 | N18: Esta métrica deverá ser conciliada com a equivalente no satélite 84 (não obrigatório a Jun23)
B19: =B17+'Estimativa - Sat. 84'!B17+'Estimativa - Sat. 83'!B17 -> 26.458333 | G19: Maturity ESG | H19: =H8 -> 1 | I19: =I9 -> 2 | J19: =J8 -> 1 | K19: =K8 -> 1 | L19: =L8 -> 3 | N19: Surgiram alterações no novo guia
G20: EU | K20: =K8 -> 1
G21: Chronic changes | J21: =J8 -> 1 | K21: =K8 -> 1 | L21: =L8 -> 3 | N21: Alteração caso a corporação envie novo ficheiro input
G22: Acute changes | J22: =J8 -> 1 | K22: =K8 -> 1 | L22: =L8 -> 3 | N22: Alteração caso a corporação envie novo ficheiro input
G23: Physical risk | J23: =J9 -> 1.5 | K23: =K8 -> 1 | N23: Alteração caso a corporação altere os países a entrar nesta métrica
G24: Nace code ESG | J24: =J8 -> 1 | K24: =K8 -> 1 | L24: =L8 -> 3 | N24: Alteração caso a corporação envie novo ficheiro de mapeamento de NACEs.
G26: * Processo de conciliação incluí apenas conciliação de valores na tabela de universo full + conciliação de valores de métricas com outros satélites + análise de diferenças face a Jun23.
B27: =SUM(I28:K28,'Estimativa - Sat. 84'!I28:K28,'Estimativa - Sat. 83'!I28:K28) -> 85.5 | C27: =B27/2 -> 42.75 | D27: =C27/4 -> 10.6875 | G27: ** Componente "Corporação" inclui ajustes manuais solicitados pela Corporação após submissão do reporte no front para garantir conciliação com Cargabal Masterizado e análises para resposta às questões da Corporação
G28: total | H28: =SUM(H16:H24) -> 5 | I28: =SUM(I16:I24) -> 5 | J28: =SUM(J16:J24) -> 9 | K28: =SUM(K16:K24) -> 10 | L28: =SUM(L16:L24) -> 21 | M28: =8+12 -> 20 | N28: O satélite 79 exigiu um conjunto muito significativo de ajustes manuais (overlays distribuidos por NACES) e preenchimento de templates de Excluidos de Paris e de Physical Risk para envio à Corporação. 8 horas de ajustes manuais + 3 interações de 4horas
H30: =SUM(H28:M28)/8 -> 8.75
H34: =H28+I28+J28+K28 -> 29
H35: =H34/8 -> 3.625

Sheet Estimativa - Sat. 84
B2: Satélite 84
B4: Campos | C4: 11 | H4: Hora | I4: Dia | J4: Proporção | Q4: =3*4*2 -> 24
H5: 24 | I5: 24 | J5: =H5/I5 -> 1
B7: Atividades | G7: Complexidade: | H7: Estudar | I7: Assessment | J7: Implementação | K7: Teste | L7: Conciliação | M7: Corporação
B8: Estudar guia | G8: Baixa | H8: =$J$5/1.5 -> 0.66666667 | I8: =$J$5 -> 1 | J8: =$J$5 -> 1 | K8: =$J$5 -> 1 | L8: =$J$5*3 -> 3 | M8: =$J$5*4 -> 4
B9: Assessment a fontes de informação | G9: Média | H9: =$J$5 -> 1 | I9: =$J$5*2 -> 2 | J9: =$J$5*1.5 -> 1.5 | K9: =$J$5*1.5 -> 1.5 | L9: =$J$5*6 -> 6 | M9: =$J$5*6 -> 6
B10: Implementação | G10: Alta | H10: =$J$5*1.5 -> 1.5 | I10: =$J$5*8 -> 8 | J10: =$J$5*2 -> 2 | K10: =$J$5*2 -> 2 | L10: =$J$5*8 -> 8 | M10: =$J$5*8 -> 8
B11: Teste
B12: Conciliação
B13: Validações Corporação
G15: Campo: | H15: Estudar | I15: Assessment | J15: Implementação | K15: Teste | L15: Conciliação* | M15: Corporação** | N15: Comentário
B16: =SUM(H16:M26)+M28 -> 104.83333 | C16: Horas Totais | G16: General Specific Purpose | H16: =H9 -> 1 | I16: =I8 -> 1 | J16: =J8 -> 1 | K16: =K9 -> 1.5 | L16: =L8 -> 3 | N16: Campo sofreu alterações face a Jun23. Necessário confirmar entendimento de alguns pontos com a Corporação
B17: =B16/8 -> 13.104167 | C17: Dias Totais | G17: Purpose ESG | H17: =H10 -> 1.5 | I17: =I10 -> 8 | J17: =J9 -> 1.5 | K17: =K9 -> 1.5 | L17: =L8 -> 3 | N17: Campo sofreu alterações face a Jun23. Necessário confirmar entendimento de alguns pontos com a Corporação. Mudar código do campo e mudar na modelação do IDComb porque tem mais uma hipotese de preenchimento. Necessário replicar esta alteração no satelite 83
G18: NFRD disclosures | H18: =H8 -> 0.66666667 | I18: =I8 -> 1 | J18: =J9 -> 1.5 | K18: =K8 -> 1 | L18: =L8 -> 3 | N18: Campo sofreu alterações face a Jun23. Será necessário implementar cruzamentos supletivos por LEI e GLCS5, à semelhança do realizado para os rácios.
G19: European Union | J19: =J8 -> 1 | K19: =K8 -> 1 | N19: Campo sofreu alterações face a Jun23. Agora é aplicável também a Financial Corporations
G20: Specific eligible | H20: =H10 -> 1.5 | I20: =I10 -> 8 | J20: =J9 -> 1.5 | K20: =K8 -> 1 | L20: =L8 -> 3 | N20: Campo sofreu alterações face a Jun23
G21: Specific sustainable | H21: =H10 -> 1.5 | I21: =I10 -> 8 | J21: =J10 -> 2 | K21: =K10 -> 2 | L21: =L9 -> 6 | N21: Campo sofreu alterações face a Jun23. Necessário pedir campos a áreas internas e confirmar pressupostos com a Corporação. Deixou de depender de CIBs vs Banca Comercial. Não há detalhe sobre tratamento de Pures e Enablings. Carece de esclarecimentos porque é uma alteração significativa da lógica de Construção do campo. Este campo deve estar em linha com Green Dashboard.
G22: Specialised lending | H22: =H8 -> 0.66666667 | I22: =I8 -> 1 | J22: =J8 -> 1 | K22: =K8 -> 1 | L22: =L8 -> 3 | N22: Campo sofreu alterações face a Jun23
G23: Originated during period | K23: =K8 -> 1
G24: ESG subsector | K24: =K8 -> 1 | L24: =L8 -> 3
G25: NACE code ESG | K25: =K8 -> 1 | L25: =L8 -> 3
G26: Rácios | J26: =J8 -> 1 | K26: =K9 -> 1.5 | N26: As functional guidelines referem nomenclaturas distintas das presentes no ficheiro de input de Jun23. Necessário validar se o novo ficheiro de input dos rácios de eligibilidade tem dados para mais rácios do que apenas o TUCCM e CACCM, se tiver é necessário colocar a formula. Validar consistência com o campo NFRD disclosures.
G28: total | H28: =SUM(H16:H26) -> 6.8333333 | I28: =SUM(I16:I26) -> 27 | J28: =SUM(J16:J26) -> 10.5 | K28: =SUM(K16:K26) -> 13.5 | L28: =SUM(L16:L26) -> 27 | M28: =4+16 -> 20 | N28: Horas da "Corporação"
G30: =SUM(H28:M28)/8 -> 13.104167
G32: * Processo de conciliação incluí apenas conciliação de valores na tabela de universo full + Green Dashboard (não incluí conciliação contabilística de idcombs).
G33: ** Componente "Corporação" inclui ajustes manuais solicitados pela Corporação após submissão do reporte no front para garantir conciliação com Cargabal Masterizado e análises para resposta às questões da Corporação
C35: Alterações | I35: =SUM(H28:K28) -> 57.833333 | J35: =I35/8 -> 7.2291667
C36: 1. Inclusão de off-balance (financial guarantees and assets under management)
C37: 2. Mapeamento dos seguintes campos:
C38: i) General_Specific purpose
C39: ii) Purpose ESG
C40: iii) Specific eligible
C41: iv) Specific sustainable
C42: v) Specialised lending
C43: vi) NFRD disclosures
C44: vii) European Union

Sheet Estimativa - Sat. 83
B2: Satélite 84
B4: Campos | C4: 5 | H4: Hora | I4: Dia | J4: Proporção | Q4: =3*4*2 -> 24
H5: 24 | I5: 24 | J5: =H5/I5 -> 1
B7: Atividades | G7: Complexidade: | H7: Estudar | I7: Assessment | J7: Implementação | K7: Teste | L7: Conciliação | M7: Corporação
B8: Estudar guia | G8: Baixa | H8: =$J$5/1.5 -> 0.66666667 | I8: =$J$5 -> 1 | J8: =$J$5 -> 1 | K8: =$J$5 -> 1 | L8: =$J$5*3 -> 3 | M8: =$J$5*4 -> 4
B9: Assessment a fontes de informação | G9: Média | H9: =$J$5 -> 1 | I9: =$J$5*2 -> 2 | J9: =$J$5*1.5 -> 1.5 | K9: =$J$5*1.5 -> 1.5 | L9: =$J$5*6 -> 6 | M9: =$J$5*6 -> 6
B10: Implementação | G10: Alta | H10: =$J$5*1.5 -> 1.5 | I10: =$J$5*8 -> 8 | J10: =$J$5*2 -> 2 | K10: =$J$5*2 -> 2 | L10: =$J$5*8 -> 8 | M10: =$J$5*8 -> 8
B11: Teste
B12: Conciliação
B13: Validações Corporação
G15: Campo: | H15: Estudar | I15: Assessment | J15: Implementação | K15: Teste | L15: Conciliação* | M15: Corporação** | N15: Comentário
B16: =SUM(H16:M26)+M28 -> 36.833333 | C16: Horas Totais
B17: =B16/8 -> 4.6041667 | C17: Dias Totais | G17: Purpose ESG | H17: =H8 -> 0.66666667 | J17: =J8 -> 1 | K17: =K9 -> 1.5 | L17: =L8 -> 3 | N17: Campo sofreu alterações face a Jun23. Replicar a alteração efetuada no staelite 84. Pressupõe que a fase de estudo e assessment é comum à do campo homólogo no satélite 84
G18: Green Financial Instrument | K18: =K8 -> 1
G19: Funding type | H19: =H8 -> 0.66666667 | I19: =I9 -> 2 | J19: =J8 -> 1 | K19: =K8 -> 1 | L19: =L8 -> 3 | N19: Campo sofreu alterações face a Jun23.
G20: Risk mitigated CCT | K20: =K9 -> 1.5 | L20: =L8 -> 3
G21: Risk Mitigates CCP | K21: =K9 -> 1.5 | L21: =L8 -> 3
G28: total | H28: =SUM(H16:H26) -> 1.3333333 | I28: =SUM(I16:I26) -> 2 | J28: =SUM(J16:J26) -> 2 | K28: =SUM(K16:K26) -> 6.5 | L28: =SUM(L16:L26) -> 12 | M28: =4+9 -> 13 | N28: Horas da "Corporação"
G30: =SUM(H28:M28)/8 -> 4.6041667
H31: =SUM(H28:K28) -> 11.833333 | I31: =H31/8 -> 1.4791667 | J31: =I31+'Estimativa - Sat. 84'!J35+'Estimativa - Sat. 79'!H35 -> 12.333333
G32: * Processo de conciliação incluí apenas conciliação de valores na tabela de universo full + Green Dashboard (não incluí conciliação contabilística de idcombs).
G33: ** Componente "Corporação" inclui ajustes manuais solicitados pela Corporação após submissão do reporte no front para garantir conciliação com Cargabal Masterizado e análises para resposta às questões da Corporação

Sheet Resumo_old
A2: 1. Inclui atividades de análise do guia, assessment, implementação, testes e suporte Corporação
C5: Controlo | E5: 45232 | F5: 45233 | G5: 45234 | H5: 45235 | I5: 45236 | J5: 45237 | K5: 45238 | L5: 45239 | M5: 45240 | N5: 45241 | O5: 45242 | P5: 45243 | Q5: 45244 | R5: 45245 | S5: 45246 | T5: 45247 | U5: 45248 | V5: 45249 | W5: 45250 | X5: 45251 | Y5: 45252 | Z5: 45253 | AA5: 45254 | AB5: 45255 | AC5: 45256 | AD5: 45257 | AE5: 45258 | AF5: 45259 | AG5: 45260 | AH5: 45261
A6: Set Up de universos | C6: =SUM(E6:AH6)-B6 -> 5 | D6: HR | I6: 5
A8: Satélite 84 | B8: =SUM('Estimativa - Sat. 84'!H28:K28)+'Estimativa - Sat. 84'!M28 -> 77.833333
A9: Especificação funcional | B9: ='Estimativa - Sat. 84'!H28 -> 6.8333333 | C9: =SUM(E9:AH9)-B9 -> -0.033333333 | D9: FS | F9: 4 | I9: 2.8
A10: Especificação técnica | B10: ='Estimativa - Sat. 84'!I28 -> 27 | C10: =SUM(E10:AH10)-B10 -> 0 | D10: RC | I10: 5 | J10: 5 | K10: 5 | L10: 5 | M10: 5 | P10: 2
A11: Implementação | B11: ='Estimativa - Sat. 84'!J28 -> 10.5 | C11: =SUM(E11:AH11)-B11 -> 0 | D11: RC | P11: 5 | Q11: 5 | R11: 0.5
A12: Testes | B12: ='Estimativa - Sat. 84'!K28 -> 13.5 | C12: =SUM(E12:AH12)-B12 -> 0 | D12: RC / FS | R12: 4.5 | S12: 5 | T12: 4
A13: Conciliação
A14: Suporte Corporação | B14: ='Estimativa - Sat. 84'!M28 -> 20 | C14: =SUM(E14:AH14)-B14 -> 0 | D14: FS / RC | W14: 5 | X14: 5 | Y14: 5 | Z14: 5
A16: Satélite 79 | B16: =SUM('Estimativa - Sat. 79'!H28:K28)+'Estimativa - Sat. 79'!M28 -> 49
A17: Especificação funcional | B17: ='Estimativa - Sat. 79'!H28 -> 5 | C17: =SUM(E17:AH17)-B17 -> 0 | D17: FS | J17: 2 | K17: 3
A18: Especificação técnica | B18: ='Estimativa - Sat. 79'!I28 -> 5 | C18: =SUM(E18:AH18)-B18 -> 0 | D18: DE | L18: 4 | M18: 1
A19: Implementação | B19: ='Estimativa - Sat. 79'!J28 -> 9 | C19: =SUM(E19:AH19)-B19 -> 0 | D19: DE | M19: 3 | P19: 4 | Q19: 2
A20: Testes | B20: ='Estimativa - Sat. 79'!K28 -> 10 | C20: =SUM(E20:AH20)-B20 -> 0 | D20: DE / HC | Q20: 2 | R20: 5 | S20: 3
A21: Conciliação
A22: Suporte Corporação | B22: ='Estimativa - Sat. 79'!M28 -> 20 | C22: =SUM(E22:AH22)-B22 -> 0 | D22: FS / DE | AA22: 1 | AD22: 4 | AE22: 4 | AF22: 4 | AG22: 4 | AH22: 3
A24: Satélite 83 | B24: =SUM('Estimativa - Sat. 83'!H28:K28)+'Estimativa - Sat. 83'!M28 -> 24.833333
A25: Especificação funcional | B25: ='Estimativa - Sat. 83'!H28 -> 1.3333333 | C25: =SUM(E25:AH25)-B25 -> -0.033333333 | D25: FS | T25: 1.3
A26: Especificação técnica | B26: ='Estimativa - Sat. 83'!I28 -> 2 | C26: =SUM(E26:AH26)-B26 -> 0 | D26: RC | W26: 2
A27: Implementação | B27: ='Estimativa - Sat. 83'!J28 -> 2 | C27: =SUM(E27:AH27)-B27 -> 0 | D27: RC | W27: 2
A28: Testes | B28: ='Estimativa - Sat. 83'!K28 -> 6.5 | C28: =SUM(E28:AH28)-B28 -> 0 | D28: RC / HC | X28: 4 | Y28: 2.5
A29: Conciliação
A30: Suporte Corporação | B30: ='Estimativa - Sat. 83'!M28 -> 13 | C30: =SUM(E30:AH30)-B30 -> 0 | D30: FS / RC | AD30: 3 | AE30: 3 | AF30: 3 | AG30: 3 | AH30: 1
A34: Esforço Global | B34: =B16+B24+B8 -> 151.66667
A35: Só implementação | B35: =SUM(B9:B12)+SUM(B17:B20)+SUM(B25:B28) -> 98.666667
B39: =SUM(B10:B12)+SUM(B18:B20)+SUM(B26:B28) -> 85.5
B40: =B39/3 -> 28.5
B41: =B40/2 -> 14.25
B42: =B41-8 -> 6.25
B43: =B41+B42 -> 20.5 | C43: =B43/5 -> 4.1 | J43: =3*5*3 -> 45

Sheet Resumo (2)
A2: 1. Inclui atividades de análise do guia, assessment, implementação, testes e suporte Corporação
C5: Controlo | E5: 45232 | F5: 45233 | G5: 45234 | H5: 45235 | I5: 45236 | J5: 45237 | K5: 45238 | L5: 45239 | M5: 45240 | N5: 45241 | O5: 45242 | P5: 45243 | Q5: 45244 | R5: 45245 | S5: 45246 | T5: 45247 | U5: 45248 | V5: 45249 | W5: 45250 | X5: 45251 | Y5: 45252 | Z5: 45253 | AA5: 45254 | AB5: 45255 | AC5: 45256 | AD5: 45257 | AE5: 45258 | AF5: 45259 | AG5: 45260 | AH5: 45261
A6: Set Up de universos | C6: =SUM(E6:AH6)-B6 -> 5 | D6: HR | I6: 5
A8: Satélite 84 | B8: =SUM('Estimativa - Sat. 84'!H28:K28)+'Estimativa - Sat. 84'!M28 -> 77.833333
A9: Especificação funcional | B9: ='Estimativa - Sat. 84'!H28 -> 6.8333333 | C9: =SUM(E9:AH9)-B9 -> -0.033333333 | D9: FS | F9: 4 | I9: 2.8
A10: Especificação técnica | B10: ='Estimativa - Sat. 84'!I28 -> 27 | C10: =SUM(E10:AH10)-B10 -> 0 | D10: RC | I10: 5 | J10: 5 | L10: 5 | P10: 6 | Q10: 6
A11: Implementação | B11: ='Estimativa - Sat. 84'!J28 -> 10.5 | C11: =SUM(E11:AH11)-B11 -> 0 | D11: RC | T11: 5 | W11: 5 | X11: 0.5
A12: Testes | B12: ='Estimativa - Sat. 84'!K28 -> 13.5 | C12: =SUM(E12:AH12)-B12 -> 0 | D12: RC / HF | X12: 4.5 | Y12: 5 | Z12: 4
A13: Conciliação
A14: Suporte Corporação | B14: ='Estimativa - Sat. 84'!M28 -> 20 | C14: =SUM(E14:AH14)-B14 -> 0 | D14: FS/HF / RC | AD14: 5 | AE14: 5 | AF14: 5 | AG14: 5
A16: Satélite 79 | B16: =SUM('Estimativa - Sat. 79'!H28:K28)+'Estimativa - Sat. 79'!M28 -> 49
A17: Especificação funcional | B17: ='Estimativa - Sat. 79'!H28 -> 5 | C17: =SUM(E17:AH17)-B17 -> 0 | D17: FS | J17: 2 | K17: 3
A18: Especificação técnica | B18: ='Estimativa - Sat. 79'!I28 -> 5 | C18: =SUM(E18:AH18)-B18 -> 0 | D18: DE | L18: 4 | M18: 1
A19: Implementação | B19: ='Estimativa - Sat. 79'!J28 -> 9 | C19: =SUM(E19:AH19)-B19 -> 0 | D19: DE | M19: 3 | P19: 4 | Q19: 2
A20: Testes | B20: ='Estimativa - Sat. 79'!K28 -> 10 | C20: =SUM(E20:AH20)-B20 -> 0 | D20: DE / HF | Q20: 2 | W20: 5 | X20: 3
A21: Conciliação
A22: Suporte Corporação | B22: ='Estimativa - Sat. 79'!M28 -> 20 | C22: =SUM(E22:AH22)-B22 -> 0 | D22: FS/ HF / DE | AA22: 1 | AD22: 4 | AE22: 4 | AF22: 4 | AG22: 4 | AH22: 3
A24: Satélite 83 | B24: =SUM('Estimativa - Sat. 83'!H28:K28)+'Estimativa - Sat. 83'!M28 -> 24.833333
A25: Especificação funcional | B25: ='Estimativa - Sat. 83'!H28 -> 1.3333333 | C25: =SUM(E25:AH25)-B25 -> -0.033333333 | D25: FS | T25: 1.3
A26: Especificação técnica | B26: ='Estimativa - Sat. 83'!I28 -> 2 | C26: =SUM(E26:AH26)-B26 -> 0 | D26: RC | Y26: 2
A27: Implementação | B27: ='Estimativa - Sat. 83'!J28 -> 2 | C27: =SUM(E27:AH27)-B27 -> 0 | D27: RC | Y27: 2
A28: Testes | B28: ='Estimativa - Sat. 83'!K28 -> 6.5 | C28: =SUM(E28:AH28)-B28 -> 0 | D28: RC / HF | Z28: 4 | AA28: 2.5
A29: Conciliação
A30: Suporte Corporação | B30: ='Estimativa - Sat. 83'!M28 -> 13 | C30: =SUM(E30:AH30)-B30 -> 0 | D30: FS / RC | AD30: 3 | AE30: 3 | AF30: 3 | AG30: 3 | AH30: 1
A34: Esforço Global | B34: =B16+B24+B8 -> 151.66667
A35: Só implementação | B35: =SUM(B9:B12)+SUM(B17:B20)+SUM(B25:B28) -> 98.666667
B39: =SUM(B10:B12)+SUM(B18:B20)+SUM(B26:B28) -> 85.5
B40: =B39/3 -> 28.5
B41: =B40/2 -> 14.25
B42: =B41-8 -> 6.25
B43: =B41+B42 -> 20.5 | C43: =B43/5 -> 4.1 | J43: =3*6*3 -> 54

Sheet Resumo
A2: 1. Inclui atividades de análise do guia, assessment, implementação, testes e suporte Corporação
C5: Controlo | E5: 45232 | F5: 45233 | G5: 45234 | H5: 45235 | I5: 45236 | J5: 45237 | K5: 45238 | L5: 45239 | M5: 45240 | N5: 45241 | O5: 45242 | P5: 45243 | Q5: 45244 | R5: 45245 | S5: 45246 | T5: 45247 | U5: 45248 | V5: 45249 | W5: 45250 | X5: 45251 | Y5: 45252 | Z5: 45253 | AA5: 45254 | AB5: 45255 | AC5: 45256 | AD5: 45257 | AE5: 45258 | AF5: 45259 | AG5: 45260 | AH5: 45261
A6: Set Up de universos | C6: =SUM(E6:AH6)-B6 -> 5 | D6: HR | I6: 5
A8: Satélite 84 | B8: =SUM('Estimativa - Sat. 84'!H28:K28)+'Estimativa - Sat. 84'!M28 -> 77.833333
A9: Especificação funcional | B9: ='Estimativa - Sat. 84'!H28 -> 6.8333333 | C9: =SUM(E9:AH9)-B9 -> -0.033333333 | D9: FS | F9: 4 | I9: 2.8
A10: Especificação técnica | B10: ='Estimativa - Sat. 84'!I28 -> 27 | C10: =SUM(E10:AH10)-B10 -> 0 | D10: RC | I10: 6 | J10: 6 | L10: 6 | P10: 6 | Q10: 3
A11: Implementação | B11: ='Estimativa - Sat. 84'!J28 -> 10.5 | C11: =SUM(E11:AH11)-B11 -> 0 | D11: RC | Q11: 5 | T11: 5 | W11: 0.5
A12: Testes | B12: ='Estimativa - Sat. 84'!K28 -> 13.5 | C12: =SUM(E12:AH12)-B12 -> 0 | D12: RC / HF | W12: 4.5 | X12: 5 | Y12: 4
A13: Conciliação
A14: Suporte Corporação | B14: ='Estimativa - Sat. 84'!M28 -> 20 | C14: =SUM(E14:AH14)-B14 -> 0 | D14: FS/HF / RC | AD14: 5 | AE14: 5 | AF14: 5 | AG14: 5
A16: Satélite 79 | B16: =SUM('Estimativa - Sat. 79'!H28:K28)+'Estimativa - Sat. 79'!M28 -> 49
A17: Especificação funcional | B17: ='Estimativa - Sat. 79'!H28 -> 5 | C17: =SUM(E17:AH17)-B17 -> 0 | D17: FS | J17: 2 | K17: 3
A18: Especificação técnica | B18: ='Estimativa - Sat. 79'!I28 -> 5 | C18: =SUM(E18:AH18)-B18 -> 0 | D18: DE | L18: 4 | M18: 1
A19: Implementação | B19: ='Estimativa - Sat. 79'!J28 -> 9 | C19: =SUM(E19:AH19)-B19 -> 0 | D19: DE | M19: 3 | P19: 4 | Q19: 2
A20: Testes | B20: ='Estimativa - Sat. 79'!K28 -> 10 | C20: =SUM(E20:AH20)-B20 -> 0 | D20: DE / HF | Q20: 2 | W20: 5 | X20: 3
A21: Conciliação
A22: Suporte Corporação | B22: ='Estimativa - Sat. 79'!M28 -> 20 | C22: =SUM(E22:AH22)-B22 -> 0 | D22: FS/ HF / DE | AA22: 1 | AD22: 4 | AE22: 4 | AF22: 4 | AG22: 4 | AH22: 3
A24: Satélite 83 | B24: =SUM('Estimativa - Sat. 83'!H28:K28)+'Estimativa - Sat. 83'!M28 -> 24.833333
A25: Especificação funcional | B25: ='Estimativa - Sat. 83'!H28 -> 1.3333333 | C25: =SUM(E25:AH25)-B25 -> -0.033333333 | D25: FS | T25: 1.3
A26: Especificação técnica | B26: ='Estimativa - Sat. 83'!I28 -> 2 | C26: =SUM(E26:AH26)-B26 -> 0 | D26: RC | W26: 2
A27: Implementação | B27: ='Estimativa - Sat. 83'!J28 -> 2 | C27: =SUM(E27:AH27)-B27 -> 0 | D27: RC | W27: 2
A28: Testes | B28: ='Estimativa - Sat. 83'!K28 -> 6.5 | C28: =SUM(E28:AH28)-B28 -> 0 | D28: RC / HF | X28: 4 | Y28: 2.5
A29: Conciliação
A30: Suporte Corporação | B30: ='Estimativa - Sat. 83'!M28 -> 13 | C30: =SUM(E30:AH30)-B30 -> 0 | D30: FS / RC | AD30: 3 | AE30: 3 | AF30: 3 | AG30: 3 | AH30: 1
A34: Esforço Global | B34: =B16+B24+B8 -> 151.66667
A35: Só implementação | B35: =SUM(B9:B12)+SUM(B17:B20)+SUM(B25:B28) -> 98.666667
B39: =SUM(B10:B12)+SUM(B18:B20)+SUM(B26:B28) -> 85.5
B40: =B39/3 -> 28.5
B41: =B40/2 -> 14.25
B42: =B41-8 -> 6.25
B43: =B41+B42 -> 20.5 | C43: =B43/5 -> 4.1 | J43: =3*6*3 -> 54

Sheet Resumo_Calendário
A3: Alocação ao Pilar 3 | C3: Controlo | E3: 45232 | F3: 45233 | G3: 45234 | H3: 45235 | I3: 45236 | J3: 45237 | K3: 45238 | L3: 45239 | M3: 45240 | N3: 45241 | O3: 45242 | P3: 45243 | Q3: 45244 | R3: 45245 | S3: 45246 | T3: 45247 | U3: 45248 | V3: 45249 | W3: 45250 | X3: 45251 | Y3: 45252 | Z3: 45253 | AA3: 45254 | AB3: 45255 | AC3: 45256 | AD3: 45257 | AE3: 45258 | AF3: 45259 | AG3: 45260 | AH3: 45261 | AI3: 45262 | AJ3: 45263 | AK3: 45264 | AL3: 45265 | AM3: 45266 | AN3: 45267 | AO3: 45268 | AP3: 45269 | AQ3: 45270 | AR3: 45271 | AS3: 45272 | AT3: 45273 | AU3: 45274 | AV3: 45275
A5: Diogo Escaleira | L5: T | M5: T | P5: M | Q5: M | W5: AP | X5: AP | AA5: AP | AG5: AP | AL5: AP | AN5: AP | AT5: AP
A7: Rita Caguerelho | I7: T | J7: T | L7: M | P7: M | Q7: D | T7: T | W7: T | X7: AP | Y7: AP | Z7: AP | AF7: AP | AK7: AP | AM7: AP | AS7: AP
