Workbook

Sheet Plano_V1
B6: Re-testes - input | D6: 0.2 | M6: =M7-M10 -> 0 | N6: =N7-N10 -> 0 | O6: =O7-O10 -> 0 | P6: =P7-P10 -> 0 | Q6: =Q7-Q10 -> 0 | R6: =R7-R10 -> 0 | S6: =S7-S10 -> 0 | T6: =T7-T10 -> 0 | ... FK6: =FK7-FK10 -> 0
B7: Re-testes - output | D7: =50%*25% -> 0.125 | L7: =AVERAGE(M7:EL7) -> 2.4923077 | M7: 3 | N7: 3 | O7: 3 | P7: 3 | Q7: 3 | R7: 2 | S7: 2 | T7: 2 | U7: 2 | V7: 2 | W7: 2 | X7: 2 | Y7: 2 | Z7: 2 | AA7: 2 | AB7: 2 | AC7: 2 | AD7: 1 | AE7: 1 | AF7: 1 | AG7: 3 | AH7: 3 | AI7: 3 | AJ7: 3 | AK7: 2 | AL7: 3 | AM7: 3 | AN7: 3 | AO7: 3 | AP7: 3 | AQ7: 2 | AR7: 2 | AS7: 2 | AT7: 0 | AU7: 1 | AV7: 1 | AW7: 0 | AX7: 1 | AY7: 1 | AZ7: 1 | BA7: 2 | BB7: 2 | BC7: 2 | BD7: 2 | BE7: 2 | BF7: 2 | BG7: 2 | BH7: 2 | BI7: 2 | BJ7: 2 | BK7: 2 | BL7: 2 | BM7: 2 | BN7: 2 | BO7: 2 | BP7: 3 | BQ7: 3 | BR7: 3 | BS7: 3 | BT7: 3 | BU7: 3 | BV7: 3 | BW7: 3 | BX7: 3 | BY7: 3 | BZ7: 3 | CA7: 3 | CB7: 3 | CC7: 3 | CD7: 3 | CE7: 3 | CF7: 3 | CG7: 3 | CH7: 3 | CI7: 3 | CJ7: 3 | CK7: 3 | CL7: 3 | CM7: 3 | CN7: 3 | CO7: 3 | CP7: 3 | CQ7: 3 | CR7: 3 | CS7: 3 | CT7: 3 | CU7: 3 | CV7: 3 | CW7: 3 | CX7: 3 | CY7: 3 | CZ7: 3 | DA7: 3 | DB7: 3 | DC7: 3 | DD7: 3 | DE7: 3 | DF7: 3 | DG7: 3 | DH7: 3 | DI7: 3 | DJ7: 3 | DK7: 3 | DL7: 3 | DM7: 3 | DN7: 2 | DO7: 3 | DP7: 3 | DQ7: 3 | DR7: 3 | DS7: 3 | DT7: 3 | DU7: 3 | DV7: 3 | DW7: 3 | DX7: 3 | DY7: 3 | DZ7: 3 | EA7: 3 | EB7: 3 | EC7: 3 | ED7: 3 | EE7: 3 | EF7: 3 | EG7: 3 | EH7: 3 | EI7: 0 | EJ7: 0 | EK7: 0 | EL7: 0 | EM7: 0 | EN7: 0 | EO7: 0 | EP7: 3 | EQ7: 3 | ER7: 3 | ES7: 3 | ET7: 3 | EU7: 3 | EV7: 3 | EW7: 3 | EX7: 3 | EY7: 3 | EZ7: 3 | FA7: 3 | FB7: 3 | FC7: 3 | FD7: 3 | FE7: 3 | FF7: 3 | FG7: 3 | FH7: 3 | FI7: 3 | FJ7: 3 | FK7: 3
M10: =SUBTOTAL(9,M14:M636) -> 3 | N10: =SUBTOTAL(9,N14:N636) -> 3 | O10: =SUBTOTAL(9,O14:O636) -> 3 | P10: =SUBTOTAL(9,P14:P636) -> 3 | Q10: =SUBTOTAL(9,Q14:Q636) -> 3 | R10: =SUBTOTAL(9,R14:R636) -> 2 | S10: =SUBTOTAL(9,S14:S636) -> 2 | T10: =SUBTOTAL(9,T14:T636) -> 2 | ... FK10: =SUBTOTAL(9,FK14:FK636) -> 3
M11: Julho | W11: Julho | AJ11: Agosto | BF11: Setembro | CA11: Outubro | CX11: Novembro | DS11: Dezembro | EO11: Janeiro
M12: =M13 -> 45474 | N12: =N13 -> 45475 | O12: =O13 -> 45476 | P12: =P13 -> 45477 | Q12: =Q13 -> 45478 | R12: =R13 -> 45481 | S12: =S13 -> 45482 | T12: =T13 -> 45483 | ... FK12: =FK13 -> 45688
B13: Âmbito | C13: Sub-âmbito | D13: Tipo de teste | E13: Tabela | F13: Campo | G13: Status | H13: Status2 | I13: Horas | J13: Dias | K13: Pendências | L13: Val | M13: 45474 | N13: =WORKDAY(M13,1) -> 45475 | O13: =WORKDAY(N13,1) -> 45476 | P13: =WORKDAY(O13,1) -> 45477 | Q13: =WORKDAY(P13,1) -> 45478 | R13: =WORKDAY(Q13,1) -> 45481 | S13: =WORKDAY(R13,1) -> 45482 | T13: =WORKDAY(S13,1) -> 45483 | U13: =WORKDAY(T13,1) -> 45484 | ... FK13: =WORKDAY(FJ13,1) -> 45688
B14: 1. Assessment | I14: =SUM(I15:I18) -> 280 | J14: =SUM(J15:J18) -> 35
B15: Pilar III | C15: Bens Imóveis | G15: 7. Por iniciar | I15: =J15*8 -> 40 | J15: 5 | L15: =J15-SUM(M15:FK15) -> 0 | W15: 1 | X15: 1 | Y15: 1 | Z15: 1 | AA15: 1
B16: Pilar III | C16: Modelo Verde | G16: 7. Por iniciar | I16: =J16*8 -> 80 | J16: 10 | L16: =J16-SUM(M16:FK16) -> 0 | R16: 2 | S16: 2 | T16: 2 | U16: 2 | V16: 2
B17: Pilar III | C17: Pilar III | G17: 7. Por iniciar | I17: =J17*8 -> 40 | J17: 5 | L17: =J17-SUM(M17:FK17) -> 0 | AB17: 1 | AC17: 1 | AD17: 1 | AE17: 1 | AF17: 0.5 | AG17: 0.5
B18: GD | C18: GD | G18: 7. Por iniciar | I18: =J18*8 -> 120 | J18: 15 | L18: =J18-SUM(M18:FK18) -> 0 | M18: 3 | N18: 3 | O18: 3 | P18: 3 | Q18: 3
B20: 2. Re-especificação | I20: =SUM(I21:I23) -> 120 | J20: =SUM(J21:J23) -> 15
B21: Pilar III | C21: Bens Imóveis | G21: 7. Por iniciar | I21: =J21*8 -> 40 | J21: 5 | L21: =J21-SUM(M21:FK21) -> 0 | W21: 0.5 | AB21: 0.5 | AG21: 0.5 | AL21: 0.5 | AQ21: 0.5 | AV21: 0.5 | BA21: 0.5 | BF21: 0.5 | BK21: 0.5 | BP21: 0.5
B22: Pilar III | C22: Modelo Verde | G22: 7. Por iniciar | I22: =J22*8 -> 40 | J22: 5 | L22: =J22-SUM(M22:FK22) -> 0 | W22: 0.5 | AB22: 0.5 | AG22: 0.5 | AL22: 0.5 | AQ22: 0.5 | AV22: 0.5 | BA22: 0.5 | BF22: 0.5 | BK22: 0.5 | BP22: 0.5
B23: Pilar III | C23: Pilar III | G23: 7. Por iniciar | I23: =J23*8 -> 40 | J23: 5 | L23: =J23-SUM(M23:FK23) -> 0 | BF23: 0.5 | BK23: 0.5 | BP23: 0.5 | BU23: 0.5 | BZ23: 0.5 | CE23: 0.5 | CJ23: 0.5 | CO23: 0.5 | CT23: 0.5 | CY23: 0.5
B25: 3. Testes / Re-testes | I25: =I26+I27+I42+I198+I362+I447 -> 1188.2 | J25: =J26+J27+J42+J198+J362+J447 -> 150
B26: Testes Regressivos | G26: 7. Por iniciar | I26: =4*22 -> 88 | J26: =I26/8 -> 11 | L26: =J26-SUM(M26:FK26) -> 0 | AA26: 0.5 | AF26: 0.5 | AK26: 0.5 | AP26: 0.5 | AU26: 0.5 | AZ26: 0.5 | BE26: 0.5 | BJ26: 0.5 | BO26: 0.5 | BT26: 0.5 | BY26: 0.5 | CD26: 0.5 | CI26: 0.5 | CN26: 0.5 | CS26: 0.5 | CX26: 0.5 | DC26: 0.5 | DH26: 0.5 | DM26: 0.5 | DR26: 0.5 | DW26: 0.5 | EB26: 0.5
B27: Pilar III | C27: Bens Imóveis - Input | I27: =SUM(I28:I41) -> 0 | J27: =ROUNDUP(I27/8,0) -> 0 | L27: =J27-SUM(M27:FK27) -> -3 | X27: 0.5 | Y27: 0.5 | AC27: 0.5 | AG27: 1 | AH27: 0.5
A28: =E28&F28 -> cd_imv_inp_certif_estimativan.a. | B28: Pilar III | C28: Bens Imóveis - Input | D28: 1. Universo | E28: cd_imv_inp_certif_estimativa | F28: n.a. | G28: =INDEX(Auxiliar!$B$16:$B$24,MATCH(Plano_V1!H28,Auxiliar!$C$16:$C$24,0),1) -> #N/A | H28: =VLOOKUP(A28,'Aux - pivots1'!$A:$B,2,0) -> #N/A | I28: =SUMIFS(Table1[Estimação (horas)],Table1[Tabela],Plano_V1!E28,Table1[Campo],Plano_V1!F28) -> 0 | J28: =I28/8 -> 0 | K28: sem pendencia | L28: =J28-SUM(M28:FK28) -> 0
A29: =E29&F29 -> cd_imv_inp_certif_estimativacempbem | B29: Pilar III | C29: Bens Imóveis - Input | D29: 2. Campo | E29: cd_imv_inp_certif_estimativa | F29: cempbem | G29: =INDEX(Auxiliar!$B$16:$B$24,MATCH(Plano_V1!H29,Auxiliar!$C$16:$C$24,0),1) -> #N/A | H29: =VLOOKUP(A29,'Aux - pivots1'!$A:$B,2,0) -> #N/A | I29: =SUMIFS(Table1[Estimação (horas)],Table1[Tabela],Plano_V1!E29,Table1[Campo],Plano_V1!F29) -> 0 | J29: =I29/8 -> 0 | K29: sem pendencia | L29: =J29-SUM(M29:FK29) -> 0
A30: =E30&F30 -> cd_imv_inp_certif_estimativachave_encriptada | B30: Pilar III | C30: Bens Imóveis - Input | D30: 2. Campo | E30: cd_imv_inp_certif_estimativa | F30: chave_encriptada | G30: =INDEX(Auxiliar!$B$16:$B$24,MATCH(Plano_V1!H30,Auxiliar!$C$16:$C$24,0),1) -> #N/A | H30: =VLOOKUP(A30,'Aux - pivots1'!$A:$B,2,0) -> #N/A | I30: =SUMIFS(Table1[Estimação (horas)],Table1[Tabela],Plano_V1!E30,Table1[Campo],Plano_V1!F30) -> 0 | J30: =I30/8 -> 0 | K30: sem pendencia | L30: =J30-SUM(M30:FK30) -> 0
A31: =E31&F31 -> cd_imv_inp_certif_estimativackbalbem | B31: Pilar III | C31: Bens Imóveis - Input | D31: 2. Campo | E31: cd_imv_inp_certif_estimativa | F31: ckbalbem | G31: =INDEX(Auxiliar!$B$16:$B$24,MATCH(Plano_V1!H31,Auxiliar!$C$16:$C$24,0),1) -> #N/A | H31: =VLOOKUP(A31,'Aux - pivots1'!$A:$B,2,0) -> #N/A | I31: =SUMIFS(Table1[Estimação (horas)],Table1[Tabela],Plano_V1!E31,Table1[Campo],Plano_V1!F31) -> 0 | J31: =I31/8 -> 0 | K31: sem pendencia | L31: =J31-SUM(M31:FK31) -> 0
A32: =E32&F32 -> cd_imv_inp_certif_estimativackctabem | B32: Pilar III | C32: Bens Imóveis - Input | D32: 2. Campo | E32: cd_imv_inp_certif_estimativa | F32: ckctabem | G32: =INDEX(Auxiliar!$B$16:$B$24,MATCH(Plano_V1!H32,Auxiliar!$C$16:$C$24,0),1) -> #N/A | H32: =VLOOKUP(A32,'Aux - pivots1'!$A:$B,2,0) -> #N/A | I32: =SUMIFS(Table1[Estimação (horas)],Table1[Tabela],Plano_V1!E32,Table1[Campo],Plano_V1!F32) -> 0 | J32: =I32/8 -> 0 | K32: sem pendencia | L32: =J32-SUM(M32:FK32) -> 0
A33: =E33&F33 -> cd_imv_inp_certif_estimativackrefbem | B33: Pilar III | C33: Bens Imóveis - Input | D33: 2. Campo | E33: cd_imv_inp_certif_estimativa | F33: ckrefbem | G33: =INDEX(Auxiliar!$B$16:$B$24,MATCH(Plano_V1!H33,Auxiliar!$C$16:$C$24,0),1) -> #N/A | H33: =VLOOKUP(A33,'Aux - pivots1'!$A:$B,2,0) -> #N/A | I33: =SUMIFS(Table1[Estimação (horas)],Table1[Tabela],Plano_V1!E33,Table1[Campo],Plano_V1!F33) -> 0 | J33: =I33/8 -> 0 | K33: sem pendencia | L33: =J33-SUM(M33:FK33) -> 0
A34: =E34&F34 -> cd_imv_inp_certif_estimativadata_extraccao_info | B34: Pilar III | C34: Bens Imóveis - Input | D34: 2. Campo | E34: cd_imv_inp_certif_estimativa | F34: data_extraccao_info | G34: =INDEX(Auxiliar!$B$16:$B$24,MATCH(Plano_V1!H34,Auxiliar!$C$16:$C$24,0),1) -> #N/A | H34: =VLOOKUP(A34,'Aux - pivots1'!$A:$B,2,0) -> #N/A | I34: =SUMIFS(Table1[Estimação (horas)],Table1[Tabela],Plano_V1!E34,Table1[Campo],Plano_V1!F34) -> 0 | J34: =I34/8 -> 0 | K34: sem pendencia | L34: =J34-SUM(M34:FK34) -> 0
A35: =E35&F35 -> cd_imv_inp_certif_estimativaepc | B35: Pilar III | C35: Bens Imóveis - Input | D35: 2. Campo | E35: cd_imv_inp_certif_estimativa | F35: epc | G35: =INDEX(Auxiliar!$B$16:$B$24,MATCH(Plano_V1!H35,Auxiliar!$C$16:$C$24,0),1) -> #N/A | H35: =VLOOKUP(A35,'Aux - pivots1'!$A:$B,2,0) -> #N/A | I35: =SUMIFS(Table1[Estimação (horas)],Table1[Tabela],Plano_V1!E35,Table1[Campo],Plano_V1!F35) -> 0 | J35: =I35/8 -> 0 | K35: sem pendencia | L35: =J35-SUM(M35:FK35) -> 0
A36: =E36&F36 -> cd_imv_inp_certif_estimativafornecedor | B36: Pilar III | C36: Bens Imóveis - Input | D36: 2. Campo | E36: cd_imv_inp_certif_estimativa | F36: fornecedor | G36: =INDEX(Auxiliar!$B$16:$B$24,MATCH(Plano_V1!H36,Auxiliar!$C$16:$C$24,0),1) -> #N/A | H36: =VLOOKUP(A36,'Aux - pivots1'!$A:$B,2,0) -> #N/A | I36: =SUMIFS(Table1[Estimação (horas)],Table1[Tabela],Plano_V1!E36,Table1[Campo],Plano_V1!F36) -> 0 | J36: =I36/8 -> 0 | K36: sem pendencia | L36: =J36-SUM(M36:FK36) -> 0
A37: =E37&F37 -> cd_imv_inp_certif_estimativametodo_info | B37: Pilar III | C37: Bens Imóveis - Input | D37: 2. Campo | E37: cd_imv_inp_certif_estimativa | F37: metodo_info | G37: =INDEX(Auxiliar!$B$16:$B$24,MATCH(Plano_V1!H37,Auxiliar!$C$16:$C$24,0),1) -> #N/A | H37: =VLOOKUP(A37,'Aux - pivots1'!$A:$B,2,0) -> #N/A | I37: =SUMIFS(Table1[Estimação (horas)],Table1[Tabela],Plano_V1!E37,Table1[Campo],Plano_V1!F37) -> 0 | J37: =I37/8 -> 0 | K37: sem pendencia | L37: =J37-SUM(M37:FK37) -> 0
A38: =E38&F38 -> cd_imv_inp_certif_estimativascore_qualidade | B38: Pilar III | C38: Bens Imóveis - Input | D38: 2. Campo | E38: cd_imv_inp_certif_estimativa | F38: score_qualidade | G38: =INDEX(Auxiliar!$B$16:$B$24,MATCH(Plano_V1!H38,Auxiliar!$C$16:$C$24,0),1) -> #N/A | H38: =VLOOKUP(A38,'Aux - pivots1'!$A:$B,2,0) -> #N/A | I38: =SUMIFS(Table1[Estimação (horas)],Table1[Tabela],Plano_V1!E38,Table1[Campo],Plano_V1!F38) -> 0 | J38: =I38/8 -> 0 | K38: sem pendencia | L38: =J38-SUM(M38:FK38) -> 0
A39: =E39&F39 -> cd_imv_inp_certif_estimativavlr_cnsm_ano | B39: Pilar III | C39: Bens Imóveis - Input | D39: 2. Campo | E39: cd_imv_inp_certif_estimativa | F39: vlr_cnsm_ano | G39: =INDEX(Auxiliar!$B$16:$B$24,MATCH(Plano_V1!H39,Auxiliar!$C$16:$C$24,0),1) -> #N/A | H39: =VLOOKUP(A39,'Aux - pivots1'!$A:$B,2,0) -> #N/A | I39: =SUMIFS(Table1[Estimação (horas)],Table1[Tabela],Plano_V1!E39,Table1[Campo],Plano_V1!F39) -> 0 | J39: =I39/8 -> 0 | K39: sem pendencia | L39: =J39-SUM(M39:FK39) -> 0
A40: =E40&F40 -> cd_imv_inp_certif_estimativavlr_emss_ano | B40: Pilar III | C40: Bens Imóveis - Input | D40: 2. Campo | E40: cd_imv_inp_certif_estimativa | F40: vlr_emss_ano | G40: =INDEX(Auxiliar!$B$16:$B$24,MATCH(Plano_V1!H40,Auxiliar!$C$16:$C$24,0),1) -> #N/A | H40: =VLOOKUP(A40,'Aux - pivots1'!$A:$B,2,0) -> #N/A | I40: =SUMIFS(Table1[Estimação (horas)],Table1[Tabela],Plano_V1!E40,Table1[Campo],Plano_V1!F40) -> 0 | J40: =I40/8 -> 0 | K40: sem pendencia | L40: =J40-SUM(M40:FK40) -> 0
A41: =E41&F41 -> Re-testesn.a. | B41: Pilar III | C41: Bens Imóveis - Input | D41: 2. Campo | E41: Re-testes | F41: n.a. | G41: 7. Por iniciar | I41: =SUM(I28:I40)*D6 -> 0 | J41: =I41/8 -> 0 | K41: sem pendencia | L41: =J41-SUM(M41:FK41) -> 0
A42: =E42&F42 | B42: Pilar III | C42: Bens Imóveis - Output | I42: =SUM(I43:I197) -> 0 | J42: =ROUNDUP(I42/8,0) -> 0 | L42: =J42-SUM(M42:FK42) -> -100 | AH42: 0.5 | AI42: 1 | AJ42: 1 | AM42: 1 | AN42: 1 | AO42: 1 | AP42: 0.5 | AR42: 1 | AS42: 2 | AU42: 0.5 | AX42: 1 | AY42: 1 | AZ42: 0.5 | BA42: 1 | BB42: 2 | BC42: 2 | BD42: 2 | BE42: 1.5 | BF42: 0.5 | BG42: 2 | BH42: 2 | BI42: 2 | BJ42: 1.5 | BK42: 0.5 | BL42: 2 | BM42: 2 | BN42: 2 | BO42: 1.5 | BP42: 1.5 | BQ42: 2 | BR42: 2 | BS42: 2 | BT42: 2 | BU42: 2 | BV42: 2 | BW42: 2 | BX42: 2 | BY42: 2 | BZ42: 2 | CA42: 2 | CB42: 2 | CC42: 2 | CD42: 2 | CE42: 2 | CF42: 2 | CG42: 2 | CH42: 2 | CI42: 2 | CJ42: 2 | CK42: 2 | CL42: 2 | CM42: 2 | CN42: 2 | CO42: 2 | CP42: 2 | CQ42: 2 | CR42: 2 | CS42: 2 | CT42: 2 | CU42: 2
A43: =E43&F43 -> cd_imv_out_prcn.a. | B43: Pilar III | C43: Bens Imóveis - Output | D43: 1. Universo | E43: cd_imv_out_prc | F43: n.a. | G43: =INDEX(Auxiliar!$B$16:$B$24,MATCH(Plano_V1!H43,Auxiliar!$C$16:$C$24,0),1) -> #N/A | H43: =VLOOKUP(A43,'Aux - pivots1'!$A:$B,2,0) -> #N/A | I43: =SUMIFS(Table1[Estimação (horas)],Table1[Tabela],Plano_V1!E43,Table1[Campo],Plano_V1!F43) -> 0 | J43: =I43/8 -> 0 | K43: cd_imv_out_trz_cred_prc | L43: =J43-SUM(M43:FK43) -> 0
A44: =E44&F44 -> cd_imv_out_prccempresa | B44: Pilar III | C44: Bens Imóveis - Output | D44: 2. Campo | E44: cd_imv_out_prc | F44: cempresa | G44: =INDEX(Auxiliar!$B$16:$B$24,MATCH(Plano_V1!H44,Auxiliar!$C$16:$C$24,0),1) -> #N/A | H44: =VLOOKUP(A44,'Aux - pivots1'!$A:$B,2,0) -> #N/A | I44: =SUMIFS(Table1[Estimação (horas)],Table1[Tabela],Plano_V1!E44,Table1[Campo],Plano_V1!F44) -> 0 | J44: =I44/8 -> 0 | K44: cd_imv_out_trz_cred_prc | L44: =J44-SUM(M44:FK44) -> 0
A45: =E45&F45 -> cd_imv_out_prcckbalcao | B45: Pilar III | C45: Bens Imóveis - Output | D45: 2. Campo | E45: cd_imv_out_prc | F45: ckbalcao | G45: =INDEX(Auxiliar!$B$16:$B$24,MATCH(Plano_V1!H45,Auxiliar!$C$16:$C$24,0),1) -> #N/A | H45: =VLOOKUP(A45,'Aux - pivots1'!$A:$B,2,0) -> #N/A | I45: =SUMIFS(Table1[Estimação (horas)],Table1[Tabela],Plano_V1!E45,Table1[Campo],Plano_V1!F45) -> 0 | J45: =I45/8 -> 0 | K45: cd_imv_out_trz_cred_prc | L45: =J45-SUM(M45:FK45) -> 0
A46: =E46&F46 -> cd_imv_out_prccknumcta | B46: Pilar III | C46: Bens Imóveis - Output | D46: 2. Campo | E46: cd_imv_out_prc | F46: cknumcta | G46: =INDEX(Auxiliar!$B$16:$B$24,MATCH(Plano_V1!H46,Auxiliar!$C$16:$C$24,0),1) -> #N/A | H46: =VLOOKUP(A46,'Aux - pivots1'!$A:$B,2,0) -> #N/A | I46: =SUMIFS(Table1[Estimação (horas)],Table1[Tabela],Plano_V1!E46,Table1[Campo],Plano_V1!F46) -> 0 | J46: =I46/8 -> 0 | K46: cd_imv_out_trz_cred_prc | L46: =J46-SUM(M46:FK46) -> 0
A47: =E47&F47 -> cd_imv_out_prccod_estd_prcs | B47: Pilar III | C47: Bens Imóveis - Output | D47: 2. Campo | E47: cd_imv_out_prc | F47: cod_estd_prcs | G47: =INDEX(Auxiliar!$B$16:$B$24,MATCH(Plano_V1!H47,Auxiliar!$C$16:$C$24,0),1) -> #N/A | H47: =VLOOKUP(A47,'Aux - pivots1'!$A:$B,2,0) -> #N/A | I47: 0 | J47: =I47/8 -> 0 | K47: cd_imv_out_trz_cred_prc | L47: =J47-SUM(M47:FK47) -> 0
A48: =E48&F48 -> cd_imv_out_prccod_grt | B48: Pilar III | C48: Bens Imóveis - Output | D48: 2. Campo | E48: cd_imv_out_prc | F48: cod_grt | G48: =INDEX(Auxiliar!$B$16:$B$24,MATCH(Plano_V1!H48,Auxiliar!$C$16:$C$24,0),1) -> #N/A | H48: =VLOOKUP(A48,'Aux - pivots1'!$A:$B,2,0) -> #N/A | I48: =SUMIFS(Table1[Estimação (horas)],Table1[Tabela],Plano_V1!E48,Table1[Campo],Plano_V1!F48) -> 0 | J48: =I48/8 -> 0 | K48: cd_imv_out_trz_cred_prc | L48: =J48-SUM(M48:FK48) -> 0
A49: =E49&F49 -> cd_imv_out_prccod_moeda | B49: Pilar III | C49: Bens Imóveis - Output | D49: 2. Campo | E49: cd_imv_out_prc | F49: cod_moeda | G49: =INDEX(Auxiliar!$B$16:$B$24,MATCH(Plano_V1!H49,Auxiliar!$C$16:$C$24,0),1) -> #N/A | H49: =VLOOKUP(A49,'Aux - pivots1'!$A:$B,2,0) -> #N/A | I49: =SUMIFS(Table1[Estimação (horas)],Table1[Tabela],Plano_V1!E49,Table1[Campo],Plano_V1!F49) -> 0 | J49: =I49/8 -> 0 | K49: cd_imv_out_trz_cred_prc | L49: =J49-SUM(M49:FK49) -> 0
...

Sheet 1. Status Resumo FY24
B6: 1. Sumário Executivo |28 de fevereiro a 07 de março
B8: 1 | AG8: 1
C9: Resumo de entregas de Especificações | P9: Detalhe Packages planeados | X9: Highlights
E10: 0 | H10: 1 | L10: 0 | X10: Resumo semana atual: 1. Modelo de Bens Imóveis: - Foram concluídos os testes de 2 campos da tabela de Output de Certificados. - Foram concluídas as especificações dos 2 campos da tabela de Output de Certificados. 2. Modelo Verde: - Conforme planeado, foram testados 5 campos. 4 destes campos foram concluídos, 1 deles encontra-se com incidências. 3. Loan Tape: - Dos 5 campos planeados para fecho de especificação, foram concluídos 4. Dar nota que estes campos são relativos aos certificados e que estão pendentes de resposta da Corporação. Caso a Corporaçao indique um mapeamento diferente do proposto, a especificação dos campos deverá ser atualizado. O campo em falta não foi fechado dado que se encontra em Validação de EF. Semana Seguinte: 1. Modelo Bens Imóveis - FY24: Fechar especificação do campo carbon_emission_value_year, para contemplar a especificação proposta pela Gloval, concluindo assim as especificações do Modelo de Bens Imóveis. 2. Modelo Verde - FY24: Fechar especificação do sstnbl_indctr, após reunião com Corporação, concluindo assim as especificações do Modelo Verde. - FY24: Concluir os testes do campo cod_nace. 3. Loan Tape - FY25: Concluir a especificações do campo pendente (CNCLLD_INSTRMNT_STTS), concluindo assim as especificações da Loan Tape. - Testar 32 campos dos entregues pela equipa de Tecnologia durante esta semana.
C11: Âmbito | E11: Entregas Semana Anterior | H11: Entregas Semana Atual | L11: Entregas Semana Seguinte | Q11: Dt. Prev. | R11: Req. FY25 | T11: Req. FY25 (atualiz.) | V11: Status
E12: Planeado | F12: Real | G12: ∆ | H12: Semana Ant. | I12: Planeado | J12: Real | K12: ∆ | L12: Semana Ant. | M12: Planeado | N12: Total | O12: 1 | P12: Package 1 | Q12: 27/jan | R12: 20 | T12: =+COUNTIFS('2. Status Detalhe Campos FY24'!$C:$C,"*Pilar*",'2. Status Detalhe Campos FY24'!$J:$J,"*"&O12&"*",'2. Status Detalhe Campos FY24'!U:U,"*Novo Plano*") -> 20 | V12: OK
C13: Modelo de Bens Imóveis | E13: 2 | F13: 0 | G13: -2 | H13: 2 | I13: =+COUNTIFS('2. Status Detalhe Campos FY24'!$C:$C,"*Bens Imóveis*",'2. Status Detalhe Campos FY24'!$J:$J,"*"&$L$10&"*") -> 0 | J13: 2 | K13: =J13-(I13+H13) -> 0 | L13: =+IF(K13<0,-K13,0) -> 0 | M13: 1 | N13: =+M13+L13 -> 1 | O13: 2 | P13: Package 2 | Q13: 4/fev | R13: 15 | T13: =+COUNTIFS('2. Status Detalhe Campos FY24'!$C:$C,"*Pilar*",'2. Status Detalhe Campos FY24'!$J:$J,"*"&O13&"*",'2. Status Detalhe Campos FY24'!U:U,"*Novo Plano*") -> 14 | V13: OK
C14: Requisitos FY24 | E14: 2 | F14: 0 | G14: -2 | H14: 2 | I14: =+COUNTIFS('2. Status Detalhe Campos FY24'!$C:$C,"*Bens Imóveis*",'2. Status Detalhe Campos FY24'!$J:$J,"*"&$L$10&"*",'2. Status Detalhe Campos FY24'!Q:Q,"*anterior*") -> 0 | J14: 2 | K14: =J14-(I14+H14) -> 0 | L14: =+IF(K14<0,-K14,0) -> 0 | M14: 1 | N14: =+M14+L14 -> 1 | O14: 3 | P14: Package 3 | Q14: 5/fev | R14: 14 | T14: =+COUNTIFS('2. Status Detalhe Campos FY24'!$C:$C,"*Pilar*",'2. Status Detalhe Campos FY24'!$J:$J,"*"&O14&"*",'2. Status Detalhe Campos FY24'!U:U,"*Novo Plano*") -> 16 | V14: OK
C15: Novos Requisitos FY25 | E15: 0 | F15: 0 | G15: 0 | H15: 0 | I15: =+COUNTIFS('2. Status Detalhe Campos FY24'!$C:$C,"*Bens Imóveis*",'2. Status Detalhe Campos FY24'!$J:$J,"*"&$L$10&"*",'2. Status Detalhe Campos FY24'!Q:Q,"*Novo Plano*") -> 0 | J15: 0 | K15: =J15-(I15+H15) -> 0 | L15: =+IF(K15<0,-K15,0) -> 0 | M15: =+COUNTIFS('2. Status Detalhe Campos FY24'!$C:$C,"*Bens Imóveis*",'2. Status Detalhe Campos FY24'!$J:$J,"*"&$L$10&"*",'2. Status Detalhe Campos FY24'!U:U,"*Novo Plano*") -> 0 | N15: =+M15+L15 -> 0 | O15: 4 | P15: Package 4 | Q15: 11/fev | R15: 13 | T15: =+COUNTIFS('2. Status Detalhe Campos FY24'!$C:$C,"*Pilar*",'2. Status Detalhe Campos FY24'!$J:$J,"*"&O15&"*",'2. Status Detalhe Campos FY24'!U:U,"*Novo Plano*") -> 14 | V15: OK
C16: Modelo Verde | E16: 1 | F16: 1 | G16: 0 | H16: 0 | I16: =+COUNTIFS('2. Status Detalhe Campos FY24'!$C:$C,"*Verde*",'2. Status Detalhe Campos FY24'!$J:$J,"*"&$L$10&"*") -> 0 | J16: 0 | K16: =J16-(I16+H16) -> 0 | L16: =+IF(K16<0,-K16,0) -> 0 | M16: 1 | N16: =+M16+L16 -> 1 | O16: 5 | P16: Package 5 | Q16: 17/fev | R16: 6 | T16: =+COUNTIFS('2. Status Detalhe Campos FY24'!$C:$C,"*Pilar*",'2. Status Detalhe Campos FY24'!$J:$J,"*"&O16&"*",'2. Status Detalhe Campos FY24'!U:U,"*Novo Plano*") -> 7 | V16: OK (6 campos)
C17: Requisitos FY24 | E17: 1 | F17: 1 | G17: 0 | H17: 0 | I17: =+COUNTIFS('2. Status Detalhe Campos FY24'!$C:$C,"*Verde*",'2. Status Detalhe Campos FY24'!$J:$J,"*"&$L$10&"*",'2. Status Detalhe Campos FY24'!Q:Q,"*anterior*") -> 0 | J17: 0 | K17: =J17-(I17+H17) -> 0 | L17: =+IF(K17<0,-K17,0) -> 0 | M17: 1 | N17: =+M17+L17 -> 1 | P17: Total | R17: =+SUM(R12:S16) -> 68 | T17: =+SUM(T12:T16) -> 71
C18: Novos Requisitos FY25 | E18: 0 | F18: 0 | G18: 0 | H18: 0 | I18: =+COUNTIFS('2. Status Detalhe Campos FY24'!$C:$C,"*Verde*",'2. Status Detalhe Campos FY24'!$J:$J,"*"&$L$10&"*",'2. Status Detalhe Campos FY24'!Q:Q,"*Novo Plano*") -> 0 | J18: 0 | K18: =J18-(I18+H18) -> 0 | L18: =+IF(K18<0,-K18,0) -> 0 | M18: =+COUNTIFS('2. Status Detalhe Campos FY24'!$C:$C,"*Verde*",'2. Status Detalhe Campos FY24'!$J:$J,"*"&$L$10&"*",'2. Status Detalhe Campos FY24'!U:U,"*Novo Plano*") -> 0 | N18: =+M18+L18 -> 0
C19: Loan Tape | E19: 8 | F19: 8 | G19: -5 | H19: 5 | I19: =+COUNTIFS('2. Status Detalhe Campos FY24'!$C:$C,"*Verde*",'2. Status Detalhe Campos FY24'!$J:$J,"*"&$L$10&"*") -> 0 | J19: 4 | K19: =J19-(I19+H19) -> -1 | L19: 1 | M19: =+COUNTIFS('2. Status Detalhe Campos FY24'!$C:$C,"*Verde*",'2. Status Detalhe Campos FY24'!$J:$J,"*"&$L$10&"*") -> 0 | N19: =+M19+L19 -> 1
C20: Requisitos FY24 | E20: 8 | F20: 7 | G20: -2 | H20: 2 | I20: =+COUNTIFS('2. Status Detalhe Campos FY24'!$C:$C,"*Verde*",'2. Status Detalhe Campos FY24'!$J:$J,"*"&$L$10&"*",'2. Status Detalhe Campos FY24'!Q:Q,"*anterior*") -> 0 | J20: 2 | K20: =J20-(I20+H20) -> 0 | L20: =+IF(K20<0,-K20,0) -> 0 | M20: =+COUNTIFS('2. Status Detalhe Campos FY24'!$C:$C,"*Verde*",'2. Status Detalhe Campos FY24'!$J:$J,"*"&$L$10&"*",'2. Status Detalhe Campos FY24'!U:U,"*anterior*") -> 0 | N20: =+M20+L20 -> 0
C21: Novos Requisitos FY25 | E21: 0 | F21: 1 | G21: -3 | H21: 3 | I21: 0 | J21: 2 | K21: =J21-(I21+H21) -> -1 | L21: =+IF(K21<0,-K21,0) -> 1 | M21: 0 | N21: =+M21+L21 -> 1
C22: Total | E22: =SUM(E13,E16,E19) -> 11 | F22: =SUM(F13,F16,F19) -> 9 | G22: =SUM(G13,G16,G19) -> -7 | H22: =SUM(H13,H16,H19) -> 7 | I22: 0 | J22: =SUM(J13,J16,J19) -> 6 | K22: =J22-(I22+H22) -> -1 | L22: =+SUM(L13,L16,L19) -> 1 | M22: =+SUM(M13,M16,M19) -> 2 | N22: =+SUM(N13,N16,N19) -> 3
C24: Resumo de Testes
E25: 1 | I25: 1 | P25: package 5
C26: Âmbito | E26: Semana Anterior | J26: Semana Atual | P26: Semana Seguinte
E27: Planeado | F27: Com Incidên. | G27: Sem Incidên. | H27: Re- Especif. | I27: ∆ | J27: Semana Ant. | K27: Planeado | L27: Com Incidên. | M27: Sem Incidên. | N27: Re- Especif. | O27: ∆ | P27: Semana Ant. | Q27: Planeado | R27: Total
C28: Modelo de Bens Imóveis | E28: 47 | F28: 0 | G28: 45 | H28: 0 | I28: -2 | J28: 2 | K28: 0 | L28: 0 | M28: 2 | N28: 0 | O28: =+SUM(J28:K28)-SUM(L28:N28) -> 0 | P28: =+COUNTIFS('2. Status Detalhe Campos FY24'!$C:$C,"*Bens Imóveis*",'2. Status Detalhe Campos FY24'!$K:$K,"*"&$P$25&"*") -> 0 | Q28: =+COUNTIFS('2. Status Detalhe Campos FY24'!$C:$C,"*Bens Imóveis*",'2. Status Detalhe Campos FY24'!$K:$K,"*"&$P$25&"*") -> 0 | R28: =+Q28+P28 -> 0
C29: RequisItos FY24 | E29: 47 | F29: 0 | G29: 45 | H29: 0 | I29: -2 | J29: 2 | K29: 0 | L29: 0 | M29: 2 | N29: 0 | O29: =+SUM(J29:K29)-SUM(L29:N29) -> 0 | P29: =+COUNTIFS('2. Status Detalhe Campos FY24'!$C:$C,"*Bens Imóveis*",'2. Status Detalhe Campos FY24'!$K:$K,"*"&$P$25&"*",'2. Status Detalhe Campos FY24'!T:T,"*anterior*") -> 0 | Q29: =+COUNTIFS('2. Status Detalhe Campos FY24'!$C:$C,"*Bens Imóveis*",'2. Status Detalhe Campos FY24'!$K:$K,"*"&$P$25&"*",'2. Status Detalhe Campos FY24'!U:U,"*anterior*") -> 0 | R29: =+Q29+P29 -> 0
C30: Novos Requisitos FY25 | E30: 0 | F30: 0 | G30: 0 | H30: 0 | I30: 0 | J30: 0 | K30: 0 | L30: 0 | M30: 0 | N30: 0 | O30: =+SUM(J30:K30)-SUM(L30:N30) -> 0 | P30: =+COUNTIFS('2. Status Detalhe Campos FY24'!$C:$C,"*Bens Imóveis*",'2. Status Detalhe Campos FY24'!$K:$K,"*"&$P$25&"*",'2. Status Detalhe Campos FY24'!T:T,"*anterior*") -> 0 | Q30: =+COUNTIFS('2. Status Detalhe Campos FY24'!$C:$C,"*Bens Imóveis*",'2. Status Detalhe Campos FY24'!$K:$K,"*"&$P$25&"*",'2. Status Detalhe Campos FY24'!U:U,"*Novo Plano*") -> 0 | R30: =+Q30+P30 -> 0
C31: Modelo Verde | E31: 17 | F31: 0 | G31: 17 | H31: 0 | I31: 0 | J31: 0 | K31: 5 | L31: 1 | M31: 4 | N31: 0 | O31: =+SUM(J31:K31)-SUM(L31:N31) -> 0 | P31: 1 | Q31: =+COUNTIFS('2. Status Detalhe Campos FY24'!$C:$C,"*Verde*",'2. Status Detalhe Campos FY24'!$K:$K,"*"&$P$25&"*") -> 0 | R31: =+Q31+P31 -> 1
C32: RequisItos FY24 | E32: 12 | F32: 0 | G32: 12 | H32: 0 | I32: 0 | J32: 0 | K32: 5 | L32: 1 | M32: 4 | N32: 0 | O32: =+SUM(J32:K32)-SUM(L32:N32) -> 0 | P32: 1 | Q32: =+COUNTIFS('2. Status Detalhe Campos FY24'!$C:$C,"*Verde*",'2. Status Detalhe Campos FY24'!$K:$K,"*"&$P$25&"*",'2. Status Detalhe Campos FY24'!U:U,"*anterior*") -> 0 | R32: =+Q32+P32 -> 1
C33: Novos Requisitos FY25 | E33: 5 | F33: 0 | G33: 5 | H33: 0 | I33: 0 | J33: 0 | K33: 0 | L33: 0 | M33: 0 | N33: 0 | O33: =+SUM(J33:K33)-SUM(L33:N33) -> 0 | P33: =+COUNTIFS('2. Status Detalhe Campos FY24'!$C:$C,"*Verde*",'2. Status Detalhe Campos FY24'!$K:$K,"*"&$P$25&"*",'2. Status Detalhe Campos FY24'!T:T,"*anterior*") -> 0 | Q33: =+COUNTIFS('2. Status Detalhe Campos FY24'!$C:$C,"*Verde*",'2. Status Detalhe Campos FY24'!$K:$K,"*"&$P$25&"*",'2. Status Detalhe Campos FY24'!U:U,"*Novo Plano*") -> 0 | R33: =+Q33+P33 -> 0
C34: Loan Tape | E34: 2 | F34: 0 | G34: 2 | H34: 0 | I34: 0 | J34: 0 | K34: 0 | L34: 0 | M34: 0 | N34: 0 | O34: =+SUM(J34:K34)-SUM(L34:N34) -> 0 | P34: =+COUNTIFS('2. Status Detalhe Campos FY24'!$C:$C,"*Bens Imóveis*",'2. Status Detalhe Campos FY24'!$K:$K,"*"&$P$25&"*") -> 0 | Q34: =+COUNTIFS('2. Status Detalhe Campos FY24'!$C:$C,"*Pilar*",'2. Status Detalhe Campos FY24'!$K:$K,"*"&$P$25&"*") -> 33 | R34: =+Q34+P34 -> 33
C35: RequisItos FY24 | E35: 2 | F35: 0 | G35: 2 | H35: 0 | I35: 0 | J35: 0 | K35: 0 | L35: 0 | M35: 0 | N35: 0 | O35: =+SUM(J35:K35)-SUM(L35:N35) -> 0 | P35: =+COUNTIFS('2. Status Detalhe Campos FY24'!$C:$C,"*Pilar*",'2. Status Detalhe Campos FY24'!$K:$K,"*"&$P$25&"*",'2. Status Detalhe Campos FY24'!T:T,"*anterior*") -> 0 | Q35: =+COUNTIFS('2. Status Detalhe Campos FY24'!$C:$C,"*Pilar*",'2. Status Detalhe Campos FY24'!$K:$K,"*"&$P$25&"*",'2. Status Detalhe Campos FY24'!U:U,"*anterior*") -> 1 | R35: =+Q35+P35 -> 1
C36: Novos Requisitos FY25 | E36: 0 | F36: 0 | G36: 0 | H36: 0 | I36: 0 | J36: 0 | K36: 0 | L36: 0 | M36: 0 | N36: 0 | O36: =+SUM(J36:K36)-SUM(L36:N36) -> 0 | P36: =+COUNTIFS('2. Status Detalhe Campos FY24'!$C:$C,"*Pilar*",'2. Status Detalhe Campos FY24'!$K:$K,"*"&$P$25&"*",'2. Status Detalhe Campos FY24'!T:T,"*anterior*") -> 0 | Q36: =+COUNTIFS('2. Status Detalhe Campos FY24'!$C:$C,"*Pilar*",'2. Status Detalhe Campos FY24'!$K:$K,"*"&$P$25&"*",'2. Status Detalhe Campos FY24'!U:U,"*Novo Plano*") -> 32 | R36: =+Q36+P36 -> 32
C37: Total | E37: =SUM(E28,E31,E34) -> 66 | F37: 0 | G37: =SUM(G28,G31,G34) -> 64 | H37: 0 | I37: -2 | J37: =SUM(J28,J31,J34) -> 2 | K37: =SUM(K28,K31,K34) -> 5 | L37: =+SUM(L28,L31,L34) -> 1 | M37: =+SUM(M28,M31,M34) -> 6 | N37: =+SUM(N28,N31,N34) -> 0 | O37: =+SUM(O28,O31,O34) -> 0 | P37: =SUM(P28,P31,P34) -> 1 | Q37: =+SUM(Q28,Q31,Q34) -> 33 | R37: =+SUM(R28,R31,R34) -> 34
B44: 1 | AG44: 1
B46: 1. Modelo de Bens Imóveis | G46: Bens Imóveis - Input | H46: Bens Imóveis - Output | I46: Modelo Verde - Input | J46: Modelo Verde - Output | K46: Pilar III
C49: Resumo | G49: Detalhe por Tabela | P49: Status (campos) | T49: 45716 | U49: =T49+7 -> 45723 | V49: ∆ | X49: Highlights
P50: 0. Cancelado | T50: =COUNTIFS('2. Status Detalhe Campos FY24'!$H$7:$H$740,'1. Status Resumo FY24'!$P50,'2. Status Detalhe Campos FY24'!$C$7:$C$740,'1. Status Resumo FY24'!$G$46,'2. Status Detalhe Campos FY24'!$D$7:$D$740,"2. Campo")+COUNTIFS('2. Status Detalhe Campos FY24'!$H$7:$H$740,'1. Status Resumo FY24'!$P50,'2. Status Detalhe Campos FY24'!$C$7:$C$740,'1. Status Resumo FY24'!$H$46,'2. Status Detalhe Campos FY24'!$D$7:$D$740,"2. Campo") -> 12 | U50: =COUNTIFS('2. Status Detalhe Campos FY24'!$G$7:$G$740,'1. Status Resumo FY24'!$P50,'2. Status Detalhe Campos FY24'!$C$7:$C$740,'1. Status Resumo FY24'!$G$46,'2. Status Detalhe Campos FY24'!$D$7:$D$740,"2. Campo")+COUNTIFS('2. Status Detalhe Campos FY24'!$G$7:$G$740,'1. Status Resumo FY24'!$P50,'2. Status Detalhe Campos FY24'!$C$7:$C$740,'1. Status Resumo FY24'!$H$46,'2. Status Detalhe Campos FY24'!$D$7:$D$740,"2. Campo") -> 12 | V50: =U50-T50 -> 0 | X50: 2. Tabela de certificados: - Foram fechadas as especificações dos 2 campos planeados e testados os 2 campos que vão ser aprovisionados ler informação da Gloval.
P51: RequisItos FY24 | T51: =COUNTIFS('2. Status Detalhe Campos FY24'!$H$7:$H$740,'1. Status Resumo FY24'!$P50,'2. Status Detalhe Campos FY24'!$C$7:$C$740,'1. Status Resumo FY24'!$G$46,'2. Status Detalhe Campos FY24'!$D$7:$D$740,"2. Campo",'2. Status Detalhe Campos FY24'!$U$7:$U$740,"*Plano anterior*") +COUNTIFS('2. Status Detalhe Campos FY24'!$H$7:$H$740,'1. Status Resumo FY24'!$P50,'2. Status Detalhe Campos FY24'!$C$7:$C$740,'1. Status Resumo FY24'!$H$46,'2. Status Detalhe Campos FY24'!$D$7:$D$740,"2. Campo",'2. Status Detalhe Campos FY24'!$U$7:$U$740,"*Plano anterior*") -> 12 | U51: =COUNTIFS('2. Status Detalhe Campos FY24'!$G$7:$G$740,'1. Status Resumo FY24'!$P50,'2. Status Detalhe Campos FY24'!$C$7:$C$740,'1. Status Resumo FY24'!$G$46,'2. Status Detalhe Campos FY24'!$D$7:$D$740,"2. Campo",'2. Status Detalhe Campos FY24'!$U$7:$U$740,"*Plano anterior*") +COUNTIFS('2. Status Detalhe Campos FY24'!$G$7:$G$740,'1. Status Resumo FY24'!$P50,'2. Status Detalhe Campos FY24'!$C$7:$C$740,'1. Status Resumo FY24'!$H$46,'2. Status Detalhe Campos FY24'!$D$7:$D$740,"2. Campo",'2. Status Detalhe Campos FY24'!$U$7:$U$740,"*Plano anterior*") -> 12 | V51: =U51-T51 -> 0
P52: Novos Requisitos FY25 | T52: =COUNTIFS('2. Status Detalhe Campos FY24'!$H$7:$H$740,'1. Status Resumo FY24'!$P51,'2. Status Detalhe Campos FY24'!$C$7:$C$740,'1. Status Resumo FY24'!$G$46,'2. Status Detalhe Campos FY24'!$D$7:$D$740,"2. Campo",'2. Status Detalhe Campos FY24'!$U$7:$U$740,"*Novo Plano*") +COUNTIFS('2. Status Detalhe Campos FY24'!$H$7:$H$740,'1. Status Resumo FY24'!$P51,'2. Status Detalhe Campos FY24'!$C$7:$C$740,'1. Status Resumo FY24'!$H$46,'2. Status Detalhe Campos FY24'!$D$7:$D$740,"2. Campo",'2. Status Detalhe Campos FY24'!$U$7:$U$740,"*Novo Plano*") -> 0 | U52: =COUNTIFS('2. Status Detalhe Campos FY24'!$G$7:$G$740,'1. Status Resumo FY24'!$P50,'2. Status Detalhe Campos FY24'!$C$7:$C$740,'1. Status Resumo FY24'!$G$46,'2. Status Detalhe Campos FY24'!$D$7:$D$740,"2. Campo",'2. Status Detalhe Campos FY24'!$U$7:$U$740,"*Novo Plano*") +COUNTIFS('2. Status Detalhe Campos FY24'!$G$7:$G$740,'1. Status Resumo FY24'!$P50,'2. Status Detalhe Campos FY24'!$C$7:$C$740,'1. Status Resumo FY24'!$H$46,'2. Status Detalhe Campos FY24'!$D$7:$D$740,"2. Campo",'2. Status Detalhe Campos FY24'!$U$7:$U$740,"*Novo Plano*") -> 0 | V52: =U52-T52 -> 0
P53: 1. Concluído | T53: =COUNTIFS('2. Status Detalhe Campos FY24'!$H$7:$H$740,'1. Status Resumo FY24'!$P53,'2. Status Detalhe Campos FY24'!$C$7:$C$740,'1. Status Resumo FY24'!$G$46,'2. Status Detalhe Campos FY24'!$D$7:$D$740,"2. Campo")+COUNTIFS('2. Status Detalhe Campos FY24'!$H$7:$H$740,'1. Status Resumo FY24'!$P53,'2. Status Detalhe Campos FY24'!$C$7:$C$740,'1. Status Resumo FY24'!$H$46,'2. Status Detalhe Campos FY24'!$D$7:$D$740,"2. Campo") -> 192 | U53: =COUNTIFS('2. Status Detalhe Campos FY24'!$G$7:$G$740,'1. Status Resumo FY24'!$P53,'2. Status Detalhe Campos FY24'!$C$7:$C$740,'1. Status Resumo FY24'!$G$46,'2. Status Detalhe Campos FY24'!$D$7:$D$740,"2. Campo")+COUNTIFS('2. Status Detalhe Campos FY24'!$G$7:$G$740,'1. Status Resumo FY24'!$P53,'2. Status Detalhe Campos FY24'!$C$7:$C$740,'1. Status Resumo FY24'!$H$46,'2. Status Detalhe Campos FY24'!$D$7:$D$740,"2. Campo") -> 192 | V53: =U53-T53 -> 0
P54: RequisItos FY24 | T54: =COUNTIFS('2. Status Detalhe Campos FY24'!$H$7:$H$740,'1. Status Resumo FY24'!$P53,'2. Status Detalhe Campos FY24'!$C$7:$C$740,'1. Status Resumo FY24'!$G$46,'2. Status Detalhe Campos FY24'!$D$7:$D$740,"2. Campo",'2. Status Detalhe Campos FY24'!$U$7:$U$740,"*Plano anterior*") +COUNTIFS('2. Status Detalhe Campos FY24'!$H$7:$H$740,'1. Status Resumo FY24'!$P53,'2. Status Detalhe Campos FY24'!$C$7:$C$740,'1. Status Resumo FY24'!$H$46,'2. Status Detalhe Campos FY24'!$D$7:$D$740,"2. Campo",'2. Status Detalhe Campos FY24'!$U$7:$U$740,"*Plano anterior*") -> 192 | U54: =COUNTIFS('2. Status Detalhe Campos FY24'!$G$7:$G$740,'1. Status Resumo FY24'!$P53,'2. Status Detalhe Campos FY24'!$C$7:$C$740,'1. Status Resumo FY24'!$G$46,'2. Status Detalhe Campos FY24'!$D$7:$D$740,"2. Campo",'2. Status Detalhe Campos FY24'!$U$7:$U$740,"*Plano anterior*") +COUNTIFS('2. Status Detalhe Campos FY24'!$G$7:$G$740,'1. Status Resumo FY24'!$P53,'2. Status Detalhe Campos FY24'!$C$7:$C$740,'1. Status Resumo FY24'!$H$46,'2. Status Detalhe Campos FY24'!$D$7:$D$740,"2. Campo",'2. Status Detalhe Campos FY24'!$U$7:$U$740,"*Plano anterior*") -> 192 | V54: =U54-T54 -> 0
P55: Novos Requisitos FY25 | T55: =COUNTIFS('2. Status Detalhe Campos FY24'!$H$7:$H$740,'1. Status Resumo FY24'!$P54,'2. Status Detalhe Campos FY24'!$C$7:$C$740,'1. Status Resumo FY24'!$G$46,'2. Status Detalhe Campos FY24'!$D$7:$D$740,"2. Campo",'2. Status Detalhe Campos FY24'!$U$7:$U$740,"*Novo Plano*") +COUNTIFS('2. Status Detalhe Campos FY24'!$H$7:$H$740,'1. Status Resumo FY24'!$P54,'2. Status Detalhe Campos FY24'!$C$7:$C$740,'1. Status Resumo FY24'!$H$46,'2. Status Detalhe Campos FY24'!$D$7:$D$740,"2. Campo",'2. Status Detalhe Campos FY24'!$U$7:$U$740,"*Novo Plano*") -> 0 | U55: =COUNTIFS('2. Status Detalhe Campos FY24'!$G$7:$G$740,'1. Status Resumo FY24'!$P53,'2. Status Detalhe Campos FY24'!$C$7:$C$740,'1. Status Resumo FY24'!$G$46,'2. Status Detalhe Campos FY24'!$D$7:$D$740,"2. Campo",'2. Status Detalhe Campos FY24'!$U$7:$U$740,"*Novo Plano*") +COUNTIFS('2. Status Detalhe Campos FY24'!$G$7:$G$740,'1. Status Resumo FY24'!$P53,'2. Status Detalhe Campos FY24'!$C$7:$C$740,'1. Status Resumo FY24'!$H$46,'2. Status Detalhe Campos FY24'!$D$7:$D$740,"2. Campo",'2. Status Detalhe Campos FY24'!$U$7:$U$740,"*Novo Plano*") -> 0 | V55: =U55-T55 -> 0
P56: 2.1 Em Teste | T56: =COUNTIFS('2. Status Detalhe Campos FY24'!$H$7:$H$740,'1. Status Resumo FY24'!$P56,'2. Status Detalhe Campos FY24'!$C$7:$C$740,'1. Status Resumo FY24'!$G$46,'2. Status Detalhe Campos FY24'!$D$7:$D$740,"2. Campo")+COUNTIFS('2. Status Detalhe Campos FY24'!$H$7:$H$740,'1. Status Resumo FY24'!$P56,'2. Status Detalhe Campos FY24'!$C$7:$C$740,'1. Status Resumo FY24'!$H$46,'2. Status Detalhe Campos FY24'!$D$7:$D$740,"2. Campo") -> 0 | U56: =COUNTIFS('2. Status Detalhe Campos FY24'!$G$7:$G$740,'1. Status Resumo FY24'!$P56,'2. Status Detalhe Campos FY24'!$C$7:$C$740,'1. Status Resumo FY24'!$G$46,'2. Status Detalhe Campos FY24'!$D$7:$D$740,"2. Campo")+COUNTIFS('2. Status Detalhe Campos FY24'!$G$7:$G$740,'1. Status Resumo FY24'!$P56,'2. Status Detalhe Campos FY24'!$C$7:$C$740,'1. Status Resumo FY24'!$H$46,'2. Status Detalhe Campos FY24'!$D$7:$D$740,"2. Campo") -> 0 | V56: =U56-T56 -> 0
...

Sheet Auxiliar
D2: Estimação Horas
B3: Tipologia de testes | D3: Complexidade
B4: Categorização de Testes | C4: Descrição | D4: Baixa | E4: Média | F4: Alta | H4: Baixa | I4: Média | J4: Alta
B5: 1. Teste de universo | C5: 1. Validação de universo de contratos (quando comparado âmbito "CDG" e "PM", e numero de registos) 2. Controlos sobre o desdobramento de chaves nas relações FR-MIS | D5: 8 | E5: 8 | F5: 8 | H5: 1 | I5: 3 | J5: 8
B6: 2. Simulação | C6: Simulação da especificação funcional. Suplementarmente, realizar reuniões de validações e esclarecimentos funcionais junto do negócio/owner. | D6: 2 | E6: 4 | F6: 8 | H6: 1 | I6: 3 | J6: 4
B7: 3. Testes comparativos (Espec. VS Impl.) | C7: A partir da simulação realizada, comparar resultados com a implementação de IT. | D7: 2 | E7: 4 | F7: 8 | H7: 1 | I7: 1 | J7: 2
B8: 4. Validação de parametrizações | C8: A partir da simulação realizada, comparar com as parametrizações implementadas por IT. | D8: 2 | E8: 4 | F8: 8 | H8: 2 | I8: 4 | J8: 4
B9: 5. Teste comparativos com LT | C9: Garantir que a informação do campo da LT-ESTR âmbito 'PM' está espelhado no âmbito 'CDG'. | D9: 1 | E9: 1 | F9: 1
B10: 6. Validação de formatos | C10: Validação de formato de acordo com o que é esperado pela Corporação (incluindo validação de codelists, missing e default values) Validar especificação e controlos da especificação vs o que está implementado | D10: 0.1 | E10: 0.1 | F10: 0.1 | H10: 0.1 | I10: 0.5 | J10: 0.5
B11: 7. Validação de controlos corporativos | C11: Validar controlos corporativos e se a especificação cumpre os requisitos. | D11: 1 | E11: 2 | F11: 2
B12: 8. Teste de Carregamento | C12: Garantir que o carregamento do ficheiro é realizado com sucesso no Front. | D12: 0.5 | E12: 0.5 | F12: 0.5 | H12: 0.5 | I12: 0.5 | J12: 0.5
B13: 9. Teste de Integridade | C13: Garantir integridade entre o ficheiro importado pela equipa de testes e o ficheiro de tecnologia (Ex: Garantir que a informação de todos os campos está correta de acordo com os dados corporativos) | D13: 0.5 | E13: 0.5 | F13: 0.5 | H13: 0.5 | I13: 0.5 | J13: 0.5
B15: Status
B16: 1. Concluído | C16: =_xlfn.NUMBERVALUE(LEFT(B16,1)) -> 1 | D16: 1 | E16: 1
A17: Pendente de outros campos/tabelas | B17: 3. Pendente de outros desenvolvimentos | C17: 4 | D17: 0.25 | E17: 0
B18: 7. Por iniciar | C18: 8 | D18: 0 | E18: 0
B19: 2.1 Em Teste | C19: =_xlfn.NUMBERVALUE(LEFT(B19,1)) -> 2 | D19: 0.5 | E19: 0.25
B20: 2.2 Em especificação | C20: 3 | D20: 0.5 | E20: 0
A21: Validação da Susana/LCM/Corp/conceito/alterações | B21: 4. Validação EF | C21: 5 | D21: 0.25 | E21: 0.25
A22: Por IT | B22: 5. Em Correção | C22: 6 | D22: 0.25 | E22: 0
A23: Por IT | B23: 6. Em implementação | C23: 7 | D23: 0.25 | E23: 0
A24: Campo eliminado | B24: 0. Cancelado | C24: =_xlfn.NUMBERVALUE(LEFT(B24,1)) -> 0 | D24: 0 | E24: 0

Sheet 2. Status Detalhe Campos FY24
J5: APAGAR | K5: APAGAR | L5: APAGAR | R5: APAGAR | S5: APAGAR | T5: APAGAR | U5: APAGAR | V5: APAGAR
B6: Âmbito | C6: Sub-âmbito | D6: Tipo de teste | E6: Tabela | F6: Campo | G6: Status Atual | H6: Status Anterior | I6: Fase | J6: Observações - Especificações | K6: Observações - Testes | L6: Observações - Testes sem visibilidade | M6: Data de Pedido correção/esclarecimento | N6: Data de correção prevista | O6: Data de correção efetiva | P6: Data Prevista de Re-especificação | Q6: Data Prevista de Teste | R6: Projeto (Aux JB) | S6: LT Âmbito | T6: LT Âmbito- Aux | U6: Plano | V6: Owner
A7: =E7&F7 -> PROPERTY_ENERGY_CERTIFICATECURRENT_ENERGY_RATING_PERCENTAGE | B7: Pilar III | C7: Bens Imóveis - Output | D7: 2. Campo | E7: PROPERTY_ENERGY_CERTIFICATE | F7: CURRENT_ENERGY_RATING_PERCENTAGE | G7: =VLOOKUP(A7,Plano_V3!$A$26:$G$768,7,0) -> 6. Em implementação | H7: 6. Em implementação | J7: Package 1 | K7: Package 1 | M7: =IF(VLOOKUP(A7,'Aux - pivots1'!$A:$E,3,0)=0, "",VLOOKUP(A7,'Aux - pivots1'!$A:$E,3,0)) | N7: =IF(VLOOKUP(A7,'Aux - pivots1'!$A:$E,4,0)=0, "",VLOOKUP(A7,'Aux - pivots1'!$A:$E,4,0)) | O7: =IF(VLOOKUP(A7,'Aux - pivots1'!$A:$E,5,0)=0, "",VLOOKUP(A7,'Aux - pivots1'!$A:$E,5,0)) | U7: Plano anterior | V7: HF
A8: =E8&F8 -> lt002_instrumentOFF_BLNC_SHT_AMNT_INSTRMNT | B8: Pilar III | C8: Pilar III | D8: 2. Campo | E8: lt002_instrument | F8: OFF_BLNC_SHT_AMNT_INSTRMNT | G8: =VLOOKUP(A8,Plano_V3!$A$26:$G$768,7,0) -> 6. Em implementação | H8: 6. Em implementação | J8: Package 4 | K8: Package 11 (23 abril) | M8: =IF(VLOOKUP(A8,'Aux - pivots1'!$A:$E,3,0)=0, "",VLOOKUP(A8,'Aux - pivots1'!$A:$E,3,0)) | N8: =IF(VLOOKUP(A8,'Aux - pivots1'!$A:$E,4,0)=0, "",VLOOKUP(A8,'Aux - pivots1'!$A:$E,4,0)) | O8: =IF(VLOOKUP(A8,'Aux - pivots1'!$A:$E,5,0)=0, "",VLOOKUP(A8,'Aux - pivots1'!$A:$E,5,0)) | R8: Novo Projeto - Em especificação | S8: ESTR, GD, GF, ESG e LF | T8: Novos Requisitos FY25 - Âmbito ESTR e (ou) LF | U8: Novo Plano | V8: HF
A9: =E9&F9 -> lt003_entityec_grp_id | B9: Pilar III | C9: Pilar III | D9: 2. Campo | E9: lt003_entity | F9: ec_grp_id | G9: =VLOOKUP(A9,Plano_V3!$A$26:$G$768,7,0) -> 6. Em implementação | H9: 6. Em implementação | J9: Package 4 | K9: Package 11 (23 abril) | M9: =IF(VLOOKUP(A9,'Aux - pivots1'!$A:$E,3,0)=0, "",VLOOKUP(A9,'Aux - pivots1'!$A:$E,3,0)) | N9: =IF(VLOOKUP(A9,'Aux - pivots1'!$A:$E,4,0)=0, "",VLOOKUP(A9,'Aux - pivots1'!$A:$E,4,0)) | O9: =IF(VLOOKUP(A9,'Aux - pivots1'!$A:$E,5,0)=0, "",VLOOKUP(A9,'Aux - pivots1'!$A:$E,5,0)) | R9: Novo Projeto - Em especificação | S9: ESTR, P3, GF e LF | T9: Novos Requisitos FY25 - Âmbito ESTR e (ou) LF | U9: Novo Plano | V9: JB
A10: =E10&F10 -> lt003_entityec_grp_nm | B10: Pilar III | C10: Pilar III | D10: 2. Campo | E10: lt003_entity | F10: ec_grp_nm | G10: =VLOOKUP(A10,Plano_V3!$A$26:$G$768,7,0) -> 6. Em implementação | H10: 6. Em implementação | J10: Package 4 | K10: Package 11 (23 abril) | M10: =IF(VLOOKUP(A10,'Aux - pivots1'!$A:$E,3,0)=0, "",VLOOKUP(A10,'Aux - pivots1'!$A:$E,3,0)) | N10: =IF(VLOOKUP(A10,'Aux - pivots1'!$A:$E,4,0)=0, "",VLOOKUP(A10,'Aux - pivots1'!$A:$E,4,0)) | O10: =IF(VLOOKUP(A10,'Aux - pivots1'!$A:$E,5,0)=0, "",VLOOKUP(A10,'Aux - pivots1'!$A:$E,5,0)) | R10: Novo Projeto - Em especificação | S10: ESTR, P3, GF e LF | T10: Novos Requisitos FY25 - Âmbito ESTR e (ou) LF | U10: Novo Plano | V10: JB
A11: =E11&F11 -> lt004_protectionRL_ESTT_ADDRSS | B11: Pilar III | C11: Pilar III | D11: 2. Campo | E11: lt004_protection | F11: RL_ESTT_ADDRSS | G11: =VLOOKUP(A11,Plano_V3!$A$26:$G$768,7,0) -> 6. Em implementação | H11: 6. Em implementação | J11: Package 4 | K11: Package 11 (23 abril) | M11: =IF(VLOOKUP(A11,'Aux - pivots1'!$A:$E,3,0)=0, "",VLOOKUP(A11,'Aux - pivots1'!$A:$E,3,0)) | N11: =IF(VLOOKUP(A11,'Aux - pivots1'!$A:$E,4,0)=0, "",VLOOKUP(A11,'Aux - pivots1'!$A:$E,4,0)) | O11: =IF(VLOOKUP(A11,'Aux - pivots1'!$A:$E,5,0)=0, "",VLOOKUP(A11,'Aux - pivots1'!$A:$E,5,0)) | R11: Novo Projeto - Em especificação | S11: ESTR e ESG | T11: Novos Requisitos FY25 - Âmbito ESTR e (ou) LF | U11: Novo Plano | V11: JB
A12: =E12&F12 -> lt004_protectionRL_ESTT_CLLTRL_LCTN_INT | B12: Pilar III | C12: Pilar III | D12: 2. Campo | E12: lt004_protection | F12: RL_ESTT_CLLTRL_LCTN_INT | G12: =VLOOKUP(A12,Plano_V3!$A$26:$G$768,7,0) -> 6. Em implementação | H12: 6. Em implementação | J12: Package 5 | K12: Package 11 (23 abril) | M12: =IF(VLOOKUP(A12,'Aux - pivots1'!$A:$E,3,0)=0, "",VLOOKUP(A12,'Aux - pivots1'!$A:$E,3,0)) | N12: =IF(VLOOKUP(A12,'Aux - pivots1'!$A:$E,4,0)=0, "",VLOOKUP(A12,'Aux - pivots1'!$A:$E,4,0)) | O12: =IF(VLOOKUP(A12,'Aux - pivots1'!$A:$E,5,0)=0, "",VLOOKUP(A12,'Aux - pivots1'!$A:$E,5,0)) | R12: Novo Projeto - Em especificação | S12: ESTR e ESG | T12: Novos Requisitos FY25 - Âmbito ESTR e (ou) LF | U12: Novo Plano | V12: JB
A13: =E13&F13 -> lt004_protectionRL_ESTT_CTY | B13: Pilar III | C13: Pilar III | D13: 2. Campo | E13: lt004_protection | F13: RL_ESTT_CTY | G13: =VLOOKUP(A13,Plano_V3!$A$26:$G$768,7,0) -> 6. Em implementação | H13: 6. Em implementação | J13: Package 3 | K13: Package 11 (23 abril) | M13: =IF(VLOOKUP(A13,'Aux - pivots1'!$A:$E,3,0)=0, "",VLOOKUP(A13,'Aux - pivots1'!$A:$E,3,0)) | N13: =IF(VLOOKUP(A13,'Aux - pivots1'!$A:$E,4,0)=0, "",VLOOKUP(A13,'Aux - pivots1'!$A:$E,4,0)) | O13: =IF(VLOOKUP(A13,'Aux - pivots1'!$A:$E,5,0)=0, "",VLOOKUP(A13,'Aux - pivots1'!$A:$E,5,0)) | R13: Novo Projeto - Em especificação | S13: ESTR e ESG | T13: Novos Requisitos FY25 - Âmbito ESTR e (ou) LF | U13: Novo Plano | V13: JB
A14: =E14&F14 -> lt004_protectionYR_CNSTRCTN | B14: Pilar III | C14: Pilar III | D14: 2. Campo | E14: lt004_protection | F14: YR_CNSTRCTN | G14: =VLOOKUP(A14,Plano_V3!$A$26:$G$768,7,0) -> 6. Em implementação | H14: 6. Em implementação | J14: Package 3 | K14: Package 11 (23 abril) | M14: =IF(VLOOKUP(A14,'Aux - pivots1'!$A:$E,3,0)=0, "",VLOOKUP(A14,'Aux - pivots1'!$A:$E,3,0)) | N14: =IF(VLOOKUP(A14,'Aux - pivots1'!$A:$E,4,0)=0, "",VLOOKUP(A14,'Aux - pivots1'!$A:$E,4,0)) | O14: =IF(VLOOKUP(A14,'Aux - pivots1'!$A:$E,5,0)=0, "",VLOOKUP(A14,'Aux - pivots1'!$A:$E,5,0)) | R14: Novo Projeto - Em especificação | S14: ESTR, P3 e ESG | T14: Novos Requisitos FY25 - Âmbito ESTR e (ou) LF | U14: Novo Plano | V14: JB
A15: =E15&F15 -> lt004_protectionBLDNG_AR | B15: Pilar III | C15: Pilar III | D15: 2. Campo | E15: lt004_protection | F15: BLDNG_AR | G15: =VLOOKUP(A15,Plano_V3!$A$26:$G$768,7,0) -> 6. Em implementação | H15: 6. Em implementação | J15: Package 3 | K15: Package 11 (23 abril) | M15: =IF(VLOOKUP(A15,'Aux - pivots1'!$A:$E,3,0)=0, "",VLOOKUP(A15,'Aux - pivots1'!$A:$E,3,0)) | N15: =IF(VLOOKUP(A15,'Aux - pivots1'!$A:$E,4,0)=0, "",VLOOKUP(A15,'Aux - pivots1'!$A:$E,4,0)) | O15: =IF(VLOOKUP(A15,'Aux - pivots1'!$A:$E,5,0)=0, "",VLOOKUP(A15,'Aux - pivots1'!$A:$E,5,0)) | R15: Novo Projeto - Em especificação | S15: P3 e ESG | T15: Novos Requisitos FY25 - Outros | U15: Novo Plano | V15: JB
A16: =E16&F16 -> lt002_instrumentNW_BSNSS | B16: Pilar III | C16: Pilar III | D16: 2. Campo | E16: lt002_instrument | F16: NW_BSNSS | G16: =VLOOKUP(A16,Plano_V3!$A$26:$G$768,7,0) -> 6. Em implementação | H16: 6. Em implementação | J16: Package 5 | K16: Package 12 (30 maio) | M16: =IF(VLOOKUP(A16,'Aux - pivots1'!$A:$E,3,0)=0, "",VLOOKUP(A16,'Aux - pivots1'!$A:$E,3,0)) | N16: =IF(VLOOKUP(A16,'Aux - pivots1'!$A:$E,4,0)=0, "",VLOOKUP(A16,'Aux - pivots1'!$A:$E,4,0)) | O16: =IF(VLOOKUP(A16,'Aux - pivots1'!$A:$E,5,0)=0, "",VLOOKUP(A16,'Aux - pivots1'!$A:$E,5,0)) | R16: Novo Projeto - Em especificação | S16: GD, P3 e GF | T16: Novos Requisitos FY25 - Outros | U16: Novo Plano | V16: RC
A17: =E17&F17 -> lt002_instrumentCNCLLD_INSTRMNT_STTS | B17: Pilar III | C17: Pilar III | D17: 2. Campo | E17: lt002_instrument | F17: CNCLLD_INSTRMNT_STTS | G17: =VLOOKUP(A17,Plano_V3!$A$26:$G$768,7,0) -> 4. Validação EF | H17: 4. Validação EF | J17: Package 5 | K17: Package 12 (30 maio) | M17: =IF(VLOOKUP(A17,'Aux - pivots1'!$A:$E,3,0)=0, "",VLOOKUP(A17,'Aux - pivots1'!$A:$E,3,0)) | N17: =IF(VLOOKUP(A17,'Aux - pivots1'!$A:$E,4,0)=0, "",VLOOKUP(A17,'Aux - pivots1'!$A:$E,4,0)) | O17: =IF(VLOOKUP(A17,'Aux - pivots1'!$A:$E,5,0)=0, "",VLOOKUP(A17,'Aux - pivots1'!$A:$E,5,0)) | R17: Novo Projeto - Em especificação | S17: GD, P3 e GF | T17: Novos Requisitos FY25 - Outros | U17: Novo Plano | V17: RC
A18: =E18&F18 -> lt002_instrumentTYP_OFF_BLNC_PRDCT | B18: Pilar III | C18: Pilar III | D18: 2. Campo | E18: lt002_instrument | F18: TYP_OFF_BLNC_PRDCT | G18: =VLOOKUP(A18,Plano_V3!$A$26:$G$768,7,0) -> 6. Em implementação | H18: 6. Em implementação | J18: Package 4 --> Não está especificado no LT - não conseguimos testar | K18: Package 12 (30 maio) | M18: =IF(VLOOKUP(A18,'Aux - pivots1'!$A:$E,3,0)=0, "",VLOOKUP(A18,'Aux - pivots1'!$A:$E,3,0)) | N18: =IF(VLOOKUP(A18,'Aux - pivots1'!$A:$E,4,0)=0, "",VLOOKUP(A18,'Aux - pivots1'!$A:$E,4,0)) | O18: =IF(VLOOKUP(A18,'Aux - pivots1'!$A:$E,5,0)=0, "",VLOOKUP(A18,'Aux - pivots1'!$A:$E,5,0)) | R18: Novo Projeto - Em especificação | S18: ESTR, GD, P3 e LF | T18: Novos Requisitos FY25 - Âmbito ESTR e (ou) LF | U18: Novo Plano | V18: JB
A19: =E19&F19 -> modesg_out_empr_info_nfinppc_trnvr_ttl_elgbl | B19: Pilar III | C19: Modelo Verde - Output | D19: 2. Campo | E19: modesg_out_empr_info_nfin | F19: ppc_trnvr_ttl_elgbl | G19: =VLOOKUP(A19,Plano_V3!$A$26:$G$768,7,0) -> 1. Concluído | H19: 1. Concluído | J19: Package 1 | K19: Package 2 | M19: =IF(VLOOKUP(A19,'Aux - pivots1'!$A:$E,3,0)=0, "",VLOOKUP(A19,'Aux - pivots1'!$A:$E,3,0)) | N19: =IF(VLOOKUP(A19,'Aux - pivots1'!$A:$E,4,0)=0, "",VLOOKUP(A19,'Aux - pivots1'!$A:$E,4,0)) | O19: =IF(VLOOKUP(A19,'Aux - pivots1'!$A:$E,5,0)=0, "",VLOOKUP(A19,'Aux - pivots1'!$A:$E,5,0)) | U19: Novo Plano
A20: =E20&F20 -> modesg_out_empr_info_nfinppc_turnover_own_prfrmnce_algnd | B20: Pilar III | C20: Modelo Verde - Output | D20: 2. Campo | E20: modesg_out_empr_info_nfin | F20: ppc_turnover_own_prfrmnce_algnd | G20: =VLOOKUP(A20,Plano_V3!$A$26:$G$768,7,0) -> 1. Concluído | H20: 1. Concluído | J20: Package 1 | K20: Package 2 | M20: =IF(VLOOKUP(A20,'Aux - pivots1'!$A:$E,3,0)=0, "",VLOOKUP(A20,'Aux - pivots1'!$A:$E,3,0)) | N20: =IF(VLOOKUP(A20,'Aux - pivots1'!$A:$E,4,0)=0, "",VLOOKUP(A20,'Aux - pivots1'!$A:$E,4,0)) | O20: =IF(VLOOKUP(A20,'Aux - pivots1'!$A:$E,5,0)=0, "",VLOOKUP(A20,'Aux - pivots1'!$A:$E,5,0)) | U20: Novo Plano
A21: =E21&F21 -> modesg_out_empr_info_nfinppc_capex_ttl_elgbl | B21: Pilar III | C21: Modelo Verde - Output | D21: 2. Campo | E21: modesg_out_empr_info_nfin | F21: ppc_capex_ttl_elgbl | G21: =VLOOKUP(A21,Plano_V3!$A$26:$G$768,7,0) -> 1. Concluído | H21: 1. Concluído | J21: Package 1 | K21: Package 2 | M21: =IF(VLOOKUP(A21,'Aux - pivots1'!$A:$E,3,0)=0, "",VLOOKUP(A21,'Aux - pivots1'!$A:$E,3,0)) | N21: =IF(VLOOKUP(A21,'Aux - pivots1'!$A:$E,4,0)=0, "",VLOOKUP(A21,'Aux - pivots1'!$A:$E,4,0)) | O21: =IF(VLOOKUP(A21,'Aux - pivots1'!$A:$E,5,0)=0, "",VLOOKUP(A21,'Aux - pivots1'!$A:$E,5,0)) | U21: Novo Plano
A22: =E22&F22 -> modesg_out_empr_info_nfinppc_capex_own_prfrmnce_algnd | B22: Pilar III | C22: Modelo Verde - Output | D22: 2. Campo | E22: modesg_out_empr_info_nfin | F22: ppc_capex_own_prfrmnce_algnd | G22: =VLOOKUP(A22,Plano_V3!$A$26:$G$768,7,0) -> 1. Concluído | H22: 1. Concluído | J22: Package 1 | K22: Package 2 | M22: =IF(VLOOKUP(A22,'Aux - pivots1'!$A:$E,3,0)=0, "",VLOOKUP(A22,'Aux - pivots1'!$A:$E,3,0)) | N22: =IF(VLOOKUP(A22,'Aux - pivots1'!$A:$E,4,0)=0, "",VLOOKUP(A22,'Aux - pivots1'!$A:$E,4,0)) | O22: =IF(VLOOKUP(A22,'Aux - pivots1'!$A:$E,5,0)=0, "",VLOOKUP(A22,'Aux - pivots1'!$A:$E,5,0)) | U22: Novo Plano
A23: =E23&F23 -> modesg_out_empr_info_nfinbio_trnvr_ttl_elgbl | B23: Pilar III | C23: Modelo Verde - Output | D23: 2. Campo | E23: modesg_out_empr_info_nfin | F23: bio_trnvr_ttl_elgbl | G23: =VLOOKUP(A23,Plano_V3!$A$26:$G$768,7,0) -> 1. Concluído | H23: 1. Concluído | J23: Package 1 | K23: Package 2 | M23: =IF(VLOOKUP(A23,'Aux - pivots1'!$A:$E,3,0)=0, "",VLOOKUP(A23,'Aux - pivots1'!$A:$E,3,0)) | N23: =IF(VLOOKUP(A23,'Aux - pivots1'!$A:$E,4,0)=0, "",VLOOKUP(A23,'Aux - pivots1'!$A:$E,4,0)) | O23: =IF(VLOOKUP(A23,'Aux - pivots1'!$A:$E,5,0)=0, "",VLOOKUP(A23,'Aux - pivots1'!$A:$E,5,0)) | U23: Novo Plano
A24: =E24&F24 -> modesg_out_empr_info_nfinbio_turnover_own_prfrmnce_algnd | B24: Pilar III | C24: Modelo Verde - Output | D24: 2. Campo | E24: modesg_out_empr_info_nfin | F24: bio_turnover_own_prfrmnce_algnd | G24: =VLOOKUP(A24,Plano_V3!$A$26:$G$768,7,0) -> 1. Concluído | H24: 1. Concluído | J24: Package 1 | K24: Package 2 | M24: =IF(VLOOKUP(A24,'Aux - pivots1'!$A:$E,3,0)=0, "",VLOOKUP(A24,'Aux - pivots1'!$A:$E,3,0)) | N24: =IF(VLOOKUP(A24,'Aux - pivots1'!$A:$E,4,0)=0, "",VLOOKUP(A24,'Aux - pivots1'!$A:$E,4,0)) | O24: =IF(VLOOKUP(A24,'Aux - pivots1'!$A:$E,5,0)=0, "",VLOOKUP(A24,'Aux - pivots1'!$A:$E,5,0)) | U24: Novo Plano
A25: =E25&F25 -> modesg_out_empr_info_nfinbio_capex_ttl_elgbl | B25: Pilar III | C25: Modelo Verde - Output | D25: 2. Campo | E25: modesg_out_empr_info_nfin | F25: bio_capex_ttl_elgbl | G25: =VLOOKUP(A25,Plano_V3!$A$26:$G$768,7,0) -> 1. Concluído | H25: 1. Concluído | J25: Package 1 | K25: Package 2 | M25: =IF(VLOOKUP(A25,'Aux - pivots1'!$A:$E,3,0)=0, "",VLOOKUP(A25,'Aux - pivots1'!$A:$E,3,0)) | N25: =IF(VLOOKUP(A25,'Aux - pivots1'!$A:$E,4,0)=0, "",VLOOKUP(A25,'Aux - pivots1'!$A:$E,4,0)) | O25: =IF(VLOOKUP(A25,'Aux - pivots1'!$A:$E,5,0)=0, "",VLOOKUP(A25,'Aux - pivots1'!$A:$E,5,0)) | U25: Novo Plano
A26: =E26&F26 -> modesg_out_empr_info_nfinbio_capex_own_prfrmnce_algnd | B26: Pilar III | C26: Modelo Verde - Output | D26: 2. Campo | E26: modesg_out_empr_info_nfin | F26: bio_capex_own_prfrmnce_algnd | G26: =VLOOKUP(A26,Plano_V3!$A$26:$G$768,7,0) -> 1. Concluído | H26: 1. Concluído | J26: Package 1 | K26: Package 2 | M26: =IF(VLOOKUP(A26,'Aux - pivots1'!$A:$E,3,0)=0, "",VLOOKUP(A26,'Aux - pivots1'!$A:$E,3,0)) | N26: =IF(VLOOKUP(A26,'Aux - pivots1'!$A:$E,4,0)=0, "",VLOOKUP(A26,'Aux - pivots1'!$A:$E,4,0)) | O26: =IF(VLOOKUP(A26,'Aux - pivots1'!$A:$E,5,0)=0, "",VLOOKUP(A26,'Aux - pivots1'!$A:$E,5,0)) | U26: Novo Plano
A27: =E27&F27 -> modesg_out_empr_info_nfinwtr_trnvr_ttl_elgbl | B27: Pilar III | C27: Modelo Verde - Output | D27: 2. Campo | E27: modesg_out_empr_info_nfin | F27: wtr_trnvr_ttl_elgbl | G27: =VLOOKUP(A27,Plano_V3!$A$26:$G$768,7,0) -> 1. Concluído | H27: 1. Concluído | J27: Package 1 | K27: Package 2 | M27: =IF(VLOOKUP(A27,'Aux - pivots1'!$A:$E,3,0)=0, "",VLOOKUP(A27,'Aux - pivots1'!$A:$E,3,0)) | N27: =IF(VLOOKUP(A27,'Aux - pivots1'!$A:$E,4,0)=0, "",VLOOKUP(A27,'Aux - pivots1'!$A:$E,4,0)) | O27: =IF(VLOOKUP(A27,'Aux - pivots1'!$A:$E,5,0)=0, "",VLOOKUP(A27,'Aux - pivots1'!$A:$E,5,0)) | U27: Novo Plano
A28: =E28&F28 -> modesg_out_empr_info_nfinwtr_trnvr_enblng_alignd | B28: Pilar III | C28: Modelo Verde - Output | D28: 2. Campo | E28: modesg_out_empr_info_nfin | F28: wtr_trnvr_enblng_alignd | G28: =VLOOKUP(A28,Plano_V3!$A$26:$G$768,7,0) -> 1. Concluído | H28: 1. Concluído | J28: Package 1 | K28: Package 2 | M28: =IF(VLOOKUP(A28,'Aux - pivots1'!$A:$E,3,0)=0, "",VLOOKUP(A28,'Aux - pivots1'!$A:$E,3,0)) | N28: =IF(VLOOKUP(A28,'Aux - pivots1'!$A:$E,4,0)=0, "",VLOOKUP(A28,'Aux - pivots1'!$A:$E,4,0)) | O28: =IF(VLOOKUP(A28,'Aux - pivots1'!$A:$E,5,0)=0, "",VLOOKUP(A28,'Aux - pivots1'!$A:$E,5,0)) | U28: Novo Plano
A29: =E29&F29 -> modesg_out_empr_info_nfinwtr_turnover_own_prfrmnce_algnd | B29: Pilar III | C29: Modelo Verde - Output | D29: 2. Campo | E29: modesg_out_empr_info_nfin | F29: wtr_turnover_own_prfrmnce_algnd | G29: =VLOOKUP(A29,Plano_V3!$A$26:$G$768,7,0) -> 1. Concluído | H29: 1. Concluído | J29: Package 1 | K29: Package 2 | M29: =IF(VLOOKUP(A29,'Aux - pivots1'!$A:$E,3,0)=0, "",VLOOKUP(A29,'Aux - pivots1'!$A:$E,3,0)) | N29: =IF(VLOOKUP(A29,'Aux - pivots1'!$A:$E,4,0)=0, "",VLOOKUP(A29,'Aux - pivots1'!$A:$E,4,0)) | O29: =IF(VLOOKUP(A29,'Aux - pivots1'!$A:$E,5,0)=0, "",VLOOKUP(A29,'Aux - pivots1'!$A:$E,5,0)) | U29: Novo Plano
A30: =E30&F30 -> modesg_out_empr_info_nfinwtr_capex_ttl_elgbl | B30: Pilar III | C30: Modelo Verde - Output | D30: 2. Campo | E30: modesg_out_empr_info_nfin | F30: wtr_capex_ttl_elgbl | G30: =VLOOKUP(A30,Plano_V3!$A$26:$G$768,7,0) -> 1. Concluído | H30: 1. Concluído | J30: Package 1 | K30: Package 2 | M30: =IF(VLOOKUP(A30,'Aux - pivots1'!$A:$E,3,0)=0, "",VLOOKUP(A30,'Aux - pivots1'!$A:$E,3,0)) | N30: =IF(VLOOKUP(A30,'Aux - pivots1'!$A:$E,4,0)=0, "",VLOOKUP(A30,'Aux - pivots1'!$A:$E,4,0)) | O30: =IF(VLOOKUP(A30,'Aux - pivots1'!$A:$E,5,0)=0, "",VLOOKUP(A30,'Aux - pivots1'!$A:$E,5,0)) | U30: Novo Plano
... A38: =E38&F38 -> modesg_out_empr_info_nfince_capex_own_prfrmnce_algnd | B38: Pilar III | C38: Modelo Verde - Output | D38: 2. Campo | E38: modesg_out_empr_info_nfin | F38: ce_capex_own_prfrmnce_algnd | G38: =VLOOKUP(A38,Plano_V3!$A$26:$G$768,7,0) -> 1. Concluído | H38: 1. Concluído | J38: Package 1 | K38: Package 2 | M38: =IF(VLOOKUP(A38,'Aux - pivots1'!$A:$E,3,0)=0, "",VLOOKUP(A38,'Aux - pivots1'!$A:$E,3,0)) | N38: =IF(VLOOKUP(A38,'Aux - pivots1'!$A:$E,4,0)=0, "",VLOOKUP(A38,'Aux - pivots1'!$A:$E,4,0)) | O38: =IF(VLOOKUP(A38,'Aux - pivots1'!$A:$E,5,0)=0, "",VLOOKUP(A38,'Aux - pivots1'!$A:$E,5,0)) | U38: Novo Plano
A39: =E39&F39 -> lt007_instr_activityPRCNTG_ACTVTY | B39: Pilar III | C39: Pilar III | D39: 2. Campo | E39: lt007_instr_activity | F39: PRCNTG_ACTVTY | G39: =VLOOKUP(A39,Plano_V3!$A$26:$G$768,7,0) -> 6. Em implementação | H39: 6. Em implementação | J39: Package 5 | K39: Package 23 abril | M39: =IF(VLOOKUP(A39,'Aux - pivots1'!$A:$E,3,0)=0, "",VLOOKUP(A39,'Aux - pivots1'!$A:$E,3,0)) | N39: =IF(VLOOKUP(A39,'Aux - pivots1'!$A:$E,4,0)=0, "",VLOOKUP(A39,'Aux - pivots1'!$A:$E,4,0)) | O39: =IF(VLOOKUP(A39,'Aux - pivots1'!$A:$E,5,0)=0, "",VLOOKUP(A39,'Aux - pivots1'!$A:$E,5,0)) | R39: Novo Projeto - Em especificação | S39: GD, P3 e GF | T39: Novos Requisitos FY25 - Outros | U39: Novo Plano | V39: RC
A40: =E40&F40 -> lt007_instr_activityFLG_SBSTNTL_CNTRBTN | B40: Pilar III | C40: Pilar III | D40: 2. Campo | E40: lt007_instr_activity | F40: FLG_SBSTNTL_CNTRBTN | G40: =VLOOKUP(A40,Plano_V3!$A$26:$G$768,7,0) -> 6. Em implementação | H40: 6. Em implementação | J40: Package 5 | K40: Package 23 abril | M40: =IF(VLOOKUP(A40,'Aux - pivots1'!$A:$E,3,0)=0, "",VLOOKUP(A40,'Aux - pivots1'!$A:$E,3,0)) | N40: =IF(VLOOKUP(A40,'Aux - pivots1'!$A:$E,4,0)=0, "",VLOOKUP(A40,'Aux - pivots1'!$A:$E,4,0)) | O40: =IF(VLOOKUP(A40,'Aux - pivots1'!$A:$E,5,0)=0, "",VLOOKUP(A40,'Aux - pivots1'!$A:$E,5,0)) | R40: Novo Projeto - Em especificação | S40: P3 | T40: Novos Requisitos FY25 - Outros | U40: Novo Plano | V40: RC
A41: =E41&F41 -> lt003_entitygrp_ecnmc_actvty | B41: Pilar III | C41: Pilar III | D41: 2. Campo | E41: lt003_entity | F41: grp_ecnmc_actvty | G41: =VLOOKUP(A41,Plano_V3!$A$26:$G$768,7,0) -> 6. Em implementação | H41: 6. Em implementação | J41: Package 5 | K41: Package 23 abril | M41: =IF(VLOOKUP(A41,'Aux - pivots1'!$A:$E,3,0)=0, "",VLOOKUP(A41,'Aux - pivots1'!$A:$E,3,0)) | N41: =IF(VLOOKUP(A41,'Aux - pivots1'!$A:$E,4,0)=0, "",VLOOKUP(A41,'Aux - pivots1'!$A:$E,4,0)) | O41: =IF(VLOOKUP(A41,'Aux - pivots1'!$A:$E,5,0)=0, "",VLOOKUP(A41,'Aux - pivots1'!$A:$E,5,0)) | R41: Novo Projeto - Em especificação | S41: P3, GF e ESG | T41: Novos Requisitos FY25 - Outros | U41: Novo Plano | V41: JB
A42: =E42&F42 -> lt006_instr_protTYP_RLTN | B42: Pilar III | C42: Pilar III | D42: 2. Campo | E42: lt006_instr_prot | F42: TYP_RLTN | G42: =VLOOKUP(A42,Plano_V3!$A$26:$G$768,7,0) -> 6. Em implementação | H42: 6. Em implementação | J42: Package 5 | K42: Package 23 abril | M42: =IF(VLOOKUP(A33,'Aux - pivots1'!$A:$E,3,0)=0, "",VLOOKUP(A33,'Aux - pivots1'!$A:$E,3,0)) | N42: =IF(VLOOKUP(A33,'Aux - pivots1'!$A:$E,4,0)=0, "",VLOOKUP(A33,'Aux - pivots1'!$A:$E,4,0)) | O42: =IF(VLOOKUP(A33,'Aux - pivots1'!$A:$E,5,0)=0, "",VLOOKUP(A33,'Aux - pivots1'!$A:$E,5,0)) | R42: Novo Projeto - Em especificação | S42: GD e P3 | T42: Novos Requisitos FY25 - Outros | U42: Novo Plano | V42: JB
A43: =E43&F43 -> lt004_protectionEPC_EMSSNS_LBL | B43: Pilar III | C43: Pilar III | D43: 2. Campo | E43: lt004_protection | F43: EPC_EMSSNS_LBL | G43: =VLOOKUP(A43,Plano_V3!$A$26:$G$768,7,0) -> 6. Em implementação | H43: 6. Em implementação | J43: Package 4 | K43: Package 23 abril | M43: =IF(VLOOKUP(A43,'Aux - pivots1'!$A:$E,3,0)=0, "",VLOOKUP(A43,'Aux - pivots1'!$A:$E,3,0)) | N43: =IF(VLOOKUP(A43,'Aux - pivots1'!$A:$E,4,0)=0, "",VLOOKUP(A43,'Aux - pivots1'!$A:$E,4,0)) | O43: =IF(VLOOKUP(A43,'Aux - pivots1'!$A:$E,5,0)=0, "",VLOOKUP(A43,'Aux - pivots1'!$A:$E,5,0)) | R43: Novo Projeto - Em especificação | S43: ESG | T43: Novos Requisitos FY25 - Outros | U43: Novo Plano | V43: JB
A44: =E44&F44 -> lt004_protectionTYP_EMSSNS_SCR | B44: Pilar III | C44: Pilar III | D44: 2. Campo | E44: lt004_protection | F44: TYP_EMSSNS_SCR | G44: =VLOOKUP(A44,Plano_V3!$A$26:$G$768,7,0) -> 6. Em implementação | H44: 6. Em implementação | J44: Package 4 | K44: Package 23 abril | M44: =IF(VLOOKUP(A44,'Aux - pivots1'!$A:$E,3,0)=0, "",VLOOKUP(A44,'Aux - pivots1'!$A:$E,3,0)) | N44: =IF(VLOOKUP(A44,'Aux - pivots1'!$A:$E,4,0)=0, "",VLOOKUP(A44,'Aux - pivots1'!$A:$E,4,0)) | O44: =IF(VLOOKUP(A44,'Aux - pivots1'!$A:$E,5,0)=0, "",VLOOKUP(A44,'Aux - pivots1'!$A:$E,5,0)) | R44: Novo Projeto - Em especificação | S44: ESG | T44: Novos Requisitos FY25 - Outros | U44: Novo Plano | V44: JB
A45: =E45&F45 -> lt004_protectionEPC_EMSSNS_SCR | B45: Pilar III | C45: Pilar III | D45: 2. Campo | E45: lt004_protection | F45: EPC_EMSSNS_SCR | G45: =VLOOKUP(A45,Plano_V3!$A$26:$G$768,7,0) -> 6. Em implementação | H45: 6. Em implementação | J45: Package 4 | K45: Package 23 abril | M45: =IF(VLOOKUP(A45,'Aux - pivots1'!$A:$E,3,0)=0, "",VLOOKUP(A45,'Aux - pivots1'!$A:$E,3,0)) | N45: =IF(VLOOKUP(A45,'Aux - pivots1'!$A:$E,4,0)=0, "",VLOOKUP(A45,'Aux - pivots1'!$A:$E,4,0)) | O45: =IF(VLOOKUP(A45,'Aux - pivots1'!$A:$E,5,0)=0, "",VLOOKUP(A45,'Aux - pivots1'!$A:$E,5,0)) | R45: Novo Projeto - Em especificação | S45: ESG | T45: Novos Requisitos FY25 - Outros | U45: Novo Plano | V45: JB
