Workbook

Sheet Âmbito de atuação
B6: Âmbito de atuação
C9: Modelo Relacional - Modelo Verde | V9: Modelo Relacional - Bens Imóveis
C39: Legenda:
D40: Tabelas âmbito de atuação

Sheet Plano_V3
B6: Re-testes - input | D6: 0.2 | R6: =R7-R10 -> 0 | S6: =S7-S10 -> 0 | T6: =T7-T10 -> 0 | U6: =U7-U10 -> 0 | V6: =V7-V10 -> 0 | W6: =W7-W10 -> 0 | X6: =X7-X10 -> 0 | Y6: =Y7-Y10 -> 0 | ... ES6: =ES7-ES10 -> 0
B7: Re-testes - output | D7: =50%*25% -> 0.125 | Q7: =AVERAGE(R7:EQ7) -> 2.4923077 | R7: 3 | S7: 3 | T7: 3 | U7: 3 | V7: 3 | W7: 2 | X7: 2 | Y7: 2 | Z7: 2 | AA7: 2 | AB7: 2 | AC7: 2 | AD7: 2 | AE7: 2 | AF7: 2 | AG7: 2 | AH7: 2 | AI7: 1 | AJ7: 1 | AK7: 1 | AL7: 3 | AM7: 3 | AN7: 3 | AO7: 3 | AP7: 2 | AQ7: 3 | AR7: 3 | AS7: 3 | AT7: 3 | AU7: 3 | AV7: 2 | AW7: 2 | AX7: 2 | AY7: 0 | AZ7: 1 | BA7: 1 | BB7: 0 | BC7: 1 | BD7: 1 | BE7: 1 | BF7: 2 | BG7: 2 | BH7: 2 | BI7: 2 | BJ7: 2 | BK7: 2 | BL7: 2 | BM7: 2 | BN7: 2 | BO7: 2 | BP7: 2 | BQ7: 2 | BR7: 2 | BS7: 2 | BT7: 2 | BU7: 3 | BV7: 3 | BW7: 3 | BX7: 3 | BY7: 3 | BZ7: 3 | CA7: 3 | CB7: 3 | CC7: 3 | CD7: 3 | CE7: 3 | CF7: 3 | CG7: 3 | CH7: 3 | CI7: 3 | CJ7: 3 | CK7: 3 | CL7: 3 | CM7: 3 | CN7: 3 | CO7: 3 | CP7: 3 | CQ7: 3 | CR7: 3 | CS7: 3 | CT7: 3 | CU7: 3 | CV7: 3 | CW7: 3 | CX7: 3 | CY7: 3 | CZ7: 3 | DA7: 3 | DB7: 3 | DC7: 3 | DD7: 3 | DE7: 3 | DF7: 3 | DG7: 3 | DH7: 3 | DI7: 3 | DJ7: 3 | DK7: 3 | DL7: 3 | DM7: 3 | DN7: 3 | DO7: 3 | DP7: 3 | DQ7: 3 | DR7: 3 | DS7: 2 | DT7: 3 | DU7: 3 | DV7: 3 | DW7: 3 | DX7: 3 | DY7: 3 | DZ7: 3 | EA7: 3 | EB7: 3 | EC7: 3 | ED7: 3 | EE7: 3 | EF7: 3 | EG7: 3 | EH7: 3 | EI7: 3 | EJ7: 3 | EK7: 3 | EL7: 3 | EM7: 3 | EN7: 0 | EO7: 0 | EP7: 0 | EQ7: 0 | ER7: 0 | ES7: 0
Q9: 45568 | R9: =IF(R13<=$Q$9,"S","N") -> S | S9: =IF(S13<=$Q$9,"S","N") -> S | T9: =IF(T13<=$Q$9,"S","N") -> S | U9: =IF(U13<=$Q$9,"S","N") -> S | V9: =IF(V13<=$Q$9,"S","N") -> S | W9: =IF(W13<=$Q$9,"S","N") -> S | X9: =IF(X13<=$Q$9,"S","N") -> S | Y9: =IF(Y13<=$Q$9,"S","N") -> S | ... ES9: =IF(ES13<=$Q$9,"S","N") -> N
R10: =SUBTOTAL(9,R14:R583) -> 3 | S10: =SUBTOTAL(9,S14:S583) -> 3 | T10: =SUBTOTAL(9,T14:T583) -> 3 | U10: =SUBTOTAL(9,U14:U583) -> 3 | V10: =SUBTOTAL(9,V14:V583) -> 3 | W10: =SUBTOTAL(9,W14:W583) -> 2 | X10: =SUBTOTAL(9,X14:X583) -> 2 | Y10: =SUBTOTAL(9,Y14:Y583) -> 2 | ... ES10: =SUBTOTAL(9,ES14:ES583) -> 0
R11: Julho | AO11: Agosto | BK11: Setembro | CF11: Outubro | DC11: Novembro | DX11: Dezembro
R12: =R13 -> 45474 | S12: =S13 -> 45475 | T12: =T13 -> 45476 | U12: =U13 -> 45477 | V12: =V13 -> 45478 | W12: =W13 -> 45481 | X12: =X13 -> 45482 | Y12: =Y13 -> 45483 | ... ES12: =ES13 -> 45657
B13: Âmbito | C13: Sub-âmbito | D13: Tipo de teste | E13: Tabela | F13: Campo | G13: Status | H13: Status2 | I13: Horas previstas | J13: Dias | K13: Horas efetivas | L13: Dias efetivos | M13: Status Estimado | N13: Status Real | O13: Desvios | P13: Observações | Q13: Val | R13: 45474 | S13: =WORKDAY(R13,1) -> 45475 | T13: =WORKDAY(S13,1) -> 45476 | U13: =WORKDAY(T13,1) -> 45477 | V13: =WORKDAY(U13,1) -> 45478 | W13: =WORKDAY(V13,1) -> 45481 | X13: =WORKDAY(W13,1) -> 45482 | Y13: =WORKDAY(X13,1) -> 45483 | Z13: =WORKDAY(Y13,1) -> 45484 | ... ES13: =WORKDAY(ER13,1) -> 45657
B14: 1. Assessment | I14: =SUM(I15:I17) -> 160 | J14: =SUM(J15:J17) -> 20 | K14: =I14 -> 160 | L14: =J14 -> 20 | M14: =SUMPRODUCT(M15:M17,I15:I17)/I14 -> 1 | N14: =SUMPRODUCT(N15:N17,J15:J17)/J14 -> 1 | O14: =N14-M14 -> 0 | P14: N/A
B15: Pilar III | C15: Bens Imóveis | G15: 7. Por iniciar | I15: =J15*8 -> 40 | J15: 5 | M15: =100% -> 1 | N15: =100% -> 1 | O15: =N15-M15 -> 0 | P15: N/A | Q15: =J15-SUM(R15:ES15) -> 0 | AB15: 1 | AC15: 1 | AD15: 1 | AE15: 1 | AF15: 1
B16: Pilar III | C16: Modelo Verde | G16: 7. Por iniciar | I16: =J16*8 -> 80 | J16: 10 | M16: =100% -> 1 | N16: =100% -> 1 | O16: =N16-M16 -> 0 | P16: N/A | Q16: =J16-SUM(R16:ES16) -> 0 | W16: 2 | X16: 2 | Y16: 2 | Z16: 2 | AA16: 2
B17: Pilar III | C17: LT Pilar III | G17: 7. Por iniciar | I17: =J17*8 -> 40 | J17: 5 | M17: =100% -> 1 | N17: =100% -> 1 | O17: =N17-M17 -> 0 | P17: N/A | Q17: =J17-SUM(R17:ES17) -> 0 | AG17: 1 | AH17: 1 | AI17: 1 | AJ17: 1 | AK17: 0.5 | AL17: 0.5
B18: GD | C18: GD | G18: 7. Por iniciar | I18: =J18*8 -> 120 | J18: 15 | N18: 1 | Q18: =J18-SUM(R18:ES18) -> 0 | R18: 3 | S18: 3 | T18: 3 | U18: 3 | V18: 3
B20: 2. Re-especificação | I20: =SUM(I21:I23) -> 120 | J20: =SUM(J21:J23) -> 15 | K20: =N20*I20 -> 92 | L20: =N20*J20 -> 11.5 | M20: =SUMPRODUCT(M21:M24,I21:I24)/I20 -> 0.8 | N20: =SUMPRODUCT(N21:N23,J21:J23)/J20 -> 0.76666667 | O20: =N20-M20 -> -0.033333333 | P20: N/A
B21: Pilar III | C21: Bens Imóveis | G21: 7. Por iniciar | I21: =J21*8 -> 40 | J21: 5 | M21: =SUMIFS(R21:ES21,$R$9:$ES$9,"S")/J21 -> 1 | N21: =100% -> 1 | O21: =N21-M21 -> 0 | P21: N/A | Q21: =J21-SUM(R21:ES21) -> 0 | AB21: 0.5 | AG21: 0.5 | AL21: 0.5 | AQ21: 0.5 | AV21: 0.5 | BA21: 0.5 | BF21: 0.5 | BK21: 0.5 | BP21: 0.5 | BU21: 0.5
B22: Pilar III | C22: Modelo Verde | G22: 7. Por iniciar | I22: =J22*8 -> 40 | J22: 5 | M22: =SUMIFS(R22:ES22,$R$9:$ES$9,"S")/J22 -> 1 | N22: 0.9 | O22: =N22-M22 -> -0.1 | P22: - Pendência de aprovação da especificação de scopes de veículos; - Pendência de atualização da tabela de parametrização (CdG) | Q22: =J22-SUM(R22:ES22) -> 0 | AB22: 0.5 | AG22: 0.5 | AL22: 0.5 | AQ22: 0.5 | AV22: 0.5 | BA22: 0.5 | BF22: 0.5 | BK22: 0.5 | BP22: 0.5 | BU22: 0.5
B23: Pilar III | C23: LT Pilar III | G23: 7. Por iniciar | I23: =J23*8 -> 40 | J23: 5 | M23: =SUMIFS(R23:ES23,$R$9:$ES$9,"S")/J23 -> 0.4 | N23: 0.4 | O23: =N23-M23 -> 0 | P23: Será foco nas próximas semanas, dado que até ao PdS de 04/10/2024 o foco foi fechar especificações de Modelo Verde e Modelo de Bens Imóveis | Q23: =J23-SUM(R23:ES23) -> 0.5 | BP23: 0.5 | BU23: 0.5 | BZ23: 0.5 | CE23: 0.5 | CJ23: 0.5 | CO23: 0.5 | CT23: 0.5 | CY23: 0.5 | DD23: 0.5
B25: 3. Testes / Re-testes | I25: =I26+I41+I204+I371+I456 -> 2164.94 | J25: =J26+J41+J204+J371+J456 -> 273 | K25: =K26+K41+K204+K371+K456 -> 1304.3881 | L25: =L26+L41+L204+L371+L456 -> 165 | M25: =((M26*J26)+(M41*J41)+(M204*J204)+(M371*J371)+(M456*J456))/J25 -> 0.39010989 | N25: =((N26*L26)+(N41*L41)+(N204*L204)+(N371*L371)+(N456*L456))/L25 -> 0.58370578 | O25: =N25-M25 -> 0.19359589 | P25: N/A
B26: Pilar III | C26: Bens Imóveis - Input | I26: =SUM(I27:I40) -> 18.24 | J26: =ROUNDUP(I26/8,0) -> 3 | K26: =SUM(K27:K40) -> 4.56 | L26: =ROUNDUP(K26/8,0) -> 1 | M26: =SUMIFS(R26:ES26,$R$9:$ES$9,"S")/J26 -> 1 | N26: =IFERROR(L26/J26,0) -> 0.33333333 | O26: =N26-M26 -> -0.66666667 | P26: - Pendência de desenvolvimentos de IT: Tabela da Gloval | Q26: =J26-SUM(R26:ES26) -> 0 | AC26: 0.5 | AD26: 0.5 | AH26: 0.5 | AO26: 0.5 | AP26: 0.5 | AQ26: 0.5
A27: =E27&F27 -> ENERGY_CERTIFICATE_EST_INPUTn.a. | B27: Pilar III | C27: Bens Imóveis - Input | D27: 1. Universo | E27: ENERGY_CERTIFICATE_EST_INPUT | F27: n.a. | G27: =INDEX(Auxiliar!$B$16:$B$24,MATCH(Plano_V3!H27,Auxiliar!$C$16:$C$24,0),1) -> 6. Em implementação (re-especificação) | H27: =VLOOKUP(A27,'Aux - pivots1'!$A:$B,2,0) -> 7 | I27: =SUMIFS(Table1[Estimação (horas)],Table1[Tabela],Plano_V3!E27,Table1[Campo],Plano_V3!F27) -> 8 | J27: =I27/8 -> 1 | K27: =SUMIFS(Table1[Horas efetivas],Table1[Tabela],Plano_V3!E27,Table1[Campo],Plano_V3!F27) -> 2 | L27: =K27/8 -> 0.25 | N27: =L27/J27 -> 0.25 | O27: =N27-M27 -> 0.25 | P27: sem pendencia | Q27: =J27-SUM(R27:ES27) -> 1
A28: =E28&F28 -> ENERGY_CERTIFICATE_EST_INPUTPROPERTY_BANK_ID | B28: Pilar III | C28: Bens Imóveis - Input | D28: 2. Campo | E28: ENERGY_CERTIFICATE_EST_INPUT | F28: PROPERTY_BANK_ID | G28: =INDEX(Auxiliar!$B$16:$B$24,MATCH(Plano_V3!H28,Auxiliar!$C$16:$C$24,0),1) -> 6. Em implementação (re-especificação) | H28: =VLOOKUP(A28,'Aux - pivots1'!$A:$B,2,0) -> 7 | I28: =SUMIFS(Table1[Estimação (horas)],Table1[Tabela],Plano_V3!E28,Table1[Campo],Plano_V3!F28) -> 0.6 | J28: =I28/8 -> 0.075 | K28: =SUMIFS(Table1[Horas efetivas],Table1[Tabela],Plano_V3!E28,Table1[Campo],Plano_V3!F28) -> 0.15 | L28: =K28/8 -> 0.01875 | N28: =L28/J28 -> 0.25 | O28: =N28-M28 -> 0.25 | P28: sem pendencia | Q28: =J28-SUM(R28:ES28) -> 0.075
A29: =E29&F29 -> ENERGY_CERTIFICATE_EST_INPUTENCRYPTED_KEY | B29: Pilar III | C29: Bens Imóveis - Input | D29: 2. Campo | E29: ENERGY_CERTIFICATE_EST_INPUT | F29: ENCRYPTED_KEY | G29: =INDEX(Auxiliar!$B$16:$B$24,MATCH(Plano_V3!H29,Auxiliar!$C$16:$C$24,0),1) -> 6. Em implementação (re-especificação) | H29: =VLOOKUP(A29,'Aux - pivots1'!$A:$B,2,0) -> 7 | I29: =SUMIFS(Table1[Estimação (horas)],Table1[Tabela],Plano_V3!E29,Table1[Campo],Plano_V3!F29) -> 0.6 | J29: =I29/8 -> 0.075 | K29: =SUMIFS(Table1[Horas efetivas],Table1[Tabela],Plano_V3!E29,Table1[Campo],Plano_V3!F29) -> 0.15 | L29: =K29/8 -> 0.01875 | N29: =L29/J29 -> 0.25 | O29: =N29-M29 -> 0.25 | P29: sem pendencia | Q29: =J29-SUM(R29:ES29) -> 0.075
A30: =E30&F30 -> ENERGY_CERTIFICATE_EST_INPUTPROPERTY_BRANCH_CODE | B30: Pilar III | C30: Bens Imóveis - Input | D30: 2. Campo | E30: ENERGY_CERTIFICATE_EST_INPUT | F30: PROPERTY_BRANCH_CODE | G30: =INDEX(Auxiliar!$B$16:$B$24,MATCH(Plano_V3!H30,Auxiliar!$C$16:$C$24,0),1) -> 6. Em implementação (re-especificação) | H30: =VLOOKUP(A30,'Aux - pivots1'!$A:$B,2,0) -> 7 | I30: =SUMIFS(Table1[Estimação (horas)],Table1[Tabela],Plano_V3!E30,Table1[Campo],Plano_V3!F30) -> 0.6 | J30: =I30/8 -> 0.075 | K30: =SUMIFS(Table1[Horas efetivas],Table1[Tabela],Plano_V3!E30,Table1[Campo],Plano_V3!F30) -> 0.15 | L30: =K30/8 -> 0.01875 | N30: =L30/J30 -> 0.25 | O30: =N30-M30 -> 0.25 | P30: sem pendencia | Q30: =J30-SUM(R30:ES30) -> 0.075
A31: =E31&F31 -> ENERGY_CERTIFICATE_EST_INPUTPROPERTY_CONTRACT_ID | B31: Pilar III | C31: Bens Imóveis - Input | D31: 2. Campo | E31: ENERGY_CERTIFICATE_EST_INPUT | F31: PROPERTY_CONTRACT_ID | G31: =INDEX(Auxiliar!$B$16:$B$24,MATCH(Plano_V3!H31,Auxiliar!$C$16:$C$24,0),1) -> 6. Em implementação (re-especificação) | H31: =VLOOKUP(A31,'Aux - pivots1'!$A:$B,2,0) -> 7 | I31: =SUMIFS(Table1[Estimação (horas)],Table1[Tabela],Plano_V3!E31,Table1[Campo],Plano_V3!F31) -> 0.6 | J31: =I31/8 -> 0.075 | K31: =SUMIFS(Table1[Horas efetivas],Table1[Tabela],Plano_V3!E31,Table1[Campo],Plano_V3!F31) -> 0.15 | L31: =K31/8 -> 0.01875 | N31: =L31/J31 -> 0.25 | O31: =N31-M31 -> 0.25 | P31: sem pendencia | Q31: =J31-SUM(R31:ES31) -> 0.075
A32: =E32&F32 -> ENERGY_CERTIFICATE_EST_INPUTPROPERTY_REFERENCE_CODE | B32: Pilar III | C32: Bens Imóveis - Input | D32: 2. Campo | E32: ENERGY_CERTIFICATE_EST_INPUT | F32: PROPERTY_REFERENCE_CODE | G32: =INDEX(Auxiliar!$B$16:$B$24,MATCH(Plano_V3!H32,Auxiliar!$C$16:$C$24,0),1) -> 6. Em implementação (re-especificação) | H32: =VLOOKUP(A32,'Aux - pivots1'!$A:$B,2,0) -> 7 | I32: =SUMIFS(Table1[Estimação (horas)],Table1[Tabela],Plano_V3!E32,Table1[Campo],Plano_V3!F32) -> 0.6 | J32: =I32/8 -> 0.075 | K32: =SUMIFS(Table1[Horas efetivas],Table1[Tabela],Plano_V3!E32,Table1[Campo],Plano_V3!F32) -> 0.15 | L32: =K32/8 -> 0.01875 | N32: =L32/J32 -> 0.25 | O32: =N32-M32 -> 0.25 | P32: sem pendencia | Q32: =J32-SUM(R32:ES32) -> 0.075
A33: =E33&F33 -> ENERGY_CERTIFICATE_EST_INPUTDATA_EXTRACTION_DATE | B33: Pilar III | C33: Bens Imóveis - Input | D33: 2. Campo | E33: ENERGY_CERTIFICATE_EST_INPUT | F33: DATA_EXTRACTION_DATE | G33: =INDEX(Auxiliar!$B$16:$B$24,MATCH(Plano_V3!H33,Auxiliar!$C$16:$C$24,0),1) -> 6. Em implementação (re-especificação) | H33: =VLOOKUP(A33,'Aux - pivots1'!$A:$B,2,0) -> 7 | I33: =SUMIFS(Table1[Estimação (horas)],Table1[Tabela],Plano_V3!E33,Table1[Campo],Plano_V3!F33) -> 0.6 | J33: =I33/8 -> 0.075 | K33: =SUMIFS(Table1[Horas efetivas],Table1[Tabela],Plano_V3!E33,Table1[Campo],Plano_V3!F33) -> 0.15 | L33: =K33/8 -> 0.01875 | N33: =L33/J33 -> 0.25 | O33: =N33-M33 -> 0.25 | P33: sem pendencia | Q33: =J33-SUM(R33:ES33) -> 0.075
A34: =E34&F34 -> ENERGY_CERTIFICATE_EST_INPUTEPC | B34: Pilar III | C34: Bens Imóveis - Input | D34: 2. Campo | E34: ENERGY_CERTIFICATE_EST_INPUT | F34: EPC | G34: =INDEX(Auxiliar!$B$16:$B$24,MATCH(Plano_V3!H34,Auxiliar!$C$16:$C$24,0),1) -> 6. Em implementação (re-especificação) | H34: =VLOOKUP(A34,'Aux - pivots1'!$A:$B,2,0) -> 7 | I34: =SUMIFS(Table1[Estimação (horas)],Table1[Tabela],Plano_V3!E34,Table1[Campo],Plano_V3!F34) -> 0.6 | J34: =I34/8 -> 0.075 | K34: =SUMIFS(Table1[Horas efetivas],Table1[Tabela],Plano_V3!E34,Table1[Campo],Plano_V3!F34) -> 0.15 | L34: =K34/8 -> 0.01875 | N34: =L34/J34 -> 0.25 | O34: =N34-M34 -> 0.25 | P34: sem pendencia | Q34: =J34-SUM(R34:ES34) -> 0.075
A35: =E35&F35 -> ENERGY_CERTIFICATE_EST_INPUTDATA_PROVIDER | B35: Pilar III | C35: Bens Imóveis - Input | D35: 2. Campo | E35: ENERGY_CERTIFICATE_EST_INPUT | F35: DATA_PROVIDER | G35: =INDEX(Auxiliar!$B$16:$B$24,MATCH(Plano_V3!H35,Auxiliar!$C$16:$C$24,0),1) -> 6. Em implementação (re-especificação) | H35: =VLOOKUP(A35,'Aux - pivots1'!$A:$B,2,0) -> 7 | I35: =SUMIFS(Table1[Estimação (horas)],Table1[Tabela],Plano_V3!E35,Table1[Campo],Plano_V3!F35) -> 0.6 | J35: =I35/8 -> 0.075 | K35: =SUMIFS(Table1[Horas efetivas],Table1[Tabela],Plano_V3!E35,Table1[Campo],Plano_V3!F35) -> 0.15 | L35: =K35/8 -> 0.01875 | N35: =L35/J35 -> 0.25 | O35: =N35-M35 -> 0.25 | P35: sem pendencia | Q35: =J35-SUM(R35:ES35) -> 0.075
A36: =E36&F36 -> ENERGY_CERTIFICATE_EST_INPUTACTUAL_VALUE_IND | B36: Pilar III | C36: Bens Imóveis - Input | D36: 2. Campo | E36: ENERGY_CERTIFICATE_EST_INPUT | F36: ACTUAL_VALUE_IND | G36: =INDEX(Auxiliar!$B$16:$B$24,MATCH(Plano_V3!H36,Auxiliar!$C$16:$C$24,0),1) -> 6. Em implementação (re-especificação) | H36: =VLOOKUP(A36,'Aux - pivots1'!$A:$B,2,0) -> 7 | I36: =SUMIFS(Table1[Estimação (horas)],Table1[Tabela],Plano_V3!E36,Table1[Campo],Plano_V3!F36) -> 0.6 | J36: =I36/8 -> 0.075 | K36: =SUMIFS(Table1[Horas efetivas],Table1[Tabela],Plano_V3!E36,Table1[Campo],Plano_V3!F36) -> 0.15 | L36: =K36/8 -> 0.01875 | N36: =L36/J36 -> 0.25 | O36: =N36-M36 -> 0.25 | P36: sem pendencia | Q36: =J36-SUM(R36:ES36) -> 0.075
A37: =E37&F37 -> ENERGY_CERTIFICATE_EST_INPUTQUALITY_SCORE | B37: Pilar III | C37: Bens Imóveis - Input | D37: 2. Campo | E37: ENERGY_CERTIFICATE_EST_INPUT | F37: QUALITY_SCORE | G37: =INDEX(Auxiliar!$B$16:$B$24,MATCH(Plano_V3!H37,Auxiliar!$C$16:$C$24,0),1) -> 6. Em implementação (re-especificação) | H37: =VLOOKUP(A37,'Aux - pivots1'!$A:$B,2,0) -> 7 | I37: =SUMIFS(Table1[Estimação (horas)],Table1[Tabela],Plano_V3!E37,Table1[Campo],Plano_V3!F37) -> 0.6 | J37: =I37/8 -> 0.075 | K37: =SUMIFS(Table1[Horas efetivas],Table1[Tabela],Plano_V3!E37,Table1[Campo],Plano_V3!F37) -> 0.15 | L37: =K37/8 -> 0.01875 | N37: =L37/J37 -> 0.25 | O37: =N37-M37 -> 0.25 | P37: sem pendencia | Q37: =J37-SUM(R37:ES37) -> 0.075
A38: =E38&F38 -> ENERGY_CERTIFICATE_EST_INPUTENERGY_CONSUMPTION_VALUE_YEAR | B38: Pilar III | C38: Bens Imóveis - Input | D38: 2. Campo | E38: ENERGY_CERTIFICATE_EST_INPUT | F38: ENERGY_CONSUMPTION_VALUE_YEAR | G38: =INDEX(Auxiliar!$B$16:$B$24,MATCH(Plano_V3!H38,Auxiliar!$C$16:$C$24,0),1) -> 6. Em implementação (re-especificação) | H38: =VLOOKUP(A38,'Aux - pivots1'!$A:$B,2,0) -> 7 | I38: =SUMIFS(Table1[Estimação (horas)],Table1[Tabela],Plano_V3!E38,Table1[Campo],Plano_V3!F38) -> 0.6 | J38: =I38/8 -> 0.075 | K38: =SUMIFS(Table1[Horas efetivas],Table1[Tabela],Plano_V3!E38,Table1[Campo],Plano_V3!F38) -> 0.15 | L38: =K38/8 -> 0.01875 | N38: =L38/J38 -> 0.25 | O38: =N38-M38 -> 0.25 | P38: sem pendencia | Q38: =J38-SUM(R38:ES38) -> 0.075
A39: =E39&F39 -> ENERGY_CERTIFICATE_EST_INPUTCARBON_EMISSION_VALUE_YEAR | B39: Pilar III | C39: Bens Imóveis - Input | D39: 2. Campo | E39: ENERGY_CERTIFICATE_EST_INPUT | F39: CARBON_EMISSION_VALUE_YEAR | G39: =INDEX(Auxiliar!$B$16:$B$24,MATCH(Plano_V3!H39,Auxiliar!$C$16:$C$24,0),1) -> 6. Em implementação (re-especificação) | H39: =VLOOKUP(A39,'Aux - pivots1'!$A:$B,2,0) -> 7 | I39: =SUMIFS(Table1[Estimação (horas)],Table1[Tabela],Plano_V3!E39,Table1[Campo],Plano_V3!F39) -> 0.6 | J39: =I39/8 -> 0.075 | K39: =SUMIFS(Table1[Horas efetivas],Table1[Tabela],Plano_V3!E39,Table1[Campo],Plano_V3!F39) -> 0.15 | L39: =K39/8 -> 0.01875 | N39: =L39/J39 -> 0.25 | O39: =N39-M39 -> 0.25 | P39: sem pendencia | Q39: =J39-SUM(R39:ES39) -> 0.075
A40: =E40&F40 -> Re-testesn.a. | B40: Pilar III | C40: Bens Imóveis - Input | D40: 2. Campo | E40: Re-testes | F40: n.a. | G40: 7. Por iniciar | I40: =SUM(I27:I39)*$D$6 -> 3.04 | J40: =I40/8 -> 0.38 | K40: =SUM(K27:K39)*$D$6 -> 0.76 | L40: =K40/8 -> 0.095 | N40: =L40/J40 -> 0.25 | O40: =N40-M40 -> 0.25 | P40: sem pendencia | Q40: =J40-SUM(R40:ES40) -> 0.38
A41: =E41&F41 | B41: Pilar III | C41: Bens Imóveis - Output | I41: =SUM(I42:I203) -> 831.0375 | J41: =ROUNDUP(I41/8,0) -> 104 | K41: =SUM(K42:K203) -> 750.20625 | L41: =ROUNDUP(K41/8,0) -> 94 | M41: =SUMIFS(R41:ES41,$R$9:$ES$9,"S")/J41 -> 0.65865385 | N41: =IFERROR(L41/J41,0)-19% -> 0.71384615 | O41: =N41-M41 -> 0.055192308 | P41: - Pendência de desenvolvimentos de IT: Tabela de certificados energéticos. Avanço significativo face ao estimado de todos os campos que não dependem das tabelas em implementação por parte de IT. | Q41: =J41-SUM(R41:ES41) -> 4 | AL41: 1 | AM41: 1 | AN41: 1 | AO41: 1 | AR41: 1 | AS41: 1 | AT41: 1 | AU41: 1 | AW41: 1 | AX41: 2 | AZ41: 1 | BC41: 1 | BD41: 1 | BE41: 1 | BF41: 1 | BG41: 2 | BH41: 2 | BI41: 2 | BJ41: 2 | BK41: 0.5 | BL41: 2 | BM41: 2 | BN41: 2 | BO41: 2 | BP41: 0.5 | BQ41: 2 | BR41: 2 | BS41: 2 | BT41: 2 | BU41: 1.5 | BV41: 2 | BW41: 2 | BX41: 2 | BY41: 2 | BZ41: 2 | CA41: 2 | CB41: 2 | CC41: 2 | CD41: 2 | CE41: 2 | CF41: 2 | CG41: 2 | CH41: 2 | CI41: 2 | CJ41: 2 | CK41: 2 | CL41: 2 | CM41: 2 | CN41: 2 | CO41: 2 | CP41: 2 | CQ41: 2 | CR41: 2 | CS41: 2 | CT41: 2 | CU41: 2 | CV41: 2 | CW41: 2 | CX41: 1.5
A42: =E42&F42 -> PROCESSn.a. | B42: Pilar III | C42: Bens Imóveis - Output | D42: 1. Universo | E42: PROCESS | F42: n.a. | G42: =INDEX(Auxiliar!$B$16:$B$24,MATCH(Plano_V3!H42,Auxiliar!$C$16:$C$24,0),1) -> 1. Concluído | H42: =VLOOKUP(A42,'Aux - pivots1'!$A:$B,2,0) -> 1 | I42: =SUMIFS(Table1[Estimação (horas)],Table1[Tabela],Plano_V3!E42,Table1[Campo],Plano_V3!F42) -> 8 | J42: =I42/8 -> 1 | K42: =SUMIFS(Table1[Horas efetivas],Table1[Tabela],Plano_V3!E42,Table1[Campo],Plano_V3!F42) -> 8 | L42: =K42/8 -> 1 | N42: =L42/J42 -> 1 | O42: =N42-M42 -> 1 | P42: cd_imv_out_trz_cred_prc | Q42: =J42-SUM(R42:ES42) -> 1
A43: =E43&F43 -> PROCESSPROCESS_BANK_ID | B43: Pilar III | C43: Bens Imóveis - Output | D43: 2. Campo | E43: PROCESS | F43: PROCESS_BANK_ID | G43: =INDEX(Auxiliar!$B$16:$B$24,MATCH(Plano_V3!H43,Auxiliar!$C$16:$C$24,0),1) -> 1. Concluído | H43: =VLOOKUP(A43,'Aux - pivots1'!$A:$B,2,0) -> 1 | I43: =SUMIFS(Table1[Estimação (horas)],Table1[Tabela],Plano_V3!E43,Table1[Campo],Plano_V3!F43) -> 4.1 | J43: =I43/8 -> 0.5125 | K43: =SUMIFS(Table1[Horas efetivas],Table1[Tabela],Plano_V3!E43,Table1[Campo],Plano_V3!F43) -> 4.1 | L43: =K43/8 -> 0.5125 | N43: =L43/J43 -> 1 | O43: =N43-M43 -> 1 | P43: cd_imv_out_trz_cred_prc | Q43: =J43-SUM(R43:ES43) -> 0.5125
A44: =E44&F44 -> PROCESSPROCESS_BRANCH_CODE | B44: Pilar III | C44: Bens Imóveis - Output | D44: 2. Campo | E44: PROCESS | F44: PROCESS_BRANCH_CODE | G44: =INDEX(Auxiliar!$B$16:$B$24,MATCH(Plano_V3!H44,Auxiliar!$C$16:$C$24,0),1) -> 1. Concluído | H44: =VLOOKUP(A44,'Aux - pivots1'!$A:$B,2,0) -> 1 | I44: =SUMIFS(Table1[Estimação (horas)],Table1[Tabela],Plano_V3!E44,Table1[Campo],Plano_V3!F44) -> 4.1 | J44: =I44/8 -> 0.5125 | K44: =SUMIFS(Table1[Horas efetivas],Table1[Tabela],Plano_V3!E44,Table1[Campo],Plano_V3!F44) -> 4.1 | L44: =K44/8 -> 0.5125 | N44: =L44/J44 -> 1 | O44: =N44-M44 -> 1 | P44: cd_imv_out_trz_cred_prc | Q44: =J44-SUM(R44:ES44) -> 0.5125
A45: =E45&F45 -> PROCESSPROCESS_ACCOUNT_ID | B45: Pilar III | C45: Bens Imóveis - Output | D45: 2. Campo | E45: PROCESS | F45: PROCESS_ACCOUNT_ID | G45: =INDEX(Auxiliar!$B$16:$B$24,MATCH(Plano_V3!H45,Auxiliar!$C$16:$C$24,0),1) -> 1. Concluído | H45: =VLOOKUP(A45,'Aux - pivots1'!$A:$B,2,0) -> 1 | I45: =SUMIFS(Table1[Estimação (horas)],Table1[Tabela],Plano_V3!E45,Table1[Campo],Plano_V3!F45) -> 4.1 | J45: =I45/8 -> 0.5125 | K45: =SUMIFS(Table1[Horas efetivas],Table1[Tabela],Plano_V3!E45,Table1[Campo],Plano_V3!F45) -> 4.1 | L45: =K45/8 -> 0.5125 | N45: =L45/J45 -> 1 | O45: =N45-M45 -> 1 | P45: cd_imv_out_trz_cred_prc | Q45: =J45-SUM(R45:ES45) -> 0.5125
A46: =E46&F46 -> PROCESScod_estd_prcs | B46: Pilar III | C46: Bens Imóveis - Output | D46: 2. Campo | E46: PROCESS | F46: cod_estd_prcs | G46: =INDEX(Auxiliar!$B$16:$B$24,MATCH(Plano_V3!H46,Auxiliar!$C$16:$C$24,0),1) -> 0. Cancelado | H46: =VLOOKUP(A46,'Aux - pivots1'!$A:$B,2,0) -> 0 | I46: 0 | J46: =I46/8 -> 0 | K46: =SUMIFS(Table1[Horas efetivas],Table1[Tabela],Plano_V3!E46,Table1[Campo],Plano_V3!F46) -> 0 | L46: =K46/8 -> 0 | N46: =L46/J46 -> #DIV/0! | O46: =N46-M46 -> #DIV/0! | P46: cd_imv_out_trz_cred_prc | Q46: =J46-SUM(R46:ES46) -> 0
A47: =E47&F47 -> PROCESSGUARANTEE_CODE | B47: Pilar III | C47: Bens Imóveis - Output | D47: 2. Campo | E47: PROCESS | F47: GUARANTEE_CODE | G47: =INDEX(Auxiliar!$B$16:$B$24,MATCH(Plano_V3!H47,Auxiliar!$C$16:$C$24,0),1) -> 1. Concluído | H47: =VLOOKUP(A47,'Aux - pivots1'!$A:$B,2,0) -> 1 | I47: =SUMIFS(Table1[Estimação (horas)],Table1[Tabela],Plano_V3!E47,Table1[Campo],Plano_V3!F47) -> 4.1 | J47: =I47/8 -> 0.5125 | K47: =SUMIFS(Table1[Horas efetivas],Table1[Tabela],Plano_V3!E47,Table1[Campo],Plano_V3!F47) -> 4.1 | L47: =K47/8 -> 0.5125 | N47: =L47/J47 -> 1 | O47: =N47-M47 -> 1 | P47: cd_imv_out_trz_cred_prc | Q47: =J47-SUM(R47:ES47) -> 0.5125
A48: =E48&F48 -> PROCESSCURRENCY_CODE | B48: Pilar III | C48: Bens Imóveis - Output | D48: 2. Campo | E48: PROCESS | F48: CURRENCY_CODE | G48: =INDEX(Auxiliar!$B$16:$B$24,MATCH(Plano_V3!H48,Auxiliar!$C$16:$C$24,0),1) -> 1. Concluído | H48: =VLOOKUP(A48,'Aux - pivots1'!$A:$B,2,0) -> 1 | I48: =SUMIFS(Table1[Estimação (horas)],Table1[Tabela],Plano_V3!E48,Table1[Campo],Plano_V3!F48) -> 4.1 | J48: =I48/8 -> 0.5125 | K48: =SUMIFS(Table1[Horas efetivas],Table1[Tabela],Plano_V3!E48,Table1[Campo],Plano_V3!F48) -> 4.1 | L48: =K48/8 -> 0.5125 | N48: =L48/J48 -> 1 | O48: =N48-M48 -> 1 | P48: cd_imv_out_trz_cred_prc | Q48: =J48-SUM(R48:ES48) -> 0.5125
...

Sheet Plano_V1
B6: Re-testes - input | D6: 0.2 | M6: =M7-M10 -> 0 | N6: =N7-N10 -> 0 | O6: =O7-O10 -> 0 | P6: =P7-P10 -> 0 | Q6: =Q7-Q10 -> 0 | R6: =R7-R10 -> 0 | S6: =S7-S10 -> 0 | T6: =T7-T10 -> 0 | ... FK6: =FK7-FK10 -> 0
B7: Re-testes - output | D7: =50%*25% -> 0.125 | L7: =AVERAGE(M7:EL7) -> 2.4923077 | M7: 3 | N7: 3 | O7: 3 | P7: 3 | Q7: 3 | R7: 2 | S7: 2 | T7: 2 | U7: 2 | V7: 2 | W7: 2 | X7: 2 | Y7: 2 | Z7: 2 | AA7: 2 | AB7: 2 | AC7: 2 | AD7: 1 | AE7: 1 | AF7: 1 | AG7: 3 | AH7: 3 | AI7: 3 | AJ7: 3 | AK7: 2 | AL7: 3 | AM7: 3 | AN7: 3 | AO7: 3 | AP7: 3 | AQ7: 2 | AR7: 2 | AS7: 2 | AT7: 0 | AU7: 1 | AV7: 1 | AW7: 0 | AX7: 1 | AY7: 1 | AZ7: 1 | BA7: 2 | BB7: 2 | BC7: 2 | BD7: 2 | BE7: 2 | BF7: 2 | BG7: 2 | BH7: 2 | BI7: 2 | BJ7: 2 | BK7: 2 | BL7: 2 | BM7: 2 | BN7: 2 | BO7: 2 | BP7: 3 | BQ7: 3 | BR7: 3 | BS7: 3 | BT7: 3 | BU7: 3 | BV7: 3 | BW7: 3 | BX7: 3 | BY7: 3 | BZ7: 3 | CA7: 3 | CB7: 3 | CC7: 3 | CD7: 3 | CE7: 3 | CF7: 3 | CG7: 3 | CH7: 3 | CI7: 3 | CJ7: 3 | CK7: 3 | CL7: 3 | CM7: 3 | CN7: 3 | CO7: 3 | CP7: 3 | CQ7: 3 | CR7: 3 | CS7: 3 | CT7: 3 | CU7: 3 | CV7: 3 | CW7: 3 | CX7: 3 | CY7: 3 | CZ7: 3 | DA7: 3 | DB7: 3 | DC7: 3 | DD7: 3 | DE7: 3 | DF7: 3 | DG7: 3 | DH7: 3 | DI7: 3 | DJ7: 3 | DK7: 3 | DL7: 3 | DM7: 3 | DN7: 2 | DO7: 3 | DP7: 3 | DQ7: 3 | DR7: 3 | DS7: 3 | DT7: 3 | DU7: 3 | DV7: 3 | DW7: 3 | DX7: 3 | DY7: 3 | DZ7: 3 | EA7: 3 | EB7: 3 | EC7: 3 | ED7: 3 | EE7: 3 | EF7: 3 | EG7: 3 | EH7: 3 | EI7: 0 | EJ7: 0 | EK7: 0 | EL7: 0 | EM7: 0 | EN7: 0 | EO7: 0 | EP7: 3 | EQ7: 3 | ER7: 3 | ES7: 3 | ET7: 3 | EU7: 3 | EV7: 3 | EW7: 3 | EX7: 3 | EY7: 3 | EZ7: 3 | FA7: 3 | FB7: 3 | FC7: 3 | FD7: 3 | FE7: 3 | FF7: 3 | FG7: 3 | FH7: 3 | FI7: 3 | FJ7: 3 | FK7: 3
M10: =SUBTOTAL(9,M14:M636) -> 3 | N10: =SUBTOTAL(9,N14:N636) -> 3 | O10: =SUBTOTAL(9,O14:O636) -> 3 | P10: =SUBTOTAL(9,P14:P636) -> 3 | Q10: =SUBTOTAL(9,Q14:Q636) -> 3 | R10: =SUBTOTAL(9,R14:R636) -> 2 | S10: =SUBTOTAL(9,S14:S636) -> 2 | T10: =SUBTOTAL(9,T14:T636) -> 2 | ... FK10: =SUBTOTAL(9,FK14:FK636) -> 3
M11: Julho | W11: Julho | AJ11: Agosto | BF11: Setembro | CA11: Outubro | CX11: Novembro | DS11: Dezembro | EO11: Janeiro
M12: =M13 -> 45474 | N12: =N13 -> 45475 | O12: =O13 -> 45476 | P12: =P13 -> 45477 | Q12: =Q13 -> 45478 | R12: =R13 -> 45481 | S12: =S13 -> 45482 | T12: =T13 -> 45483 | ... FK12: =FK13 -> 45688
B13: Âmbito | C13: Sub-âmbito | D13: Tipo de teste | E13: Tabela | F13: Campo | G13: Status | H13: Status2 | I13: Horas | J13: Dias | K13: Pendências | L13: Val | M13: 45474 | N13: =WORKDAY(M13,1) -> 45475 | O13: =WORKDAY(N13,1) -> 45476 | P13: =WORKDAY(O13,1) -> 45477 | Q13: =WORKDAY(P13,1) -> 45478 | R13: =WORKDAY(Q13,1) -> 45481 | S13: =WORKDAY(R13,1) -> 45482 | T13: =WORKDAY(S13,1) -> 45483 | U13: =WORKDAY(T13,1) -> 45484 | ... FK13: =WORKDAY(FJ13,1) -> 45688
B14: 1. Assessment | I14: =SUM(I15:I18) -> 280 | J14: =SUM(J15:J18) -> 35
B15: Pilar III | C15: Bens Imóveis | G15: 7. Por iniciar | I15: =J15*8 -> 40 | J15: 5 | L15: =J15-SUM(M15:FK15) -> 0 | W15: 1 | X15: 1 | Y15: 1 | Z15: 1 | AA15: 1
B16: Pilar III | C16: Modelo Verde | G16: 7. Por iniciar | I16: =J16*8 -> 80 | J16: 10 | L16: =J16-SUM(M16:FK16) -> 0 | R16: 2 | S16: 2 | T16: 2 | U16: 2 | V16: 2
B17: Pilar III | C17: Pilar III | G17: 7. Por iniciar | I17: =J17*8 -> 40 | J17: 5 | L17: =J17-SUM(M17:FK17) -> 0 | AB17: 1 | AC17: 1 | AD17: 1 | AE17: 1 | AF17: 0.5 | AG17: 0.5
B18: GD | C18: GD | G18: 7. Por iniciar | I18: =J18*8 -> 120 | J18: 15 | L18: =J18-SUM(M18:FK18) -> 0 | M18: 3 | N18: 3 | O18: 3 | P18: 3 | Q18: 3
B20: 2. Re-especificação | I20: =SUM(I21:I23) -> 120 | J20: =SUM(J21:J23) -> 15
B21: Pilar III | C21: Bens Imóveis | G21: 7. Por iniciar | I21: =J21*8 -> 40 | J21: 5 | L21: =J21-SUM(M21:FK21) -> 0 | W21: 0.5 | AB21: 0.5 | AG21: 0.5 | AL21: 0.5 | AQ21: 0.5 | AV21: 0.5 | BA21: 0.5 | BF21: 0.5 | BK21: 0.5 | BP21: 0.5
B22: Pilar III | C22: Modelo Verde | G22: 7. Por iniciar | I22: =J22*8 -> 40 | J22: 5 | L22: =J22-SUM(M22:FK22) -> 0 | W22: 0.5 | AB22: 0.5 | AG22: 0.5 | AL22: 0.5 | AQ22: 0.5 | AV22: 0.5 | BA22: 0.5 | BF22: 0.5 | BK22: 0.5 | BP22: 0.5
B23: Pilar III | C23: Pilar III | G23: 7. Por iniciar | I23: =J23*8 -> 40 | J23: 5 | L23: =J23-SUM(M23:FK23) -> 0 | BF23: 0.5 | BK23: 0.5 | BP23: 0.5 | BU23: 0.5 | BZ23: 0.5 | CE23: 0.5 | CJ23: 0.5 | CO23: 0.5 | CT23: 0.5 | CY23: 0.5
B25: 3. Testes / Re-testes | I25: =I26+I27+I42+I198+I362+I447 -> 1396.7625 | J25: =J26+J27+J42+J198+J362+J447 -> 176
B26: Testes Regressivos | G26: 7. Por iniciar | I26: =4*22 -> 88 | J26: =I26/8 -> 11 | L26: =J26-SUM(M26:FK26) -> 0 | AA26: 0.5 | AF26: 0.5 | AK26: 0.5 | AP26: 0.5 | AU26: 0.5 | AZ26: 0.5 | BE26: 0.5 | BJ26: 0.5 | BO26: 0.5 | BT26: 0.5 | BY26: 0.5 | CD26: 0.5 | CI26: 0.5 | CN26: 0.5 | CS26: 0.5 | CX26: 0.5 | DC26: 0.5 | DH26: 0.5 | DM26: 0.5 | DR26: 0.5 | DW26: 0.5 | EB26: 0.5
B27: Pilar III | C27: Bens Imóveis - Input | I27: =SUM(I28:I41) -> 0 | J27: =ROUNDUP(I27/8,0) -> 0 | L27: =J27-SUM(M27:FK27) -> -3 | X27: 0.5 | Y27: 0.5 | AC27: 0.5 | AG27: 1 | AH27: 0.5
A28: =E28&F28 -> cd_imv_inp_certif_estimativan.a. | B28: Pilar III | C28: Bens Imóveis - Input | D28: 1. Universo | E28: cd_imv_inp_certif_estimativa | F28: n.a. | G28: =INDEX(Auxiliar!$B$16:$B$24,MATCH(Plano_V1!H28,Auxiliar!$C$16:$C$24,0),1) -> #N/A | H28: =VLOOKUP(A28,'Aux - pivots1'!$A:$B,2,0) -> #N/A | I28: =SUMIFS(Table1[Estimação (horas)],Table1[Tabela],Plano_V1!E28,Table1[Campo],Plano_V1!F28) -> 0 | J28: =I28/8 -> 0 | K28: sem pendencia | L28: =J28-SUM(M28:FK28) -> 0
A29: =E29&F29 -> cd_imv_inp_certif_estimativacempbem | B29: Pilar III | C29: Bens Imóveis - Input | D29: 2. Campo | E29: cd_imv_inp_certif_estimativa | F29: cempbem | G29: =INDEX(Auxiliar!$B$16:$B$24,MATCH(Plano_V1!H29,Auxiliar!$C$16:$C$24,0),1) -> #N/A | H29: =VLOOKUP(A29,'Aux - pivots1'!$A:$B,2,0) -> #N/A | I29: =SUMIFS(Table1[Estimação (horas)],Table1[Tabela],Plano_V1!E29,Table1[Campo],Plano_V1!F29) -> 0 | J29: =I29/8 -> 0 | K29: sem pendencia | L29: =J29-SUM(M29:FK29) -> 0
A30: =E30&F30 -> cd_imv_inp_certif_estimativachave_encriptada | B30: Pilar III | C30: Bens Imóveis - Input | D30: 2. Campo | E30: cd_imv_inp_certif_estimativa | F30: chave_encriptada | G30: =INDEX(Auxiliar!$B$16:$B$24,MATCH(Plano_V1!H30,Auxiliar!$C$16:$C$24,0),1) -> #N/A | H30: =VLOOKUP(A30,'Aux - pivots1'!$A:$B,2,0) -> #N/A | I30: =SUMIFS(Table1[Estimação (horas)],Table1[Tabela],Plano_V1!E30,Table1[Campo],Plano_V1!F30) -> 0 | J30: =I30/8 -> 0 | K30: sem pendencia | L30: =J30-SUM(M30:FK30) -> 0
A31: =E31&F31 -> cd_imv_inp_certif_estimativackbalbem | B31: Pilar III | C31: Bens Imóveis - Input | D31: 2. Campo | E31: cd_imv_inp_certif_estimativa | F31: ckbalbem | G31: =INDEX(Auxiliar!$B$16:$B$24,MATCH(Plano_V1!H31,Auxiliar!$C$16:$C$24,0),1) -> #N/A | H31: =VLOOKUP(A31,'Aux - pivots1'!$A:$B,2,0) -> #N/A | I31: =SUMIFS(Table1[Estimação (horas)],Table1[Tabela],Plano_V1!E31,Table1[Campo],Plano_V1!F31) -> 0 | J31: =I31/8 -> 0 | K31: sem pendencia | L31: =J31-SUM(M31:FK31) -> 0
A32: =E32&F32 -> cd_imv_inp_certif_estimativackctabem | B32: Pilar III | C32: Bens Imóveis - Input | D32: 2. Campo | E32: cd_imv_inp_certif_estimativa | F32: ckctabem | G32: =INDEX(Auxiliar!$B$16:$B$24,MATCH(Plano_V1!H32,Auxiliar!$C$16:$C$24,0),1) -> #N/A | H32: =VLOOKUP(A32,'Aux - pivots1'!$A:$B,2,0) -> #N/A | I32: =SUMIFS(Table1[Estimação (horas)],Table1[Tabela],Plano_V1!E32,Table1[Campo],Plano_V1!F32) -> 0 | J32: =I32/8 -> 0 | K32: sem pendencia | L32: =J32-SUM(M32:FK32) -> 0
A33: =E33&F33 -> cd_imv_inp_certif_estimativackrefbem | B33: Pilar III | C33: Bens Imóveis - Input | D33: 2. Campo | E33: cd_imv_inp_certif_estimativa | F33: ckrefbem | G33: =INDEX(Auxiliar!$B$16:$B$24,MATCH(Plano_V1!H33,Auxiliar!$C$16:$C$24,0),1) -> #N/A | H33: =VLOOKUP(A33,'Aux - pivots1'!$A:$B,2,0) -> #N/A | I33: =SUMIFS(Table1[Estimação (horas)],Table1[Tabela],Plano_V1!E33,Table1[Campo],Plano_V1!F33) -> 0 | J33: =I33/8 -> 0 | K33: sem pendencia | L33: =J33-SUM(M33:FK33) -> 0
A34: =E34&F34 -> cd_imv_inp_certif_estimativadata_extraccao_info | B34: Pilar III | C34: Bens Imóveis - Input | D34: 2. Campo | E34: cd_imv_inp_certif_estimativa | F34: data_extraccao_info | G34: =INDEX(Auxiliar!$B$16:$B$24,MATCH(Plano_V1!H34,Auxiliar!$C$16:$C$24,0),1) -> #N/A | H34: =VLOOKUP(A34,'Aux - pivots1'!$A:$B,2,0) -> #N/A | I34: =SUMIFS(Table1[Estimação (horas)],Table1[Tabela],Plano_V1!E34,Table1[Campo],Plano_V1!F34) -> 0 | J34: =I34/8 -> 0 | K34: sem pendencia | L34: =J34-SUM(M34:FK34) -> 0
A35: =E35&F35 -> cd_imv_inp_certif_estimativaepc | B35: Pilar III | C35: Bens Imóveis - Input | D35: 2. Campo | E35: cd_imv_inp_certif_estimativa | F35: epc | G35: =INDEX(Auxiliar!$B$16:$B$24,MATCH(Plano_V1!H35,Auxiliar!$C$16:$C$24,0),1) -> #N/A | H35: =VLOOKUP(A35,'Aux - pivots1'!$A:$B,2,0) -> #N/A | I35: =SUMIFS(Table1[Estimação (horas)],Table1[Tabela],Plano_V1!E35,Table1[Campo],Plano_V1!F35) -> 0 | J35: =I35/8 -> 0 | K35: sem pendencia | L35: =J35-SUM(M35:FK35) -> 0
A36: =E36&F36 -> cd_imv_inp_certif_estimativafornecedor | B36: Pilar III | C36: Bens Imóveis - Input | D36: 2. Campo | E36: cd_imv_inp_certif_estimativa | F36: fornecedor | G36: =INDEX(Auxiliar!$B$16:$B$24,MATCH(Plano_V1!H36,Auxiliar!$C$16:$C$24,0),1) -> #N/A | H36: =VLOOKUP(A36,'Aux - pivots1'!$A:$B,2,0) -> #N/A | I36: =SUMIFS(Table1[Estimação (horas)],Table1[Tabela],Plano_V1!E36,Table1[Campo],Plano_V1!F36) -> 0 | J36: =I36/8 -> 0 | K36: sem pendencia | L36: =J36-SUM(M36:FK36) -> 0
A37: =E37&F37 -> cd_imv_inp_certif_estimativametodo_info | B37: Pilar III | C37: Bens Imóveis - Input | D37: 2. Campo | E37: cd_imv_inp_certif_estimativa | F37: metodo_info | G37: =INDEX(Auxiliar!$B$16:$B$24,MATCH(Plano_V1!H37,Auxiliar!$C$16:$C$24,0),1) -> #N/A | H37: =VLOOKUP(A37,'Aux - pivots1'!$A:$B,2,0) -> #N/A | I37: =SUMIFS(Table1[Estimação (horas)],Table1[Tabela],Plano_V1!E37,Table1[Campo],Plano_V1!F37) -> 0 | J37: =I37/8 -> 0 | K37: sem pendencia | L37: =J37-SUM(M37:FK37) -> 0
A38: =E38&F38 -> cd_imv_inp_certif_estimativascore_qualidade | B38: Pilar III | C38: Bens Imóveis - Input | D38: 2. Campo | E38: cd_imv_inp_certif_estimativa | F38: score_qualidade | G38: =INDEX(Auxiliar!$B$16:$B$24,MATCH(Plano_V1!H38,Auxiliar!$C$16:$C$24,0),1) -> #N/A | H38: =VLOOKUP(A38,'Aux - pivots1'!$A:$B,2,0) -> #N/A | I38: =SUMIFS(Table1[Estimação (horas)],Table1[Tabela],Plano_V1!E38,Table1[Campo],Plano_V1!F38) -> 0 | J38: =I38/8 -> 0 | K38: sem pendencia | L38: =J38-SUM(M38:FK38) -> 0
A39: =E39&F39 -> cd_imv_inp_certif_estimativavlr_cnsm_ano | B39: Pilar III | C39: Bens Imóveis - Input | D39: 2. Campo | E39: cd_imv_inp_certif_estimativa | F39: vlr_cnsm_ano | G39: =INDEX(Auxiliar!$B$16:$B$24,MATCH(Plano_V1!H39,Auxiliar!$C$16:$C$24,0),1) -> #N/A | H39: =VLOOKUP(A39,'Aux - pivots1'!$A:$B,2,0) -> #N/A | I39: =SUMIFS(Table1[Estimação (horas)],Table1[Tabela],Plano_V1!E39,Table1[Campo],Plano_V1!F39) -> 0 | J39: =I39/8 -> 0 | K39: sem pendencia | L39: =J39-SUM(M39:FK39) -> 0
A40: =E40&F40 -> cd_imv_inp_certif_estimativavlr_emss_ano | B40: Pilar III | C40: Bens Imóveis - Input | D40: 2. Campo | E40: cd_imv_inp_certif_estimativa | F40: vlr_emss_ano | G40: =INDEX(Auxiliar!$B$16:$B$24,MATCH(Plano_V1!H40,Auxiliar!$C$16:$C$24,0),1) -> #N/A | H40: =VLOOKUP(A40,'Aux - pivots1'!$A:$B,2,0) -> #N/A | I40: =SUMIFS(Table1[Estimação (horas)],Table1[Tabela],Plano_V1!E40,Table1[Campo],Plano_V1!F40) -> 0 | J40: =I40/8 -> 0 | K40: sem pendencia | L40: =J40-SUM(M40:FK40) -> 0
A41: =E41&F41 -> Re-testesn.a. | B41: Pilar III | C41: Bens Imóveis - Input | D41: 2. Campo | E41: Re-testes | F41: n.a. | G41: 7. Por iniciar | I41: =SUM(I28:I40)*D6 -> 0 | J41: =I41/8 -> 0 | K41: sem pendencia | L41: =J41-SUM(M41:FK41) -> 0
A42: =E42&F42 | B42: Pilar III | C42: Bens Imóveis - Output | I42: =SUM(I43:I197) -> 0 | J42: =ROUNDUP(I42/8,0) -> 0 | L42: =J42-SUM(M42:FK42) -> -100 | AH42: 0.5 | AI42: 1 | AJ42: 1 | AM42: 1 | AN42: 1 | AO42: 1 | AP42: 0.5 | AR42: 1 | AS42: 2 | AU42: 0.5 | AX42: 1 | AY42: 1 | AZ42: 0.5 | BA42: 1 | BB42: 2 | BC42: 2 | BD42: 2 | BE42: 1.5 | BF42: 0.5 | BG42: 2 | BH42: 2 | BI42: 2 | BJ42: 1.5 | BK42: 0.5 | BL42: 2 | BM42: 2 | BN42: 2 | BO42: 1.5 | BP42: 1.5 | BQ42: 2 | BR42: 2 | BS42: 2 | BT42: 2 | BU42: 2 | BV42: 2 | BW42: 2 | BX42: 2 | BY42: 2 | BZ42: 2 | CA42: 2 | CB42: 2 | CC42: 2 | CD42: 2 | CE42: 2 | CF42: 2 | CG42: 2 | CH42: 2 | CI42: 2 | CJ42: 2 | CK42: 2 | CL42: 2 | CM42: 2 | CN42: 2 | CO42: 2 | CP42: 2 | CQ42: 2 | CR42: 2 | CS42: 2 | CT42: 2 | CU42: 2
A43: =E43&F43 -> cd_imv_out_prcn.a. | B43: Pilar III | C43: Bens Imóveis - Output | D43: 1. Universo | E43: cd_imv_out_prc | F43: n.a. | G43: =INDEX(Auxiliar!$B$16:$B$24,MATCH(Plano_V1!H43,Auxiliar!$C$16:$C$24,0),1) -> #N/A | H43: =VLOOKUP(A43,'Aux - pivots1'!$A:$B,2,0) -> #N/A | I43: =SUMIFS(Table1[Estimação (horas)],Table1[Tabela],Plano_V1!E43,Table1[Campo],Plano_V1!F43) -> 0 | J43: =I43/8 -> 0 | K43: cd_imv_out_trz_cred_prc | L43: =J43-SUM(M43:FK43) -> 0
A44: =E44&F44 -> cd_imv_out_prccempresa | B44: Pilar III | C44: Bens Imóveis - Output | D44: 2. Campo | E44: cd_imv_out_prc | F44: cempresa | G44: =INDEX(Auxiliar!$B$16:$B$24,MATCH(Plano_V1!H44,Auxiliar!$C$16:$C$24,0),1) -> #N/A | H44: =VLOOKUP(A44,'Aux - pivots1'!$A:$B,2,0) -> #N/A | I44: =SUMIFS(Table1[Estimação (horas)],Table1[Tabela],Plano_V1!E44,Table1[Campo],Plano_V1!F44) -> 0 | J44: =I44/8 -> 0 | K44: cd_imv_out_trz_cred_prc | L44: =J44-SUM(M44:FK44) -> 0
A45: =E45&F45 -> cd_imv_out_prcckbalcao | B45: Pilar III | C45: Bens Imóveis - Output | D45: 2. Campo | E45: cd_imv_out_prc | F45: ckbalcao | G45: =INDEX(Auxiliar!$B$16:$B$24,MATCH(Plano_V1!H45,Auxiliar!$C$16:$C$24,0),1) -> #N/A | H45: =VLOOKUP(A45,'Aux - pivots1'!$A:$B,2,0) -> #N/A | I45: =SUMIFS(Table1[Estimação (horas)],Table1[Tabela],Plano_V1!E45,Table1[Campo],Plano_V1!F45) -> 0 | J45: =I45/8 -> 0 | K45: cd_imv_out_trz_cred_prc | L45: =J45-SUM(M45:FK45) -> 0
A46: =E46&F46 -> cd_imv_out_prccknumcta | B46: Pilar III | C46: Bens Imóveis - Output | D46: 2. Campo | E46: cd_imv_out_prc | F46: cknumcta | G46: =INDEX(Auxiliar!$B$16:$B$24,MATCH(Plano_V1!H46,Auxiliar!$C$16:$C$24,0),1) -> #N/A | H46: =VLOOKUP(A46,'Aux - pivots1'!$A:$B,2,0) -> #N/A | I46: =SUMIFS(Table1[Estimação (horas)],Table1[Tabela],Plano_V1!E46,Table1[Campo],Plano_V1!F46) -> 0 | J46: =I46/8 -> 0 | K46: cd_imv_out_trz_cred_prc | L46: =J46-SUM(M46:FK46) -> 0
A47: =E47&F47 -> cd_imv_out_prccod_estd_prcs | B47: Pilar III | C47: Bens Imóveis - Output | D47: 2. Campo | E47: cd_imv_out_prc | F47: cod_estd_prcs | G47: =INDEX(Auxiliar!$B$16:$B$24,MATCH(Plano_V1!H47,Auxiliar!$C$16:$C$24,0),1) -> #N/A | H47: =VLOOKUP(A47,'Aux - pivots1'!$A:$B,2,0) -> #N/A | I47: 0 | J47: =I47/8 -> 0 | K47: cd_imv_out_trz_cred_prc | L47: =J47-SUM(M47:FK47) -> 0
A48: =E48&F48 -> cd_imv_out_prccod_grt | B48: Pilar III | C48: Bens Imóveis - Output | D48: 2. Campo | E48: cd_imv_out_prc | F48: cod_grt | G48: =INDEX(Auxiliar!$B$16:$B$24,MATCH(Plano_V1!H48,Auxiliar!$C$16:$C$24,0),1) -> #N/A | H48: =VLOOKUP(A48,'Aux - pivots1'!$A:$B,2,0) -> #N/A | I48: =SUMIFS(Table1[Estimação (horas)],Table1[Tabela],Plano_V1!E48,Table1[Campo],Plano_V1!F48) -> 0 | J48: =I48/8 -> 0 | K48: cd_imv_out_trz_cred_prc | L48: =J48-SUM(M48:FK48) -> 0
A49: =E49&F49 -> cd_imv_out_prccod_moeda | B49: Pilar III | C49: Bens Imóveis - Output | D49: 2. Campo | E49: cd_imv_out_prc | F49: cod_moeda | G49: =INDEX(Auxiliar!$B$16:$B$24,MATCH(Plano_V1!H49,Auxiliar!$C$16:$C$24,0),1) -> #N/A | H49: =VLOOKUP(A49,'Aux - pivots1'!$A:$B,2,0) -> #N/A | I49: =SUMIFS(Table1[Estimação (horas)],Table1[Tabela],Plano_V1!E49,Table1[Campo],Plano_V1!F49) -> 0 | J49: =I49/8 -> 0 | K49: cd_imv_out_trz_cred_prc | L49: =J49-SUM(M49:FK49) -> 0
...

Sheet 1. Status Resumo
B6: Sumário Executivo |04 de outubro a 11 de outubro
B8: 1. Entrega das datas de disponibilização das tabelas em implementação por parte da Equipa de Tecnologia. 2. Reunião com a equipa de Tecnologia para alinhamento de prioridades de implementação. 3. Estamos a terminar o assessment do Pilar III.
B22: 1. Modelo de Bens Imóveis | G22: Bens Imóveis - Input | H22: Bens Imóveis - Output
C25: Resumo | G25: Detalhe por Tabela | P25: Status (campos) | T25: 45569 | U25: =T25+7 -> 45576 | V25: ∆ | X25: Highlights
P26: 0. Cancelado | T26: =COUNTIFS('2. Status Detalhe Campos'!$H$7:$H$615,'1. Status Resumo'!$P26,'2. Status Detalhe Campos'!$C$7:$C$615,'1. Status Resumo'!$G$22,'2. Status Detalhe Campos'!$D$7:$D$615,"2. Campo")+COUNTIFS('2. Status Detalhe Campos'!$H$7:$H$615,'1. Status Resumo'!$P26,'2. Status Detalhe Campos'!$C$7:$C$615,'1. Status Resumo'!$H$22,'2. Status Detalhe Campos'!$D$7:$D$615,"2. Campo") -> 10 | U26: =COUNTIFS('2. Status Detalhe Campos'!$G$7:$G$615,'1. Status Resumo'!$P26,'2. Status Detalhe Campos'!$C$7:$C$615,'1. Status Resumo'!$G$22,'2. Status Detalhe Campos'!$D$7:$D$615,"2. Campo")+COUNTIFS('2. Status Detalhe Campos'!$G$7:$G$615,'1. Status Resumo'!$P26,'2. Status Detalhe Campos'!$C$7:$C$615,'1. Status Resumo'!$H$22,'2. Status Detalhe Campos'!$D$7:$D$615,"2. Campo") -> 10 | V26: =U26-T26 -> 0 | X26: 1. Fecho da simulação da Tabela de Certificados 2. Apoio à equipa de Tecnologia nas dúvidas que surjam relativamente às re-especificação das tabelas que se encontram do lado do IT em implementação. Podem surgir ainda pequenas alterações face à nova informação de Gestão de Empreendimentos. 3. Atualmente encontram-se 4 tabelas concluídas, ficando apenas 34 campos em implementação do lado do IT 4. Datas de entrega de Tecnologia: - Entrada em produção (das 4 tabelas certificadas): 17/10/2024 - Disponibilização do carrgamento de input da Gloval (via front de Upload de Ficheiros): 24/10/2024 - Disponibilização da tabela de output de Certificados Energéticos (com as 4 fontes de informação): 11/11/2024 - Disponibilização de funcionalidades de Pedido de informação para a Gloval: 28/11/2024
P27: 1. Concluído | T27: =COUNTIFS('2. Status Detalhe Campos'!$H$7:$H$615,'1. Status Resumo'!$P27,'2. Status Detalhe Campos'!$C$7:$C$615,'1. Status Resumo'!$G$22,'2. Status Detalhe Campos'!$D$7:$D$615,"2. Campo")+COUNTIFS('2. Status Detalhe Campos'!$H$7:$H$615,'1. Status Resumo'!$P27,'2. Status Detalhe Campos'!$C$7:$C$615,'1. Status Resumo'!$H$22,'2. Status Detalhe Campos'!$D$7:$D$615,"2. Campo") -> 124 | U27: =COUNTIFS('2. Status Detalhe Campos'!$G$7:$G$615,'1. Status Resumo'!$P27,'2. Status Detalhe Campos'!$C$7:$C$615,'1. Status Resumo'!$G$22,'2. Status Detalhe Campos'!$D$7:$D$615,"2. Campo")+COUNTIFS('2. Status Detalhe Campos'!$G$7:$G$615,'1. Status Resumo'!$P27,'2. Status Detalhe Campos'!$C$7:$C$615,'1. Status Resumo'!$H$22,'2. Status Detalhe Campos'!$D$7:$D$615,"2. Campo") -> 124 | V27: =U27-T27 -> 0
P28: 2.1 Em Teste | T28: =COUNTIFS('2. Status Detalhe Campos'!$H$7:$H$615,'1. Status Resumo'!$P28,'2. Status Detalhe Campos'!$C$7:$C$615,'1. Status Resumo'!$G$22,'2. Status Detalhe Campos'!$D$7:$D$615,"2. Campo")+COUNTIFS('2. Status Detalhe Campos'!$H$7:$H$615,'1. Status Resumo'!$P28,'2. Status Detalhe Campos'!$C$7:$C$615,'1. Status Resumo'!$H$22,'2. Status Detalhe Campos'!$D$7:$D$615,"2. Campo") -> 0 | U28: =COUNTIFS('2. Status Detalhe Campos'!$G$7:$G$615,'1. Status Resumo'!$P28,'2. Status Detalhe Campos'!$C$7:$C$615,'1. Status Resumo'!$G$22,'2. Status Detalhe Campos'!$D$7:$D$615,"2. Campo")+COUNTIFS('2. Status Detalhe Campos'!$G$7:$G$615,'1. Status Resumo'!$P28,'2. Status Detalhe Campos'!$C$7:$C$615,'1. Status Resumo'!$H$22,'2. Status Detalhe Campos'!$D$7:$D$615,"2. Campo") -> 0 | V28: =U28-T28 -> 0
D29: ="# "&U35 -> # 168 | P29: 2.2 Em Re-especificação | T29: =COUNTIFS('2. Status Detalhe Campos'!$H$7:$H$615,'1. Status Resumo'!$P29,'2. Status Detalhe Campos'!$C$7:$C$615,'1. Status Resumo'!$G$22,'2. Status Detalhe Campos'!$D$7:$D$615,"2. Campo")+COUNTIFS('2. Status Detalhe Campos'!$H$7:$H$615,'1. Status Resumo'!$P29,'2. Status Detalhe Campos'!$C$7:$C$615,'1. Status Resumo'!$H$22,'2. Status Detalhe Campos'!$D$7:$D$615,"2. Campo") -> 0 | U29: =COUNTIFS('2. Status Detalhe Campos'!$G$7:$G$615,'1. Status Resumo'!$P29,'2. Status Detalhe Campos'!$C$7:$C$615,'1. Status Resumo'!$G$22,'2. Status Detalhe Campos'!$D$7:$D$615,"2. Campo")+COUNTIFS('2. Status Detalhe Campos'!$G$7:$G$615,'1. Status Resumo'!$P29,'2. Status Detalhe Campos'!$C$7:$C$615,'1. Status Resumo'!$H$22,'2. Status Detalhe Campos'!$D$7:$D$615,"2. Campo") -> 0 | V29: =U29-T29 -> 0
P30: 3. Pendente de outros desenvolvimentos | T30: =COUNTIFS('2. Status Detalhe Campos'!$H$7:$H$615,'1. Status Resumo'!$P30,'2. Status Detalhe Campos'!$C$7:$C$615,'1. Status Resumo'!$G$22,'2. Status Detalhe Campos'!$D$7:$D$615,"2. Campo")+COUNTIFS('2. Status Detalhe Campos'!$H$7:$H$615,'1. Status Resumo'!$P30,'2. Status Detalhe Campos'!$C$7:$C$615,'1. Status Resumo'!$H$22,'2. Status Detalhe Campos'!$D$7:$D$615,"2. Campo") -> 0 | U30: =COUNTIFS('2. Status Detalhe Campos'!$G$7:$G$615,'1. Status Resumo'!$P30,'2. Status Detalhe Campos'!$C$7:$C$615,'1. Status Resumo'!$G$22,'2. Status Detalhe Campos'!$D$7:$D$615,"2. Campo")+COUNTIFS('2. Status Detalhe Campos'!$G$7:$G$615,'1. Status Resumo'!$P30,'2. Status Detalhe Campos'!$C$7:$C$615,'1. Status Resumo'!$H$22,'2. Status Detalhe Campos'!$D$7:$D$615,"2. Campo") -> 0 | V30: =U30-T30 -> 0
P31: 4. Validação EF | T31: =COUNTIFS('2. Status Detalhe Campos'!$H$7:$H$615,'1. Status Resumo'!$P31,'2. Status Detalhe Campos'!$C$7:$C$615,'1. Status Resumo'!$G$22,'2. Status Detalhe Campos'!$D$7:$D$615,"2. Campo")+COUNTIFS('2. Status Detalhe Campos'!$H$7:$H$615,'1. Status Resumo'!$P31,'2. Status Detalhe Campos'!$C$7:$C$615,'1. Status Resumo'!$H$22,'2. Status Detalhe Campos'!$D$7:$D$615,"2. Campo") -> 0 | U31: =COUNTIFS('2. Status Detalhe Campos'!$G$7:$G$615,'1. Status Resumo'!$P31,'2. Status Detalhe Campos'!$C$7:$C$615,'1. Status Resumo'!$G$22,'2. Status Detalhe Campos'!$D$7:$D$615,"2. Campo")+COUNTIFS('2. Status Detalhe Campos'!$G$7:$G$615,'1. Status Resumo'!$P31,'2. Status Detalhe Campos'!$C$7:$C$615,'1. Status Resumo'!$H$22,'2. Status Detalhe Campos'!$D$7:$D$615,"2. Campo") -> 0 | V31: =U31-T31 -> 0
P32: 5. Em Correção | R32: (incidências) | T32: =COUNTIFS('2. Status Detalhe Campos'!$H$7:$H$615,'1. Status Resumo'!$P32,'2. Status Detalhe Campos'!$C$7:$C$615,'1. Status Resumo'!$G$22,'2. Status Detalhe Campos'!$D$7:$D$615,"2. Campo")+COUNTIFS('2. Status Detalhe Campos'!$H$7:$H$615,'1. Status Resumo'!$P32,'2. Status Detalhe Campos'!$C$7:$C$615,'1. Status Resumo'!$H$22,'2. Status Detalhe Campos'!$D$7:$D$615,"2. Campo") -> 0 | U32: =COUNTIFS('2. Status Detalhe Campos'!$G$7:$G$615,'1. Status Resumo'!$P32,'2. Status Detalhe Campos'!$C$7:$C$615,'1. Status Resumo'!$G$22,'2. Status Detalhe Campos'!$D$7:$D$615,"2. Campo")+COUNTIFS('2. Status Detalhe Campos'!$G$7:$G$615,'1. Status Resumo'!$P32,'2. Status Detalhe Campos'!$C$7:$C$615,'1. Status Resumo'!$H$22,'2. Status Detalhe Campos'!$D$7:$D$615,"2. Campo") -> 0 | V32: =U32-T32 -> 0
P33: 6. Em implementação (re-especificação) | T33: =COUNTIFS('2. Status Detalhe Campos'!$H$7:$H$615,'1. Status Resumo'!$P33,'2. Status Detalhe Campos'!$C$7:$C$615,'1. Status Resumo'!$G$22,'2. Status Detalhe Campos'!$D$7:$D$615,"2. Campo")+COUNTIFS('2. Status Detalhe Campos'!$H$7:$H$615,'1. Status Resumo'!$P33,'2. Status Detalhe Campos'!$C$7:$C$615,'1. Status Resumo'!$H$22,'2. Status Detalhe Campos'!$D$7:$D$615,"2. Campo") -> 34 | U33: =COUNTIFS('2. Status Detalhe Campos'!$G$7:$G$615,'1. Status Resumo'!$P33,'2. Status Detalhe Campos'!$C$7:$C$615,'1. Status Resumo'!$G$22,'2. Status Detalhe Campos'!$D$7:$D$615,"2. Campo")+COUNTIFS('2. Status Detalhe Campos'!$G$7:$G$615,'1. Status Resumo'!$P33,'2. Status Detalhe Campos'!$C$7:$C$615,'1. Status Resumo'!$H$22,'2. Status Detalhe Campos'!$D$7:$D$615,"2. Campo") -> 34 | V33: =U33-T33 -> 0
P34: 7. Por iniciar | T34: =COUNTIFS('2. Status Detalhe Campos'!$H$7:$H$615,'1. Status Resumo'!$P34,'2. Status Detalhe Campos'!$C$7:$C$615,'1. Status Resumo'!$G$22,'2. Status Detalhe Campos'!$D$7:$D$615,"2. Campo")+COUNTIFS('2. Status Detalhe Campos'!$H$7:$H$615,'1. Status Resumo'!$P34,'2. Status Detalhe Campos'!$C$7:$C$615,'1. Status Resumo'!$H$22,'2. Status Detalhe Campos'!$D$7:$D$615,"2. Campo") -> 0 | U34: =COUNTIFS('2. Status Detalhe Campos'!$G$7:$G$615,'1. Status Resumo'!$P34,'2. Status Detalhe Campos'!$C$7:$C$615,'1. Status Resumo'!$G$22,'2. Status Detalhe Campos'!$D$7:$D$615,"2. Campo")+COUNTIFS('2. Status Detalhe Campos'!$G$7:$G$615,'1. Status Resumo'!$P34,'2. Status Detalhe Campos'!$C$7:$C$615,'1. Status Resumo'!$H$22,'2. Status Detalhe Campos'!$D$7:$D$615,"2. Campo") -> 0 | V34: =U34-T34 -> 0
T35: =SUM(T26:T34) -> 168 | U35: =SUM(U26:U34) -> 168
G36: Status (Tabelas) | P36: Status (Universos)
F37: > | G37: Tabela de Bens Imóveis | L37: OK | O37: > | P37: Universo Bens Colateralizados (MUG) | T37: OK
F38: > | G38: Tabelas de Processos Imobiliários | L38: OK | O38: > | P38: Universo Bens Não Colateralizados (GP) | T38: OK
F39: > | G39: Tabela de Traçabilidade Processo -Bem | L39: OK | O39: > | P39: Universo Bens Adjudicados | T39: Não serão testados neste projeto
F40: > | G40: Tabela de Traçabilidade Crédito - Processo | L40: OK
F41: > | G41: Tabela input de Cerificados Energéticos (Gloval) | L41: Em Implementação
F42: > | G42: Tabela Output de Cerificados Energéticos | L42: Em Implementação
B48: 2. Modelo Verde | G48: Modelo Verde - Input | H48: Modelo Verde - Output
C51: Resumo | G51: Detalhe por Tabela | P51: Status (campos) | T51: =T25 -> 45569 | U51: =$U$25 -> 45576 | V51: ∆ | X51: Highlights
P52: 0. Cancelado | T52: =COUNTIFS('2. Status Detalhe Campos'!$H$7:$H$615,'1. Status Resumo'!$P52,'2. Status Detalhe Campos'!$C$7:$C$615,'1. Status Resumo'!$G$48,'2. Status Detalhe Campos'!$D$7:$D$615,"2. Campo")+COUNTIFS('2. Status Detalhe Campos'!$H$7:$H$615,'1. Status Resumo'!$P52,'2. Status Detalhe Campos'!$C$7:$C$615,'1. Status Resumo'!$H$48,'2. Status Detalhe Campos'!$D$7:$D$615,"2. Campo") -> 14 | U52: =COUNTIFS('2. Status Detalhe Campos'!$G$7:$G$615,'1. Status Resumo'!$P52,'2. Status Detalhe Campos'!$C$7:$C$615,'1. Status Resumo'!$G$48,'2. Status Detalhe Campos'!$D$7:$D$615,"2. Campo")+COUNTIFS('2. Status Detalhe Campos'!$G$7:$G$615,'1. Status Resumo'!$P52,'2. Status Detalhe Campos'!$C$7:$C$615,'1. Status Resumo'!$H$48,'2. Status Detalhe Campos'!$D$7:$D$615,"2. Campo") -> 14 | V52: =U52-T52 -> 0 | X52: 1. Fechado o único campo em teste (cod_nace_esg) da tabela de Input Risco Físico 2. Foi realizada uma sessão para alinhamento de prioridades com a equipa de tecnologia e reunião com o CdG para entrega da parametrização com os códigos das categorias atualizados. Estamos a terminar o mapeamento dos códigos das categorias e esperamos partilhar no início da próxima semana. 3. Apoio à equipa de Tecnologia nas dúvidas que surjam relativamente às re-especificação das tabelas que se encontram do lado do IT em implementação. 4. Restantes campos Em Implementação (re-especificão) ou em Em Correção.
P53: 1. Concluído | T53: =COUNTIFS('2. Status Detalhe Campos'!$H$7:$H$615,'1. Status Resumo'!$P53,'2. Status Detalhe Campos'!$C$7:$C$615,'1. Status Resumo'!$G$48,'2. Status Detalhe Campos'!$D$7:$D$615,"2. Campo")+COUNTIFS('2. Status Detalhe Campos'!$H$7:$H$615,'1. Status Resumo'!$P53,'2. Status Detalhe Campos'!$C$7:$C$615,'1. Status Resumo'!$H$48,'2. Status Detalhe Campos'!$D$7:$D$615,"2. Campo") -> 154 | U53: =COUNTIFS('2. Status Detalhe Campos'!$G$7:$G$615,'1. Status Resumo'!$P53,'2. Status Detalhe Campos'!$C$7:$C$615,'1. Status Resumo'!$G$48,'2. Status Detalhe Campos'!$D$7:$D$615,"2. Campo")+COUNTIFS('2. Status Detalhe Campos'!$G$7:$G$615,'1. Status Resumo'!$P53,'2. Status Detalhe Campos'!$C$7:$C$615,'1. Status Resumo'!$H$48,'2. Status Detalhe Campos'!$D$7:$D$615,"2. Campo") -> 154 | V53: =U53-T53 -> 0
P54: 2.1 Em Teste | T54: =COUNTIFS('2. Status Detalhe Campos'!$H$7:$H$615,'1. Status Resumo'!$P54,'2. Status Detalhe Campos'!$C$7:$C$615,'1. Status Resumo'!$G$48,'2. Status Detalhe Campos'!$D$7:$D$615,"2. Campo")+COUNTIFS('2. Status Detalhe Campos'!$H$7:$H$615,'1. Status Resumo'!$P54,'2. Status Detalhe Campos'!$C$7:$C$615,'1. Status Resumo'!$H$48,'2. Status Detalhe Campos'!$D$7:$D$615,"2. Campo") -> 0 | U54: =COUNTIFS('2. Status Detalhe Campos'!$G$7:$G$615,'1. Status Resumo'!$P54,'2. Status Detalhe Campos'!$C$7:$C$615,'1. Status Resumo'!$G$48,'2. Status Detalhe Campos'!$D$7:$D$615,"2. Campo")+COUNTIFS('2. Status Detalhe Campos'!$G$7:$G$615,'1. Status Resumo'!$P54,'2. Status Detalhe Campos'!$C$7:$C$615,'1. Status Resumo'!$H$48,'2. Status Detalhe Campos'!$D$7:$D$615,"2. Campo") -> 0 | V54: =U54-T54 -> 0
D55: ="# "&U61 -> # 245 | P55: 2.2 Em Re-especificação | T55: =COUNTIFS('2. Status Detalhe Campos'!$H$7:$H$615,'1. Status Resumo'!$P55,'2. Status Detalhe Campos'!$C$7:$C$615,'1. Status Resumo'!$G$48,'2. Status Detalhe Campos'!$D$7:$D$615,"2. Campo")+COUNTIFS('2. Status Detalhe Campos'!$H$7:$H$615,'1. Status Resumo'!$P55,'2. Status Detalhe Campos'!$C$7:$C$615,'1. Status Resumo'!$H$48,'2. Status Detalhe Campos'!$D$7:$D$615,"2. Campo") -> 0 | U55: =COUNTIFS('2. Status Detalhe Campos'!$G$7:$G$615,'1. Status Resumo'!$P55,'2. Status Detalhe Campos'!$C$7:$C$615,'1. Status Resumo'!$G$48,'2. Status Detalhe Campos'!$D$7:$D$615,"2. Campo")+COUNTIFS('2. Status Detalhe Campos'!$G$7:$G$615,'1. Status Resumo'!$P55,'2. Status Detalhe Campos'!$C$7:$C$615,'1. Status Resumo'!$H$48,'2. Status Detalhe Campos'!$D$7:$D$615,"2. Campo") -> 0 | V55: =U55-T55 -> 0
P56: 3. Pendente de outros desenvolvimentos | T56: =COUNTIFS('2. Status Detalhe Campos'!$H$7:$H$615,'1. Status Resumo'!$P56,'2. Status Detalhe Campos'!$C$7:$C$615,'1. Status Resumo'!$G$48,'2. Status Detalhe Campos'!$D$7:$D$615,"2. Campo")+COUNTIFS('2. Status Detalhe Campos'!$H$7:$H$615,'1. Status Resumo'!$P56,'2. Status Detalhe Campos'!$C$7:$C$615,'1. Status Resumo'!$H$48,'2. Status Detalhe Campos'!$D$7:$D$615,"2. Campo") -> 0 | U56: =COUNTIFS('2. Status Detalhe Campos'!$G$7:$G$615,'1. Status Resumo'!$P56,'2. Status Detalhe Campos'!$C$7:$C$615,'1. Status Resumo'!$G$48,'2. Status Detalhe Campos'!$D$7:$D$615,"2. Campo")+COUNTIFS('2. Status Detalhe Campos'!$G$7:$G$615,'1. Status Resumo'!$P56,'2. Status Detalhe Campos'!$C$7:$C$615,'1. Status Resumo'!$H$48,'2. Status Detalhe Campos'!$D$7:$D$615,"2. Campo") -> 0 | V56: =U56-T56 -> 0
P57: 4. Validação EF | T57: =COUNTIFS('2. Status Detalhe Campos'!$H$7:$H$615,'1. Status Resumo'!$P57,'2. Status Detalhe Campos'!$C$7:$C$615,'1. Status Resumo'!$G$48,'2. Status Detalhe Campos'!$D$7:$D$615,"2. Campo")+COUNTIFS('2. Status Detalhe Campos'!$H$7:$H$615,'1. Status Resumo'!$P57,'2. Status Detalhe Campos'!$C$7:$C$615,'1. Status Resumo'!$H$48,'2. Status Detalhe Campos'!$D$7:$D$615,"2. Campo") -> 0 | U57: =COUNTIFS('2. Status Detalhe Campos'!$G$7:$G$615,'1. Status Resumo'!$P57,'2. Status Detalhe Campos'!$C$7:$C$615,'1. Status Resumo'!$G$48,'2. Status Detalhe Campos'!$D$7:$D$615,"2. Campo")+COUNTIFS('2. Status Detalhe Campos'!$G$7:$G$615,'1. Status Resumo'!$P57,'2. Status Detalhe Campos'!$C$7:$C$615,'1. Status Resumo'!$H$48,'2. Status Detalhe Campos'!$D$7:$D$615,"2. Campo") -> 0 | V57: =U57-T57 -> 0
P58: 5. Em Correção | R58: (incidências) | T58: =COUNTIFS('2. Status Detalhe Campos'!$H$7:$H$615,'1. Status Resumo'!$P58,'2. Status Detalhe Campos'!$C$7:$C$615,'1. Status Resumo'!$G$48,'2. Status Detalhe Campos'!$D$7:$D$615,"2. Campo")+COUNTIFS('2. Status Detalhe Campos'!$H$7:$H$615,'1. Status Resumo'!$P58,'2. Status Detalhe Campos'!$C$7:$C$615,'1. Status Resumo'!$H$48,'2. Status Detalhe Campos'!$D$7:$D$615,"2. Campo") -> 2 | U58: =COUNTIFS('2. Status Detalhe Campos'!$G$7:$G$615,'1. Status Resumo'!$P58,'2. Status Detalhe Campos'!$C$7:$C$615,'1. Status Resumo'!$G$48,'2. Status Detalhe Campos'!$D$7:$D$615,"2. Campo")+COUNTIFS('2. Status Detalhe Campos'!$G$7:$G$615,'1. Status Resumo'!$P58,'2. Status Detalhe Campos'!$C$7:$C$615,'1. Status Resumo'!$H$48,'2. Status Detalhe Campos'!$D$7:$D$615,"2. Campo") -> 2 | V58: =U58-T58 -> 0
P59: 6. Em implementação (re-especificação) | T59: =COUNTIFS('2. Status Detalhe Campos'!$H$7:$H$615,'1. Status Resumo'!$P59,'2. Status Detalhe Campos'!$C$7:$C$615,'1. Status Resumo'!$G$48,'2. Status Detalhe Campos'!$D$7:$D$615,"2. Campo")+COUNTIFS('2. Status Detalhe Campos'!$H$7:$H$615,'1. Status Resumo'!$P59,'2. Status Detalhe Campos'!$C$7:$C$615,'1. Status Resumo'!$H$48,'2. Status Detalhe Campos'!$D$7:$D$615,"2. Campo") -> 75 | U59: =COUNTIFS('2. Status Detalhe Campos'!$G$7:$G$615,'1. Status Resumo'!$P59,'2. Status Detalhe Campos'!$C$7:$C$615,'1. Status Resumo'!$G$48,'2. Status Detalhe Campos'!$D$7:$D$615,"2. Campo")+COUNTIFS('2. Status Detalhe Campos'!$G$7:$G$615,'1. Status Resumo'!$P59,'2. Status Detalhe Campos'!$C$7:$C$615,'1. Status Resumo'!$H$48,'2. Status Detalhe Campos'!$D$7:$D$615,"2. Campo") -> 75 | V59: =U59-T59 -> 0
P60: 7. Por iniciar | T60: =COUNTIFS('2. Status Detalhe Campos'!$H$7:$H$615,'1. Status Resumo'!$P60,'2. Status Detalhe Campos'!$C$7:$C$615,'1. Status Resumo'!$G$48,'2. Status Detalhe Campos'!$D$7:$D$615,"2. Campo")+COUNTIFS('2. Status Detalhe Campos'!$H$7:$H$615,'1. Status Resumo'!$P60,'2. Status Detalhe Campos'!$C$7:$C$615,'1. Status Resumo'!$H$48,'2. Status Detalhe Campos'!$D$7:$D$615,"2. Campo") -> 0 | U60: =COUNTIFS('2. Status Detalhe Campos'!$G$7:$G$615,'1. Status Resumo'!$P60,'2. Status Detalhe Campos'!$C$7:$C$615,'1. Status Resumo'!$G$48,'2. Status Detalhe Campos'!$D$7:$D$615,"2. Campo")+COUNTIFS('2. Status Detalhe Campos'!$G$7:$G$615,'1. Status Resumo'!$P60,'2. Status Detalhe Campos'!$C$7:$C$615,'1. Status Resumo'!$H$48,'2. Status Detalhe Campos'!$D$7:$D$615,"2. Campo") -> 0 | V60: =U60-T60 -> 0
T61: =SUM(T52:T60) -> 245 | U61: =SUM(U52:U60) -> 245
P63: Status (Universos - Inputs)
O64: > | P64: modesg_inp_risco_fisico | T64: OK
O65: > | P65: modesg_inp_nfrd_alinhamento_tax | T65: OK
O66: > | P66: modesg_inp_km_medios_emss_vcls | T66: OK
O67: > | P67: modesg_inp_emss_vcls | T67: OK
O68: > | P68: modesg_inp_emss_scib | T68: OK
O69: > | P69: modesg_inp_emss_nace | T69: OK
...

Sheet 2. Status Detalhe Campos
B6: Âmbito | C6: Sub-âmbito | D6: Tipo de teste | E6: Tabela | F6: Campo | G6: Status Atual | H6: Status Anterior | I6: Observações | J6: Data de Pedido correção/esclarecimento | K6: Data de correção prevista | L6: Data de correção efetiva | M6: Data Reunião
A7: =E7&F7 -> ENERGY_CERTIFICATE_EST_INPUTn.a. | B7: Pilar III | C7: Bens Imóveis - Input | D7: 1. Universo | E7: ENERGY_CERTIFICATE_EST_INPUT | F7: n.a. | G7: =VLOOKUP(A7,Plano_V3!$A$27:$G$583,7,0) -> 6. Em implementação (re-especificação) | H7: 6. Em implementação (re-especificação) | I7: Apesar da data de correção ser 28/11 a data que importa é 24/10, uma vez que a última implementação não é relevanta para iniciar os testes à tabela | J7: =IF(VLOOKUP(A7,'Aux - pivots1'!$A:$E,3,0)=0, "",VLOOKUP(A7,'Aux - pivots1'!$A:$E,3,0)) -> 45510 | K7: =IF(VLOOKUP(A7,'Aux - pivots1'!$A:$E,4,0)=0, "",VLOOKUP(A7,'Aux - pivots1'!$A:$E,4,0)) -> 45624 | L7: =IF(VLOOKUP(A7,'Aux - pivots1'!$A:$E,5,0)=0, "",VLOOKUP(A7,'Aux - pivots1'!$A:$E,5,0))
A8: =E8&F8 -> ENERGY_CERTIFICATE_EST_INPUTPROPERTY_BANK_ID | B8: Pilar III | C8: Bens Imóveis - Input | D8: 2. Campo | E8: ENERGY_CERTIFICATE_EST_INPUT | F8: PROPERTY_BANK_ID | G8: =VLOOKUP(A8,Plano_V3!$A$27:$G$583,7,0) -> 6. Em implementação (re-especificação) | H8: 6. Em implementação (re-especificação) | I8: Apesar da data de correção ser 28/11 a data que importa é 24/10, uma vez que a última implementação não é relevanta para iniciar os testes à tabela | J8: =IF(VLOOKUP(A8,'Aux - pivots1'!$A:$E,3,0)=0, "",VLOOKUP(A8,'Aux - pivots1'!$A:$E,3,0)) -> 45510 | K8: =IF(VLOOKUP(A8,'Aux - pivots1'!$A:$E,4,0)=0, "",VLOOKUP(A8,'Aux - pivots1'!$A:$E,4,0)) -> 45624 | L8: =IF(VLOOKUP(A8,'Aux - pivots1'!$A:$E,5,0)=0, "",VLOOKUP(A8,'Aux - pivots1'!$A:$E,5,0))
A9: =E9&F9 -> ENERGY_CERTIFICATE_EST_INPUTENCRYPTED_KEY | B9: Pilar III | C9: Bens Imóveis - Input | D9: 2. Campo | E9: ENERGY_CERTIFICATE_EST_INPUT | F9: ENCRYPTED_KEY | G9: =VLOOKUP(A9,Plano_V3!$A$27:$G$583,7,0) -> 6. Em implementação (re-especificação) | H9: 6. Em implementação (re-especificação) | I9: Apesar da data de correção ser 28/11 a data que importa é 24/10, uma vez que a última implementação não é relevanta para iniciar os testes à tabela | J9: =IF(VLOOKUP(A9,'Aux - pivots1'!$A:$E,3,0)=0, "",VLOOKUP(A9,'Aux - pivots1'!$A:$E,3,0)) -> 45510 | K9: =IF(VLOOKUP(A9,'Aux - pivots1'!$A:$E,4,0)=0, "",VLOOKUP(A9,'Aux - pivots1'!$A:$E,4,0)) -> 45624 | L9: =IF(VLOOKUP(A9,'Aux - pivots1'!$A:$E,5,0)=0, "",VLOOKUP(A9,'Aux - pivots1'!$A:$E,5,0))
A10: =E10&F10 -> ENERGY_CERTIFICATE_EST_INPUTPROPERTY_BRANCH_CODE | B10: Pilar III | C10: Bens Imóveis - Input | D10: 2. Campo | E10: ENERGY_CERTIFICATE_EST_INPUT | F10: PROPERTY_BRANCH_CODE | G10: =VLOOKUP(A10,Plano_V3!$A$27:$G$583,7,0) -> 6. Em implementação (re-especificação) | H10: 6. Em implementação (re-especificação) | I10: Apesar da data de correção ser 28/11 a data que importa é 24/10, uma vez que a última implementação não é relevanta para iniciar os testes à tabela | J10: =IF(VLOOKUP(A10,'Aux - pivots1'!$A:$E,3,0)=0, "",VLOOKUP(A10,'Aux - pivots1'!$A:$E,3,0)) -> 45510 | K10: =IF(VLOOKUP(A10,'Aux - pivots1'!$A:$E,4,0)=0, "",VLOOKUP(A10,'Aux - pivots1'!$A:$E,4,0)) -> 45624 | L10: =IF(VLOOKUP(A10,'Aux - pivots1'!$A:$E,5,0)=0, "",VLOOKUP(A10,'Aux - pivots1'!$A:$E,5,0))
A11: =E11&F11 -> ENERGY_CERTIFICATE_EST_INPUTPROPERTY_CONTRACT_ID | B11: Pilar III | C11: Bens Imóveis - Input | D11: 2. Campo | E11: ENERGY_CERTIFICATE_EST_INPUT | F11: PROPERTY_CONTRACT_ID | G11: =VLOOKUP(A11,Plano_V3!$A$27:$G$583,7,0) -> 6. Em implementação (re-especificação) | H11: 6. Em implementação (re-especificação) | I11: Apesar da data de correção ser 28/11 a data que importa é 24/10, uma vez que a última implementação não é relevanta para iniciar os testes à tabela | J11: =IF(VLOOKUP(A11,'Aux - pivots1'!$A:$E,3,0)=0, "",VLOOKUP(A11,'Aux - pivots1'!$A:$E,3,0)) -> 45510 | K11: =IF(VLOOKUP(A11,'Aux - pivots1'!$A:$E,4,0)=0, "",VLOOKUP(A11,'Aux - pivots1'!$A:$E,4,0)) -> 45624 | L11: =IF(VLOOKUP(A11,'Aux - pivots1'!$A:$E,5,0)=0, "",VLOOKUP(A11,'Aux - pivots1'!$A:$E,5,0))
