Workbook

Sheet Plano_V1
B6: Re-testes - input | D6: 0.2 | M6: =M7-M10 -> 0 | N6: =N7-N10 -> 0 | O6: =O7-O10 -> 0 | P6: =P7-P10 -> 0 | Q6: =Q7-Q10 -> 0 | R6: =R7-R10 -> 0 | S6: =S7-S10 -> 0 | T6: =T7-T10 -> 0 | ... FK6: =FK7-FK10 -> 0
B7: Re-testes - output | D7: =50%*25% -> 0.125 | L7: =AVERAGE(M7:EL7) -> 2.4923077 | M7: 3 | N7: 3 | O7: 3 | P7: 3 | Q7: 3 | R7: 2 | S7: 2 | T7: 2 | U7: 2 | V7: 2 | W7: 2 | X7: 2 | Y7: 2 | Z7: 2 | AA7: 2 | AB7: 2 | AC7: 2 | AD7: 1 | AE7: 1 | AF7: 1 | AG7: 3 | AH7: 3 | AI7: 3 | AJ7: 3 | AK7: 2 | AL7: 3 | AM7: 3 | AN7: 3 | AO7: 3 | AP7: 3 | AQ7: 2 | AR7: 2 | AS7: 2 | AT7: 0 | AU7: 1 | AV7: 1 | AW7: 0 | AX7: 1 | AY7: 1 | AZ7: 1 | BA7: 2 | BB7: 2 | BC7: 2 | BD7: 2 | BE7: 2 | BF7: 2 | BG7: 2 | BH7: 2 | BI7: 2 | BJ7: 2 | BK7: 2 | BL7: 2 | BM7: 2 | BN7: 2 | BO7: 2 | BP7: 3 | BQ7: 3 | BR7: 3 | BS7: 3 | BT7: 3 | BU7: 3 | BV7: 3 | BW7: 3 | BX7: 3 | BY7: 3 | BZ7: 3 | CA7: 3 | CB7: 3 | CC7: 3 | CD7: 3 | CE7: 3 | CF7: 3 | CG7: 3 | CH7: 3 | CI7: 3 | CJ7: 3 | CK7: 3 | CL7: 3 | CM7: 3 | CN7: 3 | CO7: 3 | CP7: 3 | CQ7: 3 | CR7: 3 | CS7: 3 | CT7: 3 | CU7: 3 | CV7: 3 | CW7: 3 | CX7: 3 | CY7: 3 | CZ7: 3 | DA7: 3 | DB7: 3 | DC7: 3 | DD7: 3 | DE7: 3 | DF7: 3 | DG7: 3 | DH7: 3 | DI7: 3 | DJ7: 3 | DK7: 3 | DL7: 3 | DM7: 3 | DN7: 2 | DO7: 3 | DP7: 3 | DQ7: 3 | DR7: 3 | DS7: 3 | DT7: 3 | DU7: 3 | DV7: 3 | DW7: 3 | DX7: 3 | DY7: 3 | DZ7: 3 | EA7: 3 | EB7: 3 | EC7: 3 | ED7: 3 | EE7: 3 | EF7: 3 | EG7: 3 | EH7: 3 | EI7: 0 | EJ7: 0 | EK7: 0 | EL7: 0 | EM7: 0 | EN7: 0 | EO7: 0 | EP7: 3 | EQ7: 3 | ER7: 3 | ES7: 3 | ET7: 3 | EU7: 3 | EV7: 3 | EW7: 3 | EX7: 3 | EY7: 3 | EZ7: 3 | FA7: 3 | FB7: 3 | FC7: 3 | FD7: 3 | FE7: 3 | FF7: 3 | FG7: 3 | FH7: 3 | FI7: 3 | FJ7: 3 | FK7: 3
M10: =SUBTOTAL(9,M14:M636) -> 3 | N10: =SUBTOTAL(9,N14:N636) -> 3 | O10: =SUBTOTAL(9,O14:O636) -> 3 | P10: =SUBTOTAL(9,P14:P636) -> 3 | Q10: =SUBTOTAL(9,Q14:Q636) -> 3 | R10: =SUBTOTAL(9,R14:R636) -> 2 | S10: =SUBTOTAL(9,S14:S636) -> 2 | T10: =SUBTOTAL(9,T14:T636) -> 2 | ... FK10: =SUBTOTAL(9,FK14:FK636) -> 3
M11: Julho | W11: Julho | AJ11: Agosto | BF11: Setembro | CA11: Outubro | CX11: Novembro | DS11: Dezembro | EO11: Janeiro
M12: =M13 -> 45474 | N12: =N13 -> 45475 | O12: =O13 -> 45476 | P12: =P13 -> 45477 | Q12: =Q13 -> 45478 | R12: =R13 -> 45481 | S12: =S13 -> 45482 | T12: =T13 -> 45483 | ... FK12: =FK13 -> 45688
B13: Âmbito | C13: Sub-âmbito | D13: Tipo de teste | E13: Tabela | F13: Campo | G13: Status | H13: Status2 | I13: Horas | J13: Dias | K13: Pendências | L13: Val | M13: 45474 | N13: =WORKDAY(M13,1) -> 45475 | O13: =WORKDAY(N13,1) -> 45476 | P13: =WORKDAY(O13,1) -> 45477 | Q13: =WORKDAY(P13,1) -> 45478 | R13: =WORKDAY(Q13,1) -> 45481 | S13: =WORKDAY(R13,1) -> 45482 | T13: =WORKDAY(S13,1) -> 45483 | U13: =WORKDAY(T13,1) -> 45484 | ... FK13: =WORKDAY(FJ13,1) -> 45688
B14: 1. Assessment | I14: =SUM(I15:I18) -> 280 | J14: =SUM(J15:J18) -> 35
B15: Pilar III | C15: Bens Imóveis | G15: 7. Por iniciar | I15: =J15*8 -> 40 | J15: 5 | L15: =J15-SUM(M15:FK15) -> 0 | W15: 1 | X15: 1 | Y15: 1 | Z15: 1 | AA15: 1
B16: Pilar III | C16: Modelo Verde | G16: 7. Por iniciar | I16: =J16*8 -> 80 | J16: 10 | L16: =J16-SUM(M16:FK16) -> 0 | R16: 2 | S16: 2 | T16: 2 | U16: 2 | V16: 2
B17: Pilar III | C17: Pilar III | G17: 7. Por iniciar | I17: =J17*8 -> 40 | J17: 5 | L17: =J17-SUM(M17:FK17) -> 0 | AB17: 1 | AC17: 1 | AD17: 1 | AE17: 1 | AF17: 0.5 | AG17: 0.5
B18: GD | C18: GD | G18: 7. Por iniciar | I18: =J18*8 -> 120 | J18: 15 | L18: =J18-SUM(M18:FK18) -> 0 | M18: 3 | N18: 3 | O18: 3 | P18: 3 | Q18: 3
B20: 2. Re-especificação | I20: =SUM(I21:I23) -> 120 | J20: =SUM(J21:J23) -> 15
B21: Pilar III | C21: Bens Imóveis | G21: 7. Por iniciar | I21: =J21*8 -> 40 | J21: 5 | L21: =J21-SUM(M21:FK21) -> 0 | W21: 0.5 | AB21: 0.5 | AG21: 0.5 | AL21: 0.5 | AQ21: 0.5 | AV21: 0.5 | BA21: 0.5 | BF21: 0.5 | BK21: 0.5 | BP21: 0.5
B22: Pilar III | C22: Modelo Verde | G22: 7. Por iniciar | I22: =J22*8 -> 40 | J22: 5 | L22: =J22-SUM(M22:FK22) -> 0 | W22: 0.5 | AB22: 0.5 | AG22: 0.5 | AL22: 0.5 | AQ22: 0.5 | AV22: 0.5 | BA22: 0.5 | BF22: 0.5 | BK22: 0.5 | BP22: 0.5
B23: Pilar III | C23: Pilar III | G23: 7. Por iniciar | I23: =J23*8 -> 40 | J23: 5 | L23: =J23-SUM(M23:FK23) -> 0 | BF23: 0.5 | BK23: 0.5 | BP23: 0.5 | BU23: 0.5 | BZ23: 0.5 | CE23: 0.5 | CJ23: 0.5 | CO23: 0.5 | CT23: 0.5 | CY23: 0.5
B25: 3. Testes / Re-testes | I25: =I26+I27+I42+I198+I362+I447 -> 1341.1875 | J25: =J26+J27+J42+J198+J362+J447 -> 169
B26: Testes Regressivos | G26: 7. Por iniciar | I26: =4*22 -> 88 | J26: =I26/8 -> 11 | L26: =J26-SUM(M26:FK26) -> 0 | AA26: 0.5 | AF26: 0.5 | AK26: 0.5 | AP26: 0.5 | AU26: 0.5 | AZ26: 0.5 | BE26: 0.5 | BJ26: 0.5 | BO26: 0.5 | BT26: 0.5 | BY26: 0.5 | CD26: 0.5 | CI26: 0.5 | CN26: 0.5 | CS26: 0.5 | CX26: 0.5 | DC26: 0.5 | DH26: 0.5 | DM26: 0.5 | DR26: 0.5 | DW26: 0.5 | EB26: 0.5
B27: Pilar III | C27: Bens Imóveis - Input | I27: =SUM(I28:I41) -> 0 | J27: =ROUNDUP(I27/8,0) -> 0 | L27: =J27-SUM(M27:FK27) -> -3 | X27: 0.5 | Y27: 0.5 | AC27: 0.5 | AG27: 1 | AH27: 0.5
A28: =E28&F28 -> cd_imv_inp_certif_estimativan.a. | B28: Pilar III | C28: Bens Imóveis - Input | D28: 1. Universo | E28: cd_imv_inp_certif_estimativa | F28: n.a. | G28: =INDEX(Auxiliar!$B$16:$B$24,MATCH(Plano_V1!H28,Auxiliar!$C$16:$C$24,0),1) -> #N/A | H28: =VLOOKUP(A28,'Aux - pivots1'!$A:$B,2,0) -> #N/A | I28: =SUMIFS(Table1[Estimação (horas)],Table1[Tabela],Plano_V1!E28,Table1[Campo],Plano_V1!F28) -> 0 | J28: =I28/8 -> 0 | K28: sem pendencia | L28: =J28-SUM(M28:FK28) -> 0
A29: =E29&F29 -> cd_imv_inp_certif_estimativacempbem | B29: Pilar III | C29: Bens Imóveis - Input | D29: 2. Campo | E29: cd_imv_inp_certif_estimativa | F29: cempbem | G29: =INDEX(Auxiliar!$B$16:$B$24,MATCH(Plano_V1!H29,Auxiliar!$C$16:$C$24,0),1) -> #N/A | H29: =VLOOKUP(A29,'Aux - pivots1'!$A:$B,2,0) -> #N/A | I29: =SUMIFS(Table1[Estimação (horas)],Table1[Tabela],Plano_V1!E29,Table1[Campo],Plano_V1!F29) -> 0 | J29: =I29/8 -> 0 | K29: sem pendencia | L29: =J29-SUM(M29:FK29) -> 0
A30: =E30&F30 -> cd_imv_inp_certif_estimativachave_encriptada | B30: Pilar III | C30: Bens Imóveis - Input | D30: 2. Campo | E30: cd_imv_inp_certif_estimativa | F30: chave_encriptada | G30: =INDEX(Auxiliar!$B$16:$B$24,MATCH(Plano_V1!H30,Auxiliar!$C$16:$C$24,0),1) -> #N/A | H30: =VLOOKUP(A30,'Aux - pivots1'!$A:$B,2,0) -> #N/A | I30: =SUMIFS(Table1[Estimação (horas)],Table1[Tabela],Plano_V1!E30,Table1[Campo],Plano_V1!F30) -> 0 | J30: =I30/8 -> 0 | K30: sem pendencia | L30: =J30-SUM(M30:FK30) -> 0
A31: =E31&F31 -> cd_imv_inp_certif_estimativackbalbem | B31: Pilar III | C31: Bens Imóveis - Input | D31: 2. Campo | E31: cd_imv_inp_certif_estimativa | F31: ckbalbem | G31: =INDEX(Auxiliar!$B$16:$B$24,MATCH(Plano_V1!H31,Auxiliar!$C$16:$C$24,0),1) -> #N/A | H31: =VLOOKUP(A31,'Aux - pivots1'!$A:$B,2,0) -> #N/A | I31: =SUMIFS(Table1[Estimação (horas)],Table1[Tabela],Plano_V1!E31,Table1[Campo],Plano_V1!F31) -> 0 | J31: =I31/8 -> 0 | K31: sem pendencia | L31: =J31-SUM(M31:FK31) -> 0
A32: =E32&F32 -> cd_imv_inp_certif_estimativackctabem | B32: Pilar III | C32: Bens Imóveis - Input | D32: 2. Campo | E32: cd_imv_inp_certif_estimativa | F32: ckctabem | G32: =INDEX(Auxiliar!$B$16:$B$24,MATCH(Plano_V1!H32,Auxiliar!$C$16:$C$24,0),1) -> #N/A | H32: =VLOOKUP(A32,'Aux - pivots1'!$A:$B,2,0) -> #N/A | I32: =SUMIFS(Table1[Estimação (horas)],Table1[Tabela],Plano_V1!E32,Table1[Campo],Plano_V1!F32) -> 0 | J32: =I32/8 -> 0 | K32: sem pendencia | L32: =J32-SUM(M32:FK32) -> 0
A33: =E33&F33 -> cd_imv_inp_certif_estimativackrefbem | B33: Pilar III | C33: Bens Imóveis - Input | D33: 2. Campo | E33: cd_imv_inp_certif_estimativa | F33: ckrefbem | G33: =INDEX(Auxiliar!$B$16:$B$24,MATCH(Plano_V1!H33,Auxiliar!$C$16:$C$24,0),1) -> #N/A | H33: =VLOOKUP(A33,'Aux - pivots1'!$A:$B,2,0) -> #N/A | I33: =SUMIFS(Table1[Estimação (horas)],Table1[Tabela],Plano_V1!E33,Table1[Campo],Plano_V1!F33) -> 0 | J33: =I33/8 -> 0 | K33: sem pendencia | L33: =J33-SUM(M33:FK33) -> 0
A34: =E34&F34 -> cd_imv_inp_certif_estimativadata_extraccao_info | B34: Pilar III | C34: Bens Imóveis - Input | D34: 2. Campo | E34: cd_imv_inp_certif_estimativa | F34: data_extraccao_info | G34: =INDEX(Auxiliar!$B$16:$B$24,MATCH(Plano_V1!H34,Auxiliar!$C$16:$C$24,0),1) -> #N/A | H34: =VLOOKUP(A34,'Aux - pivots1'!$A:$B,2,0) -> #N/A | I34: =SUMIFS(Table1[Estimação (horas)],Table1[Tabela],Plano_V1!E34,Table1[Campo],Plano_V1!F34) -> 0 | J34: =I34/8 -> 0 | K34: sem pendencia | L34: =J34-SUM(M34:FK34) -> 0
A35: =E35&F35 -> cd_imv_inp_certif_estimativaepc | B35: Pilar III | C35: Bens Imóveis - Input | D35: 2. Campo | E35: cd_imv_inp_certif_estimativa | F35: epc | G35: =INDEX(Auxiliar!$B$16:$B$24,MATCH(Plano_V1!H35,Auxiliar!$C$16:$C$24,0),1) -> #N/A | H35: =VLOOKUP(A35,'Aux - pivots1'!$A:$B,2,0) -> #N/A | I35: =SUMIFS(Table1[Estimação (horas)],Table1[Tabela],Plano_V1!E35,Table1[Campo],Plano_V1!F35) -> 0 | J35: =I35/8 -> 0 | K35: sem pendencia | L35: =J35-SUM(M35:FK35) -> 0
A36: =E36&F36 -> cd_imv_inp_certif_estimativafornecedor | B36: Pilar III | C36: Bens Imóveis - Input | D36: 2. Campo | E36: cd_imv_inp_certif_estimativa | F36: fornecedor | G36: =INDEX(Auxiliar!$B$16:$B$24,MATCH(Plano_V1!H36,Auxiliar!$C$16:$C$24,0),1) -> #N/A | H36: =VLOOKUP(A36,'Aux - pivots1'!$A:$B,2,0) -> #N/A | I36: =SUMIFS(Table1[Estimação (horas)],Table1[Tabela],Plano_V1!E36,Table1[Campo],Plano_V1!F36) -> 0 | J36: =I36/8 -> 0 | K36: sem pendencia | L36: =J36-SUM(M36:FK36) -> 0
A37: =E37&F37 -> cd_imv_inp_certif_estimativametodo_info | B37: Pilar III | C37: Bens Imóveis - Input | D37: 2. Campo | E37: cd_imv_inp_certif_estimativa | F37: metodo_info | G37: =INDEX(Auxiliar!$B$16:$B$24,MATCH(Plano_V1!H37,Auxiliar!$C$16:$C$24,0),1) -> #N/A | H37: =VLOOKUP(A37,'Aux - pivots1'!$A:$B,2,0) -> #N/A | I37: =SUMIFS(Table1[Estimação (horas)],Table1[Tabela],Plano_V1!E37,Table1[Campo],Plano_V1!F37) -> 0 | J37: =I37/8 -> 0 | K37: sem pendencia | L37: =J37-SUM(M37:FK37) -> 0
A38: =E38&F38 -> cd_imv_inp_certif_estimativascore_qualidade | B38: Pilar III | C38: Bens Imóveis - Input | D38: 2. Campo | E38: cd_imv_inp_certif_estimativa | F38: score_qualidade | G38: =INDEX(Auxiliar!$B$16:$B$24,MATCH(Plano_V1!H38,Auxiliar!$C$16:$C$24,0),1) -> #N/A | H38: =VLOOKUP(A38,'Aux - pivots1'!$A:$B,2,0) -> #N/A | I38: =SUMIFS(Table1[Estimação (horas)],Table1[Tabela],Plano_V1!E38,Table1[Campo],Plano_V1!F38) -> 0 | J38: =I38/8 -> 0 | K38: sem pendencia | L38: =J38-SUM(M38:FK38) -> 0
A39: =E39&F39 -> cd_imv_inp_certif_estimativavlr_cnsm_ano | B39: Pilar III | C39: Bens Imóveis - Input | D39: 2. Campo | E39: cd_imv_inp_certif_estimativa | F39: vlr_cnsm_ano | G39: =INDEX(Auxiliar!$B$16:$B$24,MATCH(Plano_V1!H39,Auxiliar!$C$16:$C$24,0),1) -> #N/A | H39: =VLOOKUP(A39,'Aux - pivots1'!$A:$B,2,0) -> #N/A | I39: =SUMIFS(Table1[Estimação (horas)],Table1[Tabela],Plano_V1!E39,Table1[Campo],Plano_V1!F39) -> 0 | J39: =I39/8 -> 0 | K39: sem pendencia | L39: =J39-SUM(M39:FK39) -> 0
A40: =E40&F40 -> cd_imv_inp_certif_estimativavlr_emss_ano | B40: Pilar III | C40: Bens Imóveis - Input | D40: 2. Campo | E40: cd_imv_inp_certif_estimativa | F40: vlr_emss_ano | G40: =INDEX(Auxiliar!$B$16:$B$24,MATCH(Plano_V1!H40,Auxiliar!$C$16:$C$24,0),1) -> #N/A | H40: =VLOOKUP(A40,'Aux - pivots1'!$A:$B,2,0) -> #N/A | I40: =SUMIFS(Table1[Estimação (horas)],Table1[Tabela],Plano_V1!E40,Table1[Campo],Plano_V1!F40) -> 0 | J40: =I40/8 -> 0 | K40: sem pendencia | L40: =J40-SUM(M40:FK40) -> 0
A41: =E41&F41 -> Re-testesn.a. | B41: Pilar III | C41: Bens Imóveis - Input | D41: 2. Campo | E41: Re-testes | F41: n.a. | G41: 7. Por iniciar | I41: =SUM(I28:I40)*D6 -> 0 | J41: =I41/8 -> 0 | K41: sem pendencia | L41: =J41-SUM(M41:FK41) -> 0
A42: =E42&F42 | B42: Pilar III | C42: Bens Imóveis - Output | I42: =SUM(I43:I197) -> 0 | J42: =ROUNDUP(I42/8,0) -> 0 | L42: =J42-SUM(M42:FK42) -> -100 | AH42: 0.5 | AI42: 1 | AJ42: 1 | AM42: 1 | AN42: 1 | AO42: 1 | AP42: 0.5 | AR42: 1 | AS42: 2 | AU42: 0.5 | AX42: 1 | AY42: 1 | AZ42: 0.5 | BA42: 1 | BB42: 2 | BC42: 2 | BD42: 2 | BE42: 1.5 | BF42: 0.5 | BG42: 2 | BH42: 2 | BI42: 2 | BJ42: 1.5 | BK42: 0.5 | BL42: 2 | BM42: 2 | BN42: 2 | BO42: 1.5 | BP42: 1.5 | BQ42: 2 | BR42: 2 | BS42: 2 | BT42: 2 | BU42: 2 | BV42: 2 | BW42: 2 | BX42: 2 | BY42: 2 | BZ42: 2 | CA42: 2 | CB42: 2 | CC42: 2 | CD42: 2 | CE42: 2 | CF42: 2 | CG42: 2 | CH42: 2 | CI42: 2 | CJ42: 2 | CK42: 2 | CL42: 2 | CM42: 2 | CN42: 2 | CO42: 2 | CP42: 2 | CQ42: 2 | CR42: 2 | CS42: 2 | CT42: 2 | CU42: 2
A43: =E43&F43 -> cd_imv_out_prcn.a. | B43: Pilar III | C43: Bens Imóveis - Output | D43: 1. Universo | E43: cd_imv_out_prc | F43: n.a. | G43: =INDEX(Auxiliar!$B$16:$B$24,MATCH(Plano_V1!H43,Auxiliar!$C$16:$C$24,0),1) -> #N/A | H43: =VLOOKUP(A43,'Aux - pivots1'!$A:$B,2,0) -> #N/A | I43: =SUMIFS(Table1[Estimação (horas)],Table1[Tabela],Plano_V1!E43,Table1[Campo],Plano_V1!F43) -> 0 | J43: =I43/8 -> 0 | K43: cd_imv_out_trz_cred_prc | L43: =J43-SUM(M43:FK43) -> 0
A44: =E44&F44 -> cd_imv_out_prccempresa | B44: Pilar III | C44: Bens Imóveis - Output | D44: 2. Campo | E44: cd_imv_out_prc | F44: cempresa | G44: =INDEX(Auxiliar!$B$16:$B$24,MATCH(Plano_V1!H44,Auxiliar!$C$16:$C$24,0),1) -> #N/A | H44: =VLOOKUP(A44,'Aux - pivots1'!$A:$B,2,0) -> #N/A | I44: =SUMIFS(Table1[Estimação (horas)],Table1[Tabela],Plano_V1!E44,Table1[Campo],Plano_V1!F44) -> 0 | J44: =I44/8 -> 0 | K44: cd_imv_out_trz_cred_prc | L44: =J44-SUM(M44:FK44) -> 0
A45: =E45&F45 -> cd_imv_out_prcckbalcao | B45: Pilar III | C45: Bens Imóveis - Output | D45: 2. Campo | E45: cd_imv_out_prc | F45: ckbalcao | G45: =INDEX(Auxiliar!$B$16:$B$24,MATCH(Plano_V1!H45,Auxiliar!$C$16:$C$24,0),1) -> #N/A | H45: =VLOOKUP(A45,'Aux - pivots1'!$A:$B,2,0) -> #N/A | I45: =SUMIFS(Table1[Estimação (horas)],Table1[Tabela],Plano_V1!E45,Table1[Campo],Plano_V1!F45) -> 0 | J45: =I45/8 -> 0 | K45: cd_imv_out_trz_cred_prc | L45: =J45-SUM(M45:FK45) -> 0
A46: =E46&F46 -> cd_imv_out_prccknumcta | B46: Pilar III | C46: Bens Imóveis - Output | D46: 2. Campo | E46: cd_imv_out_prc | F46: cknumcta | G46: =INDEX(Auxiliar!$B$16:$B$24,MATCH(Plano_V1!H46,Auxiliar!$C$16:$C$24,0),1) -> #N/A | H46: =VLOOKUP(A46,'Aux - pivots1'!$A:$B,2,0) -> #N/A | I46: =SUMIFS(Table1[Estimação (horas)],Table1[Tabela],Plano_V1!E46,Table1[Campo],Plano_V1!F46) -> 0 | J46: =I46/8 -> 0 | K46: cd_imv_out_trz_cred_prc | L46: =J46-SUM(M46:FK46) -> 0
A47: =E47&F47 -> cd_imv_out_prccod_estd_prcs | B47: Pilar III | C47: Bens Imóveis - Output | D47: 2. Campo | E47: cd_imv_out_prc | F47: cod_estd_prcs | G47: =INDEX(Auxiliar!$B$16:$B$24,MATCH(Plano_V1!H47,Auxiliar!$C$16:$C$24,0),1) -> #N/A | H47: =VLOOKUP(A47,'Aux - pivots1'!$A:$B,2,0) -> #N/A | I47: 0 | J47: =I47/8 -> 0 | K47: cd_imv_out_trz_cred_prc | L47: =J47-SUM(M47:FK47) -> 0
A48: =E48&F48 -> cd_imv_out_prccod_grt | B48: Pilar III | C48: Bens Imóveis - Output | D48: 2. Campo | E48: cd_imv_out_prc | F48: cod_grt | G48: =INDEX(Auxiliar!$B$16:$B$24,MATCH(Plano_V1!H48,Auxiliar!$C$16:$C$24,0),1) -> #N/A | H48: =VLOOKUP(A48,'Aux - pivots1'!$A:$B,2,0) -> #N/A | I48: =SUMIFS(Table1[Estimação (horas)],Table1[Tabela],Plano_V1!E48,Table1[Campo],Plano_V1!F48) -> 0 | J48: =I48/8 -> 0 | K48: cd_imv_out_trz_cred_prc | L48: =J48-SUM(M48:FK48) -> 0
A49: =E49&F49 -> cd_imv_out_prccod_moeda | B49: Pilar III | C49: Bens Imóveis - Output | D49: 2. Campo | E49: cd_imv_out_prc | F49: cod_moeda | G49: =INDEX(Auxiliar!$B$16:$B$24,MATCH(Plano_V1!H49,Auxiliar!$C$16:$C$24,0),1) -> #N/A | H49: =VLOOKUP(A49,'Aux - pivots1'!$A:$B,2,0) -> #N/A | I49: =SUMIFS(Table1[Estimação (horas)],Table1[Tabela],Plano_V1!E49,Table1[Campo],Plano_V1!F49) -> 0 | J49: =I49/8 -> 0 | K49: cd_imv_out_trz_cred_prc | L49: =J49-SUM(M49:FK49) -> 0
...

Sheet 1. Status Resumo
B6: Sumário Executivo |13 de dezembro a 23 de dezembro
B8: - Concluídos 11 campos da Tabela de Clientes do Modelo Verde - Concluídos 15 campos da Loan Tape Pilar III
B13: 1. Visão Geral
C16: Resumo | H16: Detalhe por Tabela | P16: Status (campos) | T16: 45625 | U16: =T16+7 -> 45632 | V16: ∆ | X16: Highlights
P17: 0. Cancelado | T17: =COUNTIFS('2. Status Detalhe Campos'!$H$7:$H$574,'1. Status Resumo'!$P63,'2. Status Detalhe Campos'!$C$7:$C$574,'1. Status Resumo'!$G$59,'2. Status Detalhe Campos'!$D$7:$D$574,"2. Campo")+COUNTIFS('2. Status Detalhe Campos'!$H$7:$H$574,'1. Status Resumo'!$P63,'2. Status Detalhe Campos'!$C$7:$C$574,'1. Status Resumo'!$H$59,'2. Status Detalhe Campos'!$D$7:$D$574,"2. Campo")+COUNTIFS('2. Status Detalhe Campos'!$H$7:$H$574,'1. Status Resumo'!$P87,'2. Status Detalhe Campos'!$C$7:$C$574,'1. Status Resumo'!$G$83,'2. Status Detalhe Campos'!$D$7:$D$574,"2. Campo")+COUNTIFS('2. Status Detalhe Campos'!$H$7:$H$574,'1. Status Resumo'!$P87,'2. Status Detalhe Campos'!$C$7:$C$574,'1. Status Resumo'!$H$83,'2. Status Detalhe Campos'!$D$7:$D$574,"2. Campo")+COUNTIFS(Table4[Status Anterior],'1. Status Resumo'!$P122,Table4[Sub-âmbito],'1. Status Resumo'!$G$118,Table4[Tipo de teste],"2. Campo") -> 24 | U17: =COUNTIFS('2. Status Detalhe Campos'!$G$7:$G$574,'1. Status Resumo'!$P63,'2. Status Detalhe Campos'!$C$7:$C$574,'1. Status Resumo'!$G$59,'2. Status Detalhe Campos'!$D$7:$D$574,"2. Campo")+COUNTIFS('2. Status Detalhe Campos'!$G$7:$G$574,'1. Status Resumo'!$P63,'2. Status Detalhe Campos'!$C$7:$C$574,'1. Status Resumo'!$H$59,'2. Status Detalhe Campos'!$D$7:$D$574,"2. Campo")+COUNTIFS('2. Status Detalhe Campos'!$G$7:$G$574,'1. Status Resumo'!$P87,'2. Status Detalhe Campos'!$C$7:$C$574,'1. Status Resumo'!$G$83,'2. Status Detalhe Campos'!$D$7:$D$574,"2. Campo")+COUNTIFS('2. Status Detalhe Campos'!$G$7:$G$574,'1. Status Resumo'!$P87,'2. Status Detalhe Campos'!$C$7:$C$574,'1. Status Resumo'!$H$83,'2. Status Detalhe Campos'!$D$7:$D$574,"2. Campo")+COUNTIFS(Table4[Status Atual],'1. Status Resumo'!$P122,Table4[Sub-âmbito],'1. Status Resumo'!$G$118,Table4[Tipo de teste],"2. Campo") -> 24 | V17: =U17-T17 -> 0
P18: 1. Concluído | T18: =COUNTIFS('2. Status Detalhe Campos'!$H$7:$H$574,'1. Status Resumo'!$P64,'2. Status Detalhe Campos'!$C$7:$C$574,'1. Status Resumo'!$G$59,'2. Status Detalhe Campos'!$D$7:$D$574,"2. Campo")+COUNTIFS('2. Status Detalhe Campos'!$H$7:$H$574,'1. Status Resumo'!$P64,'2. Status Detalhe Campos'!$C$7:$C$574,'1. Status Resumo'!$H$59,'2. Status Detalhe Campos'!$D$7:$D$574,"2. Campo")+COUNTIFS('2. Status Detalhe Campos'!$H$7:$H$574,'1. Status Resumo'!$P88,'2. Status Detalhe Campos'!$C$7:$C$574,'1. Status Resumo'!$G$83,'2. Status Detalhe Campos'!$D$7:$D$574,"2. Campo")+COUNTIFS('2. Status Detalhe Campos'!$H$7:$H$574,'1. Status Resumo'!$P88,'2. Status Detalhe Campos'!$C$7:$C$574,'1. Status Resumo'!$H$83,'2. Status Detalhe Campos'!$D$7:$D$574,"2. Campo")+COUNTIFS(Table4[Status Anterior],'1. Status Resumo'!$P123,Table4[Sub-âmbito],'1. Status Resumo'!$G$118,Table4[Tipo de teste],"2. Campo") -> 473 | U18: =COUNTIFS('2. Status Detalhe Campos'!$G$7:$G$574,'1. Status Resumo'!$P64,'2. Status Detalhe Campos'!$C$7:$C$574,'1. Status Resumo'!$G$59,'2. Status Detalhe Campos'!$D$7:$D$574,"2. Campo")+COUNTIFS('2. Status Detalhe Campos'!$G$7:$G$574,'1. Status Resumo'!$P64,'2. Status Detalhe Campos'!$C$7:$C$574,'1. Status Resumo'!$H$59,'2. Status Detalhe Campos'!$D$7:$D$574,"2. Campo")+COUNTIFS('2. Status Detalhe Campos'!$G$7:$G$574,'1. Status Resumo'!$P88,'2. Status Detalhe Campos'!$C$7:$C$574,'1. Status Resumo'!$G$83,'2. Status Detalhe Campos'!$D$7:$D$574,"2. Campo")+COUNTIFS('2. Status Detalhe Campos'!$G$7:$G$574,'1. Status Resumo'!$P88,'2. Status Detalhe Campos'!$C$7:$C$574,'1. Status Resumo'!$H$83,'2. Status Detalhe Campos'!$D$7:$D$574,"2. Campo")+COUNTIFS(Table4[Status Atual],'1. Status Resumo'!$P123,Table4[Sub-âmbito],'1. Status Resumo'!$G$118,Table4[Tipo de teste],"2. Campo") -> 472 | V18: =U18-T18 -> -1
P19: 2.1 Em Teste | T19: =COUNTIFS('2. Status Detalhe Campos'!$H$7:$H$574,'1. Status Resumo'!$P65,'2. Status Detalhe Campos'!$C$7:$C$574,'1. Status Resumo'!$G$59,'2. Status Detalhe Campos'!$D$7:$D$574,"2. Campo")+COUNTIFS('2. Status Detalhe Campos'!$H$7:$H$574,'1. Status Resumo'!$P65,'2. Status Detalhe Campos'!$C$7:$C$574,'1. Status Resumo'!$H$59,'2. Status Detalhe Campos'!$D$7:$D$574,"2. Campo")+COUNTIFS('2. Status Detalhe Campos'!$H$7:$H$574,'1. Status Resumo'!$P89,'2. Status Detalhe Campos'!$C$7:$C$574,'1. Status Resumo'!$G$83,'2. Status Detalhe Campos'!$D$7:$D$574,"2. Campo")+COUNTIFS('2. Status Detalhe Campos'!$H$7:$H$574,'1. Status Resumo'!$P89,'2. Status Detalhe Campos'!$C$7:$C$574,'1. Status Resumo'!$H$83,'2. Status Detalhe Campos'!$D$7:$D$574,"2. Campo")+COUNTIFS(Table4[Status Anterior],'1. Status Resumo'!$P124,Table4[Sub-âmbito],'1. Status Resumo'!$G$118,Table4[Tipo de teste],"2. Campo") -> 26 | U19: =COUNTIFS('2. Status Detalhe Campos'!$G$7:$G$574,'1. Status Resumo'!$P65,'2. Status Detalhe Campos'!$C$7:$C$574,'1. Status Resumo'!$G$59,'2. Status Detalhe Campos'!$D$7:$D$574,"2. Campo")+COUNTIFS('2. Status Detalhe Campos'!$G$7:$G$574,'1. Status Resumo'!$P65,'2. Status Detalhe Campos'!$C$7:$C$574,'1. Status Resumo'!$H$59,'2. Status Detalhe Campos'!$D$7:$D$574,"2. Campo")+COUNTIFS('2. Status Detalhe Campos'!$G$7:$G$574,'1. Status Resumo'!$P89,'2. Status Detalhe Campos'!$C$7:$C$574,'1. Status Resumo'!$G$83,'2. Status Detalhe Campos'!$D$7:$D$574,"2. Campo")+COUNTIFS('2. Status Detalhe Campos'!$G$7:$G$574,'1. Status Resumo'!$P89,'2. Status Detalhe Campos'!$C$7:$C$574,'1. Status Resumo'!$H$83,'2. Status Detalhe Campos'!$D$7:$D$574,"2. Campo")+COUNTIFS(Table4[Status Atual],'1. Status Resumo'!$P124,Table4[Sub-âmbito],'1. Status Resumo'!$G$118,Table4[Tipo de teste],"2. Campo") -> 25 | V19: =U19-T19 -> -1
P20: 2.2 Em Re-especificação | T20: =COUNTIFS('2. Status Detalhe Campos'!$H$7:$H$574,'1. Status Resumo'!$P66,'2. Status Detalhe Campos'!$C$7:$C$574,'1. Status Resumo'!$G$59,'2. Status Detalhe Campos'!$D$7:$D$574,"2. Campo")+COUNTIFS('2. Status Detalhe Campos'!$H$7:$H$574,'1. Status Resumo'!$P66,'2. Status Detalhe Campos'!$C$7:$C$574,'1. Status Resumo'!$H$59,'2. Status Detalhe Campos'!$D$7:$D$574,"2. Campo")+COUNTIFS('2. Status Detalhe Campos'!$H$7:$H$574,'1. Status Resumo'!$P90,'2. Status Detalhe Campos'!$C$7:$C$574,'1. Status Resumo'!$G$83,'2. Status Detalhe Campos'!$D$7:$D$574,"2. Campo")+COUNTIFS('2. Status Detalhe Campos'!$H$7:$H$574,'1. Status Resumo'!$P90,'2. Status Detalhe Campos'!$C$7:$C$574,'1. Status Resumo'!$H$83,'2. Status Detalhe Campos'!$D$7:$D$574,"2. Campo")+COUNTIFS(Table4[Status Anterior],'1. Status Resumo'!$P125,Table4[Sub-âmbito],'1. Status Resumo'!$G$118,Table4[Tipo de teste],"2. Campo") -> 0 | U20: =COUNTIFS('2. Status Detalhe Campos'!$G$7:$G$574,'1. Status Resumo'!$P66,'2. Status Detalhe Campos'!$C$7:$C$574,'1. Status Resumo'!$G$59,'2. Status Detalhe Campos'!$D$7:$D$574,"2. Campo")+COUNTIFS('2. Status Detalhe Campos'!$G$7:$G$574,'1. Status Resumo'!$P66,'2. Status Detalhe Campos'!$C$7:$C$574,'1. Status Resumo'!$H$59,'2. Status Detalhe Campos'!$D$7:$D$574,"2. Campo")+COUNTIFS('2. Status Detalhe Campos'!$G$7:$G$574,'1. Status Resumo'!$P90,'2. Status Detalhe Campos'!$C$7:$C$574,'1. Status Resumo'!$G$83,'2. Status Detalhe Campos'!$D$7:$D$574,"2. Campo")+COUNTIFS('2. Status Detalhe Campos'!$G$7:$G$574,'1. Status Resumo'!$P90,'2. Status Detalhe Campos'!$C$7:$C$574,'1. Status Resumo'!$H$83,'2. Status Detalhe Campos'!$D$7:$D$574,"2. Campo")+COUNTIFS(Table4[Status Atual],'1. Status Resumo'!$P125,Table4[Sub-âmbito],'1. Status Resumo'!$G$118,Table4[Tipo de teste],"2. Campo") -> 12 | V20: =U20-T20 -> 12
P21: 3. Pendente de outros desenvolvimentos | T21: =COUNTIFS('2. Status Detalhe Campos'!$H$7:$H$574,'1. Status Resumo'!$P67,'2. Status Detalhe Campos'!$C$7:$C$574,'1. Status Resumo'!$G$59,'2. Status Detalhe Campos'!$D$7:$D$574,"2. Campo")+COUNTIFS('2. Status Detalhe Campos'!$H$7:$H$574,'1. Status Resumo'!$P67,'2. Status Detalhe Campos'!$C$7:$C$574,'1. Status Resumo'!$H$59,'2. Status Detalhe Campos'!$D$7:$D$574,"2. Campo")+COUNTIFS('2. Status Detalhe Campos'!$H$7:$H$574,'1. Status Resumo'!$P91,'2. Status Detalhe Campos'!$C$7:$C$574,'1. Status Resumo'!$G$83,'2. Status Detalhe Campos'!$D$7:$D$574,"2. Campo")+COUNTIFS('2. Status Detalhe Campos'!$H$7:$H$574,'1. Status Resumo'!$P91,'2. Status Detalhe Campos'!$C$7:$C$574,'1. Status Resumo'!$H$83,'2. Status Detalhe Campos'!$D$7:$D$574,"2. Campo")+COUNTIFS(Table4[Status Anterior],'1. Status Resumo'!$P126,Table4[Sub-âmbito],'1. Status Resumo'!$G$118,Table4[Tipo de teste],"2. Campo") -> 0 | U21: =COUNTIFS('2. Status Detalhe Campos'!$G$7:$G$574,'1. Status Resumo'!$P67,'2. Status Detalhe Campos'!$C$7:$C$574,'1. Status Resumo'!$G$59,'2. Status Detalhe Campos'!$D$7:$D$574,"2. Campo")+COUNTIFS('2. Status Detalhe Campos'!$G$7:$G$574,'1. Status Resumo'!$P67,'2. Status Detalhe Campos'!$C$7:$C$574,'1. Status Resumo'!$H$59,'2. Status Detalhe Campos'!$D$7:$D$574,"2. Campo")+COUNTIFS('2. Status Detalhe Campos'!$G$7:$G$574,'1. Status Resumo'!$P91,'2. Status Detalhe Campos'!$C$7:$C$574,'1. Status Resumo'!$G$83,'2. Status Detalhe Campos'!$D$7:$D$574,"2. Campo")+COUNTIFS('2. Status Detalhe Campos'!$G$7:$G$574,'1. Status Resumo'!$P91,'2. Status Detalhe Campos'!$C$7:$C$574,'1. Status Resumo'!$H$83,'2. Status Detalhe Campos'!$D$7:$D$574,"2. Campo")+COUNTIFS(Table4[Status Atual],'1. Status Resumo'!$P126,Table4[Sub-âmbito],'1. Status Resumo'!$G$118,Table4[Tipo de teste],"2. Campo") -> 0 | V21: =U21-T21 -> 0
P22: 4. Validação EF | T22: =COUNTIFS('2. Status Detalhe Campos'!$H$7:$H$574,'1. Status Resumo'!$P68,'2. Status Detalhe Campos'!$C$7:$C$574,'1. Status Resumo'!$G$59,'2. Status Detalhe Campos'!$D$7:$D$574,"2. Campo")+COUNTIFS('2. Status Detalhe Campos'!$H$7:$H$574,'1. Status Resumo'!$P68,'2. Status Detalhe Campos'!$C$7:$C$574,'1. Status Resumo'!$H$59,'2. Status Detalhe Campos'!$D$7:$D$574,"2. Campo")+COUNTIFS('2. Status Detalhe Campos'!$H$7:$H$574,'1. Status Resumo'!$P92,'2. Status Detalhe Campos'!$C$7:$C$574,'1. Status Resumo'!$G$83,'2. Status Detalhe Campos'!$D$7:$D$574,"2. Campo")+COUNTIFS('2. Status Detalhe Campos'!$H$7:$H$574,'1. Status Resumo'!$P92,'2. Status Detalhe Campos'!$C$7:$C$574,'1. Status Resumo'!$H$83,'2. Status Detalhe Campos'!$D$7:$D$574,"2. Campo")+COUNTIFS(Table4[Status Anterior],'1. Status Resumo'!$P127,Table4[Sub-âmbito],'1. Status Resumo'!$G$118,Table4[Tipo de teste],"2. Campo") -> 3 | U22: =COUNTIFS('2. Status Detalhe Campos'!$G$7:$G$574,'1. Status Resumo'!$P68,'2. Status Detalhe Campos'!$C$7:$C$574,'1. Status Resumo'!$G$59,'2. Status Detalhe Campos'!$D$7:$D$574,"2. Campo")+COUNTIFS('2. Status Detalhe Campos'!$G$7:$G$574,'1. Status Resumo'!$P68,'2. Status Detalhe Campos'!$C$7:$C$574,'1. Status Resumo'!$H$59,'2. Status Detalhe Campos'!$D$7:$D$574,"2. Campo")+COUNTIFS('2. Status Detalhe Campos'!$G$7:$G$574,'1. Status Resumo'!$P92,'2. Status Detalhe Campos'!$C$7:$C$574,'1. Status Resumo'!$G$83,'2. Status Detalhe Campos'!$D$7:$D$574,"2. Campo")+COUNTIFS('2. Status Detalhe Campos'!$G$7:$G$574,'1. Status Resumo'!$P92,'2. Status Detalhe Campos'!$C$7:$C$574,'1. Status Resumo'!$H$83,'2. Status Detalhe Campos'!$D$7:$D$574,"2. Campo")+COUNTIFS(Table4[Status Atual],'1. Status Resumo'!$P127,Table4[Sub-âmbito],'1. Status Resumo'!$G$118,Table4[Tipo de teste],"2. Campo") -> 15 | V22: =U22-T22 -> 12
P23: 5. Em Correção | R23: (incidências) | T23: =COUNTIFS('2. Status Detalhe Campos'!$H$7:$H$574,'1. Status Resumo'!$P69,'2. Status Detalhe Campos'!$C$7:$C$574,'1. Status Resumo'!$G$59,'2. Status Detalhe Campos'!$D$7:$D$574,"2. Campo")+COUNTIFS('2. Status Detalhe Campos'!$H$7:$H$574,'1. Status Resumo'!$P69,'2. Status Detalhe Campos'!$C$7:$C$574,'1. Status Resumo'!$H$59,'2. Status Detalhe Campos'!$D$7:$D$574,"2. Campo")+COUNTIFS('2. Status Detalhe Campos'!$H$7:$H$574,'1. Status Resumo'!$P93,'2. Status Detalhe Campos'!$C$7:$C$574,'1. Status Resumo'!$G$83,'2. Status Detalhe Campos'!$D$7:$D$574,"2. Campo")+COUNTIFS('2. Status Detalhe Campos'!$H$7:$H$574,'1. Status Resumo'!$P93,'2. Status Detalhe Campos'!$C$7:$C$574,'1. Status Resumo'!$H$83,'2. Status Detalhe Campos'!$D$7:$D$574,"2. Campo")+COUNTIFS(Table4[Status Anterior],'1. Status Resumo'!$P128,Table4[Sub-âmbito],'1. Status Resumo'!$G$118,Table4[Tipo de teste],"2. Campo") -> 6 | U23: =COUNTIFS('2. Status Detalhe Campos'!$G$7:$G$574,'1. Status Resumo'!$P69,'2. Status Detalhe Campos'!$C$7:$C$574,'1. Status Resumo'!$G$59,'2. Status Detalhe Campos'!$D$7:$D$574,"2. Campo")+COUNTIFS('2. Status Detalhe Campos'!$G$7:$G$574,'1. Status Resumo'!$P69,'2. Status Detalhe Campos'!$C$7:$C$574,'1. Status Resumo'!$H$59,'2. Status Detalhe Campos'!$D$7:$D$574,"2. Campo")+COUNTIFS('2. Status Detalhe Campos'!$G$7:$G$574,'1. Status Resumo'!$P93,'2. Status Detalhe Campos'!$C$7:$C$574,'1. Status Resumo'!$G$83,'2. Status Detalhe Campos'!$D$7:$D$574,"2. Campo")+COUNTIFS('2. Status Detalhe Campos'!$G$7:$G$574,'1. Status Resumo'!$P93,'2. Status Detalhe Campos'!$C$7:$C$574,'1. Status Resumo'!$H$83,'2. Status Detalhe Campos'!$D$7:$D$574,"2. Campo")+COUNTIFS(Table4[Status Atual],'1. Status Resumo'!$P128,Table4[Sub-âmbito],'1. Status Resumo'!$G$118,Table4[Tipo de teste],"2. Campo") -> 1 | V23: =U23-T23 -> -5
P24: 6. Em implementação (re-especificação) | T24: =COUNTIFS('2. Status Detalhe Campos'!$H$7:$H$574,'1. Status Resumo'!$P70,'2. Status Detalhe Campos'!$C$7:$C$574,'1. Status Resumo'!$G$59,'2. Status Detalhe Campos'!$D$7:$D$574,"2. Campo")+COUNTIFS('2. Status Detalhe Campos'!$H$7:$H$574,'1. Status Resumo'!$P70,'2. Status Detalhe Campos'!$C$7:$C$574,'1. Status Resumo'!$H$59,'2. Status Detalhe Campos'!$D$7:$D$574,"2. Campo")+COUNTIFS('2. Status Detalhe Campos'!$H$7:$H$574,'1. Status Resumo'!$P94,'2. Status Detalhe Campos'!$C$7:$C$574,'1. Status Resumo'!$G$83,'2. Status Detalhe Campos'!$D$7:$D$574,"2. Campo")+COUNTIFS('2. Status Detalhe Campos'!$H$7:$H$574,'1. Status Resumo'!$P94,'2. Status Detalhe Campos'!$C$7:$C$574,'1. Status Resumo'!$H$83,'2. Status Detalhe Campos'!$D$7:$D$574,"2. Campo")+COUNTIFS(Table4[Status Anterior],'1. Status Resumo'!$P129,Table4[Sub-âmbito],'1. Status Resumo'!$G$118,Table4[Tipo de teste],"2. Campo") -> 17 | U24: =COUNTIFS('2. Status Detalhe Campos'!$G$7:$G$574,'1. Status Resumo'!$P70,'2. Status Detalhe Campos'!$C$7:$C$574,'1. Status Resumo'!$G$59,'2. Status Detalhe Campos'!$D$7:$D$574,"2. Campo")+COUNTIFS('2. Status Detalhe Campos'!$G$7:$G$574,'1. Status Resumo'!$P70,'2. Status Detalhe Campos'!$C$7:$C$574,'1. Status Resumo'!$H$59,'2. Status Detalhe Campos'!$D$7:$D$574,"2. Campo")+COUNTIFS('2. Status Detalhe Campos'!$G$7:$G$574,'1. Status Resumo'!$P94,'2. Status Detalhe Campos'!$C$7:$C$574,'1. Status Resumo'!$G$83,'2. Status Detalhe Campos'!$D$7:$D$574,"2. Campo")+COUNTIFS('2. Status Detalhe Campos'!$G$7:$G$574,'1. Status Resumo'!$P94,'2. Status Detalhe Campos'!$C$7:$C$574,'1. Status Resumo'!$H$83,'2. Status Detalhe Campos'!$D$7:$D$574,"2. Campo")+COUNTIFS(Table4[Status Atual],'1. Status Resumo'!$P129,Table4[Sub-âmbito],'1. Status Resumo'!$G$118,Table4[Tipo de teste],"2. Campo") -> 0 | V24: =U24-T24 -> -17
P25: 7. Por iniciar | T25: =COUNTIFS('2. Status Detalhe Campos'!$H$7:$H$574,'1. Status Resumo'!$P71,'2. Status Detalhe Campos'!$C$7:$C$574,'1. Status Resumo'!$G$59,'2. Status Detalhe Campos'!$D$7:$D$574,"2. Campo")+COUNTIFS('2. Status Detalhe Campos'!$H$7:$H$574,'1. Status Resumo'!$P71,'2. Status Detalhe Campos'!$C$7:$C$574,'1. Status Resumo'!$H$59,'2. Status Detalhe Campos'!$D$7:$D$574,"2. Campo")+COUNTIFS('2. Status Detalhe Campos'!$H$7:$H$574,'1. Status Resumo'!$P95,'2. Status Detalhe Campos'!$C$7:$C$574,'1. Status Resumo'!$G$83,'2. Status Detalhe Campos'!$D$7:$D$574,"2. Campo")+COUNTIFS('2. Status Detalhe Campos'!$H$7:$H$574,'1. Status Resumo'!$P95,'2. Status Detalhe Campos'!$C$7:$C$574,'1. Status Resumo'!$H$83,'2. Status Detalhe Campos'!$D$7:$D$574,"2. Campo")+COUNTIFS(Table4[Status Anterior],'1. Status Resumo'!$P130,Table4[Sub-âmbito],'1. Status Resumo'!$G$118,Table4[Tipo de teste],"2. Campo") -> 0 | U25: =COUNTIFS('2. Status Detalhe Campos'!$G$7:$G$574,'1. Status Resumo'!$P71,'2. Status Detalhe Campos'!$C$7:$C$574,'1. Status Resumo'!$G$59,'2. Status Detalhe Campos'!$D$7:$D$574,"2. Campo")+COUNTIFS('2. Status Detalhe Campos'!$G$7:$G$574,'1. Status Resumo'!$P71,'2. Status Detalhe Campos'!$C$7:$C$574,'1. Status Resumo'!$H$59,'2. Status Detalhe Campos'!$D$7:$D$574,"2. Campo")+COUNTIFS('2. Status Detalhe Campos'!$G$7:$G$574,'1. Status Resumo'!$P95,'2. Status Detalhe Campos'!$C$7:$C$574,'1. Status Resumo'!$G$83,'2. Status Detalhe Campos'!$D$7:$D$574,"2. Campo")+COUNTIFS('2. Status Detalhe Campos'!$G$7:$G$574,'1. Status Resumo'!$P95,'2. Status Detalhe Campos'!$C$7:$C$574,'1. Status Resumo'!$H$83,'2. Status Detalhe Campos'!$D$7:$D$574,"2. Campo")+COUNTIFS(Table4[Status Atual],'1. Status Resumo'!$P130,Table4[Sub-âmbito],'1. Status Resumo'!$G$118,Table4[Tipo de teste],"2. Campo") -> 0 | V25: =U25-T25 -> 0
T26: =SUM(T17:T25) -> 549 | U26: =SUM(U17:U25) -> 549
B30: 1. Plano de Testes
X34: Highlights
D35: T. Campos | E35: T. Concluídos | F35: T. Cancelados | G35: Por testar | H35: 45646 | I35: 45649 | J35: 20 e 23 / Dez | K35: 45660 | L35: 45667 | M35: 45667 | N35: 45674 | O35: 45678 | P35: Plano | X35: Testes 20 e 23/Dez: 1. Modelo Verde: Foram concluídos 11 campos dos 16 previstos da tabela de output de Clientes. 5 necessitam de re-especificação devido a alterações de inputs. 2. Pilar III: Dos 29 campos previstos fechar no Pilar III foram concluídos 15. - 6 foram testados mas reportados com incidências - 2 não foram possíveis testar por dependência da atualização das Categorias SFICS - 3 estão pendentes: a) da atualização da tabela de parametrização de Marcação Verde do Modelo Verde; b) Da implementação do campo 'cagarant_bem' da tabela de Bens do Modelo de Bens Imóveis - Não foi possível concluir os testes de 6 campos para a totalidade do universo Testes 10/Jan: 1. Modelo Bens Imóveis: Está previsto testar 13 campos do Modelo verde 2. Modelo Verde: Está previsto testar 5 campos que não foram possíveis testar a 20 e 23 /Dez 3. Pilar III: Está previsto testar 14 campos que não foram possíveis testar a 20 e 23 /Dez
C36: MBI | D36: =T72 -> 169 | E36: =T64 -> 146 | F36: =T63 -> 10 | G36: =D36-E36-F36 -> 13 | H36: 0 | I36: 0 | J36: 0 | K36: 0 | L36: 13 | M36: 13 | N36: 0 | O36: 0 | P36: =SUM(M36:O36) -> 13
C37: MV | D37: =T96 -> 245 | E37: =T88 -> 209 | F37: =T87 -> 14 | G37: =D37-E37-F37 -> 22 | H37: 16 | I37: 0 | J37: 11 | K37: 0 | L37: 0 | M37: 5 | N37: =4+12 -> 16 | O37: tbd | P37: =SUM(M37:O37) -> 21
C38: Pilar III | D38: =T131 -> 135 | E38: =T123 -> 118 | F38: =T122 -> 0 | G38: =D38-E38-F38 -> 17 | H38: 23 | I38: 6 | J38: 15 | K38: 0 | L38: 0 | M38: 14 | N38: 3 | O38: 0 | P38: =SUM(M38:O38) -> 17
C39: TOTAL | D39: =SUM(D36:D38) -> 549 | E39: =SUM(E36:E38) -> 473 | F39: =SUM(F36:F38) -> 24 | G39: =SUM(G36:G38) -> 52 | H39: =SUM(H36:H38) -> 39 | I39: 6 | J39: =SUM(J36:J38) -> 26 | K39: 0 | L39: 13 | M39: =SUM(M36:M38) -> 32 | N39: =SUM(N36:N38) -> 19 | O39: 0 | P39: =SUM(P36:P38) -> 51
C40: Status | E40: =E39/$D$39 -> 0.86156648 | F40: =F39/$D$39 -> 0.043715847 | G40: =G39/$D$39 -> 0.094717668
C41: Satus s/ cancelados | E41: =E39/($D$39-$F$39) -> 0.90095238 | F41: - | G41: =G39/($D$39-$F$39) -> 0.099047619
D44: T. Campos | E44: T. Concluídos | F44: T. Cancelados | G44: Por testar | H44: 20 e 23 / Dez | I44: 45660 | J44: 45667 | K44: 45674 | L44: 45678 | M44: Plano
C45: MBI | D45: =U72 -> 169 | E45: =U64 -> 147 | F45: =U63 -> 10 | G45: =D45-E45-F45 -> 12 | H45: 0 | I45: 0 | J45: 13 | K45: 0 | L45: 0 | M45: =SUM(I45:L45) -> 13
C46: MV | D46: =U96 -> 245 | E46: =U88 -> 205 | F46: =U87 -> 14 | G46: =D46-E46-F46 -> 26 | H46: 11 | I46: 0 | J46: 5 | K46: =4+12 -> 16 | L46: tbd | M46: =SUM(I46:L46) -> 21
C47: Pilar III | D47: =U131 -> 135 | E47: =U123 -> 120 | F47: =U122 -> 0 | G47: =D47-E47-F47 -> 15 | H47: 15 | I47: 0 | J47: 14 | K47: 3 | L47: 0 | M47: =SUM(I47:L47) -> 17
C48: TOTAL | D48: =SUM(D45:D47) -> 549 | E48: =SUM(E45:E47) -> 472 | F48: =SUM(F45:F47) -> 24 | G48: =SUM(G45:G47) -> 53 | H48: =SUM(H45:H47) -> 26 | I48: =SUM(I45:I47) -> 0 | J48: =SUM(J45:J47) -> 32 | K48: =SUM(K45:K47) -> 19 | L48: 0 | M48: =SUM(M45:M47) -> 51
C49: Status | E49: =E48/$D$48 -> 0.85974499 | F49: =F48/$D$48 -> 0.043715847 | G49: =G48/$D$48 -> 0.096539162
C50: Satus s/ cancelados | E50: =E48/($D$48-F48) -> 0.89904762 | F50: - | G50: =G48/($D$48-F48) -> 0.10095238
B59: 2. Modelo de Bens Imóveis | G59: Bens Imóveis - Input | H59: Bens Imóveis - Output | I59: Modelo Verde - Input | J59: Modelo Verde - Output | K59: Pilar III
C62: Resumo | G62: Detalhe por Tabela | P62: Status (campos) | T62: 45639 | U62: =T62+10 -> 45649 | V62: ∆ | X62: Highlights
P63: 0. Cancelado | T63: =COUNTIFS('2. Status Detalhe Campos'!$H$7:$H$574,'1. Status Resumo'!$P63,'2. Status Detalhe Campos'!$C$7:$C$574,'1. Status Resumo'!$G$59,'2. Status Detalhe Campos'!$D$7:$D$574,"2. Campo")+COUNTIFS('2. Status Detalhe Campos'!$H$7:$H$574,'1. Status Resumo'!$P63,'2. Status Detalhe Campos'!$C$7:$C$574,'1. Status Resumo'!$H$59,'2. Status Detalhe Campos'!$D$7:$D$574,"2. Campo") -> 10 | U63: =COUNTIFS('2. Status Detalhe Campos'!$G$7:$G$574,'1. Status Resumo'!$P63,'2. Status Detalhe Campos'!$C$7:$C$574,'1. Status Resumo'!$G$59,'2. Status Detalhe Campos'!$D$7:$D$574,"2. Campo")+COUNTIFS('2. Status Detalhe Campos'!$G$7:$G$574,'1. Status Resumo'!$P63,'2. Status Detalhe Campos'!$C$7:$C$574,'1. Status Resumo'!$H$59,'2. Status Detalhe Campos'!$D$7:$D$574,"2. Campo") -> 10 | V63: =U63-T63 -> 0 | X63: 1. Testes: - Testado o campo CGARANT_BEM (tabela Property), o que permitiu dar a tabela como terminada - Conforme previsto, foram realizados os testes à tabela de input da Gloval bem como à tabela unificada/ traçabilidade. Contudo, a tabela de input encontra-se em Validação EF uma vez que está dependente de validação do CDO.
P64: 1. Concluído | T64: =COUNTIFS('2. Status Detalhe Campos'!$H$7:$H$574,'1. Status Resumo'!$P64,'2. Status Detalhe Campos'!$C$7:$C$574,'1. Status Resumo'!$G$59,'2. Status Detalhe Campos'!$D$7:$D$574,"2. Campo")+COUNTIFS('2. Status Detalhe Campos'!$H$7:$H$574,'1. Status Resumo'!$P64,'2. Status Detalhe Campos'!$C$7:$C$574,'1. Status Resumo'!$H$59,'2. Status Detalhe Campos'!$D$7:$D$574,"2. Campo") -> 146 | U64: =COUNTIFS('2. Status Detalhe Campos'!$G$7:$G$574,'1. Status Resumo'!$P64,'2. Status Detalhe Campos'!$C$7:$C$574,'1. Status Resumo'!$G$59,'2. Status Detalhe Campos'!$D$7:$D$574,"2. Campo")+COUNTIFS('2. Status Detalhe Campos'!$G$7:$G$574,'1. Status Resumo'!$P64,'2. Status Detalhe Campos'!$C$7:$C$574,'1. Status Resumo'!$H$59,'2. Status Detalhe Campos'!$D$7:$D$574,"2. Campo") -> 147 | V64: =U64-T64 -> 1
P65: 2.1 Em Teste | T65: =COUNTIFS('2. Status Detalhe Campos'!$H$7:$H$574,'1. Status Resumo'!$P65,'2. Status Detalhe Campos'!$C$7:$C$574,'1. Status Resumo'!$G$59,'2. Status Detalhe Campos'!$D$7:$D$574,"2. Campo")+COUNTIFS('2. Status Detalhe Campos'!$H$7:$H$574,'1. Status Resumo'!$P65,'2. Status Detalhe Campos'!$C$7:$C$574,'1. Status Resumo'!$H$59,'2. Status Detalhe Campos'!$D$7:$D$574,"2. Campo") -> 1 | U65: =COUNTIFS('2. Status Detalhe Campos'!$G$7:$G$574,'1. Status Resumo'!$P65,'2. Status Detalhe Campos'!$C$7:$C$574,'1. Status Resumo'!$G$59,'2. Status Detalhe Campos'!$D$7:$D$574,"2. Campo")+COUNTIFS('2. Status Detalhe Campos'!$G$7:$G$574,'1. Status Resumo'!$P65,'2. Status Detalhe Campos'!$C$7:$C$574,'1. Status Resumo'!$H$59,'2. Status Detalhe Campos'!$D$7:$D$574,"2. Campo") -> 0 | V65: =U65-T65 -> -1
D66: ="# "&U72 -> # 169 | P66: 2.2 Em Re-especificação | T66: =COUNTIFS('2. Status Detalhe Campos'!$H$7:$H$574,'1. Status Resumo'!$P66,'2. Status Detalhe Campos'!$C$7:$C$574,'1. Status Resumo'!$G$59,'2. Status Detalhe Campos'!$D$7:$D$574,"2. Campo")+COUNTIFS('2. Status Detalhe Campos'!$H$7:$H$574,'1. Status Resumo'!$P66,'2. Status Detalhe Campos'!$C$7:$C$574,'1. Status Resumo'!$H$59,'2. Status Detalhe Campos'!$D$7:$D$574,"2. Campo") -> 0 | U66: =COUNTIFS('2. Status Detalhe Campos'!$G$7:$G$574,'1. Status Resumo'!$P66,'2. Status Detalhe Campos'!$C$7:$C$574,'1. Status Resumo'!$G$59,'2. Status Detalhe Campos'!$D$7:$D$574,"2. Campo")+COUNTIFS('2. Status Detalhe Campos'!$G$7:$G$574,'1. Status Resumo'!$P66,'2. Status Detalhe Campos'!$C$7:$C$574,'1. Status Resumo'!$H$59,'2. Status Detalhe Campos'!$D$7:$D$574,"2. Campo") -> 0 | V66: =U66-T66 -> 0
P67: 3. Pendente de outros desenvolvimentos | T67: =COUNTIFS('2. Status Detalhe Campos'!$H$7:$H$574,'1. Status Resumo'!$P67,'2. Status Detalhe Campos'!$C$7:$C$574,'1. Status Resumo'!$G$59,'2. Status Detalhe Campos'!$D$7:$D$574,"2. Campo")+COUNTIFS('2. Status Detalhe Campos'!$H$7:$H$574,'1. Status Resumo'!$P67,'2. Status Detalhe Campos'!$C$7:$C$574,'1. Status Resumo'!$H$59,'2. Status Detalhe Campos'!$D$7:$D$574,"2. Campo") -> 0 | U67: =COUNTIFS('2. Status Detalhe Campos'!$G$7:$G$574,'1. Status Resumo'!$P67,'2. Status Detalhe Campos'!$C$7:$C$574,'1. Status Resumo'!$G$59,'2. Status Detalhe Campos'!$D$7:$D$574,"2. Campo")+COUNTIFS('2. Status Detalhe Campos'!$G$7:$G$574,'1. Status Resumo'!$P67,'2. Status Detalhe Campos'!$C$7:$C$574,'1. Status Resumo'!$H$59,'2. Status Detalhe Campos'!$D$7:$D$574,"2. Campo") -> 0 | V67: =U67-T67 -> 0
P68: 4. Validação EF | T68: =COUNTIFS('2. Status Detalhe Campos'!$H$7:$H$574,'1. Status Resumo'!$P68,'2. Status Detalhe Campos'!$C$7:$C$574,'1. Status Resumo'!$G$59,'2. Status Detalhe Campos'!$D$7:$D$574,"2. Campo")+COUNTIFS('2. Status Detalhe Campos'!$H$7:$H$574,'1. Status Resumo'!$P68,'2. Status Detalhe Campos'!$C$7:$C$574,'1. Status Resumo'!$H$59,'2. Status Detalhe Campos'!$D$7:$D$574,"2. Campo") -> 0 | U68: =COUNTIFS('2. Status Detalhe Campos'!$G$7:$G$574,'1. Status Resumo'!$P68,'2. Status Detalhe Campos'!$C$7:$C$574,'1. Status Resumo'!$G$59,'2. Status Detalhe Campos'!$D$7:$D$574,"2. Campo")+COUNTIFS('2. Status Detalhe Campos'!$G$7:$G$574,'1. Status Resumo'!$P68,'2. Status Detalhe Campos'!$C$7:$C$574,'1. Status Resumo'!$H$59,'2. Status Detalhe Campos'!$D$7:$D$574,"2. Campo") -> 12 | V68: =U68-T68 -> 12
P69: 5. Em Correção | R69: (incidências) | T69: =COUNTIFS('2. Status Detalhe Campos'!$H$7:$H$574,'1. Status Resumo'!$P69,'2. Status Detalhe Campos'!$C$7:$C$574,'1. Status Resumo'!$G$59,'2. Status Detalhe Campos'!$D$7:$D$574,"2. Campo")+COUNTIFS('2. Status Detalhe Campos'!$H$7:$H$574,'1. Status Resumo'!$P69,'2. Status Detalhe Campos'!$C$7:$C$574,'1. Status Resumo'!$H$59,'2. Status Detalhe Campos'!$D$7:$D$574,"2. Campo") -> 0 | U69: =COUNTIFS('2. Status Detalhe Campos'!$G$7:$G$574,'1. Status Resumo'!$P69,'2. Status Detalhe Campos'!$C$7:$C$574,'1. Status Resumo'!$G$59,'2. Status Detalhe Campos'!$D$7:$D$574,"2. Campo")+COUNTIFS('2. Status Detalhe Campos'!$G$7:$G$574,'1. Status Resumo'!$P69,'2. Status Detalhe Campos'!$C$7:$C$574,'1. Status Resumo'!$H$59,'2. Status Detalhe Campos'!$D$7:$D$574,"2. Campo") -> 0 | V69: =U69-T69 -> 0
P70: 6. Em implementação (re-especificação) | T70: =COUNTIFS('2. Status Detalhe Campos'!$H$7:$H$574,'1. Status Resumo'!$P70,'2. Status Detalhe Campos'!$C$7:$C$574,'1. Status Resumo'!$G$59,'2. Status Detalhe Campos'!$D$7:$D$574,"2. Campo")+COUNTIFS('2. Status Detalhe Campos'!$H$7:$H$574,'1. Status Resumo'!$P70,'2. Status Detalhe Campos'!$C$7:$C$574,'1. Status Resumo'!$H$59,'2. Status Detalhe Campos'!$D$7:$D$574,"2. Campo") -> 12 | U70: =COUNTIFS('2. Status Detalhe Campos'!$G$7:$G$574,'1. Status Resumo'!$P70,'2. Status Detalhe Campos'!$C$7:$C$574,'1. Status Resumo'!$G$59,'2. Status Detalhe Campos'!$D$7:$D$574,"2. Campo")+COUNTIFS('2. Status Detalhe Campos'!$G$7:$G$574,'1. Status Resumo'!$P70,'2. Status Detalhe Campos'!$C$7:$C$574,'1. Status Resumo'!$H$59,'2. Status Detalhe Campos'!$D$7:$D$574,"2. Campo") -> 0 | V70: =U70-T70 -> -12
...

Sheet 2. Status Detalhe Campos
B6: Âmbito | C6: Sub-âmbito | D6: Tipo de teste | E6: Tabela | F6: Campo | G6: Status Atual | H6: Status Anterior | I6: Observações | J6: Data de Pedido correção/esclarecimento | K6: Data de correção prevista | L6: Data de correção efetiva | M6: Data Prevista de Re-especificação | N6: Data Prevista de Teste | O6: Modelo
A7: =E7&F7 -> ENERGY_CERTIFICATE_EST_INPUTn.a. | B7: Pilar III | C7: Bens Imóveis - Input | D7: 1. Universo | E7: ENERGY_CERTIFICATE_EST_INPUT | F7: n.a. | G7: =VLOOKUP(A7,Plano_V3!$A$26:$G$592,7,0) -> 4. Validação EF | H7: 6. Em implementação (re-especificação) | I7: A validar por CDO | J7: =IF(VLOOKUP(A7,'Aux - pivots1'!$A:$E,3,0)=0, "",VLOOKUP(A7,'Aux - pivots1'!$A:$E,3,0)) -> 45510 | K7: =IF(VLOOKUP(A7,'Aux - pivots1'!$A:$E,4,0)=0, "",VLOOKUP(A7,'Aux - pivots1'!$A:$E,4,0)) -> 45624 | L7: =IF(VLOOKUP(A7,'Aux - pivots1'!$A:$E,5,0)=0, "",VLOOKUP(A7,'Aux - pivots1'!$A:$E,5,0)) | O7: Bens Imóveis
A8: =E8&F8 -> ENERGY_CERTIFICATE_EST_INPUTPROPERTY_BANK_ID | B8: Pilar III | C8: Bens Imóveis - Input | D8: 2. Campo | E8: ENERGY_CERTIFICATE_EST_INPUT | F8: PROPERTY_BANK_ID | G8: =VLOOKUP(A8,Plano_V3!$A$26:$G$592,7,0) -> 4. Validação EF | H8: 6. Em implementação (re-especificação) | I8: A validar por CDO | J8: =IF(VLOOKUP(A8,'Aux - pivots1'!$A:$E,3,0)=0, "",VLOOKUP(A8,'Aux - pivots1'!$A:$E,3,0)) -> 45510 | K8: =IF(VLOOKUP(A8,'Aux - pivots1'!$A:$E,4,0)=0, "",VLOOKUP(A8,'Aux - pivots1'!$A:$E,4,0)) -> 45624 | L8: =IF(VLOOKUP(A8,'Aux - pivots1'!$A:$E,5,0)=0, "",VLOOKUP(A8,'Aux - pivots1'!$A:$E,5,0)) | O8: Bens Imóveis
A9: =E9&F9 -> ENERGY_CERTIFICATE_EST_INPUTENCRYPTED_KEY | B9: Pilar III | C9: Bens Imóveis - Input | D9: 2. Campo | E9: ENERGY_CERTIFICATE_EST_INPUT | F9: ENCRYPTED_KEY | G9: =VLOOKUP(A9,Plano_V3!$A$26:$G$592,7,0) -> 4. Validação EF | H9: 6. Em implementação (re-especificação) | I9: A validar por CDO | J9: =IF(VLOOKUP(A9,'Aux - pivots1'!$A:$E,3,0)=0, "",VLOOKUP(A9,'Aux - pivots1'!$A:$E,3,0)) -> 45510 | K9: =IF(VLOOKUP(A9,'Aux - pivots1'!$A:$E,4,0)=0, "",VLOOKUP(A9,'Aux - pivots1'!$A:$E,4,0)) -> 45624 | L9: =IF(VLOOKUP(A9,'Aux - pivots1'!$A:$E,5,0)=0, "",VLOOKUP(A9,'Aux - pivots1'!$A:$E,5,0)) | O9: Bens Imóveis
A10: =E10&F10 -> ENERGY_CERTIFICATE_EST_INPUTPROPERTY_BRANCH_CODE | B10: Pilar III | C10: Bens Imóveis - Input | D10: 2. Campo | E10: ENERGY_CERTIFICATE_EST_INPUT | F10: PROPERTY_BRANCH_CODE | G10: =VLOOKUP(A10,Plano_V3!$A$26:$G$592,7,0) -> 4. Validação EF | H10: 6. Em implementação (re-especificação) | I10: A validar por CDO | J10: =IF(VLOOKUP(A10,'Aux - pivots1'!$A:$E,3,0)=0, "",VLOOKUP(A10,'Aux - pivots1'!$A:$E,3,0)) -> 45510 | K10: =IF(VLOOKUP(A10,'Aux - pivots1'!$A:$E,4,0)=0, "",VLOOKUP(A10,'Aux - pivots1'!$A:$E,4,0)) -> 45624 | L10: =IF(VLOOKUP(A10,'Aux - pivots1'!$A:$E,5,0)=0, "",VLOOKUP(A10,'Aux - pivots1'!$A:$E,5,0)) | O10: Bens Imóveis
A11: =E11&F11 -> ENERGY_CERTIFICATE_EST_INPUTPROPERTY_CONTRACT_ID | B11: Pilar III | C11: Bens Imóveis - Input | D11: 2. Campo | E11: ENERGY_CERTIFICATE_EST_INPUT | F11: PROPERTY_CONTRACT_ID | G11: =VLOOKUP(A11,Plano_V3!$A$26:$G$592,7,0) -> 4. Validação EF | H11: 6. Em implementação (re-especificação) | I11: A validar por CDO | J11: =IF(VLOOKUP(A11,'Aux - pivots1'!$A:$E,3,0)=0, "",VLOOKUP(A11,'Aux - pivots1'!$A:$E,3,0)) -> 45510 | K11: =IF(VLOOKUP(A11,'Aux - pivots1'!$A:$E,4,0)=0, "",VLOOKUP(A11,'Aux - pivots1'!$A:$E,4,0)) -> 45624 | L11: =IF(VLOOKUP(A11,'Aux - pivots1'!$A:$E,5,0)=0, "",VLOOKUP(A11,'Aux - pivots1'!$A:$E,5,0)) | O11: Bens Imóveis
A12: =E12&F12 -> ENERGY_CERTIFICATE_EST_INPUTPROPERTY_REFERENCE_CODE | B12: Pilar III | C12: Bens Imóveis - Input | D12: 2. Campo | E12: ENERGY_CERTIFICATE_EST_INPUT | F12: PROPERTY_REFERENCE_CODE | G12: =VLOOKUP(A12,Plano_V3!$A$26:$G$592,7,0) -> 4. Validação EF | H12: 6. Em implementação (re-especificação) | I12: A validar por CDO | J12: =IF(VLOOKUP(A12,'Aux - pivots1'!$A:$E,3,0)=0, "",VLOOKUP(A12,'Aux - pivots1'!$A:$E,3,0)) -> 45510 | K12: =IF(VLOOKUP(A12,'Aux - pivots1'!$A:$E,4,0)=0, "",VLOOKUP(A12,'Aux - pivots1'!$A:$E,4,0)) -> 45624 | L12: =IF(VLOOKUP(A12,'Aux - pivots1'!$A:$E,5,0)=0, "",VLOOKUP(A12,'Aux - pivots1'!$A:$E,5,0)) | O12: Bens Imóveis
A13: =E13&F13 -> ENERGY_CERTIFICATE_EST_INPUTDATA_EXTRACTION_DATE | B13: Pilar III | C13: Bens Imóveis - Input | D13: 2. Campo | E13: ENERGY_CERTIFICATE_EST_INPUT | F13: DATA_EXTRACTION_DATE | G13: =VLOOKUP(A13,Plano_V3!$A$26:$G$592,7,0) -> 4. Validação EF | H13: 6. Em implementação (re-especificação) | I13: A validar por CDO | J13: =IF(VLOOKUP(A13,'Aux - pivots1'!$A:$E,3,0)=0, "",VLOOKUP(A13,'Aux - pivots1'!$A:$E,3,0)) -> 45510 | K13: =IF(VLOOKUP(A13,'Aux - pivots1'!$A:$E,4,0)=0, "",VLOOKUP(A13,'Aux - pivots1'!$A:$E,4,0)) -> 45624 | L13: =IF(VLOOKUP(A13,'Aux - pivots1'!$A:$E,5,0)=0, "",VLOOKUP(A13,'Aux - pivots1'!$A:$E,5,0)) | O13: Bens Imóveis
A14: =E14&F14 -> ENERGY_CERTIFICATE_EST_INPUTEPC | B14: Pilar III | C14: Bens Imóveis - Input | D14: 2. Campo | E14: ENERGY_CERTIFICATE_EST_INPUT | F14: EPC | G14: =VLOOKUP(A14,Plano_V3!$A$26:$G$592,7,0) -> 4. Validação EF | H14: 6. Em implementação (re-especificação) | I14: A validar por CDO | J14: =IF(VLOOKUP(A14,'Aux - pivots1'!$A:$E,3,0)=0, "",VLOOKUP(A14,'Aux - pivots1'!$A:$E,3,0)) -> 45510 | K14: =IF(VLOOKUP(A14,'Aux - pivots1'!$A:$E,4,0)=0, "",VLOOKUP(A14,'Aux - pivots1'!$A:$E,4,0)) -> 45624 | L14: =IF(VLOOKUP(A14,'Aux - pivots1'!$A:$E,5,0)=0, "",VLOOKUP(A14,'Aux - pivots1'!$A:$E,5,0)) | O14: Bens Imóveis
A15: =E15&F15 -> ENERGY_CERTIFICATE_EST_INPUTDATA_PROVIDER | B15: Pilar III | C15: Bens Imóveis - Input | D15: 2. Campo | E15: ENERGY_CERTIFICATE_EST_INPUT | F15: DATA_PROVIDER | G15: =VLOOKUP(A15,Plano_V3!$A$26:$G$592,7,0) -> 4. Validação EF | H15: 6. Em implementação (re-especificação) | I15: A validar por CDO | J15: =IF(VLOOKUP(A15,'Aux - pivots1'!$A:$E,3,0)=0, "",VLOOKUP(A15,'Aux - pivots1'!$A:$E,3,0)) -> 45510 | K15: =IF(VLOOKUP(A15,'Aux - pivots1'!$A:$E,4,0)=0, "",VLOOKUP(A15,'Aux - pivots1'!$A:$E,4,0)) -> 45624 | L15: =IF(VLOOKUP(A15,'Aux - pivots1'!$A:$E,5,0)=0, "",VLOOKUP(A15,'Aux - pivots1'!$A:$E,5,0)) | O15: Bens Imóveis
A16: =E16&F16 -> ENERGY_CERTIFICATE_EST_INPUTACTUAL_VALUE_IND | B16: Pilar III | C16: Bens Imóveis - Input | D16: 2. Campo | E16: ENERGY_CERTIFICATE_EST_INPUT | F16: ACTUAL_VALUE_IND | G16: =VLOOKUP(A16,Plano_V3!$A$26:$G$592,7,0) -> 4. Validação EF | H16: 6. Em implementação (re-especificação) | I16: A validar por CDO | J16: =IF(VLOOKUP(A16,'Aux - pivots1'!$A:$E,3,0)=0, "",VLOOKUP(A16,'Aux - pivots1'!$A:$E,3,0)) -> 45510 | K16: =IF(VLOOKUP(A16,'Aux - pivots1'!$A:$E,4,0)=0, "",VLOOKUP(A16,'Aux - pivots1'!$A:$E,4,0)) -> 45624 | L16: =IF(VLOOKUP(A16,'Aux - pivots1'!$A:$E,5,0)=0, "",VLOOKUP(A16,'Aux - pivots1'!$A:$E,5,0)) | O16: Bens Imóveis
A17: =E17&F17 -> ENERGY_CERTIFICATE_EST_INPUTQUALITY_SCORE | B17: Pilar III | C17: Bens Imóveis - Input | D17: 2. Campo | E17: ENERGY_CERTIFICATE_EST_INPUT | F17: QUALITY_SCORE | G17: =VLOOKUP(A17,Plano_V3!$A$26:$G$592,7,0) -> 4. Validação EF | H17: 6. Em implementação (re-especificação) | I17: A validar por CDO | J17: =IF(VLOOKUP(A17,'Aux - pivots1'!$A:$E,3,0)=0, "",VLOOKUP(A17,'Aux - pivots1'!$A:$E,3,0)) -> 45510 | K17: =IF(VLOOKUP(A17,'Aux - pivots1'!$A:$E,4,0)=0, "",VLOOKUP(A17,'Aux - pivots1'!$A:$E,4,0)) -> 45624 | L17: =IF(VLOOKUP(A17,'Aux - pivots1'!$A:$E,5,0)=0, "",VLOOKUP(A17,'Aux - pivots1'!$A:$E,5,0)) | O17: Bens Imóveis
A18: =E18&F18 -> ENERGY_CERTIFICATE_EST_INPUTENERGY_CONSUMPTION_VALUE_YEAR | B18: Pilar III | C18: Bens Imóveis - Input | D18: 2. Campo | E18: ENERGY_CERTIFICATE_EST_INPUT | F18: ENERGY_CONSUMPTION_VALUE_YEAR | G18: =VLOOKUP(A18,Plano_V3!$A$26:$G$592,7,0) -> 4. Validação EF | H18: 6. Em implementação (re-especificação) | I18: A validar por CDO | J18: =IF(VLOOKUP(A18,'Aux - pivots1'!$A:$E,3,0)=0, "",VLOOKUP(A18,'Aux - pivots1'!$A:$E,3,0)) -> 45510 | K18: =IF(VLOOKUP(A18,'Aux - pivots1'!$A:$E,4,0)=0, "",VLOOKUP(A18,'Aux - pivots1'!$A:$E,4,0)) -> 45624 | L18: =IF(VLOOKUP(A18,'Aux - pivots1'!$A:$E,5,0)=0, "",VLOOKUP(A18,'Aux - pivots1'!$A:$E,5,0)) | O18: Bens Imóveis
A19: =E19&F19 -> ENERGY_CERTIFICATE_EST_INPUTCARBON_EMISSION_VALUE_YEAR | B19: Pilar III | C19: Bens Imóveis - Input | D19: 2. Campo | E19: ENERGY_CERTIFICATE_EST_INPUT | F19: CARBON_EMISSION_VALUE_YEAR | G19: =VLOOKUP(A19,Plano_V3!$A$26:$G$592,7,0) -> 4. Validação EF | H19: 6. Em implementação (re-especificação) | I19: A validar por CDO | J19: =IF(VLOOKUP(A19,'Aux - pivots1'!$A:$E,3,0)=0, "",VLOOKUP(A19,'Aux - pivots1'!$A:$E,3,0)) -> 45510 | K19: =IF(VLOOKUP(A19,'Aux - pivots1'!$A:$E,4,0)=0, "",VLOOKUP(A19,'Aux - pivots1'!$A:$E,4,0)) -> 45624 | L19: =IF(VLOOKUP(A19,'Aux - pivots1'!$A:$E,5,0)=0, "",VLOOKUP(A19,'Aux - pivots1'!$A:$E,5,0)) | O19: Bens Imóveis
A20: =E20&F20 -> PROCESSn.a. | B20: Pilar III | C20: Bens Imóveis - Output | D20: 1. Universo | E20: PROCESS | F20: n.a. | G20: =VLOOKUP(A20,Plano_V3!$A$26:$G$592,7,0) -> 1. Concluído | H20: 1. Concluído | J20: =IF(VLOOKUP(A20,'Aux - pivots1'!$A:$E,3,0)=0, "",VLOOKUP(A20,'Aux - pivots1'!$A:$E,3,0)) | K20: =IF(VLOOKUP(A20,'Aux - pivots1'!$A:$E,4,0)=0, "",VLOOKUP(A20,'Aux - pivots1'!$A:$E,4,0)) | L20: =IF(VLOOKUP(A20,'Aux - pivots1'!$A:$E,5,0)=0, "",VLOOKUP(A20,'Aux - pivots1'!$A:$E,5,0)) | O20: Bens Imóveis
A21: =E21&F21 -> PROCESSPROCESS_BANK_ID | B21: Pilar III | C21: Bens Imóveis - Output | D21: 2. Campo | E21: PROCESS | F21: PROCESS_BANK_ID | G21: =VLOOKUP(A21,Plano_V3!$A$26:$G$592,7,0) -> 1. Concluído | H21: 1. Concluído | I21: 26/07/2024: Conclusão de testes ao universo MUG e GP. Adjudicados fora de âmbito deste projeto. | J21: =IF(VLOOKUP(A21,'Aux - pivots1'!$A:$E,3,0)=0, "",VLOOKUP(A21,'Aux - pivots1'!$A:$E,3,0)) | K21: =IF(VLOOKUP(A21,'Aux - pivots1'!$A:$E,4,0)=0, "",VLOOKUP(A21,'Aux - pivots1'!$A:$E,4,0)) | L21: =IF(VLOOKUP(A21,'Aux - pivots1'!$A:$E,5,0)=0, "",VLOOKUP(A21,'Aux - pivots1'!$A:$E,5,0)) | O21: Bens Imóveis
A22: =E22&F22 -> PROCESSPROCESS_BRANCH_CODE | B22: Pilar III | C22: Bens Imóveis - Output | D22: 2. Campo | E22: PROCESS | F22: PROCESS_BRANCH_CODE | G22: =VLOOKUP(A22,Plano_V3!$A$26:$G$592,7,0) -> 1. Concluído | H22: 1. Concluído | I22: 26/07/2024: Conclusão de testes ao universo MUG e GP. Adjudicados fora de âmbito deste projeto. | J22: =IF(VLOOKUP(A22,'Aux - pivots1'!$A:$E,3,0)=0, "",VLOOKUP(A22,'Aux - pivots1'!$A:$E,3,0)) | K22: =IF(VLOOKUP(A22,'Aux - pivots1'!$A:$E,4,0)=0, "",VLOOKUP(A22,'Aux - pivots1'!$A:$E,4,0)) | L22: =IF(VLOOKUP(A22,'Aux - pivots1'!$A:$E,5,0)=0, "",VLOOKUP(A22,'Aux - pivots1'!$A:$E,5,0)) | O22: Bens Imóveis
A23: =E23&F23 -> PROCESSPROCESS_ACCOUNT_ID | B23: Pilar III | C23: Bens Imóveis - Output | D23: 2. Campo | E23: PROCESS | F23: PROCESS_ACCOUNT_ID | G23: =VLOOKUP(A23,Plano_V3!$A$26:$G$592,7,0) -> 1. Concluído | H23: 1. Concluído | I23: 26/07/2024: Conclusão de testes ao universo MUG e GP. Adjudicados fora de âmbito deste projeto. | J23: =IF(VLOOKUP(A23,'Aux - pivots1'!$A:$E,3,0)=0, "",VLOOKUP(A23,'Aux - pivots1'!$A:$E,3,0)) | K23: =IF(VLOOKUP(A23,'Aux - pivots1'!$A:$E,4,0)=0, "",VLOOKUP(A23,'Aux - pivots1'!$A:$E,4,0)) | L23: =IF(VLOOKUP(A23,'Aux - pivots1'!$A:$E,5,0)=0, "",VLOOKUP(A23,'Aux - pivots1'!$A:$E,5,0)) | O23: Bens Imóveis
A24: =E24&F24 -> PROCESScod_estd_prcs | B24: Pilar III | C24: Bens Imóveis - Output | D24: 2. Campo | E24: PROCESS | F24: cod_estd_prcs | G24: =VLOOKUP(A24,Plano_V3!$A$26:$G$592,7,0) -> 0. Cancelado | H24: 0. Cancelado | I24: 19/07/2024: Campo eliminado do Modelo para garantir coerência com MUG | J24: =IF(VLOOKUP(A24,'Aux - pivots1'!$A:$E,3,0)=0, "",VLOOKUP(A24,'Aux - pivots1'!$A:$E,3,0)) | K24: =IF(VLOOKUP(A24,'Aux - pivots1'!$A:$E,4,0)=0, "",VLOOKUP(A24,'Aux - pivots1'!$A:$E,4,0)) | L24: =IF(VLOOKUP(A24,'Aux - pivots1'!$A:$E,5,0)=0, "",VLOOKUP(A24,'Aux - pivots1'!$A:$E,5,0)) | O24: Bens Imóveis
A25: =E25&F25 -> PROCESSGUARANTEE_CODE | B25: Pilar III | C25: Bens Imóveis - Output | D25: 2. Campo | E25: PROCESS | F25: GUARANTEE_CODE | G25: =VLOOKUP(A25,Plano_V3!$A$26:$G$592,7,0) -> 1. Concluído | H25: 1. Concluído | J25: =IF(VLOOKUP(A25,'Aux - pivots1'!$A:$E,3,0)=0, "",VLOOKUP(A25,'Aux - pivots1'!$A:$E,3,0)) | K25: =IF(VLOOKUP(A25,'Aux - pivots1'!$A:$E,4,0)=0, "",VLOOKUP(A25,'Aux - pivots1'!$A:$E,4,0)) | L25: =IF(VLOOKUP(A25,'Aux - pivots1'!$A:$E,5,0)=0, "",VLOOKUP(A25,'Aux - pivots1'!$A:$E,5,0)) | O25: Bens Imóveis
A26: =E26&F26 -> PROCESSCURRENCY_CODE | B26: Pilar III | C26: Bens Imóveis - Output | D26: 2. Campo | E26: PROCESS | F26: CURRENCY_CODE | G26: =VLOOKUP(A26,Plano_V3!$A$26:$G$592,7,0) -> 1. Concluído | H26: 1. Concluído | J26: =IF(VLOOKUP(A26,'Aux - pivots1'!$A:$E,3,0)=0, "",VLOOKUP(A26,'Aux - pivots1'!$A:$E,3,0)) -> 45512 | K26: =IF(VLOOKUP(A26,'Aux - pivots1'!$A:$E,4,0)=0, "",VLOOKUP(A26,'Aux - pivots1'!$A:$E,4,0)) -> 45526 | L26: =IF(VLOOKUP(A26,'Aux - pivots1'!$A:$E,5,0)=0, "",VLOOKUP(A26,'Aux - pivots1'!$A:$E,5,0)) | O26: Bens Imóveis
A27: =E27&F27 -> PROCESSPROCESS_CAMPAIGN_CODE | B27: Pilar III | C27: Bens Imóveis - Output | D27: 2. Campo | E27: PROCESS | F27: PROCESS_CAMPAIGN_CODE | G27: =VLOOKUP(A27,Plano_V3!$A$26:$G$592,7,0) -> 1. Concluído | H27: 1. Concluído | J27: =IF(VLOOKUP(A27,'Aux - pivots1'!$A:$E,3,0)=0, "",VLOOKUP(A27,'Aux - pivots1'!$A:$E,3,0)) | K27: =IF(VLOOKUP(A27,'Aux - pivots1'!$A:$E,4,0)=0, "",VLOOKUP(A27,'Aux - pivots1'!$A:$E,4,0)) | L27: =IF(VLOOKUP(A27,'Aux - pivots1'!$A:$E,5,0)=0, "",VLOOKUP(A27,'Aux - pivots1'!$A:$E,5,0)) | O27: Bens Imóveis
A28: =E28&F28 -> PROCESSPROCESS_PRODUCT_ID | B28: Pilar III | C28: Bens Imóveis - Output | D28: 2. Campo | E28: PROCESS | F28: PROCESS_PRODUCT_ID | G28: =VLOOKUP(A28,Plano_V3!$A$26:$G$592,7,0) -> 1. Concluído | H28: 1. Concluído | J28: =IF(VLOOKUP(A28,'Aux - pivots1'!$A:$E,3,0)=0, "",VLOOKUP(A28,'Aux - pivots1'!$A:$E,3,0)) | K28: =IF(VLOOKUP(A28,'Aux - pivots1'!$A:$E,4,0)=0, "",VLOOKUP(A28,'Aux - pivots1'!$A:$E,4,0)) | L28: =IF(VLOOKUP(A28,'Aux - pivots1'!$A:$E,5,0)=0, "",VLOOKUP(A28,'Aux - pivots1'!$A:$E,5,0)) | O28: Bens Imóveis
A29: =E29&F29 -> PROCESSPROCESS_SUBPRODUCT_ID | B29: Pilar III | C29: Bens Imóveis - Output | D29: 2. Campo | E29: PROCESS | F29: PROCESS_SUBPRODUCT_ID | G29: =VLOOKUP(A29,Plano_V3!$A$26:$G$592,7,0) -> 1. Concluído | H29: 1. Concluído | J29: =IF(VLOOKUP(A29,'Aux - pivots1'!$A:$E,3,0)=0, "",VLOOKUP(A29,'Aux - pivots1'!$A:$E,3,0)) | K29: =IF(VLOOKUP(A29,'Aux - pivots1'!$A:$E,4,0)=0, "",VLOOKUP(A29,'Aux - pivots1'!$A:$E,4,0)) | L29: =IF(VLOOKUP(A29,'Aux - pivots1'!$A:$E,5,0)=0, "",VLOOKUP(A29,'Aux - pivots1'!$A:$E,5,0)) | O29: Bens Imóveis
A30: =E30&F30 -> PROCESSGUARANTEE_TYPE_CODE | B30: Pilar III | C30: Bens Imóveis - Output | D30: 2. Campo | E30: PROCESS | F30: GUARANTEE_TYPE_CODE | G30: =VLOOKUP(A30,Plano_V3!$A$26:$G$592,7,0) -> 1. Concluído | H30: 1. Concluído | J30: =IF(VLOOKUP(A30,'Aux - pivots1'!$A:$E,3,0)=0, "",VLOOKUP(A30,'Aux - pivots1'!$A:$E,3,0)) | K30: =IF(VLOOKUP(A30,'Aux - pivots1'!$A:$E,4,0)=0, "",VLOOKUP(A30,'Aux - pivots1'!$A:$E,4,0)) | L30: =IF(VLOOKUP(A30,'Aux - pivots1'!$A:$E,5,0)=0, "",VLOOKUP(A30,'Aux - pivots1'!$A:$E,5,0)) | O30: Bens Imóveis
A31: =E31&F31 -> PROCESSPROCESS_REFERENCE_CODE | B31: Pilar III | C31: Bens Imóveis - Output | D31: 2. Campo | E31: PROCESS | F31: PROCESS_REFERENCE_CODE | G31: =VLOOKUP(A31,Plano_V3!$A$26:$G$592,7,0) -> 1. Concluído | H31: 1. Concluído | J31: =IF(VLOOKUP(A31,'Aux - pivots1'!$A:$E,3,0)=0, "",VLOOKUP(A31,'Aux - pivots1'!$A:$E,3,0)) | K31: =IF(VLOOKUP(A31,'Aux - pivots1'!$A:$E,4,0)=0, "",VLOOKUP(A31,'Aux - pivots1'!$A:$E,4,0)) | L31: =IF(VLOOKUP(A31,'Aux - pivots1'!$A:$E,5,0)=0, "",VLOOKUP(A31,'Aux - pivots1'!$A:$E,5,0)) | O31: Bens Imóveis
A32: =E32&F32 -> PROCESSPROCESS_START_DATE | B32: Pilar III | C32: Bens Imóveis - Output | D32: 2. Campo | E32: PROCESS | F32: PROCESS_START_DATE | G32: =VLOOKUP(A32,Plano_V3!$A$26:$G$592,7,0) -> 1. Concluído | H32: 1. Concluído | J32: =IF(VLOOKUP(A32,'Aux - pivots1'!$A:$E,3,0)=0, "",VLOOKUP(A32,'Aux - pivots1'!$A:$E,3,0)) | K32: =IF(VLOOKUP(A32,'Aux - pivots1'!$A:$E,4,0)=0, "",VLOOKUP(A32,'Aux - pivots1'!$A:$E,4,0)) | L32: =IF(VLOOKUP(A32,'Aux - pivots1'!$A:$E,5,0)=0, "",VLOOKUP(A32,'Aux - pivots1'!$A:$E,5,0)) | O32: Bens Imóveis
A33: =E33&F33 -> PROCESSPROCESS_DUE_DATE | B33: Pilar III | C33: Bens Imóveis - Output | D33: 2. Campo | E33: PROCESS | F33: PROCESS_DUE_DATE | G33: =VLOOKUP(A33,Plano_V3!$A$26:$G$592,7,0) -> 1. Concluído | H33: 1. Concluído | J33: =IF(VLOOKUP(A33,'Aux - pivots1'!$A:$E,3,0)=0, "",VLOOKUP(A33,'Aux - pivots1'!$A:$E,3,0)) | K33: =IF(VLOOKUP(A33,'Aux - pivots1'!$A:$E,4,0)=0, "",VLOOKUP(A33,'Aux - pivots1'!$A:$E,4,0)) | L33: =IF(VLOOKUP(A33,'Aux - pivots1'!$A:$E,5,0)=0, "",VLOOKUP(A33,'Aux - pivots1'!$A:$E,5,0)) | O33: Bens Imóveis
