Workbook

Sheet Âmbito de atuação
B6: Âmbito de atuação
C9: Modelo Relacional - Modelo Verde | V9: Modelo Relacional - Bens Imóveis
C39: Legenda:
D40: Tabelas âmbito de atuação

Sheet Plano_V3
B6: Re-testes - input | D6: 0.2 | P6: =P7-P10 -> 0 | Q6: =Q7-Q10 -> 0 | R6: =R7-R10 -> 0 | S6: =S7-S10 -> 0 | T6: =T7-T10 -> 0 | U6: =U7-U10 -> 0 | V6: =V7-V10 -> 0 | W6: =W7-W10 -> 0 | ... EQ6: =EQ7-EQ10 -> 0
B7: Re-testes - output | D7: =50%*25% -> 0.125 | O7: =AVERAGE(P7:EO7) -> 2.4923077 | P7: 3 | Q7: 3 | R7: 3 | S7: 3 | T7: 3 | U7: 2 | V7: 2 | W7: 2 | X7: 2 | Y7: 2 | Z7: 2 | AA7: 2 | AB7: 2 | AC7: 2 | AD7: 2 | AE7: 2 | AF7: 2 | AG7: 1 | AH7: 1 | AI7: 1 | AJ7: 3 | AK7: 3 | AL7: 3 | AM7: 3 | AN7: 2 | AO7: 3 | AP7: 3 | AQ7: 3 | AR7: 3 | AS7: 3 | AT7: 2 | AU7: 2 | AV7: 2 | AW7: 0 | AX7: 1 | AY7: 1 | AZ7: 0 | BA7: 1 | BB7: 1 | BC7: 1 | BD7: 2 | BE7: 2 | BF7: 2 | BG7: 2 | BH7: 2 | BI7: 2 | BJ7: 2 | BK7: 2 | BL7: 2 | BM7: 2 | BN7: 2 | BO7: 2 | BP7: 2 | BQ7: 2 | BR7: 2 | BS7: 3 | BT7: 3 | BU7: 3 | BV7: 3 | BW7: 3 | BX7: 3 | BY7: 3 | BZ7: 3 | CA7: 3 | CB7: 3 | CC7: 3 | CD7: 3 | CE7: 3 | CF7: 3 | CG7: 3 | CH7: 3 | CI7: 3 | CJ7: 3 | CK7: 3 | CL7: 3 | CM7: 3 | CN7: 3 | CO7: 3 | CP7: 3 | CQ7: 3 | CR7: 3 | CS7: 3 | CT7: 3 | CU7: 3 | CV7: 3 | CW7: 3 | CX7: 3 | CY7: 3 | CZ7: 3 | DA7: 3 | DB7: 3 | DC7: 3 | DD7: 3 | DE7: 3 | DF7: 3 | DG7: 3 | DH7: 3 | DI7: 3 | DJ7: 3 | DK7: 3 | DL7: 3 | DM7: 3 | DN7: 3 | DO7: 3 | DP7: 3 | DQ7: 2 | DR7: 3 | DS7: 3 | DT7: 3 | DU7: 3 | DV7: 3 | DW7: 3 | DX7: 3 | DY7: 3 | DZ7: 3 | EA7: 3 | EB7: 3 | EC7: 3 | ED7: 3 | EE7: 3 | EF7: 3 | EG7: 3 | EH7: 3 | EI7: 3 | EJ7: 3 | EK7: 3 | EL7: 0 | EM7: 0 | EN7: 0 | EO7: 0 | EP7: 0 | EQ7: 0
P10: =SUBTOTAL(9,P14:P583) -> 3 | Q10: =SUBTOTAL(9,Q14:Q583) -> 3 | R10: =SUBTOTAL(9,R14:R583) -> 3 | S10: =SUBTOTAL(9,S14:S583) -> 3 | T10: =SUBTOTAL(9,T14:T583) -> 3 | U10: =SUBTOTAL(9,U14:U583) -> 2 | V10: =SUBTOTAL(9,V14:V583) -> 2 | W10: =SUBTOTAL(9,W14:W583) -> 2 | ... EQ10: =SUBTOTAL(9,EQ14:EQ583) -> 0
P11: Julho | Z11: Julho | AM11: Agosto | BI11: Setembro | CD11: Outubro | DA11: Novembro | DV11: Dezembro
P12: =P13 -> 45474 | Q12: =Q13 -> 45475 | R12: =R13 -> 45476 | S12: =S13 -> 45477 | T12: =T13 -> 45478 | U12: =U13 -> 45481 | V12: =V13 -> 45482 | W12: =W13 -> 45483 | ... EQ12: =EQ13 -> 45657
B13: Âmbito | C13: Sub-âmbito | D13: Tipo de teste | E13: Tabela | F13: Campo | G13: Status | H13: Status2 | I13: Horas previstas | J13: Dias | K13: Horas efetivas | L13: Dias efetivos | M13: % Status | N13: Pendências | O13: Val | P13: 45474 | Q13: =WORKDAY(P13,1) -> 45475 | R13: =WORKDAY(Q13,1) -> 45476 | S13: =WORKDAY(R13,1) -> 45477 | T13: =WORKDAY(S13,1) -> 45478 | U13: =WORKDAY(T13,1) -> 45481 | V13: =WORKDAY(U13,1) -> 45482 | W13: =WORKDAY(V13,1) -> 45483 | X13: =WORKDAY(W13,1) -> 45484 | ... EQ13: =WORKDAY(EP13,1) -> 45657
B14: 1. Assessment | I14: =SUM(I15:I18) -> 280 | J14: =SUM(J15:J18) -> 35 | M14: =SUMPRODUCT(M15:M18,J15:J18)/J14 -> 0.71428571
B15: Pilar III | C15: Bens Imóveis | G15: 7. Por iniciar | I15: =J15*8 -> 40 | J15: 5 | M15: 0.5 | O15: =J15-SUM(P15:EQ15) -> 0 | Z15: 1 | AA15: 1 | AB15: 1 | AC15: 1 | AD15: 1
B16: Pilar III | C16: Modelo Verde | G16: 7. Por iniciar | I16: =J16*8 -> 80 | J16: 10 | M16: 0.5 | O16: =J16-SUM(P16:EQ16) -> 0 | U16: 2 | V16: 2 | W16: 2 | X16: 2 | Y16: 2
B17: Pilar III | C17: Pilar III | G17: 7. Por iniciar | I17: =J17*8 -> 40 | J17: 5 | M17: 0.5 | O17: =J17-SUM(P17:EQ17) -> 0 | AE17: 1 | AF17: 1 | AG17: 1 | AH17: 1 | AI17: 0.5 | AJ17: 0.5
B18: GD | C18: GD | G18: 7. Por iniciar | I18: =J18*8 -> 120 | J18: 15 | M18: 1 | O18: =J18-SUM(P18:EQ18) -> 0 | P18: 3 | Q18: 3 | R18: 3 | S18: 3 | T18: 3
B20: 2. Re-especificação | I20: =SUM(I21:I23) -> 120 | J20: =SUM(J21:J23) -> 15
B21: Pilar III | C21: Bens Imóveis | G21: 7. Por iniciar | I21: =J21*8 -> 40 | J21: 5 | O21: =J21-SUM(P21:EQ21) -> 0 | Z21: 0.5 | AE21: 0.5 | AJ21: 0.5 | AO21: 0.5 | AT21: 0.5 | AY21: 0.5 | BD21: 0.5 | BI21: 0.5 | BN21: 0.5 | BS21: 0.5
B22: Pilar III | C22: Modelo Verde | G22: 7. Por iniciar | I22: =J22*8 -> 40 | J22: 5 | O22: =J22-SUM(P22:EQ22) -> 0 | Z22: 0.5 | AE22: 0.5 | AJ22: 0.5 | AO22: 0.5 | AT22: 0.5 | AY22: 0.5 | BD22: 0.5 | BI22: 0.5 | BN22: 0.5 | BS22: 0.5
B23: Pilar III | C23: Pilar III | G23: 7. Por iniciar | I23: =J23*8 -> 40 | J23: 5 | O23: =J23-SUM(P23:EQ23) -> 0 | BI23: 0.5 | BN23: 0.5 | BS23: 0.5 | BX23: 0.5 | CC23: 0.5 | CH23: 0.5 | CM23: 0.5 | CR23: 0.5 | CW23: 0.5 | DB23: 0.5
B25: 3. Testes / Re-testes | I25: =I26+I41+I204+I371+I456 -> 2164.94 | J25: =J26+J41+J204+J371+J456 -> 273
B26: Pilar III | C26: Bens Imóveis - Input | I26: =SUM(I27:I40) -> 18.24 | J26: =ROUNDUP(I26/8,0) -> 3 | K26: =SUM(K27:K40) -> 4.56 | L26: =ROUNDUP(K26/8,0) -> 1 | O26: =J26-SUM(P26:EQ26) -> 0 | AA26: 0.5 | AB26: 0.5 | AF26: 0.5 | AM26: 0.5 | AN26: 0.5 | AO26: 0.5
A27: =E27&F27 -> cd_imv_inp_certif_estimativan.a. | B27: Pilar III | C27: Bens Imóveis - Input | D27: 1. Universo | E27: cd_imv_inp_certif_estimativa | F27: n.a. | G27: =INDEX(Auxiliar!$B$16:$B$23,MATCH(Plano_V3!H27,Auxiliar!$C$16:$C$23,0),1) -> 6. Em implementação (re-especificação) | H27: =VLOOKUP(A27,'Aux - pivots1'!$A:$B,2,0) -> 6 | I27: =SUMIFS(Table1[Estimação (horas)],Table1[Tabela],Plano_V3!E27,Table1[Campo],Plano_V3!F27) -> 8 | J27: =I27/8 -> 1 | K27: =SUMIFS(Table1[Horas efetivas],Table1[Tabela],Plano_V3!E27,Table1[Campo],Plano_V3!F27) -> 2 | L27: =K27/8 -> 0.25 | M27: =L27/J27 -> 0.25 | N27: sem pendencia | O27: =J27-SUM(P27:EQ27) -> 1
A28: =E28&F28 -> cd_imv_inp_certif_estimativacempbem | B28: Pilar III | C28: Bens Imóveis - Input | D28: 2. Campo | E28: cd_imv_inp_certif_estimativa | F28: cempbem | G28: =INDEX(Auxiliar!$B$16:$B$23,MATCH(Plano_V3!H28,Auxiliar!$C$16:$C$23,0),1) -> 6. Em implementação (re-especificação) | H28: =VLOOKUP(A28,'Aux - pivots1'!$A:$B,2,0) -> 6 | I28: =SUMIFS(Table1[Estimação (horas)],Table1[Tabela],Plano_V3!E28,Table1[Campo],Plano_V3!F28) -> 0.6 | J28: =I28/8 -> 0.075 | K28: =SUMIFS(Table1[Horas efetivas],Table1[Tabela],Plano_V3!E28,Table1[Campo],Plano_V3!F28) -> 0.15 | L28: =K28/8 -> 0.01875 | M28: =L28/J28 -> 0.25 | N28: sem pendencia | O28: =J28-SUM(P28:EQ28) -> 0.075
A29: =E29&F29 -> cd_imv_inp_certif_estimativachave_encriptada | B29: Pilar III | C29: Bens Imóveis - Input | D29: 2. Campo | E29: cd_imv_inp_certif_estimativa | F29: chave_encriptada | G29: =INDEX(Auxiliar!$B$16:$B$23,MATCH(Plano_V3!H29,Auxiliar!$C$16:$C$23,0),1) -> 6. Em implementação (re-especificação) | H29: =VLOOKUP(A29,'Aux - pivots1'!$A:$B,2,0) -> 6 | I29: =SUMIFS(Table1[Estimação (horas)],Table1[Tabela],Plano_V3!E29,Table1[Campo],Plano_V3!F29) -> 0.6 | J29: =I29/8 -> 0.075 | K29: =SUMIFS(Table1[Horas efetivas],Table1[Tabela],Plano_V3!E29,Table1[Campo],Plano_V3!F29) -> 0.15 | L29: =K29/8 -> 0.01875 | M29: =L29/J29 -> 0.25 | N29: sem pendencia | O29: =J29-SUM(P29:EQ29) -> 0.075
A30: =E30&F30 -> cd_imv_inp_certif_estimativackbalbem | B30: Pilar III | C30: Bens Imóveis - Input | D30: 2. Campo | E30: cd_imv_inp_certif_estimativa | F30: ckbalbem | G30: =INDEX(Auxiliar!$B$16:$B$23,MATCH(Plano_V3!H30,Auxiliar!$C$16:$C$23,0),1) -> 6. Em implementação (re-especificação) | H30: =VLOOKUP(A30,'Aux - pivots1'!$A:$B,2,0) -> 6 | I30: =SUMIFS(Table1[Estimação (horas)],Table1[Tabela],Plano_V3!E30,Table1[Campo],Plano_V3!F30) -> 0.6 | J30: =I30/8 -> 0.075 | K30: =SUMIFS(Table1[Horas efetivas],Table1[Tabela],Plano_V3!E30,Table1[Campo],Plano_V3!F30) -> 0.15 | L30: =K30/8 -> 0.01875 | M30: =L30/J30 -> 0.25 | N30: sem pendencia | O30: =J30-SUM(P30:EQ30) -> 0.075
A31: =E31&F31 -> cd_imv_inp_certif_estimativackctabem | B31: Pilar III | C31: Bens Imóveis - Input | D31: 2. Campo | E31: cd_imv_inp_certif_estimativa | F31: ckctabem | G31: =INDEX(Auxiliar!$B$16:$B$23,MATCH(Plano_V3!H31,Auxiliar!$C$16:$C$23,0),1) -> 6. Em implementação (re-especificação) | H31: =VLOOKUP(A31,'Aux - pivots1'!$A:$B,2,0) -> 6 | I31: =SUMIFS(Table1[Estimação (horas)],Table1[Tabela],Plano_V3!E31,Table1[Campo],Plano_V3!F31) -> 0.6 | J31: =I31/8 -> 0.075 | K31: =SUMIFS(Table1[Horas efetivas],Table1[Tabela],Plano_V3!E31,Table1[Campo],Plano_V3!F31) -> 0.15 | L31: =K31/8 -> 0.01875 | M31: =L31/J31 -> 0.25 | N31: sem pendencia | O31: =J31-SUM(P31:EQ31) -> 0.075
A32: =E32&F32 -> cd_imv_inp_certif_estimativackrefbem | B32: Pilar III | C32: Bens Imóveis - Input | D32: 2. Campo | E32: cd_imv_inp_certif_estimativa | F32: ckrefbem | G32: =INDEX(Auxiliar!$B$16:$B$23,MATCH(Plano_V3!H32,Auxiliar!$C$16:$C$23,0),1) -> 6. Em implementação (re-especificação) | H32: =VLOOKUP(A32,'Aux - pivots1'!$A:$B,2,0) -> 6 | I32: =SUMIFS(Table1[Estimação (horas)],Table1[Tabela],Plano_V3!E32,Table1[Campo],Plano_V3!F32) -> 0.6 | J32: =I32/8 -> 0.075 | K32: =SUMIFS(Table1[Horas efetivas],Table1[Tabela],Plano_V3!E32,Table1[Campo],Plano_V3!F32) -> 0.15 | L32: =K32/8 -> 0.01875 | M32: =L32/J32 -> 0.25 | N32: sem pendencia | O32: =J32-SUM(P32:EQ32) -> 0.075
A33: =E33&F33 -> cd_imv_inp_certif_estimativadata_extraccao_info | B33: Pilar III | C33: Bens Imóveis - Input | D33: 2. Campo | E33: cd_imv_inp_certif_estimativa | F33: data_extraccao_info | G33: =INDEX(Auxiliar!$B$16:$B$23,MATCH(Plano_V3!H33,Auxiliar!$C$16:$C$23,0),1) -> 6. Em implementação (re-especificação) | H33: =VLOOKUP(A33,'Aux - pivots1'!$A:$B,2,0) -> 6 | I33: =SUMIFS(Table1[Estimação (horas)],Table1[Tabela],Plano_V3!E33,Table1[Campo],Plano_V3!F33) -> 0.6 | J33: =I33/8 -> 0.075 | K33: =SUMIFS(Table1[Horas efetivas],Table1[Tabela],Plano_V3!E33,Table1[Campo],Plano_V3!F33) -> 0.15 | L33: =K33/8 -> 0.01875 | M33: =L33/J33 -> 0.25 | N33: sem pendencia | O33: =J33-SUM(P33:EQ33) -> 0.075
A34: =E34&F34 -> cd_imv_inp_certif_estimativaepc | B34: Pilar III | C34: Bens Imóveis - Input | D34: 2. Campo | E34: cd_imv_inp_certif_estimativa | F34: epc | G34: =INDEX(Auxiliar!$B$16:$B$23,MATCH(Plano_V3!H34,Auxiliar!$C$16:$C$23,0),1) -> 6. Em implementação (re-especificação) | H34: =VLOOKUP(A34,'Aux - pivots1'!$A:$B,2,0) -> 6 | I34: =SUMIFS(Table1[Estimação (horas)],Table1[Tabela],Plano_V3!E34,Table1[Campo],Plano_V3!F34) -> 0.6 | J34: =I34/8 -> 0.075 | K34: =SUMIFS(Table1[Horas efetivas],Table1[Tabela],Plano_V3!E34,Table1[Campo],Plano_V3!F34) -> 0.15 | L34: =K34/8 -> 0.01875 | M34: =L34/J34 -> 0.25 | N34: sem pendencia | O34: =J34-SUM(P34:EQ34) -> 0.075
A35: =E35&F35 -> cd_imv_inp_certif_estimativafornecedor | B35: Pilar III | C35: Bens Imóveis - Input | D35: 2. Campo | E35: cd_imv_inp_certif_estimativa | F35: fornecedor | G35: =INDEX(Auxiliar!$B$16:$B$23,MATCH(Plano_V3!H35,Auxiliar!$C$16:$C$23,0),1) -> 6. Em implementação (re-especificação) | H35: =VLOOKUP(A35,'Aux - pivots1'!$A:$B,2,0) -> 6 | I35: =SUMIFS(Table1[Estimação (horas)],Table1[Tabela],Plano_V3!E35,Table1[Campo],Plano_V3!F35) -> 0.6 | J35: =I35/8 -> 0.075 | K35: =SUMIFS(Table1[Horas efetivas],Table1[Tabela],Plano_V3!E35,Table1[Campo],Plano_V3!F35) -> 0.15 | L35: =K35/8 -> 0.01875 | M35: =L35/J35 -> 0.25 | N35: sem pendencia | O35: =J35-SUM(P35:EQ35) -> 0.075
A36: =E36&F36 -> cd_imv_inp_certif_estimativametodo_info | B36: Pilar III | C36: Bens Imóveis - Input | D36: 2. Campo | E36: cd_imv_inp_certif_estimativa | F36: metodo_info | G36: =INDEX(Auxiliar!$B$16:$B$23,MATCH(Plano_V3!H36,Auxiliar!$C$16:$C$23,0),1) -> 6. Em implementação (re-especificação) | H36: =VLOOKUP(A36,'Aux - pivots1'!$A:$B,2,0) -> 6 | I36: =SUMIFS(Table1[Estimação (horas)],Table1[Tabela],Plano_V3!E36,Table1[Campo],Plano_V3!F36) -> 0.6 | J36: =I36/8 -> 0.075 | K36: =SUMIFS(Table1[Horas efetivas],Table1[Tabela],Plano_V3!E36,Table1[Campo],Plano_V3!F36) -> 0.15 | L36: =K36/8 -> 0.01875 | M36: =L36/J36 -> 0.25 | N36: sem pendencia | O36: =J36-SUM(P36:EQ36) -> 0.075
A37: =E37&F37 -> cd_imv_inp_certif_estimativascore_qualidade | B37: Pilar III | C37: Bens Imóveis - Input | D37: 2. Campo | E37: cd_imv_inp_certif_estimativa | F37: score_qualidade | G37: =INDEX(Auxiliar!$B$16:$B$23,MATCH(Plano_V3!H37,Auxiliar!$C$16:$C$23,0),1) -> 6. Em implementação (re-especificação) | H37: =VLOOKUP(A37,'Aux - pivots1'!$A:$B,2,0) -> 6 | I37: =SUMIFS(Table1[Estimação (horas)],Table1[Tabela],Plano_V3!E37,Table1[Campo],Plano_V3!F37) -> 0.6 | J37: =I37/8 -> 0.075 | K37: =SUMIFS(Table1[Horas efetivas],Table1[Tabela],Plano_V3!E37,Table1[Campo],Plano_V3!F37) -> 0.15 | L37: =K37/8 -> 0.01875 | M37: =L37/J37 -> 0.25 | N37: sem pendencia | O37: =J37-SUM(P37:EQ37) -> 0.075
A38: =E38&F38 -> cd_imv_inp_certif_estimativavlr_cnsm_ano | B38: Pilar III | C38: Bens Imóveis - Input | D38: 2. Campo | E38: cd_imv_inp_certif_estimativa | F38: vlr_cnsm_ano | G38: =INDEX(Auxiliar!$B$16:$B$23,MATCH(Plano_V3!H38,Auxiliar!$C$16:$C$23,0),1) -> 6. Em implementação (re-especificação) | H38: =VLOOKUP(A38,'Aux - pivots1'!$A:$B,2,0) -> 6 | I38: =SUMIFS(Table1[Estimação (horas)],Table1[Tabela],Plano_V3!E38,Table1[Campo],Plano_V3!F38) -> 0.6 | J38: =I38/8 -> 0.075 | K38: =SUMIFS(Table1[Horas efetivas],Table1[Tabela],Plano_V3!E38,Table1[Campo],Plano_V3!F38) -> 0.15 | L38: =K38/8 -> 0.01875 | M38: =L38/J38 -> 0.25 | N38: sem pendencia | O38: =J38-SUM(P38:EQ38) -> 0.075
A39: =E39&F39 -> cd_imv_inp_certif_estimativavlr_emss_ano | B39: Pilar III | C39: Bens Imóveis - Input | D39: 2. Campo | E39: cd_imv_inp_certif_estimativa | F39: vlr_emss_ano | G39: =INDEX(Auxiliar!$B$16:$B$23,MATCH(Plano_V3!H39,Auxiliar!$C$16:$C$23,0),1) -> 6. Em implementação (re-especificação) | H39: =VLOOKUP(A39,'Aux - pivots1'!$A:$B,2,0) -> 6 | I39: =SUMIFS(Table1[Estimação (horas)],Table1[Tabela],Plano_V3!E39,Table1[Campo],Plano_V3!F39) -> 0.6 | J39: =I39/8 -> 0.075 | K39: =SUMIFS(Table1[Horas efetivas],Table1[Tabela],Plano_V3!E39,Table1[Campo],Plano_V3!F39) -> 0.15 | L39: =K39/8 -> 0.01875 | M39: =L39/J39 -> 0.25 | N39: sem pendencia | O39: =J39-SUM(P39:EQ39) -> 0.075
A40: =E40&F40 -> Re-testesn.a. | B40: Pilar III | C40: Bens Imóveis - Input | D40: 2. Campo | E40: Re-testes | F40: n.a. | G40: 7. Por iniciar | I40: =SUM(I27:I39)*$D$6 -> 3.04 | J40: =I40/8 -> 0.38 | K40: =SUM(K27:K39)*$D$6 -> 0.76 | L40: =K40/8 -> 0.095 | M40: =L40/J40 -> 0.25 | N40: sem pendencia | O40: =J40-SUM(P40:EQ40) -> 0.38
A41: =E41&F41 | B41: Pilar III | C41: Bens Imóveis - Output | I41: =SUM(I42:I203) -> 831.0375 | J41: =ROUNDUP(I41/8,0) -> 104 | O41: =J41-SUM(P41:EQ41) -> 4 | AJ41: 1 | AK41: 1 | AL41: 1 | AM41: 1 | AP41: 1 | AQ41: 1 | AR41: 1 | AS41: 1 | AU41: 1 | AV41: 2 | AX41: 1 | BA41: 1 | BB41: 1 | BC41: 1 | BD41: 1 | BE41: 2 | BF41: 2 | BG41: 2 | BH41: 2 | BI41: 0.5 | BJ41: 2 | BK41: 2 | BL41: 2 | BM41: 2 | BN41: 0.5 | BO41: 2 | BP41: 2 | BQ41: 2 | BR41: 2 | BS41: 1.5 | BT41: 2 | BU41: 2 | BV41: 2 | BW41: 2 | BX41: 2 | BY41: 2 | BZ41: 2 | CA41: 2 | CB41: 2 | CC41: 2 | CD41: 2 | CE41: 2 | CF41: 2 | CG41: 2 | CH41: 2 | CI41: 2 | CJ41: 2 | CK41: 2 | CL41: 2 | CM41: 2 | CN41: 2 | CO41: 2 | CP41: 2 | CQ41: 2 | CR41: 2 | CS41: 2 | CT41: 2 | CU41: 2 | CV41: 1.5
A42: =E42&F42 -> cd_imv_out_prcn.a. | B42: Pilar III | C42: Bens Imóveis - Output | D42: 1. Universo | E42: cd_imv_out_prc | F42: n.a. | G42: =INDEX(Auxiliar!$B$16:$B$23,MATCH(Plano_V3!H42,Auxiliar!$C$16:$C$23,0),1) -> 1. Concluído | H42: =VLOOKUP(A42,'Aux - pivots1'!$A:$B,2,0) -> 1 | I42: =SUMIFS(Table1[Estimação (horas)],Table1[Tabela],Plano_V3!E42,Table1[Campo],Plano_V3!F42) -> 8 | J42: =I42/8 -> 1 | K42: =SUMIFS(Table1[Horas efetivas],Table1[Tabela],Plano_V3!E42,Table1[Campo],Plano_V3!F42) -> 8 | L42: =K42/8 -> 1 | M42: =L42/J42 -> 1 | N42: cd_imv_out_trz_cred_prc | O42: =J42-SUM(P42:EQ42) -> 1
A43: =E43&F43 -> cd_imv_out_prccempresa | B43: Pilar III | C43: Bens Imóveis - Output | D43: 2. Campo | E43: cd_imv_out_prc | F43: cempresa | G43: =INDEX(Auxiliar!$B$16:$B$23,MATCH(Plano_V3!H43,Auxiliar!$C$16:$C$23,0),1) -> 1. Concluído | H43: =VLOOKUP(A43,'Aux - pivots1'!$A:$B,2,0) -> 1 | I43: =SUMIFS(Table1[Estimação (horas)],Table1[Tabela],Plano_V3!E43,Table1[Campo],Plano_V3!F43) -> 4.1 | J43: =I43/8 -> 0.5125 | K43: =SUMIFS(Table1[Horas efetivas],Table1[Tabela],Plano_V3!E43,Table1[Campo],Plano_V3!F43) -> 4.1 | L43: =K43/8 -> 0.5125 | M43: =L43/J43 -> 1 | N43: cd_imv_out_trz_cred_prc | O43: =J43-SUM(P43:EQ43) -> 0.5125
A44: =E44&F44 -> cd_imv_out_prcckbalcao | B44: Pilar III | C44: Bens Imóveis - Output | D44: 2. Campo | E44: cd_imv_out_prc | F44: ckbalcao | G44: =INDEX(Auxiliar!$B$16:$B$23,MATCH(Plano_V3!H44,Auxiliar!$C$16:$C$23,0),1) -> 1. Concluído | H44: =VLOOKUP(A44,'Aux - pivots1'!$A:$B,2,0) -> 1 | I44: =SUMIFS(Table1[Estimação (horas)],Table1[Tabela],Plano_V3!E44,Table1[Campo],Plano_V3!F44) -> 4.1 | J44: =I44/8 -> 0.5125 | K44: =SUMIFS(Table1[Horas efetivas],Table1[Tabela],Plano_V3!E44,Table1[Campo],Plano_V3!F44) -> 4.1 | L44: =K44/8 -> 0.5125 | M44: =L44/J44 -> 1 | N44: cd_imv_out_trz_cred_prc | O44: =J44-SUM(P44:EQ44) -> 0.5125
A45: =E45&F45 -> cd_imv_out_prccknumcta | B45: Pilar III | C45: Bens Imóveis - Output | D45: 2. Campo | E45: cd_imv_out_prc | F45: cknumcta | G45: =INDEX(Auxiliar!$B$16:$B$23,MATCH(Plano_V3!H45,Auxiliar!$C$16:$C$23,0),1) -> 1. Concluído | H45: =VLOOKUP(A45,'Aux - pivots1'!$A:$B,2,0) -> 1 | I45: =SUMIFS(Table1[Estimação (horas)],Table1[Tabela],Plano_V3!E45,Table1[Campo],Plano_V3!F45) -> 4.1 | J45: =I45/8 -> 0.5125 | K45: =SUMIFS(Table1[Horas efetivas],Table1[Tabela],Plano_V3!E45,Table1[Campo],Plano_V3!F45) -> 4.1 | L45: =K45/8 -> 0.5125 | M45: =L45/J45 -> 1 | N45: cd_imv_out_trz_cred_prc | O45: =J45-SUM(P45:EQ45) -> 0.5125
A46: =E46&F46 -> cd_imv_out_prccod_estd_prcs | B46: Pilar III | C46: Bens Imóveis - Output | D46: 2. Campo | E46: cd_imv_out_prc | F46: cod_estd_prcs | G46: =INDEX(Auxiliar!$B$16:$B$23,MATCH(Plano_V3!H46,Auxiliar!$C$16:$C$23,0),1) -> 0. Cancelado | H46: =VLOOKUP(A46,'Aux - pivots1'!$A:$B,2,0) -> 0 | I46: 0 | J46: =I46/8 -> 0 | K46: =SUMIFS(Table1[Horas efetivas],Table1[Tabela],Plano_V3!E46,Table1[Campo],Plano_V3!F46) -> 0 | L46: =K46/8 -> 0 | M46: =L46/J46 -> #DIV/0! | N46: cd_imv_out_trz_cred_prc | O46: =J46-SUM(P46:EQ46) -> 0
A47: =E47&F47 -> cd_imv_out_prccod_grt | B47: Pilar III | C47: Bens Imóveis - Output | D47: 2. Campo | E47: cd_imv_out_prc | F47: cod_grt | G47: =INDEX(Auxiliar!$B$16:$B$23,MATCH(Plano_V3!H47,Auxiliar!$C$16:$C$23,0),1) -> 1. Concluído | H47: =VLOOKUP(A47,'Aux - pivots1'!$A:$B,2,0) -> 1 | I47: =SUMIFS(Table1[Estimação (horas)],Table1[Tabela],Plano_V3!E47,Table1[Campo],Plano_V3!F47) -> 4.1 | J47: =I47/8 -> 0.5125 | K47: =SUMIFS(Table1[Horas efetivas],Table1[Tabela],Plano_V3!E47,Table1[Campo],Plano_V3!F47) -> 4.1 | L47: =K47/8 -> 0.5125 | M47: =L47/J47 -> 1 | N47: cd_imv_out_trz_cred_prc | O47: =J47-SUM(P47:EQ47) -> 0.5125
A48: =E48&F48 -> cd_imv_out_prccod_moeda | B48: Pilar III | C48: Bens Imóveis - Output | D48: 2. Campo | E48: cd_imv_out_prc | F48: cod_moeda | G48: =INDEX(Auxiliar!$B$16:$B$23,MATCH(Plano_V3!H48,Auxiliar!$C$16:$C$23,0),1) -> 1. Concluído | H48: =VLOOKUP(A48,'Aux - pivots1'!$A:$B,2,0) -> 1 | I48: =SUMIFS(Table1[Estimação (horas)],Table1[Tabela],Plano_V3!E48,Table1[Campo],Plano_V3!F48) -> 4.1 | J48: =I48/8 -> 0.5125 | K48: =SUMIFS(Table1[Horas efetivas],Table1[Tabela],Plano_V3!E48,Table1[Campo],Plano_V3!F48) -> 4.1 | L48: =K48/8 -> 0.5125 | M48: =L48/J48 -> 1 | N48: cd_imv_out_trz_cred_prc | O48: =J48-SUM(P48:EQ48) -> 0.5125
A49: =E49&F49 -> cd_imv_out_prccod_observacao | B49: Pilar III | C49: Bens Imóveis - Output | D49: 2. Campo | E49: cd_imv_out_prc | F49: cod_observacao | G49: =INDEX(Auxiliar!$B$16:$B$23,MATCH(Plano_V3!H49,Auxiliar!$C$16:$C$23,0),1) -> 1. Concluído | H49: =VLOOKUP(A49,'Aux - pivots1'!$A:$B,2,0) -> 1 | I49: =SUMIFS(Table1[Estimação (horas)],Table1[Tabela],Plano_V3!E49,Table1[Campo],Plano_V3!F49) -> 4.1 | J49: =I49/8 -> 0.5125 | K49: =SUMIFS(Table1[Horas efetivas],Table1[Tabela],Plano_V3!E49,Table1[Campo],Plano_V3!F49) -> 4.1 | L49: =K49/8 -> 0.5125 | M49: =L49/J49 -> 1 | N49: cd_imv_out_trz_cred_prc | O49: =J49-SUM(P49:EQ49) -> 0.5125
...

Sheet Plano_V1
B6: Re-testes - input | D6: 0.2 | M6: =M7-M10 -> 0 | N6: =N7-N10 -> 0 | O6: =O7-O10 -> 0 | P6: =P7-P10 -> 0 | Q6: =Q7-Q10 -> 0 | R6: =R7-R10 -> 0 | S6: =S7-S10 -> 0 | T6: =T7-T10 -> 0 | ... FK6: =FK7-FK10 -> 0
B7: Re-testes - output | D7: =50%*25% -> 0.125 | L7: =AVERAGE(M7:EL7) -> 2.4923077 | M7: 3 | N7: 3 | O7: 3 | P7: 3 | Q7: 3 | R7: 2 | S7: 2 | T7: 2 | U7: 2 | V7: 2 | W7: 2 | X7: 2 | Y7: 2 | Z7: 2 | AA7: 2 | AB7: 2 | AC7: 2 | AD7: 1 | AE7: 1 | AF7: 1 | AG7: 3 | AH7: 3 | AI7: 3 | AJ7: 3 | AK7: 2 | AL7: 3 | AM7: 3 | AN7: 3 | AO7: 3 | AP7: 3 | AQ7: 2 | AR7: 2 | AS7: 2 | AT7: 0 | AU7: 1 | AV7: 1 | AW7: 0 | AX7: 1 | AY7: 1 | AZ7: 1 | BA7: 2 | BB7: 2 | BC7: 2 | BD7: 2 | BE7: 2 | BF7: 2 | BG7: 2 | BH7: 2 | BI7: 2 | BJ7: 2 | BK7: 2 | BL7: 2 | BM7: 2 | BN7: 2 | BO7: 2 | BP7: 3 | BQ7: 3 | BR7: 3 | BS7: 3 | BT7: 3 | BU7: 3 | BV7: 3 | BW7: 3 | BX7: 3 | BY7: 3 | BZ7: 3 | CA7: 3 | CB7: 3 | CC7: 3 | CD7: 3 | CE7: 3 | CF7: 3 | CG7: 3 | CH7: 3 | CI7: 3 | CJ7: 3 | CK7: 3 | CL7: 3 | CM7: 3 | CN7: 3 | CO7: 3 | CP7: 3 | CQ7: 3 | CR7: 3 | CS7: 3 | CT7: 3 | CU7: 3 | CV7: 3 | CW7: 3 | CX7: 3 | CY7: 3 | CZ7: 3 | DA7: 3 | DB7: 3 | DC7: 3 | DD7: 3 | DE7: 3 | DF7: 3 | DG7: 3 | DH7: 3 | DI7: 3 | DJ7: 3 | DK7: 3 | DL7: 3 | DM7: 3 | DN7: 2 | DO7: 3 | DP7: 3 | DQ7: 3 | DR7: 3 | DS7: 3 | DT7: 3 | DU7: 3 | DV7: 3 | DW7: 3 | DX7: 3 | DY7: 3 | DZ7: 3 | EA7: 3 | EB7: 3 | EC7: 3 | ED7: 3 | EE7: 3 | EF7: 3 | EG7: 3 | EH7: 3 | EI7: 0 | EJ7: 0 | EK7: 0 | EL7: 0 | EM7: 0 | EN7: 0 | EO7: 0 | EP7: 3 | EQ7: 3 | ER7: 3 | ES7: 3 | ET7: 3 | EU7: 3 | EV7: 3 | EW7: 3 | EX7: 3 | EY7: 3 | EZ7: 3 | FA7: 3 | FB7: 3 | FC7: 3 | FD7: 3 | FE7: 3 | FF7: 3 | FG7: 3 | FH7: 3 | FI7: 3 | FJ7: 3 | FK7: 3
M10: =SUBTOTAL(9,M14:M636) -> 3 | N10: =SUBTOTAL(9,N14:N636) -> 3 | O10: =SUBTOTAL(9,O14:O636) -> 3 | P10: =SUBTOTAL(9,P14:P636) -> 3 | Q10: =SUBTOTAL(9,Q14:Q636) -> 3 | R10: =SUBTOTAL(9,R14:R636) -> 2 | S10: =SUBTOTAL(9,S14:S636) -> 2 | T10: =SUBTOTAL(9,T14:T636) -> 2 | ... FK10: =SUBTOTAL(9,FK14:FK636) -> 3
M11: Julho | W11: Julho | AJ11: Agosto | BF11: Setembro | CA11: Outubro | CX11: Novembro | DS11: Dezembro | EO11: Janeiro
M12: =M13 -> 45474 | N12: =N13 -> 45475 | O12: =O13 -> 45476 | P12: =P13 -> 45477 | Q12: =Q13 -> 45478 | R12: =R13 -> 45481 | S12: =S13 -> 45482 | T12: =T13 -> 45483 | ... FK12: =FK13 -> 45688
B13: Âmbito | C13: Sub-âmbito | D13: Tipo de teste | E13: Tabela | F13: Campo | G13: Status | H13: Status2 | I13: Horas | J13: Dias | K13: Pendências | L13: Val | M13: 45474 | N13: =WORKDAY(M13,1) -> 45475 | O13: =WORKDAY(N13,1) -> 45476 | P13: =WORKDAY(O13,1) -> 45477 | Q13: =WORKDAY(P13,1) -> 45478 | R13: =WORKDAY(Q13,1) -> 45481 | S13: =WORKDAY(R13,1) -> 45482 | T13: =WORKDAY(S13,1) -> 45483 | U13: =WORKDAY(T13,1) -> 45484 | ... FK13: =WORKDAY(FJ13,1) -> 45688
B14: 1. Assessment | I14: =SUM(I15:I18) -> 280 | J14: =SUM(J15:J18) -> 35
B15: Pilar III | C15: Bens Imóveis | G15: 7. Por iniciar | I15: =J15*8 -> 40 | J15: 5 | L15: =J15-SUM(M15:FK15) -> 0 | W15: 1 | X15: 1 | Y15: 1 | Z15: 1 | AA15: 1
B16: Pilar III | C16: Modelo Verde | G16: 7. Por iniciar | I16: =J16*8 -> 80 | J16: 10 | L16: =J16-SUM(M16:FK16) -> 0 | R16: 2 | S16: 2 | T16: 2 | U16: 2 | V16: 2
B17: Pilar III | C17: Pilar III | G17: 7. Por iniciar | I17: =J17*8 -> 40 | J17: 5 | L17: =J17-SUM(M17:FK17) -> 0 | AB17: 1 | AC17: 1 | AD17: 1 | AE17: 1 | AF17: 0.5 | AG17: 0.5
B18: GD | C18: GD | G18: 7. Por iniciar | I18: =J18*8 -> 120 | J18: 15 | L18: =J18-SUM(M18:FK18) -> 0 | M18: 3 | N18: 3 | O18: 3 | P18: 3 | Q18: 3
B20: 2. Re-especificação | I20: =SUM(I21:I23) -> 120 | J20: =SUM(J21:J23) -> 15
B21: Pilar III | C21: Bens Imóveis | G21: 7. Por iniciar | I21: =J21*8 -> 40 | J21: 5 | L21: =J21-SUM(M21:FK21) -> 0 | W21: 0.5 | AB21: 0.5 | AG21: 0.5 | AL21: 0.5 | AQ21: 0.5 | AV21: 0.5 | BA21: 0.5 | BF21: 0.5 | BK21: 0.5 | BP21: 0.5
B22: Pilar III | C22: Modelo Verde | G22: 7. Por iniciar | I22: =J22*8 -> 40 | J22: 5 | L22: =J22-SUM(M22:FK22) -> 0 | W22: 0.5 | AB22: 0.5 | AG22: 0.5 | AL22: 0.5 | AQ22: 0.5 | AV22: 0.5 | BA22: 0.5 | BF22: 0.5 | BK22: 0.5 | BP22: 0.5
B23: Pilar III | C23: Pilar III | G23: 7. Por iniciar | I23: =J23*8 -> 40 | J23: 5 | L23: =J23-SUM(M23:FK23) -> 0 | BF23: 0.5 | BK23: 0.5 | BP23: 0.5 | BU23: 0.5 | BZ23: 0.5 | CE23: 0.5 | CJ23: 0.5 | CO23: 0.5 | CT23: 0.5 | CY23: 0.5
B25: 3. Testes / Re-testes | I25: =I26+I27+I42+I198+I362+I447 -> 2213.7525 | J25: =J26+J27+J42+J198+J362+J447 -> 279
B26: Testes Regressivos | G26: 7. Por iniciar | I26: =4*22 -> 88 | J26: =I26/8 -> 11 | L26: =J26-SUM(M26:FK26) -> 0 | AA26: 0.5 | AF26: 0.5 | AK26: 0.5 | AP26: 0.5 | AU26: 0.5 | AZ26: 0.5 | BE26: 0.5 | BJ26: 0.5 | BO26: 0.5 | BT26: 0.5 | BY26: 0.5 | CD26: 0.5 | CI26: 0.5 | CN26: 0.5 | CS26: 0.5 | CX26: 0.5 | DC26: 0.5 | DH26: 0.5 | DM26: 0.5 | DR26: 0.5 | DW26: 0.5 | EB26: 0.5
B27: Pilar III | C27: Bens Imóveis - Input | I27: =SUM(I28:I41) -> 18.24 | J27: =ROUNDUP(I27/8,0) -> 3 | L27: =J27-SUM(M27:FK27) -> 0 | X27: 0.5 | Y27: 0.5 | AC27: 0.5 | AG27: 1 | AH27: 0.5
A28: =E28&F28 -> cd_imv_inp_certif_estimativan.a. | B28: Pilar III | C28: Bens Imóveis - Input | D28: 1. Universo | E28: cd_imv_inp_certif_estimativa | F28: n.a. | G28: =INDEX(Auxiliar!$B$16:$B$23,MATCH(Plano_V1!H28,Auxiliar!$C$16:$C$23,0),1) -> 6. Em implementação (re-especificação) | H28: =VLOOKUP(A28,'Aux - pivots1'!$A:$B,2,0) -> 6 | I28: =SUMIFS(Table1[Estimação (horas)],Table1[Tabela],Plano_V1!E28,Table1[Campo],Plano_V1!F28) -> 8 | J28: =I28/8 -> 1 | K28: sem pendencia | L28: =J28-SUM(M28:FK28) -> 1
A29: =E29&F29 -> cd_imv_inp_certif_estimativacempbem | B29: Pilar III | C29: Bens Imóveis - Input | D29: 2. Campo | E29: cd_imv_inp_certif_estimativa | F29: cempbem | G29: =INDEX(Auxiliar!$B$16:$B$23,MATCH(Plano_V1!H29,Auxiliar!$C$16:$C$23,0),1) -> 6. Em implementação (re-especificação) | H29: =VLOOKUP(A29,'Aux - pivots1'!$A:$B,2,0) -> 6 | I29: =SUMIFS(Table1[Estimação (horas)],Table1[Tabela],Plano_V1!E29,Table1[Campo],Plano_V1!F29) -> 0.6 | J29: =I29/8 -> 0.075 | K29: sem pendencia | L29: =J29-SUM(M29:FK29) -> 0.075
A30: =E30&F30 -> cd_imv_inp_certif_estimativachave_encriptada | B30: Pilar III | C30: Bens Imóveis - Input | D30: 2. Campo | E30: cd_imv_inp_certif_estimativa | F30: chave_encriptada | G30: =INDEX(Auxiliar!$B$16:$B$23,MATCH(Plano_V1!H30,Auxiliar!$C$16:$C$23,0),1) -> 6. Em implementação (re-especificação) | H30: =VLOOKUP(A30,'Aux - pivots1'!$A:$B,2,0) -> 6 | I30: =SUMIFS(Table1[Estimação (horas)],Table1[Tabela],Plano_V1!E30,Table1[Campo],Plano_V1!F30) -> 0.6 | J30: =I30/8 -> 0.075 | K30: sem pendencia | L30: =J30-SUM(M30:FK30) -> 0.075
A31: =E31&F31 -> cd_imv_inp_certif_estimativackbalbem | B31: Pilar III | C31: Bens Imóveis - Input | D31: 2. Campo | E31: cd_imv_inp_certif_estimativa | F31: ckbalbem | G31: =INDEX(Auxiliar!$B$16:$B$23,MATCH(Plano_V1!H31,Auxiliar!$C$16:$C$23,0),1) -> 6. Em implementação (re-especificação) | H31: =VLOOKUP(A31,'Aux - pivots1'!$A:$B,2,0) -> 6 | I31: =SUMIFS(Table1[Estimação (horas)],Table1[Tabela],Plano_V1!E31,Table1[Campo],Plano_V1!F31) -> 0.6 | J31: =I31/8 -> 0.075 | K31: sem pendencia | L31: =J31-SUM(M31:FK31) -> 0.075
A32: =E32&F32 -> cd_imv_inp_certif_estimativackctabem | B32: Pilar III | C32: Bens Imóveis - Input | D32: 2. Campo | E32: cd_imv_inp_certif_estimativa | F32: ckctabem | G32: =INDEX(Auxiliar!$B$16:$B$23,MATCH(Plano_V1!H32,Auxiliar!$C$16:$C$23,0),1) -> 6. Em implementação (re-especificação) | H32: =VLOOKUP(A32,'Aux - pivots1'!$A:$B,2,0) -> 6 | I32: =SUMIFS(Table1[Estimação (horas)],Table1[Tabela],Plano_V1!E32,Table1[Campo],Plano_V1!F32) -> 0.6 | J32: =I32/8 -> 0.075 | K32: sem pendencia | L32: =J32-SUM(M32:FK32) -> 0.075
A33: =E33&F33 -> cd_imv_inp_certif_estimativackrefbem | B33: Pilar III | C33: Bens Imóveis - Input | D33: 2. Campo | E33: cd_imv_inp_certif_estimativa | F33: ckrefbem | G33: =INDEX(Auxiliar!$B$16:$B$23,MATCH(Plano_V1!H33,Auxiliar!$C$16:$C$23,0),1) -> 6. Em implementação (re-especificação) | H33: =VLOOKUP(A33,'Aux - pivots1'!$A:$B,2,0) -> 6 | I33: =SUMIFS(Table1[Estimação (horas)],Table1[Tabela],Plano_V1!E33,Table1[Campo],Plano_V1!F33) -> 0.6 | J33: =I33/8 -> 0.075 | K33: sem pendencia | L33: =J33-SUM(M33:FK33) -> 0.075
A34: =E34&F34 -> cd_imv_inp_certif_estimativadata_extraccao_info | B34: Pilar III | C34: Bens Imóveis - Input | D34: 2. Campo | E34: cd_imv_inp_certif_estimativa | F34: data_extraccao_info | G34: =INDEX(Auxiliar!$B$16:$B$23,MATCH(Plano_V1!H34,Auxiliar!$C$16:$C$23,0),1) -> 6. Em implementação (re-especificação) | H34: =VLOOKUP(A34,'Aux - pivots1'!$A:$B,2,0) -> 6 | I34: =SUMIFS(Table1[Estimação (horas)],Table1[Tabela],Plano_V1!E34,Table1[Campo],Plano_V1!F34) -> 0.6 | J34: =I34/8 -> 0.075 | K34: sem pendencia | L34: =J34-SUM(M34:FK34) -> 0.075
A35: =E35&F35 -> cd_imv_inp_certif_estimativaepc | B35: Pilar III | C35: Bens Imóveis - Input | D35: 2. Campo | E35: cd_imv_inp_certif_estimativa | F35: epc | G35: =INDEX(Auxiliar!$B$16:$B$23,MATCH(Plano_V1!H35,Auxiliar!$C$16:$C$23,0),1) -> 6. Em implementação (re-especificação) | H35: =VLOOKUP(A35,'Aux - pivots1'!$A:$B,2,0) -> 6 | I35: =SUMIFS(Table1[Estimação (horas)],Table1[Tabela],Plano_V1!E35,Table1[Campo],Plano_V1!F35) -> 0.6 | J35: =I35/8 -> 0.075 | K35: sem pendencia | L35: =J35-SUM(M35:FK35) -> 0.075
A36: =E36&F36 -> cd_imv_inp_certif_estimativafornecedor | B36: Pilar III | C36: Bens Imóveis - Input | D36: 2. Campo | E36: cd_imv_inp_certif_estimativa | F36: fornecedor | G36: =INDEX(Auxiliar!$B$16:$B$23,MATCH(Plano_V1!H36,Auxiliar!$C$16:$C$23,0),1) -> 6. Em implementação (re-especificação) | H36: =VLOOKUP(A36,'Aux - pivots1'!$A:$B,2,0) -> 6 | I36: =SUMIFS(Table1[Estimação (horas)],Table1[Tabela],Plano_V1!E36,Table1[Campo],Plano_V1!F36) -> 0.6 | J36: =I36/8 -> 0.075 | K36: sem pendencia | L36: =J36-SUM(M36:FK36) -> 0.075
A37: =E37&F37 -> cd_imv_inp_certif_estimativametodo_info | B37: Pilar III | C37: Bens Imóveis - Input | D37: 2. Campo | E37: cd_imv_inp_certif_estimativa | F37: metodo_info | G37: =INDEX(Auxiliar!$B$16:$B$23,MATCH(Plano_V1!H37,Auxiliar!$C$16:$C$23,0),1) -> 6. Em implementação (re-especificação) | H37: =VLOOKUP(A37,'Aux - pivots1'!$A:$B,2,0) -> 6 | I37: =SUMIFS(Table1[Estimação (horas)],Table1[Tabela],Plano_V1!E37,Table1[Campo],Plano_V1!F37) -> 0.6 | J37: =I37/8 -> 0.075 | K37: sem pendencia | L37: =J37-SUM(M37:FK37) -> 0.075
A38: =E38&F38 -> cd_imv_inp_certif_estimativascore_qualidade | B38: Pilar III | C38: Bens Imóveis - Input | D38: 2. Campo | E38: cd_imv_inp_certif_estimativa | F38: score_qualidade | G38: =INDEX(Auxiliar!$B$16:$B$23,MATCH(Plano_V1!H38,Auxiliar!$C$16:$C$23,0),1) -> 6. Em implementação (re-especificação) | H38: =VLOOKUP(A38,'Aux - pivots1'!$A:$B,2,0) -> 6 | I38: =SUMIFS(Table1[Estimação (horas)],Table1[Tabela],Plano_V1!E38,Table1[Campo],Plano_V1!F38) -> 0.6 | J38: =I38/8 -> 0.075 | K38: sem pendencia | L38: =J38-SUM(M38:FK38) -> 0.075
A39: =E39&F39 -> cd_imv_inp_certif_estimativavlr_cnsm_ano | B39: Pilar III | C39: Bens Imóveis - Input | D39: 2. Campo | E39: cd_imv_inp_certif_estimativa | F39: vlr_cnsm_ano | G39: =INDEX(Auxiliar!$B$16:$B$23,MATCH(Plano_V1!H39,Auxiliar!$C$16:$C$23,0),1) -> 6. Em implementação (re-especificação) | H39: =VLOOKUP(A39,'Aux - pivots1'!$A:$B,2,0) -> 6 | I39: =SUMIFS(Table1[Estimação (horas)],Table1[Tabela],Plano_V1!E39,Table1[Campo],Plano_V1!F39) -> 0.6 | J39: =I39/8 -> 0.075 | K39: sem pendencia | L39: =J39-SUM(M39:FK39) -> 0.075
A40: =E40&F40 -> cd_imv_inp_certif_estimativavlr_emss_ano | B40: Pilar III | C40: Bens Imóveis - Input | D40: 2. Campo | E40: cd_imv_inp_certif_estimativa | F40: vlr_emss_ano | G40: =INDEX(Auxiliar!$B$16:$B$23,MATCH(Plano_V1!H40,Auxiliar!$C$16:$C$23,0),1) -> 6. Em implementação (re-especificação) | H40: =VLOOKUP(A40,'Aux - pivots1'!$A:$B,2,0) -> 6 | I40: =SUMIFS(Table1[Estimação (horas)],Table1[Tabela],Plano_V1!E40,Table1[Campo],Plano_V1!F40) -> 0.6 | J40: =I40/8 -> 0.075 | K40: sem pendencia | L40: =J40-SUM(M40:FK40) -> 0.075
A41: =E41&F41 -> Re-testesn.a. | B41: Pilar III | C41: Bens Imóveis - Input | D41: 2. Campo | E41: Re-testes | F41: n.a. | G41: 7. Por iniciar | I41: =SUM(I28:I40)*D6 -> 3.04 | J41: =I41/8 -> 0.38 | K41: sem pendencia | L41: =J41-SUM(M41:FK41) -> 0.38
A42: =E42&F42 | B42: Pilar III | C42: Bens Imóveis - Output | I42: =SUM(I43:I197) -> 798.75 | J42: =ROUNDUP(I42/8,0) -> 100 | L42: =J42-SUM(M42:FK42) -> 0 | AH42: 0.5 | AI42: 1 | AJ42: 1 | AM42: 1 | AN42: 1 | AO42: 1 | AP42: 0.5 | AR42: 1 | AS42: 2 | AU42: 0.5 | AX42: 1 | AY42: 1 | AZ42: 0.5 | BA42: 1 | BB42: 2 | BC42: 2 | BD42: 2 | BE42: 1.5 | BF42: 0.5 | BG42: 2 | BH42: 2 | BI42: 2 | BJ42: 1.5 | BK42: 0.5 | BL42: 2 | BM42: 2 | BN42: 2 | BO42: 1.5 | BP42: 1.5 | BQ42: 2 | BR42: 2 | BS42: 2 | BT42: 2 | BU42: 2 | BV42: 2 | BW42: 2 | BX42: 2 | BY42: 2 | BZ42: 2 | CA42: 2 | CB42: 2 | CC42: 2 | CD42: 2 | CE42: 2 | CF42: 2 | CG42: 2 | CH42: 2 | CI42: 2 | CJ42: 2 | CK42: 2 | CL42: 2 | CM42: 2 | CN42: 2 | CO42: 2 | CP42: 2 | CQ42: 2 | CR42: 2 | CS42: 2 | CT42: 2 | CU42: 2
A43: =E43&F43 -> cd_imv_out_prcn.a. | B43: Pilar III | C43: Bens Imóveis - Output | D43: 1. Universo | E43: cd_imv_out_prc | F43: n.a. | G43: =INDEX(Auxiliar!$B$16:$B$23,MATCH(Plano_V1!H43,Auxiliar!$C$16:$C$23,0),1) -> 1. Concluído | H43: =VLOOKUP(A43,'Aux - pivots1'!$A:$B,2,0) -> 1 | I43: =SUMIFS(Table1[Estimação (horas)],Table1[Tabela],Plano_V1!E43,Table1[Campo],Plano_V1!F43) -> 8 | J43: =I43/8 -> 1 | K43: cd_imv_out_trz_cred_prc | L43: =J43-SUM(M43:FK43) -> 1
A44: =E44&F44 -> cd_imv_out_prccempresa | B44: Pilar III | C44: Bens Imóveis - Output | D44: 2. Campo | E44: cd_imv_out_prc | F44: cempresa | G44: =INDEX(Auxiliar!$B$16:$B$23,MATCH(Plano_V1!H44,Auxiliar!$C$16:$C$23,0),1) -> 1. Concluído | H44: =VLOOKUP(A44,'Aux - pivots1'!$A:$B,2,0) -> 1 | I44: =SUMIFS(Table1[Estimação (horas)],Table1[Tabela],Plano_V1!E44,Table1[Campo],Plano_V1!F44) -> 4.1 | J44: =I44/8 -> 0.5125 | K44: cd_imv_out_trz_cred_prc | L44: =J44-SUM(M44:FK44) -> 0.5125
A45: =E45&F45 -> cd_imv_out_prcckbalcao | B45: Pilar III | C45: Bens Imóveis - Output | D45: 2. Campo | E45: cd_imv_out_prc | F45: ckbalcao | G45: =INDEX(Auxiliar!$B$16:$B$23,MATCH(Plano_V1!H45,Auxiliar!$C$16:$C$23,0),1) -> 1. Concluído | H45: =VLOOKUP(A45,'Aux - pivots1'!$A:$B,2,0) -> 1 | I45: =SUMIFS(Table1[Estimação (horas)],Table1[Tabela],Plano_V1!E45,Table1[Campo],Plano_V1!F45) -> 4.1 | J45: =I45/8 -> 0.5125 | K45: cd_imv_out_trz_cred_prc | L45: =J45-SUM(M45:FK45) -> 0.5125
A46: =E46&F46 -> cd_imv_out_prccknumcta | B46: Pilar III | C46: Bens Imóveis - Output | D46: 2. Campo | E46: cd_imv_out_prc | F46: cknumcta | G46: =INDEX(Auxiliar!$B$16:$B$23,MATCH(Plano_V1!H46,Auxiliar!$C$16:$C$23,0),1) -> 1. Concluído | H46: =VLOOKUP(A46,'Aux - pivots1'!$A:$B,2,0) -> 1 | I46: =SUMIFS(Table1[Estimação (horas)],Table1[Tabela],Plano_V1!E46,Table1[Campo],Plano_V1!F46) -> 4.1 | J46: =I46/8 -> 0.5125 | K46: cd_imv_out_trz_cred_prc | L46: =J46-SUM(M46:FK46) -> 0.5125
A47: =E47&F47 -> cd_imv_out_prccod_estd_prcs | B47: Pilar III | C47: Bens Imóveis - Output | D47: 2. Campo | E47: cd_imv_out_prc | F47: cod_estd_prcs | G47: =INDEX(Auxiliar!$B$16:$B$23,MATCH(Plano_V1!H47,Auxiliar!$C$16:$C$23,0),1) -> 0. Cancelado | H47: =VLOOKUP(A47,'Aux - pivots1'!$A:$B,2,0) -> 0 | I47: 0 | J47: =I47/8 -> 0 | K47: cd_imv_out_trz_cred_prc | L47: =J47-SUM(M47:FK47) -> 0
A48: =E48&F48 -> cd_imv_out_prccod_grt | B48: Pilar III | C48: Bens Imóveis - Output | D48: 2. Campo | E48: cd_imv_out_prc | F48: cod_grt | G48: =INDEX(Auxiliar!$B$16:$B$23,MATCH(Plano_V1!H48,Auxiliar!$C$16:$C$23,0),1) -> 1. Concluído | H48: =VLOOKUP(A48,'Aux - pivots1'!$A:$B,2,0) -> 1 | I48: =SUMIFS(Table1[Estimação (horas)],Table1[Tabela],Plano_V1!E48,Table1[Campo],Plano_V1!F48) -> 4.1 | J48: =I48/8 -> 0.5125 | K48: cd_imv_out_trz_cred_prc | L48: =J48-SUM(M48:FK48) -> 0.5125
A49: =E49&F49 -> cd_imv_out_prccod_moeda | B49: Pilar III | C49: Bens Imóveis - Output | D49: 2. Campo | E49: cd_imv_out_prc | F49: cod_moeda | G49: =INDEX(Auxiliar!$B$16:$B$23,MATCH(Plano_V1!H49,Auxiliar!$C$16:$C$23,0),1) -> 1. Concluído | H49: =VLOOKUP(A49,'Aux - pivots1'!$A:$B,2,0) -> 1 | I49: =SUMIFS(Table1[Estimação (horas)],Table1[Tabela],Plano_V1!E49,Table1[Campo],Plano_V1!F49) -> 4.1 | J49: =I49/8 -> 0.5125 | K49: cd_imv_out_trz_cred_prc | L49: =J49-SUM(M49:FK49) -> 0.5125
...

Sheet 1. Status Resumo
B6: Sumário Executivo |16 de Setembro a 27 de setembro
B8: 1. Foram realizadas reuniões de esclarecimento relativas à informação proveniente de Gestão de Empreendimentos, tendo sido as especificações dos campos esclarecidos sido enviados para implementação de tecnologia. Concluiram-se as simulações de 2 tabelas do MBI em inglês. Atualmente, encontram-se fechadas 4 tabelas, totalizando 77% de campos concluídos no Modelo de Bens Imóveis. 2. No âmbito do Modelo Verde, foram realizadas várias reuniões que permitiram fechar re-especificações, que neste momento se encontram em validação ou em implementação do lado do IT. 3. Foram concluidos os testes às tabelas de inputs corporativos.
B22: 1. Modelo de Bens Imóveis | G22: Bens Imóveis - Input | H22: Bens Imóveis - Output
C25: Resumo | G25: Detalhe por Tabela | P25: Status (campos) | T25: 45551 | U25: =T25+11 -> 45562 | V25: ∆ | X25: Highlights
P26: 0. Cancelado | T26: =COUNTIFS('2. Status Detalhe Campos'!$H$7:$H$608,'1. Status Resumo'!$P26,'2. Status Detalhe Campos'!$C$7:$C$608,'1. Status Resumo'!$G$22,'2. Status Detalhe Campos'!$D$7:$D$608,"2. Campo")+COUNTIFS('2. Status Detalhe Campos'!$H$7:$H$608,'1. Status Resumo'!$P26,'2. Status Detalhe Campos'!$C$7:$C$608,'1. Status Resumo'!$H$22,'2. Status Detalhe Campos'!$D$7:$D$608,"2. Campo") -> 10 | U26: =COUNTIFS('2. Status Detalhe Campos'!$G$7:$G$608,'1. Status Resumo'!$P26,'2. Status Detalhe Campos'!$C$7:$C$608,'1. Status Resumo'!$G$22,'2. Status Detalhe Campos'!$D$7:$D$608,"2. Campo")+COUNTIFS('2. Status Detalhe Campos'!$G$7:$G$608,'1. Status Resumo'!$P26,'2. Status Detalhe Campos'!$C$7:$C$608,'1. Status Resumo'!$H$22,'2. Status Detalhe Campos'!$D$7:$D$608,"2. Campo") -> 10 | V26: =U26-T26 -> 0 | X26: 1. Realizaram-se reuniões de esclarecimento dos ficheiros da OCR da aplicação de Gestão de Empreendimentos de forma a compreender o Modelo de Dados e garantir coerência na informação. 2. A equipa enviou a especificação dos campos esclarecidos da tabela de certificados energéticos para implementação do IT. 3. Atualmente, existem apenas temas de certificados, 4 tabelas concluídas no Modelo de Bens Imóveis e 77% dos campos fechados, com 15% dos campos em Implementação e 3 campos Em Validação EF. 4. Continuação das simulações do MBI em inglês. Concluíram-se as simulações de 2 tabelas: PROCESS e RESPONSIBILITY_PROCESS_REL.
P27: 1. Concluído | T27: =COUNTIFS('2. Status Detalhe Campos'!$H$7:$H$608,'1. Status Resumo'!$P27,'2. Status Detalhe Campos'!$C$7:$C$608,'1. Status Resumo'!$G$22,'2. Status Detalhe Campos'!$D$7:$D$608,"2. Campo")+COUNTIFS('2. Status Detalhe Campos'!$H$7:$H$608,'1. Status Resumo'!$P27,'2. Status Detalhe Campos'!$C$7:$C$608,'1. Status Resumo'!$H$22,'2. Status Detalhe Campos'!$D$7:$D$608,"2. Campo") -> 132 | U27: =COUNTIFS('2. Status Detalhe Campos'!$G$7:$G$608,'1. Status Resumo'!$P27,'2. Status Detalhe Campos'!$C$7:$C$608,'1. Status Resumo'!$G$22,'2. Status Detalhe Campos'!$D$7:$D$608,"2. Campo")+COUNTIFS('2. Status Detalhe Campos'!$G$7:$G$608,'1. Status Resumo'!$P27,'2. Status Detalhe Campos'!$C$7:$C$608,'1. Status Resumo'!$H$22,'2. Status Detalhe Campos'!$D$7:$D$608,"2. Campo") -> 124 | V27: =U27-T27 -> -8
P28: 2. Em Teste | T28: =COUNTIFS('2. Status Detalhe Campos'!$H$7:$H$608,'1. Status Resumo'!$P28,'2. Status Detalhe Campos'!$C$7:$C$608,'1. Status Resumo'!$G$22,'2. Status Detalhe Campos'!$D$7:$D$608,"2. Campo")+COUNTIFS('2. Status Detalhe Campos'!$H$7:$H$608,'1. Status Resumo'!$P28,'2. Status Detalhe Campos'!$C$7:$C$608,'1. Status Resumo'!$H$22,'2. Status Detalhe Campos'!$D$7:$D$608,"2. Campo") -> 0 | U28: =COUNTIFS('2. Status Detalhe Campos'!$G$7:$G$608,'1. Status Resumo'!$P28,'2. Status Detalhe Campos'!$C$7:$C$608,'1. Status Resumo'!$G$22,'2. Status Detalhe Campos'!$D$7:$D$608,"2. Campo")+COUNTIFS('2. Status Detalhe Campos'!$G$7:$G$608,'1. Status Resumo'!$P28,'2. Status Detalhe Campos'!$C$7:$C$608,'1. Status Resumo'!$H$22,'2. Status Detalhe Campos'!$D$7:$D$608,"2. Campo") -> 0 | V28: =U28-T28 -> 0
D29: ="# "&U34 -> # 161 | P29: 3. Pendente de outros desenvolvimentos | T29: =COUNTIFS('2. Status Detalhe Campos'!$H$7:$H$608,'1. Status Resumo'!$P29,'2. Status Detalhe Campos'!$C$7:$C$608,'1. Status Resumo'!$G$22,'2. Status Detalhe Campos'!$D$7:$D$608,"2. Campo")+COUNTIFS('2. Status Detalhe Campos'!$H$7:$H$608,'1. Status Resumo'!$P29,'2. Status Detalhe Campos'!$C$7:$C$608,'1. Status Resumo'!$H$22,'2. Status Detalhe Campos'!$D$7:$D$608,"2. Campo") -> 0 | U29: =COUNTIFS('2. Status Detalhe Campos'!$G$7:$G$608,'1. Status Resumo'!$P29,'2. Status Detalhe Campos'!$C$7:$C$608,'1. Status Resumo'!$G$22,'2. Status Detalhe Campos'!$D$7:$D$608,"2. Campo")+COUNTIFS('2. Status Detalhe Campos'!$G$7:$G$608,'1. Status Resumo'!$P29,'2. Status Detalhe Campos'!$C$7:$C$608,'1. Status Resumo'!$H$22,'2. Status Detalhe Campos'!$D$7:$D$608,"2. Campo") -> 0 | V29: =U29-T29 -> 0
P30: 4. Validação EF | T30: =COUNTIFS('2. Status Detalhe Campos'!$H$7:$H$608,'1. Status Resumo'!$P30,'2. Status Detalhe Campos'!$C$7:$C$608,'1. Status Resumo'!$G$22,'2. Status Detalhe Campos'!$D$7:$D$608,"2. Campo")+COUNTIFS('2. Status Detalhe Campos'!$H$7:$H$608,'1. Status Resumo'!$P30,'2. Status Detalhe Campos'!$C$7:$C$608,'1. Status Resumo'!$H$22,'2. Status Detalhe Campos'!$D$7:$D$608,"2. Campo") -> 7 | U30: =COUNTIFS('2. Status Detalhe Campos'!$G$7:$G$608,'1. Status Resumo'!$P30,'2. Status Detalhe Campos'!$C$7:$C$608,'1. Status Resumo'!$G$22,'2. Status Detalhe Campos'!$D$7:$D$608,"2. Campo")+COUNTIFS('2. Status Detalhe Campos'!$G$7:$G$608,'1. Status Resumo'!$P30,'2. Status Detalhe Campos'!$C$7:$C$608,'1. Status Resumo'!$H$22,'2. Status Detalhe Campos'!$D$7:$D$608,"2. Campo") -> 3 | V30: =U30-T30 -> -4
P31: 5. Em Correção | R31: (incidências) | T31: =COUNTIFS('2. Status Detalhe Campos'!$H$7:$H$608,'1. Status Resumo'!$P31,'2. Status Detalhe Campos'!$C$7:$C$608,'1. Status Resumo'!$G$22,'2. Status Detalhe Campos'!$D$7:$D$608,"2. Campo")+COUNTIFS('2. Status Detalhe Campos'!$H$7:$H$608,'1. Status Resumo'!$P31,'2. Status Detalhe Campos'!$C$7:$C$608,'1. Status Resumo'!$H$22,'2. Status Detalhe Campos'!$D$7:$D$608,"2. Campo") -> 0 | U31: =COUNTIFS('2. Status Detalhe Campos'!$G$7:$G$608,'1. Status Resumo'!$P31,'2. Status Detalhe Campos'!$C$7:$C$608,'1. Status Resumo'!$G$22,'2. Status Detalhe Campos'!$D$7:$D$608,"2. Campo")+COUNTIFS('2. Status Detalhe Campos'!$G$7:$G$608,'1. Status Resumo'!$P31,'2. Status Detalhe Campos'!$C$7:$C$608,'1. Status Resumo'!$H$22,'2. Status Detalhe Campos'!$D$7:$D$608,"2. Campo") -> 0 | V31: =U31-T31 -> 0
P32: 6. Em implementação (re-especificação) | T32: =COUNTIFS('2. Status Detalhe Campos'!$H$7:$H$608,'1. Status Resumo'!$P32,'2. Status Detalhe Campos'!$C$7:$C$608,'1. Status Resumo'!$G$22,'2. Status Detalhe Campos'!$D$7:$D$608,"2. Campo")+COUNTIFS('2. Status Detalhe Campos'!$H$7:$H$608,'1. Status Resumo'!$P32,'2. Status Detalhe Campos'!$C$7:$C$608,'1. Status Resumo'!$H$22,'2. Status Detalhe Campos'!$D$7:$D$608,"2. Campo") -> 12 | U32: =COUNTIFS('2. Status Detalhe Campos'!$G$7:$G$608,'1. Status Resumo'!$P32,'2. Status Detalhe Campos'!$C$7:$C$608,'1. Status Resumo'!$G$22,'2. Status Detalhe Campos'!$D$7:$D$608,"2. Campo")+COUNTIFS('2. Status Detalhe Campos'!$G$7:$G$608,'1. Status Resumo'!$P32,'2. Status Detalhe Campos'!$C$7:$C$608,'1. Status Resumo'!$H$22,'2. Status Detalhe Campos'!$D$7:$D$608,"2. Campo") -> 24 | V32: =U32-T32 -> 12
P33: 7. Por iniciar | T33: =COUNTIFS('2. Status Detalhe Campos'!$H$7:$H$608,'1. Status Resumo'!$P33,'2. Status Detalhe Campos'!$C$7:$C$608,'1. Status Resumo'!$G$22,'2. Status Detalhe Campos'!$D$7:$D$608,"2. Campo")+COUNTIFS('2. Status Detalhe Campos'!$H$7:$H$608,'1. Status Resumo'!$P33,'2. Status Detalhe Campos'!$C$7:$C$608,'1. Status Resumo'!$H$22,'2. Status Detalhe Campos'!$D$7:$D$608,"2. Campo") -> 0 | U33: =COUNTIFS('2. Status Detalhe Campos'!$G$7:$G$608,'1. Status Resumo'!$P33,'2. Status Detalhe Campos'!$C$7:$C$608,'1. Status Resumo'!$G$22,'2. Status Detalhe Campos'!$D$7:$D$608,"2. Campo")+COUNTIFS('2. Status Detalhe Campos'!$G$7:$G$608,'1. Status Resumo'!$P33,'2. Status Detalhe Campos'!$C$7:$C$608,'1. Status Resumo'!$H$22,'2. Status Detalhe Campos'!$D$7:$D$608,"2. Campo") -> 0 | V33: =U33-T33 -> 0
T34: =SUM(T26:T33) -> 161 | U34: =SUM(U26:U33) -> 161
G35: Status (Tabelas) | P35: Status (Universos)
F36: > | G36: Tabela de Bens Imóveis | L36: OK | O36: > | P36: Universo Bens Colateralizados (MUG) | T36: OK
F37: > | G37: Tabelas de Processos Imobiliários | L37: OK | O37: > | P37: Universo Bens Não Colateralizados (GP) | T37: OK
F38: > | G38: Tabela de Traçabilidade Processo -Bem | L38: OK | O38: > | P38: Universo Bens Adjudicados | T38: Não serão testados neste projeto
F39: > | G39: Tabela de Traçabilidade Crédito - Processo | L39: OK
F40: > | G40: Tabela input de Cerificados Energéticos (Gloval) | L40: Em Implementação
F41: > | G41: Tabela Output de Cerificados Energéticos | L41: Validação Especificação Funcional
B48: 2. Modelo Verde | G48: Modelo Verde - Input | H48: Modelo Verde - Output
C51: Resumo | G51: Detalhe por Tabela | P51: Status (campos) | T51: =T25 -> 45551 | U51: =$U$25 -> 45562 | V51: ∆ | X51: Highlights
P52: 0. Cancelado | T52: =COUNTIFS('2. Status Detalhe Campos'!$H$7:$H$608,'1. Status Resumo'!$P52,'2. Status Detalhe Campos'!$C$7:$C$608,'1. Status Resumo'!$G$48,'2. Status Detalhe Campos'!$D$7:$D$608,"2. Campo")+COUNTIFS('2. Status Detalhe Campos'!$H$7:$H$608,'1. Status Resumo'!$P52,'2. Status Detalhe Campos'!$C$7:$C$608,'1. Status Resumo'!$H$48,'2. Status Detalhe Campos'!$D$7:$D$608,"2. Campo") -> 13 | U52: =COUNTIFS('2. Status Detalhe Campos'!$G$7:$G$608,'1. Status Resumo'!$P52,'2. Status Detalhe Campos'!$C$7:$C$608,'1. Status Resumo'!$G$48,'2. Status Detalhe Campos'!$D$7:$D$608,"2. Campo")+COUNTIFS('2. Status Detalhe Campos'!$G$7:$G$608,'1. Status Resumo'!$P52,'2. Status Detalhe Campos'!$C$7:$C$608,'1. Status Resumo'!$H$48,'2. Status Detalhe Campos'!$D$7:$D$608,"2. Campo") -> 14 | V52: =U52-T52 -> 1 | X52: 1. Continua em curso o assessment ao Modelo Verde. 2. Temas endereçados: 2.1 Inputs Corporativos: Foi carregado e testado o input nace (modesg_inp_emss_nace), após alteração manual ao campo do cod nace. 2.2. Universo de Veiculos (Modesg_out_ems_vcls): - Já foi partilhada a re-especificação do novo universo com IT para implementação - Adicionalmente, a especificação da nova tat já foi também partilhada com o IT do MUG para implementação - Após reunião com CDO relativamente à tabela de parametrização, a mesma foi aprovada e estamos a fechar a especificação (dependente de resposta do lease). - Estamos a terminar a re-especificação dos campos das scopes. 2.3. Tabela de Clientes (modesg_out_empr_info_nfin) - O universo de clientes foi testado e está ok - Foram partilhados 4 re-especificações relativamente aos campos cod nace, flag exclusão de paris, flg nfrd e rácios de eligibilidade e flags de risco físico para aprovação. - Estamos a terminar a re-especificação dos campos das scopes. 2.4. Tabela de Marcação Verde (output e parametrização) Foi realizada uma sessão de validação com o CDO e já foi partilhado o e-mail de re-especificação para desenvolvimento por parte do IT. Aguardamos o envio da tabela de parametrização com os códigos das categorias atualizados pelo Controlo de Gestão. 2.5. Tabela de Bens Imóveis -Após reunião com CDO relativamente à tabela de parametrização, a mesma foi aprovada e estamos a fechar a especificação (dependente de resposta do lease) - Foi partilhada a re-especificações relativa aos campos das flags de risco físico para aprovação. -O término da re-especificação dos campos de scopes desta tabela está dependente de uma dúvida de uma metodologia colocada à corporação e da tabela de parametrização. Contudo, parte da re-especificação já foi partilhada com o IT.
P53: 1. Concluído | T53: =COUNTIFS('2. Status Detalhe Campos'!$H$7:$H$608,'1. Status Resumo'!$P53,'2. Status Detalhe Campos'!$C$7:$C$608,'1. Status Resumo'!$G$48,'2. Status Detalhe Campos'!$D$7:$D$608,"2. Campo")+COUNTIFS('2. Status Detalhe Campos'!$H$7:$H$608,'1. Status Resumo'!$P53,'2. Status Detalhe Campos'!$C$7:$C$608,'1. Status Resumo'!$H$48,'2. Status Detalhe Campos'!$D$7:$D$608,"2. Campo") -> 148 | U53: =COUNTIFS('2. Status Detalhe Campos'!$G$7:$G$608,'1. Status Resumo'!$P53,'2. Status Detalhe Campos'!$C$7:$C$608,'1. Status Resumo'!$G$48,'2. Status Detalhe Campos'!$D$7:$D$608,"2. Campo")+COUNTIFS('2. Status Detalhe Campos'!$G$7:$G$608,'1. Status Resumo'!$P53,'2. Status Detalhe Campos'!$C$7:$C$608,'1. Status Resumo'!$H$48,'2. Status Detalhe Campos'!$D$7:$D$608,"2. Campo") -> 150 | V53: =U53-T53 -> 2
P54: 2. Em Teste | T54: =COUNTIFS('2. Status Detalhe Campos'!$H$7:$H$608,'1. Status Resumo'!$P54,'2. Status Detalhe Campos'!$C$7:$C$608,'1. Status Resumo'!$G$48,'2. Status Detalhe Campos'!$D$7:$D$608,"2. Campo")+COUNTIFS('2. Status Detalhe Campos'!$H$7:$H$608,'1. Status Resumo'!$P54,'2. Status Detalhe Campos'!$C$7:$C$608,'1. Status Resumo'!$H$48,'2. Status Detalhe Campos'!$D$7:$D$608,"2. Campo") -> 11 | U54: =COUNTIFS('2. Status Detalhe Campos'!$G$7:$G$608,'1. Status Resumo'!$P54,'2. Status Detalhe Campos'!$C$7:$C$608,'1. Status Resumo'!$G$48,'2. Status Detalhe Campos'!$D$7:$D$608,"2. Campo")+COUNTIFS('2. Status Detalhe Campos'!$G$7:$G$608,'1. Status Resumo'!$P54,'2. Status Detalhe Campos'!$C$7:$C$608,'1. Status Resumo'!$H$48,'2. Status Detalhe Campos'!$D$7:$D$608,"2. Campo") -> 15 | V54: =U54-T54 -> 4
D55: ="# "&U60 -> # 245 | P55: 3. Pendente de outros desenvolvimentos | T55: =COUNTIFS('2. Status Detalhe Campos'!$H$7:$H$608,'1. Status Resumo'!$P55,'2. Status Detalhe Campos'!$C$7:$C$608,'1. Status Resumo'!$G$48,'2. Status Detalhe Campos'!$D$7:$D$608,"2. Campo")+COUNTIFS('2. Status Detalhe Campos'!$H$7:$H$608,'1. Status Resumo'!$P55,'2. Status Detalhe Campos'!$C$7:$C$608,'1. Status Resumo'!$H$48,'2. Status Detalhe Campos'!$D$7:$D$608,"2. Campo") -> 0 | U55: =COUNTIFS('2. Status Detalhe Campos'!$G$7:$G$608,'1. Status Resumo'!$P55,'2. Status Detalhe Campos'!$C$7:$C$608,'1. Status Resumo'!$G$48,'2. Status Detalhe Campos'!$D$7:$D$608,"2. Campo")+COUNTIFS('2. Status Detalhe Campos'!$G$7:$G$608,'1. Status Resumo'!$P55,'2. Status Detalhe Campos'!$C$7:$C$608,'1. Status Resumo'!$H$48,'2. Status Detalhe Campos'!$D$7:$D$608,"2. Campo") -> 0 | V55: =U55-T55 -> 0
P56: 4. Validação EF | T56: =COUNTIFS('2. Status Detalhe Campos'!$H$7:$H$608,'1. Status Resumo'!$P56,'2. Status Detalhe Campos'!$C$7:$C$608,'1. Status Resumo'!$G$48,'2. Status Detalhe Campos'!$D$7:$D$608,"2. Campo")+COUNTIFS('2. Status Detalhe Campos'!$H$7:$H$608,'1. Status Resumo'!$P56,'2. Status Detalhe Campos'!$C$7:$C$608,'1. Status Resumo'!$H$48,'2. Status Detalhe Campos'!$D$7:$D$608,"2. Campo") -> 43 | U56: =COUNTIFS('2. Status Detalhe Campos'!$G$7:$G$608,'1. Status Resumo'!$P56,'2. Status Detalhe Campos'!$C$7:$C$608,'1. Status Resumo'!$G$48,'2. Status Detalhe Campos'!$D$7:$D$608,"2. Campo")+COUNTIFS('2. Status Detalhe Campos'!$G$7:$G$608,'1. Status Resumo'!$P56,'2. Status Detalhe Campos'!$C$7:$C$608,'1. Status Resumo'!$H$48,'2. Status Detalhe Campos'!$D$7:$D$608,"2. Campo") -> 36 | V56: =U56-T56 -> -7
P57: 5. Em Correção | R57: (incidências) | T57: =COUNTIFS('2. Status Detalhe Campos'!$H$7:$H$608,'1. Status Resumo'!$P57,'2. Status Detalhe Campos'!$C$7:$C$608,'1. Status Resumo'!$G$48,'2. Status Detalhe Campos'!$D$7:$D$608,"2. Campo")+COUNTIFS('2. Status Detalhe Campos'!$H$7:$H$608,'1. Status Resumo'!$P57,'2. Status Detalhe Campos'!$C$7:$C$608,'1. Status Resumo'!$H$48,'2. Status Detalhe Campos'!$D$7:$D$608,"2. Campo") -> 0 | U57: =COUNTIFS('2. Status Detalhe Campos'!$G$7:$G$608,'1. Status Resumo'!$P57,'2. Status Detalhe Campos'!$C$7:$C$608,'1. Status Resumo'!$G$48,'2. Status Detalhe Campos'!$D$7:$D$608,"2. Campo")+COUNTIFS('2. Status Detalhe Campos'!$G$7:$G$608,'1. Status Resumo'!$P57,'2. Status Detalhe Campos'!$C$7:$C$608,'1. Status Resumo'!$H$48,'2. Status Detalhe Campos'!$D$7:$D$608,"2. Campo") -> 0 | V57: =U57-T57 -> 0
P58: 6. Em implementação (re-especificação) | T58: =COUNTIFS('2. Status Detalhe Campos'!$H$7:$H$608,'1. Status Resumo'!$P58,'2. Status Detalhe Campos'!$C$7:$C$608,'1. Status Resumo'!$G$48,'2. Status Detalhe Campos'!$D$7:$D$608,"2. Campo")+COUNTIFS('2. Status Detalhe Campos'!$H$7:$H$608,'1. Status Resumo'!$P58,'2. Status Detalhe Campos'!$C$7:$C$608,'1. Status Resumo'!$H$48,'2. Status Detalhe Campos'!$D$7:$D$608,"2. Campo") -> 30 | U58: =COUNTIFS('2. Status Detalhe Campos'!$G$7:$G$608,'1. Status Resumo'!$P58,'2. Status Detalhe Campos'!$C$7:$C$608,'1. Status Resumo'!$G$48,'2. Status Detalhe Campos'!$D$7:$D$608,"2. Campo")+COUNTIFS('2. Status Detalhe Campos'!$G$7:$G$608,'1. Status Resumo'!$P58,'2. Status Detalhe Campos'!$C$7:$C$608,'1. Status Resumo'!$H$48,'2. Status Detalhe Campos'!$D$7:$D$608,"2. Campo") -> 30 | V58: =U58-T58 -> 0
P59: 7. Por iniciar | T59: =COUNTIFS('2. Status Detalhe Campos'!$H$7:$H$608,'1. Status Resumo'!$P59,'2. Status Detalhe Campos'!$C$7:$C$608,'1. Status Resumo'!$G$48,'2. Status Detalhe Campos'!$D$7:$D$608,"2. Campo")+COUNTIFS('2. Status Detalhe Campos'!$H$7:$H$608,'1. Status Resumo'!$P59,'2. Status Detalhe Campos'!$C$7:$C$608,'1. Status Resumo'!$H$48,'2. Status Detalhe Campos'!$D$7:$D$608,"2. Campo") -> 0 | U59: =COUNTIFS('2. Status Detalhe Campos'!$G$7:$G$608,'1. Status Resumo'!$P59,'2. Status Detalhe Campos'!$C$7:$C$608,'1. Status Resumo'!$G$48,'2. Status Detalhe Campos'!$D$7:$D$608,"2. Campo")+COUNTIFS('2. Status Detalhe Campos'!$G$7:$G$608,'1. Status Resumo'!$P59,'2. Status Detalhe Campos'!$C$7:$C$608,'1. Status Resumo'!$H$48,'2. Status Detalhe Campos'!$D$7:$D$608,"2. Campo") -> 0 | V59: =U59-T59 -> 0
T60: =SUM(T52:T59) -> 245 | U60: =SUM(U52:U59) -> 245
P62: Status (Universos - Inputs)
O63: > | P63: modesg_inp_risco_fisico | T63: OK
O64: > | P64: modesg_inp_nfrd_alinhamento_tax | T64: OK
O65: > | P65: modesg_inp_km_medios_emss_vcls | T65: OK
O66: > | P66: modesg_inp_emss_vcls | T66: OK
O67: > | P67: modesg_inp_emss_scib | T67: OK
O68: > | P68: modesg_inp_emss_nace | T68: OK
O69: > | P69: modesg_inp_emss_bens_imoveis | T69: OK
O70: > | P70: modesg_inp_empr_excl_paris | T70: OK
...

Sheet 2. Status Detalhe Campos
B6: Âmbito | C6: Sub-âmbito | D6: Tipo de teste | E6: Tabela | F6: Campo | G6: Status Atual | H6: Status Anterior | I6: Observações | J6: Data de Pedido correção/esclarecimento | K6: Data de correção prevista | L6: Data de correção efetiva | M6: Data Reunião
A7: =E7&F7 -> cd_imv_inp_certif_estimativan.a. | B7: Pilar III | C7: Bens Imóveis - Input | D7: 1. Universo | E7: cd_imv_inp_certif_estimativa | F7: n.a. | G7: =VLOOKUP(A7,Plano_V3!$A$27:$G$583,7,0) -> 6. Em implementação (re-especificação) | H7: 6. Em implementação (re-especificação) | J7: =IF(VLOOKUP(A7,'Aux - pivots1'!$A:$E,3,0)=0, "",VLOOKUP(A7,'Aux - pivots1'!$A:$E,3,0)) | K7: =IF(VLOOKUP(A7,'Aux - pivots1'!$A:$E,4,0)=0, "",VLOOKUP(A7,'Aux - pivots1'!$A:$E,4,0)) | L7: =IF(VLOOKUP(A7,'Aux - pivots1'!$A:$E,5,0)=0, "",VLOOKUP(A7,'Aux - pivots1'!$A:$E,5,0))
A8: =E8&F8 -> cd_imv_inp_certif_estimativacempbem | B8: Pilar III | C8: Bens Imóveis - Input | D8: 2. Campo | E8: cd_imv_inp_certif_estimativa | F8: cempbem | G8: =VLOOKUP(A8,Plano_V3!$A$27:$G$583,7,0) -> 6. Em implementação (re-especificação) | H8: 6. Em implementação (re-especificação) | J8: =IF(VLOOKUP(A8,'Aux - pivots1'!$A:$E,3,0)=0, "",VLOOKUP(A8,'Aux - pivots1'!$A:$E,3,0)) | K8: =IF(VLOOKUP(A8,'Aux - pivots1'!$A:$E,4,0)=0, "",VLOOKUP(A8,'Aux - pivots1'!$A:$E,4,0)) | L8: =IF(VLOOKUP(A8,'Aux - pivots1'!$A:$E,5,0)=0, "",VLOOKUP(A8,'Aux - pivots1'!$A:$E,5,0))
A9: =E9&F9 -> cd_imv_inp_certif_estimativachave_encriptada | B9: Pilar III | C9: Bens Imóveis - Input | D9: 2. Campo | E9: cd_imv_inp_certif_estimativa | F9: chave_encriptada | G9: =VLOOKUP(A9,Plano_V3!$A$27:$G$583,7,0) -> 6. Em implementação (re-especificação) | H9: 6. Em implementação (re-especificação) | J9: =IF(VLOOKUP(A9,'Aux - pivots1'!$A:$E,3,0)=0, "",VLOOKUP(A9,'Aux - pivots1'!$A:$E,3,0)) | K9: =IF(VLOOKUP(A9,'Aux - pivots1'!$A:$E,4,0)=0, "",VLOOKUP(A9,'Aux - pivots1'!$A:$E,4,0)) | L9: =IF(VLOOKUP(A9,'Aux - pivots1'!$A:$E,5,0)=0, "",VLOOKUP(A9,'Aux - pivots1'!$A:$E,5,0))
A10: =E10&F10 -> cd_imv_inp_certif_estimativackbalbem | B10: Pilar III | C10: Bens Imóveis - Input | D10: 2. Campo | E10: cd_imv_inp_certif_estimativa | F10: ckbalbem | G10: =VLOOKUP(A10,Plano_V3!$A$27:$G$583,7,0) -> 6. Em implementação (re-especificação) | H10: 6. Em implementação (re-especificação) | J10: =IF(VLOOKUP(A10,'Aux - pivots1'!$A:$E,3,0)=0, "",VLOOKUP(A10,'Aux - pivots1'!$A:$E,3,0)) | K10: =IF(VLOOKUP(A10,'Aux - pivots1'!$A:$E,4,0)=0, "",VLOOKUP(A10,'Aux - pivots1'!$A:$E,4,0)) | L10: =IF(VLOOKUP(A10,'Aux - pivots1'!$A:$E,5,0)=0, "",VLOOKUP(A10,'Aux - pivots1'!$A:$E,5,0))
A11: =E11&F11 -> cd_imv_inp_certif_estimativackctabem | B11: Pilar III | C11: Bens Imóveis - Input | D11: 2. Campo | E11: cd_imv_inp_certif_estimativa | F11: ckctabem | G11: =VLOOKUP(A11,Plano_V3!$A$27:$G$583,7,0) -> 6. Em implementação (re-especificação) | H11: 6. Em implementação (re-especificação) | J11: =IF(VLOOKUP(A11,'Aux - pivots1'!$A:$E,3,0)=0, "",VLOOKUP(A11,'Aux - pivots1'!$A:$E,3,0)) | K11: =IF(VLOOKUP(A11,'Aux - pivots1'!$A:$E,4,0)=0, "",VLOOKUP(A11,'Aux - pivots1'!$A:$E,4,0)) | L11: =IF(VLOOKUP(A11,'Aux - pivots1'!$A:$E,5,0)=0, "",VLOOKUP(A11,'Aux - pivots1'!$A:$E,5,0))
A12: =E12&F12 -> cd_imv_inp_certif_estimativackrefbem | B12: Pilar III | C12: Bens Imóveis - Input | D12: 2. Campo | E12: cd_imv_inp_certif_estimativa | F12: ckrefbem | G12: =VLOOKUP(A12,Plano_V3!$A$27:$G$583,7,0) -> 6. Em implementação (re-especificação) | H12: 6. Em implementação (re-especificação) | J12: =IF(VLOOKUP(A12,'Aux - pivots1'!$A:$E,3,0)=0, "",VLOOKUP(A12,'Aux - pivots1'!$A:$E,3,0)) | K12: =IF(VLOOKUP(A12,'Aux - pivots1'!$A:$E,4,0)=0, "",VLOOKUP(A12,'Aux - pivots1'!$A:$E,4,0)) | L12: =IF(VLOOKUP(A12,'Aux - pivots1'!$A:$E,5,0)=0, "",VLOOKUP(A12,'Aux - pivots1'!$A:$E,5,0))
A13: =E13&F13 -> cd_imv_inp_certif_estimativadata_extraccao_info | B13: Pilar III | C13: Bens Imóveis - Input | D13: 2. Campo | E13: cd_imv_inp_certif_estimativa | F13: data_extraccao_info | G13: =VLOOKUP(A13,Plano_V3!$A$27:$G$583,7,0) -> 6. Em implementação (re-especificação) | H13: 6. Em implementação (re-especificação) | J13: =IF(VLOOKUP(A13,'Aux - pivots1'!$A:$E,3,0)=0, "",VLOOKUP(A13,'Aux - pivots1'!$A:$E,3,0)) | K13: =IF(VLOOKUP(A13,'Aux - pivots1'!$A:$E,4,0)=0, "",VLOOKUP(A13,'Aux - pivots1'!$A:$E,4,0)) | L13: =IF(VLOOKUP(A13,'Aux - pivots1'!$A:$E,5,0)=0, "",VLOOKUP(A13,'Aux - pivots1'!$A:$E,5,0))
A14: =E14&F14 -> cd_imv_inp_certif_estimativaepc | B14: Pilar III | C14: Bens Imóveis - Input | D14: 2. Campo | E14: cd_imv_inp_certif_estimativa | F14: epc | G14: =VLOOKUP(A14,Plano_V3!$A$27:$G$583,7,0) -> 6. Em implementação (re-especificação) | H14: 6. Em implementação (re-especificação) | J14: =IF(VLOOKUP(A14,'Aux - pivots1'!$A:$E,3,0)=0, "",VLOOKUP(A14,'Aux - pivots1'!$A:$E,3,0)) | K14: =IF(VLOOKUP(A14,'Aux - pivots1'!$A:$E,4,0)=0, "",VLOOKUP(A14,'Aux - pivots1'!$A:$E,4,0)) | L14: =IF(VLOOKUP(A14,'Aux - pivots1'!$A:$E,5,0)=0, "",VLOOKUP(A14,'Aux - pivots1'!$A:$E,5,0))
A15: =E15&F15 -> cd_imv_inp_certif_estimativafornecedor | B15: Pilar III | C15: Bens Imóveis - Input | D15: 2. Campo | E15: cd_imv_inp_certif_estimativa | F15: fornecedor | G15: =VLOOKUP(A15,Plano_V3!$A$27:$G$583,7,0) -> 6. Em implementação (re-especificação) | H15: 6. Em implementação (re-especificação) | J15: =IF(VLOOKUP(A15,'Aux - pivots1'!$A:$E,3,0)=0, "",VLOOKUP(A15,'Aux - pivots1'!$A:$E,3,0)) | K15: =IF(VLOOKUP(A15,'Aux - pivots1'!$A:$E,4,0)=0, "",VLOOKUP(A15,'Aux - pivots1'!$A:$E,4,0)) | L15: =IF(VLOOKUP(A15,'Aux - pivots1'!$A:$E,5,0)=0, "",VLOOKUP(A15,'Aux - pivots1'!$A:$E,5,0))
