Workbook

Sheet Plano_V1
B6: Re-testes - input | D6: 0.2 | M6: =M7-M10 -> 0 | N6: =N7-N10 -> 0 | O6: =O7-O10 -> 0 | P6: =P7-P10 -> 0 | Q6: =Q7-Q10 -> 0 | R6: =R7-R10 -> 0 | S6: =S7-S10 -> 0 | T6: =T7-T10 -> 0 | ... FK6: =FK7-FK10 -> 0
B7: Re-testes - output | D7: =50%*25% -> 0.125 | L7: =AVERAGE(M7:EL7) -> 2.4923077 | M7: 3 | N7: 3 | O7: 3 | P7: 3 | Q7: 3 | R7: 2 | S7: 2 | T7: 2 | U7: 2 | V7: 2 | W7: 2 | X7: 2 | Y7: 2 | Z7: 2 | AA7: 2 | AB7: 2 | AC7: 2 | AD7: 1 | AE7: 1 | AF7: 1 | AG7: 3 | AH7: 3 | AI7: 3 | AJ7: 3 | AK7: 2 | AL7: 3 | AM7: 3 | AN7: 3 | AO7: 3 | AP7: 3 | AQ7: 2 | AR7: 2 | AS7: 2 | AT7: 0 | AU7: 1 | AV7: 1 | AW7: 0 | AX7: 1 | AY7: 1 | AZ7: 1 | BA7: 2 | BB7: 2 | BC7: 2 | BD7: 2 | BE7: 2 | BF7: 2 | BG7: 2 | BH7: 2 | BI7: 2 | BJ7: 2 | BK7: 2 | BL7: 2 | BM7: 2 | BN7: 2 | BO7: 2 | BP7: 3 | BQ7: 3 | BR7: 3 | BS7: 3 | BT7: 3 | BU7: 3 | BV7: 3 | BW7: 3 | BX7: 3 | BY7: 3 | BZ7: 3 | CA7: 3 | CB7: 3 | CC7: 3 | CD7: 3 | CE7: 3 | CF7: 3 | CG7: 3 | CH7: 3 | CI7: 3 | CJ7: 3 | CK7: 3 | CL7: 3 | CM7: 3 | CN7: 3 | CO7: 3 | CP7: 3 | CQ7: 3 | CR7: 3 | CS7: 3 | CT7: 3 | CU7: 3 | CV7: 3 | CW7: 3 | CX7: 3 | CY7: 3 | CZ7: 3 | DA7: 3 | DB7: 3 | DC7: 3 | DD7: 3 | DE7: 3 | DF7: 3 | DG7: 3 | DH7: 3 | DI7: 3 | DJ7: 3 | DK7: 3 | DL7: 3 | DM7: 3 | DN7: 2 | DO7: 3 | DP7: 3 | DQ7: 3 | DR7: 3 | DS7: 3 | DT7: 3 | DU7: 3 | DV7: 3 | DW7: 3 | DX7: 3 | DY7: 3 | DZ7: 3 | EA7: 3 | EB7: 3 | EC7: 3 | ED7: 3 | EE7: 3 | EF7: 3 | EG7: 3 | EH7: 3 | EI7: 0 | EJ7: 0 | EK7: 0 | EL7: 0 | EM7: 0 | EN7: 0 | EO7: 0 | EP7: 3 | EQ7: 3 | ER7: 3 | ES7: 3 | ET7: 3 | EU7: 3 | EV7: 3 | EW7: 3 | EX7: 3 | EY7: 3 | EZ7: 3 | FA7: 3 | FB7: 3 | FC7: 3 | FD7: 3 | FE7: 3 | FF7: 3 | FG7: 3 | FH7: 3 | FI7: 3 | FJ7: 3 | FK7: 3
M10: =SUBTOTAL(9,M14:M636) -> 3 | N10: =SUBTOTAL(9,N14:N636) -> 3 | O10: =SUBTOTAL(9,O14:O636) -> 3 | P10: =SUBTOTAL(9,P14:P636) -> 3 | Q10: =SUBTOTAL(9,Q14:Q636) -> 3 | R10: =SUBTOTAL(9,R14:R636) -> 2 | S10: =SUBTOTAL(9,S14:S636) -> 2 | T10: =SUBTOTAL(9,T14:T636) -> 2 | ... FK10: =SUBTOTAL(9,FK14:FK636) -> 3
M11: Julho | W11: Julho | AJ11: Agosto | BF11: Setembro | CA11: Outubro | CX11: Novembro | DS11: Dezembro | EO11: Janeiro
M12: =M13 -> 45474 | N12: =N13 -> 45475 | O12: =O13 -> 45476 | P12: =P13 -> 45477 | Q12: =Q13 -> 45478 | R12: =R13 -> 45481 | S12: =S13 -> 45482 | T12: =T13 -> 45483 | ... FK12: =FK13 -> 45688
B13: Âmbito | C13: Sub-âmbito | D13: Tipo de teste | E13: Tabela | F13: Campo | G13: Status | H13: Status2 | I13: Horas | J13: Dias | K13: Pendências | L13: Val | M13: 45474 | N13: =WORKDAY(M13,1) -> 45475 | O13: =WORKDAY(N13,1) -> 45476 | P13: =WORKDAY(O13,1) -> 45477 | Q13: =WORKDAY(P13,1) -> 45478 | R13: =WORKDAY(Q13,1) -> 45481 | S13: =WORKDAY(R13,1) -> 45482 | T13: =WORKDAY(S13,1) -> 45483 | U13: =WORKDAY(T13,1) -> 45484 | ... FK13: =WORKDAY(FJ13,1) -> 45688
B14: 1. Assessment | I14: =SUM(I15:I18) -> 280 | J14: =SUM(J15:J18) -> 35
B15: Pilar III | C15: Bens Imóveis | G15: 7. Por iniciar | I15: =J15*8 -> 40 | J15: 5 | L15: =J15-SUM(M15:FK15) -> 0 | W15: 1 | X15: 1 | Y15: 1 | Z15: 1 | AA15: 1
B16: Pilar III | C16: Modelo Verde | G16: 7. Por iniciar | I16: =J16*8 -> 80 | J16: 10 | L16: =J16-SUM(M16:FK16) -> 0 | R16: 2 | S16: 2 | T16: 2 | U16: 2 | V16: 2
B17: Pilar III | C17: Pilar III | G17: 7. Por iniciar | I17: =J17*8 -> 40 | J17: 5 | L17: =J17-SUM(M17:FK17) -> 0 | AB17: 1 | AC17: 1 | AD17: 1 | AE17: 1 | AF17: 0.5 | AG17: 0.5
B18: GD | C18: GD | G18: 7. Por iniciar | I18: =J18*8 -> 120 | J18: 15 | L18: =J18-SUM(M18:FK18) -> 0 | M18: 3 | N18: 3 | O18: 3 | P18: 3 | Q18: 3
B20: 2. Re-especificação | I20: =SUM(I21:I23) -> 120 | J20: =SUM(J21:J23) -> 15
B21: Pilar III | C21: Bens Imóveis | G21: 7. Por iniciar | I21: =J21*8 -> 40 | J21: 5 | L21: =J21-SUM(M21:FK21) -> 0 | W21: 0.5 | AB21: 0.5 | AG21: 0.5 | AL21: 0.5 | AQ21: 0.5 | AV21: 0.5 | BA21: 0.5 | BF21: 0.5 | BK21: 0.5 | BP21: 0.5
B22: Pilar III | C22: Modelo Verde | G22: 7. Por iniciar | I22: =J22*8 -> 40 | J22: 5 | L22: =J22-SUM(M22:FK22) -> 0 | W22: 0.5 | AB22: 0.5 | AG22: 0.5 | AL22: 0.5 | AQ22: 0.5 | AV22: 0.5 | BA22: 0.5 | BF22: 0.5 | BK22: 0.5 | BP22: 0.5
B23: Pilar III | C23: Pilar III | G23: 7. Por iniciar | I23: =J23*8 -> 40 | J23: 5 | L23: =J23-SUM(M23:FK23) -> 0 | BF23: 0.5 | BK23: 0.5 | BP23: 0.5 | BU23: 0.5 | BZ23: 0.5 | CE23: 0.5 | CJ23: 0.5 | CO23: 0.5 | CT23: 0.5 | CY23: 0.5
B25: 3. Testes / Re-testes | I25: =I26+I27+I42+I198+I362+I447 -> 1192.8125 | J25: =J26+J27+J42+J198+J362+J447 -> 151
B26: Testes Regressivos | G26: 7. Por iniciar | I26: =4*22 -> 88 | J26: =I26/8 -> 11 | L26: =J26-SUM(M26:FK26) -> 0 | AA26: 0.5 | AF26: 0.5 | AK26: 0.5 | AP26: 0.5 | AU26: 0.5 | AZ26: 0.5 | BE26: 0.5 | BJ26: 0.5 | BO26: 0.5 | BT26: 0.5 | BY26: 0.5 | CD26: 0.5 | CI26: 0.5 | CN26: 0.5 | CS26: 0.5 | CX26: 0.5 | DC26: 0.5 | DH26: 0.5 | DM26: 0.5 | DR26: 0.5 | DW26: 0.5 | EB26: 0.5
B27: Pilar III | C27: Bens Imóveis - Input | I27: =SUM(I28:I41) -> 0 | J27: =ROUNDUP(I27/8,0) -> 0 | L27: =J27-SUM(M27:FK27) -> -3 | X27: 0.5 | Y27: 0.5 | AC27: 0.5 | AG27: 1 | AH27: 0.5
A28: =E28&F28 -> cd_imv_inp_certif_estimativan.a. | B28: Pilar III | C28: Bens Imóveis - Input | D28: 1. Universo | E28: cd_imv_inp_certif_estimativa | F28: n.a. | G28: =INDEX(Auxiliar!$B$16:$B$24,MATCH(Plano_V1!H28,Auxiliar!$C$16:$C$24,0),1) -> #N/A | H28: =VLOOKUP(A28,'Aux - pivots1'!$A:$B,2,0) -> #N/A | I28: =SUMIFS(Table1[Estimação (horas)],Table1[Tabela],Plano_V1!E28,Table1[Campo],Plano_V1!F28) -> 0 | J28: =I28/8 -> 0 | K28: sem pendencia | L28: =J28-SUM(M28:FK28) -> 0
A29: =E29&F29 -> cd_imv_inp_certif_estimativacempbem | B29: Pilar III | C29: Bens Imóveis - Input | D29: 2. Campo | E29: cd_imv_inp_certif_estimativa | F29: cempbem | G29: =INDEX(Auxiliar!$B$16:$B$24,MATCH(Plano_V1!H29,Auxiliar!$C$16:$C$24,0),1) -> #N/A | H29: =VLOOKUP(A29,'Aux - pivots1'!$A:$B,2,0) -> #N/A | I29: =SUMIFS(Table1[Estimação (horas)],Table1[Tabela],Plano_V1!E29,Table1[Campo],Plano_V1!F29) -> 0 | J29: =I29/8 -> 0 | K29: sem pendencia | L29: =J29-SUM(M29:FK29) -> 0
A30: =E30&F30 -> cd_imv_inp_certif_estimativachave_encriptada | B30: Pilar III | C30: Bens Imóveis - Input | D30: 2. Campo | E30: cd_imv_inp_certif_estimativa | F30: chave_encriptada | G30: =INDEX(Auxiliar!$B$16:$B$24,MATCH(Plano_V1!H30,Auxiliar!$C$16:$C$24,0),1) -> #N/A | H30: =VLOOKUP(A30,'Aux - pivots1'!$A:$B,2,0) -> #N/A | I30: =SUMIFS(Table1[Estimação (horas)],Table1[Tabela],Plano_V1!E30,Table1[Campo],Plano_V1!F30) -> 0 | J30: =I30/8 -> 0 | K30: sem pendencia | L30: =J30-SUM(M30:FK30) -> 0
A31: =E31&F31 -> cd_imv_inp_certif_estimativackbalbem | B31: Pilar III | C31: Bens Imóveis - Input | D31: 2. Campo | E31: cd_imv_inp_certif_estimativa | F31: ckbalbem | G31: =INDEX(Auxiliar!$B$16:$B$24,MATCH(Plano_V1!H31,Auxiliar!$C$16:$C$24,0),1) -> #N/A | H31: =VLOOKUP(A31,'Aux - pivots1'!$A:$B,2,0) -> #N/A | I31: =SUMIFS(Table1[Estimação (horas)],Table1[Tabela],Plano_V1!E31,Table1[Campo],Plano_V1!F31) -> 0 | J31: =I31/8 -> 0 | K31: sem pendencia | L31: =J31-SUM(M31:FK31) -> 0
A32: =E32&F32 -> cd_imv_inp_certif_estimativackctabem | B32: Pilar III | C32: Bens Imóveis - Input | D32: 2. Campo | E32: cd_imv_inp_certif_estimativa | F32: ckctabem | G32: =INDEX(Auxiliar!$B$16:$B$24,MATCH(Plano_V1!H32,Auxiliar!$C$16:$C$24,0),1) -> #N/A | H32: =VLOOKUP(A32,'Aux - pivots1'!$A:$B,2,0) -> #N/A | I32: =SUMIFS(Table1[Estimação (horas)],Table1[Tabela],Plano_V1!E32,Table1[Campo],Plano_V1!F32) -> 0 | J32: =I32/8 -> 0 | K32: sem pendencia | L32: =J32-SUM(M32:FK32) -> 0
A33: =E33&F33 -> cd_imv_inp_certif_estimativackrefbem | B33: Pilar III | C33: Bens Imóveis - Input | D33: 2. Campo | E33: cd_imv_inp_certif_estimativa | F33: ckrefbem | G33: =INDEX(Auxiliar!$B$16:$B$24,MATCH(Plano_V1!H33,Auxiliar!$C$16:$C$24,0),1) -> #N/A | H33: =VLOOKUP(A33,'Aux - pivots1'!$A:$B,2,0) -> #N/A | I33: =SUMIFS(Table1[Estimação (horas)],Table1[Tabela],Plano_V1!E33,Table1[Campo],Plano_V1!F33) -> 0 | J33: =I33/8 -> 0 | K33: sem pendencia | L33: =J33-SUM(M33:FK33) -> 0
A34: =E34&F34 -> cd_imv_inp_certif_estimativadata_extraccao_info | B34: Pilar III | C34: Bens Imóveis - Input | D34: 2. Campo | E34: cd_imv_inp_certif_estimativa | F34: data_extraccao_info | G34: =INDEX(Auxiliar!$B$16:$B$24,MATCH(Plano_V1!H34,Auxiliar!$C$16:$C$24,0),1) -> #N/A | H34: =VLOOKUP(A34,'Aux - pivots1'!$A:$B,2,0) -> #N/A | I34: =SUMIFS(Table1[Estimação (horas)],Table1[Tabela],Plano_V1!E34,Table1[Campo],Plano_V1!F34) -> 0 | J34: =I34/8 -> 0 | K34: sem pendencia | L34: =J34-SUM(M34:FK34) -> 0
A35: =E35&F35 -> cd_imv_inp_certif_estimativaepc | B35: Pilar III | C35: Bens Imóveis - Input | D35: 2. Campo | E35: cd_imv_inp_certif_estimativa | F35: epc | G35: =INDEX(Auxiliar!$B$16:$B$24,MATCH(Plano_V1!H35,Auxiliar!$C$16:$C$24,0),1) -> #N/A | H35: =VLOOKUP(A35,'Aux - pivots1'!$A:$B,2,0) -> #N/A | I35: =SUMIFS(Table1[Estimação (horas)],Table1[Tabela],Plano_V1!E35,Table1[Campo],Plano_V1!F35) -> 0 | J35: =I35/8 -> 0 | K35: sem pendencia | L35: =J35-SUM(M35:FK35) -> 0
A36: =E36&F36 -> cd_imv_inp_certif_estimativafornecedor | B36: Pilar III | C36: Bens Imóveis - Input | D36: 2. Campo | E36: cd_imv_inp_certif_estimativa | F36: fornecedor | G36: =INDEX(Auxiliar!$B$16:$B$24,MATCH(Plano_V1!H36,Auxiliar!$C$16:$C$24,0),1) -> #N/A | H36: =VLOOKUP(A36,'Aux - pivots1'!$A:$B,2,0) -> #N/A | I36: =SUMIFS(Table1[Estimação (horas)],Table1[Tabela],Plano_V1!E36,Table1[Campo],Plano_V1!F36) -> 0 | J36: =I36/8 -> 0 | K36: sem pendencia | L36: =J36-SUM(M36:FK36) -> 0
A37: =E37&F37 -> cd_imv_inp_certif_estimativametodo_info | B37: Pilar III | C37: Bens Imóveis - Input | D37: 2. Campo | E37: cd_imv_inp_certif_estimativa | F37: metodo_info | G37: =INDEX(Auxiliar!$B$16:$B$24,MATCH(Plano_V1!H37,Auxiliar!$C$16:$C$24,0),1) -> #N/A | H37: =VLOOKUP(A37,'Aux - pivots1'!$A:$B,2,0) -> #N/A | I37: =SUMIFS(Table1[Estimação (horas)],Table1[Tabela],Plano_V1!E37,Table1[Campo],Plano_V1!F37) -> 0 | J37: =I37/8 -> 0 | K37: sem pendencia | L37: =J37-SUM(M37:FK37) -> 0
A38: =E38&F38 -> cd_imv_inp_certif_estimativascore_qualidade | B38: Pilar III | C38: Bens Imóveis - Input | D38: 2. Campo | E38: cd_imv_inp_certif_estimativa | F38: score_qualidade | G38: =INDEX(Auxiliar!$B$16:$B$24,MATCH(Plano_V1!H38,Auxiliar!$C$16:$C$24,0),1) -> #N/A | H38: =VLOOKUP(A38,'Aux - pivots1'!$A:$B,2,0) -> #N/A | I38: =SUMIFS(Table1[Estimação (horas)],Table1[Tabela],Plano_V1!E38,Table1[Campo],Plano_V1!F38) -> 0 | J38: =I38/8 -> 0 | K38: sem pendencia | L38: =J38-SUM(M38:FK38) -> 0
A39: =E39&F39 -> cd_imv_inp_certif_estimativavlr_cnsm_ano | B39: Pilar III | C39: Bens Imóveis - Input | D39: 2. Campo | E39: cd_imv_inp_certif_estimativa | F39: vlr_cnsm_ano | G39: =INDEX(Auxiliar!$B$16:$B$24,MATCH(Plano_V1!H39,Auxiliar!$C$16:$C$24,0),1) -> #N/A | H39: =VLOOKUP(A39,'Aux - pivots1'!$A:$B,2,0) -> #N/A | I39: =SUMIFS(Table1[Estimação (horas)],Table1[Tabela],Plano_V1!E39,Table1[Campo],Plano_V1!F39) -> 0 | J39: =I39/8 -> 0 | K39: sem pendencia | L39: =J39-SUM(M39:FK39) -> 0
A40: =E40&F40 -> cd_imv_inp_certif_estimativavlr_emss_ano | B40: Pilar III | C40: Bens Imóveis - Input | D40: 2. Campo | E40: cd_imv_inp_certif_estimativa | F40: vlr_emss_ano | G40: =INDEX(Auxiliar!$B$16:$B$24,MATCH(Plano_V1!H40,Auxiliar!$C$16:$C$24,0),1) -> #N/A | H40: =VLOOKUP(A40,'Aux - pivots1'!$A:$B,2,0) -> #N/A | I40: =SUMIFS(Table1[Estimação (horas)],Table1[Tabela],Plano_V1!E40,Table1[Campo],Plano_V1!F40) -> 0 | J40: =I40/8 -> 0 | K40: sem pendencia | L40: =J40-SUM(M40:FK40) -> 0
A41: =E41&F41 -> Re-testesn.a. | B41: Pilar III | C41: Bens Imóveis - Input | D41: 2. Campo | E41: Re-testes | F41: n.a. | G41: 7. Por iniciar | I41: =SUM(I28:I40)*D6 -> 0 | J41: =I41/8 -> 0 | K41: sem pendencia | L41: =J41-SUM(M41:FK41) -> 0
A42: =E42&F42 | B42: Pilar III | C42: Bens Imóveis - Output | I42: =SUM(I43:I197) -> 0 | J42: =ROUNDUP(I42/8,0) -> 0 | L42: =J42-SUM(M42:FK42) -> -100 | AH42: 0.5 | AI42: 1 | AJ42: 1 | AM42: 1 | AN42: 1 | AO42: 1 | AP42: 0.5 | AR42: 1 | AS42: 2 | AU42: 0.5 | AX42: 1 | AY42: 1 | AZ42: 0.5 | BA42: 1 | BB42: 2 | BC42: 2 | BD42: 2 | BE42: 1.5 | BF42: 0.5 | BG42: 2 | BH42: 2 | BI42: 2 | BJ42: 1.5 | BK42: 0.5 | BL42: 2 | BM42: 2 | BN42: 2 | BO42: 1.5 | BP42: 1.5 | BQ42: 2 | BR42: 2 | BS42: 2 | BT42: 2 | BU42: 2 | BV42: 2 | BW42: 2 | BX42: 2 | BY42: 2 | BZ42: 2 | CA42: 2 | CB42: 2 | CC42: 2 | CD42: 2 | CE42: 2 | CF42: 2 | CG42: 2 | CH42: 2 | CI42: 2 | CJ42: 2 | CK42: 2 | CL42: 2 | CM42: 2 | CN42: 2 | CO42: 2 | CP42: 2 | CQ42: 2 | CR42: 2 | CS42: 2 | CT42: 2 | CU42: 2
A43: =E43&F43 -> cd_imv_out_prcn.a. | B43: Pilar III | C43: Bens Imóveis - Output | D43: 1. Universo | E43: cd_imv_out_prc | F43: n.a. | G43: =INDEX(Auxiliar!$B$16:$B$24,MATCH(Plano_V1!H43,Auxiliar!$C$16:$C$24,0),1) -> #N/A | H43: =VLOOKUP(A43,'Aux - pivots1'!$A:$B,2,0) -> #N/A | I43: =SUMIFS(Table1[Estimação (horas)],Table1[Tabela],Plano_V1!E43,Table1[Campo],Plano_V1!F43) -> 0 | J43: =I43/8 -> 0 | K43: cd_imv_out_trz_cred_prc | L43: =J43-SUM(M43:FK43) -> 0
A44: =E44&F44 -> cd_imv_out_prccempresa | B44: Pilar III | C44: Bens Imóveis - Output | D44: 2. Campo | E44: cd_imv_out_prc | F44: cempresa | G44: =INDEX(Auxiliar!$B$16:$B$24,MATCH(Plano_V1!H44,Auxiliar!$C$16:$C$24,0),1) -> #N/A | H44: =VLOOKUP(A44,'Aux - pivots1'!$A:$B,2,0) -> #N/A | I44: =SUMIFS(Table1[Estimação (horas)],Table1[Tabela],Plano_V1!E44,Table1[Campo],Plano_V1!F44) -> 0 | J44: =I44/8 -> 0 | K44: cd_imv_out_trz_cred_prc | L44: =J44-SUM(M44:FK44) -> 0
A45: =E45&F45 -> cd_imv_out_prcckbalcao | B45: Pilar III | C45: Bens Imóveis - Output | D45: 2. Campo | E45: cd_imv_out_prc | F45: ckbalcao | G45: =INDEX(Auxiliar!$B$16:$B$24,MATCH(Plano_V1!H45,Auxiliar!$C$16:$C$24,0),1) -> #N/A | H45: =VLOOKUP(A45,'Aux - pivots1'!$A:$B,2,0) -> #N/A | I45: =SUMIFS(Table1[Estimação (horas)],Table1[Tabela],Plano_V1!E45,Table1[Campo],Plano_V1!F45) -> 0 | J45: =I45/8 -> 0 | K45: cd_imv_out_trz_cred_prc | L45: =J45-SUM(M45:FK45) -> 0
A46: =E46&F46 -> cd_imv_out_prccknumcta | B46: Pilar III | C46: Bens Imóveis - Output | D46: 2. Campo | E46: cd_imv_out_prc | F46: cknumcta | G46: =INDEX(Auxiliar!$B$16:$B$24,MATCH(Plano_V1!H46,Auxiliar!$C$16:$C$24,0),1) -> #N/A | H46: =VLOOKUP(A46,'Aux - pivots1'!$A:$B,2,0) -> #N/A | I46: =SUMIFS(Table1[Estimação (horas)],Table1[Tabela],Plano_V1!E46,Table1[Campo],Plano_V1!F46) -> 0 | J46: =I46/8 -> 0 | K46: cd_imv_out_trz_cred_prc | L46: =J46-SUM(M46:FK46) -> 0
A47: =E47&F47 -> cd_imv_out_prccod_estd_prcs | B47: Pilar III | C47: Bens Imóveis - Output | D47: 2. Campo | E47: cd_imv_out_prc | F47: cod_estd_prcs | G47: =INDEX(Auxiliar!$B$16:$B$24,MATCH(Plano_V1!H47,Auxiliar!$C$16:$C$24,0),1) -> #N/A | H47: =VLOOKUP(A47,'Aux - pivots1'!$A:$B,2,0) -> #N/A | I47: 0 | J47: =I47/8 -> 0 | K47: cd_imv_out_trz_cred_prc | L47: =J47-SUM(M47:FK47) -> 0
A48: =E48&F48 -> cd_imv_out_prccod_grt | B48: Pilar III | C48: Bens Imóveis - Output | D48: 2. Campo | E48: cd_imv_out_prc | F48: cod_grt | G48: =INDEX(Auxiliar!$B$16:$B$24,MATCH(Plano_V1!H48,Auxiliar!$C$16:$C$24,0),1) -> #N/A | H48: =VLOOKUP(A48,'Aux - pivots1'!$A:$B,2,0) -> #N/A | I48: =SUMIFS(Table1[Estimação (horas)],Table1[Tabela],Plano_V1!E48,Table1[Campo],Plano_V1!F48) -> 0 | J48: =I48/8 -> 0 | K48: cd_imv_out_trz_cred_prc | L48: =J48-SUM(M48:FK48) -> 0
A49: =E49&F49 -> cd_imv_out_prccod_moeda | B49: Pilar III | C49: Bens Imóveis - Output | D49: 2. Campo | E49: cd_imv_out_prc | F49: cod_moeda | G49: =INDEX(Auxiliar!$B$16:$B$24,MATCH(Plano_V1!H49,Auxiliar!$C$16:$C$24,0),1) -> #N/A | H49: =VLOOKUP(A49,'Aux - pivots1'!$A:$B,2,0) -> #N/A | I49: =SUMIFS(Table1[Estimação (horas)],Table1[Tabela],Plano_V1!E49,Table1[Campo],Plano_V1!F49) -> 0 | J49: =I49/8 -> 0 | K49: cd_imv_out_trz_cred_prc | L49: =J49-SUM(M49:FK49) -> 0
...

Sheet 1. Status Resumo FY24
B6: 1. Sumário Executivo |31 de janeiro a 07 de fevereiro
B8: 1 | AG8: 1
C9: Resumo de entregas de Especificações | P9: Detalhe Packages planeados | X9: Highlights
E10: 0 | H10: 1 | L10: 4 | X10: 1. Resumo de especificações: Modelo de Bens Imóveis - Relativo aos requisitos de 2024, foi fechada e partilhada a especificação de 49 campos (conforme planeado), sendo 44 referentes a tabela de input da Gloval e 5 referentes à tabela de certificados. Modelo Verde - Relativo aos requisitos de 2024, foi fechada e partilhada a especificação de 1 campo referente à tabela de clientes (conforme planeado). - Relativo aos requisitos de 2025, foi fechada e partilhada a especificação de 20 campos referente à tabela de clientes (conforme planeado). Loan Tape - Relativo aos requisitos de 2025, foi fechada e partilhada a especificação de 20 campos referente à tabela de clientes (conforme planeado). Denote-se que relativo aos novos requisitos de FY 2025 estavam planeados a entrega de 68 campos ao longo das semanas. No entanto, na nova versão disponibilizada pela corporação verificámos que 2 campos dos partilhados na proposta tinham sido cancelados e foram adicionados 5 novos campos, que por sua vez, perfaz um total de 71 campos. O 1º package de campos foi especificado e partilhado como previsto. Na próxima semana será disponibilizado 30 campos (referentes aos packages 2 e 3). 2. Resumo de testes: Modelo de Bens Imóveis - Relativo aos requisitos de 2024, foi testado 1 campo (rácio NTC) na tabela de certificados (conforme planeado). Em virtude de terem sido verificadas incidências no mesmo, este será re-testado na próxima semana (após correção). Loan Tape - Relativo aos requisitos de 2024, foram testados 3 campos (conforme planeado) e não foram detetadas incidências. No entanto, é necessário re-especificar estes campos em virtude das alterações da nova versão do guia corporativo.
C11: Âmbito | E11: Entregas Semana Anterior | H11: Entregas Semana Atual | L11: Entregas Semana Seguinte | Q11: Dt. Prev. | R11: Req. FY25 | T11: Req. FY25 (atualiz.) | V11: Status
E12: Planeado | F12: Real | G12: ∆ | H12: Semana Ant. | I12: Planeado | J12: Real | K12: ∆ | L12: Semana Ant. | M12: Planeado | N12: Total | O12: 1 | P12: Package 1 | Q12: 27/jan | R12: 20 | T12: =+COUNTIFS('2. Status Detalhe Campos FY24'!$C:$C,"*Pilar*",'2. Status Detalhe Campos FY24'!$I:$I,"*"&O12&"*",'2. Status Detalhe Campos FY24'!T:T,"*Novo Plano*") -> 20 | V12: OK
C13: Modelo de Bens Imóveis | E13: 49 | F13: 49 | G13: =+F13-E13 -> 0 | H13: =+IF(G13<0,-G13,0) -> 0 | I13: 0 | J13: 0 | K13: =+J13-I13 -> 0 | L13: =+IF(K13<0,-K13,0) -> 0 | M13: =+COUNTIFS('2. Status Detalhe Campos FY24'!$C:$C,"*Bens Imóveis*",'2. Status Detalhe Campos FY24'!$I:$I,"*"&$L$10&"*") -> 0 | N13: =+M13+L13 -> 0 | O13: 2 | P13: Package 2 | Q13: 4/fev | R13: 15 | T13: =+COUNTIFS('2. Status Detalhe Campos FY24'!$C:$C,"*Pilar*",'2. Status Detalhe Campos FY24'!$I:$I,"*"&O13&"*",'2. Status Detalhe Campos FY24'!T:T,"*Novo Plano*") -> 14 | V13: OK
C14: Requisitos FY24 | E14: 49 | F14: 49 | G14: =+F14-E14 -> 0 | H14: =+IF(G14<0,-G14,0) -> 0 | I14: 0 | J14: 0 | K14: =+J14-I14 -> 0 | L14: =+IF(K14<0,-K14,0) -> 0 | M14: =+COUNTIFS('2. Status Detalhe Campos FY24'!$C:$C,"*Bens Imóveis*",'2. Status Detalhe Campos FY24'!$I:$I,"*"&$L$10&"*",'2. Status Detalhe Campos FY24'!T:T,"*anterior*") -> 0 | N14: =+M14+L14 -> 0 | O14: 3 | P14: Package 3 | Q14: 5/fev | R14: 14 | T14: =+COUNTIFS('2. Status Detalhe Campos FY24'!$C:$C,"*Pilar*",'2. Status Detalhe Campos FY24'!$I:$I,"*"&O14&"*",'2. Status Detalhe Campos FY24'!T:T,"*Novo Plano*") -> 16 | V14: OK
C15: Novos Requisitos FY25 | E15: 0 | F15: 0 | G15: =+F15-E15 -> 0 | H15: =+IF(G15<0,-G15,0) -> 0 | I15: 0 | J15: 0 | K15: =+J15-I15 -> 0 | L15: =+IF(K15<0,-K15,0) -> 0 | M15: =+COUNTIFS('2. Status Detalhe Campos FY24'!$C:$C,"*Bens Imóveis*",'2. Status Detalhe Campos FY24'!$I:$I,"*"&$L$10&"*",'2. Status Detalhe Campos FY24'!T:T,"*Novo Plano*") -> 0 | N15: =+M15+L15 -> 0 | O15: 4 | P15: Package 4 | Q15: 11/fev | R15: 13 | T15: =+COUNTIFS('2. Status Detalhe Campos FY24'!$C:$C,"*Pilar*",'2. Status Detalhe Campos FY24'!$I:$I,"*"&O15&"*",'2. Status Detalhe Campos FY24'!T:T,"*Novo Plano*") -> 14 | V15: Por Iniciar
C16: Modelo Verde | E16: 21 | F16: 21 | G16: =+F16-E16 -> 0 | H16: =+IF(G16<0,-G16,0) -> 0 | I16: 13 | J16: 13 | K16: =+J16-I16 -> 0 | L16: =+IF(K16<0,-K16,0) -> 0 | M16: =+COUNTIFS('2. Status Detalhe Campos FY24'!$C:$C,"*Verde*",'2. Status Detalhe Campos FY24'!$I:$I,"*"&$L$10&"*") -> 0 | N16: =+M16+L16 -> 0 | O16: 5 | P16: Package 5 | Q16: 17/fev | R16: 6 | T16: =+COUNTIFS('2. Status Detalhe Campos FY24'!$C:$C,"*Pilar*",'2. Status Detalhe Campos FY24'!$I:$I,"*"&O16&"*",'2. Status Detalhe Campos FY24'!T:T,"*Novo Plano*") -> 7 | V16: Por Iniciar
C17: Requisitos FY24 | E17: 1 | F17: 1 | G17: =+F17-E17 -> 0 | H17: =+IF(G17<0,-G17,0) -> 0 | I17: 8 | J17: 8 | K17: =+J17-I17 -> 0 | L17: =+IF(K17<0,-K17,0) -> 0 | M17: =+COUNTIFS('2. Status Detalhe Campos FY24'!$C:$C,"*Verde*",'2. Status Detalhe Campos FY24'!$I:$I,"*"&$L$10&"*",'2. Status Detalhe Campos FY24'!T:T,"*anterior*") -> 0 | N17: =+M17+L17 -> 0 | P17: Total | R17: =+SUM(R12:S16) -> 68 | T17: =+SUM(T12:T16) -> 71
C18: Novos Requisitos FY25 | E18: 20 | F18: 20 | G18: =+F18-E18 -> 0 | H18: =+IF(G18<0,-G18,0) -> 0 | I18: 5 | J18: 5 | K18: =+J18-I18 -> 0 | L18: =+IF(K18<0,-K18,0) -> 0 | M18: =+COUNTIFS('2. Status Detalhe Campos FY24'!$C:$C,"*Verde*",'2. Status Detalhe Campos FY24'!$I:$I,"*"&$L$10&"*",'2. Status Detalhe Campos FY24'!T:T,"*Novo Plano*") -> 0 | N18: =+M18+L18 -> 0
C19: Loan Tape | E19: 20 | F19: 20 | G19: =+F19-E19 -> 0 | H19: =+IF(G19<0,-G19,0) -> 0 | I19: 32 | J19: 32 | K19: =+J19-I19 -> 0 | L19: =+IF(K19<0,-K19,0) -> 0 | M19: =+COUNTIFS('2. Status Detalhe Campos FY24'!$C:$C,"*Pilar*",'2. Status Detalhe Campos FY24'!$I:$I,"*"&$L$10&"*") -> 14 | N19: =+M19+L19 -> 14
C20: Requisitos FY24 | E20: 0 | F20: 0 | G20: =+F20-E20 -> 0 | H20: =+IF(G20<0,-G20,0) -> 0 | I20: 2 | J20: 2 | K20: =+J20-I20 -> 0 | L20: =+IF(K20<0,-K20,0) -> 0 | M20: =+COUNTIFS('2. Status Detalhe Campos FY24'!$C:$C,"*Pilar*",'2. Status Detalhe Campos FY24'!$I:$I,"*"&$L$10&"*",'2. Status Detalhe Campos FY24'!T:T,"*anterior*") -> 0 | N20: =+M20+L20 -> 0
C21: Novos Requisitos FY25 | E21: 20 | F21: 20 | G21: =+F21-E21 -> 0 | H21: =+IF(G21<0,-G21,0) -> 0 | I21: 30 | J21: 30 | K21: =+J21-I21 -> 0 | L21: =+IF(K21<0,-K21,0) -> 0 | M21: =+COUNTIFS('2. Status Detalhe Campos FY24'!$C:$C,"*Pilar*",'2. Status Detalhe Campos FY24'!$I:$I,"*"&$L$10&"*",'2. Status Detalhe Campos FY24'!T:T,"*Novo Plano*") -> 14 | N21: =+M21+L21 -> 14
C22: Total | E22: 90 | F22: 90 | G22: 0 | H22: =+SUM(H13,H16,H19) -> 0 | I22: 45 | J22: 45 | K22: =+SUM(K13,K16,K19) -> 0 | L22: =+SUM(L13,L16,L19) -> 0 | M22: =+SUM(M13,M16,M19) -> 14 | N22: =+SUM(N13,N16,N19) -> 14
C24: Resumo de Testes
E25: 1 | I25: 1 | P25: 2
C26: Âmbito | E26: Semana Anterior | J26: Semana Atual | P26: Semana Seguinte
E27: Planeado | F27: Com Incidên. | G27: Sem Incidên. | H27: Re- Especif. | I27: ∆ | J27: Semana Ant. | K27: Planeado | L27: Com Incidên. | M27: Sem Incidên. | N27: Re- Especif. | O27: ∆ | P27: Semana Ant. | Q27: Planeado | R27: Total
C28: Modelo de Bens Imóveis | E28: 1 | F28: 1 | G28: 0 | H28: 0 | I28: 0 | J28: 1 | K28: 0 | L28: 0 | M28: 1 | N28: 0 | O28: =+SUM(J28:K28)-SUM(L28:N28) -> 0 | P28: 0 | Q28: =+COUNTIFS('2. Status Detalhe Campos FY24'!$C:$C,"*Bens Imóveis*",'2. Status Detalhe Campos FY24'!$J:$J,"*"&$P$25&"*") -> 0 | R28: =+Q28+P28 -> 0
C29: RequisItos FY24 | E29: 1 | F29: 1 | G29: 0 | H29: 0 | I29: 0 | J29: 1 | K29: 0 | L29: 0 | M29: 1 | N29: 0 | O29: =+SUM(J29:K29)-SUM(L29:N29) -> 0 | P29: =+IF(O29<0,-O29,0) -> 0 | Q29: =+COUNTIFS('2. Status Detalhe Campos FY24'!$C:$C,"*Bens Imóveis*",'2. Status Detalhe Campos FY24'!$J:$J,"*"&$P$25&"*",'2. Status Detalhe Campos FY24'!T:T,"*anterior*") -> 0 | R29: =+Q29+P29 -> 0
C30: Novos Requisitos FY25 | E30: 0 | F30: 0 | G30: 0 | H30: 0 | I30: 0 | J30: 0 | K30: 0 | L30: 0 | M30: 0 | N30: 0 | O30: =+SUM(J30:K30)-SUM(L30:N30) -> 0 | P30: =+IF(O30<0,-O30,0) -> 0 | Q30: =+COUNTIFS('2. Status Detalhe Campos FY24'!$C:$C,"*Bens Imóveis*",'2. Status Detalhe Campos FY24'!$J:$J,"*"&$P$25&"*",'2. Status Detalhe Campos FY24'!T:T,"*Novo Plano*") -> 0 | R30: =+Q30+P30 -> 0
C31: Modelo Verde | E31: 0 | F31: 0 | G31: 0 | H31: 0 | I31: 0 | J31: 0 | K31: 0 | L31: 0 | M31: 0 | N31: 0 | O31: =+SUM(J31:K31)-SUM(L31:N31) -> 0 | P31: =+IF(O31<0,-O31,0) -> 0 | Q31: =+COUNTIFS('2. Status Detalhe Campos FY24'!$C:$C,"*Verde*",'2. Status Detalhe Campos FY24'!$J:$J,"*"&$P$25&"*") -> 20 | R31: =+Q31+P31 -> 20
C32: RequisItos FY24 | E32: 0 | F32: 0 | G32: 0 | H32: 0 | I32: 0 | J32: 0 | K32: 0 | L32: 0 | M32: 0 | N32: 0 | O32: =+SUM(J32:K32)-SUM(L32:N32) -> 0 | P32: =+IF(O32<0,-O32,0) -> 0 | Q32: =+COUNTIFS('2. Status Detalhe Campos FY24'!$C:$C,"*Verde*",'2. Status Detalhe Campos FY24'!$J:$J,"*"&$P$25&"*",'2. Status Detalhe Campos FY24'!T:T,"*anterior*") -> 0 | R32: =+Q32+P32 -> 0
C33: Novos Requisitos FY25 | E33: 0 | F33: 0 | G33: 0 | H33: 0 | I33: 0 | J33: 0 | K33: 0 | L33: 0 | M33: 0 | N33: 0 | O33: =+SUM(J33:K33)-SUM(L33:N33) -> 0 | P33: =+IF(O33<0,-O33,0) -> 0 | Q33: =+COUNTIFS('2. Status Detalhe Campos FY24'!$C:$C,"*Verde*",'2. Status Detalhe Campos FY24'!$J:$J,"*"&$P$25&"*",'2. Status Detalhe Campos FY24'!T:T,"*Novo Plano*") -> 20 | R33: =+Q33+P33 -> 20
C34: Loan Tape | E34: 3 | F34: 0 | G34: 0 | H34: 3 | I34: 0 | J34: 0 | K34: 0 | L34: 0 | M34: 0 | N34: 0 | O34: =+SUM(J34:K34)-SUM(L34:N34) -> 0 | P34: =+IF(O34<0,-O34,0) -> 0 | Q34: =+COUNTIFS('2. Status Detalhe Campos FY24'!$C:$C,"*Pilar*",'2. Status Detalhe Campos FY24'!$J:$J,"*"&$P$25&"*") -> 0 | R34: =+Q34+P34 -> 0
C35: RequisItos FY24 | E35: 3 | F35: 0 | G35: 0 | H35: 3 | I35: 0 | J35: 0 | K35: 0 | L35: 0 | M35: 0 | N35: 0 | O35: =+SUM(J35:K35)-SUM(L35:N35) -> 0 | P35: =+IF(O35<0,-O35,0) -> 0 | Q35: =+COUNTIFS('2. Status Detalhe Campos FY24'!$C:$C,"*Pilar*",'2. Status Detalhe Campos FY24'!$J:$J,"*"&$P$25&"*",'2. Status Detalhe Campos FY24'!T:T,"*anterior*") -> 0 | R35: =+Q35+P35 -> 0
C36: Novos Requisitos FY25 | E36: 0 | F36: 0 | G36: 0 | H36: 0 | I36: 0 | J36: 0 | K36: 0 | L36: 0 | M36: 0 | N36: 0 | O36: =+SUM(J36:K36)-SUM(L36:N36) -> 0 | P36: =+IF(O36<0,-O36,0) -> 0 | Q36: =+COUNTIFS('2. Status Detalhe Campos FY24'!$C:$C,"*Pilar*",'2. Status Detalhe Campos FY24'!$J:$J,"*"&$P$25&"*",'2. Status Detalhe Campos FY24'!T:T,"*Novo Plano*") -> 0 | R36: =+Q36+P36 -> 0
C37: Total | E37: 4 | F37: 1 | G37: 0 | H37: 3 | I37: 0 | J37: 1 | K37: 0 | L37: =+SUM(L28,L31,L34) -> 0 | M37: =+SUM(M28,M31,M34) -> 1 | N37: =+SUM(N28,N31,N34) -> 0 | O37: =+SUM(O28,O31,O34) -> 0 | P37: =+SUM(P28,P31,P34) -> 0 | Q37: =+SUM(Q28,Q31,Q34) -> 20 | R37: =+SUM(R28,R31,R34) -> 20
B41: 1 | AG41: 1
B43: 1. Modelo de Bens Imóveis | G43: Bens Imóveis - Input | H43: Bens Imóveis - Output | I43: Modelo Verde - Input | J43: Modelo Verde - Output | K43: Pilar III
C46: Resumo | G46: Detalhe por Tabela | P46: Status (campos) | T46: 45688 | U46: =T46+7 -> 45695 | V46: ∆ | X46: Highlights
P47: 0. Cancelado | T47: =COUNTIFS('2. Status Detalhe Campos FY24'!$H$7:$H$731,'1. Status Resumo FY24'!$P47,'2. Status Detalhe Campos FY24'!$C$7:$C$731,'1. Status Resumo FY24'!$G$43,'2. Status Detalhe Campos FY24'!$D$7:$D$731,"2. Campo")+COUNTIFS('2. Status Detalhe Campos FY24'!$H$7:$H$731,'1. Status Resumo FY24'!$P47,'2. Status Detalhe Campos FY24'!$C$7:$C$731,'1. Status Resumo FY24'!$H$43,'2. Status Detalhe Campos FY24'!$D$7:$D$731,"2. Campo") -> 12 | U47: =COUNTIFS('2. Status Detalhe Campos FY24'!$G$7:$G$731,'1. Status Resumo FY24'!$P47,'2. Status Detalhe Campos FY24'!$C$7:$C$731,'1. Status Resumo FY24'!$G$43,'2. Status Detalhe Campos FY24'!$D$7:$D$731,"2. Campo")+COUNTIFS('2. Status Detalhe Campos FY24'!$G$7:$G$731,'1. Status Resumo FY24'!$P47,'2. Status Detalhe Campos FY24'!$C$7:$C$731,'1. Status Resumo FY24'!$H$43,'2. Status Detalhe Campos FY24'!$D$7:$D$731,"2. Campo") -> 12 | V47: =U47-T47 -> 0 | X47: 1. Gloval: - Os desenvolvimentos referente à Gloval serão entregues pela equipa de Tecnologia no dia 10/02. - Encontrámos uma solução com a equipa de IT que permite avançar com os testes dos campos da tabela de Certificados que são aprovisionados pela tabela de Input da Gloval (4 campos). Contudo, para testar o front e a tabela de Input será necessário obter os acessos ao mesmo. 2. Tabela de Certificados: - Adicionalmente, foi retestado e concluído o novo campo da tabela de certificados (rácio NTC).
P48: RequisItos FY24 | T48: =COUNTIFS('2. Status Detalhe Campos FY24'!$H$7:$H$731,'1. Status Resumo FY24'!$P47,'2. Status Detalhe Campos FY24'!$C$7:$C$731,'1. Status Resumo FY24'!$G$43,'2. Status Detalhe Campos FY24'!$D$7:$D$731,"2. Campo",'2. Status Detalhe Campos FY24'!$T$7:$T$731,"*Plano anterior*") +COUNTIFS('2. Status Detalhe Campos FY24'!$H$7:$H$731,'1. Status Resumo FY24'!$P47,'2. Status Detalhe Campos FY24'!$C$7:$C$731,'1. Status Resumo FY24'!$H$43,'2. Status Detalhe Campos FY24'!$D$7:$D$731,"2. Campo",'2. Status Detalhe Campos FY24'!$T$7:$T$731,"*Plano anterior*") -> 12 | U48: =COUNTIFS('2. Status Detalhe Campos FY24'!$G$7:$G$731,'1. Status Resumo FY24'!$P47,'2. Status Detalhe Campos FY24'!$C$7:$C$731,'1. Status Resumo FY24'!$G$43,'2. Status Detalhe Campos FY24'!$D$7:$D$731,"2. Campo",'2. Status Detalhe Campos FY24'!$T$7:$T$731,"*Plano anterior*") +COUNTIFS('2. Status Detalhe Campos FY24'!$G$7:$G$731,'1. Status Resumo FY24'!$P47,'2. Status Detalhe Campos FY24'!$C$7:$C$731,'1. Status Resumo FY24'!$H$43,'2. Status Detalhe Campos FY24'!$D$7:$D$731,"2. Campo",'2. Status Detalhe Campos FY24'!$T$7:$T$731,"*Plano anterior*") -> 12 | V48: =U48-T48 -> 0
P49: Novos Requisitos FY25 | T49: =COUNTIFS('2. Status Detalhe Campos FY24'!$H$7:$H$731,'1. Status Resumo FY24'!$P48,'2. Status Detalhe Campos FY24'!$C$7:$C$731,'1. Status Resumo FY24'!$G$43,'2. Status Detalhe Campos FY24'!$D$7:$D$731,"2. Campo",'2. Status Detalhe Campos FY24'!$T$7:$T$731,"*Novo Plano*") +COUNTIFS('2. Status Detalhe Campos FY24'!$H$7:$H$731,'1. Status Resumo FY24'!$P48,'2. Status Detalhe Campos FY24'!$C$7:$C$731,'1. Status Resumo FY24'!$H$43,'2. Status Detalhe Campos FY24'!$D$7:$D$731,"2. Campo",'2. Status Detalhe Campos FY24'!$T$7:$T$731,"*Novo Plano*") -> 0 | U49: =COUNTIFS('2. Status Detalhe Campos FY24'!$G$7:$G$731,'1. Status Resumo FY24'!$P47,'2. Status Detalhe Campos FY24'!$C$7:$C$731,'1. Status Resumo FY24'!$G$43,'2. Status Detalhe Campos FY24'!$D$7:$D$731,"2. Campo",'2. Status Detalhe Campos FY24'!$T$7:$T$731,"*Novo Plano*") +COUNTIFS('2. Status Detalhe Campos FY24'!$G$7:$G$731,'1. Status Resumo FY24'!$P47,'2. Status Detalhe Campos FY24'!$C$7:$C$731,'1. Status Resumo FY24'!$H$43,'2. Status Detalhe Campos FY24'!$D$7:$D$731,"2. Campo",'2. Status Detalhe Campos FY24'!$T$7:$T$731,"*Novo Plano*") -> 0 | V49: =U49-T49 -> 0
P50: 1. Concluído | T50: =COUNTIFS('2. Status Detalhe Campos FY24'!$H$7:$H$731,'1. Status Resumo FY24'!$P50,'2. Status Detalhe Campos FY24'!$C$7:$C$731,'1. Status Resumo FY24'!$G$43,'2. Status Detalhe Campos FY24'!$D$7:$D$731,"2. Campo")+COUNTIFS('2. Status Detalhe Campos FY24'!$H$7:$H$731,'1. Status Resumo FY24'!$P50,'2. Status Detalhe Campos FY24'!$C$7:$C$731,'1. Status Resumo FY24'!$H$43,'2. Status Detalhe Campos FY24'!$D$7:$D$731,"2. Campo") -> 143 | U50: =COUNTIFS('2. Status Detalhe Campos FY24'!$G$7:$G$731,'1. Status Resumo FY24'!$P50,'2. Status Detalhe Campos FY24'!$C$7:$C$731,'1. Status Resumo FY24'!$G$43,'2. Status Detalhe Campos FY24'!$D$7:$D$731,"2. Campo")+COUNTIFS('2. Status Detalhe Campos FY24'!$G$7:$G$731,'1. Status Resumo FY24'!$P50,'2. Status Detalhe Campos FY24'!$C$7:$C$731,'1. Status Resumo FY24'!$H$43,'2. Status Detalhe Campos FY24'!$D$7:$D$731,"2. Campo") -> 144 | V50: =U50-T50 -> 1
P51: RequisItos FY24 | T51: =COUNTIFS('2. Status Detalhe Campos FY24'!$H$7:$H$731,'1. Status Resumo FY24'!$P50,'2. Status Detalhe Campos FY24'!$C$7:$C$731,'1. Status Resumo FY24'!$G$43,'2. Status Detalhe Campos FY24'!$D$7:$D$731,"2. Campo",'2. Status Detalhe Campos FY24'!$T$7:$T$731,"*Plano anterior*") +COUNTIFS('2. Status Detalhe Campos FY24'!$H$7:$H$731,'1. Status Resumo FY24'!$P50,'2. Status Detalhe Campos FY24'!$C$7:$C$731,'1. Status Resumo FY24'!$H$43,'2. Status Detalhe Campos FY24'!$D$7:$D$731,"2. Campo",'2. Status Detalhe Campos FY24'!$T$7:$T$731,"*Plano anterior*") -> 143 | U51: =COUNTIFS('2. Status Detalhe Campos FY24'!$G$7:$G$731,'1. Status Resumo FY24'!$P50,'2. Status Detalhe Campos FY24'!$C$7:$C$731,'1. Status Resumo FY24'!$G$43,'2. Status Detalhe Campos FY24'!$D$7:$D$731,"2. Campo",'2. Status Detalhe Campos FY24'!$T$7:$T$731,"*Plano anterior*") +COUNTIFS('2. Status Detalhe Campos FY24'!$G$7:$G$731,'1. Status Resumo FY24'!$P50,'2. Status Detalhe Campos FY24'!$C$7:$C$731,'1. Status Resumo FY24'!$H$43,'2. Status Detalhe Campos FY24'!$D$7:$D$731,"2. Campo",'2. Status Detalhe Campos FY24'!$T$7:$T$731,"*Plano anterior*") -> 144 | V51: =U51-T51 -> 1
P52: Novos Requisitos FY25 | T52: =COUNTIFS('2. Status Detalhe Campos FY24'!$H$7:$H$731,'1. Status Resumo FY24'!$P51,'2. Status Detalhe Campos FY24'!$C$7:$C$731,'1. Status Resumo FY24'!$G$43,'2. Status Detalhe Campos FY24'!$D$7:$D$731,"2. Campo",'2. Status Detalhe Campos FY24'!$T$7:$T$731,"*Novo Plano*") +COUNTIFS('2. Status Detalhe Campos FY24'!$H$7:$H$731,'1. Status Resumo FY24'!$P51,'2. Status Detalhe Campos FY24'!$C$7:$C$731,'1. Status Resumo FY24'!$H$43,'2. Status Detalhe Campos FY24'!$D$7:$D$731,"2. Campo",'2. Status Detalhe Campos FY24'!$T$7:$T$731,"*Novo Plano*") -> 0 | U52: =COUNTIFS('2. Status Detalhe Campos FY24'!$G$7:$G$731,'1. Status Resumo FY24'!$P50,'2. Status Detalhe Campos FY24'!$C$7:$C$731,'1. Status Resumo FY24'!$G$43,'2. Status Detalhe Campos FY24'!$D$7:$D$731,"2. Campo",'2. Status Detalhe Campos FY24'!$T$7:$T$731,"*Novo Plano*") +COUNTIFS('2. Status Detalhe Campos FY24'!$G$7:$G$731,'1. Status Resumo FY24'!$P50,'2. Status Detalhe Campos FY24'!$C$7:$C$731,'1. Status Resumo FY24'!$H$43,'2. Status Detalhe Campos FY24'!$D$7:$D$731,"2. Campo",'2. Status Detalhe Campos FY24'!$T$7:$T$731,"*Novo Plano*") -> 0 | V52: =U52-T52 -> 0
P53: 2.1 Em Teste | T53: =COUNTIFS('2. Status Detalhe Campos FY24'!$H$7:$H$731,'1. Status Resumo FY24'!$P53,'2. Status Detalhe Campos FY24'!$C$7:$C$731,'1. Status Resumo FY24'!$G$43,'2. Status Detalhe Campos FY24'!$D$7:$D$731,"2. Campo")+COUNTIFS('2. Status Detalhe Campos FY24'!$H$7:$H$731,'1. Status Resumo FY24'!$P53,'2. Status Detalhe Campos FY24'!$C$7:$C$731,'1. Status Resumo FY24'!$H$43,'2. Status Detalhe Campos FY24'!$D$7:$D$731,"2. Campo") -> 0 | U53: =COUNTIFS('2. Status Detalhe Campos FY24'!$G$7:$G$731,'1. Status Resumo FY24'!$P53,'2. Status Detalhe Campos FY24'!$C$7:$C$731,'1. Status Resumo FY24'!$G$43,'2. Status Detalhe Campos FY24'!$D$7:$D$731,"2. Campo")+COUNTIFS('2. Status Detalhe Campos FY24'!$G$7:$G$731,'1. Status Resumo FY24'!$P53,'2. Status Detalhe Campos FY24'!$C$7:$C$731,'1. Status Resumo FY24'!$H$43,'2. Status Detalhe Campos FY24'!$D$7:$D$731,"2. Campo") -> 0 | V53: =U53-T53 -> 0
...

Sheet Auxiliar
D2: Estimação Horas
B3: Tipologia de testes | D3: Complexidade
B4: Categorização de Testes | C4: Descrição | D4: Baixa | E4: Média | F4: Alta | H4: Baixa | I4: Média | J4: Alta
B5: 1. Teste de universo | C5: 1. Validação de universo de contratos (quando comparado âmbito "CDG" e "PM", e numero de registos) 2. Controlos sobre o desdobramento de chaves nas relações FR-MIS | D5: 8 | E5: 8 | F5: 8 | H5: 1 | I5: 3 | J5: 8
B6: 2. Simulação | C6: Simulação da especificação funcional. Suplementarmente, realizar reuniões de validações e esclarecimentos funcionais junto do negócio/owner. | D6: 2 | E6: 4 | F6: 8 | H6: 1 | I6: 3 | J6: 4
B7: 3. Testes comparativos (Espec. VS Impl.) | C7: A partir da simulação realizada, comparar resultados com a implementação de IT. | D7: 2 | E7: 4 | F7: 8 | H7: 1 | I7: 1 | J7: 2
B8: 4. Validação de parametrizações | C8: A partir da simulação realizada, comparar com as parametrizações implementadas por IT. | D8: 2 | E8: 4 | F8: 8 | H8: 2 | I8: 4 | J8: 4
B9: 5. Teste comparativos com LT | C9: Garantir que a informação do campo da LT-ESTR âmbito 'PM' está espelhado no âmbito 'CDG'. | D9: 1 | E9: 1 | F9: 1
B10: 6. Validação de formatos | C10: Validação de formato de acordo com o que é esperado pela Corporação (incluindo validação de codelists, missing e default values) Validar especificação e controlos da especificação vs o que está implementado | D10: 0.1 | E10: 0.1 | F10: 0.1 | H10: 0.1 | I10: 0.5 | J10: 0.5
B11: 7. Validação de controlos corporativos | C11: Validar controlos corporativos e se a especificação cumpre os requisitos. | D11: 1 | E11: 2 | F11: 2
B12: 8. Teste de Carregamento | C12: Garantir que o carregamento do ficheiro é realizado com sucesso no Front. | D12: 0.5 | E12: 0.5 | F12: 0.5 | H12: 0.5 | I12: 0.5 | J12: 0.5
B13: 9. Teste de Integridade | C13: Garantir integridade entre o ficheiro importado pela equipa de testes e o ficheiro de tecnologia (Ex: Garantir que a informação de todos os campos está correta de acordo com os dados corporativos) | D13: 0.5 | E13: 0.5 | F13: 0.5 | H13: 0.5 | I13: 0.5 | J13: 0.5
B15: Status
B16: 1. Concluído | C16: =_xlfn.NUMBERVALUE(LEFT(B16,1)) -> 1 | D16: 1 | E16: 1
A17: Pendente de outros campos/tabelas | B17: 3. Pendente de outros desenvolvimentos | C17: 4 | D17: 0.25 | E17: 0
B18: 7. Por iniciar | C18: 8 | D18: 0 | E18: 0
B19: 2.1 Em Teste | C19: =_xlfn.NUMBERVALUE(LEFT(B19,1)) -> 2 | D19: 0.5 | E19: 0.25
B20: 2.2 Em especificação | C20: 3 | D20: 0.5 | E20: 0
A21: Validação da Susana/LCM/Corp/conceito/alterações | B21: 4. Validação EF | C21: 5 | D21: 0.25 | E21: 0.25
A22: Por IT | B22: 5. Em Correção | C22: 6 | D22: 0.25 | E22: 0
A23: Por IT | B23: 6. Em implementação | C23: 7 | D23: 0.25 | E23: 0
A24: Campo eliminado | B24: 0. Cancelado | C24: =_xlfn.NUMBERVALUE(LEFT(B24,1)) -> 0 | D24: 0 | E24: 0

Sheet Aux - Pivots2
B2: 1. Visão Geral
B6: Âmbito | C6: Pilar III
B7: Tipo de teste | C7: 2. Campo
C9: Column Labels
C10: 0. Cancelado | D10: 1. Concluído | E10: 2.1 Em Teste | F10: 3. Pendente de outros desenvolvimentos | G10: 4. Validação EF | H10: 7. Por iniciar | I10: 6. Em implementação | J10: 2.2 Em especificação | K10: Grand Total
B11: Count of Campo | C11: 32 | D11: 444 | E11: 26 | F11: 10 | G11: 2 | H11: 21 | I11: 113 | J11: 58 | K11: 706
B20: Âmbito | C20: Pilar III
B21: Tipo de teste | C21: 2. Campo
B23: Row Labels | C23: Count of Campo
B24: 0. Cancelado | C24: 32
B25: 1. Concluído | C25: 444
B26: 2.1 Em Teste | C26: 26
B27: 3. Pendente de outros desenvolvimentos | C27: 10
B28: 4. Validação EF | C28: 2
B29: 7. Por iniciar | C29: 21
B30: 6. Em implementação | C30: 113
B31: 2.2 Em especificação | C31: 58
B32: Grand Total | C32: 706
B42: 2. Modelo Bens imóveis
B45: Âmbito | C45: Pilar III
B46: Sub-âmbito | C46: (Multiple Items)
B47: Tipo de teste | C47: 2. Campo
B49: Count of Campo | C49: Column Labels
B50: Row Labels | C50: 0. Cancelado | D50: 1. Concluído | E50: 6. Em implementação | F50: Grand Total
B51: RESPONSIBILITY_PROCESS_REL | C51: 3 | D51: 17 | F51: 20
B52: PROPERTY_ENERGY_CERTIFICATE | D52: 69 | E52: 4 | F52: 73
B53: PROPERTY | C53: 2 | D53: 31 | F53: 33
B54: PROCESS_PROPERTY_REL | C54: 1 | D54: 14 | F54: 15
B55: PROCESS | C55: 4 | D55: 13 | F55: 17
B56: ENERGY_CERTIFICATE_EST_INPUT | C56: 2 | E56: 44 | F56: 46
B57: Grand Total | C57: 12 | D57: 144 | E57: 48 | F57: 204
B62: Âmbito | C62: Pilar III
B63: Sub-âmbito | C63: (Multiple Items)
B64: Tipo de teste | C64: 2. Campo
B66: Row Labels | C66: Count of Campo
B67: 0. Cancelado | C67: 12
B68: 1. Concluído | C68: 144
B69: 6. Em implementação | C69: 48
B70: Grand Total | C70: 204
B81: 3. Modelo Verde
...

Sheet 2. Status Detalhe Campos FY24
E2: Novos requisitos
I5: APAGAR | J5: APAGAR | K5: APAGAR | Q5: APAGAR | R5: APAGAR | S5: APAGAR | T5: APAGAR | U5: APAGAR
B6: Âmbito | C6: Sub-âmbito | D6: Tipo de teste | E6: Tabela | F6: Campo | G6: Status Atual | H6: Status Anterior | I6: Observações - Especificações | J6: Observações - Testes | K6: Observações - Testes sem visibilidade | L6: Data de Pedido correção/esclarecimento | M6: Data de correção prevista | N6: Data de correção efetiva | O6: Data Prevista de Re-especificação | P6: Data Prevista de Teste | Q6: Projeto (Aux JB) | R6: LT Âmbito | S6: LT Âmbito- Aux | T6: Plano | U6: Owner
A7: =E7&F7 -> ENERGY_CERTIFICATE_EST_INPUTn.a. | B7: Pilar III | C7: Bens Imóveis - Input | D7: 1. Universo | E7: ENERGY_CERTIFICATE_EST_INPUT | F7: n.a. | G7: =VLOOKUP(A7,Plano_V3!$A$26:$G$759,7,0) -> 6. Em implementação | H7: 6. Em implementação | L7: =IF(VLOOKUP(A7,'Aux - pivots1'!$A:$E,3,0)=0, "",VLOOKUP(A7,'Aux - pivots1'!$A:$E,3,0)) | M7: =IF(VLOOKUP(A7,'Aux - pivots1'!$A:$E,4,0)=0, "",VLOOKUP(A7,'Aux - pivots1'!$A:$E,4,0)) | N7: =IF(VLOOKUP(A7,'Aux - pivots1'!$A:$E,5,0)=0, "",VLOOKUP(A7,'Aux - pivots1'!$A:$E,5,0)) | T7: Plano anterior
A8: =E8&F8 -> ENERGY_CERTIFICATE_EST_INPUTCHAVE_GLOVAL | B8: Pilar III | C8: Bens Imóveis - Input | D8: 2. Campo | E8: ENERGY_CERTIFICATE_EST_INPUT | F8: CHAVE_GLOVAL | G8: =VLOOKUP(A8,Plano_V3!$A$26:$G$759,7,0) -> 6. Em implementação | H8: 6. Em implementação | I8: Package 1 | J8: Package X | L8: =IF(VLOOKUP(A8,'Aux - pivots1'!$A:$E,3,0)=0, "",VLOOKUP(A8,'Aux - pivots1'!$A:$E,3,0)) | M8: =IF(VLOOKUP(A8,'Aux - pivots1'!$A:$E,4,0)=0, "",VLOOKUP(A8,'Aux - pivots1'!$A:$E,4,0)) | N8: =IF(VLOOKUP(A8,'Aux - pivots1'!$A:$E,5,0)=0, "",VLOOKUP(A8,'Aux - pivots1'!$A:$E,5,0)) | T8: Plano anterior (alteração nome)
A9: =E9&F9 -> ENERGY_CERTIFICATE_EST_INPUTPROPERTY_BANK_ID | B9: Pilar III | C9: Bens Imóveis - Input | D9: 2. Campo | E9: ENERGY_CERTIFICATE_EST_INPUT | F9: PROPERTY_BANK_ID | G9: =VLOOKUP(A9,Plano_V3!$A$26:$G$759,7,0) -> 6. Em implementação | H9: 6. Em implementação | I9: Package 1 | J9: Package X | L9: =IF(VLOOKUP(A9,'Aux - pivots1'!$A:$E,3,0)=0, "",VLOOKUP(A9,'Aux - pivots1'!$A:$E,3,0)) | M9: =IF(VLOOKUP(A9,'Aux - pivots1'!$A:$E,4,0)=0, "",VLOOKUP(A9,'Aux - pivots1'!$A:$E,4,0)) | N9: =IF(VLOOKUP(A9,'Aux - pivots1'!$A:$E,5,0)=0, "",VLOOKUP(A9,'Aux - pivots1'!$A:$E,5,0)) | T9: Plano anterior
A10: =E10&F10 -> ENERGY_CERTIFICATE_EST_INPUTPROPERTY_BRANCH_CODE | B10: Pilar III | C10: Bens Imóveis - Input | D10: 2. Campo | E10: ENERGY_CERTIFICATE_EST_INPUT | F10: PROPERTY_BRANCH_CODE | G10: =VLOOKUP(A10,Plano_V3!$A$26:$G$759,7,0) -> 6. Em implementação | H10: 6. Em implementação | I10: Package 1 | J10: Package X | L10: =IF(VLOOKUP(A10,'Aux - pivots1'!$A:$E,3,0)=0, "",VLOOKUP(A10,'Aux - pivots1'!$A:$E,3,0)) | M10: =IF(VLOOKUP(A10,'Aux - pivots1'!$A:$E,4,0)=0, "",VLOOKUP(A10,'Aux - pivots1'!$A:$E,4,0)) | N10: =IF(VLOOKUP(A10,'Aux - pivots1'!$A:$E,5,0)=0, "",VLOOKUP(A10,'Aux - pivots1'!$A:$E,5,0)) | T10: Plano anterior
A11: =E11&F11 -> ENERGY_CERTIFICATE_EST_INPUTPROPERTY_CONTRACT_ID | B11: Pilar III | C11: Bens Imóveis - Input | D11: 2. Campo | E11: ENERGY_CERTIFICATE_EST_INPUT | F11: PROPERTY_CONTRACT_ID | G11: =VLOOKUP(A11,Plano_V3!$A$26:$G$759,7,0) -> 6. Em implementação | H11: 6. Em implementação | I11: Package 1 | J11: Package X | L11: =IF(VLOOKUP(A11,'Aux - pivots1'!$A:$E,3,0)=0, "",VLOOKUP(A11,'Aux - pivots1'!$A:$E,3,0)) | M11: =IF(VLOOKUP(A11,'Aux - pivots1'!$A:$E,4,0)=0, "",VLOOKUP(A11,'Aux - pivots1'!$A:$E,4,0)) | N11: =IF(VLOOKUP(A11,'Aux - pivots1'!$A:$E,5,0)=0, "",VLOOKUP(A11,'Aux - pivots1'!$A:$E,5,0)) | T11: Plano anterior
A12: =E12&F12 -> ENERGY_CERTIFICATE_EST_INPUTPROPERTY_REFERENCE_CODE | B12: Pilar III | C12: Bens Imóveis - Input | D12: 2. Campo | E12: ENERGY_CERTIFICATE_EST_INPUT | F12: PROPERTY_REFERENCE_CODE | G12: =VLOOKUP(A12,Plano_V3!$A$26:$G$759,7,0) -> 6. Em implementação | H12: 6. Em implementação | I12: Package 1 | J12: Package X | L12: =IF(VLOOKUP(A12,'Aux - pivots1'!$A:$E,3,0)=0, "",VLOOKUP(A12,'Aux - pivots1'!$A:$E,3,0)) | M12: =IF(VLOOKUP(A12,'Aux - pivots1'!$A:$E,4,0)=0, "",VLOOKUP(A12,'Aux - pivots1'!$A:$E,4,0)) | N12: =IF(VLOOKUP(A12,'Aux - pivots1'!$A:$E,5,0)=0, "",VLOOKUP(A12,'Aux - pivots1'!$A:$E,5,0)) | T12: Plano anterior
A13: =E13&F13 -> ENERGY_CERTIFICATE_EST_INPUTCÓDIGO_DISTRITO | B13: Pilar III | C13: Bens Imóveis - Input | D13: 2. Campo | E13: ENERGY_CERTIFICATE_EST_INPUT | F13: CÓDIGO_DISTRITO | G13: =VLOOKUP(A13,Plano_V3!$A$26:$G$759,7,0) -> 6. Em implementação | H13: 6. Em implementação | I13: Package 1 | J13: Package X | L13: =IF(VLOOKUP(A13,'Aux - pivots1'!$A:$E,3,0)=0, "",VLOOKUP(A13,'Aux - pivots1'!$A:$E,3,0)) | M13: =IF(VLOOKUP(A13,'Aux - pivots1'!$A:$E,4,0)=0, "",VLOOKUP(A13,'Aux - pivots1'!$A:$E,4,0)) | N13: =IF(VLOOKUP(A13,'Aux - pivots1'!$A:$E,5,0)=0, "",VLOOKUP(A13,'Aux - pivots1'!$A:$E,5,0)) | T13: Plano anterior (sem visibilidade no PdS enviado 17/01)
A14: =E14&F14 -> ENERGY_CERTIFICATE_EST_INPUTNOMBRE_DISTRITO | B14: Pilar III | C14: Bens Imóveis - Input | D14: 2. Campo | E14: ENERGY_CERTIFICATE_EST_INPUT | F14: NOMBRE_DISTRITO | G14: =VLOOKUP(A14,Plano_V3!$A$26:$G$759,7,0) -> 6. Em implementação | H14: 6. Em implementação | I14: Package 1 | J14: Package X | L14: =IF(VLOOKUP(A14,'Aux - pivots1'!$A:$E,3,0)=0, "",VLOOKUP(A14,'Aux - pivots1'!$A:$E,3,0)) | M14: =IF(VLOOKUP(A14,'Aux - pivots1'!$A:$E,4,0)=0, "",VLOOKUP(A14,'Aux - pivots1'!$A:$E,4,0)) | N14: =IF(VLOOKUP(A14,'Aux - pivots1'!$A:$E,5,0)=0, "",VLOOKUP(A14,'Aux - pivots1'!$A:$E,5,0)) | T14: Plano anterior (sem visibilidade no PdS enviado 17/01)
A15: =E15&F15 -> ENERGY_CERTIFICATE_EST_INPUTCÓDIGO_CONCEJO | B15: Pilar III | C15: Bens Imóveis - Input | D15: 2. Campo | E15: ENERGY_CERTIFICATE_EST_INPUT | F15: CÓDIGO_CONCEJO | G15: =VLOOKUP(A15,Plano_V3!$A$26:$G$759,7,0) -> 6. Em implementação | H15: 6. Em implementação | I15: Package 1 | J15: Package X | L15: =IF(VLOOKUP(A15,'Aux - pivots1'!$A:$E,3,0)=0, "",VLOOKUP(A15,'Aux - pivots1'!$A:$E,3,0)) | M15: =IF(VLOOKUP(A15,'Aux - pivots1'!$A:$E,4,0)=0, "",VLOOKUP(A15,'Aux - pivots1'!$A:$E,4,0)) | N15: =IF(VLOOKUP(A15,'Aux - pivots1'!$A:$E,5,0)=0, "",VLOOKUP(A15,'Aux - pivots1'!$A:$E,5,0)) | T15: Plano anterior (sem visibilidade no PdS enviado 17/01)
A16: =E16&F16 -> ENERGY_CERTIFICATE_EST_INPUTNOMBRE_CONCEJO | B16: Pilar III | C16: Bens Imóveis - Input | D16: 2. Campo | E16: ENERGY_CERTIFICATE_EST_INPUT | F16: NOMBRE_CONCEJO | G16: =VLOOKUP(A16,Plano_V3!$A$26:$G$759,7,0) -> 6. Em implementação | H16: 6. Em implementação | I16: Package 1 | J16: Package X | L16: =IF(VLOOKUP(A16,'Aux - pivots1'!$A:$E,3,0)=0, "",VLOOKUP(A16,'Aux - pivots1'!$A:$E,3,0)) | M16: =IF(VLOOKUP(A16,'Aux - pivots1'!$A:$E,4,0)=0, "",VLOOKUP(A16,'Aux - pivots1'!$A:$E,4,0)) | N16: =IF(VLOOKUP(A16,'Aux - pivots1'!$A:$E,5,0)=0, "",VLOOKUP(A16,'Aux - pivots1'!$A:$E,5,0)) | T16: Plano anterior (sem visibilidade no PdS enviado 17/01)
A17: =E17&F17 -> ENERGY_CERTIFICATE_EST_INPUTCÓDIGO_FREGUESIA | B17: Pilar III | C17: Bens Imóveis - Input | D17: 2. Campo | E17: ENERGY_CERTIFICATE_EST_INPUT | F17: CÓDIGO_FREGUESIA | G17: =VLOOKUP(A17,Plano_V3!$A$26:$G$759,7,0) -> 6. Em implementação | H17: 6. Em implementação | I17: Package 1 | J17: Package X | L17: =IF(VLOOKUP(A17,'Aux - pivots1'!$A:$E,3,0)=0, "",VLOOKUP(A17,'Aux - pivots1'!$A:$E,3,0)) | M17: =IF(VLOOKUP(A17,'Aux - pivots1'!$A:$E,4,0)=0, "",VLOOKUP(A17,'Aux - pivots1'!$A:$E,4,0)) | N17: =IF(VLOOKUP(A17,'Aux - pivots1'!$A:$E,5,0)=0, "",VLOOKUP(A17,'Aux - pivots1'!$A:$E,5,0)) | T17: Plano anterior (sem visibilidade no PdS enviado 17/01)
A18: =E18&F18 -> ENERGY_CERTIFICATE_EST_INPUTNOMBRE_FREGUESIA | B18: Pilar III | C18: Bens Imóveis - Input | D18: 2. Campo | E18: ENERGY_CERTIFICATE_EST_INPUT | F18: NOMBRE_FREGUESIA | G18: =VLOOKUP(A18,Plano_V3!$A$26:$G$759,7,0) -> 6. Em implementação | H18: 6. Em implementação | I18: Package 1 | J18: Package X | L18: =IF(VLOOKUP(A18,'Aux - pivots1'!$A:$E,3,0)=0, "",VLOOKUP(A18,'Aux - pivots1'!$A:$E,3,0)) | M18: =IF(VLOOKUP(A18,'Aux - pivots1'!$A:$E,4,0)=0, "",VLOOKUP(A18,'Aux - pivots1'!$A:$E,4,0)) | N18: =IF(VLOOKUP(A18,'Aux - pivots1'!$A:$E,5,0)=0, "",VLOOKUP(A18,'Aux - pivots1'!$A:$E,5,0)) | T18: Plano anterior (sem visibilidade no PdS enviado 17/01)
A19: =E19&F19 -> ENERGY_CERTIFICATE_EST_INPUTLOCALIDADE | B19: Pilar III | C19: Bens Imóveis - Input | D19: 2. Campo | E19: ENERGY_CERTIFICATE_EST_INPUT | F19: LOCALIDADE | G19: =VLOOKUP(A19,Plano_V3!$A$26:$G$759,7,0) -> 6. Em implementação | H19: 6. Em implementação | I19: Package 1 | J19: Package X | L19: =IF(VLOOKUP(A19,'Aux - pivots1'!$A:$E,3,0)=0, "",VLOOKUP(A19,'Aux - pivots1'!$A:$E,3,0)) | M19: =IF(VLOOKUP(A19,'Aux - pivots1'!$A:$E,4,0)=0, "",VLOOKUP(A19,'Aux - pivots1'!$A:$E,4,0)) | N19: =IF(VLOOKUP(A19,'Aux - pivots1'!$A:$E,5,0)=0, "",VLOOKUP(A19,'Aux - pivots1'!$A:$E,5,0)) | T19: Plano anterior (sem visibilidade no PdS enviado 17/01)
... A41: =E41&F41 -> ENERGY_CERTIFICATE_EST_INPUTART_MATRICIAIS | B41: Pilar III | C41: Bens Imóveis - Input | D41: 2. Campo | E41: ENERGY_CERTIFICATE_EST_INPUT | F41: ART_MATRICIAIS | G41: =VLOOKUP(A41,Plano_V3!$A$26:$G$759,7,0) -> 6. Em implementação | H41: 6. Em implementação | I41: Package 1 | J41: Package X | L41: =IF(VLOOKUP(A41,'Aux - pivots1'!$A:$E,3,0)=0, "",VLOOKUP(A41,'Aux - pivots1'!$A:$E,3,0)) | M41: =IF(VLOOKUP(A41,'Aux - pivots1'!$A:$E,4,0)=0, "",VLOOKUP(A41,'Aux - pivots1'!$A:$E,4,0)) | N41: =IF(VLOOKUP(A41,'Aux - pivots1'!$A:$E,5,0)=0, "",VLOOKUP(A41,'Aux - pivots1'!$A:$E,5,0)) | T41: Plano anterior (sem visibilidade no PdS enviado 17/01)
A42: =E42&F42 -> ENERGY_CERTIFICATE_EST_INPUTDATA_PROVIDER | B42: Pilar III | C42: Bens Imóveis - Input | D42: 2. Campo | E42: ENERGY_CERTIFICATE_EST_INPUT | F42: DATA_PROVIDER | G42: =VLOOKUP(A42,Plano_V3!$A$26:$G$759,7,0) -> 0. Cancelado | H42: 0. Cancelado | L42: =IF(VLOOKUP(A42,'Aux - pivots1'!$A:$E,3,0)=0, "",VLOOKUP(A42,'Aux - pivots1'!$A:$E,3,0)) | M42: =IF(VLOOKUP(A42,'Aux - pivots1'!$A:$E,4,0)=0, "",VLOOKUP(A42,'Aux - pivots1'!$A:$E,4,0)) | N42: =IF(VLOOKUP(A42,'Aux - pivots1'!$A:$E,5,0)=0, "",VLOOKUP(A42,'Aux - pivots1'!$A:$E,5,0)) | T42: Plano anterior
A43: =E43&F43 -> ENERGY_CERTIFICATE_EST_INPUTACTUAL_VALUE_IND | B43: Pilar III | C43: Bens Imóveis - Input | D43: 2. Campo | E43: ENERGY_CERTIFICATE_EST_INPUT | F43: ACTUAL_VALUE_IND | G43: =VLOOKUP(A43,Plano_V3!$A$26:$G$759,7,0) -> 0. Cancelado | H43: 0. Cancelado | L43: =IF(VLOOKUP(A43,'Aux - pivots1'!$A:$E,3,0)=0, "",VLOOKUP(A43,'Aux - pivots1'!$A:$E,3,0)) | M43: =IF(VLOOKUP(A43,'Aux - pivots1'!$A:$E,4,0)=0, "",VLOOKUP(A43,'Aux - pivots1'!$A:$E,4,0)) | N43: =IF(VLOOKUP(A43,'Aux - pivots1'!$A:$E,5,0)=0, "",VLOOKUP(A43,'Aux - pivots1'!$A:$E,5,0)) | T43: Plano anterior
A44: =E44&F44 -> ENERGY_CERTIFICATE_EST_INPUTFRACCAO_AUTONOMA | B44: Pilar III | C44: Bens Imóveis - Input | D44: 2. Campo | E44: ENERGY_CERTIFICATE_EST_INPUT | F44: FRACCAO_AUTONOMA | G44: =VLOOKUP(A44,Plano_V3!$A$26:$G$759,7,0) -> 6. Em implementação | H44: 6. Em implementação | I44: Package 1 | J44: Package X | L44: =IF(VLOOKUP(A44,'Aux - pivots1'!$A:$E,3,0)=0, "",VLOOKUP(A44,'Aux - pivots1'!$A:$E,3,0)) | M44: =IF(VLOOKUP(A44,'Aux - pivots1'!$A:$E,4,0)=0, "",VLOOKUP(A44,'Aux - pivots1'!$A:$E,4,0)) | N44: =IF(VLOOKUP(A44,'Aux - pivots1'!$A:$E,5,0)=0, "",VLOOKUP(A44,'Aux - pivots1'!$A:$E,5,0)) | T44: Plano anterior (sem visibilidade no PdS enviado 17/01)
A45: =E45&F45 -> ENERGY_CERTIFICATE_EST_INPUTFINALIDADE_BEM | B45: Pilar III | C45: Bens Imóveis - Input | D45: 2. Campo | E45: ENERGY_CERTIFICATE_EST_INPUT | F45: FINALIDADE_BEM | G45: =VLOOKUP(A45,Plano_V3!$A$26:$G$759,7,0) -> 6. Em implementação | H45: 6. Em implementação | I45: Package 1 | J45: Package X | L45: =IF(VLOOKUP(A45,'Aux - pivots1'!$A:$E,3,0)=0, "",VLOOKUP(A45,'Aux - pivots1'!$A:$E,3,0)) | M45: =IF(VLOOKUP(A45,'Aux - pivots1'!$A:$E,4,0)=0, "",VLOOKUP(A45,'Aux - pivots1'!$A:$E,4,0)) | N45: =IF(VLOOKUP(A45,'Aux - pivots1'!$A:$E,5,0)=0, "",VLOOKUP(A45,'Aux - pivots1'!$A:$E,5,0)) | T45: Plano anterior (sem visibilidade no PdS enviado 17/01)
A46: =E46&F46 -> ENERGY_CERTIFICATE_EST_INPUTCLASS_GPT31 | B46: Pilar III | C46: Bens Imóveis - Input | D46: 2. Campo | E46: ENERGY_CERTIFICATE_EST_INPUT | F46: CLASS_GPT31 | G46: =VLOOKUP(A46,Plano_V3!$A$26:$G$759,7,0) -> 6. Em implementação | H46: 6. Em implementação | I46: Package 1 | J46: Package X | L46: =IF(VLOOKUP(A46,'Aux - pivots1'!$A:$E,3,0)=0, "",VLOOKUP(A46,'Aux - pivots1'!$A:$E,3,0)) | M46: =IF(VLOOKUP(A46,'Aux - pivots1'!$A:$E,4,0)=0, "",VLOOKUP(A46,'Aux - pivots1'!$A:$E,4,0)) | N46: =IF(VLOOKUP(A46,'Aux - pivots1'!$A:$E,5,0)=0, "",VLOOKUP(A46,'Aux - pivots1'!$A:$E,5,0)) | T46: Plano anterior (sem visibilidade no PdS enviado 17/01)
A47: =E47&F47 -> ENERGY_CERTIFICATE_EST_INPUTCLASS_STCLIM | B47: Pilar III | C47: Bens Imóveis - Input | D47: 2. Campo | E47: ENERGY_CERTIFICATE_EST_INPUT | F47: CLASS_STCLIM | G47: =VLOOKUP(A47,Plano_V3!$A$26:$G$759,7,0) -> 6. Em implementação | H47: 6. Em implementação | I47: Package 1 | J47: Package X | L47: =IF(VLOOKUP(A47,'Aux - pivots1'!$A:$E,3,0)=0, "",VLOOKUP(A47,'Aux - pivots1'!$A:$E,3,0)) | M47: =IF(VLOOKUP(A47,'Aux - pivots1'!$A:$E,4,0)=0, "",VLOOKUP(A47,'Aux - pivots1'!$A:$E,4,0)) | N47: =IF(VLOOKUP(A47,'Aux - pivots1'!$A:$E,5,0)=0, "",VLOOKUP(A47,'Aux - pivots1'!$A:$E,5,0)) | T47: Plano anterior (sem visibilidade no PdS enviado 17/01)
A48: =E48&F48 -> ENERGY_CERTIFICATE_EST_INPUTCONF_STCLIM | B48: Pilar III | C48: Bens Imóveis - Input | D48: 2. Campo | E48: ENERGY_CERTIFICATE_EST_INPUT | F48: CONF_STCLIM | G48: =VLOOKUP(A48,Plano_V3!$A$26:$G$759,7,0) -> 6. Em implementação | H48: 6. Em implementação | I48: Package 1 | J48: Package X | L48: =IF(VLOOKUP(A48,'Aux - pivots1'!$A:$E,3,0)=0, "",VLOOKUP(A48,'Aux - pivots1'!$A:$E,3,0)) | M48: =IF(VLOOKUP(A48,'Aux - pivots1'!$A:$E,4,0)=0, "",VLOOKUP(A48,'Aux - pivots1'!$A:$E,4,0)) | N48: =IF(VLOOKUP(A48,'Aux - pivots1'!$A:$E,5,0)=0, "",VLOOKUP(A48,'Aux - pivots1'!$A:$E,5,0)) | T48: Plano anterior (sem visibilidade no PdS enviado 17/01)
A49: =E49&F49 -> ENERGY_CERTIFICATE_EST_INPUTCLASSE_ENERGETICA | B49: Pilar III | C49: Bens Imóveis - Input | D49: 2. Campo | E49: ENERGY_CERTIFICATE_EST_INPUT | F49: CLASSE_ENERGETICA | G49: =VLOOKUP(A49,Plano_V3!$A$26:$G$759,7,0) -> 6. Em implementação | H49: 6. Em implementação | I49: Package 1 | J49: Package X | L49: =IF(VLOOKUP(A49,'Aux - pivots1'!$A:$E,3,0)=0, "",VLOOKUP(A49,'Aux - pivots1'!$A:$E,3,0)) | M49: =IF(VLOOKUP(A49,'Aux - pivots1'!$A:$E,4,0)=0, "",VLOOKUP(A49,'Aux - pivots1'!$A:$E,4,0)) | N49: =IF(VLOOKUP(A49,'Aux - pivots1'!$A:$E,5,0)=0, "",VLOOKUP(A49,'Aux - pivots1'!$A:$E,5,0)) | T49: Plano anterior (alteração nome)
A50: =E50&F50 -> ENERGY_CERTIFICATE_EST_INPUTFIABILIDAD | B50: Pilar III | C50: Bens Imóveis - Input | D50: 2. Campo | E50: ENERGY_CERTIFICATE_EST_INPUT | F50: FIABILIDAD | G50: =VLOOKUP(A50,Plano_V3!$A$26:$G$759,7,0) -> 6. Em implementação | H50: 6. Em implementação | I50: Package 1 | J50: Package X | L50: =IF(VLOOKUP(A50,'Aux - pivots1'!$A:$E,3,0)=0, "",VLOOKUP(A50,'Aux - pivots1'!$A:$E,3,0)) | M50: =IF(VLOOKUP(A50,'Aux - pivots1'!$A:$E,4,0)=0, "",VLOOKUP(A50,'Aux - pivots1'!$A:$E,4,0)) | N50: =IF(VLOOKUP(A50,'Aux - pivots1'!$A:$E,5,0)=0, "",VLOOKUP(A50,'Aux - pivots1'!$A:$E,5,0)) | T50: Plano anterior (alteração nome)
A51: =E51&F51 -> ENERGY_CERTIFICATE_EST_INPUTEMISSIONES | B51: Pilar III | C51: Bens Imóveis - Input | D51: 2. Campo | E51: ENERGY_CERTIFICATE_EST_INPUT | F51: EMISSIONES | G51: =VLOOKUP(A51,Plano_V3!$A$26:$G$759,7,0) -> 6. Em implementação | H51: 6. Em implementação | I51: Package 1 | J51: Package X | L51: =IF(VLOOKUP(A51,'Aux - pivots1'!$A:$E,3,0)=0, "",VLOOKUP(A51,'Aux - pivots1'!$A:$E,3,0)) | M51: =IF(VLOOKUP(A51,'Aux - pivots1'!$A:$E,4,0)=0, "",VLOOKUP(A51,'Aux - pivots1'!$A:$E,4,0)) | N51: =IF(VLOOKUP(A51,'Aux - pivots1'!$A:$E,5,0)=0, "",VLOOKUP(A51,'Aux - pivots1'!$A:$E,5,0)) | T51: Plano anterior (alteração nome)
A52: =E52&F52 -> ENERGY_CERTIFICATE_EST_INPUTCONSUMOS | B52: Pilar III | C52: Bens Imóveis - Input | D52: 2. Campo | E52: ENERGY_CERTIFICATE_EST_INPUT | F52: CONSUMOS | G52: =VLOOKUP(A52,Plano_V3!$A$26:$G$759,7,0) -> 6. Em implementação | H52: 6. Em implementação | I52: Package 1 | J52: Package X | L52: =IF(VLOOKUP(A52,'Aux - pivots1'!$A:$E,3,0)=0, "",VLOOKUP(A52,'Aux - pivots1'!$A:$E,3,0)) | M52: =IF(VLOOKUP(A52,'Aux - pivots1'!$A:$E,4,0)=0, "",VLOOKUP(A52,'Aux - pivots1'!$A:$E,4,0)) | N52: =IF(VLOOKUP(A52,'Aux - pivots1'!$A:$E,5,0)=0, "",VLOOKUP(A52,'Aux - pivots1'!$A:$E,5,0)) | T52: Plano anterior (alteração nome)
A53: =E53&F53 -> ENERGY_CERTIFICATE_EST_INPUTDATA_ENVIO | B53: Pilar III | C53: Bens Imóveis - Input | D53: 2. Campo | E53: ENERGY_CERTIFICATE_EST_INPUT | F53: DATA_ENVIO | G53: =VLOOKUP(A53,Plano_V3!$A$26:$G$759,7,0) -> 6. Em implementação | H53: 6. Em implementação | I53: Package 1 | J53: Package X | L53: =IF(VLOOKUP(A53,'Aux - pivots1'!$A:$E,3,0)=0, "",VLOOKUP(A53,'Aux - pivots1'!$A:$E,3,0)) | M53: =IF(VLOOKUP(A53,'Aux - pivots1'!$A:$E,4,0)=0, "",VLOOKUP(A53,'Aux - pivots1'!$A:$E,4,0)) | N53: =IF(VLOOKUP(A53,'Aux - pivots1'!$A:$E,5,0)=0, "",VLOOKUP(A53,'Aux - pivots1'!$A:$E,5,0)) | T53: Plano anterior (alteração nome)
A54: =E54&F54 -> PROCESSn.a. | B54: Pilar III | C54: Bens Imóveis - Output | D54: 1. Universo | E54: PROCESS | F54: n.a. | G54: =VLOOKUP(A54,Plano_V3!$A$26:$G$759,7,0) -> 1. Concluído | H54: 1. Concluído | L54: =IF(VLOOKUP(A54,'Aux - pivots1'!$A:$E,3,0)=0, "",VLOOKUP(A54,'Aux - pivots1'!$A:$E,3,0)) | M54: =IF(VLOOKUP(A54,'Aux - pivots1'!$A:$E,4,0)=0, "",VLOOKUP(A54,'Aux - pivots1'!$A:$E,4,0)) | N54: =IF(VLOOKUP(A54,'Aux - pivots1'!$A:$E,5,0)=0, "",VLOOKUP(A54,'Aux - pivots1'!$A:$E,5,0)) | T54: Plano anterior
A55: =E55&F55 -> PROCESSPROCESS_BANK_ID | B55: Pilar III | C55: Bens Imóveis - Output | D55: 2. Campo | E55: PROCESS | F55: PROCESS_BANK_ID | G55: =VLOOKUP(A55,Plano_V3!$A$26:$G$759,7,0) -> 1. Concluído | H55: 1. Concluído | L55: =IF(VLOOKUP(A55,'Aux - pivots1'!$A:$E,3,0)=0, "",VLOOKUP(A55,'Aux - pivots1'!$A:$E,3,0)) | M55: =IF(VLOOKUP(A55,'Aux - pivots1'!$A:$E,4,0)=0, "",VLOOKUP(A55,'Aux - pivots1'!$A:$E,4,0)) | N55: =IF(VLOOKUP(A55,'Aux - pivots1'!$A:$E,5,0)=0, "",VLOOKUP(A55,'Aux - pivots1'!$A:$E,5,0)) | T55: Plano anterior
A56: =E56&F56 -> PROCESSPROCESS_BRANCH_CODE | B56: Pilar III | C56: Bens Imóveis - Output | D56: 2. Campo | E56: PROCESS | F56: PROCESS_BRANCH_CODE | G56: =VLOOKUP(A56,Plano_V3!$A$26:$G$759,7,0) -> 1. Concluído | H56: 1. Concluído | L56: =IF(VLOOKUP(A56,'Aux - pivots1'!$A:$E,3,0)=0, "",VLOOKUP(A56,'Aux - pivots1'!$A:$E,3,0)) | M56: =IF(VLOOKUP(A56,'Aux - pivots1'!$A:$E,4,0)=0, "",VLOOKUP(A56,'Aux - pivots1'!$A:$E,4,0)) | N56: =IF(VLOOKUP(A56,'Aux - pivots1'!$A:$E,5,0)=0, "",VLOOKUP(A56,'Aux - pivots1'!$A:$E,5,0)) | T56: Plano anterior
A57: =E57&F57 -> PROCESSPROCESS_ACCOUNT_ID | B57: Pilar III | C57: Bens Imóveis - Output | D57: 2. Campo | E57: PROCESS | F57: PROCESS_ACCOUNT_ID | G57: =VLOOKUP(A57,Plano_V3!$A$26:$G$759,7,0) -> 1. Concluído | H57: 1. Concluído | L57: =IF(VLOOKUP(A57,'Aux - pivots1'!$A:$E,3,0)=0, "",VLOOKUP(A57,'Aux - pivots1'!$A:$E,3,0)) | M57: =IF(VLOOKUP(A57,'Aux - pivots1'!$A:$E,4,0)=0, "",VLOOKUP(A57,'Aux - pivots1'!$A:$E,4,0)) | N57: =IF(VLOOKUP(A57,'Aux - pivots1'!$A:$E,5,0)=0, "",VLOOKUP(A57,'Aux - pivots1'!$A:$E,5,0)) | T57: Plano anterior
A58: =E58&F58 -> PROCESScod_estd_prcs | B58: Pilar III | C58: Bens Imóveis - Output | D58: 2. Campo | E58: PROCESS | F58: cod_estd_prcs | G58: =VLOOKUP(A58,Plano_V3!$A$26:$G$759,7,0) -> 0. Cancelado | H58: 0. Cancelado | L58: =IF(VLOOKUP(A58,'Aux - pivots1'!$A:$E,3,0)=0, "",VLOOKUP(A58,'Aux - pivots1'!$A:$E,3,0)) | M58: =IF(VLOOKUP(A58,'Aux - pivots1'!$A:$E,4,0)=0, "",VLOOKUP(A58,'Aux - pivots1'!$A:$E,4,0)) | N58: =IF(VLOOKUP(A58,'Aux - pivots1'!$A:$E,5,0)=0, "",VLOOKUP(A58,'Aux - pivots1'!$A:$E,5,0)) | T58: Plano anterior
A59: =E59&F59 -> PROCESSGUARANTEE_CODE | B59: Pilar III | C59: Bens Imóveis - Output | D59: 2. Campo | E59: PROCESS | F59: GUARANTEE_CODE | G59: =VLOOKUP(A59,Plano_V3!$A$26:$G$759,7,0) -> 1. Concluído | H59: 1. Concluído | L59: =IF(VLOOKUP(A59,'Aux - pivots1'!$A:$E,3,0)=0, "",VLOOKUP(A59,'Aux - pivots1'!$A:$E,3,0)) | M59: =IF(VLOOKUP(A59,'Aux - pivots1'!$A:$E,4,0)=0, "",VLOOKUP(A59,'Aux - pivots1'!$A:$E,4,0)) | N59: =IF(VLOOKUP(A59,'Aux - pivots1'!$A:$E,5,0)=0, "",VLOOKUP(A59,'Aux - pivots1'!$A:$E,5,0)) | T59: Plano anterior
