Workbook

Sheet 1. Tipologias Testes GD
B8: Âmbito | C8: Origem | D8: Campo | E8: Status | F8: Tipologia_Testes | G8: Necessidade de re-especificação? (campo) | H8: Complexidade | I8: Estimação (horas) | J8: Notas
B9: GD | C9: - | D9: n.a. | F9: 1. Teste de universo | G9: Sim | H9: Alta | I9: =INDEX(Auxiliar!$D$5:$F$11,MATCH(Table1[[#This Row],[Tipologia_Testes]],Auxiliar!$B$5:$B$11,0),MATCH(Table1[[#This Row],[Complexidade]],Auxiliar!$D$4:$F$4,0)) -> 8
B10: GD | C10: Modelo Verde | D10: SSTNBL_CTGRY | E10: Concluído | F10: 2. Simulação | G10: Sim | H10: Alta | I10: =INDEX(Auxiliar!$D$5:$F$11,MATCH(Table1[[#This Row],[Tipologia_Testes]],Auxiliar!$B$5:$B$11,0),MATCH(Table1[[#This Row],[Complexidade]],Auxiliar!$D$4:$F$4,0)) -> 8
B11: GD | C11: Modelo Verde | D11: SSTNBL_CTGRY | E11: Concluído | F11: 3. Testes comparativos (Espec. VS Impl.) | G11: Sim | H11: Alta | I11: =INDEX(Auxiliar!$D$5:$F$11,MATCH(Table1[[#This Row],[Tipologia_Testes]],Auxiliar!$B$5:$B$11,0),MATCH(Table1[[#This Row],[Complexidade]],Auxiliar!$D$4:$F$4,0)) -> 8
B12: GD | C12: Modelo Verde | D12: SSTNBL_CTGRY | E12: Concluído | F12: 4. Validação de parametrizações | G12: Sim | H12: Alta | I12: =INDEX(Auxiliar!$D$5:$F$11,MATCH(Table1[[#This Row],[Tipologia_Testes]],Auxiliar!$B$5:$B$11,0),MATCH(Table1[[#This Row],[Complexidade]],Auxiliar!$D$4:$F$4,0)) -> 8 | J12: Parametrização a ser implementada: lt803
B13: GD | C13: Modelo Verde | D13: SSTNBL_CTGRY | E13: Concluído | F13: 6. Validação de formatos | G13: Sim | H13: Alta | I13: =INDEX(Auxiliar!$D$5:$F$11,MATCH(Table1[[#This Row],[Tipologia_Testes]],Auxiliar!$B$5:$B$11,0),MATCH(Table1[[#This Row],[Complexidade]],Auxiliar!$D$4:$F$4,0)) -> 0.1
B14: GD | C14: Modelo Verde | D14: SSTNBL_CTGRY | E14: Concluído | F14: 7. Validação de controlos corporativos | G14: Sim | H14: Alta | I14: =INDEX(Auxiliar!$D$5:$F$11,MATCH(Table1[[#This Row],[Tipologia_Testes]],Auxiliar!$B$5:$B$11,0),MATCH(Table1[[#This Row],[Complexidade]],Auxiliar!$D$4:$F$4,0)) -> 2
B15: GD | C15: LT ESTR | D15: DFLT_STTS_INSTRMNT | E15: Concluído | F15: 5. Teste comparativos com LT | G15: Não | H15: Baixa | I15: =INDEX(Auxiliar!$D$5:$F$11,MATCH(Table1[[#This Row],[Tipologia_Testes]],Auxiliar!$B$5:$B$11,0),MATCH(Table1[[#This Row],[Complexidade]],Auxiliar!$D$4:$F$4,0)) -> 1
B16: GD | C16: LT ESTR | D16: ACCMLTD_CHNGS_FV_CR_INSTRMNT | E16: Concluído | F16: 5. Teste comparativos com LT | G16: Não | H16: Baixa | I16: =INDEX(Auxiliar!$D$5:$F$11,MATCH(Table1[[#This Row],[Tipologia_Testes]],Auxiliar!$B$5:$B$11,0),MATCH(Table1[[#This Row],[Complexidade]],Auxiliar!$D$4:$F$4,0)) -> 1
B17: GD | C17: LT ESTR | D17: ACCMLTD_IMPRMNT_INSTRMNT | E17: Concluído | F17: 5. Teste comparativos com LT | G17: Não | H17: Baixa | I17: =INDEX(Auxiliar!$D$5:$F$11,MATCH(Table1[[#This Row],[Tipologia_Testes]],Auxiliar!$B$5:$B$11,0),MATCH(Table1[[#This Row],[Complexidade]],Auxiliar!$D$4:$F$4,0)) -> 1
B18: GD | C18: LT ESTR | D18: ACCNTNG_CLSSFCTN | E18: Concluído | F18: 5. Teste comparativos com LT | G18: Não | H18: Baixa | I18: =INDEX(Auxiliar!$D$5:$F$11,MATCH(Table1[[#This Row],[Tipologia_Testes]],Auxiliar!$B$5:$B$11,0),MATCH(Table1[[#This Row],[Complexidade]],Auxiliar!$D$4:$F$4,0)) -> 1
B19: GD | C19: LT ESTR | D19: COD_SOC | E19: Concluído | F19: 5. Teste comparativos com LT | G19: Não | H19: Baixa | I19: =INDEX(Auxiliar!$D$5:$F$11,MATCH(Table1[[#This Row],[Tipologia_Testes]],Auxiliar!$B$5:$B$11,0),MATCH(Table1[[#This Row],[Complexidade]],Auxiliar!$D$4:$F$4,0)) -> 1
B20: GD | C20: LT ESTR | D20: DT_RFRNC | E20: Concluído | F20: 5. Teste comparativos com LT | G20: Não | H20: Baixa | I20: =INDEX(Auxiliar!$D$5:$F$11,MATCH(Table1[[#This Row],[Tipologia_Testes]],Auxiliar!$B$5:$B$11,0),MATCH(Table1[[#This Row],[Complexidade]],Auxiliar!$D$4:$F$4,0)) -> 1
B21: GD | C21: LT ESTR | D21: GRSS_CRRYNG_AMNT_INSTRMNT | E21: Concluído | F21: 5. Teste comparativos com LT | G21: Não | H21: Baixa | I21: =INDEX(Auxiliar!$D$5:$F$11,MATCH(Table1[[#This Row],[Tipologia_Testes]],Auxiliar!$B$5:$B$11,0),MATCH(Table1[[#This Row],[Complexidade]],Auxiliar!$D$4:$F$4,0)) -> 1
B22: GD | C22: LT ESTR | D22: IDCMB | E22: Concluído | F22: 5. Teste comparativos com LT | G22: Não | H22: Baixa | I22: =INDEX(Auxiliar!$D$5:$F$11,MATCH(Table1[[#This Row],[Tipologia_Testes]],Auxiliar!$B$5:$B$11,0),MATCH(Table1[[#This Row],[Complexidade]],Auxiliar!$D$4:$F$4,0)) -> 1
B23: GD | C23: LT ESTR | D23: IMPRMNT_STTS | E23: Concluído | F23: 5. Teste comparativos com LT | G23: Não | H23: Baixa | I23: =INDEX(Auxiliar!$D$5:$F$11,MATCH(Table1[[#This Row],[Tipologia_Testes]],Auxiliar!$B$5:$B$11,0),MATCH(Table1[[#This Row],[Complexidade]],Auxiliar!$D$4:$F$4,0)) -> 1
B24: GD | C24: Outro | D24: INSTRMNT_ID | E24: Em Teste | F24: 2. Simulação | G24: Sim | H24: Alta | I24: 4 | J24: Pendente de Business_area; Campo já simulado
B25: GD | C25: Outro | D25: INSTRMNT_ID | E25: Em Teste | F25: 3. Testes comparativos (Espec. VS Impl.) | G25: Sim | H25: Alta | I25: =INDEX(Auxiliar!$D$5:$F$11,MATCH(Table1[[#This Row],[Tipologia_Testes]],Auxiliar!$B$5:$B$11,0),MATCH(Table1[[#This Row],[Complexidade]],Auxiliar!$D$4:$F$4,0)) -> 8 | J25: Pendente de Business_area
B26: GD | C26: Outro | D26: INSTRMNT_ID | E26: Em Teste | F26: 6. Validação de formatos | G26: Sim | H26: Alta | I26: =INDEX(Auxiliar!$D$5:$F$11,MATCH(Table1[[#This Row],[Tipologia_Testes]],Auxiliar!$B$5:$B$11,0),MATCH(Table1[[#This Row],[Complexidade]],Auxiliar!$D$4:$F$4,0)) -> 0.1 | J26: Pendente de Business_area
B27: GD | C27: LT ESTR | D27: LCL_INSTMRNT_ID | E27: Concluído | F27: 5. Teste comparativos com LT | G27: Não | H27: Baixa | I27: =INDEX(Auxiliar!$D$5:$F$11,MATCH(Table1[[#This Row],[Tipologia_Testes]],Auxiliar!$B$5:$B$11,0),MATCH(Table1[[#This Row],[Complexidade]],Auxiliar!$D$4:$F$4,0)) -> 1
B28: GD | C28: LT ESTR | D28: OFF_BLNC_SHT_AMNT_INSTRMNT | E28: Concluído | F28: 5. Teste comparativos com LT | G28: Não | H28: Baixa | I28: =INDEX(Auxiliar!$D$5:$F$11,MATCH(Table1[[#This Row],[Tipologia_Testes]],Auxiliar!$B$5:$B$11,0),MATCH(Table1[[#This Row],[Complexidade]],Auxiliar!$D$4:$F$4,0)) -> 1
B29: GD | C29: LT ESTR | D29: PRFRMNG_STTS | E29: Concluído | F29: 5. Teste comparativos com LT | G29: Não | H29: Baixa | I29: =INDEX(Auxiliar!$D$5:$F$11,MATCH(Table1[[#This Row],[Tipologia_Testes]],Auxiliar!$B$5:$B$11,0),MATCH(Table1[[#This Row],[Complexidade]],Auxiliar!$D$4:$F$4,0)) -> 1
B30: GD | C30: LT ESTR | D30: PRVSNS_OFF_BLNC_SHT | E30: Concluído | F30: 5. Teste comparativos com LT | G30: Não | H30: Baixa | I30: =INDEX(Auxiliar!$D$5:$F$11,MATCH(Table1[[#This Row],[Tipologia_Testes]],Auxiliar!$B$5:$B$11,0),MATCH(Table1[[#This Row],[Complexidade]],Auxiliar!$D$4:$F$4,0)) -> 1
B31: GD | C31: LT ESTR | D31: SUBPORTFOLIO_ID | E31: Concluído | F31: 5. Teste comparativos com LT | G31: Não | H31: Baixa | I31: =INDEX(Auxiliar!$D$5:$F$11,MATCH(Table1[[#This Row],[Tipologia_Testes]],Auxiliar!$B$5:$B$11,0),MATCH(Table1[[#This Row],[Complexidade]],Auxiliar!$D$4:$F$4,0)) -> 1
B32: GD | C32: LT ESTR | D32: TYP_INSTRMNT | E32: Concluído | F32: 5. Teste comparativos com LT | G32: Não | H32: Baixa | I32: =INDEX(Auxiliar!$D$5:$F$11,MATCH(Table1[[#This Row],[Tipologia_Testes]],Auxiliar!$B$5:$B$11,0),MATCH(Table1[[#This Row],[Complexidade]],Auxiliar!$D$4:$F$4,0)) -> 1
B33: GD | C33: LT ESTR | D33: RWA | E33: Concluído | F33: 5. Teste comparativos com LT | G33: Não | H33: Baixa | I33: =INDEX(Auxiliar!$D$5:$F$11,MATCH(Table1[[#This Row],[Tipologia_Testes]],Auxiliar!$B$5:$B$11,0),MATCH(Table1[[#This Row],[Complexidade]],Auxiliar!$D$4:$F$4,0)) -> 1
B34: GD | C34: LT ESTR | D34: COD_SOC_INTRGRP | E34: Concluído | F34: 5. Teste comparativos com LT | G34: Não | H34: Baixa | I34: =INDEX(Auxiliar!$D$5:$F$11,MATCH(Table1[[#This Row],[Tipologia_Testes]],Auxiliar!$B$5:$B$11,0),MATCH(Table1[[#This Row],[Complexidade]],Auxiliar!$D$4:$F$4,0)) -> 1
B35: GD | C35: Corporativo | D35: BSNSS_AREA_DSTNTN | E35: Concluído | F35: 2. Simulação | G35: Não | H35: Baixa | I35: =INDEX(Auxiliar!$D$5:$F$11,MATCH(Table1[[#This Row],[Tipologia_Testes]],Auxiliar!$B$5:$B$11,0),MATCH(Table1[[#This Row],[Complexidade]],Auxiliar!$D$4:$F$4,0)) -> 2
B36: GD | C36: Corporativo | D36: BSNSS_AREA_DSTNTN | E36: Concluído | F36: 3. Testes comparativos (Espec. VS Impl.) | G36: Não | H36: Baixa | I36: =INDEX(Auxiliar!$D$5:$F$11,MATCH(Table1[[#This Row],[Tipologia_Testes]],Auxiliar!$B$5:$B$11,0),MATCH(Table1[[#This Row],[Complexidade]],Auxiliar!$D$4:$F$4,0)) -> 2
B37: GD | C37: Corporativo | D37: BSNSS_AREA_DSTNTN | E37: Concluído | F37: 6. Validação de formatos | G37: Não | H37: Baixa | I37: =INDEX(Auxiliar!$D$5:$F$11,MATCH(Table1[[#This Row],[Tipologia_Testes]],Auxiliar!$B$5:$B$11,0),MATCH(Table1[[#This Row],[Complexidade]],Auxiliar!$D$4:$F$4,0)) -> 0.1
B38: GD | C38: Corporativo | D38: BSNSS_AREA_DSTNTN | E38: Concluído | F38: 7. Validação de controlos corporativos | G38: Não | H38: Baixa | I38: =INDEX(Auxiliar!$D$5:$F$11,MATCH(Table1[[#This Row],[Tipologia_Testes]],Auxiliar!$B$5:$B$11,0),MATCH(Table1[[#This Row],[Complexidade]],Auxiliar!$D$4:$F$4,0)) -> 1
... B50: GD | C50: Corporativo | D50: COD_SOC_DSTNTN | E50: Concluído | F50: 7. Validação de controlos corporativos | G50: Não | H50: Baixa | I50: =INDEX(Auxiliar!$D$5:$F$11,MATCH(Table1[[#This Row],[Tipologia_Testes]],Auxiliar!$B$5:$B$11,0),MATCH(Table1[[#This Row],[Complexidade]],Auxiliar!$D$4:$F$4,0)) -> 1
B51: GD | C51: Corporativo | D51: RWA_OFF_BLNC | E51: Concluído | F51: 2. Simulação | G51: Não | H51: Baixa | I51: =INDEX(Auxiliar!$D$5:$F$11,MATCH(Table1[[#This Row],[Tipologia_Testes]],Auxiliar!$B$5:$B$11,0),MATCH(Table1[[#This Row],[Complexidade]],Auxiliar!$D$4:$F$4,0)) -> 2 | J51: 27/03/2024 (Corp): Deve ser aprovisionado localmente com o valor correspondente de não aplicável (11111111111)
B52: GD | C52: Corporativo | D52: RWA_OFF_BLNC | E52: Concluído | F52: 3. Testes comparativos (Espec. VS Impl.) | G52: Não | H52: Baixa | I52: =INDEX(Auxiliar!$D$5:$F$11,MATCH(Table1[[#This Row],[Tipologia_Testes]],Auxiliar!$B$5:$B$11,0),MATCH(Table1[[#This Row],[Complexidade]],Auxiliar!$D$4:$F$4,0)) -> 2 | J52: =J51 -> 27/03/2024 (Corp): Deve ser aprovisionado localmente com o valor correspondente de não aplicável (11111111111)
B53: GD | C53: Corporativo | D53: RWA_OFF_BLNC | E53: Concluído | F53: 6. Validação de formatos | G53: Não | H53: Baixa | I53: =INDEX(Auxiliar!$D$5:$F$11,MATCH(Table1[[#This Row],[Tipologia_Testes]],Auxiliar!$B$5:$B$11,0),MATCH(Table1[[#This Row],[Complexidade]],Auxiliar!$D$4:$F$4,0)) -> 0.1 | J53: =J52 -> 27/03/2024 (Corp): Deve ser aprovisionado localmente com o valor correspondente de não aplicável (11111111111)
B54: GD | C54: Corporativo | D54: RWA_OFF_BLNC | E54: Concluído | F54: 7. Validação de controlos corporativos | G54: Não | H54: Baixa | I54: =INDEX(Auxiliar!$D$5:$F$11,MATCH(Table1[[#This Row],[Tipologia_Testes]],Auxiliar!$B$5:$B$11,0),MATCH(Table1[[#This Row],[Complexidade]],Auxiliar!$D$4:$F$4,0)) -> 1 | J54: =J53 -> 27/03/2024 (Corp): Deve ser aprovisionado localmente com o valor correspondente de não aplicável (11111111111)
B55: GD | C55: Rentabilidade | D55: INTRNL_TRNSFR_RT_OFF_BLNC | E55: Concluído | F55: 2. Simulação | G55: Não | H55: Baixa | I55: =INDEX(Auxiliar!$D$5:$F$11,MATCH(Table1[[#This Row],[Tipologia_Testes]],Auxiliar!$B$5:$B$11,0),MATCH(Table1[[#This Row],[Complexidade]],Auxiliar!$D$4:$F$4,0)) -> 2 | J55: 27/03/2024 (Corp): O campo Internal transfer rate from off balance amounts não está incluído no âmbito de contratos do Santander Portugal. Assim, o campo deverá ser aprovisionado com o valor correspondente a não aplicável (11111111111).
B56: GD | C56: Rentabilidade | D56: INTRNL_TRNSFR_RT_OFF_BLNC | E56: Concluído | F56: 3. Testes comparativos (Espec. VS Impl.) | G56: Não | H56: Baixa | I56: =INDEX(Auxiliar!$D$5:$F$11,MATCH(Table1[[#This Row],[Tipologia_Testes]],Auxiliar!$B$5:$B$11,0),MATCH(Table1[[#This Row],[Complexidade]],Auxiliar!$D$4:$F$4,0)) -> 2 | J56: =J55 -> 27/03/2024 (Corp): O campo Internal transfer rate from off balance amounts não está incluído no âmbito de contratos do Santander Portugal. Assim, o campo deverá ser aprovisionado com o valor correspondente a não aplicável (11111111111).
B57: GD | C57: Rentabilidade | D57: INTRNL_TRNSFR_RT_OFF_BLNC | E57: Concluído | F57: 6. Validação de formatos | G57: Não | H57: Baixa | I57: =INDEX(Auxiliar!$D$5:$F$11,MATCH(Table1[[#This Row],[Tipologia_Testes]],Auxiliar!$B$5:$B$11,0),MATCH(Table1[[#This Row],[Complexidade]],Auxiliar!$D$4:$F$4,0)) -> 0.1 | J57: =J56 -> 27/03/2024 (Corp): O campo Internal transfer rate from off balance amounts não está incluído no âmbito de contratos do Santander Portugal. Assim, o campo deverá ser aprovisionado com o valor correspondente a não aplicável (11111111111).
B58: GD | C58: Rentabilidade | D58: INTRNL_TRNSFR_RT_OFF_BLNC | E58: Concluído | F58: 7. Validação de controlos corporativos | G58: Não | H58: Baixa | I58: =INDEX(Auxiliar!$D$5:$F$11,MATCH(Table1[[#This Row],[Tipologia_Testes]],Auxiliar!$B$5:$B$11,0),MATCH(Table1[[#This Row],[Complexidade]],Auxiliar!$D$4:$F$4,0)) -> 1 | J58: =J57 -> 27/03/2024 (Corp): O campo Internal transfer rate from off balance amounts não está incluído no âmbito de contratos do Santander Portugal. Assim, o campo deverá ser aprovisionado com o valor correspondente a não aplicável (11111111111).
...

Sheet 2. Controlos Corporativos
A1: Campo | B1: LT_VALIDATION_LABEL | C1: LT_VALIDATION_DESCRIPTION | D1: LT_VALIDAT_TABLE | E1: LT_VALIDAT_FIELD | F1: LT_VALIDATION_TYPE | G1: LT_PROC_STEP_ID | H1: LT_PROC_VAL_NEW_STATUS | I1: LT_VAL_EXECUTED | J1: LT_VAL_INCIDENTS | K1: VL_PERCENT
A2: =VLOOKUP(E2,Table1[[#All],[Campo]],1,0) -> COD_SOC | B2: LT_C_EN_001_01 | C2: "Entity code of the informing society." should be a Char not null (default values not allowed) | D2: INTRA_N1_EN | E2: COD_SOC | F2: NOT_NULL_CHAR | G2: LT_C_EN | H2: OK | I2: 1096295 | J2: 0 | K2: 0
A3: =VLOOKUP(E3,Table1[[#All],[Campo]],1,0) -> DT_RFRNC | B3: LT_C_EN_009_01 | C3: "Reference date." should be a Date not null (default values not allowed) | D3: INTRA_N1_EN | E3: DT_RFRNC | F3: NOT_NULL_DATE | G3: LT_C_EN | H3: OK | I3: 1096295 | J3: 0 | K3: 0
A4: =VLOOKUP(E4,Table1[[#All],[Campo]],1,0) -> COD_SOC | B4: LT_C_IE_001_01 | C4: "Entity code of the informing society." should be a Char not null (default values not allowed) | D4: INTRA_N1_IE | E4: COD_SOC | F4: NOT_NULL_CHAR | G4: LT_C_IE | H4: OK | I4: 2490665 | J4: 0 | K4: 0
A5: =VLOOKUP(E5,Table1[[#All],[Campo]],1,0) -> DT_RFRNC | B5: LT_C_IE_002_01 | C5: "Reference date" should be a Date not null (default values not allowed) | D5: INTRA_N1_IE | E5: DT_RFRNC | F5: NOT_NULL_DATE | G5: LT_C_IE | H5: OK | I5: 2490665 | J5: 0 | K5: 0
A6: =VLOOKUP(E6,Table1[[#All],[Campo]],1,0) -> INSTRMNT_ID | B6: LT_C_IE_004_01 | C6: "Instrument ID" should be a Char not null (default values not allowed) | D6: INTRA_N1_IE | E6: INSTRMNT_ID | F6: NOT_NULL_CHAR | G6: LT_C_IE | H6: OK | I6: 2490665 | J6: 0 | K6: 0
A7: =VLOOKUP(E7,Table1[[#All],[Campo]],1,0) -> COD_SOC | B7: LT_C_IN_001_01 | C7: "Entity code of the informing society." should be a Char not null (default values not allowed) | D7: INTRA_N1_IN | E7: COD_SOC | F7: NOT_NULL_CHAR | G7: LT_C_IN | H7: OK | I7: 2002411 | J7: 0 | K7: 0
A8: =VLOOKUP(E8,Table1[[#All],[Campo]],1,0) -> DT_RFRNC | B8: LT_C_IN_007_01 | C8: "Reference date" should be a Date not null (default values not allowed) | D8: INTRA_N1_IN | E8: DT_RFRNC | F8: NOT_NULL_DATE | G8: LT_C_IN | H8: OK | I8: 2002411 | J8: 0 | K8: 0
A9: =VLOOKUP(E9,Table1[[#All],[Campo]],1,0) -> INSTRMNT_ID | B9: LT_C_IN_008_01 | C9: "Instrument ID" should be a Char not null (default values not allowed) | D9: INTRA_N1_IN | E9: INSTRMNT_ID | F9: NOT_NULL_CHAR | G9: LT_C_IN | H9: OK | I9: 2002411 | J9: 0 | K9: 0
A10: =VLOOKUP(E10,Table1[[#All],[Campo]],1,0) -> DFLT_STTS_INSTRMNT | B10: LT_C_IN_020_01 | C10: "Default status of the instrument" should be a num not null (default values for not applicable fields not allowed) | D10: INSTRUMENT | E10: DFLT_STTS_INSTRMNT | F10: NOT_NULL_NUM_NA | G10: LT_C_IN | H10: KO | I10: 2002411 | J10: 96182 | K10: 4.8033
A11: =VLOOKUP(E11,Table1[[#All],[Campo]],1,0) -> PRFRMNG_STTS | B11: LT_C_IN_044_01 | C11: "Performing status" should be a num not null (default values for not applicable fields not allowed) | D11: INSTRUMENT | E11: PRFRMNG_STTS | F11: NOT_NULL_NUM_NA | G11: LT_C_IN | H11: OK | I11: 2002411 | J11: 0 | K11: 0
A12: =VLOOKUP(E12,Table1[[#All],[Campo]],1,0) -> LCL_INSTMRNT_ID | B12: LT_C_IN_193_01 | C12: "Local Instrument ID" should be a Char not null (default values not allowed) | D12: INTRA_N1_IN | E12: LCL_INSTMRNT_ID | F12: NOT_NULL_CHAR | G12: LT_C_IN | H12: KO | I12: 2002411 | J12: 2002411 | K12: 100
A13: =VLOOKUP(E13,Table1[[#All],[Campo]],1,0) -> SSTNBL_INDCTR | B13: LT_C_IN_194_01 | C13: "Sustainable Indicator" should be a Char not null (default values for not applicable fields not allowed) | D13: INSTRUMENT | E13: SSTNBL_INDCTR | F13: NOT_NULL_NA | G13: LT_C_IN | H13: KO | I13: 2002318 | J13: 2002318 | K13: 100
... A18: =VLOOKUP(E18,Table1[[#All],[Campo]],1,0) -> BSNSS_AREA_CCRR | B18: LT_C_IN_222_01 | C18: "Business Area related to CIB" should be a Char not null (default values for not applicable fields not allowed) | D18: INSTRUMENT | E18: BSNSS_AREA_CCRR | F18: NOT_NULL_NA | G18: LT_C_IN | H18: KO | I18: 2002411 | J18: 2002411 | K18: 100
A19: CNCLLD_INSTRMNT_STTS | B19: LT_C_IN_245_01 | C19: "Flag of instrument cancelled" should be a Char not null (default values for not applicable fields not allowed) | D19: INSTRUMENT | E19: FLG_INSTRMNT_CNCLLD | F19: NOT_NULL_NA | G19: LT_C_IN | H19: KO | I19: 2002411 | J19: 2002411 | K19: 100
A20: =VLOOKUP(E20,Table1[[#All],[Campo]],1,0) -> IDCMB | B20: LT_C_IN_246_01 | C20: "IDCOMB" should be a Char not null (default values not allowed) | D20: INTRA_N1_IN | E20: IDCMB | F20: NOT_NULL_CHAR | G20: LT_C_IN | H20: KO | I20: 2002411 | J20: 1 | K20: 0
A21: =VLOOKUP(E21,Table1[[#All],[Campo]],1,0) -> COD_SOC | B21: LT_C_IP_001_01 | C21: "Entity code of the informing society." should be a Char not null (default values not allowed) | D21: INTRA_N1_IP | E21: COD_SOC | F21: NOT_NULL_CHAR | G21: LT_C_IP | H21: OK | I21: 731165 | J21: 0 | K21: 0
A22: =VLOOKUP(E22,Table1[[#All],[Campo]],1,0) -> DT_RFRNC | B22: LT_C_IP_002_01 | C22: "Reference date" should be a Date not null (default values not allowed) | D22: INTRA_N1_IP | E22: DT_RFRNC | F22: NOT_NULL_DATE | G22: LT_C_IP | H22: OK | I22: 731165 | J22: 0 | K22: 0
A23: =VLOOKUP(E23,Table1[[#All],[Campo]],1,0) -> INSTRMNT_ID | B23: LT_C_IP_003_01 | C23: "Instrument ID" should be a Char not null (default values not allowed) | D23: INTRA_N1_IP | E23: INSTRMNT_ID | F23: NOT_NULL_CHAR | G23: LT_C_IP | H23: OK | I23: 731165 | J23: 0 | K23: 0
A24: =VLOOKUP(E24,Table1[[#All],[Campo]],1,0) -> COD_SOC | B24: LT_C_PR_001_01 | C24: "Entity code of the informing society." should be a Char not null (default values not allowed) | D24: INTRA_N1_PR | E24: COD_SOC | F24: NOT_NULL_CHAR | G24: LT_C_PR | H24: OK | I24: 456960 | J24: 0 | K24: 0
A25: =VLOOKUP(E25,Table1[[#All],[Campo]],1,0) -> DT_RFRNC | B25: LT_C_PR_003_01 | C25: "Reference date" should be a Date not null (default values not allowed) | D25: INTRA_N1_PR | E25: DT_RFRNC | F25: NOT_NULL_DATE | G25: LT_C_PR | H25: OK | I25: 456960 | J25: 0 | K25: 0
A26: =VLOOKUP(E26,Table1[[#All],[Campo]],1,0) -> INSTRMNT_ID | B26: LT_D_IN_008_01 | C26: Duplicates by "Instrument ID" in INSTRUMENT table | D26: INSTRUMENT | E26: INSTRMNT_ID | F26: DUPLICATES PK | G26: LT_D_ | H26: OK | I26: 2003033 | J26: 0 | K26: 0
A27: =VLOOKUP(E27,Table1[[#All],[Campo]],1,0) -> INSTRMNT_ID | B27: LT_D_IP_003_01 | C27: Duplicates by "Instrument ID" and "Protection ID" in INSTR_PROTECTION table | D27: INSTR_PROTECTION | E27: INSTRMNT_ID | F27: DUPLICATES PK | G27: LT_D_ | H27: OK | I27: 731165 | J27: 0 | K27: 0
A28: =VLOOKUP(E28,Table1[[#All],[Campo]],1,0) -> COD_SOC | B28: LT_F_EN_001_01 | C28: "Entity code of the informing society." should match the information on the Codelist | D28: ENTITY | E28: COD_SOC | F28: LISTA | G28: LT_F_EN | H28: OK | I28: 1096295 | J28: 0 | K28: 0
A29: =VLOOKUP(E29,Table1[[#All],[Campo]],1,0) -> DT_RFRNC | B29: LT_F_EN_009_01 | C29: "Reference date." must have a Date format (yyyy-mm-dd) | D29: ENTITY | E29: DT_RFRNC | F29: FORMAT_DATE | G29: LT_F_EN | H29: OK | I29: 1096295 | J29: 0 | K29: 0
A30: =VLOOKUP(E30,Table1[[#All],[Campo]],1,0) -> COD_SOC | B30: LT_F_IE_001_01 | C30: "Entity code of the informing society." should match the information on the Codelist | D30: INSTR_ENTITY | E30: COD_SOC | F30: LISTA | G30: LT_F_IE | H30: OK | I30: 2490665 | J30: 0 | K30: 0
A31: =VLOOKUP(E31,Table1[[#All],[Campo]],1,0) -> DT_RFRNC | B31: LT_F_IE_002_01 | C31: "Reference date" must have a Date format (yyyy-mm-dd) | D31: INSTR_ENTITY | E31: DT_RFRNC | F31: FORMAT_DATE | G31: LT_F_IE | H31: OK | I31: 2490665 | J31: 0 | K31: 0
... A54: =VLOOKUP(E54,Table1[[#All],[Campo]],1,0) -> GRSS_INTRST_INCM | B54: LT_F_IN_198_01 | C54: "Gross Interest income before distribution to SCIB under the Collabotarion Revenues distribution agreement" should have a Format numeric (2 decimal places) | D54: INSTRUMENT | E54: GRSS_INTRST_INCM | F54: FORMAT_NUM | G54: LT_F_IN | H54: OK | I54: 2003033 | J54: 0 | K54: 0
A55: GRSS_CMMSSN_INCM | B55: LT_F_IN_199_01 | C55: "Gross fee and commission income before distribution to SCIB under the Collabotarion Revenues distribution agreement" should have a Format numeric (2 decimal places) | D55: INSTRUMENT | E55: GRSS_FEE_CMMSSN_INCM | F55: FORMAT_NUM | G55: LT_F_IN | H55: OK | I55: 2003033 | J55: 0 | K55: 0
A56: =VLOOKUP(E56,Table1[[#All],[Campo]],1,0) -> INTRNL_TRNSFR_RT | B56: LT_F_IN_200_01 | C56: "Internal transfer rate amount" should have a Format numeric (2 decimal places) | D56: INSTRUMENT | E56: INTRNL_TRNSFR_RT | F56: FORMAT_NUM | G56: LT_F_IN | H56: OK | I56: 2003033 | J56: 0 | K56: 0
A57: =VLOOKUP(E57,Table1[[#All],[Campo]],1,0) -> NT_LN_LSS_PRVSN | B57: LT_F_IN_201_01 | C57: "Net loan-loss provisions" should have a Format numeric (2 decimal places) | D57: INSTRUMENT | E57: NT_LN_LSS_PRVSN | F57: FORMAT_NUM | G57: LT_F_IN | H57: OK | I57: 2003033 | J57: 0 | K57: 0
A58: =VLOOKUP(E58,Table1[[#All],[Campo]],1,0) -> BSNSS_AREA | B58: LT_F_IN_202_01 | C58: "Business Area" should match the information on the Codelist | D58: INSTRUMENT | E58: BSNSS_AREA | F58: LISTA | G58: LT_F_IN | H58: KO | I58: 2003033 | J58: 2003033 | K58: 100
A59: =VLOOKUP(E59,Table1[[#All],[Campo]],1,0) -> MNGMNT_PRDCT | B59: LT_F_IN_203_01 | C59: "Management Product" should match the information on the Codelist | D59: INSTRUMENT | E59: MNGMNT_PRDCT | F59: LISTA | G59: LT_F_IN | H59: KO | I59: 2003033 | J59: 2003033 | K59: 100
A60: GRSS_CMMSSN_EXPNS | B60: LT_F_IN_204_01 | C60: "Gross fee and commission expense before distribution to SCIB under the Collabotarion Revenues distribution agreement" should have a Format numeric (2 decimal places) | D60: INSTRUMENT | E60: GRSS_FEE_CMMSSN_EXPNS | F60: FORMAT_NUM | G60: LT_F_IN | H60: OK | I60: 2003033 | J60: 0 | K60: 0
A61: =VLOOKUP(E61,Table1[[#All],[Campo]],1,0) -> GNS_FNNCL_TRNSCTN_EXCHNG_DFFRNCS | B61: LT_F_IN_205_01 | C61: "Gains (Losses) On Financial Transaction (gft) And Exchange Differences, before distribution to SCIB under the Collabotarion Revenues distribution agreement" should have a Format numeric (2 decimal places) | D61: INSTRUMENT | E61: GNS_FNNCL_TRNSCTN_EXCHNG_DFFRNCS | F61: FORMAT_NUM | G61: LT_F_IN | H61: OK | I61: 2003033 | J61: 0 | K61: 0
A62: =VLOOKUP(E62,Table1[[#All],[Campo]],1,0) -> FLG_INTRBSNSS | B62: LT_F_IN_206_01 | C62: "Flag of interbusiness" should match the information on the Codelist | D62: INSTRUMENT | E62: FLG_INTRBSNSS | F62: LISTA | G62: LT_F_IN | H62: KO | I62: 2003033 | J62: 2003033 | K62: 100
A63: =VLOOKUP(E63,Table1[[#All],[Campo]],1,0) -> INTRBSNSS_ADJ_COD | B63: LT_F_IN_207_01 | C63: "Interbusiness adjustment code" should match the information on the Codelist | D63: INSTRUMENT | E63: INTRBSNSS_ADJ_COD | F63: LISTA | G63: LT_F_IN | H63: KO | I63: 2003033 | J63: 2003033 | K63: 100
A64: =VLOOKUP(E64,Table1[[#All],[Campo]],1,0) -> COD_SOC_DSTNTN | B64: LT_F_IN_208_01 | C64: "Cargabal identification code of the destination entity" should match the information on the Codelist | D64: INSTRUMENT | E64: COD_SOC_DSTNTN | F64: LISTA | G64: LT_F_IN | H64: KO | I64: 2003033 | J64: 2003033 | K64: 100
A65: =VLOOKUP(E65,Table1[[#All],[Campo]],1,0) -> BSNSS_AREA_DSTNTN | B65: LT_F_IN_209_01 | C65: "Destination Business area" should match the information on the Codelist | D65: INSTRUMENT | E65: BSNSS_AREA_DSTNTN | F65: LISTA | G65: LT_F_IN | H65: KO | I65: 2003033 | J65: 2003033 | K65: 100
A66: =VLOOKUP(E66,Table1[[#All],[Campo]],1,0) -> AVRG_BLNC_OFF_BLNC | B66: LT_F_IN_210_01 | C66: "Average balance corresponding to undrawn balances committed" should have a Format numeric (2 decimal places) | D66: INSTRUMENT | E66: AVRG_BLNC_OFF_BLNC | F66: FORMAT_NUM | G66: LT_F_IN | H66: OK | I66: 2003033 | J66: 0 | K66: 0
...

Sheet 3. Plano
L6: =SUM(L11:L61) -> 2 | M6: =SUM(M11:M61) -> 2 | N6: =SUM(N11:N61) -> 1 | O6: =SUM(O11:O61) -> 1 | P6: =SUM(P11:P61) -> 1.5 | Q6: =SUM(Q11:Q61) -> 1.5 | R6: =SUM(R11:R61) -> 1.5 | S6: =SUM(S11:S61) -> 1.5 | ... AE6: =SUM(AE11:AE61) -> 2.5
K7: FTEs Máx | L7: 2 | M7: 2 | N7: 1 | O7: 1 | P7: 1.5 | Q7: 1.5 | R7: 1.5 | S7: 1.5 | T7: 1.5 | U7: 1.5 | V7: 1.5 | W7: 1.5 | X7: 1.5 | Y7: 1.5 | Z7: 1 | AA7: 1 | AB7: 1 | AC7: 2.5 | AD7: 2.5 | AE7: 2.5
L8: Julho | AF8: Agosto
L9: 45477 | M9: 45478 | N9: =WORKDAY(M9,1) -> 45481 | O9: =WORKDAY(N9,1) -> 45482 | P9: =WORKDAY(O9,1) -> 45483 | Q9: =WORKDAY(P9,1) -> 45484 | R9: =WORKDAY(Q9,1) -> 45485 | S9: =WORKDAY(R9,1) -> 45488 | T9: =WORKDAY(S9,1) -> 45489 | U9: =WORKDAY(T9,1) -> 45490 | ... AE9: =WORKDAY(AD9,1) -> 45504 | AF9: 1 | AG9: 2
B10: Âmbito | C10: Origem | D10: Campo | E10: Status | F10: Total Horas | G10: Column1 | H10: Validação | I10: Ordem
B11: GD | C11: - | D11: n.a. | F11: =IF(Table13[[#This Row],[Status]]="Concluído",0,(SUMIFS(Table1[Estimação (horas)],Table1[Campo],Table13[[#This Row],[Campo]]))) -> 8 | G11: =Table13[[#This Row],[Total Horas]]/8 -> 1 | H11: =ROUND(Table13[[#This Row],[Column1]]-SUM(L11:BB11),2) -> 0 | I11: 1 | P11: 1
B12: GD | C12: Modelo Verde | D12: SSTNBL_CTGRY | E12: Concluído | F12: =IF(Table13[[#This Row],[Status]]="Concluído",0,(SUMIFS(Table1[Estimação (horas)],Table1[Campo],Table13[[#This Row],[Campo]]))) -> 0 | G12: =Table13[[#This Row],[Total Horas]]/8 -> 0 | H12: =ROUND(Table13[[#This Row],[Column1]]-SUM(L12:BB12),2) -> 0
B13: GD | C13: LT ESTR | D13: DFLT_STTS_INSTRMNT | E13: Concluído | F13: =IF(Table13[[#This Row],[Status]]="Concluído",0,(SUMIFS(Table1[Estimação (horas)],Table1[Campo],Table13[[#This Row],[Campo]]))) -> 0 | G13: =Table13[[#This Row],[Total Horas]]/8 -> 0 | H13: =ROUND(Table13[[#This Row],[Column1]]-SUM(L13:BB13),2) -> 0
B14: GD | C14: LT ESTR | D14: ACCMLTD_CHNGS_FV_CR_INSTRMNT | E14: Concluído | F14: =IF(Table13[[#This Row],[Status]]="Concluído",0,(SUMIFS(Table1[Estimação (horas)],Table1[Campo],Table13[[#This Row],[Campo]]))) -> 0 | G14: =Table13[[#This Row],[Total Horas]]/8 -> 0 | H14: =ROUND(Table13[[#This Row],[Column1]]-SUM(L14:BB14),2) -> 0
B15: GD | C15: LT ESTR | D15: ACCMLTD_IMPRMNT_INSTRMNT | E15: Concluído | F15: =IF(Table13[[#This Row],[Status]]="Concluído",0,(SUMIFS(Table1[Estimação (horas)],Table1[Campo],Table13[[#This Row],[Campo]]))) -> 0 | G15: =Table13[[#This Row],[Total Horas]]/8 -> 0 | H15: =ROUND(Table13[[#This Row],[Column1]]-SUM(L15:BB15),2) -> 0
B16: GD | C16: LT ESTR | D16: ACCNTNG_CLSSFCTN | E16: Concluído | F16: =IF(Table13[[#This Row],[Status]]="Concluído",0,(SUMIFS(Table1[Estimação (horas)],Table1[Campo],Table13[[#This Row],[Campo]]))) -> 0 | G16: =Table13[[#This Row],[Total Horas]]/8 -> 0 | H16: =ROUND(Table13[[#This Row],[Column1]]-SUM(L16:BB16),2) -> 0
B17: GD | C17: LT ESTR | D17: COD_SOC | E17: Concluído | F17: =IF(Table13[[#This Row],[Status]]="Concluído",0,(SUMIFS(Table1[Estimação (horas)],Table1[Campo],Table13[[#This Row],[Campo]]))) -> 0 | G17: =Table13[[#This Row],[Total Horas]]/8 -> 0 | H17: =ROUND(Table13[[#This Row],[Column1]]-SUM(L17:BB17),2) -> 0
B18: GD | C18: LT ESTR | D18: DT_RFRNC | E18: Concluído | F18: =IF(Table13[[#This Row],[Status]]="Concluído",0,(SUMIFS(Table1[Estimação (horas)],Table1[Campo],Table13[[#This Row],[Campo]]))) -> 0 | G18: =Table13[[#This Row],[Total Horas]]/8 -> 0 | H18: =ROUND(Table13[[#This Row],[Column1]]-SUM(L18:BB18),2) -> 0
B19: GD | C19: LT ESTR | D19: GRSS_CRRYNG_AMNT_INSTRMNT | E19: Concluído | F19: =IF(Table13[[#This Row],[Status]]="Concluído",0,(SUMIFS(Table1[Estimação (horas)],Table1[Campo],Table13[[#This Row],[Campo]]))) -> 0 | G19: =Table13[[#This Row],[Total Horas]]/8 -> 0 | H19: =ROUND(Table13[[#This Row],[Column1]]-SUM(L19:BB19),2) -> 0
B20: GD | C20: LT ESTR | D20: IDCMB | E20: Concluído | F20: =IF(Table13[[#This Row],[Status]]="Concluído",0,(SUMIFS(Table1[Estimação (horas)],Table1[Campo],Table13[[#This Row],[Campo]]))) -> 0 | G20: =Table13[[#This Row],[Total Horas]]/8 -> 0 | H20: =ROUND(Table13[[#This Row],[Column1]]-SUM(L20:BB20),2) -> 0
B21: GD | C21: LT ESTR | D21: IMPRMNT_STTS | E21: Concluído | F21: =IF(Table13[[#This Row],[Status]]="Concluído",0,(SUMIFS(Table1[Estimação (horas)],Table1[Campo],Table13[[#This Row],[Campo]]))) -> 0 | G21: =Table13[[#This Row],[Total Horas]]/8 -> 0 | H21: =ROUND(Table13[[#This Row],[Column1]]-SUM(L21:BB21),2) -> 0
B22: GD | C22: Rentabilidade | D22: BSNSS_AREA | E22: Em Teste | F22: =IF(Table13[[#This Row],[Status]]="Concluído",0,(SUMIFS(Table1[Estimação (horas)],Table1[Campo],Table13[[#This Row],[Campo]]))) -> 22.1 | G22: =Table13[[#This Row],[Total Horas]]/8 -> 2.7625 | H22: =ROUND(Table13[[#This Row],[Column1]]-SUM(M22:BB22),2) -> 0.01 | I22: 2 | L22: 1 | M22: 1 | N22: 0.5 | O22: 1 | P22: 0.25
B23: GD | C23: LT ESTR | D23: LCL_INSTMRNT_ID | E23: Concluído | F23: =IF(Table13[[#This Row],[Status]]="Concluído",0,(SUMIFS(Table1[Estimação (horas)],Table1[Campo],Table13[[#This Row],[Campo]]))) -> 0 | G23: =Table13[[#This Row],[Total Horas]]/8 -> 0 | H23: =ROUND(Table13[[#This Row],[Column1]]-SUM(M23:BB23),2) -> 0
B24: GD | C24: LT ESTR | D24: OFF_BLNC_SHT_AMNT_INSTRMNT | E24: Concluído | F24: =IF(Table13[[#This Row],[Status]]="Concluído",0,(SUMIFS(Table1[Estimação (horas)],Table1[Campo],Table13[[#This Row],[Campo]]))) -> 0 | G24: =Table13[[#This Row],[Total Horas]]/8 -> 0 | H24: =ROUND(Table13[[#This Row],[Column1]]-SUM(M24:BB24),2) -> 0
B25: GD | C25: LT ESTR | D25: PRFRMNG_STTS | E25: Concluído | F25: =IF(Table13[[#This Row],[Status]]="Concluído",0,(SUMIFS(Table1[Estimação (horas)],Table1[Campo],Table13[[#This Row],[Campo]]))) -> 0 | G25: =Table13[[#This Row],[Total Horas]]/8 -> 0 | H25: =ROUND(Table13[[#This Row],[Column1]]-SUM(M25:BB25),2) -> 0
B26: GD | C26: LT ESTR | D26: PRVSNS_OFF_BLNC_SHT | E26: Concluído | F26: =IF(Table13[[#This Row],[Status]]="Concluído",0,(SUMIFS(Table1[Estimação (horas)],Table1[Campo],Table13[[#This Row],[Campo]]))) -> 0 | G26: =Table13[[#This Row],[Total Horas]]/8 -> 0 | H26: =ROUND(Table13[[#This Row],[Column1]]-SUM(M26:BB26),2) -> 0
B27: GD | C27: LT ESTR | D27: SUBPORTFOLIO_ID | E27: Concluído | F27: =IF(Table13[[#This Row],[Status]]="Concluído",0,(SUMIFS(Table1[Estimação (horas)],Table1[Campo],Table13[[#This Row],[Campo]]))) -> 0 | G27: =Table13[[#This Row],[Total Horas]]/8 -> 0 | H27: =ROUND(Table13[[#This Row],[Column1]]-SUM(M27:BB27),2) -> 0
B28: GD | C28: LT ESTR | D28: TYP_INSTRMNT | E28: Concluído | F28: =IF(Table13[[#This Row],[Status]]="Concluído",0,(SUMIFS(Table1[Estimação (horas)],Table1[Campo],Table13[[#This Row],[Campo]]))) -> 0 | G28: =Table13[[#This Row],[Total Horas]]/8 -> 0 | H28: =ROUND(Table13[[#This Row],[Column1]]-SUM(M28:BB28),2) -> 0
B29: GD | C29: LT ESTR | D29: RWA | E29: Concluído | F29: =IF(Table13[[#This Row],[Status]]="Concluído",0,(SUMIFS(Table1[Estimação (horas)],Table1[Campo],Table13[[#This Row],[Campo]]))) -> 0 | G29: =Table13[[#This Row],[Total Horas]]/8 -> 0 | H29: =ROUND(Table13[[#This Row],[Column1]]-SUM(M29:BB29),2) -> 0
B30: GD | C30: LT ESTR | D30: COD_SOC_INTRGRP | E30: Concluído | F30: =IF(Table13[[#This Row],[Status]]="Concluído",0,(SUMIFS(Table1[Estimação (horas)],Table1[Campo],Table13[[#This Row],[Campo]]))) -> 0 | G30: =Table13[[#This Row],[Total Horas]]/8 -> 0 | H30: =ROUND(Table13[[#This Row],[Column1]]-SUM(M30:BB30),2) -> 0
B31: GD | C31: Corporativo | D31: BSNSS_AREA_DSTNTN | E31: Concluído | F31: =IF(Table13[[#This Row],[Status]]="Concluído",0,(SUMIFS(Table1[Estimação (horas)],Table1[Campo],Table13[[#This Row],[Campo]]))) -> 0 | G31: =Table13[[#This Row],[Total Horas]]/8 -> 0 | H31: =ROUND(Table13[[#This Row],[Column1]]-SUM(M31:BB31),2) -> 0
B32: GD | C32: Corporativo | D32: FLG_INTRBSNSS | E32: Concluído | F32: =IF(Table13[[#This Row],[Status]]="Concluído",0,(SUMIFS(Table1[Estimação (horas)],Table1[Campo],Table13[[#This Row],[Campo]]))) -> 0 | G32: =Table13[[#This Row],[Total Horas]]/8 -> 0 | H32: =ROUND(Table13[[#This Row],[Column1]]-SUM(M32:BB32),2) -> 0
B33: GD | C33: Corporativo | D33: INTRBSNSS_ADJ_COD | E33: Concluído | F33: =IF(Table13[[#This Row],[Status]]="Concluído",0,(SUMIFS(Table1[Estimação (horas)],Table1[Campo],Table13[[#This Row],[Campo]]))) -> 0 | G33: =Table13[[#This Row],[Total Horas]]/8 -> 0 | H33: =ROUND(Table13[[#This Row],[Column1]]-SUM(M33:BB33),2) -> 0
B34: GD | C34: Corporativo | D34: COD_SOC_DSTNTN | E34: Concluído | F34: =IF(Table13[[#This Row],[Status]]="Concluído",0,(SUMIFS(Table1[Estimação (horas)],Table1[Campo],Table13[[#This Row],[Campo]]))) -> 0 | G34: =Table13[[#This Row],[Total Horas]]/8 -> 0 | H34: =ROUND(Table13[[#This Row],[Column1]]-SUM(M34:BB34),2) -> 0
... B36: GD | C36: Rentabilidade | D36: INTRNL_TRNSFR_RT_OFF_BLNC | E36: Concluído | F36: =IF(Table13[[#This Row],[Status]]="Concluído",0,(SUMIFS(Table1[Estimação (horas)],Table1[Campo],Table13[[#This Row],[Campo]]))) -> 0 | G36: =Table13[[#This Row],[Total Horas]]/8 -> 0 | H36: =ROUND(Table13[[#This Row],[Column1]]-SUM(M36:BB36),2) -> 0
B37: GD | C37: Outro | D37: INSTRMNT_ID | E37: Em Teste | F37: =IF(Table13[[#This Row],[Status]]="Concluído",0,(SUMIFS(Table1[Estimação (horas)],Table1[Campo],Table13[[#This Row],[Campo]]))) -> 12.1 | G37: =Table13[[#This Row],[Total Horas]]/8 -> 1.5125 | H37: =ROUND(Table13[[#This Row],[Column1]]-SUM(M37:BB37),2) -> 0.01 | I37: 3 | L37: 0.2 | M37: 1 | N37: 0.5
B38: GD | C38: Rentabilidade | D38: BSNSS_AREA_CCRR | E38: Em Teste | F38: =IF(Table13[[#This Row],[Status]]="Concluído",0,(SUMIFS(Table1[Estimação (horas)],Table1[Campo],Table13[[#This Row],[Campo]]))) -> 0.1 | G38: =Table13[[#This Row],[Total Horas]]/8 -> 0.0125 | H38: =ROUND(Table13[[#This Row],[Column1]]-SUM(M38:BB38),2) -> 0.01 | L38: 0.1
B39: GD | C39: Rentabilidade | D39: CNCLLD_INSTRMNT_STTS | E39: Em Correção | F39: =IF(Table13[[#This Row],[Status]]="Concluído",0,(SUMIFS(Table1[Estimação (horas)],Table1[Campo],Table13[[#This Row],[Campo]]))) -> 12.1 | G39: =Table13[[#This Row],[Total Horas]]/8 -> 1.5125 | H39: =ROUND(Table13[[#This Row],[Column1]]-SUM(M39:BB39),2) -> 0.01 | I39: 4 | P39: 0.25 | Q39: 1 | R39: 0.25
B40: GD | C40: Rentabilidade | D40: GNS_FNNCL_TRNSCTN_EXCHNG_CCRR | E40: Em Teste | F40: =IF(Table13[[#This Row],[Status]]="Concluído",0,(SUMIFS(Table1[Estimação (horas)],Table1[Campo],Table13[[#This Row],[Campo]]))) -> 0.1 | G40: =Table13[[#This Row],[Total Horas]]/8 -> 0.0125 | H40: =ROUND(Table13[[#This Row],[Column1]]-SUM(M40:BB40),2) -> 0.01 | L40: 0.1
B41: GD | C41: Rentabilidade | D41: MNGMNT_PRDCT | E41: Em Teste | F41: =IF(Table13[[#This Row],[Status]]="Concluído",0,(SUMIFS(Table1[Estimação (horas)],Table1[Campo],Table13[[#This Row],[Campo]]))) -> 14.1 | G41: =Table13[[#This Row],[Total Horas]]/8 -> 1.7625 | H41: =ROUND(Table13[[#This Row],[Column1]]-SUM(M41:BB41),2) -> 0.01 | I41: 5 | Q41: 0.5 | R41: 1 | S41: 0.25
B42: GD | C42: Rentabilidade | D42: NW_BSNSS | E42: Em Teste | F42: =IF(Table13[[#This Row],[Status]]="Concluído",0,(SUMIFS(Table1[Estimação (horas)],Table1[Campo],Table13[[#This Row],[Campo]]))) -> 10.1 | G42: =Table13[[#This Row],[Total Horas]]/8 -> 1.2625 | H42: =ROUND(Table13[[#This Row],[Column1]]-SUM(M42:BB42),2) -> 0.01 | I42: 6 | R42: 0.25 | S42: 1
B43: GD | C43: Modelo Verde | D43: SSTNBL_INDCTR | E43: Em Correção | F43: =IF(Table13[[#This Row],[Status]]="Concluído",0,(SUMIFS(Table1[Estimação (horas)],Table1[Campo],Table13[[#This Row],[Campo]]))) -> 14.1 | G43: =Table13[[#This Row],[Total Horas]]/8 -> 1.7625 | H43: =ROUND(Table13[[#This Row],[Column1]]-SUM(M43:BB43),2) -> 0.01 | I43: 7 | S43: 0.25 | T43: 1 | U43: 0.5
B44: GD | C44: Rentabilidade | D44: AVRG_BLNC | E44: Em Teste | F44: =IF(Table13[[#This Row],[Status]]="Concluído",0,(SUMIFS(Table1[Estimação (horas)],Table1[Campo],Table13[[#This Row],[Campo]]))) -> 10.1 | G44: =Table13[[#This Row],[Total Horas]]/8 -> 1.2625 | H44: =ROUND(Table13[[#This Row],[Column1]]-SUM(M44:BB44),2) -> 0.01 | I44: 8 | T44: 0.5 | U44: 0.75
B45: GD | C45: Rentabilidade | D45: GRSS_CMMSSN_EXPNS_CCRR | E45: Em Teste | F45: =IF(Table13[[#This Row],[Status]]="Concluído",0,(SUMIFS(Table1[Estimação (horas)],Table1[Campo],Table13[[#This Row],[Campo]]))) -> 0.1 | G45: =Table13[[#This Row],[Total Horas]]/8 -> 0.0125 | H45: =ROUND(Table13[[#This Row],[Column1]]-SUM(M45:BB45),2) -> 0.01 | L45: 0.1
B46: GD | C46: Rentabilidade | D46: AVRG_BLNC_OFF_BLNC | E46: Em Teste | F46: =IF(Table13[[#This Row],[Status]]="Concluído",0,(SUMIFS(Table1[Estimação (horas)],Table1[Campo],Table13[[#This Row],[Campo]]))) -> 10.1 | G46: =Table13[[#This Row],[Total Horas]]/8 -> 1.2625 | H46: =ROUND(Table13[[#This Row],[Column1]]-SUM(M46:BB46),2) -> 0.01 | I46: 9 | U46: 0.25 | V46: 1
...

Sheet Auxiliar
B2: Tipologia de testes | D2: Estimação Horas
D3: Complexidade
B4: Categorização de Testes | C4: Descrição | D4: Baixa | E4: Média | F4: Alta
B5: 1. Teste de universo | C5: 1. Validação de universo de contratos quando comparado âmbito "CDG" e "PM" 2. Controlos sobre o desdobramento de chaves nas relações FR-MIS | D5: 8 | E5: 8 | F5: 8
B6: 2. Simulação | C6: Simulação da especificação funcional. Suplementarmente, realizar reuniões de validações e esclarecimentos funcionais junto do negócio/owner. | D6: 2 | E6: 4 | F6: 8
B7: 3. Testes comparativos (Espec. VS Impl.) | C7: A partir da simulação realizada, comparar resultados com a implementação de IT. | D7: 2 | E7: 4 | F7: 8
B8: 4. Validação de parametrizações | C8: A partir da simulação realizada, comparar com as parametrizações implementadas por IT. | D8: 2 | E8: 4 | F8: 8
B9: 5. Teste comparativos com LT | C9: Garantir que a informação do campo da LT-ESTR âmbito 'PM' está espelhado no âmbito 'CDG'. | D9: 1 | E9: 1 | F9: 1
B10: 6. Validação de formatos | C10: Validação de formato de acordo com o que é esperado pela Corporação (incluindo validação de codelists, missing e default values) | D10: 0.1 | E10: 0.1 | F10: 0.1
B11: 7. Validação de controlos corporativos | C11: Validar controlos corporativos e se a especificação cumpre os requisitos. | D11: 1 | E11: 2 | F11: 2
B15: Status
B17: Concluído
B18: Por iniciar
B19: Em Teste
B20: Em Correção
B21: Cancelado

Sheet Tipologias de Testes GD (2)
B8: Origem | C8: Campo | D8: Status | E8: Tipologia de testes | H8: ID Categoria | I8: Categorização de Testes | J8: Descrição
B9: Modelo Verde | C9: SSTNBL_CTGRY | D9: Concluído | E9: 1,2,3,4,6,7 | H9: 1 | I9: Testes End-to-End / Amostragem | J9: - Simulação da EF; - Testes de comparação com o desenvolvido por IT: - Validação de escolha de BSNSS_AREA e construção do instrmnt_id - Validação de saldos associados ao campo em análise - Identificação da origem de incidências.
B10: LT ESTR | C10: DFLT_STTS_INSTRMNT | D10: Concluído | E10: 5.7 | H10: 2 | I10: Testes / Validações Funcionais - EF | J10: - Garantir que o que está desenvolvido se encontra de acordo com a EF do campo; - Validações e esclarecimentos funcionais junto do negócio/owner.
B11: LT ESTR | C11: ACCMLTD_CHNGS_FV_CR_INSTRMNT | D11: Concluído | E11: 5.7 | H11: 3 | I11: Testes / Validações às parametrizações | J11: - Garantir que as parametrizações carregadas se encontram OK; - Validações e esclarecimentos funcionais junto do negócio/owner.
B12: LT ESTR | C12: ACCMLTD_IMPRMNT_INSTRMNT | D12: Concluído | E12: 5.7 | H12: 4 | I12: Testes de Informação Corporativa | J12: - Garantir que a informação do campo corporativo está de acordo com a info que a corporação espera receber.
B13: LT ESTR | C13: ACCNTNG_CLSSFCTN | D13: Concluído | E13: 5.7 | H13: 5 | I13: Testes de Informação LT ESTR - Comparação com 'PM' | J13: - Garantir que a informação do campo da LT-ESTR âmbito 'PM' está espelhado no âmbito 'CDG'.
B14: LT ESTR | C14: COD_SOC | D14: Concluído | E14: 5.7 | H14: 6 | I14: Controlos - Garantir Traçabilidade da tradução de chaves | J14: - Controlos sobre o desdobramento de chaves nas relações FR-MIS (N:N) - Controlos sobre o desdobramento de chaves nas relações MASTER-MIS (N:N)
B15: LT ESTR | C15: DT_RFRNC | D15: Concluído | E15: 5.7 | H15: 7 | I15: Re-Testes | J15: - Re-Teste dos campos com incidência aberta
B16: LT ESTR | C16: GRSS_CRRYNG_AMNT_INSTRMNT | D16: Concluído | E16: 5.7
B17: LT ESTR | C17: IDCMB | D17: Concluído | E17: 5.7
B18: LT ESTR | C18: IMPRMNT_STTS | D18: Concluído | E18: 5.7
B19: LT ESTR | C19: INSTRMNT_ID | D19: Concluído | E19: 5.7
B20: LT ESTR | C20: LCL_INSTMRNT_ID | D20: Concluído | E20: 5.7
B21: LT ESTR | C21: OFF_BLNC_SHT_AMNT_INSTRMNT | D21: Concluído | E21: 5.7
B22: LT ESTR | C22: PRFRMNG_STTS | D22: Concluído | E22: 5.7
B23: LT ESTR | C23: PRVSNS_OFF_BLNC_SHT | D23: Concluído | E23: 5.7
B24: LT ESTR | C24: SUBPORTFOLIO_ID | D24: Concluído | E24: 5.7
B25: LT ESTR | C25: TYP_INSTRMNT | D25: Concluído | E25: 5.7
B26: LT ESTR | C26: RWA | D26: Concluído | E26: 5.7
B27: LT ESTR | C27: COD_SOC_INTRGRP | D27: Concluído | E27: 5.7
... B33: Rentabilidade* | C33: INTRNL_TRNSFR_RT_OFF_BLNC | D33: Concluído | E33: 4.7
B34: Rentabilidade | C34: BSNSS_AREA | D34: Em Teste | E34: 1,2,3,4,6,7
B35: Rentabilidade | C35: AVRG_BLNC | D35: Em Teste | E35: 1,2,3,6,7
B36: Rentabilidade | C36: NT_LN_LSS_PRVSN | D36: Em Teste | E36: 1,2,3,6,7
B37: Rentabilidade | C37: MNGMNT_PRDCT | D37: Em Teste | E37: 1,2,3,4,6,7
B38: Rentabilidade | C38: NW_BSNSS | D38: Em Teste | E38: 1,2,3,6,7
B39: Rentabilidade | C39: GRSS_INTRST_INCM_CCRR | D39: Em Teste | E39: 1,2,3,6,7
B40: Rentabilidade | C40: NT_LN_LSS_PRVSN_OFF_BLNC | D40: Em Teste | E40: 1,2,3,6,7
B41: Rentabilidade | C41: AVRG_BLNC_OFF_BLNC | D41: Em Teste | E41: 1,2,3,6,7
B42: Rentabilidade | C42: BSNSS_AREA_CCRR ** | D42: Em Teste | E42: 1,2,3,4,6,7
B43: Rentabilidade | C43: GRSS_CMMSSN_INCM_OFF_BLNC | D43: Em Teste | E43: 1,2,3,6,7
B44: Rentabilidade | C44: GRSS_CMMSSN_EXPNS_OFF_BLNC_CCRR ** | D44: Em Teste | E44: 1,2,3,6,7
B45: Rentabilidade | C45: GRSS_CMMSSN_EXPNS_OFF_BLNC | D45: Em Teste | E45: 1,2,3,6,7
... B58: Modelo Verde | C58: SSTNBL_INDCTR | D58: Em Correção | E58: 1,2,3,6,7
B62: * Campo com Origem na Rentabilidade mas definido pela corporação
B63: ** Campo desconsiderado com a nova EF - instrmnt_id com sufixo do BSNSS_AREA e reporte de saldo com essa granularidade
