Workbook
Name _ftnref1_50: '[1]Table 39_'!#REF!
Name _ftnref1_51: '[1]Table 39_'!#REF!
Name _ftref1_50: '[1]Table 39_'!#REF!
Name Carlos: #REF!
Name DataPointIDs: #REF!
Name DataPointTooltips: #REF!
Name DBName: #REF!
Name dsa: #REF!
Name F20.04: #REF!
Name F20.04ES: #REF!
Name F20.06: #REF!
Name F20.061: #REF!
Name F20.062: #REF!
Name fdsg: '[1]Table 39_'!#REF!
Name ho: #REF!
Name JedenRadekPodSestavou: #REF!
Name JedenRadekPodSestavou_11: #REF!
Name JedenRadekPodSestavou_2: #REF!
Name JedenRadekPodSestavou_28: #REF!
Name JedenRadekVedleSestavy: #REF!
Name JedenRadekVedleSestavy_11: #REF!
Name JedenRadekVedleSestavy_2: #REF!
Name JedenRadekVedleSestavy_28: #REF!
Name MaxOblastTabulky: #REF!
Name MaxOblastTabulky_11: #REF!
Name MaxOblastTabulky_2: #REF!
Name MaxOblastTabulky_28: #REF!
Name myData: OFFSET(#REF!,0,0,MATCH("*",#REF!,-1),6)
Name myFilterSelection: #REF!
Name myPivotTable: #REF!
Name myPivotTableStart: #REF!
Name OblastDat2: #REF!
Name OblastDat2_11: #REF!
Name OblastDat2_2: #REF!
Name OblastDat2_28: #REF!
Name OblastNadpisuRadku: #REF!
Name OblastNadpisuRadku_11: #REF!
Name OblastNadpisuRadku_2: #REF!
Name OblastNadpisuRadku_28: #REF!
Name OblastNadpisuSloupcu: #REF!
Name OblastNadpisuSloupcu_11: #REF!
Name OblastNadpisuSloupcu_2: #REF!
Name OblastNadpisuSloupcu_28: #REF!
Name OLE_LINK11: 'BST individual BS Oct25'!#REF!
Name Print_Area_MI: #REF!
Name Print_Area_MI_11: #REF!
Name Print_Area_MI_2: #REF!
Name Print_Area_MI_28: #REF!
Name Print_Titles_MI: #REF!
Name Print_Titles_MI_11: #REF!
Name Print_Titles_MI_2: #REF!
Name Print_Titles_MI_28: #REF!
Name rfgf: '[1]Table 39_'!#REF!
Name Templates: #REF!

Sheet Accounting Check
B2: Accounting
B4: Bucket | C4: # | D4: Instruments | F4: 30Oct24 | G4: 15Nov24 | I4: Δ Abs | J4: Δ % | K4: Status | L4: Justificacion
B5: 1 | C5: 1 | D5: Common Equity Tier 1 | F5: =SUMIF(Inventory!AF:AF,C5,Inventory!AB:AB) -> 1566022662 | G5: =SUMIF('B0200'!Q:Q,B5,'B0200'!BX:BX) -> 1566022662 | I5: =+G5-F5 -> 0 | J5: =(G5-F5)/F5 -> 0 | K5: =IF(ABS(J5)<0.05,"OK",IF(ABS(J5)<0.1,"Warning","KO")) -> OK
B6: 2 | C6: 2 | D6: Additional Tier 1 Instruments | F6: =SUMIF(Inventory!AF:AF,C6,Inventory!AB:AB) -> 1200000000 | G6: =SUMIF('B0200'!Q:Q,B6,'B0200'!BX:BX) -> 1200000000 | I6: =+G6-F6 -> 0 | J6: =(G6-F6)/F6 -> 0 | K6: =IF(ABS(J6)<0.05,"OK",IF(ABS(J6)<0.1,"Warning","KO")) -> OK
B7: 3 | C7: 3 | D7: Subordinated debt (Tier 2) | F7: =SUMIF(Inventory!AF:AF,C7,Inventory!AB:AB) -> 2.1138497e+08 | G7: =SUMIF('B0200'!Q:Q,B7,'B0200'!BX:BX) -> 2.1176845e+08 | I7: =+G7-F7 -> 383482.05 | J7: =(G7-F7)/F7 -> 0.0018141406 | K7: =IF(ABS(J7)<0.05,"OK",IF(ABS(J7)<0.1,"Warning","KO")) -> OK | L7: Accrued interest
B8: 8 | C8: 8 | D8: Senior Non-preferred debt | F8: =SUMIF(Inventory!AF:AF,C8,Inventory!AB:AB) -> 1.112872e+09 | G8: =SUMIF('B0200'!Q:Q,B8,'B0200'!BX:BX) -> 1.1143596e+09 | I8: =+G8-F8 -> 1487567.1 | J8: =(G8-F8)/F8 -> 0.001336692 | K8: =IF(ABS(J8)<0.05,"OK",IF(ABS(J8)<0.1,"Warning","KO")) -> OK | L8: Accrued interest

Sheet Summary SRB
B2: Summary of controls
D4: Total # Controls | E4: Controls KO > 1% | H4: Comments
B5: Level 1 | D5: =COUNT('V_Level 1'!L5:L44) -> 40 | E5: =COUNTIF('V_Level 1'!N5:N44,">1%") -> 0 | F5: =E5/D5 -> 0
B6: B0200 | D6: =COUNT('V_Level 1'!L5:L43) -> 39 | E6: =COUNTIF('V_Level 1'!N5:N43,">1%") -> 0 | F6: =E6/D6 -> 0
B7: B9000 | D7: =COUNT('V_Level 1'!L44) -> 1 | E7: =COUNTIF('V_Level 1'!N44,">1%") -> 0 | F7: =E7/D7 -> 0
B8: Level 2 | D8: =COUNT('V_Level 2'!L4:L43) -> 40 | E8: =COUNTIF('V_Level 2'!N4:N43,">1%") -> 2 | F8: =E8/D8 -> 0.05
B9: B0200 | D9: =COUNT('V_Level 2'!L4:L39) -> 36 | E9: =COUNTIF('V_Level 2'!N4:N39,">1%") -> 0 | F9: =E9/D9 -> 0
B10: B9000 | D10: =COUNT('V_Level 2'!L40:L43) -> 4 | E10: =COUNTIF('V_Level 2'!N40:N43,">1%") -> 2 | F10: =E10/D10 -> 0.5 | H10: Controls not designed for Non resolution entities?

Sheet B9900
A2: Name of Legal Entity | B2: LEI of Legal Entity | C2: Country of incorporation | D2: Name of the ultimate parent entity | E2: LEI of the ultimate parent entity | F2: Name of the Resolution Entity | G2: LEI of the Resolution Entity | H2: Reporting entity type | I2: Reference date | J2: Reported currency | K2: EUR exchange rate
A3: c0010 | B3: c0020 | C3: c0030 | D3: c0040 | E3: c0041 | F3: c0050 | G3: c0051 | H3: c0060 | I3: c0070 | J3: c0080 | K3: c0090
A4: Banco Santander Totta, SA | B4: 549300URJH9VSI58CS32 | C4: PT | D4: Banco Santander, S.A. | E4: 5493006QMFDDMYWIAM13 | F4: Banco Santander, S.A. | G4: 5493006QMFDDMYWIAM13 | H4: Non-Resolution Entity | I4: 45976 | J4: EUR | K4: 1

Sheet B0200
CB1: Requirements for Non-Resolution Entities | CD1: Validations
A2: Row number | B2: Unique internal identification number | C2: Unique identification number (known to the counterparty) | D2: Type of the unique identifier (known to the counterparty) | E2: Original amount issued in EUR | F2: Original amount issued in foreign currency | G2: Contract currency | H2: Outstanding principal amount | I2: Portion of instrument or liability held by the reporting entity | J2: Accrued interest | K2: Applicable fees and charges | L2: Outstanding amount | M2: Relevant amount for Bail-in/WDC | N2: Nature of the liability | O2: Nature of the liability (if other) | P2: Structurally subordinated | Q2: Insolvency ranking | R2: Contractual subordination | S2: Bail-in cascade | T2: Date of issuance | U2: Date of the next interest payment | V2: Date of the next (partial) redemption payment | W2: Earliest redemption date | X2: Legal maturity | Y2: Governing law | Z2: Bail-in recognition clause | AA2: Zero-Coupon | AB2: Structured product | AC2: Guaranteed minimum repayment amount of the structured product | AD2: Fair value of the structured product | AE2: Not covered and not preferential deposit | AF2: Not covered but preferential deposit | AG2: Covered portion of eligible deposits | AH2: Secured/Unsecured | AI2: Amount of pledge, lien or collateral | AJ2: Amount of the uncollateralized part | AK2: Internal identification number of the pledge, lien or collateral/collateral pool | AL2: Type of the collateral | AM2: Type of the collateral (if other) | AN2: Trading method | AO2: Denomination / Nominal value per security in EUR | AP2: Denomination / Nominal value per security in original currency | AQ2: Number of securities outstanding not held by the reporting entity | AR2: Number of securities outstanding held by the reporting entity | AS2: Accrued interest per security | AT2: Fees and charges per security | AU2: Fair value per security | AV2: Principal amount of the global note in EUR | AW2: Principal amount of the global note in original currency | AX2: Nature of the global note | AY2: Current pool factor | AZ2: Central securities depository | BA2: Central securities depository (LEI) | BB2: Central securities depository name (if other) | BC2: (Mandated) paying agent | BD2: (Mandated) paying agent (LEI) | BE2: Trading venue | BF2: Trading venue (LEI) | BG2: Registrar for information about creditors/holders | BH2: Registrar for information about creditors/holders (LEI) | BI2: National Numbering Agency | BJ2: National Numbering Agency (LEI) | BK2: Common Depository | BL2: Common Depository (LEI) | BM2: Common Service Provider | BN2: Common Service Provider (LEI) | BO2: Type of own funds at individual level | BP2: Eligible amount for own funds at individual level | BQ2: Type of own funds at consolidated level | BR2: Eligible amount for own funds at consolidated level | BS2: Amount of the security interest provided | BT2: Security interest provider (Name) | BU2: Security interest provider (LEI) | BV2: Type of security interest provided by a third party | BW2: Collateral for an asset position | BX2: Carrying amount IFRS | BY2: Balance sheet item according to IFRS | BZ2: Carrying amount national GAAP | CA2: Balance sheet item at Resolution entity level according to national GAAP | CB2: Instrument/liability is issued to or bought by an existing shareholder that is not part of the same resolution group | CC2: Instrument/liability meets the requirements of Art. 21(7a) SRMR | CD2: Level 1 | DQ2: Level 2
CD3: =COUNTIF(CD5:CD1048576,"KO") -> 0 | CE3: =COUNTIF(CE5:CE1048576,"KO") -> 0 | CF3: =COUNTIF(CF5:CF1048576,"KO") -> 0 | CG3: =COUNTIF(CG5:CG1048576,"KO") -> 0 | CH3: =COUNTIF(CH5:CH1048576,"KO") -> 0 | CI3: =COUNTIF(CI5:CI1048576,"KO") -> 0 | CJ3: =COUNTIF(CJ5:CJ1048576,"KO") -> 0 | CK3: =COUNTIF(CK5:CK1048576,"KO") -> 0 | ... EZ3: =COUNTIF(EZ5:EZ1048576,"KO") -> 0
A4: c0010 | B4: c0020 | C4: c0030 | D4: c0040 | E4: c0050 | F4: c0060 | G4: c0070 | H4: c0080 | I4: c0090 | J4: c0100 | K4: c0110 | L4: c0120 | M4: c0130 | N4: c0140 | O4: c0141 | P4: c0150 | Q4: c0160 | R4: c0161 | S4: c0162 | T4: c0170 | U4: c0180 | V4: c0190 | W4: c0200 | X4: c0210 | Y4: c0220 | Z4: c0230 | AA4: c0240 | AB4: c0250 | AC4: c0260 | AD4: c0270 | AE4: c0280 | AF4: c0290 | AG4: c0300 | AH4: c0310 | AI4: c0320 | AJ4: c0330 | AK4: c0340 | AL4: c0350 | AM4: c0351 | AN4: c0360 | AO4: c0370 | AP4: c0380 | AQ4: c0390 | AR4: c0391 | AS4: c0400 | AT4: c0410 | AU4: c0420 | AV4: c0430 | AW4: c0431 | AX4: c0440 | AY4: c0450 | AZ4: c0460 | BA4: c0461 | BB4: c0462 | BC4: c0470 | BD4: c0471 | BE4: c0480 | BF4: c0481 | BG4: c0490 | BH4: c0491 | BI4: c0500 | BJ4: c0501 | BK4: c0510 | BL4: c0511 | BM4: c0520 | BN4: c0521 | BO4: c0530 | BP4: c0540 | BQ4: c0550 | BR4: c0560 | BS4: c0570 | BT4: c0580 | BU4: c0581 | BV4: c0590 | BW4: c0600 | BX4: c0610 | BY4: c0620 | BZ4: c0630 | CA4: c0640 | CB4: c5000 | CC4: c5010 | CD4: v_1_0001 | CE4: v_1_0002 | CF4: v_1_0003 | CG4: v_1_0004 | CH4: v_1_0005 | CI4: v_1_0006 | CJ4: v_1_0007 | CK4: v_1_0008 | CL4: v_1_0009 | CM4: v_1_0010 | CN4: v_1_0011 | CO4: v_1_0012 | CP4: v_1_0013 | CQ4: v_1_0014 | CR4: v_1_0015 | CS4: v_1_0016 | CT4: v_1_0017 | CU4: v_1_0018 | CV4: v_1_0019 | CW4: v_1_0020 | CX4: v_1_0021 | CY4: v_1_0022 | CZ4: v_1_0023 | DA4: v_1_0024 | DB4: v_1_0025 | DC4: v_1_0026 | DD4: v_1_0027 | DE4: v_1_0028 | DF4: v_1_0029 | DG4: v_1_0030 | DH4: v_1_0031 | DI4: v_1_0032 | DJ4: v_1_0033 | DK4: v_1_0034 | DL4: v_1_0035 | DM4: v_1_0036 | DN4: v_1_0037 | DO4: v_1_0038 | DP4: v_1_0039 | DQ4: v_2_0001 | DR4: v_2_0003 | DS4: v_2_0004 | DT4: v_2_0005 | DU4: v_2_0006 | DV4: v_2_0007 | DW4: v_2_0008 | DX4: v_2_0009 | DY4: v_2_0011 | DZ4: v_2_0012 | EA4: v_2_0013 | EB4: v_2_0014 | EC4: v_2_0015 | ED4: v_2_0016 | EE4: v_2_0017 | EF4: v_2_0018 | EG4: v_2_0019 | EH4: v_2_0020 | EI4: v_2_0021 | EJ4: v_2_0022 | EK4: v_2_0023 | EL4: v_2_0024 | EM4: v_2_0025 | EN4: v_2_0026 | EO4: v_2_0027 | EP4: v_2_0028 | EQ4: v_2_0029 | ER4: v_2_0030 | ES4: v_2_0031 | ET4: v_2_0032 | EU4: v_2_0033 | EV4: v_2_0034 | EW4: v_2_0035 | EX4: v_2_0036 | EY4: v_2_0037 | EZ4: v_2_0038
A5: 1 | B5: 31641600000000000PTBSREOM0028000 | C5: PTBSREOM0028 | D5: ISIN | E5: 7599000 | F5: 999999999999999 | G5: EUR | H5: 7599000 | I5: 0 | J5: 62457.537 | K5: 0 | L5: 7661457.5 | M5: 7661457.5 | N5: Registered Bond | O5: Not applicable | P5: Not applicable | Q5: 3 | R5: 999999999999999 | S5: 3 | T5: 2016-09-28 | U5: 2026-10-06 | V5: 2026-10-06 | W5: 2026-10-06 | X5: 2026-10-06 | Y5: PT | Z5: Yes, supported by Legal Opinion | AA5: No ZCB | AB5: Non-structured/Vanilla | AC5: 999999999999999 | AD5: 999999999999999 | AE5: FALSE | AF5: FALSE | AG5: 999999999999999 | AH5: Unsecured | AI5: 999999999999999 | AJ5: 999999999999999 | AK5: Not applicable | AL5: Not applicable | AM5: Not applicable | AN5: Nominal | AO5: 1000 | AP5: 1000 | AQ5: 7599 | AR5: 0 | AS5: =+B02.00[[#This Row],[c0100]]/B02.00[[#This Row],[c0390]] -> 8.2191784 | AT5: 0 | AU5: 999999999999999 | AV5: 999999999999999 | AW5: 999999999999999 | AX5: Not applicable | AY5: -10000 | AZ5: INTERBOLSA_PT | BA5: 529900LG70TCAGWCXT47 | BB5: Not applicable | BC5: BANCO SANTANDER TOTTA S,A, | BD5: 549300URJH9VSI58CS32 | BE5: Not applicable | BF5: Not applicable | BG5: INTERBOLSA_PT | BH5: 529900LG70TCAGWCXT47 | BI5: INTERBOLSA_PT | BJ5: 529900LG70TCAGWCXT47 | BK5: Not applicable | BL5: Not applicable | BM5: Not applicable | BN5: Not applicable | BO5: Fully Compliant T2 | BP5: 382215.35 | BQ5: Fully Compliant T2 | BR5: 382215.35 | BS5: 0 | BT5: Not applicable | BU5: Not applicable | BV5: Not applicable | BW5: FALSE | BX5: 7661457.5 | BY5: 110 Financial liabilities at amortized cost | BZ5: 999999999999999 | CA5: Not applicable | CB5: FALSE | CC5: TRUE | CD5: =IF(B02.00[[#This Row],[c0010]]="","KO","OK") -> OK | CE5: =IF(B02.00[[#This Row],[c0030]]="","KO","OK") -> OK | CF5: =IF(B02.00[[#This Row],[c0040]]="","KO","OK") -> OK | CG5: =IF(B02.00[[#This Row],[c0070]]="","KO","OK") -> OK | CH5: =IF(OR(B02.00[[#This Row],[c0250]]= "Non-Structured/Vanilla",B02.00[[#This Row],[c0250]]="Other non-standard terms"),(IF(B02.00[[#This Row],[c0080]]="","KO","OK")),"OK") -> OK | CI5: =IF(OR(B02.00[[#This Row],[c0250]]= "Structured",B02.00[[#This Row],[c0250]]="Only structured coupon"),(IF(B02.00[[#This Row],[c0080]]="","KO","OK")),"OK") -> OK | CJ5: =IF(B02.00[[#This Row],[c0040]]="ISIN",(IF(B02.00[[#This Row],[c0090]]="","KO","OK")),"OK") -> OK | CK5: =IF(AND(OR(B02.00[[#This Row],[c0250]]="Non-Structured/Vanilla",B02.00[[#This Row],[c0250]]="Other non-standard terms"),B02.00[[#This Row],[c0240]]<>"ZCB issued at discount"),(IF(B02.00[[#This Row],[c0100]]="","KO","OK")),"OK") -> OK | CL5: =IF(OR(B02.00[[#This Row],[c0250]]<> "Non-Structured/Vanilla",B02.00[[#This Row],[c0460]]<>"Other non-standard terms"),(IF(B02.00[[#This Row],[c0100]]="","KO","OK")),"OK") -> OK | CM5: =IF(OR(B02.00[[#This Row],[c0250]]= "Non-Structured/Vanilla",B02.00[[#This Row],[c0460]]="Other non-standard terms"),(IF(B02.00[[#This Row],[c0120]]="","KO","OK")),"OK") -> OK | CN5: =IF(OR(B02.00[[#This Row],[c0250]]<> "Structured",B02.00[[#This Row],[c0250]]<>"Only structured coupon"),(IF(B02.00[[#This Row],[c0120]]="","KO","OK")),"OK") -> OK | CO5: =IF(B02.00[[#This Row],[c0130]]="","KO","OK") -> OK | CP5: =IF(B02.00[[#This Row],[c0140]]="","KO","OK") -> OK | CQ5: =IF(B02.00[[#This Row],[c0140]]="Other",(IF(B02.00[[#This Row],[c0141]]="","KO","OK")),"OK") -> OK | CR5: =IF(B02.00[[#This Row],[c0160]]="","KO","OK") -> OK | CS5: =IF(B02.00[[#This Row],[c0162]]="","KO","OK") -> OK | CT5: =IF(AND(OR(B02.00[[#This Row],[c0250]]= "Non-Structured/Vanilla",B02.00[[#This Row],[c0250]]="Other non-standard terms"),B02.00[[#This Row],[c0240]]<>"ZCB issued at discount"),(IF(B02.00[[#This Row],[c0180]]="","KO","OK")),"OK") -> OK | CU5: =IF(AND(B02.00[[#This Row],[c0250]]<> "Structured",B02.00[[#This Row],[c0250]]<>"Only structured coupon"),(IF(B02.00[[#This Row],[c0180]]="","KO","OK")),"OK") -> OK | CV5: =IF(B02.00[[#This Row],[c0200]]="","KO","OK") -> OK | CW5: =IF(B02.00[[#This Row],[c0140]]<>"Cash account/saving account",(IF(B02.00[[#This Row],[c0210]]="","KO","OK")),"OK") -> OK | CX5: =IF(B02.00[[#This Row],[c0220]]="","KO","OK") -> OK | CY5: =IF(B02.00[[#This Row],[c0250]]="","KO","OK") -> OK | CZ5: =IF(OR(B02.00[[#This Row],[c0250]]="Structured",B02.00[[#This Row],[c0250]]="Only structured coupon"),(IF(B02.00[[#This Row],[c0260]]="","KO","OK")),"OK") -> OK | DA5: =IF(OR(B02.00[[#This Row],[c0250]]="Structured",B02.00[[#This Row],[c0250]]="Only structured coupon"),(IF(B02.00[[#This Row],[c0270]]="","KO","OK")),"OK") -> OK | DB5: =IF(OR(B02.00[[#This Row],[c0280]]="TRUE",B02.00[[#This Row],[c0290]]="TRUE"),(IF(B02.00[[#This Row],[c0300]]="","KO","OK")),"OK") -> OK | DC5: =IF(B02.00[[#This Row],[c0310]]="","KO","OK") -> OK | DD5: =IF(B02.00[[#This Row],[c0310]]="Secured",(IF(B02.00[[#This Row],[c0320]]="","KO","OK")),"OK") -> OK | DE5: =IF(B02.00[[#This Row],[c0310]]="Secured",(IF(B02.00[[#This Row],[c0330]]="","KO","OK")),"OK") -> OK | DF5: =IF(B02.00[[#This Row],[c0310]]="Secured",(IF(B02.00[[#This Row],[c0350]]="","KO","OK")),"OK") -> OK | DG5: =IF(B02.00[[#This Row],[c0350]]="Other",(IF(B02.00[[#This Row],[c0351]]="","KO","OK")),"OK") -> OK | DH5: =IF(AND(B02.00[[#This Row],[c0040]]="ISIN",B02.00[[#This Row],[c0360]]="Nominal "),(IF(B02.00[[#This Row],[c0370]]="","KO","OK")),"OK") -> OK | DI5: =IF(AND(B02.00[[#This Row],[c0040]]="ISIN",B02.00[[#This Row],[c0360]]="Unit "),(IF(B02.00[[#This Row],[c0370]]="","KO","OK")),"OK") -> OK | DJ5: =IF(B02.00[[#This Row],[c0040]]="ISIN",(IF(B02.00[[#This Row],[c0390]]="","KO","OK")),"OK") -> OK | DK5: =IF(B02.00[[#This Row],[c0040]]="ISIN",(IF(B02.00[[#This Row],[c0391]]="","KO","OK")),"OK") -> OK | DL5: =IF(AND(B02.00[[#This Row],[c0040]]="ISIN",OR(B02.00[[#This Row],[c0250]]= "Non-Structured/Vanilla",B02.00[[#This Row],[c0250]]="Other non-standard terms"),B02.00[[#This Row],[c0240]]<>"ZCB issued at discount"),(IF(B02.00[[#This Row],[c0400]]="","KO","OK")),"OK") -> OK | DM5: =IF(AND(B02.00[[#This Row],[c0040]]="ISIN",AND(B02.00[[#This Row],[c0250]]<>"Structured",B02.00[[#This Row],[c0250]]<>"Only structured coupon")),(IF(B02.00[[#This Row],[c0400]]="","KO","OK")),"OK") -> OK | DN5: =IF(B02.00[[#This Row],[c0610]]="","KO","OK") -> OK | DO5: =IF('B9900'!$H$4="Non-Resolution Entity",(IF(B02.00[[#This Row],[c5000]]="","KO","OK")),"OK") -> OK | DP5: =IF('B9900'!$H$4="Non-Resolution Entity",(IF(B02.00[[#This Row],[c5010]]="","KO","OK")),"OK") -> OK | DQ5: =IF(B02.00[[#This Row],[c0040]]="ISIN",(IF(AND(LEN(B02.00[[#This Row],[c0030]]=12),NOT(ISNUMBER(LEFT(B02.00[[#This Row],[c0030]],2)))),"OK","KO")),"OK") -> OK | DR5: =IF(AND(B02.00[[#This Row],[c0020]]<>"NCNP",B02.00[[#This Row],[c0020]]<>"NCBP"),(IF(AND(LEN(B02.00[[#This Row],[c0070]])=3,NOT(ISERROR(MATCH(UPPER(B02.00[[#This Row],[c0070]]),Tabelle1[Alphabetic Code],0)))),"OK","KO")),"OK") -> OK | DS5: =IF(B02.00[[#This Row],[c0080]]>0,"OK","KO") -> OK | DT5: =IF(B02.00[[#This Row],[c0040]]="ISIN",(IF(B02.00[[#This Row],[c0090]]>=0,"OK","KO")),"OK") -> OK | DU5: =IF(B02.00[[#This Row],[c0100]]>=0,"OK","KO") -> OK | DV5: =IF(B02.00[[#This Row],[c0110]]>=0,"OK","KO") -> OK | DW5: =IF(B02.00[[#This Row],[c0120]]>=0,"OK","KO") -> OK | DX5: =IF(B02.00[[#This Row],[c0120]]=(H5+J5+K5),"OK","KO") -> OK | DY5: =IF(OR(B02.00[[#This Row],[c0250]]="Non-structured /Vanilla",B02.00[[#This Row],[c0250]]="Other non-standard terms"),(IF(B02.00[[#This Row],[c0130]]=MAX(0,B02.00[[#This Row],[c0120]],B02.00[[#This Row],[c0300]],B02.00[[#This Row],[c0320]]),"OK","KO")),"OK") -> OK | DZ5: =IF(OR(B02.00[[#This Row],[c0250]]="Structured",B02.00[[#This Row],[c0250]]="Only structured coupon"),(IF(OR(B02.00[[#This Row],[c0130]]=MAX(0,B02.00[[#This Row],[c0270]],B02.00[[#This Row],[c0300]],B02.00[[#This Row],[c0320]]),B02.00[[#This Row],[c0130]]=MAX(0,B02.00[[#This Row],[c0120]],B02.00[[#This Row],[c0300]],B02.00[[#This Row],[c0320]])),"OK","KO")),"OK") -> OK | EA5: =IF(OR(B02.00[[#This Row],[c0140]]="Registered Bond",B02.00[[#This Row],[c0140]]="Bearrer Bond",B02.00[[#This Row],[c0140]]="Borrower Note Loan",B02.00[[#This Row],[c0140]]="Certificate of Deposit / Commercial Paper",B02.00[[#This Row],[c0140]]="Title of ownership",B02.00[[#This Row],[c0140]]="Cash account/saving account",B02.00[[#This Row],[c0140]]="Term deposit",B02.00[[#This Row],[c0140]]="Loan",B02.00[[#This Row],[c0140]]="Bill of exchange",B02.00[[#This Row],[c0140]]="Other"),"OK","KO") -> OK | EB5: =IF(B02.00[[#This Row],[c0160]]>=1,"OK","KO") -> OK | EC5: =IF(AND(B02.00[[#This Row],[c0020]]<>"NCNP",B02.00[[#This Row],[c0020]]<>"NCBP"),(IF(B02.00[[#This Row],[c0170]]>DATE(1900,1,1),"OK","KO")),"OK") -> OK | ED5: =IF(AND(OR(B02.00[[#This Row],[c0190]]<>"",B02.00[[#This Row],[c0200]]<>""),AND(B02.00[[#This Row],[c0020]]<>"NCNP",B02.00[[#This Row],[c0020]]<>"NCBP")),(IF(AND(B02.00[[#This Row],[c0170]]<B02.00[[#This Row],[c0190]],B02.00[[#This Row],[c0170]]<B02.00[[#This Row],[c0200]]),"OK","KO")),"OK") -> OK | EE5: =IF(AND(B02.00[[#This Row],[c0020]]<>"NCNP",B02.00[[#This Row],[c0020]]<>"NCBP"),IF(B02.00[[#This Row],[c0180]]="","KO",IF(B02.00[[#This Row],[c0180]]>DATE(1900,1,1),"OK","KO")),"OK") -> OK | EF5: =IF(AND('B9900'!$I$4<>"",B02.00[[#This Row],[c0020]]<>"NCNP",B02.00[[#This Row],[c0020]]<>"NCBP"),IF(B02.00[[#This Row],[c0180]]="","KO",IF(B02.00[[#This Row],[c0180]]>'B9900'!$I$4,"OK","KO")),"OK") -> OK | EG5: =IF(AND(B02.00[[#This Row],[c0020]]<>"NCNP",B02.00[[#This Row],[c0020]]<>"NCBP"),(IF(B02.00[[#This Row],[c0200]]>DATE(1900,1,1),"OK","KO")),"OK") -> OK | EH5: =IF(AND('B9900'!$I$4<>"",AND(B02.00[[#This Row],[c0020]]<>"NCNP",B02.00[[#This Row],[c0020]]<>"NCBP")),(IF(B02.00[[#This Row],[c0200]]>'B9900'!$I$4,"OK","KO")),"OK") -> OK | EI5: =IF(AND(B02.00[[#This Row],[c0020]]<>"NCNP",B02.00[[#This Row],[c0020]]<>"NCBP"),(IF(B02.00[[#This Row],[c0210]]>DATE(1900,1,1),"OK","KO")),"OK") -> OK | EJ5: =IF(AND('B9900'!$I$4<>"",AND(B02.00[[#This Row],[c0020]]<>"NCNP",B02.00[[#This Row],[c0020]]<>"NCBP")),(IF(B02.00[[#This Row],[c0210]]>'B9900'!$I$4,"OK","KO")),"OK") -> OK | EK5: =IF(AND(B02.00[[#This Row],[c0020]]<>"NCNP",B02.00[[#This Row],[c0020]]<>"NCBP"),(IF(OR(NOT(ISERROR(MATCH(B02.00[[#This Row],[c0220]],'ISO 3166'!B:B,0))),NOT(ISERROR(MATCH(B02.00[[#This Row],[c0220]],'ISO 3166'!E:E,0)))),"OK","KO")),"OK") -> OK | EL5: =IF(AND(B02.00[[#This Row],[c0020]]<>"NCNP",B02.00[[#This Row],[c0020]]<>"NCBP"),(IF(OR(B02.00[[#This Row],[c0230]]="Yes, supported by Legal Opinion",B02.00[[#This Row],[c0230]]="Yes, not supported by Legal Opinion",B02.00[[#This Row],[c0230]]="No",B02.00[[#This Row],[c0230]]="Not applicable",B02.00[[#This Row],[c0230]]="Aggregated"),"OK","KO")),"OK") -> OK | EM5: =IF(OR(B02.00[[#This Row],[c0250]]="Non-structured/Vanilla",B02.00[[#This Row],[c0250]]="Structured",B02.00[[#This Row],[c0250]]="Other non-standard terms",B02.00[[#This Row],[c0250]]="Only structured coupon",B02.00[[#This Row],[c0250]]="Aggregated"),"OK","KO") -> OK | EN5: =IF(OR(B02.00[[#This Row],[c0310]]="Secured",B02.00[[#This Row],[c0310]]="Unsecured"),"OK","KO") -> OK | EO5: =IF(AND(B02.00[[#This Row],[c0310]]="Secured",OR(B02.00[[#This Row],[c0250]]="Non-structured/Vanilla",B02.00[[#This Row],[c0250]]="Other non-standard terms"),B02.00[[#This Row],[c0240]]<>"ZCB issued at discount"),(IF(B02.00[[#This Row],[c0330]]=MAX(0,B02.00[[#This Row],[c0120]],B02.00[[#This Row],[c0320]]),"OK","KO")),"OK") -> OK | EP5: =IF(AND(B02.00[[#This Row],[c0310]]="Secured",OR(B02.00[[#This Row],[c0250]]="Structured",B02.00[[#This Row],[c0250]]="Only structured coupon")),(IF(OR(B02.00[[#This Row],[c0330]]=MAX(0,B02.00[[#This Row],[c0270]],B02.00[[#This Row],[c0320]]),B02.00[[#This Row],[c0330]]=MAX(0,B02.00[[#This Row],[c0120]],B02.00[[#This Row],[c0320]])),"OK","KO")),"OK") -> OK | EQ5: =IF(OR(B02.00[[#This Row],[c0350]]="Real estate",B02.00[[#This Row],[c0350]]="Ships",B02.00[[#This Row],[c0350]]="Aircraft",B02.00[[#This Row],[c0350]]="Financial",B02.00[[#This Row],[c0350]]="Other",B02.00[[#This Row],[c0350]]="Not applicable"),"OK","KO") -> OK | ER5: =IF(B02.00[[#This Row],[c0310]]="Unsecured",(IF(B02.00[[#This Row],[c0350]]="Not applicable","OK","KO")),"OK") -> OK | ES5: =IF(OR(B02.00[[#This Row],[c0440]]="NGN",B02.00[[#This Row],[c0440]]="CGN",B02.00[[#This Row],[c0440]]="Not applicable"),"OK","KO") -> OK | ET5: =IF(OR(B02.00[[#This Row],[c0530]]="T2 in phase-out",B02.00[[#This Row],[c0530]]="Grandfathered T2",B02.00[[#This Row],[c0530]]="Fully Compliant T2",B02.00[[#This Row],[c0530]]="Partially (A)T1 and T2",B02.00[[#This Row],[c0530]]="Grandfathered AT1",B02.00[[#This Row],[c0530]]="Fully Compliant AT1",B02.00[[#This Row],[c0530]]="CET1",B02.00[[#This Row],[c0530]]="No"),"OK","KO") -> OK | EU5: =IF(B02.00[[#This Row],[c0540]] ="","KO",IF(B02.00[[#This Row],[c0540]]>=0,"OK","KO")) -> OK | EV5: =IF(OR(B02.00[[#This Row],[c0550]]="T2 in phase-out",B02.00[[#This Row],[c0550]]="Grandfathered T2",B02.00[[#This Row],[c0550]]="Fully Compliant T2",B02.00[[#This Row],[c0550]]="Partially (A)T1 and T2",B02.00[[#This Row],[c0550]]="Grandfathered AT1",B02.00[[#This Row],[c0550]]="Fully Compliant AT1",B02.00[[#This Row],[c0550]]="CET1",B02.00[[#This Row],[c0550]]="No"),"OK","KO") -> OK | EW5: =IF(B02.00[[#This Row],[c0560]]="","KO",IF(B02.00[[#This Row],[c0560]]>=0,"OK","KO")) -> OK | EX5: =IF(OR(B02.00[[#This Row],[c0590]]="Lien",B02.00[[#This Row],[c0590]]="Guarantee",B02.00[[#This Row],[c0590]]="Surety",B02.00[[#This Row],[c0590]]="Guarantee obligation",B02.00[[#This Row],[c0590]]="Other",B02.00[[#This Row],[c0590]]="Not applicable",B02.00[[#This Row],[c0590]]="Aggregated"),"OK","KO") -> OK | EY5: =IF(B02.00[[#This Row],[c0610]]="","KO",IF(B02.00[[#This Row],[c0610]]>=0,"OK","KO")) -> OK | EZ5: =IF(OR(B02.00[[#This Row],[c0620]]="010 Financial liabilities held for trading",B02.00[[#This Row],[c0620]]="070 Financial liabilities at fair value through profit or loss",B02.00[[#This Row],[c0620]]="110 Financial liabilities at amortized cost",B02.00[[#This Row],[c0620]]="280 Other liabilities",B02.00[[#This Row],[c0620]]="300 Total equity",),"OK","KO") -> OK
A6: 2 | B6: 31641600000000000PTSTOEOM0021000 | C6: PTSTOEOM0021 | D6: ISIN | E6: 600000000 | F6: 999999999999999 | G6: EUR | H6: 600000000 | I6: 0 | J6: 8348547.9 | K6: 0 | L6: 6.0834855e+08 | M6: 6.0834855e+08 | N6: Registered Bond | O6: Not applicable | P6: Not applicable | Q6: 8 | R6: 999999999999999 | S6: 8 | T6: 2022-06-01 | U6: 2026-06-03 | V6: 2027-06-03 | W6: 2026-06-03 | X6: 2027-06-03 | Y6: PT | Z6: Yes, supported by Legal Opinion | AA6: No ZCB | AB6: Non-structured/Vanilla | AC6: 999999999999999 | AD6: 999999999999999 | AE6: FALSE | AF6: FALSE | AG6: 999999999999999 | AH6: Unsecured | AI6: 999999999999999 | AJ6: 999999999999999 | AK6: Not applicable | AL6: Not applicable | AM6: Not applicable | AN6: Nominal | AO6: 100000 | AP6: 100000 | AQ6: 6000 | AR6: 0 | AS6: =+B02.00[[#This Row],[c0100]]/B02.00[[#This Row],[c0390]] -> 1391.4247 | AT6: 0 | AU6: 999999999999999 | AV6: 999999999999999 | AW6: 999999999999999 | AX6: Not applicable | AY6: -10000 | AZ6: INTERBOLSA_PT | BA6: 529900LG70TCAGWCXT47 | BB6: Not applicable | BC6: BANCO SANTANDER TOTTA S,A, | BD6: 549300URJH9VSI58CS32 | BE6: Not applicable | BF6: Not applicable | BG6: INTERBOLSA_PT | BH6: 529900LG70TCAGWCXT47 | BI6: INTERBOLSA_PT | BJ6: 529900LG70TCAGWCXT47 | BK6: Not applicable | BL6: Not applicable | BM6: Not applicable | BN6: Not applicable | BO6: No | BP6: 0 | BQ6: No | BR6: 0 | BS6: 0 | BT6: Not applicable | BU6: Not applicable | BV6: Not applicable | BW6: FALSE | BX6: 6.0834855e+08 | BY6: 110 Financial liabilities at amortized cost | BZ6: 999999999999999 | CA6: Not applicable | CB6: FALSE | CC6: TRUE | CD6: =IF(B02.00[[#This Row],[c0010]]="","KO","OK") -> OK | CE6: =IF(B02.00[[#This Row],[c0030]]="","KO","OK") -> OK | CF6: =IF(B02.00[[#This Row],[c0040]]="","KO","OK") -> OK | CG6: =IF(B02.00[[#This Row],[c0070]]="","KO","OK") -> OK | CH6: =IF(OR(B02.00[[#This Row],[c0250]]= "Non-Structured/Vanilla",B02.00[[#This Row],[c0250]]="Other non-standard terms"),(IF(B02.00[[#This Row],[c0080]]="","KO","OK")),"OK") -> OK | CI6: =IF(OR(B02.00[[#This Row],[c0250]]= "Structured",B02.00[[#This Row],[c0250]]="Only structured coupon"),(IF(B02.00[[#This Row],[c0080]]="","KO","OK")),"OK") -> OK | CJ6: =IF(B02.00[[#This Row],[c0040]]="ISIN",(IF(B02.00[[#This Row],[c0090]]="","KO","OK")),"OK") -> OK | CK6: =IF(AND(OR(B02.00[[#This Row],[c0250]]="Non-Structured/Vanilla",B02.00[[#This Row],[c0250]]="Other non-standard terms"),B02.00[[#This Row],[c0240]]<>"ZCB issued at discount"),(IF(B02.00[[#This Row],[c0100]]="","KO","OK")),"OK") -> OK | CL6: =IF(OR(B02.00[[#This Row],[c0250]]<> "Non-Structured/Vanilla",B02.00[[#This Row],[c0460]]<>"Other non-standard terms"),IF(B02.00[[#This Row],[c0100]]="","KO","OK")) -> OK | CM6: =IF(OR(B02.00[[#This Row],[c0250]]= "Non-Structured/Vanilla",B02.00[[#This Row],[c0460]]="Other non-standard terms"),(IF(B02.00[[#This Row],[c0120]]="","KO","OK")),"OK") -> OK | CN6: =IF(OR(B02.00[[#This Row],[c0250]]<> "Structured",B02.00[[#This Row],[c0250]]<>"Only structured coupon"),(IF(B02.00[[#This Row],[c0120]]="","KO","OK")),"OK") -> OK | CO6: =IF(B02.00[[#This Row],[c0130]]="","KO","OK") -> OK | CP6: =IF(B02.00[[#This Row],[c0140]]="","KO","OK") -> OK | CQ6: =IF(B02.00[[#This Row],[c0140]]="Other",(IF(B02.00[[#This Row],[c0141]]="","KO","OK")),"OK") -> OK | CR6: =IF(B02.00[[#This Row],[c0160]]="","KO","OK") -> OK | CS6: =IF(B02.00[[#This Row],[c0162]]="","KO","OK") -> OK | CT6: =IF(AND(OR(B02.00[[#This Row],[c0250]]= "Non-Structured/Vanilla",B02.00[[#This Row],[c0250]]="Other non-standard terms"),B02.00[[#This Row],[c0240]]<>"ZCB issued at discount"),(IF(B02.00[[#This Row],[c0180]]="","KO","OK")),"OK") -> OK | CU6: =IF(AND(B02.00[[#This Row],[c0250]]<> "Structured",B02.00[[#This Row],[c0250]]<>"Only structured coupon"),(IF(B02.00[[#This Row],[c0180]]="","KO","OK")),"OK") -> OK | CV6: =IF(B02.00[[#This Row],[c0200]]="","KO","OK") -> OK | CW6: =IF(B02.00[[#This Row],[c0140]]<>"Cash account/saving account",(IF(B02.00[[#This Row],[c0210]]="","KO","OK")),"OK") -> OK | CX6: =IF(B02.00[[#This Row],[c0220]]="","KO","OK") -> OK | CY6: =IF(B02.00[[#This Row],[c0250]]="","KO","OK") -> OK | CZ6: =IF(OR(B02.00[[#This Row],[c0250]]="Structured",B02.00[[#This Row],[c0250]]="Only structured coupon"),(IF(B02.00[[#This Row],[c0260]]="","KO","OK")),"OK") -> OK | DA6: =IF(OR(B02.00[[#This Row],[c0250]]="Structured",B02.00[[#This Row],[c0250]]="Only structured coupon"),(IF(B02.00[[#This Row],[c0270]]="","KO","OK")),"OK") -> OK | DB6: =IF(OR(B02.00[[#This Row],[c0280]]="TRUE",B02.00[[#This Row],[c0290]]="TRUE"),(IF(B02.00[[#This Row],[c0300]]="","KO","OK")),"OK") -> OK | DC6: =IF(B02.00[[#This Row],[c0310]]="","KO","OK") -> OK | DD6: =IF(B02.00[[#This Row],[c0310]]="Secured",(IF(B02.00[[#This Row],[c0320]]="","KO","OK")),"OK") -> OK | DE6: =IF(B02.00[[#This Row],[c0310]]="Secured",(IF(B02.00[[#This Row],[c0330]]="","KO","OK")),"OK") -> OK | DF6: =IF(B02.00[[#This Row],[c0310]]="Secured",(IF(B02.00[[#This Row],[c0350]]="","KO","OK")),"OK") -> OK | DG6: =IF(B02.00[[#This Row],[c0350]]="Other",(IF(B02.00[[#This Row],[c0351]]="","KO","OK")),"OK") -> OK | DH6: =IF(AND(B02.00[[#This Row],[c0040]]="ISIN",B02.00[[#This Row],[c0360]]="Nominal "),(IF(B02.00[[#This Row],[c0370]]="","KO","OK")),"OK") -> OK | DI6: =IF(AND(B02.00[[#This Row],[c0040]]="ISIN",B02.00[[#This Row],[c0360]]="Unit "),(IF(B02.00[[#This Row],[c0370]]="","KO","OK")),"OK") -> OK | DJ6: =IF(B02.00[[#This Row],[c0040]]="ISIN",(IF(B02.00[[#This Row],[c0390]]="","KO","OK")),"OK") -> OK | DK6: =IF(B02.00[[#This Row],[c0040]]="ISIN",(IF(B02.00[[#This Row],[c0391]]="","KO","OK")),"OK") -> OK | DL6: =IF(AND(B02.00[[#This Row],[c0040]]="ISIN",OR(B02.00[[#This Row],[c0250]]= "Non-Structured/Vanilla",B02.00[[#This Row],[c0250]]="Other non-standard terms"),B02.00[[#This Row],[c0240]]<>"ZCB issued at discount"),(IF(B02.00[[#This Row],[c0400]]="","KO","OK")),"OK") -> OK | DM6: =IF(AND(B02.00[[#This Row],[c0040]]="ISIN",AND(B02.00[[#This Row],[c0250]]<>"Structured",B02.00[[#This Row],[c0250]]<>"Only structured coupon")),(IF(B02.00[[#This Row],[c0400]]="","KO","OK")),"OK") -> OK | DN6: =IF(B02.00[[#This Row],[c0610]]="","KO","OK") -> OK | DO6: =IF('B9900'!$H$4="Non-Resolution Entity",(IF(B02.00[[#This Row],[c5000]]="","KO","OK")),"OK") -> OK | DP6: =IF('B9900'!$H$4="Non-Resolution Entity",(IF(B02.00[[#This Row],[c5010]]="","KO","OK")),"OK") -> OK | DQ6: =IF(B02.00[[#This Row],[c0040]]="ISIN",(IF(AND(LEN(B02.00[[#This Row],[c0030]]=12),NOT(ISNUMBER(LEFT(B02.00[[#This Row],[c0030]],2)))),"OK","KO")),"OK") -> OK | DR6: =IF(AND(B02.00[[#This Row],[c0020]]<>"NCNP",B02.00[[#This Row],[c0020]]<>"NCBP"),(IF(AND(LEN(B02.00[[#This Row],[c0070]])=3,NOT(ISERROR(MATCH(UPPER(B02.00[[#This Row],[c0070]]),Tabelle1[Alphabetic Code],0)))),"OK","KO")),"OK") -> OK | DS6: =IF(B02.00[[#This Row],[c0080]]>0,"OK","KO") -> OK | DT6: =IF(B02.00[[#This Row],[c0040]]="ISIN",(IF(B02.00[[#This Row],[c0090]]>=0,"OK","KO")),"OK") -> OK | DU6: =IF(B02.00[[#This Row],[c0100]]>=0,"OK","KO") -> OK | DV6: =IF(B02.00[[#This Row],[c0110]]>=0,"OK","KO") -> OK | DW6: =IF(B02.00[[#This Row],[c0120]]>=0,"OK","KO") -> OK | DX6: =IF(B02.00[[#This Row],[c0120]]=(H6+J6+K6),"OK","KO") -> OK | DY6: =IF(OR(B02.00[[#This Row],[c0250]]="Non-structured /Vanilla",B02.00[[#This Row],[c0250]]="Other non-standard terms"),(IF(B02.00[[#This Row],[c0130]]=MAX(0,B02.00[[#This Row],[c0120]],B02.00[[#This Row],[c0300]],B02.00[[#This Row],[c0320]]),"OK","KO")),"OK") -> OK | DZ6: =IF(OR(B02.00[[#This Row],[c0250]]="Structured",B02.00[[#This Row],[c0250]]="Only structured coupon"),(IF(OR(B02.00[[#This Row],[c0130]]=MAX(0,B02.00[[#This Row],[c0270]],B02.00[[#This Row],[c0300]],B02.00[[#This Row],[c0320]]),B02.00[[#This Row],[c0130]]=MAX(0,B02.00[[#This Row],[c0120]],B02.00[[#This Row],[c0300]],B02.00[[#This Row],[c0320]])),"OK","KO")),"OK") -> OK | EA6: =IF(OR(B02.00[[#This Row],[c0140]]="Registered Bond",B02.00[[#This Row],[c0140]]="Bearrer Bond",B02.00[[#This Row],[c0140]]="Borrower Note Loan",B02.00[[#This Row],[c0140]]="Certificate of Deposit / Commercial Paper",B02.00[[#This Row],[c0140]]="Title of ownership",B02.00[[#This Row],[c0140]]="Cash account/saving account",B02.00[[#This Row],[c0140]]="Term deposit",B02.00[[#This Row],[c0140]]="Loan",B02.00[[#This Row],[c0140]]="Bill of exchange",B02.00[[#This Row],[c0140]]="Other"),"OK","KO") -> OK | EB6: =IF(B02.00[[#This Row],[c0160]]>=1,"OK","KO") -> OK | EC6: =IF(AND(B02.00[[#This Row],[c0020]]<>"NCNP",B02.00[[#This Row],[c0020]]<>"NCBP"),(IF(B02.00[[#This Row],[c0170]]>DATE(1900,1,1),"OK","KO")),"OK") -> OK | ED6: =IF(AND(OR(B02.00[[#This Row],[c0190]]<>"",B02.00[[#This Row],[c0200]]<>""),AND(B02.00[[#This Row],[c0020]]<>"NCNP",B02.00[[#This Row],[c0020]]<>"NCBP")),(IF(AND(B02.00[[#This Row],[c0170]]<B02.00[[#This Row],[c0190]],B02.00[[#This Row],[c0170]]<B02.00[[#This Row],[c0200]]),"OK","KO")),"OK") -> OK | EE6: =IF(AND(B02.00[[#This Row],[c0020]]<>"NCNP",B02.00[[#This Row],[c0020]]<>"NCBP"),IF(B02.00[[#This Row],[c0180]]="","KO",IF(B02.00[[#This Row],[c0180]]>DATE(1900,1,1),"OK","KO")),"OK") -> OK | EF6: =IF(AND('B9900'!$I$4<>"",B02.00[[#This Row],[c0020]]<>"NCNP",B02.00[[#This Row],[c0020]]<>"NCBP"),IF(B02.00[[#This Row],[c0180]]="","KO",IF(B02.00[[#This Row],[c0180]]>'B9900'!$I$4,"OK","KO")),"OK") -> OK | EG6: =IF(AND(B02.00[[#This Row],[c0020]]<>"NCNP",B02.00[[#This Row],[c0020]]<>"NCBP"),(IF(B02.00[[#This Row],[c0200]]>DATE(1900,1,1),"OK","KO")),"OK") -> OK | EH6: =IF(AND('B9900'!$I$4<>"",AND(B02.00[[#This Row],[c0020]]<>"NCNP",B02.00[[#This Row],[c0020]]<>"NCBP")),(IF(B02.00[[#This Row],[c0200]]>'B9900'!$I$4,"OK","KO")),"OK") -> OK | EI6: =IF(AND(B02.00[[#This Row],[c0020]]<>"NCNP",B02.00[[#This Row],[c0020]]<>"NCBP"),(IF(B02.00[[#This Row],[c0210]]>DATE(1900,1,1),"OK","KO")),"OK") -> OK | EJ6: =IF(AND('B9900'!$I$4<>"",AND(B02.00[[#This Row],[c0020]]<>"NCNP",B02.00[[#This Row],[c0020]]<>"NCBP")),(IF(B02.00[[#This Row],[c0210]]>'B9900'!$I$4,"OK","KO")),"OK") -> OK | EK6: =IF(AND(B02.00[[#This Row],[c0020]]<>"NCNP",B02.00[[#This Row],[c0020]]<>"NCBP"),(IF(OR(NOT(ISERROR(MATCH(B02.00[[#This Row],[c0220]],'ISO 3166'!B:B,0))),NOT(ISERROR(MATCH(B02.00[[#This Row],[c0220]],'ISO 3166'!E:E,0)))),"OK","KO")),"OK") -> OK | EL6: =IF(AND(B02.00[[#This Row],[c0020]]<>"NCNP",B02.00[[#This Row],[c0020]]<>"NCBP"),(IF(OR(B02.00[[#This Row],[c0230]]="Yes, supported by Legal Opinion",B02.00[[#This Row],[c0230]]="Yes, not supported by Legal Opinion",B02.00[[#This Row],[c0230]]="No",B02.00[[#This Row],[c0230]]="Not applicable",B02.00[[#This Row],[c0230]]="Aggregated"),"OK","KO")),"OK") -> OK | EM6: =IF(OR(B02.00[[#This Row],[c0250]]="Non-structured/Vanilla",B02.00[[#This Row],[c0250]]="Structured",B02.00[[#This Row],[c0250]]="Other non-standard terms",B02.00[[#This Row],[c0250]]="Only structured coupon",B02.00[[#This Row],[c0250]]="Aggregated"),"OK","KO") -> OK | EN6: =IF(OR(B02.00[[#This Row],[c0310]]="Secured",B02.00[[#This Row],[c0310]]="Unsecured"),"OK","KO") -> OK | EO6: =IF(AND(B02.00[[#This Row],[c0310]]="Secured",OR(B02.00[[#This Row],[c0250]]="Non-structured/Vanilla",B02.00[[#This Row],[c0250]]="Other non-standard terms"),B02.00[[#This Row],[c0240]]<>"ZCB issued at discount"),(IF(B02.00[[#This Row],[c0330]]=MAX(0,B02.00[[#This Row],[c0120]],B02.00[[#This Row],[c0320]]),"OK","KO")),"OK") -> OK | EP6: =IF(AND(B02.00[[#This Row],[c0310]]="Secured",OR(B02.00[[#This Row],[c0250]]="Structured",B02.00[[#This Row],[c0250]]="Only structured coupon")),(IF(OR(B02.00[[#This Row],[c0330]]=MAX(0,B02.00[[#This Row],[c0270]],B02.00[[#This Row],[c0320]]),B02.00[[#This Row],[c0330]]=MAX(0,B02.00[[#This Row],[c0120]],B02.00[[#This Row],[c0320]])),"OK","KO")),"OK") -> OK | EQ6: =IF(OR(B02.00[[#This Row],[c0350]]="Real estate",B02.00[[#This Row],[c0350]]="Ships",B02.00[[#This Row],[c0350]]="Aircraft",B02.00[[#This Row],[c0350]]="Financial",B02.00[[#This Row],[c0350]]="Other",B02.00[[#This Row],[c0350]]="Not applicable"),"OK","KO") -> OK | ER6: =IF(B02.00[[#This Row],[c0310]]="Unsecured",(IF(B02.00[[#This Row],[c0350]]="Not applicable","OK","KO")),"OK") -> OK | ES6: =IF(OR(B02.00[[#This Row],[c0440]]="NGN",B02.00[[#This Row],[c0440]]="CGN",B02.00[[#This Row],[c0440]]="Not applicable"),"OK","KO") -> OK | ET6: =IF(OR(B02.00[[#This Row],[c0530]]="T2 in phase-out",B02.00[[#This Row],[c0530]]="Grandfathered T2",B02.00[[#This Row],[c0530]]="Fully Compliant T2",B02.00[[#This Row],[c0530]]="Partially (A)T1 and T2",B02.00[[#This Row],[c0530]]="Grandfathered AT1",B02.00[[#This Row],[c0530]]="Fully Compliant AT1",B02.00[[#This Row],[c0530]]="CET1",B02.00[[#This Row],[c0530]]="No"),"OK","KO") -> OK | EU6: =IF(B02.00[[#This Row],[c0540]] ="","KO",IF(B02.00[[#This Row],[c0540]]>=0,"OK","KO")) -> OK | EV6: =IF(OR(B02.00[[#This Row],[c0550]]="T2 in phase-out",B02.00[[#This Row],[c0550]]="Grandfathered T2",B02.00[[#This Row],[c0550]]="Fully Compliant T2",B02.00[[#This Row],[c0550]]="Partially (A)T1 and T2",B02.00[[#This Row],[c0550]]="Grandfathered AT1",B02.00[[#This Row],[c0550]]="Fully Compliant AT1",B02.00[[#This Row],[c0550]]="CET1",B02.00[[#This Row],[c0550]]="No"),"OK","KO") -> OK | EW6: =IF(B02.00[[#This Row],[c0560]]="","KO",IF(B02.00[[#This Row],[c0560]]>=0,"OK","KO")) -> OK | EX6: =IF(OR(B02.00[[#This Row],[c0590]]="Lien",B02.00[[#This Row],[c0590]]="Guarantee",B02.00[[#This Row],[c0590]]="Surety",B02.00[[#This Row],[c0590]]="Guarantee obligation",B02.00[[#This Row],[c0590]]="Other",B02.00[[#This Row],[c0590]]="Not applicable",B02.00[[#This Row],[c0590]]="Aggregated"),"OK","KO") -> OK | EY6: =IF(B02.00[[#This Row],[c0610]]="","KO",IF(B02.00[[#This Row],[c0610]]>=0,"OK","KO")) -> OK | EZ6: =IF(OR(B02.00[[#This Row],[c0620]]="010 Financial liabilities held for trading",B02.00[[#This Row],[c0620]]="070 Financial liabilities at fair value through profit or loss",B02.00[[#This Row],[c0620]]="110 Financial liabilities at amortized cost",B02.00[[#This Row],[c0620]]="280 Other liabilities",B02.00[[#This Row],[c0620]]="300 Total equity",),"OK","KO") -> OK
A7: 3 | B7: 31641600000000000PTSTOFOM0004000 | C7: PTSTOFOM0004 | D7: ISIN | E7: 200000000 | F7: 999999999999999 | G7: EUR | H7: 200000000 | I7: 0 | J7: 4106991.8 | K7: 0 | L7: 2.0410699e+08 | M7: 2.0410699e+08 | N7: Registered Bond | O7: Not applicable | P7: Not applicable | Q7: 3 | R7: 999999999999999 | S7: 3 | T7: 2022-06-07 | U7: 2026-06-09 | V7: 2027-06-09 | W7: 2027-06-09 | X7: 2027-06-09 | Y7: PT | Z7: Yes, supported by Legal Opinion | AA7: No ZCB | AB7: Non-structured/Vanilla | AC7: 999999999999999 | AD7: 999999999999999 | AE7: FALSE | AF7: FALSE | AG7: 999999999999999 | AH7: Unsecured | AI7: 999999999999999 | AJ7: 999999999999999 | AK7: Not applicable | AL7: Not applicable | AM7: Not applicable | AN7: Nominal | AO7: 100000 | AP7: 100000 | AQ7: 2000 | AR7: 0 | AS7: =+B02.00[[#This Row],[c0100]]/B02.00[[#This Row],[c0390]] -> 2053.4959 | AT7: 0 | AU7: 999999999999999 | AV7: 999999999999999 | AW7: 999999999999999 | AX7: Not applicable | AY7: -10000 | AZ7: INTERBOLSA_PT | BA7: 529900LG70TCAGWCXT47 | BB7: Not applicable | BC7: BANCO SANTANDER TOTTA S,A, | BD7: 549300URJH9VSI58CS32 | BE7: Not applicable | BF7: Not applicable | BG7: INTERBOLSA_PT | BH7: 529900LG70TCAGWCXT47 | BI7: INTERBOLSA_PT | BJ7: 529900LG70TCAGWCXT47 | BK7: Not applicable | BL7: Not applicable | BM7: Not applicable | BN7: Not applicable | BO7: Fully Compliant T2 | BP7: 2.0410699e+08 | BQ7: Fully Compliant T2 | BR7: 2.0410699e+08 | BS7: 0 | BT7: Not applicable | BU7: Not applicable | BV7: Not applicable | BW7: FALSE | BX7: 2.0410699e+08 | BY7: 110 Financial liabilities at amortized cost | BZ7: 999999999999999 | CA7: Not applicable | CB7: FALSE | CC7: TRUE | CD7: =IF(B02.00[[#This Row],[c0010]]="","KO","OK") -> OK | CE7: =IF(B02.00[[#This Row],[c0030]]="","KO","OK") -> OK | CF7: =IF(B02.00[[#This Row],[c0040]]="","KO","OK") -> OK | CG7: =IF(B02.00[[#This Row],[c0070]]="","KO","OK") -> OK | CH7: =IF(OR(B02.00[[#This Row],[c0250]]= "Non-Structured/Vanilla",B02.00[[#This Row],[c0250]]="Other non-standard terms"),(IF(B02.00[[#This Row],[c0080]]="","KO","OK")),"OK") -> OK | CI7: =IF(OR(B02.00[[#This Row],[c0250]]= "Structured",B02.00[[#This Row],[c0250]]="Only structured coupon"),(IF(B02.00[[#This Row],[c0080]]="","KO","OK")),"OK") -> OK | CJ7: =IF(B02.00[[#This Row],[c0040]]="ISIN",(IF(B02.00[[#This Row],[c0090]]="","KO","OK")),"OK") -> OK | CK7: =IF(AND(OR(B02.00[[#This Row],[c0250]]="Non-Structured/Vanilla",B02.00[[#This Row],[c0250]]="Other non-standard terms"),B02.00[[#This Row],[c0240]]<>"ZCB issued at discount"),(IF(B02.00[[#This Row],[c0100]]="","KO","OK")),"OK") -> OK | CL7: =IF(OR(B02.00[[#This Row],[c0250]]<> "Non-Structured/Vanilla",B02.00[[#This Row],[c0460]]<>"Other non-standard terms"),IF(B02.00[[#This Row],[c0100]]="","KO","OK")) -> OK | CM7: =IF(OR(B02.00[[#This Row],[c0250]]= "Non-Structured/Vanilla",B02.00[[#This Row],[c0460]]="Other non-standard terms"),(IF(B02.00[[#This Row],[c0120]]="","KO","OK")),"OK") -> OK | CN7: =IF(OR(B02.00[[#This Row],[c0250]]<> "Structured",B02.00[[#This Row],[c0250]]<>"Only structured coupon"),(IF(B02.00[[#This Row],[c0120]]="","KO","OK")),"OK") -> OK | CO7: =IF(B02.00[[#This Row],[c0130]]="","KO","OK") -> OK | CP7: =IF(B02.00[[#This Row],[c0140]]="","KO","OK") -> OK | CQ7: =IF(B02.00[[#This Row],[c0140]]="Other",(IF(B02.00[[#This Row],[c0141]]="","KO","OK")),"OK") -> OK | CR7: =IF(B02.00[[#This Row],[c0160]]="","KO","OK") -> OK | CS7: =IF(B02.00[[#This Row],[c0162]]="","KO","OK") -> OK | CT7: =IF(AND(OR(B02.00[[#This Row],[c0250]]= "Non-Structured/Vanilla",B02.00[[#This Row],[c0250]]="Other non-standard terms"),B02.00[[#This Row],[c0240]]<>"ZCB issued at discount"),(IF(B02.00[[#This Row],[c0180]]="","KO","OK")),"OK") -> OK | CU7: =IF(AND(B02.00[[#This Row],[c0250]]<> "Structured",B02.00[[#This Row],[c0250]]<>"Only structured coupon"),(IF(B02.00[[#This Row],[c0180]]="","KO","OK")),"OK") -> OK | CV7: =IF(B02.00[[#This Row],[c0200]]="","KO","OK") -> OK | CW7: =IF(B02.00[[#This Row],[c0140]]<>"Cash account/saving account",(IF(B02.00[[#This Row],[c0210]]="","KO","OK")),"OK") -> OK | CX7: =IF(B02.00[[#This Row],[c0220]]="","KO","OK") -> OK | CY7: =IF(B02.00[[#This Row],[c0250]]="","KO","OK") -> OK | CZ7: =IF(OR(B02.00[[#This Row],[c0250]]="Structured",B02.00[[#This Row],[c0250]]="Only structured coupon"),(IF(B02.00[[#This Row],[c0260]]="","KO","OK")),"OK") -> OK | DA7: =IF(OR(B02.00[[#This Row],[c0250]]="Structured",B02.00[[#This Row],[c0250]]="Only structured coupon"),(IF(B02.00[[#This Row],[c0270]]="","KO","OK")),"OK") -> OK | DB7: =IF(OR(B02.00[[#This Row],[c0280]]="TRUE",B02.00[[#This Row],[c0290]]="TRUE"),(IF(B02.00[[#This Row],[c0300]]="","KO","OK")),"OK") -> OK | DC7: =IF(B02.00[[#This Row],[c0310]]="","KO","OK") -> OK | DD7: =IF(B02.00[[#This Row],[c0310]]="Secured",(IF(B02.00[[#This Row],[c0320]]="","KO","OK")),"OK") -> OK | DE7: =IF(B02.00[[#This Row],[c0310]]="Secured",(IF(B02.00[[#This Row],[c0330]]="","KO","OK")),"OK") -> OK | DF7: =IF(B02.00[[#This Row],[c0310]]="Secured",(IF(B02.00[[#This Row],[c0350]]="","KO","OK")),"OK") -> OK | DG7: =IF(B02.00[[#This Row],[c0350]]="Other",(IF(B02.00[[#This Row],[c0351]]="","KO","OK")),"OK") -> OK | DH7: =IF(AND(B02.00[[#This Row],[c0040]]="ISIN",B02.00[[#This Row],[c0360]]="Nominal "),(IF(B02.00[[#This Row],[c0370]]="","KO","OK")),"OK") -> OK | DI7: =IF(AND(B02.00[[#This Row],[c0040]]="ISIN",B02.00[[#This Row],[c0360]]="Unit "),(IF(B02.00[[#This Row],[c0370]]="","KO","OK")),"OK") -> OK | DJ7: =IF(B02.00[[#This Row],[c0040]]="ISIN",(IF(B02.00[[#This Row],[c0390]]="","KO","OK")),"OK") -> OK | DK7: =IF(B02.00[[#This Row],[c0040]]="ISIN",(IF(B02.00[[#This Row],[c0391]]="","KO","OK")),"OK") -> OK | DL7: =IF(AND(B02.00[[#This Row],[c0040]]="ISIN",OR(B02.00[[#This Row],[c0250]]= "Non-Structured/Vanilla",B02.00[[#This Row],[c0250]]="Other non-standard terms"),B02.00[[#This Row],[c0240]]<>"ZCB issued at discount"),(IF(B02.00[[#This Row],[c0400]]="","KO","OK")),"OK") -> OK | DM7: =IF(AND(B02.00[[#This Row],[c0040]]="ISIN",AND(B02.00[[#This Row],[c0250]]<>"Structured",B02.00[[#This Row],[c0250]]<>"Only structured coupon")),(IF(B02.00[[#This Row],[c0400]]="","KO","OK")),"OK") -> OK | DN7: =IF(B02.00[[#This Row],[c0610]]="","KO","OK") -> OK | DO7: =IF('B9900'!$H$4="Non-Resolution Entity",(IF(B02.00[[#This Row],[c5000]]="","KO","OK")),"OK") -> OK | DP7: =IF('B9900'!$H$4="Non-Resolution Entity",(IF(B02.00[[#This Row],[c5010]]="","KO","OK")),"OK") -> OK | DQ7: =IF(B02.00[[#This Row],[c0040]]="ISIN",(IF(AND(LEN(B02.00[[#This Row],[c0030]]=12),NOT(ISNUMBER(LEFT(B02.00[[#This Row],[c0030]],2)))),"OK","KO")),"OK") -> OK | DR7: =IF(AND(B02.00[[#This Row],[c0020]]<>"NCNP",B02.00[[#This Row],[c0020]]<>"NCBP"),(IF(AND(LEN(B02.00[[#This Row],[c0070]])=3,NOT(ISERROR(MATCH(UPPER(B02.00[[#This Row],[c0070]]),Tabelle1[Alphabetic Code],0)))),"OK","KO")),"OK") -> OK | DS7: =IF(B02.00[[#This Row],[c0080]]>0,"OK","KO") -> OK | DT7: =IF(B02.00[[#This Row],[c0040]]="ISIN",(IF(B02.00[[#This Row],[c0090]]>=0,"OK","KO")),"OK") -> OK | DU7: =IF(B02.00[[#This Row],[c0100]]>=0,"OK","KO") -> OK | DV7: =IF(B02.00[[#This Row],[c0110]]>=0,"OK","KO") -> OK | DW7: =IF(B02.00[[#This Row],[c0120]]>=0,"OK","KO") -> OK | DX7: =IF(B02.00[[#This Row],[c0120]]=(H7+J7+K7),"OK","KO") -> OK | DY7: =IF(OR(B02.00[[#This Row],[c0250]]="Non-structured /Vanilla",B02.00[[#This Row],[c0250]]="Other non-standard terms"),(IF(B02.00[[#This Row],[c0130]]=MAX(0,B02.00[[#This Row],[c0120]],B02.00[[#This Row],[c0300]],B02.00[[#This Row],[c0320]]),"OK","KO")),"OK") -> OK | DZ7: =IF(OR(B02.00[[#This Row],[c0250]]="Structured",B02.00[[#This Row],[c0250]]="Only structured coupon"),(IF(OR(B02.00[[#This Row],[c0130]]=MAX(0,B02.00[[#This Row],[c0270]],B02.00[[#This Row],[c0300]],B02.00[[#This Row],[c0320]]),B02.00[[#This Row],[c0130]]=MAX(0,B02.00[[#This Row],[c0120]],B02.00[[#This Row],[c0300]],B02.00[[#This Row],[c0320]])),"OK","KO")),"OK") -> OK | EA7: =IF(OR(B02.00[[#This Row],[c0140]]="Registered Bond",B02.00[[#This Row],[c0140]]="Bearrer Bond",B02.00[[#This Row],[c0140]]="Borrower Note Loan",B02.00[[#This Row],[c0140]]="Certificate of Deposit / Commercial Paper",B02.00[[#This Row],[c0140]]="Title of ownership",B02.00[[#This Row],[c0140]]="Cash account/saving account",B02.00[[#This Row],[c0140]]="Term deposit",B02.00[[#This Row],[c0140]]="Loan",B02.00[[#This Row],[c0140]]="Bill of exchange",B02.00[[#This Row],[c0140]]="Other"),"OK","KO") -> OK | EB7: =IF(B02.00[[#This Row],[c0160]]>=1,"OK","KO") -> OK | EC7: =IF(AND(B02.00[[#This Row],[c0020]]<>"NCNP",B02.00[[#This Row],[c0020]]<>"NCBP"),(IF(B02.00[[#This Row],[c0170]]>DATE(1900,1,1),"OK","KO")),"OK") -> OK | ED7: =IF(AND(OR(B02.00[[#This Row],[c0190]]<>"",B02.00[[#This Row],[c0200]]<>""),AND(B02.00[[#This Row],[c0020]]<>"NCNP",B02.00[[#This Row],[c0020]]<>"NCBP")),(IF(AND(B02.00[[#This Row],[c0170]]<B02.00[[#This Row],[c0190]],B02.00[[#This Row],[c0170]]<B02.00[[#This Row],[c0200]]),"OK","KO")),"OK") -> OK | EE7: =IF(AND(B02.00[[#This Row],[c0020]]<>"NCNP",B02.00[[#This Row],[c0020]]<>"NCBP"),IF(B02.00[[#This Row],[c0180]]="","KO",IF(B02.00[[#This Row],[c0180]]>DATE(1900,1,1),"OK","KO")),"OK") -> OK | EF7: =IF(AND('B9900'!$I$4<>"",B02.00[[#This Row],[c0020]]<>"NCNP",B02.00[[#This Row],[c0020]]<>"NCBP"),IF(B02.00[[#This Row],[c0180]]="","KO",IF(B02.00[[#This Row],[c0180]]>'B9900'!$I$4,"OK","KO")),"OK") -> OK | EG7: =IF(AND(B02.00[[#This Row],[c0020]]<>"NCNP",B02.00[[#This Row],[c0020]]<>"NCBP"),(IF(B02.00[[#This Row],[c0200]]>DATE(1900,1,1),"OK","KO")),"OK") -> OK | EH7: =IF(AND('B9900'!$I$4<>"",AND(B02.00[[#This Row],[c0020]]<>"NCNP",B02.00[[#This Row],[c0020]]<>"NCBP")),(IF(B02.00[[#This Row],[c0200]]>'B9900'!$I$4,"OK","KO")),"OK") -> OK | EI7: =IF(AND(B02.00[[#This Row],[c0020]]<>"NCNP",B02.00[[#This Row],[c0020]]<>"NCBP"),(IF(B02.00[[#This Row],[c0210]]>DATE(1900,1,1),"OK","KO")),"OK") -> OK | EJ7: =IF(AND('B9900'!$I$4<>"",AND(B02.00[[#This Row],[c0020]]<>"NCNP",B02.00[[#This Row],[c0020]]<>"NCBP")),(IF(B02.00[[#This Row],[c0210]]>'B9900'!$I$4,"OK","KO")),"OK") -> OK | EK7: =IF(AND(B02.00[[#This Row],[c0020]]<>"NCNP",B02.00[[#This Row],[c0020]]<>"NCBP"),(IF(OR(NOT(ISERROR(MATCH(B02.00[[#This Row],[c0220]],'ISO 3166'!B:B,0))),NOT(ISERROR(MATCH(B02.00[[#This Row],[c0220]],'ISO 3166'!E:E,0)))),"OK","KO")),"OK") -> OK | EL7: =IF(AND(B02.00[[#This Row],[c0020]]<>"NCNP",B02.00[[#This Row],[c0020]]<>"NCBP"),(IF(OR(B02.00[[#This Row],[c0230]]="Yes, supported by Legal Opinion",B02.00[[#This Row],[c0230]]="Yes, not supported by Legal Opinion",B02.00[[#This Row],[c0230]]="No",B02.00[[#This Row],[c0230]]="Not applicable",B02.00[[#This Row],[c0230]]="Aggregated"),"OK","KO")),"OK") -> OK | EM7: =IF(OR(B02.00[[#This Row],[c0250]]="Non-structured/Vanilla",B02.00[[#This Row],[c0250]]="Structured",B02.00[[#This Row],[c0250]]="Other non-standard terms",B02.00[[#This Row],[c0250]]="Only structured coupon",B02.00[[#This Row],[c0250]]="Aggregated"),"OK","KO") -> OK | EN7: =IF(OR(B02.00[[#This Row],[c0310]]="Secured",B02.00[[#This Row],[c0310]]="Unsecured"),"OK","KO") -> OK | EO7: =IF(AND(B02.00[[#This Row],[c0310]]="Secured",OR(B02.00[[#This Row],[c0250]]="Non-structured/Vanilla",B02.00[[#This Row],[c0250]]="Other non-standard terms"),B02.00[[#This Row],[c0240]]<>"ZCB issued at discount"),(IF(B02.00[[#This Row],[c0330]]=MAX(0,B02.00[[#This Row],[c0120]],B02.00[[#This Row],[c0320]]),"OK","KO")),"OK") -> OK | EP7: =IF(AND(B02.00[[#This Row],[c0310]]="Secured",OR(B02.00[[#This Row],[c0250]]="Structured",B02.00[[#This Row],[c0250]]="Only structured coupon")),(IF(OR(B02.00[[#This Row],[c0330]]=MAX(0,B02.00[[#This Row],[c0270]],B02.00[[#This Row],[c0320]]),B02.00[[#This Row],[c0330]]=MAX(0,B02.00[[#This Row],[c0120]],B02.00[[#This Row],[c0320]])),"OK","KO")),"OK") -> OK | EQ7: =IF(OR(B02.00[[#This Row],[c0350]]="Real estate",B02.00[[#This Row],[c0350]]="Ships",B02.00[[#This Row],[c0350]]="Aircraft",B02.00[[#This Row],[c0350]]="Financial",B02.00[[#This Row],[c0350]]="Other",B02.00[[#This Row],[c0350]]="Not applicable"),"OK","KO") -> OK | ER7: =IF(B02.00[[#This Row],[c0310]]="Unsecured",(IF(B02.00[[#This Row],[c0350]]="Not applicable","OK","KO")),"OK") -> OK | ES7: =IF(OR(B02.00[[#This Row],[c0440]]="NGN",B02.00[[#This Row],[c0440]]="CGN",B02.00[[#This Row],[c0440]]="Not applicable"),"OK","KO") -> OK | ET7: =IF(OR(B02.00[[#This Row],[c0530]]="T2 in phase-out",B02.00[[#This Row],[c0530]]="Grandfathered T2",B02.00[[#This Row],[c0530]]="Fully Compliant T2",B02.00[[#This Row],[c0530]]="Partially (A)T1 and T2",B02.00[[#This Row],[c0530]]="Grandfathered AT1",B02.00[[#This Row],[c0530]]="Fully Compliant AT1",B02.00[[#This Row],[c0530]]="CET1",B02.00[[#This Row],[c0530]]="No"),"OK","KO") -> OK | EU7: =IF(B02.00[[#This Row],[c0540]] ="","KO",IF(B02.00[[#This Row],[c0540]]>=0,"OK","KO")) -> OK | EV7: =IF(OR(B02.00[[#This Row],[c0550]]="T2 in phase-out",B02.00[[#This Row],[c0550]]="Grandfathered T2",B02.00[[#This Row],[c0550]]="Fully Compliant T2",B02.00[[#This Row],[c0550]]="Partially (A)T1 and T2",B02.00[[#This Row],[c0550]]="Grandfathered AT1",B02.00[[#This Row],[c0550]]="Fully Compliant AT1",B02.00[[#This Row],[c0550]]="CET1",B02.00[[#This Row],[c0550]]="No"),"OK","KO") -> OK | EW7: =IF(B02.00[[#This Row],[c0560]]="","KO",IF(B02.00[[#This Row],[c0560]]>=0,"OK","KO")) -> OK | EX7: =IF(OR(B02.00[[#This Row],[c0590]]="Lien",B02.00[[#This Row],[c0590]]="Guarantee",B02.00[[#This Row],[c0590]]="Surety",B02.00[[#This Row],[c0590]]="Guarantee obligation",B02.00[[#This Row],[c0590]]="Other",B02.00[[#This Row],[c0590]]="Not applicable",B02.00[[#This Row],[c0590]]="Aggregated"),"OK","KO") -> OK | EY7: =IF(B02.00[[#This Row],[c0610]]="","KO",IF(B02.00[[#This Row],[c0610]]>=0,"OK","KO")) -> OK | EZ7: =IF(OR(B02.00[[#This Row],[c0620]]="010 Financial liabilities held for trading",B02.00[[#This Row],[c0620]]="070 Financial liabilities at fair value through profit or loss",B02.00[[#This Row],[c0620]]="110 Financial liabilities at amortized cost",B02.00[[#This Row],[c0620]]="280 Other liabilities",B02.00[[#This Row],[c0620]]="300 Total equity",),"OK","KO") -> OK
