Workbook

Sheet QUERY BUILDER
A1: COD_KPI | B1: CAMPO | C1: THEN | D1: DESCRIÇÃO | E1: REFDATE | F1: TIPOLOGIA_TESTE | G1: TABELA | H1: CASE WHEN | I1: ELSE | J1: DIF | K1: QUERY | L1: Comentar
A2: v_1_0001 | B2: 0010_row_nmbr | C2: 1 | D2: =+VLOOKUP(A2,Descrição!A:K,11,FALSE) -> Testar se o campo está a missing. O campo tem de ser reportado. | E2: "& RefDate &" | F2: REGULAMENTAR | G2: BU_LOANTAPE_WORK.OUT_B0200_MAIN_LIABILITIES | H2: `0010_row_nmbr` IS NULL or cast(`0010_row_nmbr` as string)='' | I2: =+IF(C2=1,0,1) -> 0 | J2: =+IF(C2=0,"THEN NULL ELSE X.CHAVE_IT END","THEN X.CHAVE_IT ELSE NULL END") -> THEN X.CHAVE_IT ELSE NULL END | K2: ="UNION ALL SELECT '"&E2&"' AS REF_DATE, '"&A2&"' AS COD_KPI, '"&F2&"' AS TIPOLOGIA_TESTE, '"&D2&"' AS DESCRIÇÃO, '"&G2&"' AS TABELA, '"&B2&"' AS CAMPO, COUNT(*) AS NUM_REG, SUM(IF("&H2&","&C2&" ,"&I2&")) AS NUM_REG_DIF, GROUP_CONCAT(CASE WHEN "&H2&" "&J2&", '; ') AS DETALHE FROM (SELECT *, 0020_UNIQ_ID AS CHAVE_IT, "&B2&" AS CAMPO_IT FROM "&G2&" WHERE REF_DATE='"&E2&"')X GROUP BY 1" -> UNION ALL SELECT '"& RefDate &"' AS REF_DATE, 'v_1_0001' AS COD_KPI, 'REGULAMENTAR' AS TIPOLOGIA_TESTE, 'Testar se o campo está a missing. O campo tem de ser reportado.' AS DESCRIÇÃO, 'BU_LOANTAPE_WORK.OUT_B0200_MAIN_LIABILITIES' AS TABELA, '0010_row_nmbr' AS CAMPO, COUNT(*) AS NUM_REG, SUM(IF(`0010_row_nmbr` IS NULL or cast(`0010_row_nmbr` as string)='',1 ,0)) AS NUM_REG_DIF, GROUP_CONCAT(CASE WHEN `0010_row_nmbr` IS NULL or cast(`0010_row_nmbr` as string)='' THEN X.CHAVE_IT ELSE NULL END, '; ') AS DETALHE FROM (SELECT *, 0020_UNIQ_ID AS CHAVE_IT, 0010_row_nmbr AS CAMPO_IT FROM BU_LOANTAPE_WORK.OUT_B0200_MAIN_LIABILITIES WHERE REF_DATE='"& RefDate &"')X GROUP BY 1
A3: v_1_0002 | B3: 0030_uniq_id_knwn_cntrprty | C3: 1 | D3: =+VLOOKUP(A3,Descrição!A:K,11,FALSE) -> Testar se o campo está a missing. O campo tem de ser reportado. | E3: "& RefDate &" | F3: REGULAMENTAR | G3: BU_LOANTAPE_WORK.OUT_B0200_MAIN_LIABILITIES | H3: `0030_uniq_id_knwn_cntrprty` = '' | I3: =+IF(C3=1,0,1) -> 0 | J3: =+IF(C3=0,"THEN NULL ELSE X.CHAVE_IT END","THEN X.CHAVE_IT ELSE NULL END") -> THEN X.CHAVE_IT ELSE NULL END | K3: ="UNION ALL SELECT '"&E3&"' AS REF_DATE, '"&A3&"' AS COD_KPI, '"&F3&"' AS TIPOLOGIA_TESTE, '"&D3&"' AS DESCRIÇÃO, '"&G3&"' AS TABELA, '"&B3&"' AS CAMPO, COUNT(*) AS NUM_REG, SUM(IF("&H3&","&C3&" ,"&I3&")) AS NUM_REG_DIF, GROUP_CONCAT(CASE WHEN "&H3&" "&J3&", '; ') AS DETALHE FROM (SELECT *, 0020_UNIQ_ID AS CHAVE_IT, "&B3&" AS CAMPO_IT FROM "&G3&" WHERE REF_DATE='"&E3&"')X GROUP BY 1" -> UNION ALL SELECT '"& RefDate &"' AS REF_DATE, 'v_1_0002' AS COD_KPI, 'REGULAMENTAR' AS TIPOLOGIA_TESTE, 'Testar se o campo está a missing. O campo tem de ser reportado.' AS DESCRIÇÃO, 'BU_LOANTAPE_WORK.OUT_B0200_MAIN_LIABILITIES' AS TABELA, '0030_uniq_id_knwn_cntrprty' AS CAMPO, COUNT(*) AS NUM_REG, SUM(IF(`0030_uniq_id_knwn_cntrprty` = '',1 ,0)) AS NUM_REG_DIF, GROUP_CONCAT(CASE WHEN `0030_uniq_id_knwn_cntrprty` = '' THEN X.CHAVE_IT ELSE NULL END, '; ') AS DETALHE FROM (SELECT *, 0020_UNIQ_ID AS CHAVE_IT, 0030_uniq_id_knwn_cntrprty AS CAMPO_IT FROM BU_LOANTAPE_WORK.OUT_B0200_MAIN_LIABILITIES WHERE REF_DATE='"& RefDate &"')X GROUP BY 1
A4: v_1_0003 | B4: 0040_typ_uniq_id_knwn_cntrprty | C4: 1 | D4: =+VLOOKUP(A4,Descrição!A:K,11,FALSE) -> Testar se o campo está a missing. O campo tem de ser reportado. | E4: "& RefDate &" | F4: REGULAMENTAR | G4: BU_LOANTAPE_WORK.OUT_B0200_MAIN_LIABILITIES | H4: `0040_typ_uniq_id_knwn_cntrprty` = '' | I4: =+IF(C4=1,0,1) -> 0 | J4: =+IF(C4=0,"THEN NULL ELSE X.CHAVE_IT END","THEN X.CHAVE_IT ELSE NULL END") -> THEN X.CHAVE_IT ELSE NULL END | K4: ="UNION ALL SELECT '"&E4&"' AS REF_DATE, '"&A4&"' AS COD_KPI, '"&F4&"' AS TIPOLOGIA_TESTE, '"&D4&"' AS DESCRIÇÃO, '"&G4&"' AS TABELA, '"&B4&"' AS CAMPO, COUNT(*) AS NUM_REG, SUM(IF("&H4&","&C4&" ,"&I4&")) AS NUM_REG_DIF, GROUP_CONCAT(CASE WHEN "&H4&" "&J4&", '; ') AS DETALHE FROM (SELECT *, 0020_UNIQ_ID AS CHAVE_IT, "&B4&" AS CAMPO_IT FROM "&G4&" WHERE REF_DATE='"&E4&"')X GROUP BY 1" -> UNION ALL SELECT '"& RefDate &"' AS REF_DATE, 'v_1_0003' AS COD_KPI, 'REGULAMENTAR' AS TIPOLOGIA_TESTE, 'Testar se o campo está a missing. O campo tem de ser reportado.' AS DESCRIÇÃO, 'BU_LOANTAPE_WORK.OUT_B0200_MAIN_LIABILITIES' AS TABELA, '0040_typ_uniq_id_knwn_cntrprty' AS CAMPO, COUNT(*) AS NUM_REG, SUM(IF(`0040_typ_uniq_id_knwn_cntrprty` = '' ,1 ,0)) AS NUM_REG_DIF, GROUP_CONCAT(CASE WHEN `0040_typ_uniq_id_knwn_cntrprty` = '' THEN X.CHAVE_IT ELSE NULL END, '; ') AS DETALHE FROM (SELECT *, 0020_UNIQ_ID AS CHAVE_IT, 0040_typ_uniq_id_knwn_cntrprty AS CAMPO_IT FROM BU_LOANTAPE_WORK.OUT_B0200_MAIN_LIABILITIES WHERE REF_DATE='"& RefDate &"')X GROUP BY 1
A5: v_1_0004 | B5: 0070_cntrct_crrncy | C5: 1 | D5: =+VLOOKUP(A5,Descrição!A:K,11,FALSE) -> Testar se o campo está a missing. O campo tem de ser reportado. | E5: "& RefDate &" | F5: REGULAMENTAR | G5: BU_LOANTAPE_WORK.OUT_B0200_MAIN_LIABILITIES | H5: `0070_cntrct_crrncy` = '' | I5: =+IF(C5=1,0,1) -> 0 | J5: =+IF(C5=0,"THEN NULL ELSE X.CHAVE_IT END","THEN X.CHAVE_IT ELSE NULL END") -> THEN X.CHAVE_IT ELSE NULL END | K5: ="UNION ALL SELECT '"&E5&"' AS REF_DATE, '"&A5&"' AS COD_KPI, '"&F5&"' AS TIPOLOGIA_TESTE, '"&D5&"' AS DESCRIÇÃO, '"&G5&"' AS TABELA, '"&B5&"' AS CAMPO, COUNT(*) AS NUM_REG, SUM(IF("&H5&","&C5&" ,"&I5&")) AS NUM_REG_DIF, GROUP_CONCAT(CASE WHEN "&H5&" "&J5&", '; ') AS DETALHE FROM (SELECT *, 0020_UNIQ_ID AS CHAVE_IT, "&B5&" AS CAMPO_IT FROM "&G5&" WHERE REF_DATE='"&E5&"')X GROUP BY 1" -> UNION ALL SELECT '"& RefDate &"' AS REF_DATE, 'v_1_0004' AS COD_KPI, 'REGULAMENTAR' AS TIPOLOGIA_TESTE, 'Testar se o campo está a missing. O campo tem de ser reportado.' AS DESCRIÇÃO, 'BU_LOANTAPE_WORK.OUT_B0200_MAIN_LIABILITIES' AS TABELA, '0070_cntrct_crrncy' AS CAMPO, COUNT(*) AS NUM_REG, SUM(IF(`0070_cntrct_crrncy` = '',1 ,0)) AS NUM_REG_DIF, GROUP_CONCAT(CASE WHEN `0070_cntrct_crrncy` = '' THEN X.CHAVE_IT ELSE NULL END, '; ') AS DETALHE FROM (SELECT *, 0020_UNIQ_ID AS CHAVE_IT, 0070_cntrct_crrncy AS CAMPO_IT FROM BU_LOANTAPE_WORK.OUT_B0200_MAIN_LIABILITIES WHERE REF_DATE='"& RefDate &"')X GROUP BY 1
A6: v_1_0005 | B6: 0080_otstndng_prncpl_amnt | C6: 1 | D6: =+VLOOKUP(A6,Descrição!A:K,11,FALSE) -> Testar se o campo está a missing. O campo deve ser reportado para passivos não estruturados. | E6: "& RefDate &" | F6: REGULAMENTAR | G6: BU_LOANTAPE_WORK.OUT_B0200_MAIN_LIABILITIES | H6: (`0080_otstndng_prncpl_amnt` IS NULL OR CAST(`0080_otstndng_prncpl_amnt` AS STRING) = '') AND `0250_strctrd_prdct` IN ('Non-Structured/Vanilla', 'Other non-standard terms') | I6: =+IF(C6=1,0,1) -> 0 | J6: =+IF(C6=0,"THEN NULL ELSE X.CHAVE_IT END","THEN X.CHAVE_IT ELSE NULL END") -> THEN X.CHAVE_IT ELSE NULL END | K6: ="UNION ALL SELECT '"&E6&"' AS REF_DATE, '"&A6&"' AS COD_KPI, '"&F6&"' AS TIPOLOGIA_TESTE, '"&D6&"' AS DESCRIÇÃO, '"&G6&"' AS TABELA, '"&B6&"' AS CAMPO, COUNT(*) AS NUM_REG, SUM(IF("&H6&","&C6&" ,"&I6&")) AS NUM_REG_DIF, GROUP_CONCAT(CASE WHEN "&H6&" "&J6&", '; ') AS DETALHE FROM (SELECT *, 0020_UNIQ_ID AS CHAVE_IT, "&B6&" AS CAMPO_IT FROM "&G6&" WHERE REF_DATE='"&E6&"')X GROUP BY 1" -> UNION ALL SELECT '"& RefDate &"' AS REF_DATE, 'v_1_0005' AS COD_KPI, 'REGULAMENTAR' AS TIPOLOGIA_TESTE, 'Testar se o campo está a missing. O campo deve ser reportado para passivos não estruturados.' AS DESCRIÇÃO, 'BU_LOANTAPE_WORK.OUT_B0200_MAIN_LIABILITIES' AS TABELA, '0080_otstndng_prncpl_amnt' AS CAMPO, COUNT(*) AS NUM_REG, SUM(IF((`0080_otstndng_prncpl_amnt` IS NULL OR CAST(`0080_otstndng_prncpl_amnt` AS STRING) = '') AND `0250_strctrd_prdct` IN ('Non-Structured/Vanilla', 'Other non-standard terms'),1 ,0)) AS NUM_REG_DIF, GROUP_CONCAT(CASE WHEN (`0080_otstndng_prncpl_amnt` IS NULL OR CAST(`0080_otstndng_prncpl_amnt` AS STRING) = '') AND `0250_strctrd_prdct` IN ('Non-Structured/Vanilla', 'Other non-standard terms') THEN X.CHAVE_IT ELSE NULL END, '; ') AS DETALHE FROM (SELECT *, 0020_UNIQ_ID AS CHAVE_IT, 0080_otstndng_prncpl_amnt AS CAMPO_IT FROM BU_LOANTAPE_WORK.OUT_B0200_MAIN_LIABILITIES WHERE REF_DATE='"& RefDate &"')X GROUP BY 1
A7: v_1_0006 | B7: 0080_otstndng_prncpl_amnt | C7: 1 | D7: =+VLOOKUP(A7,Descrição!A:K,11,FALSE) -> Alerta: Testar se o campo está a missing. Para passivos estruturados, o campo tem de ser reportado se a informação existir. | E7: "& RefDate &" | F7: REGULAMENTAR | G7: BU_LOANTAPE_WORK.OUT_B0200_MAIN_LIABILITIES | H7: (`0080_otstndng_prncpl_amnt` IS NULL OR CAST(`0080_otstndng_prncpl_amnt` AS STRING) = '') AND `0250_strctrd_prdct` IN ('Structured', 'Only structured coupon') | I7: =+IF(C7=1,0,1) -> 0 | J7: =+IF(C7=0,"THEN NULL ELSE X.CHAVE_IT END","THEN X.CHAVE_IT ELSE NULL END") -> THEN X.CHAVE_IT ELSE NULL END | K7: ="UNION ALL SELECT '"&E7&"' AS REF_DATE, '"&A7&"' AS COD_KPI, '"&F7&"' AS TIPOLOGIA_TESTE, '"&D7&"' AS DESCRIÇÃO, '"&G7&"' AS TABELA, '"&B7&"' AS CAMPO, COUNT(*) AS NUM_REG, SUM(IF("&H7&","&C7&" ,"&I7&")) AS NUM_REG_DIF, GROUP_CONCAT(CASE WHEN "&H7&" "&J7&", '; ') AS DETALHE FROM (SELECT *, 0020_UNIQ_ID AS CHAVE_IT, "&B7&" AS CAMPO_IT FROM "&G7&" WHERE REF_DATE='"&E7&"')X GROUP BY 1" -> UNION ALL SELECT '"& RefDate &"' AS REF_DATE, 'v_1_0006' AS COD_KPI, 'REGULAMENTAR' AS TIPOLOGIA_TESTE, 'Alerta: Testar se o campo está a missing. Para passivos estruturados, o campo tem de ser reportado se a informação existir.' AS DESCRIÇÃO, 'BU_LOANTAPE_WORK.OUT_B0200_MAIN_LIABILITIES' AS TABELA, '0080_otstndng_prncpl_amnt' AS CAMPO, COUNT(*) AS NUM_REG, SUM(IF((`0080_otstndng_prncpl_amnt` IS NULL OR CAST(`0080_otstndng_prncpl_amnt` AS STRING) = '') AND `0250_strctrd_prdct` IN ('Structured', 'Only structured coupon'),1 ,0)) AS NUM_REG_DIF, GROUP_CONCAT(CASE WHEN (`0080_otstndng_prncpl_amnt` IS NULL OR CAST(`0080_otstndng_prncpl_amnt` AS STRING) = '') AND `0250_strctrd_prdct` IN ('Structured', 'Only structured coupon') THEN X.CHAVE_IT ELSE NULL END, '; ') AS DETALHE FROM (SELECT *, 0020_UNIQ_ID AS CHAVE_IT, 0080_otstndng_prncpl_amnt AS CAMPO_IT FROM BU_LOANTAPE_WORK.OUT_B0200_MAIN_LIABILITIES WHERE REF_DATE='"& RefDate &"')X GROUP BY 1
A8: v_1_0007 | B8: 0090_prtn_amnt_rprtng_entty | C8: 1 | D8: =+VLOOKUP(A8,Descrição!A:K,11,FALSE) -> Testar se o campo está a missing. O campo deve ser reportado para valores mobiliários. | E8: "& RefDate &" | F8: REGULAMENTAR | G8: BU_LOANTAPE_WORK.OUT_B0200_MAIN_LIABILITIES | H8: (`0090_prtn_amnt_rprtng_entty` IS NULL OR CAST(`0090_prtn_amnt_rprtng_entty` AS STRING) = '') AND `0040_typ_uniq_id_knwn_cntrprty` = 'ISIN' | I8: =+IF(C8=1,0,1) -> 0 | J8: =+IF(C8=0,"THEN NULL ELSE X.CHAVE_IT END","THEN X.CHAVE_IT ELSE NULL END") -> THEN X.CHAVE_IT ELSE NULL END | K8: ="UNION ALL SELECT '"&E8&"' AS REF_DATE, '"&A8&"' AS COD_KPI, '"&F8&"' AS TIPOLOGIA_TESTE, '"&D8&"' AS DESCRIÇÃO, '"&G8&"' AS TABELA, '"&B8&"' AS CAMPO, COUNT(*) AS NUM_REG, SUM(IF("&H8&","&C8&" ,"&I8&")) AS NUM_REG_DIF, GROUP_CONCAT(CASE WHEN "&H8&" "&J8&", '; ') AS DETALHE FROM (SELECT *, 0020_UNIQ_ID AS CHAVE_IT, "&B8&" AS CAMPO_IT FROM "&G8&" WHERE REF_DATE='"&E8&"')X GROUP BY 1" -> UNION ALL SELECT '"& RefDate &"' AS REF_DATE, 'v_1_0007' AS COD_KPI, 'REGULAMENTAR' AS TIPOLOGIA_TESTE, 'Testar se o campo está a missing. O campo deve ser reportado para valores mobiliários.' AS DESCRIÇÃO, 'BU_LOANTAPE_WORK.OUT_B0200_MAIN_LIABILITIES' AS TABELA, '0090_prtn_amnt_rprtng_entty' AS CAMPO, COUNT(*) AS NUM_REG, SUM(IF((`0090_prtn_amnt_rprtng_entty` IS NULL OR CAST(`0090_prtn_amnt_rprtng_entty` AS STRING) = '') AND `0040_typ_uniq_id_knwn_cntrprty` = 'ISIN',1 ,0)) AS NUM_REG_DIF, GROUP_CONCAT(CASE WHEN (`0090_prtn_amnt_rprtng_entty` IS NULL OR CAST(`0090_prtn_amnt_rprtng_entty` AS STRING) = '') AND `0040_typ_uniq_id_knwn_cntrprty` = 'ISIN' THEN X.CHAVE_IT ELSE NULL END, '; ') AS DETALHE FROM (SELECT *, 0020_UNIQ_ID AS CHAVE_IT, 0090_prtn_amnt_rprtng_entty AS CAMPO_IT FROM BU_LOANTAPE_WORK.OUT_B0200_MAIN_LIABILITIES WHERE REF_DATE='"& RefDate &"')X GROUP BY 1
A9: v_1_0008 | B9: 0100_accrd_intrst_instrmnt | C9: 1 | D9: =+VLOOKUP(A9,Descrição!A:K,11,FALSE) -> Testar se o campo está a missing. Para passivos não estruturados que não sejam zero coupon bonds emitidas com desconto, este campo deve ser reportado. | E9: "& RefDate &" | F9: REGULAMENTAR | G9: BU_LOANTAPE_WORK.OUT_B0200_MAIN_LIABILITIES | H9: (`0100_accrd_intrst_instrmnt` IS NULL OR CAST(`0100_accrd_intrst_instrmnt` AS STRING) = '') AND `0250_strctrd_prdct` IN ('Non-Structured', 'Other non-standard terms') AND `0240_zero_coupon` != 'ZCB issued at discount' | I9: =+IF(C9=1,0,1) -> 0 | J9: =+IF(C9=0,"THEN NULL ELSE X.CHAVE_IT END","THEN X.CHAVE_IT ELSE NULL END") -> THEN X.CHAVE_IT ELSE NULL END | K9: ="UNION ALL SELECT '"&E9&"' AS REF_DATE, '"&A9&"' AS COD_KPI, '"&F9&"' AS TIPOLOGIA_TESTE, '"&D9&"' AS DESCRIÇÃO, '"&G9&"' AS TABELA, '"&B9&"' AS CAMPO, COUNT(*) AS NUM_REG, SUM(IF("&H9&","&C9&" ,"&I9&")) AS NUM_REG_DIF, GROUP_CONCAT(CASE WHEN "&H9&" "&J9&", '; ') AS DETALHE FROM (SELECT *, 0020_UNIQ_ID AS CHAVE_IT, "&B9&" AS CAMPO_IT FROM "&G9&" WHERE REF_DATE='"&E9&"')X GROUP BY 1" -> UNION ALL SELECT '"& RefDate &"' AS REF_DATE, 'v_1_0008' AS COD_KPI, 'REGULAMENTAR' AS TIPOLOGIA_TESTE, 'Testar se o campo está a missing. Para passivos não estruturados que não sejam zero coupon bonds emitidas com desconto, este campo deve ser reportado.' AS DESCRIÇÃO, 'BU_LOANTAPE_WORK.OUT_B0200_MAIN_LIABILITIES' AS TABELA, '0100_accrd_intrst_instrmnt' AS CAMPO, COUNT(*) AS NUM_REG, SUM(IF((`0100_accrd_intrst_instrmnt` IS NULL OR CAST(`0100_accrd_intrst_instrmnt` AS STRING) = '') AND `0250_strctrd_prdct` IN ('Non-Structured', 'Other non-standard terms') AND `0240_zero_coupon` != 'ZCB issued at discount',1 ,0)) AS NUM_REG_DIF, GROUP_CONCAT(CASE WHEN (`0100_accrd_intrst_instrmnt` IS NULL OR CAST(`0100_accrd_intrst_instrmnt` AS STRING) = '') AND `0250_strctrd_prdct` IN ('Non-Structured', 'Other non-standard terms') AND `0240_zero_coupon` != 'ZCB issued at discount' THEN X.CHAVE_IT ELSE NULL END, '; ') AS DETALHE FROM (SELECT *, 0020_UNIQ_ID AS CHAVE_IT, 0100_accrd_intrst_instrmnt AS CAMPO_IT FROM BU_LOANTAPE_WORK.OUT_B0200_MAIN_LIABILITIES WHERE REF_DATE='"& RefDate &"')X GROUP BY 1
A10: v_1_0009 | B10: 0100_accrd_intrst_instrmnt | C10: 1 | D10: =+VLOOKUP(A10,Descrição!A:K,11,FALSE) -> Alerta: Testar se o campo está a missing. Para passivos estruturados, o campo tem de ser reportado se a informação existir. | E10: "& RefDate &" | F10: REGULAMENTAR | G10: BU_LOANTAPE_WORK.OUT_B0200_MAIN_LIABILITIES | H10: (`0100_accrd_intrst_instrmnt` IS NULL OR CAST(`0100_accrd_intrst_instrmnt` AS STRING) = '') AND `0250_strctrd_prdct` IN ('Structured', 'Only structured coupon') | I10: =+IF(C10=1,0,1) -> 0 | J10: =+IF(C10=0,"THEN NULL ELSE X.CHAVE_IT END","THEN X.CHAVE_IT ELSE NULL END") -> THEN X.CHAVE_IT ELSE NULL END | K10: ="UNION ALL SELECT '"&E10&"' AS REF_DATE, '"&A10&"' AS COD_KPI, '"&F10&"' AS TIPOLOGIA_TESTE, '"&D10&"' AS DESCRIÇÃO, '"&G10&"' AS TABELA, '"&B10&"' AS CAMPO, COUNT(*) AS NUM_REG, SUM(IF("&H10&","&C10&" ,"&I10&")) AS NUM_REG_DIF, GROUP_CONCAT(CASE WHEN "&H10&" "&J10&", '; ') AS DETALHE FROM (SELECT *, 0020_UNIQ_ID AS CHAVE_IT, "&B10&" AS CAMPO_IT FROM "&G10&" WHERE REF_DATE='"&E10&"')X GROUP BY 1" -> UNION ALL SELECT '"& RefDate &"' AS REF_DATE, 'v_1_0009' AS COD_KPI, 'REGULAMENTAR' AS TIPOLOGIA_TESTE, 'Alerta: Testar se o campo está a missing. Para passivos estruturados, o campo tem de ser reportado se a informação existir.' AS DESCRIÇÃO, 'BU_LOANTAPE_WORK.OUT_B0200_MAIN_LIABILITIES' AS TABELA, '0100_accrd_intrst_instrmnt' AS CAMPO, COUNT(*) AS NUM_REG, SUM(IF((`0100_accrd_intrst_instrmnt` IS NULL OR CAST(`0100_accrd_intrst_instrmnt` AS STRING) = '') AND `0250_strctrd_prdct` IN ('Structured', 'Only structured coupon') ,1 ,0)) AS NUM_REG_DIF, GROUP_CONCAT(CASE WHEN (`0100_accrd_intrst_instrmnt` IS NULL OR CAST(`0100_accrd_intrst_instrmnt` AS STRING) = '') AND `0250_strctrd_prdct` IN ('Structured', 'Only structured coupon') THEN X.CHAVE_IT ELSE NULL END, '; ') AS DETALHE FROM (SELECT *, 0020_UNIQ_ID AS CHAVE_IT, 0100_accrd_intrst_instrmnt AS CAMPO_IT FROM BU_LOANTAPE_WORK.OUT_B0200_MAIN_LIABILITIES WHERE REF_DATE='"& RefDate &"')X GROUP BY 1
A11: v_1_0010 | B11: 0120_otstndng_amnt | C11: 1 | D11: =+VLOOKUP(A11,Descrição!A:K,11,FALSE) -> Testar se o campo está a missing. Para passivos não estruturados, este campo deve ser declarado. | E11: "& RefDate &" | F11: REGULAMENTAR | G11: BU_LOANTAPE_WORK.OUT_B0200_MAIN_LIABILITIES | H11: (`0120_otstndng_amnt` IS NULL OR CAST(`0120_otstndng_amnt` AS STRING) = '') AND `0250_strctrd_prdct` IN ('Non-Structured/Vanilla', 'Other non-standard terms') | I11: =+IF(C11=1,0,1) -> 0 | J11: =+IF(C11=0,"THEN NULL ELSE X.CHAVE_IT END","THEN X.CHAVE_IT ELSE NULL END") -> THEN X.CHAVE_IT ELSE NULL END | K11: ="UNION ALL SELECT '"&E11&"' AS REF_DATE, '"&A11&"' AS COD_KPI, '"&F11&"' AS TIPOLOGIA_TESTE, '"&D11&"' AS DESCRIÇÃO, '"&G11&"' AS TABELA, '"&B11&"' AS CAMPO, COUNT(*) AS NUM_REG, SUM(IF("&H11&","&C11&" ,"&I11&")) AS NUM_REG_DIF, GROUP_CONCAT(CASE WHEN "&H11&" "&J11&", '; ') AS DETALHE FROM (SELECT *, 0020_UNIQ_ID AS CHAVE_IT, "&B11&" AS CAMPO_IT FROM "&G11&" WHERE REF_DATE='"&E11&"')X GROUP BY 1" -> UNION ALL SELECT '"& RefDate &"' AS REF_DATE, 'v_1_0010' AS COD_KPI, 'REGULAMENTAR' AS TIPOLOGIA_TESTE, 'Testar se o campo está a missing. Para passivos não estruturados, este campo deve ser declarado.' AS DESCRIÇÃO, 'BU_LOANTAPE_WORK.OUT_B0200_MAIN_LIABILITIES' AS TABELA, '0120_otstndng_amnt' AS CAMPO, COUNT(*) AS NUM_REG, SUM(IF((`0120_otstndng_amnt` IS NULL OR CAST(`0120_otstndng_amnt` AS STRING) = '') AND `0250_strctrd_prdct` IN ('Non-Structured/Vanilla', 'Other non-standard terms'),1 ,0)) AS NUM_REG_DIF, GROUP_CONCAT(CASE WHEN (`0120_otstndng_amnt` IS NULL OR CAST(`0120_otstndng_amnt` AS STRING) = '') AND `0250_strctrd_prdct` IN ('Non-Structured/Vanilla', 'Other non-standard terms') THEN X.CHAVE_IT ELSE NULL END, '; ') AS DETALHE FROM (SELECT *, 0020_UNIQ_ID AS CHAVE_IT, 0120_otstndng_amnt AS CAMPO_IT FROM BU_LOANTAPE_WORK.OUT_B0200_MAIN_LIABILITIES WHERE REF_DATE='"& RefDate &"')X GROUP BY 1
A12: v_1_0011 | B12: 0120_otstndng_amnt | C12: 1 | D12: =+VLOOKUP(A12,Descrição!A:K,11,FALSE) -> Alerta: Testar se o campo está a missing. Para passivos estruturados, o campo tem de ser reportado se a informação existir. | E12: "& RefDate &" | F12: REGULAMENTAR | G12: BU_LOANTAPE_WORK.OUT_B0200_MAIN_LIABILITIES | H12: (`0120_otstndng_amnt` IS NULL OR CAST(`0120_otstndng_amnt` AS STRING) = '') AND `0250_strctrd_prdct` NOT IN ('Structured', 'Only structured coupon') | I12: =+IF(C12=1,0,1) -> 0 | J12: =+IF(C12=0,"THEN NULL ELSE X.CHAVE_IT END","THEN X.CHAVE_IT ELSE NULL END") -> THEN X.CHAVE_IT ELSE NULL END | K12: ="UNION ALL SELECT '"&E12&"' AS REF_DATE, '"&A12&"' AS COD_KPI, '"&F12&"' AS TIPOLOGIA_TESTE, '"&D12&"' AS DESCRIÇÃO, '"&G12&"' AS TABELA, '"&B12&"' AS CAMPO, COUNT(*) AS NUM_REG, SUM(IF("&H12&","&C12&" ,"&I12&")) AS NUM_REG_DIF, GROUP_CONCAT(CASE WHEN "&H12&" "&J12&", '; ') AS DETALHE FROM (SELECT *, 0020_UNIQ_ID AS CHAVE_IT, "&B12&" AS CAMPO_IT FROM "&G12&" WHERE REF_DATE='"&E12&"')X GROUP BY 1" -> UNION ALL SELECT '"& RefDate &"' AS REF_DATE, 'v_1_0011' AS COD_KPI, 'REGULAMENTAR' AS TIPOLOGIA_TESTE, 'Alerta: Testar se o campo está a missing. Para passivos estruturados, o campo tem de ser reportado se a informação existir.' AS DESCRIÇÃO, 'BU_LOANTAPE_WORK.OUT_B0200_MAIN_LIABILITIES' AS TABELA, '0120_otstndng_amnt' AS CAMPO, COUNT(*) AS NUM_REG, SUM(IF((`0120_otstndng_amnt` IS NULL OR CAST(`0120_otstndng_amnt` AS STRING) = '') AND `0250_strctrd_prdct` NOT IN ('Structured', 'Only structured coupon'),1 ,0)) AS NUM_REG_DIF, GROUP_CONCAT(CASE WHEN (`0120_otstndng_amnt` IS NULL OR CAST(`0120_otstndng_amnt` AS STRING) = '') AND `0250_strctrd_prdct` NOT IN ('Structured', 'Only structured coupon') THEN X.CHAVE_IT ELSE NULL END, '; ') AS DETALHE FROM (SELECT *, 0020_UNIQ_ID AS CHAVE_IT, 0120_otstndng_amnt AS CAMPO_IT FROM BU_LOANTAPE_WORK.OUT_B0200_MAIN_LIABILITIES WHERE REF_DATE='"& RefDate &"')X GROUP BY 1
A13: v_1_0012 | B13: 0130_rlvnt_amnt_wdc | C13: 1 | D13: =+VLOOKUP(A13,Descrição!A:K,11,FALSE) -> Testar se o campo está a missing. O campo tem de ser reportado. | E13: "& RefDate &" | F13: REGULAMENTAR | G13: BU_LOANTAPE_WORK.OUT_B0200_MAIN_LIABILITIES | H13: `0130_rlvnt_amnt_wdc` IS NULL OR CAST(`0130_rlvnt_amnt_wdc` AS STRING) = '' | I13: =+IF(C13=1,0,1) -> 0 | J13: =+IF(C13=0,"THEN NULL ELSE X.CHAVE_IT END","THEN X.CHAVE_IT ELSE NULL END") -> THEN X.CHAVE_IT ELSE NULL END | K13: ="UNION ALL SELECT '"&E13&"' AS REF_DATE, '"&A13&"' AS COD_KPI, '"&F13&"' AS TIPOLOGIA_TESTE, '"&D13&"' AS DESCRIÇÃO, '"&G13&"' AS TABELA, '"&B13&"' AS CAMPO, COUNT(*) AS NUM_REG, SUM(IF("&H13&","&C13&" ,"&I13&")) AS NUM_REG_DIF, GROUP_CONCAT(CASE WHEN "&H13&" "&J13&", '; ') AS DETALHE FROM (SELECT *, 0020_UNIQ_ID AS CHAVE_IT, "&B13&" AS CAMPO_IT FROM "&G13&" WHERE REF_DATE='"&E13&"')X GROUP BY 1" -> UNION ALL SELECT '"& RefDate &"' AS REF_DATE, 'v_1_0012' AS COD_KPI, 'REGULAMENTAR' AS TIPOLOGIA_TESTE, 'Testar se o campo está a missing. O campo tem de ser reportado.' AS DESCRIÇÃO, 'BU_LOANTAPE_WORK.OUT_B0200_MAIN_LIABILITIES' AS TABELA, '0130_rlvnt_amnt_wdc' AS CAMPO, COUNT(*) AS NUM_REG, SUM(IF(`0130_rlvnt_amnt_wdc` IS NULL OR CAST(`0130_rlvnt_amnt_wdc` AS STRING) = '',1 ,0)) AS NUM_REG_DIF, GROUP_CONCAT(CASE WHEN `0130_rlvnt_amnt_wdc` IS NULL OR CAST(`0130_rlvnt_amnt_wdc` AS STRING) = '' THEN X.CHAVE_IT ELSE NULL END, '; ') AS DETALHE FROM (SELECT *, 0020_UNIQ_ID AS CHAVE_IT, 0130_rlvnt_amnt_wdc AS CAMPO_IT FROM BU_LOANTAPE_WORK.OUT_B0200_MAIN_LIABILITIES WHERE REF_DATE='"& RefDate &"')X GROUP BY 1
... A38: v_1_0037 | B38: 0610_crryng_amnt_ifrs | C38: 1 | D38: =+VLOOKUP(A38,Descrição!A:K,11,FALSE) -> Alerta: Testar se o campo está a missing. O campo deve ser reportado se a informação existir, ou seja, se a entidade reportar em IFRS. | E38: "& RefDate &" | F38: REGULAMENTAR | G38: BU_LOANTAPE_WORK.OUT_B0200_MAIN_LIABILITIES | H38: (`0610_crryng_amnt_ifrs` IS NULL or cast(`0610_crryng_amnt_ifrs` as string)='') | I38: =+IF(C38=1,0,1) -> 0 | J38: =+IF(C38=0,"THEN NULL ELSE X.CHAVE_IT END","THEN X.CHAVE_IT ELSE NULL END") -> THEN X.CHAVE_IT ELSE NULL END | K38: ="UNION ALL SELECT '"&E38&"' AS REF_DATE, '"&A38&"' AS COD_KPI, '"&F38&"' AS TIPOLOGIA_TESTE, '"&D38&"' AS DESCRIÇÃO, '"&G38&"' AS TABELA, '"&B38&"' AS CAMPO, COUNT(*) AS NUM_REG, SUM(IF("&H38&","&C38&" ,"&I38&")) AS NUM_REG_DIF, GROUP_CONCAT(CASE WHEN "&H38&" "&J38&", '; ') AS DETALHE FROM (SELECT *, 0020_UNIQ_ID AS CHAVE_IT, "&B38&" AS CAMPO_IT FROM "&G38&" WHERE REF_DATE='"&E38&"')X GROUP BY 1" -> UNION ALL SELECT '"& RefDate &"' AS REF_DATE, 'v_1_0037' AS COD_KPI, 'REGULAMENTAR' AS TIPOLOGIA_TESTE, 'Alerta: Testar se o campo está a missing. O campo deve ser reportado se a informação existir, ou seja, se a entidade reportar em IFRS.' AS DESCRIÇÃO, 'BU_LOANTAPE_WORK.OUT_B0200_MAIN_LIABILITIES' AS TABELA, '0610_crryng_amnt_ifrs' AS CAMPO, COUNT(*) AS NUM_REG, SUM(IF((`0610_crryng_amnt_ifrs` IS NULL or cast(`0610_crryng_amnt_ifrs` as string)=''),1 ,0)) AS NUM_REG_DIF, GROUP_CONCAT(CASE WHEN (`0610_crryng_amnt_ifrs` IS NULL or cast(`0610_crryng_amnt_ifrs` as string)='') THEN X.CHAVE_IT ELSE NULL END, '; ') AS DETALHE FROM (SELECT *, 0020_UNIQ_ID AS CHAVE_IT, 0610_crryng_amnt_ifrs AS CAMPO_IT FROM BU_LOANTAPE_WORK.OUT_B0200_MAIN_LIABILITIES WHERE REF_DATE='"& RefDate &"')X GROUP BY 1
A39: v_1_0038 | B39: 5000_flg_shrhldr_not_rsltn_grp | C39: 1 | D39: =+VLOOKUP(A39,Descrição!A:K,11,FALSE) -> Testar se o campo está a missing. O campo deve ser reportado para Non-Resolution Entities. | E39: "& RefDate &" | F39: REGULAMENTAR | G39: BU_LOANTAPE_WORK.OUT_B0200_MAIN_LIABILITIES | H39: (`5000_flg_shrhldr_not_rsltn_grp` IS MISSING or cast(`5000_flg_shrhldr_not_rsltn_grp` as string) = '') AND B99.`0060_orgnl_amnt_fx` = 'Non-Resolution Entity' | I39: =+IF(C39=1,0,1) -> 0 | J39: =+IF(C39=0,"THEN NULL ELSE X.CHAVE_IT END","THEN X.CHAVE_IT ELSE NULL END") -> THEN X.CHAVE_IT ELSE NULL END | K39: ="--UNION ALL SELECT '"&E39&"' AS REF_DATE, '"&A39&"' AS COD_KPI, '"&F39&"' AS TIPOLOGIA_TESTE, '"&D39&"' AS DESCRIÇÃO, '"&G39&"' AS TABELA, '"&B39&"' AS CAMPO, COUNT(*) AS NUM_REG, SUM(IF("&H39&","&C39&" ,"&I39&")) AS NUM_REG_DIF, GROUP_CONCAT(CASE WHEN "&H39&" "&J39&", '; ') AS DETALHE FROM (SELECT *, 0020_UNIQ_ID AS CHAVE_IT, "&B39&" AS CAMPO_IT FROM "&G39&" WHERE REF_DATE='"&E39&"')X GROUP BY 1" -> --UNION ALL SELECT '"& RefDate &"' AS REF_DATE, 'v_1_0038' AS COD_KPI, 'REGULAMENTAR' AS TIPOLOGIA_TESTE, 'Testar se o campo está a missing. O campo deve ser reportado para Non-Resolution Entities.' AS DESCRIÇÃO, 'BU_LOANTAPE_WORK.OUT_B0200_MAIN_LIABILITIES' AS TABELA, '5000_flg_shrhldr_not_rsltn_grp' AS CAMPO, COUNT(*) AS NUM_REG, SUM(IF((`5000_flg_shrhldr_not_rsltn_grp` IS MISSING or cast(`5000_flg_shrhldr_not_rsltn_grp` as string) = '') AND B99.`0060_orgnl_amnt_fx` = 'Non-Resolution Entity',1 ,0)) AS NUM_REG_DIF, GROUP_CONCAT(CASE WHEN (`5000_flg_shrhldr_not_rsltn_grp` IS MISSING or cast(`5000_flg_shrhldr_not_rsltn_grp` as string) = '') AND B99.`0060_orgnl_amnt_fx` = 'Non-Resolution Entity' THEN X.CHAVE_IT ELSE NULL END, '; ') AS DETALHE FROM (SELECT *, 0020_UNIQ_ID AS CHAVE_IT, 5000_flg_shrhldr_not_rsltn_grp AS CAMPO_IT FROM BU_LOANTAPE_WORK.OUT_B0200_MAIN_LIABILITIES WHERE REF_DATE='"& RefDate &"')X GROUP BY 1
A40: v_1_0039 | B40: 5010_flg_art21_7a_srmr | C40: 1 | D40: =+VLOOKUP(A40,Descrição!A:K,11,FALSE) -> Testar se o campo está a missing. O campo deve ser reportado para Non-Resolution Entities. | E40: "& RefDate &" | F40: REGULAMENTAR | G40: BU_LOANTAPE_WORK.OUT_B0200_MAIN_LIABILITIES | H40: (`5010_flg_art21_7a_srmr` IS MISSING or cast(`5010_flg_art21_7a_srmr` as string) = '') AND B99.`0060_orgnl_amnt_fx` = 'Non-Resolution Entity' | I40: =+IF(C40=1,0,1) -> 0 | J40: =+IF(C40=0,"THEN NULL ELSE X.CHAVE_IT END","THEN X.CHAVE_IT ELSE NULL END") -> THEN X.CHAVE_IT ELSE NULL END | K40: ="--UNION ALL SELECT '"&E40&"' AS REF_DATE, '"&A40&"' AS COD_KPI, '"&F40&"' AS TIPOLOGIA_TESTE, '"&D40&"' AS DESCRIÇÃO, '"&G40&"' AS TABELA, '"&B40&"' AS CAMPO, COUNT(*) AS NUM_REG, SUM(IF("&H40&","&C40&" ,"&I40&")) AS NUM_REG_DIF, GROUP_CONCAT(CASE WHEN "&H40&" "&J40&", '; ') AS DETALHE FROM (SELECT *, 0020_UNIQ_ID AS CHAVE_IT, "&B40&" AS CAMPO_IT FROM "&G40&" WHERE REF_DATE='"&E40&"')X GROUP BY 1" -> --UNION ALL SELECT '"& RefDate &"' AS REF_DATE, 'v_1_0039' AS COD_KPI, 'REGULAMENTAR' AS TIPOLOGIA_TESTE, 'Testar se o campo está a missing. O campo deve ser reportado para Non-Resolution Entities.' AS DESCRIÇÃO, 'BU_LOANTAPE_WORK.OUT_B0200_MAIN_LIABILITIES' AS TABELA, '5010_flg_art21_7a_srmr' AS CAMPO, COUNT(*) AS NUM_REG, SUM(IF((`5010_flg_art21_7a_srmr` IS MISSING or cast(`5010_flg_art21_7a_srmr` as string) = '') AND B99.`0060_orgnl_amnt_fx` = 'Non-Resolution Entity',1 ,0)) AS NUM_REG_DIF, GROUP_CONCAT(CASE WHEN (`5010_flg_art21_7a_srmr` IS MISSING or cast(`5010_flg_art21_7a_srmr` as string) = '') AND B99.`0060_orgnl_amnt_fx` = 'Non-Resolution Entity' THEN X.CHAVE_IT ELSE NULL END, '; ') AS DETALHE FROM (SELECT *, 0020_UNIQ_ID AS CHAVE_IT, 5010_flg_art21_7a_srmr AS CAMPO_IT FROM BU_LOANTAPE_WORK.OUT_B0200_MAIN_LIABILITIES WHERE REF_DATE='"& RefDate &"')X GROUP BY 1
A41: v_2_0001 | B41: 0030_uniq_id_knwn_cntrprty | C41: 0 | D41: =+VLOOKUP(A41,Descrição!A:K,11,FALSE) -> Se o ID for um ISIN (c0030 = ISIN), então o ID reportado em c0020 deve ter as características de um ISIN, por exemplo, 12 caracteres e começar com 2 letras que significam o código de país ISO. | E41: "& RefDate &" | F41: REGULAMENTAR | G41: BU_LOANTAPE_WORK.OUT_B0200_MAIN_LIABILITIES | H41: `0040_typ_uniq_id_knwn_cntrprty` = 'ISIN' AND LENGTH(`0030_uniq_id_knwn_cntrprty`) <= 12 AND SUBSTR(`0030_uniq_id_knwn_cntrprty`, 1, 2) RLIKE '[A-Za-z]$' | I41: =+IF(C41=1,0,1) -> 1 | J41: =+IF(C41=0,"THEN NULL ELSE X.CHAVE_IT END","THEN X.CHAVE_IT ELSE NULL END") -> THEN NULL ELSE X.CHAVE_IT END | K41: ="UNION ALL SELECT '"&E41&"' AS REF_DATE, '"&A41&"' AS COD_KPI, '"&F41&"' AS TIPOLOGIA_TESTE, '"&D41&"' AS DESCRIÇÃO, '"&G41&"' AS TABELA, '"&B41&"' AS CAMPO, COUNT(*) AS NUM_REG, SUM(IF("&H41&","&C41&" ,"&I41&")) AS NUM_REG_DIF, GROUP_CONCAT(CASE WHEN "&H41&" "&J41&", '; ') AS DETALHE FROM (SELECT *, 0020_UNIQ_ID AS CHAVE_IT, "&B41&" AS CAMPO_IT FROM "&G41&" WHERE REF_DATE='"&E41&"')X GROUP BY 1" -> UNION ALL SELECT '"& RefDate &"' AS REF_DATE, 'v_2_0001' AS COD_KPI, 'REGULAMENTAR' AS TIPOLOGIA_TESTE, 'Se o ID for um ISIN (c0030 = ISIN), então o ID reportado em c0020 deve ter as características de um ISIN, por exemplo, 12 caracteres e começar com 2 letras que significam o código de país ISO.' AS DESCRIÇÃO, 'BU_LOANTAPE_WORK.OUT_B0200_MAIN_LIABILITIES' AS TABELA, '0030_uniq_id_knwn_cntrprty' AS CAMPO, COUNT(*) AS NUM_REG, SUM(IF(`0040_typ_uniq_id_knwn_cntrprty` = 'ISIN' AND LENGTH(`0030_uniq_id_knwn_cntrprty`) <= 12 AND SUBSTR(`0030_uniq_id_knwn_cntrprty`, 1, 2) RLIKE '[A-Za-z]$',0 ,1)) AS NUM_REG_DIF, GROUP_CONCAT(CASE WHEN `0040_typ_uniq_id_knwn_cntrprty` = 'ISIN' AND LENGTH(`0030_uniq_id_knwn_cntrprty`) <= 12 AND SUBSTR(`0030_uniq_id_knwn_cntrprty`, 1, 2) RLIKE '[A-Za-z]$' THEN NULL ELSE X.CHAVE_IT END, '; ') AS DETALHE FROM (SELECT *, 0020_UNIQ_ID AS CHAVE_IT, 0030_uniq_id_knwn_cntrprty AS CAMPO_IT FROM BU_LOANTAPE_WORK.OUT_B0200_MAIN_LIABILITIES WHERE REF_DATE='"& RefDate &"')X GROUP BY 1
A42: v_2_0003 | B42: 0070_cntrct_crrncy | C42: 1 | D42: =+VLOOKUP(A42,Descrição!A:K,11,FALSE) -> As moedas devem ser reportadas usando o código ISO 4217 de 3 letras. | E42: "& RefDate &" | F42: REGULAMENTAR | G42: BU_LOANTAPE_WORK.OUT_B0200_MAIN_LIABILITIES | H42: `0020_uniq_id` NOT IN ('NCNP', 'NCBP') AND `0070_cntrct_crrncy` NOT IN ('AFN', 'EUR', 'ALL', 'DZD', 'USD', 'EUR', 'AOA', 'XCD', 'XCD', 'XAD', 'ARS', 'AMD', 'AWG', 'AUD', 'EUR', 'AZN', 'BSD', 'BHD', 'BDT', 'BBD', 'BYN', 'EUR', 'BZD', 'XOF', 'BMD', 'INR', 'BTN', 'BOB', 'BOV', 'USD', 'BAM', 'BWP', 'NOK', 'BRL', 'USD', 'BND', 'BGN', 'XOF', 'BIF', 'CVE', 'KHR', 'XAF', 'CAD', 'KYD', 'XAF', 'XAF', 'CLP', 'CLF', 'CNY', 'CNH', 'AUD', 'AUD', 'COP', 'COU', 'KMF', 'CDF', 'XAF', 'NZD', 'CRC', 'XOF', 'EUR', 'CUP', 'XCG', 'EUR', 'CZK', 'DKK', 'DJF', 'XCD', 'DOP', 'USD', 'EGP', 'SVC', 'USD', 'XAF', 'ERN', 'EUR', 'SZL', 'ETB', 'EUR', 'FKP', 'DKK', 'FJD', 'EUR', 'EUR', 'EUR', 'XPF', 'EUR', 'XAF', 'GMD', 'GEL', 'EUR', 'GHS', 'GIP', 'EUR', 'DKK', 'XCD', 'EUR', 'USD', 'GTQ', 'GBP', 'GNF', 'XOF', 'GYD', 'HTG', 'USD', 'AUD', 'EUR', 'HNL', 'HKD', 'HUF', 'ISK', 'INR', 'IDR', 'XDR', 'IRR', 'IQD', 'EUR', 'GBP', 'ILS', 'EUR', 'JMD', 'JPY', 'GBP', 'JOD', 'KZT', 'KES', 'AUD', 'KPW', 'KRW', 'KWD', 'KGS', 'LAK', 'EUR', 'LBP', 'LSL', 'ZAR', 'LRD', 'LYD', 'CHF', 'EUR', 'EUR', 'MOP', 'MGA', 'MWK', 'MYR', 'MVR', 'XOF', 'EUR', 'USD', 'EUR', 'MRU', 'MUR', 'EUR', 'XUA', 'MXN', 'MXV', 'USD', 'MDL', 'EUR', 'MNT', 'EUR', 'XCD', 'MAD', 'MZN', 'MMK', 'NAD', 'ZAR', 'AUD', 'NPR', 'EUR', 'XPF', 'NZD', 'NIO', 'XOF', 'NGN', 'NZD', 'AUD', 'MKD', 'USD', 'NOK', 'OMR', 'PKR', 'USD', 'PAB', 'USD', 'PGK', 'PYG', 'PEN', 'PHP', 'NZD', 'PLN', 'EUR', 'USD', 'QAR', 'EUR', 'RON', 'RUB', 'RWF', 'EUR', 'SHP', 'XCD', 'XCD', 'EUR', 'EUR', 'XCD', 'WST', 'EUR', 'STN', 'SAR', 'XOF', 'RSD', 'SCR', 'SLE', 'SGD', 'XCG', 'XSU', 'EUR', 'EUR', 'SBD', 'SOS', 'ZAR', 'SSP', 'EUR', 'LKR', 'SDG', 'SRD', 'NOK', 'SEK', 'CHF', 'CHE', 'CHW', 'SYP', 'TWD', 'TJS', 'TZS', 'THB', 'USD', 'XOF', 'NZD', 'TOP', 'TTD', 'TND', 'TRY', 'TMT', 'USD', 'AUD', 'UGX', 'UAH', 'AED', 'GBP', 'USD', 'USD', 'USN', 'UYU', 'UYI', 'UYW', 'UZS', 'VUV', 'VES', 'VED', 'VND', 'USD', 'USD', 'XPF', 'MAD', 'YER', 'ZMW', 'ZWG', 'XBA', 'XBB', 'XBC', 'XBD', 'XTS', 'XXX', 'XAU', 'XPD', 'XPT', 'XAG') | I42: =+IF(C42=1,0,1) -> 0 | J42: =+IF(C42=0,"THEN NULL ELSE X.CHAVE_IT END","THEN X.CHAVE_IT ELSE NULL END") -> THEN X.CHAVE_IT ELSE NULL END | K42: ="UNION ALL SELECT '"&E42&"' AS REF_DATE, '"&A42&"' AS COD_KPI, '"&F42&"' AS TIPOLOGIA_TESTE, '"&D42&"' AS DESCRIÇÃO, '"&G42&"' AS TABELA, '"&B42&"' AS CAMPO, COUNT(*) AS NUM_REG, SUM(IF("&H42&","&C42&" ,"&I42&")) AS NUM_REG_DIF, GROUP_CONCAT(CASE WHEN "&H42&" "&J42&", '; ') AS DETALHE FROM (SELECT *, 0020_UNIQ_ID AS CHAVE_IT, "&B42&" AS CAMPO_IT FROM "&G42&" WHERE REF_DATE='"&E42&"')X GROUP BY 1" -> UNION ALL SELECT '"& RefDate &"' AS REF_DATE, 'v_2_0003' AS COD_KPI, 'REGULAMENTAR' AS TIPOLOGIA_TESTE, 'As moedas devem ser reportadas usando o código ISO 4217 de 3 letras.' AS DESCRIÇÃO, 'BU_LOANTAPE_WORK.OUT_B0200_MAIN_LIABILITIES' AS TABELA, '0070_cntrct_crrncy' AS CAMPO, COUNT(*) AS NUM_REG, SUM(IF(`0020_uniq_id` NOT IN ('NCNP', 'NCBP') AND `0070_cntrct_crrncy` NOT IN ('AFN', 'EUR', 'ALL', 'DZD', 'USD', 'EUR', 'AOA', 'XCD', 'XCD', 'XAD', 'ARS', 'AMD', 'AWG', 'AUD', 'EUR', 'AZN', 'BSD', 'BHD', 'BDT', 'BBD', 'BYN', 'EUR', 'BZD', 'XOF', 'BMD', 'INR', 'BTN', 'BOB', 'BOV', 'USD', 'BAM', 'BWP', 'NOK', 'BRL', 'USD', 'BND', 'BGN', 'XOF', 'BIF', 'CVE', 'KHR', 'XAF', 'CAD', 'KYD', 'XAF', 'XAF', 'CLP', 'CLF', 'CNY', 'CNH', 'AUD', 'AUD', 'COP', 'COU', 'KMF', 'CDF', 'XAF', 'NZD', 'CRC', 'XOF', 'EUR', 'CUP', 'XCG', 'EUR', 'CZK', 'DKK', 'DJF', 'XCD', 'DOP', 'USD', 'EGP', 'SVC', 'USD', 'XAF', 'ERN', 'EUR', 'SZL', 'ETB', 'EUR', 'FKP', 'DKK', 'FJD', 'EUR', 'EUR', 'EUR', 'XPF', 'EUR', 'XAF', 'GMD', 'GEL', 'EUR', 'GHS', 'GIP', 'EUR', 'DKK', 'XCD', 'EUR', 'USD', 'GTQ', 'GBP', 'GNF', 'XOF', 'GYD', 'HTG', 'USD', 'AUD', 'EUR', 'HNL', 'HKD', 'HUF', 'ISK', 'INR', 'IDR', 'XDR', 'IRR', 'IQD', 'EUR', 'GBP', 'ILS', 'EUR', 'JMD', 'JPY', 'GBP', 'JOD', 'KZT', 'KES', 'AUD', 'KPW', 'KRW', 'KWD', 'KGS', 'LAK', 'EUR', 'LBP', 'LSL', 'ZAR', 'LRD', 'LYD', 'CHF', 'EUR', 'EUR', 'MOP', 'MGA', 'MWK', 'MYR', 'MVR', 'XOF', 'EUR', 'USD', 'EUR', 'MRU', 'MUR', 'EUR', 'XUA', 'MXN', 'MXV', 'USD', 'MDL', 'EUR', 'MNT', 'EUR', 'XCD', 'MAD', 'MZN', 'MMK', 'NAD', 'ZAR', 'AUD', 'NPR', 'EUR', 'XPF', 'NZD', 'NIO', 'XOF', 'NGN', 'NZD', 'AUD', 'MKD', 'USD', 'NOK', 'OMR', 'PKR', 'USD', 'PAB', 'USD', 'PGK', 'PYG', 'PEN', 'PHP', 'NZD', 'PLN', 'EUR', 'USD', 'QAR', 'EUR', 'RON', 'RUB', 'RWF', 'EUR', 'SHP', 'XCD', 'XCD', 'EUR', 'EUR', 'XCD', 'WST', 'EUR', 'STN', 'SAR', 'XOF', 'RSD', 'SCR', 'SLE', 'SGD', 'XCG', 'XSU', 'EUR', 'EUR', 'SBD', 'SOS', 'ZAR', 'SSP', 'EUR', 'LKR', 'SDG', 'SRD', 'NOK', 'SEK', 'CHF', 'CHE', 'CHW', 'SYP', 'TWD', 'TJS', 'TZS', 'THB', 'USD', 'XOF', 'NZD', 'TOP', 'TTD', 'TND', 'TRY', 'TMT', 'USD', 'AUD', 'UGX', 'UAH', 'AED', 'GBP', 'USD', 'USD', 'USN', 'UYU', 'UYI', 'UYW', 'UZS', 'VUV', 'VES', 'VED', 'VND', 'USD', 'USD', 'XPF', 'MAD', 'YER', 'ZMW', 'ZWG', 'XBA', 'XBB', 'XBC', 'XBD', 'XTS', 'XXX', 'XAU', 'XPD', 'XPT', 'XAG'),1 ,0)) AS NUM_REG_DIF, GROUP_CONCAT(CASE WHEN `0020_uniq_id` NOT IN ('NCNP', 'NCBP') AND `0070_cntrct_crrncy` NOT IN ('AFN', 'EUR', 'ALL', 'DZD', 'USD', 'EUR', 'AOA', 'XCD', 'XCD', 'XAD', 'ARS', 'AMD', 'AWG', 'AUD', 'EUR', 'AZN', 'BSD', 'BHD', 'BDT', 'BBD', 'BYN', 'EUR', 'BZD', 'XOF', 'BMD', 'INR', 'BTN', 'BOB', 'BOV', 'USD', 'BAM', 'BWP', 'NOK', 'BRL', 'USD', 'BND', 'BGN', 'XOF', 'BIF', 'CVE', 'KHR', 'XAF', 'CAD', 'KYD', 'XAF', 'XAF', 'CLP', 'CLF', 'CNY', 'CNH', 'AUD', 'AUD', 'COP', 'COU', 'KMF', 'CDF', 'XAF', 'NZD', 'CRC', 'XOF', 'EUR', 'CUP', 'XCG', 'EUR', 'CZK', 'DKK', 'DJF', 'XCD', 'DOP', 'USD', 'EGP', 'SVC', 'USD', 'XAF', 'ERN', 'EUR', 'SZL', 'ETB', 'EUR', 'FKP', 'DKK', 'FJD', 'EUR', 'EUR', 'EUR', 'XPF', 'EUR', 'XAF', 'GMD', 'GEL', 'EUR', 'GHS', 'GIP', 'EUR', 'DKK', 'XCD', 'EUR', 'USD', 'GTQ', 'GBP', 'GNF', 'XOF', 'GYD', 'HTG', 'USD', 'AUD', 'EUR', 'HNL', 'HKD', 'HUF', 'ISK', 'INR', 'IDR', 'XDR', 'IRR', 'IQD', 'EUR', 'GBP', 'ILS', 'EUR', 'JMD', 'JPY', 'GBP', 'JOD', 'KZT', 'KES', 'AUD', 'KPW', 'KRW', 'KWD', 'KGS', 'LAK', 'EUR', 'LBP', 'LSL', 'ZAR', 'LRD', 'LYD', 'CHF', 'EUR', 'EUR', 'MOP', 'MGA', 'MWK', 'MYR', 'MVR', 'XOF', 'EUR', 'USD', 'EUR', 'MRU', 'MUR', 'EUR', 'XUA', 'MXN', 'MXV', 'USD', 'MDL', 'EUR', 'MNT', 'EUR', 'XCD', 'MAD', 'MZN', 'MMK', 'NAD', 'ZAR', 'AUD', 'NPR', 'EUR', 'XPF', 'NZD', 'NIO', 'XOF', 'NGN', 'NZD', 'AUD', 'MKD', 'USD', 'NOK', 'OMR', 'PKR', 'USD', 'PAB', 'USD', 'PGK', 'PYG', 'PEN', 'PHP', 'NZD', 'PLN', 'EUR', 'USD', 'QAR', 'EUR', 'RON', 'RUB', 'RWF', 'EUR', 'SHP', 'XCD', 'XCD', 'EUR', 'EUR', 'XCD', 'WST', 'EUR', 'STN', 'SAR', 'XOF', 'RSD', 'SCR', 'SLE', 'SGD', 'XCG', 'XSU', 'EUR', 'EUR', 'SBD', 'SOS', 'ZAR', 'SSP', 'EUR', 'LKR', 'SDG', 'SRD', 'NOK', 'SEK', 'CHF', 'CHE', 'CHW', 'SYP', 'TWD', 'TJS', 'TZS', 'THB', 'USD', 'XOF', 'NZD', 'TOP', 'TTD', 'TND', 'TRY', 'TMT', 'USD', 'AUD', 'UGX', 'UAH', 'AED', 'GBP', 'USD', 'USD', 'USN', 'UYU', 'UYI', 'UYW', 'UZS', 'VUV', 'VES', 'VED', 'VND', 'USD', 'USD', 'XPF', 'MAD', 'YER', 'ZMW', 'ZWG', 'XBA', 'XBB', 'XBC', 'XBD', 'XTS', 'XXX', 'XAU', 'XPD', 'XPT', 'XAG') THEN X.CHAVE_IT ELSE NULL END, '; ') AS DETALHE FROM (SELECT *, 0020_UNIQ_ID AS CHAVE_IT, 0070_cntrct_crrncy AS CAMPO_IT FROM BU_LOANTAPE_WORK.OUT_B0200_MAIN_LIABILITIES WHERE REF_DATE='"& RefDate &"')X GROUP BY 1
A43: v_2_0004 | B43: 0080_otstndng_prncpl_amnt | C43: 1 | D43: =+VLOOKUP(A43,Descrição!A:K,11,FALSE) -> Alerta: o valor declarado deve, em geral, ser positivo. | E43: "& RefDate &" | F43: REGULAMENTAR | G43: BU_LOANTAPE_WORK.OUT_B0200_MAIN_LIABILITIES | H43: `0080_otstndng_prncpl_amnt` <= 0 | I43: =+IF(C43=1,0,1) -> 0 | J43: =+IF(C43=0,"THEN NULL ELSE X.CHAVE_IT END","THEN X.CHAVE_IT ELSE NULL END") -> THEN X.CHAVE_IT ELSE NULL END | K43: ="UNION ALL SELECT '"&E43&"' AS REF_DATE, '"&A43&"' AS COD_KPI, '"&F43&"' AS TIPOLOGIA_TESTE, '"&D43&"' AS DESCRIÇÃO, '"&G43&"' AS TABELA, '"&B43&"' AS CAMPO, COUNT(*) AS NUM_REG, SUM(IF("&H43&","&C43&" ,"&I43&")) AS NUM_REG_DIF, GROUP_CONCAT(CASE WHEN "&H43&" "&J43&", '; ') AS DETALHE FROM (SELECT *, 0020_UNIQ_ID AS CHAVE_IT, "&B43&" AS CAMPO_IT FROM "&G43&" WHERE REF_DATE='"&E43&"')X GROUP BY 1" -> UNION ALL SELECT '"& RefDate &"' AS REF_DATE, 'v_2_0004' AS COD_KPI, 'REGULAMENTAR' AS TIPOLOGIA_TESTE, 'Alerta: o valor declarado deve, em geral, ser positivo.' AS DESCRIÇÃO, 'BU_LOANTAPE_WORK.OUT_B0200_MAIN_LIABILITIES' AS TABELA, '0080_otstndng_prncpl_amnt' AS CAMPO, COUNT(*) AS NUM_REG, SUM(IF(`0080_otstndng_prncpl_amnt` <= 0,1 ,0)) AS NUM_REG_DIF, GROUP_CONCAT(CASE WHEN `0080_otstndng_prncpl_amnt` <= 0 THEN X.CHAVE_IT ELSE NULL END, '; ') AS DETALHE FROM (SELECT *, 0020_UNIQ_ID AS CHAVE_IT, 0080_otstndng_prncpl_amnt AS CAMPO_IT FROM BU_LOANTAPE_WORK.OUT_B0200_MAIN_LIABILITIES WHERE REF_DATE='"& RefDate &"')X GROUP BY 1
A44: v_2_0005 | B44: 0090_prtn_amnt_rprtng_entty | C44: 1 | D44: =+VLOOKUP(A44,Descrição!A:K,11,FALSE) -> O valor declarado deve ser positivo ou zero. | E44: "& RefDate &" | F44: REGULAMENTAR | G44: BU_LOANTAPE_WORK.OUT_B0200_MAIN_LIABILITIES | H44: `0090_prtn_amnt_rprtng_entty` <0 AND `0040_typ_uniq_id_knwn_cntrprty` = 'ISIN' | I44: =+IF(C44=1,0,1) -> 0 | J44: =+IF(C44=0,"THEN NULL ELSE X.CHAVE_IT END","THEN X.CHAVE_IT ELSE NULL END") -> THEN X.CHAVE_IT ELSE NULL END | K44: ="UNION ALL SELECT '"&E44&"' AS REF_DATE, '"&A44&"' AS COD_KPI, '"&F44&"' AS TIPOLOGIA_TESTE, '"&D44&"' AS DESCRIÇÃO, '"&G44&"' AS TABELA, '"&B44&"' AS CAMPO, COUNT(*) AS NUM_REG, SUM(IF("&H44&","&C44&" ,"&I44&")) AS NUM_REG_DIF, GROUP_CONCAT(CASE WHEN "&H44&" "&J44&", '; ') AS DETALHE FROM (SELECT *, 0020_UNIQ_ID AS CHAVE_IT, "&B44&" AS CAMPO_IT FROM "&G44&" WHERE REF_DATE='"&E44&"')X GROUP BY 1" -> UNION ALL SELECT '"& RefDate &"' AS REF_DATE, 'v_2_0005' AS COD_KPI, 'REGULAMENTAR' AS TIPOLOGIA_TESTE, 'O valor declarado deve ser positivo ou zero.' AS DESCRIÇÃO, 'BU_LOANTAPE_WORK.OUT_B0200_MAIN_LIABILITIES' AS TABELA, '0090_prtn_amnt_rprtng_entty' AS CAMPO, COUNT(*) AS NUM_REG, SUM(IF(`0090_prtn_amnt_rprtng_entty` <0 AND `0040_typ_uniq_id_knwn_cntrprty` = 'ISIN',1 ,0)) AS NUM_REG_DIF, GROUP_CONCAT(CASE WHEN `0090_prtn_amnt_rprtng_entty` <0 AND `0040_typ_uniq_id_knwn_cntrprty` = 'ISIN' THEN X.CHAVE_IT ELSE NULL END, '; ') AS DETALHE FROM (SELECT *, 0020_UNIQ_ID AS CHAVE_IT, 0090_prtn_amnt_rprtng_entty AS CAMPO_IT FROM BU_LOANTAPE_WORK.OUT_B0200_MAIN_LIABILITIES WHERE REF_DATE='"& RefDate &"')X GROUP BY 1
A45: v_2_0006 | B45: 0100_accrd_intrst_instrmnt | C45: 1 | D45: =+VLOOKUP(A45,Descrição!A:K,11,FALSE) -> Alerta: o valor declarado deve ser positivo ou zero. No entanto, juros acumulados negativos são, em princípio, permitidos, se devidamente justificados pela entidade reportante. | E45: "& RefDate &" | F45: REGULAMENTAR | G45: BU_LOANTAPE_WORK.OUT_B0200_MAIN_LIABILITIES | H45: `0100_accrd_intrst_instrmnt` <0 | I45: =+IF(C45=1,0,1) -> 0 | J45: =+IF(C45=0,"THEN NULL ELSE X.CHAVE_IT END","THEN X.CHAVE_IT ELSE NULL END") -> THEN X.CHAVE_IT ELSE NULL END | K45: ="UNION ALL SELECT '"&E45&"' AS REF_DATE, '"&A45&"' AS COD_KPI, '"&F45&"' AS TIPOLOGIA_TESTE, '"&D45&"' AS DESCRIÇÃO, '"&G45&"' AS TABELA, '"&B45&"' AS CAMPO, COUNT(*) AS NUM_REG, SUM(IF("&H45&","&C45&" ,"&I45&")) AS NUM_REG_DIF, GROUP_CONCAT(CASE WHEN "&H45&" "&J45&", '; ') AS DETALHE FROM (SELECT *, 0020_UNIQ_ID AS CHAVE_IT, "&B45&" AS CAMPO_IT FROM "&G45&" WHERE REF_DATE='"&E45&"')X GROUP BY 1" -> UNION ALL SELECT '"& RefDate &"' AS REF_DATE, 'v_2_0006' AS COD_KPI, 'REGULAMENTAR' AS TIPOLOGIA_TESTE, 'Alerta: o valor declarado deve ser positivo ou zero. No entanto, juros acumulados negativos são, em princípio, permitidos, se devidamente justificados pela entidade reportante.' AS DESCRIÇÃO, 'BU_LOANTAPE_WORK.OUT_B0200_MAIN_LIABILITIES' AS TABELA, '0100_accrd_intrst_instrmnt' AS CAMPO, COUNT(*) AS NUM_REG, SUM(IF(`0100_accrd_intrst_instrmnt` <0,1 ,0)) AS NUM_REG_DIF, GROUP_CONCAT(CASE WHEN `0100_accrd_intrst_instrmnt` <0 THEN X.CHAVE_IT ELSE NULL END, '; ') AS DETALHE FROM (SELECT *, 0020_UNIQ_ID AS CHAVE_IT, 0100_accrd_intrst_instrmnt AS CAMPO_IT FROM BU_LOANTAPE_WORK.OUT_B0200_MAIN_LIABILITIES WHERE REF_DATE='"& RefDate &"')X GROUP BY 1
A46: v_2_0007 | B46: 0110_applcbl_fees_charges | C46: 1 | D46: =+VLOOKUP(A46,Descrição!A:K,11,FALSE) -> Alerta: o valor declarado deve ser, em geral, positivo ou zero. | E46: "& RefDate &" | F46: REGULAMENTAR | G46: BU_LOANTAPE_WORK.OUT_B0200_MAIN_LIABILITIES | H46: `0110_applcbl_fees_charges` < 0 | I46: =+IF(C46=1,0,1) -> 0 | J46: =+IF(C46=0,"THEN NULL ELSE X.CHAVE_IT END","THEN X.CHAVE_IT ELSE NULL END") -> THEN X.CHAVE_IT ELSE NULL END | K46: ="UNION ALL SELECT '"&E46&"' AS REF_DATE, '"&A46&"' AS COD_KPI, '"&F46&"' AS TIPOLOGIA_TESTE, '"&D46&"' AS DESCRIÇÃO, '"&G46&"' AS TABELA, '"&B46&"' AS CAMPO, COUNT(*) AS NUM_REG, SUM(IF("&H46&","&C46&" ,"&I46&")) AS NUM_REG_DIF, GROUP_CONCAT(CASE WHEN "&H46&" "&J46&", '; ') AS DETALHE FROM (SELECT *, 0020_UNIQ_ID AS CHAVE_IT, "&B46&" AS CAMPO_IT FROM "&G46&" WHERE REF_DATE='"&E46&"')X GROUP BY 1" -> UNION ALL SELECT '"& RefDate &"' AS REF_DATE, 'v_2_0007' AS COD_KPI, 'REGULAMENTAR' AS TIPOLOGIA_TESTE, 'Alerta: o valor declarado deve ser, em geral, positivo ou zero.' AS DESCRIÇÃO, 'BU_LOANTAPE_WORK.OUT_B0200_MAIN_LIABILITIES' AS TABELA, '0110_applcbl_fees_charges' AS CAMPO, COUNT(*) AS NUM_REG, SUM(IF(`0110_applcbl_fees_charges` < 0,1 ,0)) AS NUM_REG_DIF, GROUP_CONCAT(CASE WHEN `0110_applcbl_fees_charges` < 0 THEN X.CHAVE_IT ELSE NULL END, '; ') AS DETALHE FROM (SELECT *, 0020_UNIQ_ID AS CHAVE_IT, 0110_applcbl_fees_charges AS CAMPO_IT FROM BU_LOANTAPE_WORK.OUT_B0200_MAIN_LIABILITIES WHERE REF_DATE='"& RefDate &"')X GROUP BY 1
A47: v_2_0008 | B47: 0120_otstndng_amnt | C47: 1 | D47: =+VLOOKUP(A47,Descrição!A:K,11,FALSE) -> O valor reportado deve ser positivo. | E47: "& RefDate &" | F47: REGULAMENTAR | G47: BU_LOANTAPE_WORK.OUT_B0200_MAIN_LIABILITIES | H47: `0120_otstndng_amnt` >=0 | I47: =+IF(C47=1,0,1) -> 0 | J47: =+IF(C47=0,"THEN NULL ELSE X.CHAVE_IT END","THEN X.CHAVE_IT ELSE NULL END") -> THEN X.CHAVE_IT ELSE NULL END | K47: ="UNION ALL SELECT '"&E47&"' AS REF_DATE, '"&A47&"' AS COD_KPI, '"&F47&"' AS TIPOLOGIA_TESTE, '"&D47&"' AS DESCRIÇÃO, '"&G47&"' AS TABELA, '"&B47&"' AS CAMPO, COUNT(*) AS NUM_REG, SUM(IF("&H47&","&C47&" ,"&I47&")) AS NUM_REG_DIF, GROUP_CONCAT(CASE WHEN "&H47&" "&J47&", '; ') AS DETALHE FROM (SELECT *, 0020_UNIQ_ID AS CHAVE_IT, "&B47&" AS CAMPO_IT FROM "&G47&" WHERE REF_DATE='"&E47&"')X GROUP BY 1" -> UNION ALL SELECT '"& RefDate &"' AS REF_DATE, 'v_2_0008' AS COD_KPI, 'REGULAMENTAR' AS TIPOLOGIA_TESTE, 'O valor reportado deve ser positivo.' AS DESCRIÇÃO, 'BU_LOANTAPE_WORK.OUT_B0200_MAIN_LIABILITIES' AS TABELA, '0120_otstndng_amnt' AS CAMPO, COUNT(*) AS NUM_REG, SUM(IF(`0120_otstndng_amnt` >=0,1 ,0)) AS NUM_REG_DIF, GROUP_CONCAT(CASE WHEN `0120_otstndng_amnt` >=0 THEN X.CHAVE_IT ELSE NULL END, '; ') AS DETALHE FROM (SELECT *, 0020_UNIQ_ID AS CHAVE_IT, 0120_otstndng_amnt AS CAMPO_IT FROM BU_LOANTAPE_WORK.OUT_B0200_MAIN_LIABILITIES WHERE REF_DATE='"& RefDate &"')X GROUP BY 1
A48: v_2_0009 | B48: 0120_otstndng_amnt | C48: 1 | D48: =+VLOOKUP(A48,Descrição!A:K,11,FALSE) -> O valor declarado deve ser igual a: c0080 + c0100 + c0110. | E48: "& RefDate &" | F48: REGULAMENTAR | G48: BU_LOANTAPE_WORK.OUT_B0200_MAIN_LIABILITIES | H48: `0120_otstndng_amnt` != (`0080_otstndng_prncpl_amnt`+`0100_accrd_intrst_instrmnt`+`0110_applcbl_fees_charges`) | I48: =+IF(C48=1,0,1) -> 0 | J48: =+IF(C48=0,"THEN NULL ELSE X.CHAVE_IT END","THEN X.CHAVE_IT ELSE NULL END") -> THEN X.CHAVE_IT ELSE NULL END | K48: ="UNION ALL SELECT '"&E48&"' AS REF_DATE, '"&A48&"' AS COD_KPI, '"&F48&"' AS TIPOLOGIA_TESTE, '"&D48&"' AS DESCRIÇÃO, '"&G48&"' AS TABELA, '"&B48&"' AS CAMPO, COUNT(*) AS NUM_REG, SUM(IF("&H48&","&C48&" ,"&I48&")) AS NUM_REG_DIF, GROUP_CONCAT(CASE WHEN "&H48&" "&J48&", '; ') AS DETALHE FROM (SELECT *, 0020_UNIQ_ID AS CHAVE_IT, "&B48&" AS CAMPO_IT FROM "&G48&" WHERE REF_DATE='"&E48&"')X GROUP BY 1" -> UNION ALL SELECT '"& RefDate &"' AS REF_DATE, 'v_2_0009' AS COD_KPI, 'REGULAMENTAR' AS TIPOLOGIA_TESTE, 'O valor declarado deve ser igual a: c0080 + c0100 + c0110.' AS DESCRIÇÃO, 'BU_LOANTAPE_WORK.OUT_B0200_MAIN_LIABILITIES' AS TABELA, '0120_otstndng_amnt' AS CAMPO, COUNT(*) AS NUM_REG, SUM(IF(`0120_otstndng_amnt` != (`0080_otstndng_prncpl_amnt`+`0100_accrd_intrst_instrmnt`+`0110_applcbl_fees_charges`),1 ,0)) AS NUM_REG_DIF, GROUP_CONCAT(CASE WHEN `0120_otstndng_amnt` != (`0080_otstndng_prncpl_amnt`+`0100_accrd_intrst_instrmnt`+`0110_applcbl_fees_charges`) THEN X.CHAVE_IT ELSE NULL END, '; ') AS DETALHE FROM (SELECT *, 0020_UNIQ_ID AS CHAVE_IT, 0120_otstndng_amnt AS CAMPO_IT FROM BU_LOANTAPE_WORK.OUT_B0200_MAIN_LIABILITIES WHERE REF_DATE='"& RefDate &"')X GROUP BY 1
A49: v_2_0011 | B49: 0130_rlvnt_amnt_wdc | C49: 1 | D49: =+VLOOKUP(A49,Descrição!A:K,11,FALSE) -> O montante declarado deve ser igual a: c0120 - c0300 - c0320, exceto para Zero Coupon Bonds para as quais se possam aplicar disposições específicas. | E49: "& RefDate &" | F49: REGULAMENTAR | G49: BU_LOANTAPE_WORK.OUT_B0200_MAIN_LIABILITIES | H49: `0130_rlvnt_amnt_wdc` != GREATEST(0, `0120_otstndng_amnt`-`0300_amnt_cvrd_elgbl_dpsts`-`0320_amnt_clltrl`) AND `0250_strctrd_prdct` IN ('Non-structured/Vanilla', 'Other non-standard terms') AND `0240_zero_coupon` != 'ZCB issued at discount' | I49: =+IF(C49=1,0,1) -> 0 | J49: =+IF(C49=0,"THEN NULL ELSE X.CHAVE_IT END","THEN X.CHAVE_IT ELSE NULL END") -> THEN X.CHAVE_IT ELSE NULL END | K49: ="UNION ALL SELECT '"&E49&"' AS REF_DATE, '"&A49&"' AS COD_KPI, '"&F49&"' AS TIPOLOGIA_TESTE, '"&D49&"' AS DESCRIÇÃO, '"&G49&"' AS TABELA, '"&B49&"' AS CAMPO, COUNT(*) AS NUM_REG, SUM(IF("&H49&","&C49&" ,"&I49&")) AS NUM_REG_DIF, GROUP_CONCAT(CASE WHEN "&H49&" "&J49&", '; ') AS DETALHE FROM (SELECT *, 0020_UNIQ_ID AS CHAVE_IT, "&B49&" AS CAMPO_IT FROM "&G49&" WHERE REF_DATE='"&E49&"')X GROUP BY 1" -> UNION ALL SELECT '"& RefDate &"' AS REF_DATE, 'v_2_0011' AS COD_KPI, 'REGULAMENTAR' AS TIPOLOGIA_TESTE, 'O montante declarado deve ser igual a: c0120 - c0300 - c0320, exceto para Zero Coupon Bonds para as quais se possam aplicar disposições específicas.' AS DESCRIÇÃO, 'BU_LOANTAPE_WORK.OUT_B0200_MAIN_LIABILITIES' AS TABELA, '0130_rlvnt_amnt_wdc' AS CAMPO, COUNT(*) AS NUM_REG, SUM(IF(`0130_rlvnt_amnt_wdc` != GREATEST(0, `0120_otstndng_amnt`-`0300_amnt_cvrd_elgbl_dpsts`-`0320_amnt_clltrl`) AND `0250_strctrd_prdct` IN ('Non-structured/Vanilla', 'Other non-standard terms') AND `0240_zero_coupon` != 'ZCB issued at discount',1 ,0)) AS NUM_REG_DIF, GROUP_CONCAT(CASE WHEN `0130_rlvnt_amnt_wdc` != GREATEST(0, `0120_otstndng_amnt`-`0300_amnt_cvrd_elgbl_dpsts`-`0320_amnt_clltrl`) AND `0250_strctrd_prdct` IN ('Non-structured/Vanilla', 'Other non-standard terms') AND `0240_zero_coupon` != 'ZCB issued at discount' THEN X.CHAVE_IT ELSE NULL END, '; ') AS DETALHE FROM (SELECT *, 0020_UNIQ_ID AS CHAVE_IT, 0130_rlvnt_amnt_wdc AS CAMPO_IT FROM BU_LOANTAPE_WORK.OUT_B0200_MAIN_LIABILITIES WHERE REF_DATE='"& RefDate &"')X GROUP BY 1
A50: v_2_0012 | B50: 0130_rlvnt_amnt_wdc | C50: 1 | D50: =+VLOOKUP(A50,Descrição!A:K,11,FALSE) -> Para produtos estruturados, o montante declarado deve ser igual a: (c0270 - c0300 - c0320) se o valor justo for utilizado para apoiar a determinação do montante relevante para o bail-in, OU (c0120 - c0300 - c0320) caso contrário. | E50: "& RefDate &" | F50: REGULAMENTAR | G50: BU_LOANTAPE_WORK.OUT_B0200_MAIN_LIABILITIES | H50: `0130_rlvnt_amnt_wdc` != GREATEST(0, `0270_fv_amnt_strctrd_prdct`-`0300_amnt_cvrd_elgbl_dpsts`-`0320_amnt_clltrl`) AND `0130_rlvnt_amnt_wdc` != GREATEST(0, `0120_otstndng_amnt`-`0300_amnt_cvrd_elgbl_dpsts`-`0320_amnt_clltrl`) AND `0250_strctrd_prdct` IN ('Structured', 'Structured coupon only') | I50: =+IF(C50=1,0,1) -> 0 | J50: =+IF(C50=0,"THEN NULL ELSE X.CHAVE_IT END","THEN X.CHAVE_IT ELSE NULL END") -> THEN X.CHAVE_IT ELSE NULL END | K50: ="UNION ALL SELECT '"&E50&"' AS REF_DATE, '"&A50&"' AS COD_KPI, '"&F50&"' AS TIPOLOGIA_TESTE, '"&D50&"' AS DESCRIÇÃO, '"&G50&"' AS TABELA, '"&B50&"' AS CAMPO, COUNT(*) AS NUM_REG, SUM(IF("&H50&","&C50&" ,"&I50&")) AS NUM_REG_DIF, GROUP_CONCAT(CASE WHEN "&H50&" "&J50&", '; ') AS DETALHE FROM (SELECT *, 0020_UNIQ_ID AS CHAVE_IT, "&B50&" AS CAMPO_IT FROM "&G50&" WHERE REF_DATE='"&E50&"')X GROUP BY 1" -> UNION ALL SELECT '"& RefDate &"' AS REF_DATE, 'v_2_0012' AS COD_KPI, 'REGULAMENTAR' AS TIPOLOGIA_TESTE, 'Para produtos estruturados, o montante declarado deve ser igual a: (c0270 - c0300 - c0320) se o valor justo for utilizado para apoiar a determinação do montante relevante para o bail-in, OU (c0120 - c0300 - c0320) caso contrário.' AS DESCRIÇÃO, 'BU_LOANTAPE_WORK.OUT_B0200_MAIN_LIABILITIES' AS TABELA, '0130_rlvnt_amnt_wdc' AS CAMPO, COUNT(*) AS NUM_REG, SUM(IF(`0130_rlvnt_amnt_wdc` != GREATEST(0, `0270_fv_amnt_strctrd_prdct`-`0300_amnt_cvrd_elgbl_dpsts`-`0320_amnt_clltrl`) AND `0130_rlvnt_amnt_wdc` != GREATEST(0, `0120_otstndng_amnt`-`0300_amnt_cvrd_elgbl_dpsts`-`0320_amnt_clltrl`) AND `0250_strctrd_prdct` IN ('Structured', 'Structured coupon only'),1 ,0)) AS NUM_REG_DIF, GROUP_CONCAT(CASE WHEN `0130_rlvnt_amnt_wdc` != GREATEST(0, `0270_fv_amnt_strctrd_prdct`-`0300_amnt_cvrd_elgbl_dpsts`-`0320_amnt_clltrl`) AND `0130_rlvnt_amnt_wdc` != GREATEST(0, `0120_otstndng_amnt`-`0300_amnt_cvrd_elgbl_dpsts`-`0320_amnt_clltrl`) AND `0250_strctrd_prdct` IN ('Structured', 'Structured coupon only') THEN X.CHAVE_IT ELSE NULL END, '; ') AS DETALHE FROM (SELECT *, 0020_UNIQ_ID AS CHAVE_IT, 0130_rlvnt_amnt_wdc AS CAMPO_IT FROM BU_LOANTAPE_WORK.OUT_B0200_MAIN_LIABILITIES WHERE REF_DATE='"& RefDate &"')X GROUP BY 1
A51: v_2_0013 | B51: 0140_ntr_lblty | C51: 1 | D51: =+VLOOKUP(A51,Descrição!A:K,11,FALSE) -> Os valores dos dropdowns devem ser respeitados. | E51: "& RefDate &" | F51: REGULAMENTAR | G51: BU_LOANTAPE_WORK.OUT_B0200_MAIN_LIABILITIES | H51: `0140_ntr_lblty` NOT IN ('Registered Bond', 'Bearer Bond', 'Borrower Note Loan', 'Certificate of Deposit / Commercial paper', 'Title of ownership', 'Cash account/saving account', 'Term deposit', 'Loan', 'Bill of exchange ', 'Other') | I51: =+IF(C51=1,0,1) -> 0 | J51: =+IF(C51=0,"THEN NULL ELSE X.CHAVE_IT END","THEN X.CHAVE_IT ELSE NULL END") -> THEN X.CHAVE_IT ELSE NULL END | K51: ="UNION ALL SELECT '"&E51&"' AS REF_DATE, '"&A51&"' AS COD_KPI, '"&F51&"' AS TIPOLOGIA_TESTE, '"&D51&"' AS DESCRIÇÃO, '"&G51&"' AS TABELA, '"&B51&"' AS CAMPO, COUNT(*) AS NUM_REG, SUM(IF("&H51&","&C51&" ,"&I51&")) AS NUM_REG_DIF, GROUP_CONCAT(CASE WHEN "&H51&" "&J51&", '; ') AS DETALHE FROM (SELECT *, 0020_UNIQ_ID AS CHAVE_IT, "&B51&" AS CAMPO_IT FROM "&G51&" WHERE REF_DATE='"&E51&"')X GROUP BY 1" -> UNION ALL SELECT '"& RefDate &"' AS REF_DATE, 'v_2_0013' AS COD_KPI, 'REGULAMENTAR' AS TIPOLOGIA_TESTE, 'Os valores dos dropdowns devem ser respeitados.' AS DESCRIÇÃO, 'BU_LOANTAPE_WORK.OUT_B0200_MAIN_LIABILITIES' AS TABELA, '0140_ntr_lblty' AS CAMPO, COUNT(*) AS NUM_REG, SUM(IF(`0140_ntr_lblty` NOT IN ('Registered Bond', 'Bearer Bond', 'Borrower Note Loan', 'Certificate of Deposit / Commercial paper', 'Title of ownership', 'Cash account/saving account', 'Term deposit', 'Loan', 'Bill of exchange ', 'Other'),1 ,0)) AS NUM_REG_DIF, GROUP_CONCAT(CASE WHEN `0140_ntr_lblty` NOT IN ('Registered Bond', 'Bearer Bond', 'Borrower Note Loan', 'Certificate of Deposit / Commercial paper', 'Title of ownership', 'Cash account/saving account', 'Term deposit', 'Loan', 'Bill of exchange ', 'Other') THEN X.CHAVE_IT ELSE NULL END, '; ') AS DETALHE FROM (SELECT *, 0020_UNIQ_ID AS CHAVE_IT, 0140_ntr_lblty AS CAMPO_IT FROM BU_LOANTAPE_WORK.OUT_B0200_MAIN_LIABILITIES WHERE REF_DATE='"& RefDate &"')X GROUP BY 1
A52: v_2_0014 | B52: 0160_rank_insolv | C52: 1 | D52: =+VLOOKUP(A52,Descrição!A:K,11,FALSE) -> Os valores numéricos a partir de 1 devem ser reportados. | E52: "& RefDate &" | F52: REGULAMENTAR | G52: BU_LOANTAPE_WORK.OUT_B0200_MAIN_LIABILITIES | H52: CAST(`0160_rank_insolv` AS STRING) NOT REGEXP '^-?[0-9]+$' | I52: =+IF(C52=1,0,1) -> 0 | J52: =+IF(C52=0,"THEN NULL ELSE X.CHAVE_IT END","THEN X.CHAVE_IT ELSE NULL END") -> THEN X.CHAVE_IT ELSE NULL END | K52: ="UNION ALL SELECT '"&E52&"' AS REF_DATE, '"&A52&"' AS COD_KPI, '"&F52&"' AS TIPOLOGIA_TESTE, '"&D52&"' AS DESCRIÇÃO, '"&G52&"' AS TABELA, '"&B52&"' AS CAMPO, COUNT(*) AS NUM_REG, SUM(IF("&H52&","&C52&" ,"&I52&")) AS NUM_REG_DIF, GROUP_CONCAT(CASE WHEN "&H52&" "&J52&", '; ') AS DETALHE FROM (SELECT *, 0020_UNIQ_ID AS CHAVE_IT, "&B52&" AS CAMPO_IT FROM "&G52&" WHERE REF_DATE='"&E52&"')X GROUP BY 1" -> UNION ALL SELECT '"& RefDate &"' AS REF_DATE, 'v_2_0014' AS COD_KPI, 'REGULAMENTAR' AS TIPOLOGIA_TESTE, 'Os valores numéricos a partir de 1 devem ser reportados.' AS DESCRIÇÃO, 'BU_LOANTAPE_WORK.OUT_B0200_MAIN_LIABILITIES' AS TABELA, '0160_rank_insolv' AS CAMPO, COUNT(*) AS NUM_REG, SUM(IF(CAST(`0160_rank_insolv` AS STRING) NOT REGEXP '^-?[0-9]+$',1 ,0)) AS NUM_REG_DIF, GROUP_CONCAT(CASE WHEN CAST(`0160_rank_insolv` AS STRING) NOT REGEXP '^-?[0-9]+$' THEN X.CHAVE_IT ELSE NULL END, '; ') AS DETALHE FROM (SELECT *, 0020_UNIQ_ID AS CHAVE_IT, 0160_rank_insolv AS CAMPO_IT FROM BU_LOANTAPE_WORK.OUT_B0200_MAIN_LIABILITIES WHERE REF_DATE='"& RefDate &"')X GROUP BY 1
... A55: v_2_0017 | B55: 0180_dt_nxt_intrst_pymnt | C55: 1 | D55: =+VLOOKUP(A55,Descrição!A:K,11,FALSE) -> O valor reportado deve ser uma data (yyy-mm-dd). | E55: "& RefDate &" | F55: REGULAMENTAR | G55: BU_LOANTAPE_WORK.OUT_B0200_MAIN_LIABILITIES | H55: `0180_dt_nxt_intrst_pymnt` NOT REGEXP '^[0-9]{4}-[0-9]{2}-[0-9]{2}$' AND `0020_uniq_id` NOT IN ('NCNP', 'NCBP') | I55: =+IF(C55=1,0,1) -> 0 | J55: =+IF(C55=0,"THEN NULL ELSE X.CHAVE_IT END","THEN X.CHAVE_IT ELSE NULL END") -> THEN X.CHAVE_IT ELSE NULL END | K55: ="UNION ALL SELECT '"&E55&"' AS REF_DATE, '"&A55&"' AS COD_KPI, '"&F55&"' AS TIPOLOGIA_TESTE, '"&D55&"' AS DESCRIÇÃO, '"&G55&"' AS TABELA, '"&B55&"' AS CAMPO, COUNT(*) AS NUM_REG, SUM(IF("&H55&","&C55&" ,"&I55&")) AS NUM_REG_DIF, GROUP_CONCAT(CASE WHEN "&H55&" "&J55&", '; ') AS DETALHE FROM (SELECT *, 0020_UNIQ_ID AS CHAVE_IT, "&B55&" AS CAMPO_IT FROM "&G55&" WHERE REF_DATE='"&E55&"')X GROUP BY 1" -> UNION ALL SELECT '"& RefDate &"' AS REF_DATE, 'v_2_0017' AS COD_KPI, 'REGULAMENTAR' AS TIPOLOGIA_TESTE, 'O valor reportado deve ser uma data (yyy-mm-dd).' AS DESCRIÇÃO, 'BU_LOANTAPE_WORK.OUT_B0200_MAIN_LIABILITIES' AS TABELA, '0180_dt_nxt_intrst_pymnt' AS CAMPO, COUNT(*) AS NUM_REG, SUM(IF(`0180_dt_nxt_intrst_pymnt` NOT REGEXP '^[0-9]{4}-[0-9]{2}-[0-9]{2}$' AND `0020_uniq_id` NOT IN ('NCNP', 'NCBP'),1 ,0)) AS NUM_REG_DIF, GROUP_CONCAT(CASE WHEN `0180_dt_nxt_intrst_pymnt` NOT REGEXP '^[0-9]{4}-[0-9]{2}-[0-9]{2}$' AND `0020_uniq_id` NOT IN ('NCNP', 'NCBP') THEN X.CHAVE_IT ELSE NULL END, '; ') AS DETALHE FROM (SELECT *, 0020_UNIQ_ID AS CHAVE_IT, 0180_dt_nxt_intrst_pymnt AS CAMPO_IT FROM BU_LOANTAPE_WORK.OUT_B0200_MAIN_LIABILITIES WHERE REF_DATE='"& RefDate &"')X GROUP BY 1
A56: v_2_0018 | B56: 0180_dt_nxt_intrst_pymnt | C56: 0 | D56: =+VLOOKUP(A56,Descrição!A:K,11,FALSE) -> O valor declarado deve ser posterior à data de referência reportada em B99.00 (c0070). | E56: "& RefDate &" | F56: REGULAMENTAR | G56: BU_LOANTAPE_WORK.OUT_B0200_MAIN_LIABILITIES | H56: (`0180_dt_nxt_intrst_pymnt` > `0070_cntrct_crrncy` AND `0070_cntrct_crrncy` != '' AND `0020_uniq_id` NOT IN ('NCNP', 'NCBP')) OR `0180_dt_nxt_intrst_pymnt` IN ('0001-01-01', '') | I56: =+IF(C56=1,0,1) -> 1 | J56: =+IF(C56=0,"THEN NULL ELSE X.CHAVE_IT END","THEN X.CHAVE_IT ELSE NULL END") -> THEN NULL ELSE X.CHAVE_IT END | K56: ="--UNION ALL SELECT '"&E56&"' AS REF_DATE, '"&A56&"' AS COD_KPI, '"&F56&"' AS TIPOLOGIA_TESTE, '"&D56&"' AS DESCRIÇÃO, '"&G56&"' AS TABELA, '"&B56&"' AS CAMPO, COUNT(*) AS NUM_REG, SUM(IF("&H56&","&C56&" ,"&I56&")) AS NUM_REG_DIF, GROUP_CONCAT(CASE WHEN "&H56&" "&J56&", '; ') AS DETALHE FROM (SELECT *, 0020_UNIQ_ID AS CHAVE_IT, "&B56&" AS CAMPO_IT FROM "&G56&" WHERE REF_DATE='"&E56&"')X GROUP BY 1" -> --UNION ALL SELECT '"& RefDate &"' AS REF_DATE, 'v_2_0018' AS COD_KPI, 'REGULAMENTAR' AS TIPOLOGIA_TESTE, 'O valor declarado deve ser posterior à data de referência reportada em B99.00 (c0070).' AS DESCRIÇÃO, 'BU_LOANTAPE_WORK.OUT_B0200_MAIN_LIABILITIES' AS TABELA, '0180_dt_nxt_intrst_pymnt' AS CAMPO, COUNT(*) AS NUM_REG, SUM(IF((`0180_dt_nxt_intrst_pymnt` > `0070_cntrct_crrncy` AND `0070_cntrct_crrncy` != '' AND `0020_uniq_id` NOT IN ('NCNP', 'NCBP')) OR `0180_dt_nxt_intrst_pymnt` IN ('0001-01-01', ''),0 ,1)) AS NUM_REG_DIF, GROUP_CONCAT(CASE WHEN (`0180_dt_nxt_intrst_pymnt` > `0070_cntrct_crrncy` AND `0070_cntrct_crrncy` != '' AND `0020_uniq_id` NOT IN ('NCNP', 'NCBP')) OR `0180_dt_nxt_intrst_pymnt` IN ('0001-01-01', '') THEN NULL ELSE X.CHAVE_IT END, '; ') AS DETALHE FROM (SELECT *, 0020_UNIQ_ID AS CHAVE_IT, 0180_dt_nxt_intrst_pymnt AS CAMPO_IT FROM BU_LOANTAPE_WORK.OUT_B0200_MAIN_LIABILITIES WHERE REF_DATE='"& RefDate &"')X GROUP BY 1
A57: v_2_0019 | B57: 0200_dt_erlst_rdmptn | C57: 1 | D57: =+VLOOKUP(A57,Descrição!A:K,11,FALSE) -> O valor reportado deve ser uma data (yyy-mm-dd). | E57: "& RefDate &" | F57: REGULAMENTAR | G57: BU_LOANTAPE_WORK.OUT_B0200_MAIN_LIABILITIES | H57: `0200_dt_erlst_rdmptn` NOT REGEXP '^[0-9]{4}-[0-9]{2}-[0-9]{2}$' AND `0020_uniq_id` NOT IN ('NCNP', 'NCBP') | I57: =+IF(C57=1,0,1) -> 0 | J57: =+IF(C57=0,"THEN NULL ELSE X.CHAVE_IT END","THEN X.CHAVE_IT ELSE NULL END") -> THEN X.CHAVE_IT ELSE NULL END | K57: ="UNION ALL SELECT '"&E57&"' AS REF_DATE, '"&A57&"' AS COD_KPI, '"&F57&"' AS TIPOLOGIA_TESTE, '"&D57&"' AS DESCRIÇÃO, '"&G57&"' AS TABELA, '"&B57&"' AS CAMPO, COUNT(*) AS NUM_REG, SUM(IF("&H57&","&C57&" ,"&I57&")) AS NUM_REG_DIF, GROUP_CONCAT(CASE WHEN "&H57&" "&J57&", '; ') AS DETALHE FROM (SELECT *, 0020_UNIQ_ID AS CHAVE_IT, "&B57&" AS CAMPO_IT FROM "&G57&" WHERE REF_DATE='"&E57&"')X GROUP BY 1" -> UNION ALL SELECT '"& RefDate &"' AS REF_DATE, 'v_2_0019' AS COD_KPI, 'REGULAMENTAR' AS TIPOLOGIA_TESTE, 'O valor reportado deve ser uma data (yyy-mm-dd).' AS DESCRIÇÃO, 'BU_LOANTAPE_WORK.OUT_B0200_MAIN_LIABILITIES' AS TABELA, '0200_dt_erlst_rdmptn' AS CAMPO, COUNT(*) AS NUM_REG, SUM(IF(`0200_dt_erlst_rdmptn` NOT REGEXP '^[0-9]{4}-[0-9]{2}-[0-9]{2}$' AND `0020_uniq_id` NOT IN ('NCNP', 'NCBP'),1 ,0)) AS NUM_REG_DIF, GROUP_CONCAT(CASE WHEN `0200_dt_erlst_rdmptn` NOT REGEXP '^[0-9]{4}-[0-9]{2}-[0-9]{2}$' AND `0020_uniq_id` NOT IN ('NCNP', 'NCBP') THEN X.CHAVE_IT ELSE NULL END, '; ') AS DETALHE FROM (SELECT *, 0020_UNIQ_ID AS CHAVE_IT, 0200_dt_erlst_rdmptn AS CAMPO_IT FROM BU_LOANTAPE_WORK.OUT_B0200_MAIN_LIABILITIES WHERE REF_DATE='"& RefDate &"')X GROUP BY 1
