Workbook

Sheet Level 1
A1: v_1_0001 | B1: MBDT - Level 1 Validation Rules: completeness checks. | U1: utilizar union all's (HF) | V1: utilizar case when's
B2: Check ID | C2: Tab | D2: Data point (Row/Column) | E2: Data point (Label) | F2: Data point type | G2: High severity (i.e the validation rule should in general not be breached) | H2: Warning only (i.e. the validation rule can be breached in certain cases) | I2: Type of test (missing values means "not applicable" or "not available") | J2: Prerequisite / Dependency | K2: Explanation | L2: AUX_ALERT | M2: AUX_TAB | N2: AUX_FIELD1 | O2: FIELD2 | P2: AUX_FIELD2 | Q2: FIELD3 | R2: AUX_FIELD3 | S2: FIELD4 | T2: AUX_FIELD4 | U2: OPTION 1 | V2: OPTION 2
A3: 0001 | B3: =CONCATENATE("v_1_",A3) -> v_1_0001 | C3: B02.00 | D3: =VLOOKUP(CONCATENATE(C3,"_",E3),'Data types'!A:E,4,FALSE) -> 0010 | E3: Row number | F3: =VLOOKUP(CONCATENATE(C3,"_",E3),'Data types'!A:F,6,FALSE) -> Numeric: Integer | G3: X | I3: Test for missing values. | K3: Missing value. The field must be reported. | L3: =+IF(G3="X","HIGH","WARNING") -> HIGH | M3: =+LEFT(C3,3) -> B02 | N3: ="`"&VLOOKUP(D3,'B02_Mapping fields'!B:C,2,FALSE)&"`" -> `0010_row_nmbr` | U3: =+",SELECT '"&M3&"' AS TAB, '"&L3&"' AS ALERT_TYPE, '"&B3&"' AS CHECK_ID, ROW_NUMBER, CASE WHEN A.ISSUES >0 THEN 1 ELSE 0 END AS "&B3&" FROM (SELECT COUNT(*) AS ISSUES FROM "&M3&" WHERE "&M3&"."&D3&" IS MISSING) AS A;" -> ,SELECT 'B02' AS TAB, 'HIGH' AS ALERT_TYPE, 'v_1_0001' AS CHECK_ID, ROW_NUMBER, CASE WHEN A.ISSUES >0 THEN 1 ELSE 0 END AS v_1_0001 FROM (SELECT COUNT(*) AS ISSUES FROM B02 WHERE B02.0010 IS MISSING) AS A; | V3: =+",CASE WHEN "&N3&" IS MISSING THEN 1 ELSE 0 END AS "&B3 -> ,CASE WHEN `0010_row_nmbr` IS MISSING THEN 1 ELSE 0 END AS v_1_0001 | W3: =+"SUM("&B3&") AS LVL1_H_"&MID(N3,2,LEN(N3)-2)&"," -> SUM(v_1_0001) AS LVL1_H_0010_row_nmbr,
A4: 0002 | B4: =CONCATENATE("v_1_",A4) -> v_1_0002 | C4: B02.00 | D4: =VLOOKUP(CONCATENATE(C4,"_",E4),'Data types'!A:E,4,FALSE) -> 0030 | E4: Unique identification number (known to the counterparty) | F4: =VLOOKUP(CONCATENATE(C4,"_",E4),'Data types'!A:F,6,FALSE) -> String: Free text | G4: X | I4: Test for missing values. | K4: Missing value. The field must be reported. | L4: =+IF(G4="X","HIGH","WARNING") -> HIGH | M4: =+LEFT(C4,3) -> B02 | N4: ="`"&VLOOKUP(D4,'B02_Mapping fields'!B:C,2,FALSE)&"`" -> `0030_uniq_id_knwn_cntrprty` | U4: =+",SELECT '"&M4&"' AS TAB, '"&L4&"' AS ALERT_TYPE, '"&B4&"' AS CHECK_ID, ROW_NUMBER, CASE WHEN A.ISSUES >0 THEN 1 ELSE 0 END AS "&B4&" FROM (SELECT COUNT(*) AS ISSUES FROM "&M4&" WHERE "&M4&"."&D4&" IS MISSING) AS A;" -> ,SELECT 'B02' AS TAB, 'HIGH' AS ALERT_TYPE, 'v_1_0002' AS CHECK_ID, ROW_NUMBER, CASE WHEN A.ISSUES >0 THEN 1 ELSE 0 END AS v_1_0002 FROM (SELECT COUNT(*) AS ISSUES FROM B02 WHERE B02.0030 IS MISSING) AS A; | V4: =+",CASE WHEN "&N4&" IS MISSING THEN 1 ELSE 0 END AS "&B4 -> ,CASE WHEN `0030_uniq_id_knwn_cntrprty` IS MISSING THEN 1 ELSE 0 END AS v_1_0002 | W4: =+"SUM("&B4&") AS LVL1_H_"&MID(N4,2,LEN(N4)-2)&"," -> SUM(v_1_0002) AS LVL1_H_0030_uniq_id_knwn_cntrprty,
A5: 0003 | B5: =CONCATENATE("v_1_",A5) -> v_1_0003 | C5: B02.00 | D5: =VLOOKUP(CONCATENATE(C5,"_",E5),'Data types'!A:E,4,FALSE) -> 0040 | E5: Type of the unique identifier (known to the counterparty) | F5: =VLOOKUP(CONCATENATE(C5,"_",E5),'Data types'!A:F,6,FALSE) -> String: Free text, but fixed values for specific items | G5: X | I5: Test for missing values. | K5: Missing value. The field must be reported. | L5: =+IF(G5="X","HIGH","WARNING") -> HIGH | M5: =+LEFT(C5,3) -> B02 | N5: ="`"&VLOOKUP(D5,'B02_Mapping fields'!B:C,2,FALSE)&"`" -> `0040_typ_uniq_id_knwn_cntrprty` | U5: =+",SELECT '"&M5&"' AS TAB, '"&L5&"' AS ALERT_TYPE, '"&B5&"' AS CHECK_ID, ROW_NUMBER, CASE WHEN A.ISSUES >0 THEN 1 ELSE 0 END AS "&B5&" FROM (SELECT COUNT(*) AS ISSUES FROM "&M5&" WHERE "&M5&"."&D5&" IS MISSING) AS A;" -> ,SELECT 'B02' AS TAB, 'HIGH' AS ALERT_TYPE, 'v_1_0003' AS CHECK_ID, ROW_NUMBER, CASE WHEN A.ISSUES >0 THEN 1 ELSE 0 END AS v_1_0003 FROM (SELECT COUNT(*) AS ISSUES FROM B02 WHERE B02.0040 IS MISSING) AS A; | V5: =+",CASE WHEN "&N5&" IS MISSING THEN 1 ELSE 0 END AS "&B5 -> ,CASE WHEN `0040_typ_uniq_id_knwn_cntrprty` IS MISSING THEN 1 ELSE 0 END AS v_1_0003 | W5: =+"SUM("&B5&") AS LVL1_H_"&MID(N5,2,LEN(N5)-2)&"," -> SUM(v_1_0003) AS LVL1_H_0040_typ_uniq_id_knwn_cntrprty,
A6: 0004 | B6: =CONCATENATE("v_1_",A6) -> v_1_0004 | C6: B02.00 | D6: =VLOOKUP(CONCATENATE(C6,"_",E6),'Data types'!A:E,4,FALSE) -> 0070 | E6: Contract Currency | F6: =VLOOKUP(CONCATENATE(C6,"_",E6),'Data types'!A:F,6,FALSE) -> String: 3-letters ISO 4217 | G6: X | I6: Test for missing values. | K6: Missing value. The field must be reported. | L6: =+IF(G6="X","HIGH","WARNING") -> HIGH | M6: =+LEFT(C6,3) -> B02 | N6: ="`"&VLOOKUP(D6,'B02_Mapping fields'!B:C,2,FALSE)&"`" -> `0070_cntrct_crrncy` | U6: =+",SELECT '"&M6&"' AS TAB, '"&L6&"' AS ALERT_TYPE, '"&B6&"' AS CHECK_ID, ROW_NUMBER, CASE WHEN A.ISSUES >0 THEN 1 ELSE 0 END AS "&B6&" FROM (SELECT COUNT(*) AS ISSUES FROM "&M6&" WHERE "&M6&"."&D6&" IS MISSING) AS A;" -> ,SELECT 'B02' AS TAB, 'HIGH' AS ALERT_TYPE, 'v_1_0004' AS CHECK_ID, ROW_NUMBER, CASE WHEN A.ISSUES >0 THEN 1 ELSE 0 END AS v_1_0004 FROM (SELECT COUNT(*) AS ISSUES FROM B02 WHERE B02.0070 IS MISSING) AS A; | V6: =+",CASE WHEN "&N6&" IS MISSING THEN 1 ELSE 0 END AS "&B6 -> ,CASE WHEN `0070_cntrct_crrncy` IS MISSING THEN 1 ELSE 0 END AS v_1_0004 | W6: =+"SUM("&B6&") AS LVL1_H_"&MID(N6,2,LEN(N6)-2)&"," -> SUM(v_1_0004) AS LVL1_H_0070_cntrct_crrncy,
A7: 0005 | B7: =CONCATENATE("v_1_",A7) -> v_1_0005 | C7: B02.00 | D7: =VLOOKUP(CONCATENATE(C7,"_",E7),'Data types'!A:E,4,FALSE) -> 0080 | E7: Outstanding principal amount | F7: =VLOOKUP(CONCATENATE(C7,"_",E7),'Data types'!A:F,6,FALSE) -> Numeric: 2 decimals | G7: X | I7: Test for missing values. | J7: Rule applicable if c0250 = ("Non-Structured/Vanilla" OR "Other non-standard terms") | K7: Missing value. The field must be reported for non-structured liabilities. | L7: =+IF(G7="X","HIGH","WARNING") -> HIGH | M7: =+LEFT(C7,3) -> B02 | N7: ="`"&VLOOKUP(D7,'B02_Mapping fields'!B:C,2,FALSE)&"`" -> `0080_otstndng_prncpl_amnt` | O7: 0250 | P7: ="`"&VLOOKUP(O7,'B02_Mapping fields'!B:C,2,FALSE)&"`" -> `0250_strctrd_prdct` | U7: =+",SELECT '"&M7&"' AS TAB, '"&L7&"' AS ALERT_TYPE, '"&B7&"' AS CHECK_ID, ROW_NUMBER, CASE WHEN A.ISSUES >0 THEN 1 ELSE 0 END AS "&B7&" FROM (SELECT COUNT(*) AS ISSUES FROM "&M7&" WHERE "&M7&"."&D7&" IS MISSING AND c0250 IN ('Non-Structured/Vanilla', 'Other non-standard terms')) AS A;" -> ,SELECT 'B02' AS TAB, 'HIGH' AS ALERT_TYPE, 'v_1_0005' AS CHECK_ID, ROW_NUMBER, CASE WHEN A.ISSUES >0 THEN 1 ELSE 0 END AS v_1_0005 FROM (SELECT COUNT(*) AS ISSUES FROM B02 WHERE B02.0080 IS MISSING AND c0250 IN ('Non-Structured/Vanilla', 'Other non-standard terms')) AS A; | V7: =+",CASE WHEN "&N7&" IS MISSING AND "&P7&" IN ('Non-Structured/Vanilla', 'Other non-standard terms') THEN 1 ELSE 0 END AS "&B7 -> ,CASE WHEN `0080_otstndng_prncpl_amnt` IS MISSING AND `0250_strctrd_prdct` IN ('Non-Structured/Vanilla', 'Other non-standard terms') THEN 1 ELSE 0 END AS v_1_0005 | W7: =+"SUM("&B7&") AS LVL1_H_"&MID(N7,2,LEN(N7)-2)&"," -> SUM(v_1_0005) AS LVL1_H_0080_otstndng_prncpl_amnt,
A8: 0006 | B8: =CONCATENATE("v_1_",A8) -> v_1_0006 | C8: B02.00 | D8: =VLOOKUP(CONCATENATE(C8,"_",E8),'Data types'!A:E,4,FALSE) -> 0080 | E8: Outstanding principal amount | F8: =VLOOKUP(CONCATENATE(C8,"_",E8),'Data types'!A:F,6,FALSE) -> Numeric: 2 decimals | H8: X | I8: Test for missing values. | J8: Rule applicable if c0250 = ("Structured" OR "Only structured coupon") | K8: Missing value (warning only). For structured liabilities, the field has to be reported if the information exists. | L8: =+IF(G8="X","HIGH","WARNING") -> WARNING | M8: =+LEFT(C8,3) -> B02 | N8: ="`"&VLOOKUP(D8,'B02_Mapping fields'!B:C,2,FALSE)&"`" -> `0080_otstndng_prncpl_amnt` | O8: 0250 | P8: ="`"&VLOOKUP(O8,'B02_Mapping fields'!B:C,2,FALSE)&"`" -> `0250_strctrd_prdct` | U8: =+",SELECT '"&M8&"' AS TAB, '"&L8&"' AS ALERT_TYPE, '"&B8&"' AS CHECK_ID, ROW_NUMBER, CASE WHEN A.ISSUES >0 THEN 1 ELSE 0 END AS "&B8&" FROM (SELECT COUNT(*) AS ISSUES FROM "&M8&" WHERE "&M8&"."&D8&" IS MISSING AND c0250 IN ('Structured', 'Only structured coupon')) AS A;" -> ,SELECT 'B02' AS TAB, 'WARNING' AS ALERT_TYPE, 'v_1_0006' AS CHECK_ID, ROW_NUMBER, CASE WHEN A.ISSUES >0 THEN 1 ELSE 0 END AS v_1_0006 FROM (SELECT COUNT(*) AS ISSUES FROM B02 WHERE B02.0080 IS MISSING AND c0250 IN ('Structured', 'Only structured coupon')) AS A; | V8: =+",CASE WHEN "&N8&" IS MISSING AND "&P8&" IN ('Structured', 'Only structured coupon') THEN 1 ELSE 0 END AS "&B8 -> ,CASE WHEN `0080_otstndng_prncpl_amnt` IS MISSING AND `0250_strctrd_prdct` IN ('Structured', 'Only structured coupon') THEN 1 ELSE 0 END AS v_1_0006 | W8: =+"SUM("&B8&") AS LVL1_W_"&MID(N8,2,LEN(N8)-2)&"," -> SUM(v_1_0006) AS LVL1_W_0080_otstndng_prncpl_amnt,
A9: 0007 | B9: =CONCATENATE("v_1_",A9) -> v_1_0007 | C9: B02.00 | D9: =VLOOKUP(CONCATENATE(C9,"_",E9),'Data types'!A:E,4,FALSE) -> 0090 | E9: Portion of instrument or liability held by the reporting entity | F9: =VLOOKUP(CONCATENATE(C9,"_",E9),'Data types'!A:F,6,FALSE) -> Numeric: 2 decimals | G9: X | I9: Test for missing values. | J9: Rule applicable only if c0040 = "ISIN" | K9: Missing value. The field must be reported for securities. | L9: =+IF(G9="X","HIGH","WARNING") -> HIGH | M9: =+LEFT(C9,3) -> B02 | N9: ="`"&VLOOKUP(D9,'B02_Mapping fields'!B:C,2,FALSE)&"`" -> `0090_prtn_amnt_rprtng_entty` | O9: 0040 | P9: ="`"&VLOOKUP(O9,'B02_Mapping fields'!B:C,2,FALSE)&"`" -> `0040_typ_uniq_id_knwn_cntrprty` | U9: =+",SELECT '"&M9&"' AS TAB, '"&L9&"' AS ALERT_TYPE, '"&B9&"' AS CHECK_ID, ROW_NUMBER, CASE WHEN A.ISSUES >0 THEN 1 ELSE 0 END AS "&B9&" FROM (SELECT COUNT(*) AS ISSUES FROM "&M9&" WHERE "&M9&"."&D9&" IS MISSING AND c0040 = 'ISIN') AS A;" -> ,SELECT 'B02' AS TAB, 'HIGH' AS ALERT_TYPE, 'v_1_0007' AS CHECK_ID, ROW_NUMBER, CASE WHEN A.ISSUES >0 THEN 1 ELSE 0 END AS v_1_0007 FROM (SELECT COUNT(*) AS ISSUES FROM B02 WHERE B02.0090 IS MISSING AND c0040 = 'ISIN') AS A; | V9: =+",CASE WHEN "&N9&" IS MISSING AND "&P9&" = 'ISIN' THEN 1 ELSE 0 END AS "&B9 -> ,CASE WHEN `0090_prtn_amnt_rprtng_entty` IS MISSING AND `0040_typ_uniq_id_knwn_cntrprty` = 'ISIN' THEN 1 ELSE 0 END AS v_1_0007 | W9: =+"SUM("&B9&") AS LVL1_H_"&MID(N9,2,LEN(N9)-2)&"," -> SUM(v_1_0007) AS LVL1_H_0090_prtn_amnt_rprtng_entty,
A10: 0008 | B10: =CONCATENATE("v_1_",A10) -> v_1_0008 | C10: B02.00 | D10: =VLOOKUP(CONCATENATE(C10,"_",E10),'Data types'!A:E,4,FALSE) -> 0100 | E10: Accrued interest | F10: =VLOOKUP(CONCATENATE(C10,"_",E10),'Data types'!A:F,6,FALSE) -> Numeric: 2 decimals | G10: X | I10: Test for missing values. | J10: Rule applicable if c0250 = ("Non-Structured" OR "Other non-standard terms") AND c0240 != "ZCB issued at discount" | K10: Missing value. For non-structured liabilities that are not zero coupon bonds issued at discount, this field must be reported. | L10: =+IF(G10="X","HIGH","WARNING") -> HIGH | M10: =+LEFT(C10,3) -> B02 | N10: ="`"&VLOOKUP(D10,'B02_Mapping fields'!B:C,2,FALSE)&"`" -> `0100_accrd_intrst_instrmnt` | O10: 0250 | P10: ="`"&VLOOKUP(O10,'B02_Mapping fields'!B:C,2,FALSE)&"`" -> `0250_strctrd_prdct` | Q10: 0240 | R10: ="`"&VLOOKUP(Q10,'B02_Mapping fields'!B:C,2,FALSE)&"`" -> `0240_zero_coupon` | U10: =+",SELECT '"&M10&"' AS TAB, '"&L10&"' AS ALERT_TYPE, '"&B10&"' AS CHECK_ID, ROW_NUMBER, CASE WHEN A.ISSUES >0 THEN 1 ELSE 0 END AS "&B10&" FROM (SELECT COUNT(*) AS ISSUES FROM "&M10&" WHERE "&M10&"."&D10&" IS MISSING AND c0250 IN ('Non-Structured', 'Other non-standard terms') AND c0240 != 'ZCB issued at discount') AS A;" -> ,SELECT 'B02' AS TAB, 'HIGH' AS ALERT_TYPE, 'v_1_0008' AS CHECK_ID, ROW_NUMBER, CASE WHEN A.ISSUES >0 THEN 1 ELSE 0 END AS v_1_0008 FROM (SELECT COUNT(*) AS ISSUES FROM B02 WHERE B02.0100 IS MISSING AND c0250 IN ('Non-Structured', 'Other non-standard terms') AND c0240 != 'ZCB issued at discount') AS A; | V10: =+",CASE WHEN "&N10&" IS MISSING AND "&P10&" IN ('Non-Structured', 'Other non-standard terms') AND "&R10&" != 'ZCB issued at discount' THEN 1 ELSE 0 END AS "&B10 -> ,CASE WHEN `0100_accrd_intrst_instrmnt` IS MISSING AND `0250_strctrd_prdct` IN ('Non-Structured', 'Other non-standard terms') AND `0240_zero_coupon` != 'ZCB issued at discount' THEN 1 ELSE 0 END AS v_1_0008 | W10: =+"SUM("&B10&") AS LVL1_H_"&MID(N10,2,LEN(N10)-2)&"," -> SUM(v_1_0008) AS LVL1_H_0100_accrd_intrst_instrmnt,
A11: 0009 | B11: =CONCATENATE("v_1_",A11) -> v_1_0009 | C11: B02.00 | D11: =VLOOKUP(CONCATENATE(C11,"_",E11),'Data types'!A:E,4,FALSE) -> 0100 | E11: Accrued interest | F11: =VLOOKUP(CONCATENATE(C11,"_",E11),'Data types'!A:F,6,FALSE) -> Numeric: 2 decimals | H11: X | I11: Test for missing values. | J11: Rule applicable only if c0250 != ("Structured" OR "Only structured coupon") | K11: Missing value (warning only). For structured liabilities, the field has to be reported if the information exists. | L11: =+IF(G11="X","HIGH","WARNING") -> WARNING | M11: =+LEFT(C11,3) -> B02 | N11: ="`"&VLOOKUP(D11,'B02_Mapping fields'!B:C,2,FALSE)&"`" -> `0100_accrd_intrst_instrmnt` | O11: 0250 | P11: ="`"&VLOOKUP(O11,'B02_Mapping fields'!B:C,2,FALSE)&"`" -> `0250_strctrd_prdct` | U11: =+",SELECT '"&M11&"' AS TAB, '"&L11&"' AS ALERT_TYPE, '"&B11&"' AS CHECK_ID, ROW_NUMBER, CASE WHEN A.ISSUES >0 THEN 1 ELSE 0 END AS "&B11&" FROM (SELECT COUNT(*) AS ISSUES FROM "&M11&" WHERE "&M11&"."&D11&" IS MISSING AND c0250 IN ('Structured', 'Only structured coupon')) AS A;" -> ,SELECT 'B02' AS TAB, 'WARNING' AS ALERT_TYPE, 'v_1_0009' AS CHECK_ID, ROW_NUMBER, CASE WHEN A.ISSUES >0 THEN 1 ELSE 0 END AS v_1_0009 FROM (SELECT COUNT(*) AS ISSUES FROM B02 WHERE B02.0100 IS MISSING AND c0250 IN ('Structured', 'Only structured coupon')) AS A; | V11: =+",CASE WHEN "&N11&" IS MISSING AND "&P11&" IN ('Structured', 'Only structured coupon') THEN 1 ELSE 0 END AS "&B11 -> ,CASE WHEN `0100_accrd_intrst_instrmnt` IS MISSING AND `0250_strctrd_prdct` IN ('Structured', 'Only structured coupon') THEN 1 ELSE 0 END AS v_1_0009 | W11: =+"SUM("&B11&") AS LVL1_W_"&MID(N11,2,LEN(N11)-2)&"," -> SUM(v_1_0009) AS LVL1_W_0100_accrd_intrst_instrmnt,
A12: 0010 | B12: =CONCATENATE("v_1_",A12) -> v_1_0010 | C12: B02.00 | D12: =VLOOKUP(CONCATENATE(C12,"_",E12),'Data types'!A:E,4,FALSE) -> 0120 | E12: Outstanding amount | F12: =VLOOKUP(CONCATENATE(C12,"_",E12),'Data types'!A:F,6,FALSE) -> Numeric: 2 decimals | G12: X | I12: Test for missing values. | J12: Rule applicable if c0250 = ("Non-Structured/Vanilla" OR "Other non-standard terms") | K12: Missing value. For non-structured liabilities, this field must be reported. | L12: =+IF(G12="X","HIGH","WARNING") -> HIGH | M12: =+LEFT(C12,3) -> B02 | N12: ="`"&VLOOKUP(D12,'B02_Mapping fields'!B:C,2,FALSE)&"`" -> `0120_otstndng_amnt` | O12: 0250 | P12: ="`"&VLOOKUP(O12,'B02_Mapping fields'!B:C,2,FALSE)&"`" -> `0250_strctrd_prdct` | U12: =+",SELECT '"&M12&"' AS TAB, '"&L12&"' AS ALERT_TYPE, '"&B12&"' AS CHECK_ID, ROW_NUMBER, CASE WHEN A.ISSUES >0 THEN 1 ELSE 0 END AS "&B12&" FROM (SELECT COUNT(*) AS ISSUES FROM "&M12&" WHERE "&M12&"."&D12&" IS MISSING AND c0250 IN ('Non-Structured/Vanilla', 'Other non-standard terms')) AS A;" -> ,SELECT 'B02' AS TAB, 'HIGH' AS ALERT_TYPE, 'v_1_0010' AS CHECK_ID, ROW_NUMBER, CASE WHEN A.ISSUES >0 THEN 1 ELSE 0 END AS v_1_0010 FROM (SELECT COUNT(*) AS ISSUES FROM B02 WHERE B02.0120 IS MISSING AND c0250 IN ('Non-Structured/Vanilla', 'Other non-standard terms')) AS A; | V12: =+",CASE WHEN "&N12&" IS MISSING AND "&P12&" IN ('Non-Structured/Vanilla', 'Other non-standard terms') THEN 1 ELSE 0 END AS "&B12 -> ,CASE WHEN `0120_otstndng_amnt` IS MISSING AND `0250_strctrd_prdct` IN ('Non-Structured/Vanilla', 'Other non-standard terms') THEN 1 ELSE 0 END AS v_1_0010 | W12: =+"SUM("&B12&") AS LVL1_H_"&MID(N12,2,LEN(N12)-2)&"," -> SUM(v_1_0010) AS LVL1_H_0120_otstndng_amnt,
A13: 0011 | B13: =CONCATENATE("v_1_",A13) -> v_1_0011 | C13: B02.00 | D13: =VLOOKUP(CONCATENATE(C13,"_",E13),'Data types'!A:E,4,FALSE) -> 0120 | E13: Outstanding amount | F13: =VLOOKUP(CONCATENATE(C13,"_",E13),'Data types'!A:F,6,FALSE) -> Numeric: 2 decimals | H13: X | I13: Test for missing values. | J13: Rule applicable only if c0250 != ("Structured" OR "Only structured coupon") | K13: Missing value (warning only). For structured liabilities, the field has to be reported if the information exists. | L13: =+IF(G13="X","HIGH","WARNING") -> WARNING | M13: =+LEFT(C13,3) -> B02 | N13: ="`"&VLOOKUP(D13,'B02_Mapping fields'!B:C,2,FALSE)&"`" -> `0120_otstndng_amnt` | O13: 0250 | P13: ="`"&VLOOKUP(O13,'B02_Mapping fields'!B:C,2,FALSE)&"`" -> `0250_strctrd_prdct` | U13: =+",SELECT '"&M13&"' AS TAB, '"&L13&"' AS ALERT_TYPE, '"&B13&"' AS CHECK_ID, ROW_NUMBER, CASE WHEN A.ISSUES >0 THEN 1 ELSE 0 END AS "&B13&" FROM (SELECT COUNT(*) AS ISSUES FROM "&M13&" WHERE "&M13&"."&D13&" IS MISSING AND c0250 NOT IN ('Structured', 'Only structured coupon')) AS A;" -> ,SELECT 'B02' AS TAB, 'WARNING' AS ALERT_TYPE, 'v_1_0011' AS CHECK_ID, ROW_NUMBER, CASE WHEN A.ISSUES >0 THEN 1 ELSE 0 END AS v_1_0011 FROM (SELECT COUNT(*) AS ISSUES FROM B02 WHERE B02.0120 IS MISSING AND c0250 NOT IN ('Structured', 'Only structured coupon')) AS A; | V13: =+",CASE WHEN "&N13&" IS MISSING AND "&P13&" NOT IN ('Structured', 'Only structured coupon') THEN 1 ELSE 0 END AS "&B13 -> ,CASE WHEN `0120_otstndng_amnt` IS MISSING AND `0250_strctrd_prdct` NOT IN ('Structured', 'Only structured coupon') THEN 1 ELSE 0 END AS v_1_0011 | W13: =+"SUM("&B13&") AS LVL1_W_"&MID(N13,2,LEN(N13)-2)&"," -> SUM(v_1_0011) AS LVL1_W_0120_otstndng_amnt,
A14: 0012 | B14: =CONCATENATE("v_1_",A14) -> v_1_0012 | C14: B02.00 | D14: =VLOOKUP(CONCATENATE(C14,"_",E14),'Data types'!A:E,4,FALSE) -> 0130 | E14: Relevant amount for Bail-in/WDC | F14: =VLOOKUP(CONCATENATE(C14,"_",E14),'Data types'!A:F,6,FALSE) -> Numeric: 2 decimals | G14: X | I14: Test for missing values. | K14: Missing value. The field must be reported. | L14: =+IF(G14="X","HIGH","WARNING") -> HIGH | M14: =+LEFT(C14,3) -> B02 | N14: ="`"&VLOOKUP(D14,'B02_Mapping fields'!B:C,2,FALSE)&"`" -> `0130_rlvnt_amnt_wdc` | U14: =+",SELECT '"&M14&"' AS TAB, '"&L14&"' AS ALERT_TYPE, '"&B14&"' AS CHECK_ID, ROW_NUMBER, CASE WHEN A.ISSUES >0 THEN 1 ELSE 0 END AS "&B14&" FROM (SELECT COUNT(*) AS ISSUES FROM "&M14&" WHERE "&M14&"."&D14&" IS MISSING) AS A;" -> ,SELECT 'B02' AS TAB, 'HIGH' AS ALERT_TYPE, 'v_1_0012' AS CHECK_ID, ROW_NUMBER, CASE WHEN A.ISSUES >0 THEN 1 ELSE 0 END AS v_1_0012 FROM (SELECT COUNT(*) AS ISSUES FROM B02 WHERE B02.0130 IS MISSING) AS A; | V14: =+",CASE WHEN "&N14&" IS MISSING THEN 1 ELSE 0 END AS "&B14 -> ,CASE WHEN `0130_rlvnt_amnt_wdc` IS MISSING THEN 1 ELSE 0 END AS v_1_0012 | W14: =+"SUM("&B14&") AS LVL1_H_"&MID(N14,2,LEN(N14)-2)&"," -> SUM(v_1_0012) AS LVL1_H_0130_rlvnt_amnt_wdc,
A15: 0013 | B15: =CONCATENATE("v_1_",A15) -> v_1_0013 | C15: B02.00 | D15: =VLOOKUP(CONCATENATE(C15,"_",E15),'Data types'!A:E,4,FALSE) -> 0140 | E15: Nature of the liability | F15: =VLOOKUP(CONCATENATE(C15,"_",E15),'Data types'!A:F,6,FALSE) -> String: Drop-down | G15: X | I15: Test for missing values. | K15: Missing value. The field must be reported. | L15: =+IF(G15="X","HIGH","WARNING") -> HIGH | M15: =+LEFT(C15,3) -> B02 | N15: ="`"&VLOOKUP(D15,'B02_Mapping fields'!B:C,2,FALSE)&"`" -> `0140_ntr_lblty` | U15: =+",SELECT '"&M15&"' AS TAB, '"&L15&"' AS ALERT_TYPE, '"&B15&"' AS CHECK_ID, ROW_NUMBER, CASE WHEN A.ISSUES >0 THEN 1 ELSE 0 END AS "&B15&" FROM (SELECT COUNT(*) AS ISSUES FROM "&M15&" WHERE "&M15&"."&D15&" IS MISSING) AS A;" -> ,SELECT 'B02' AS TAB, 'HIGH' AS ALERT_TYPE, 'v_1_0013' AS CHECK_ID, ROW_NUMBER, CASE WHEN A.ISSUES >0 THEN 1 ELSE 0 END AS v_1_0013 FROM (SELECT COUNT(*) AS ISSUES FROM B02 WHERE B02.0140 IS MISSING) AS A; | V15: =+",CASE WHEN "&N15&" IS MISSING THEN 1 ELSE 0 END AS "&B15 -> ,CASE WHEN `0140_ntr_lblty` IS MISSING THEN 1 ELSE 0 END AS v_1_0013 | W15: =+"SUM("&B15&") AS LVL1_H_"&MID(N15,2,LEN(N15)-2)&"," -> SUM(v_1_0013) AS LVL1_H_0140_ntr_lblty,
A16: 0014 | B16: =CONCATENATE("v_1_",A16) -> v_1_0014 | C16: B02.00 | D16: =VLOOKUP(CONCATENATE(C16,"_",E16),'Data types'!A:E,4,FALSE) -> 0141 | E16: Nature of the liability (if other) | F16: =VLOOKUP(CONCATENATE(C16,"_",E16),'Data types'!A:F,6,FALSE) -> String: Free text | G16: X | I16: Test for missing values. | J16: Rule applicable only if c0140 = "Other". | K16: Missing value. The field must be reported if option "Other" has been selected in c0140. | L16: =+IF(G16="X","HIGH","WARNING") -> HIGH | M16: =+LEFT(C16,3) -> B02 | N16: ="`"&VLOOKUP(D16,'B02_Mapping fields'!B:C,2,FALSE)&"`" -> `0141_ntr_lblty_othr` | O16: 0140 | P16: ="`"&VLOOKUP(O16,'B02_Mapping fields'!B:C,2,FALSE)&"`" -> `0140_ntr_lblty` | U16: =+",SELECT '"&M16&"' AS TAB, '"&L16&"' AS ALERT_TYPE, '"&B16&"' AS CHECK_ID, ROW_NUMBER, CASE WHEN A.ISSUES >0 THEN 1 ELSE 0 END AS "&B16&" FROM (SELECT COUNT(*) AS ISSUES FROM "&M16&" WHERE "&M16&"."&D16&" IS MISSING AND c0140 = 'Other') AS A;" -> ,SELECT 'B02' AS TAB, 'HIGH' AS ALERT_TYPE, 'v_1_0014' AS CHECK_ID, ROW_NUMBER, CASE WHEN A.ISSUES >0 THEN 1 ELSE 0 END AS v_1_0014 FROM (SELECT COUNT(*) AS ISSUES FROM B02 WHERE B02.0141 IS MISSING AND c0140 = 'Other') AS A; | V16: =+",CASE WHEN "&N16&" IS MISSING AND "&P16&" = 'Other' THEN 1 ELSE 0 END AS "&B16 -> ,CASE WHEN `0141_ntr_lblty_othr` IS MISSING AND `0140_ntr_lblty` = 'Other' THEN 1 ELSE 0 END AS v_1_0014 | W16: =+"SUM("&B16&") AS LVL1_H_"&MID(N16,2,LEN(N16)-2)&"," -> SUM(v_1_0014) AS LVL1_H_0141_ntr_lblty_othr,
A17: 0015 | B17: =CONCATENATE("v_1_",A17) -> v_1_0015 | C17: B02.00 | D17: =VLOOKUP(CONCATENATE(C17,"_",E17),'Data types'!A:E,4,FALSE) -> 0160 | E17: Insolvency ranking | F17: =VLOOKUP(CONCATENATE(C17,"_",E17),'Data types'!A:F,6,FALSE) -> Numeric: Integer | G17: X | I17: Test for missing values. | K17: Missing value. The field must be reported. | L17: =+IF(G17="X","HIGH","WARNING") -> HIGH | M17: =+LEFT(C17,3) -> B02 | N17: ="`"&VLOOKUP(D17,'B02_Mapping fields'!B:C,2,FALSE)&"`" -> `0160_rank_insolv` | U17: =+",SELECT '"&M17&"' AS TAB, '"&L17&"' AS ALERT_TYPE, '"&B17&"' AS CHECK_ID, ROW_NUMBER, CASE WHEN A.ISSUES >0 THEN 1 ELSE 0 END AS "&B17&" FROM (SELECT COUNT(*) AS ISSUES FROM "&M17&" WHERE "&M17&"."&D17&" IS MISSING) AS A;" -> ,SELECT 'B02' AS TAB, 'HIGH' AS ALERT_TYPE, 'v_1_0015' AS CHECK_ID, ROW_NUMBER, CASE WHEN A.ISSUES >0 THEN 1 ELSE 0 END AS v_1_0015 FROM (SELECT COUNT(*) AS ISSUES FROM B02 WHERE B02.0160 IS MISSING) AS A; | V17: =+",CASE WHEN "&N17&" IS MISSING THEN 1 ELSE 0 END AS "&B17 -> ,CASE WHEN `0160_rank_insolv` IS MISSING THEN 1 ELSE 0 END AS v_1_0015 | W17: =+"SUM("&B17&") AS LVL1_H_"&MID(N17,2,LEN(N17)-2)&"," -> SUM(v_1_0015) AS LVL1_H_0160_rank_insolv,
A18: 0016 | B18: =CONCATENATE("v_1_",A18) -> v_1_0016 | C18: B02.00 | D18: =VLOOKUP(CONCATENATE(C18,"_",E18),'Data types'!A:E,4,FALSE) -> 0162 | E18: Bail-in cascade | F18: =VLOOKUP(CONCATENATE(C18,"_",E18),'Data types'!A:F,6,FALSE) -> String: Fixed values | G18: X | I18: Test for missing values. | K18: Missing value. The field must be reported. | L18: =+IF(G18="X","HIGH","WARNING") -> HIGH | M18: =+LEFT(C18,3) -> B02 | N18: ="`"&VLOOKUP(D18,'B02_Mapping fields'!B:C,2,FALSE)&"`" -> `0162_bail_in_cascade` | U18: =+",SELECT '"&M18&"' AS TAB, '"&L18&"' AS ALERT_TYPE, '"&B18&"' AS CHECK_ID, ROW_NUMBER, CASE WHEN A.ISSUES >0 THEN 1 ELSE 0 END AS "&B18&" FROM (SELECT COUNT(*) AS ISSUES FROM "&M18&" WHERE "&M18&"."&D18&" IS MISSING) AS A;" -> ,SELECT 'B02' AS TAB, 'HIGH' AS ALERT_TYPE, 'v_1_0016' AS CHECK_ID, ROW_NUMBER, CASE WHEN A.ISSUES >0 THEN 1 ELSE 0 END AS v_1_0016 FROM (SELECT COUNT(*) AS ISSUES FROM B02 WHERE B02.0162 IS MISSING) AS A; | V18: =+",CASE WHEN "&N18&" IS MISSING THEN 1 ELSE 0 END AS "&B18 -> ,CASE WHEN `0162_bail_in_cascade` IS MISSING THEN 1 ELSE 0 END AS v_1_0016 | W18: =+"SUM("&B18&") AS LVL1_H_"&MID(N18,2,LEN(N18)-2)&"," -> SUM(v_1_0016) AS LVL1_H_0162_bail_in_cascade,
A19: 0017 | B19: =CONCATENATE("v_1_",A19) -> v_1_0017 | C19: B02.00 | D19: =VLOOKUP(CONCATENATE(C19,"_",E19),'Data types'!A:E,4,FALSE) -> 0180 | E19: Date of the next interest payment | F19: =VLOOKUP(CONCATENATE(C19,"_",E19),'Data types'!A:F,6,FALSE) -> Date: yyyy-mm-dd | G19: X | I19: Test for missing values. | J19: Rule applicable if c0250 = ("Non-Structured/Vanilla" OR "Other non-standard terms") AND c0240 != "ZCB issued at discount" | K19: Missing value. For non-structured liabilities that are not zero coupon bonds issued at discount, this field is must be reported. | L19: =+IF(G19="X","HIGH","WARNING") -> HIGH | M19: =+LEFT(C19,3) -> B02 | N19: ="`"&VLOOKUP(D19,'B02_Mapping fields'!B:C,2,FALSE)&"`" -> `0180_dt_nxt_intrst_pymnt` | O19: 0250 | P19: ="`"&VLOOKUP(O19,'B02_Mapping fields'!B:C,2,FALSE)&"`" -> `0250_strctrd_prdct` | Q19: 0240 | R19: ="`"&VLOOKUP(Q19,'B02_Mapping fields'!B:C,2,FALSE)&"`" -> `0240_zero_coupon` | U19: =+",SELECT '"&M19&"' AS TAB, '"&L19&"' AS ALERT_TYPE, '"&B19&"' AS CHECK_ID, ROW_NUMBER, CASE WHEN A.ISSUES >0 THEN 1 ELSE 0 END AS "&B19&" FROM (SELECT COUNT(*) AS ISSUES FROM "&M19&" WHERE "&M19&"."&D19&" IS MISSING AND c0250 IN ('Non-Structured/Vanilla', 'Other non-standard terms') AND c0240 != 'ZCB issued at discount') AS A;" -> ,SELECT 'B02' AS TAB, 'HIGH' AS ALERT_TYPE, 'v_1_0017' AS CHECK_ID, ROW_NUMBER, CASE WHEN A.ISSUES >0 THEN 1 ELSE 0 END AS v_1_0017 FROM (SELECT COUNT(*) AS ISSUES FROM B02 WHERE B02.0180 IS MISSING AND c0250 IN ('Non-Structured/Vanilla', 'Other non-standard terms') AND c0240 != 'ZCB issued at discount') AS A; | V19: =+",CASE WHEN "&N19&" IS MISSING AND "&P19&" IN ('Non-Structured/Vanilla', 'Other non-standard terms') AND "&R19&" != 'ZCB issued at discount' THEN 1 ELSE 0 END AS "&B19 -> ,CASE WHEN `0180_dt_nxt_intrst_pymnt` IS MISSING AND `0250_strctrd_prdct` IN ('Non-Structured/Vanilla', 'Other non-standard terms') AND `0240_zero_coupon` != 'ZCB issued at discount' THEN 1 ELSE 0 END AS v_1_0017 | W19: =+"SUM("&B19&") AS LVL1_H_"&MID(N19,2,LEN(N19)-2)&"," -> SUM(v_1_0017) AS LVL1_H_0180_dt_nxt_intrst_pymnt,
A20: 0018 | B20: =CONCATENATE("v_1_",A20) -> v_1_0018 | C20: B02.00 | D20: =VLOOKUP(CONCATENATE(C20,"_",E20),'Data types'!A:E,4,FALSE) -> 0180 | E20: Date of the next interest payment | F20: =VLOOKUP(CONCATENATE(C20,"_",E20),'Data types'!A:F,6,FALSE) -> Date: yyyy-mm-dd | H20: X | I20: Test for missing values. | J20: Rule applicable only if c0250 != ("Structured" OR "Only structured coupon") | K20: Missing value (warning only). For structured liabilities, this field should be reported only if the information exists.. | L20: =+IF(G20="X","HIGH","WARNING") -> WARNING | M20: =+LEFT(C20,3) -> B02 | N20: ="`"&VLOOKUP(D20,'B02_Mapping fields'!B:C,2,FALSE)&"`" -> `0180_dt_nxt_intrst_pymnt` | O20: 0250 | P20: ="`"&VLOOKUP(O20,'B02_Mapping fields'!B:C,2,FALSE)&"`" -> `0250_strctrd_prdct` | U20: =+",SELECT '"&M20&"' AS TAB, '"&L20&"' AS ALERT_TYPE, '"&B20&"' AS CHECK_ID, ROW_NUMBER, CASE WHEN A.ISSUES >0 THEN 1 ELSE 0 END AS "&B20&" FROM (SELECT COUNT(*) AS ISSUES FROM "&M20&" WHERE "&M20&"."&D20&" IS MISSING AND c0250 NOT IN ('Structured', 'Only structured coupon')) AS A;" -> ,SELECT 'B02' AS TAB, 'WARNING' AS ALERT_TYPE, 'v_1_0018' AS CHECK_ID, ROW_NUMBER, CASE WHEN A.ISSUES >0 THEN 1 ELSE 0 END AS v_1_0018 FROM (SELECT COUNT(*) AS ISSUES FROM B02 WHERE B02.0180 IS MISSING AND c0250 NOT IN ('Structured', 'Only structured coupon')) AS A; | V20: =+",CASE WHEN "&N20&" IS MISSING AND "&P20&" NOT IN ('Structured', 'Only structured coupon') THEN 1 ELSE 0 END AS "&B20 -> ,CASE WHEN `0180_dt_nxt_intrst_pymnt` IS MISSING AND `0250_strctrd_prdct` NOT IN ('Structured', 'Only structured coupon') THEN 1 ELSE 0 END AS v_1_0018 | W20: =+"SUM("&B20&") AS LVL1_W_"&MID(N20,2,LEN(N20)-2)&"," -> SUM(v_1_0018) AS LVL1_W_0180_dt_nxt_intrst_pymnt,
A21: 0019 | B21: =CONCATENATE("v_1_",A21) -> v_1_0019 | C21: B02.00 | D21: =VLOOKUP(CONCATENATE(C21,"_",E21),'Data types'!A:E,4,FALSE) -> 0200 | E21: Earliest redemption date | F21: =VLOOKUP(CONCATENATE(C21,"_",E21),'Data types'!A:F,6,FALSE) -> Date: yyyy-mm-dd | H21: X | I21: Test for missing values. | K21: Missing value (warning only). This field needs to be reported if the information exists. | L21: =+IF(G21="X","HIGH","WARNING") -> WARNING | M21: =+LEFT(C21,3) -> B02 | N21: ="`"&VLOOKUP(D21,'B02_Mapping fields'!B:C,2,FALSE)&"`" -> `0200_dt_erlst_rdmptn` | U21: =+",SELECT '"&M21&"' AS TAB, '"&L21&"' AS ALERT_TYPE, '"&B21&"' AS CHECK_ID, ROW_NUMBER, CASE WHEN A.ISSUES >0 THEN 1 ELSE 0 END AS "&B21&" FROM (SELECT COUNT(*) AS ISSUES FROM "&M21&" WHERE "&M21&"."&D21&" IS MISSING) AS A;" -> ,SELECT 'B02' AS TAB, 'WARNING' AS ALERT_TYPE, 'v_1_0019' AS CHECK_ID, ROW_NUMBER, CASE WHEN A.ISSUES >0 THEN 1 ELSE 0 END AS v_1_0019 FROM (SELECT COUNT(*) AS ISSUES FROM B02 WHERE B02.0200 IS MISSING) AS A; | V21: =+",CASE WHEN "&N21&" IS MISSING THEN 1 ELSE 0 END AS "&B21 -> ,CASE WHEN `0200_dt_erlst_rdmptn` IS MISSING THEN 1 ELSE 0 END AS v_1_0019 | W21: =+"SUM("&B21&") AS LVL1_W_"&MID(N21,2,LEN(N21)-2)&"," -> SUM(v_1_0019) AS LVL1_W_0200_dt_erlst_rdmptn,
A22: 0020 | B22: =CONCATENATE("v_1_",A22) -> v_1_0020 | C22: B02.00 | D22: =VLOOKUP(CONCATENATE(C22,"_",E22),'Data types'!A:E,4,FALSE) -> 0210 | E22: Legal maturity | F22: =VLOOKUP(CONCATENATE(C22,"_",E22),'Data types'!A:F,6,FALSE) -> Date: yyyy-mm-dd | G22: X | I22: Test for missing values. | J22: Rule applicable if c0140 != "Cash account/saving account". | K22: Missing value.For liabilities other than of the type "Cash account/savings account, the field must be reported. | L22: =+IF(G22="X","HIGH","WARNING") -> HIGH | M22: =+LEFT(C22,3) -> B02 | N22: ="`"&VLOOKUP(D22,'B02_Mapping fields'!B:C,2,FALSE)&"`" -> `0210_dt_lgl_fnl_mtrty` | O22: 0140 | P22: ="`"&VLOOKUP(O22,'B02_Mapping fields'!B:C,2,FALSE)&"`" -> `0140_ntr_lblty` | U22: =+",SELECT '"&M22&"' AS TAB, '"&L22&"' AS ALERT_TYPE, '"&B22&"' AS CHECK_ID, ROW_NUMBER, CASE WHEN A.ISSUES >0 THEN 1 ELSE 0 END AS "&B22&" FROM (SELECT COUNT(*) AS ISSUES FROM "&M22&" WHERE "&M22&"."&D22&" IS MISSING AND c0240 != 'Cash account/saving account') AS A;" -> ,SELECT 'B02' AS TAB, 'HIGH' AS ALERT_TYPE, 'v_1_0020' AS CHECK_ID, ROW_NUMBER, CASE WHEN A.ISSUES >0 THEN 1 ELSE 0 END AS v_1_0020 FROM (SELECT COUNT(*) AS ISSUES FROM B02 WHERE B02.0210 IS MISSING AND c0240 != 'Cash account/saving account') AS A; | V22: =+",CASE WHEN "&N22&" IS MISSING AND "&P22&" != 'Cash account/saving account' THEN 1 ELSE 0 END AS "&B22 -> ,CASE WHEN `0210_dt_lgl_fnl_mtrty` IS MISSING AND `0140_ntr_lblty` != 'Cash account/saving account' THEN 1 ELSE 0 END AS v_1_0020 | W22: =+"SUM("&B22&") AS LVL1_H_"&MID(N22,2,LEN(N22)-2)&"," -> SUM(v_1_0020) AS LVL1_H_0210_dt_lgl_fnl_mtrty,
A23: 0021 | B23: =CONCATENATE("v_1_",A23) -> v_1_0021 | C23: B02.00 | D23: =VLOOKUP(CONCATENATE(C23,"_",E23),'Data types'!A:E,4,FALSE) -> 0220 | E23: Governing law | F23: =VLOOKUP(CONCATENATE(C23,"_",E23),'Data types'!A:F,6,FALSE) -> String: ISO 3166-1 alpha 2 / ISO 3166-2 | G23: X | I23: Test for missing values. | K23: Missing value. The field must be reported. | L23: =+IF(G23="X","HIGH","WARNING") -> HIGH | M23: =+LEFT(C23,3) -> B02 | N23: ="`"&VLOOKUP(D23,'B02_Mapping fields'!B:C,2,FALSE)&"`" -> `0220_governing_law` | U23: =+",SELECT '"&M23&"' AS TAB, '"&L23&"' AS ALERT_TYPE, '"&B23&"' AS CHECK_ID, ROW_NUMBER, CASE WHEN A.ISSUES >0 THEN 1 ELSE 0 END AS "&B23&" FROM (SELECT COUNT(*) AS ISSUES FROM "&M23&" WHERE "&M23&"."&D23&" IS MISSING) AS A;" -> ,SELECT 'B02' AS TAB, 'HIGH' AS ALERT_TYPE, 'v_1_0021' AS CHECK_ID, ROW_NUMBER, CASE WHEN A.ISSUES >0 THEN 1 ELSE 0 END AS v_1_0021 FROM (SELECT COUNT(*) AS ISSUES FROM B02 WHERE B02.0220 IS MISSING) AS A; | V23: =+",CASE WHEN "&N23&" IS MISSING THEN 1 ELSE 0 END AS "&B23 -> ,CASE WHEN `0220_governing_law` IS MISSING THEN 1 ELSE 0 END AS v_1_0021 | W23: =+"SUM("&B23&") AS LVL1_H_"&MID(N23,2,LEN(N23)-2)&"," -> SUM(v_1_0021) AS LVL1_H_0220_governing_law,
A24: 0022 | B24: =CONCATENATE("v_1_",A24) -> v_1_0022 | C24: B02.00 | D24: =VLOOKUP(CONCATENATE(C24,"_",E24),'Data types'!A:E,4,FALSE) -> 0250 | E24: Structured product | F24: =VLOOKUP(CONCATENATE(C24,"_",E24),'Data types'!A:F,6,FALSE) -> String: Drop-down | G24: X | I24: Test for missing values. | K24: Missing value. The field must be reported. | L24: =+IF(G24="X","HIGH","WARNING") -> HIGH | M24: =+LEFT(C24,3) -> B02 | N24: ="`"&VLOOKUP(D24,'B02_Mapping fields'!B:C,2,FALSE)&"`" -> `0250_strctrd_prdct` | U24: =+",SELECT '"&M24&"' AS TAB, '"&L24&"' AS ALERT_TYPE, '"&B24&"' AS CHECK_ID, ROW_NUMBER, CASE WHEN A.ISSUES >0 THEN 1 ELSE 0 END AS "&B24&" FROM (SELECT COUNT(*) AS ISSUES FROM "&M24&" WHERE "&M24&"."&D24&" IS MISSING) AS A;" -> ,SELECT 'B02' AS TAB, 'HIGH' AS ALERT_TYPE, 'v_1_0022' AS CHECK_ID, ROW_NUMBER, CASE WHEN A.ISSUES >0 THEN 1 ELSE 0 END AS v_1_0022 FROM (SELECT COUNT(*) AS ISSUES FROM B02 WHERE B02.0250 IS MISSING) AS A; | V24: =+",CASE WHEN "&N24&" IS MISSING THEN 1 ELSE 0 END AS "&B24 -> ,CASE WHEN `0250_strctrd_prdct` IS MISSING THEN 1 ELSE 0 END AS v_1_0022 | W24: =+"SUM("&B24&") AS LVL1_H_"&MID(N24,2,LEN(N24)-2)&"," -> SUM(v_1_0022) AS LVL1_H_0250_strctrd_prdct,
A25: 0023 | B25: =CONCATENATE("v_1_",A25) -> v_1_0023 | C25: B02.00 | D25: =VLOOKUP(CONCATENATE(C25,"_",E25),'Data types'!A:E,4,FALSE) -> 0260 | E25: Guaranteed minimum repayment amount of the structured product | F25: =VLOOKUP(CONCATENATE(C25,"_",E25),'Data types'!A:F,6,FALSE) -> Numeric: 2 decimals | H25: X | I25: Test for missing values. | J25: Rule applicable only if c0250 = ("Structured" OR "Structured coupon only") | K25: Missing value (warning only). For structured liabilities, this field should be reported if the information exists.. | L25: =+IF(G25="X","HIGH","WARNING") -> WARNING | M25: =+LEFT(C25,3) -> B02 | N25: ="`"&VLOOKUP(D25,'B02_Mapping fields'!B:C,2,FALSE)&"`" -> `0260_grntd_min_amnt_strctrd_prdct` | O25: 0250 | P25: ="`"&VLOOKUP(O25,'B02_Mapping fields'!B:C,2,FALSE)&"`" -> `0250_strctrd_prdct` | U25: =+",SELECT '"&M25&"' AS TAB, '"&L25&"' AS ALERT_TYPE, '"&B25&"' AS CHECK_ID, ROW_NUMBER, CASE WHEN A.ISSUES >0 THEN 1 ELSE 0 END AS "&B25&" FROM (SELECT COUNT(*) AS ISSUES FROM "&M25&" WHERE "&M25&"."&D25&" IS MISSING AND c0250 IN ('Structured', 'Only structured coupon')) AS A;" -> ,SELECT 'B02' AS TAB, 'WARNING' AS ALERT_TYPE, 'v_1_0023' AS CHECK_ID, ROW_NUMBER, CASE WHEN A.ISSUES >0 THEN 1 ELSE 0 END AS v_1_0023 FROM (SELECT COUNT(*) AS ISSUES FROM B02 WHERE B02.0260 IS MISSING AND c0250 IN ('Structured', 'Only structured coupon')) AS A; | V25: =+",CASE WHEN "&N25&" IS MISSING AND "&P25&" IN ('Structured', 'Only structured coupon') THEN 1 ELSE 0 END AS "&B25 -> ,CASE WHEN `0260_grntd_min_amnt_strctrd_prdct` IS MISSING AND `0250_strctrd_prdct` IN ('Structured', 'Only structured coupon') THEN 1 ELSE 0 END AS v_1_0023 | W25: =+"SUM("&B25&") AS LVL1_W_"&MID(N25,2,LEN(N25)-2)&"," -> SUM(v_1_0023) AS LVL1_W_0260_grntd_min_amnt_strctrd_prdct,
A26: 0024 | B26: =CONCATENATE("v_1_",A26) -> v_1_0024 | C26: B02.00 | D26: =VLOOKUP(CONCATENATE(C26,"_",E26),'Data types'!A:E,4,FALSE) -> 0270 | E26: Fair value of the structured product | F26: =VLOOKUP(CONCATENATE(C26,"_",E26),'Data types'!A:F,6,FALSE) -> Numeric: 2 decimals | G26: X | I26: Test for missing values. | J26: Rule applicable only if c0250 = ("Structured" OR "Structured coupon only") | K26: Missing value. The field must be reported for structured products. | L26: =+IF(G26="X","HIGH","WARNING") -> HIGH | M26: =+LEFT(C26,3) -> B02 | N26: ="`"&VLOOKUP(D26,'B02_Mapping fields'!B:C,2,FALSE)&"`" -> `0270_fv_amnt_strctrd_prdct` | O26: 0250 | P26: ="`"&VLOOKUP(O26,'B02_Mapping fields'!B:C,2,FALSE)&"`" -> `0250_strctrd_prdct` | U26: =+",SELECT '"&M26&"' AS TAB, '"&L26&"' AS ALERT_TYPE, '"&B26&"' AS CHECK_ID, ROW_NUMBER, CASE WHEN A.ISSUES >0 THEN 1 ELSE 0 END AS "&B26&" FROM (SELECT COUNT(*) AS ISSUES FROM "&M26&" WHERE "&M26&"."&D26&" IS MISSING AND c0250 IN ('Structured', 'Only structured coupon')) AS A;" -> ,SELECT 'B02' AS TAB, 'HIGH' AS ALERT_TYPE, 'v_1_0024' AS CHECK_ID, ROW_NUMBER, CASE WHEN A.ISSUES >0 THEN 1 ELSE 0 END AS v_1_0024 FROM (SELECT COUNT(*) AS ISSUES FROM B02 WHERE B02.0270 IS MISSING AND c0250 IN ('Structured', 'Only structured coupon')) AS A; | V26: =+",CASE WHEN "&N26&" IS MISSING AND "&P26&" IN ('Structured', 'Only structured coupon') THEN 1 ELSE 0 END AS "&B26 -> ,CASE WHEN `0270_fv_amnt_strctrd_prdct` IS MISSING AND `0250_strctrd_prdct` IN ('Structured', 'Only structured coupon') THEN 1 ELSE 0 END AS v_1_0024 | W26: =+"SUM("&B26&") AS LVL1_H_"&MID(N26,2,LEN(N26)-2)&"," -> SUM(v_1_0024) AS LVL1_H_0270_fv_amnt_strctrd_prdct,
A27: 0025 | B27: =CONCATENATE("v_1_",A27) -> v_1_0025 | C27: B02.00 | D27: =VLOOKUP(CONCATENATE(C27,"_",E27),'Data types'!A:E,4,FALSE) -> 0300 | E27: Covered portion of eligible deposits | F27: =VLOOKUP(CONCATENATE(C27,"_",E27),'Data types'!A:F,6,FALSE) -> Numeric: 2 decimals | G27: X | I27: Test for missing values. | J27: Rule applicable only if c0280 = "TRUE" or c0290 = "TRUE". | K27: Missing value. The field must be reported for eligible deposits. If the value is zero, "0" should be entered. | L27: =+IF(G27="X","HIGH","WARNING") -> HIGH | M27: =+LEFT(C27,3) -> B02 | N27: ="`"&VLOOKUP(D27,'B02_Mapping fields'!B:C,2,FALSE)&"`" -> `0300_amnt_cvrd_elgbl_dpsts` | O27: 0280 | P27: ="`"&VLOOKUP(O27,'B02_Mapping fields'!B:C,2,FALSE)&"`" -> `0280_flg_ncnp_dpsts` | Q27: 0290 | R27: ="`"&VLOOKUP(Q27,'B02_Mapping fields'!B:C,2,FALSE)&"`" -> `0290_flg_ncbp_dpsts` | U27: =+",SELECT '"&M27&"' AS TAB, '"&L27&"' AS ALERT_TYPE, '"&B27&"' AS CHECK_ID, ROW_NUMBER, CASE WHEN A.ISSUES >0 THEN 1 ELSE 0 END AS "&B27&" FROM (SELECT COUNT(*) AS ISSUES FROM "&M27&" WHERE "&M27&"."&D27&" IS MISSING AND (c0280 = 'TRUE' or c0290 = 'TRUE')) AS A;" -> ,SELECT 'B02' AS TAB, 'HIGH' AS ALERT_TYPE, 'v_1_0025' AS CHECK_ID, ROW_NUMBER, CASE WHEN A.ISSUES >0 THEN 1 ELSE 0 END AS v_1_0025 FROM (SELECT COUNT(*) AS ISSUES FROM B02 WHERE B02.0300 IS MISSING AND (c0280 = 'TRUE' or c0290 = 'TRUE')) AS A; | V27: =+",CASE WHEN "&N27&" IS MISSING AND ("&P27&" = 'TRUE' or "&R27&" = 'TRUE') THEN 1 ELSE 0 END AS "&B27 -> ,CASE WHEN `0300_amnt_cvrd_elgbl_dpsts` IS MISSING AND (`0280_flg_ncnp_dpsts` = 'TRUE' or `0290_flg_ncbp_dpsts` = 'TRUE') THEN 1 ELSE 0 END AS v_1_0025 | W27: =+"SUM("&B27&") AS LVL1_H_"&MID(N27,2,LEN(N27)-2)&"," -> SUM(v_1_0025) AS LVL1_H_0300_amnt_cvrd_elgbl_dpsts,
A28: 0026 | B28: =CONCATENATE("v_1_",A28) -> v_1_0026 | C28: B02.00 | D28: =VLOOKUP(CONCATENATE(C28,"_",E28),'Data types'!A:E,4,FALSE) -> 0310 | E28: Secured/Unsecured | F28: =VLOOKUP(CONCATENATE(C28,"_",E28),'Data types'!A:F,6,FALSE) -> String: Drop-down | G28: X | I28: Test for missing values. | K28: Missing value. The field must be reported. | L28: =+IF(G28="X","HIGH","WARNING") -> HIGH | M28: =+LEFT(C28,3) -> B02 | N28: ="`"&VLOOKUP(D28,'B02_Mapping fields'!B:C,2,FALSE)&"`" -> `0310_flg_clltrl_agrmnts` | U28: =+",SELECT '"&M28&"' AS TAB, '"&L28&"' AS ALERT_TYPE, '"&B28&"' AS CHECK_ID, ROW_NUMBER, CASE WHEN A.ISSUES >0 THEN 1 ELSE 0 END AS "&B28&" FROM (SELECT COUNT(*) AS ISSUES FROM "&M28&" WHERE "&M28&"."&D28&" IS MISSING) AS A;" -> ,SELECT 'B02' AS TAB, 'HIGH' AS ALERT_TYPE, 'v_1_0026' AS CHECK_ID, ROW_NUMBER, CASE WHEN A.ISSUES >0 THEN 1 ELSE 0 END AS v_1_0026 FROM (SELECT COUNT(*) AS ISSUES FROM B02 WHERE B02.0310 IS MISSING) AS A; | V28: =+",CASE WHEN "&N28&" IS MISSING THEN 1 ELSE 0 END AS "&B28 -> ,CASE WHEN `0310_flg_clltrl_agrmnts` IS MISSING THEN 1 ELSE 0 END AS v_1_0026 | W28: =+"SUM("&B28&") AS LVL1_H_"&MID(N28,2,LEN(N28)-2)&"," -> SUM(v_1_0026) AS LVL1_H_0310_flg_clltrl_agrmnts,
A29: 0027 | B29: =CONCATENATE("v_1_",A29) -> v_1_0027 | C29: B02.00 | D29: =VLOOKUP(CONCATENATE(C29,"_",E29),'Data types'!A:E,4,FALSE) -> 0320 | E29: Amount of pledge, lien or collateral based on the current internal valuation | F29: =VLOOKUP(CONCATENATE(C29,"_",E29),'Data types'!A:F,6,FALSE) -> Numeric: 2 decimals | G29: X | I29: Test for missing values. | J29: Rule applicable only if c0310 = "Secured" | K29: Missing value. The field must be reported for secured products. If the value is zero, "0" should be entered. | L29: =+IF(G29="X","HIGH","WARNING") -> HIGH | M29: =+LEFT(C29,3) -> B02 | N29: ="`"&VLOOKUP(D29,'B02_Mapping fields'!B:C,2,FALSE)&"`" -> `0320_amnt_clltrl` | O29: 0310 | P29: ="`"&VLOOKUP(O29,'B02_Mapping fields'!B:C,2,FALSE)&"`" -> `0310_flg_clltrl_agrmnts` | U29: =+",SELECT '"&M29&"' AS TAB, '"&L29&"' AS ALERT_TYPE, '"&B29&"' AS CHECK_ID, ROW_NUMBER, CASE WHEN A.ISSUES >0 THEN 1 ELSE 0 END AS "&B29&" FROM (SELECT COUNT(*) AS ISSUES FROM "&M29&" WHERE "&M29&"."&D29&" IS MISSING AND c0310 = 'Secured') AS A;" -> ,SELECT 'B02' AS TAB, 'HIGH' AS ALERT_TYPE, 'v_1_0027' AS CHECK_ID, ROW_NUMBER, CASE WHEN A.ISSUES >0 THEN 1 ELSE 0 END AS v_1_0027 FROM (SELECT COUNT(*) AS ISSUES FROM B02 WHERE B02.0320 IS MISSING AND c0310 = 'Secured') AS A; | V29: =+",CASE WHEN "&N29&" IS MISSING AND "&P29&" = 'Secured' THEN 1 ELSE 0 END AS "&B29 -> ,CASE WHEN `0320_amnt_clltrl` IS MISSING AND `0310_flg_clltrl_agrmnts` = 'Secured' THEN 1 ELSE 0 END AS v_1_0027 | W29: =+"SUM("&B29&") AS LVL1_H_"&MID(N29,2,LEN(N29)-2)&"," -> SUM(v_1_0027) AS LVL1_H_0320_amnt_clltrl,
A30: 0028 | B30: =CONCATENATE("v_1_",A30) -> v_1_0028 | C30: B02.00 | D30: =VLOOKUP(CONCATENATE(C30,"_",E30),'Data types'!A:E,4,FALSE) -> 0330 | E30: Amount of the uncollateralized part | F30: =VLOOKUP(CONCATENATE(C30,"_",E30),'Data types'!A:F,6,FALSE) -> Numeric: 2 decimals | G30: X | I30: Test for missing values. | J30: Rule applicable only if c0310 = "Secured" | K30: Missing value. The field must be reported for secured products. | L30: =+IF(G30="X","HIGH","WARNING") -> HIGH | M30: =+LEFT(C30,3) -> B02 | N30: ="`"&VLOOKUP(D30,'B02_Mapping fields'!B:C,2,FALSE)&"`" -> `0330_amnt_unclltrlzd` | O30: 0310 | P30: ="`"&VLOOKUP(O30,'B02_Mapping fields'!B:C,2,FALSE)&"`" -> `0310_flg_clltrl_agrmnts` | U30: =+",SELECT '"&M30&"' AS TAB, '"&L30&"' AS ALERT_TYPE, '"&B30&"' AS CHECK_ID, ROW_NUMBER, CASE WHEN A.ISSUES >0 THEN 1 ELSE 0 END AS "&B30&" FROM (SELECT COUNT(*) AS ISSUES FROM "&M30&" WHERE "&M30&"."&D30&" IS MISSING AND c0310 = 'Secured') AS A;" -> ,SELECT 'B02' AS TAB, 'HIGH' AS ALERT_TYPE, 'v_1_0028' AS CHECK_ID, ROW_NUMBER, CASE WHEN A.ISSUES >0 THEN 1 ELSE 0 END AS v_1_0028 FROM (SELECT COUNT(*) AS ISSUES FROM B02 WHERE B02.0330 IS MISSING AND c0310 = 'Secured') AS A; | V30: =+",CASE WHEN "&N30&" IS MISSING AND "&P30&" = 'Secured' THEN 1 ELSE 0 END AS "&B30 -> ,CASE WHEN `0330_amnt_unclltrlzd` IS MISSING AND `0310_flg_clltrl_agrmnts` = 'Secured' THEN 1 ELSE 0 END AS v_1_0028 | W30: =+"SUM("&B30&") AS LVL1_H_"&MID(N30,2,LEN(N30)-2)&"," -> SUM(v_1_0028) AS LVL1_H_0330_amnt_unclltrlzd,
A31: 0029 | B31: =CONCATENATE("v_1_",A31) -> v_1_0029 | C31: B02.00 | D31: =VLOOKUP(CONCATENATE(C31,"_",E31),'Data types'!A:E,4,FALSE) -> 0350 | E31: Type of the collateral | F31: =VLOOKUP(CONCATENATE(C31,"_",E31),'Data types'!A:F,6,FALSE) -> String: Drop-down | G31: X | I31: Test for missing values. | J31: Rule applicable only if c0310 = "Secured" | K31: Missing value. The field must be reported for secured products. | L31: =+IF(G31="X","HIGH","WARNING") -> HIGH | M31: =+LEFT(C31,3) -> B02 | N31: ="`"&VLOOKUP(D31,'B02_Mapping fields'!B:C,2,FALSE)&"`" -> `0350_typ_clltrl` | O31: 0310 | P31: ="`"&VLOOKUP(O31,'B02_Mapping fields'!B:C,2,FALSE)&"`" -> `0310_flg_clltrl_agrmnts` | U31: =+",SELECT '"&M31&"' AS TAB, '"&L31&"' AS ALERT_TYPE, '"&B31&"' AS CHECK_ID, ROW_NUMBER, CASE WHEN A.ISSUES >0 THEN 1 ELSE 0 END AS "&B31&" FROM (SELECT COUNT(*) AS ISSUES FROM "&M31&" WHERE "&M31&"."&D31&" IS MISSING AND c0310 = 'Secured') AS A;" -> ,SELECT 'B02' AS TAB, 'HIGH' AS ALERT_TYPE, 'v_1_0029' AS CHECK_ID, ROW_NUMBER, CASE WHEN A.ISSUES >0 THEN 1 ELSE 0 END AS v_1_0029 FROM (SELECT COUNT(*) AS ISSUES FROM B02 WHERE B02.0350 IS MISSING AND c0310 = 'Secured') AS A; | V31: =+",CASE WHEN "&N31&" IS MISSING AND "&P31&" = 'Secured' THEN 1 ELSE 0 END AS "&B31 -> ,CASE WHEN `0350_typ_clltrl` IS MISSING AND `0310_flg_clltrl_agrmnts` = 'Secured' THEN 1 ELSE 0 END AS v_1_0029 | W31: =+"SUM("&B31&") AS LVL1_H_"&MID(N31,2,LEN(N31)-2)&"," -> SUM(v_1_0029) AS LVL1_H_0350_typ_clltrl,
A32: 0030 | B32: =CONCATENATE("v_1_",A32) -> v_1_0030 | C32: B02.00 | D32: =VLOOKUP(CONCATENATE(C32,"_",E32),'Data types'!A:E,4,FALSE) -> 0351 | E32: Type of the collateral (if other) | F32: =VLOOKUP(CONCATENATE(C32,"_",E32),'Data types'!A:F,6,FALSE) -> String: Free text | G32: X | I32: Test for missing values. | J32: Rule applicable only if c0350 = "Other" | K32: Missing value (warning). The field should be reported if c0350 = "Other". | L32: =+IF(G32="X","HIGH","WARNING") -> HIGH | M32: =+LEFT(C32,3) -> B02 | N32: ="`"&VLOOKUP(D32,'B02_Mapping fields'!B:C,2,FALSE)&"`" -> `0351_typ_clltrl_othr` | O32: 0350 | P32: ="`"&VLOOKUP(O32,'B02_Mapping fields'!B:C,2,FALSE)&"`" -> `0350_typ_clltrl` | U32: =+",SELECT '"&M32&"' AS TAB, '"&L32&"' AS ALERT_TYPE, '"&B32&"' AS CHECK_ID, ROW_NUMBER, CASE WHEN A.ISSUES >0 THEN 1 ELSE 0 END AS "&B32&" FROM (SELECT COUNT(*) AS ISSUES FROM "&M32&" WHERE "&M32&"."&D32&" IS MISSING AND c0350 = 'Other') AS A;" -> ,SELECT 'B02' AS TAB, 'HIGH' AS ALERT_TYPE, 'v_1_0030' AS CHECK_ID, ROW_NUMBER, CASE WHEN A.ISSUES >0 THEN 1 ELSE 0 END AS v_1_0030 FROM (SELECT COUNT(*) AS ISSUES FROM B02 WHERE B02.0351 IS MISSING AND c0350 = 'Other') AS A; | V32: =+",CASE WHEN "&N32&" IS MISSING AND "&P32&" = 'Other' THEN 1 ELSE 0 END AS "&B32 -> ,CASE WHEN `0351_typ_clltrl_othr` IS MISSING AND `0350_typ_clltrl` = 'Other' THEN 1 ELSE 0 END AS v_1_0030 | W32: =+"SUM("&B32&") AS LVL1_H_"&MID(N32,2,LEN(N32)-2)&"," -> SUM(v_1_0030) AS LVL1_H_0351_typ_clltrl_othr,
A33: 0031 | B33: =CONCATENATE("v_1_",A33) -> v_1_0031 | C33: B02.00 | D33: =VLOOKUP(CONCATENATE(C33,"_",E33),'Data types'!A:E,4,FALSE) -> 0370 | E33: Denomination / Nominal value per security in EUR | F33: =VLOOKUP(CONCATENATE(C33,"_",E33),'Data types'!A:F,6,FALSE) -> Numeric: 2 decimals | G33: X | I33: Test for missing values. | J33: Rule applicable only if c0040 = "ISIN" and c0360 = "Nominal" | K33: Missing value. The field must be reported for securities with trading-method = "Nominal". | L33: =+IF(G33="X","HIGH","WARNING") -> HIGH | M33: =+LEFT(C33,3) -> B02 | N33: ="`"&VLOOKUP(D33,'B02_Mapping fields'!B:C,2,FALSE)&"`" -> `0370_amnt_scrty_eur` | O33: 0040 | P33: ="`"&VLOOKUP(O33,'B02_Mapping fields'!B:C,2,FALSE)&"`" -> `0040_typ_uniq_id_knwn_cntrprty` | Q33: 0360 | R33: ="`"&VLOOKUP(Q33,'B02_Mapping fields'!B:C,2,FALSE)&"`" -> `0360_trdng_mthd` | U33: =+",SELECT '"&M33&"' AS TAB, '"&L33&"' AS ALERT_TYPE, '"&B33&"' AS CHECK_ID, ROW_NUMBER, CASE WHEN A.ISSUES >0 THEN 1 ELSE 0 END AS "&B33&" FROM (SELECT COUNT(*) AS ISSUES FROM "&M33&" WHERE "&M33&"."&D33&" IS MISSING AND c0040 = 'ISIN' AND c0360 = 'Nominal') AS A;" -> ,SELECT 'B02' AS TAB, 'HIGH' AS ALERT_TYPE, 'v_1_0031' AS CHECK_ID, ROW_NUMBER, CASE WHEN A.ISSUES >0 THEN 1 ELSE 0 END AS v_1_0031 FROM (SELECT COUNT(*) AS ISSUES FROM B02 WHERE B02.0370 IS MISSING AND c0040 = 'ISIN' AND c0360 = 'Nominal') AS A; | V33: =+",CASE WHEN "&N33&" IS MISSING AND "&P33&" = 'ISIN' AND "&R33&" = 'Nominal' THEN 1 ELSE 0 END AS "&B33 -> ,CASE WHEN `0370_amnt_scrty_eur` IS MISSING AND `0040_typ_uniq_id_knwn_cntrprty` = 'ISIN' AND `0360_trdng_mthd` = 'Nominal' THEN 1 ELSE 0 END AS v_1_0031 | W33: =+"SUM("&B33&") AS LVL1_H_"&MID(N33,2,LEN(N33)-2)&"," -> SUM(v_1_0031) AS LVL1_H_0370_amnt_scrty_eur,
A34: 0032 | B34: =CONCATENATE("v_1_",A34) -> v_1_0032 | C34: B02.00 | D34: =VLOOKUP(CONCATENATE(C34,"_",E34),'Data types'!A:E,4,FALSE) -> 0370 | E34: Denomination / Nominal value per security in EUR | F34: =VLOOKUP(CONCATENATE(C34,"_",E34),'Data types'!A:F,6,FALSE) -> Numeric: 2 decimals | H34: X | J34: Rule applicable only if c0040 = "ISIN" and c0360 = "Unit" | K34: Missing value (warning only). The field should be reported for securities with trading-method = "Unit" if the information exists. | L34: =+IF(G34="X","HIGH","WARNING") -> WARNING | M34: =+LEFT(C34,3) -> B02 | N34: ="`"&VLOOKUP(D34,'B02_Mapping fields'!B:C,2,FALSE)&"`" -> `0370_amnt_scrty_eur` | O34: 0040 | P34: ="`"&VLOOKUP(O34,'B02_Mapping fields'!B:C,2,FALSE)&"`" -> `0040_typ_uniq_id_knwn_cntrprty` | Q34: 0360 | R34: ="`"&VLOOKUP(Q34,'B02_Mapping fields'!B:C,2,FALSE)&"`" -> `0360_trdng_mthd` | U34: =+",SELECT '"&M34&"' AS TAB, '"&L34&"' AS ALERT_TYPE, '"&B34&"' AS CHECK_ID, ROW_NUMBER, CASE WHEN A.ISSUES >0 THEN 1 ELSE 0 END AS "&B34&" FROM (SELECT COUNT(*) AS ISSUES FROM "&M34&" WHERE "&M34&"."&D34&" IS MISSING AND c0040 = 'ISIN' AND c0360 = 'Unit') AS A;" -> ,SELECT 'B02' AS TAB, 'WARNING' AS ALERT_TYPE, 'v_1_0032' AS CHECK_ID, ROW_NUMBER, CASE WHEN A.ISSUES >0 THEN 1 ELSE 0 END AS v_1_0032 FROM (SELECT COUNT(*) AS ISSUES FROM B02 WHERE B02.0370 IS MISSING AND c0040 = 'ISIN' AND c0360 = 'Unit') AS A; | V34: =+",CASE WHEN "&N34&" IS MISSING AND "&P34&" = 'ISIN' AND "&R34&" = 'Unit' THEN 1 ELSE 0 END AS "&B34 -> ,CASE WHEN `0370_amnt_scrty_eur` IS MISSING AND `0040_typ_uniq_id_knwn_cntrprty` = 'ISIN' AND `0360_trdng_mthd` = 'Unit' THEN 1 ELSE 0 END AS v_1_0032 | W34: =+"SUM("&B34&") AS LVL1_W_"&MID(N34,2,LEN(N34)-2)&"," -> SUM(v_1_0032) AS LVL1_W_0370_amnt_scrty_eur,
A35: 0033 | B35: =CONCATENATE("v_1_",A35) -> v_1_0033 | C35: B02.00 | D35: =VLOOKUP(CONCATENATE(C35,"_",E35),'Data types'!A:E,4,FALSE) -> 0390 | E35: Number of securities outstanding not held by the reporting entity | F35: =VLOOKUP(CONCATENATE(C35,"_",E35),'Data types'!A:F,6,FALSE) -> Numeric: Integer | G35: X | I35: Test for missing values. | J35: Rule applicable only if c0040 = "ISIN". | K35: Missing value. The field must be reported when c0040 = "ISIN". If the value is zero, "0" must be entered. | L35: =+IF(G35="X","HIGH","WARNING") -> HIGH | M35: =+LEFT(C35,3) -> B02 | N35: ="`"&VLOOKUP(D35,'B02_Mapping fields'!B:C,2,FALSE)&"`" -> `0390_nmbr_scrts_not_rprtng_entty` | O35: 0040 | P35: ="`"&VLOOKUP(O35,'B02_Mapping fields'!B:C,2,FALSE)&"`" -> `0040_typ_uniq_id_knwn_cntrprty` | U35: =+",SELECT '"&M35&"' AS TAB, '"&L35&"' AS ALERT_TYPE, '"&B35&"' AS CHECK_ID, ROW_NUMBER, CASE WHEN A.ISSUES >0 THEN 1 ELSE 0 END AS "&B35&" FROM (SELECT COUNT(*) AS ISSUES FROM "&M35&" WHERE "&M35&"."&D35&" IS MISSING AND c0040 = 'ISIN') AS A;" -> ,SELECT 'B02' AS TAB, 'HIGH' AS ALERT_TYPE, 'v_1_0033' AS CHECK_ID, ROW_NUMBER, CASE WHEN A.ISSUES >0 THEN 1 ELSE 0 END AS v_1_0033 FROM (SELECT COUNT(*) AS ISSUES FROM B02 WHERE B02.0390 IS MISSING AND c0040 = 'ISIN') AS A; | V35: =+",CASE WHEN "&N35&" IS MISSING AND "&P35&" = 'ISIN' THEN 1 ELSE 0 END AS "&B35 -> ,CASE WHEN `0390_nmbr_scrts_not_rprtng_entty` IS MISSING AND `0040_typ_uniq_id_knwn_cntrprty` = 'ISIN' THEN 1 ELSE 0 END AS v_1_0033 | W35: =+"SUM("&B35&") AS LVL1_H_"&MID(N35,2,LEN(N35)-2)&"," -> SUM(v_1_0033) AS LVL1_H_0390_nmbr_scrts_not_rprtng_entty,
A36: 0034 | B36: =CONCATENATE("v_1_",A36) -> v_1_0034 | C36: B02.00 | D36: =VLOOKUP(CONCATENATE(C36,"_",E36),'Data types'!A:E,4,FALSE) -> 0391 | E36: Number of securities outstanding held by the reporting entity | F36: =VLOOKUP(CONCATENATE(C36,"_",E36),'Data types'!A:F,6,FALSE) -> Numeric: Integer | G36: X | I36: Test for missing values. | J36: Rule applicable only if c0040 = "ISIN". | K36: Missing value. The field must be reported for securities. If the value is zero, "0" must be entered. | L36: =+IF(G36="X","HIGH","WARNING") -> HIGH | M36: =+LEFT(C36,3) -> B02 | N36: ="`"&VLOOKUP(D36,'B02_Mapping fields'!B:C,2,FALSE)&"`" -> `0391_nmbr_scrts_rprtng_entty` | O36: 0040 | P36: ="`"&VLOOKUP(O36,'B02_Mapping fields'!B:C,2,FALSE)&"`" -> `0040_typ_uniq_id_knwn_cntrprty` | U36: =+",SELECT '"&M36&"' AS TAB, '"&L36&"' AS ALERT_TYPE, '"&B36&"' AS CHECK_ID, ROW_NUMBER, CASE WHEN A.ISSUES >0 THEN 1 ELSE 0 END AS "&B36&" FROM (SELECT COUNT(*) AS ISSUES FROM "&M36&" WHERE "&M36&"."&D36&" IS MISSING AND c0040 = 'ISIN') AS A;" -> ,SELECT 'B02' AS TAB, 'HIGH' AS ALERT_TYPE, 'v_1_0034' AS CHECK_ID, ROW_NUMBER, CASE WHEN A.ISSUES >0 THEN 1 ELSE 0 END AS v_1_0034 FROM (SELECT COUNT(*) AS ISSUES FROM B02 WHERE B02.0391 IS MISSING AND c0040 = 'ISIN') AS A; | V36: =+",CASE WHEN "&N36&" IS MISSING AND "&P36&" = 'ISIN' THEN 1 ELSE 0 END AS "&B36 -> ,CASE WHEN `0391_nmbr_scrts_rprtng_entty` IS MISSING AND `0040_typ_uniq_id_knwn_cntrprty` = 'ISIN' THEN 1 ELSE 0 END AS v_1_0034 | W36: =+"SUM("&B36&") AS LVL1_H_"&MID(N36,2,LEN(N36)-2)&"," -> SUM(v_1_0034) AS LVL1_H_0391_nmbr_scrts_rprtng_entty,
A37: 0035 | B37: =CONCATENATE("v_1_",A37) -> v_1_0035 | C37: B02.00 | D37: =VLOOKUP(CONCATENATE(C37,"_",E37),'Data types'!A:E,4,FALSE) -> 0400 | E37: Accrued interest per security | F37: =VLOOKUP(CONCATENATE(C37,"_",E37),'Data types'!A:F,6,FALSE) -> Numeric: 4 decimals | G37: X | I37: Test for missing values. | J37: Rule applicable if c0040 = "ISIN", c0250 = ("Non-Structured/Vanilla" OR "Other non-standard terms) AND c0240 != "ZCB issued at discount" | K37: Missing value. The field must be reported for non-structured securities that are not zero coupon bonds issued at discount. | L37: =+IF(G37="X","HIGH","WARNING") -> HIGH | M37: =+LEFT(C37,3) -> B02 | N37: ="`"&VLOOKUP(D37,'B02_Mapping fields'!B:C,2,FALSE)&"`" -> `0400_accrd_intrst_scrty` | O37: 0040 | P37: ="`"&VLOOKUP(O37,'B02_Mapping fields'!B:C,2,FALSE)&"`" -> `0040_typ_uniq_id_knwn_cntrprty` | Q37: 0250 | R37: ="`"&VLOOKUP(Q37,'B02_Mapping fields'!B:C,2,FALSE)&"`" -> `0250_strctrd_prdct` | S37: 0240 | T37: ="`"&VLOOKUP(S37,'B02_Mapping fields'!B:C,2,FALSE)&"`" -> `0240_zero_coupon` | U37: =+",SELECT '"&M37&"' AS TAB, '"&L37&"' AS ALERT_TYPE, '"&B37&"' AS CHECK_ID, ROW_NUMBER, CASE WHEN A.ISSUES >0 THEN 1 ELSE 0 END AS "&B37&" FROM (SELECT COUNT(*) AS ISSUES FROM "&M37&" WHERE "&M37&"."&D37&" IS MISSING AND c0250 IN ('Non-Structured/Vanilla', 'Other non-standard terms') AND c0240 != 'ZCB issued at discount') AS A;" -> ,SELECT 'B02' AS TAB, 'HIGH' AS ALERT_TYPE, 'v_1_0035' AS CHECK_ID, ROW_NUMBER, CASE WHEN A.ISSUES >0 THEN 1 ELSE 0 END AS v_1_0035 FROM (SELECT COUNT(*) AS ISSUES FROM B02 WHERE B02.0400 IS MISSING AND c0250 IN ('Non-Structured/Vanilla', 'Other non-standard terms') AND c0240 != 'ZCB issued at discount') AS A; | V37: =+",CASE WHEN "&N37&" IS MISSING AND "&P37&" = 'ISIN' AND "&R37&" IN ('Non-Structured/Vanilla', 'Other non-standard terms') AND "&T37&" != 'ZCB issued at discount' THEN 1 ELSE 0 END AS "&B37 -> ,CASE WHEN `0400_accrd_intrst_scrty` IS MISSING AND `0040_typ_uniq_id_knwn_cntrprty` = 'ISIN' AND `0250_strctrd_prdct` IN ('Non-Structured/Vanilla', 'Other non-standard terms') AND `0240_zero_coupon` != 'ZCB issued at discount' THEN 1 ELSE 0 END AS v_1_0035 | W37: =+"SUM("&B37&") AS LVL1_H_"&MID(N37,2,LEN(N37)-2)&"," -> SUM(v_1_0035) AS LVL1_H_0400_accrd_intrst_scrty,
A38: 0036 | B38: =CONCATENATE("v_1_",A38) -> v_1_0036 | C38: B02.00 | D38: =VLOOKUP(CONCATENATE(C38,"_",E38),'Data types'!A:E,4,FALSE) -> 0400 | E38: Accrued interest per security | F38: =VLOOKUP(CONCATENATE(C38,"_",E38),'Data types'!A:F,6,FALSE) -> Numeric: 4 decimals | H38: X | I38: Test for missing values. | J38: Rule applicable if c0040 = "ISIN", c0250 != ("Structured" OR "Only structured coupon") | K38: Missing value (warning only). This field must be reported for structured securities if the information exists. | L38: =+IF(G38="X","HIGH","WARNING") -> WARNING | M38: =+LEFT(C38,3) -> B02 | N38: ="`"&VLOOKUP(D38,'B02_Mapping fields'!B:C,2,FALSE)&"`" -> `0400_accrd_intrst_scrty` | O38: 0040 | P38: ="`"&VLOOKUP(O38,'B02_Mapping fields'!B:C,2,FALSE)&"`" -> `0040_typ_uniq_id_knwn_cntrprty` | Q38: 0250 | R38: ="`"&VLOOKUP(Q38,'B02_Mapping fields'!B:C,2,FALSE)&"`" -> `0250_strctrd_prdct` | U38: =+",SELECT '"&M38&"' AS TAB, '"&L38&"' AS ALERT_TYPE, '"&B38&"' AS CHECK_ID, ROW_NUMBER, CASE WHEN A.ISSUES >0 THEN 1 ELSE 0 END AS "&B38&" FROM (SELECT COUNT(*) AS ISSUES FROM "&M38&" WHERE "&M38&"."&D38&" IS MISSING AND c0040 = 'ISIN' AND c0250 NOT IN ('Structured', 'Only structured coupon')) AS A;" -> ,SELECT 'B02' AS TAB, 'WARNING' AS ALERT_TYPE, 'v_1_0036' AS CHECK_ID, ROW_NUMBER, CASE WHEN A.ISSUES >0 THEN 1 ELSE 0 END AS v_1_0036 FROM (SELECT COUNT(*) AS ISSUES FROM B02 WHERE B02.0400 IS MISSING AND c0040 = 'ISIN' AND c0250 NOT IN ('Structured', 'Only structured coupon')) AS A; | V38: =+",CASE WHEN "&N38&" IS MISSING AND "&P38&" = 'ISIN' AND "&R38&" NOT IN ('Structured', 'Only structured coupon') THEN 1 ELSE 0 END AS "&B38 -> ,CASE WHEN `0400_accrd_intrst_scrty` IS MISSING AND `0040_typ_uniq_id_knwn_cntrprty` = 'ISIN' AND `0250_strctrd_prdct` NOT IN ('Structured', 'Only structured coupon') THEN 1 ELSE 0 END AS v_1_0036 | W38: =+"SUM("&B38&") AS LVL1_W_"&MID(N38,2,LEN(N38)-2)&"," -> SUM(v_1_0036) AS LVL1_W_0400_accrd_intrst_scrty,
A39: 0037 | B39: =CONCATENATE("v_1_",A39) -> v_1_0037 | C39: B02.00 | D39: =VLOOKUP(CONCATENATE(C39,"_",E39),'Data types'!A:E,4,FALSE) -> 0610 | E39: Carrying amount IFRS | F39: =VLOOKUP(CONCATENATE(C39,"_",E39),'Data types'!A:F,6,FALSE) -> Numeric: 2 decimals | H39: X | I39: Test for missing values. | K39: Missing value (warning only). The field must be reported if the information exists, i.e. the entity reports in IFRS. | L39: =+IF(G39="X","HIGH","WARNING") -> WARNING | M39: =+LEFT(C39,3) -> B02 | N39: ="`"&VLOOKUP(D39,'B02_Mapping fields'!B:C,2,FALSE)&"`" -> `0610_crryng_amnt_ifrs` | U39: =+",SELECT '"&M39&"' AS TAB, '"&L39&"' AS ALERT_TYPE, '"&B39&"' AS CHECK_ID, ROW_NUMBER, CASE WHEN A.ISSUES >0 THEN 1 ELSE 0 END AS "&B39&" FROM (SELECT COUNT(*) AS ISSUES FROM "&M39&" WHERE "&M39&"."&D39&" IS MISSING) AS A;" -> ,SELECT 'B02' AS TAB, 'WARNING' AS ALERT_TYPE, 'v_1_0037' AS CHECK_ID, ROW_NUMBER, CASE WHEN A.ISSUES >0 THEN 1 ELSE 0 END AS v_1_0037 FROM (SELECT COUNT(*) AS ISSUES FROM B02 WHERE B02.0610 IS MISSING) AS A; | V39: =+",CASE WHEN "&N39&" IS MISSING THEN 1 ELSE 0 END AS "&B39 -> ,CASE WHEN `0610_crryng_amnt_ifrs` IS MISSING THEN 1 ELSE 0 END AS v_1_0037 | W39: =+"SUM("&B39&") AS LVL1_W_"&MID(N39,2,LEN(N39)-2)&"," -> SUM(v_1_0037) AS LVL1_W_0610_crryng_amnt_ifrs,
A40: 0038 | B40: =CONCATENATE("v_1_",A40) -> v_1_0038 | C40: B02.00 | D40: =VLOOKUP(CONCATENATE(C40,"_",E40),'Data types'!A:E,4,FALSE) -> 5000 | E40: Instrument/liability is issued to or bought by an existing shareholder that is not part of the same resolution group | F40: =VLOOKUP(CONCATENATE(C40,"_",E40),'Data types'!A:F,6,FALSE) -> String: TRUE / FALSE boolean | G40: X | I40: Test for missing values. | J40: if {B99.00;c0060} = "Non-Resolution Entity" | K40: Missing value. The field must be reported for Non-Resolution Entities. | L40: =+IF(G40="X","HIGH","WARNING") -> HIGH | M40: =+LEFT(C40,3) -> B02 | N40: ="`"&VLOOKUP(D40,'B02_Mapping fields'!B:C,2,FALSE)&"`" -> `5000_flg_shrhldr_not_rsltn_grp` | O40: 0060 | P40: ="`"&VLOOKUP(O40,'B02_Mapping fields'!B:C,2,FALSE)&"`" -> `0060_orgnl_amnt_fx` | V40: =+",CASE WHEN "&N40&" IS MISSING AND B99."&P40&" = 'Non-Resolution Entity' THEN 1 ELSE 0 END AS "&B40 -> ,CASE WHEN `5000_flg_shrhldr_not_rsltn_grp` IS MISSING AND B99.`0060_orgnl_amnt_fx` = 'Non-Resolution Entity' THEN 1 ELSE 0 END AS v_1_0038 | W40: =+"SUM("&B40&") AS LVL1_H_"&MID(N40,2,LEN(N40)-2)&"," -> SUM(v_1_0038) AS LVL1_H_5000_flg_shrhldr_not_rsltn_grp, | X40: --> Requer left join com B99 filtrado por c0011 por B02.00 e usando c0020 como chave
...

Sheet Level 2
B1: Level 2 Validation Rules: internal consistency checks. | Y1: utilizar case when's
B2: Check ID | C2: Tab | D2: Data point (Row/Column) | E2: Data point (Label) | F2: Data point type | G2: High severity (i.e the validation rule should in general not be breached) | H2: Warning only (i.e. the validation rule can be breached in certain cases) | I2: Type of test | J2: Prerequisites | K2: Explanation | L2: AUX_ALERT | M2: AUX_TAB | N2: AUX_FIELD1 | O2: FIELD2 | P2: AUX_FIELD2 | Q2: FIELD3 | R2: AUX_FIELD3 | S2: FIELD4 | T2: AUX_FIELD4 | U2: FIELD5 | V2: AUX_FIELD5 | W2: FIELD6 | X2: AUX_FIELD6 | Y2: OPTION 2
