Workbook
Name asefadf: #REF!
Name bn: #REF!

Sheet 1. Campos
G2: Campos adicionados ao âmbito na nova versão da Corporação
G3: Campos fora de âmbito na nova versão da Corporação
G4: Campos por especificar do plano anterior (colunas AM/AN - Novo projeto martelado com não)
G5: Campos por testar do plano anterior (colunas AM/AN - Novo projeto martelado com não)
C6: Obs:. É necessário filtrar tudo o que não esta fora de âmbito, tudo o que não esta no PDS e excluir os verdes que são para testes e os vermelhos que foram excluidos.
B8: ID Data field / Field order | C8: Table | D8: Category | E8: Anacredit | G8: Data field | H8: Efectivo y otros depósitos a la vista / Cash balances and other deposits | I8: Bancos Centrales / Central Banks | J8: Administraciones públicas / General governments | K8: Entidades de crédito / Credit institutions | L8: Otras sociedades financieras / Other financial corporations | M8: Sociedades no financieras / Non financial corporations | N8: Hogares / Households | O8: DEBT SECURITIES (this column only applies to report the instrument table) | P8: Non-contractual balances and Accounting adjustments (this column only applies to report the instrument table) | Q8: Instrument cancelled (this column only applies to report the instrument and instrument activity tables) | R8: Data Types | S8: Guidance on data types | T8: Default value for missing data | U8: Default value for not applicable fields to be used WHEN the field is applicable for the corresponding segment (F to L columns ) | V8: Default value for not applicable fields to be used WHEN: (1) Non-contractual balances and accounting adjustments (2) If the field is not applicable for the corresponding segment (F to L columns) | W8: Field name | X8: Field Definition / Additional Guidance | Y8: BDR Status (*) Not applicable = not identified as available in BDR | Z8: BDR Definition | AA8: BDR Comments | AB8: Structural ECB Loan Tape | AC8: Green Dashboard | AD8: Pillar III ESG & CSRD | AE8: Green Finance | AF8: ESG Risks | AG8: Leveraged Finance | AH8: D + 15 [Green Dashboard] | AI8: D + 18 [+ Pillar III ESG] | AJ8: > D + 18 [+ ECB Loan Tape] | AK8: Âmbito | AL8: ESPEC PM | AM8: ESPEC PILAR 3 V12 | AN8: PdS 5.12 | AO8: Novo Projeto | AP8: PROJ GF | AQ8: STATUS PdS | AR8: STATUS GF | AT8: Especificação | AU8: Teste | AV8: Package | AW8: Status Entregas | AX8: Comentários
A9: =+C9&G9 -> ENTITYCOD_SOC | B9: EN.001 | C9: ENTITY | D9: Cargabal entity | E9: N | F9: COD_SOC | G9: COD_SOC | H9: Y | I9: Y | J9: Y | K9: Y | L9: Y | M9: Y | N9: Y | R9: VARCHAR2(5) | S9: Free (latin) text without special characters (semicolon, quotes, …) | T9: Default value not allowed | U9: Default value not allowed | V9: Default value not allowed | W9: Entity code of the informing society. | X9: Cargabal code or internal identifier of the informing society. | Y9: Not applicable | Z9: N/A | AA9: - | AB9: Y | AC9: N | AD9: Y | AE9: Y | AF9: Y | AG9: Y | AH9: N | AI9: Y | AJ9: Y | AK9: =+IF(AND(AD9="N",AF9="N"),"Fora de âmbito", IF(AND(AD9="N",AF9="Y"),"Apenas ESG Risk", IF(AND(AD9="Y",AF9="N"),"Apenas Pilar 3", IF(AND(AD9="Y",AF9="Y"),"Comum","")))) -> Comum | AL9: =+IF(IFERROR(VLOOKUP(A9,Ficheiros!I:I,1,FALSE),"")=A9,"Sim","Não") -> Sim | AM9: =+IF(IFERROR(VLOOKUP(A9,Ficheiros!E:E,1,FALSE),"")=A9,"Sim","Não") -> Não | AN9: =+IF(IFERROR(VLOOKUP(A9,Ficheiros!O:O,1,FALSE),"")=A9,"Sim","Não") -> Sim | AO9: =+IF(IFERROR(VLOOKUP(A9,'Especificação Novos Req. LT (2'!A:A,1,FALSE),"")=A9,"Sim","Não") -> Não | AP9: =+IF(IFERROR(VLOOKUP(A9,Ficheiros!T:T,1,FALSE),"")=A9,"Sim","Não") -> Sim | AQ9: =+VLOOKUP(A9,Ficheiros!O:P,2,FALSE) -> 1. Concluído | AR9: =+VLOOKUP(A9,Ficheiros!T:U,2,FALSE) -> 9. Concluído | AS9: =+VLOOKUP(A9,Ficheiros!T:V,3,FALSE) -> PM
A10: =+C10&G10 -> ENTITYCNTRY | B10: EN.002 | C10: ENTITY | D10: General | E10: Y | F10: CNTRY | G10: CNTRY | H10: Y | I10: Y | J10: Y | K10: Y | L10: Y | M10: Y | N10: Y | R10: Code list | S10: Use codes from the code list sheet | T10: MISS | U10: Default value not allowed | V10: N/A | W10: Country of counterparty residence | X10: Country of counterparty residence. | Y10: Yes - Mapping | Z10: BDR - Code List | AA10: - | AB10: Y | AC10: N | AD10: Y | AE10: Y | AF10: Y | AG10: Y | AH10: N | AI10: Y | AJ10: Y | AK10: =+IF(AND(AD10="N",AF10="N"),"Fora de âmbito", IF(AND(AD10="N",AF10="Y"),"Apenas ESG Risk", IF(AND(AD10="Y",AF10="N"),"Apenas Pilar 3", IF(AND(AD10="Y",AF10="Y"),"Comum","")))) -> Comum | AL10: =+IF(IFERROR(VLOOKUP(A10,Ficheiros!I:I,1,FALSE),"")=A10,"Sim","Não") -> Sim | AM10: =+IF(IFERROR(VLOOKUP(A10,Ficheiros!E:E,1,FALSE),"")=A10,"Sim","Não") -> Não | AN10: =+IF(IFERROR(VLOOKUP(A10,Ficheiros!O:O,1,FALSE),"")=A10,"Sim","Não") -> Sim | AO10: =+IF(IFERROR(VLOOKUP(A10,'Especificação Novos Req. LT (2'!A:A,1,FALSE),"")=A10,"Sim","Não") -> Não | AP10: =+IF(IFERROR(VLOOKUP(A10,Ficheiros!T:T,1,FALSE),"")=A10,"Sim","Não") -> Sim | AQ10: =+VLOOKUP(A10,Ficheiros!O:P,2,FALSE) -> 1. Concluído | AR10: =+VLOOKUP(A10,Ficheiros!T:U,2,FALSE) -> 9. Concluído | AS10: =+VLOOKUP(A10,Ficheiros!T:V,3,FALSE) -> PM
A11: =+C11&G11 -> ENTITYDT_BRTH | B11: EN.003 | C11: ENTITY | D11: General | E11: Y | F11: DT_BRTH | G11: DT_BRTH | H11: N | I11: N | J11: N | K11: N | L11: N | M11: Y | N11: Y | R11: DATE | S11: YYYY-MM-DD | T11: 0000-00-00 | U11: Default value not allowed | V11: 1111-11-11 | W11: Birth date counterparty | X11: Date when the entity was born / registered. | Y11: Yes - Equivalent | Z11: JM_CLIENT_BII - G4093_FECNACIM | AA11: - | AB11: Y | AC11: N | AD11: N | AE11: N | AF11: N | AG11: N | AH11: N | AI11: N | AJ11: Y | AK11: =+IF(AND(AD11="N",AF11="N"),"Fora de âmbito", IF(AND(AD11="N",AF11="Y"),"Apenas ESG Risk", IF(AND(AD11="Y",AF11="N"),"Apenas Pilar 3", IF(AND(AD11="Y",AF11="Y"),"Comum","")))) -> Fora de âmbito | AL11: =+IF(IFERROR(VLOOKUP(A11,Ficheiros!I:I,1,FALSE),"")=A11,"Sim","Não") -> Sim | AM11: =+IF(IFERROR(VLOOKUP(A11,Ficheiros!E:E,1,FALSE),"")=A11,"Sim","Não") -> Não | AN11: =+IF(IFERROR(VLOOKUP(A11,Ficheiros!O:O,1,FALSE),"")=A11,"Sim","Não") -> Não | AO11: =+IF(IFERROR(VLOOKUP(A11,'Especificação Novos Req. LT (2'!A:A,1,FALSE),"")=A11,"Sim","Não") -> Não | AP11: =+IF(IFERROR(VLOOKUP(A11,Ficheiros!T:T,1,FALSE),"")=A11,"Sim","Não") -> Sim | AQ11: =+VLOOKUP(A11,Ficheiros!O:P,2,FALSE) -> #N/A | AR11: =+VLOOKUP(A11,Ficheiros!T:U,2,FALSE) -> 7. Analisar controlos e completude | AS11: =+VLOOKUP(A11,Ficheiros!T:V,3,FALSE) -> PM
A12: =+C12&G12 -> ENTITYDT_DFLT_STTS | B12: EN.004 | C12: ENTITY | D12: General | E12: Y | F12: DT_DFLT_STTS | G12: DT_DFLT_STTS | H12: Y | I12: Y | J12: Y | K12: Y | L12: Y | M12: Y | N12: Y | R12: DATE | S12: YYYY-MM-DD | T12: 0000-00-00 | U12: 1111-11-11 | V12: 1111-11-11 | W12: Date of default status | X12: The date on which the default status, as reported in the data attribute “Default status”, is considered to have arisen. If "Not in default" since inception then this attribute is to be reported equally to the inception date. If default classification performed on instrument level then Entity is classified as defaulted when at least one instrument is classified as defaulted. If more than one Instrument is classified as defaulted then the earliest date has to be provided. The definition of default is aligned with Art 178 of Regulation (EU) No 575/2013. | Y12: Not applicable | Z12: N/A | AA12: - | AB12: Y | AC12: N | AD12: N | AE12: N | AF12: N | AG12: Y | AH12: N | AI12: N | AJ12: Y | AK12: =+IF(AND(AD12="N",AF12="N"),"Fora de âmbito", IF(AND(AD12="N",AF12="Y"),"Apenas ESG Risk", IF(AND(AD12="Y",AF12="N"),"Apenas Pilar 3", IF(AND(AD12="Y",AF12="Y"),"Comum","")))) -> Fora de âmbito | AL12: =+IF(IFERROR(VLOOKUP(A12,Ficheiros!I:I,1,FALSE),"")=A12,"Sim","Não") -> Sim | AM12: =+IF(IFERROR(VLOOKUP(A12,Ficheiros!E:E,1,FALSE),"")=A12,"Sim","Não") -> Não | AN12: =+IF(IFERROR(VLOOKUP(A12,Ficheiros!O:O,1,FALSE),"")=A12,"Sim","Não") -> Não | AO12: =+IF(IFERROR(VLOOKUP(A12,'Especificação Novos Req. LT (2'!A:A,1,FALSE),"")=A12,"Sim","Não") -> Não | AP12: =+IF(IFERROR(VLOOKUP(A12,Ficheiros!T:T,1,FALSE),"")=A12,"Sim","Não") -> Sim | AQ12: =+VLOOKUP(A12,Ficheiros!O:P,2,FALSE) -> #N/A | AR12: =+VLOOKUP(A12,Ficheiros!T:U,2,FALSE) -> 3. Pendente de decisão | AS12: =+VLOOKUP(A12,Ficheiros!T:V,3,FALSE) -> LF
A13: =+C13&G13 -> ENTITYDT_FNNCL_STTMTS | B13: EN.005 | C13: ENTITY | D13: General | E13: N | F13: DT_FNNCL_STTMTS | G13: DT_FNNCL_STTMTS | H13: Y | I13: Y | J13: Y | K13: Y | L13: Y | M13: Y | N13: N | R13: DATE | S13: YYYY-MM-DD | T13: 0000-00-00 | U13: 1111-11-11 | V13: 1111-11-11 | W13: Date of financial statements | X13: Date of financial statements. Please report on solo entity level unless advised otherwise. | Y13: Not applicable | Z13: N/A | AA13: - | AB13: Y | AC13: N | AD13: N | AE13: N | AF13: N | AG13: Y | AH13: N | AI13: N | AJ13: Y | AK13: =+IF(AND(AD13="N",AF13="N"),"Fora de âmbito", IF(AND(AD13="N",AF13="Y"),"Apenas ESG Risk", IF(AND(AD13="Y",AF13="N"),"Apenas Pilar 3", IF(AND(AD13="Y",AF13="Y"),"Comum","")))) -> Fora de âmbito | AL13: =+IF(IFERROR(VLOOKUP(A13,Ficheiros!I:I,1,FALSE),"")=A13,"Sim","Não") -> Sim | AM13: =+IF(IFERROR(VLOOKUP(A13,Ficheiros!E:E,1,FALSE),"")=A13,"Sim","Não") -> Não | AN13: =+IF(IFERROR(VLOOKUP(A13,Ficheiros!O:O,1,FALSE),"")=A13,"Sim","Não") -> Não | AO13: =+IF(IFERROR(VLOOKUP(A13,'Especificação Novos Req. LT (2'!A:A,1,FALSE),"")=A13,"Sim","Não") -> Não | AP13: =+IF(IFERROR(VLOOKUP(A13,Ficheiros!T:T,1,FALSE),"")=A13,"Sim","Não") -> Sim | AQ13: =+VLOOKUP(A13,Ficheiros!O:P,2,FALSE) -> #N/A | AR13: =+VLOOKUP(A13,Ficheiros!T:U,2,FALSE) -> 2. Alterar especificação | AS13: =+VLOOKUP(A13,Ficheiros!T:V,3,FALSE) -> PM & LF
A14: =+C14&G14 -> ENTITYDT_FNNCL_STTMTS_PRVS | B14: EN.006 | C14: ENTITY | D14: General | E14: N | F14: DT_FNNCL_STTMTS_PRVS | G14: DT_FNNCL_STTMTS_PRVS | H14: Y | I14: Y | J14: Y | K14: Y | L14: Y | M14: Y | N14: N | R14: DATE | S14: YYYY-MM-DD | T14: 0000-00-00 | U14: 1111-11-11 | V14: 1111-11-11 | W14: Date of previous fiscal year financial statements | X14: Date of previous fiscal year financial statements. Please report on solo entity level unless advised otherwise. | Y14: Not applicable | Z14: N/A | AA14: - | AB14: Y | AC14: N | AD14: N | AE14: N | AF14: N | AG14: Y | AH14: N | AI14: N | AJ14: Y | AK14: =+IF(AND(AD14="N",AF14="N"),"Fora de âmbito", IF(AND(AD14="N",AF14="Y"),"Apenas ESG Risk", IF(AND(AD14="Y",AF14="N"),"Apenas Pilar 3", IF(AND(AD14="Y",AF14="Y"),"Comum","")))) -> Fora de âmbito | AL14: =+IF(IFERROR(VLOOKUP(A14,Ficheiros!I:I,1,FALSE),"")=A14,"Sim","Não") -> Sim | AM14: =+IF(IFERROR(VLOOKUP(A14,Ficheiros!E:E,1,FALSE),"")=A14,"Sim","Não") -> Não | AN14: =+IF(IFERROR(VLOOKUP(A14,Ficheiros!O:O,1,FALSE),"")=A14,"Sim","Não") -> Não | AO14: =+IF(IFERROR(VLOOKUP(A14,'Especificação Novos Req. LT (2'!A:A,1,FALSE),"")=A14,"Sim","Não") -> Não | AP14: =+IF(IFERROR(VLOOKUP(A14,Ficheiros!T:T,1,FALSE),"")=A14,"Sim","Não") -> Sim | AQ14: =+VLOOKUP(A14,Ficheiros!O:P,2,FALSE) -> #N/A | AR14: =+VLOOKUP(A14,Ficheiros!T:U,2,FALSE) -> 2. Alterar especificação | AS14: =+VLOOKUP(A14,Ficheiros!T:V,3,FALSE) -> PM & LF
A15: =+C15&G15 -> ENTITYDT_INTTN_LGL_PRCDNGS_LE | B15: EN.007 | C15: ENTITY | D15: General | E15: Y | F15: DT_INTTN_LGL_PRCDNGS_LE | G15: DT_INTTN_LGL_PRCDNGS_LE | H15: Y | I15: Y | J15: Y | K15: Y | L15: Y | M15: Y | N15: Y | R15: DATE | S15: YYYY-MM-DD | T15: 0000-00-00 | U15: 1111-11-11 | V15: 1111-11-11 | W15: Date of initiation of legal proceedings counterparty (LE) | X15: Date of initiation of legal proceedings counterparty (LE). Only for Retail portfolios: The date when the hard collection process was initiated for given entity. If the hard collection process is defined on the level of instrument or protection and more instruments or protections with status "Other legal measures" are linked to the same entity the oldest date is reported. | Y15: Yes - Computed | Z15: IF E0623_GEST_SIT in (8;9) THEN E0623_FECULTMO | AA15: - | AB15: Y | AC15: N | AD15: N | AE15: N | AF15: N | AG15: Y | AH15: N | AI15: N | AJ15: Y | AK15: =+IF(AND(AD15="N",AF15="N"),"Fora de âmbito", IF(AND(AD15="N",AF15="Y"),"Apenas ESG Risk", IF(AND(AD15="Y",AF15="N"),"Apenas Pilar 3", IF(AND(AD15="Y",AF15="Y"),"Comum","")))) -> Fora de âmbito | AL15: =+IF(IFERROR(VLOOKUP(A15,Ficheiros!I:I,1,FALSE),"")=A15,"Sim","Não") -> Sim | AM15: =+IF(IFERROR(VLOOKUP(A15,Ficheiros!E:E,1,FALSE),"")=A15,"Sim","Não") -> Não | AN15: =+IF(IFERROR(VLOOKUP(A15,Ficheiros!O:O,1,FALSE),"")=A15,"Sim","Não") -> Não | AO15: =+IF(IFERROR(VLOOKUP(A15,'Especificação Novos Req. LT (2'!A:A,1,FALSE),"")=A15,"Sim","Não") -> Não | AP15: =+IF(IFERROR(VLOOKUP(A15,Ficheiros!T:T,1,FALSE),"")=A15,"Sim","Não") -> Sim | AQ15: =+VLOOKUP(A15,Ficheiros!O:P,2,FALSE) -> #N/A | AR15: =+VLOOKUP(A15,Ficheiros!T:U,2,FALSE) -> 9. Concluído | AS15: =+VLOOKUP(A15,Ficheiros!T:V,3,FALSE) -> PM
A16: =+C16&G16 -> ENTITYDT_PRFRMNG_STTS_LE | B16: EN.008 | C16: ENTITY | D16: General | E16: N | F16: DT_PRFRMNG_STTS_LE | G16: DT_PRFRMNG_STTS_LE | H16: Y | I16: Y | J16: Y | K16: Y | L16: Y | M16: Y | N16: Y | R16: DATE | S16: YYYY-MM-DD | T16: 0000-00-00 | U16: 1111-11-11 | V16: 1111-11-11 | W16: Date of performing status | X16: The date at which the latest change of the performing status according to Part 17 of Annex V to Implementing Regulation (EU) No 680/2014 occurred. For entities performing from inception this date should be equal to inception date. | Y16: Not applicable | Z16: N/A | AA16: - | AB16: Y | AC16: N | AD16: N | AE16: N | AF16: N | AG16: Y | AH16: N | AI16: N | AJ16: Y | AK16: =+IF(AND(AD16="N",AF16="N"),"Fora de âmbito", IF(AND(AD16="N",AF16="Y"),"Apenas ESG Risk", IF(AND(AD16="Y",AF16="N"),"Apenas Pilar 3", IF(AND(AD16="Y",AF16="Y"),"Comum","")))) -> Fora de âmbito | AL16: =+IF(IFERROR(VLOOKUP(A16,Ficheiros!I:I,1,FALSE),"")=A16,"Sim","Não") -> Sim | AM16: =+IF(IFERROR(VLOOKUP(A16,Ficheiros!E:E,1,FALSE),"")=A16,"Sim","Não") -> Não | AN16: =+IF(IFERROR(VLOOKUP(A16,Ficheiros!O:O,1,FALSE),"")=A16,"Sim","Não") -> Não | AO16: =+IF(IFERROR(VLOOKUP(A16,'Especificação Novos Req. LT (2'!A:A,1,FALSE),"")=A16,"Sim","Não") -> Não | AP16: =+IF(IFERROR(VLOOKUP(A16,Ficheiros!T:T,1,FALSE),"")=A16,"Sim","Não") -> Sim | AQ16: =+VLOOKUP(A16,Ficheiros!O:P,2,FALSE) -> #N/A | AR16: =+VLOOKUP(A16,Ficheiros!T:U,2,FALSE) -> 3. Pendente de decisão | AS16: =+VLOOKUP(A16,Ficheiros!T:V,3,FALSE) -> LF
A17: =+C17&G17 -> ENTITYDT_RFRNC | B17: EN.009 | C17: ENTITY | D17: General | E17: Y | F17: DT_RFRNC | G17: DT_RFRNC | H17: Y | I17: Y | J17: Y | K17: Y | L17: Y | M17: Y | N17: Y | R17: DATE | S17: YYYY-MM-DD | T17: Default value not allowed | U17: Default value not allowed | V17: Default value not allowed | W17: Reference date. | X17: Reference date. The reference date can refer to end-of-month, end-of-quarter or end-of-year. The value is fixed for the entire loan tape and will be defined and communicated by the Head of Mission. | Y17: Not applicable | Z17: N/A | AA17: - | AB17: Y | AC17: N | AD17: Y | AE17: Y | AF17: N | AG17: Y | AH17: N | AI17: Y | AJ17: Y | AK17: =+IF(AND(AD17="N",AF17="N"),"Fora de âmbito", IF(AND(AD17="N",AF17="Y"),"Apenas ESG Risk", IF(AND(AD17="Y",AF17="N"),"Apenas Pilar 3", IF(AND(AD17="Y",AF17="Y"),"Comum","")))) -> Apenas Pilar 3 | AL17: =+IF(IFERROR(VLOOKUP(A17,Ficheiros!I:I,1,FALSE),"")=A17,"Sim","Não") -> Sim | AM17: =+IF(IFERROR(VLOOKUP(A17,Ficheiros!E:E,1,FALSE),"")=A17,"Sim","Não") -> Não | AN17: =+IF(IFERROR(VLOOKUP(A17,Ficheiros!O:O,1,FALSE),"")=A17,"Sim","Não") -> Sim | AO17: =+IF(IFERROR(VLOOKUP(A17,'Especificação Novos Req. LT (2'!A:A,1,FALSE),"")=A17,"Sim","Não") -> Não | AP17: =+IF(IFERROR(VLOOKUP(A17,Ficheiros!T:T,1,FALSE),"")=A17,"Sim","Não") -> Sim | AQ17: =+VLOOKUP(A17,Ficheiros!O:P,2,FALSE) -> 1. Concluído | AR17: =+VLOOKUP(A17,Ficheiros!T:U,2,FALSE) -> 9. Concluído | AS17: =+VLOOKUP(A17,Ficheiros!T:V,3,FALSE) -> PM
A18: =+C18&G18 -> ENTITYENTTY_ID | B18: EN.010 | C18: ENTITY | D18: General | E18: Y | F18: ENTTY_ID | G18: ENTTY_ID | H18: Y | I18: Y | J18: Y | K18: Y | L18: Y | M18: Y | N18: Y | R18: VARCHAR2(255) | S18: Free (latin) text without special characters (semicolon, quotes, …) | T18: Default value not allowed | U18: Default value not allowed | V18: Default value not allowed | W18: Entity ID | X18: An identifier applied by the reporting agent to uniquely identify each counterparty. Each counterparty has a unique and exclusive counterparty identifier. This means that this value will not change over time and can never be used as the counterparty identifier for any other counterparty. | Y18: Not applicable | Z18: N/A | AA18: - | AB18: Y | AC18: N | AD18: Y | AE18: Y | AF18: Y | AG18: Y | AH18: N | AI18: Y | AJ18: Y | AK18: =+IF(AND(AD18="N",AF18="N"),"Fora de âmbito", IF(AND(AD18="N",AF18="Y"),"Apenas ESG Risk", IF(AND(AD18="Y",AF18="N"),"Apenas Pilar 3", IF(AND(AD18="Y",AF18="Y"),"Comum","")))) -> Comum | AL18: =+IF(IFERROR(VLOOKUP(A18,Ficheiros!I:I,1,FALSE),"")=A18,"Sim","Não") -> Sim | AM18: =+IF(IFERROR(VLOOKUP(A18,Ficheiros!E:E,1,FALSE),"")=A18,"Sim","Não") -> Não | AN18: =+IF(IFERROR(VLOOKUP(A18,Ficheiros!O:O,1,FALSE),"")=A18,"Sim","Não") -> Sim | AO18: =+IF(IFERROR(VLOOKUP(A18,'Especificação Novos Req. LT (2'!A:A,1,FALSE),"")=A18,"Sim","Não") -> Não | AP18: =+IF(IFERROR(VLOOKUP(A18,Ficheiros!T:T,1,FALSE),"")=A18,"Sim","Não") -> Sim | AQ18: =+VLOOKUP(A18,Ficheiros!O:P,2,FALSE) -> 1. Concluído | AR18: =+VLOOKUP(A18,Ficheiros!T:U,2,FALSE) -> 7. Analisar controlos e completude | AS18: =+VLOOKUP(A18,Ficheiros!T:V,3,FALSE) -> LF
A19: =+C19&G19 -> ENTITYGCC_PRNT_ID | B19: EN.011 | C19: ENTITY | D19: General | E19: N | F19: GCC_PRNT_ID | G19: GCC_PRNT_ID | H19: Y | I19: Y | J19: Y | K19: Y | L19: Y | M19: Y | N19: N | R19: VARCHAR2(255) | S19: Free (latin) text without special characters (semicolon, quotes, …) | T19: MISS | U19: N/A | V19: N/A | W19: Identifier for the parent entity of a group of connected clients | X19: The unique identifier of the group of connected clients according to Art 4 para. 39 of Regulation (EU) No 575/2013. If an entity is part of more than one group of connected clients please report the identifier for the most relevant. | Y19: Yes - Equivalent | Z19: JM_GRUP_ECONO - G5512_GRUP_ECO | AA19: - | AB19: Y | AC19: N | AD19: N | AE19: N | AF19: N | AG19: Y | AH19: N | AI19: N | AJ19: Y | AK19: =+IF(AND(AD19="N",AF19="N"),"Fora de âmbito", IF(AND(AD19="N",AF19="Y"),"Apenas ESG Risk", IF(AND(AD19="Y",AF19="N"),"Apenas Pilar 3", IF(AND(AD19="Y",AF19="Y"),"Comum","")))) -> Fora de âmbito | AL19: =+IF(IFERROR(VLOOKUP(A19,Ficheiros!I:I,1,FALSE),"")=A19,"Sim","Não") -> Sim | AM19: =+IF(IFERROR(VLOOKUP(A19,Ficheiros!E:E,1,FALSE),"")=A19,"Sim","Não") -> Não | AN19: =+IF(IFERROR(VLOOKUP(A19,Ficheiros!O:O,1,FALSE),"")=A19,"Sim","Não") -> Não | AO19: =+IF(IFERROR(VLOOKUP(A19,'Especificação Novos Req. LT (2'!A:A,1,FALSE),"")=A19,"Sim","Não") -> Não | AP19: =+IF(IFERROR(VLOOKUP(A19,Ficheiros!T:T,1,FALSE),"")=A19,"Sim","Não") -> Sim | AQ19: =+VLOOKUP(A19,Ficheiros!O:P,2,FALSE) -> #N/A | AR19: =+VLOOKUP(A19,Ficheiros!T:U,2,FALSE) -> 9. Concluído | AS19: =+VLOOKUP(A19,Ficheiros!T:V,3,FALSE) -> PM
A20: =+C20&G20 -> ENTITYGCC_PRNT_NM | B20: EN.012 | C20: ENTITY | D20: General | E20: N | F20: GCC_PRNT_NM | G20: GCC_PRNT_NM | H20: Y | I20: Y | J20: Y | K20: Y | L20: Y | M20: Y | N20: N | R20: VARCHAR2(255) | S20: Free (latin) text without special characters (semicolon, quotes, …) | T20: MISS | U20: N/A | V20: N/A | W20: Name of the parent entity of a group of connected clients | X20: The name of the group of connected clients according to Art 4 para. 39 of Regulation (EU) No 575/2013. If an entity is part of more than one group of connected clients please report the name for the most relevant. | Y20: Yes - Equivalent | Z20: JM_GRUP_ECONO - G5512_DGRUPO | AA20: Report Name of the entity reported in EN.011 | AB20: Y | AC20: N | AD20: N | AE20: N | AF20: N | AG20: Y | AH20: N | AI20: N | AJ20: Y | AK20: =+IF(AND(AD20="N",AF20="N"),"Fora de âmbito", IF(AND(AD20="N",AF20="Y"),"Apenas ESG Risk", IF(AND(AD20="Y",AF20="N"),"Apenas Pilar 3", IF(AND(AD20="Y",AF20="Y"),"Comum","")))) -> Fora de âmbito | AL20: =+IF(IFERROR(VLOOKUP(A20,Ficheiros!I:I,1,FALSE),"")=A20,"Sim","Não") -> Sim | AM20: =+IF(IFERROR(VLOOKUP(A20,Ficheiros!E:E,1,FALSE),"")=A20,"Sim","Não") -> Não | AN20: =+IF(IFERROR(VLOOKUP(A20,Ficheiros!O:O,1,FALSE),"")=A20,"Sim","Não") -> Não | AO20: =+IF(IFERROR(VLOOKUP(A20,'Especificação Novos Req. LT (2'!A:A,1,FALSE),"")=A20,"Sim","Não") -> Não | AP20: =+IF(IFERROR(VLOOKUP(A20,Ficheiros!T:T,1,FALSE),"")=A20,"Sim","Não") -> Sim | AQ20: =+VLOOKUP(A20,Ficheiros!O:P,2,FALSE) -> #N/A | AR20: =+VLOOKUP(A20,Ficheiros!T:U,2,FALSE) -> 9. Concluído | AS20: =+VLOOKUP(A20,Ficheiros!T:V,3,FALSE) -> PM
... A23: =+C23&G23 -> ENTITYLEI | B23: EN.015 | C23: ENTITY | D23: General | E23: Y | F23: LEI | G23: LEI | H23: Y | I23: Y | J23: Y | K23: Y | L23: Y | M23: Y | N23: N | R23: VARCHAR2(20) | S23: Free (latin) text without special characters (semicolon, quotes, …) | T23: MISS | U23: N/A | V23: N/A | W23: Legal entity identifier Counterparty | X23: Legal entity identifier counterparty. | Y23: Not applicable | Z23: N/A | AA23: - | AB23: Y | AC23: N | AD23: Y | AE23: N | AF23: N | AG23: Y | AH23: N | AI23: Y | AJ23: Y | AK23: =+IF(AND(AD23="N",AF23="N"),"Fora de âmbito", IF(AND(AD23="N",AF23="Y"),"Apenas ESG Risk", IF(AND(AD23="Y",AF23="N"),"Apenas Pilar 3", IF(AND(AD23="Y",AF23="Y"),"Comum","")))) -> Apenas Pilar 3 | AL23: =+IF(IFERROR(VLOOKUP(A23,Ficheiros!I:I,1,FALSE),"")=A23,"Sim","Não") -> Sim | AM23: =+IF(IFERROR(VLOOKUP(A23,Ficheiros!E:E,1,FALSE),"")=A23,"Sim","Não") -> Não | AN23: =+IF(IFERROR(VLOOKUP(A23,Ficheiros!O:O,1,FALSE),"")=A23,"Sim","Não") -> Sim | AO23: =+IF(IFERROR(VLOOKUP(A23,'Especificação Novos Req. LT (2'!A:A,1,FALSE),"")=A23,"Sim","Não") -> Não | AP23: =+IF(IFERROR(VLOOKUP(A23,Ficheiros!T:T,1,FALSE),"")=A23,"Sim","Não") -> Sim | AQ23: =+VLOOKUP(A23,Ficheiros!O:P,2,FALSE) -> 1. Concluído | AR23: =+VLOOKUP(A23,Ficheiros!T:U,2,FALSE) -> 9. Concluído | AS23: =+VLOOKUP(A23,Ficheiros!T:V,3,FALSE) -> PM
A24: =+C24&G24 -> ENTITYENTTY_NM | B24: EN.016 | C24: ENTITY | D24: General | E24: Y | F24: ENTTY_NM | G24: ENTTY_NM | H24: Y | I24: Y | J24: Y | K24: Y | L24: Y | M24: Y | N24: Y | R24: VARCHAR2(255) | S24: Free (latin) text without special characters (semicolon, quotes, …) | T24: MISS | U24: Default value not allowed | V24: Default value not allowed | W24: Name Counterparty | X24: Name counterparty. | Y24: Not applicable | Z24: N/A | AA24: - | AB24: Y | AC24: N | AD24: Y | AE24: Y | AF24: N | AG24: Y | AH24: N | AI24: Y | AJ24: Y | AK24: =+IF(AND(AD24="N",AF24="N"),"Fora de âmbito", IF(AND(AD24="N",AF24="Y"),"Apenas ESG Risk", IF(AND(AD24="Y",AF24="N"),"Apenas Pilar 3", IF(AND(AD24="Y",AF24="Y"),"Comum","")))) -> Apenas Pilar 3 | AL24: =+IF(IFERROR(VLOOKUP(A24,Ficheiros!I:I,1,FALSE),"")=A24,"Sim","Não") -> Sim | AM24: =+IF(IFERROR(VLOOKUP(A24,Ficheiros!E:E,1,FALSE),"")=A24,"Sim","Não") -> Não | AN24: =+IF(IFERROR(VLOOKUP(A24,Ficheiros!O:O,1,FALSE),"")=A24,"Sim","Não") -> Não | AO24: =+IF(IFERROR(VLOOKUP(A24,'Especificação Novos Req. LT (2'!A:A,1,FALSE),"")=A24,"Sim","Não") -> Sim | AP24: =+IF(IFERROR(VLOOKUP(A24,Ficheiros!T:T,1,FALSE),"")=A24,"Sim","Não") -> Sim | AQ24: =+VLOOKUP(A24,Ficheiros!O:P,2,FALSE) -> #N/A | AR24: =+VLOOKUP(A24,Ficheiros!T:U,2,FALSE) -> 9. Concluído | AS24: =+VLOOKUP(A24,Ficheiros!T:V,3,FALSE) -> PM | AV24: Package 3
A25: =+C25&G25 -> ENTITYEXTRNL_RTNG_NM | B25: EN.017 | C25: ENTITY | D25: General | E25: N | F25: EXTRNL_RTNG_NM | G25: EXTRNL_RTNG_NM | H25: Y | I25: Y | J25: Y | K25: Y | L25: Y | M25: Y | N25: N | R25: VARCHAR2(255) | S25: Free (latin) text without special characters (semicolon, quotes, …) | T25: MISS | U25: N/A | V25: N/A | W25: Name of external rating agency | X25: Name of external rating agency for the external rating at the reference date. | Y25: Yes - Equivalent | Z25: JM_CAL_EXT_CL - R9415_COD_AGEN | AA25: - | AB25: Y | AC25: N | AD25: N | AE25: N | AF25: N | AG25: Y | AH25: N | AI25: N | AJ25: Y | AK25: =+IF(AND(AD25="N",AF25="N"),"Fora de âmbito", IF(AND(AD25="N",AF25="Y"),"Apenas ESG Risk", IF(AND(AD25="Y",AF25="N"),"Apenas Pilar 3", IF(AND(AD25="Y",AF25="Y"),"Comum","")))) -> Fora de âmbito | AL25: =+IF(IFERROR(VLOOKUP(A25,Ficheiros!I:I,1,FALSE),"")=A25,"Sim","Não") -> Sim | AM25: =+IF(IFERROR(VLOOKUP(A25,Ficheiros!E:E,1,FALSE),"")=A25,"Sim","Não") -> Não | AN25: =+IF(IFERROR(VLOOKUP(A25,Ficheiros!O:O,1,FALSE),"")=A25,"Sim","Não") -> Não | AO25: =+IF(IFERROR(VLOOKUP(A25,'Especificação Novos Req. LT (2'!A:A,1,FALSE),"")=A25,"Sim","Não") -> Não | AP25: =+IF(IFERROR(VLOOKUP(A25,Ficheiros!T:T,1,FALSE),"")=A25,"Sim","Não") -> Sim | AQ25: =+VLOOKUP(A25,Ficheiros!O:P,2,FALSE) -> #N/A | AR25: =+VLOOKUP(A25,Ficheiros!T:U,2,FALSE) -> 2. Alterar especificação | AS25: =+VLOOKUP(A25,Ficheiros!T:V,3,FALSE) -> LF
A26: =+C26&G26 -> ENTITYACCNTNG_FRMWRK_SL | B26: EN.018 | C26: ENTITY | D26: Classification | E26: Y | F26: ACCNTNG_FRMWRK_SL | G26: ACCNTNG_FRMWRK_SL | H26: Y | I26: Y | J26: Y | K26: Y | L26: Y | M26: Y | N26: N | R26: Code List | S26: Use codes from the code list sheet | T26: 99999999999 | U26: 11111111111 | V26: 11111111111 | W26: Accounting standard counterparty | X26: Accounting standard counterparty. | Y26: Not applicable | Z26: N/A | AA26: - | AB26: Y | AC26: N | AD26: N | AE26: N | AF26: N | AG26: Y | AH26: N | AI26: N | AJ26: Y | AK26: =+IF(AND(AD26="N",AF26="N"),"Fora de âmbito", IF(AND(AD26="N",AF26="Y"),"Apenas ESG Risk", IF(AND(AD26="Y",AF26="N"),"Apenas Pilar 3", IF(AND(AD26="Y",AF26="Y"),"Comum","")))) -> Fora de âmbito | AL26: =+IF(IFERROR(VLOOKUP(A26,Ficheiros!I:I,1,FALSE),"")=A26,"Sim","Não") -> Sim | AM26: =+IF(IFERROR(VLOOKUP(A26,Ficheiros!E:E,1,FALSE),"")=A26,"Sim","Não") -> Não | AN26: =+IF(IFERROR(VLOOKUP(A26,Ficheiros!O:O,1,FALSE),"")=A26,"Sim","Não") -> Não | AO26: =+IF(IFERROR(VLOOKUP(A26,'Especificação Novos Req. LT (2'!A:A,1,FALSE),"")=A26,"Sim","Não") -> Não | AP26: =+IF(IFERROR(VLOOKUP(A26,Ficheiros!T:T,1,FALSE),"")=A26,"Sim","Não") -> Sim | AQ26: =+VLOOKUP(A26,Ficheiros!O:P,2,FALSE) -> #N/A | AR26: =+VLOOKUP(A26,Ficheiros!T:U,2,FALSE) -> 2. Alterar especificação | AS26: =+VLOOKUP(A26,Ficheiros!T:V,3,FALSE) -> PM & LF
A27: =+C27&G27 -> ENTITYCR_FLG | B27: EN.019 | C27: ENTITY | D27: Classification | E27: N | F27: CR_FLG | G27: CR_FLG | H27: Y | I27: Y | J27: Y | K27: Y | L27: Y | M27: Y | N27: Y | R27: Y, N | S27: Boolean: Y/N | T27: MISS | U27: N/A | V27: N/A | W27: Cure flag for entity which was classified as non-performing in the last 1.5 years and is classified as performing at the reference date | X27: The entity is to be classified on the reference date under one of the following categories: performing or non-performing, in accordance with Annex V to Implementing Regulation (EU) No 680/2014. | Y27: Yes - Computed | Z27: IF H0883_IND_CURA = 1 THEN T; ELSE IF H0883_IND_CURA = 0 THEN F; THEN N/A | AA27: - | AB27: Y | AC27: N | AD27: N | AE27: N | AF27: N | AG27: N | AH27: N | AI27: N | AJ27: Y | AK27: =+IF(AND(AD27="N",AF27="N"),"Fora de âmbito", IF(AND(AD27="N",AF27="Y"),"Apenas ESG Risk", IF(AND(AD27="Y",AF27="N"),"Apenas Pilar 3", IF(AND(AD27="Y",AF27="Y"),"Comum","")))) -> Fora de âmbito | AL27: =+IF(IFERROR(VLOOKUP(A27,Ficheiros!I:I,1,FALSE),"")=A27,"Sim","Não") -> Sim | AM27: =+IF(IFERROR(VLOOKUP(A27,Ficheiros!E:E,1,FALSE),"")=A27,"Sim","Não") -> Não | AN27: =+IF(IFERROR(VLOOKUP(A27,Ficheiros!O:O,1,FALSE),"")=A27,"Sim","Não") -> Não | AO27: =+IF(IFERROR(VLOOKUP(A27,'Especificação Novos Req. LT (2'!A:A,1,FALSE),"")=A27,"Sim","Não") -> Não | AP27: =+IF(IFERROR(VLOOKUP(A27,Ficheiros!T:T,1,FALSE),"")=A27,"Sim","Não") -> Sim | AQ27: =+VLOOKUP(A27,Ficheiros!O:P,2,FALSE) -> #N/A | AR27: =+VLOOKUP(A27,Ficheiros!T:U,2,FALSE) -> 7. Analisar controlos e completude | AS27: =+VLOOKUP(A27,Ficheiros!T:V,3,FALSE) -> PM
A28: =+C28&G28 -> ENTITYDCSD | B28: EN.020 | C28: ENTITY | D28: Classification | E28: N | F28: DCSD | G28: DCSD | H28: N | I28: N | J28: N | K28: N | L28: N | M28: N | N28: Y | R28: Y, N | S28: Boolean: Y/N | T28: MISS | U28: N/A | V28: N/A | W28: Entity deceased | X28: Indicator as to whether the Entity has passed away. The data attribute is applicable to natural persons only. | Y28: Not applicable | Z28: N/A | AA28: - | AB28: Y | AC28: N | AD28: N | AE28: N | AF28: N | AG28: N | AH28: N | AI28: N | AJ28: Y | AK28: =+IF(AND(AD28="N",AF28="N"),"Fora de âmbito", IF(AND(AD28="N",AF28="Y"),"Apenas ESG Risk", IF(AND(AD28="Y",AF28="N"),"Apenas Pilar 3", IF(AND(AD28="Y",AF28="Y"),"Comum","")))) -> Fora de âmbito | AL28: =+IF(IFERROR(VLOOKUP(A28,Ficheiros!I:I,1,FALSE),"")=A28,"Sim","Não") -> Sim | AM28: =+IF(IFERROR(VLOOKUP(A28,Ficheiros!E:E,1,FALSE),"")=A28,"Sim","Não") -> Não | AN28: =+IF(IFERROR(VLOOKUP(A28,Ficheiros!O:O,1,FALSE),"")=A28,"Sim","Não") -> Não | AO28: =+IF(IFERROR(VLOOKUP(A28,'Especificação Novos Req. LT (2'!A:A,1,FALSE),"")=A28,"Sim","Não") -> Não | AP28: =+IF(IFERROR(VLOOKUP(A28,Ficheiros!T:T,1,FALSE),"")=A28,"Sim","Não") -> Sim | AQ28: =+VLOOKUP(A28,Ficheiros!O:P,2,FALSE) -> #N/A | AR28: =+VLOOKUP(A28,Ficheiros!T:U,2,FALSE) -> 9. Concluído | AS28: =+VLOOKUP(A28,Ficheiros!T:V,3,FALSE) -> PM
A29: =+C29&G29 -> ENTITYDFLT_STTS | B29: EN.021 | C29: ENTITY | D29: Classification | E29: Y | F29: DFLT_STTS | G29: DFLT_STTS | H29: Y | I29: Y | J29: Y | K29: Y | L29: Y | M29: Y | N29: Y | R29: Code List | S29: Use codes from the code list sheet | T29: 99999999999 | U29: 11111111111 | V29: 11111111111 | W29: Default status of the entity | X29: Identification of the default status of the counterparty. Categories describing the motives for which the counterparty can be in default in accordance with Article 178 of Regulation (EU) No 575/2013. For retail only: If default classification performed on instrument level then Entity is classified as defaulted when at least one instrument is classified as defaulted. For corporate, SME, CRE and LF: if default classification performed on instrument level then entity level is "not applicable". | Y29: Not applicable | Z29: N/A | AA29: - | AB29: Y | AC29: N | AD29: N | AE29: N | AF29: N | AG29: Y | AH29: N | AI29: N | AJ29: Y | AK29: =+IF(AND(AD29="N",AF29="N"),"Fora de âmbito", IF(AND(AD29="N",AF29="Y"),"Apenas ESG Risk", IF(AND(AD29="Y",AF29="N"),"Apenas Pilar 3", IF(AND(AD29="Y",AF29="Y"),"Comum","")))) -> Fora de âmbito | AL29: =+IF(IFERROR(VLOOKUP(A29,Ficheiros!I:I,1,FALSE),"")=A29,"Sim","Não") -> Sim | AM29: =+IF(IFERROR(VLOOKUP(A29,Ficheiros!E:E,1,FALSE),"")=A29,"Sim","Não") -> Não | AN29: =+IF(IFERROR(VLOOKUP(A29,Ficheiros!O:O,1,FALSE),"")=A29,"Sim","Não") -> Não | AO29: =+IF(IFERROR(VLOOKUP(A29,'Especificação Novos Req. LT (2'!A:A,1,FALSE),"")=A29,"Sim","Não") -> Não | AP29: =+IF(IFERROR(VLOOKUP(A29,Ficheiros!T:T,1,FALSE),"")=A29,"Sim","Não") -> Sim | AQ29: =+VLOOKUP(A29,Ficheiros!O:P,2,FALSE) -> #N/A | AR29: =+VLOOKUP(A29,Ficheiros!T:U,2,FALSE) -> 3. Pendente de decisão | AS29: =+VLOOKUP(A29,Ficheiros!T:V,3,FALSE) -> LF
A30: =+C30&G30 -> ENTITYDT_EXTRNL_RTNG | B30: EN.022 | C30: ENTITY | D30: Classification | E30: N | F30: DT_EXTRNL_RTNG | G30: DT_EXTRNL_RTNG | H30: Y | I30: Y | J30: Y | K30: Y | L30: Y | M30: Y | N30: N | R30: DATE | S30: YYYY-MM-DD | T30: 0000-00-00 | U30: 1111-11-11 | V30: 1111-11-11 | W30: Date of external rating | X30: Date of the most recent external rating, i.e. applicable at the reference date. | Y30: Yes - Equivalent | Z30: JM_CAL_EXT_CL - R9415_FECCALIF | AA30: - | AB30: Y | AC30: N | AD30: N | AE30: N | AF30: N | AG30: Y | AH30: N | AI30: N | AJ30: Y | AK30: =+IF(AND(AD30="N",AF30="N"),"Fora de âmbito", IF(AND(AD30="N",AF30="Y"),"Apenas ESG Risk", IF(AND(AD30="Y",AF30="N"),"Apenas Pilar 3", IF(AND(AD30="Y",AF30="Y"),"Comum","")))) -> Fora de âmbito | AL30: =+IF(IFERROR(VLOOKUP(A30,Ficheiros!I:I,1,FALSE),"")=A30,"Sim","Não") -> Sim | AM30: =+IF(IFERROR(VLOOKUP(A30,Ficheiros!E:E,1,FALSE),"")=A30,"Sim","Não") -> Não | AN30: =+IF(IFERROR(VLOOKUP(A30,Ficheiros!O:O,1,FALSE),"")=A30,"Sim","Não") -> Não | AO30: =+IF(IFERROR(VLOOKUP(A30,'Especificação Novos Req. LT (2'!A:A,1,FALSE),"")=A30,"Sim","Não") -> Não | AP30: =+IF(IFERROR(VLOOKUP(A30,Ficheiros!T:T,1,FALSE),"")=A30,"Sim","Não") -> Sim | AQ30: =+VLOOKUP(A30,Ficheiros!O:P,2,FALSE) -> #N/A | AR30: =+VLOOKUP(A30,Ficheiros!T:U,2,FALSE) -> 2. Alterar especificação | AS30: =+VLOOKUP(A30,Ficheiros!T:V,3,FALSE) -> LF
A31: =+C31&G31 -> ENTITYDT_INTRNL_RTNG | B31: EN.023 | C31: ENTITY | D31: Classification | E31: N | F31: DT_INTRNL_RTNG | G31: DT_INTRNL_RTNG | H31: Y | I31: Y | J31: Y | K31: Y | L31: Y | M31: Y | N31: Y | R31: DATE | S31: YYYY-MM-DD | T31: 0000-00-00 | U31: 1111-11-11 | V31: 1111-11-11 | W31: Date of internal rating | X31: Date of the most recent internal rating according to Regulation (EU) No 575/2013, i.e. applicable rating as at the reference date. If the rating is assigned on instrument level then provide the rating for the instrument with the highest EAD. | Y31: Yes - Equivalent | Z31: JM_CAL_IN_CL - E9954_FECCALI | AA31: - | AB31: Y | AC31: N | AD31: N | AE31: N | AF31: N | AG31: Y | AH31: N | AI31: N | AJ31: Y | AK31: =+IF(AND(AD31="N",AF31="N"),"Fora de âmbito", IF(AND(AD31="N",AF31="Y"),"Apenas ESG Risk", IF(AND(AD31="Y",AF31="N"),"Apenas Pilar 3", IF(AND(AD31="Y",AF31="Y"),"Comum","")))) -> Fora de âmbito | AL31: =+IF(IFERROR(VLOOKUP(A31,Ficheiros!I:I,1,FALSE),"")=A31,"Sim","Não") -> Sim | AM31: =+IF(IFERROR(VLOOKUP(A31,Ficheiros!E:E,1,FALSE),"")=A31,"Sim","Não") -> Não | AN31: =+IF(IFERROR(VLOOKUP(A31,Ficheiros!O:O,1,FALSE),"")=A31,"Sim","Não") -> Não | AO31: =+IF(IFERROR(VLOOKUP(A31,'Especificação Novos Req. LT (2'!A:A,1,FALSE),"")=A31,"Sim","Não") -> Não | AP31: =+IF(IFERROR(VLOOKUP(A31,Ficheiros!T:T,1,FALSE),"")=A31,"Sim","Não") -> Sim | AQ31: =+VLOOKUP(A31,Ficheiros!O:P,2,FALSE) -> #N/A | AR31: =+VLOOKUP(A31,Ficheiros!T:U,2,FALSE) -> 5.1 Em testes - Re-especificação | AS31: =+VLOOKUP(A31,Ficheiros!T:V,3,FALSE) -> LF
A32: =+C32&G32 -> ENTITYECNMC_ACTVTY | B32: EN.024 | C32: ENTITY | D32: Classification | E32: Y | F32: ECNMC_ACTVTY | G32: ECNMC_ACTVTY | H32: N | I32: Y | J32: Y | K32: Y | L32: Y | M32: Y | N32: N | R32: Code list | S32: Use codes from the code list sheet | T32: MISS | U32: N/A | V32: N/A | W32: Economic activity counterparty | X32: The level four NACE code in accordance with Regulation (EC) No 1893/2006 is generally reported. If the level four NACE code is not available it may be allowed to report a level three or level two NACE code. | Y32: Not applicable | Z32: N/A | AA32: - | AB32: Y | AC32: N | AD32: Y | AE32: Y | AF32: Y | AG32: Y | AH32: N | AI32: Y | AJ32: Y | AK32: =+IF(AND(AD32="N",AF32="N"),"Fora de âmbito", IF(AND(AD32="N",AF32="Y"),"Apenas ESG Risk", IF(AND(AD32="Y",AF32="N"),"Apenas Pilar 3", IF(AND(AD32="Y",AF32="Y"),"Comum","")))) -> Comum | AL32: =+IF(IFERROR(VLOOKUP(A32,Ficheiros!I:I,1,FALSE),"")=A32,"Sim","Não") -> Sim | AM32: =+IF(IFERROR(VLOOKUP(A32,Ficheiros!E:E,1,FALSE),"")=A32,"Sim","Não") -> Não | AN32: =+IF(IFERROR(VLOOKUP(A32,Ficheiros!O:O,1,FALSE),"")=A32,"Sim","Não") -> Sim | AO32: =+IF(IFERROR(VLOOKUP(A32,'Especificação Novos Req. LT (2'!A:A,1,FALSE),"")=A32,"Sim","Não") -> Não | AP32: =+IF(IFERROR(VLOOKUP(A32,Ficheiros!T:T,1,FALSE),"")=A32,"Sim","Não") -> Sim | AQ32: =+VLOOKUP(A32,Ficheiros!O:P,2,FALSE) -> 1. Concluído | AR32: =+VLOOKUP(A32,Ficheiros!T:U,2,FALSE) -> 9. Concluído | AS32: =+VLOOKUP(A32,Ficheiros!T:V,3,FALSE) -> PM
A33: =+C33&G33 -> ENTITYEMPLYMNT_STTS_INTRNL | B33: EN.025 | C33: ENTITY | D33: Classification | E33: N | F33: EMPLYMNT_STTS_INTRNL | G33: EMPLYMNT_STTS_INTRNL | H33: N | I33: N | J33: N | K33: N | L33: N | M33: N | N33: Y | R33: VARCHAR2(255) | S33: Free (latin) text without special characters (semicolon, quotes, …) | T33: MISS | U33: N/A | V33: N/A | W33: Employment status according to bank-internal classification | X33: Employment status according to bank-internal classification. | Y33: Not applicable | Z33: N/A | AA33: - | AB33: Y | AC33: N | AD33: N | AE33: N | AF33: N | AG33: N | AH33: N | AI33: N | AJ33: Y | AK33: =+IF(AND(AD33="N",AF33="N"),"Fora de âmbito", IF(AND(AD33="N",AF33="Y"),"Apenas ESG Risk", IF(AND(AD33="Y",AF33="N"),"Apenas Pilar 3", IF(AND(AD33="Y",AF33="Y"),"Comum","")))) -> Fora de âmbito | AL33: =+IF(IFERROR(VLOOKUP(A33,Ficheiros!I:I,1,FALSE),"")=A33,"Sim","Não") -> Sim | AM33: =+IF(IFERROR(VLOOKUP(A33,Ficheiros!E:E,1,FALSE),"")=A33,"Sim","Não") -> Não | AN33: =+IF(IFERROR(VLOOKUP(A33,Ficheiros!O:O,1,FALSE),"")=A33,"Sim","Não") -> Não | AO33: =+IF(IFERROR(VLOOKUP(A33,'Especificação Novos Req. LT (2'!A:A,1,FALSE),"")=A33,"Sim","Não") -> Não | AP33: =+IF(IFERROR(VLOOKUP(A33,Ficheiros!T:T,1,FALSE),"")=A33,"Sim","Não") -> Sim | AQ33: =+VLOOKUP(A33,Ficheiros!O:P,2,FALSE) -> #N/A | AR33: =+VLOOKUP(A33,Ficheiros!T:U,2,FALSE) -> 9. Concluído | AS33: =+VLOOKUP(A33,Ficheiros!T:V,3,FALSE) -> PM
A34: =+C34&G34 -> ENTITYEMPLYMNT_STTS | B34: EN.026 | C34: ENTITY | D34: Classification | E34: N | F34: EMPLYMNT_STTS | G34: EMPLYMNT_STTS | H34: N | I34: N | J34: N | K34: N | L34: N | M34: N | N34: Y | R34: Code List | S34: Use codes from the code list sheet | T34: 99999999999 | U34: 11111111111 | V34: 11111111111 | W34: Employment status (Code List) | X34: Employment status. | Y34: Not applicable | Z34: N/A | AA34: - | AB34: Y | AC34: N | AD34: N | AE34: N | AF34: N | AG34: N | AH34: N | AI34: N | AJ34: Y | AK34: =+IF(AND(AD34="N",AF34="N"),"Fora de âmbito", IF(AND(AD34="N",AF34="Y"),"Apenas ESG Risk", IF(AND(AD34="Y",AF34="N"),"Apenas Pilar 3", IF(AND(AD34="Y",AF34="Y"),"Comum","")))) -> Fora de âmbito | AL34: =+IF(IFERROR(VLOOKUP(A34,Ficheiros!I:I,1,FALSE),"")=A34,"Sim","Não") -> Sim | AM34: =+IF(IFERROR(VLOOKUP(A34,Ficheiros!E:E,1,FALSE),"")=A34,"Sim","Não") -> Não | AN34: =+IF(IFERROR(VLOOKUP(A34,Ficheiros!O:O,1,FALSE),"")=A34,"Sim","Não") -> Não | AO34: =+IF(IFERROR(VLOOKUP(A34,'Especificação Novos Req. LT (2'!A:A,1,FALSE),"")=A34,"Sim","Não") -> Não | AP34: =+IF(IFERROR(VLOOKUP(A34,Ficheiros!T:T,1,FALSE),"")=A34,"Sim","Não") -> Sim | AQ34: =+VLOOKUP(A34,Ficheiros!O:P,2,FALSE) -> #N/A | AR34: =+VLOOKUP(A34,Ficheiros!T:U,2,FALSE) -> 9. Concluído | AS34: =+VLOOKUP(A34,Ficheiros!T:V,3,FALSE) -> PM
A35: =+C35&G35 -> ENTITYENTRPRS_SZ_LE | B35: EN.027 | C35: ENTITY | D35: Classification | E35: Y | F35: ENTRPRS_SZ_LE | G35: ENTRPRS_SZ_LE | H35: N | I35: N | J35: N | K35: N | L35: N | M35: Y | N35: N | R35: Code List | S35: Use codes from the code list sheet | T35: 99999999999 | U35: 11111111111 | V35: 11111111111 | W35: Enterprise size Counterparty (LE) | X35: Enterprise size counterparty (LE). Classification of enterprises by size, in accordance with the Annex to Commission Recommendation 2003/361/EC. However, if the local NCB decides not to request this attribute as part of the AnaC reporting data set then please report "Not applicable". | Y35: Yes - Computed | Z35: IF ((G5508_NUM_EMPL IS <250 AND >=50) AND ((G5508_IMPFACTM <=50MM) OR (G5508_TOT_ACTI<=43MM))) THEN 2; ELSE IF ((G5508_NUM_EMPL IS <50 AND >=10) AND ((G5508_IMPFACTM <=10MM) OR (G5508_TOT_ACTI<=10MM))) THEN 3; ELSE IF ((G5508_NUM_EMPL IS <10) AND ((G5508_IMPFACTM <=2MM) OR (G5508_TOT_ACTI<=2MM))) THEN 4; ELSE 1 | AA35: - | AB35: Y | AC35: N | AD35: N | AE35: N | AF35: N | AG35: N | AH35: N | AI35: N | AJ35: Y | AK35: =+IF(AND(AD35="N",AF35="N"),"Fora de âmbito", IF(AND(AD35="N",AF35="Y"),"Apenas ESG Risk", IF(AND(AD35="Y",AF35="N"),"Apenas Pilar 3", IF(AND(AD35="Y",AF35="Y"),"Comum","")))) -> Fora de âmbito | AL35: =+IF(IFERROR(VLOOKUP(A35,Ficheiros!I:I,1,FALSE),"")=A35,"Sim","Não") -> Sim | AM35: =+IF(IFERROR(VLOOKUP(A35,Ficheiros!E:E,1,FALSE),"")=A35,"Sim","Não") -> Não | AN35: =+IF(IFERROR(VLOOKUP(A35,Ficheiros!O:O,1,FALSE),"")=A35,"Sim","Não") -> Não | AO35: =+IF(IFERROR(VLOOKUP(A35,'Especificação Novos Req. LT (2'!A:A,1,FALSE),"")=A35,"Sim","Não") -> Não | AP35: =+IF(IFERROR(VLOOKUP(A35,Ficheiros!T:T,1,FALSE),"")=A35,"Sim","Não") -> Sim | AQ35: =+VLOOKUP(A35,Ficheiros!O:P,2,FALSE) -> #N/A | AR35: =+VLOOKUP(A35,Ficheiros!T:U,2,FALSE) -> 7. Analisar controlos e completude | AS35: =+VLOOKUP(A35,Ficheiros!T:V,3,FALSE) -> PM
A36: =+C36&G36 -> ENTITYEXTRNL_RTNG | B36: EN.028 | C36: ENTITY | D36: Classification | E36: N | F36: EXTRNL_RTNG | G36: EXTRNL_RTNG | H36: Y | I36: Y | J36: Y | K36: Y | L36: Y | M36: Y | N36: N | R36: Code List | S36: Use codes from the code list sheet | T36: 99999999999 | U36: 11111111111 | V36: 11111111111 | W36: External rating | X36: External rating at the reference date. | Y36: Yes - Computed | Z36: R9415_CALIFMAE following the conditions: 1) In those cases in which more than one ECAI provides an external rating: - Where two credit assessments are available from nominated ECAIs and the two correspond to different risk weights for a rated item, the higher risk weight shall be assigned - Where more than two credit assessments are available from nominated ECAIs for a rated item, the two assessments generating the two lowest risk weights shall be referred to. If the two lowest risk weights are different, the higher risk weight shall be assigned. If the two lowest risk weights are the same, that risk weight shall be assigned 2) If the rating is not available, the unit should report “99999999999” in the Loan Tape. In case, for example, of exposures calculated under the IRB approach, where the external rating does not apply, the expected value is “11111111111” 3) If the client was not part of any applicable portfolio in the prior year, the value informed should be “11111111111”, as not applicable | AA36: - | AB36: Y | AC36: N | AD36: N | AE36: N | AF36: N | AG36: Y | AH36: N | AI36: N | AJ36: Y | AK36: =+IF(AND(AD36="N",AF36="N"),"Fora de âmbito", IF(AND(AD36="N",AF36="Y"),"Apenas ESG Risk", IF(AND(AD36="Y",AF36="N"),"Apenas Pilar 3", IF(AND(AD36="Y",AF36="Y"),"Comum","")))) -> Fora de âmbito | AL36: =+IF(IFERROR(VLOOKUP(A36,Ficheiros!I:I,1,FALSE),"")=A36,"Sim","Não") -> Sim | AM36: =+IF(IFERROR(VLOOKUP(A36,Ficheiros!E:E,1,FALSE),"")=A36,"Sim","Não") -> Não | AN36: =+IF(IFERROR(VLOOKUP(A36,Ficheiros!O:O,1,FALSE),"")=A36,"Sim","Não") -> Não | AO36: =+IF(IFERROR(VLOOKUP(A36,'Especificação Novos Req. LT (2'!A:A,1,FALSE),"")=A36,"Sim","Não") -> Não | AP36: =+IF(IFERROR(VLOOKUP(A36,Ficheiros!T:T,1,FALSE),"")=A36,"Sim","Não") -> Sim | AQ36: =+VLOOKUP(A36,Ficheiros!O:P,2,FALSE) -> #N/A | AR36: =+VLOOKUP(A36,Ficheiros!T:U,2,FALSE) -> 2. Alterar especificação | AS36: =+VLOOKUP(A36,Ficheiros!T:V,3,FALSE) -> LF
A37: =+C37&G37 -> ENTITYEXTRNL_RTNG_PRVS | B37: EN.029 | C37: ENTITY | D37: Classification | E37: N | F37: EXTRNL_RTNG_PRVS | G37: EXTRNL_RTNG_PRVS | H37: Y | I37: Y | J37: Y | K37: Y | L37: Y | M37: Y | N37: N | R37: Code List | S37: Use codes from the code list sheet | T37: 99999999999 | U37: 11111111111 | V37: 11111111111 | W37: External rating T-1 | X37: External rating one year prior to the reference date. | Y37: Yes - Computed | Z37: R9415_CALIFMAE having R9415_CALIFMAE one year prior to the reference date and following the conditions: 1) In those cases in which more than one ECAI provides an external rating: - Where two credit assessments are available from nominated ECAIs and the two correspond to different risk weights for a rated item, the higher risk weight shall be assigned - Where more than two credit assessments are available from nominated ECAIs for a rated item, the two assessments generating the two lowest risk weights shall be referred to. If the two lowest risk weights are different, the higher risk weight shall be assigned. If the two lowest risk weights are the same, that risk weight shall be assigned 2) If the rating is not available, the unit should report “99999999999” in the Loan Tape. In case, for example, of exposures calculated under the IRB approach, where the external rating does not apply, the expected value is “11111111111” 3) If the client was not part of any applicable portfolio in the prior year, the value informed should be “11111111111”, as not applicable | AA37: - | AB37: Y | AC37: N | AD37: N | AE37: N | AF37: N | AG37: Y | AH37: N | AI37: N | AJ37: Y | AK37: =+IF(AND(AD37="N",AF37="N"),"Fora de âmbito", IF(AND(AD37="N",AF37="Y"),"Apenas ESG Risk", IF(AND(AD37="Y",AF37="N"),"Apenas Pilar 3", IF(AND(AD37="Y",AF37="Y"),"Comum","")))) -> Fora de âmbito | AL37: =+IF(IFERROR(VLOOKUP(A37,Ficheiros!I:I,1,FALSE),"")=A37,"Sim","Não") -> Sim | AM37: =+IF(IFERROR(VLOOKUP(A37,Ficheiros!E:E,1,FALSE),"")=A37,"Sim","Não") -> Não | AN37: =+IF(IFERROR(VLOOKUP(A37,Ficheiros!O:O,1,FALSE),"")=A37,"Sim","Não") -> Não | AO37: =+IF(IFERROR(VLOOKUP(A37,'Especificação Novos Req. LT (2'!A:A,1,FALSE),"")=A37,"Sim","Não") -> Não | AP37: =+IF(IFERROR(VLOOKUP(A37,Ficheiros!T:T,1,FALSE),"")=A37,"Sim","Não") -> Sim | AQ37: =+VLOOKUP(A37,Ficheiros!O:P,2,FALSE) -> #N/A | AR37: =+VLOOKUP(A37,Ficheiros!T:U,2,FALSE) -> 2. Alterar especificação | AS37: =+VLOOKUP(A37,Ficheiros!T:V,3,FALSE) -> LF
A38: =+C38&G38 -> ENTITYFLG_BNKRPTCY_IN_GRP | B38: EN.030 | C38: ENTITY | D38: Classification | E38: N | F38: FLG_BNKRPTCY_IN_GRP | G38: FLG_BNKRPTCY_IN_GRP | H38: N | I38: Y | J38: Y | K38: Y | L38: Y | M38: Y | N38: N | R38: Y, N | S38: Boolean: Y/N | T38: MISS | U38: N/A | V38: N/A | W38: Any legal entity within the group of connected clients of the debtor (incl. subsidiaries of the debtor) has filed bankruptcy application | X38: Report "Y' if any legal entity within the group of connected clients of the debtor (incl. subsidiaries of the debtor) has filed bankruptcy application according to local insolvency law. | Y38: Yes - Computed | Z38: IF G4093_UTP_CLI = 00001 for any of the related clientes (necessary to identify the Group of the cliente (E1963_GRUP_ECO) and then all the connected clients (E1963_IDNUMCLI) for this Group) THEN Y; ELSE N | AA38: - | AB38: Y | AC38: N | AD38: N | AE38: N | AF38: N | AG38: N | AH38: N | AI38: N | AJ38: Y | AK38: =+IF(AND(AD38="N",AF38="N"),"Fora de âmbito", IF(AND(AD38="N",AF38="Y"),"Apenas ESG Risk", IF(AND(AD38="Y",AF38="N"),"Apenas Pilar 3", IF(AND(AD38="Y",AF38="Y"),"Comum","")))) -> Fora de âmbito | AL38: =+IF(IFERROR(VLOOKUP(A38,Ficheiros!I:I,1,FALSE),"")=A38,"Sim","Não") -> Sim | AM38: =+IF(IFERROR(VLOOKUP(A38,Ficheiros!E:E,1,FALSE),"")=A38,"Sim","Não") -> Não | AN38: =+IF(IFERROR(VLOOKUP(A38,Ficheiros!O:O,1,FALSE),"")=A38,"Sim","Não") -> Não | AO38: =+IF(IFERROR(VLOOKUP(A38,'Especificação Novos Req. LT (2'!A:A,1,FALSE),"")=A38,"Sim","Não") -> Não | AP38: =+IF(IFERROR(VLOOKUP(A38,Ficheiros!T:T,1,FALSE),"")=A38,"Sim","Não") -> Sim | AQ38: =+VLOOKUP(A38,Ficheiros!O:P,2,FALSE) -> #N/A | AR38: =+VLOOKUP(A38,Ficheiros!T:U,2,FALSE) -> 9. Concluído | AS38: =+VLOOKUP(A38,Ficheiros!T:V,3,FALSE) -> PM
A39: =+C39&G39 -> ENTITYFLG_HGH_CDS | B39: EN.031 | C39: ENTITY | D39: Classification | E39: N | F39: FLG_HGH_CDS | G39: FLG_HGH_CDS | H39: Y | I39: Y | J39: Y | K39: Y | L39: Y | M39: Y | N39: N | R39: Y, N | S39: Boolean: Y/N | T39: MISS | U39: N/A | V39: N/A | W39: 5Y CDS > 1,000bps over the last 12 months | X39: Report "Y" if 5Y CDS > 1,000bps over the last 12 months. The flag would be required to be reported "Y" if the 5y CDS spread of a debtor is at least once greater or equal 1000bps within the last 12 months. | Y39: Not applicable | Z39: N/A | AA39: - | AB39: Y | AC39: N | AD39: N | AE39: N | AF39: N | AG39: N | AH39: N | AI39: N | AJ39: Y | AK39: =+IF(AND(AD39="N",AF39="N"),"Fora de âmbito", IF(AND(AD39="N",AF39="Y"),"Apenas ESG Risk", IF(AND(AD39="Y",AF39="N"),"Apenas Pilar 3", IF(AND(AD39="Y",AF39="Y"),"Comum","")))) -> Fora de âmbito | AL39: =+IF(IFERROR(VLOOKUP(A39,Ficheiros!I:I,1,FALSE),"")=A39,"Sim","Não") -> Sim | AM39: =+IF(IFERROR(VLOOKUP(A39,Ficheiros!E:E,1,FALSE),"")=A39,"Sim","Não") -> Não | AN39: =+IF(IFERROR(VLOOKUP(A39,Ficheiros!O:O,1,FALSE),"")=A39,"Sim","Não") -> Não | AO39: =+IF(IFERROR(VLOOKUP(A39,'Especificação Novos Req. LT (2'!A:A,1,FALSE),"")=A39,"Sim","Não") -> Não | AP39: =+IF(IFERROR(VLOOKUP(A39,Ficheiros!T:T,1,FALSE),"")=A39,"Sim","Não") -> Sim | AQ39: =+VLOOKUP(A39,Ficheiros!O:P,2,FALSE) -> #N/A | AR39: =+VLOOKUP(A39,Ficheiros!T:U,2,FALSE) -> 9. Concluído | AS39: =+VLOOKUP(A39,Ficheiros!T:V,3,FALSE) -> PM
A40: =+C40&G40 -> ENTITYFLG_ISDA_CRDT_EVNT | B40: EN.032 | C40: ENTITY | D40: Classification | E40: N | F40: FLG_ISDA_CRDT_EVNT | G40: FLG_ISDA_CRDT_EVNT | H40: Y | I40: Y | J40: Y | K40: Y | L40: Y | M40: Y | N40: N | R40: Y, N | S40: Boolean: Y/N | T40: MISS | U40: N/A | V40: N/A | W40: ISDA credit event declared | X40: The flag would be required to be reported "Y" if a credit event occurred under any ISDA master agreement associated with this debtor. | Y40: Not applicable | Z40: N/A | AA40: - | AB40: Y | AC40: N | AD40: N | AE40: N | AF40: N | AG40: N | AH40: N | AI40: N | AJ40: Y | AK40: =+IF(AND(AD40="N",AF40="N"),"Fora de âmbito", IF(AND(AD40="N",AF40="Y"),"Apenas ESG Risk", IF(AND(AD40="Y",AF40="N"),"Apenas Pilar 3", IF(AND(AD40="Y",AF40="Y"),"Comum","")))) -> Fora de âmbito | AL40: =+IF(IFERROR(VLOOKUP(A40,Ficheiros!I:I,1,FALSE),"")=A40,"Sim","Não") -> Sim | AM40: =+IF(IFERROR(VLOOKUP(A40,Ficheiros!E:E,1,FALSE),"")=A40,"Sim","Não") -> Não | AN40: =+IF(IFERROR(VLOOKUP(A40,Ficheiros!O:O,1,FALSE),"")=A40,"Sim","Não") -> Não | AO40: =+IF(IFERROR(VLOOKUP(A40,'Especificação Novos Req. LT (2'!A:A,1,FALSE),"")=A40,"Sim","Não") -> Não | AP40: =+IF(IFERROR(VLOOKUP(A40,Ficheiros!T:T,1,FALSE),"")=A40,"Sim","Não") -> Sim | AQ40: =+VLOOKUP(A40,Ficheiros!O:P,2,FALSE) -> #N/A | AR40: =+VLOOKUP(A40,Ficheiros!T:U,2,FALSE) -> 9. Concluído | AS40: =+VLOOKUP(A40,Ficheiros!T:V,3,FALSE) -> PM
A41: =+C41&G41 -> ENTITYFLG_NN_ACCRL | B41: EN.033 | C41: ENTITY | D41: Classification | E41: N | F41: FLG_NN_ACCRL | G41: FLG_NN_ACCRL | H41: N | I41: N | J41: N | K41: N | L41: N | M41: Y | N41: Y | R41: Y, N | S41: Boolean: Y/N | T41: MISS | U41: N/A | V41: N/A | W41: Credit obligation on non-accrual status | X41: Report "Y" if any credit obligation associated to this debtor is set on non-accrual status. | Y41: Not applicable | Z41: N/A | AA41: - | AB41: Y | AC41: N | AD41: N | AE41: N | AF41: N | AG41: N | AH41: N | AI41: N | AJ41: Y | AK41: =+IF(AND(AD41="N",AF41="N"),"Fora de âmbito", IF(AND(AD41="N",AF41="Y"),"Apenas ESG Risk", IF(AND(AD41="Y",AF41="N"),"Apenas Pilar 3", IF(AND(AD41="Y",AF41="Y"),"Comum","")))) -> Fora de âmbito | AL41: =+IF(IFERROR(VLOOKUP(A41,Ficheiros!I:I,1,FALSE),"")=A41,"Sim","Não") -> Sim | AM41: =+IF(IFERROR(VLOOKUP(A41,Ficheiros!E:E,1,FALSE),"")=A41,"Sim","Não") -> Não | AN41: =+IF(IFERROR(VLOOKUP(A41,Ficheiros!O:O,1,FALSE),"")=A41,"Sim","Não") -> Não | AO41: =+IF(IFERROR(VLOOKUP(A41,'Especificação Novos Req. LT (2'!A:A,1,FALSE),"")=A41,"Sim","Não") -> Não | AP41: =+IF(IFERROR(VLOOKUP(A41,Ficheiros!T:T,1,FALSE),"")=A41,"Sim","Não") -> Sim | AQ41: =+VLOOKUP(A41,Ficheiros!O:P,2,FALSE) -> #N/A | AR41: =+VLOOKUP(A41,Ficheiros!T:U,2,FALSE) -> 9. Concluído | AS41: =+VLOOKUP(A41,Ficheiros!T:V,3,FALSE) -> PM
A42: =+C42&G42 -> ENTITYFLG_RQST_BNKRPTCY | B42: EN.034 | C42: ENTITY | D42: Classification | E42: N | F42: FLG_RQST_BNKRPTCY | G42: FLG_RQST_BNKRPTCY | H42: N | I42: Y | J42: Y | K42: Y | L42: Y | M42: Y | N42: N | R42: Y, N | S42: Boolean: Y/N | T42: MISS | U42: N/A | V42: N/A | W42: Request by the institution for the obligor's bankruptcy | X42: Flag "Y" if bankruptcy proceedings have been initiated by the bank according to local insolvency law, e.g. due to illiquidity, over-indebtedness. | Y42: Not applicable | Z42: N/A | AA42: - | AB42: Y | AC42: N | AD42: N | AE42: N | AF42: N | AG42: N | AH42: N | AI42: N | AJ42: Y | AK42: =+IF(AND(AD42="N",AF42="N"),"Fora de âmbito", IF(AND(AD42="N",AF42="Y"),"Apenas ESG Risk", IF(AND(AD42="Y",AF42="N"),"Apenas Pilar 3", IF(AND(AD42="Y",AF42="Y"),"Comum","")))) -> Fora de âmbito | AL42: =+IF(IFERROR(VLOOKUP(A42,Ficheiros!I:I,1,FALSE),"")=A42,"Sim","Não") -> Sim | AM42: =+IF(IFERROR(VLOOKUP(A42,Ficheiros!E:E,1,FALSE),"")=A42,"Sim","Não") -> Não | AN42: =+IF(IFERROR(VLOOKUP(A42,Ficheiros!O:O,1,FALSE),"")=A42,"Sim","Não") -> Não | AO42: =+IF(IFERROR(VLOOKUP(A42,'Especificação Novos Req. LT (2'!A:A,1,FALSE),"")=A42,"Sim","Não") -> Não | AP42: =+IF(IFERROR(VLOOKUP(A42,Ficheiros!T:T,1,FALSE),"")=A42,"Sim","Não") -> Sim | AQ42: =+VLOOKUP(A42,Ficheiros!O:P,2,FALSE) -> #N/A | AR42: =+VLOOKUP(A42,Ficheiros!T:U,2,FALSE) -> 9. Concluído | AS42: =+VLOOKUP(A42,Ficheiros!T:V,3,FALSE) -> PM
A43: =+C43&G43 -> ENTITYFLG_RQST_DSTRSSD_RSTRCTRNG | B43: EN.035 | C43: ENTITY | D43: Classification | E43: N | F43: FLG_RQST_DSTRSSD_RSTRCTRNG | G43: FLG_RQST_DSTRSSD_RSTRCTRNG | H43: N | I43: N | J43: N | K43: N | L43: N | M43: Y | N43: Y | R43: Y, N | S43: Boolean: Y/N | T43: MISS | U43: N/A | V43: N/A | W43: Request for current concession of forbearance measures as defined in EBA/ITS/2013/03 resulting in distressed restructuring of the credit obligation | X43: Report "Y" if there is a request for current concession of forbearance measures as defined in EBA/ITS/2013/03 resulting in distressed restructuring of the credit obligation. | Y43: Not applicable | Z43: N/A | AA43: - | AB43: Y | AC43: N | AD43: N | AE43: N | AF43: N | AG43: N | AH43: N | AI43: N | AJ43: Y | AK43: =+IF(AND(AD43="N",AF43="N"),"Fora de âmbito", IF(AND(AD43="N",AF43="Y"),"Apenas ESG Risk", IF(AND(AD43="Y",AF43="N"),"Apenas Pilar 3", IF(AND(AD43="Y",AF43="Y"),"Comum","")))) -> Fora de âmbito | AL43: =+IF(IFERROR(VLOOKUP(A43,Ficheiros!I:I,1,FALSE),"")=A43,"Sim","Não") -> Sim | AM43: =+IF(IFERROR(VLOOKUP(A43,Ficheiros!E:E,1,FALSE),"")=A43,"Sim","Não") -> Não | AN43: =+IF(IFERROR(VLOOKUP(A43,Ficheiros!O:O,1,FALSE),"")=A43,"Sim","Não") -> Não | AO43: =+IF(IFERROR(VLOOKUP(A43,'Especificação Novos Req. LT (2'!A:A,1,FALSE),"")=A43,"Sim","Não") -> Não | AP43: =+IF(IFERROR(VLOOKUP(A43,Ficheiros!T:T,1,FALSE),"")=A43,"Sim","Não") -> Sim | AQ43: =+VLOOKUP(A43,Ficheiros!O:P,2,FALSE) -> #N/A | AR43: =+VLOOKUP(A43,Ficheiros!T:U,2,FALSE) -> 1. Especificar | AS43: =+VLOOKUP(A43,Ficheiros!T:V,3,FALSE) -> PM
A44: =+C44&G44 -> ENTITYFLG_RQST_EMRGNCY_FNDNG | B44: EN.036 | C44: ENTITY | D44: Classification | E44: N | F44: FLG_RQST_EMRGNCY_FNDNG | G44: FLG_RQST_EMRGNCY_FNDNG | H44: N | I44: N | J44: N | K44: N | L44: Y | M44: Y | N44: Y | R44: Y, N | S44: Boolean: Y/N | T44: MISS | U44: Default value not allowed | V44: N/A | W44: Request by the debtor for emergency funding from the bank | X44: Report "Y" if there is a request by the debtor for emergency funding from the bank. | Y44: Not applicable | Z44: N/A | AA44: - | AB44: Y | AC44: N | AD44: N | AE44: N | AF44: N | AG44: Y | AH44: N | AI44: N | AJ44: Y | AK44: =+IF(AND(AD44="N",AF44="N"),"Fora de âmbito", IF(AND(AD44="N",AF44="Y"),"Apenas ESG Risk", IF(AND(AD44="Y",AF44="N"),"Apenas Pilar 3", IF(AND(AD44="Y",AF44="Y"),"Comum","")))) -> Fora de âmbito | AL44: =+IF(IFERROR(VLOOKUP(A44,Ficheiros!I:I,1,FALSE),"")=A44,"Sim","Não") -> Sim | AM44: =+IF(IFERROR(VLOOKUP(A44,Ficheiros!E:E,1,FALSE),"")=A44,"Sim","Não") -> Não | AN44: =+IF(IFERROR(VLOOKUP(A44,Ficheiros!O:O,1,FALSE),"")=A44,"Sim","Não") -> Não | AO44: =+IF(IFERROR(VLOOKUP(A44,'Especificação Novos Req. LT (2'!A:A,1,FALSE),"")=A44,"Sim","Não") -> Não | AP44: =+IF(IFERROR(VLOOKUP(A44,Ficheiros!T:T,1,FALSE),"")=A44,"Sim","Não") -> Sim | AQ44: =+VLOOKUP(A44,Ficheiros!O:P,2,FALSE) -> #N/A | AR44: =+VLOOKUP(A44,Ficheiros!T:U,2,FALSE) -> 9. Concluído | AS44: =+VLOOKUP(A44,Ficheiros!T:V,3,FALSE) -> PM
...

Sheet 2. Entregas 31Jan
B2: Âmbito | C2: Tabela | D2: Campo | E2: Visibilidade em Plano | F2: Status
B3: Modelo de Bens Imóveis | C3: Certificados | D3: Especificação: Gloval + Novo Campo | E3: Sim | F3: Concluido
B4: Modelo de Bens Imóveis | C4: Input Gloval | D4: Especificação: Input Gloval | E4: Sim | F4: Concluido
B5: Modelo de Bens Imóveis | C5: Certificados | D5: Teste: Campo Rácio NTC | E5: Sim | F5: WIP
B6: Modelo de Bens Imóveis | C6: Certificados | D6: Teste: Restantes Campos (exceto Gloval) | E6: Não | F6: WIP
B8: Modelo Verde | C8: Veiculos | D8: Especificação: Scopes & Origens & Unid | E8: Não | F8: WIP
B9: Modelo Verde | C9: Imóveis | D9: Especificação: Scopes & Origens & Unid | E9: Não | F9: WIP
B10: Modelo Verde | C10: Clientes | D10: Especificação: Code Nace (TAT) no Risco Físico + SPV + Campo Code Nace | E10: Sim | F10: WIP
B11: Modelo Verde | C11: Imóveis | D11: Especificação: Code Nace (TAT) no Risco Físico | E11: Sim | F11: WIP
B13: Pilar III | C13: Protection | D13: Especificação: TYP_EPC_LBL & EPC_LBL | E13: Não | F13: Concluido
B14: Pilar III | C14: Protection | D14: Especificação: 6 campos (emissões e origens --> as emissões dependem das origens do MV (ex: eletricos) | E14: Não | F14: WIP
B15: Pilar III | C15: Instrument | D15: Especificação: Métodos obtenção das scopes na LT827 (móveis e imóveis) | E15: Não | F15: WIP
... B19: Novo Projeto | C19: Modelo Verde | D19: Especificação: 20 campos de rácio de elegi | E19: Sim | F19: Concluido
B21: Marcação Verde | D21: Tempo perdido em reuniões
B23: Restantes To Do's
B24: - Confirmar com a MR campos da LT006
B25: - Enviar e-mail a Zneida acerca do universo de ESG RISK
B26: - Confirmar se a LT007 vai ter os contratos todos

Sheet Input >>

Sheet Ficheiros
B2: Pilar 3 - V12 | G2: LOAN TAPE | K2: Plano 5.12 | R2: Projeto GF
B3: TABELA | C3: NOME COLUNA | D3: AUX_TABELA | E3: AUX_COMBINAÇÃO | G3: TABELA | H3: NOME COLUNA | I3: AUX_COMBINAÇÃO | K3: TABELA | L3: NOME COLUNA | M3: STATUS | N3: AUX_TABELA | O3: AUX_COMBINAÇÃO | P3: STATUS | R3: TABELA | S3: NOME COLUNA | T3: AUX_COMBINAÇÃO | U3: STATUS
B4: lt004_protection | C4: orgnl_prtctn_vl | D4: =+UPPER(MID(B4,FIND("_",B4,1)+1,LEN(B4))) -> PROTECTION | E4: =+D4&UPPER(C4) -> PROTECTIONORGNL_PRTCTN_VL | G4: INSTRUMENT | H4: ACCMLTD_CHNGS_FV_CR_INSTRMNT | I4: =+G4&H4 -> INSTRUMENTACCMLTD_CHNGS_FV_CR_INSTRMNT | K4: lt003_entity | L4: nace_esg | M4: 1. Concluído | N4: =+UPPER(MID(K4,FIND("_",K4,1)+1,LEN(K4))) -> ENTITY | O4: =+N4&UPPER(L4) -> ENTITYNACE_ESG | P4: 1. Concluído | R4: INSTRUMENT | S4: ACCMLTD_CHNGS_FV_CR_INSTRMNT | T4: =+R4&S4 -> INSTRUMENTACCMLTD_CHNGS_FV_CR_INSTRMNT | U4: 9. Concluído | V4: PM
B5: lt004_protection | C5: typ_prtctn | D5: =+UPPER(MID(B5,FIND("_",B5,1)+1,LEN(B5))) -> PROTECTION | E5: =+D5&UPPER(C5) -> PROTECTIONTYP_PRTCTN | G5: INSTRUMENT | H5: ACCMLTD_IMPRMNT_INSTRMNT | I5: =+G5&H5 -> INSTRUMENTACCMLTD_IMPRMNT_INSTRMNT | K5: lt003_entity | L5: txnmy_elgbl_capex_ccm | M5: 1. Concluído | N5: =+UPPER(MID(K5,FIND("_",K5,1)+1,LEN(K5))) -> ENTITY | O5: =+N5&UPPER(L5) -> ENTITYTXNMY_ELGBL_CAPEX_CCM | P5: 1. Concluído | R5: INSTRUMENT | S5: ACCMLTD_IMPRMNT_INSTRMNT | T5: =+R5&S5 -> INSTRUMENTACCMLTD_IMPRMNT_INSTRMNT | U5: 9. Concluído | V5: PM
B6: lt003_entity | C6: nace_esg | D6: =+UPPER(MID(B6,FIND("_",B6,1)+1,LEN(B6))) -> ENTITY | E6: =+D6&UPPER(C6) -> ENTITYNACE_ESG | G6: INSTRUMENT | H6: ACCMLTD_IMPRMNT_INSTRMNT_PRVS | I6: =+G6&H6 -> INSTRUMENTACCMLTD_IMPRMNT_INSTRMNT_PRVS | K6: lt003_entity | L6: txnmy_elgbl_trnvr_ccm | M6: 1. Concluído | N6: =+UPPER(MID(K6,FIND("_",K6,1)+1,LEN(K6))) -> ENTITY | O6: =+N6&UPPER(L6) -> ENTITYTXNMY_ELGBL_TRNVR_CCM | P6: 1. Concluído | R6: INSTRUMENT | S6: ACCMLTD_IMPRMNT_INSTRMNT_PRVS | T6: =+R6&S6 -> INSTRUMENTACCMLTD_IMPRMNT_INSTRMNT_PRVS | U6: 5.2 Em testes - Incidência | V6: LF
B7: lt003_entity | C7: txnmy_elgbl_capex_ccm | D7: =+UPPER(MID(B7,FIND("_",B7,1)+1,LEN(B7))) -> ENTITY | E7: =+D7&UPPER(C7) -> ENTITYTXNMY_ELGBL_CAPEX_CCM | G7: INSTRUMENT | H7: ACCMLTD_WRTFFS_INSTRMNT | I7: =+G7&H7 -> INSTRUMENTACCMLTD_WRTFFS_INSTRMNT | K7: lt003_entity | L7: txnmy_elgbl_capex_cca | M7: 1. Concluído | N7: =+UPPER(MID(K7,FIND("_",K7,1)+1,LEN(K7))) -> ENTITY | O7: =+N7&UPPER(L7) -> ENTITYTXNMY_ELGBL_CAPEX_CCA | P7: 1. Concluído | R7: INSTRUMENT | S7: ACCMLTD_WRTFFS_INSTRMNT | T7: =+R7&S7 -> INSTRUMENTACCMLTD_WRTFFS_INSTRMNT | U7: 9. Concluído | V7: PM
