Workbook

Sheet Instruções
B2: Instruções:
B3: 1. Alterar apenas o que está a amarelo (nota: no campo ref_date, colocar a plica no início da data para manter como texto)
C5: Schema AS IS (prod) | D5: cd_loan_tapes_bce | F5: TABLE_NAME | G5: Tabela LT_AS_IS | H5: Tabela LT_TO_BE | I5: Chave1 | J5: Chave2
C6: Schema TO BE (testes) | D6: bu_loantape_work | F6: ENTTY | G6: lt003_entity | H6: lt003_entity | I6: entty_id
C7: ref_date | D7: 2025-06-30 | F7: INSTR_ENTTY | G7: lt005_instr_ent | H7: lt005_instr_ent | I7: instrmnt_id | J7: entty_id
C8: nome_perimetro | D8: Individual IDComb | F8: INSTR_PRTCTN | G8: lt006_instr_prot | H8: lt006_instr_prot | I8: instrmnt_id | J8: prtctn_id
C9: segmento | D9: ESTR | F9: INSTRMNT | G9: lt002_instrument | H9: lt002_instrument | I9: instrmnt_id
C10: ambito | D10: PM | F10: PRTCTN | G10: lt004_protection | H10: lt004_protection | I10: prtctn_id
C11: filtro final | D11: ="ref_date='"&$D$7&"' AND nome_perimetro= '"&$D$8&"' AND segmento= '"&$D$9&"' AND ambito= '"&$D$10&"' AND entidade='00100' AND cod_visao = 1" -> ref_date='2025-06-30' AND nome_perimetro= 'Individual IDComb' AND segmento= 'ESTR' AND ambito= 'PM' AND entidade='00100' AND cod_visao = 1
B13: 2. Criar tabelas AS-IS no schema BU_CAPTOOLS_WORK (executar código infra a verde)
B15: ="DROP TABLE IF EXISTS "&$D$5&"."&G6&"; CREATE TABLE "&$D$5&"."&G6&" as SELECT * FROM "&$D$6&"."&H6&" WHERE "&$D$11&";" -> DROP TABLE IF EXISTS cd_loan_tapes_bce.lt003_entity; CREATE TABLE cd_loan_tapes_bce.lt003_entity as SELECT * FROM bu_loantape_work.lt003_entity WHERE ref_date='2025-06-30' AND nome_perimetro= 'Individual IDComb' AND segmento= 'ESTR' AND ambito= 'PM' AND entidade='00100' AND cod_visao = 1;
B16: ="DROP TABLE IF EXISTS "&$D$5&"."&G7&"; CREATE TABLE "&$D$5&"."&G7&" as SELECT * FROM "&$D$6&"."&H7&" WHERE "&$D$11&";" -> DROP TABLE IF EXISTS cd_loan_tapes_bce.lt005_instr_ent; CREATE TABLE cd_loan_tapes_bce.lt005_instr_ent as SELECT * FROM bu_loantape_work.lt005_instr_ent WHERE ref_date='2025-06-30' AND nome_perimetro= 'Individual IDComb' AND segmento= 'ESTR' AND ambito= 'PM' AND entidade='00100' AND cod_visao = 1;
B17: ="DROP TABLE IF EXISTS "&$D$5&"."&G8&"; CREATE TABLE "&$D$5&"."&G8&" as SELECT * FROM "&$D$6&"."&H8&" WHERE "&$D$11&";" -> DROP TABLE IF EXISTS cd_loan_tapes_bce.lt006_instr_prot; CREATE TABLE cd_loan_tapes_bce.lt006_instr_prot as SELECT * FROM bu_loantape_work.lt006_instr_prot WHERE ref_date='2025-06-30' AND nome_perimetro= 'Individual IDComb' AND segmento= 'ESTR' AND ambito= 'PM' AND entidade='00100' AND cod_visao = 1;
B18: ="DROP TABLE IF EXISTS "&$D$5&"."&G9&"; CREATE TABLE "&$D$5&"."&G9&" as SELECT * FROM "&$D$6&"."&H9&" WHERE "&$D$11&";" -> DROP TABLE IF EXISTS cd_loan_tapes_bce.lt002_instrument; CREATE TABLE cd_loan_tapes_bce.lt002_instrument as SELECT * FROM bu_loantape_work.lt002_instrument WHERE ref_date='2025-06-30' AND nome_perimetro= 'Individual IDComb' AND segmento= 'ESTR' AND ambito= 'PM' AND entidade='00100' AND cod_visao = 1;
B19: ="DROP TABLE IF EXISTS "&$D$5&"."&G10&"; CREATE TABLE "&$D$5&"."&G10&" as SELECT * FROM "&$D$6&"."&H10&" WHERE "&$D$11&";" -> DROP TABLE IF EXISTS cd_loan_tapes_bce.lt004_protection; CREATE TABLE cd_loan_tapes_bce.lt004_protection as SELECT * FROM bu_loantape_work.lt004_protection WHERE ref_date='2025-06-30' AND nome_perimetro= 'Individual IDComb' AND segmento= 'ESTR' AND ambito= 'PM' AND entidade='00100' AND cod_visao = 1;
B21: 3. Executar no HUE as linhas da coluna UNION ALL por blocos na sheet testes resgressivos > correr cada bloco de cada (de 30 em 30)

Sheet Teste Regressivo
B3: TABLE_NAME | C3: TABELA_LT_AS_IS | D3: TABELA_LT_AS_TO_BE | E3: COLUMN_NAME | F3: COLUMN_NAME_AS_IS | G3: COLUMN_NAME_TO_BE | H3: UNIVERSO AS IS | I3: UNIVERSO TO BE | J3: CRUZAMENTO | K3: CONDIÇÃO | L3: QUERY 1 | M3: Tipologia testes | N3: QUERY 2 | O3: UNION ALL | P3: contagem
B4: ENTTY | C4: =_xlfn.CONCAT(Instruções!$D$5,".",VLOOKUP(B4,Instruções!$F$5:$H$10,2,0)) -> cd_loan_tapes_bce.lt003_entity | D4: =_xlfn.CONCAT(Instruções!$D$6,".",VLOOKUP(B4,Instruções!$F$5:$H$10,3,0)) -> bu_loantape_work.lt003_entity | E4: accntng_frmwrk_sl | F4: =E4&"_as_is" -> accntng_frmwrk_sl_as_is | G4: =E4&"_to_be" -> accntng_frmwrk_sl_to_be | H4: =IF(VLOOKUP(B4,Instruções!$F$6:$J$10,5,0)="", "(SELECT "&VLOOKUP(B4,Instruções!$F$6:$J$10,4,0)&" as "&VLOOKUP(B4,Instruções!$F$6:$J$10,4,0)&"_as_is, "&E4&" as "&F4&" FROM "&C4&" WHERE "&Instruções!$D$11&") A ", "(SELECT "&VLOOKUP(B4,Instruções!$F$6:$J$10,4,0)&" as "&VLOOKUP(B4,Instruções!$F$6:$J$10,4,0)&"_as_is, "&VLOOKUP(B4,Instruções!$F$6:$J$10,5,0)&" as "&VLOOKUP(B4,Instruções!$F$6:$J$10,5,0)&"_as_is,"&E4&" as "&F4&" FROM "&C4&" WHERE "&Instruções!$D$11&") A ") -> (SELECT entty_id as entty_id_as_is, accntng_frmwrk_sl as accntng_frmwrk_sl_as_is FROM cd_loan_tapes_bce.lt003_entity WHERE ref_date='2025-06-30' AND nome_perimetro= 'Individual IDComb' AND segmento= 'ESTR' AND ambito= 'PM' AND entidade='00100' AND cod_visao = 1) A | I4: =IF(VLOOKUP(B4,Instruções!$F$6:$J$10,5,0)="", "(SELECT "&VLOOKUP(B4,Instruções!$F$6:$J$10,4,0)&" as "&VLOOKUP(B4,Instruções!$F$6:$J$10,4,0)&"_to_be, "&E4&" as "&G4&" FROM "&D4&" WHERE "&Instruções!$D$11&") B ", "(SELECT "&VLOOKUP(B4,Instruções!$F$6:$J$10,4,0)&" as "&VLOOKUP(B4,Instruções!$F$6:$J$10,4,0)&"_to_be, "&VLOOKUP(B4,Instruções!$F$6:$J$10,5,0)&" as "&VLOOKUP(B4,Instruções!$F$6:$J$10,5,0)&"_to_be,"&E4&" as "&G4&" FROM "&D4&" WHERE "&Instruções!$D$11&") B ") -> (SELECT entty_id as entty_id_to_be, accntng_frmwrk_sl as accntng_frmwrk_sl_to_be FROM bu_loantape_work.lt003_entity WHERE ref_date='2025-06-30' AND nome_perimetro= 'Individual IDComb' AND segmento= 'ESTR' AND ambito= 'PM' AND entidade='00100' AND cod_visao = 1) B | J4: =IF(VLOOKUP(B4,Instruções!$F$6:$J$10,5,0)="", "ON "&VLOOKUP(B4,Instruções!$F$6:$J$10,4,0)&"_as_is = "&VLOOKUP(B4,Instruções!$F$6:$J$10,4,0)&"_to_be ", "ON "&VLOOKUP(B4,Instruções!$F$6:$J$10,4,0)&"_as_is = "&VLOOKUP(B4,Instruções!$F$6:$J$10,4,0)&"_to_be AND "&VLOOKUP(B4,Instruções!$F$6:$J$10,5,0)&"_as_is = "&VLOOKUP(B4,Instruções!$F$6:$J$10,5,0)&"_to_be ") -> ON entty_id_as_is = entty_id_to_be | K4: ="WHERE coalesce(cast("&F4&" as string), '') <> coalesce(cast("&G4&" as string), '') " -> WHERE coalesce(cast(accntng_frmwrk_sl_as_is as string), '') <> coalesce(cast(accntng_frmwrk_sl_to_be as string), '') | L4: ="SELECT count(*) AS NUM_REG_DIF FROM "&H4&" Inner join "&I4&J4&K4 -> SELECT count(*) AS NUM_REG_DIF FROM (SELECT entty_id as entty_id_as_is, accntng_frmwrk_sl as accntng_frmwrk_sl_as_is FROM cd_loan_tapes_bce.lt003_entity WHERE ref_date='2025-06-30' AND nome_perimetro= 'Individual IDComb' AND segmento= 'ESTR' AND ambito= 'PM' AND entidade='00100' AND cod_visao = 1) A Inner join (SELECT entty_id as entty_id_to_be, accntng_frmwrk_sl as accntng_frmwrk_sl_to_be FROM bu_loantape_work.lt003_entity WHERE ref_date='2025-06-30' AND nome_perimetro= 'Individual IDComb' AND segmento= 'ESTR' AND ambito= 'PM' AND entidade='00100' AND cod_visao = 1) B ON entty_id_as_is = entty_id_to_be WHERE coalesce(cast(accntng_frmwrk_sl_as_is as string), '') <> coalesce(cast(accntng_frmwrk_sl_to_be as string), '') | M4: Validação de campos | N4: ="SELECT 'Validação de campos' as tipologia_teste, '"&VLOOKUP(B4,Instruções!$F$6:$J$10,3,0)&"' AS TABELA, '"&E4&"' AS CAMPO, '"&Instruções!$D$7&"' as ref_date, coalesce(NUM_REG_DIF, 0) AS NUM_REG_DIF FROM ("&L4&") A " -> SELECT 'Validação de campos' as tipologia_teste, 'lt003_entity' AS TABELA, 'accntng_frmwrk_sl' AS CAMPO, '2025-06-30' as ref_date, coalesce(NUM_REG_DIF, 0) AS NUM_REG_DIF FROM (SELECT count(*) AS NUM_REG_DIF FROM (SELECT entty_id as entty_id_as_is, accntng_frmwrk_sl as accntng_frmwrk_sl_as_is FROM cd_loan_tapes_bce.lt003_entity WHERE ref_date='2025-06-30' AND nome_perimetro= 'Individual IDComb' AND segmento= 'ESTR' AND ambito= 'PM' AND entidade='00100' AND cod_visao = 1) A Inner join (SELECT entty_id as entty_id_to_be, accntng_frmwrk_sl as accntng_frmwrk_sl_to_be FROM bu_loantape_work.lt003_entity WHERE ref_date='2025-06-30' AND nome_perimetro= 'Individual IDComb' AND segmento= 'ESTR' AND ambito= 'PM' AND entidade='00100' AND cod_visao = 1) B ON entty_id_as_is = entty_id_to_be WHERE coalesce(cast(accntng_frmwrk_sl_as_is as string), '') <> coalesce(cast(accntng_frmwrk_sl_to_be as string), '') ) A | O4: =IF(O5="",N4,N4&$O$3) -> SELECT 'Validação de campos' as tipologia_teste, 'lt003_entity' AS TABELA, 'accntng_frmwrk_sl' AS CAMPO, '2025-06-30' as ref_date, coalesce(NUM_REG_DIF, 0) AS NUM_REG_DIF FROM (SELECT count(*) AS NUM_REG_DIF FROM (SELECT entty_id as entty_id_as_is, accntng_frmwrk_sl as accntng_frmwrk_sl_as_is FROM cd_loan_tapes_bce.lt003_entity WHERE ref_date='2025-06-30' AND nome_perimetro= 'Individual IDComb' AND segmento= 'ESTR' AND ambito= 'PM' AND entidade='00100' AND cod_visao = 1) A Inner join (SELECT entty_id as entty_id_to_be, accntng_frmwrk_sl as accntng_frmwrk_sl_to_be FROM bu_loantape_work.lt003_entity WHERE ref_date='2025-06-30' AND nome_perimetro= 'Individual IDComb' AND segmento= 'ESTR' AND ambito= 'PM' AND entidade='00100' AND cod_visao = 1) B ON entty_id_as_is = entty_id_to_be WHERE coalesce(cast(accntng_frmwrk_sl_as_is as string), '') <> coalesce(cast(accntng_frmwrk_sl_to_be as string), '') ) A UNION ALL | P4: =1 -> 1
B5: ENTTY | C5: =_xlfn.CONCAT(Instruções!$D$5,".",VLOOKUP(B5,Instruções!$F$5:$H$10,2,0)) -> cd_loan_tapes_bce.lt003_entity | D5: =_xlfn.CONCAT(Instruções!$D$6,".",VLOOKUP(B5,Instruções!$F$5:$H$10,3,0)) -> bu_loantape_work.lt003_entity | E5: annl_trnvr_le | F5: =E5&"_as_is" -> annl_trnvr_le_as_is | G5: =E5&"_to_be" -> annl_trnvr_le_to_be | H5: =IF(VLOOKUP(B5,Instruções!$F$6:$J$10,5,0)="", "(SELECT "&VLOOKUP(B5,Instruções!$F$6:$J$10,4,0)&" as "&VLOOKUP(B5,Instruções!$F$6:$J$10,4,0)&"_as_is, "&E5&" as "&F5&" FROM "&C5&" WHERE "&Instruções!$D$11&") A ", "(SELECT "&VLOOKUP(B5,Instruções!$F$6:$J$10,4,0)&" as "&VLOOKUP(B5,Instruções!$F$6:$J$10,4,0)&"_as_is, "&VLOOKUP(B5,Instruções!$F$6:$J$10,5,0)&" as "&VLOOKUP(B5,Instruções!$F$6:$J$10,5,0)&"_as_is,"&E5&" as "&F5&" FROM "&C5&" WHERE "&Instruções!$D$11&") A ") -> (SELECT entty_id as entty_id_as_is, annl_trnvr_le as annl_trnvr_le_as_is FROM cd_loan_tapes_bce.lt003_entity WHERE ref_date='2025-06-30' AND nome_perimetro= 'Individual IDComb' AND segmento= 'ESTR' AND ambito= 'PM' AND entidade='00100' AND cod_visao = 1) A | I5: =IF(VLOOKUP(B5,Instruções!$F$6:$J$10,5,0)="", "(SELECT "&VLOOKUP(B5,Instruções!$F$6:$J$10,4,0)&" as "&VLOOKUP(B5,Instruções!$F$6:$J$10,4,0)&"_to_be, "&E5&" as "&G5&" FROM "&D5&" WHERE "&Instruções!$D$11&") B ", "(SELECT "&VLOOKUP(B5,Instruções!$F$6:$J$10,4,0)&" as "&VLOOKUP(B5,Instruções!$F$6:$J$10,4,0)&"_to_be, "&VLOOKUP(B5,Instruções!$F$6:$J$10,5,0)&" as "&VLOOKUP(B5,Instruções!$F$6:$J$10,5,0)&"_to_be,"&E5&" as "&G5&" FROM "&D5&" WHERE "&Instruções!$D$11&") B ") -> (SELECT entty_id as entty_id_to_be, annl_trnvr_le as annl_trnvr_le_to_be FROM bu_loantape_work.lt003_entity WHERE ref_date='2025-06-30' AND nome_perimetro= 'Individual IDComb' AND segmento= 'ESTR' AND ambito= 'PM' AND entidade='00100' AND cod_visao = 1) B | J5: =IF(VLOOKUP(B5,Instruções!$F$6:$J$10,5,0)="", "ON "&VLOOKUP(B5,Instruções!$F$6:$J$10,4,0)&"_as_is = "&VLOOKUP(B5,Instruções!$F$6:$J$10,4,0)&"_to_be ", "ON "&VLOOKUP(B5,Instruções!$F$6:$J$10,4,0)&"_as_is = "&VLOOKUP(B5,Instruções!$F$6:$J$10,4,0)&"_to_be AND "&VLOOKUP(B5,Instruções!$F$6:$J$10,5,0)&"_as_is = "&VLOOKUP(B5,Instruções!$F$6:$J$10,5,0)&"_to_be ") -> ON entty_id_as_is = entty_id_to_be | K5: ="WHERE coalesce(cast("&F5&" as string), '') <> coalesce(cast("&G5&" as string), '') " -> WHERE coalesce(cast(annl_trnvr_le_as_is as string), '') <> coalesce(cast(annl_trnvr_le_to_be as string), '') | L5: ="SELECT count(*) AS NUM_REG_DIF FROM "&H5&" Inner join "&I5&J5&K5 -> SELECT count(*) AS NUM_REG_DIF FROM (SELECT entty_id as entty_id_as_is, annl_trnvr_le as annl_trnvr_le_as_is FROM cd_loan_tapes_bce.lt003_entity WHERE ref_date='2025-06-30' AND nome_perimetro= 'Individual IDComb' AND segmento= 'ESTR' AND ambito= 'PM' AND entidade='00100' AND cod_visao = 1) A Inner join (SELECT entty_id as entty_id_to_be, annl_trnvr_le as annl_trnvr_le_to_be FROM bu_loantape_work.lt003_entity WHERE ref_date='2025-06-30' AND nome_perimetro= 'Individual IDComb' AND segmento= 'ESTR' AND ambito= 'PM' AND entidade='00100' AND cod_visao = 1) B ON entty_id_as_is = entty_id_to_be WHERE coalesce(cast(annl_trnvr_le_as_is as string), '') <> coalesce(cast(annl_trnvr_le_to_be as string), '') | M5: Validação de campos | N5: ="SELECT 'Validação de campos' as tipologia_teste, '"&VLOOKUP(B5,Instruções!$F$6:$J$10,3,0)&"' AS TABELA, '"&E5&"' AS CAMPO, '"&Instruções!$D$7&"' as ref_date, coalesce(NUM_REG_DIF, 0) AS NUM_REG_DIF FROM ("&L5&") A " -> SELECT 'Validação de campos' as tipologia_teste, 'lt003_entity' AS TABELA, 'annl_trnvr_le' AS CAMPO, '2025-06-30' as ref_date, coalesce(NUM_REG_DIF, 0) AS NUM_REG_DIF FROM (SELECT count(*) AS NUM_REG_DIF FROM (SELECT entty_id as entty_id_as_is, annl_trnvr_le as annl_trnvr_le_as_is FROM cd_loan_tapes_bce.lt003_entity WHERE ref_date='2025-06-30' AND nome_perimetro= 'Individual IDComb' AND segmento= 'ESTR' AND ambito= 'PM' AND entidade='00100' AND cod_visao = 1) A Inner join (SELECT entty_id as entty_id_to_be, annl_trnvr_le as annl_trnvr_le_to_be FROM bu_loantape_work.lt003_entity WHERE ref_date='2025-06-30' AND nome_perimetro= 'Individual IDComb' AND segmento= 'ESTR' AND ambito= 'PM' AND entidade='00100' AND cod_visao = 1) B ON entty_id_as_is = entty_id_to_be WHERE coalesce(cast(annl_trnvr_le_as_is as string), '') <> coalesce(cast(annl_trnvr_le_to_be as string), '') ) A | O5: =IF(O6="",N5,N5&$O$3) -> SELECT 'Validação de campos' as tipologia_teste, 'lt003_entity' AS TABELA, 'annl_trnvr_le' AS CAMPO, '2025-06-30' as ref_date, coalesce(NUM_REG_DIF, 0) AS NUM_REG_DIF FROM (SELECT count(*) AS NUM_REG_DIF FROM (SELECT entty_id as entty_id_as_is, annl_trnvr_le as annl_trnvr_le_as_is FROM cd_loan_tapes_bce.lt003_entity WHERE ref_date='2025-06-30' AND nome_perimetro= 'Individual IDComb' AND segmento= 'ESTR' AND ambito= 'PM' AND entidade='00100' AND cod_visao = 1) A Inner join (SELECT entty_id as entty_id_to_be, annl_trnvr_le as annl_trnvr_le_to_be FROM bu_loantape_work.lt003_entity WHERE ref_date='2025-06-30' AND nome_perimetro= 'Individual IDComb' AND segmento= 'ESTR' AND ambito= 'PM' AND entidade='00100' AND cod_visao = 1) B ON entty_id_as_is = entty_id_to_be WHERE coalesce(cast(annl_trnvr_le_as_is as string), '') <> coalesce(cast(annl_trnvr_le_to_be as string), '') ) A UNION ALL | P5: =P4+1 -> 2
B6: ENTTY | C6: =_xlfn.CONCAT(Instruções!$D$5,".",VLOOKUP(B6,Instruções!$F$5:$H$10,2,0)) -> cd_loan_tapes_bce.lt003_entity | D6: =_xlfn.CONCAT(Instruções!$D$6,".",VLOOKUP(B6,Instruções!$F$5:$H$10,3,0)) -> bu_loantape_work.lt003_entity | E6: annl_trnvr_le_bdr | F6: =E6&"_as_is" -> annl_trnvr_le_bdr_as_is | G6: =E6&"_to_be" -> annl_trnvr_le_bdr_to_be | H6: =IF(VLOOKUP(B6,Instruções!$F$6:$J$10,5,0)="", "(SELECT "&VLOOKUP(B6,Instruções!$F$6:$J$10,4,0)&" as "&VLOOKUP(B6,Instruções!$F$6:$J$10,4,0)&"_as_is, "&E6&" as "&F6&" FROM "&C6&" WHERE "&Instruções!$D$11&") A ", "(SELECT "&VLOOKUP(B6,Instruções!$F$6:$J$10,4,0)&" as "&VLOOKUP(B6,Instruções!$F$6:$J$10,4,0)&"_as_is, "&VLOOKUP(B6,Instruções!$F$6:$J$10,5,0)&" as "&VLOOKUP(B6,Instruções!$F$6:$J$10,5,0)&"_as_is,"&E6&" as "&F6&" FROM "&C6&" WHERE "&Instruções!$D$11&") A ") -> (SELECT entty_id as entty_id_as_is, annl_trnvr_le_bdr as annl_trnvr_le_bdr_as_is FROM cd_loan_tapes_bce.lt003_entity WHERE ref_date='2025-06-30' AND nome_perimetro= 'Individual IDComb' AND segmento= 'ESTR' AND ambito= 'PM' AND entidade='00100' AND cod_visao = 1) A | I6: =IF(VLOOKUP(B6,Instruções!$F$6:$J$10,5,0)="", "(SELECT "&VLOOKUP(B6,Instruções!$F$6:$J$10,4,0)&" as "&VLOOKUP(B6,Instruções!$F$6:$J$10,4,0)&"_to_be, "&E6&" as "&G6&" FROM "&D6&" WHERE "&Instruções!$D$11&") B ", "(SELECT "&VLOOKUP(B6,Instruções!$F$6:$J$10,4,0)&" as "&VLOOKUP(B6,Instruções!$F$6:$J$10,4,0)&"_to_be, "&VLOOKUP(B6,Instruções!$F$6:$J$10,5,0)&" as "&VLOOKUP(B6,Instruções!$F$6:$J$10,5,0)&"_to_be,"&E6&" as "&G6&" FROM "&D6&" WHERE "&Instruções!$D$11&") B ") -> (SELECT entty_id as entty_id_to_be, annl_trnvr_le_bdr as annl_trnvr_le_bdr_to_be FROM bu_loantape_work.lt003_entity WHERE ref_date='2025-06-30' AND nome_perimetro= 'Individual IDComb' AND segmento= 'ESTR' AND ambito= 'PM' AND entidade='00100' AND cod_visao = 1) B | J6: =IF(VLOOKUP(B6,Instruções!$F$6:$J$10,5,0)="", "ON "&VLOOKUP(B6,Instruções!$F$6:$J$10,4,0)&"_as_is = "&VLOOKUP(B6,Instruções!$F$6:$J$10,4,0)&"_to_be ", "ON "&VLOOKUP(B6,Instruções!$F$6:$J$10,4,0)&"_as_is = "&VLOOKUP(B6,Instruções!$F$6:$J$10,4,0)&"_to_be AND "&VLOOKUP(B6,Instruções!$F$6:$J$10,5,0)&"_as_is = "&VLOOKUP(B6,Instruções!$F$6:$J$10,5,0)&"_to_be ") -> ON entty_id_as_is = entty_id_to_be | K6: ="WHERE coalesce(cast("&F6&" as string), '') <> coalesce(cast("&G6&" as string), '') " -> WHERE coalesce(cast(annl_trnvr_le_bdr_as_is as string), '') <> coalesce(cast(annl_trnvr_le_bdr_to_be as string), '') | L6: ="SELECT count(*) AS NUM_REG_DIF FROM "&H6&" Inner join "&I6&J6&K6 -> SELECT count(*) AS NUM_REG_DIF FROM (SELECT entty_id as entty_id_as_is, annl_trnvr_le_bdr as annl_trnvr_le_bdr_as_is FROM cd_loan_tapes_bce.lt003_entity WHERE ref_date='2025-06-30' AND nome_perimetro= 'Individual IDComb' AND segmento= 'ESTR' AND ambito= 'PM' AND entidade='00100' AND cod_visao = 1) A Inner join (SELECT entty_id as entty_id_to_be, annl_trnvr_le_bdr as annl_trnvr_le_bdr_to_be FROM bu_loantape_work.lt003_entity WHERE ref_date='2025-06-30' AND nome_perimetro= 'Individual IDComb' AND segmento= 'ESTR' AND ambito= 'PM' AND entidade='00100' AND cod_visao = 1) B ON entty_id_as_is = entty_id_to_be WHERE coalesce(cast(annl_trnvr_le_bdr_as_is as string), '') <> coalesce(cast(annl_trnvr_le_bdr_to_be as string), '') | M6: Validação de campos | N6: ="SELECT 'Validação de campos' as tipologia_teste, '"&VLOOKUP(B6,Instruções!$F$6:$J$10,3,0)&"' AS TABELA, '"&E6&"' AS CAMPO, '"&Instruções!$D$7&"' as ref_date, coalesce(NUM_REG_DIF, 0) AS NUM_REG_DIF FROM ("&L6&") A " -> SELECT 'Validação de campos' as tipologia_teste, 'lt003_entity' AS TABELA, 'annl_trnvr_le_bdr' AS CAMPO, '2025-06-30' as ref_date, coalesce(NUM_REG_DIF, 0) AS NUM_REG_DIF FROM (SELECT count(*) AS NUM_REG_DIF FROM (SELECT entty_id as entty_id_as_is, annl_trnvr_le_bdr as annl_trnvr_le_bdr_as_is FROM cd_loan_tapes_bce.lt003_entity WHERE ref_date='2025-06-30' AND nome_perimetro= 'Individual IDComb' AND segmento= 'ESTR' AND ambito= 'PM' AND entidade='00100' AND cod_visao = 1) A Inner join (SELECT entty_id as entty_id_to_be, annl_trnvr_le_bdr as annl_trnvr_le_bdr_to_be FROM bu_loantape_work.lt003_entity WHERE ref_date='2025-06-30' AND nome_perimetro= 'Individual IDComb' AND segmento= 'ESTR' AND ambito= 'PM' AND entidade='00100' AND cod_visao = 1) B ON entty_id_as_is = entty_id_to_be WHERE coalesce(cast(annl_trnvr_le_bdr_as_is as string), '') <> coalesce(cast(annl_trnvr_le_bdr_to_be as string), '') ) A | O6: =IF(O7="",N6,N6&$O$3) -> SELECT 'Validação de campos' as tipologia_teste, 'lt003_entity' AS TABELA, 'annl_trnvr_le_bdr' AS CAMPO, '2025-06-30' as ref_date, coalesce(NUM_REG_DIF, 0) AS NUM_REG_DIF FROM (SELECT count(*) AS NUM_REG_DIF FROM (SELECT entty_id as entty_id_as_is, annl_trnvr_le_bdr as annl_trnvr_le_bdr_as_is FROM cd_loan_tapes_bce.lt003_entity WHERE ref_date='2025-06-30' AND nome_perimetro= 'Individual IDComb' AND segmento= 'ESTR' AND ambito= 'PM' AND entidade='00100' AND cod_visao = 1) A Inner join (SELECT entty_id as entty_id_to_be, annl_trnvr_le_bdr as annl_trnvr_le_bdr_to_be FROM bu_loantape_work.lt003_entity WHERE ref_date='2025-06-30' AND nome_perimetro= 'Individual IDComb' AND segmento= 'ESTR' AND ambito= 'PM' AND entidade='00100' AND cod_visao = 1) B ON entty_id_as_is = entty_id_to_be WHERE coalesce(cast(annl_trnvr_le_bdr_as_is as string), '') <> coalesce(cast(annl_trnvr_le_bdr_to_be as string), '') ) A UNION ALL | P6: =P5+1 -> 3
B7: ENTTY | C7: =_xlfn.CONCAT(Instruções!$D$5,".",VLOOKUP(B7,Instruções!$F$5:$H$10,2,0)) -> cd_loan_tapes_bce.lt003_entity | D7: =_xlfn.CONCAT(Instruções!$D$6,".",VLOOKUP(B7,Instruções!$F$5:$H$10,3,0)) -> bu_loantape_work.lt003_entity | E7: annl_trnvr_prvs | F7: =E7&"_as_is" -> annl_trnvr_prvs_as_is | G7: =E7&"_to_be" -> annl_trnvr_prvs_to_be | H7: =IF(VLOOKUP(B7,Instruções!$F$6:$J$10,5,0)="", "(SELECT "&VLOOKUP(B7,Instruções!$F$6:$J$10,4,0)&" as "&VLOOKUP(B7,Instruções!$F$6:$J$10,4,0)&"_as_is, "&E7&" as "&F7&" FROM "&C7&" WHERE "&Instruções!$D$11&") A ", "(SELECT "&VLOOKUP(B7,Instruções!$F$6:$J$10,4,0)&" as "&VLOOKUP(B7,Instruções!$F$6:$J$10,4,0)&"_as_is, "&VLOOKUP(B7,Instruções!$F$6:$J$10,5,0)&" as "&VLOOKUP(B7,Instruções!$F$6:$J$10,5,0)&"_as_is,"&E7&" as "&F7&" FROM "&C7&" WHERE "&Instruções!$D$11&") A ") -> (SELECT entty_id as entty_id_as_is, annl_trnvr_prvs as annl_trnvr_prvs_as_is FROM cd_loan_tapes_bce.lt003_entity WHERE ref_date='2025-06-30' AND nome_perimetro= 'Individual IDComb' AND segmento= 'ESTR' AND ambito= 'PM' AND entidade='00100' AND cod_visao = 1) A | I7: =IF(VLOOKUP(B7,Instruções!$F$6:$J$10,5,0)="", "(SELECT "&VLOOKUP(B7,Instruções!$F$6:$J$10,4,0)&" as "&VLOOKUP(B7,Instruções!$F$6:$J$10,4,0)&"_to_be, "&E7&" as "&G7&" FROM "&D7&" WHERE "&Instruções!$D$11&") B ", "(SELECT "&VLOOKUP(B7,Instruções!$F$6:$J$10,4,0)&" as "&VLOOKUP(B7,Instruções!$F$6:$J$10,4,0)&"_to_be, "&VLOOKUP(B7,Instruções!$F$6:$J$10,5,0)&" as "&VLOOKUP(B7,Instruções!$F$6:$J$10,5,0)&"_to_be,"&E7&" as "&G7&" FROM "&D7&" WHERE "&Instruções!$D$11&") B ") -> (SELECT entty_id as entty_id_to_be, annl_trnvr_prvs as annl_trnvr_prvs_to_be FROM bu_loantape_work.lt003_entity WHERE ref_date='2025-06-30' AND nome_perimetro= 'Individual IDComb' AND segmento= 'ESTR' AND ambito= 'PM' AND entidade='00100' AND cod_visao = 1) B | J7: =IF(VLOOKUP(B7,Instruções!$F$6:$J$10,5,0)="", "ON "&VLOOKUP(B7,Instruções!$F$6:$J$10,4,0)&"_as_is = "&VLOOKUP(B7,Instruções!$F$6:$J$10,4,0)&"_to_be ", "ON "&VLOOKUP(B7,Instruções!$F$6:$J$10,4,0)&"_as_is = "&VLOOKUP(B7,Instruções!$F$6:$J$10,4,0)&"_to_be AND "&VLOOKUP(B7,Instruções!$F$6:$J$10,5,0)&"_as_is = "&VLOOKUP(B7,Instruções!$F$6:$J$10,5,0)&"_to_be ") -> ON entty_id_as_is = entty_id_to_be | K7: ="WHERE coalesce(cast("&F7&" as string), '') <> coalesce(cast("&G7&" as string), '') " -> WHERE coalesce(cast(annl_trnvr_prvs_as_is as string), '') <> coalesce(cast(annl_trnvr_prvs_to_be as string), '') | L7: ="SELECT count(*) AS NUM_REG_DIF FROM "&H7&" Inner join "&I7&J7&K7 -> SELECT count(*) AS NUM_REG_DIF FROM (SELECT entty_id as entty_id_as_is, annl_trnvr_prvs as annl_trnvr_prvs_as_is FROM cd_loan_tapes_bce.lt003_entity WHERE ref_date='2025-06-30' AND nome_perimetro= 'Individual IDComb' AND segmento= 'ESTR' AND ambito= 'PM' AND entidade='00100' AND cod_visao = 1) A Inner join (SELECT entty_id as entty_id_to_be, annl_trnvr_prvs as annl_trnvr_prvs_to_be FROM bu_loantape_work.lt003_entity WHERE ref_date='2025-06-30' AND nome_perimetro= 'Individual IDComb' AND segmento= 'ESTR' AND ambito= 'PM' AND entidade='00100' AND cod_visao = 1) B ON entty_id_as_is = entty_id_to_be WHERE coalesce(cast(annl_trnvr_prvs_as_is as string), '') <> coalesce(cast(annl_trnvr_prvs_to_be as string), '') | M7: Validação de campos | N7: ="SELECT 'Validação de campos' as tipologia_teste, '"&VLOOKUP(B7,Instruções!$F$6:$J$10,3,0)&"' AS TABELA, '"&E7&"' AS CAMPO, '"&Instruções!$D$7&"' as ref_date, coalesce(NUM_REG_DIF, 0) AS NUM_REG_DIF FROM ("&L7&") A " -> SELECT 'Validação de campos' as tipologia_teste, 'lt003_entity' AS TABELA, 'annl_trnvr_prvs' AS CAMPO, '2025-06-30' as ref_date, coalesce(NUM_REG_DIF, 0) AS NUM_REG_DIF FROM (SELECT count(*) AS NUM_REG_DIF FROM (SELECT entty_id as entty_id_as_is, annl_trnvr_prvs as annl_trnvr_prvs_as_is FROM cd_loan_tapes_bce.lt003_entity WHERE ref_date='2025-06-30' AND nome_perimetro= 'Individual IDComb' AND segmento= 'ESTR' AND ambito= 'PM' AND entidade='00100' AND cod_visao = 1) A Inner join (SELECT entty_id as entty_id_to_be, annl_trnvr_prvs as annl_trnvr_prvs_to_be FROM bu_loantape_work.lt003_entity WHERE ref_date='2025-06-30' AND nome_perimetro= 'Individual IDComb' AND segmento= 'ESTR' AND ambito= 'PM' AND entidade='00100' AND cod_visao = 1) B ON entty_id_as_is = entty_id_to_be WHERE coalesce(cast(annl_trnvr_prvs_as_is as string), '') <> coalesce(cast(annl_trnvr_prvs_to_be as string), '') ) A | O7: =IF(O8="",N7,N7&$O$3) -> SELECT 'Validação de campos' as tipologia_teste, 'lt003_entity' AS TABELA, 'annl_trnvr_prvs' AS CAMPO, '2025-06-30' as ref_date, coalesce(NUM_REG_DIF, 0) AS NUM_REG_DIF FROM (SELECT count(*) AS NUM_REG_DIF FROM (SELECT entty_id as entty_id_as_is, annl_trnvr_prvs as annl_trnvr_prvs_as_is FROM cd_loan_tapes_bce.lt003_entity WHERE ref_date='2025-06-30' AND nome_perimetro= 'Individual IDComb' AND segmento= 'ESTR' AND ambito= 'PM' AND entidade='00100' AND cod_visao = 1) A Inner join (SELECT entty_id as entty_id_to_be, annl_trnvr_prvs as annl_trnvr_prvs_to_be FROM bu_loantape_work.lt003_entity WHERE ref_date='2025-06-30' AND nome_perimetro= 'Individual IDComb' AND segmento= 'ESTR' AND ambito= 'PM' AND entidade='00100' AND cod_visao = 1) B ON entty_id_as_is = entty_id_to_be WHERE coalesce(cast(annl_trnvr_prvs_as_is as string), '') <> coalesce(cast(annl_trnvr_prvs_to_be as string), '') ) A UNION ALL | P7: =P6+1 -> 4
B8: ENTTY | C8: =_xlfn.CONCAT(Instruções!$D$5,".",VLOOKUP(B8,Instruções!$F$5:$H$10,2,0)) -> cd_loan_tapes_bce.lt003_entity | D8: =_xlfn.CONCAT(Instruções!$D$6,".",VLOOKUP(B8,Instruções!$F$5:$H$10,3,0)) -> bu_loantape_work.lt003_entity | E8: annl_trnvr_prvs_bdr | F8: =E8&"_as_is" -> annl_trnvr_prvs_bdr_as_is | G8: =E8&"_to_be" -> annl_trnvr_prvs_bdr_to_be | H8: =IF(VLOOKUP(B8,Instruções!$F$6:$J$10,5,0)="", "(SELECT "&VLOOKUP(B8,Instruções!$F$6:$J$10,4,0)&" as "&VLOOKUP(B8,Instruções!$F$6:$J$10,4,0)&"_as_is, "&E8&" as "&F8&" FROM "&C8&" WHERE "&Instruções!$D$11&") A ", "(SELECT "&VLOOKUP(B8,Instruções!$F$6:$J$10,4,0)&" as "&VLOOKUP(B8,Instruções!$F$6:$J$10,4,0)&"_as_is, "&VLOOKUP(B8,Instruções!$F$6:$J$10,5,0)&" as "&VLOOKUP(B8,Instruções!$F$6:$J$10,5,0)&"_as_is,"&E8&" as "&F8&" FROM "&C8&" WHERE "&Instruções!$D$11&") A ") -> (SELECT entty_id as entty_id_as_is, annl_trnvr_prvs_bdr as annl_trnvr_prvs_bdr_as_is FROM cd_loan_tapes_bce.lt003_entity WHERE ref_date='2025-06-30' AND nome_perimetro= 'Individual IDComb' AND segmento= 'ESTR' AND ambito= 'PM' AND entidade='00100' AND cod_visao = 1) A | I8: =IF(VLOOKUP(B8,Instruções!$F$6:$J$10,5,0)="", "(SELECT "&VLOOKUP(B8,Instruções!$F$6:$J$10,4,0)&" as "&VLOOKUP(B8,Instruções!$F$6:$J$10,4,0)&"_to_be, "&E8&" as "&G8&" FROM "&D8&" WHERE "&Instruções!$D$11&") B ", "(SELECT "&VLOOKUP(B8,Instruções!$F$6:$J$10,4,0)&" as "&VLOOKUP(B8,Instruções!$F$6:$J$10,4,0)&"_to_be, "&VLOOKUP(B8,Instruções!$F$6:$J$10,5,0)&" as "&VLOOKUP(B8,Instruções!$F$6:$J$10,5,0)&"_to_be,"&E8&" as "&G8&" FROM "&D8&" WHERE "&Instruções!$D$11&") B ") -> (SELECT entty_id as entty_id_to_be, annl_trnvr_prvs_bdr as annl_trnvr_prvs_bdr_to_be FROM bu_loantape_work.lt003_entity WHERE ref_date='2025-06-30' AND nome_perimetro= 'Individual IDComb' AND segmento= 'ESTR' AND ambito= 'PM' AND entidade='00100' AND cod_visao = 1) B | J8: =IF(VLOOKUP(B8,Instruções!$F$6:$J$10,5,0)="", "ON "&VLOOKUP(B8,Instruções!$F$6:$J$10,4,0)&"_as_is = "&VLOOKUP(B8,Instruções!$F$6:$J$10,4,0)&"_to_be ", "ON "&VLOOKUP(B8,Instruções!$F$6:$J$10,4,0)&"_as_is = "&VLOOKUP(B8,Instruções!$F$6:$J$10,4,0)&"_to_be AND "&VLOOKUP(B8,Instruções!$F$6:$J$10,5,0)&"_as_is = "&VLOOKUP(B8,Instruções!$F$6:$J$10,5,0)&"_to_be ") -> ON entty_id_as_is = entty_id_to_be | K8: ="WHERE coalesce(cast("&F8&" as string), '') <> coalesce(cast("&G8&" as string), '') " -> WHERE coalesce(cast(annl_trnvr_prvs_bdr_as_is as string), '') <> coalesce(cast(annl_trnvr_prvs_bdr_to_be as string), '') | L8: ="SELECT count(*) AS NUM_REG_DIF FROM "&H8&" Inner join "&I8&J8&K8 -> SELECT count(*) AS NUM_REG_DIF FROM (SELECT entty_id as entty_id_as_is, annl_trnvr_prvs_bdr as annl_trnvr_prvs_bdr_as_is FROM cd_loan_tapes_bce.lt003_entity WHERE ref_date='2025-06-30' AND nome_perimetro= 'Individual IDComb' AND segmento= 'ESTR' AND ambito= 'PM' AND entidade='00100' AND cod_visao = 1) A Inner join (SELECT entty_id as entty_id_to_be, annl_trnvr_prvs_bdr as annl_trnvr_prvs_bdr_to_be FROM bu_loantape_work.lt003_entity WHERE ref_date='2025-06-30' AND nome_perimetro= 'Individual IDComb' AND segmento= 'ESTR' AND ambito= 'PM' AND entidade='00100' AND cod_visao = 1) B ON entty_id_as_is = entty_id_to_be WHERE coalesce(cast(annl_trnvr_prvs_bdr_as_is as string), '') <> coalesce(cast(annl_trnvr_prvs_bdr_to_be as string), '') | M8: Validação de campos | N8: ="SELECT 'Validação de campos' as tipologia_teste, '"&VLOOKUP(B8,Instruções!$F$6:$J$10,3,0)&"' AS TABELA, '"&E8&"' AS CAMPO, '"&Instruções!$D$7&"' as ref_date, coalesce(NUM_REG_DIF, 0) AS NUM_REG_DIF FROM ("&L8&") A " -> SELECT 'Validação de campos' as tipologia_teste, 'lt003_entity' AS TABELA, 'annl_trnvr_prvs_bdr' AS CAMPO, '2025-06-30' as ref_date, coalesce(NUM_REG_DIF, 0) AS NUM_REG_DIF FROM (SELECT count(*) AS NUM_REG_DIF FROM (SELECT entty_id as entty_id_as_is, annl_trnvr_prvs_bdr as annl_trnvr_prvs_bdr_as_is FROM cd_loan_tapes_bce.lt003_entity WHERE ref_date='2025-06-30' AND nome_perimetro= 'Individual IDComb' AND segmento= 'ESTR' AND ambito= 'PM' AND entidade='00100' AND cod_visao = 1) A Inner join (SELECT entty_id as entty_id_to_be, annl_trnvr_prvs_bdr as annl_trnvr_prvs_bdr_to_be FROM bu_loantape_work.lt003_entity WHERE ref_date='2025-06-30' AND nome_perimetro= 'Individual IDComb' AND segmento= 'ESTR' AND ambito= 'PM' AND entidade='00100' AND cod_visao = 1) B ON entty_id_as_is = entty_id_to_be WHERE coalesce(cast(annl_trnvr_prvs_bdr_as_is as string), '') <> coalesce(cast(annl_trnvr_prvs_bdr_to_be as string), '') ) A | O8: =IF(O9="",N8,N8&$O$3) -> SELECT 'Validação de campos' as tipologia_teste, 'lt003_entity' AS TABELA, 'annl_trnvr_prvs_bdr' AS CAMPO, '2025-06-30' as ref_date, coalesce(NUM_REG_DIF, 0) AS NUM_REG_DIF FROM (SELECT count(*) AS NUM_REG_DIF FROM (SELECT entty_id as entty_id_as_is, annl_trnvr_prvs_bdr as annl_trnvr_prvs_bdr_as_is FROM cd_loan_tapes_bce.lt003_entity WHERE ref_date='2025-06-30' AND nome_perimetro= 'Individual IDComb' AND segmento= 'ESTR' AND ambito= 'PM' AND entidade='00100' AND cod_visao = 1) A Inner join (SELECT entty_id as entty_id_to_be, annl_trnvr_prvs_bdr as annl_trnvr_prvs_bdr_to_be FROM bu_loantape_work.lt003_entity WHERE ref_date='2025-06-30' AND nome_perimetro= 'Individual IDComb' AND segmento= 'ESTR' AND ambito= 'PM' AND entidade='00100' AND cod_visao = 1) B ON entty_id_as_is = entty_id_to_be WHERE coalesce(cast(annl_trnvr_prvs_bdr_as_is as string), '') <> coalesce(cast(annl_trnvr_prvs_bdr_to_be as string), '') ) A UNION ALL | P8: =P7+1 -> 5
B9: ENTTY | C9: =_xlfn.CONCAT(Instruções!$D$5,".",VLOOKUP(B9,Instruções!$F$5:$H$10,2,0)) -> cd_loan_tapes_bce.lt003_entity | D9: =_xlfn.CONCAT(Instruções!$D$6,".",VLOOKUP(B9,Instruções!$F$5:$H$10,3,0)) -> bu_loantape_work.lt003_entity | E9: capex | F9: =E9&"_as_is" -> capex_as_is | G9: =E9&"_to_be" -> capex_to_be | H9: =IF(VLOOKUP(B9,Instruções!$F$6:$J$10,5,0)="", "(SELECT "&VLOOKUP(B9,Instruções!$F$6:$J$10,4,0)&" as "&VLOOKUP(B9,Instruções!$F$6:$J$10,4,0)&"_as_is, "&E9&" as "&F9&" FROM "&C9&" WHERE "&Instruções!$D$11&") A ", "(SELECT "&VLOOKUP(B9,Instruções!$F$6:$J$10,4,0)&" as "&VLOOKUP(B9,Instruções!$F$6:$J$10,4,0)&"_as_is, "&VLOOKUP(B9,Instruções!$F$6:$J$10,5,0)&" as "&VLOOKUP(B9,Instruções!$F$6:$J$10,5,0)&"_as_is,"&E9&" as "&F9&" FROM "&C9&" WHERE "&Instruções!$D$11&") A ") -> (SELECT entty_id as entty_id_as_is, capex as capex_as_is FROM cd_loan_tapes_bce.lt003_entity WHERE ref_date='2025-06-30' AND nome_perimetro= 'Individual IDComb' AND segmento= 'ESTR' AND ambito= 'PM' AND entidade='00100' AND cod_visao = 1) A | I9: =IF(VLOOKUP(B9,Instruções!$F$6:$J$10,5,0)="", "(SELECT "&VLOOKUP(B9,Instruções!$F$6:$J$10,4,0)&" as "&VLOOKUP(B9,Instruções!$F$6:$J$10,4,0)&"_to_be, "&E9&" as "&G9&" FROM "&D9&" WHERE "&Instruções!$D$11&") B ", "(SELECT "&VLOOKUP(B9,Instruções!$F$6:$J$10,4,0)&" as "&VLOOKUP(B9,Instruções!$F$6:$J$10,4,0)&"_to_be, "&VLOOKUP(B9,Instruções!$F$6:$J$10,5,0)&" as "&VLOOKUP(B9,Instruções!$F$6:$J$10,5,0)&"_to_be,"&E9&" as "&G9&" FROM "&D9&" WHERE "&Instruções!$D$11&") B ") -> (SELECT entty_id as entty_id_to_be, capex as capex_to_be FROM bu_loantape_work.lt003_entity WHERE ref_date='2025-06-30' AND nome_perimetro= 'Individual IDComb' AND segmento= 'ESTR' AND ambito= 'PM' AND entidade='00100' AND cod_visao = 1) B | J9: =IF(VLOOKUP(B9,Instruções!$F$6:$J$10,5,0)="", "ON "&VLOOKUP(B9,Instruções!$F$6:$J$10,4,0)&"_as_is = "&VLOOKUP(B9,Instruções!$F$6:$J$10,4,0)&"_to_be ", "ON "&VLOOKUP(B9,Instruções!$F$6:$J$10,4,0)&"_as_is = "&VLOOKUP(B9,Instruções!$F$6:$J$10,4,0)&"_to_be AND "&VLOOKUP(B9,Instruções!$F$6:$J$10,5,0)&"_as_is = "&VLOOKUP(B9,Instruções!$F$6:$J$10,5,0)&"_to_be ") -> ON entty_id_as_is = entty_id_to_be | K9: ="WHERE coalesce(cast("&F9&" as string), '') <> coalesce(cast("&G9&" as string), '') " -> WHERE coalesce(cast(capex_as_is as string), '') <> coalesce(cast(capex_to_be as string), '') | L9: ="SELECT count(*) AS NUM_REG_DIF FROM "&H9&" Inner join "&I9&J9&K9 -> SELECT count(*) AS NUM_REG_DIF FROM (SELECT entty_id as entty_id_as_is, capex as capex_as_is FROM cd_loan_tapes_bce.lt003_entity WHERE ref_date='2025-06-30' AND nome_perimetro= 'Individual IDComb' AND segmento= 'ESTR' AND ambito= 'PM' AND entidade='00100' AND cod_visao = 1) A Inner join (SELECT entty_id as entty_id_to_be, capex as capex_to_be FROM bu_loantape_work.lt003_entity WHERE ref_date='2025-06-30' AND nome_perimetro= 'Individual IDComb' AND segmento= 'ESTR' AND ambito= 'PM' AND entidade='00100' AND cod_visao = 1) B ON entty_id_as_is = entty_id_to_be WHERE coalesce(cast(capex_as_is as string), '') <> coalesce(cast(capex_to_be as string), '') | M9: Validação de campos | N9: ="SELECT 'Validação de campos' as tipologia_teste, '"&VLOOKUP(B9,Instruções!$F$6:$J$10,3,0)&"' AS TABELA, '"&E9&"' AS CAMPO, '"&Instruções!$D$7&"' as ref_date, coalesce(NUM_REG_DIF, 0) AS NUM_REG_DIF FROM ("&L9&") A " -> SELECT 'Validação de campos' as tipologia_teste, 'lt003_entity' AS TABELA, 'capex' AS CAMPO, '2025-06-30' as ref_date, coalesce(NUM_REG_DIF, 0) AS NUM_REG_DIF FROM (SELECT count(*) AS NUM_REG_DIF FROM (SELECT entty_id as entty_id_as_is, capex as capex_as_is FROM cd_loan_tapes_bce.lt003_entity WHERE ref_date='2025-06-30' AND nome_perimetro= 'Individual IDComb' AND segmento= 'ESTR' AND ambito= 'PM' AND entidade='00100' AND cod_visao = 1) A Inner join (SELECT entty_id as entty_id_to_be, capex as capex_to_be FROM bu_loantape_work.lt003_entity WHERE ref_date='2025-06-30' AND nome_perimetro= 'Individual IDComb' AND segmento= 'ESTR' AND ambito= 'PM' AND entidade='00100' AND cod_visao = 1) B ON entty_id_as_is = entty_id_to_be WHERE coalesce(cast(capex_as_is as string), '') <> coalesce(cast(capex_to_be as string), '') ) A | O9: =IF(O10="",N9,N9&$O$3) -> SELECT 'Validação de campos' as tipologia_teste, 'lt003_entity' AS TABELA, 'capex' AS CAMPO, '2025-06-30' as ref_date, coalesce(NUM_REG_DIF, 0) AS NUM_REG_DIF FROM (SELECT count(*) AS NUM_REG_DIF FROM (SELECT entty_id as entty_id_as_is, capex as capex_as_is FROM cd_loan_tapes_bce.lt003_entity WHERE ref_date='2025-06-30' AND nome_perimetro= 'Individual IDComb' AND segmento= 'ESTR' AND ambito= 'PM' AND entidade='00100' AND cod_visao = 1) A Inner join (SELECT entty_id as entty_id_to_be, capex as capex_to_be FROM bu_loantape_work.lt003_entity WHERE ref_date='2025-06-30' AND nome_perimetro= 'Individual IDComb' AND segmento= 'ESTR' AND ambito= 'PM' AND entidade='00100' AND cod_visao = 1) B ON entty_id_as_is = entty_id_to_be WHERE coalesce(cast(capex_as_is as string), '') <> coalesce(cast(capex_to_be as string), '') ) A UNION ALL | P9: =P8+1 -> 6
B10: ENTTY | C10: =_xlfn.CONCAT(Instruções!$D$5,".",VLOOKUP(B10,Instruções!$F$5:$H$10,2,0)) -> cd_loan_tapes_bce.lt003_entity | D10: =_xlfn.CONCAT(Instruções!$D$6,".",VLOOKUP(B10,Instruções!$F$5:$H$10,3,0)) -> bu_loantape_work.lt003_entity | E10: capex_prvs | F10: =E10&"_as_is" -> capex_prvs_as_is | G10: =E10&"_to_be" -> capex_prvs_to_be | H10: =IF(VLOOKUP(B10,Instruções!$F$6:$J$10,5,0)="", "(SELECT "&VLOOKUP(B10,Instruções!$F$6:$J$10,4,0)&" as "&VLOOKUP(B10,Instruções!$F$6:$J$10,4,0)&"_as_is, "&E10&" as "&F10&" FROM "&C10&" WHERE "&Instruções!$D$11&") A ", "(SELECT "&VLOOKUP(B10,Instruções!$F$6:$J$10,4,0)&" as "&VLOOKUP(B10,Instruções!$F$6:$J$10,4,0)&"_as_is, "&VLOOKUP(B10,Instruções!$F$6:$J$10,5,0)&" as "&VLOOKUP(B10,Instruções!$F$6:$J$10,5,0)&"_as_is,"&E10&" as "&F10&" FROM "&C10&" WHERE "&Instruções!$D$11&") A ") -> (SELECT entty_id as entty_id_as_is, capex_prvs as capex_prvs_as_is FROM cd_loan_tapes_bce.lt003_entity WHERE ref_date='2025-06-30' AND nome_perimetro= 'Individual IDComb' AND segmento= 'ESTR' AND ambito= 'PM' AND entidade='00100' AND cod_visao = 1) A | I10: =IF(VLOOKUP(B10,Instruções!$F$6:$J$10,5,0)="", "(SELECT "&VLOOKUP(B10,Instruções!$F$6:$J$10,4,0)&" as "&VLOOKUP(B10,Instruções!$F$6:$J$10,4,0)&"_to_be, "&E10&" as "&G10&" FROM "&D10&" WHERE "&Instruções!$D$11&") B ", "(SELECT "&VLOOKUP(B10,Instruções!$F$6:$J$10,4,0)&" as "&VLOOKUP(B10,Instruções!$F$6:$J$10,4,0)&"_to_be, "&VLOOKUP(B10,Instruções!$F$6:$J$10,5,0)&" as "&VLOOKUP(B10,Instruções!$F$6:$J$10,5,0)&"_to_be,"&E10&" as "&G10&" FROM "&D10&" WHERE "&Instruções!$D$11&") B ") -> (SELECT entty_id as entty_id_to_be, capex_prvs as capex_prvs_to_be FROM bu_loantape_work.lt003_entity WHERE ref_date='2025-06-30' AND nome_perimetro= 'Individual IDComb' AND segmento= 'ESTR' AND ambito= 'PM' AND entidade='00100' AND cod_visao = 1) B | J10: =IF(VLOOKUP(B10,Instruções!$F$6:$J$10,5,0)="", "ON "&VLOOKUP(B10,Instruções!$F$6:$J$10,4,0)&"_as_is = "&VLOOKUP(B10,Instruções!$F$6:$J$10,4,0)&"_to_be ", "ON "&VLOOKUP(B10,Instruções!$F$6:$J$10,4,0)&"_as_is = "&VLOOKUP(B10,Instruções!$F$6:$J$10,4,0)&"_to_be AND "&VLOOKUP(B10,Instruções!$F$6:$J$10,5,0)&"_as_is = "&VLOOKUP(B10,Instruções!$F$6:$J$10,5,0)&"_to_be ") -> ON entty_id_as_is = entty_id_to_be | K10: ="WHERE coalesce(cast("&F10&" as string), '') <> coalesce(cast("&G10&" as string), '') " -> WHERE coalesce(cast(capex_prvs_as_is as string), '') <> coalesce(cast(capex_prvs_to_be as string), '') | L10: ="SELECT count(*) AS NUM_REG_DIF FROM "&H10&" Inner join "&I10&J10&K10 -> SELECT count(*) AS NUM_REG_DIF FROM (SELECT entty_id as entty_id_as_is, capex_prvs as capex_prvs_as_is FROM cd_loan_tapes_bce.lt003_entity WHERE ref_date='2025-06-30' AND nome_perimetro= 'Individual IDComb' AND segmento= 'ESTR' AND ambito= 'PM' AND entidade='00100' AND cod_visao = 1) A Inner join (SELECT entty_id as entty_id_to_be, capex_prvs as capex_prvs_to_be FROM bu_loantape_work.lt003_entity WHERE ref_date='2025-06-30' AND nome_perimetro= 'Individual IDComb' AND segmento= 'ESTR' AND ambito= 'PM' AND entidade='00100' AND cod_visao = 1) B ON entty_id_as_is = entty_id_to_be WHERE coalesce(cast(capex_prvs_as_is as string), '') <> coalesce(cast(capex_prvs_to_be as string), '') | M10: Validação de campos | N10: ="SELECT 'Validação de campos' as tipologia_teste, '"&VLOOKUP(B10,Instruções!$F$6:$J$10,3,0)&"' AS TABELA, '"&E10&"' AS CAMPO, '"&Instruções!$D$7&"' as ref_date, coalesce(NUM_REG_DIF, 0) AS NUM_REG_DIF FROM ("&L10&") A " -> SELECT 'Validação de campos' as tipologia_teste, 'lt003_entity' AS TABELA, 'capex_prvs' AS CAMPO, '2025-06-30' as ref_date, coalesce(NUM_REG_DIF, 0) AS NUM_REG_DIF FROM (SELECT count(*) AS NUM_REG_DIF FROM (SELECT entty_id as entty_id_as_is, capex_prvs as capex_prvs_as_is FROM cd_loan_tapes_bce.lt003_entity WHERE ref_date='2025-06-30' AND nome_perimetro= 'Individual IDComb' AND segmento= 'ESTR' AND ambito= 'PM' AND entidade='00100' AND cod_visao = 1) A Inner join (SELECT entty_id as entty_id_to_be, capex_prvs as capex_prvs_to_be FROM bu_loantape_work.lt003_entity WHERE ref_date='2025-06-30' AND nome_perimetro= 'Individual IDComb' AND segmento= 'ESTR' AND ambito= 'PM' AND entidade='00100' AND cod_visao = 1) B ON entty_id_as_is = entty_id_to_be WHERE coalesce(cast(capex_prvs_as_is as string), '') <> coalesce(cast(capex_prvs_to_be as string), '') ) A | O10: =IF(O11="",N10,N10&$O$3) -> SELECT 'Validação de campos' as tipologia_teste, 'lt003_entity' AS TABELA, 'capex_prvs' AS CAMPO, '2025-06-30' as ref_date, coalesce(NUM_REG_DIF, 0) AS NUM_REG_DIF FROM (SELECT count(*) AS NUM_REG_DIF FROM (SELECT entty_id as entty_id_as_is, capex_prvs as capex_prvs_as_is FROM cd_loan_tapes_bce.lt003_entity WHERE ref_date='2025-06-30' AND nome_perimetro= 'Individual IDComb' AND segmento= 'ESTR' AND ambito= 'PM' AND entidade='00100' AND cod_visao = 1) A Inner join (SELECT entty_id as entty_id_to_be, capex_prvs as capex_prvs_to_be FROM bu_loantape_work.lt003_entity WHERE ref_date='2025-06-30' AND nome_perimetro= 'Individual IDComb' AND segmento= 'ESTR' AND ambito= 'PM' AND entidade='00100' AND cod_visao = 1) B ON entty_id_as_is = entty_id_to_be WHERE coalesce(cast(capex_prvs_as_is as string), '') <> coalesce(cast(capex_prvs_to_be as string), '') ) A UNION ALL | P10: =P9+1 -> 7
B11: ENTTY | C11: =_xlfn.CONCAT(Instruções!$D$5,".",VLOOKUP(B11,Instruções!$F$5:$H$10,2,0)) -> cd_loan_tapes_bce.lt003_entity | D11: =_xlfn.CONCAT(Instruções!$D$6,".",VLOOKUP(B11,Instruções!$F$5:$H$10,3,0)) -> bu_loantape_work.lt003_entity | E11: cllctn_md | F11: =E11&"_as_is" -> cllctn_md_as_is | G11: =E11&"_to_be" -> cllctn_md_to_be | H11: =IF(VLOOKUP(B11,Instruções!$F$6:$J$10,5,0)="", "(SELECT "&VLOOKUP(B11,Instruções!$F$6:$J$10,4,0)&" as "&VLOOKUP(B11,Instruções!$F$6:$J$10,4,0)&"_as_is, "&E11&" as "&F11&" FROM "&C11&" WHERE "&Instruções!$D$11&") A ", "(SELECT "&VLOOKUP(B11,Instruções!$F$6:$J$10,4,0)&" as "&VLOOKUP(B11,Instruções!$F$6:$J$10,4,0)&"_as_is, "&VLOOKUP(B11,Instruções!$F$6:$J$10,5,0)&" as "&VLOOKUP(B11,Instruções!$F$6:$J$10,5,0)&"_as_is,"&E11&" as "&F11&" FROM "&C11&" WHERE "&Instruções!$D$11&") A ") -> (SELECT entty_id as entty_id_as_is, cllctn_md as cllctn_md_as_is FROM cd_loan_tapes_bce.lt003_entity WHERE ref_date='2025-06-30' AND nome_perimetro= 'Individual IDComb' AND segmento= 'ESTR' AND ambito= 'PM' AND entidade='00100' AND cod_visao = 1) A | I11: =IF(VLOOKUP(B11,Instruções!$F$6:$J$10,5,0)="", "(SELECT "&VLOOKUP(B11,Instruções!$F$6:$J$10,4,0)&" as "&VLOOKUP(B11,Instruções!$F$6:$J$10,4,0)&"_to_be, "&E11&" as "&G11&" FROM "&D11&" WHERE "&Instruções!$D$11&") B ", "(SELECT "&VLOOKUP(B11,Instruções!$F$6:$J$10,4,0)&" as "&VLOOKUP(B11,Instruções!$F$6:$J$10,4,0)&"_to_be, "&VLOOKUP(B11,Instruções!$F$6:$J$10,5,0)&" as "&VLOOKUP(B11,Instruções!$F$6:$J$10,5,0)&"_to_be,"&E11&" as "&G11&" FROM "&D11&" WHERE "&Instruções!$D$11&") B ") -> (SELECT entty_id as entty_id_to_be, cllctn_md as cllctn_md_to_be FROM bu_loantape_work.lt003_entity WHERE ref_date='2025-06-30' AND nome_perimetro= 'Individual IDComb' AND segmento= 'ESTR' AND ambito= 'PM' AND entidade='00100' AND cod_visao = 1) B | J11: =IF(VLOOKUP(B11,Instruções!$F$6:$J$10,5,0)="", "ON "&VLOOKUP(B11,Instruções!$F$6:$J$10,4,0)&"_as_is = "&VLOOKUP(B11,Instruções!$F$6:$J$10,4,0)&"_to_be ", "ON "&VLOOKUP(B11,Instruções!$F$6:$J$10,4,0)&"_as_is = "&VLOOKUP(B11,Instruções!$F$6:$J$10,4,0)&"_to_be AND "&VLOOKUP(B11,Instruções!$F$6:$J$10,5,0)&"_as_is = "&VLOOKUP(B11,Instruções!$F$6:$J$10,5,0)&"_to_be ") -> ON entty_id_as_is = entty_id_to_be | K11: ="WHERE coalesce(cast("&F11&" as string), '') <> coalesce(cast("&G11&" as string), '') " -> WHERE coalesce(cast(cllctn_md_as_is as string), '') <> coalesce(cast(cllctn_md_to_be as string), '') | L11: ="SELECT count(*) AS NUM_REG_DIF FROM "&H11&" Inner join "&I11&J11&K11 -> SELECT count(*) AS NUM_REG_DIF FROM (SELECT entty_id as entty_id_as_is, cllctn_md as cllctn_md_as_is FROM cd_loan_tapes_bce.lt003_entity WHERE ref_date='2025-06-30' AND nome_perimetro= 'Individual IDComb' AND segmento= 'ESTR' AND ambito= 'PM' AND entidade='00100' AND cod_visao = 1) A Inner join (SELECT entty_id as entty_id_to_be, cllctn_md as cllctn_md_to_be FROM bu_loantape_work.lt003_entity WHERE ref_date='2025-06-30' AND nome_perimetro= 'Individual IDComb' AND segmento= 'ESTR' AND ambito= 'PM' AND entidade='00100' AND cod_visao = 1) B ON entty_id_as_is = entty_id_to_be WHERE coalesce(cast(cllctn_md_as_is as string), '') <> coalesce(cast(cllctn_md_to_be as string), '') | M11: Validação de campos | N11: ="SELECT 'Validação de campos' as tipologia_teste, '"&VLOOKUP(B11,Instruções!$F$6:$J$10,3,0)&"' AS TABELA, '"&E11&"' AS CAMPO, '"&Instruções!$D$7&"' as ref_date, coalesce(NUM_REG_DIF, 0) AS NUM_REG_DIF FROM ("&L11&") A " -> SELECT 'Validação de campos' as tipologia_teste, 'lt003_entity' AS TABELA, 'cllctn_md' AS CAMPO, '2025-06-30' as ref_date, coalesce(NUM_REG_DIF, 0) AS NUM_REG_DIF FROM (SELECT count(*) AS NUM_REG_DIF FROM (SELECT entty_id as entty_id_as_is, cllctn_md as cllctn_md_as_is FROM cd_loan_tapes_bce.lt003_entity WHERE ref_date='2025-06-30' AND nome_perimetro= 'Individual IDComb' AND segmento= 'ESTR' AND ambito= 'PM' AND entidade='00100' AND cod_visao = 1) A Inner join (SELECT entty_id as entty_id_to_be, cllctn_md as cllctn_md_to_be FROM bu_loantape_work.lt003_entity WHERE ref_date='2025-06-30' AND nome_perimetro= 'Individual IDComb' AND segmento= 'ESTR' AND ambito= 'PM' AND entidade='00100' AND cod_visao = 1) B ON entty_id_as_is = entty_id_to_be WHERE coalesce(cast(cllctn_md_as_is as string), '') <> coalesce(cast(cllctn_md_to_be as string), '') ) A | O11: =IF(O12="",N11,N11&$O$3) -> SELECT 'Validação de campos' as tipologia_teste, 'lt003_entity' AS TABELA, 'cllctn_md' AS CAMPO, '2025-06-30' as ref_date, coalesce(NUM_REG_DIF, 0) AS NUM_REG_DIF FROM (SELECT count(*) AS NUM_REG_DIF FROM (SELECT entty_id as entty_id_as_is, cllctn_md as cllctn_md_as_is FROM cd_loan_tapes_bce.lt003_entity WHERE ref_date='2025-06-30' AND nome_perimetro= 'Individual IDComb' AND segmento= 'ESTR' AND ambito= 'PM' AND entidade='00100' AND cod_visao = 1) A Inner join (SELECT entty_id as entty_id_to_be, cllctn_md as cllctn_md_to_be FROM bu_loantape_work.lt003_entity WHERE ref_date='2025-06-30' AND nome_perimetro= 'Individual IDComb' AND segmento= 'ESTR' AND ambito= 'PM' AND entidade='00100' AND cod_visao = 1) B ON entty_id_as_is = entty_id_to_be WHERE coalesce(cast(cllctn_md_as_is as string), '') <> coalesce(cast(cllctn_md_to_be as string), '') ) A UNION ALL | P11: =P10+1 -> 8
B12: ENTTY | C12: =_xlfn.CONCAT(Instruções!$D$5,".",VLOOKUP(B12,Instruções!$F$5:$H$10,2,0)) -> cd_loan_tapes_bce.lt003_entity | D12: =_xlfn.CONCAT(Instruções!$D$6,".",VLOOKUP(B12,Instruções!$F$5:$H$10,3,0)) -> bu_loantape_work.lt003_entity | E12: cntry | F12: =E12&"_as_is" -> cntry_as_is | G12: =E12&"_to_be" -> cntry_to_be | H12: =IF(VLOOKUP(B12,Instruções!$F$6:$J$10,5,0)="", "(SELECT "&VLOOKUP(B12,Instruções!$F$6:$J$10,4,0)&" as "&VLOOKUP(B12,Instruções!$F$6:$J$10,4,0)&"_as_is, "&E12&" as "&F12&" FROM "&C12&" WHERE "&Instruções!$D$11&") A ", "(SELECT "&VLOOKUP(B12,Instruções!$F$6:$J$10,4,0)&" as "&VLOOKUP(B12,Instruções!$F$6:$J$10,4,0)&"_as_is, "&VLOOKUP(B12,Instruções!$F$6:$J$10,5,0)&" as "&VLOOKUP(B12,Instruções!$F$6:$J$10,5,0)&"_as_is,"&E12&" as "&F12&" FROM "&C12&" WHERE "&Instruções!$D$11&") A ") -> (SELECT entty_id as entty_id_as_is, cntry as cntry_as_is FROM cd_loan_tapes_bce.lt003_entity WHERE ref_date='2025-06-30' AND nome_perimetro= 'Individual IDComb' AND segmento= 'ESTR' AND ambito= 'PM' AND entidade='00100' AND cod_visao = 1) A | I12: =IF(VLOOKUP(B12,Instruções!$F$6:$J$10,5,0)="", "(SELECT "&VLOOKUP(B12,Instruções!$F$6:$J$10,4,0)&" as "&VLOOKUP(B12,Instruções!$F$6:$J$10,4,0)&"_to_be, "&E12&" as "&G12&" FROM "&D12&" WHERE "&Instruções!$D$11&") B ", "(SELECT "&VLOOKUP(B12,Instruções!$F$6:$J$10,4,0)&" as "&VLOOKUP(B12,Instruções!$F$6:$J$10,4,0)&"_to_be, "&VLOOKUP(B12,Instruções!$F$6:$J$10,5,0)&" as "&VLOOKUP(B12,Instruções!$F$6:$J$10,5,0)&"_to_be,"&E12&" as "&G12&" FROM "&D12&" WHERE "&Instruções!$D$11&") B ") -> (SELECT entty_id as entty_id_to_be, cntry as cntry_to_be FROM bu_loantape_work.lt003_entity WHERE ref_date='2025-06-30' AND nome_perimetro= 'Individual IDComb' AND segmento= 'ESTR' AND ambito= 'PM' AND entidade='00100' AND cod_visao = 1) B | J12: =IF(VLOOKUP(B12,Instruções!$F$6:$J$10,5,0)="", "ON "&VLOOKUP(B12,Instruções!$F$6:$J$10,4,0)&"_as_is = "&VLOOKUP(B12,Instruções!$F$6:$J$10,4,0)&"_to_be ", "ON "&VLOOKUP(B12,Instruções!$F$6:$J$10,4,0)&"_as_is = "&VLOOKUP(B12,Instruções!$F$6:$J$10,4,0)&"_to_be AND "&VLOOKUP(B12,Instruções!$F$6:$J$10,5,0)&"_as_is = "&VLOOKUP(B12,Instruções!$F$6:$J$10,5,0)&"_to_be ") -> ON entty_id_as_is = entty_id_to_be | K12: ="WHERE coalesce(cast("&F12&" as string), '') <> coalesce(cast("&G12&" as string), '') " -> WHERE coalesce(cast(cntry_as_is as string), '') <> coalesce(cast(cntry_to_be as string), '') | L12: ="SELECT count(*) AS NUM_REG_DIF FROM "&H12&" Inner join "&I12&J12&K12 -> SELECT count(*) AS NUM_REG_DIF FROM (SELECT entty_id as entty_id_as_is, cntry as cntry_as_is FROM cd_loan_tapes_bce.lt003_entity WHERE ref_date='2025-06-30' AND nome_perimetro= 'Individual IDComb' AND segmento= 'ESTR' AND ambito= 'PM' AND entidade='00100' AND cod_visao = 1) A Inner join (SELECT entty_id as entty_id_to_be, cntry as cntry_to_be FROM bu_loantape_work.lt003_entity WHERE ref_date='2025-06-30' AND nome_perimetro= 'Individual IDComb' AND segmento= 'ESTR' AND ambito= 'PM' AND entidade='00100' AND cod_visao = 1) B ON entty_id_as_is = entty_id_to_be WHERE coalesce(cast(cntry_as_is as string), '') <> coalesce(cast(cntry_to_be as string), '') | M12: Validação de campos | N12: ="SELECT 'Validação de campos' as tipologia_teste, '"&VLOOKUP(B12,Instruções!$F$6:$J$10,3,0)&"' AS TABELA, '"&E12&"' AS CAMPO, '"&Instruções!$D$7&"' as ref_date, coalesce(NUM_REG_DIF, 0) AS NUM_REG_DIF FROM ("&L12&") A " -> SELECT 'Validação de campos' as tipologia_teste, 'lt003_entity' AS TABELA, 'cntry' AS CAMPO, '2025-06-30' as ref_date, coalesce(NUM_REG_DIF, 0) AS NUM_REG_DIF FROM (SELECT count(*) AS NUM_REG_DIF FROM (SELECT entty_id as entty_id_as_is, cntry as cntry_as_is FROM cd_loan_tapes_bce.lt003_entity WHERE ref_date='2025-06-30' AND nome_perimetro= 'Individual IDComb' AND segmento= 'ESTR' AND ambito= 'PM' AND entidade='00100' AND cod_visao = 1) A Inner join (SELECT entty_id as entty_id_to_be, cntry as cntry_to_be FROM bu_loantape_work.lt003_entity WHERE ref_date='2025-06-30' AND nome_perimetro= 'Individual IDComb' AND segmento= 'ESTR' AND ambito= 'PM' AND entidade='00100' AND cod_visao = 1) B ON entty_id_as_is = entty_id_to_be WHERE coalesce(cast(cntry_as_is as string), '') <> coalesce(cast(cntry_to_be as string), '') ) A | O12: =IF(O13="",N12,N12&$O$3) -> SELECT 'Validação de campos' as tipologia_teste, 'lt003_entity' AS TABELA, 'cntry' AS CAMPO, '2025-06-30' as ref_date, coalesce(NUM_REG_DIF, 0) AS NUM_REG_DIF FROM (SELECT count(*) AS NUM_REG_DIF FROM (SELECT entty_id as entty_id_as_is, cntry as cntry_as_is FROM cd_loan_tapes_bce.lt003_entity WHERE ref_date='2025-06-30' AND nome_perimetro= 'Individual IDComb' AND segmento= 'ESTR' AND ambito= 'PM' AND entidade='00100' AND cod_visao = 1) A Inner join (SELECT entty_id as entty_id_to_be, cntry as cntry_to_be FROM bu_loantape_work.lt003_entity WHERE ref_date='2025-06-30' AND nome_perimetro= 'Individual IDComb' AND segmento= 'ESTR' AND ambito= 'PM' AND entidade='00100' AND cod_visao = 1) B ON entty_id_as_is = entty_id_to_be WHERE coalesce(cast(cntry_as_is as string), '') <> coalesce(cast(cntry_to_be as string), '') ) A UNION ALL | P12: =P11+1 -> 9
B13: ENTTY | C13: =_xlfn.CONCAT(Instruções!$D$5,".",VLOOKUP(B13,Instruções!$F$5:$H$10,2,0)) -> cd_loan_tapes_bce.lt003_entity | D13: =_xlfn.CONCAT(Instruções!$D$6,".",VLOOKUP(B13,Instruções!$F$5:$H$10,3,0)) -> bu_loantape_work.lt003_entity | E13: cod_soc | F13: =E13&"_as_is" -> cod_soc_as_is | G13: =E13&"_to_be" -> cod_soc_to_be | H13: =IF(VLOOKUP(B13,Instruções!$F$6:$J$10,5,0)="", "(SELECT "&VLOOKUP(B13,Instruções!$F$6:$J$10,4,0)&" as "&VLOOKUP(B13,Instruções!$F$6:$J$10,4,0)&"_as_is, "&E13&" as "&F13&" FROM "&C13&" WHERE "&Instruções!$D$11&") A ", "(SELECT "&VLOOKUP(B13,Instruções!$F$6:$J$10,4,0)&" as "&VLOOKUP(B13,Instruções!$F$6:$J$10,4,0)&"_as_is, "&VLOOKUP(B13,Instruções!$F$6:$J$10,5,0)&" as "&VLOOKUP(B13,Instruções!$F$6:$J$10,5,0)&"_as_is,"&E13&" as "&F13&" FROM "&C13&" WHERE "&Instruções!$D$11&") A ") -> (SELECT entty_id as entty_id_as_is, cod_soc as cod_soc_as_is FROM cd_loan_tapes_bce.lt003_entity WHERE ref_date='2025-06-30' AND nome_perimetro= 'Individual IDComb' AND segmento= 'ESTR' AND ambito= 'PM' AND entidade='00100' AND cod_visao = 1) A | I13: =IF(VLOOKUP(B13,Instruções!$F$6:$J$10,5,0)="", "(SELECT "&VLOOKUP(B13,Instruções!$F$6:$J$10,4,0)&" as "&VLOOKUP(B13,Instruções!$F$6:$J$10,4,0)&"_to_be, "&E13&" as "&G13&" FROM "&D13&" WHERE "&Instruções!$D$11&") B ", "(SELECT "&VLOOKUP(B13,Instruções!$F$6:$J$10,4,0)&" as "&VLOOKUP(B13,Instruções!$F$6:$J$10,4,0)&"_to_be, "&VLOOKUP(B13,Instruções!$F$6:$J$10,5,0)&" as "&VLOOKUP(B13,Instruções!$F$6:$J$10,5,0)&"_to_be,"&E13&" as "&G13&" FROM "&D13&" WHERE "&Instruções!$D$11&") B ") -> (SELECT entty_id as entty_id_to_be, cod_soc as cod_soc_to_be FROM bu_loantape_work.lt003_entity WHERE ref_date='2025-06-30' AND nome_perimetro= 'Individual IDComb' AND segmento= 'ESTR' AND ambito= 'PM' AND entidade='00100' AND cod_visao = 1) B | J13: =IF(VLOOKUP(B13,Instruções!$F$6:$J$10,5,0)="", "ON "&VLOOKUP(B13,Instruções!$F$6:$J$10,4,0)&"_as_is = "&VLOOKUP(B13,Instruções!$F$6:$J$10,4,0)&"_to_be ", "ON "&VLOOKUP(B13,Instruções!$F$6:$J$10,4,0)&"_as_is = "&VLOOKUP(B13,Instruções!$F$6:$J$10,4,0)&"_to_be AND "&VLOOKUP(B13,Instruções!$F$6:$J$10,5,0)&"_as_is = "&VLOOKUP(B13,Instruções!$F$6:$J$10,5,0)&"_to_be ") -> ON entty_id_as_is = entty_id_to_be | K13: ="WHERE coalesce(cast("&F13&" as string), '') <> coalesce(cast("&G13&" as string), '') " -> WHERE coalesce(cast(cod_soc_as_is as string), '') <> coalesce(cast(cod_soc_to_be as string), '') | L13: ="SELECT count(*) AS NUM_REG_DIF FROM "&H13&" Inner join "&I13&J13&K13 -> SELECT count(*) AS NUM_REG_DIF FROM (SELECT entty_id as entty_id_as_is, cod_soc as cod_soc_as_is FROM cd_loan_tapes_bce.lt003_entity WHERE ref_date='2025-06-30' AND nome_perimetro= 'Individual IDComb' AND segmento= 'ESTR' AND ambito= 'PM' AND entidade='00100' AND cod_visao = 1) A Inner join (SELECT entty_id as entty_id_to_be, cod_soc as cod_soc_to_be FROM bu_loantape_work.lt003_entity WHERE ref_date='2025-06-30' AND nome_perimetro= 'Individual IDComb' AND segmento= 'ESTR' AND ambito= 'PM' AND entidade='00100' AND cod_visao = 1) B ON entty_id_as_is = entty_id_to_be WHERE coalesce(cast(cod_soc_as_is as string), '') <> coalesce(cast(cod_soc_to_be as string), '') | M13: Validação de campos | N13: ="SELECT 'Validação de campos' as tipologia_teste, '"&VLOOKUP(B13,Instruções!$F$6:$J$10,3,0)&"' AS TABELA, '"&E13&"' AS CAMPO, '"&Instruções!$D$7&"' as ref_date, coalesce(NUM_REG_DIF, 0) AS NUM_REG_DIF FROM ("&L13&") A " -> SELECT 'Validação de campos' as tipologia_teste, 'lt003_entity' AS TABELA, 'cod_soc' AS CAMPO, '2025-06-30' as ref_date, coalesce(NUM_REG_DIF, 0) AS NUM_REG_DIF FROM (SELECT count(*) AS NUM_REG_DIF FROM (SELECT entty_id as entty_id_as_is, cod_soc as cod_soc_as_is FROM cd_loan_tapes_bce.lt003_entity WHERE ref_date='2025-06-30' AND nome_perimetro= 'Individual IDComb' AND segmento= 'ESTR' AND ambito= 'PM' AND entidade='00100' AND cod_visao = 1) A Inner join (SELECT entty_id as entty_id_to_be, cod_soc as cod_soc_to_be FROM bu_loantape_work.lt003_entity WHERE ref_date='2025-06-30' AND nome_perimetro= 'Individual IDComb' AND segmento= 'ESTR' AND ambito= 'PM' AND entidade='00100' AND cod_visao = 1) B ON entty_id_as_is = entty_id_to_be WHERE coalesce(cast(cod_soc_as_is as string), '') <> coalesce(cast(cod_soc_to_be as string), '') ) A | O13: =IF(O14="",N13,N13&$O$3) -> SELECT 'Validação de campos' as tipologia_teste, 'lt003_entity' AS TABELA, 'cod_soc' AS CAMPO, '2025-06-30' as ref_date, coalesce(NUM_REG_DIF, 0) AS NUM_REG_DIF FROM (SELECT count(*) AS NUM_REG_DIF FROM (SELECT entty_id as entty_id_as_is, cod_soc as cod_soc_as_is FROM cd_loan_tapes_bce.lt003_entity WHERE ref_date='2025-06-30' AND nome_perimetro= 'Individual IDComb' AND segmento= 'ESTR' AND ambito= 'PM' AND entidade='00100' AND cod_visao = 1) A Inner join (SELECT entty_id as entty_id_to_be, cod_soc as cod_soc_to_be FROM bu_loantape_work.lt003_entity WHERE ref_date='2025-06-30' AND nome_perimetro= 'Individual IDComb' AND segmento= 'ESTR' AND ambito= 'PM' AND entidade='00100' AND cod_visao = 1) B ON entty_id_as_is = entty_id_to_be WHERE coalesce(cast(cod_soc_as_is as string), '') <> coalesce(cast(cod_soc_to_be as string), '') ) A UNION ALL | P13: =P12+1 -> 10
