Workbook

Sheet Filtros dos Segmentos
A1: • Exposures to legal persons: tipo_conta='A' e instrumento_financeiro='credito concedido e outros ativos financeiros' e contraparte <> ‘particulares’ e contraparte_i <> ‘particulares’ e carteira_contabilistica <> 'ativos nao correntes detidos para venda' • Exposures to natural persons: tipo_conta='A' e instrumento_financeiro='credito concedido e outros ativos financeiros' e contraparte = ‘particulares’ e contraparte_i = ‘particulares’ e carteira_contabilistica <> 'ativos nao correntes detidos para venda' • Off-balance sheet exposures: tipo_conta='EA' • Derivatives: instrumento_financeiro='derivados’ e tipo_conta in ('A', 'P') • Debt securities: tipo_conta='A' e instrumento_financeiro='instrumentos de divida' • Equity: tipo_conta='A' e instrumento_financeiro='instrumentos de capital' e carteira_contabilistica <> 'ativos nao correntes detidos para venda'

Sheet LEGAL PERSONS DATA SETS
A1: SRB DATA SET FOR EXPOSURES TO LEGAL PERSONS The AnaCredit database provides very detailed and individual information concerning exposures to legal persons. The SRB Valuation Data Set complements the AnaCredit database and provides data fields on segments, which allows mapping individual exposures with prudential reporting segments (FINREP and COREP), and credit risk data parameters aimed at supporting valuers. The SRB Valuation Data Set also provides data fields on risk parameters provided by banks’ internal risk models, which valuers are able to rely on in order to perform valuations on an aggregated basis, where necessary. Serão produzidos cinco ficheiros de report referentes a Legal Persons: ‣ SRB Instruments Data Set for exposures to legal persons (LEGALP_INSTRUMENTS); ‣ SRB Counterparties Data Set for exposures to legal persons (LEGALP_COUNTERPARTIES); ‣ SRB Protection received Data Set for exposures to legal persons (LEGALP_PROTECTIONS); ‣ SRB Instrument/Counterparty mapping Data Set for exposures to legal persons (LEGALP_INSTRUMENT_COUNTERPARTY); ‣ SRB Instrument/Protection mapping Data Set for exposures to legal persons (LEGALP_INSTRUMENT_PROTECTION);
A2: SRB DATA SET FOR EXPOSURES TO LEGAL PERSONS A base de dados AnaCredit disponibiliza informação muito detalhada e individualizada sobre exposições a pessoas coletivas. O dataset de avaliação do SRB complementa a base de dados AnaCredit e fornece campos de dados por segmentos, o que permite mapear exposições individuais com segmentos de reporte prudencial (FINREP e COREP) e parâmetros de dados de risco de crédito destinados a apoiar os avaliadores. O dataset de avaliação do CUR também fornece campos de dados sobre parâmetros de risco fornecidos pelos modelos de risco internos dos bancos, nos quais os avaliadores podem confiar para realizar avaliações numa base agregada, sempre que necessário. Serão produzidos três ficheiros de report referentes a Legal Persons: ‣ SRB Instruments Data Set for exposures to legal persons (VDS_OUT_LEGALP_INSTRUMENTS); ‣ SRB Counterparties Data Set for exposures to legal persons (VDS_OUT_LEGALP_COUNTERPARTIES); ‣ SRB Protection received Data Set for exposures to legal persons (VDS_OUT_LEGALP_PROTECTIONS).

Sheet LEGALP_INSTRUMENTS
A1: Instruções SRB | G1: Mapeamento efetuado pela Corporação e respetiva Descrição Loan Tape (LT) | K1: Análise IT
A2: ID | B2: Categoria | C2: Coluna | D2: Tipo de dados | E2: Descrição | G2: Mapeamentos Corporação (LT) | H2: Descrição (LT) | I2: Additional Guidance (LT) | K2: Novo campo na tabela LT002? | L2: Nome do campo no ficheiro | M2: Mapeamento | N2: Notas
A3: V_1 | B3: Identification information | C3: Instrument Identifier | D3: Alphanumeric | E3: An identifier applied to uniquely identify each instrument. Each instrument must have one instrument identifier | G3: INSTRUMENT-INSTRMNT_ID | H3: Instrument ID | I3: An identifier applied by the reporting agent to uniquely identify each instrument under a single contract. Each instrument must have one instrument identifier. This value will not change over time and cannot be used as the instrument identifier for any other instrument under the same contract. Supervised Insitutions are asked to furnish the INSTRMNT_ID with the exact same value as it is reported to AnaCredit (or any similar central credit register). If this is not available, the value shall be reported as it is internally used. If an instrument is not reported to AnaCredit but requested for the purposes of the on-site inspection please provide the bank-internally used value. | K3: NÃO | L3: instrument_id | M3: LT002_INSTRUMENT.INSTRMNT_ID
A7: V_2 | B7: Identification information | C7: Counterparty Identifier | D7: Alphanumeric | E7: Identifier applied to uniquely identify each counterparty. | G7: Not applicable: To be reported as "N/A". This information will be availabe in "01_04_leg_instr_count" table | H7: - | I7: - | K7: SIM | L7: counterparty_id | M7: Reportar sempre: 'N/A'
A8: V_3 | B8: Exposure class | C8: CRR Exposure class | D8: String | E8: The exposures classes for the calculation of risk-weighted assets (RWAs) for credit risks are as follows (not applicable when exposures are classified in the CRR trading book as defined in Article 4(1)(86) of Regulation (EU) No 575/2013): Where a bank uses the standardised approach: ‣ Central governments or central banks (SCENGOV) ‣ Regional governments or local authorities (SREGGOV) ‣ Public sector entities (SPUBSEC) ‣ Multilateral development banks (SDEVBAN) ‣ International organisation (SINTORG) ‣ Institutions (SINSTIT) ‣ Corporates (SCORPOR) ‣ Retail (SRETAIL) ‣ Secured by mortgages and immovable property (SSECMOR) ‣ Defaulted (SDEFAUL) ‣ High risk (SHIGHRI) ‣ Covered bonds (SCOVBON) ‣ Items representing securitisation positions ‣ Institutions and corporates with a short term credit assessment (SSHOTER) ‣ Collective investment undertakings (SCOLINV) ‣ Equity (SEQUITY) ‣ Other (SOTHERI) Where a bank uses the IRB approach: ‣ Central governments and central banks (ICENGOV) ‣ Institutions (IINSTIT) ‣ Corporates (ICORPOR) ‣ Retail (IRETAIL) ‣ Equity (IEQUITY) ‣ Items representing securitisation positions ‣ Other non-credit-obligation assets (IOTHERC) | G8: - | H8: - | I8: - | K8: SIM | L8: crr_exposure_class | M8: ‣ Utilizar o campo "segmento_corep_final" da tabela ct013_rwa_princ; Nota: Os códigos "segmento_corep_final" seguem sempre a mesma estrutura, começam com um caracter que identifica se é IRB (I_...) ou Standard (S_...) e de seguida um numérico (ex. I_3.1, I_5.1, S_1.0). ‣ Para o mesmo contrato este campo pode retornar vários códigos "segmento_corep_final" distintos, de seguida estão os passos que permitem resolver esta ambiguidade: 1. Deve seguir a lógica do campo RWA_MTHD, de momento a lógica é, se existir IRB e Standard então trazer informação relativa a IRB; 2. Se mesmo aplicando o passo 1 ainda existirem vários códigos "segmento_corep_final" distintos (vários códigos IRB ou vários códigos Standard) então: recuperar o código "segmento_corep_final" com o menor numérico associado. ‣ Traduzir o campo "segmento_corep_final" seguindo a parametrização apresentada na sheet 'LT831' filtrando por tabela_conceito = 'LT002_INSTRUMENT' e campo_conceito = 'CRR_EXPOSURE_CLASS' Exemplo: O contrato A tem associados os seguintes códigos "segmento_corep_final" distintos: I_3.1, I_5.1, S_1.0: 1. Remover o Standard: I_3.1, I_5.1; 2. Ficar com o menor numérico: I_3.1.
A11: V_4 | B11: Exposure class | C11: FINREP Exposure class | D11: String | E11: Classification of the facility (exposure class) as defined in ITS 680/2014 Annex V Instructions FINREP (Counterparty breakdown). Options: ‣ Central banks ‣ Central governments ‣ Credit institutions ‣ Other financial corporations ‣ Non-financial corporations ‣ Households | G11: - | H11: - | I11: - | K11: NÃO | L11: finrep_exposure_class | M11: LT002_INSTRUMENT.INTRNL_SGMNT ‣ Traduzir o campo "INTRNL_SGMNT" seguindo as parametrizações apresentadas nas sheets: ‣ LT829 - filtrando por campo_conceito = 'INTRNL_SGMNT' e regra_conversao = '1'; ‣ LT830 - filtrando por segmento = 'Exposures to legal persons' e campo_conceito = 'INTRNL_SGMNT'.
A18: V_5 | B18: Risk parameters | C18: Total Risk Exposure Amount | D18: Numeric (euro) | E18: The total risk exposure amount of the instrument, calculated according to Articles 92(3) and 92(4) of Regulation (EU) No 575/2013 (CRR), where applicable. | G18: INSTRUMENT-RWA | H18: RWA | I18: RWA according to Regulation (EU) No 575/2013. | K18: NÃO | L18: total_risk_exposure_amount | M18: LT002_INSTRUMENT.RWA
A21: V_6 | B21: Risk parameters | C21: CRR Loss given default | D21: Numeric. Basis points | E21: Current level of the ‘Loss given default’ of the loan, determined in accordance with Articles 161, 164, 179 and 181 of Regulation (EU) No 575/2013. | G21: INSTRUMENT-LGD | H21: Regulatory LGD | I21: If differences between regulatory and internal LGD exist, use regulatory LGD (according to Regulation (EU) No 575/2013). In particular, in IRB-F use regulatory LGD values. | K21: NÃO | L21: crr_loss_given_default | M21: LT002_INSTRUMENT.LGD
A25: V_7 | B25: Risk parameters | C25: IFRS 9 Loss given default | D25: Numeric. Basis points | E25: Current level of the ‘Loss given default’ of the loan determined for accounting purposes. | G25: INSTRUMENT-IFRS9_LGD | H25: IFRS 9 accounting LGD | I25: IFRS 9 accounting Loss Given Default as at reference date for defaulted and non-defaulted exposures. In case the bank models time-depended LGD variable for non-defaulted exposures then 12-month LGD as at reference date regardless the classification as Stage 1 or 2 | K25: NÃO | L25: ifrs9_loss_given_default | M25: LT002_INSTRUMENT.IFRS9_LGD

Sheet LEGALP_COUNTERPARTIES
A1: Instruções SRB | G1: Mapeamento efetuado pela Corporação e respetiva Descrição Loan Tape (LT) | K1: Análise IT
A2: ID | B2: Categoria | C2: Coluna | D2: Tipo de dados | E2: Descrição | G2: Mapeamentos Corporação (LT) | H2: Descrição (LT) | I2: Additional Guidance (LT) | K2: Novo campo na tabela LT003? | L2: Nome do campo no ficheiro | M2: Mapeamento | N2: Notas
A3: V_2 | B3: Identification information | C3: Counterparty Identifier | D3: Alphanumeric | E3: Identifier applied to uniquely identify each counterparty. | G3: ENTITY-ENTTY_ID | H3: Entity ID | I3: An identifier applied by the reporting agent to uniquely identify each counterparty. Each counterparty has a unique and exclusive counterparty identifier. This means that this value will not change over time and can never be used as the counterparty identifier for any other counterparty. | K3: NÃO | L3: counterparty_id | M3: LT003_ENTITY.ENTTY_ID
A4: V_8 | B4: Risk parameters | C4: Current Internal Credit Rating/Scoring | D4: Numeric / alphanumeric | E4: Internal credit rating/scoring issued to the counterparty. | G4: ENTITY-INTRNL_RTNG | H4: Internal rating at reference date | I4: Internal rating at the reference date according to Regulation (EU) No 575/2013. Please also add in sheet "Code List" the list of values used, i.e. bank-internal masterscale. | K4: NÃO | L4: internal_credit_rating | M4: LT003_ENTITY.INTRNL_RTNG
A5: V_9 | B5: Risk parameters | C5: External Credit rating | D5: Alphanumeric | E5: External credit rating issued to the counterparty at cut-off date. In case several ratings are assigned, the approach described in Art. 138 of the CRR applies. | G5: ENTITY-EXTRNL_RTNG | H5: External rating | I5: External rating at the reference date. | K5: NÃO | L5: external_credit_rating | M5: LT003_ENTITY.EXTRNL_RTNG
A6: V_10 | B6: Risk parameters | C6: IFRS 9 Probability of default/impairment | D6: Numeric. Basis points | E6: The probability of default/impairment is calculated in accordance with the requirements specific to probability of default (PD) estimation as laid down in the accounting framework. If PDs are produced at the instrument level only, the counterparty’s PD is to be reported as the exposure-weighted average PD across the PDs of all instruments of the counterparty. If, for a given counterparty, PDs are estimated for both the counterparty and (some of) the products of the counterparty, it is the counterparty’s PD which is to be reported. No documento "Feedback Statement in response to the consultation on the SRB valuation data set" é referida a seguinte nota sobre este campo: "‘Data Point V_10’, entitled ‘IFRS 9 Probability of default’, refers to PDs used for accounting purposes, being a 12-month PD for stage 1 exposures and a lifetime PD for stage 2 and 3 exposures as per the accounting framework." | G6: ENTITY-PD_IFRS9_12M_RD | H6: 12-month PD at reporting date according to IFRS 9 | I6: 12-month PD at reference date which is used by the bank for computation of stage 1 ECL or for SICR assessment if bank use 12 month proxy for staging. If the PD is calculated on instruments level please provide an EAD weighted average. | K6: SIM | L6: ifrs9_prob_default_impairment | M6: Necessário validar a necessidade de criar um novo campo ("PD misto" ) na LT002_INSTRUMENT dado que se solicita um "misto" entre a PD 12m (PD12M_IFRS9) e a PD lifetime (PD_LT_IFRS9), campos já existentes nessa tabela. A lógica a validar será: -Se stage 1: Se loss_type LIKE 'Lifetime expected credit losses%' selecionar PD_LT_IFRS9 da tabela BU_IFRS9.IFRS9_OUT_EXPECTED_LOSS_REPORTING, caso contrário selecionar PD12M_IFRS9 da tabela BU_IFRS9.IFRS9_OUT_EXPECTED_LOSS_REPORTING -Se stage 2: selecionar PD_LT_IFRS9 da tabela BU_IFRS9.IFRS9_OUT_EXPECTED_LOSS_REPORTING -Se stage 3: forçar 1 Sugere-se criar o campo na LT002_INSTRUMENT e não na LT003_ENTITY porque após consultar a a LT003_ENTITY verificou-se que existia o campo PD_IFRS9_12M_RD para o qual é usada a LT005_INSTR_ENT para identificar todos os contratos onde o cliente é o 1º Titular, de seguida para cada cliente aplica-se uma média ponderada da PD em relação ao EAD (porque cada cliente pode ter vários contratos). Assim sugere-se replicar esta lógica para o novo campo "PD misto" adicionado na LT002_INSTRUMENT de forma a poder ser criado também um novo campo "PD misto" na LT003_ENTITY. Lógica proposta para a criação do novo campo na LT002: CASE WHEN IMPRMNT_STTS_INSTRMNT = '23' --(Stage 1) THEN IF( loss_type LIKE 'Lifetime expected credit losses%', PD_LT_IFRS9, PD12M_IFRS9) WHEN IMPRMNT_STTS_INSTRMNT = '24' --(Stage 2) THEN PD_LT_IFRS9 WHEN IMPRMNT_STTS_INSTRMNT = '25' --(Stage 3) THEN 1 ELSE 'N/A' END as PD_IFRS9_12M_LFTM_RD WHERE IMCATF046_FLAG_FECHO.CMES = REF_DATE Lógica proposta para a criação do novo campo na LT003: 1) Identificar contratos onde o cliente é o 1º Titular: LT005_INSTR_ENT WHERE CRELACAO_CL_CNT = '1' AND CSEQUENCIA_REL = '00001' 2) Aplicar o seguinte cáclulo por entidade: CASE WHEN SUM(IFRS9_EAD)<> 0 THEN SUM(PD_IFRS9_12M_LFTM_RD * IFRS9_EAD) / SUM(IFRS9_EAD) ELSE AVG(PD_IFRS9_12M_LFTM_RD) END as ifrs9_prob_default_impairment | N6: Em análise
A17: V_11 | B17: Risk parameters | C17: Probability of default (others) | D17: Numeric. Basis points | E17: Applicable only to institutions not using CRR IRB models. These institutions should maintain records of probabilities of default or scores provided by scoring/rating models. In the case of PDs produced at the instrument level only, the counterparty’s PD is to be reported as the exposure-weighted average PD across the PDs of all instruments of the counterparty. If, for a given counterparty, PDs are estimated for both the counterparty and (some of) the products of the counterparty, it is the counterparty’s PD which is to be reported. | G17: - | H17: - | I17: - | K17: SIM | L17: probability_default_others | M17: Reportar sempre: 11111111111

Sheet LEGALP_PROTECTIONS
A1: Instruções SRB | G1: Mapeamento efetuado pela Corporação e respetiva Descrição Loan Tape (LT) | K1: Análise IT
A2: ID | B2: Categoria | C2: Coluna | D2: Tipo de dados | E2: Descrição | G2: Mapeamentos Corporação (LT) | H2: Descrição (LT) | I2: Additional Guidance (LT) | K2: Novo campo na tabela LT004? | L2: Nome do campo no ficheiro | M2: Mapeamento | N2: Notas
A3: V_12 | B3: Identification information | C3: Protection identifier | D3: Alphanumeric | E3: An identifier applied to uniquely identify each protection/collateral used to secure the instrument. | G3: PROTECTION-PRTCTN_ID | H3: Protection ID | I3: An identifier applied by the reporting agent to uniquely identify each protection used to secure the instrument. Each protection must have one protection identifier. This value will not change over time and cannot be used as the protection identifier for any other protection. | K3: NÃO | L3: protection_id | M3: LT004_PROTECTION.PRTCTN_ID
A7: V_1 | B7: Identification information | C7: Instrument Identifier | D7: Alphanumeric | E7: An identifier applied to uniquely identify each instrument. Each instrument must have one instrument identifier. | G7: Not applicable: To be reported as "N/A". This information will be availabe in "01_05_leg_instr_prot" table | H7: - | I7: - | K7: SIM | L7: instrument_id | M7: Reportar sempre: 'N/A'
A11: V_187 | B11: Identification information | C11: Type of collateral | D11: String | E11: The AnaCredit item “type of protection” (Section 9.4.3. of the Anacredit Reporting Manual part II - Dataset and data attributes) provides a breakdown of collateral eligible in accordance with the CRR. The proposed breakdown adds several categories. Options: ‣ Gold ‣ Currency and deposits ‣ Securities ‣ Loans ‣ Equity and investment fund shares or units ‣ Credit derivatives ‣ Financial guarantees other than credit derivatives ‣ Trade receivables ‣ Life insurance policies pledged ‣ Residential real estate collateral ‣ Offices and commercial premises ‣ Commercial real estate collateral ‣ Other physical collateral ‣ Other protection ‣ Hotels & entertainment ‣ Infrastructure projects ‣ Factories – warehouses ‣ Equipment & machinery ‣ Automotive ‣ Aircraft ‣ Shipping | G11: PROTECTION-TYP_PRTCTN | H11: Protection type | I11: Type of protection received, irrespective of its eligibility for credit risk mitigation. | K11: NÃO | L11: type_collateral | M11: LT004_PROTECTION.TYP_PRTCTN ‣ Traduzir o campo "TYP_PRTCTN" seguindo as parametrizações apresentadas nas sheets: ‣ LT829 - filtrando por campo_conceito = 'TYP_PRTCTN' e regra_conversao = '1'; ‣ LT830 - filtrando por segmento = 'Exposures to legal persons' e campo_conceito = 'TYP_PRTCTN'.
A14: V_14 | B14: Size collateral | C14: Building Area (M2) | D14: Numeric | E14: Building area of the building in square metres. Only applicable to Residential real estate collateral, Offices and commercial premises, Commercial real estate collateral, Hotels & entertainment, Factories – warehouses. | G14: - | H14: - | I14: - | K14: SIM gross_area | L14: building_area_m2 | M14: Campo "narbrut" da tabela cd_garantias.gt009_bens_imov
A15: V_15 | B15: Size collateral | C15: Land Area (M2) | D15: Numeric | E15: Land area of the property in square metres, including any land surrounding the building(s) on the property that is part of the property. | G15: - | H15: - | I15: - | K15: SIM land_area | L15: land_area_m2 | M15: Campo "narterr" da tabela cd_garantias.gt009_bens_imov
A16: V_16 | B16: Location | C16: Property postcode | D16: Numeric | E16: Postcode where the property is located. Only applicable to Residential real estate collateral, Offices and commercial premises, Commercial real estate collateral, Hotels & entertainment, Factories – warehouses. | G16: PROTECTION-RL_ESTT_PST_CD | H16: Post code / ZIP | I16: Post code / ZIP. | K16: NÃO | L16: property_postcode | M16: LT004_PROTECTION.RL_ESTT_PST_CD
A17: V_17 | B17: Lien | C17: Lien position | D17: Numeric | E17: The highest ranking position(s) in relation to the collateral held by the counterparty to secure the facility. If the facility has several liens on one collateral, the highest claim is reported in this data field. | G17: - | H17: - | I17: - | K17: SIM | L17: lien_position | M17: Reportar sempre: 1
A18: V_18 | B18: Collateral characteristics | C18: Detailed type of Shipping collateral | D18: String | E18: Detailed type of collateral received. Applicable only to shipping portfolios. Options: ‣ Bulker (1) ‣ Container (2) ‣ Crude Oil Tanker (3) ‣ Product Tanker (4) ‣ Chemical Tanker (5) ‣ Cruise Ship (6) ‣ Ferry (7) ‣ LPG Carrier (8) ‣ Offshore (9) ‣ Other (10) | G18: - | H18: - | I18: - | K18: SIM | L18: det_type_ship_collateral | M18: Conceito a revisitar no futuro | N18: Em análise

Sheet LEGALP_INSTRUMENT_COUNTERPARTY
A1: Instruções SRB | G1: Mapeamento efetuado pela Corporação e respetiva Descrição Loan Tape (LT) | K1: Análise IT
A2: ID | B2: Categoria | C2: Coluna | D2: Tipo de dados | E2: Descrição | G2: Mapeamentos Corporação (LT) | H2: Descrição (LT) | I2: Additional Guidance (LT) | K2: Novo campo na tabela LT005? | L2: Nome do campo no ficheiro | M2: Mapeamento | N2: Notas
A3: V_1 | B3: Identification information | C3: Instrument Identifier | D3: Alphanumeric | E3: An identifier applied to uniquely identify each instrument. Each instrument must have one instrument identifier | G3: INSTR_ENTITY-INSTRMNT_ID | H3: Instrument ID | I3: An identifier applied by the reporting agent to uniquely identify each instrument under a single contract. Each instrument must have one instrument identifier. This value will not change over time and cannot be used as the instrument identifier for any other instrument under the same contract. Supervised Insitutions are asked to furnish the INSTRMNT_ID with the exact same value as it is reported to AnaCredit (or any similar central credit register). If this is not available, the value shall be reported as it is internally used. If an instrument is not reported to AnaCredit but requested for the purposes of the on-site inspection please provide the bank-internally used value. Foreign Key from INSTRUMENT table. | K3: NÃO | L3: instrument_id | M3: LT005_INSTR_ENT.INSTRMNT_ID
A7: V_2 | B7: Identification information | C7: Counterparty Identifier | D7: Alphanumeric | E7: Identifier applied to uniquely identify each counterparty. | G7: INSTR_ENTITY-ENTTY_ID | H7: Entity ID | I7: An identifier applied by the reporting agent to uniquely identify each counterparty. Each counterparty has a unique and exclusive counterparty identifier. This means that this value will not change over time and can never be used as the counterparty identifier for any other counterparty. Foreign key from ENTITY table. | K7: NÃO | L7: counterparty_id | M7: LT005_INSTR_ENT.ENTTY_ID

Sheet LEGALP_INSTRUMENT_PROTECTION
A1: Instruções SRB | G1: Mapeamento efetuado pela Corporação e respetiva Descrição Loan Tape (LT) | K1: Análise IT
A2: ID | B2: Categoria | C2: Coluna | D2: Tipo de dados | E2: Descrição | G2: Mapeamentos Corporação (LT) | H2: Descrição (LT) | I2: Additional Guidance (LT) | K2: Novo campo na tabela LT006? | L2: Nome do campo no ficheiro | M2: Mapeamento | N2: Notas
A3: V_1 | B3: Identification information | C3: Instrument Identifier | D3: Alphanumeric | E3: An identifier applied to uniquely identify each instrument. Each instrument must have one instrument identifier | G3: INSTR_PROTECTION-INSTRMNT_ID | H3: Instrument ID | I3: An identifier applied by the reporting agent to uniquely identify each instrument under a single contract. Each instrument must have one instrument identifier. This value will not change over time and cannot be used as the instrument identifier for any other instrument under the same contract. Supervised Insitutions are asked to furnish the INSTRMNT_ID with the exact same value as it is reported to AnaCredit (or any similar central credit register). If this is not available, the value shall be reported as it is internally used. If an instrument is not reported to AnaCredit but requested for the purposes of the on-site inspection please provide the bank-internally used value. Foreign Key from INSTRUMENT table. | K3: NÃO | L3: instrument_id | M3: LT006_INSTR_PROT.INSTRMNT_ID
A7: V_12 | B7: Identification information | C7: Protection identifier | D7: Alphanumeric | E7: An identifier applied to uniquely identify each protection/collateral used to secure the instrument. | G7: INSTR_PROTECTION-PRTCTN_ID | H7: Protection ID | I7: An identifier applied by the reporting agent to uniquely identify each protection used to secure the instrument. Each protection must have one protection identifier. This value will not change over time and cannot be used as the protection identifier for any other protection. Foreign Key from PROTECTION table. | K7: NÃO | L7: protection_id | M7: LT006_INSTR_PROT.PRTCTN_ID

Sheet NATURAL PERSONS DATA SETS
A1: SRB DATA SET FOR EXPOSURES TO NATURAL PERSONS The following data set covers exposures to natural persons, which, in many cases, represent the main type of exposures on banks’ balance sheets (e.g. retail institutions or mortgage institutions). Such exposures might comprise lending products such as mortgages, consumer loans, credit cards, etc. Valuations of retail portfolios are usually made with lesser granularity than valuations of corporate portfolios. However, in specific circumstances (e.g. high default rates in mortgage portfolios) a collective assessment might not suffice and the valuer might rely on a more granular approach for qualitatively and quantitatively assessing the level of economic impairment of exposures to natural persons that would typically be impaired on a collective basis under International Financial Reporting Standard (IFRS 9). In this case, the valuer would require a more granular data set to perform valuations. To avoid any duplication of data points or definitions, the data set for exposures to natural persons is based on the AnaCredit data points and definitions for legal persons. However, institutions can leverage on the definitions, data points and reporting thresholds of local standards or legislation, provided those definitions and data points are, in the IRT’s view, equivalent to those envisaged for AnaCredit. Serão produzidos cinco ficheiros de report referentes a Natural Persons: ‣ SRB Instruments Data Set for exposures to natural persons (NATURALP_INSTRUMENTS); ‣ SRB Counterparties Data Set for exposures to natural persons (NATURALP_COUNTERPARTIES); ‣ SRB Protection received Data Set for exposures to natural persons (NATURALP_PROTECTIONS); ‣ SRB Instrument/Counterparty mapping Data Set for exposures to natural persons (NATURALP_INSTRUMENT_COUNTERPARTY); ‣ SRB Instrument/Protection mapping Data Set for exposures to natural persons (NATURALP_INSTRUMENT_PROTECTION);
A2: SRB DATA SET FOR EXPOSURES TO NATURAL PERSONS O seguinte data set abrange exposições a pessoas singulares, que, em muitos casos, representam o principal tipo de exposições nos balanços dos bancos (por exemplo, instituições de retalho ou instituições hipotecárias). Essas exposições podem incluir produtos de empréstimo, como hipotecas, empréstimos pessoais, cartões de crédito, etc. As avaliações de carteiras de retalho são geralmente feitas com menos granularidade do que as avaliações de carteiras corporativas. No entanto, em circunstâncias específicas (por exemplo, elevadas taxas de incumprimento em carteiras hipotecárias), uma avaliação colectiva pode não ser suficiente e o avaliador pode basear-se numa abordagem mais granular para avaliar qualitativa e quantitativamente o nível de imparidade económica das exposições a pessoas singulares que normalmente seriam prejudicadas numa base colectiva ao abrigo da International Financial Reporting Standard (IFRS 9). Neste caso, o avaliador necessitaria de um conjunto de dados mais granular para realizar avaliações. Para evitar qualquer duplicação de pontos de dados ou definições, o data set para exposições a pessoas singulares baseia-se nos pontos de dados e definições da AnaCredit para pessoas coletivas. No entanto, as instituições podem aproveitar as definições, os pontos de dados e os limites de reporte das normas ou legislação local, desde que essas definições e pontos de dados sejam, na opinião do IRT, equivalentes aos previstos para o AnaCredit. Serão produzidos cinco ficheiros de report referentes a Natural Persons: ‣ SRB Instruments Data Set for exposures to natural persons (VDS_OUT_NATURALP_INSTRUMENTS); ‣ SRB Counterparties Data Set for exposures to natural persons (VDS_OUT_NATURALP_COUNTERPARTIES); ‣ SRB Protection received Data Set for exposures to natural persons (VDS_OUT_NATURALP_PROTECTIONS).

Sheet NATURALP_INSTRUMENTS
A1: Instruções SRB | G1: Mapeamento efetuado pela Corporação e respetiva Descrição Loan Tape (LT) | K1: Análise IT
A2: ID | B2: Categoria | C2: Coluna | D2: Tipo de dados | E2: Descrição | G2: Mapeamentos Corporação (LT) | H2: Descrição (LT) | I2: Additional Guidance (LT) | K2: Novo campo na tabela LT002? | L2: Nome do campo no ficheiro | M2: Mapeamento | N2: Notas
A3: V_1 | B3: Identification information | C3: Instrument Identifier | D3: Alphanumeric | E3: Identifier applied to uniquely identify each instrument. Each instrument must have one instrument identifier. | G3: INSTRUMENT-INSTRMNT_ID | H3: Instrument ID | I3: An identifier applied by the reporting agent to uniquely identify each instrument under a single contract. Each instrument must have one instrument identifier. This value will not change over time and cannot be used as the instrument identifier for any other instrument under the same contract. Supervised Insitutions are asked to furnish the INSTRMNT_ID with the exact same value as it is reported to AnaCredit (or any similar central credit register). If this is not available, the value shall be reported as it is internally used. If an instrument is not reported to AnaCredit but requested for the purposes of the on-site inspection please provide the bank-internally used value. | K3: NÃO | L3: instrument_id | M3: LT002_INSTRUMENT.INSTRMNT_ID
A7: V_2 | B7: Identification information | C7: Counterparty Identifier | D7: Alphanumeric | E7: Identifier applied to uniquely identify each counterparty. | G7: Not applicable: To be reported as "N/A". This information will be availabe in "02_04_nat_instr_count" table | H7: - | I7: - | K7: SIM | L7: counterparty_id | M7: Reportar sempre: 'N/A'
A8: V_139 | B8: Identification information | C8: Reporting data identifier | D8: Alphanumeric | E8: The counterparty identifier of the reporting agent which reports the data. | G8: INSTRUMENT-COD_SOC | H8: Entity code of the informing society. | I8: Cargabal code or internal identifier of the informing society. | K8: NÃO | L8: reporting_data_id | M8: LT002_INSTRUMENT.COD_SOC
A9: V_140 | B9: Identification information | C9: Observed agent identifier | D9: Alphanumeric | E9: The counterparty identifier of the observed agent (i.e. an institutional unit of the reporting agent) whose data are reported by the reporting agent. | G9: INSTRUMENT-OBSRVD_AGNT_ID | H9: Observed agent identifier | I9: Counterparty identifier for the observed agent. If there are several observed agents to be reported please separate by comma (,). | K9: NÃO | L9: observed_agent_id | M9: LT002_INSTRUMENT.OBSRVD_AGNT_ID
A10: V_141 | B10: Identification information | C10: Contract identifier | D10: Alphanumeric | E10: An identifier applied by the reporting agent to uniquely identify each contract. The contract identifier refers to the credit agreement between two or more parties under which the instrument is created. | G10: INSTRUMENT-CNTRCT_ID | H10: Contract ID | I10: An identifier applied by the reporting agent to uniquely identify each contract. Each contract must have one contract identifier. This value will not change over time and cannot be used as the contract identifier for any other contract. | K10: NÃO | L10: contract_id | M10: LT002_INSTRUMENT.CNTRCT_ID
A14: V_3 | B14: Exposure class | C14: CRR Exposure class | D14: String | E14: The exposures classes for the calculation of RWAs for credit risks are as follows (not applicable when exposures are classified in the CRR trading book as defined in Article 4(1)(86) of Regulation (EU) No 575/2013): Where a bank uses the standardised approach: ‣ Central governments or central banks (SCENGOV) ‣ Regional governments or local authorities (SREGGOV) ‣ Public sector entities (SPUBSEC) ‣ Multilateral development banks (SDEVBAN) ‣ International organisation (SINTORG) ‣ Institutions (SINSTIT) ‣ Corporates (SCORPOR) ‣ Retail (SRETAIL) ‣ Secured by mortgages and immovable property (SSECMOR) ‣ Defaulted (SDEFAUL) ‣ High risk (SHIGHRI) ‣ Covered bonds (SCOVBON) ‣ Items representing securitisation positions ‣ Institutions and corporates with a short term credit assessment (SSHOTER) ‣ Collective investment undertakings (SCOLINV) ‣ Equity (SEQUITY) ‣ Other (SOTHERI) Where a bank uses the IRB approach: ‣ Central governments and central banks (ICENGOV) ‣ Institutions (IINSTIT) ‣ Corporates (ICORPOR) ‣ Retail (IRETAIL) ‣ Equity (IEQUITY) ‣ Items representing securitisation positions ‣ Other non-credit-obligation assets (IOTHERC) | G14: - | H14: - | I14: - | K14: SIM | L14: crr_exposure_class | M14: ‣ Utilizar o campo "segmento_corep_final" da tabela ct013_rwa_princ; Nota: Os códigos "segmento_corep_final" seguem sempre a mesma estrutura, começam com um caracter que identifica se é IRB (I_...) ou Standard (S_...) e de seguida um numérico (ex. I_3.1, I_5.1, S_1.0). ‣ Para o mesmo contrato este campo pode retornar vários códigos "segmento_corep_final" distintos, de seguida estão os passos que permitem resolver esta ambiguidade: 1. Deve seguir a lógica do campo RWA_MTHD, de momento a lógica é, se existir IRB e Standard então trazer informação relativa a IRB; 2. Se mesmo aplicando o passo 1 ainda existirem vários códigos "segmento_corep_final" distintos (vários códigos IRB ou vários códigos Standard) então: recuperar o código "segmento_corep_final" com o menor numérico associado. ‣ Traduzir o campo "segmento_corep_final" seguindo a parametrização apresentada na sheet 'LT831' filtrando por tabela_conceito = 'LT002_INSTRUMENT' e campo_conceito = 'CRR_EXPOSURE_CLASS' Exemplo: O contrato A tem associados os seguintes códigos "segmento_corep_final" distintos: I_3.1, I_5.1, S_1.0: 1. Remover o Standard: I_3.1, I_5.1; 2. Ficar com o menor numérico: I_3.1.
A17: V_4 | B17: Exposure class | C17: FINREP Exposure class | D17: String | E17: Classification of the facility (exposure class) as defined in ITS 680/2014 Annex V Instructions FINREP (Counterparty breakdown). Opções: ‣ Central banks ‣ Central governments ‣ Credit institutions ‣ Other financial corporations ‣ Non-financial corporations ‣ Households | G17: - | H17: - | I17: - | K17: NÃO | L17: finrep_exposure_class | M17: LT002_INSTRUMENT.INTRNL_SGMNT ‣ Traduzir o campo "INTRNL_SGMNT" seguindo as parametrizações apresentadas nas sheets: ‣ LT829 - filtrando por campo_conceito = 'INTRNL_SGMNT' e regra_conversao = '1'; ‣ LT830 - filtrando por segmento = 'Exposures to natural persons' e campo_conceito = 'INTRNL_SGMNT'.
A24: V_5 | B24: Risk parameters | C24: Total Risk Exposure Amount | D24: Numeric (euro) | E24: The total risk exposure amount of the instrument, calculated according to Articles 92(3) and 92(4) of Regulation (EU) No 575/2013 (CRR), where applicable. | G24: INSTRUMENT-RWA | H24: RWA | I24: RWA according to Regulation (EU) No 575/2013. | K24: NÃO | L24: total_risk_exposure_amount | M24: LT002_INSTRUMENT.RWA
A27: V_6 | B27: Risk parameters | C27: CRR Loss given default | D27: Numeric. Basis points | E27: Current level of the ‘Loss given default’ of the loan, determined in accordance with Articles 161, 164, 179 and 181 of Regulation (EU) No 575/2013. | G27: INSTRUMENT-LGD | H27: Regulatory LGD | I27: If differences between regulatory and internal LGD exist, use regulatory LGD (according to Regulation (EU) No 575/2013). In particular, in IRB-F use regulatory LGD values. | K27: NÃO | L27: crr_loss_given_default | M27: LT002_INSTRUMENT.LGD
A31: V_7 | B31: Risk parameters | C31: IFRS 9 Loss given default | D31: Numeric. Basis points | E31: Current level of the ‘Loss given default’ of the loan determined for accounting purposes. | G31: INSTRUMENT-IFRS9_LGD | H31: IFRS 9 accounting LGD | I31: IFRS 9 accounting Loss Given Default as at reference date for defaulted and non-defaulted exposures. In case the bank models time-depended LGD variable for non-defaulted exposures then 12-month LGD as at reference date regardless the classification as Stage 1 or 2 | K31: NÃO | L31: ifrs9_loss_given_default | M31: LT002_INSTRUMENT.IFRS9_LGD
A34: V_35 | B34: Instruments characteristics | C34: Type of instrument | D34: String | E34: Classification of the instrument according to the type of contractual terms agreed between the parties. Opções: ‣ Overdraft ‣ Credit card debt ‣ Revolving credit other than overdrafts and credit card debt ‣ Credit lines other than revolving credit ‣ Financial lease ‣ Loan ‣ Other | G34: INSTRUMENT-TYP_INSTRMNT | H34: Type of instrument | I34: Classification of the instrument according to the type of contractual terms agreed between the parties. | K34: NÃO | L34: type_instrument | M34: LT002_INSTRUMENT.TYP_INSTRMNT ‣ Traduzir o campo "TYP_INSTRMNT" seguindo as parametrizações apresentadas nas sheets: ‣ LT829 - filtrando por campo_conceito = 'TYP_INSTRMNT' e regra_conversao = '1'; ‣ LT830 - filtrando por segmento = 'Exposures to natural persons' e campo_conceito = 'TYP_INSTRMNT'.
A37: V_142 | B37: Instruments characteristics | C37: Amortization type | D37: String | E37: Type of amortisation of the instrument including principal and interest at the reporting reference date. Opções: ‣ French ‣ German ‣ Fixed amortisation schedule ‣ Bullet ‣ Other | G37: INSTRUMENT-TYP_AMRTSTN | H37: Type of amortisation | I37: Type of amortisation of the instrument including principal and interest. | K37: NÃO | L37: amortization_type | M37: LT002_INSTRUMENT.TYP_AMRTSTN ‣ Traduzir o campo "TYP_AMRTSTN" seguindo as parametrizações apresentadas nas sheets: ‣ LT829 - filtrando por campo_conceito = 'TYP_AMRTSTN' e regra_conversao = '1'; ‣ LT830 - filtrando por segmento = 'Exposures to natural persons' e campo_conceito = 'TYP_AMRTSTN'.
... A43: V_145 | B43: Interest rate information | C43: End date of interest-only period | D43: DD/MM/AA | E43: The date on which the interest-only period ends. | G43: INSTRUMENT-DT_END_INTRST_ONLY | H43: End date of the interest-only period | I43: The date on which the interest-only period ends. Interest-only instruments are those for which, for a contractually set period, only the interest on the principal balance is paid, with the principal balance remaining unchanged. The scope of the field refers to any interest only period, either due to renegotiations or interest only agreements at loan inception. | K43: NÃO | L43: end_date_interest_only_period | M43: LT002_INSTRUMENT.DT_END_INTRST_ONLY
A44: V_146 | B44: Interest rate information | C44: Interest rate cap | D44: Numeric. Reported in basis points with the same convention as for the attribute “interest rate spread/margin”. | E44: The maximum interest rate per annum that can be charged on the outstanding nominal amount (or parts thereof). | G44: - | H44: - | I44: - | K44: SIM | L44: interest_rate_cap | M44: ‣ Necessário criar um novo campo no Loan Tapes que deverá ser alimentado pela tabela al029_cnt_core_m. No entanto de momento esta informação não existe na tabela al029_cnt_core_m, está em curso a análise de um desenvolvimento no ambiente ALM que prevê adicionar 8 campos à tabela al029_cnt_core_m: cap do indexante passivo, cap do all-in passivo (indexante+spread), floor do indexante passivo, floor do all-in passivo (indexante+spread), cap do indexante ativo, cap do all-in ativo(indexante+spread), floor do indexante ativo, floor do all-in ativo(indexante+spread). Este datapoint será alimentado por um destes novos campos. | N44: Em análise
A45: V_147 | B45: Interest rate information | C45: Interest rate floor | D45: Numeric. Reported in basis points with the same convention as for the attribute “interest rate spread/margin”. | E45: The minimum interest rate per annum that can be charged on the outstanding nominal amount (or parts thereof). | G45: - | H45: - | I45: - | K45: SIM | L45: interest_rate_floor | M45: ‣ Necessário criar um novo campo no Loan Tapes que deverá ser alimentado pela tabela al029_cnt_core_m. No entanto de momento esta informação não existe na tabela al029_cnt_core_m, está em curso a análise de um desenvolvimento no ambiente ALM que prevê adicionar 8 campos à tabela al029_cnt_core_m: cap do indexante passivo, cap do all-in passivo (indexante+spread), floor do indexante passivo, floor do all-in passivo (indexante+spread), cap do indexante ativo, cap do all-in ativo(indexante+spread), floor do indexante ativo, floor do all-in ativo(indexante+spread). Este datapoint será alimentado por um destes novos campos. | N45: Em análise
A46: V_148 | B46: Interest rate information | C46: Interest rate reset frequency | D46: String | E46: Frequency at which the interest rate is reset after the initial fixed-rate period, if any. Opções: ‣ Overnight ‣ Monthly/quarterly/semiannual/annual ‣ At creditor discretion ‣ Other frequency | G46: INSTRUMENT-INTRST_RT_RST_FRQNCY | H46: Interest rate reset frequency | I46: Frequency at which the interest rate is reset after the initial fixed-rate period, if any. | K46: NÃO | L46: interest_rate_reset_freq | M46: LT002_INSTRUMENT.INTRST_RT_RST_FRQNCY ‣ Traduzir o campo "INTRST_RT_RST_FRQNCY" seguindo as parametrizações apresentadas nas sheets: ‣ LT829 - filtrando por campo_conceito = 'INTRST_RT_RST_FRQNCY' e regra_conversao = '1'; ‣ LT830 - filtrando por segmento = 'Exposures to natural persons' e campo_conceito = 'INTRST_RT_RST_FRQNCY'.
A47: V_149 | B47: Interest rate information | C47: Interest rate spread/margin | D47: Numeric (percentage) | E47: Margin or spread to add to the reference rate that is used for the calculation of the interest rate in basis points. This applies to interest rates charged for variable interest loans. | G47: - | H47: - | I47: - | K47: NÃO | L47: interest_rate_spread_margin | M47: LT002_INSTRUMENT.SPRD
A49: V_150 | B49: Interest rate information | C49: Interest rate type | D49: String | E49: Classification of credit exposures based on the base rate for establishing the interest rate for each payment period. Opções: ‣ Fixed ‣ Variable ‣ Mixed | G49: INSTRUMENT-TYP_INTRST_RT | H49: Type of interest rate | I49: Classification of credit exposures based on the base rate for establishing the interest rate for each payment period. | K49: NÃO | L49: interest_rate_type | M49: ILT002_INSTRUMENT.TYP_INTRST_RT ‣ Traduzir o campo "TYP_INTRST_RT" seguindo as parametrizações apresentadas nas sheets: ‣ LT829 - filtrando por campo_conceito = 'TYP_INTRST_RT' e regra_conversao = '1'; ‣ LT830 - filtrando por segmento = 'Exposures to natural persons' e campo_conceito = 'TYP_INTRST_RT'.
A50: V_151 | B50: Instrument characteristics | C50: Legal final maturity date | D50: DD/MM/AA | E50: The contractual maturity date of the instrument, taking into account any agreements amending initial contracts. | G50: INSTRUMENT-DT_LGL_FNL_MTRTY | H50: Legal final maturity date (latest repayment date) | I50: The contractual maturity date of the instrument, taking into account any agreements amending initial contracts. As for retail revolving credit facilities this attribute is to be reported "not applicable". | K50: NÃO | L50: maturity_date | M50: LT002_INSTRUMENT.DT_LGL_FNL_MTRTY
A51: V_152 | B51: Instrument characteristics | C51: Commitment amount at inception | D51: Numeric (euro) | E51: Observed agent’s maximum exposure to credit risk on the inception date of the instrument, without taking into account any protection held or other credit enhancements. | G51: INSTRUMENT-CMMTMNT_INCPTN_INSTRMNT | H51: Commitment amount at inception | I51: Observed agent’s maximum exposure to credit risk on the inception date of the instrument, without taking into account any protection held or other credit enhancements. Total commitment amount on the inception date is established during the approval process and is intended to restrict an observed agent’s amount of credit risk to a given counterparty for the relevant instrument. | K51: NÃO | L51: commitment_amount_inception | M51: LT002_INSTRUMENT.CMMTMNT_INCPTN_INSTRMNT
A52: V_153 | B52: Instrument characteristics | C52: Payment frequency | D52: String | E52: Frequency of payments due, either of principal or interest, i.e. number of months between payments at the reporting reference date. Opções: ‣ Monthly/quarterly/semiannual/annual ‣ Bullet ‣ Zero coupon ‣ Other | G52: INSTRUMENT-PYMNT_FRQNCY | H52: Payment frequency | I52: Frequency of payments due, either of principal or interest, i.e. number of months between payments. | K52: NÃO | L52: payment_freq | M52: LT002_INSTRUMENT.PYMNT_FRQNCY ‣ Traduzir o campo "PYMNT_FRQNCY" seguindo as parametrizações apresentadas nas sheets: ‣ LT829 - filtrando por campo_conceito = 'PYMNT_FRQNCY' e regra_conversao = '1'; ‣ LT830 - filtrando por segmento = 'Exposures to natural persons' e campo_conceito = 'PYMNT_FRQNCY'.
A59: V_154 | B59: Instrument characteristics | C59: Reference rate | D59: String | E59: Reference rate used for the calculation of the actual interest rate. The reference rate code is a combination of the reference rate value and maturity value. Opções: ‣ EURIBOR ‣ USD LIBOR ‣ GBP LIBOR ‣ EUR LIBOR ‣ JPY LIBOR ‣ CHF LIBOR ‣ MIBOR ‣ OTHER SINGLE REFERENCE RATES ‣ OTHER MULTIPLE REFERENCE RATES | G59: - | H59: - | I59: - | K59: SIM | L59: reference_rate | M59: ‣ Reportar o campo "cod_tipo_taxa_ref_act" da tabela cd_alm.al029_cnt_core_m; ‣ O campo acima responde à finalidade pedida neste report, no entanto é necessário criar um campo novo no Loan Tape, que tem de ser genérico, caso outros reports também necessitem do o consumir. Necessário confirmar se a seguinte regra responde de forma genérica a este conceito: Reportar: SELECT CONCAT(TRIM(cod_tipo_taxa_ref_act),TRIM(cod_tipo_taxa_ref_pas)) FROM cd_alm.al029_cnt_core_m; ‣ Falta finalizar a parametrização a aplicar neste campo. | N59: Em análise
A60: V_155 | B60: Instrument characteristics | C60: Settlement date | D60: DD/MM/AA | E60: The date on which the conditions specified in the contract are or can be executed for the first time, i.e. the date on which financial instruments are initially exchanged or created. | G60: - | H60: - | I60: - | K60: SIM | L60: settlement_date | M60: Criar um novo campo "SETTLEMENT_DATE" na tabela LT002_INSTRUMENT, que será uma 'cópia' do campo LT002_INSTRUMENT.DT_INCPTN.
A61: V_156 | B61: Interest rate information | C61: Interest rate | D61: Numeric (percentage with two decimals, both positive and negative values). | E61: Annualised agreed rate or narrowly defined interest rate in accordance with Part 1 of Annex I to Regulation (EU) No 1072/2013 of the European Central Bank (ECB/2013/34) | G61: INSTRUMENT-ANNLSD_AGRD_RT | H61: Interest rate at the reference date | I61: Annualised agreed rate or narrowly defined interest rate at reference date in accordance with Regulation (EU) No 1072/2013 of the European Central Bank (ECB/2013/34). | K61: NÃO | L61: interest_rate | M61: LT002_INSTRUMENT.ANNLSD_AGRD_RT
A63: V_157 | B63: Interest rate information | C63: Next interest rate reset date | D63: DD/MM/AA | E63: The date when the next interest rate reset, as defined in Part 3 of Annex I to Regulation (EU) No 1071/2013 (ECB/2013/33), takes place. | G63: INSTRUMENT-DT_NXT_INTRST_RT_RST | H63: Next interest rate reset date | I63: The date when the next interest rate reset, as defined in Part 3 of Annex I to Regulation (EU) No 1071/2013 (ECB/2013/33), takes place. | K63: NÃO | L63: next_interest_rate_reset_date | M63: LT002_INSTRUMENT.DT_NXT_INTRST_RT_RST
A65: V_158 | B65: Financial information | C65: Default status of the instrument | D65: String | E65: Identification of the default status of the instrument in accordance with Article 178 of Regulation (EU) No 575/2013. Opções: ‣ Not in default ‣ Default because unlikely to pay (not more than 90/180 days past due) ‣ Default because more than 90/180 days past due ‣ Default because both unlikely to pay and more than 90/180 days past due. | G65: INSTRUMENT-DFLT_STTS_INSTRMNT | H65: Default status of the instrument | I65: Identification of the default status of the instrument. Categories describing the situations in which an instrument can be described as being at default in accordance with Article 178 of Regulation (EU) No 575/2013. | K65: NÃO | L65: default_status_instrument | M65: LT002_INSTRUMENT.DFLT_STTS_INSTRMNT ‣ Traduzir o campo "DFLT_STTS_INSTRMNT" seguindo as parametrizações apresentadas nas sheets: ‣ LT829 - filtrando por campo_conceito = 'DFLT_STTS_INSTRMNT' e regra_conversao = '1'; ‣ LT830 - filtrando por segmento = 'Exposures to natural persons', campo_conceito = 'DFLT_STTS_INSTRMNT'.
A68: V_159 | B68: Financial information | C68: Date of the default status of the instrument | D68: DD/MM/AA | E68: The date on which the default status, as reported in the data attribute “default status of the instrument”, is considered to have occurred. | G68: INSTRUMENT-DT_DFLT_STTS_INSTRMNT | H68: Date of default status | I68: The date on which the default status, as reported in the data attribute “Default status”, is considered to have arisen. If "Not in default" since inception then this attribute is to be reported equally to the inception date. If more than one Instrument is classified as defaulted then the earliest date has to be provided. The definition of default is aligned with Art 178 of Regulation (EU) No 575/2013. | K68: NÃO | L68: date_default_status_instrument | M68: LT002_INSTRUMENT.DT_DFLT_STTS_INSTRMNT
A69: V_160 | B69: Financial information | C69: Transferred amount | D69: Numeric (euro) | E69: Transferred amount of the economic ownership of the financial asset to third parties. This data attribute captures the part of the outstanding nominal amount that has been transferred to another creditor. | G69: - | H69: - | I69: - | K69: SIM | L69: transferred_amount | M69: Reportar sempre: 11111111111
A70: V_161 | B70: Financial information | C70: Arrears for the instrument | D70: Numeric (euro) | E70: Aggregated amount of the principal, interest and any fee payment outstanding at the reporting date, which is contractually due and has not been paid (past due). | G70: INSTRUMENT-ARRRS_INSTRMNT | H70: Total exposure in arrears | I70: Aggregated amount of the principal, interest and any fee payment outstanding at the reporting date, which is contractually due and has not been paid (past due). | K70: NÃO | L70: arrears_instrument | M70: LT002_INSTRUMENT.ARRRS_INSTRMNT
A71: V_162 | B71: Financial information | C71: Date of past due for the instrument | D71: DD/MM/AA | E71: The date on which the instrument became past due in accordance with Part 2.96 of Annex V to the amended Implementing Regulation (EU) No 680/2014. | G71: INSTRUMENT-DT_PST_D | H71: Date past due | I71: The date on which the instrument became past due in accordance with Part 2.96 of Annex V to the amended Implementing Regulation (EU) No 680/2014. This is the latest such date prior to the reporting reference date and it is to be reported if the instrument is past due on the reporting reference date. | K71: NÃO | L71: date_past_due_instrument | M71: LT002_INSTRUMENT.DT_PST_D
A72: V_163 | B72: Financial information/Instrument characteristics | C72: Type of securitization | D72: String | E72: Captures the type of securitisation, if any, to which the instrument has been subject, in accordance with Article 242(10), (11), 243 and 244 of Regulation (EU) No 575/2013. Opções: ‣ Traditional securitisation ‣ Synthetic securitisation ‣ Not securitised | G72: - | H72: - | I72: - | K72: SIM | L72: type_securitization | M72: ‣ Esta informação não existia no Datalake, foi necessário pedir a ingesta da tabela “JM_SPV” da BDR, a qual já foi implementada; ‣ O Loan Tape não pode consumir informação diretamente da ingesta acima. A informação ingestada deve ser processada e introduzida numa nova tabela cd_captools.ctxxx_securitis_cap. A lógica desta tabela já foi definida e o seu desenvolvimento já foi endereçado; ‣ De seguida está a lógica que foi definida para produzir este campo, falta apenas confirmar qual o campo da tabela ct013_rwa_princ que deverá ser usado como fator de peso de forma a resolver a ambiguidade que surge ao ligar o universo FINREP ao universo da BDR: 1º Passo - Obter para cada contrato (INSTRMNT_ID) o par (S1EMP, COD_SPV) mais 'significativo': 1. Seguir a lógica do campo RWA_MTHD, de momento a lógica é: se existir IRB e Standard então trazer informação relativa a IRB; 2. Se mesmo assim ainda existirem vários pares (S1EMP, COD_SPV) distintos então: recuperar o par (S1EMP, COD_SPV) com o maior valor atribuído no campo !CAMPO DE PESO!; 3. Ficamos então com uma tabela intermédia (TITU_TIP_INTR) com uma relação única entre cada contrato (INSTRMNT_ID) e os campos (S1EMP, COD_SPV). 2ª Passo - Ligar os pares (S1EMP, COD_SPV) obtidos no passo anterior com a tabela cd_captools.ctxxx_securitis_cap de forma a obter o campo TITU_TIP: TITU_TIP_INTR LEFT JOIN (SELECT S1EMP, COD_SPV, TITU_TIP FROM cd_captools.ctxxx_securitis_cap ) as SECUR_CAP ON TITU_TIP_INTR.S1EMP = SECUR_CAP.S1EMP AND TITU_TIP_INTR.COD_SPV = SECUR_CAP.COD_SPV ‣ Traduzir o campo " TITU_TIP " seguindo a parametrização apresentada na sheet 'LT831' filtrando por tabela_conceito = 'LT002_INSTRUMENT' e campo_conceito = 'TYPE_SECURITIZATION'. | N72: Em análise
A73: V_164 | B73: Instrument charcteristics | C73: Outstanding nominal amount | D73: Numeric (euro) | E73: Principal amount outstanding at the end of the reporting reference date, including unpaid past due interest but excluding accrued interest, net of write-offs and write-downs as determined by the relevant accounting practices. | G73: INSTRUMENT-OTSTNDNG_NMNL_AMNT_INSTRMNT | H73: Outstanding gross nominal amount | I73: Principal amount outstanding at the end of the reporting reference date, including unpaid past due interest but excluding accrued interest. The outstanding nominal amount must be reported net of write-offs and write-downs as determined by the relevant accounting practices. | K73: NÃO | L73: outstanding_nominal_amount | M73: LT002_INSTRUMENT.OTSTNDNG_NMNL_AMNT_INSTRMNT
A74: V_165 | B74: Instrument charcteristics | C74: Accrued interest | D74: Numeric (euro) | E74: The amount of accrued interest on loans at the reporting reference date as defined in Regulation (EU) No 1071/2013 (ECB/2013/33). | G74: INSTRUMENT-ACCRD_INTRST_INSTRMNT | H74: Accrued interest balance as recognised on the balance sheet | I74: The amount of accrued interest on loans at the reporting reference date as defined in Regulation (EU) No 1071/2013 (ECB/2013/33). In accordance with the general principle of accruals accounting, interest receivable on instruments should be subject to on-balance sheet recording as it accrues (i.e. on an accruals basis) rather than when it is actually received (i.e. on a cash basis). | K74: NÃO | L74: accrued_interest | M74: LT002_INSTRUMENT.ACCRD_INTRST_INSTRMNT
A75: V_166 | B75: Financial information | C75: Off-balancesheet amount | D75: Numeric (euro) | E75: Total nominal amount of off-balance-sheet exposures. | G75: INSTRUMENT-OFF_BLNC_SHT_AMNT_INSTRMNT | H75: Off-balance sheet amount | I75: Total nominal amount of off-balance-sheet exposures. This includes any commitment to lend before considering conversion factors and credit risk mitigation techniques. It is the amount that best represents the institution’s maximum exposure to credit risk without taking into account any protection held or other credit enhancements. To be reported in accordance with Annex V Regulation 680/2014. If no amount can be drawn by or disbursed to the debtor without contractual changes, the off-balance-sheet amount of the instrument is reported as ”not applicable”. | K75: NÃO | L75: off_balance_sheet_amount | M75: LT002_INSTRUMENT.OFF_BLNC_SHT_AMNT_INSTRMNT
A76: V_167 | B76: Financial information | C76: Joint liabilities amount | D76: Numeric (euro) | E76: Outstanding nominal amount for which each debtor is liable in relation to a single instrument where there are two or more debtors. | G76: Not applicable: To be reported as "11111111111". This information will be availabe in "02_04_nat_instr_count" table | H76: - | I76: - | K76: SIM | L76: joint_liabilities_amount | M76: Reportar sempre: 11111111111
A77: V_168 | B77: Informação financeira | C77: Accounting classification of instruments | D77: String | E77: Accounting portfolio where the instrument is recorded in accordance with the accounting standard – IFRS or national GAAP – under Regulation (EU) 2015/534 (ECB/2015/13) applied by the observed agent’s legal entity. Opções: | G77: INSTRUMENT-ACCNTNG_CLSSFCTN | H77: Accounting portfolio | I77: Accounting portfolio where the instrument is recorded in accordance with the accounting standard – IFRS or national GAAP – under Regulation (EU) 2015/534 (ECB/2015/13) applied by the observed agent’s legal entity. | K77: NÃO | L77: accounting_classification | M77: LT002_INSTRUMENT.ACCNTNG_CLSSFCTN ‣ Traduzir o campo "ACCNTNG_CLSSFCTN" seguindo as parametrizações apresentadas nas sheets: ‣ LT829 - filtrando por campo_conceito = 'ACCNTNG_CLSSFCTN' e regra_conversao = '1'; ‣ LT830 - filtrando por segmento = 'Exposures to natural persons', campo_conceito = 'ACCNTNG_CLSSFCTN'.
A84: V_169 | B84: Informação financeira | C84: Balance sheet recognition | D84: String | E84: Balance sheet recognition of the financial asset. This data attribute classifies the reported instruments pursuant to their balance sheet recognition in accordance with Annex III and Template 15 in Annex IV to the ITS. Opções: ‣ Entirely recognised ‣ Recognised to the extent of the institution’s continuing involvement ‣ Entirely derecognised | G84: - | H84: - | I84: - | K84: SIM | L84: balance_sheet_recogn | M84: Reportar sempre: 'Entirely recognised'
A85: V_170 | B85: Financial information | C85: Accumulated write-offs | D85: Numeric (euro) | E85: Cumulative amount of principal and past due interest of any debt instrument that the institution is no longer recognising because they are considered uncollectible, independently of the portfolio in which they were included. | G85: INSTRUMENT-ACCMLTD_WRTFFS_INSTRMNT | H85: Accumulated write-offs | I85: Cumulative amount of principal and past due interest of any debt instrument that the institution is no longer recognising because they are considered uncollectible, independently of the portfolio in which they were included. Write-offs could be caused both by reductions in the carrying amount of financial assets recognised directly in profit or loss and by reductions in the amounts of the allowance accounts for credit losses set off against the carrying amount of financial assets. | K85: NÃO | L85: accum_write_offs | M85: LT002_INSTRUMENT.ACCMLTD_WRTFFS_INSTRMNT
...

Sheet NATURALP_COUNTERPARTIES
A1: Instruções SRB | G1: Mapeamento efetuado pela Corporação e respetiva Descrição Loan Tape (LT) | K1: Análise IT
A2: ID | B2: Categoria | C2: Coluna | D2: Tipo de dados | E2: Descrição | G2: Mapeamentos Corporação (LT) | H2: Descrição (LT) | I2: Additional Guidance (LT) | K2: Novo campo na tabela LT003? | L2: Nome do campo no ficheiro | M2: Mapeamento | N2: Notas
A3: V_2 | B3: Identification information | C3: Counterparty Identifier | D3: Alphanumeric | E3: Identifier applied to uniquely identify each counterparty. | G3: ENTITY-ENTTY_ID | H3: Entity ID | I3: An identifier applied by the reporting agent to uniquely identify each counterparty. Each counterparty has a unique and exclusive counterparty identifier. This means that this value will not change over time and can never be used as the counterparty identifier for any other counterparty. | K3: NÃO | L3: counterparty_id | M3: LT003_ENTITY.ENTTY_ID
