Workbook
Name asefadf: #REF!
Name bn: #REF!

Sheet Plano_DE
I1: 823.2 | J1: 16.8 | K1: 16.8 | L1: 16.8 | M1: 16.8 | N1: 16.8 | O1: 16.8 | P1: 16.8 | Q1: 16.8 | R1: 16.8 | S1: 16.8 | T1: 16.8 | U1: 16.8 | V1: 16.8 | W1: 16.8 | X1: 16.8 | Y1: 16.8 | Z1: 16.8 | AA1: 16.8 | AB1: 16.8 | AC1: 16.8 | AD1: 16.8 | AE1: 16.8 | AF1: 16.8 | AG1: 16.8 | AH1: 16.8 | AI1: 16.8 | AJ1: 16.8 | AK1: 16.8 | AL1: 16.8 | AM1: 16.8 | AN1: 16.8 | AO1: 16.8 | AP1: 16.8 | AQ1: 16.8 | AR1: 16.8 | AS1: 16.8 | AT1: 16.8 | AU1: 16.8 | AV1: 16.8 | AW1: 16.8 | AX1: 16.8 | AY1: 16.8 | AZ1: 16.8 | BA1: 16.8 | BB1: 16.8 | BC1: 16.8 | BD1: 16.8 | BE1: 16.8 | BF1: 16.8
I2: VAL | J2: 0 | K2: 0 | L2: 0 | M2: 0 | N2: 0 | O2: 0 | P2: 0 | Q2: 0 | R2: 0 | S2: 0 | T2: 0 | U2: 0 | V2: 0 | W2: 0 | X2: 0 | Y2: 0 | Z2: 0 | AA2: 0 | AB2: 0 | AC2: 0 | AD2: 0 | AE2: 0 | AF2: 0 | AG2: 0 | AH2: 0 | AI2: 0 | AJ2: 0 | AK2: 0 | AL2: 0 | AM2: 0 | AN2: 0 | AO2: 0 | AP2: 0 | AQ2: 0 | AR2: 0 | AS2: 0 | AT2: 0 | AU2: 0 | AV2: 0 | AW2: 0 | AX2: 0 | AY2: 0 | AZ2: 0 | BA2: 0 | BB2: 0 | BC2: 0 | BD2: 0 | BE2: 0 | BF2: -1.575
I3: FTE REAIS | J3: 2.1 | K3: 2.1 | L3: 2.1 | M3: 2.1 | N3: 2.1 | O3: 2.1 | P3: 2.1 | Q3: 2.1 | R3: 2.1 | S3: 2.1 | T3: 2.1 | U3: 2.1 | V3: 2.1 | W3: 2.1 | X3: 2.1 | Y3: 2.1 | Z3: 2.1 | AA3: 2.1 | AB3: 2.1 | AC3: 2.1 | AD3: 2.1 | AE3: 2.1 | AF3: 2.1 | AG3: 2.1 | AH3: 2.1 | AI3: 2.1 | AJ3: 2.1 | AK3: 2.1 | AL3: 2.1 | AM3: 2.1 | AN3: 2.1 | AO3: 2.1 | AP3: 2.1 | AQ3: 2.1 | AR3: 2.1 | AS3: 2.1 | AT3: 2.1 | AU3: 2.1 | AV3: 2.1 | AW3: 2.1 | AX3: 2.1 | AY3: 2.1 | AZ3: 2.1 | BA3: 2.1 | BB3: 2.1 | BC3: 2.1 | BD3: 2.1 | BE3: 2.1 | BF3: 0.525
I4: FTE ESP. | J4: 2.1 | K4: 2.1 | L4: 2.1 | M4: 2.1 | N4: 2.1 | O4: 2.1 | P4: 2.1 | Q4: 2.1 | R4: 2.1 | S4: 2.1 | T4: 2.1 | U4: 2.1 | V4: 2.1 | W4: 2.1 | X4: 2.1 | Y4: 2.1 | Z4: 2.1 | AA4: 2.1 | AB4: 2.1 | AC4: 2.1 | AD4: 2.1 | AE4: 2.1 | AF4: 2.1 | AG4: 2.1 | AH4: 2.1 | AI4: 2.1 | AJ4: 2.1 | AK4: 2.1 | AL4: 2.1 | AM4: 2.1 | AN4: 2.1 | AO4: 2.1 | AP4: 2.1 | AQ4: 2.1 | AR4: 2.1 | AS4: 2.1 | AT4: 2.1 | AU4: 2.1 | AV4: 2.1 | AW4: 2.1 | AX4: 2.1 | AY4: 2.1 | AZ4: 2.1 | BA4: 2.1 | BB4: 2.1 | BC4: 2.1 | BD4: 2.1 | BE4: 2.1 | BF4: 2.1
J5: Mês 1 | AG5: Mês 2 | BD5: Mês 3
I6: 45657 | J6: 45658 | K6: 45659 | L6: 45660 | M6: 4 | N6: 5 | O6: 6 | P6: 9 | Q6: 10 | R6: 11 | S6: 12 | T6: 13 | U6: 16 | V6: 17 | W6: 18 | X6: 19
F7: # Campos | G7: Duração (horas) | H7: Duração (Dias) | I7: VAL | J7: 1 | K7: 2 | L7: 3 | M7: 4 | N7: 5 | O7: 6 | P7: 7 | Q7: 8 | R7: 9 | S7: 10 | T7: 11 | U7: 12 | V7: 13 | W7: 14 | X7: 15 | Y7: 16 | Z7: 17 | AA7: 18 | AB7: 19 | AC7: 20 | AD7: 21 | AE7: 22 | AF7: 23 | AG7: 24 | AH7: 25 | AI7: 26 | AJ7: 27 | AK7: 28 | AL7: 29 | AM7: 30 | AN7: 31 | AO7: 32 | AP7: 33 | AQ7: 34 | AR7: 35 | AS7: 36 | AT7: 37 | AU7: 38 | AV7: 39 | AW7: 40 | AX7: 41 | AY7: 42 | AZ7: 43 | BA7: 44 | BB7: 45 | BC7: 46 | BD7: 47 | BE7: 48 | BF7: 49 | BG7: 50 | BH7: 51 | BI7: 52 | BJ7: 53 | BK7: 54 | BL7: 55 | BM7: 56 | BN7: 57 | BO7: 58 | BP7: 59 | BQ7: 60 | BR7: 61 | BS7: 62 | BT7: 63 | BU7: 64 | BV7: 65 | BW7: 66 | BX7: 67 | BY7: 68 | BZ7: 69
C9: Gestão Projeto | F9: n.a. | G9: 0 | H9: 0
C10: 0. Gestão Projeto | F10: n.a. | G10: 51.2 | H10: 6.4 | I10: 0 | J10: 0.1 | K10: 0.1 | L10: 0.1 | M10: 0.1 | N10: 0.1 | O10: 0.1 | P10: 0.1 | Q10: 0.1 | R10: 0.1 | S10: 0.1 | T10: 0.1 | U10: 0.1 | V10: 0.1 | W10: 0.1 | X10: 0.1 | Y10: 0.1 | Z10: 0.1 | AA10: 0.1 | AB10: 0.1 | AC10: 0.1 | AD10: 0.1 | AE10: 0.1 | AF10: 0.1 | AG10: 0.1 | AH10: 0.1 | AI10: 0.1 | AJ10: 0.1 | AK10: 0.1 | AL10: 0.1 | AM10: 0.1 | AN10: 0.1 | AO10: 0.1 | AP10: 0.1 | AQ10: 0.1 | AR10: 0.1 | AS10: 0.1 | AT10: 0.1 | AU10: 0.1 | AV10: 0.1 | AW10: 0.1 | AX10: 0.1 | AY10: 0.1 | AZ10: 0.1 | BA10: 0.1 | BB10: 0.1 | BC10: 0.1 | BD10: 0.1 | BE10: 0.1 | BF10: 0.1 | BG10: 0.1 | BH10: 0.1 | BI10: 0.1 | BJ10: 0.1 | BK10: 0.1 | BL10: 0.1 | BM10: 0.1 | BN10: 0.1 | BO10: 0.1 | BP10: 0.1 | BQ10: 0.1 | BR10: 0.1 | BS10: 0.1 | BT10: 0.1 | BU10: 0.1 | BV10: 0.1 | BW10: 0.1 | BX10: 0.1 | BY10: 0.1 | BZ10: 0.1
C11: 1. Set-Up | F11: n.a. | G11: 32 | H11: 4 | I11: 0 | J11: 2 | K11: 2
C12: 2. Assessment ao Green Dashboard (Esp. Atual) | F12: n.a. | G12: 64 | H12: 8 | I12: 0 | L12: 2 | M12: 2 | N12: 2 | O12: 2
C13: 3. Re-testes aos campos concluídos do GD âmbito projeto anterior | F13: 23 | G13: 82 | H13: 10.25 | I13: 0 | P13: 2 | Q13: 2 | R13: 2 | S13: 2 | T13: 2 | U13: 0.25
B14: INSTRUMENT_COD_SOC | C14: INSTRUMENT | D14: COD_SOC | F14: SCA SCB1 | G14: 3.5 | I14: 0
B15: INSTRUMENT_SUBPORTFOLIO_ID | C15: INSTRUMENT | D15: SUBPORTFOLIO_ID | F15: SCA SCB1 | G15: 3.5 | I15: 0
B16: INSTRUMENT_DT_RFRNC | C16: INSTRUMENT | D16: DT_RFRNC | F16: SCA SCB1 | G16: 3.5 | I16: 0
B17: INSTRUMENT_DFLT_STTS_INSTRMNT | C17: INSTRUMENT | D17: DFLT_STTS_INSTRMNT | F17: SCA SCB1 | G17: 3.5 | I17: 0
B18: INSTRUMENT_IMPRMNT_STTS | C18: INSTRUMENT | D18: IMPRMNT_STTS | F18: SCA SCB1 | G18: 3.5 | I18: 0
B19: INSTRUMENT_PRFRMNG_STTS | C19: INSTRUMENT | D19: PRFRMNG_STTS | F19: SCA SCB1 | G19: 3.5 | I19: 0
B20: INSTRUMENT_TYP_INSTRMNT | C20: INSTRUMENT | D20: TYP_INSTRMNT | F20: SCA SCB1 | G20: 3.5 | I20: 0
B21: INSTRUMENT_GRSS_CRRYNG_AMNT_INSTRMNT | C21: INSTRUMENT | D21: GRSS_CRRYNG_AMNT_INSTRMNT | F21: SCA SCB1 | G21: 3.5 | I21: 0
B22: INSTRUMENT_ACCMLTD_CHNGS_FV_CR_INSTRMNT | C22: INSTRUMENT | D22: ACCMLTD_CHNGS_FV_CR_INSTRMNT | F22: SCA SCB1 | G22: 3.5 | I22: 0
B23: INSTRUMENT_ACCNTNG_CLSSFCTN | C23: INSTRUMENT | D23: ACCNTNG_CLSSFCTN | F23: SCA SCB1 | G23: 3.5 | I23: 0
B24: INSTRUMENT_OFF_BLNC_SHT_AMNT_INSTRMNT | C24: INSTRUMENT | D24: OFF_BLNC_SHT_AMNT_INSTRMNT | F24: SCA SCB1 | G24: 3.5 | I24: 0
B25: INSTRUMENT_PRVSNS_OFF_BLNC_SHT | C25: INSTRUMENT | D25: PRVSNS_OFF_BLNC_SHT | F25: SCA SCB1 | G25: 3.5 | I25: 0
... B36: INSTRUMENT_RWA_OFF_BLNC | C36: INSTRUMENT | D36: RWA_OFF_BLNC | F36: SCA SCB1 | G36: 3.5 | I36: 0
C37: 4. Especificação de novos requisitos | F37: 14 | G37: 15 | H37: 1.875 | I37: 0 | U37: 1.75 | V37: 0.125
B38: INSTRUMENT_CCF | C38: INSTRUMENT | D38: CCF | F38: SCA SCB1 | G38: 1 | I38: 0
B39: INSTRUMENT_EAD | C39: INSTRUMENT | D39: EAD | F39: SCA SCB1 | G39: 1 | I39: 0
B40: INSTRUMENT_TYP_OFF_BLNC_PRDCT | C40: INSTRUMENT | D40: TYP_OFF_BLNC_PRDCT | F40: SCA SCB1 | G40: 1 | I40: 0
B41: INSTR_PROTECTION_COD_SOC | C41: INSTR_PROTECTION | D41: COD_SOC | F41: SCA SCB1 | G41: 1 | I41: 0
B42: INSTR_PROTECTION_DT_RFRNC | C42: INSTR_PROTECTION | D42: DT_RFRNC | F42: SCA SCB1 | G42: 1 | I42: 0
B43: INSTR_PROTECTION_INSTRMNT_ID | C43: INSTR_PROTECTION | D43: INSTRMNT_ID | F43: SCA SCB1 | G43: 1 | I43: 0
B44: INSTR_PROTECTION_PRTCTN_ID | C44: INSTR_PROTECTION | D44: PRTCTN_ID | F44: SCA SCB1 | G44: 1 | I44: 0
B45: PROTECTION_COD_SOC | C45: PROTECTION | D45: COD_SOC | F45: SCA SCB1 | G45: 1 | I45: 0
B46: PROTECTION_DT_RFRNC | C46: PROTECTION | D46: DT_RFRNC | F46: SCA SCB1 | G46: 1 | I46: 0
B47: PROTECTION_PRTCTN_ID | C47: PROTECTION | D47: PRTCTN_ID | F47: SCA SCB1 | G47: 1 | I47: 0
B48: PROTECTION_TYP_PRTCTN | C48: PROTECTION | D48: TYP_PRTCTN | F48: SCA SCB1 | G48: 1 | I48: 0
B49: PROTECTION_PRTCTN_VL | C49: PROTECTION | D49: PRTCTN_VL | F49: SCA SCB1 | G49: 1 | I49: 0
... B51: INSTR_ACTIVITY_PRCNTG_ACTVTY | C51: INSTR_ACTIVITY | D51: PRCNTG_ACTVTY | F51: SCA SCB1 | G51: 1 | I51: 0
C52: 5. Testes/Re-testes | G52: 498.4 | I52: 0
...

Sheet Macro_Plano_2025_v1
V6: 2 corresponde a 1 dia de trabalho
V7: Terminamos no dia 11
N8: Janeiro | R8: Fevereiro | U8: Março
C9: ID | D9: Atividade | G9: Status | H9: # Campos | I9: Duração (semana) | J9: Duração (horas) | L9: 45660 | M9: =L9+7 -> 45667 | N9: =M9+7 -> 45674 | O9: =N9+7 -> 45681 | P9: =O9+7 -> 45688 | Q9: =P9+7 -> 45695 | R9: =Q9+7 -> 45702 | S9: =R9+7 -> 45709 | T9: =S9+7 -> 45716 | ... V9: =U9+7 -> 45730
C11: 0. | D11: Gestão Projeto | H11: n.a. | J11: =SUM(L11:V11)*8 -> 41.6 | L11: =0.1*2 -> 0.2 | M11: =0.1*5 -> 0.5 | N11: =0.1*5 -> 0.5 | O11: =0.1*5 -> 0.5 | P11: =0.1*5 -> 0.5 | Q11: =0.1*5 -> 0.5 | R11: =0.1*5 -> 0.5 | S11: =0.1*5 -> 0.5 | T11: =0.1*5 -> 0.5 | ... V11: =0.1*5 -> 0.5
C13: 1. | D13: Set-Up | H13: n.a. | J13: =SUM(L13:M13)*8 -> #REF! | L13: =SUM(#REF!) -> #REF!
C15: 2. | D15: Assessment ao Green Dashboard (Especificação Atual) | H15: n.a. | J15: =SUM(L15:V15)*8 -> 64 | M15: =SUM('[1]Plano SCA'!$L$13:$P$13) -> 8
C17: 3. | D17: Testes regressivos aos campos concluidos do GD (âmbito projeto anterior) | H17: =COUNTA(E18:E40) -> 23 | I17: =SUM(I18:I40) -> 2.05 | J17: =SUM(J18:J40) -> 82 | M17: =#REF! -> #REF! | N17: =+SUM(#REF!) -> #REF!
B18: =D18&"_"&E18 -> INSTRUMENT_COD_SOC | C18: 3.1. | D18: INSTRUMENT | E18: COD_SOC | I18: =J18/8/5 -> 0.0875 | J18: =SUMIF(Aux!B:B,Macro_Plano_2025_v1!B18,Aux!I:I)+SUMIF(Aux!B:B,Macro_Plano_2025_v1!B18,Aux!O:O) -> 3.5 | M18: =J18/8 -> 0.4375
B19: =D19&"_"&E19 -> INSTRUMENT_SUBPORTFOLIO_ID | C19: 3.2. | D19: INSTRUMENT | E19: SUBPORTFOLIO_ID | I19: =J19/8/5 -> 0.0875 | J19: =SUMIF(Aux!B:B,Macro_Plano_2025_v1!B19,Aux!I:I)+SUMIF(Aux!B:B,Macro_Plano_2025_v1!B19,Aux!O:O) -> 3.5 | M19: =J19/8 -> 0.4375
B20: =D20&"_"&E20 -> INSTRUMENT_DT_RFRNC | C20: 3.3. | D20: INSTRUMENT | E20: DT_RFRNC | I20: =J20/8/5 -> 0.0875 | J20: =SUMIF(Aux!B:B,Macro_Plano_2025_v1!B20,Aux!I:I)+SUMIF(Aux!B:B,Macro_Plano_2025_v1!B20,Aux!O:O) -> 3.5 | M20: =J20/8 -> 0.4375
B21: =D21&"_"&E21 -> INSTRUMENT_DFLT_STTS_INSTRMNT | C21: 3.4. | D21: INSTRUMENT | E21: DFLT_STTS_INSTRMNT | I21: =J21/8/5 -> 0.0875 | J21: =SUMIF(Aux!B:B,Macro_Plano_2025_v1!B21,Aux!I:I)+SUMIF(Aux!B:B,Macro_Plano_2025_v1!B21,Aux!O:O) -> 3.5 | M21: =J21/8 -> 0.4375
B22: =D22&"_"&E22 -> INSTRUMENT_IMPRMNT_STTS | C22: 3.5. | D22: INSTRUMENT | E22: IMPRMNT_STTS | I22: =J22/8/5 -> 0.0875 | J22: =SUMIF(Aux!B:B,Macro_Plano_2025_v1!B22,Aux!I:I)+SUMIF(Aux!B:B,Macro_Plano_2025_v1!B22,Aux!O:O) -> 3.5 | M22: =M17-SUM(M18:M21) -> #REF! | N22: =(J22/8)-M22 -> #REF!
B23: =D23&"_"&E23 -> INSTRUMENT_PRFRMNG_STTS | C23: 3.6. | D23: INSTRUMENT | E23: PRFRMNG_STTS | I23: =J23/8/5 -> 0.0875 | J23: =SUMIF(Aux!B:B,Macro_Plano_2025_v1!B23,Aux!I:I)+SUMIF(Aux!B:B,Macro_Plano_2025_v1!B23,Aux!O:O) -> 3.5 | N23: =J23/8 -> 0.4375
B24: =D24&"_"&E24 -> INSTRUMENT_TYP_INSTRMNT | C24: 3.7. | D24: INSTRUMENT | E24: TYP_INSTRMNT | I24: =J24/8/5 -> 0.0875 | J24: =SUMIF(Aux!B:B,Macro_Plano_2025_v1!B24,Aux!I:I)+SUMIF(Aux!B:B,Macro_Plano_2025_v1!B24,Aux!O:O) -> 3.5 | N24: =J24/8 -> 0.4375
B25: =D25&"_"&E25 -> INSTRUMENT_GRSS_CRRYNG_AMNT_INSTRMNT | C25: 3.8. | D25: INSTRUMENT | E25: GRSS_CRRYNG_AMNT_INSTRMNT | I25: =J25/8/5 -> 0.0875 | J25: =SUMIF(Aux!B:B,Macro_Plano_2025_v1!B25,Aux!I:I)+SUMIF(Aux!B:B,Macro_Plano_2025_v1!B25,Aux!O:O) -> 3.5 | N25: =J25/8 -> 0.4375
B26: =D26&"_"&E26 -> INSTRUMENT_ACCMLTD_CHNGS_FV_CR_INSTRMNT | C26: 3.9. | D26: INSTRUMENT | E26: ACCMLTD_CHNGS_FV_CR_INSTRMNT | I26: =J26/8/5 -> 0.0875 | J26: =SUMIF(Aux!B:B,Macro_Plano_2025_v1!B26,Aux!I:I)+SUMIF(Aux!B:B,Macro_Plano_2025_v1!B26,Aux!O:O) -> 3.5 | N26: =J26/8 -> 0.4375
B27: =D27&"_"&E27 -> INSTRUMENT_ACCNTNG_CLSSFCTN | C27: 3.10. | D27: INSTRUMENT | E27: ACCNTNG_CLSSFCTN | I27: =J27/8/5 -> 0.0875 | J27: =SUMIF(Aux!B:B,Macro_Plano_2025_v1!B27,Aux!I:I)+SUMIF(Aux!B:B,Macro_Plano_2025_v1!B27,Aux!O:O) -> 3.5 | N27: =J27/8 -> 0.4375
B28: =D28&"_"&E28 -> INSTRUMENT_OFF_BLNC_SHT_AMNT_INSTRMNT | C28: 3.11. | D28: INSTRUMENT | E28: OFF_BLNC_SHT_AMNT_INSTRMNT | I28: =J28/8/5 -> 0.0875 | J28: =SUMIF(Aux!B:B,Macro_Plano_2025_v1!B28,Aux!I:I)+SUMIF(Aux!B:B,Macro_Plano_2025_v1!B28,Aux!O:O) -> 3.5 | N28: =J28/8 -> 0.4375
B29: =D29&"_"&E29 -> INSTRUMENT_PRVSNS_OFF_BLNC_SHT | C29: 3.12. | D29: INSTRUMENT | E29: PRVSNS_OFF_BLNC_SHT | I29: =J29/8/5 -> 0.0875 | J29: =SUMIF(Aux!B:B,Macro_Plano_2025_v1!B29,Aux!I:I)+SUMIF(Aux!B:B,Macro_Plano_2025_v1!B29,Aux!O:O) -> 3.5 | N29: =J29/8 -> 0.4375
B30: =D30&"_"&E30 -> INSTRUMENT_RWA | C30: 3.13. | D30: INSTRUMENT | E30: RWA | I30: =J30/8/5 -> 0.0875 | J30: =SUMIF(Aux!B:B,Macro_Plano_2025_v1!B30,Aux!I:I)+SUMIF(Aux!B:B,Macro_Plano_2025_v1!B30,Aux!O:O) -> 3.5 | N30: =J30/8 -> 0.4375
B31: =D31&"_"&E31 -> INSTRUMENT_ACCMLTD_IMPRMNT_INSTRMNT | C31: 3.14. | D31: INSTRUMENT | E31: ACCMLTD_IMPRMNT_INSTRMNT | I31: =J31/8/5 -> 0.0875 | J31: =SUMIF(Aux!B:B,Macro_Plano_2025_v1!B31,Aux!I:I)+SUMIF(Aux!B:B,Macro_Plano_2025_v1!B31,Aux!O:O) -> 3.5 | N31: =J31/8 -> 0.4375
B32: =D32&"_"&E32 -> INSTRUMENT_COD_SOC_INTRGRP | C32: 3.15. | D32: INSTRUMENT | E32: COD_SOC_INTRGRP | I32: =J32/8/5 -> 0.0875 | J32: =SUMIF(Aux!B:B,Macro_Plano_2025_v1!B32,Aux!I:I)+SUMIF(Aux!B:B,Macro_Plano_2025_v1!B32,Aux!O:O) -> 3.5 | N32: =J32/8 -> 0.4375
B33: =D33&"_"&E33 -> INSTRUMENT_LCL_INSTMRNT_ID | C33: 3.16. | D33: INSTRUMENT | E33: LCL_INSTMRNT_ID | I33: =J33/8/5 -> 0.0875 | J33: =SUMIF(Aux!B:B,Macro_Plano_2025_v1!B33,Aux!I:I)+SUMIF(Aux!B:B,Macro_Plano_2025_v1!B33,Aux!O:O) -> 3.5 | N33: =J33/8 -> 0.4375
B34: =D34&"_"&E34 -> INSTRUMENT_FLG_INTRBSNSS | C34: 3.17. | D34: INSTRUMENT | E34: FLG_INTRBSNSS | I34: =J34/8/5 -> 0.1 | J34: =SUMIF(Aux!B:B,Macro_Plano_2025_v1!B34,Aux!I:I)+SUMIF(Aux!B:B,Macro_Plano_2025_v1!B34,Aux!O:O) -> 4 | N34: =J34/8 -> 0.5
... B40: =D40&"_"&E40 -> INSTRUMENT_RWA_OFF_BLNC | C40: 3.23. | D40: INSTRUMENT | E40: RWA_OFF_BLNC | I40: =J40/8/5 -> 0.0875 | J40: =SUMIF(Aux!B:B,Macro_Plano_2025_v1!B40,Aux!I:I)+SUMIF(Aux!B:B,Macro_Plano_2025_v1!B40,Aux!O:O) -> 3.5 | N40: =J40/8 -> 0.4375
C42: 4. | D42: Re-especificações e especificação de novos requisitos | H42: =COUNTA(E43:E56) -> 14 | I42: =+SUM(I43:I56) -> #REF! | J42: =SUM(J43:J56) -> #REF! | N42: =SUM(#REF!) -> #REF! | O42: =SUM(#REF!) -> #REF!
B43: =D43&"_"&E43 -> INSTRUMENT_CCF | C43: 4.1. | D43: INSTRUMENT | E43: CCF | I43: =J43/8/5 -> #REF! | J43: =SUMIF(#REF!,Macro_Plano_2025_v1!B43,#REF!) -> #REF! | N43: =J43/8 -> #REF!
B44: =D44&"_"&E44 -> INSTRUMENT_EAD | C44: 4.2. | D44: INSTRUMENT | E44: EAD | I44: =J44/8/5 -> #REF! | J44: =SUMIF(#REF!,Macro_Plano_2025_v1!B44,#REF!) -> #REF! | N44: =J44/8 -> #REF!
B45: =D45&"_"&E45 -> INSTRUMENT_TYP_OFF_BLNC_PRDCT | C45: 4.3. | D45: INSTRUMENT | E45: TYP_OFF_BLNC_PRDCT | I45: =J45/8/5 -> #REF! | J45: =SUMIF(#REF!,Macro_Plano_2025_v1!B45,#REF!) -> #REF! | N45: =J45/8 -> #REF!
B46: =D46&"_"&E46 -> INSTR_PROTECTION_COD_SOC | C46: 4.4. | D46: INSTR_PROTECTION | E46: COD_SOC | I46: =J46/8/5 -> #REF! | J46: =SUMIF(#REF!,Macro_Plano_2025_v1!B46,#REF!) -> #REF! | N46: =J46/8 -> #REF!
B47: =D47&"_"&E47 -> INSTR_PROTECTION_DT_RFRNC | C47: 4.5. | D47: INSTR_PROTECTION | E47: DT_RFRNC | I47: =J47/8/5 -> #REF! | J47: =SUMIF(#REF!,Macro_Plano_2025_v1!B47,#REF!) -> #REF! | N47: =J47/8 -> #REF!
B48: =D48&"_"&E48 -> INSTR_PROTECTION_INSTRMNT_ID | C48: 4.6. | D48: INSTR_PROTECTION | E48: INSTRMNT_ID | I48: =J48/8/5 -> #REF! | J48: =SUMIF(#REF!,Macro_Plano_2025_v1!B48,#REF!) -> #REF! | N48: =J48/8 -> #REF!
B49: =D49&"_"&E49 -> INSTR_PROTECTION_PRTCTN_ID | C49: 4.7. | D49: INSTR_PROTECTION | E49: PRTCTN_ID | I49: =J49/8/5 -> #REF! | J49: =SUMIF(#REF!,Macro_Plano_2025_v1!B49,#REF!) -> #REF! | N49: =J49/8 -> #REF!
B50: =D50&"_"&E50 -> PROTECTION_COD_SOC | C50: 4.8. | D50: PROTECTION | E50: COD_SOC | I50: =J50/8/5 -> #REF! | J50: =SUMIF(#REF!,Macro_Plano_2025_v1!B50,#REF!) -> #REF! | N50: =J50/8 -> #REF!
B51: =D51&"_"&E51 -> PROTECTION_DT_RFRNC | C51: 4.9. | D51: PROTECTION | E51: DT_RFRNC | I51: =J51/8/5 -> #REF! | J51: =SUMIF(#REF!,Macro_Plano_2025_v1!B51,#REF!) -> #REF! | N51: =J51/8 -> #REF!
B52: =D52&"_"&E52 -> PROTECTION_PRTCTN_ID | C52: 4.10 | D52: PROTECTION | E52: PRTCTN_ID | I52: =J52/8/5 -> #REF! | J52: =SUMIF(#REF!,Macro_Plano_2025_v1!B52,#REF!) -> #REF! | N52: =J52/8 -> #REF!
B53: =D53&"_"&E53 -> PROTECTION_TYP_PRTCTN | C53: 4.11. | D53: PROTECTION | E53: TYP_PRTCTN | I53: =J53/8/5 -> #REF! | J53: =SUMIF(#REF!,Macro_Plano_2025_v1!B53,#REF!) -> #REF! | N53: =J53/8 -> #REF!
B54: =D54&"_"&E54 -> PROTECTION_PRTCTN_VL | C54: 4.12. | D54: PROTECTION | E54: PRTCTN_VL | I54: =J54/8/5 -> #REF! | J54: =SUMIF(#REF!,Macro_Plano_2025_v1!B54,#REF!) -> #REF! | N54: =J54/8 -> #REF!
B55: =D55&"_"&E55 -> PROTECTION_FLG_ELCTRC_VHCL | C55: 4.13. | D55: PROTECTION | E55: FLG_ELCTRC_VHCL | I55: =J55/8/5 -> #REF! | J55: =SUMIF(#REF!,Macro_Plano_2025_v1!B55,#REF!) -> #REF! | N55: =J55/8 -> #REF!
...

Sheet Lista - Âmbito Projeto GD
Y1: &
B2: DEZEMBRO | F2: ESTR | G2: GD | H2: PILAR3 | I2: GFINANCE | J2: ESG_RISKS | K2: LF | L2: Comparação com lista ATUAL | V2: Comparação com lista ATUAL | AC2: Estimativas
A3: ID Data field / Field order | B3: CONCAT | C3: Table | D3: Data field | E3: Field name | F3: Structural ECB Loan Tape | G3: Green Dashboard | H3: Pillar III ESG | I3: Green Finance | J3: ESG Risks | K3: Leveraged Finance | L3: ATUAL_Structural ECB Loan Tape | M3: val_ESTR | N3: ATUAL_Green Dashboard | O3: val_GD | P3: ATUAL_Pillar III ESG | Q3: val_PILAR3 | R3: ATUAL_Green Finance | S3: ATUAL_ESG Risks | T3: val_ESG_RISKS | U3: ATUAL_Leveraged Finance | V3: Fonte manual LF | W3: Status Data Lake | X3: Status Data Lake (Detalhe) | Y3: AMBITO | Z3: STATUS | AA3: Est anterior | AB3: format | AC3: Complexidade (todos) | AD3: Especificação | AE3: Simulação | AF3: 2. Testes comparativos | AG3: Complexidade (code list) | AH3: 3. Val. Code List | AI3: 4. Val. Formatos | AJ3: 5. Val.Controlos Corp. | AK3: Total Testes | AL3: Observações
A4: IN.001 | B4: INSTRUMENT_COD_SOC | C4: INSTRUMENT | D4: COD_SOC | E4: Entity code of the informing society. | F4: Y | G4: Y | H4: Y | I4: N | J4: Y | K4: Y | L4: Y | M4: Igual | N4: Y | O4: Igual | P4: Y | Q4: Igual | R4: n/a | S4: Y | T4: Igual | U4: n/a | V4: N | W4: n/a | X4: n/a | Y4: ESTR & GD & PILAR3 | Z4: Sem alteração | AA4: Baixa | AB4: VARCHAR2(5) | AC4: M. Baixa | AD4: 0 | AE4: 1 | AF4: 1 | AG4: n.a. | AH4: 0 | AI4: 0.5 | AJ4: 1 | AK4: 2.5
A5: IN.002 | B5: INSTRUMENT_SUBPORTFOLIO_ID | C5: INSTRUMENT | D5: SUBPORTFOLIO_ID | E5: Subportfolio ID | F5: Y | G5: Y | H5: Y | I5: N | J5: Y | K5: Y | L5: Y | M5: Igual | N5: Y | O5: Igual | P5: Y | Q5: Igual | R5: n/a | S5: Y | T5: Igual | U5: n/a | V5: N | W5: n/a | X5: n/a | Y5: ESTR & GD & PILAR3 | Z5: Sem alteração | AA5: Baixa | AB5: Code List | AC5: M. Baixa | AD5: 0 | AE5: 1 | AF5: 1 | AG5: n.a. | AH5: 0 | AI5: 0.5 | AJ5: 1 | AK5: 2.5
A6: IN.007 | B6: INSTRUMENT_DT_RFRNC | C6: INSTRUMENT | D6: DT_RFRNC | E6: Reference date | F6: Y | G6: Y | H6: Y | I6: N | J6: Y | K6: Y | L6: Y | M6: Igual | N6: Y | O6: Igual | P6: Y | Q6: Igual | R6: n/a | S6: Y | T6: Igual | U6: n/a | V6: N | W6: n/a | X6: n/a | Y6: ESTR & GD & PILAR3 | Z6: Sem alteração | AA6: Baixa | AB6: DATE | AC6: M. Baixa | AD6: 0 | AE6: 1 | AF6: 1 | AG6: n.a. | AH6: 0 | AI6: 0.5 | AJ6: 1 | AK6: 2.5
A7: IN.008 | B7: INSTRUMENT_INSTRMNT_ID | C7: INSTRUMENT | D7: INSTRMNT_ID | E7: Instrument ID | F7: Y | G7: Y | H7: Y | I7: N | J7: Y | K7: Y | L7: Y | M7: Igual | N7: Y | O7: Igual | P7: Y | Q7: Igual | R7: n/a | S7: Y | T7: Igual | U7: n/a | V7: N | W7: n/a | X7: n/a | Y7: ESTR & GD & PILAR3 | Z7: Sem alteração | AA7: Alta | AB7: VARCHAR2(60) | AC7: M. Alta | AD7: 0 | AE7: 8 | AF7: 3 | AG7: n.a. | AH7: 0 | AI7: 1 | AJ7: 2 | AK7: 6
A8: IN.020 | B8: INSTRUMENT_DFLT_STTS_INSTRMNT | C8: INSTRUMENT | D8: DFLT_STTS_INSTRMNT | E8: Default status of the instrument | F8: Y | G8: Y | H8: Y | I8: N | J8: N | K8: Y | L8: Y | M8: Igual | N8: Y | O8: Igual | P8: Y | Q8: Igual | R8: n/a | S8: N | T8: Igual | U8: n/a | V8: N | W8: n/a | X8: n/a | Y8: ESTR & GD & PILAR3 | Z8: Sem alteração | AA8: Baixa | AB8: Code List | AC8: M. Baixa | AD8: 0 | AE8: 1 | AF8: 1 | AG8: n.a. | AH8: 0 | AI8: 0.5 | AJ8: 1 | AK8: 2.5 | AL8: default
A9: IN.034 | B9: INSTRUMENT_IMPRMNT_STTS | C9: INSTRUMENT | D9: IMPRMNT_STTS | E9: Impairment status | F9: Y | G9: Y | H9: Y | I9: N | J9: N | K9: Y | L9: Y | M9: Igual | N9: Y | O9: Igual | P9: Y | Q9: Igual | R9: n/a | S9: N | T9: Igual | U9: n/a | V9: N | W9: n/a | X9: n/a | Y9: ESTR & GD & PILAR3 | Z9: Sem alteração | AA9: Baixa | AB9: Code List | AC9: M. Baixa | AD9: 0 | AE9: 1 | AF9: 1 | AG9: n.a. | AH9: 0 | AI9: 0.5 | AJ9: 1 | AK9: 2.5 | AL9: mudança de fonte ifrs
A10: IN.044 | B10: INSTRUMENT_PRFRMNG_STTS | C10: INSTRUMENT | D10: PRFRMNG_STTS | E10: Performing status | F10: Y | G10: Y | H10: Y | I10: N | J10: N | K10: Y | L10: Y | M10: Igual | N10: Y | O10: Igual | P10: Y | Q10: Igual | R10: n/a | S10: N | T10: Igual | U10: n/a | V10: N | W10: n/a | X10: n/a | Y10: ESTR & GD & PILAR3 | Z10: Sem alteração | AA10: Baixa | AB10: Code List | AC10: M. Baixa | AD10: 0 | AE10: 1 | AF10: 1 | AG10: n.a. | AH10: 0 | AI10: 0.5 | AJ10: 1 | AK10: 2.5 | AL10: mudança de fonte ifrs
A11: IN.055 | B11: INSTRUMENT_TYP_INSTRMNT | C11: INSTRUMENT | D11: TYP_INSTRMNT | E11: Type of instrument | F11: Y | G11: Y | H11: Y | I11: N | J11: N | K11: Y | L11: Y | M11: Igual | N11: Y | O11: Igual | P11: Y | Q11: Igual | R11: n/a | S11: N | T11: Igual | U11: n/a | V11: N | W11: n/a | X11: n/a | Y11: ESTR & GD & PILAR3 | Z11: Sem alteração | AA11: Baixa | AB11: Code List | AC11: M. Baixa | AD11: 0 | AE11: 1 | AF11: 1 | AG11: n.a. | AH11: 0 | AI11: 0.5 | AJ11: 1 | AK11: 2.5
A12: IN.060 | B12: INSTRUMENT_GRSS_CRRYNG_AMNT_INSTRMNT | C12: INSTRUMENT | D12: GRSS_CRRYNG_AMNT_INSTRMNT | E12: Gross carrying amount | F12: Y | G12: Y | H12: Y | I12: N | J12: Y | K12: Y | L12: Y | M12: Igual | N12: Y | O12: Igual | P12: Y | Q12: Igual | R12: n/a | S12: Y | T12: Igual | U12: n/a | V12: N | W12: n/a | X12: n/a | Y12: ESTR & GD & PILAR3 | Z12: Sem alteração | AA12: Baixa | AB12: FLOAT 2 decimal places | AC12: M. Baixa | AD12: 0 | AE12: 1 | AF12: 1 | AG12: n.a. | AH12: 0 | AI12: 0.5 | AJ12: 1 | AK12: 2.5
A13: IN.061 | B13: INSTRUMENT_ACCMLTD_CHNGS_FV_CR_INSTRMNT | C13: INSTRUMENT | D13: ACCMLTD_CHNGS_FV_CR_INSTRMNT | E13: Accumulated changes in fair value due to credit risk | F13: Y | G13: Y | H13: Y | I13: N | J13: N | K13: N | L13: Y | M13: Igual | N13: Y | O13: Igual | P13: Y | Q13: Igual | R13: n/a | S13: N | T13: Igual | U13: n/a | V13: N | W13: n/a | X13: n/a | Y13: ESTR & GD & PILAR3 | Z13: Sem alteração | AA13: Baixa | AB13: FLOAT 2 decimal places | AC13: M. Baixa | AD13: 0 | AE13: 1 | AF13: 1 | AG13: n.a. | AH13: 0 | AI13: 0.5 | AJ13: 1 | AK13: 2.5
A14: IN.062 | B14: INSTRUMENT_ACCNTNG_CLSSFCTN | C14: INSTRUMENT | D14: ACCNTNG_CLSSFCTN | E14: Accounting portfolio | F14: Y | G14: Y | H14: Y | I14: N | J14: N | K14: Y | L14: Y | M14: Igual | N14: Y | O14: Igual | P14: Y | Q14: Igual | R14: n/a | S14: N | T14: Igual | U14: n/a | V14: N | W14: n/a | X14: n/a | Y14: ESTR & GD & PILAR3 | Z14: Sem alteração | AA14: Baixa | AB14: Code List | AC14: M. Baixa | AD14: 0 | AE14: 1 | AF14: 1 | AG14: n.a. | AH14: 0 | AI14: 0.5 | AJ14: 1 | AK14: 2.5
A15: IN.065 | B15: INSTRUMENT_CCF | C15: INSTRUMENT | D15: CCF | E15: Credit conversion factor (CCF) according to CRR | F15: Y | G15: Y | H15: N | I15: N | J15: N | K15: Y | L15: Y | M15: Igual | N15: N | O15: Diferente | P15: N | Q15: Igual | R15: n/a | S15: N | T15: Igual | U15: n/a | V15: N | W15: n/a | X15: n/a | Y15: ESTR & GD | Z15: Sem alteração | AA15: Baixa | AB15: FLOAT 6 decimal places | AC15: M. Baixa | AD15: 1 | AE15: 1 | AF15: 1 | AG15: n.a. | AH15: 0 | AI15: 0.5 | AJ15: 1 | AK15: 2.5
A16: IN.074 | B16: INSTRUMENT_EAD | C16: INSTRUMENT | D16: EAD | E16: Regulatory EAD | F16: Y | G16: Y | H16: N | I16: N | J16: Y | K16: Y | L16: Y | M16: Igual | N16: N | O16: Diferente | P16: N | Q16: Igual | R16: n/a | S16: Y | T16: Igual | U16: n/a | V16: N | W16: n/a | X16: n/a | Y16: ESG_RISKS & ESTR & GD | Z16: Novo Campo | AA16: Baixa | AB16: FLOAT 2 decimal places | AC16: M. Baixa | AD16: 1 | AE16: 1 | AF16: 1 | AG16: n.a. | AH16: 0 | AI16: 0.5 | AJ16: 1 | AK16: 2.5 | AL16: Capital
A17: IN.078 | B17: INSTRUMENT_OFF_BLNC_SHT_AMNT_INSTRMNT | C17: INSTRUMENT | D17: OFF_BLNC_SHT_AMNT_INSTRMNT | E17: Off-balance sheet amount | F17: Y | G17: Y | H17: N | I17: N | J17: Y | K17: Y | L17: Y | M17: Igual | N17: Y | O17: Igual | P17: N | Q17: Igual | R17: n/a | S17: Y | T17: Igual | U17: n/a | V17: N | W17: n/a | X17: n/a | Y17: ESG_RISKS & ESTR & GD | Z17: Novo Campo | AA17: Baixa | AB17: FLOAT 2 decimal places | AC17: M. Baixa | AD17: 0 | AE17: 1 | AF17: 1 | AG17: n.a. | AH17: 0 | AI17: 0.5 | AJ17: 1 | AK17: 2.5
A18: IN.082 | B18: INSTRUMENT_PRVSNS_OFF_BLNC_SHT | C18: INSTRUMENT | D18: PRVSNS_OFF_BLNC_SHT | E18: Provisions associated with off-balance sheet exposures | F18: Y | G18: Y | H18: N | I18: N | J18: N | K18: N | L18: Y | M18: Igual | N18: Y | O18: Igual | P18: N | Q18: Igual | R18: n/a | S18: N | T18: Igual | U18: n/a | V18: N | W18: n/a | X18: n/a | Y18: ESTR & GD | Z18: Sem alteração | AA18: Baixa | AB18: FLOAT 2 decimal places | AC18: M. Baixa | AD18: 0 | AE18: 1 | AF18: 1 | AG18: n.a. | AH18: 0 | AI18: 0.5 | AJ18: 1 | AK18: 2.5
A19: IN.085 | B19: INSTRUMENT_RWA | C19: INSTRUMENT | D19: RWA | E19: RWA | F19: Y | G19: Y | H19: N | I19: N | J19: N | K19: Y | L19: Y | M19: Igual | N19: Y | O19: Igual | P19: N | Q19: Igual | R19: n/a | S19: N | T19: Igual | U19: n/a | V19: N | W19: n/a | X19: n/a | Y19: ESTR & GD | Z19: Sem alteração | AA19: Baixa | AB19: FLOAT 2 decimal places | AC19: M. Baixa | AD19: 0 | AE19: 1 | AF19: 1 | AG19: n.a. | AH19: 0 | AI19: 0.5 | AJ19: 1 | AK19: 2.5 | AL19: Capital
A20: IN.088 | B20: INSTRUMENT_ACCMLTD_IMPRMNT_INSTRMNT | C20: INSTRUMENT | D20: ACCMLTD_IMPRMNT_INSTRMNT | E20: Sum of LLPs and other allowances | F20: Y | G20: Y | H20: Y | I20: N | J20: N | K20: Y | L20: Y | M20: Igual | N20: Y | O20: Igual | P20: Y | Q20: Igual | R20: n/a | S20: N | T20: Igual | U20: n/a | V20: N | W20: n/a | X20: n/a | Y20: ESTR & GD & PILAR3 | Z20: Sem alteração | AA20: Baixa | AB20: FLOAT 2 decimal places | AC20: M. Baixa | AD20: 0 | AE20: 1 | AF20: 1 | AG20: n.a. | AH20: 0 | AI20: 0.5 | AJ20: 1 | AK20: 2.5
A21: IN.192 | B21: INSTRUMENT_COD_SOC_INTRGRP | C21: INSTRUMENT | D21: COD_SOC_INTRGRP | E21: Cargabal identification code of the intragroup exposure | F21: Y | G21: Y | H21: N | I21: N | J21: N | K21: N | L21: Y | M21: Igual | N21: Y | O21: Igual | P21: N | Q21: Igual | R21: n/a | S21: N | T21: Igual | U21: n/a | V21: N | W21: n/a | X21: n/a | Y21: ESTR & GD | Z21: Sem alteração | AA21: Baixa | AB21: VARCHAR2(5) | AC21: M. Baixa | AD21: 0 | AE21: 1 | AF21: 1 | AG21: n.a. | AH21: 0 | AI21: 0.5 | AJ21: 1 | AK21: 2.5
A22: IN.193 | B22: INSTRUMENT_LCL_INSTMRNT_ID | C22: INSTRUMENT | D22: LCL_INSTMRNT_ID | E22: Local Instrument ID | F22: Y | G22: Y | H22: Y | I22: N | J22: N | K22: N | L22: Y | M22: Igual | N22: Y | O22: Igual | P22: Y | Q22: Igual | R22: n/a | S22: N | T22: Igual | U22: n/a | V22: N | W22: n/a | X22: n/a | Y22: ESTR & GD & PILAR3 | Z22: Sem alteração | AA22: Baixa | AB22: VARCHAR2(60) | AC22: M. Baixa | AD22: 0 | AE22: 1 | AF22: 1 | AG22: n.a. | AH22: 0 | AI22: 0.5 | AJ22: 1 | AK22: 2.5
A23: IN.196 | B23: INSTRUMENT_AVRG_BLNC | C23: INSTRUMENT | D23: AVRG_BLNC | E23: Average balance | F23: N | G23: Y | H23: N | I23: N | J23: N | K23: N | L23: N | M23: Igual | N23: Y | O23: Igual | P23: N | Q23: Igual | R23: n/a | S23: N | T23: Igual | U23: n/a | V23: N | W23: n/a | X23: n/a | Y23: GD | Z23: Sem alteração | AA23: Média | AB23: FLOAT 2 decimal places | AC23: Média | AD23: 0 | AE23: 3 | AF23: 3 | AG23: n.a. | AH23: 0 | AI23: 0.5 | AJ23: 1 | AK23: 4.5
A24: IN.197 | B24: INSTRUMENT_NW_BSNSS | C24: INSTRUMENT | D24: NW_BSNSS | E24: New Business | F24: N | G24: Y | H24: Y | I24: N | J24: N | K24: N | L24: N | M24: Igual | N24: Y | O24: Igual | P24: N | Q24: Diferente | R24: n/a | S24: N | T24: Igual | U24: n/a | V24: N | W24: n/a | X24: n/a | Y24: GD & PILAR3 | Z24: Novo Campo | AA24: Média | AB24: Y, N | AC24: M. Alta | AD24: 0 | AE24: 8 | AF24: 3 | AG24: M. Alta | AH24: 1 | AI24: 1 | AJ24: 2 | AK24: 7
A25: IN.198 | B25: INSTRUMENT_GRSS_INTRST_INCM | C25: INSTRUMENT | D25: GRSS_INTRST_INCM | E25: Gross Interest income before distribution to SCIB under the Collabotarion Revenues distribution agreement | F25: N | G25: Y | H25: Y | I25: N | J25: N | K25: N | L25: N | M25: Igual | N25: Y | O25: Igual | P25: Y | Q25: Igual | R25: n/a | S25: N | T25: Igual | U25: n/a | V25: N | W25: n/a | X25: n/a | Y25: GD & PILAR3 | Z25: Sem alteração | AA25: Alta | AB25: FLOAT 2 decimal places | AC25: Alta | AD25: 0 | AE25: 6 | AF25: 6 | AG25: n.a. | AH25: 0 | AI25: 0.5 | AJ25: 1 | AK25: 7.5
A26: IN.199 | B26: INSTRUMENT_GRSS_CMMSSN_INCM | C26: INSTRUMENT | D26: GRSS_CMMSSN_INCM | E26: Gross fee and commission income before distribution to SCIB under the Collabotarion Revenues distribution agreement | F26: N | G26: Y | H26: Y | I26: N | J26: N | K26: N | L26: N | M26: Igual | N26: Y | O26: Igual | P26: Y | Q26: Igual | R26: n/a | S26: N | T26: Igual | U26: n/a | V26: N | W26: n/a | X26: n/a | Y26: GD & PILAR3 | Z26: Sem alteração | AA26: Alta | AB26: FLOAT 2 decimal places | AC26: Alta | AD26: 0 | AE26: 6 | AF26: 6 | AG26: n.a. | AH26: 0 | AI26: 0.5 | AJ26: 1 | AK26: 7.5
A27: IN.200 | B27: INSTRUMENT_INTRNL_TRNSFR_RT | C27: INSTRUMENT | D27: INTRNL_TRNSFR_RT | E27: Internal transfer rate amount | F27: N | G27: Y | H27: N | I27: N | J27: N | K27: N | L27: N | M27: Igual | N27: Y | O27: Igual | P27: N | Q27: Igual | R27: n/a | S27: N | T27: Igual | U27: n/a | V27: N | W27: n/a | X27: n/a | Y27: GD | Z27: Sem alteração | AA27: Alta | AB27: FLOAT 2 decimal places | AC27: Média | AD27: 0 | AE27: 3 | AF27: 3 | AG27: n.a. | AH27: 0 | AI27: 0.5 | AJ27: 1 | AK27: 4.5
A28: IN.201 | B28: INSTRUMENT_NT_LN_LSS_PRVSN | C28: INSTRUMENT | D28: NT_LN_LSS_PRVSN | E28: Net loan-loss provisions | F28: N | G28: Y | H28: N | I28: N | J28: N | K28: N | L28: N | M28: Igual | N28: Y | O28: Igual | P28: N | Q28: Igual | R28: n/a | S28: N | T28: Igual | U28: n/a | V28: N | W28: n/a | X28: n/a | Y28: GD | Z28: Sem alteração | AA28: Média | AB28: FLOAT 2 decimal places | AC28: Média | AD28: 0 | AE28: 3 | AF28: 3 | AG28: n.a. | AH28: 0 | AI28: 0.5 | AJ28: 1 | AK28: 4.5
A29: IN.202 | B29: INSTRUMENT_BSNSS_AREA | C29: INSTRUMENT | D29: BSNSS_AREA | E29: Business Area | F29: N | G29: Y | H29: N | I29: N | J29: N | K29: N | L29: N | M29: Igual | N29: Y | O29: Igual | P29: N | Q29: Igual | R29: n/a | S29: N | T29: Igual | U29: n/a | V29: N | W29: n/a | X29: n/a | Y29: GD | Z29: Sem alteração | AA29: Alta | AB29: Code List | AC29: Alta | AD29: 0 | AE29: 6 | AF29: 6 | AG29: Alta | AH29: 0.5 | AI29: 0.5 | AJ29: 1 | AK29: 8
A30: IN.203 | B30: INSTRUMENT_MNGMNT_PRDCT | C30: INSTRUMENT | D30: MNGMNT_PRDCT | E30: Management Product | F30: N | G30: Y | H30: N | I30: N | J30: N | K30: N | L30: N | M30: Igual | N30: Y | O30: Igual | P30: N | Q30: Igual | R30: n/a | S30: N | T30: Igual | U30: n/a | V30: N | W30: n/a | X30: n/a | Y30: GD | Z30: Sem alteração | AA30: Média | AB30: Code List | AC30: Alta | AD30: 0 | AE30: 6 | AF30: 6 | AG30: Alta | AH30: 0.5 | AI30: 0.5 | AJ30: 1 | AK30: 8
A31: IN.204 | B31: INSTRUMENT_GRSS_CMMSSN_EXPNS | C31: INSTRUMENT | D31: GRSS_CMMSSN_EXPNS | E31: Gross fee and commission expense before distribution to SCIB under the Collabotarion Revenues distribution agreement | F31: N | G31: Y | H31: N | I31: N | J31: N | K31: N | L31: N | M31: Igual | N31: Y | O31: Igual | P31: N | Q31: Igual | R31: n/a | S31: N | T31: Igual | U31: n/a | V31: N | W31: n/a | X31: n/a | Y31: GD | Z31: Sem alteração | AA31: Alta | AB31: FLOAT 2 decimal places | AC31: Média | AD31: 0 | AE31: 3 | AF31: 3 | AG31: n.a. | AH31: 0 | AI31: 0.5 | AJ31: 1 | AK31: 4.5
... A52: IN.233 | B52: INSTRUMENT_CNCLLD_INSTRMNT_STTS | C52: INSTRUMENT | D52: CNCLLD_INSTRMNT_STTS | E52: Cancelled instrument status | F52: N | G52: Y | H52: N | I52: N | J52: N | K52: N | L52: N | M52: Igual | N52: Y | O52: Igual | P52: N | Q52: Igual | R52: n/a | S52: N | T52: Igual | U52: n/a | V52: N | W52: n/a | X52: n/a | Y52: GD | Z52: Sem alteração | AA52: Alta | AB52: Code List | AC52: Média | AD52: 0 | AE52: 3 | AF52: 3 | AG52: Média | AH52: 0.5 | AI52: 0.5 | AJ52: 1 | AK52: 5
A53: IN.234 | B53: INSTRUMENT_IDCMB | C53: INSTRUMENT | D53: IDCMB | E53: IDCOMB | F53: Y | G53: Y | H53: Y | I53: N | J53: Y | K53: Y | L53: Y | M53: Igual | N53: Y | O53: Igual | P53: Y | Q53: Igual | R53: n/a | S53: Y | T53: Igual | U53: n/a | V53: N | W53: n/a | X53: n/a | Y53: ESTR & GD & PILAR3 | Z53: Sem alteração | AA53: Baixa | AB53: VARCHAR2(255) | AC53: M. Baixa | AD53: 0 | AE53: 1 | AF53: 1 | AG53: n.a. | AH53: 0 | AI53: 0.5 | AJ53: 1 | AK53: 2.5 | AL53: Contabilidade
A54: IN.247 | B54: INSTRUMENT_TYP_OFF_BLNC_PRDCT | C54: INSTRUMENT | D54: TYP_OFF_BLNC_PRDCT | E54: Type of off balance product | F54: Y | G54: Y | H54: Y | I54: N | J54: N | K54: Y | L54: Novo | M54: Novo Campo | N54: Novo | O54: Novo Campo | P54: Novo | Q54: Novo Campo | R54: n/a | S54: Novo | T54: Novo Campo | U54: n/a | V54: N | W54: n/a | X54: n/a | Y54: ESTR & GD & PILAR3 | Z54: Novo Campo | AA54: Média | AB54: Code List | AC54: M. Baixa | AD54: 1 | AE54: 1 | AF54: 1 | AG54: M. Baixa | AH54: 0.5 | AI54: 0.5 | AJ54: 1 | AK54: 3
A55: IP.001 | B55: INSTR_PROTECTION_COD_SOC | C55: INSTR_PROTECTION | D55: COD_SOC | E55: Entity code of the informing society. | F55: Y | G55: Y | H55: Y | I55: N | J55: N | K55: N | L55: Y | M55: Igual | N55: N | O55: Diferente | P55: Y | Q55: Igual | R55: n/a | S55: N | T55: Igual | U55: n/a | V55: N | W55: n/a | X55: n/a | Y55: ESTR & GD & PILAR3 | Z55: Sem alteração | AA55: Baixa | AB55: VARCHAR2(5) | AC55: M. Baixa | AD55: 1 | AE55: 1 | AF55: 1 | AG55: n.a. | AH55: 0 | AI55: 0.5 | AJ55: 1 | AK55: 2.5
A56: IP.002 | B56: INSTR_PROTECTION_DT_RFRNC | C56: INSTR_PROTECTION | D56: DT_RFRNC | E56: Reference date | F56: Y | G56: Y | H56: Y | I56: N | J56: N | K56: N | L56: Y | M56: Igual | N56: N | O56: Diferente | P56: Y | Q56: Igual | R56: n/a | S56: N | T56: Igual | U56: n/a | V56: N | W56: n/a | X56: n/a | Y56: ESTR & GD & PILAR3 | Z56: Sem alteração | AA56: Baixa | AB56: DATE | AC56: M. Baixa | AD56: 1 | AE56: 1 | AF56: 1 | AG56: n.a. | AH56: 0 | AI56: 0.5 | AJ56: 1 | AK56: 2.5
A57: IP.003 | B57: INSTR_PROTECTION_INSTRMNT_ID | C57: INSTR_PROTECTION | D57: INSTRMNT_ID | E57: Instrument ID | F57: Y | G57: Y | H57: Y | I57: N | J57: N | K57: N | L57: Y | M57: Igual | N57: N | O57: Diferente | P57: Y | Q57: Igual | R57: n/a | S57: N | T57: Igual | U57: n/a | V57: N | W57: n/a | X57: n/a | Y57: ESTR & GD & PILAR3 | Z57: Sem alteração | AA57: Baixa | AB57: VARCHAR2(60) | AC57: M. Baixa | AD57: 1 | AE57: 1 | AF57: 1 | AG57: n.a. | AH57: 0 | AI57: 0.5 | AJ57: 1 | AK57: 2.5
A58: IP.004 | B58: INSTR_PROTECTION_PRTCTN_ID | C58: INSTR_PROTECTION | D58: PRTCTN_ID | E58: Protection ID | F58: Y | G58: Y | H58: Y | I58: N | J58: N | K58: N | L58: Y | M58: Igual | N58: N | O58: Diferente | P58: Y | Q58: Igual | R58: n/a | S58: N | T58: Igual | U58: n/a | V58: N | W58: n/a | X58: n/a | Y58: ESTR & GD & PILAR3 | Z58: Sem alteração | AA58: Baixa | AB58: VARCHAR2(60) | AC58: M. Baixa | AD58: 1 | AE58: 1 | AF58: 1 | AG58: n.a. | AH58: 0 | AI58: 0.5 | AJ58: 1 | AK58: 2.5
A59: IP.007 | B59: INSTR_PROTECTION_TYP_RLTN | C59: INSTR_PROTECTION | D59: TYP_RLTN | E59: Type of relation | F59: N | G59: Y | H59: Y | I59: N | J59: N | K59: N | L59: Novo | M59: Novo Campo | N59: Novo | O59: Novo Campo | P59: Novo | Q59: Novo Campo | R59: n/a | S59: Novo | T59: Novo Campo | U59: n/a | V59: N | W59: n/a | X59: n/a | Y59: GD & PILAR3 | Z59: Novo Campo | AA59: Alta | AB59: Code List | AC59: M. Baixa | AD59: 0 | AE59: 1 | AF59: 1 | AG59: M. Baixa | AH59: 0.5 | AI59: 0.5 | AJ59: 1 | AK59: 3
A60: PR.001 | B60: PROTECTION_COD_SOC | C60: PROTECTION | D60: COD_SOC | E60: Entity code of the informing society. | F60: Y | G60: Y | H60: Y | I60: N | J60: Y | K60: N | L60: Y | M60: Igual | N60: N | O60: Diferente | P60: Y | Q60: Igual | R60: n/a | S60: Y | T60: Igual | U60: n/a | V60: N | W60: n/a | X60: n/a | Y60: ESTR & GD & PILAR3 | Z60: Sem alteração | AA60: Baixa | AB60: VARCHAR2(5) | AC60: M. Baixa | AD60: 1 | AE60: 1 | AF60: 1 | AG60: n.a. | AH60: 0 | AI60: 0.5 | AJ60: 1 | AK60: 2.5
...

Sheet Aux
F3: 527 | H3: 15 | I3: 178.5 | O3: 285.5 | Q3: 527 | R3: 364 | S3: 163
B4: CONCAT | C4: Table | D4: Data field | E4: Est anterior | F4: Est anterior | G4: Complexidade (todos) | H4: Especificação | I4: Simulação | J4: 2. Testes comparativos | K4: Complexidade (code list) | L4: 3. Val. Code List | M4: 4. Val. Formatos | N4: 5. Val.Controlos Corp. | O4: Total Testes | P4: Cenário | Q4: Tempo SC1 | R4: Tempo SC B1 | S4: Tempo SC B2 | T4: Flg Concluído
B5: INSTRUMENT_COD_SOC | C5: INSTRUMENT | D5: COD_SOC | E5: Baixa | F5: 2 | G5: M. Baixa | H5: 0 | I5: 1 | J5: 1 | K5: n.a. | L5: 0 | M5: 0.5 | N5: 1 | O5: 2.5 | P5: SCA SCB1 | Q5: 2 | R5: 2 | S5: 0 | T5: Y
B6: INSTRUMENT_SUBPORTFOLIO_ID | C6: INSTRUMENT | D6: SUBPORTFOLIO_ID | E6: Baixa | F6: 2 | G6: M. Baixa | H6: 0 | I6: 1 | J6: 1 | K6: n.a. | L6: 0 | M6: 0.5 | N6: 1 | O6: 2.5 | P6: SCA SCB1 | Q6: 2 | R6: 2 | S6: 0 | T6: Y
B7: INSTRUMENT_DT_RFRNC | C7: INSTRUMENT | D7: DT_RFRNC | E7: Baixa | F7: 2 | G7: M. Baixa | H7: 0 | I7: 1 | J7: 1 | K7: n.a. | L7: 0 | M7: 0.5 | N7: 1 | O7: 2.5 | P7: SCA SCB1 | Q7: 2 | R7: 2 | S7: 0 | T7: Y
B8: INSTRUMENT_INSTRMNT_ID | C8: INSTRUMENT | D8: INSTRMNT_ID | E8: Alta | F8: 25.2 | G8: M. Alta | H8: 0 | I8: 12 | J8: 3 | K8: n.a. | L8: 0 | M8: 1 | N8: 2 | O8: 10 | P8: SCA SCB1 | Q8: 25.2 | R8: 25.2 | S8: 0 | T8: N
B9: INSTRUMENT_DFLT_STTS_INSTRMNT | C9: INSTRUMENT | D9: DFLT_STTS_INSTRMNT | E9: Baixa | F9: 2 | G9: M. Baixa | H9: 0 | I9: 1 | J9: 1 | K9: n.a. | L9: 0 | M9: 0.5 | N9: 1 | O9: 2.5 | P9: SCA SCB1 | Q9: 2 | R9: 2 | S9: 0 | T9: Y
B10: INSTRUMENT_IMPRMNT_STTS | C10: INSTRUMENT | D10: IMPRMNT_STTS | E10: Baixa | F10: 2 | G10: M. Baixa | H10: 0 | I10: 1 | J10: 1 | K10: n.a. | L10: 0 | M10: 0.5 | N10: 1 | O10: 2.5 | P10: SCA SCB1 | Q10: 2 | R10: 2 | S10: 0 | T10: Y
B11: INSTRUMENT_PRFRMNG_STTS | C11: INSTRUMENT | D11: PRFRMNG_STTS | E11: Baixa | F11: 2 | G11: M. Baixa | H11: 0 | I11: 1 | J11: 1 | K11: n.a. | L11: 0 | M11: 0.5 | N11: 1 | O11: 2.5 | P11: SCA SCB1 | Q11: 2 | R11: 2 | S11: 0 | T11: Y
B12: INSTRUMENT_TYP_INSTRMNT | C12: INSTRUMENT | D12: TYP_INSTRMNT | E12: Baixa | F12: 2 | G12: M. Baixa | H12: 0 | I12: 1 | J12: 1 | K12: n.a. | L12: 0 | M12: 0.5 | N12: 1 | O12: 2.5 | P12: SCA SCB1 | Q12: 2 | R12: 2 | S12: 0 | T12: Y
B13: INSTRUMENT_GRSS_CRRYNG_AMNT_INSTRMNT | C13: INSTRUMENT | D13: GRSS_CRRYNG_AMNT_INSTRMNT | E13: Baixa | F13: 2 | G13: M. Baixa | H13: 0 | I13: 1 | J13: 1 | K13: n.a. | L13: 0 | M13: 0.5 | N13: 1 | O13: 2.5 | P13: SCA SCB1 | Q13: 2 | R13: 2 | S13: 0 | T13: Y
B14: INSTRUMENT_ACCMLTD_CHNGS_FV_CR_INSTRMNT | C14: INSTRUMENT | D14: ACCMLTD_CHNGS_FV_CR_INSTRMNT | E14: Baixa | F14: 2 | G14: M. Baixa | H14: 0 | I14: 1 | J14: 1 | K14: n.a. | L14: 0 | M14: 0.5 | N14: 1 | O14: 2.5 | P14: SCA SCB1 | Q14: 2 | R14: 2 | S14: 0 | T14: Y
B15: INSTRUMENT_ACCNTNG_CLSSFCTN | C15: INSTRUMENT | D15: ACCNTNG_CLSSFCTN | E15: Baixa | F15: 2 | G15: M. Baixa | H15: 0 | I15: 1 | J15: 1 | K15: n.a. | L15: 0 | M15: 0.5 | N15: 1 | O15: 2.5 | P15: SCA SCB1 | Q15: 2 | R15: 2 | S15: 0 | T15: Y
B16: INSTRUMENT_CCF | C16: INSTRUMENT | D16: CCF | E16: Baixa | F16: 2 | G16: M. Baixa | H16: 1 | I16: 1 | J16: 1 | K16: n.a. | L16: 0 | M16: 0.5 | N16: 1 | O16: 2.5 | P16: SCA SCB1 | Q16: 2 | R16: 2 | S16: 0 | T16: N
... B72: INSTR_ACTIVITY_SSTNBL_INDCTR | C72: INSTR_ACTIVITY | D72: SSTNBL_INDCTR | E72: Alta | F72: 18.1 | G72: Alta | H72: 0 | I72: 8 | J72: 1.5 | K72: Baixa | L72: 0.5 | M72: 0.5 | N72: 1 | O72: 10 | P72: SCA SCB 2 | Q72: 18.1 | R72: 0 | S72: 18.1 | T72: N

Sheet Férias
C6: F | D6: Férias | L6: Saldo | N6: por marcar | Q6: Aniversário
C7: F1 | D7: Férias 2024 | I7: Filipa Carreira | L7: 2x | N7: 2x | Q7: 45814
C8: A | D8: Aniversário | I8: Rita Matias | L8: =22+4 -> 26 | N8: 22 | Q8: 45814
D9: Fim de semana
D10: Feriado
Q13: Janeiro
C14: 45659 | D14: =C14+1 -> 45660 | E14: =D14+1 -> 45661 | F14: =E14+1 -> 45662 | G14: =F14+1 -> 45663 | H14: =G14+1 -> 45664 | I14: =H14+1 -> 45665 | J14: =I14+1 -> 45666 | K14: =J14+1 -> 45667 | ... AF14: =AE14+1 -> 45688
B16: Filipa Carreira
B17: Rita Matias
P19: Fevereiro
C20: 45689 | D20: =C20+1 -> 45690 | E20: =D20+1 -> 45691 | F20: =E20+1 -> 45692 | G20: =F20+1 -> 45693 | H20: =G20+1 -> 45694 | I20: =H20+1 -> 45695 | J20: =I20+1 -> 45696 | K20: =J20+1 -> 45697 | ... AD20: =AC20+1 -> 45716
B22: Filipa Carreira | AD22: F
B23: Rita Matias
Q25: Março
C26: 45717 | D26: =+C26+1 -> 45718 | E26: =+D26+1 -> 45719 | F26: =+E26+1 -> 45720 | G26: =+F26+1 -> 45721 | H26: =+G26+1 -> 45722 | I26: =+H26+1 -> 45723 | J26: =+I26+1 -> 45724 | K26: =+J26+1 -> 45725 | ... AG26: =+AF26+1 -> 45747
B28: Filipa Carreira | E28: F | G28: F | H28: F | I28: F | L28: F | M28: F | N28: F | O28: F | P28: F
B29: Rita Matias
