Workbook
Name \a: #REF!
Name \b: #REF!
Name \c: #REF!
Name \d: #REF!
Name \e: #REF!
Name \m: #REF!
Name \p: #REF!
Name \q: #REF!
Name \s: #REF!
Name \v: #REF!
Name ___GRUPO_ENVIO: [1]GENMASIVA!$AC$4
Name ___INDEX_SHEET___ASAP_Utilities: #REF!
Name ___PERIODO: [1]GENMASIVA!$AC$2
Name ___td2: #REF!
Name ___td3: #REF!
Name ___td4: #REF!
Name ___ti1: #REF!
Name ___ti2: #REF!
Name ___ti3: #REF!
Name ___ti4: #REF!
Name ___tp1: #REF!
Name ___tp2: #REF!
Name ___tp3: #REF!
Name ___tp4: #REF!
Name __td1: #REF!
Name __td2: #REF!
Name __td3: #REF!
Name __td4: #REF!
Name __ti1: #REF!
Name __ti2: #REF!
Name __ti3: #REF!
Name __ti4: #REF!
Name __tp1: #REF!
Name __tp2: #REF!
Name __tp3: #REF!
Name __tp4: #REF!
Name _1: #REF!
Name _1_.1205_A_Automaticos: #REF!
Name _1detmar97acu: #REF!
Name _2_.1205_A_Manual: #REF!
Name _2detmar97acu: #REF!
Name _3_.1205_S: #REF!
Name _56101501880000: #REF!
Name _5detmar97acu: #REF!
Name _col010_iNdEx_4: #REF!
Name _col020_iNdEx_5: #REF!
Name _col030_iNdEx_6: #REF!
Name _col040_iNdEx_7: #REF!
Name _col050_iNdEx_8: #REF!
Name _col060_iNdEx_9: #REF!
Name _col070_iNdEx_10: #REF!
Name _col080_iNdEx_11: #REF!
Name _col090_iNdEx_12: #REF!
Name _col100_iNdEx_13: #REF!
Name _col110_iNdEx_14: #REF!
Name _col120_iNdEx_15: #REF!
Name _col130_iNdEx_16: #REF!
Name _col140_iNdEx_17: #REF!
Name _col150_iNdEx_18: #REF!
Name _col160_iNdEx_19: #REF!

Sheet Index
B6: Variáveis
C9: Variável | D9: Valor | E9: Comentário
C11: CRE_RRE | D11: Habitacao | E11: Valor para identificar o universo de Mortgages Loans
D12: Habitacao - MISS | E12: Valor para identificar o universo de Mortgages Loans (Bens associados a financiamentos onde não foi possível calcular qualquer emissão)
D13: CRE_OUTRO | E13: Valor para identificar o universo de Commercial Real Estate
D14: CRE_OUTRO - MISS | E14: Valor para identificar o universo de Commercial Real Estate (Bens associados a financiamentos onde não foi possível calcular qualquer emissão)
D15: CRE_OUTRO - Nao Aplicavel | E15: Valor para identificar o universo de Mortgages Loans (Bens associados a financiamentos onde o cliente detém uma atividade económica que não se enquadra nos setores aplicáveis)
D16: CRE_FC | E16: Valor para identificar o universo de Financiamentos para Construção (FC)
C17: TIPOLOGIA_CERTIFICADO | D17: Certificado Real | E17: Valor para identificar a categora da letra do certificado energético
D18: Certificado Estimado | E18: Valor para identificar a categora da letra do certificado energético
D19: Sem Certificado | E19: Valor para identificar a categora da letra do certificado energético
C20: EPC | D20: A+ | E20: Letra A+ do Certificado Energético
D21: A | E21: Letra A do Certificado Energético
D22: B | E22: Letra B do Certificado Energético
D23: B- | E23: Letra B- do Certificado Energético
D24: C | E24: Letra C do Certificado Energético
D25: D | E25: Letra D do Certificado Energético
D26: E | E26: Letra E do Certificado Energético
D27: F | E27: Letra F do Certificado Energético
D28: G | E28: Letra G do Certificado Energético
C29: ORIGEM_SCP1_EMSS & ORIGEM_SCP2_EMSS | D29: RE_DQS3_2A | E29: Metodologia de cálculo Data Quality Score 3
D30: RE_DQS4_2B | E30: Metodologia de cálculo Data Quality Score 4
D31: RE_DQS5_3 | E31: Metodologia de cálculo Data Quality Score 5
D32: MISS | E32: Valor de Missing Value
D33: Nao Aplicavel | E33: Valor de Não Aplicável
C34: FINALIDADE_BEM | D34: 01 | E34: Habitação
D35: 02 | E35: Comércio
D36: 03 | E36: Escritório
D37: 04 | E37: Armazém
D38: 05 | E38: Indústria
D39: 06 | E39: Estacionamento
D40: 07 | E40: Garagem
D41: 08 | E41: Outras
D42: 09 | E42: Hotel
D43: 10 | E43: Educação
D44: 11 | E44: Saúde
D45: 12 | E45: Lazer
D46: 13 | E46: Agricultura
D47: 14 | E47: Centro Comercial
D48: Sem informação | E48: Sem informação
...

Sheet Input
B6: Input
C9: cre_rre | D9: finalidade_bem | E9: epc | F9: tipologia_certificado | G9: area_ponderada | H9: origem_scp1_emss | I9: origem_scp2_emss | J9: emissao_scp1 | K9: emissao_scp2 | L9: emissao | M9: tipologia_montante | N9: amount | O9: ref_date

Sheet Capa
B18: =TODAY() -> 46043

Sheet Pressupostos
B6: Pressupostos
C8: A tabela infra apresenta os pressupostos considerados para o cálculo das emissões financiadas em âmbito de Portfolio Alignment:
C10: Tópico | D10: Pressupostos
C11: Granularidade de reporte | D11: Considerar granularidade ao nível do Bem Imóvel.
C12: Universo | D12: Considerar universo corporativo, cuja a exposição se encontre associada a um contrato com classificação específica CRE (considerando apenas operçaões cuja contraparte seja uma empresa que possua CCAE 41.10, 55.11 e 58) ou Habitação e que possua, pelo menos, uma garantia imobiliário associada.
D13: Considerar todas as exposições CRE (via classificação da classificação do empréstimo combinado com a classificação do propósito do bem imóvel), exceto operações de financiamento à construção.
D14: Considerar todas as exposições mortgage (via classificação do propósito do empréstimo combinado com a classificação do propósito do bem imóvel), incluíndo operações de financiamento à construção.
D15: Considerar país como Portugal para todo o universo de bens imóveis.
C16: Cálculo das emissões financiadas | D16: Considerar, em caso de ausência de informação relativa às características dos bens necessárias para aplicação de determinada metologia de cálculo, uma metodologia de data quality score mais conservadora.
D17: Desconsiderar valores de EPC fora dos definidos pelo input corporativo, será adotada uma metodologia de data quality score mais conservadora, sempre que possível o cruzamento com finalidade do bem.
D18: Desconsiderar cálculo das emissões sempre que não é possível efetuar cruzamento com as características definidas pelo input corporativo.
D19: Considerar, em caso aplicável, o fator de emissão associado ao ano mais recente presente no input corporativo.
D20: Garantir que o quociente entre o montante em dívida do contrato e o valor do imóvel na originação assume, no máximo, o valor 1.
C21: Outstanding amount | D21: Considerar o valor bruto atual do empréstimo (gross carrying amount).
C22: Property value at origination | D22: Considerar o valor total do imóvel ('preço_aquisição') no momento da transação e, quando não for possível, considerar uma das seguintes alternativas: - Montante de avaliação do bem ('mavalia'); - Montante de avaliação do bem rateado ('mavaliaa').
D23: Desconsiderar o valor total do imóvel quando este é igual a 0, passando supletivamente para o montante de avaliação do bem.
C24: Classificação da finalidade do bem | D24: Considerar, para a classificação de CRE/Mortgage, o campos de finalidade do bem ('property_purpose_code') e descritivo da garantia ('property_code').
D25: Considerar, para a classificação de CRE/Mortgage, nos casos em que a finalidade do bem corresponde a outras ('property_purpose_code' = 08), o código da garantia associado ao bem ('cgarant_bem').
D26: Considerar todas as exposições CRE/Mortgage, sem ter em conta o fator de geração de rendimento.
D27: Revisitar, em cada data de reporte, o mapeamento da finalidade dado que os inputs corporativos poderão alterar os valores admissíveis e/ou poderá ser adicionada ou alterado algum código de finalidade das tabelas do banco (este mapeamento será do ownership da área responsável pela tabela de modesg_out_bens_imoveis).

Sheet Overview - Emissões 
B6: Sumário Executivo
C8: O quadro infra apresenta o valor da exposição (€) e emissões (tCO2e):
D9: CRE
C10: Setor | D10: Valor bruto (€) | E10: Valor bruto (%) | F10: Emissões Financiadas (tCO2e)
A11: CTO_IMO
A12: CRE_OUTRO | C12: Commercial Real Estate (CRE) | D12: =+SUMIFS(Input!N:N,Input!C:C,Index!D13) -> 0 | E12: =+D12/$D$16 -> #DIV/0! | F12: =+SUMIFS(Input!L:L,Input!C:C,Index!D13) -> 0
A13: Habitacao | C13: Mortgages Loans | D13: =+SUMIFS(Input!N:N,Input!C:C,Index!D11) -> 0 | E13: =+D13/$D$16 -> #DIV/0! | F13: =+SUMIFS(Input!L:L,Input!C:C,Index!D11) -> 0
A14: CRE_FC | C14: Financiamentos para Construção (FC) | D14: =+SUMIFS(Input!N:N,Input!C:C,Index!D16) -> 0 | E14: =+D14/$D$16 -> #DIV/0! | F14: =+SUMIFS(Input!L:L,Input!C:C,Index!D16) -> 0
C15: Fora de âmbito do cálculo | D15: =+SUMIFS(Input!N:N,Input!C:C,Index!D12)+SUMIFS(Input!N:N,Input!C:C,Index!D14) -> 0 | E15: =+D15/$D$16 -> #DIV/0! | F15: =+SUMIFS(Input!L:L,Input!C:C,Index!D12)+SUMIFS(Input!L:L,Input!C:C,Index!D14) -> 0
C16: Total | D16: =+D14+D13+D12+D15 -> 0 | E16: =+E12+E13+E14 -> #DIV/0! | F16: =+F14+F13+F12 -> 0
C19: Resumo Global
C21: Setor | D21: Valor bruto (€) | E21: Scope de Emissões | F21: Emissões Financiadas (tCO2e) | G21: Physical Emission Intensity (kgCO2e/m2) | H21: Economic Emission Intensity (tCO2e/€M) | I21: PCAF Score
C23: Commercial Real Estate (CRE) | D23: =+D12 -> 0 | E23: 1+2 | F23: =+F12 -> 0 | G23: =+('3. Área Ponderada'!D13+'3. Área Ponderada'!D14)*1000/'3. Área Ponderada'!F12 -> #DIV/0! | H23: =+F23/(D23/1000000) -> #DIV/0! | I23: =+('3. Área Ponderada'!D13*3+'3. Área Ponderada'!D14*4+'3. Área Ponderada'!D15*5)/'3. Área Ponderada'!D12 -> #DIV/0!
C24: Mortgages Loans | D24: =+D13 -> 0 | E24: 1+2 | F24: =+F13 -> 0 | G24: =+('3. Área Ponderada'!D17+'3. Área Ponderada'!D18)*1000/'3. Área Ponderada'!F16 -> #DIV/0! | H24: =+F24/(D24/1000000) -> #DIV/0! | I24: =+('3. Área Ponderada'!D17*3+'3. Área Ponderada'!D18*4+'3. Área Ponderada'!D19*5)/'3. Área Ponderada'!D16 -> #DIV/0!
C25: Total | D25: =SUM(D23:D24) -> 0 | F25: =SUM(F23:F24) -> 0

Sheet 1. EPC - Commercial Real Estate
B6: 1. Certificados Energéticos - Commercial Real Estate
C8: O quadro infra apresenta a distribuição das letras dos Certificados Energético do Banco, de acordo com a metodologia PCAF Score 3.
C10: EPC | D10: Valor bruto (€) | E10: Valor bruto (%) | F10: Emissões Financiadas (tCO2e)
C12: Data Quality Score 3
C13: Certificado Energético Real | D13: =+SUM(D14:D22) -> 0 | E13: =+SUM(E14:E22) -> #DIV/0! | F13: =+SUM(F14:F22) -> 0
C14: Letra A+ | D14: =+SUMIFS(Input!$N:$N,Input!$C:$C,Index!$D$13,Input!$H:$H,Index!$D$29,Input!$F:$F,Index!$D$17,Input!$E:$E,Index!D20) -> 0 | E14: =+D14/$D$13 -> #DIV/0! | F14: =+SUMIFS(Input!$L:$L,Input!$C:$C,Index!$D$13,Input!$H:$H,Index!$D$29,Input!$F:$F,Index!$D$17,Input!$E:$E,Index!D20) -> 0
C15: Letra A | D15: =+SUMIFS(Input!$N:$N,Input!$C:$C,Index!$D$13,Input!$H:$H,Index!$D$29,Input!$F:$F,Index!$D$17,Input!$E:$E,Index!D21) -> 0 | E15: =+D15/$D$13 -> #DIV/0! | F15: =+SUMIFS(Input!$L:$L,Input!$C:$C,Index!$D$13,Input!$H:$H,Index!$D$29,Input!$F:$F,Index!$D$17,Input!$E:$E,Index!D21) -> 0
C16: Letra B | D16: =+SUMIFS(Input!$N:$N,Input!$C:$C,Index!$D$13,Input!$H:$H,Index!$D$29,Input!$F:$F,Index!$D$17,Input!$E:$E,Index!D22) -> 0 | E16: =+D16/$D$13 -> #DIV/0! | F16: =+SUMIFS(Input!$L:$L,Input!$C:$C,Index!$D$13,Input!$H:$H,Index!$D$29,Input!$F:$F,Index!$D$17,Input!$E:$E,Index!D22) -> 0
C17: Letra B- | D17: =+SUMIFS(Input!$N:$N,Input!$C:$C,Index!$D$13,Input!$H:$H,Index!$D$29,Input!$F:$F,Index!$D$17,Input!$E:$E,Index!D23) -> 0 | E17: =+D17/$D$13 -> #DIV/0! | F17: =+SUMIFS(Input!$L:$L,Input!$C:$C,Index!$D$13,Input!$H:$H,Index!$D$29,Input!$F:$F,Index!$D$17,Input!$E:$E,Index!D23) -> 0
C18: Letra C | D18: =+SUMIFS(Input!$N:$N,Input!$C:$C,Index!$D$13,Input!$H:$H,Index!$D$29,Input!$F:$F,Index!$D$17,Input!$E:$E,Index!D24) -> 0 | E18: =+D18/$D$13 -> #DIV/0! | F18: =+SUMIFS(Input!$L:$L,Input!$C:$C,Index!$D$13,Input!$H:$H,Index!$D$29,Input!$F:$F,Index!$D$17,Input!$E:$E,Index!D24) -> 0
C19: Letra D | D19: =+SUMIFS(Input!$N:$N,Input!$C:$C,Index!$D$13,Input!$H:$H,Index!$D$29,Input!$F:$F,Index!$D$17,Input!$E:$E,Index!D25) -> 0 | E19: =+D19/$D$13 -> #DIV/0! | F19: =+SUMIFS(Input!$L:$L,Input!$C:$C,Index!$D$13,Input!$H:$H,Index!$D$29,Input!$F:$F,Index!$D$17,Input!$E:$E,Index!D25) -> 0
C20: Letra E | D20: =+SUMIFS(Input!$N:$N,Input!$C:$C,Index!$D$13,Input!$H:$H,Index!$D$29,Input!$F:$F,Index!$D$17,Input!$E:$E,Index!D26) -> 0 | E20: =+D20/$D$13 -> #DIV/0! | F20: =+SUMIFS(Input!$L:$L,Input!$C:$C,Index!$D$13,Input!$H:$H,Index!$D$29,Input!$F:$F,Index!$D$17,Input!$E:$E,Index!D26) -> 0
C21: Letra F | D21: =+SUMIFS(Input!$N:$N,Input!$C:$C,Index!$D$13,Input!$H:$H,Index!$D$29,Input!$F:$F,Index!$D$17,Input!$E:$E,Index!D27) -> 0 | E21: =+D21/$D$13 -> #DIV/0! | F21: =+SUMIFS(Input!$L:$L,Input!$C:$C,Index!$D$13,Input!$H:$H,Index!$D$29,Input!$F:$F,Index!$D$17,Input!$E:$E,Index!D27) -> 0
C22: Letra G | D22: =+SUMIFS(Input!$N:$N,Input!$C:$C,Index!$D$13,Input!$H:$H,Index!$D$29,Input!$F:$F,Index!$D$17,Input!$E:$E,Index!D28) -> 0 | E22: =+D22/$D$13 -> #DIV/0! | F22: =+SUMIFS(Input!$L:$L,Input!$C:$C,Index!$D$13,Input!$H:$H,Index!$D$29,Input!$F:$F,Index!$D$17,Input!$E:$E,Index!D28) -> 0
C23: Total | D23: =+D13 -> 0 | E23: =+E13 -> #DIV/0! | F23: =+F13 -> 0
C25: O quadro infra apresenta a distribuição das letras dos Certificados Energético do Banco, de acordo com a metodologia PCAF Score 4.
C26: ▪ Denote-se que estas letras dos Certificados Energéticos não são utilizadas para apurar o fator de emissão do imóvel.
C28: EPC | D28: Valor bruto (€) | E28: Valor bruto (%) | F28: Emissões Financiadas (tCO2e)
C30: Data Quality Score 4
C31: Certificado Energético Real | D31: =+SUM(D32:D40) -> 0 | E31: =+D31/$D$52 -> #DIV/0! | F31: =+SUM(F32:F40) -> 0
C32: Letra A+ | D32: =+SUMIFS(Input!$N:$N,Input!$C:$C,Index!$D$13,Input!$H:$H,Index!$D$30,Input!$F:$F,Index!$D$17,Input!$E:$E,Index!D20) -> 0 | E32: =+IFERROR(D32/$D$31,0) -> 0 | F32: =+SUMIFS(Input!$L:$L,Input!$C:$C,Index!$D$13,Input!$H:$H,Index!$D$30,Input!$F:$F,Index!$D$17,Input!$E:$E,Index!D20) -> 0
C33: Letra A | D33: =+SUMIFS(Input!$N:$N,Input!$C:$C,Index!$D$13,Input!$H:$H,Index!$D$30,Input!$F:$F,Index!$D$17,Input!$E:$E,Index!D21) -> 0 | E33: =+IFERROR(D33/$D$31,0) -> 0 | F33: =+SUMIFS(Input!$L:$L,Input!$C:$C,Index!$D$13,Input!$H:$H,Index!$D$30,Input!$F:$F,Index!$D$17,Input!$E:$E,Index!D21) -> 0
C34: Letra B | D34: =+SUMIFS(Input!$N:$N,Input!$C:$C,Index!$D$13,Input!$H:$H,Index!$D$30,Input!$F:$F,Index!$D$17,Input!$E:$E,Index!D22) -> 0 | E34: =+IFERROR(D34/$D$31,0) -> 0 | F34: =+SUMIFS(Input!$L:$L,Input!$C:$C,Index!$D$13,Input!$H:$H,Index!$D$30,Input!$F:$F,Index!$D$17,Input!$E:$E,Index!D22) -> 0
C35: Letra B- | D35: =+SUMIFS(Input!$N:$N,Input!$C:$C,Index!$D$13,Input!$H:$H,Index!$D$30,Input!$F:$F,Index!$D$17,Input!$E:$E,Index!D23) -> 0 | E35: =+IFERROR(D35/$D$31,0) -> 0 | F35: =+SUMIFS(Input!$L:$L,Input!$C:$C,Index!$D$13,Input!$H:$H,Index!$D$30,Input!$F:$F,Index!$D$17,Input!$E:$E,Index!D23) -> 0
C36: Letra C | D36: =+SUMIFS(Input!$N:$N,Input!$C:$C,Index!$D$13,Input!$H:$H,Index!$D$30,Input!$F:$F,Index!$D$17,Input!$E:$E,Index!D24) -> 0 | E36: =+IFERROR(D36/$D$31,0) -> 0 | F36: =+SUMIFS(Input!$L:$L,Input!$C:$C,Index!$D$13,Input!$H:$H,Index!$D$30,Input!$F:$F,Index!$D$17,Input!$E:$E,Index!D24) -> 0
C37: Letra D | D37: =+SUMIFS(Input!$N:$N,Input!$C:$C,Index!$D$13,Input!$H:$H,Index!$D$30,Input!$F:$F,Index!$D$17,Input!$E:$E,Index!D25) -> 0 | E37: =+IFERROR(D37/$D$31,0) -> 0 | F37: =+SUMIFS(Input!$L:$L,Input!$C:$C,Index!$D$13,Input!$H:$H,Index!$D$30,Input!$F:$F,Index!$D$17,Input!$E:$E,Index!D25) -> 0
C38: Letra E | D38: =+SUMIFS(Input!$N:$N,Input!$C:$C,Index!$D$13,Input!$H:$H,Index!$D$30,Input!$F:$F,Index!$D$17,Input!$E:$E,Index!D26) -> 0 | E38: =+IFERROR(D38/$D$31,0) -> 0 | F38: =+SUMIFS(Input!$L:$L,Input!$C:$C,Index!$D$13,Input!$H:$H,Index!$D$30,Input!$F:$F,Index!$D$17,Input!$E:$E,Index!D26) -> 0
C39: Letra F | D39: =+SUMIFS(Input!$N:$N,Input!$C:$C,Index!$D$13,Input!$H:$H,Index!$D$30,Input!$F:$F,Index!$D$17,Input!$E:$E,Index!D27) -> 0 | E39: =+IFERROR(D39/$D$31,0) -> 0 | F39: =+SUMIFS(Input!$L:$L,Input!$C:$C,Index!$D$13,Input!$H:$H,Index!$D$30,Input!$F:$F,Index!$D$17,Input!$E:$E,Index!D27) -> 0
C40: Letra G | D40: =+SUMIFS(Input!$N:$N,Input!$C:$C,Index!$D$13,Input!$H:$H,Index!$D$30,Input!$F:$F,Index!$D$17,Input!$E:$E,Index!D28) -> 0 | E40: =+IFERROR(D40/$D$31,0) -> 0 | F40: =+SUMIFS(Input!$L:$L,Input!$C:$C,Index!$D$13,Input!$H:$H,Index!$D$30,Input!$F:$F,Index!$D$17,Input!$E:$E,Index!D28) -> 0
C41: Certificado Energético Estimado | D41: =+SUM(D42:D50) -> 0 | E41: =+D41/$D$52 -> #DIV/0! | F41: =+SUM(F42:F50) -> 0
C42: Letra A+ | D42: =+SUMIFS(Input!$N:$N,Input!$C:$C,Index!$D$13,Input!$H:$H,Index!$D$30,Input!$F:$F,Index!$D$18,Input!$E:$E,Index!D20) -> 0 | E42: =+IFERROR(D42/$D$41,0) -> 0 | F42: =+SUMIFS(Input!$L:$L,Input!$C:$C,Index!$D$13,Input!$H:$H,Index!$D$30,Input!$F:$F,Index!$D$18,Input!$E:$E,Index!D20) -> 0
C43: Letra A | D43: =+SUMIFS(Input!$N:$N,Input!$C:$C,Index!$D$13,Input!$H:$H,Index!$D$30,Input!$F:$F,Index!$D$18,Input!$E:$E,Index!D21) -> 0 | E43: =+IFERROR(D43/$D$41,0) -> 0 | F43: =+SUMIFS(Input!$L:$L,Input!$C:$C,Index!$D$13,Input!$H:$H,Index!$D$30,Input!$F:$F,Index!$D$18,Input!$E:$E,Index!D21) -> 0
C44: Letra B | D44: =+SUMIFS(Input!$N:$N,Input!$C:$C,Index!$D$13,Input!$H:$H,Index!$D$30,Input!$F:$F,Index!$D$18,Input!$E:$E,Index!D22) -> 0 | E44: =+IFERROR(D44/$D$41,0) -> 0 | F44: =+SUMIFS(Input!$L:$L,Input!$C:$C,Index!$D$13,Input!$H:$H,Index!$D$30,Input!$F:$F,Index!$D$18,Input!$E:$E,Index!D22) -> 0
C45: Letra B- | D45: =+SUMIFS(Input!$N:$N,Input!$C:$C,Index!$D$13,Input!$H:$H,Index!$D$30,Input!$F:$F,Index!$D$18,Input!$E:$E,Index!D23) -> 0 | E45: =+IFERROR(D45/$D$41,0) -> 0 | F45: =+SUMIFS(Input!$L:$L,Input!$C:$C,Index!$D$13,Input!$H:$H,Index!$D$30,Input!$F:$F,Index!$D$18,Input!$E:$E,Index!D23) -> 0
C46: Letra C | D46: =+SUMIFS(Input!$N:$N,Input!$C:$C,Index!$D$13,Input!$H:$H,Index!$D$30,Input!$F:$F,Index!$D$18,Input!$E:$E,Index!D24) -> 0 | E46: =+IFERROR(D46/$D$41,0) -> 0 | F46: =+SUMIFS(Input!$L:$L,Input!$C:$C,Index!$D$13,Input!$H:$H,Index!$D$30,Input!$F:$F,Index!$D$18,Input!$E:$E,Index!D24) -> 0
C47: Letra D | D47: =+SUMIFS(Input!$N:$N,Input!$C:$C,Index!$D$13,Input!$H:$H,Index!$D$30,Input!$F:$F,Index!$D$18,Input!$E:$E,Index!D25) -> 0 | E47: =+IFERROR(D47/$D$41,0) -> 0 | F47: =+SUMIFS(Input!$L:$L,Input!$C:$C,Index!$D$13,Input!$H:$H,Index!$D$30,Input!$F:$F,Index!$D$18,Input!$E:$E,Index!D25) -> 0
C48: Letra E | D48: =+SUMIFS(Input!$N:$N,Input!$C:$C,Index!$D$13,Input!$H:$H,Index!$D$30,Input!$F:$F,Index!$D$18,Input!$E:$E,Index!D26) -> 0 | E48: =+IFERROR(D48/$D$41,0) -> 0 | F48: =+SUMIFS(Input!$L:$L,Input!$C:$C,Index!$D$13,Input!$H:$H,Index!$D$30,Input!$F:$F,Index!$D$18,Input!$E:$E,Index!D26) -> 0
C49: Letra F | D49: =+SUMIFS(Input!$N:$N,Input!$C:$C,Index!$D$13,Input!$H:$H,Index!$D$30,Input!$F:$F,Index!$D$18,Input!$E:$E,Index!D27) -> 0 | E49: =+IFERROR(D49/$D$41,0) -> 0 | F49: =+SUMIFS(Input!$L:$L,Input!$C:$C,Index!$D$13,Input!$H:$H,Index!$D$30,Input!$F:$F,Index!$D$18,Input!$E:$E,Index!D27) -> 0
C50: Letra G | D50: =+SUMIFS(Input!$N:$N,Input!$C:$C,Index!$D$13,Input!$H:$H,Index!$D$30,Input!$F:$F,Index!$D$18,Input!$E:$E,Index!D28) -> 0 | E50: =+IFERROR(D50/$D$41,0) -> 0 | F50: =+SUMIFS(Input!$L:$L,Input!$C:$C,Index!$D$13,Input!$H:$H,Index!$D$30,Input!$F:$F,Index!$D$18,Input!$E:$E,Index!D28) -> 0
C51: Sem Certificado Energético | D51: =+SUMIFS(Input!$N:$N,Input!$C:$C,Index!$D$13,Input!$H:$H,Index!$D$30,Input!$F:$F,Index!$D$19) -> 0 | E51: =+D51/$D$52 -> #DIV/0! | F51: =+SUMIFS(Input!$L:$L,Input!$C:$C,Index!$D$13,Input!$H:$H,Index!$D$30,Input!$F:$F,Index!$D$19) -> 0
...

Sheet 2. EPC - Mortgages Loans
B6: 2. Certificados Energéticos - Mortgages Loans
C8: O quadro infra apresenta a distribuição das letras dos Certificados Energético do Banco, de acordo com a metodologia PCAF Score 3.
C10: EPC | D10: Valor bruto (€) | E10: Valor bruto (%) | F10: Emissões Financiadas (tCO2e)
C12: Data Quality Score 3
C13: Certificado Energético Real | D13: =+SUM(D14:D22) -> 0 | E13: =+SUM(E14:E22) -> #DIV/0! | F13: =+SUM(F14:F22) -> 0
C14: Letra A+ | D14: =+SUMIFS(Input!$N:$N,Input!$C:$C,Index!$D$11,Input!$H:$H,Index!$D$29,Input!$F:$F,Index!$D$17,Input!$E:$E,Index!D20) -> 0 | E14: =+D14/$D$13 -> #DIV/0! | F14: =+SUMIFS(Input!$L:$L,Input!$C:$C,Index!$D$11,Input!$H:$H,Index!$D$29,Input!$F:$F,Index!$D$17,Input!$E:$E,Index!D20) -> 0
C15: Letra A | D15: =+SUMIFS(Input!$N:$N,Input!$C:$C,Index!$D$11,Input!$H:$H,Index!$D$29,Input!$F:$F,Index!$D$17,Input!$E:$E,Index!D21) -> 0 | E15: =+D15/$D$13 -> #DIV/0! | F15: =+SUMIFS(Input!$L:$L,Input!$C:$C,Index!$D$11,Input!$H:$H,Index!$D$29,Input!$F:$F,Index!$D$17,Input!$E:$E,Index!D21) -> 0
C16: Letra B | D16: =+SUMIFS(Input!$N:$N,Input!$C:$C,Index!$D$11,Input!$H:$H,Index!$D$29,Input!$F:$F,Index!$D$17,Input!$E:$E,Index!D22) -> 0 | E16: =+D16/$D$13 -> #DIV/0! | F16: =+SUMIFS(Input!$L:$L,Input!$C:$C,Index!$D$11,Input!$H:$H,Index!$D$29,Input!$F:$F,Index!$D$17,Input!$E:$E,Index!D22) -> 0
C17: Letra B- | D17: =+SUMIFS(Input!$N:$N,Input!$C:$C,Index!$D$11,Input!$H:$H,Index!$D$29,Input!$F:$F,Index!$D$17,Input!$E:$E,Index!D23) -> 0 | E17: =+D17/$D$13 -> #DIV/0! | F17: =+SUMIFS(Input!$L:$L,Input!$C:$C,Index!$D$11,Input!$H:$H,Index!$D$29,Input!$F:$F,Index!$D$17,Input!$E:$E,Index!D23) -> 0
C18: Letra C | D18: =+SUMIFS(Input!$N:$N,Input!$C:$C,Index!$D$11,Input!$H:$H,Index!$D$29,Input!$F:$F,Index!$D$17,Input!$E:$E,Index!D24) -> 0 | E18: =+D18/$D$13 -> #DIV/0! | F18: =+SUMIFS(Input!$L:$L,Input!$C:$C,Index!$D$11,Input!$H:$H,Index!$D$29,Input!$F:$F,Index!$D$17,Input!$E:$E,Index!D24) -> 0
C19: Letra D | D19: =+SUMIFS(Input!$N:$N,Input!$C:$C,Index!$D$11,Input!$H:$H,Index!$D$29,Input!$F:$F,Index!$D$17,Input!$E:$E,Index!D25) -> 0 | E19: =+D19/$D$13 -> #DIV/0! | F19: =+SUMIFS(Input!$L:$L,Input!$C:$C,Index!$D$11,Input!$H:$H,Index!$D$29,Input!$F:$F,Index!$D$17,Input!$E:$E,Index!D25) -> 0
C20: Letra E | D20: =+SUMIFS(Input!$N:$N,Input!$C:$C,Index!$D$11,Input!$H:$H,Index!$D$29,Input!$F:$F,Index!$D$17,Input!$E:$E,Index!D26) -> 0 | E20: =+D20/$D$13 -> #DIV/0! | F20: =+SUMIFS(Input!$L:$L,Input!$C:$C,Index!$D$11,Input!$H:$H,Index!$D$29,Input!$F:$F,Index!$D$17,Input!$E:$E,Index!D26) -> 0
C21: Letra F | D21: =+SUMIFS(Input!$N:$N,Input!$C:$C,Index!$D$11,Input!$H:$H,Index!$D$29,Input!$F:$F,Index!$D$17,Input!$E:$E,Index!D27) -> 0 | E21: =+D21/$D$13 -> #DIV/0! | F21: =+SUMIFS(Input!$L:$L,Input!$C:$C,Index!$D$11,Input!$H:$H,Index!$D$29,Input!$F:$F,Index!$D$17,Input!$E:$E,Index!D27) -> 0
C22: Letra G | D22: =+SUMIFS(Input!$N:$N,Input!$C:$C,Index!$D$11,Input!$H:$H,Index!$D$29,Input!$F:$F,Index!$D$17,Input!$E:$E,Index!D28) -> 0 | E22: =+D22/$D$13 -> #DIV/0! | F22: =+SUMIFS(Input!$L:$L,Input!$C:$C,Index!$D$11,Input!$H:$H,Index!$D$29,Input!$F:$F,Index!$D$17,Input!$E:$E,Index!D28) -> 0
C23: Total | D23: =+D13 -> 0 | E23: =+E13 -> #DIV/0! | F23: =+F13 -> 0
C25: O quadro infra apresenta a distribuição das letras dos Certificados Energético do Banco, de acordo com a metodologia PCAF Score 4.
C26: ▪ Denote-se que estas letras dos Certificados Energéticos não são utilizadas para apurar o fator de emissão do imóvel.
C28: EPC | D28: Valor bruto (€) | E28: Valor bruto (%) | F28: Emissões Financiadas (tCO2e)
C30: Data Quality Score 4
C31: Certificado Energético Real | D31: =+SUM(D32:D40) -> 0 | E31: =+D31/$D$52 -> #DIV/0! | F31: =+SUM(F32:F40) -> 0
C32: Letra A+ | D32: =+SUMIFS(Input!$N:$N,Input!$C:$C,Index!$D$11,Input!$H:$H,Index!$D$30,Input!$F:$F,Index!$D$17,Input!$E:$E,Index!D20) -> 0 | E32: =+IFERROR(D32/$D$31,0) -> 0 | F32: =+SUMIFS(Input!$L:$L,Input!$C:$C,Index!$D$11,Input!$H:$H,Index!$D$30,Input!$F:$F,Index!$D$17,Input!$E:$E,Index!D20) -> 0
C33: Letra A | D33: =+SUMIFS(Input!$N:$N,Input!$C:$C,Index!$D$11,Input!$H:$H,Index!$D$30,Input!$F:$F,Index!$D$17,Input!$E:$E,Index!D21) -> 0 | E33: =+IFERROR(D33/$D$31,0) -> 0 | F33: =+SUMIFS(Input!$L:$L,Input!$C:$C,Index!$D$11,Input!$H:$H,Index!$D$30,Input!$F:$F,Index!$D$17,Input!$E:$E,Index!D21) -> 0
C34: Letra B | D34: =+SUMIFS(Input!$N:$N,Input!$C:$C,Index!$D$11,Input!$H:$H,Index!$D$30,Input!$F:$F,Index!$D$17,Input!$E:$E,Index!D22) -> 0 | E34: =+IFERROR(D34/$D$31,0) -> 0 | F34: =+SUMIFS(Input!$L:$L,Input!$C:$C,Index!$D$11,Input!$H:$H,Index!$D$30,Input!$F:$F,Index!$D$17,Input!$E:$E,Index!D22) -> 0
C35: Letra B- | D35: =+SUMIFS(Input!$N:$N,Input!$C:$C,Index!$D$11,Input!$H:$H,Index!$D$30,Input!$F:$F,Index!$D$17,Input!$E:$E,Index!D23) -> 0 | E35: =+IFERROR(D35/$D$31,0) -> 0 | F35: =+SUMIFS(Input!$L:$L,Input!$C:$C,Index!$D$11,Input!$H:$H,Index!$D$30,Input!$F:$F,Index!$D$17,Input!$E:$E,Index!D23) -> 0
C36: Letra C | D36: =+SUMIFS(Input!$N:$N,Input!$C:$C,Index!$D$11,Input!$H:$H,Index!$D$30,Input!$F:$F,Index!$D$17,Input!$E:$E,Index!D24) -> 0 | E36: =+IFERROR(D36/$D$31,0) -> 0 | F36: =+SUMIFS(Input!$L:$L,Input!$C:$C,Index!$D$11,Input!$H:$H,Index!$D$30,Input!$F:$F,Index!$D$17,Input!$E:$E,Index!D24) -> 0
C37: Letra D | D37: =+SUMIFS(Input!$N:$N,Input!$C:$C,Index!$D$11,Input!$H:$H,Index!$D$30,Input!$F:$F,Index!$D$17,Input!$E:$E,Index!D25) -> 0 | E37: =+IFERROR(D37/$D$31,0) -> 0 | F37: =+SUMIFS(Input!$L:$L,Input!$C:$C,Index!$D$11,Input!$H:$H,Index!$D$30,Input!$F:$F,Index!$D$17,Input!$E:$E,Index!D25) -> 0
C38: Letra E | D38: =+SUMIFS(Input!$N:$N,Input!$C:$C,Index!$D$11,Input!$H:$H,Index!$D$30,Input!$F:$F,Index!$D$17,Input!$E:$E,Index!D26) -> 0 | E38: =+IFERROR(D38/$D$31,0) -> 0 | F38: =+SUMIFS(Input!$L:$L,Input!$C:$C,Index!$D$11,Input!$H:$H,Index!$D$30,Input!$F:$F,Index!$D$17,Input!$E:$E,Index!D26) -> 0
C39: Letra F | D39: =+SUMIFS(Input!$N:$N,Input!$C:$C,Index!$D$11,Input!$H:$H,Index!$D$30,Input!$F:$F,Index!$D$17,Input!$E:$E,Index!D27) -> 0 | E39: =+IFERROR(D39/$D$31,0) -> 0 | F39: =+SUMIFS(Input!$L:$L,Input!$C:$C,Index!$D$11,Input!$H:$H,Index!$D$30,Input!$F:$F,Index!$D$17,Input!$E:$E,Index!D27) -> 0
C40: Letra G | D40: =+SUMIFS(Input!$N:$N,Input!$C:$C,Index!$D$11,Input!$H:$H,Index!$D$30,Input!$F:$F,Index!$D$17,Input!$E:$E,Index!D28) -> 0 | E40: =+IFERROR(D40/$D$31,0) -> 0 | F40: =+SUMIFS(Input!$L:$L,Input!$C:$C,Index!$D$11,Input!$H:$H,Index!$D$30,Input!$F:$F,Index!$D$17,Input!$E:$E,Index!D28) -> 0
C41: Certificado Energético Estimado | D41: =+SUM(D42:D50) -> 0 | E41: =+D41/$D$52 -> #DIV/0! | F41: =+SUM(F42:F50) -> 0
C42: Letra A+ | D42: =+SUMIFS(Input!$N:$N,Input!$C:$C,Index!$D$11,Input!$H:$H,Index!$D$30,Input!$F:$F,Index!$D$18,Input!$E:$E,Index!D20) -> 0 | E42: =+IFERROR(D42/$D$41,0) -> 0 | F42: =+SUMIFS(Input!$L:$L,Input!$C:$C,Index!$D$11,Input!$H:$H,Index!$D$30,Input!$F:$F,Index!$D$18,Input!$E:$E,Index!D20) -> 0
C43: Letra A | D43: =+SUMIFS(Input!$N:$N,Input!$C:$C,Index!$D$11,Input!$H:$H,Index!$D$30,Input!$F:$F,Index!$D$18,Input!$E:$E,Index!D21) -> 0 | E43: =+IFERROR(D43/$D$41,0) -> 0 | F43: =+SUMIFS(Input!$L:$L,Input!$C:$C,Index!$D$11,Input!$H:$H,Index!$D$30,Input!$F:$F,Index!$D$18,Input!$E:$E,Index!D21) -> 0
C44: Letra B | D44: =+SUMIFS(Input!$N:$N,Input!$C:$C,Index!$D$11,Input!$H:$H,Index!$D$30,Input!$F:$F,Index!$D$18,Input!$E:$E,Index!D22) -> 0 | E44: =+IFERROR(D44/$D$41,0) -> 0 | F44: =+SUMIFS(Input!$L:$L,Input!$C:$C,Index!$D$11,Input!$H:$H,Index!$D$30,Input!$F:$F,Index!$D$18,Input!$E:$E,Index!D22) -> 0
C45: Letra B- | D45: =+SUMIFS(Input!$N:$N,Input!$C:$C,Index!$D$11,Input!$H:$H,Index!$D$30,Input!$F:$F,Index!$D$18,Input!$E:$E,Index!D23) -> 0 | E45: =+IFERROR(D45/$D$41,0) -> 0 | F45: =+SUMIFS(Input!$L:$L,Input!$C:$C,Index!$D$11,Input!$H:$H,Index!$D$30,Input!$F:$F,Index!$D$18,Input!$E:$E,Index!D23) -> 0
C46: Letra C | D46: =+SUMIFS(Input!$N:$N,Input!$C:$C,Index!$D$11,Input!$H:$H,Index!$D$30,Input!$F:$F,Index!$D$18,Input!$E:$E,Index!D24) -> 0 | E46: =+IFERROR(D46/$D$41,0) -> 0 | F46: =+SUMIFS(Input!$L:$L,Input!$C:$C,Index!$D$11,Input!$H:$H,Index!$D$30,Input!$F:$F,Index!$D$18,Input!$E:$E,Index!D24) -> 0
C47: Letra D | D47: =+SUMIFS(Input!$N:$N,Input!$C:$C,Index!$D$11,Input!$H:$H,Index!$D$30,Input!$F:$F,Index!$D$18,Input!$E:$E,Index!D25) -> 0 | E47: =+IFERROR(D47/$D$41,0) -> 0 | F47: =+SUMIFS(Input!$L:$L,Input!$C:$C,Index!$D$11,Input!$H:$H,Index!$D$30,Input!$F:$F,Index!$D$18,Input!$E:$E,Index!D25) -> 0
C48: Letra E | D48: =+SUMIFS(Input!$N:$N,Input!$C:$C,Index!$D$11,Input!$H:$H,Index!$D$30,Input!$F:$F,Index!$D$18,Input!$E:$E,Index!D26) -> 0 | E48: =+IFERROR(D48/$D$41,0) -> 0 | F48: =+SUMIFS(Input!$L:$L,Input!$C:$C,Index!$D$11,Input!$H:$H,Index!$D$30,Input!$F:$F,Index!$D$18,Input!$E:$E,Index!D26) -> 0
C49: Letra F | D49: =+SUMIFS(Input!$N:$N,Input!$C:$C,Index!$D$11,Input!$H:$H,Index!$D$30,Input!$F:$F,Index!$D$18,Input!$E:$E,Index!D27) -> 0 | E49: =+IFERROR(D49/$D$41,0) -> 0 | F49: =+SUMIFS(Input!$L:$L,Input!$C:$C,Index!$D$11,Input!$H:$H,Index!$D$30,Input!$F:$F,Index!$D$18,Input!$E:$E,Index!D27) -> 0
C50: Letra G | D50: =+SUMIFS(Input!$N:$N,Input!$C:$C,Index!$D$11,Input!$H:$H,Index!$D$30,Input!$F:$F,Index!$D$18,Input!$E:$E,Index!D28) -> 0 | E50: =+IFERROR(D50/$D$41,0) -> 0 | F50: =+SUMIFS(Input!$L:$L,Input!$C:$C,Index!$D$11,Input!$H:$H,Index!$D$30,Input!$F:$F,Index!$D$18,Input!$E:$E,Index!D28) -> 0
C51: Sem Certificado Energético | D51: =+SUMIFS(Input!$N:$N,Input!$C:$C,Index!$D$11,Input!$H:$H,Index!$D$30,Input!$F:$F,Index!$D$19) -> 0 | E51: =+D51/$D$52 -> #DIV/0! | F51: =+SUMIFS(Input!$L:$L,Input!$C:$C,Index!$D$11,Input!$H:$H,Index!$D$30,Input!$F:$F,Index!$D$19) -> 0
...

Sheet 3. Área Ponderada
B6: 3. Área Ponderada
C8: O quadro infra apresenta a distribuição da área do imóvel para a carteira de Commercial Real Estate (CRE) e Mortgages Loans.
C10: Setor | D10: Emissões Financiadas (tCO2e) | E10: Emissões Financiadas (%) | F10: Área Ponderada (m2)1
C12: Commercial Real Estate (CRE) | D12: =+SUM(D13:D15) -> 0 | E12: =+D12/$D$20 -> #DIV/0! | F12: =+SUM(F13:F15) -> 0
C13: Metodologia floor area (Data Quality Score 3) | D13: =+SUMIFS(Input!$L:$L,Input!$C:$C,Index!$D$13,Input!$H:$H,Index!$D29) -> 0 | E13: =+D13/$D$12 -> #DIV/0! | F13: =+SUMIFS(Input!$G:$G,Input!$C:$C,Index!$D$13,Input!$H:$H,Index!$D29) -> 0
C14: Metodologia floor area (Data Quality Score 4) | D14: =+SUMIFS(Input!$L:$L,Input!$C:$C,Index!$D$13,Input!$H:$H,Index!$D30) -> 0 | E14: =+D14/$D$12 -> #DIV/0! | F14: =+SUMIFS(Input!$G:$G,Input!$C:$C,Index!$D$13,Input!$H:$H,Index!$D30) -> 0
C15: Metodologia number of buildings (Data Quality Score 5) | D15: =+SUMIFS(Input!$L:$L,Input!$C:$C,Index!$D$13,Input!$H:$H,Index!$D31) -> 0 | E15: =+D15/$D$12 -> #DIV/0! | F15: Não Aplicável
C16: Mortgages Loans | D16: =+SUM(D17:D19) -> 0 | E16: =+D16/$D$20 -> #DIV/0! | F16: =+SUM(F17:F19) -> 0
C17: Metodologia floor area (Data Quality Score 3) | D17: =+SUMIFS(Input!$L:$L,Input!$C:$C,Index!$D$11,Input!$H:$H,Index!$D29) -> 0 | E17: =+D17/$D$16 -> #DIV/0! | F17: =+SUMIFS(Input!$G:$G,Input!$C:$C,Index!$D$11,Input!$H:$H,Index!$D29) -> 0
C18: Metodologia floor area (Data Quality Score 4) | D18: =+SUMIFS(Input!$L:$L,Input!$C:$C,Index!$D$11,Input!$H:$H,Index!$D30) -> 0 | E18: =+D18/$D$16 -> #DIV/0! | F18: =+SUMIFS(Input!$G:$G,Input!$C:$C,Index!$D$11,Input!$H:$H,Index!$D30) -> 0
C19: Metodologia number of buildings (Data Quality Score 5) | D19: =+SUMIFS(Input!$L:$L,Input!$C:$C,Index!$D$11,Input!$H:$H,Index!$D31) -> 0 | E19: =+D19/$D$16 -> #DIV/0! | F19: Não Aplicável
C20: Total | D20: =+SUM(D16,D12) -> 0 | E20: =+SUM(E16,E12) -> #DIV/0! | F20: =+SUM(F16,F12) -> 0
C22: 1Área útil do imóvel atribuída ao financiamento correspondente ao produto entre a área útil do imóvel e o fator de atribuição utilizado no cálculo
C23: das emissões financiadas, expressa em m2.

Sheet 4. Finalidade do Imóvel
B6: 4. Finalidade do Imóvel
C8: O quadro infra apresenta o mapeamento das finalidades do bem, para a carteira Commercial Real Estate (CRE)1
C10: Finalidade do Imóvel | D10: Valor bruto (€) | E10: Valor bruto (%) | F10: Emissões Financiadas (tCO2e)
C12: CRE_OUTRO
C13: Finalidade do Bem | D13: =+SUM(D14:D27) -> 0 | E13: =+D13/$D$31 -> #DIV/0! | F13: =+SUM(F14:F27) -> 0
C14: Habitação | D14: =+SUMIFS(Input!$N:$N,Input!$C:$C,Index!$D$13,Input!$D:$D,Index!$D34) -> 0 | E14: =+D14/$D$13 -> #DIV/0! | F14: =+SUMIFS(Input!$L:$L,Input!$C:$C,Index!$D$13,Input!$D:$D,Index!$D34) -> 0
C15: Comércio | D15: =+SUMIFS(Input!$N:$N,Input!$C:$C,Index!$D$13,Input!$D:$D,Index!$D35) -> 0 | E15: =+D15/$D$13 -> #DIV/0! | F15: =+SUMIFS(Input!$L:$L,Input!$C:$C,Index!$D$13,Input!$D:$D,Index!$D35) -> 0
C16: Escritório | D16: =+SUMIFS(Input!$N:$N,Input!$C:$C,Index!$D$13,Input!$D:$D,Index!$D36) -> 0 | E16: =+D16/$D$13 -> #DIV/0! | F16: =+SUMIFS(Input!$L:$L,Input!$C:$C,Index!$D$13,Input!$D:$D,Index!$D36) -> 0
C17: Armazém | D17: =+SUMIFS(Input!$N:$N,Input!$C:$C,Index!$D$13,Input!$D:$D,Index!$D37) -> 0 | E17: =+D17/$D$13 -> #DIV/0! | F17: =+SUMIFS(Input!$L:$L,Input!$C:$C,Index!$D$13,Input!$D:$D,Index!$D37) -> 0
C18: Indústria | D18: =+SUMIFS(Input!$N:$N,Input!$C:$C,Index!$D$13,Input!$D:$D,Index!$D38) -> 0 | E18: =+D18/$D$13 -> #DIV/0! | F18: =+SUMIFS(Input!$L:$L,Input!$C:$C,Index!$D$13,Input!$D:$D,Index!$D38) -> 0
C19: Estacionamento | D19: =+SUMIFS(Input!$N:$N,Input!$C:$C,Index!$D$13,Input!$D:$D,Index!$D39) -> 0 | E19: =+D19/$D$13 -> #DIV/0! | F19: Não Aplicável
C20: Garagem | D20: =+SUMIFS(Input!$N:$N,Input!$C:$C,Index!$D$13,Input!$D:$D,Index!$D40) -> 0 | E20: =+D20/$D$13 -> #DIV/0! | F20: Não Aplicável
C21: Outras | D21: =+SUMIFS(Input!$N:$N,Input!$C:$C,Index!$D$13,Input!$D:$D,Index!$D41) -> 0 | E21: =+D21/$D$13 -> #DIV/0! | F21: =+SUMIFS(Input!$L:$L,Input!$C:$C,Index!$D$13,Input!$D:$D,Index!$D41) -> 0
C22: Hotel | D22: =+SUMIFS(Input!$N:$N,Input!$C:$C,Index!$D$13,Input!$D:$D,Index!$D42) -> 0 | E22: =+D22/$D$13 -> #DIV/0! | F22: =+SUMIFS(Input!$L:$L,Input!$C:$C,Index!$D$13,Input!$D:$D,Index!$D42) -> 0
C23: Educação | D23: =+SUMIFS(Input!$N:$N,Input!$C:$C,Index!$D$13,Input!$D:$D,Index!$D43) -> 0 | E23: =+D23/$D$13 -> #DIV/0! | F23: =+SUMIFS(Input!$L:$L,Input!$C:$C,Index!$D$13,Input!$D:$D,Index!$D43) -> 0
C24: Saúde | D24: =+SUMIFS(Input!$N:$N,Input!$C:$C,Index!$D$13,Input!$D:$D,Index!$D44) -> 0 | E24: =+D24/$D$13 -> #DIV/0! | F24: =+SUMIFS(Input!$L:$L,Input!$C:$C,Index!$D$13,Input!$D:$D,Index!$D44) -> 0
C25: Lazer | D25: =+SUMIFS(Input!$N:$N,Input!$C:$C,Index!$D$13,Input!$D:$D,Index!$D45) -> 0 | E25: =+D25/$D$13 -> #DIV/0! | F25: =+SUMIFS(Input!$L:$L,Input!$C:$C,Index!$D$13,Input!$D:$D,Index!$D45) -> 0
C26: Agricultura | D26: =+SUMIFS(Input!$N:$N,Input!$C:$C,Index!$D$13,Input!$D:$D,Index!$D46) -> 0 | E26: =+D26/$D$13 -> #DIV/0! | F26: =+SUMIFS(Input!$L:$L,Input!$C:$C,Index!$D$13,Input!$D:$D,Index!$D46) -> 0
C27: Centro Comercial | D27: =+SUMIFS(Input!$N:$N,Input!$C:$C,Index!$D$13,Input!$D:$D,Index!$D47) -> 0 | E27: =+D27/$D$13 -> #DIV/0! | F27: =+SUMIFS(Input!$L:$L,Input!$C:$C,Index!$D$13,Input!$D:$D,Index!$D47) -> 0
C28: Sem informação da finalidade | D28: =+SUMIFS(Input!$N:$N,Input!$C:$C,Index!$D$13,Input!$D:$D,Index!$D48) -> 0 | E28: =+D28/$D$31 -> #DIV/0! | F28: =+SUMIFS(Input!$L:$L,Input!$C:$C,Index!$D$13,Input!$D:$D,Index!$D48) -> 0
C29: Exposição não colaterizada | D29: =+SUMIFS(Input!N:N,Input!C:C,Index!D13,Input!M:M,Index!D50) -> 0 | E29: =+D29/$D$31 -> #DIV/0! | F29: Não Aplicável
C30: Fora de âmbito do cálculo | D30: =+SUMIFS(Input!N:N,Input!C:C,Index!D14) -> 0 | E30: =+D30/$D$31 -> #DIV/0! | F30: Não Aplicável
C31: Total | D31: =+SUM(D13,D28:D30) -> 0 | E31: =+SUM(E13,E28:E30) -> #DIV/0! | F31: =+SUM(F13,F28) -> 0
C33: 1Considera-se apenas as exposições associas a códigos de atividade económica (CCAE) 41.10 (Promoção imobiliária e desenvolvimento
C34: de projetos), 55.11 (Estabelecimentos hoteleiros) e 68 (Atividades imobiliárias).
C36: O quadro infra apresenta o mapeamento das finalidades do bem, para a carteira de Mortgages Loans
C38: Finalidade do Imóvel | D38: Valor bruto (€) | E38: Valor bruto (%) | F38: Emissões Financiadas (tCO2e)
C40: Habitacao
C41: Finalidade do Bem | D41: =+SUM(D42:D55) -> 0 | E41: =+D41/$D$59 -> #DIV/0! | F41: =+SUM(F42:F55) -> 0
C42: Habitação | D42: =+SUMIFS(Input!$N:$N,Input!$C:$C,Index!$D$11,Input!$D:$D,Index!$D34) -> 0 | E42: =+D42/$D$41 -> #DIV/0! | F42: =+SUMIFS(Input!$L:$L,Input!$C:$C,Index!$D$11,Input!$D:$D,Index!$D34) -> 0
C43: Comércio | D43: =+SUMIFS(Input!$N:$N,Input!$C:$C,Index!$D$11,Input!$D:$D,Index!$D35) -> 0 | E43: =+D43/$D$41 -> #DIV/0! | F43: =+SUMIFS(Input!$L:$L,Input!$C:$C,Index!$D$11,Input!$D:$D,Index!$D35) -> 0
C44: Escritório | D44: =+SUMIFS(Input!$N:$N,Input!$C:$C,Index!$D$11,Input!$D:$D,Index!$D36) -> 0 | E44: =+D44/$D$41 -> #DIV/0! | F44: =+SUMIFS(Input!$L:$L,Input!$C:$C,Index!$D$11,Input!$D:$D,Index!$D36) -> 0
C45: Armazém | D45: =+SUMIFS(Input!$N:$N,Input!$C:$C,Index!$D$11,Input!$D:$D,Index!$D37) -> 0 | E45: =+D45/$D$41 -> #DIV/0! | F45: =+SUMIFS(Input!$L:$L,Input!$C:$C,Index!$D$11,Input!$D:$D,Index!$D37) -> 0
C46: Indústria | D46: =+SUMIFS(Input!$N:$N,Input!$C:$C,Index!$D$11,Input!$D:$D,Index!$D38) -> 0 | E46: =+D46/$D$41 -> #DIV/0! | F46: =+SUMIFS(Input!$L:$L,Input!$C:$C,Index!$D$11,Input!$D:$D,Index!$D38) -> 0
C47: Estacionamento | D47: =+SUMIFS(Input!$N:$N,Input!$C:$C,Index!$D$11,Input!$D:$D,Index!$D39) -> 0 | E47: =+D47/$D$41 -> #DIV/0! | F47: Não Aplicável
C48: Garagem | D48: =+SUMIFS(Input!$N:$N,Input!$C:$C,Index!$D$11,Input!$D:$D,Index!$D40) -> 0 | E48: =+D48/$D$41 -> #DIV/0! | F48: Não Aplicável
C49: Outras | D49: =+SUMIFS(Input!$N:$N,Input!$C:$C,Index!$D$11,Input!$D:$D,Index!$D41) -> 0 | E49: =+D49/$D$41 -> #DIV/0! | F49: =+SUMIFS(Input!$L:$L,Input!$C:$C,Index!$D$11,Input!$D:$D,Index!$D41) -> 0
C50: Hotel | D50: =+SUMIFS(Input!$N:$N,Input!$C:$C,Index!$D$11,Input!$D:$D,Index!$D42) -> 0 | E50: =+D50/$D$41 -> #DIV/0! | F50: =+SUMIFS(Input!$L:$L,Input!$C:$C,Index!$D$11,Input!$D:$D,Index!$D42) -> 0
C51: Educação | D51: =+SUMIFS(Input!$N:$N,Input!$C:$C,Index!$D$11,Input!$D:$D,Index!$D43) -> 0 | E51: =+D51/$D$41 -> #DIV/0! | F51: =+SUMIFS(Input!$L:$L,Input!$C:$C,Index!$D$11,Input!$D:$D,Index!$D43) -> 0
C52: Saúde | D52: =+SUMIFS(Input!$N:$N,Input!$C:$C,Index!$D$11,Input!$D:$D,Index!$D44) -> 0 | E52: =+D52/$D$41 -> #DIV/0! | F52: =+SUMIFS(Input!$L:$L,Input!$C:$C,Index!$D$11,Input!$D:$D,Index!$D44) -> 0
...
