Workbook
Name BM: #REF!
Name IQ_CH: 110000
Name IQ_CQ: 5000
Name IQ_CY: 10000
Name IQ_DAILY: 500000
Name IQ_FH: 100000
Name IQ_FQ: 500
Name IQ_FY: 1000
Name IQ_LTM: 2000
Name IQ_MONTH: 15000
Name IQ_NTM: 6000
Name IQ_WEEK: 50000
Name IQ_YTD: 3000

Sheet Comparativos granulares
B8: Métrica | C8: Casuística | D8: Δ Montante vs Tático Dez24
B9: EPC_label | C9: Atualização dos certificados tabela da property | D9: 3.3673329e+08
B10: A | C10: Antes era B agora é A | D10: 8201154.9
C11: Antes era C agora é A | D11: 27617020
C12: Antes era D agora é A | D12: 33051637
C13: Antes era E agora é A | D13: 15249718
C14: Antes era F agora é A | D14: 14576645
C15: Antes era G agora é A | D15: 130808.94
B16: B | C16: Antes era A agora é B | D16: 7101374.7 | E16: atualizações GLOVAL
C17: Antes era C agora é B | D17: 43621693
C18: Antes era D agora é B | D18: 19951302
C19: Antes era E agora é B | D19: 10045173
C20: Antes era F agora é B | D20: 6835478.8
C21: Antes era G agora é B | D21: 433251.01
B22: C | C22: Antes era A agora é C | D22: 3973022.5 | E22: atualizações GLOVAL
C23: Antes era B agora é C | D23: 7609426.8 | E23: atualizações GLOVAL
C24: Antes era D agora é C | D24: 27387869
C25: Antes era E agora é C | D25: 8798801.5
C26: Antes era F agora é C | D26: 3136828
C27: Antes era G agora é C | D27: 239684.33
B28: D | C28: Antes era A agora é D | D28: 3401058.3 | E28: atualizações GLOVAL
C29: Antes era B agora é D | D29: 3964789.4 | E29: atualizações GLOVAL
C30: Antes era C agora é D | D30: 29827746 | E30: atualizações GLOVAL
C31: Antes era E agora é D | D31: 6667194.2
C32: Antes era F agora é D | D32: 2844654.7
C33: Antes era G agora é D | D33: 105618.16
C34: Antes era 'Sem dados' agora é D | D34: 33194.76
B35: E | C35: Antes era A agora é E | D35: 1420013.4 | E35: atualizações GLOVAL
C36: Antes era B agora é E | D36: 1869955.9 | E36: atualizações GLOVAL
C37: Antes era C agora é E | D37: 14013342 | E37: atualizações GLOVAL
C38: Antes era D agora é E | D38: 14850420 | E38: atualizações GLOVAL
C39: Antes era F agora é E | D39: 3556949.5
C40: Antes era G agora é E | D40: 0
B41: F | C41: Antes era A agora é F | D41: 623482.33 | E41: atualizações GLOVAL
C42: Antes era B agora é F | D42: 1344742.6 | E42: atualizações GLOVAL
C43: Antes era C agora é F | D43: 3670791.2 | E43: atualizações GLOVAL
C44: Antes era D agora é F | D44: 5571150.1 | E44: atualizações GLOVAL
C45: Antes era E agora é F | D45: 3869773.7 | E45: atualizações GLOVAL
C46: Antes era G agora é F | D46: 0
B47: G | C47: Antes era A agora é G | D47: 0
...

Sheet Variação Absoluta
C8: Exposição | F8: 0; <= 100 | I8: > 100; <= 200 | L8: > 200; <= 300 | O8: > 300; <= 400 | R8: > 400; <= 500 | U8: > 500 | X8: A | AA8: B | AD8: C | AG8: D | AJ8: E | AM8: F | AP8: G | AS8: Without EPC label of collateral
C9: Dez24 Tático | D9: Dez24 Estrutural | E9: ∆ | F9: Dez24 Tático | G9: Dez24 Estrutural | H9: ∆ | I9: Dez24 Tático | J9: Dez24 Estrutural | K9: ∆ | L9: Dez24 Tático | M9: Dez24 Estrutural | N9: ∆ | O9: Dez24 Tático | P9: Dez24 Estrutural | Q9: ∆ | R9: Dez24 Tático | S9: Dez24 Estrutural | T9: ∆ | U9: Dez24 Tático | V9: Dez24 Estrutural | W9: ∆ | X9: Dez24 Tático | Y9: Dez24 Estrutural | Z9: ∆ | AA9: Dez24 Tático | AB9: Dez24 Estrutural | AC9: ∆ | AD9: Dez24 Tático | AE9: Dez24 Estrutural | AF9: ∆ | AG9: Dez24 Tático | AH9: Dez24 Estrutural | AI9: ∆ | AJ9: Dez24 Tático | AK9: Dez24 Estrutural | AL9: ∆ | AM9: Dez24 Tático | AN9: Dez24 Estrutural | AO9: ∆ | AP9: Dez24 Tático | AQ9: Dez24 Estrutural | AR9: ∆ | AS9: Dez24 Tático | AT9: Dez24 Estrutural | AU9: ∆
B10: Total EU area | C10: ='Dez24'!D14 -> 26904.628 | D10: =Paralelo!D14 -> 26833.997 | E10: =D10-C10 -> -70.63112 | F10: ='Dez24'!E14 -> 13857.398 | G10: =Paralelo!E14 -> 8842.7385 | H10: =G10-F10 -> -5014.6597 | I10: ='Dez24'!F14 -> 10225.192 | J10: =Paralelo!F14 -> 6594.472 | K10: =J10-I10 -> -3630.7196 | L10: ='Dez24'!G14 -> 2367.2076 | M10: =Paralelo!G14 -> 1780.6512 | N10: =M10-L10 -> -586.55637 | O10: ='Dez24'!H14 -> 188.21098 | P10: =Paralelo!H14 -> 249.81568 | Q10: =P10-O10 -> 61.604692 | R10: ='Dez24'!I14 -> 1.11082 | S10: =Paralelo!I14 -> 73.330776 | T10: =S10-R10 -> 72.219956 | U10: ='Dez24'!J14 -> 1.520131 | V10: =Paralelo!J14 -> 87.354293 | W10: =V10-U10 -> 85.834162 | X10: ='Dez24'!K14 -> 1671.4506 | Y10: =Paralelo!K14 -> 1745.4755 | Z10: =Y10-X10 -> 74.024922 | AA10: ='Dez24'!L14 -> 1784.964 | AB10: =Paralelo!L14 -> 1814.1564 | AC10: =AB10-AA10 -> 29.192434 | AD10: ='Dez24'!M14 -> 3299.9853 | AE10: =Paralelo!M14 -> 3317.725 | AF10: =AE10-AD10 -> 17.739767 | AG10: ='Dez24'!N14 -> 3275.3678 | AH10: =Paralelo!N14 -> 3289.7223 | AI10: =AH10-AG10 -> 14.35443 | AJ10: ='Dez24'!O14 -> 1823.4568 | AK10: =Paralelo!O14 -> 1832.8599 | AL10: =AK10-AJ10 -> 9.403095 | AM10: ='Dez24'!P14 -> 817.21933 | AN10: =Paralelo!P14 -> 821.85213 | AO10: =AN10-AM10 -> 4.632806 | AP10: ='Dez24'!Q14 -> 2.979175 | AQ10: =Paralelo!Q14 -> 2.979174 | AR10: =AQ10-AP10 -> -1e-06 | AS10: ='Dez24'!R14 -> 14229.205 | AT10: =Paralelo!R14 -> 14009.226 | AU10: =AT10-AS10 -> -219.97857
B11: Of which Loans collateralised by commercial immovable property | C11: ='Dez24'!D15 -> 3564.4292 | D11: =Paralelo!D15 -> 3564.4292 | E11: =D11-C11 -> -4.9999999e-06 | F11: ='Dez24'!E15 -> 1309.5766 | G11: =Paralelo!E15 -> 1195.7892 | H11: =G11-F11 -> -113.7874 | I11: ='Dez24'!F15 -> 1805.1866 | J11: =Paralelo!F15 -> 1697.3294 | K11: =J11-I11 -> -107.85725 | L11: ='Dez24'!G15 -> 215.60634 | M11: =Paralelo!G15 -> 208.25165 | N11: =M11-L11 -> -7.354696 | O11: ='Dez24'!H15 -> 9.019911 | P11: =Paralelo!H15 -> 10.462529 | Q11: =P11-O11 -> 1.442618 | R11: ='Dez24'!I15 -> 1e-05 | S11: =Paralelo!I15 -> 5.413442 | T11: =S11-R11 -> 5.413432 | U11: ='Dez24'!J15 -> 1.520131 | V11: =Paralelo!J15 -> 13.34354 | W11: =V11-U11 -> 11.823409 | X11: ='Dez24'!K15 -> 76.726507 | Y11: =Paralelo!K15 -> 76.93894 | Z11: =Y11-X11 -> 0.212433 | AA11: ='Dez24'!L15 -> 162.19559 | AB11: =Paralelo!L15 -> 160.71633 | AC11: =AB11-AA11 -> -1.479257 | AD11: ='Dez24'!M15 -> 106.2662 | AE11: =Paralelo!M15 -> 107.04453 | AF11: =AE11-AD11 -> 0.778332 | AG11: ='Dez24'!N15 -> 75.884761 | AH11: =Paralelo!N15 -> 76.000791 | AI11: =AH11-AG11 -> 0.11603 | AJ11: ='Dez24'!O15 -> 35.911971 | AK11: =Paralelo!O15 -> 36.374197 | AL11: =AK11-AJ11 -> 0.462226 | AM11: ='Dez24'!P15 -> 33.117264 | AN11: =Paralelo!P15 -> 33.117265 | AO11: =AN11-AM11 -> 1e-06 | AP11: ='Dez24'!Q15 -> 0.712814 | AQ11: =Paralelo!Q15 -> 0.712814 | AR11: =AQ11-AP11 -> 0 | AS11: ='Dez24'!R15 -> 3073.6141 | AT11: =Paralelo!R15 -> 3073.5243 | AU11: =AT11-AS11 -> -0.08977
B12: Of which Loans collateralised by residential immovable property | C12: ='Dez24'!D16 -> 23291.747 | D12: =Paralelo!D16 -> 23269.568 | E12: =D12-C12 -> -22.179548 | F12: ='Dez24'!E16 -> 12529.955 | G12: =Paralelo!E16 -> 7646.9493 | H12: =G12-F12 -> -4883.0059 | I12: ='Dez24'!F16 -> 8394.6604 | J12: =Paralelo!F16 -> 4897.1426 | K12: =J12-I12 -> -3497.5177 | L12: ='Dez24'!G16 -> 2149.7291 | M12: =Paralelo!G16 -> 1572.3996 | N12: =M12-L12 -> -577.32951 | O12: ='Dez24'!H16 -> 178.97959 | P12: =Paralelo!H16 -> 239.35315 | Q12: =P12-O12 -> 60.373556 | R12: ='Dez24'!I16 -> 1.11081 | S12: =Paralelo!I16 -> 67.917334 | T12: =S12-R12 -> 66.806524 | U12: ='Dez24'!J16 -> 0 | V12: =Paralelo!J16 -> 74.010753 | W12: =V12-U12 -> 74.010753 | X12: ='Dez24'!K16 -> 1594.7241 | Y12: =Paralelo!K16 -> 1668.5366 | Z12: =Y12-X12 -> 73.812489 | AA12: ='Dez24'!L16 -> 1622.6418 | AB12: =Paralelo!L16 -> 1653.4401 | AC12: =AB12-AA12 -> 30.798274 | AD12: ='Dez24'!M16 -> 3193.2777 | AE12: =Paralelo!M16 -> 3210.6805 | AF12: =AE12-AD12 -> 17.402803 | AG12: ='Dez24'!N16 -> 3199.1957 | AH12: =Paralelo!N16 -> 3213.7215 | AI12: =AH12-AG12 -> 14.525807 | AJ12: ='Dez24'!O16 -> 1787.2819 | AK12: =Paralelo!O16 -> 1796.4857 | AL12: =AK12-AJ12 -> 9.203803 | AM12: ='Dez24'!P16 -> 783.44509 | AN12: =Paralelo!P16 -> 788.73487 | AO12: =AN12-AM12 -> 5.289778 | AP12: ='Dez24'!Q16 -> 2.266361 | AQ12: =Paralelo!Q16 -> 2.26636 | AR12: =AQ12-AP12 -> -1e-06 | AS12: ='Dez24'!R16 -> 11108.915 | AT12: =Paralelo!R16 -> 10935.702 | AU12: =AT12-AS12 -> -173.2125
B13: Of which Collateral obtained by taking possession: residential and commercial immovable properties | C13: ='Dez24'!D17 -> 48.451567 | D13: =Paralelo!D17 -> 0 | E13: =D13-C13 -> -48.451567 | F13: ='Dez24'!E17 -> 17.866427 | G13: =Paralelo!E17 -> 0 | H13: =G13-F13 -> -17.866427 | I13: ='Dez24'!F17 -> 25.344676 | J13: =Paralelo!F17 -> 0 | K13: =J13-I13 -> -25.344676 | L13: ='Dez24'!G17 -> 1.872164 | M13: =Paralelo!G17 -> 0 | N13: =M13-L13 -> -1.872164 | O13: ='Dez24'!H17 -> 0.211482 | P13: =Paralelo!H17 -> 0 | Q13: =P13-O13 -> -0.211482 | R13: ='Dez24'!I17 -> 0 | S13: =Paralelo!I17 -> 0 | T13: =S13-R13 -> 0 | U13: ='Dez24'!J17 -> 0 | V13: =Paralelo!J17 -> 0 | W13: =V13-U13 -> 0 | X13: ='Dez24'!K17 -> 0 | Y13: =Paralelo!K17 -> 0 | Z13: =Y13-X13 -> 0 | AA13: ='Dez24'!L17 -> 0.126583 | AB13: =Paralelo!L17 -> 0 | AC13: =AB13-AA13 -> -0.126583 | AD13: ='Dez24'!M17 -> 0.441368 | AE13: =Paralelo!M17 -> 0 | AF13: =AE13-AD13 -> -0.441368 | AG13: ='Dez24'!N17 -> 0.287407 | AH13: =Paralelo!N17 -> 0 | AI13: =AH13-AG13 -> -0.287407 | AJ13: ='Dez24'!O17 -> 0.262934 | AK13: =Paralelo!O17 -> 0 | AL13: =AK13-AJ13 -> -0.262934 | AM13: ='Dez24'!P17 -> 0.656973 | AN13: =Paralelo!P17 -> 0 | AO13: =AN13-AM13 -> -0.656973 | AP13: ='Dez24'!Q17 -> 0 | AQ13: =Paralelo!Q17 -> 0 | AR13: =AQ13-AP13 -> 0 | AS13: ='Dez24'!R17 -> 46.676302 | AT13: =Paralelo!R17 -> 0 | AU13: =AT13-AS13 -> -46.676302
B14: Of which Level of energy efficiency (EP score in kWh/m² of collateral) estimated | C14: ='Dez24'!D18 -> 26640.639 | D14: =Paralelo!D18 -> 17628.363 | E14: =D14-C14 -> -9012.2769 | F14: ='Dez24'!E18 -> 13857.398 | G14: =Paralelo!E18 -> 8842.7385 | H14: =G14-F14 -> -5014.6597 | I14: ='Dez24'!F18 -> 10225.192 | J14: =Paralelo!F18 -> 6594.472 | K14: =J14-I14 -> -3630.7196 | L14: ='Dez24'!G18 -> 2367.2076 | M14: =Paralelo!G18 -> 1780.6512 | N14: =M14-L14 -> -586.55637 | O14: ='Dez24'!H18 -> 188.21098 | P14: =Paralelo!H18 -> 249.81568 | Q14: =P14-O14 -> 61.604692 | R14: ='Dez24'!I18 -> 1.11082 | S14: =Paralelo!I18 -> 73.330776 | T14: =S14-R14 -> 72.219956 | U14: ='Dez24'!J18 -> 1.520131 | V14: =Paralelo!J18 -> 87.354293 | W14: =V14-U14 -> 85.834162 | AS14: ='Dez24'!R18 -> 13965.712 | AT14: =Paralelo!R18 -> 13749.273 | AU14: =AT14-AS14 -> -216.43899
B15: Total non-EU area | C15: ='Dez24'!D19 -> 0 | D15: =Paralelo!D19 -> 22.179551 | E15: =D15-C15 -> 22.179551 | F15: ='Dez24'!E19 -> 0 | G15: =Paralelo!E19 -> 10.931941 | H15: =G15-F15 -> 10.931941 | I15: ='Dez24'!F19 -> 0 | J15: =Paralelo!F19 -> 3.517605 | K15: =J15-I15 -> 3.517605 | L15: ='Dez24'!G19 -> 0 | M15: =Paralelo!G19 -> 2.41924 | N15: =M15-L15 -> 2.41924 | O15: ='Dez24'!H19 -> 0 | P15: =Paralelo!H19 -> 0.941389 | Q15: =P15-O15 -> 0.941389 | R15: ='Dez24'!I19 -> 0 | S15: =Paralelo!I19 -> 0.437974 | T15: =S15-R15 -> 0.437974 | U15: ='Dez24'!J19 -> 0 | V15: =Paralelo!J19 -> 0.135323 | W15: =V15-U15 -> 0.135323 | X15: ='Dez24'!K19 -> 0 | Y15: =Paralelo!K19 -> 3.06369 | Z15: =Y15-X15 -> 3.06369 | AA15: ='Dez24'!L19 -> 0 | AB15: =Paralelo!L19 -> 7.041839 | AC15: =AB15-AA15 -> 7.041839 | AD15: ='Dez24'!M19 -> 0 | AE15: =Paralelo!M19 -> 2.354883 | AF15: =AE15-AD15 -> 2.354883 | AG15: ='Dez24'!N19 -> 0 | AH15: =Paralelo!N19 -> 2.103447 | AI15: =AH15-AG15 -> 2.103447 | AJ15: ='Dez24'!O19 -> 0 | AK15: =Paralelo!O19 -> 2.369308 | AL15: =AK15-AJ15 -> 2.369308 | AM15: ='Dez24'!P19 -> 0 | AN15: =Paralelo!P19 -> 1.225682 | AO15: =AN15-AM15 -> 1.225682 | AP15: ='Dez24'!Q19 -> 0 | AQ15: =Paralelo!Q19 -> 0 | AR15: =AQ15-AP15 -> 0 | AS15: ='Dez24'!R19 -> 0 | AT15: =Paralelo!R19 -> 4.020702 | AU15: =AT15-AS15 -> 4.020702
B16: Of which Loans collateralised by commercial immovable property | C16: ='Dez24'!D20 -> 0 | D16: =Paralelo!D20 -> 0 | E16: =D16-C16 -> 0 | F16: ='Dez24'!E20 -> 0 | G16: =Paralelo!E20 -> 0 | H16: =G16-F16 -> 0 | I16: ='Dez24'!F20 -> 0 | J16: =Paralelo!F20 -> 0 | K16: =J16-I16 -> 0 | L16: ='Dez24'!G20 -> 0 | M16: =Paralelo!G20 -> 0 | N16: =M16-L16 -> 0 | O16: ='Dez24'!H20 -> 0 | P16: =Paralelo!H20 -> 0 | Q16: =P16-O16 -> 0 | R16: ='Dez24'!I20 -> 0 | S16: =Paralelo!I20 -> 0 | T16: =S16-R16 -> 0 | U16: ='Dez24'!J20 -> 0 | V16: =Paralelo!J20 -> 0 | W16: =V16-U16 -> 0 | X16: ='Dez24'!K20 -> 0 | Y16: =Paralelo!K20 -> 0 | Z16: =Y16-X16 -> 0 | AA16: ='Dez24'!L20 -> 0 | AB16: =Paralelo!L20 -> 0 | AC16: =AB16-AA16 -> 0 | AD16: ='Dez24'!M20 -> 0 | AE16: =Paralelo!M20 -> 0 | AF16: =AE16-AD16 -> 0 | AG16: ='Dez24'!N20 -> 0 | AH16: =Paralelo!N20 -> 0 | AI16: =AH16-AG16 -> 0 | AJ16: ='Dez24'!O20 -> 0 | AK16: =Paralelo!O20 -> 0 | AL16: =AK16-AJ16 -> 0 | AM16: ='Dez24'!P20 -> 0 | AN16: =Paralelo!P20 -> 0 | AO16: =AN16-AM16 -> 0 | AP16: ='Dez24'!Q20 -> 0 | AQ16: =Paralelo!Q20 -> 0 | AR16: =AQ16-AP16 -> 0 | AS16: ='Dez24'!R20 -> 0 | AT16: =Paralelo!R20 -> 0 | AU16: =AT16-AS16 -> 0
B17: Of which Loans collateralised by residential immovable property | C17: ='Dez24'!D21 -> 0 | D17: =Paralelo!D21 -> 22.179551 | E17: =D17-C17 -> 22.179551 | F17: ='Dez24'!E21 -> 0 | G17: =Paralelo!E21 -> 10.931941 | H17: =G17-F17 -> 10.931941 | I17: ='Dez24'!F21 -> 0 | J17: =Paralelo!F21 -> 3.517605 | K17: =J17-I17 -> 3.517605 | L17: ='Dez24'!G21 -> 0 | M17: =Paralelo!G21 -> 2.41924 | N17: =M17-L17 -> 2.41924 | O17: ='Dez24'!H21 -> 0 | P17: =Paralelo!H21 -> 0.941389 | Q17: =P17-O17 -> 0.941389 | R17: ='Dez24'!I21 -> 0 | S17: =Paralelo!I21 -> 0.437974 | T17: =S17-R17 -> 0.437974 | U17: ='Dez24'!J21 -> 0 | V17: =Paralelo!J21 -> 0.135323 | W17: =V17-U17 -> 0.135323 | X17: ='Dez24'!K21 -> 0 | Y17: =Paralelo!K21 -> 3.06369 | Z17: =Y17-X17 -> 3.06369 | AA17: ='Dez24'!L21 -> 0 | AB17: =Paralelo!L21 -> 7.041839 | AC17: =AB17-AA17 -> 7.041839 | AD17: ='Dez24'!M21 -> 0 | AE17: =Paralelo!M21 -> 2.354883 | AF17: =AE17-AD17 -> 2.354883 | AG17: ='Dez24'!N21 -> 0 | AH17: =Paralelo!N21 -> 2.103447 | AI17: =AH17-AG17 -> 2.103447 | AJ17: ='Dez24'!O21 -> 0 | AK17: =Paralelo!O21 -> 2.369308 | AL17: =AK17-AJ17 -> 2.369308 | AM17: ='Dez24'!P21 -> 0 | AN17: =Paralelo!P21 -> 1.225682 | AO17: =AN17-AM17 -> 1.225682 | AP17: ='Dez24'!Q21 -> 0 | AQ17: =Paralelo!Q21 -> 0 | AR17: =AQ17-AP17 -> 0 | AS17: ='Dez24'!R21 -> 0 | AT17: =Paralelo!R21 -> 4.020702 | AU17: =AT17-AS17 -> 4.020702
B18: Of which Collateral obtained by taking possession: residential and commercial immovable properties | C18: ='Dez24'!D22 -> 0 | D18: =Paralelo!D22 -> 0 | E18: =D18-C18 -> 0 | F18: ='Dez24'!E22 -> 0 | G18: =Paralelo!E22 -> 0 | H18: =G18-F18 -> 0 | I18: ='Dez24'!F22 -> 0 | J18: =Paralelo!F22 -> 0 | K18: =J18-I18 -> 0 | L18: ='Dez24'!G22 -> 0 | M18: =Paralelo!G22 -> 0 | N18: =M18-L18 -> 0 | O18: ='Dez24'!H22 -> 0 | P18: =Paralelo!H22 -> 0 | Q18: =P18-O18 -> 0 | R18: ='Dez24'!I22 -> 0 | S18: =Paralelo!I22 -> 0 | T18: =S18-R18 -> 0 | U18: ='Dez24'!J22 -> 0 | V18: =Paralelo!J22 -> 0 | W18: =V18-U18 -> 0 | X18: ='Dez24'!K22 -> 0 | Y18: =Paralelo!K22 -> 0 | Z18: =Y18-X18 -> 0 | AA18: ='Dez24'!L22 -> 0 | AB18: =Paralelo!L22 -> 0 | AC18: =AB18-AA18 -> 0 | AD18: ='Dez24'!M22 -> 0 | AE18: =Paralelo!M22 -> 0 | AF18: =AE18-AD18 -> 0 | AG18: ='Dez24'!N22 -> 0 | AH18: =Paralelo!N22 -> 0 | AI18: =AH18-AG18 -> 0 | AJ18: ='Dez24'!O22 -> 0 | AK18: =Paralelo!O22 -> 0 | AL18: =AK18-AJ18 -> 0 | AM18: ='Dez24'!P22 -> 0 | AN18: =Paralelo!P22 -> 0 | AO18: =AN18-AM18 -> 0 | AP18: ='Dez24'!Q22 -> 0 | AQ18: =Paralelo!Q22 -> 0 | AR18: =AQ18-AP18 -> 0 | AS18: ='Dez24'!R22 -> 0 | AT18: =Paralelo!R22 -> 0 | AU18: =AT18-AS18 -> 0
B19: Of which Level of energy efficiency (EP score in kWh/m² of collateral) estimated | C19: ='Dez24'!D23 -> 0 | D19: =Paralelo!D23 -> 18.383472 | E19: =D19-C19 -> 18.383472 | F19: ='Dez24'!E23 -> 0 | G19: =Paralelo!E23 -> 10.931941 | H19: =G19-F19 -> 10.931941 | I19: ='Dez24'!F23 -> 0 | J19: =Paralelo!F23 -> 3.517605 | K19: =J19-I19 -> 3.517605 | L19: ='Dez24'!G23 -> 0 | M19: =Paralelo!G23 -> 2.41924 | N19: =M19-L19 -> 2.41924 | O19: ='Dez24'!H23 -> 0 | P19: =Paralelo!H23 -> 0.941389 | Q19: =P19-O19 -> 0.941389 | R19: ='Dez24'!I23 -> 0 | S19: =Paralelo!I23 -> 0.437974 | T19: =S19-R19 -> 0.437974 | U19: ='Dez24'!J23 -> 0 | V19: =Paralelo!J23 -> 0.135323 | W19: =V19-U19 -> 0.135323 | AS19: ='Dez24'!R23 -> 0 | AT19: =Paralelo!R23 -> 2.34661 | AU19: =AT19-AS19 -> 2.34661

Sheet Variação Percentual (pp)
C8: Exposição | H8: 0; <= 100 | M8: > 100; <= 200 | R8: > 200; <= 300 | W8: > 300; <= 400 | AB8: > 400; <= 500 | AG8: > 500 | AL8: A | AQ8: B | AV8: C | BA8: D | BF8: E | BK8: F | BP8: G | BU8: Without EPC label of collateral
C9: Dez24 Tático | D9: peso dez24 tático | E9: Dez24 Estrutural | F9: peso dez24 estrutural | G9: ∆ (pp) | H9: Dez24 Tático | I9: peso dez24 tático | J9: Dez24 Estrutural | K9: peso dez24 estrutural | L9: ∆ (pp) | M9: Dez24 Tático | N9: peso dez24 tático | O9: Dez24 Estrutural | P9: peso dez24 estrutural | Q9: ∆ (pp) | R9: Dez24 Tático | S9: peso dez24 tático | T9: Dez24 Estrutural | U9: peso dez24 estrutural | V9: ∆ (pp) | W9: Dez24 Tático | X9: peso dez24 tático | Y9: Dez24 Estrutural | Z9: peso dez24 estrutural | AA9: ∆ (pp) | AB9: Dez24 Tático | AC9: peso dez24 tático | AD9: Dez24 Estrutural | AE9: peso dez24 estrutural | AF9: ∆ (pp) | AG9: Dez24 Tático | AH9: peso dez24 tático | AI9: Dez24 Estrutural | AJ9: peso dez24 estrutural | AK9: ∆ (pp) | AL9: Dez24 Tático | AM9: peso dez24 tático | AN9: Dez24 Estrutural | AO9: peso dez24 estrutural | AP9: ∆ (pp) | AQ9: Dez24 Tático | AR9: peso dez24 tático | AS9: Dez24 Estrutural | AT9: peso dez24 estrutural | AU9: ∆ (pp) | AV9: Dez24 Tático | AW9: peso dez24 tático | AX9: Dez24 Estrutural | AY9: peso dez24 estrutural | AZ9: ∆ (pp) | BA9: Dez24 Tático | BB9: peso dez24 tático | BC9: Dez24 Estrutural | BD9: peso dez24 estrutural | BE9: ∆ (pp) | BF9: Dez24 Tático | BG9: peso dez24 tático | BH9: Dez24 Estrutural | BI9: peso dez24 estrutural | BJ9: ∆ (pp) | BK9: Dez24 Tático | BL9: peso dez24 tático | BM9: Dez24 Estrutural | BN9: peso dez24 estrutural | BO9: ∆ (pp) | BP9: Dez24 Tático | BQ9: peso dez24 tático | BR9: Dez24 Estrutural | BS9: peso dez24 estrutural | BT9: ∆ (pp) | BU9: Dez24 Tático | BV9: peso dez24 tático | BW9: Dez24 Estrutural | BX9: peso dez24 estrutural | BY9: ∆ (pp)
B10: Total EU area | C10: ='Dez24'!D14 -> 26904.628 | E10: =Paralelo!D14 -> 26833.997 | H10: ='Dez24'!E14 -> 13857.398 | J10: =Paralelo!E14 -> 8842.7385 | M10: ='Dez24'!F14 -> 10225.192 | O10: =Paralelo!F14 -> 6594.472 | R10: ='Dez24'!G14 -> 2367.2076 | T10: =Paralelo!G14 -> 1780.6512 | W10: ='Dez24'!H14 -> 188.21098 | Y10: =Paralelo!H14 -> 249.81568 | AB10: ='Dez24'!I14 -> 1.11082 | AD10: =Paralelo!I14 -> 73.330776 | AG10: ='Dez24'!J14 -> 1.520131 | AI10: =Paralelo!J14 -> 87.354293 | AL10: ='Dez24'!K14 -> 1671.4506 | AN10: =Paralelo!K14 -> 1745.4755 | AQ10: ='Dez24'!L14 -> 1784.964 | AS10: =Paralelo!L14 -> 1814.1564 | AV10: ='Dez24'!M14 -> 3299.9853 | AX10: =Paralelo!M14 -> 3317.725 | BA10: ='Dez24'!N14 -> 3275.3678 | BC10: =Paralelo!N14 -> 3289.7223 | BF10: ='Dez24'!O14 -> 1823.4568 | BH10: =Paralelo!O14 -> 1832.8599 | BK10: ='Dez24'!P14 -> 817.21933 | BM10: =Paralelo!P14 -> 821.85213 | BP10: ='Dez24'!Q14 -> 2.979175 | BR10: =Paralelo!Q14 -> 2.979174 | BU10: ='Dez24'!R14 -> 14229.205 | BW10: =Paralelo!R14 -> 14009.226
B11: Of which Loans collateralised by commercial immovable property | C11: ='Dez24'!D15 -> 3564.4292 | D11: =IFERROR(C11/C$10,"-") -> 0.13248387 | E11: =Paralelo!D15 -> 3564.4292 | F11: =IFERROR(E11/E$10,"-") -> 0.13283259 | G11: =D11-F11 -> -0.0003487173 | H11: ='Dez24'!E15 -> 1309.5766 | I11: =IFERROR(H11/H$10,"-") -> 0.094503787 | J11: =Paralelo!E15 -> 1195.7892 | K11: =IFERROR(J11/J$10,"-") -> 0.13522838 | L11: =I11-K11 -> -0.040724593 | M11: ='Dez24'!F15 -> 1805.1866 | N11: =IFERROR(M11/M$10,"-") -> 0.17654306 | O11: =Paralelo!F15 -> 1697.3294 | P11: =IFERROR(O11/O$10,"-") -> 0.2573867 | Q11: =N11-P11 -> -0.080843638 | R11: ='Dez24'!G15 -> 215.60634 | S11: =IFERROR(R11/R$10,"-") -> 0.091080454 | T11: =Paralelo!G15 -> 208.25165 | U11: =IFERROR(T11/T$10,"-") -> 0.11695252 | V11: =S11-U11 -> -0.025872065 | W11: ='Dez24'!H15 -> 9.019911 | X11: =IFERROR(W11/W$10,"-") -> 0.047924467 | Y11: =Paralelo!H15 -> 10.462529 | Z11: =IFERROR(Y11/Y$10,"-") -> 0.041880995 | AA11: =X11-Z11 -> 0.0060434718 | AB11: ='Dez24'!I15 -> 1e-05 | AC11: =IFERROR(AB11/AB$10,"-") -> 9.0023586e-06 | AD11: =Paralelo!I15 -> 5.413442 | AE11: =IFERROR(AD11/AD$10,"-") -> 0.073822238 | AF11: =AC11-AE11 -> -0.073813236 | AG11: ='Dez24'!J15 -> 1.520131 | AH11: =IFERROR(AG11/AG$10,"-") -> 1 | AI11: =Paralelo!J15 -> 13.34354 | AJ11: =IFERROR(AI11/AI$10,"-") -> 0.15275197 | AK11: =AH11-AJ11 -> 0.84724803 | AL11: ='Dez24'!K15 -> 76.726507 | AM11: =IFERROR(AL11/AL$10,"-") -> 0.045904142 | AN11: =Paralelo!K15 -> 76.93894 | AO11: =IFERROR(AN11/AN$10,"-") -> 0.044079071 | AP11: =AM11-AO11 -> 0.0018250714 | AQ11: ='Dez24'!L15 -> 162.19559 | AR11: =IFERROR(AQ11/AQ$10,"-") -> 0.09086771 | AS11: =Paralelo!L15 -> 160.71633 | AT11: =IFERROR(AS11/AS$10,"-") -> 0.088590119 | AU11: =AR11-AT11 -> 0.0022775911 | AV11: ='Dez24'!M15 -> 106.2662 | AW11: =IFERROR(AV11/AV$10,"-") -> 0.032202023 | AX11: =Paralelo!M15 -> 107.04453 | AY11: =IFERROR(AX11/AX$10,"-") -> 0.032264438 | AZ11: =AW11-AY11 -> -6.2414943e-05 | BA11: ='Dez24'!N15 -> 75.884761 | BB11: =IFERROR(BA11/BA$10,"-") -> 0.023168317 | BC11: =Paralelo!N15 -> 76.000791 | BD11: =IFERROR(BC11/BC$10,"-") -> 0.023102495 | BE11: =BB11-BD11 -> 6.5822574e-05 | BF11: ='Dez24'!O15 -> 35.911971 | BG11: =IFERROR(BF11/BF$10,"-") -> 0.019694446 | BH11: =Paralelo!O15 -> 36.374197 | BI11: =IFERROR(BH11/BH$10,"-") -> 0.019845596 | BJ11: =BG11-BI11 -> -0.00015115026 | BK11: ='Dez24'!P15 -> 33.117264 | BL11: =IFERROR(BK11/BK$10,"-") -> 0.040524328 | BM11: =Paralelo!P15 -> 33.117265 | BN11: =IFERROR(BM11/BM$10,"-") -> 0.040295892 | BO11: =BL11-BN11 -> 0.00022843568 | BP11: ='Dez24'!Q15 -> 0.712814 | BQ11: =IFERROR(BP11/BP$10,"-") -> 0.23926557 | BR11: =Paralelo!Q15 -> 0.712814 | BS11: =IFERROR(BR11/BR$10,"-") -> 0.23926565 | BT11: =BQ11-BS11 -> -8.031272e-08 | BU11: ='Dez24'!R15 -> 3073.6141 | BV11: =IFERROR(BU11/BU$10,"-") -> 0.21600744 | BW11: =Paralelo!R15 -> 3073.5243 | BX11: =IFERROR(BW11/BW$10,"-") -> 0.21939287 | BY11: =BV11-BX11 -> -0.0033854287
B12: Of which Loans collateralised by residential immovable property | C12: ='Dez24'!D16 -> 23291.747 | D12: =IFERROR(C12/C$10,"-") -> 0.86571527 | E12: =Paralelo!D16 -> 23269.568 | F12: =IFERROR(E12/E$10,"-") -> 0.86716741 | G12: =D12-F12 -> -0.0014521464 | H12: ='Dez24'!E16 -> 12529.955 | I12: =IFERROR(H12/H$10,"-") -> 0.90420691 | J12: =Paralelo!E16 -> 7646.9493 | K12: =IFERROR(J12/J$10,"-") -> 0.86477162 | L12: =I12-K12 -> 0.039435287 | M12: ='Dez24'!F16 -> 8394.6604 | N12: =IFERROR(M12/M$10,"-") -> 0.82097829 | O12: =Paralelo!F16 -> 4897.1426 | P12: =IFERROR(O12/O$10,"-") -> 0.7426133 | Q12: =N12-P12 -> 0.078364987 | R12: ='Dez24'!G16 -> 2149.7291 | S12: =IFERROR(R12/R$10,"-") -> 0.90812867 | T12: =Paralelo!G16 -> 1572.3996 | U12: =IFERROR(T12/T$10,"-") -> 0.88304748 | V12: =S12-U12 -> 0.02508119 | W12: ='Dez24'!H16 -> 178.97959 | X12: =IFERROR(W12/W$10,"-") -> 0.95095189 | Y12: =Paralelo!H16 -> 239.35315 | Z12: =IFERROR(Y12/Y$10,"-") -> 0.95811901 | AA12: =X12-Z12 -> -0.0071671151 | AB12: ='Dez24'!I16 -> 1.11081 | AC12: =IFERROR(AB12/AB$10,"-") -> 0.999991 | AD12: =Paralelo!I16 -> 67.917334 | AE12: =IFERROR(AD12/AD$10,"-") -> 0.92617776 | AF12: =AC12-AE12 -> 0.073813236 | AG12: ='Dez24'!J16 -> 0 | AH12: =IFERROR(AG12/AG$10,"-") -> 0 | AI12: =Paralelo!J16 -> 74.010753 | AJ12: =IFERROR(AI12/AI$10,"-") -> 0.84724803 | AK12: =AH12-AJ12 -> -0.84724803 | AL12: ='Dez24'!K16 -> 1594.7241 | AM12: =IFERROR(AL12/AL$10,"-") -> 0.95409586 | AN12: =Paralelo!K16 -> 1668.5366 | AO12: =IFERROR(AN12/AN$10,"-") -> 0.95592093 | AP12: =AM12-AO12 -> -0.0018250714 | AQ12: ='Dez24'!L16 -> 1622.6418 | AR12: =IFERROR(AQ12/AQ$10,"-") -> 0.90906137 | AS12: =Paralelo!L16 -> 1653.4401 | AT12: =IFERROR(AS12/AS$10,"-") -> 0.91140988 | AU12: =AR12-AT12 -> -0.0023485074 | AV12: ='Dez24'!M16 -> 3193.2777 | AW12: =IFERROR(AV12/AV$10,"-") -> 0.96766423 | AX12: =Paralelo!M16 -> 3210.6805 | AY12: =IFERROR(AX12/AX$10,"-") -> 0.96773556 | AZ12: =AW12-AY12 -> -7.1333532e-05 | BA12: ='Dez24'!N16 -> 3199.1957 | BB12: =IFERROR(BA12/BA$10,"-") -> 0.97674393 | BC12: =Paralelo!N16 -> 3213.7215 | BD12: =IFERROR(BC12/BC$10,"-") -> 0.97689751 | BE12: =BB12-BD12 -> -0.00015357058 | BF12: ='Dez24'!O16 -> 1787.2819 | BG12: =IFERROR(BF12/BF$10,"-") -> 0.98016136 | BH12: =Paralelo!O16 -> 1796.4857 | BI12: =IFERROR(BH12/BH$10,"-") -> 0.9801544 | BJ12: =BG12-BI12 -> 6.9549065e-06 | BK12: ='Dez24'!P16 -> 783.44509 | BL12: =IFERROR(BK12/BK$10,"-") -> 0.95867176 | BM12: =Paralelo!P16 -> 788.73487 | BN12: =IFERROR(BM12/BM$10,"-") -> 0.95970411 | BO12: =BL12-BN12 -> -0.0010323484 | BP12: ='Dez24'!Q16 -> 2.266361 | BQ12: =IFERROR(BP12/BP$10,"-") -> 0.76073443 | BR12: =Paralelo!Q16 -> 2.26636 | BS12: =IFERROR(BR12/BR$10,"-") -> 0.76073435 | BT12: =BQ12-BS12 -> 8.031272e-08 | BU12: ='Dez24'!R16 -> 11108.915 | BV12: =IFERROR(BU12/BU$10,"-") -> 0.78071225 | BW12: =Paralelo!R16 -> 10935.702 | BX12: =IFERROR(BW12/BW$10,"-") -> 0.78060713 | BY12: =BV12-BX12 -> 0.00010511182
B13: Of which Collateral obtained by taking possession: residential and commercial immovable properties | C13: ='Dez24'!D17 -> 48.451567 | D13: =IFERROR(C13/C$10,"-") -> 0.0018008637 | E13: =Paralelo!D17 -> 0 | F13: =IFERROR(E13/E$10,"-") -> 0 | G13: =D13-F13 -> 0.0018008637 | H13: ='Dez24'!E17 -> 17.866427 | I13: =IFERROR(H13/H$10,"-") -> 0.001289306 | J13: =Paralelo!E17 -> 0 | K13: =IFERROR(J13/J$10,"-") -> 0 | L13: =I13-K13 -> 0.001289306 | M13: ='Dez24'!F17 -> 25.344676 | N13: =IFERROR(M13/M$10,"-") -> 0.0024786505 | O13: =Paralelo!F17 -> 0 | P13: =IFERROR(O13/O$10,"-") -> 0 | Q13: =N13-P13 -> 0.0024786505 | R13: ='Dez24'!G17 -> 1.872164 | S13: =IFERROR(R13/R$10,"-") -> 0.00079087444 | T13: =Paralelo!G17 -> 0 | U13: =IFERROR(T13/T$10,"-") -> 0 | V13: =S13-U13 -> 0.00079087444 | W13: ='Dez24'!H17 -> 0.211482 | X13: =IFERROR(W13/W$10,"-") -> 0.0011236432 | Y13: =Paralelo!H17 -> 0 | Z13: =IFERROR(Y13/Y$10,"-") -> 0 | AA13: =X13-Z13 -> 0.0011236432 | AB13: ='Dez24'!I17 -> 0 | AC13: =IFERROR(AB13/AB$10,"-") -> 0 | AD13: =Paralelo!I17 -> 0 | AE13: =IFERROR(AD13/AD$10,"-") -> 0 | AF13: =AC13-AE13 -> 0 | AG13: ='Dez24'!J17 -> 0 | AH13: =IFERROR(AG13/AG$10,"-") -> 0 | AI13: =Paralelo!J17 -> 0 | AJ13: =IFERROR(AI13/AI$10,"-") -> 0 | AK13: =AH13-AJ13 -> 0 | AL13: ='Dez24'!K17 -> 0 | AM13: =IFERROR(AL13/AL$10,"-") -> 0 | AN13: =Paralelo!K17 -> 0 | AO13: =IFERROR(AN13/AN$10,"-") -> 0 | AP13: =AM13-AO13 -> 0 | AQ13: ='Dez24'!L17 -> 0.126583 | AR13: =IFERROR(AQ13/AQ$10,"-") -> 7.0916276e-05 | AS13: =Paralelo!L17 -> 0 | AT13: =IFERROR(AS13/AS$10,"-") -> 0 | AU13: =AR13-AT13 -> 7.0916276e-05 | AV13: ='Dez24'!M17 -> 0.441368 | AW13: =IFERROR(AV13/AV$10,"-") -> 0.00013374848 | AX13: =Paralelo!M17 -> 0 | AY13: =IFERROR(AX13/AX$10,"-") -> 0 | AZ13: =AW13-AY13 -> 0.00013374848 | BA13: ='Dez24'!N17 -> 0.287407 | BB13: =IFERROR(BA13/BA$10,"-") -> 8.7748007e-05 | BC13: =Paralelo!N17 -> 0 | BD13: =IFERROR(BC13/BC$10,"-") -> 0 | BE13: =BB13-BD13 -> 8.7748007e-05 | BF13: ='Dez24'!O17 -> 0.262934 | BG13: =IFERROR(BF13/BF$10,"-") -> 0.00014419536 | BH13: =Paralelo!O17 -> 0 | BI13: =IFERROR(BH13/BH$10,"-") -> 0 | BJ13: =BG13-BI13 -> 0.00014419536 | BK13: ='Dez24'!P17 -> 0.656973 | BL13: =IFERROR(BK13/BK$10,"-") -> 0.00080391271 | BM13: =Paralelo!P17 -> 0 | BN13: =IFERROR(BM13/BM$10,"-") -> 0 | BO13: =BL13-BN13 -> 0.00080391271 | BP13: ='Dez24'!Q17 -> 0 | BQ13: =IFERROR(BP13/BP$10,"-") -> 0 | BR13: =Paralelo!Q17 -> 0 | BS13: =IFERROR(BR13/BR$10,"-") -> 0 | BT13: =BQ13-BS13 -> 0 | BU13: ='Dez24'!R17 -> 46.676302 | BV13: =IFERROR(BU13/BU$10,"-") -> 0.0032803169 | BW13: =Paralelo!R17 -> 0 | BX13: =IFERROR(BW13/BW$10,"-") -> 0 | BY13: =BV13-BX13 -> 0.0032803169
B14: Of which Level of energy efficiency (EP score in kWh/m² of collateral) estimated | C14: ='Dez24'!D18 -> 26640.639 | D14: =IFERROR(C14/C$10,"-") -> 0.99018798 | E14: =Paralelo!D18 -> 17628.363 | F14: =IFERROR(E14/E$10,"-") -> 0.65694136 | G14: =D14-F14 -> 0.33324662 | H14: ='Dez24'!E18 -> 13857.398 | I14: =IFERROR(H14/H$10,"-") -> 1 | J14: =Paralelo!E18 -> 8842.7385 | K14: =IFERROR(J14/J$10,"-") -> 1 | L14: =I14-K14 -> 0 | M14: ='Dez24'!F18 -> 10225.192 | N14: =IFERROR(M14/M$10,"-") -> 1 | O14: =Paralelo!F18 -> 6594.472 | P14: =IFERROR(O14/O$10,"-") -> 1 | Q14: =N14-P14 -> 0 | R14: ='Dez24'!G18 -> 2367.2076 | S14: =IFERROR(R14/R$10,"-") -> 1 | T14: =Paralelo!G18 -> 1780.6512 | U14: =IFERROR(T14/T$10,"-") -> 1 | V14: =S14-U14 -> 0 | W14: ='Dez24'!H18 -> 188.21098 | X14: =IFERROR(W14/W$10,"-") -> 1 | Y14: =Paralelo!H18 -> 249.81568 | Z14: =IFERROR(Y14/Y$10,"-") -> 1 | AA14: =X14-Z14 -> 0 | AB14: ='Dez24'!I18 -> 1.11082 | AC14: =IFERROR(AB14/AB$10,"-") -> 1 | AD14: =Paralelo!I18 -> 73.330776 | AE14: =IFERROR(AD14/AD$10,"-") -> 1 | AF14: =AC14-AE14 -> 0 | AG14: ='Dez24'!J18 -> 1.520131 | AH14: =IFERROR(AG14/AG$10,"-") -> 1 | AI14: =Paralelo!J18 -> 87.354293 | AJ14: =IFERROR(AI14/AI$10,"-") -> 1 | AK14: =AH14-AJ14 -> 0 | AL14: ='Dez24'!K18 -> 0 | AM14: =IFERROR(AL14/AL$10,"-") -> 0 | AN14: =Paralelo!K18 -> 0 | AO14: =IFERROR(AN14/AN$10,"-") -> 0 | AP14: =AM14-AO14 -> 0 | AQ14: ='Dez24'!L18 -> 0 | AR14: =IFERROR(AQ14/AQ$10,"-") -> 0 | AS14: =Paralelo!L18 -> 0 | AT14: =IFERROR(AS14/AS$10,"-") -> 0 | AU14: =AR14-AT14 -> 0 | AV14: ='Dez24'!M18 -> 0 | AW14: =IFERROR(AV14/AV$10,"-") -> 0 | AX14: =Paralelo!M18 -> 0 | AY14: =IFERROR(AX14/AX$10,"-") -> 0 | AZ14: =AW14-AY14 -> 0 | BA14: ='Dez24'!N18 -> 0 | BB14: =IFERROR(BA14/BA$10,"-") -> 0 | BC14: =Paralelo!N18 -> 0 | BD14: =IFERROR(BC14/BC$10,"-") -> 0 | BE14: =BB14-BD14 -> 0 | BF14: ='Dez24'!O18 -> 0 | BG14: =IFERROR(BF14/BF$10,"-") -> 0 | BH14: =Paralelo!O18 -> 0 | BI14: =IFERROR(BH14/BH$10,"-") -> 0 | BJ14: =BG14-BI14 -> 0 | BK14: ='Dez24'!P18 -> 0 | BL14: =IFERROR(BK14/BK$10,"-") -> 0 | BM14: =Paralelo!P18 -> 0 | BN14: =IFERROR(BM14/BM$10,"-") -> 0 | BO14: =BL14-BN14 -> 0 | BP14: ='Dez24'!Q18 -> 0 | BQ14: =IFERROR(BP14/BP$10,"-") -> 0 | BR14: =Paralelo!Q18 -> 0 | BS14: =IFERROR(BR14/BR$10,"-") -> 0 | BT14: =BQ14-BS14 -> 0 | BU14: ='Dez24'!R18 -> 13965.712 | BV14: =IFERROR(BU14/BU$10,"-") -> 0.98148227 | BW14: =Paralelo!R18 -> 13749.273 | BX14: =IFERROR(BW14/BW$10,"-") -> 0.98144415 | BY14: =BV14-BX14 -> 3.8112349e-05
B15: Total non-EU area | C15: ='Dez24'!D19 -> 0 | E15: =Paralelo!D19 -> 22.179551 | H15: ='Dez24'!E19 -> 0 | J15: =Paralelo!E19 -> 10.931941 | M15: ='Dez24'!F19 -> 0 | O15: =Paralelo!F19 -> 3.517605 | R15: ='Dez24'!G19 -> 0 | T15: =Paralelo!G19 -> 2.41924 | W15: ='Dez24'!H19 -> 0 | Y15: =Paralelo!H19 -> 0.941389 | AB15: ='Dez24'!I19 -> 0 | AD15: =Paralelo!I19 -> 0.437974 | AG15: ='Dez24'!J19 -> 0 | AI15: =Paralelo!J19 -> 0.135323 | AL15: ='Dez24'!K19 -> 0 | AN15: =Paralelo!K19 -> 3.06369 | AQ15: ='Dez24'!L19 -> 0 | AS15: =Paralelo!L19 -> 7.041839 | AV15: ='Dez24'!M19 -> 0 | AX15: =Paralelo!M19 -> 2.354883 | BA15: ='Dez24'!N19 -> 0 | BC15: =Paralelo!N19 -> 2.103447 | BF15: ='Dez24'!O19 -> 0 | BH15: =Paralelo!O19 -> 2.369308 | BK15: ='Dez24'!P19 -> 0 | BM15: =Paralelo!P19 -> 1.225682 | BP15: ='Dez24'!Q19 -> 0 | BR15: =Paralelo!Q19 -> 0 | BU15: ='Dez24'!R19 -> 0 | BW15: =Paralelo!R19 -> 4.020702
B16: Of which Loans collateralised by commercial immovable property | C16: ='Dez24'!D20 -> 0 | D16: =IFERROR(C16/C$15,"-") -> - | E16: =Paralelo!D20 -> 0 | F16: =IFERROR(E16/E$15,"-") -> 0 | G16: =IFERROR(D16-F16,"-") -> - | H16: ='Dez24'!E20 -> 0 | I16: =IFERROR(H16/H$15,"-") -> - | J16: =Paralelo!E20 -> 0 | K16: =IFERROR(J16/J$15,"-") -> 0 | L16: =IFERROR(I16-K16,"-") -> - | M16: ='Dez24'!F20 -> 0 | N16: =IFERROR(M16/M$15,"-") -> - | O16: =Paralelo!F20 -> 0 | P16: =IFERROR(O16/O$15,"-") -> 0 | Q16: =IFERROR(N16-P16,"-") -> - | R16: ='Dez24'!G20 -> 0 | S16: =IFERROR(R16/R$15,"-") -> - | T16: =Paralelo!G20 -> 0 | U16: =IFERROR(T16/T$15,"-") -> 0 | V16: =IFERROR(S16-U16,"-") -> - | W16: ='Dez24'!H20 -> 0 | X16: =IFERROR(W16/W$15,"-") -> - | Y16: =Paralelo!H20 -> 0 | Z16: =IFERROR(Y16/Y$15,"-") -> 0 | AA16: =IFERROR(X16-Z16,"-") -> - | AB16: ='Dez24'!I20 -> 0 | AC16: =IFERROR(AB16/AB$15,"-") -> - | AD16: =Paralelo!I20 -> 0 | AE16: =IFERROR(AD16/AD$15,"-") -> 0 | AF16: =IFERROR(AC16-AE16,"-") -> - | AG16: ='Dez24'!J20 -> 0 | AH16: =IFERROR(AG16/AG$15,"-") -> - | AI16: =Paralelo!J20 -> 0 | AJ16: =IFERROR(AI16/AI$15,"-") -> 0 | AK16: =IFERROR(AH16-AJ16,"-") -> - | AL16: ='Dez24'!K20 -> 0 | AM16: =IFERROR(AL16/AL$15,"-") -> - | AN16: =Paralelo!K20 -> 0 | AO16: =IFERROR(AN16/AN$15,"-") -> 0 | AP16: =IFERROR(AM16-AO16,"-") -> - | AQ16: ='Dez24'!L20 -> 0 | AR16: =IFERROR(AQ16/AQ$15,"-") -> - | AS16: =Paralelo!L20 -> 0 | AT16: =IFERROR(AS16/AS$15,"-") -> 0 | AU16: =IFERROR(AR16-AT16,"-") -> - | AV16: ='Dez24'!M20 -> 0 | AW16: =IFERROR(AV16/AV$15,"-") -> - | AX16: =Paralelo!M20 -> 0 | AY16: =IFERROR(AX16/AX$15,"-") -> 0 | AZ16: =IFERROR(AW16-AY16,"-") -> - | BA16: ='Dez24'!N20 -> 0 | BB16: =IFERROR(BA16/BA$15,"-") -> - | BC16: =Paralelo!N20 -> 0 | BD16: =IFERROR(BC16/BC$15,"-") -> 0 | BE16: =IFERROR(BB16-BD16,"-") -> - | BF16: ='Dez24'!O20 -> 0 | BG16: =IFERROR(BF16/BF$15,"-") -> - | BH16: =Paralelo!O20 -> 0 | BI16: =IFERROR(BH16/BH$15,"-") -> 0 | BJ16: =IFERROR(BG16-BI16,"-") -> - | BK16: ='Dez24'!P20 -> 0 | BL16: =IFERROR(BK16/BK$15,"-") -> - | BM16: =Paralelo!P20 -> 0 | BN16: =IFERROR(BM16/BM$15,"-") -> 0 | BO16: =IFERROR(BL16-BN16,"-") -> - | BP16: ='Dez24'!Q20 -> 0 | BQ16: =IFERROR(BP16/BP$15,"-") -> - | BR16: =Paralelo!Q20 -> 0 | BS16: =IFERROR(BR16/BR$15,"-") -> - | BT16: =IFERROR(BQ16-BS16,"-") -> - | BU16: ='Dez24'!R20 -> 0 | BV16: =IFERROR(BU16/BU$15,"-") -> - | BW16: =Paralelo!R20 -> 0 | BX16: =IFERROR(BW16/BW$15,"-") -> 0 | BY16: =IFERROR(BV16-BX16,"-") -> -
B17: Of which Loans collateralised by residential immovable property | C17: ='Dez24'!D21 -> 0 | D17: =IFERROR(C17/C$15,"-") -> - | E17: =Paralelo!D21 -> 22.179551 | F17: =IFERROR(E17/E$15,"-") -> 1 | G17: =IFERROR(D17-F17,"-") -> - | H17: ='Dez24'!E21 -> 0 | I17: =IFERROR(H17/H$15,"-") -> - | J17: =Paralelo!E21 -> 10.931941 | K17: =IFERROR(J17/J$15,"-") -> 1 | L17: =IFERROR(I17-K17,"-") -> - | M17: ='Dez24'!F21 -> 0 | N17: =IFERROR(M17/M$15,"-") -> - | O17: =Paralelo!F21 -> 3.517605 | P17: =IFERROR(O17/O$15,"-") -> 1 | Q17: =IFERROR(N17-P17,"-") -> - | R17: ='Dez24'!G21 -> 0 | S17: =IFERROR(R17/R$15,"-") -> - | T17: =Paralelo!G21 -> 2.41924 | U17: =IFERROR(T17/T$15,"-") -> 1 | V17: =IFERROR(S17-U17,"-") -> - | W17: ='Dez24'!H21 -> 0 | X17: =IFERROR(W17/W$15,"-") -> - | Y17: =Paralelo!H21 -> 0.941389 | Z17: =IFERROR(Y17/Y$15,"-") -> 1 | AA17: =IFERROR(X17-Z17,"-") -> - | AB17: ='Dez24'!I21 -> 0 | AC17: =IFERROR(AB17/AB$15,"-") -> - | AD17: =Paralelo!I21 -> 0.437974 | AE17: =IFERROR(AD17/AD$15,"-") -> 1 | AF17: =IFERROR(AC17-AE17,"-") -> - | AG17: ='Dez24'!J21 -> 0 | AH17: =IFERROR(AG17/AG$15,"-") -> - | AI17: =Paralelo!J21 -> 0.135323 | AJ17: =IFERROR(AI17/AI$15,"-") -> 1 | AK17: =IFERROR(AH17-AJ17,"-") -> - | AL17: ='Dez24'!K21 -> 0 | AM17: =IFERROR(AL17/AL$15,"-") -> - | AN17: =Paralelo!K21 -> 3.06369 | AO17: =IFERROR(AN17/AN$15,"-") -> 1 | AP17: =IFERROR(AM17-AO17,"-") -> - | AQ17: ='Dez24'!L21 -> 0 | AR17: =IFERROR(AQ17/AQ$15,"-") -> - | AS17: =Paralelo!L21 -> 7.041839 | AT17: =IFERROR(AS17/AS$15,"-") -> 1 | AU17: =IFERROR(AR17-AT17,"-") -> - | AV17: ='Dez24'!M21 -> 0 | AW17: =IFERROR(AV17/AV$15,"-") -> - | AX17: =Paralelo!M21 -> 2.354883 | AY17: =IFERROR(AX17/AX$15,"-") -> 1 | AZ17: =IFERROR(AW17-AY17,"-") -> - | BA17: ='Dez24'!N21 -> 0 | BB17: =IFERROR(BA17/BA$15,"-") -> - | BC17: =Paralelo!N21 -> 2.103447 | BD17: =IFERROR(BC17/BC$15,"-") -> 1 | BE17: =IFERROR(BB17-BD17,"-") -> - | BF17: ='Dez24'!O21 -> 0 | BG17: =IFERROR(BF17/BF$15,"-") -> - | BH17: =Paralelo!O21 -> 2.369308 | BI17: =IFERROR(BH17/BH$15,"-") -> 1 | BJ17: =IFERROR(BG17-BI17,"-") -> - | BK17: ='Dez24'!P21 -> 0 | BL17: =IFERROR(BK17/BK$15,"-") -> - | BM17: =Paralelo!P21 -> 1.225682 | BN17: =IFERROR(BM17/BM$15,"-") -> 1 | BO17: =IFERROR(BL17-BN17,"-") -> - | BP17: ='Dez24'!Q21 -> 0 | BQ17: =IFERROR(BP17/BP$15,"-") -> - | BR17: =Paralelo!Q21 -> 0 | BS17: =IFERROR(BR17/BR$15,"-") -> - | BT17: =IFERROR(BQ17-BS17,"-") -> - | BU17: ='Dez24'!R21 -> 0 | BV17: =IFERROR(BU17/BU$15,"-") -> - | BW17: =Paralelo!R21 -> 4.020702 | BX17: =IFERROR(BW17/BW$15,"-") -> 1 | BY17: =IFERROR(BV17-BX17,"-") -> -
B18: Of which Collateral obtained by taking possession: residential and commercial immovable properties | C18: ='Dez24'!D22 -> 0 | D18: =IFERROR(C18/C$15,"-") -> - | E18: =Paralelo!D22 -> 0 | F18: =IFERROR(E18/E$15,"-") -> 0 | G18: =IFERROR(D18-F18,"-") -> - | H18: ='Dez24'!E22 -> 0 | I18: =IFERROR(H18/H$15,"-") -> - | J18: =Paralelo!E22 -> 0 | K18: =IFERROR(J18/J$15,"-") -> 0 | L18: =IFERROR(I18-K18,"-") -> - | M18: ='Dez24'!F22 -> 0 | N18: =IFERROR(M18/M$15,"-") -> - | O18: =Paralelo!F22 -> 0 | P18: =IFERROR(O18/O$15,"-") -> 0 | Q18: =IFERROR(N18-P18,"-") -> - | R18: ='Dez24'!G22 -> 0 | S18: =IFERROR(R18/R$15,"-") -> - | T18: =Paralelo!G22 -> 0 | U18: =IFERROR(T18/T$15,"-") -> 0 | V18: =IFERROR(S18-U18,"-") -> - | W18: ='Dez24'!H22 -> 0 | X18: =IFERROR(W18/W$15,"-") -> - | Y18: =Paralelo!H22 -> 0 | Z18: =IFERROR(Y18/Y$15,"-") -> 0 | AA18: =IFERROR(X18-Z18,"-") -> - | AB18: ='Dez24'!I22 -> 0 | AC18: =IFERROR(AB18/AB$15,"-") -> - | AD18: =Paralelo!I22 -> 0 | AE18: =IFERROR(AD18/AD$15,"-") -> 0 | AF18: =IFERROR(AC18-AE18,"-") -> - | AG18: ='Dez24'!J22 -> 0 | AH18: =IFERROR(AG18/AG$15,"-") -> - | AI18: =Paralelo!J22 -> 0 | AJ18: =IFERROR(AI18/AI$15,"-") -> 0 | AK18: =IFERROR(AH18-AJ18,"-") -> - | AL18: ='Dez24'!K22 -> 0 | AM18: =IFERROR(AL18/AL$15,"-") -> - | AN18: =Paralelo!K22 -> 0 | AO18: =IFERROR(AN18/AN$15,"-") -> 0 | AP18: =IFERROR(AM18-AO18,"-") -> - | AQ18: ='Dez24'!L22 -> 0 | AR18: =IFERROR(AQ18/AQ$15,"-") -> - | AS18: =Paralelo!L22 -> 0 | AT18: =IFERROR(AS18/AS$15,"-") -> 0 | AU18: =IFERROR(AR18-AT18,"-") -> - | AV18: ='Dez24'!M22 -> 0 | AW18: =IFERROR(AV18/AV$15,"-") -> - | AX18: =Paralelo!M22 -> 0 | AY18: =IFERROR(AX18/AX$15,"-") -> 0 | AZ18: =IFERROR(AW18-AY18,"-") -> - | BA18: ='Dez24'!N22 -> 0 | BB18: =IFERROR(BA18/BA$15,"-") -> - | BC18: =Paralelo!N22 -> 0 | BD18: =IFERROR(BC18/BC$15,"-") -> 0 | BE18: =IFERROR(BB18-BD18,"-") -> - | BF18: ='Dez24'!O22 -> 0 | BG18: =IFERROR(BF18/BF$15,"-") -> - | BH18: =Paralelo!O22 -> 0 | BI18: =IFERROR(BH18/BH$15,"-") -> 0 | BJ18: =IFERROR(BG18-BI18,"-") -> - | BK18: ='Dez24'!P22 -> 0 | BL18: =IFERROR(BK18/BK$15,"-") -> - | BM18: =Paralelo!P22 -> 0 | BN18: =IFERROR(BM18/BM$15,"-") -> 0 | BO18: =IFERROR(BL18-BN18,"-") -> - | BP18: ='Dez24'!Q22 -> 0 | BQ18: =IFERROR(BP18/BP$15,"-") -> - | BR18: =Paralelo!Q22 -> 0 | BS18: =IFERROR(BR18/BR$15,"-") -> - | BT18: =IFERROR(BQ18-BS18,"-") -> - | BU18: ='Dez24'!R22 -> 0 | BV18: =IFERROR(BU18/BU$15,"-") -> - | BW18: =Paralelo!R22 -> 0 | BX18: =IFERROR(BW18/BW$15,"-") -> 0 | BY18: =IFERROR(BV18-BX18,"-") -> -
B19: Of which Level of energy efficiency (EP score in kWh/m² of collateral) estimated | C19: ='Dez24'!D23 -> 0 | D19: =IFERROR(C19/C$15,"-") -> - | E19: =Paralelo!D23 -> 18.383472 | F19: =IFERROR(E19/E$15,"-") -> 0.8288478 | G19: =IFERROR(D19-F19,"-") -> - | H19: ='Dez24'!E23 -> 0 | I19: =IFERROR(H19/H$15,"-") -> - | J19: =Paralelo!E23 -> 10.931941 | K19: =IFERROR(J19/J$15,"-") -> 1 | L19: =IFERROR(I19-K19,"-") -> - | M19: ='Dez24'!F23 -> 0 | N19: =IFERROR(M19/M$15,"-") -> - | O19: =Paralelo!F23 -> 3.517605 | P19: =IFERROR(O19/O$15,"-") -> 1 | Q19: =IFERROR(N19-P19,"-") -> - | R19: ='Dez24'!G23 -> 0 | S19: =IFERROR(R19/R$15,"-") -> - | T19: =Paralelo!G23 -> 2.41924 | U19: =IFERROR(T19/T$15,"-") -> 1 | V19: =IFERROR(S19-U19,"-") -> - | W19: ='Dez24'!H23 -> 0 | X19: =IFERROR(W19/W$15,"-") -> - | Y19: =Paralelo!H23 -> 0.941389 | Z19: =IFERROR(Y19/Y$15,"-") -> 1 | AA19: =IFERROR(X19-Z19,"-") -> - | AB19: ='Dez24'!I23 -> 0 | AC19: =IFERROR(AB19/AB$15,"-") -> - | AD19: =Paralelo!I23 -> 0.437974 | AE19: =IFERROR(AD19/AD$15,"-") -> 1 | AF19: =IFERROR(AC19-AE19,"-") -> - | AG19: ='Dez24'!J23 -> 0 | AH19: =IFERROR(AG19/AG$15,"-") -> - | AI19: =Paralelo!J23 -> 0.135323 | AJ19: =IFERROR(AI19/AI$15,"-") -> 1 | AK19: =IFERROR(AH19-AJ19,"-") -> - | AL19: ='Dez24'!K23 -> 0 | AM19: =IFERROR(AL19/AL$15,"-") -> - | AN19: =Paralelo!K23 -> 0 | AO19: =IFERROR(AN19/AN$15,"-") -> 0 | AP19: =IFERROR(AM19-AO19,"-") -> - | AQ19: ='Dez24'!L23 -> 0 | AR19: =IFERROR(AQ19/AQ$15,"-") -> - | AS19: =Paralelo!L23 -> 0 | AT19: =IFERROR(AS19/AS$15,"-") -> 0 | AU19: =IFERROR(AR19-AT19,"-") -> - | AV19: ='Dez24'!M23 -> 0 | AW19: =IFERROR(AV19/AV$15,"-") -> - | AX19: =Paralelo!M23 -> 0 | AY19: =IFERROR(AX19/AX$15,"-") -> 0 | AZ19: =IFERROR(AW19-AY19,"-") -> - | BA19: ='Dez24'!N23 -> 0 | BB19: =IFERROR(BA19/BA$15,"-") -> - | BC19: =Paralelo!N23 -> 0 | BD19: =IFERROR(BC19/BC$15,"-") -> 0 | BE19: =IFERROR(BB19-BD19,"-") -> - | BF19: ='Dez24'!O23 -> 0 | BG19: =IFERROR(BF19/BF$15,"-") -> - | BH19: =Paralelo!O23 -> 0 | BI19: =IFERROR(BH19/BH$15,"-") -> 0 | BJ19: =IFERROR(BG19-BI19,"-") -> - | BK19: ='Dez24'!P23 -> 0 | BL19: =IFERROR(BK19/BK$15,"-") -> - | BM19: =Paralelo!P23 -> 0 | BN19: =IFERROR(BM19/BM$15,"-") -> 0 | BO19: =IFERROR(BL19-BN19,"-") -> - | BP19: ='Dez24'!Q23 -> 0 | BQ19: =IFERROR(BP19/BP$15,"-") -> - | BR19: =Paralelo!Q23 -> 0 | BS19: =IFERROR(BR19/BR$15,"-") -> - | BT19: =IFERROR(BQ19-BS19,"-") -> - | BU19: ='Dez24'!R23 -> 0 | BV19: =IFERROR(BU19/BU$15,"-") -> - | BW19: =Paralelo!R23 -> 2.34661 | BX19: =IFERROR(BW19/BW$15,"-") -> 0.58363191 | BY19: =IFERROR(BV19-BX19,"-") -> -

Sheet Input >>

Sheet Paralelo
C8: Template 2: Banking book - Climate change transition risk: Loans collateralised by immovable property - Energy efficiency of the collateral
D10: a | E10: b | F10: c | G10: d | H10: e | I10: f | J10: g | K10: h | L10: i | M10: j | N10: k | O10: l | P10: m | Q10: n | R10: o | S10: p
C11: Counterparty sector | D11: Total gross carrying amount amount (in MEUR)
E12: Level of energy efficiency (EP score in kWh/m² of collateral) | K12: Level of energy efficiency (EPC label of collateral) | R12: Without EPC label of collateral
E13: 0; <= 100 | F13: > 100; <= 200 | G13: > 200; <= 300 | H13: > 300; <= 400 | I13: > 400; <= 500 | J13: > 500 | K13: A | L13: B | M13: C | N13: D | O13: E | P13: F | Q13: G | S13: Of which level of energy efficiency (EP score in kWh/m² of collateral) estimated
A14: 1000000 | B14: 1 | C14: Total EU area | D14: 26833.997 | E14: 8842.7385 | F14: 6594.472 | G14: 1780.6512 | H14: 249.81568 | I14: 73.330776 | J14: 87.354293 | K14: 1745.4755 | L14: 1814.1564 | M14: 3317.725 | N14: 3289.7223 | O14: 1832.8599 | P14: 821.85213 | Q14: 2.979174 | R14: 14009.226 | S14: 0.98145716
B15: 2 | C15: Of which Loans collateralised by commercial immovable property | D15: 3564.4292 | E15: 1195.7892 | F15: 1697.3294 | G15: 208.25165 | H15: 10.462529 | I15: 5.413442 | J15: 13.34354 | K15: 76.93894 | L15: 160.71633 | M15: 107.04453 | N15: 76.000791 | O15: 36.374197 | P15: 33.117265 | Q15: 0.712814 | R15: 3073.5243 | S15: 0.92701625
B16: 3 | C16: Of which Loans collateralised by residential immovable property | D16: 23269.568 | E16: 7646.9493 | F16: 4897.1426 | G16: 1572.3996 | H16: 239.35315 | I16: 67.917334 | J16: 74.010753 | K16: 1668.5366 | L16: 1653.4401 | M16: 3210.6805 | N16: 3213.7215 | O16: 1796.4857 | P16: 788.73487 | Q16: 2.26636 | R16: 10935.702 | S16: 0.99675801
B17: 4 | C17: Of which Collateral obtained by taking possession: residential and commercial immovable properties | D17: 0 | E17: 0 | F17: 0 | G17: 0 | H17: 0 | I17: 0 | J17: 0 | K17: 0 | L17: 0 | M17: 0 | N17: 0 | O17: 0 | P17: 0 | Q17: 0 | R17: 0 | S17: 0
B18: 5 | C18: Of which Level of energy efficiency (EP score in kWh/m² of collateral) estimated | D18: 17628.363 | E18: 8842.7385 | F18: 6594.472 | G18: 1780.6512 | H18: 249.81568 | I18: 73.330776 | J18: 87.354293 | R18: 13749.273 | S18: 1.0000133
B19: 6 | C19: Total non-EU area | D19: 22.179551 | E19: 10.931941 | F19: 3.517605 | G19: 2.41924 | H19: 0.941389 | I19: 0.437974 | J19: 0.135323 | K19: 3.06369 | L19: 7.041839 | M19: 2.354883 | N19: 2.103447 | O19: 2.369308 | P19: 1.225682 | Q19: 0 | R19: 4.020702 | S19: 0.58363191
B20: 7 | C20: Of which Loans collateralised by commercial immovable property | D20: 0 | E20: 0 | F20: 0 | G20: 0 | H20: 0 | I20: 0 | J20: 0 | K20: 0 | L20: 0 | M20: 0 | N20: 0 | O20: 0 | P20: 0 | Q20: 0 | R20: 0 | S20: 0
B21: 8 | C21: Of which Loans collateralised by residential immovable property | D21: 22.179551 | E21: 10.931941 | F21: 3.517605 | G21: 2.41924 | H21: 0.941389 | I21: 0.437974 | J21: 0.135323 | K21: 3.06369 | L21: 7.041839 | M21: 2.354883 | N21: 2.103447 | O21: 2.369308 | P21: 1.225682 | Q21: 0 | R21: 4.020702 | S21: 0.58363191
B22: 9 | C22: Of which Collateral obtained by taking possession: residential and commercial immovable properties | D22: 0 | E22: 0 | F22: 0 | G22: 0 | H22: 0 | I22: 0 | J22: 0 | K22: 0 | L22: 0 | M22: 0 | N22: 0 | O22: 0 | P22: 0 | Q22: 0 | R22: 0 | S22: 0
B23: 10 | C23: Of which Level of energy efficiency (EP score in kWh/m² of collateral) estimated | D23: 18.383472 | E23: 10.931941 | F23: 3.517605 | G23: 2.41924 | H23: 0.941389 | I23: 0.437974 | J23: 0.135323 | R23: 2.34661 | S23: 1

Sheet Dez24
C8: Template 2: Banking book - Climate change transition risk: Loans collateralised by immovable property - Energy efficiency of the collateral
D10: a | E10: b | F10: c | G10: d | H10: e | I10: f | J10: g | K10: h | L10: i | M10: j | N10: k | O10: l | P10: m | Q10: n | R10: o | S10: p
C11: Counterparty sector | D11: Total gross carrying amount amount (in MEUR)
E12: Level of energy efficiency (EP score in kWh/m² of collateral) | K12: Level of energy efficiency (EPC label of collateral) | R12: Without EPC label of collateral
E13: 0; <= 100 | F13: > 100; <= 200 | G13: > 200; <= 300 | H13: > 300; <= 400 | I13: > 400; <= 500 | J13: > 500 | K13: A | L13: B | M13: C | N13: D | O13: E | P13: F | Q13: G | S13: Of which level of energy efficiency (EP score in kWh/m² of collateral) estimated
A14: 1000000 | B14: 1 | C14: Total EU area | D14: 26904.628 | E14: 13857.398 | F14: 10225.192 | G14: 2367.2076 | H14: 188.21098 | I14: 1.11082 | J14: 1.520131 | K14: 1671.4506 | L14: 1784.964 | M14: 3299.9853 | N14: 3275.3678 | O14: 1823.4568 | P14: 817.21933 | Q14: 2.979175 | R14: 14229.205 | S14: 0.98145783
B15: 2 | C15: Of which Loans collateralised by commercial immovable property | D15: 3564.4292 | E15: 1309.5766 | F15: 1805.1866 | G15: 215.60634 | H15: 9.019911 | I15: 1e-05 | J15: 1.520131 | K15: 76.726507 | L15: 162.19559 | M15: 106.2662 | N15: 75.884761 | O15: 35.911971 | P15: 33.117264 | Q15: 0.712814 | R15: 3073.6141 | S15: 0.92727751
B16: 3 | C16: Of which Loans collateralised by residential immovable property | D16: 23291.747 | E16: 12529.955 | F16: 8394.6604 | G16: 2149.7291 | H16: 178.97959 | I16: 1.11081 | J16: 0 | K16: 1594.7241 | L16: 1622.6418 | M16: 3193.2777 | N16: 3199.1957 | O16: 1787.2819 | P16: 783.44509 | Q16: 2.266361 | R16: 11108.915 | S16: 0.99666213
B17: 4 | C17: Of which Collateral obtained by taking possession: residential and commercial immovable properties | D17: 48.451567 | E17: 17.866427 | F17: 25.344676 | G17: 1.872164 | H17: 0.211482 | I17: 0 | J17: 0 | K17: 0 | L17: 0.126583 | M17: 0.441368 | N17: 0.287407 | O17: 0.262934 | P17: 0.656973 | Q17: 0 | R17: 46.676302 | S17: 0.93059913
B18: 5 | C18: Of which Level of energy efficiency (EP score in kWh/m² of collateral) estimated | D18: 26640.639 | E18: 13857.398 | F18: 10225.192 | G18: 2367.2076 | H18: 188.21098 | I18: 1.11082 | J18: 1.520131 | R18: 13965.712 | S18: 0.9999751
B19: 6 | C19: Total non-EU area | D19: 0 | E19: 0 | F19: 0 | G19: 0 | H19: 0 | I19: 0 | J19: 0 | K19: 0 | L19: 0 | M19: 0 | N19: 0 | O19: 0 | P19: 0 | Q19: 0 | R19: 0 | S19: 0
B20: 7 | C20: Of which Loans collateralised by commercial immovable property | D20: 0 | E20: 0 | F20: 0 | G20: 0 | H20: 0 | I20: 0 | J20: 0 | K20: 0 | L20: 0 | M20: 0 | N20: 0 | O20: 0 | P20: 0 | Q20: 0 | R20: 0 | S20: 0
B21: 8 | C21: Of which Loans collateralised by residential immovable property | D21: 0 | E21: 0 | F21: 0 | G21: 0 | H21: 0 | I21: 0 | J21: 0 | K21: 0 | L21: 0 | M21: 0 | N21: 0 | O21: 0 | P21: 0 | Q21: 0 | R21: 0 | S21: 0
B22: 9 | C22: Of which Collateral obtained by taking possession: residential and commercial immovable properties | D22: 0 | E22: 0 | F22: 0 | G22: 0 | H22: 0 | I22: 0 | J22: 0 | K22: 0 | L22: 0 | M22: 0 | N22: 0 | O22: 0 | P22: 0 | Q22: 0 | R22: 0 | S22: 0
B23: 10 | C23: Of which Level of energy efficiency (EP score in kWh/m² of collateral) estimated | D23: 0 | E23: 0 | F23: 0 | G23: 0 | H23: 0 | I23: 0 | J23: 0 | R23: 0 | S23: 0
